Workbook
Name 변수H: 변수!$C$1:$AO$1
Name 환율: 변수!$C$6:$AO$13
Name BS연결H: BS연결!$C$1:$AO$1
Name BS연결: BS연결!$C$5:$AO$105
Name BS별도H: BS별도!$C$1:$AO$1
Name BS별도: BS별도!$C$5:$AO$91
Name SUBQH: subQ!$A$1:$AO$1
Name subQ: subQ!$A$5:$AO$41

Sheet README
A1: 한일철강(002220) 실적 모델 — ARGUS 한국조선
A2: 기준 분기 2026Q2 · 마지막 실적 2026Q2 · 생성 2026-10-13
A3: 모든 수치는 모델 산출값(DART 공개 재무제표 + 우리 추정)이다 — 목표주가·투자 추천 아님. 참고용 · 투자조언 아님.
A5: 시트
A6: 변수 가정 시계열. 환율 8행(ECB via frankfurter — L2 fx.json; 추정 분기 = 노란 가정), 추정 드라이버(노란 셀 = 모델값에서 역산한 가정, 바꾸면 재계산; 연녹 셀 = 3절 스칼라 참조 수식), 3절 스칼라 가정(세율·판관비율·지배주주비중·이자율·종가·PER 밴드·COE·외화 순노출·헤지비율)
A7: BS연결/BS별도 FnGuide 계정명 × 기간 값 덤프(백만원). 행1 분기라벨, 행4 YYYY.MM / YYYY.12A. 이름정의 BS연결H·BS연결(계정명 C열부터)
A8: subQ 분기 서브모델(억원 = 백만원/100). 확정 행: =IFERROR(VLOOKUP($D행,BS연결,MATCH(E$1,BS연결H,0),0)/100,"") 추정 행: 변수 시트 가정 셀 참조 수식. 외환손익·파생상품손익은 BS 계정 합·차, 기타금융손익은 잔차, OPM·EPS·BPS·PER·PBR 은 파생 수식
A9: SLS 선표(조선사만, sls json 있을 때): 요약 행(sls 저장값) + 계약별 스케줄(백만$) × (헤지비율 × 헤지환율 + (1−헤지비율) × 건조시점 환율[변수 원/달러(평균)]) → 원화 수식 블록 → 합계 행이 subQ 매출조선에 연결
A10: 시나리오 신규수주 보수/기준/낙관(forecast_panel 패널, 모델에 scenarios 가 있을 때만): 매출액·영업이익 = subQ 기준값 ± (시나리오 신규 − base 신규) × OPM. base 만 subQ 행에 포함, 나머지는 합산 안 함
A11: 분기/연간예상 subQ 를 이름(A열 key)으로 VLOOKUP 한 보고서 표(억원)
A12: TP PER 밴드 × 12M fwd EPS, PBR = ROE/COE × BPS — 모델 산출값 구간, 목표주가·추천 아님
A13: 외화 환율 QoQ, 외화 순노출 × Δ기말환율 → 환관련손익 추정
... A34: 백테스트: {"freeze": "2025Q2", "horizon": 4, "revenue_wape_pct": 20.5, "op_wape_pct": 88.9, "n": 4, "note": "단일 회사 4분기 — 통계 아님", "driver_at_freeze": "trend_seasonal", "selection_oos_at_freeze": null, "frozen_inputs": "fin(연결/별도)·고객 조선사 모델·지주 자회사 모델은 2025Q2 까지의 분기만; 선표는 체결일 ≤ 2025Q2 말일 계약(원장 최신 금액·코호트 등급, 환산 없음); 잔고는 yards_cache 2025Q2; 시세·환율 forward·prices·forecast_panel 신규수주 미사용. 고객 가중치(suppliers.json 언급 비중)와 합병 체인링크는 현재 지식; 고객 연동 채택은 동결 모델 안에서도 자기 la−4분기 OOS 규칙(selection_oos_at_freeze)", "detail": [{"q": "2025Q3", "rev_pred": 420.44, "rev_act": 508.41, "op_pred": 2.4, "op_act": 14.24}, {"q": "2025Q4", "rev_pred": 537.81, "rev_act": 456.95, "op_pred": 3.08, "op_act": 0.26}, {"q": "2026Q1", "rev_pred": 475.16, "rev_act": 618.74, "op_pred": 2.72, "op_act": 4.63}, {"q": "2026Q2", "rev_pred": 478.52, "rev_act": 617.57, "op_pred": 2.74, "op_act": 28.56}]}

Sheet 변수
C1: 이름: 변수H | E1: 4Q21 | F1: 2021 | G1: 1Q22 | H1: 2Q22 | I1: 3Q22 | J1: 4Q22 | K1: 2022 | L1: 1Q23 | M1: 2Q23 | N1: 3Q23 | O1: 4Q23 | P1: 2023 | Q1: 1Q24 | R1: 2Q24 | S1: 3Q24 | T1: 4Q24 | U1: 2024 | V1: 1Q25 | W1: 2Q25 | X1: 3Q25 | Y1: 4Q25 | Z1: 2025 | AA1: 1Q26 | AB1: 2Q26 | AC1: 3Q26 | AD1: 4Q26 | AE1: 2026 | AF1: 1Q27 | AG1: 2Q27 | AH1: 3Q27 | AI1: 4Q27 | AJ1: 2027 | AK1: 1Q28 | AL1: 2Q28 | AM1: 3Q28 | AN1: 4Q28 | AO1: 2028
A2: 가정 시계열 — 노란 셀은 추정 가정(모델값에서 역산), 연녹 셀은 3절 스칼라 참조 수식. 바꾸면 subQ·분기·연간예상·TP·시나리오가 재계산됩니다.
E3: 1 | F3: 2 | G3: 3 | H3: 4 | I3: 5 | J3: 6 | K3: 7 | L3: 8 | M3: 9 | N3: 10 | O3: 11 | P3: 12 | Q3: 13 | R3: 14 | S3: 15 | T3: 16 | U3: 17 | V3: 18 | W3: 19 | X3: 20 | Y3: 21 | Z3: 22 | AA3: 23 | AB3: 24 | AC3: 25 | AD3: 26 | AE3: 27 | AF3: 28 | AG3: 29 | AH3: 30 | AI3: 31 | AJ3: 32 | AK3: 33 | AL3: 34 | AM3: 35 | AN3: 36 | AO3: 37
E4: 2021.12 | F4: 2021.12A | G4: 2022.03 | H4: 2022.06 | I4: 2022.09 | J4: 2022.12 | K4: 2022.12A | L4: 2023.03 | M4: 2023.06 | N4: 2023.09 | O4: 2023.12 | P4: 2023.12A | Q4: 2024.03 | R4: 2024.06 | S4: 2024.09 | T4: 2024.12 | U4: 2024.12A | V4: 2025.03 | W4: 2025.06 | X4: 2025.09 | Y4: 2025.12 | Z4: 2025.12A | AA4: 2026.03 | AB4: 2026.06 | AC4: 2026.09 | AD4: 2026.12 | AE4: 2026.12A | AF4: 2027.03 | AG4: 2027.06 | AH4: 2027.09 | AI4: 2027.12 | AJ4: 2027.12A | AK4: 2028.03 | AL4: 2028.06 | AM4: 2028.09 | AN4: 2028.12 | AO4: 2028.12A
B5: 1. FX | C5: 이름: 환율
A6: USDKRW_avg | C6: 원/달러(평균) | E6: 1183.5 | F6: 1145.51 | G6: 1205.78 | H6: 1262.09 | I6: 1341.93 | J6: 1360.12 | K6: 1292.98 | L6: 1276.95 | M6: 1315.69 | N6: 1313.62 | O6: 1322.01 | P6: 1306.85 | Q6: 1330.14 | R6: 1371.28 | S6: 1356.22 | T6: 1396.3 | U6: 1363.53 | V6: 1452.28 | W6: 1398.52 | X6: 1386.95 | Y6: 1449.19 | Z6: 1421.52 | AA6: 1466.12 | AB6: 1501.75 | AC6: 1418.75 | AD6: 1343.63 | AE6: 1456.58 | AF6: 1333.09 | AG6: 1333.09 | AH6: 1333.09 | AI6: 1333.09 | AK6: 1333.09 | AL6: 1333.09 | AM6: 1333.09 | AN6: 1333.09
A7: USDKRW_end | C7: 원/달러(기말) | E7: 1188.75 | F7: 1188.75 | G7: 1213.74 | H7: 1301.24 | I7: 1436.9 | J7: 1260.16 | K7: 1260.16 | L7: 1305.99 | M7: 1321.44 | N7: 1345.35 | O7: 1297.43 | P7: 1297.43 | Q7: 1349.25 | R7: 1377.73 | S7: 1312.17 | T7: 1474.78 | U7: 1474.78 | V7: 1474.54 | W7: 1355.13 | X7: 1403.67 | Y7: 1444.2 | Z7: 1444.2 | AA7: 1524.8 | AB7: 1550.89 | AC7: 1355.4 | AD7: 1333.09 | AE7: 1333.09 | AF7: 1333.09 | AG7: 1333.09 | AH7: 1333.09 | AI7: 1333.09 | AK7: 1333.09 | AL7: 1333.09 | AM7: 1333.09 | AN7: 1333.09
A8: JPY100KRW_avg | C8: 원/100Y(평균) | E8: 1041.02 | F8: 1042.74 | G8: 1036.79 | H8: 972.23 | I8: 970.61 | J8: 961.03 | K8: 985.1 | L8: 964.89 | M8: 957.36 | N8: 909 | O8: 893.22 | P8: 931.11 | Q8: 896.29 | R8: 880.14 | S8: 909.35 | T8: 917.25 | U8: 900.92 | V8: 952.59 | W8: 967.92 | X8: 940.32 | Y8: 940.77 | Z8: 950.17 | AA8: 934.39 | AB8: 942.16 | AC8: 890.41 | AD8: 849.51 | AE8: 918.81 | AF8: 840.54 | AG8: 840.54 | AH8: 840.54 | AI8: 840.54 | AK8: 840.54 | AL8: 840.54 | AM8: 840.54 | AN8: 840.54
A9: JPY100KRW_end | C9: 원/100Y(기말) | E9: 1032.62 | F9: 1032.62 | G9: 996.83 | H9: 954.9 | I9: 993.29 | J9: 955.54 | K9: 955.54 | L9: 980.62 | M9: 913.67 | N9: 901.47 | O9: 917.04 | P9: 917.04 | Q9: 892.42 | R9: 857.76 | S9: 919.21 | T9: 939.65 | U9: 939.65 | V9: 986.84 | W9: 938.85 | X9: 948.49 | Y9: 921.81 | Z9: 921.81 | AA9: 955.99 | AB9: 954.75 | AC9: 863.31 | AD9: 840.54 | AE9: 840.54 | AF9: 840.54 | AG9: 840.54 | AH9: 840.54 | AI9: 840.54 | AK9: 840.54 | AL9: 840.54 | AM9: 840.54 | AN9: 840.54
A10: EURKRW_avg | C10: W/Euro(평균) | E10: 1353.32 | F10: 1354.06 | G10: 1352.29 | H10: 1343.31 | I10: 1350.63 | J10: 1386.07 | K10: 1358.07 | L10: 1369.93 | M10: 1432.41 | N10: 1429.41 | O10: 1420.91 | P10: 1412.88 | Q10: 1444.21 | R10: 1476.42 | S10: 1489.3 | T10: 1490.78 | U10: 1475.4 | V10: 1528.33 | W10: 1585.13 | X10: 1620.04 | Y10: 1686.02 | Z10: 1605.45 | AA10: 1715.47 | AB10: 1746.09 | AC10: 1631.97 | AD10: 1507.34 | AE10: 1688.95 | AF10: 1490.54 | AG10: 1490.54 | AH10: 1490.54 | AI10: 1490.54 | AK10: 1490.54 | AL10: 1490.54 | AM10: 1490.54 | AN10: 1490.54
A11: EURKRW_end | C11: W/Euro(기말) | E11: 1346.38 | F11: 1346.38 | G11: 1347.37 | H11: 1351.6 | I11: 1400.62 | J11: 1344.08 | K11: 1344.08 | L11: 1420.26 | M11: 1435.88 | N11: 1425.26 | O11: 1433.66 | P11: 1433.66 | Q11: 1458.68 | R11: 1474.86 | S11: 1469.1 | T11: 1532.14 | U11: 1532.14 | V11: 1594.72 | W11: 1588.22 | X11: 1648.04 | Y11: 1696.94 | Z11: 1696.94 | AA11: 1753.21 | AB11: 1767.09 | AC11: 1539.06 | AD11: 1490.54 | AE11: 1490.54 | AF11: 1490.54 | AG11: 1490.54 | AH11: 1490.54 | AI11: 1490.54 | AK11: 1490.54 | AL11: 1490.54 | AM11: 1490.54 | AN11: 1490.54
A12: CNYKRW_avg | C12: 원/중국원(평균) | E12: 185.14 | F12: 177.65 | G12: 189.93 | H12: 190.76 | I12: 195.79 | J12: 191.09 | K12: 191.93 | L12: 186.59 | M12: 187.45 | N12: 181.28 | O12: 182.86 | P12: 184.52 | Q12: 185.04 | R12: 189.35 | S12: 189.24 | T12: 194.24 | U12: 189.49 | V12: 199.63 | W12: 193.41 | X12: 193.79 | Y12: 204.38 | Z12: 197.8 | AA12: 211.75 | AB12: 220.8 | AC12: 210.43 | AD12: 200.5 | AE12: 213.68 | AF12: 199.18 | AG12: 199.18 | AH12: 199.18 | AI12: 199.18 | AK12: 199.18 | AL12: 199.18 | AM12: 199.18 | AN12: 199.18
A13: CNYKRW_end | C13: 원/중국원(기말) | E13: 187.13 | F13: 187.13 | G13: 191.38 | H13: 194.13 | I13: 201.92 | J13: 182.67 | K13: 182.67 | L13: 189.97 | M13: 181.8 | N13: 184.26 | O13: 182.61 | P13: 182.61 | Q13: 186.66 | R13: 189.7 | S13: 187.12 | T13: 202.04 | U13: 202.04 | V13: 203.3 | W13: 189.14 | X13: 197.16 | Y13: 206.28 | Z13: 206.28 | AA13: 220.97 | AB13: 228.56 | AC13: 202.16 | AD13: 199.18 | AE13: 199.18 | AF13: 199.18 | AG13: 199.18 | AH13: 199.18 | AI13: 199.18 | AK13: 199.18 | AL13: 199.18 | AM13: 199.18 | AN13: 199.18
B14: 1b. 종가
A15: price_close_end | C15: 종가(기말) | E15: 2675 | G15: 4050 | H15: 3785 | I15: 3335 | J15: 2815 | L15: 3060 | M15: 3375 | N15: 2720 | O15: 2390 | Q15: 2640 | R15: 2310 | S15: 2030 | T15: 1910 | V15: 1834 | W15: 2550 | X15: 3310 | Y15: 5070 | AA15: 3835 | AB15: 4205 | AC15: 2830 | AD15: 2900
A16: price_high | C16: 종가(최고) | E16: 3635 | G16: 4700 | H16: 6730 | I16: 4705 | J16: 3900 | L16: 3525 | M16: 4065 | N16: 3470 | O16: 2760 | Q16: 2890 | R16: 2765 | S16: 2305 | T16: 2190 | V16: 2025 | W16: 3060 | X16: 3600 | Y16: 5500 | AA16: 5700 | AB16: 6470 | AC16: 4770 | AD16: 3150
A17: price_low | C17: 종가(최저) | E17: 2495 | G17: 2675 | H17: 3400 | I17: 3275 | J17: 2755 | L17: 2640 | M17: 2970 | N17: 2635 | O17: 2245 | Q17: 2330 | R17: 2265 | S17: 1950 | T17: 1854 | V17: 1609 | W17: 1765 | X17: 2485 | Y17: 3190 | AA17: 3500 | AB17: 3810 | AC17: 2330 | AD17: 2725
A18: price_avg | C18: 종가(평균) | E18: 2948.2 | G18: 3349.1 | H18: 4652.4 | I18: 3941.8 | J18: 3124.7 | L18: 3078.4 | M18: 3248.4 | N18: 3082.1 | O18: 2531.2 | Q18: 2554.8 | R18: 2421.8 | S18: 2123.5 | T18: 1995.6 | V18: 1890.9 | W18: 2159.9 | X18: 2976 | Y18: 4424.1 | AA18: 4393.9 | AB18: 4846.3 | AC18: 3358.6 | AD18: 2882.9
B20: 2. 추정 드라이버 | C20: 실적 열 = subQ 실현값(수식), 추정 열 = 가정(노란 = 모델값 역산, 연녹 = 3절 스칼라 참조)
A21: drv:매출액 | B21: yoy | C21: 매출액 YoY | J21: =IFERROR(subQ!J5/subQ!E5-1,"") | L21: =IFERROR(subQ!L5/subQ!G5-1,"") | M21: =IFERROR(subQ!M5/subQ!H5-1,"") | N21: =IFERROR(subQ!N5/subQ!I5-1,"") | O21: =IFERROR(subQ!O5/subQ!J5-1,"") | Q21: =IFERROR(subQ!Q5/subQ!L5-1,"") | R21: =IFERROR(subQ!R5/subQ!M5-1,"") | S21: =IFERROR(subQ!S5/subQ!N5-1,"") | T21: =IFERROR(subQ!T5/subQ!O5-1,"") | V21: =IFERROR(subQ!V5/subQ!Q5-1,"") | W21: =IFERROR(subQ!W5/subQ!R5-1,"") | X21: =IFERROR(subQ!X5/subQ!S5-1,"") | Y21: =IFERROR(subQ!Y5/subQ!T5-1,"") | AA21: =IFERROR(subQ!AA5/subQ!V5-1,"") | AB21: =IFERROR(subQ!AB5/subQ!W5-1,"") | AC21: 0.099663008 | AD21: 0.099655981 | AF21: 0.099660534 | AG21: 0.099661432 | AH21: 0.04981398 | AI21: 0.049831837 | AK21: 0.049823633 | AL21: 0.049814466 | AM21: 0.024926311 | AN21: 0.024908536
A22: drv:판관비 | B22: ratio | C22: 판관비율(/매출) | E22: =IFERROR(subQ!E8/subQ!E5,"") | F22: =IFERROR(subQ!F8/subQ!F5,"") | G22: =IFERROR(subQ!G8/subQ!G5,"") | H22: =IFERROR(subQ!H8/subQ!H5,"") | I22: =IFERROR(subQ!I8/subQ!I5,"") | J22: =IFERROR(subQ!J8/subQ!J5,"") | K22: =IFERROR(subQ!K8/subQ!K5,"") | L22: =IFERROR(subQ!L8/subQ!L5,"") | ... AB22: =IFERROR(subQ!AB8/subQ!AB5,"") | AC22: =$D$50 | AD22: =$D$50 | AE22: =IFERROR(subQ!AE8/subQ!AE5,"") | AF22: =$D$50 | AG22: =$D$50 | AH22: =$D$50 | AI22: =$D$50 | AJ22: =IFERROR(subQ!AJ8/subQ!AJ5,"") | AK22: =$D$50 | AL22: =$D$50 | AM22: =$D$50 | AN22: =$D$50 | AO22: =IFERROR(subQ!AO8/subQ!AO5,"")
A23: drv:영업이익 | B23: ratio | C23: 영업이익률(OPM) | E23: =IFERROR(subQ!E9/subQ!E5,"") | F23: =IFERROR(subQ!F9/subQ!F5,"") | G23: =IFERROR(subQ!G9/subQ!G5,"") | H23: =IFERROR(subQ!H9/subQ!H5,"") | I23: =IFERROR(subQ!I9/subQ!I5,"") | J23: =IFERROR(subQ!J9/subQ!J5,"") | K23: =IFERROR(subQ!K9/subQ!K5,"") | L23: =IFERROR(subQ!L9/subQ!L5,"") | ... AB23: =IFERROR(subQ!AB9/subQ!AB5,"") | AC23: 0.005652143 | AD23: 0.005651854 | AE23: =IFERROR(subQ!AE9/subQ!AE5,"") | AF23: 0.005643739 | AG23: 0.005639651 | AH23: 0.005639514 | AI23: 0.005648968 | AJ23: =IFERROR(subQ!AJ9/subQ!AJ5,"") | AK23: 0.005641887 | AL23: 0.005638544 | AM23: 0.005651972 | AN23: 0.005641149 | AO23: =IFERROR(subQ!AO9/subQ!AO5,"")
A24: drv:외환손익 | B24: abs | C24: 외환손익 (가정, 억원) | E24: =subQ!E13 | F24: =subQ!F13 | G24: =subQ!G13 | H24: =subQ!H13 | I24: =subQ!I13 | J24: =subQ!J13 | K24: =subQ!K13 | L24: =subQ!L13 | ... AB24: =subQ!AB13 | AC24: 0 | AD24: 0 | AE24: =subQ!AE13 | AF24: 0 | AG24: 0 | AH24: 0 | AI24: 0 | AJ24: =subQ!AJ13 | AK24: 0 | AL24: 0 | AM24: 0 | AN24: 0 | AO24: =subQ!AO13
A25: drv:기타영업외손익 | B25: abs | C25: 기타영업외손익 (가정, 억원) | E25: =subQ!E14 | F25: =subQ!F14 | G25: =subQ!G14 | H25: =subQ!H14 | I25: =subQ!I14 | J25: =subQ!J14 | K25: =subQ!K14 | L25: =subQ!L14 | ... AB25: =subQ!AB14 | AC25: 0 | AD25: 0 | AE25: =subQ!AE14 | AF25: 0 | AG25: 0 | AH25: 0 | AI25: 0 | AJ25: =subQ!AJ14 | AK25: 0 | AL25: 0 | AM25: 0 | AN25: 0 | AO25: =subQ!AO14
A26: drv:지분법손익 | B26: abs | C26: 지분법손익 (가정, 억원) | E26: =subQ!E15 | F26: =subQ!F15 | G26: =subQ!G15 | H26: =subQ!H15 | I26: =subQ!I15 | J26: =subQ!J15 | K26: =subQ!K15 | L26: =subQ!L15 | ... AB26: =subQ!AB15 | AC26: 4.94 | AD26: 4.94 | AE26: =subQ!AE15 | AF26: 4.94 | AG26: 4.94 | AH26: 4.94 | AI26: 4.94 | AJ26: =subQ!AJ15 | AK26: 4.94 | AL26: 4.94 | AM26: 4.94 | AN26: 4.94 | AO26: =subQ!AO15
A27: drv:법인세비용 | B27: ratio | C27: 법인세율(/세전) | E27: =IFERROR(subQ!E17/subQ!E16,"") | F27: =IFERROR(subQ!F17/subQ!F16,"") | G27: =IFERROR(subQ!G17/subQ!G16,"") | H27: =IFERROR(subQ!H17/subQ!H16,"") | I27: =IFERROR(subQ!I17/subQ!I16,"") | J27: =IFERROR(subQ!J17/subQ!J16,"") | K27: =IFERROR(subQ!K17/subQ!K16,"") | L27: =IFERROR(subQ!L17/subQ!L16,"") | ... AB27: =IFERROR(subQ!AB17/subQ!AB16,"") | AC27: 0 | AD27: 0 | AE27: =IFERROR(subQ!AE17/subQ!AE16,"") | AF27: 0 | AG27: 0 | AH27: 0 | AI27: 0 | AJ27: =IFERROR(subQ!AJ17/subQ!AJ16,"") | AK27: 0 | AL27: 0 | AM27: 0 | AN27: 0 | AO27: =IFERROR(subQ!AO17/subQ!AO16,"")
A28: drv:지배주주순이익 | B28: ratio | C28: 지배주주 비중(/당기순이익) | E28: =IFERROR(subQ!E19/subQ!E18,"") | F28: =IFERROR(subQ!F19/subQ!F18,"") | G28: =IFERROR(subQ!G19/subQ!G18,"") | H28: =IFERROR(subQ!H19/subQ!H18,"") | I28: =IFERROR(subQ!I19/subQ!I18,"") | J28: =IFERROR(subQ!J19/subQ!J18,"") | K28: =IFERROR(subQ!K19/subQ!K18,"") | L28: =IFERROR(subQ!L19/subQ!L18,"") | ... AB28: =IFERROR(subQ!AB19/subQ!AB18,"") | AC28: =$D$51 | AD28: =$D$51 | AE28: =IFERROR(subQ!AE19/subQ!AE18,"") | AF28: =$D$51 | AG28: =$D$51 | AH28: =$D$51 | AI28: =$D$51 | AJ28: =IFERROR(subQ!AJ19/subQ!AJ18,"") | AK28: =$D$51 | AL28: =$D$51 | AM28: =$D$51 | AN28: =$D$51 | AO28: =IFERROR(subQ!AO19/subQ!AO18,"")
A29: drv:부채총계 | B29: qoq | C29: 부채총계 QoQ | G29: =IFERROR(subQ!G21/subQ!E21-1,"") | H29: =IFERROR(subQ!H21/subQ!G21-1,"") | I29: =IFERROR(subQ!I21/subQ!H21-1,"") | J29: =IFERROR(subQ!J21/subQ!I21-1,"") | L29: =IFERROR(subQ!L21/subQ!J21-1,"") | M29: =IFERROR(subQ!M21/subQ!L21-1,"") | N29: =IFERROR(subQ!N21/subQ!M21-1,"") | O29: =IFERROR(subQ!O21/subQ!N21-1,"") | Q29: =IFERROR(subQ!Q21/subQ!O21-1,"") | R29: =IFERROR(subQ!R21/subQ!Q21-1,"") | S29: =IFERROR(subQ!S21/subQ!R21-1,"") | T29: =IFERROR(subQ!T21/subQ!S21-1,"") | V29: =IFERROR(subQ!V21/subQ!T21-1,"") | W29: =IFERROR(subQ!W21/subQ!V21-1,"") | X29: =IFERROR(subQ!X21/subQ!W21-1,"") | Y29: =IFERROR(subQ!Y21/subQ!X21-1,"") | AA29: =IFERROR(subQ!AA21/subQ!Y21-1,"") | AB29: =IFERROR(subQ!AB21/subQ!AA21-1,"") | AC29: 3.43e-07 | AD29: 0 | AF29: 0 | AG29: 0 | AH29: 0 | AI29: 0 | AK29: 0 | AL29: 0 | AM29: 0 | AN29: 0
A30: drv:자본총계 | B30: roll | C30: 자본총계 기타변동(배당 등, 억원) | G30: =IFERROR(subQ!E22+subQ!G18-subQ!G22,"") | H30: =IFERROR(subQ!G22+subQ!H18-subQ!H22,"") | I30: =IFERROR(subQ!H22+subQ!I18-subQ!I22,"") | J30: =IFERROR(subQ!I22+subQ!J18-subQ!J22,"") | L30: =IFERROR(subQ!J22+subQ!L18-subQ!L22,"") | M30: =IFERROR(subQ!L22+subQ!M18-subQ!M22,"") | N30: =IFERROR(subQ!M22+subQ!N18-subQ!N22,"") | O30: =IFERROR(subQ!N22+subQ!O18-subQ!O22,"") | Q30: =IFERROR(subQ!O22+subQ!Q18-subQ!Q22,"") | R30: =IFERROR(subQ!Q22+subQ!R18-subQ!R22,"") | S30: =IFERROR(subQ!R22+subQ!S18-subQ!S22,"") | T30: =IFERROR(subQ!S22+subQ!T18-subQ!T22,"") | V30: =IFERROR(subQ!T22+subQ!V18-subQ!V22,"") | W30: =IFERROR(subQ!V22+subQ!W18-subQ!W22,"") | X30: =IFERROR(subQ!W22+subQ!X18-subQ!X22,"") | Y30: =IFERROR(subQ!X22+subQ!Y18-subQ!Y22,"") | AA30: =IFERROR(subQ!Y22+subQ!AA18-subQ!AA22,"") | AB30: =IFERROR(subQ!AA22+subQ!AB18-subQ!AB22,"") | AC30: 0.011097911 | AD30: 0.00012058 | AF30: -0.001880475 | AG30: 7.1235981 | AH30: -0.000760963 | AI30: 0.008484846 | AK30: 0.004156655 | AL30: 7.1178071 | AM30: 0.001536749 | AN30: 0.008039599
A31: drv:지배주주지분 | B31: roll | C31: 지배주주지분 기타변동(배당 등, 억원) | G31: =IFERROR(subQ!E23+subQ!G19-subQ!G23,"") | H31: =IFERROR(subQ!G23+subQ!H19-subQ!H23,"") | I31: =IFERROR(subQ!H23+subQ!I19-subQ!I23,"") | J31: =IFERROR(subQ!I23+subQ!J19-subQ!J23,"") | L31: =IFERROR(subQ!J23+subQ!L19-subQ!L23,"") | M31: =IFERROR(subQ!L23+subQ!M19-subQ!M23,"") | N31: =IFERROR(subQ!M23+subQ!N19-subQ!N23,"") | O31: =IFERROR(subQ!N23+subQ!O19-subQ!O23,"") | Q31: =IFERROR(subQ!O23+subQ!Q19-subQ!Q23,"") | R31: =IFERROR(subQ!Q23+subQ!R19-subQ!R23,"") | S31: =IFERROR(subQ!R23+subQ!S19-subQ!S23,"") | T31: =IFERROR(subQ!S23+subQ!T19-subQ!T23,"") | V31: =IFERROR(subQ!T23+subQ!V19-subQ!V23,"") | W31: =IFERROR(subQ!V23+subQ!W19-subQ!W23,"") | X31: =IFERROR(subQ!W23+subQ!X19-subQ!X23,"") | Y31: =IFERROR(subQ!X23+subQ!Y19-subQ!Y23,"") | AA31: =IFERROR(subQ!Y23+subQ!AA19-subQ!AA23,"") | AB31: =IFERROR(subQ!AA23+subQ!AB19-subQ!AB23,"") | AC31: 0.005397911 | AD31: 0.01012058 | AF31: -0.001880475 | AG31: 7.1235981 | AH31: -0.000760963 | AI31: -0.001515154 | AK31: 0.004156655 | AL31: 7.1178071 | AM31: 0.011536749 | AN31: -0.001960401
A32: drv:총차입금 | B32: qoq | C32: 총차입금 QoQ | G32: =IFERROR(subQ!G24/subQ!E24-1,"") | H32: =IFERROR(subQ!H24/subQ!G24-1,"") | I32: =IFERROR(subQ!I24/subQ!H24-1,"") | J32: =IFERROR(subQ!J24/subQ!I24-1,"") | L32: =IFERROR(subQ!L24/subQ!J24-1,"") | M32: =IFERROR(subQ!M24/subQ!L24-1,"") | N32: =IFERROR(subQ!N24/subQ!M24-1,"") | O32: =IFERROR(subQ!O24/subQ!N24-1,"") | Q32: =IFERROR(subQ!Q24/subQ!O24-1,"") | R32: =IFERROR(subQ!R24/subQ!Q24-1,"") | S32: =IFERROR(subQ!S24/subQ!R24-1,"") | T32: =IFERROR(subQ!T24/subQ!S24-1,"") | V32: =IFERROR(subQ!V24/subQ!T24-1,"") | W32: =IFERROR(subQ!W24/subQ!V24-1,"") | X32: =IFERROR(subQ!X24/subQ!W24-1,"") | Y32: =IFERROR(subQ!Y24/subQ!X24-1,"") | AA32: =IFERROR(subQ!AA24/subQ!Y24-1,"") | AB32: =IFERROR(subQ!AB24/subQ!AA24-1,"") | AC32: 4.089e-06 | AD32: 0 | AF32: 0 | AG32: 0 | AH32: 0 | AI32: 0 | AK32: 0 | AL32: 0 | AM32: 0 | AN32: 0
A33: drv:순차입금 | B33: qoq | C33: 순차입금 QoQ | G33: =IFERROR(subQ!G25/subQ!E25-1,"") | H33: =IFERROR(subQ!H25/subQ!G25-1,"") | I33: =IFERROR(subQ!I25/subQ!H25-1,"") | J33: =IFERROR(subQ!J25/subQ!I25-1,"") | L33: =IFERROR(subQ!L25/subQ!J25-1,"") | M33: =IFERROR(subQ!M25/subQ!L25-1,"") | N33: =IFERROR(subQ!N25/subQ!M25-1,"") | O33: =IFERROR(subQ!O25/subQ!N25-1,"") | Q33: =IFERROR(subQ!Q25/subQ!O25-1,"") | R33: =IFERROR(subQ!R25/subQ!Q25-1,"") | S33: =IFERROR(subQ!S25/subQ!R25-1,"") | T33: =IFERROR(subQ!T25/subQ!S25-1,"") | V33: =IFERROR(subQ!V25/subQ!T25-1,"") | W33: =IFERROR(subQ!W25/subQ!V25-1,"") | X33: =IFERROR(subQ!X25/subQ!W25-1,"") | Y33: =IFERROR(subQ!Y25/subQ!X25-1,"") | AA33: =IFERROR(subQ!AA25/subQ!Y25-1,"") | AB33: =IFERROR(subQ!AB25/subQ!AA25-1,"") | AC33: 0.014156745 | AD33: 0.014482704 | AF33: 0.013115304 | AG33: 0.022123218 | AH33: 0.013599342 | AI33: 0.013932916 | AK33: 0.012590277 | AL33: 0.021061953 | AM33: 0.013196911 | AN33: 0.013522424
A34: drv:이자발생자산 | B34: qoq | C34: 이자발생자산 QoQ | G34: =IFERROR(subQ!G26/subQ!E26-1,"") | H34: =IFERROR(subQ!H26/subQ!G26-1,"") | I34: =IFERROR(subQ!I26/subQ!H26-1,"") | J34: =IFERROR(subQ!J26/subQ!I26-1,"") | L34: =IFERROR(subQ!L26/subQ!J26-1,"") | M34: =IFERROR(subQ!M26/subQ!L26-1,"") | N34: =IFERROR(subQ!N26/subQ!M26-1,"") | O34: =IFERROR(subQ!O26/subQ!N26-1,"") | Q34: =IFERROR(subQ!Q26/subQ!O26-1,"") | R34: =IFERROR(subQ!R26/subQ!Q26-1,"") | S34: =IFERROR(subQ!S26/subQ!R26-1,"") | T34: =IFERROR(subQ!T26/subQ!S26-1,"") | V34: =IFERROR(subQ!V26/subQ!T26-1,"") | W34: =IFERROR(subQ!W26/subQ!V26-1,"") | X34: =IFERROR(subQ!X26/subQ!W26-1,"") | Y34: =IFERROR(subQ!Y26/subQ!X26-1,"") | AA34: =IFERROR(subQ!AA26/subQ!Y26-1,"") | AB34: =IFERROR(subQ!AB26/subQ!AA26-1,"") | AC34: -0.023105855 | AD34: -0.02453675 | AF34: -0.02310891 | AG34: -0.040402866 | AH34: -0.026469519 | AI34: -0.028259841 | AK34: -0.026621912 | AL34: -0.046329201 | AM34: -0.031052472 | AN34: -0.033329535
A35: drv:현금및현금성자산 | B35: qoq | C35: 현금및현금성자산 QoQ | G35: =IFERROR(subQ!G27/subQ!E27-1,"") | H35: =IFERROR(subQ!H27/subQ!G27-1,"") | I35: =IFERROR(subQ!I27/subQ!H27-1,"") | J35: =IFERROR(subQ!J27/subQ!I27-1,"") | L35: =IFERROR(subQ!L27/subQ!J27-1,"") | M35: =IFERROR(subQ!M27/subQ!L27-1,"") | N35: =IFERROR(subQ!N27/subQ!M27-1,"") | O35: =IFERROR(subQ!O27/subQ!N27-1,"") | Q35: =IFERROR(subQ!Q27/subQ!O27-1,"") | R35: =IFERROR(subQ!R27/subQ!Q27-1,"") | S35: =IFERROR(subQ!S27/subQ!R27-1,"") | T35: =IFERROR(subQ!T27/subQ!S27-1,"") | V35: =IFERROR(subQ!V27/subQ!T27-1,"") | W35: =IFERROR(subQ!W27/subQ!V27-1,"") | X35: =IFERROR(subQ!X27/subQ!W27-1,"") | Y35: =IFERROR(subQ!Y27/subQ!X27-1,"") | AA35: =IFERROR(subQ!AA27/subQ!Y27-1,"") | AB35: =IFERROR(subQ!AB27/subQ!AA27-1,"")
A36: drv:CAPEX | B36: yoy | C36: CAPEX YoY | J36: =IFERROR(subQ!J28/subQ!E28-1,"") | L36: =IFERROR(subQ!L28/subQ!G28-1,"") | M36: =IFERROR(subQ!M28/subQ!H28-1,"") | N36: =IFERROR(subQ!N28/subQ!I28-1,"") | O36: =IFERROR(subQ!O28/subQ!J28-1,"") | Q36: =IFERROR(subQ!Q28/subQ!L28-1,"") | R36: =IFERROR(subQ!R28/subQ!M28-1,"") | S36: =IFERROR(subQ!S28/subQ!N28-1,"") | T36: =IFERROR(subQ!T28/subQ!O28-1,"") | V36: =IFERROR(subQ!V28/subQ!Q28-1,"") | W36: =IFERROR(subQ!W28/subQ!R28-1,"") | X36: =IFERROR(subQ!X28/subQ!S28-1,"") | Y36: =IFERROR(subQ!Y28/subQ!T28-1,"") | AA36: =IFERROR(subQ!AA28/subQ!V28-1,"") | AB36: =IFERROR(subQ!AB28/subQ!W28-1,"") | AC36: 0.41411615 | AD36: -0.46536495 | AF36: 0.49450985 | AG36: -0.22634862 | AH36: 0 | AI36: 0 | AK36: 0 | AL36: 0 | AM36: 0 | AN36: 0
A37: drv:영업활동현금흐름 | B37: yoy | C37: 영업활동현금흐름 YoY | J37: =IFERROR(subQ!J29/subQ!E29-1,"") | L37: =IFERROR(subQ!L29/subQ!G29-1,"") | M37: =IFERROR(subQ!M29/subQ!H29-1,"") | N37: =IFERROR(subQ!N29/subQ!I29-1,"") | O37: =IFERROR(subQ!O29/subQ!J29-1,"") | Q37: =IFERROR(subQ!Q29/subQ!L29-1,"") | R37: =IFERROR(subQ!R29/subQ!M29-1,"") | S37: =IFERROR(subQ!S29/subQ!N29-1,"") | T37: =IFERROR(subQ!T29/subQ!O29-1,"") | V37: =IFERROR(subQ!V29/subQ!Q29-1,"") | W37: =IFERROR(subQ!W29/subQ!R29-1,"") | X37: =IFERROR(subQ!X29/subQ!S29-1,"") | Y37: =IFERROR(subQ!Y29/subQ!T29-1,"") | AA37: =IFERROR(subQ!AA29/subQ!V29-1,"") | AB37: =IFERROR(subQ!AB29/subQ!W29-1,"")
A38: drv:주식수 | B38: qoq | C38: 주식수 QoQ | G38: =IFERROR(subQ!G30/subQ!E30-1,"") | H38: =IFERROR(subQ!H30/subQ!G30-1,"") | I38: =IFERROR(subQ!I30/subQ!H30-1,"") | J38: =IFERROR(subQ!J30/subQ!I30-1,"") | L38: =IFERROR(subQ!L30/subQ!J30-1,"") | M38: =IFERROR(subQ!M30/subQ!L30-1,"") | N38: =IFERROR(subQ!N30/subQ!M30-1,"") | O38: =IFERROR(subQ!O30/subQ!N30-1,"") | Q38: =IFERROR(subQ!Q30/subQ!O30-1,"") | R38: =IFERROR(subQ!R30/subQ!Q30-1,"") | S38: =IFERROR(subQ!S30/subQ!R30-1,"") | T38: =IFERROR(subQ!T30/subQ!S30-1,"") | V38: =IFERROR(subQ!V30/subQ!T30-1,"") | W38: =IFERROR(subQ!W30/subQ!V30-1,"") | X38: =IFERROR(subQ!X30/subQ!W30-1,"") | Y38: =IFERROR(subQ!Y30/subQ!X30-1,"") | AA38: =IFERROR(subQ!AA30/subQ!Y30-1,"") | AB38: =IFERROR(subQ!AB30/subQ!AA30-1,"") | AC38: 0 | AD38: 0 | AF38: 0 | AG38: 0 | AH38: 0 | AI38: 0 | AK38: 0 | AL38: 0 | AM38: 0 | AN38: 0
A39: drv:DPS | B39: abs | C39: DPS (가정, 원) | E39: =subQ!E33 | F39: =subQ!F33 | G39: =subQ!G33 | H39: =subQ!H33 | I39: =subQ!I33 | J39: =subQ!J33 | K39: =subQ!K33 | L39: =subQ!L33 | ... AB39: =subQ!AB33 | AD39: 30 | AE39: =subQ!AE33 | AI39: 30 | AJ39: =subQ!AJ33 | AN39: 30 | AO39: =subQ!AO33
B41: 3. 밸류에이션·스칼라 | C41: 노란 셀 = 가정. '연결' 표시는 추정 전 분기 수식이 이 셀을 참조한다는 뜻
A42: sc:종가 | C42: 종가 | D42: 2900 | E42: 원 — 네이버 정규장 종가(aik 확정종가 대조 · aik 3,020원)
...

Sheet BS연결
B1: (백만원) | C1: 이름: BS연결H | E1: 4Q21 | F1: 2021 | G1: 1Q22 | H1: 2Q22 | I1: 3Q22 | J1: 4Q22 | K1: 2022 | L1: 1Q23 | M1: 2Q23 | N1: 3Q23 | O1: 4Q23 | P1: 2023 | Q1: 1Q24 | R1: 2Q24 | S1: 3Q24 | T1: 4Q24 | U1: 2024 | V1: 1Q25 | W1: 2Q25 | X1: 3Q25 | Y1: 4Q25 | Z1: 2025 | AA1: 1Q26 | AB1: 2Q26 | AC1: 3Q26 | AD1: 4Q26 | AE1: 2026 | AF1: 1Q27 | AG1: 2Q27 | AH1: 3Q27 | AI1: 4Q27 | AJ1: 2027 | AK1: 1Q28 | AL1: 2Q28 | AM1: 3Q28 | AN1: 4Q28 | AO1: 2028
B2: 연결 | D2: fin json(kship_fin.py)
B3: 한일철강(연) | C3: UPDATE: 26-10-13 | E3: 1 | F3: 2 | G3: 3 | H3: 4 | I3: 5 | J3: 6 | K3: 7 | L3: 8 | M3: 9 | N3: 10 | O3: 11 | P3: 12 | Q3: 13 | R3: 14 | S3: 15 | T3: 16 | U3: 17 | V3: 18 | W3: 19 | X3: 20 | Y3: 21 | Z3: 22 | AA3: 23 | AB3: 24 | AC3: 25 | AD3: 26 | AE3: 27 | AF3: 28 | AG3: 29 | AH3: 30 | AI3: 31 | AJ3: 32 | AK3: 33 | AL3: 34 | AM3: 35 | AN3: 36 | AO3: 37
B4: Account Code | C4: AccountNAME | E4: 2021.12 | F4: 2021.12A | G4: 2022.03 | H4: 2022.06 | I4: 2022.09 | J4: 2022.12 | K4: 2022.12A | L4: 2023.03 | M4: 2023.06 | N4: 2023.09 | O4: 2023.12 | P4: 2023.12A | Q4: 2024.03 | R4: 2024.06 | S4: 2024.09 | T4: 2024.12 | U4: 2024.12A | V4: 2025.03 | W4: 2025.06 | X4: 2025.09 | Y4: 2025.12 | Z4: 2025.12A | AA4: 2026.03 | AB4: 2026.06 | AC4: 2026.09 | AD4: 2026.12 | AE4: 2026.12A | AF4: 2027.03 | AG4: 2027.06 | AH4: 2027.09 | AI4: 2027.12 | AJ4: 2027.12A | AK4: 2028.03 | AL4: 2028.06 | AM4: 2028.09 | AN4: 2028.12 | AO4: 2028.12A
A5: 1 | C5: 유동자산 | E5: 109937.95 | F5: 109937.95 | G5: 118389.01 | H5: 124221.47 | I5: 120714.71 | J5: 105439.73 | K5: 105439.73 | L5: 100867.84 | M5: 103150.61 | N5: 109295.75 | O5: 96584.58 | P5: 96584.58 | Q5: 94917.36 | R5: 99915.72 | S5: 100005.89 | T5: 102427.18 | U5: 102427.18 | V5: 106184.2 | W5: 98415.96 | X5: 109120.87 | Y5: 97807.54 | Z5: 97807.54 | AA5: 103061.93 | AB5: 129882.74
A6: 1 | C6: 현금및현금성자산 | E6: 12776.01 | F6: 12776.01 | G6: 8489.31 | H6: 11125.59 | I6: 7570.64 | J6: 12401.56 | K6: 12401.56 | L6: 12008.24 | M6: 10418.08 | N6: 10507.76 | O6: 12942.53 | P6: 12942.53 | Q6: 6171.37 | R6: 8915.64 | S6: 14674.49 | T6: 11719.23 | U6: 11719.23 | V6: 13164.5 | W6: 10230.18 | X6: 9647.29 | Y6: 5890.6 | Z6: 5890.6 | AA6: 14534.04 | AB6: 14412.5
A7: 1 | C7: 단기금융상품 | E7: 15764.23 | F7: 15764.23 | G7: 23915.86 | J7: 28060 | K7: 28060 | L7: 18860 | M7: 18860 | N7: 16960 | O7: 16960 | P7: 16960 | Q7: 16460 | R7: 16460 | S7: 17460 | T7: 22260 | U7: 22260 | V7: 24260 | W7: 24260 | X7: 23410 | Y7: 23410 | Z7: 23410 | AA7: 21410 | AB7: 27610
A8: 1 | C8: 단기금융자산 | E8: 15764.23 | F8: 15764.23 | G8: 23915.86 | J8: 28060 | K8: 28060 | L8: 18860 | M8: 18860 | N8: 16960 | O8: 16960 | P8: 16960 | Q8: 16460 | R8: 16460 | S8: 17460 | T8: 22260 | U8: 22260 | V8: 24260 | W8: 24260 | X8: 23410 | Y8: 23410 | Z8: 23410 | AA8: 21410 | AB8: 27610
A9: 1 | C9: 매출채권및기타채권 | E9: 37085.46 | F9: 37085.46 | G9: 41100.6 | H9: 36743.63 | I9: 39143.39 | J9: 36796.2 | K9: 36796.2 | L9: 34123.23 | M9: 31403.44 | N9: 33549.25 | O9: 30795.01 | P9: 30795.01 | Q9: 30030.49 | R9: 31252.87 | S9: 24368.33 | T9: 31744.1 | U9: 31744.1 | V9: 29160.69 | W9: 26084.76 | X9: 30811.22 | Y9: 27655.13 | Z9: 27655.13 | AA9: 40017.83 | AB9: 39561.82
A10: 1 | C10: 기타유동자산 | E10: 2311.65 | F10: 2311.65 | G10: 1648.85 | H10: 321.66 | I10: 1403.57 | J10: 159.22 | K10: 159.22 | L10: 108.21 | M10: 268.95 | N10: 355.02 | O10: 195.94 | P10: 195.94 | Q10: 670.66 | R10: 1196.03 | S10: 304.9 | T10: 1209.62 | U10: 1209.62 | V10: 1101.65 | W10: 808.89 | X10: 1429.32 | AA10: 1004.28 | AB10: 1033.6
A11: 1 | C11: 기타유동금융자산 | E11: 853.93 | F11: 853.93 | G11: 1142.6 | H11: 27724.32 | I11: 29300.95 | J11: 0 | K11: 0 | L11: 0 | M11: 0 | N11: 0 | O11: 0 | P11: 0 | Q11: 0 | R11: 0 | S11: 0 | T11: 0 | U11: 0 | V11: 0 | W11: 0 | X11: 0
A12: 1 | C12: 재고자산 | E12: 41146.48 | F12: 41146.48 | G12: 42652.67 | H12: 47805.07 | I12: 42796.59 | J12: 27056.33 | K12: 27056.33 | L12: 35222.56 | M12: 41631.71 | N12: 47241.83 | O12: 35045.74 | P12: 35045.74 | Q12: 41370.67 | R12: 42064.67 | S12: 38097.63 | T12: 35354.35 | U12: 35354.35 | V12: 38462.11 | W12: 36970.98 | X12: 43702.79 | Y12: 39224.09 | Z12: 39224.09 | AA12: 26063.29 | AB12: 47225.02
A13: 1 | C13: 당기법인세자산(선급법인세) | E13: 0.2 | F13: 0.2 | G13: -560.88 | H13: 0 | I13: 0 | J13: 463.92 | K13: 463.92 | L13: 36.16 | M13: 56.91 | N13: 168.11 | O13: 117.08 | P13: 117.08 | Q13: -35.69 | R13: 26.52 | S13: 100.54 | T13: 139.88 | U13: 139.88 | V13: 35.25 | W13: 61.15 | X13: 120.26 | Y13: 153.12 | Z13: 153.12 | AA13: 32.49 | AB13: 39.81
A14: 1 | C14: 비유동자산 | E14: 228804.89 | F14: 228804.89 | G14: 230737.7 | H14: 231574.9 | I14: 235241.32 | J14: 233715.25 | K14: 233715.25 | L14: 232023.34 | M14: 231521.2 | N14: 233192.62 | O14: 234444.41 | P14: 234444.41 | Q14: 234992.25 | R14: 236204.63 | S14: 235904.86 | T14: 238024.87 | U14: 238024.87 | V14: 236992.17 | W14: 236534.3 | X14: 236131.59 | Y14: 238311.7 | Z14: 238311.7 | AA14: 237987.52 | AB14: 240223.41
A15: 1 | C15: 장기금융자산 | E15: 2022.2 | F15: 2022.2 | G15: 2024.1 | H15: 1001.97 | I15: 1001.97 | J15: 1019.08 | K15: 1019.08 | L15: 1006.13 | M15: 1010.81 | N15: 1020.81 | O15: 1021.24 | P15: 1021.24 | Q15: 1026.54 | R15: 1025.2 | S15: 1025.36 | T15: 1026.43 | U15: 1026.43 | V15: 1025.4 | W15: 1026.75 | X15: 269.28 | Y15: 4756.97 | Z15: 4756.97 | AA15: 4160.83 | AB15: 4160.6
A16: 1 | C16: 투자자산 | E16: 19410.42 | F16: 19410.42 | G16: 20341.59 | H16: 19607.94 | I16: 20439.76 | J16: 19901.21 | K16: 19901.21 | L16: 19914.05 | M16: 19730.23 | N16: 20023.5 | O16: 19963.51 | P16: 19963.51 | Q16: 19996.52 | R16: 19441.4 | S16: 19283.03 | T16: 19786.7 | U16: 19786.7 | V16: 19886.32 | W16: 19664.93 | X16: 18580.16 | Y16: 4756.97 | Z16: 4756.97 | AA16: 4160.83 | AB16: 4160.6
A17: 1 | C17: 종속기업및관계기업투자 | E17: 17388.22 | F17: 17388.22 | G17: 18317.49 | H17: 18605.97 | I17: 19437.79 | J17: 18882.13 | K17: 18882.13 | L17: 18907.92 | M17: 18719.42 | N17: 19002.69 | O17: 18942.27 | P17: 18942.27 | Q17: 18969.98 | R17: 18416.2 | S17: 18257.67 | T17: 18760.27 | U17: 18760.27 | V17: 18860.92 | W17: 18638.18 | X17: 18310.88
A18: 1 | C18: 투자부동산 | E18: 123818.87 | F18: 123818.87 | G18: 123772.16 | H18: 123725.45 | I18: 123678.75 | J18: 126970.6 | K18: 126970.6 | L18: 126917.2 | M18: 126864.93 | N18: 126812.67 | O18: 126760.4 | P18: 126760.4 | Q18: 126708.73 | R18: 126657.06 | S18: 127437.03 | T18: 129203.81 | U18: 129203.81 | V18: 129078.73 | W18: 129005.13 | X18: 128931.53 | Y18: 129028.38 | Z18: 129028.38 | AA18: 128953.32 | AB18: 128878.27
A19: 1 | C19: 유형자산 | E19: 83403.78 | F19: 83403.78 | G19: 84428.42 | H19: 83789.91 | I19: 86230.94 | J19: 81789.07 | K19: 81789.07 | L19: 80242.11 | M19: 79910.87 | N19: 81575.55 | O19: 82980.54 | P19: 82980.54 | Q19: 83904.66 | R19: 84168.14 | S19: 83457.65 | T19: 83201.22 | U19: 83201.22 | V19: 81479.21 | W19: 81112.24 | X19: 81461.88 | Y19: 82202.22 | Z19: 82202.22 | AA19: 82226.49
A20: 1 | C20: 무형자산 | E20: 2171.82 | F20: 2171.82 | G20: 2195.54 | H20: 2234.71 | I20: 2602.04 | J20: 2480.47 | K20: 2480.47 | L20: 2508.63 | M20: 2446.01 | N20: 2449.6 | O20: 2413.09 | P20: 2413.09 | Q20: 2427.41 | R20: 2439.6 | S20: 2414.72 | T20: 2471.27 | U20: 2471.27 | V20: 2475.03 | W20: 2389.78 | X20: 2417.63 | Y20: 3263.45 | Z20: 3263.45 | AA20: 3322.62 | AB20: 3420.56
A21: 1 | C21: 자산총계 | E21: 338742.84 | F21: 338742.84 | G21: 349126.71 | H21: 355796.37 | I21: 355956.03 | J21: 339154.97 | K21: 339154.97 | L21: 332891.18 | M21: 334671.81 | N21: 342488.37 | O21: 331029 | P21: 331029 | Q21: 329909.61 | R21: 336120.36 | S21: 335910.75 | T21: 340452.05 | U21: 340452.05 | V21: 343176.37 | W21: 334950.25 | X21: 345252.46 | Y21: 336119.24 | Z21: 336119.24 | AA21: 341049.45 | AB21: 370106.16
A22: 1 | C22: 유동부채 | E22: 89112.97 | F22: 89112.97 | G22: 116574.85 | H22: 132097.58 | I22: 130826.02 | J22: 112789.05 | K22: 112789.05 | L22: 116243.12 | M22: 114861.62 | N22: 128507.5 | O22: 121158.78 | P22: 121158.78 | Q22: 122286.13 | R22: 130229.48 | S22: 124334.16 | T22: 130607.4 | U22: 130607.4 | V22: 133771.7 | W22: 125461.37 | X22: 141760.88 | Y22: 134154.2 | Z22: 134154.2 | AA22: 140352.17 | AB22: 167169.41
A23: 1 | C23: 매입채무및기타채무 | E23: 11865.99 | F23: 11865.99 | G23: 14499.47 | J23: 14960.61 | K23: 14960.61 | L23: 13995.89 | M23: 19061.29 | N23: 26345.46 | O23: 17259.94 | P23: 17259.94 | Q23: 22385.8 | R23: 17874.15 | S23: 15613.39 | T23: 20092.91 | U23: 20092.91 | V23: 16094.37 | W23: 14780.91 | X23: 19530.68 | Y23: 17224.67 | Z23: 17224.67 | AA23: 23010.35 | AB23: 45474.98
A24: 1 | C24: 단기차입금 | E24: 71751.24 | F24: 71751.24 | G24: 96994.05 | H24: 110555.26 | I24: 99830.82 | J24: 93382.91 | K24: 93382.91 | L24: 97263.34 | M24: 81325.41 | N24: 80225.72 | O24: 79006.06 | P24: 79006.06 | Q24: 95514.09 | R24: 107988.29 | S24: 103875.06 | T24: 105141.35 | U24: 105141.35 | V24: 112136.48 | W24: 105858.38 | X24: 111772.67 | Y24: 111910.03 | Z24: 111910.03 | AA24: 112787.7 | AB24: 117391.52
A25: 1 | C25: 유동성장기부채 | E25: 0 | F25: 0 | G25: 0 | H25: 6464.5 | I25: 6464.5 | M25: 10494 | N25: 16494 | O25: 20494 | P25: 20494 | X25: 6000 | AB25: 0
A26: 1 | C26: 당기법인세부채(미지급법인세) | E26: 881.52 | F26: 881.52 | G26: 0 | H26: 513.91 | I26: 65.52 | J26: 3.35 | K26: 3.35 | L26: 0 | M26: 98.98 | N26: 98.98 | O26: 0 | P26: 0 | Q26: -62.83 | R26: 0 | S26: 0 | T26: 0 | U26: 0 | V26: 243.54 | W26: 0 | X26: 0 | Y26: 0.49 | Z26: 0.49 | AA26: 0.04 | AB26: 0
A27: 1 | C27: 기타유동금융부채 | E27: 2156.76 | F27: 2156.76 | G27: 2740.93 | H27: 5343.77 | I27: 8115.97 | J27: 1691 | K27: 1691 | L27: 1505 | M27: 1505 | N27: 1505 | O27: 1505 | P27: 1505 | Q27: 1505 | R27: 1505 | S27: 1605 | T27: 1605 | U27: 1605 | V27: 2305 | W27: 2290 | X27: 1990 | Y27: 1990 | Z27: 1990 | AA27: 1990 | AB27: 1990
A28: 1 | C28: 단기금융부채 | E28: 2156.76 | F28: 2156.76 | G28: 2740.93 | H28: 5343.77 | I28: 8115.97 | J28: 1961.29 | K28: 1961.29 | L28: 1800.75 | M28: 1714.46 | N28: 1826.51 | O28: 1828.92 | P28: 1828.92 | Q28: 1831.37 | R28: 1835.69 | S28: 1943.81 | T28: 1947.3 | U28: 1947.3 | V28: 2650.83 | W28: 2639.39 | X28: 2341.25 | Y28: 2344.42 | Z28: 2344.42 | AA28: 2347.62 | AB28: 2350.85
A29: 1 | C29: 기타유동부채 | E29: 2457.46 | F29: 2457.46 | G29: 2340.39 | H29: 2180.91 | I29: 2618 | J29: 2480.89 | K29: 2480.89 | L29: 3183.14 | M29: 2167.48 | N29: 3516.83 | O29: 2569.86 | P29: 2569.86 | Q29: 2617.7 | R29: 2531.35 | S29: 2901.9 | T29: 3425.84 | U29: 3425.84 | V29: 2646.48 | W29: 2182.69 | X29: 2116.29 | Y29: 2674.59 | Z29: 2674.59 | AA29: 2206.46 | AB29: 1952.06
A30: 1 | C30: 단기파생상품부채 | E30: 0 | F30: 0 | G30: 0
A31: 1 | C31: 비유동부채 | E31: 71869.08 | F31: 71869.08 | G31: 51629.61 | H31: 44371.91 | I31: 50439.46 | J31: 51833.29 | K31: 51833.29 | L31: 41227.03 | M31: 45324.58 | N31: 39578.38 | O31: 36300.81 | P31: 36300.81 | Q31: 36681.48 | R31: 36436.88 | S31: 42927.7 | T31: 41394.91 | U31: 41394.91 | V31: 41361.14 | W31: 41627.46 | X31: 35901.99 | Y31: 36858.97 | Z31: 36858.97 | AA31: 36768.36 | AB31: 36888.53
A32: 1 | C32: 장기차입금 | E32: 16421.5 | F32: 16421.5 | G32: 16548 | H32: 10494 | I32: 16494 | J32: 16494 | K32: 16494 | L32: 6000 | M32: 10000 | N32: 4000 | O32: 0 | P32: 0 | Q32: 0 | R32: 0 | S32: 6000 | T32: 6000 | U32: 6000 | V32: 6000 | W32: 6000 | X32: 0 | Y32: 0 | Z32: 0 | AB32: 0
A33: 1 | C33: 사채 | E33: 21317.19 | F33: 21317.19 | G33: 0 | H33: 0 | I33: 0 | J33: 0 | K33: 0 | L33: 0 | M33: 0 | N33: 0 | O33: 0 | P33: 0 | Q33: 0 | R33: 0 | S33: 0 | T33: 0 | U33: 0 | V33: 0 | W33: 0 | X33: 0
A34: 1 | C34: 확정급여부채 | E34: -36.18 | F34: -36.18 | G34: 710.59 | H34: 0 | I34: 0 | J34: 0 | K34: 0 | L34: 0 | M34: 0 | N34: 0 | O34: 0 | P34: 0 | Q34: 0 | R34: 0 | S34: 0 | T34: 0 | U34: 0 | V34: 138.85 | W34: 0 | X34: 2.67
A35: 1 | C35: 이연법인세부채 | E35: 34166.58 | F35: 34166.58 | G35: 34371.02 | H35: 33667.11 | I35: 33823.31 | J35: 35227.03 | K35: 35227.03 | L35: 35227.03 | M35: 35324.58 | N35: 35328.74 | O35: 36133.3 | P35: 36133.3 | Q35: 36597.17 | R35: 36436.88 | S35: 36664.32 | T35: 33712.52 | U35: 33712.52 | V35: 33627.69 | W35: 34121.57 | X35: 34121.57 | Y35: 35171.03 | Z35: 35171.03 | AA35: 35171.03 | AB35: 35382.63
A36: 1 | C36: 기타비유동금융부채 | E36: 0 | F36: 0 | G36: 0 | H36: 210.8 | I36: 122.15 | J36: 0 | K36: 0 | L36: 0 | M36: 0 | N36: 0 | O36: 0 | P36: 0 | Q36: 0 | R36: 0 | S36: 0 | T36: 1505.9 | U36: 1505.9 | V36: 1505.9 | W36: 1505.9 | X36: 1505.9 | Y36: 1505.9 | Z36: 1505.9 | AA36: 1505.9 | AB36: 1505.9
A37: 1 | C37: 장기금융부채 | E37: 0 | F37: 0 | G37: 0 | H37: 210.8 | I37: 122.15 | J37: 112.26 | K37: 112.26 | L37: 0 | M37: 0 | N37: 249.64 | O37: 167.52 | P37: 167.52 | Q37: 84.31 | R37: 0 | S37: 263.38 | T37: 1682.39 | U37: 1682.39 | V37: 1594.6 | W37: 1505.9 | X37: 1777.75 | Y37: 1687.95 | Z37: 1687.95 | AA37: 1597.33 | AB37: 1505.9
A38: 1 | C38: 장기파생상품부채 | E38: 0 | F38: 0 | G38: 0
A39: 1 | C39: 부채총계 | E39: 160982.05 | F39: 160982.05 | G39: 168204.46 | H39: 176469.49 | I39: 181265.48 | J39: 164622.34 | K39: 164622.34 | L39: 157470.15 | M39: 160186.2 | N39: 168085.88 | O39: 157459.59 | P39: 157459.59 | Q39: 158967.6 | R39: 166666.36 | S39: 167261.86 | T39: 172002.31 | U39: 172002.31 | V39: 175132.83 | W39: 167088.84 | X39: 177662.88 | Y39: 171013.17 | Z39: 171013.17 | AA39: 177120.53 | AB39: 204057.93
A40: 1 | C40: 지배주주지분 | E40: 175373.74 | F40: 175373.74 | G40: 178416.58 | H40: 176777.89 | I40: 172119.68 | J40: 172060.81 | K40: 172060.81 | L40: 172775.39 | M40: 172021.78 | N40: 171657.17 | O40: 170727.11 | P40: 170727.11 | Q40: 167995.92 | R40: 166292.58 | S40: 165362 | T40: 164663.51 | U40: 164663.51 | V40: 164234.34 | W40: 164359.13 | X40: 163915.81 | Y40: 161191.79 | Z40: 161191.79 | AA40: 159720.6 | AB40: 161791.65
...

Sheet BS별도
B1: (백만원) | C1: 이름: BS별도H | E1: 4Q21 | F1: 2021 | G1: 1Q22 | H1: 2Q22 | I1: 3Q22 | J1: 4Q22 | K1: 2022 | L1: 1Q23 | M1: 2Q23 | N1: 3Q23 | O1: 4Q23 | P1: 2023 | Q1: 1Q24 | R1: 2Q24 | S1: 3Q24 | T1: 4Q24 | U1: 2024 | V1: 1Q25 | W1: 2Q25 | X1: 3Q25 | Y1: 4Q25 | Z1: 2025 | AA1: 1Q26 | AB1: 2Q26 | AC1: 3Q26 | AD1: 4Q26 | AE1: 2026 | AF1: 1Q27 | AG1: 2Q27 | AH1: 3Q27 | AI1: 4Q27 | AJ1: 2027 | AK1: 1Q28 | AL1: 2Q28 | AM1: 3Q28 | AN1: 4Q28 | AO1: 2028
B2: 별도 | D2: fin json(kship_fin.py)
B3: 한일철강(별) | C3: UPDATE: 26-10-13 | E3: 1 | F3: 2 | G3: 3 | H3: 4 | I3: 5 | J3: 6 | K3: 7 | L3: 8 | M3: 9 | N3: 10 | O3: 11 | P3: 12 | Q3: 13 | R3: 14 | S3: 15 | T3: 16 | U3: 17 | V3: 18 | W3: 19 | X3: 20 | Y3: 21 | Z3: 22 | AA3: 23 | AB3: 24 | AC3: 25 | AD3: 26 | AE3: 27 | AF3: 28 | AG3: 29 | AH3: 30 | AI3: 31 | AJ3: 32 | AK3: 33 | AL3: 34 | AM3: 35 | AN3: 36 | AO3: 37
B4: Account Code | C4: AccountNAME | E4: 2021.12 | F4: 2021.12A | G4: 2022.03 | H4: 2022.06 | I4: 2022.09 | J4: 2022.12 | K4: 2022.12A | L4: 2023.03 | M4: 2023.06 | N4: 2023.09 | O4: 2023.12 | P4: 2023.12A | Q4: 2024.03 | R4: 2024.06 | S4: 2024.09 | T4: 2024.12 | U4: 2024.12A | V4: 2025.03 | W4: 2025.06 | X4: 2025.09 | Y4: 2025.12 | Z4: 2025.12A | AA4: 2026.03 | AB4: 2026.06 | AC4: 2026.09 | AD4: 2026.12 | AE4: 2026.12A | AF4: 2027.03 | AG4: 2027.06 | AH4: 2027.09 | AI4: 2027.12 | AJ4: 2027.12A | AK4: 2028.03 | AL4: 2028.06 | AM4: 2028.09 | AN4: 2028.12 | AO4: 2028.12A
A5: 1 | C5: 유동자산 | E5: 100757.61 | F5: 100757.61 | G5: 109694.49 | H5: 115803.92 | I5: 111415.04 | J5: 97097.76 | K5: 97097.76 | L5: 93163.68 | M5: 95669.95 | N5: 100327.26 | O5: 88583.79 | P5: 88583.79 | Q5: 86581.44 | R5: 90750.88 | S5: 90620.84 | T5: 91087.56 | U5: 91087.56 | V5: 95796.32 | W5: 90092.83 | X5: 99580.08 | Y5: 87689.27 | Z5: 87689.27 | AA5: 92414.99 | AB5: 118854.64
A6: 1 | C6: 현금및현금성자산 | E6: 10446 | F6: 10446 | G6: 6078.01 | H6: 8350.23 | I6: 4642.59 | J6: 10051.2 | K6: 10051.2 | L6: 9359.84 | M6: 7952.02 | N6: 8582.24 | O6: 11500.72 | P6: 11500.72 | Q6: 4882.61 | R6: 7842.77 | S6: 13295.94 | T6: 10642.71 | U6: 10642.71 | V6: 12207.98 | W6: 8822.59 | X6: 8315.96 | Y6: 5100.11 | Z6: 5100.11 | AA6: 13604.18 | AB6: 13406.66
A7: 1 | C7: 단기금융상품 | E7: 15764.23 | F7: 15764.23 | G7: 23915.86 | J7: 28060 | K7: 28060 | L7: 18860 | M7: 18860 | N7: 16960 | O7: 16960 | P7: 16960 | Q7: 16460 | R7: 16460 | S7: 17460 | T7: 22260 | U7: 22260 | V7: 24260 | W7: 24260 | X7: 23410 | Y7: 23410 | Z7: 23410 | AA7: 21410 | AB7: 27610
A8: 1 | C8: 단기금융자산 | E8: 15764.23 | F8: 15764.23 | G8: 23915.86 | J8: 28060 | K8: 28060 | L8: 18860 | M8: 18860 | N8: 16960 | O8: 16960 | P8: 16960 | Q8: 16460 | R8: 16460 | S8: 17460 | T8: 22260 | U8: 22260 | V8: 24260 | W8: 24260 | X8: 23410 | Y8: 23410 | Z8: 23410 | AA8: 21410 | AB8: 27610
A9: 1 | C9: 매출채권및기타채권 | E9: 33674.87 | F9: 33674.87 | G9: 37446.69 | H9: 33382.63 | I9: 34950.15 | J9: 32939.3 | K9: 32939.3 | L9: 31261.88 | M9: 28341.76 | N9: 28785.92 | O9: 26576.18 | P9: 26576.18 | Q9: 25875.81 | R9: 25940.53 | S9: 18749.58 | T9: 24842.89 | U9: 24842.89 | V9: 23191.57 | W9: 22222.42 | X9: 25583.11 | Y9: 21243.36 | Z9: 21243.36 | AA9: 33824.43 | AB9: 33298.82
A10: 1 | C10: 기타유동자산 | E10: 1266.27 | F10: 1266.27 | G10: 1009.1 | H10: 207.8 | I10: 1224.4 | J10: 84.46 | K10: 84.46 | L10: 24.02 | M10: 209.47 | N10: 265.63 | O10: 110.58 | P10: 110.58 | Q10: 569.98 | R10: 1063.43 | S10: 162.85 | T10: 1123.6 | U10: 1123.6 | V10: 993.03 | W10: 744.38 | X10: 1325.08 | Y10: 1388.99 | Z10: 1388.99 | AA10: 734.33 | AB10: 685.74
A11: 1 | C11: 재고자산 | E11: 38752.31 | F11: 38752.31 | G11: 40102.23 | H11: 45636.11 | I11: 40797.23 | J11: 24996.52 | K11: 24996.52 | L11: 33112.48 | M11: 39738.38 | N11: 45051.74 | O11: 32791.14 | P11: 32791.14 | Q11: 38828.97 | R11: 39417.72 | S11: 35852.07 | T11: 32078.65 | U11: 32078.65 | V11: 35108.71 | W11: 33982.36 | X11: 40825.76 | Y11: 36393.77 | Z11: 36393.77 | AA11: 22809.72 | AB11: 43813.67
A12: 1 | C12: 당기법인세자산(선급법인세) | E12: 853.93 | F12: 853.93 | G12: 1142.6 | J12: 463.78 | K12: 463.78 | L12: 36.01 | M12: 56.8 | N12: 167.96 | O12: 116.89 | P12: 116.89 | Q12: -35.93 | R12: 26.43 | S12: 100.39 | T12: 139.7 | U12: 139.7 | V12: 35.03 | W12: 61.08 | X12: 120.16 | Y12: 152.99 | Z12: 152.99 | AA12: 32.32 | AB12: 39.75
A13: 1 | C13: 비유동자산 | E13: 227446.48 | F13: 227446.48 | G13: 228488.38 | H13: 229062.92 | I13: 231802.79 | J13: 231306.38 | K13: 231306.38 | L13: 229537.95 | M13: 229540.78 | N13: 230978.22 | O13: 231937.73 | P13: 231937.73 | Q13: 232416.09 | R13: 233876.77 | S13: 233890.5 | T13: 235331.54 | U13: 235331.54 | V13: 234341.28 | W13: 234468.68 | X13: 234369.48 | Y13: 236701.77 | Z13: 236701.77 | AA13: 235613.25 | AB13: 237197.05
A14: 1 | C14: 장기금융자산 | E14: 2022.2 | F14: 2022.2 | G14: 2024.1 | H14: 2701.97 | I14: 2701.97 | J14: 2751.77 | K14: 2751.77 | L14: 2739.68 | M14: 2845.54 | N14: 2751.07 | O14: 2406.71 | P14: 2406.71 | Q14: 2433.72 | R14: 3889.68 | S14: 3857.13 | T14: 4095.37 | U14: 4095.37 | V14: 4848.42 | W14: 4959.87 | X14: 4759.81 | Y14: 4507.1 | Z14: 4507.1 | AA14: 3910.97 | AB14: 3910.74
A15: 1 | C15: 투자자산 | E15: 23065.17 | F15: 23065.17 | G15: 23067.07 | H15: 23744.94 | I15: 23744.94 | J15: 23794.74 | K15: 23794.74 | L15: 23782.65 | M15: 23888.51 | N15: 23794.04 | O15: 23449.68 | P15: 23449.68 | Q15: 23476.69 | R15: 24932.65 | S15: 24900.1 | T15: 25138.34 | U15: 25138.34 | V15: 25891.39 | W15: 26002.84 | X15: 25802.78 | Y15: 25550.07 | Z15: 25550.07 | AA15: 24953.94 | AB15: 24953.71
A16: 1 | C16: 종속기업및관계기업투자 | E16: 21042.97 | F16: 21042.97 | G16: 21042.97 | H16: 21042.97 | I16: 21042.97 | J16: 21042.97 | K16: 21042.97 | L16: 21042.97 | M16: 21042.97 | N16: 21042.97 | O16: 21042.97 | P16: 21042.97 | Q16: 21042.97 | R16: 21042.97 | S16: 21042.97 | T16: 21042.97 | U16: 21042.97 | V16: 21042.97 | W16: 21042.97 | X16: 21042.97 | Y16: 21042.97 | Z16: 21042.97 | AA16: 21042.97 | AB16: 21042.97
A17: 1 | C17: 투자부동산 | E17: 123818.87 | F17: 123818.87 | G17: 123772.16 | H17: 123725.45 | I17: 123678.75 | J17: 126970.6 | K17: 126970.6 | L17: 126917.2 | M17: 126864.93 | N17: 126812.67 | O17: 126760.4 | P17: 126760.4 | Q17: 126708.73 | R17: 126657.06 | S17: 127437.03 | T17: 129203.81 | U17: 129203.81 | V17: 129078.73 | W17: 129005.13 | X17: 128931.53 | Y17: 129028.38 | Z17: 129028.38 | AA17: 128953.32 | AB17: 128878.27
A18: 1 | C18: 유형자산 | E18: 79576.93 | F18: 79576.93 | G18: 80663.64 | H18: 80090.14 | I18: 82463.76 | J18: 78366.85 | K18: 78366.85 | L18: 76797.3 | M18: 76719.92 | N18: 78437.49 | O18: 79703.13 | P18: 79703.13 | Q18: 80349.93 | R18: 80569.99 | S18: 79989.58 | T18: 79613.34 | U18: 79613.34 | V18: 78038.17 | W18: 77948.49 | X18: 78302.19 | Y18: 79024.46 | Z18: 79024.46 | AA18: 78775.13 | AB18: 80392.2
A19: 1 | C19: 무형자산 | E19: 985.51 | F19: 985.51 | G19: 985.51 | H19: 985.51 | I19: 1325.51 | J19: 1332.99 | K19: 1332.99 | L19: 1332.99 | M19: 1332.99 | N19: 1332.99 | O19: 1332.99 | P19: 1332.99 | Q19: 1332.99 | R19: 1332.99 | S19: 1332.99 | T19: 1332.99 | U19: 1332.99 | V19: 1332.99 | W19: 1332.99 | X19: 1332.99 | Y19: 2150.59 | Z19: 2150.59 | AA19: 2150.59 | AB19: 2150.59
A20: 1 | C20: 자산총계 | E20: 328204.09 | F20: 328204.09 | G20: 338182.87 | H20: 344866.84 | I20: 343217.83 | J20: 328404.14 | K20: 328404.14 | L20: 322701.63 | M20: 325210.72 | N20: 331305.48 | O20: 320521.52 | P20: 320521.52 | Q20: 318997.53 | R20: 324627.66 | S20: 324511.34 | T20: 326419.09 | U20: 326419.09 | V20: 330137.61 | W20: 324561.51 | X20: 333949.57 | Y20: 324391.04 | Z20: 324391.04 | AA20: 328028.24 | AB20: 356051.69
A21: 1 | C21: 유동부채 | E21: 83381.67 | F21: 83381.67 | G21: 111599.8 | H21: 127332.52 | I21: 125356.55 | J21: 108057.66 | K21: 108057.66 | L21: 112589.2 | M21: 111306.67 | N21: 124266.64 | O21: 117815.02 | P21: 117815.02 | Q21: 118931.95 | R21: 126325.31 | S21: 120571.21 | T21: 126126.23 | U21: 126126.23 | V21: 130437.25 | W21: 123617.41 | X21: 139174.27 | Y21: 131595.14 | Z21: 131595.14 | AA21: 137787.2 | AB21: 164199.8
A22: 1 | C22: 매입채무및기타채무 | E22: 10647.08 | F22: 10647.08 | G22: 13256.08 | J22: 13281.56 | K22: 13281.56 | L22: 12620.22 | M22: 17648.35 | N22: 23860.85 | O22: 15496.3 | P22: 15496.3 | Q22: 20538.31 | R22: 15120.43 | S22: 12816.33 | T22: 16179.18 | U22: 16179.18 | V22: 13331.37 | W22: 13166.01 | X22: 17296.07 | Y22: 15340.61 | Z22: 15340.61 | AA22: 20765.19 | AB22: 42765.12
A23: 1 | C23: 단기차입금 | E23: 68188.62 | F23: 68188.62 | G23: 93367.77 | H23: 106674.39 | I23: 102467.94 | J23: 90476.5 | K23: 90476.5 | L23: 95053.95 | M23: 79232.24 | N23: 95061.29 | O23: 98053.34 | P23: 98053.34 | Q23: 94213.84 | R23: 107036.14 | S23: 103686.32 | T23: 104940.08 | U23: 104940.08 | V23: 111934.8 | W23: 105669.22 | X23: 117575.85 | Y23: 111705.27 | Z23: 111705.27 | AA23: 112569 | AB23: 117164.55
A24: 1 | C24: 유동성장기부채 | E24: 0 | F24: 0 | G24: 0 | H24: 6464.5 | I24: 0 | M24: 10494 | N24: 0
A25: 1 | C25: 기타유동금융부채 | E25: 2157.76 | F25: 2157.76 | G25: 2741.93 | H25: 4977.18 | I25: 7671.2 | J25: 1692 | K25: 1692 | L25: 1506 | M25: 1506 | N25: 1506 | O25: 1506 | P25: 1506 | Q25: 1506 | R25: 1506 | S25: 1606 | T25: 1606 | U25: 1606 | V25: 2306 | W25: 2291 | X25: 1991 | Y25: 1991 | Z25: 1991 | AA25: 1991 | AB25: 1991
A26: 1 | C26: 단기금융부채 | E26: 2157.76 | F26: 2157.76 | G26: 2741.93 | H26: 4977.18 | I26: 7671.2 | J26: 1962.29 | K26: 1962.29 | L26: 1801.75 | M26: 1715.46 | N26: 1827.51 | O26: 1829.92 | P26: 1829.92 | Q26: 1832.37 | R26: 1836.69 | S26: 1944.81 | T26: 1948.3 | U26: 1948.3 | V26: 2651.83 | W26: 2640.39 | X26: 2342.25 | Y26: 2345.42 | Z26: 2345.42 | AA26: 2348.62 | AB26: 2351.85
A27: 1 | C27: 기타유동부채 | E27: 2388.2 | F27: 2388.2 | G27: 2234.03 | H27: 2138.98 | I27: 2548.84 | J27: 2333.97 | K27: 2333.97 | L27: 3113.29 | M27: 2117.64 | N27: 3418 | O27: 2435.45 | P27: 2435.45 | Q27: 2410.27 | R27: 2332.05 | S27: 2123.74 | T27: 3058.67 | U27: 3058.67 | V27: 2519.24 | W27: 2141.78 | X27: 1960.11 | Y27: 2203.36 | Z27: 2203.36 | AA27: 2104.34 | AB27: 1918.28
A28: 1 | C28: 비유동부채 | E28: 71484.77 | F28: 71484.77 | G28: 51040.86 | H28: 43719.69 | I28: 49631.04 | J28: 51402.38 | K28: 51402.38 | L28: 40796.12 | M28: 44880.1 | N28: 39129.74 | O28: 35180.47 | P28: 35180.47 | Q28: 35097.26 | R28: 35432.1 | S28: 41695.48 | T28: 40858.95 | U28: 40858.95 | V28: 40910.01 | W28: 41130.47 | X28: 35405 | Y28: 36361.98 | Z28: 36361.98 | AA28: 36271.36 | AB28: 36391.54
A29: 1 | C29: 장기차입금 | E29: 16421.5 | F29: 16421.5 | G29: 16548 | H29: 10494 | I29: 16494 | J29: 16494 | K29: 16494 | L29: 6000 | M29: 10000 | N29: 4000 | O29: 0 | P29: 0 | Q29: 0 | R29: 0 | S29: 6000 | T29: 6000 | U29: 6000 | V29: 6000 | W29: 6000 | X29: 0 | Y29: 0 | Z29: 0
A30: 1 | C30: 사채 | E30: 21317.19 | F30: 21317.19 | G30: 0 | H30: 0 | I30: 0 | J30: 0 | K30: 0 | L30: 0 | M30: 0 | N30: 0 | O30: 0 | P30: 0 | Q30: 0 | R30: 0 | S30: 0 | T30: 0 | U30: 0 | V30: 0 | W30: 0 | X30: 0
A31: 1 | C31: 확정급여부채 | E31: -36.18 | F31: -36.18 | G31: 710.59 | J31: 0 | K31: 0 | L31: 0 | M31: 0 | N31: 0 | O31: 0 | P31: 0 | Q31: 0 | R31: 0 | S31: 0 | T31: 0 | U31: 0 | V31: 138.85 | W31: 0 | X31: 2.67
A32: 1 | C32: 이연법인세부채 | E32: 33782.27 | F32: 33782.27 | G32: 33782.27 | H32: 33014.89 | I32: 33014.89 | J32: 34796.12 | K32: 34796.12 | L32: 34796.12 | M32: 34880.1 | N32: 34880.1 | O32: 35012.95 | P32: 35012.95 | Q32: 35012.95 | R32: 35432.1 | S32: 35432.1 | T32: 33176.57 | U32: 33176.57 | V32: 33176.57 | W32: 33624.58 | X32: 33624.58 | Y32: 34674.03 | Z32: 34674.03 | AA32: 34674.03 | AB32: 34885.64
A33: 1 | C33: 기타비유동금융부채 | E33: 0 | F33: 0 | G33: 0 | H33: 210.8 | I33: 122.15 | J33: 0 | K33: 0 | L33: 0 | M33: 0 | N33: 0 | O33: 0 | P33: 0 | Q33: 0 | R33: 0 | S33: 0 | T33: 1505.9 | U33: 1505.9 | V33: 1505.9 | W33: 1505.9 | X33: 1505.9 | Y33: 1505.9 | Z33: 1505.9 | AA33: 1505.9 | AB33: 1505.9
A34: 1 | C34: 장기금융부채 | E34: 0 | F34: 0 | G34: 0 | H34: 210.8 | I34: 122.15 | J34: 112.26 | K34: 112.26 | L34: 0 | M34: 0 | N34: 249.64 | O34: 167.52 | P34: 167.52 | Q34: 84.31 | R34: 0 | S34: 263.38 | T34: 1682.39 | U34: 1682.39 | V34: 1594.6 | W34: 1505.9 | X34: 1777.75 | Y34: 1687.95 | Z34: 1687.95 | AA34: 1597.33 | AB34: 1505.9
A35: 1 | C35: 부채총계 | E35: 154866.44 | F35: 154866.44 | G35: 162640.66 | H35: 171052.21 | I35: 174987.59 | J35: 159460.03 | K35: 159460.03 | L35: 153385.32 | M35: 156186.77 | N35: 163396.37 | O35: 152995.49 | P35: 152995.49 | Q35: 154029.21 | R35: 161757.41 | S35: 162266.69 | T35: 166985.18 | U35: 166985.18 | V35: 171347.25 | W35: 164747.88 | X35: 174579.27 | Y35: 167957.12 | Z35: 167957.12 | AA35: 174058.56 | AB35: 200591.34
A36: 1 | C36: 자본금 | E36: 13348.73 | F36: 13348.73 | G36: 13348.73 | H36: 13348.73 | I36: 13348.73 | J36: 13348.73 | K36: 13348.73 | L36: 13348.73 | M36: 13348.73 | N36: 13348.73 | O36: 13348.73 | P36: 13348.73 | Q36: 13348.73 | R36: 13348.73 | S36: 13348.73 | T36: 13348.73 | U36: 13348.73 | V36: 13348.73 | W36: 13348.73 | X36: 13348.73 | Y36: 13348.73 | Z36: 13348.73 | AA36: 13348.73 | AB36: 13348.73
A37: 1 | C37: 자본잉여금 | E37: 11140.41 | F37: 11140.41 | G37: 11140.41 | H37: 11140.41 | I37: 11140.41 | J37: 11140.41 | K37: 11140.41 | L37: 11140.41 | M37: 11140.41 | N37: 11140.41 | O37: 11140.41 | P37: 11140.41 | Q37: 11140.41 | R37: 11140.41 | S37: 11140.41 | T37: 11140.41 | U37: 11140.41 | V37: 11140.41 | W37: 9948.95 | X37: 9948.95 | Y37: 14513.78 | Z37: 14513.78 | AA37: 14513.78 | AB37: 14513.78
A38: 1 | C38: 이익잉여금 | E38: 148994.34 | F38: 148994.34 | G38: 151197.62 | H38: 149475.92 | I38: 143895.6 | J38: 144613 | K38: 144613 | L38: 144990.53 | M38: 144694.54 | N38: 143578.91 | O38: 143195.25 | P38: 143195.25 | Q38: 140633.35 | R38: 138536.34 | S38: 137914.57 | T38: 135102.98 | U38: 135102.98 | V38: 134460.23 | W38: 136673.91 | X38: 136081.32 | Y38: 135033 | Z38: 135033 | AA38: 132568.77 | AB38: 134059.44
A39: 1 | C39: 자본총계 | E39: 173337.65 | F39: 173337.65 | G39: 175542.21 | H39: 173814.63 | I39: 168230.23 | J39: 168944.1 | K39: 168944.1 | L39: 169316.31 | M39: 169023.96 | N39: 167909.1 | O39: 167526.03 | P39: 167526.03 | Q39: 164968.32 | R39: 162870.25 | S39: 162244.65 | T39: 159433.91 | U39: 159433.91 | V39: 158790.35 | W39: 159813.63 | X39: 159370.29 | Y39: 156433.92 | Z39: 156433.92 | AA39: 153969.68 | AB39: 155460.35
A40: 1 | C40: 부채와자본총계 | E40: 328204.09 | F40: 328204.09 | G40: 338182.87 | H40: 344866.84 | I40: 343217.83 | J40: 328404.14 | K40: 328404.14 | L40: 322701.63 | M40: 325210.72 | N40: 331305.48 | O40: 320521.52 | P40: 320521.52 | Q40: 318997.53 | R40: 324627.66 | S40: 324511.34 | T40: 326419.09 | U40: 326419.09 | V40: 330137.61 | W40: 324561.51 | X40: 333949.57 | Y40: 324391.04 | Z40: 324391.04 | AA40: 328028.24 | AB40: 356051.69
...

Sheet subQ
A1: YQ | C1: subQ 분기 서브모델(억원, U=100) | E1: 4Q21 | F1: 2021 | G1: 1Q22 | H1: 2Q22 | I1: 3Q22 | J1: 4Q22 | K1: 2022 | L1: 1Q23 | M1: 2Q23 | N1: 3Q23 | O1: 4Q23 | P1: 2023 | Q1: 1Q24 | R1: 2Q24 | S1: 3Q24 | T1: 4Q24 | U1: 2024 | V1: 1Q25 | W1: 2Q25 | X1: 3Q25 | Y1: 4Q25 | Z1: 2025 | AA1: 1Q26 | AB1: 2Q26 | AC1: 3Q26 | AD1: 4Q26 | AE1: 2026 | AF1: 1Q27 | AG1: 2Q27 | AH1: 3Q27 | AI1: 4Q27 | AJ1: 2027 | AK1: 1Q28 | AL1: 2Q28 | AM1: 3Q28 | AN1: 4Q28 | AO1: 2028
A2: A=이름(key) B=그룹 C=단위 D=FnGuide 계정명(VLOOKUP 키). 확정=VLOOKUP(BS), 추정=변수 가정 참조
E3: 1 | F3: 2 | G3: 3 | H3: 4 | I3: 5 | J3: 6 | K3: 7 | L3: 8 | M3: 9 | N3: 10 | O3: 11 | P3: 12 | Q3: 13 | R3: 14 | S3: 15 | T3: 16 | U3: 17 | V3: 18 | W3: 19 | X3: 20 | Y3: 21 | Z3: 22 | AA3: 23 | AB3: 24 | AC3: 25 | AD3: 26 | AE3: 27 | AF3: 28 | AG3: 29 | AH3: 30 | AI3: 31 | AJ3: 32 | AK3: 33 | AL3: 34 | AM3: 35 | AN3: 36 | AO3: 37
E4: 2021.12 | F4: 2021.12A | G4: 2022.03 | H4: 2022.06 | I4: 2022.09 | J4: 2022.12 | K4: 2022.12A | L4: 2023.03 | M4: 2023.06 | N4: 2023.09 | O4: 2023.12 | P4: 2023.12A | Q4: 2024.03 | R4: 2024.06 | S4: 2024.09 | T4: 2024.12 | U4: 2024.12A | V4: 2025.03 | W4: 2025.06 | X4: 2025.09 | Y4: 2025.12 | Z4: 2025.12A | AA4: 2026.03 | AB4: 2026.06 | AC4: 2026.09 | AD4: 2026.12 | AE4: 2026.12A | AF4: 2027.03 | AG4: 2027.06 | AH4: 2027.09 | AI4: 2027.12 | AJ4: 2027.12A | AK4: 2028.03 | AL4: 2028.06 | AM4: 2028.09 | AN4: 2028.12 | AO4: 2028.12A
A5: 매출액 | B5: 손익 | C5: 억원 | D5: 매출액(수익) | E5: =IFERROR(VLOOKUP($D5,BS연결,MATCH(E$1,BS연결H,0),0)/100,"") | G5: =IFERROR(VLOOKUP($D5,BS연결,MATCH(G$1,BS연결H,0),0)/100,"") | H5: =IFERROR(VLOOKUP($D5,BS연결,MATCH(H$1,BS연결H,0),0)/100,"") | I5: =IFERROR(VLOOKUP($D5,BS연결,MATCH(I$1,BS연결H,0),0)/100,"") | J5: =IFERROR(VLOOKUP($D5,BS연결,MATCH(J$1,BS연결H,0),0)/100,"") | K5: =IFERROR(VLOOKUP($D5,BS연결,MATCH(K$1,BS연결H,0),0)/100,"") | L5: =IFERROR(VLOOKUP($D5,BS연결,MATCH(L$1,BS연결H,0),0)/100,"") | M5: =IFERROR(VLOOKUP($D5,BS연결,MATCH(M$1,BS연결H,0),0)/100,"") | N5: =IFERROR(VLOOKUP($D5,BS연결,MATCH(N$1,BS연결H,0),0)/100,"") | ... AB5: =IFERROR(VLOOKUP($D5,BS연결,MATCH(AB$1,BS연결H,0),0)/100,"") | AC5: =IFERROR(X5*(1+변수!AC21),"") | AD5: =IFERROR(Y5*(1+변수!AD21),"") | AE5: =SUM(AA5:AD5) | AF5: =IFERROR(AA5*(1+변수!AF21),"") | AG5: =IFERROR(AB5*(1+변수!AG21),"") | AH5: =IFERROR(AC5*(1+변수!AH21),"") | AI5: =IFERROR(AD5*(1+변수!AI21),"") | AJ5: =SUM(AF5:AI5) | AK5: =IFERROR(AF5*(1+변수!AK21),"") | AL5: =IFERROR(AG5*(1+변수!AL21),"") | AM5: =IFERROR(AH5*(1+변수!AM21),"") | AN5: =IFERROR(AI5*(1+변수!AN21),"") | AO5: =SUM(AK5:AN5)
A6: 매출원가 | B6: 손익 | C6: 억원 | D6: 매출원가 | E6: =IFERROR(VLOOKUP($D6,BS연결,MATCH(E$1,BS연결H,0),0)/100,"") | G6: =IFERROR(VLOOKUP($D6,BS연결,MATCH(G$1,BS연결H,0),0)/100,"") | H6: =IFERROR(VLOOKUP($D6,BS연결,MATCH(H$1,BS연결H,0),0)/100,"") | I6: =IFERROR(VLOOKUP($D6,BS연결,MATCH(I$1,BS연결H,0),0)/100,"") | J6: =IFERROR(VLOOKUP($D6,BS연결,MATCH(J$1,BS연결H,0),0)/100,"") | K6: =IFERROR(VLOOKUP($D6,BS연결,MATCH(K$1,BS연결H,0),0)/100,"") | L6: =IFERROR(VLOOKUP($D6,BS연결,MATCH(L$1,BS연결H,0),0)/100,"") | M6: =IFERROR(VLOOKUP($D6,BS연결,MATCH(M$1,BS연결H,0),0)/100,"") | N6: =IFERROR(VLOOKUP($D6,BS연결,MATCH(N$1,BS연결H,0),0)/100,"") | ... AB6: =IFERROR(VLOOKUP($D6,BS연결,MATCH(AB$1,BS연결H,0),0)/100,"") | AC6: =IFERROR(AC5-AC7,"") | AD6: =IFERROR(AD5-AD7,"") | AE6: =SUM(AA6:AD6) | AF6: =IFERROR(AF5-AF7,"") | AG6: =IFERROR(AG5-AG7,"") | AH6: =IFERROR(AH5-AH7,"") | AI6: =IFERROR(AI5-AI7,"") | AJ6: =SUM(AF6:AI6) | AK6: =IFERROR(AK5-AK7,"") | AL6: =IFERROR(AL5-AL7,"") | AM6: =IFERROR(AM5-AM7,"") | AN6: =IFERROR(AN5-AN7,"") | AO6: =SUM(AK6:AN6)
A7: 매출총이익 | B7: 손익 | C7: 억원 | D7: 매출총이익 | E7: =IFERROR(VLOOKUP($D7,BS연결,MATCH(E$1,BS연결H,0),0)/100,"") | G7: =IFERROR(VLOOKUP($D7,BS연결,MATCH(G$1,BS연결H,0),0)/100,"") | H7: =IFERROR(VLOOKUP($D7,BS연결,MATCH(H$1,BS연결H,0),0)/100,"") | I7: =IFERROR(VLOOKUP($D7,BS연결,MATCH(I$1,BS연결H,0),0)/100,"") | J7: =IFERROR(VLOOKUP($D7,BS연결,MATCH(J$1,BS연결H,0),0)/100,"") | K7: =IFERROR(VLOOKUP($D7,BS연결,MATCH(K$1,BS연결H,0),0)/100,"") | L7: =IFERROR(VLOOKUP($D7,BS연결,MATCH(L$1,BS연결H,0),0)/100,"") | M7: =IFERROR(VLOOKUP($D7,BS연결,MATCH(M$1,BS연결H,0),0)/100,"") | N7: =IFERROR(VLOOKUP($D7,BS연결,MATCH(N$1,BS연결H,0),0)/100,"") | ... AB7: =IFERROR(VLOOKUP($D7,BS연결,MATCH(AB$1,BS연결H,0),0)/100,"") | AC7: =IFERROR(AC9+AC8,"") | AD7: =IFERROR(AD9+AD8,"") | AE7: =SUM(AA7:AD7) | AF7: =IFERROR(AF9+AF8,"") | AG7: =IFERROR(AG9+AG8,"") | AH7: =IFERROR(AH9+AH8,"") | AI7: =IFERROR(AI9+AI8,"") | AJ7: =SUM(AF7:AI7) | AK7: =IFERROR(AK9+AK8,"") | AL7: =IFERROR(AL9+AL8,"") | AM7: =IFERROR(AM9+AM8,"") | AN7: =IFERROR(AN9+AN8,"") | AO7: =SUM(AK7:AN7)
A8: 판관비 | B8: 손익 | C8: 억원 | D8: 판관비 | E8: =IFERROR(VLOOKUP($D8,BS연결,MATCH(E$1,BS연결H,0),0)/100,"") | G8: =IFERROR(VLOOKUP($D8,BS연결,MATCH(G$1,BS연결H,0),0)/100,"") | H8: =IFERROR(VLOOKUP($D8,BS연결,MATCH(H$1,BS연결H,0),0)/100,"") | I8: =IFERROR(VLOOKUP($D8,BS연결,MATCH(I$1,BS연결H,0),0)/100,"") | J8: =IFERROR(VLOOKUP($D8,BS연결,MATCH(J$1,BS연결H,0),0)/100,"") | K8: =IFERROR(VLOOKUP($D8,BS연결,MATCH(K$1,BS연결H,0),0)/100,"") | L8: =IFERROR(VLOOKUP($D8,BS연결,MATCH(L$1,BS연결H,0),0)/100,"") | M8: =IFERROR(VLOOKUP($D8,BS연결,MATCH(M$1,BS연결H,0),0)/100,"") | N8: =IFERROR(VLOOKUP($D8,BS연결,MATCH(N$1,BS연결H,0),0)/100,"") | ... AB8: =IFERROR(VLOOKUP($D8,BS연결,MATCH(AB$1,BS연결H,0),0)/100,"") | AC8: =IFERROR(AC5*변수!AC22,"") | AD8: =IFERROR(AD5*변수!AD22,"") | AE8: =SUM(AA8:AD8) | AF8: =IFERROR(AF5*변수!AF22,"") | AG8: =IFERROR(AG5*변수!AG22,"") | AH8: =IFERROR(AH5*변수!AH22,"") | AI8: =IFERROR(AI5*변수!AI22,"") | AJ8: =SUM(AF8:AI8) | AK8: =IFERROR(AK5*변수!AK22,"") | AL8: =IFERROR(AL5*변수!AL22,"") | AM8: =IFERROR(AM5*변수!AM22,"") | AN8: =IFERROR(AN5*변수!AN22,"") | AO8: =SUM(AK8:AN8)
A9: 영업이익 | B9: 손익 | C9: 억원 | D9: 영업이익 | E9: =IFERROR(VLOOKUP($D9,BS연결,MATCH(E$1,BS연결H,0),0)/100,"") | G9: =IFERROR(VLOOKUP($D9,BS연결,MATCH(G$1,BS연결H,0),0)/100,"") | H9: =IFERROR(VLOOKUP($D9,BS연결,MATCH(H$1,BS연결H,0),0)/100,"") | I9: =IFERROR(VLOOKUP($D9,BS연결,MATCH(I$1,BS연결H,0),0)/100,"") | J9: =IFERROR(VLOOKUP($D9,BS연결,MATCH(J$1,BS연결H,0),0)/100,"") | K9: =IFERROR(VLOOKUP($D9,BS연결,MATCH(K$1,BS연결H,0),0)/100,"") | L9: =IFERROR(VLOOKUP($D9,BS연결,MATCH(L$1,BS연결H,0),0)/100,"") | M9: =IFERROR(VLOOKUP($D9,BS연결,MATCH(M$1,BS연결H,0),0)/100,"") | N9: =IFERROR(VLOOKUP($D9,BS연결,MATCH(N$1,BS연결H,0),0)/100,"") | ... AB9: =IFERROR(VLOOKUP($D9,BS연결,MATCH(AB$1,BS연결H,0),0)/100,"") | AC9: =IFERROR(AC5*변수!AC23,"") | AD9: =IFERROR(AD5*변수!AD23,"") | AE9: =SUM(AA9:AD9) | AF9: =IFERROR(AF5*변수!AF23,"") | AG9: =IFERROR(AG5*변수!AG23,"") | AH9: =IFERROR(AH5*변수!AH23,"") | AI9: =IFERROR(AI5*변수!AI23,"") | AJ9: =SUM(AF9:AI9) | AK9: =IFERROR(AK5*변수!AK23,"") | AL9: =IFERROR(AL5*변수!AL23,"") | AM9: =IFERROR(AM5*변수!AM23,"") | AN9: =IFERROR(AN5*변수!AN23,"") | AO9: =SUM(AK9:AN9)
A10: OPM | B10: 손익 | C10: % | D10: 영업이익률 | E10: =IFERROR(E9/E5,"") | G10: =IFERROR(G9/G5,"") | H10: =IFERROR(H9/H5,"") | I10: =IFERROR(I9/I5,"") | J10: =IFERROR(J9/J5,"") | K10: =IFERROR(K9/K5,"") | L10: =IFERROR(L9/L5,"") | M10: =IFERROR(M9/M5,"") | N10: =IFERROR(N9/N5,"") | ... AO10: =IFERROR(AO9/AO5,"")
A11: 금융손익 | B11: 손익 | C11: 억원 | D11: 금융손익 | E11: =IFERROR(VLOOKUP($D11,BS연결,MATCH(E$1,BS연결H,0),0)/100,"") | G11: =IFERROR(VLOOKUP($D11,BS연결,MATCH(G$1,BS연결H,0),0)/100,"") | H11: =IFERROR(VLOOKUP($D11,BS연결,MATCH(H$1,BS연결H,0),0)/100,"") | I11: =IFERROR(VLOOKUP($D11,BS연결,MATCH(I$1,BS연결H,0),0)/100,"") | J11: =IFERROR(VLOOKUP($D11,BS연결,MATCH(J$1,BS연결H,0),0)/100,"") | K11: =IFERROR(VLOOKUP($D11,BS연결,MATCH(K$1,BS연결H,0),0)/100,"") | L11: =IFERROR(VLOOKUP($D11,BS연결,MATCH(L$1,BS연결H,0),0)/100,"") | M11: =IFERROR(VLOOKUP($D11,BS연결,MATCH(M$1,BS연결H,0),0)/100,"") | N11: =IFERROR(VLOOKUP($D11,BS연결,MATCH(N$1,BS연결H,0),0)/100,"") | ... T11: =IFERROR(VLOOKUP($D11,BS연결,MATCH(T$1,BS연결H,0),0)/100,"") | U11: =SUM(Q11:T11) | V11: =IFERROR(VLOOKUP($D11,BS연결,MATCH(V$1,BS연결H,0),0)/100,"") | W11: =IFERROR(VLOOKUP($D11,BS연결,MATCH(W$1,BS연결H,0),0)/100,"") | X11: =IFERROR(VLOOKUP($D11,BS연결,MATCH(X$1,BS연결H,0),0)/100,"") | Y11: =IFERROR(VLOOKUP($D11,BS연결,MATCH(Y$1,BS연결H,0),0)/100,"") | Z11: =IFERROR(VLOOKUP($D11,BS연결,MATCH(Z$1,BS연결H,0),0)/100,"") | AA11: =IFERROR(VLOOKUP($D11,BS연결,MATCH(AA$1,BS연결H,0),0)/100,"") | AB11: =IFERROR(VLOOKUP($D11,BS연결,MATCH(AB$1,BS연결H,0),0)/100,"") | AC11: =IFERROR(AC12+AC13,"") | AD11: =IFERROR(AD12+AD13,"") | AE11: =SUM(AA11:AD11) | AF11: =IFERROR(AF12+AF13,"") | AG11: =IFERROR(AG12+AG13,"") | AH11: =IFERROR(AH12+AH13,"") | AI11: =IFERROR(AI12+AI13,"") | AJ11: =SUM(AF11:AI11) | AK11: =IFERROR(AK12+AK13,"") | AL11: =IFERROR(AL12+AL13,"") | AM11: =IFERROR(AM12+AM13,"") | AN11: =IFERROR(AN12+AN13,"") | AO11: =SUM(AK11:AN11)
