Workbook
Name 변수H: 변수!$C$1:$AO$1
Name 환율: 변수!$C$6:$AO$13
Name BS연결H: BS연결!$C$1:$AO$1
Name BS연결: BS연결!$C$5:$AO$110
Name BS별도H: BS별도!$C$1:$AO$1
Name BS별도: BS별도!$C$5:$AO$94
Name SUBQH: subQ!$A$1:$AO$1
Name subQ: subQ!$A$5:$AO$47

Sheet README
A1: 케이씨씨(002380) 실적 모델 — ARGUS 한국조선
A2: 기준 분기 2026Q2 · 마지막 실적 2026Q2 · 생성 2026-10-12
A3: 모든 수치는 모델 산출값(DART 공개 재무제표 + 우리 추정)이다 — 목표주가·투자 추천 아님. 참고용 · 투자조언 아님.
A5: 시트
A6: 변수 가정 시계열. 환율 8행(ECB via frankfurter — L2 fx.json; 추정 분기 = 노란 가정), 추정 드라이버(노란 셀 = 모델값에서 역산한 가정, 바꾸면 재계산; 연녹 셀 = 3절 스칼라 참조 수식), 3절 스칼라 가정(세율·판관비율·지배주주비중·이자율·종가·PER 밴드·COE·외화 순노출·헤지비율)
A7: BS연결/BS별도 FnGuide 계정명 × 기간 값 덤프(백만원). 행1 분기라벨, 행4 YYYY.MM / YYYY.12A. 이름정의 BS연결H·BS연결(계정명 C열부터)
A8: subQ 분기 서브모델(억원 = 백만원/100). 확정 행: =IFERROR(VLOOKUP($D행,BS연결,MATCH(E$1,BS연결H,0),0)/100,"") 추정 행: 변수 시트 가정 셀 참조 수식. 외환손익·파생상품손익은 BS 계정 합·차, 기타금융손익은 잔차, OPM·EPS·BPS·PER·PBR 은 파생 수식, 조정EPS 는 EPS 참조(일회성 의심 분기만 산식 셀)
A9: SLS 선표(조선사만, sls json 있을 때): 요약 행(sls 저장값) + 계약별 스케줄(백만$) × (헤지비율 × 헤지환율 + (1−헤지비율) × 건조시점 환율[변수 원/달러(평균)]) → 원화 수식 블록 → 합계 행이 subQ 매출조선에 연결
A10: 시나리오 신규수주 보수/기준/낙관(forecast_panel 패널, 모델에 scenarios 가 있을 때만): 매출액·영업이익 = subQ 기준값 ± (시나리오 신규 − base 신규) × OPM. base 만 subQ 행에 포함, 나머지는 합산 안 함
A11: 분기/연간예상 subQ 를 이름(A열 key)으로 VLOOKUP 한 보고서 표(억원)
A12: TP PER 밴드 × 12M fwd EPS, PBR = ROE/COE × BPS — 모델 산출값 구간, 목표주가·추천 아님
A13: 외화 환율 QoQ, 외화 순노출 × Δ기말환율 → 환관련손익 추정
... A35: 백테스트: {"freeze": "2025Q2", "horizon": 4, "revenue_wape_pct": 32.2, "op_wape_pct": 43.9, "n": 4, "note": "단일 회사 4분기 — 통계 아님", "driver_at_freeze": "customer_yard_revenue_weighted", "selection_oos_at_freeze": {"freeze": "2024Q2", "n": 4, "wape_link": null, "wape_trend": 3.9, "adopted": "undetermined", "decision": "undetermined", "note": "현재 채택 조합(suppliers_mentions·시차 4·ma4·창 8)을 동결 데이터로 재적합할 수 없음(짝·고객 모델 부족) → 연동 WAPE 없음, undetermined(유의성 조건만으로 채택)"}, "frozen_inputs": "fin(연결/별도)·고객 조선사 모델·지주 자회사 모델은 2025Q2 까지의 분기만; 선표는 체결일 ≤ 2025Q2 말일 계약(원장 최신 금액·코호트 등급, 환산 없음); 잔고는 yards_cache 2025Q2; 시세·환율 forward·prices·forecast_panel 신규수주 미사용. 고객 가중치(suppliers.json 언급 비중)와 합병 체인링크는 현재 지식; 고객 연동 채택은 동결 모델 안에서도 자기 la−4분기 OOS 규칙(selection_oos_at_freeze)", "detail": [{"q": "2025Q3", "rev_pred": 20450.78, "rev_act": 16228.33, "op_pred": 1349.61, "op_act": 1172.64}, {"q": "2025Q4", "rev_pred": 21141.06, "rev_act": 15564.18, "op_pred": 1395.17, "op_act": 665.27}, {"q": "2026Q1", "rev_pred": 21947.17, "rev_act": 16264.0, "op_pred": 1448.37, "op_act": 881.28}, {"q": "2026Q2", "rev_pred": 23848.0, "rev_act": 18060.19, "op_pred": 1573.81, "op_act": 1288.84}]}

Sheet 변수
C1: 이름: 변수H | E1: 4Q21 | F1: 2021 | G1: 1Q22 | H1: 2Q22 | I1: 3Q22 | J1: 4Q22 | K1: 2022 | L1: 1Q23 | M1: 2Q23 | N1: 3Q23 | O1: 4Q23 | P1: 2023 | Q1: 1Q24 | R1: 2Q24 | S1: 3Q24 | T1: 4Q24 | U1: 2024 | V1: 1Q25 | W1: 2Q25 | X1: 3Q25 | Y1: 4Q25 | Z1: 2025 | AA1: 1Q26 | AB1: 2Q26 | AC1: 3Q26 | AD1: 4Q26 | AE1: 2026 | AF1: 1Q27 | AG1: 2Q27 | AH1: 3Q27 | AI1: 4Q27 | AJ1: 2027 | AK1: 1Q28 | AL1: 2Q28 | AM1: 3Q28 | AN1: 4Q28 | AO1: 2028
A2: 가정 시계열 — 노란 셀은 추정 가정(모델값에서 역산), 연녹 셀은 3절 스칼라 참조 수식. 바꾸면 subQ·분기·연간예상·TP·시나리오가 재계산됩니다.
E3: 1 | F3: 2 | G3: 3 | H3: 4 | I3: 5 | J3: 6 | K3: 7 | L3: 8 | M3: 9 | N3: 10 | O3: 11 | P3: 12 | Q3: 13 | R3: 14 | S3: 15 | T3: 16 | U3: 17 | V3: 18 | W3: 19 | X3: 20 | Y3: 21 | Z3: 22 | AA3: 23 | AB3: 24 | AC3: 25 | AD3: 26 | AE3: 27 | AF3: 28 | AG3: 29 | AH3: 30 | AI3: 31 | AJ3: 32 | AK3: 33 | AL3: 34 | AM3: 35 | AN3: 36 | AO3: 37
E4: 2021.12 | F4: 2021.12A | G4: 2022.03 | H4: 2022.06 | I4: 2022.09 | J4: 2022.12 | K4: 2022.12A | L4: 2023.03 | M4: 2023.06 | N4: 2023.09 | O4: 2023.12 | P4: 2023.12A | Q4: 2024.03 | R4: 2024.06 | S4: 2024.09 | T4: 2024.12 | U4: 2024.12A | V4: 2025.03 | W4: 2025.06 | X4: 2025.09 | Y4: 2025.12 | Z4: 2025.12A | AA4: 2026.03 | AB4: 2026.06 | AC4: 2026.09 | AD4: 2026.12 | AE4: 2026.12A | AF4: 2027.03 | AG4: 2027.06 | AH4: 2027.09 | AI4: 2027.12 | AJ4: 2027.12A | AK4: 2028.03 | AL4: 2028.06 | AM4: 2028.09 | AN4: 2028.12 | AO4: 2028.12A
B5: 1. FX | C5: 이름: 환율
A6: USDKRW_avg | C6: 원/달러(평균) | E6: 1183.5 | F6: 1145.51 | G6: 1205.78 | H6: 1262.09 | I6: 1341.93 | J6: 1360.12 | K6: 1292.98 | L6: 1276.95 | M6: 1315.69 | N6: 1313.62 | O6: 1322.01 | P6: 1306.85 | Q6: 1330.14 | R6: 1371.28 | S6: 1356.22 | T6: 1396.3 | U6: 1363.53 | V6: 1452.28 | W6: 1398.52 | X6: 1386.95 | Y6: 1449.19 | Z6: 1421.52 | AA6: 1466.12 | AB6: 1501.75 | AC6: 1418.75 | AD6: 1345.14 | AE6: 1457.21 | AF6: 1341.49 | AG6: 1341.49 | AH6: 1341.49 | AI6: 1341.49 | AK6: 1341.49 | AL6: 1341.49 | AM6: 1341.49 | AN6: 1341.49
A7: USDKRW_end | C7: 원/달러(기말) | E7: 1188.75 | F7: 1188.75 | G7: 1213.74 | H7: 1301.24 | I7: 1436.9 | J7: 1260.16 | K7: 1260.16 | L7: 1305.99 | M7: 1321.44 | N7: 1345.35 | O7: 1297.43 | P7: 1297.43 | Q7: 1349.25 | R7: 1377.73 | S7: 1312.17 | T7: 1474.78 | U7: 1474.78 | V7: 1474.54 | W7: 1355.13 | X7: 1403.67 | Y7: 1444.2 | Z7: 1444.2 | AA7: 1524.8 | AB7: 1550.89 | AC7: 1355.4 | AD7: 1341.49 | AE7: 1341.49 | AF7: 1341.49 | AG7: 1341.49 | AH7: 1341.49 | AI7: 1341.49 | AK7: 1341.49 | AL7: 1341.49 | AM7: 1341.49 | AN7: 1341.49
A8: JPY100KRW_avg | C8: 원/100Y(평균) | E8: 1041.02 | F8: 1042.74 | G8: 1036.79 | H8: 972.23 | I8: 970.61 | J8: 961.03 | K8: 985.1 | L8: 964.89 | M8: 957.36 | N8: 909 | O8: 893.22 | P8: 931.11 | Q8: 896.29 | R8: 880.14 | S8: 909.35 | T8: 917.25 | U8: 900.92 | V8: 952.59 | W8: 967.92 | X8: 940.32 | Y8: 940.77 | Z8: 950.17 | AA8: 934.39 | AB8: 942.16 | AC8: 890.41 | AD8: 850.79 | AE8: 919.21 | AF8: 847.7 | AG8: 847.7 | AH8: 847.7 | AI8: 847.7 | AK8: 847.7 | AL8: 847.7 | AM8: 847.7 | AN8: 847.7
A9: JPY100KRW_end | C9: 원/100Y(기말) | E9: 1032.62 | F9: 1032.62 | G9: 996.83 | H9: 954.9 | I9: 993.29 | J9: 955.54 | K9: 955.54 | L9: 980.62 | M9: 913.67 | N9: 901.47 | O9: 917.04 | P9: 917.04 | Q9: 892.42 | R9: 857.76 | S9: 919.21 | T9: 939.65 | U9: 939.65 | V9: 986.84 | W9: 938.85 | X9: 948.49 | Y9: 921.81 | Z9: 921.81 | AA9: 955.99 | AB9: 954.75 | AC9: 863.31 | AD9: 847.7 | AE9: 847.7 | AF9: 847.7 | AG9: 847.7 | AH9: 847.7 | AI9: 847.7 | AK9: 847.7 | AL9: 847.7 | AM9: 847.7 | AN9: 847.7
A10: EURKRW_avg | C10: W/Euro(평균) | E10: 1353.32 | F10: 1354.06 | G10: 1352.29 | H10: 1343.31 | I10: 1350.63 | J10: 1386.07 | K10: 1358.07 | L10: 1369.93 | M10: 1432.41 | N10: 1429.41 | O10: 1420.91 | P10: 1412.88 | Q10: 1444.21 | R10: 1476.42 | S10: 1489.3 | T10: 1490.78 | U10: 1475.4 | V10: 1528.33 | W10: 1585.13 | X10: 1620.04 | Y10: 1686.02 | Z10: 1605.45 | AA10: 1715.47 | AB10: 1746.09 | AC10: 1631.97 | AD10: 1509.74 | AE10: 1689.95 | AF10: 1503.27 | AG10: 1503.27 | AH10: 1503.27 | AI10: 1503.27 | AK10: 1503.27 | AL10: 1503.27 | AM10: 1503.27 | AN10: 1503.27
A11: EURKRW_end | C11: W/Euro(기말) | E11: 1346.38 | F11: 1346.38 | G11: 1347.37 | H11: 1351.6 | I11: 1400.62 | J11: 1344.08 | K11: 1344.08 | L11: 1420.26 | M11: 1435.88 | N11: 1425.26 | O11: 1433.66 | P11: 1433.66 | Q11: 1458.68 | R11: 1474.86 | S11: 1469.1 | T11: 1532.14 | U11: 1532.14 | V11: 1594.72 | W11: 1588.22 | X11: 1648.04 | Y11: 1696.94 | Z11: 1696.94 | AA11: 1753.21 | AB11: 1767.09 | AC11: 1539.06 | AD11: 1503.27 | AE11: 1503.27 | AF11: 1503.27 | AG11: 1503.27 | AH11: 1503.27 | AI11: 1503.27 | AK11: 1503.27 | AL11: 1503.27 | AM11: 1503.27 | AN11: 1503.27
A12: CNYKRW_avg | C12: 원/중국원(평균) | E12: 185.14 | F12: 177.65 | G12: 189.93 | H12: 190.76 | I12: 195.79 | J12: 191.09 | K12: 191.93 | L12: 186.59 | M12: 187.45 | N12: 181.28 | O12: 182.86 | P12: 184.52 | Q12: 185.04 | R12: 189.35 | S12: 189.24 | T12: 194.24 | U12: 189.49 | V12: 199.63 | W12: 193.41 | X12: 193.79 | Y12: 204.38 | Z12: 197.8 | AA12: 211.75 | AB12: 220.8 | AC12: 210.43 | AD12: 200.69 | AE12: 213.75 | AF12: 200.46 | AG12: 200.46 | AH12: 200.46 | AI12: 200.46 | AK12: 200.46 | AL12: 200.46 | AM12: 200.46 | AN12: 200.46
A13: CNYKRW_end | C13: 원/중국원(기말) | E13: 187.13 | F13: 187.13 | G13: 191.38 | H13: 194.13 | I13: 201.92 | J13: 182.67 | K13: 182.67 | L13: 189.97 | M13: 181.8 | N13: 184.26 | O13: 182.61 | P13: 182.61 | Q13: 186.66 | R13: 189.7 | S13: 187.12 | T13: 202.04 | U13: 202.04 | V13: 203.3 | W13: 189.14 | X13: 197.16 | Y13: 206.28 | Z13: 206.28 | AA13: 220.97 | AB13: 228.56 | AC13: 202.16 | AD13: 200.46 | AE13: 200.46 | AF13: 200.46 | AG13: 200.46 | AH13: 200.46 | AI13: 200.46 | AK13: 200.46 | AL13: 200.46 | AM13: 200.46 | AN13: 200.46
B14: 1b. 종가
A15: price_close_end | C15: 종가(기말) | E15: 315000 | G15: 342000 | H15: 287500 | I15: 231500 | J15: 204500 | L15: 222000 | M15: 196400 | N15: 246500 | O15: 228500 | Q15: 259500 | R15: 308500 | S15: 301500 | T15: 235500 | V15: 252500 | W15: 312000 | X15: 384000 | Y15: 420500 | AA15: 482000 | AB15: 486500 | AC15: 470500 | AD15: 455000
A16: price_high | C16: 종가(최고) | E16: 420500 | G16: 414500 | H16: 382500 | I16: 319500 | J16: 266000 | L16: 261500 | M16: 244500 | N16: 271500 | O16: 250500 | Q16: 294000 | R16: 327500 | S16: 345000 | T16: 306500 | V16: 289500 | W16: 344000 | X16: 441000 | Y16: 460000 | AA16: 692000 | AB16: 656000 | AC16: 514000 | AD16: 479000
A17: price_low | C17: 종가(최저) | E17: 271000 | G17: 296000 | H17: 268000 | I17: 227500 | J17: 203500 | L17: 191500 | M17: 192000 | N17: 186700 | O17: 207000 | Q17: 199900 | R17: 225000 | S17: 270500 | T17: 216500 | V17: 226500 | W17: 231000 | X17: 314000 | Y17: 367000 | AA17: 382500 | AB17: 452000 | AC17: 336000 | AD17: 452000
A18: price_avg | C18: 종가(평균) | E18: 328738.1 | G18: 348330.5 | H18: 329846.8 | I18: 284865.1 | J18: 239016.1 | L18: 229911.3 | M18: 215073.8 | N18: 216145.2 | O18: 229691.7 | Q18: 253950.8 | R18: 277025 | S18: 306096.8 | T18: 249426.2 | V18: 263310.3 | W18: 275991.7 | X18: 379915.4 | Y18: 415796.6 | AA18: 502076.3 | AB18: 534524.6 | AC18: 451483.9 | AD18: 466583.3
B20: 2. 추정 드라이버 | C20: 실적 열 = subQ 실현값(수식), 추정 열 = 가정(노란 = 모델값 역산, 연녹 = 3절 스칼라 참조)
A21: drv:매출액 | B21: yoy | C21: 매출액 YoY | J21: =IFERROR(subQ!J5/subQ!E5-1,"") | L21: =IFERROR(subQ!L5/subQ!G5-1,"") | M21: =IFERROR(subQ!M5/subQ!H5-1,"") | N21: =IFERROR(subQ!N5/subQ!I5-1,"") | O21: =IFERROR(subQ!O5/subQ!J5-1,"") | Q21: =IFERROR(subQ!Q5/subQ!L5-1,"") | R21: =IFERROR(subQ!R5/subQ!M5-1,"") | S21: =IFERROR(subQ!S5/subQ!N5-1,"") | T21: =IFERROR(subQ!T5/subQ!O5-1,"") | V21: =IFERROR(subQ!V5/subQ!Q5-1,"") | W21: =IFERROR(subQ!W5/subQ!R5-1,"") | X21: =IFERROR(subQ!X5/subQ!S5-1,"") | Y21: =IFERROR(subQ!Y5/subQ!T5-1,"") | AA21: =IFERROR(subQ!AA5/subQ!V5-1,"") | AB21: =IFERROR(subQ!AB5/subQ!W5-1,"") | AC21: 0.002340026 | AD21: 0.002340156 | AF21: 0.002340415 | AG21: 0.002340429 | AH21: 0.001170518 | AI21: 0.001170468 | AK21: 0.001169791 | AL21: 0.001170007 | AM21: 0.000584575 | AN21: 0.00058455
A22: drv:판관비 | B22: ratio | C22: 판관비율(/매출) | E22: =IFERROR(subQ!E8/subQ!E5,"") | F22: =IFERROR(subQ!F8/subQ!F5,"") | G22: =IFERROR(subQ!G8/subQ!G5,"") | H22: =IFERROR(subQ!H8/subQ!H5,"") | I22: =IFERROR(subQ!I8/subQ!I5,"") | J22: =IFERROR(subQ!J8/subQ!J5,"") | K22: =IFERROR(subQ!K8/subQ!K5,"") | L22: =IFERROR(subQ!L8/subQ!L5,"") | ... AB22: =IFERROR(subQ!AB8/subQ!AB5,"") | AC22: =$D$54 | AD22: =$D$54 | AE22: =IFERROR(subQ!AE8/subQ!AE5,"") | AF22: =$D$54 | AG22: =$D$54 | AH22: =$D$54 | AI22: =$D$54 | AJ22: =IFERROR(subQ!AJ8/subQ!AJ5,"") | AK22: =$D$54 | AL22: =$D$54 | AM22: =$D$54 | AN22: =$D$54 | AO22: =IFERROR(subQ!AO8/subQ!AO5,"")
A23: drv:영업이익 | B23: ratio | C23: 영업이익률(OPM) | E23: =IFERROR(subQ!E9/subQ!E5,"") | F23: =IFERROR(subQ!F9/subQ!F5,"") | G23: =IFERROR(subQ!G9/subQ!G5,"") | H23: =IFERROR(subQ!H9/subQ!H5,"") | I23: =IFERROR(subQ!I9/subQ!I5,"") | J23: =IFERROR(subQ!J9/subQ!J5,"") | K23: =IFERROR(subQ!K9/subQ!K5,"") | L23: =IFERROR(subQ!L9/subQ!L5,"") | ... AB23: =IFERROR(subQ!AB9/subQ!AB5,"") | AC23: 0.06802223 | AD23: 0.068022384 | AE23: =IFERROR(subQ!AE9/subQ!AE5,"") | AF23: 0.068022078 | AG23: 0.068022247 | AH23: 0.068021914 | AI23: 0.06802225 | AJ23: =IFERROR(subQ!AJ9/subQ!AJ5,"") | AK23: 0.068022251 | AL23: 0.068022207 | AM23: 0.068022063 | AN23: 0.068022183 | AO23: =IFERROR(subQ!AO9/subQ!AO5,"")
A24: drv:외환손익 | B24: abs | C24: 외환손익 (가정, 억원) | E24: =subQ!E13 | F24: =subQ!F13 | G24: =subQ!G13 | H24: =subQ!H13 | I24: =subQ!I13 | J24: =subQ!J13 | K24: =subQ!K13 | L24: =subQ!L13 | ... AB24: =subQ!AB13 | AC24: 0 | AD24: 0 | AE24: =subQ!AE13 | AF24: 0 | AG24: 0 | AH24: 0 | AI24: 0 | AJ24: =subQ!AJ13 | AK24: 0 | AL24: 0 | AM24: 0 | AN24: 0 | AO24: =subQ!AO13
A25: drv:파생상품손익 | B25: abs | C25: 파생상품손익 (가정, 억원) | E25: =subQ!E14 | F25: =subQ!F14 | G25: =subQ!G14 | H25: =subQ!H14 | I25: =subQ!I14 | J25: =subQ!J14 | K25: =subQ!K14 | L25: =subQ!L14 | ... AB25: =subQ!AB14 | AC25: 0 | AD25: 0 | AE25: =subQ!AE14 | AF25: 0 | AG25: 0 | AH25: 0 | AI25: 0 | AJ25: =subQ!AJ14 | AK25: 0 | AL25: 0 | AM25: 0 | AN25: 0 | AO25: =subQ!AO14
A26: drv:기타금융손익 | B26: abs | C26: 기타금융손익 (가정, 억원) | E26: =subQ!E15 | F26: =subQ!F15 | G26: =subQ!G15 | H26: =subQ!H15 | I26: =subQ!I15 | J26: =subQ!J15 | K26: =subQ!K15 | L26: =subQ!L15 | ... AB26: =subQ!AB15 | AC26: 0 | AD26: 0 | AE26: =subQ!AE15 | AF26: 0 | AG26: 0 | AH26: 0 | AI26: 0 | AJ26: =subQ!AJ15 | AK26: 0 | AL26: 0 | AM26: 0 | AN26: 0 | AO26: =subQ!AO15
A27: drv:기타영업외손익 | B27: abs | C27: 기타영업외손익 (가정, 억원) | E27: =subQ!E16 | F27: =subQ!F16 | G27: =subQ!G16 | H27: =subQ!H16 | I27: =subQ!I16 | J27: =subQ!J16 | K27: =subQ!K16 | L27: =subQ!L16 | ... AB27: =subQ!AB16 | AC27: 0 | AD27: 0 | AE27: =subQ!AE16 | AF27: 0 | AG27: 0 | AH27: 0 | AI27: 0 | AJ27: =subQ!AJ16 | AK27: 0 | AL27: 0 | AM27: 0 | AN27: 0 | AO27: =subQ!AO16
A28: drv:지분법손익 | B28: abs | C28: 지분법손익 (가정, 억원) | E28: =subQ!E17 | F28: =subQ!F17 | G28: =subQ!G17 | H28: =subQ!H17 | I28: =subQ!I17 | J28: =subQ!J17 | K28: =subQ!K17 | L28: =subQ!L17 | ... AB28: =subQ!AB17 | AC28: 26.09 | AD28: 26.09 | AE28: =subQ!AE17 | AF28: 26.09 | AG28: 26.09 | AH28: 26.09 | AI28: 26.09 | AJ28: =subQ!AJ17 | AK28: 26.09 | AL28: 26.09 | AM28: 26.09 | AN28: 26.09 | AO28: =subQ!AO17
A29: drv:법인세비용 | B29: tax | C29: 법인세율(/세전) — 법인세 = MAX(세전,0) × 세율 | E29: =IFERROR(subQ!E19/subQ!E18,"") | F29: =IFERROR(subQ!F19/subQ!F18,"") | G29: =IFERROR(subQ!G19/subQ!G18,"") | H29: =IFERROR(subQ!H19/subQ!H18,"") | I29: =IFERROR(subQ!I19/subQ!I18,"") | J29: =IFERROR(subQ!J19/subQ!J18,"") | K29: =IFERROR(subQ!K19/subQ!K18,"") | L29: =IFERROR(subQ!L19/subQ!L18,"") | ... AB29: =IFERROR(subQ!AB19/subQ!AB18,"") | AC29: =$D$53 | AD29: =$D$53 | AE29: =IFERROR(subQ!AE19/subQ!AE18,"") | AF29: =$D$53 | AG29: =$D$53 | AH29: =$D$53 | AI29: =$D$53 | AJ29: =IFERROR(subQ!AJ19/subQ!AJ18,"") | AK29: =$D$53 | AL29: =$D$53 | AM29: =$D$53 | AN29: =$D$53 | AO29: =IFERROR(subQ!AO19/subQ!AO18,"")
A30: drv:지배주주순이익 | B30: ratio | C30: 지배주주 비중(/당기순이익) | E30: =IFERROR(subQ!E21/subQ!E20,"") | F30: =IFERROR(subQ!F21/subQ!F20,"") | G30: =IFERROR(subQ!G21/subQ!G20,"") | H30: =IFERROR(subQ!H21/subQ!H20,"") | I30: =IFERROR(subQ!I21/subQ!I20,"") | J30: =IFERROR(subQ!J21/subQ!J20,"") | K30: =IFERROR(subQ!K21/subQ!K20,"") | L30: =IFERROR(subQ!L21/subQ!L20,"") | ... AB30: =IFERROR(subQ!AB21/subQ!AB20,"") | AC30: =$D$55 | AD30: =$D$55 | AE30: =IFERROR(subQ!AE21/subQ!AE20,"") | AF30: =$D$55 | AG30: =$D$55 | AH30: =$D$55 | AI30: =$D$55 | AJ30: =IFERROR(subQ!AJ21/subQ!AJ20,"") | AK30: =$D$55 | AL30: =$D$55 | AM30: =$D$55 | AN30: =$D$55 | AO30: =IFERROR(subQ!AO21/subQ!AO20,"")
A31: drv:중단사업이익 | B31: abs | C31: 중단사업이익 (가정, 억원) | E31: =subQ!E22 | F31: =subQ!F22 | G31: =subQ!G22 | H31: =subQ!H22 | I31: =subQ!I22 | J31: =subQ!J22 | K31: =subQ!K22 | L31: =subQ!L22 | ... AB31: =subQ!AB22 | AE31: =subQ!AE22 | AJ31: =subQ!AJ22 | AO31: =subQ!AO22
A32: drv:감가상각비 | B32: abs | C32: 감가상각비 (가정, 억원) | E32: =subQ!E23 | F32: =subQ!F23 | G32: =subQ!G23 | H32: =subQ!H23 | I32: =subQ!I23 | J32: =subQ!J23 | K32: =subQ!K23 | L32: =subQ!L23 | ... AB32: =subQ!AB23 | AC32: 927.98 | AD32: 927.98 | AE32: =subQ!AE23 | AF32: 927.98 | AG32: 927.98 | AH32: 927.98 | AI32: 927.98 | AJ32: =subQ!AJ23 | AK32: 927.98 | AL32: 927.98 | AM32: 927.98 | AN32: 927.98 | AO32: =subQ!AO23
A33: drv:부채총계 | B33: qoq | C33: 부채총계 QoQ | G33: =IFERROR(subQ!G26/subQ!E26-1,"") | H33: =IFERROR(subQ!H26/subQ!G26-1,"") | I33: =IFERROR(subQ!I26/subQ!H26-1,"") | J33: =IFERROR(subQ!J26/subQ!I26-1,"") | L33: =IFERROR(subQ!L26/subQ!J26-1,"") | M33: =IFERROR(subQ!M26/subQ!L26-1,"") | N33: =IFERROR(subQ!N26/subQ!M26-1,"") | O33: =IFERROR(subQ!O26/subQ!N26-1,"") | Q33: =IFERROR(subQ!Q26/subQ!O26-1,"") | R33: =IFERROR(subQ!R26/subQ!Q26-1,"") | S33: =IFERROR(subQ!S26/subQ!R26-1,"") | T33: =IFERROR(subQ!T26/subQ!S26-1,"") | V33: =IFERROR(subQ!V26/subQ!T26-1,"") | W33: =IFERROR(subQ!W26/subQ!V26-1,"") | X33: =IFERROR(subQ!X26/subQ!W26-1,"") | Y33: =IFERROR(subQ!Y26/subQ!X26-1,"") | AA33: =IFERROR(subQ!AA26/subQ!Y26-1,"") | AB33: =IFERROR(subQ!AB26/subQ!AA26-1,"") | AC33: 2.4e-08 | AD33: 0 | AF33: 0 | AG33: 0 | AH33: 0 | AI33: 0 | AK33: 0 | AL33: 0 | AM33: 0 | AN33: 0
A34: drv:자본총계 | B34: roll | C34: 자본총계 기타변동(배당 등, 억원) | G34: =IFERROR(subQ!E27+subQ!G20-subQ!G27,"") | H34: =IFERROR(subQ!G27+subQ!H20-subQ!H27,"") | I34: =IFERROR(subQ!H27+subQ!I20-subQ!I27,"") | J34: =IFERROR(subQ!I27+subQ!J20-subQ!J27,"") | L34: =IFERROR(subQ!J27+subQ!L20-subQ!L27,"") | M34: =IFERROR(subQ!L27+subQ!M20-subQ!M27,"") | N34: =IFERROR(subQ!M27+subQ!N20-subQ!N27,"") | O34: =IFERROR(subQ!N27+subQ!O20-subQ!O27,"") | Q34: =IFERROR(subQ!O27+subQ!Q20-subQ!Q27,"") | R34: =IFERROR(subQ!Q27+subQ!R20-subQ!R27,"") | S34: =IFERROR(subQ!R27+subQ!S20-subQ!S27,"") | T34: =IFERROR(subQ!S27+subQ!T20-subQ!T27,"") | V34: =IFERROR(subQ!T27+subQ!V20-subQ!V27,"") | W34: =IFERROR(subQ!V27+subQ!W20-subQ!W27,"") | X34: =IFERROR(subQ!W27+subQ!X20-subQ!X27,"") | Y34: =IFERROR(subQ!X27+subQ!Y20-subQ!Y27,"") | AA34: =IFERROR(subQ!Y27+subQ!AA20-subQ!AA27,"") | AB34: =IFERROR(subQ!AA27+subQ!AB20-subQ!AB27,"") | AC34: -0.005080478 | AD34: 0.003856558 | AF34: -0.004643765 | AG34: 1103.1314 | AH34: -0.009517324 | AI34: 0.00171645 | AK34: 0.0011091 | AL34: 1103.1275 | AM34: -0.008428075 | AN34: 0.000101345
A35: drv:지배주주지분 | B35: roll | C35: 지배주주지분 기타변동(배당 등, 억원) | G35: =IFERROR(subQ!E28+subQ!G21-subQ!G28,"") | H35: =IFERROR(subQ!G28+subQ!H21-subQ!H28,"") | I35: =IFERROR(subQ!H28+subQ!I21-subQ!I28,"") | J35: =IFERROR(subQ!I28+subQ!J21-subQ!J28,"") | L35: =IFERROR(subQ!J28+subQ!L21-subQ!L28,"") | M35: =IFERROR(subQ!L28+subQ!M21-subQ!M28,"") | N35: =IFERROR(subQ!M28+subQ!N21-subQ!N28,"") | O35: =IFERROR(subQ!N28+subQ!O21-subQ!O28,"") | Q35: =IFERROR(subQ!O28+subQ!Q21-subQ!Q28,"") | R35: =IFERROR(subQ!Q28+subQ!R21-subQ!R28,"") | S35: =IFERROR(subQ!R28+subQ!S21-subQ!S28,"") | T35: =IFERROR(subQ!S28+subQ!T21-subQ!T28,"") | V35: =IFERROR(subQ!T28+subQ!V21-subQ!V28,"") | W35: =IFERROR(subQ!V28+subQ!W21-subQ!W28,"") | X35: =IFERROR(subQ!W28+subQ!X21-subQ!X28,"") | Y35: =IFERROR(subQ!X28+subQ!Y21-subQ!Y28,"") | AA35: =IFERROR(subQ!Y28+subQ!AA21-subQ!AA28,"") | AB35: =IFERROR(subQ!AA28+subQ!AB21-subQ!AB28,"") | AC35: -0.005080478 | AD35: 0.003856558 | AF35: -0.004643765 | AG35: 1103.1314 | AH35: -0.009517324 | AI35: 0.00171645 | AK35: 0.0011091 | AL35: 1103.1275 | AM35: -0.008428075 | AN35: 0.000101345
A36: drv:총차입금 | B36: qoq | C36: 총차입금 QoQ | G36: =IFERROR(subQ!G29/subQ!E29-1,"") | H36: =IFERROR(subQ!H29/subQ!G29-1,"") | I36: =IFERROR(subQ!I29/subQ!H29-1,"") | J36: =IFERROR(subQ!J29/subQ!I29-1,"") | L36: =IFERROR(subQ!L29/subQ!J29-1,"") | M36: =IFERROR(subQ!M29/subQ!L29-1,"") | N36: =IFERROR(subQ!N29/subQ!M29-1,"") | O36: =IFERROR(subQ!O29/subQ!N29-1,"") | Q36: =IFERROR(subQ!Q29/subQ!O29-1,"") | R36: =IFERROR(subQ!R29/subQ!Q29-1,"") | S36: =IFERROR(subQ!S29/subQ!R29-1,"") | T36: =IFERROR(subQ!T29/subQ!S29-1,"") | V36: =IFERROR(subQ!V29/subQ!T29-1,"") | W36: =IFERROR(subQ!W29/subQ!V29-1,"") | X36: =IFERROR(subQ!X29/subQ!W29-1,"") | Y36: =IFERROR(subQ!Y29/subQ!X29-1,"") | AA36: =IFERROR(subQ!AA29/subQ!Y29-1,"") | AB36: =IFERROR(subQ!AB29/subQ!AA29-1,"") | AC36: -2.8e-08 | AD36: 0 | AF36: 0 | AG36: 0 | AH36: 0 | AI36: 0 | AK36: 0 | AL36: 0 | AM36: 0 | AN36: 0
A37: drv:순차입금 | B37: qoq | C37: 순차입금 QoQ | G37: =IFERROR(subQ!G30/subQ!E30-1,"") | H37: =IFERROR(subQ!H30/subQ!G30-1,"") | I37: =IFERROR(subQ!I30/subQ!H30-1,"") | J37: =IFERROR(subQ!J30/subQ!I30-1,"") | L37: =IFERROR(subQ!L30/subQ!J30-1,"") | M37: =IFERROR(subQ!M30/subQ!L30-1,"") | N37: =IFERROR(subQ!N30/subQ!M30-1,"") | O37: =IFERROR(subQ!O30/subQ!N30-1,"") | Q37: =IFERROR(subQ!Q30/subQ!O30-1,"") | R37: =IFERROR(subQ!R30/subQ!Q30-1,"") | S37: =IFERROR(subQ!S30/subQ!R30-1,"") | T37: =IFERROR(subQ!T30/subQ!S30-1,"") | V37: =IFERROR(subQ!V30/subQ!T30-1,"") | W37: =IFERROR(subQ!W30/subQ!V30-1,"") | X37: =IFERROR(subQ!X30/subQ!W30-1,"") | Y37: =IFERROR(subQ!Y30/subQ!X30-1,"") | AA37: =IFERROR(subQ!AA30/subQ!Y30-1,"") | AB37: =IFERROR(subQ!AB30/subQ!AA30-1,"") | AC37: -0.008628067 | AD37: -0.007833687 | AF37: -0.008833684 | AG37: 0.016519056 | AH37: -0.008739267 | AI37: -0.007937616 | AK37: -0.008948733 | AL37: 0.016637568 | AM37: -0.008840655 | AN37: -0.008032313
A38: drv:이자발생자산 | B38: qoq | C38: 이자발생자산 QoQ | G38: =IFERROR(subQ!G31/subQ!E31-1,"") | H38: =IFERROR(subQ!H31/subQ!G31-1,"") | I38: =IFERROR(subQ!I31/subQ!H31-1,"") | J38: =IFERROR(subQ!J31/subQ!I31-1,"") | L38: =IFERROR(subQ!L31/subQ!J31-1,"") | M38: =IFERROR(subQ!M31/subQ!L31-1,"") | N38: =IFERROR(subQ!N31/subQ!M31-1,"") | O38: =IFERROR(subQ!O31/subQ!N31-1,"") | Q38: =IFERROR(subQ!Q31/subQ!O31-1,"") | R38: =IFERROR(subQ!R31/subQ!Q31-1,"") | S38: =IFERROR(subQ!S31/subQ!R31-1,"") | T38: =IFERROR(subQ!T31/subQ!S31-1,"") | V38: =IFERROR(subQ!V31/subQ!T31-1,"") | W38: =IFERROR(subQ!W31/subQ!V31-1,"") | X38: =IFERROR(subQ!X31/subQ!W31-1,"") | Y38: =IFERROR(subQ!Y31/subQ!X31-1,"") | AA38: =IFERROR(subQ!AA31/subQ!Y31-1,"") | AB38: =IFERROR(subQ!AB31/subQ!AA31-1,"") | AC38: 0.003364731 | AD38: 0.003018382 | AF38: 0.003366768 | AG38: -0.006219407 | AH38: 0.003365566 | AI38: 0.00302005 | AK38: 0.003367653 | AL38: -0.006184141 | AM38: 0.003361509 | AN38: 0.003017008
A39: drv:현금및현금성자산 | B39: qoq | C39: 현금및현금성자산 QoQ | G39: =IFERROR(subQ!G32/subQ!E32-1,"") | H39: =IFERROR(subQ!H32/subQ!G32-1,"") | I39: =IFERROR(subQ!I32/subQ!H32-1,"") | J39: =IFERROR(subQ!J32/subQ!I32-1,"") | L39: =IFERROR(subQ!L32/subQ!J32-1,"") | M39: =IFERROR(subQ!M32/subQ!L32-1,"") | N39: =IFERROR(subQ!N32/subQ!M32-1,"") | O39: =IFERROR(subQ!O32/subQ!N32-1,"") | Q39: =IFERROR(subQ!Q32/subQ!O32-1,"") | R39: =IFERROR(subQ!R32/subQ!Q32-1,"") | S39: =IFERROR(subQ!S32/subQ!R32-1,"") | T39: =IFERROR(subQ!T32/subQ!S32-1,"") | V39: =IFERROR(subQ!V32/subQ!T32-1,"") | W39: =IFERROR(subQ!W32/subQ!V32-1,"") | X39: =IFERROR(subQ!X32/subQ!W32-1,"") | Y39: =IFERROR(subQ!Y32/subQ!X32-1,"") | AA39: =IFERROR(subQ!AA32/subQ!Y32-1,"") | AB39: =IFERROR(subQ!AB32/subQ!AA32-1,"")
A40: drv:CAPEX | B40: yoy | C40: CAPEX YoY | J40: =IFERROR(subQ!J33/subQ!E33-1,"") | L40: =IFERROR(subQ!L33/subQ!G33-1,"") | M40: =IFERROR(subQ!M33/subQ!H33-1,"") | N40: =IFERROR(subQ!N33/subQ!I33-1,"") | O40: =IFERROR(subQ!O33/subQ!J33-1,"") | Q40: =IFERROR(subQ!Q33/subQ!L33-1,"") | R40: =IFERROR(subQ!R33/subQ!M33-1,"") | S40: =IFERROR(subQ!S33/subQ!N33-1,"") | T40: =IFERROR(subQ!T33/subQ!O33-1,"") | V40: =IFERROR(subQ!V33/subQ!Q33-1,"") | W40: =IFERROR(subQ!W33/subQ!R33-1,"") | X40: =IFERROR(subQ!X33/subQ!S33-1,"") | Y40: =IFERROR(subQ!Y33/subQ!T33-1,"") | AA40: =IFERROR(subQ!AA33/subQ!V33-1,"") | AB40: =IFERROR(subQ!AB33/subQ!W33-1,"") | AC40: 0.1855448 | AD40: -0.21637063 | AF40: -0.055900001 | AG40: 0.062937285 | AH40: 0 | AI40: 0 | AK40: 0 | AL40: 0 | AM40: 0 | AN40: 0
A41: drv:영업활동현금흐름 | B41: yoy | C41: 영업활동현금흐름 YoY | J41: =IFERROR(subQ!J34/subQ!E34-1,"") | L41: =IFERROR(subQ!L34/subQ!G34-1,"") | M41: =IFERROR(subQ!M34/subQ!H34-1,"") | N41: =IFERROR(subQ!N34/subQ!I34-1,"") | O41: =IFERROR(subQ!O34/subQ!J34-1,"") | Q41: =IFERROR(subQ!Q34/subQ!L34-1,"") | R41: =IFERROR(subQ!R34/subQ!M34-1,"") | S41: =IFERROR(subQ!S34/subQ!N34-1,"") | T41: =IFERROR(subQ!T34/subQ!O34-1,"") | V41: =IFERROR(subQ!V34/subQ!Q34-1,"") | W41: =IFERROR(subQ!W34/subQ!R34-1,"") | X41: =IFERROR(subQ!X34/subQ!S34-1,"") | Y41: =IFERROR(subQ!Y34/subQ!T34-1,"") | AA41: =IFERROR(subQ!AA34/subQ!V34-1,"") | AB41: =IFERROR(subQ!AB34/subQ!W34-1,"")
...

Sheet BS연결
B1: (백만원) | C1: 이름: BS연결H | E1: 4Q21 | F1: 2021 | G1: 1Q22 | H1: 2Q22 | I1: 3Q22 | J1: 4Q22 | K1: 2022 | L1: 1Q23 | M1: 2Q23 | N1: 3Q23 | O1: 4Q23 | P1: 2023 | Q1: 1Q24 | R1: 2Q24 | S1: 3Q24 | T1: 4Q24 | U1: 2024 | V1: 1Q25 | W1: 2Q25 | X1: 3Q25 | Y1: 4Q25 | Z1: 2025 | AA1: 1Q26 | AB1: 2Q26 | AC1: 3Q26 | AD1: 4Q26 | AE1: 2026 | AF1: 1Q27 | AG1: 2Q27 | AH1: 3Q27 | AI1: 4Q27 | AJ1: 2027 | AK1: 1Q28 | AL1: 2Q28 | AM1: 3Q28 | AN1: 4Q28 | AO1: 2028
B2: 연결 | D2: fin json(kship_fin.py)
B3: 케이씨씨(연) | C3: UPDATE: 26-10-12 | E3: 1 | F3: 2 | G3: 3 | H3: 4 | I3: 5 | J3: 6 | K3: 7 | L3: 8 | M3: 9 | N3: 10 | O3: 11 | P3: 12 | Q3: 13 | R3: 14 | S3: 15 | T3: 16 | U3: 17 | V3: 18 | W3: 19 | X3: 20 | Y3: 21 | Z3: 22 | AA3: 23 | AB3: 24 | AC3: 25 | AD3: 26 | AE3: 27 | AF3: 28 | AG3: 29 | AH3: 30 | AI3: 31 | AJ3: 32 | AK3: 33 | AL3: 34 | AM3: 35 | AN3: 36 | AO3: 37
B4: Account Code | C4: AccountNAME | E4: 2021.12 | F4: 2021.12A | G4: 2022.03 | H4: 2022.06 | I4: 2022.09 | J4: 2022.12 | K4: 2022.12A | L4: 2023.03 | M4: 2023.06 | N4: 2023.09 | O4: 2023.12 | P4: 2023.12A | Q4: 2024.03 | R4: 2024.06 | S4: 2024.09 | T4: 2024.12 | U4: 2024.12A | V4: 2025.03 | W4: 2025.06 | X4: 2025.09 | Y4: 2025.12 | Z4: 2025.12A | AA4: 2026.03 | AB4: 2026.06 | AC4: 2026.09 | AD4: 2026.12 | AE4: 2026.12A | AF4: 2027.03 | AG4: 2027.06 | AH4: 2027.09 | AI4: 2027.12 | AJ4: 2027.12A | AK4: 2028.03 | AL4: 2028.06 | AM4: 2028.09 | AN4: 2028.12 | AO4: 2028.12A
A5: 1 | C5: 유동자산 | E5: 3668126.4 | F5: 3668126.4 | G5: 4388794.5 | H5: 4604773.5 | I5: 4303363.8 | J5: 4029782.8 | K5: 4029782.8 | L5: 4221561.5 | M5: 4296128.5 | N5: 4348879 | O5: 4178193 | P5: 4178193 | Q5: 4390977.8 | R5: 4398762 | S5: 4372544.2 | T5: 3994488.4 | U5: 3994488.4 | V5: 4495685 | W5: 4012252.1 | X5: 4018869.3 | Y5: 3982829.9 | Z5: 3982829.9 | AA5: 4548827.1 | AB5: 4351935.5
A6: 1 | C6: 현금및현금성자산 | E6: 541200.62 | F6: 541200.62 | G6: 328395.52 | H6: 394154.02 | I6: 467291.37 | J6: 776747.67 | K6: 776747.67 | L6: 830350.62 | M6: 973610.32 | N6: 1029439.4 | O6: 1045142.1 | P6: 1045142.1 | Q6: 1083647.9 | R6: 1072629.7 | S6: 1040909.6 | T6: 501329.76 | U6: 501329.76 | V6: 906545.13 | W6: 781684.86 | X6: 915207.59 | Y6: 1193612.4 | Z6: 1193612.4 | AA6: 1469494.9 | AB6: 1177380.3
A7: 1 | C7: 단기금융상품 | E7: 604744.65 | F7: 604744.65 | G7: 1125967 | H7: 1207028.9 | I7: 722731.82 | J7: 408423.84 | K7: 408423.84 | L7: 488875.35 | M7: 540229.59 | N7: 514967.23 | O7: 509868.88 | P7: 509868.88 | Q7: 548928.53 | R7: 436662.92 | S7: 486318.59 | T7: 510145.13 | U7: 510145.13 | V7: 531205.28 | W7: 374098.57 | X7: 216899.41 | Y7: 36838.55 | Z7: 36838.55 | AA7: 60084.28 | AB7: 25343.85
A8: 1 | C8: 단기금융자산 | E8: 604744.65 | F8: 604744.65 | G8: 1125967 | H8: 1207028.9 | I8: 722731.82 | J8: 408423.84 | K8: 408423.84 | L8: 488875.35 | M8: 540229.59 | N8: 514967.23 | O8: 509868.88 | P8: 509868.88 | Q8: 548928.53 | R8: 436662.92 | S8: 486318.59 | T8: 510145.13 | U8: 510145.13 | V8: 531205.28 | W8: 374098.57 | X8: 216899.41 | Y8: 36838.55 | Z8: 36838.55 | AA8: 60084.28 | AB8: 25343.85
A9: 1 | C9: 매출채권및기타채권 | E9: 1128138.5 | F9: 1128138.5 | G9: 1365742.9 | H9: 1337604.6 | I9: 1349237.7 | J9: 1201308.8 | K9: 1201308.8 | L9: 1251304.2 | M9: 1187458.7 | N9: 1189899.4 | O9: 1129052.8 | P9: 1129052.8 | Q9: 1262422.2 | R9: 1351795.6 | S9: 1287510.7 | T9: 1308739.7 | U9: 1308739.7 | V9: 1395653.1 | W9: 1291995.4 | X9: 1316162.4 | Y9: 1151524.4 | Z9: 1151524.4 | AA9: 1387502 | AB9: 1426533.1
A10: 1 | C10: 선급금 | E10: 21880.21 | F10: 21880.21 | G10: 20911.89 | H10: 26966.86 | I10: 24710.22 | J10: 16748.69 | K10: 16748.69 | L10: 17795.19 | M10: 20965.92 | N10: 16992.43 | O10: 16696.26 | P10: 16696.26 | Q10: 18973.96 | R10: 19135.57 | S10: 15662.25 | T10: 16911.15 | U10: 16911.15 | V10: 15380.8 | W10: 14394.72 | X10: 15964.33 | Y10: 20684.08 | Z10: 20684.08 | AA10: 11462.28 | AB10: 23789.06
A11: 1 | C11: 선급금등 | E11: 21880.21 | F11: 21880.21 | G11: 20911.89 | H11: 26966.86 | I11: 24710.22 | J11: 16748.69 | K11: 16748.69 | L11: 17795.19 | M11: 20965.92 | N11: 16992.43 | O11: 16696.26 | P11: 16696.26 | Q11: 18973.96 | R11: 19135.57 | S11: 15662.25 | T11: 16911.15 | U11: 16911.15 | V11: 15380.8 | W11: 14394.72 | X11: 15964.33 | Y11: 20684.08 | Z11: 20684.08 | AA11: 11462.28 | AB11: 23789.06
A12: 1 | C12: 기타유동자산 | E12: 61566.05 | F12: 61566.05 | G12: 96209.91 | H12: 68073.73 | I12: 74488.96 | J12: 60506.58 | K12: 60506.58 | L12: 59181.06 | M12: 55254.5 | N12: 57264.98 | O12: 61945.71 | P12: 61945.71 | Q12: 54900.67 | R12: 50923.01 | S12: 48941.01 | T12: 67473.09 | U12: 67473.09 | V12: 55718.2 | W12: 47145.6 | X12: 58209.21 | Y12: 67889.43 | Z12: 67889.43 | AA12: 46702.25 | AB12: 62995.36
A13: 1 | C13: 기타유동금융자산 | E13: 2441.16 | F13: 2441.16 | G13: 3064.61 | H13: 3882.13 | I13: 2942.33 | J13: 3839.8 | K13: 3839.8 | L13: 3404.55 | M13: 5060.48 | N13: 60182.83 | O13: 32224.01 | P13: 32224.01 | Q13: 21085.95 | R13: 18838.42 | S13: 16384.87 | T13: 21694.68 | U13: 21694.68 | V13: 3308.78 | W13: 2839.46 | X13: 1445.52 | Y13: 96.7 | Z13: 96.7 | AA13: 95.68 | AB13: 37.51
A14: 1 | C14: 당기법인세자산(선급법인세) | E14: 1131.35 | F14: 1131.35 | G14: 1694 | H14: 1435.97 | I14: 2525.43 | J14: 2855.83 | K14: 2855.83 | L14: 2618.99 | M14: 1256.31 | N14: 858.08 | O14: 959.7 | P14: 959.7 | Q14: 1147.54 | R14: 1253.98 | S14: 3237.56 | T14: 1870.04 | U14: 1870.04 | V14: 1931.28 | W14: 1468.67 | X14: 2716.73 | Y14: 2882.51 | Z14: 2882.51 | AA14: 3208.47 | AB14: 1728.72
A15: 1 | C15: 재고자산 | E15: 1306422 | F15: 1306422 | G15: 1445238.6 | H15: 1570112 | I15: 1661664.2 | J15: 1576100.2 | K15: 1576100.2 | L15: 1585826.8 | M15: 1533258.7 | N15: 1473785 | O15: 1398999.7 | P15: 1398999.7 | Q15: 1418845.1 | R15: 1466658.4 | S15: 1489241.9 | T15: 1583236 | U15: 1583236 | V15: 1601323.2 | W15: 1513019.5 | X15: 1508228.4 | Y15: 1529985.8 | Z15: 1529985.8 | AA15: 1581739.6 | AB15: 1657916.7
A16: 1 | C16: 비유동자산 | E16: 9210736.8 | F16: 9210736.8 | G16: 9030509.2 | H16: 9328258.7 | I16: 9284742.8 | J16: 9088703.5 | K16: 9088703.5 | L16: 9083349.5 | M16: 9108641.7 | N16: 9061670.2 | O16: 9175278.1 | P16: 9175278.1 | Q16: 9712507.6 | R16: 9245830.2 | S16: 9130814.9 | T16: 9114061.7 | U16: 9114061.7 | V16: 10570486 | W16: 11577430 | X16: 12193006 | Y16: 12820730 | Z16: 12820730 | AA16: 13074193 | AB16: 16770864
... A35: 1 | C35: 사채 | E35: 1168017.8 | F35: 1168017.8 | G35: 968354.81 | H35: 1117873.4 | I35: 1118099.2 | J35: 798493.51 | K35: 798493.51 | L35: 798672.52 | M35: 918134.68 | N35: 918321.73 | O35: 748637.26 | P35: 748637.26 | Q35: 1327305 | R35: 1057792.4 | S35: 1058013.4 | T35: 1307469.1 | U35: 1307469.1 | V35: 1561826.9 | W35: 1287383.7 | X35: 1287652.9 | Y35: 2097835.7 | Z35: 2097835.7 | AA35: 2167189.8 | AB35: 2151185.3
A36: 1 | C36: 기타비유동금융부채 | E36: 43512.69 | F36: 43512.69 | G36: 29627.88 | H36: 5566.21 | I36: 1607.17 | J36: 57445.32 | K36: 57445.32 | L36: 31577.61 | M36: 20696.72 | N36: 3749.29 | Y36: 11164.39 | Z36: 11164.39 | AA36: 7518.41 | AB36: 14633.96
A37: 1 | C37: 장기금융부채 | E37: 43512.69 | F37: 43512.69 | G37: 29627.88 | H37: 5566.21 | I37: 1607.17 | J37: 57445.32 | K37: 57445.32 | L37: 31577.61 | M37: 20696.72 | N37: 3749.29 | Y37: 11164.39 | Z37: 11164.39 | AA37: 7518.41 | AB37: 14633.96
A38: 1 | C38: 확정급여부채 | E38: 429025.14 | F38: 429025.14 | G38: 434418.07 | H38: 450907.6 | I38: 478463.69 | J38: 274253.73 | K38: 274253.73 | L38: 297962.49 | M38: 293544.05 | N38: 297047.35 | O38: 356537.68 | P38: 356537.68 | Q38: 372291.58 | R38: 372888.79 | S38: 369268.19 | T38: 366277.72 | U38: 366277.72 | V38: 371287.7 | W38: 367388.72 | X38: 383162.46 | Y38: 349309.9 | Z38: 349309.9 | AA38: 367217.75 | AB38: 373999.49
A39: 1 | C39: 장기충당부채 | E39: 16886.93 | F39: 16886.93 | G39: 17237.78 | H39: 17616.08 | I39: 19202.98 | J39: 14527.3 | K39: 14527.3 | L39: 15566.4 | M39: 26897.75 | N39: 20150.73 | O39: 21640.37 | P39: 21640.37 | Q39: 22140.19 | R39: 22358.91 | S39: 22724.52 | T39: 24331.4 | U39: 24331.4 | V39: 25673.97 | W39: 23374.57 | X39: 23857.48 | Y39: 24880.68 | Z39: 24880.68 | AA39: 26077.86 | AB39: 25560.83
A40: 1 | C40: 이연법인세부채 | E40: 587271.93 | F40: 587271.93 | G40: 554089.62 | H40: 595406.37 | I40: 499683.99 | J40: 448431.11 | K40: 448431.11 | L40: 487002.07 | M40: 504457.57 | N40: 507454.11 | O40: 497063.26 | P40: 497063.26 | Q40: 601509.36 | R40: 580081.85 | S40: 583884.87 | T40: 430851.84 | U40: 430851.84 | V40: 737437.77 | W40: 1081628.8 | X40: 1178925.3 | Y40: 1410256.4 | Z40: 1410256.4 | AA40: 1458153.1 | AB40: 2384318.6
A41: 1 | C41: 부채총계 | E41: 7502796.3 | F41: 7502796.3 | G41: 8061671.4 | H41: 8366463.3 | I41: 8164670.7 | J41: 7567347.8 | K41: 7567347.8 | L41: 7771258.7 | M41: 7879075.7 | N41: 7913369.2 | O41: 7905941.7 | P41: 7905941.7 | Q41: 8261675.1 | R41: 8535877.6 | S41: 8392005.6 | T41: 8069234.7 | U41: 8069234.7 | V41: 8805934.5 | W41: 8520441.4 | X41: 8761128.7 | Y41: 8979073.7 | Z41: 8979073.7 | AA41: 9523275.8 | AB41: 10106056
A42: 1 | C42: 지배주주지분 | E42: 5035301.2 | F42: 5035301.2 | G42: 4970965.3 | H42: 5160875.9 | I42: 4993943.9 | J42: 5117785.1 | K42: 5117785.1 | L42: 5119406.8 | M42: 5156838 | N42: 5179538 | O42: 5177363.2 | P42: 5177363.2 | Q42: 5605468.9 | R42: 5108714.6 | S42: 5111353.5 | T42: 5039315.4 | U42: 5039315.4 | V42: 6260236.2 | W42: 7069241 | X42: 7450746.4 | Y42: 7824485.7 | Z42: 7824485.7 | AA42: 8099744 | AB42: 11016744
A43: 1 | C43: 자본금 | E43: 48084.66 | F43: 48084.66 | G43: 48084.66 | H43: 48084.66 | I43: 48084.66 | J43: 48084.66 | K43: 48084.66 | L43: 48084.66 | M43: 48084.66 | N43: 48084.66 | O43: 48084.66 | P43: 48084.66 | Q43: 48084.66 | R43: 48084.66 | S43: 48084.66 | T43: 48084.66 | U43: 48084.66 | V43: 48084.66 | W43: 48084.66 | X43: 48084.66 | Y43: 48084.66 | Z43: 48084.66 | AA43: 48084.66 | AB43: 48084.66
A44: 1 | C44: 자본잉여금 | E44: 552912.6 | F44: 552912.6 | G44: 552912.6 | H44: 552912.6 | I44: 552912.6 | J44: 552912.6 | K44: 552912.6 | L44: 552912.6 | M44: 552912.6 | N44: 552912.6 | O44: 552912.6 | P44: 552912.6 | Q44: 552912.6 | R44: 349758.89 | S44: 349758.89 | T44: 349758.89 | U44: 349758.89 | V44: 349758.89 | W44: 349758.89 | X44: 349758.89 | Y44: 349758.89 | Z44: 349758.89 | AA44: 313103.99 | AB44: 313103.99
A45: 1 | C45: 기타자본 | E45: -204952.84 | F45: -204952.84 | G45: -286379.5 | H45: -304846.77 | I45: -304846.77 | J45: -304846.77 | K45: -304846.77 | L45: -304846.77 | M45: -304846.77 | N45: -304846.77 | O45: -304846.77 | P45: -304846.77 | Q45: -304846.77 | R45: -504350.31 | S45: -504350.31 | T45: -504350.31 | U45: -504350.31 | V45: -504350.31 | W45: -504350.31 | X45: -504350.31 | Y45: -504350.31 | Z45: -504350.31 | AA45: -504350.31 | AB45: -445944.44
A46: 1 | C46: 기타포괄이익누계액 | E46: -39155.72 | F46: -39155.72 | G46: 17601.15 | H46: 56623.62 | I46: 164890.87 | J46: 23231.82 | K46: 23231.82 | L46: 68771.61 | M46: 15208.9 | N46: -1701.23 | O46: -21227.45 | P46: -21227.45 | Q46: -12456.69 | R46: -73685.65 | S46: -21581.85 | T46: -20214.98 | U46: -20214.98 | V46: 995115.73 | W46: 910874.52 | X46: 971446.89 | Y46: 1004614.4 | Z46: 1004614.4 | AA46: 1165819.1 | AB46: 1243695.2
A47: 1 | C47: 이익잉여금 | E47: 4678412.5 | F47: 4678412.5 | G47: 4638746.4 | H47: 4808101.8 | I47: 4532902.5 | J47: 4798402.8 | K47: 4798402.8 | L47: 4754484.7 | M47: 4845478.7 | N47: 4885088.8 | O47: 4902440.2 | P47: 4902440.2 | Q47: 5321775.1 | R47: 5288907 | S47: 5239442.1 | T47: 5166037.2 | U47: 5166037.2 | V47: 5371627.2 | W47: 6264873.2 | X47: 6585806.3 | Y47: 6926378.1 | Z47: 6926378.1 | AA47: 7077086.6 | AB47: 9857804.6
A48: 1 | C48: 비지배주주지분 | E48: 340765.65 | F48: 340765.65 | G48: 386667 | H48: 405692.9 | I48: 429492.09 | J48: 433353.43 | K48: 433353.43 | L48: 414245.5 | M48: 368856.52 | N48: 317642.01 | O48: 270166.21 | P48: 270166.21 | Q48: 236341.47 | R48: 0 | S48: 0 | V48: 0
A49: 1 | C49: 자본총계 | E49: 5376066.9 | F49: 5376066.9 | G49: 5357632.3 | H49: 5566568.8 | I49: 5423436 | J49: 5551138.5 | K49: 5551138.5 | L49: 5533652.3 | M49: 5525694.6 | N49: 5497180 | O49: 5447529.4 | P49: 5447529.4 | Q49: 5841810.4 | R49: 5108714.6 | S49: 5111353.5 | T49: 5039315.4 | U49: 5039315.4 | V49: 6260236.2 | W49: 7069241 | X49: 7450746.4 | Y49: 7824485.7 | Z49: 7824485.7 | AA49: 8099744 | AB49: 11016744
A50: 1 | C50: 부채와자본총계 | E50: 12878863 | F50: 12878863 | G50: 13419304 | H50: 13933032 | I50: 13588107 | J50: 13118486 | K50: 13118486 | L50: 13304911 | M50: 13404770 | N50: 13410549 | O50: 13353471 | P50: 13353471 | Q50: 14103485 | R50: 13644592 | S50: 13503359 | T50: 13108550 | U50: 13108550 | V50: 15066171 | W50: 15589682 | X50: 16211875 | Y50: 16803559 | Z50: 16803559 | AA50: 17623020 | AB50: 21122800
A51: 1 | C51: 총차입금 | E51: 4588864.1 | F51: 4588864.1 | G51: 5066717.4 | H51: 5369417 | I51: 5176146.9 | J51: 4881670.2 | K51: 4881670.2 | L51: 5096574.5 | M51: 5280827.9 | N51: 5349823.7 | O51: 5150850.2 | P51: 5150850.2 | Q51: 5276565.5 | R51: 5592274.2 | S51: 5516006.9 | T51: 5186962.7 | U51: 5186962.7 | V51: 5642147.7 | W51: 5225879.1 | X51: 5059496.1 | Y51: 5010779.2 | Z51: 5010779.2 | AA51: 5437429.8 | AB51: 5265511.2
A52: 1 | C52: 순차입금 | E52: 3442918.8 | F52: 3442918.8 | G52: 3612354.9 | H52: 3768234.1 | I52: 3986123.7 | J52: 3696498.6 | K52: 3696498.6 | L52: 3777348.6 | M52: 3766988 | N52: 3805417 | O52: 3595839.2 | P52: 3595839.2 | Q52: 3643989.1 | R52: 4082981.6 | S52: 3988778.7 | T52: 4175487.8 | U52: 4175487.8 | V52: 4204397.2 | W52: 4070095.7 | X52: 3927389.1 | Y52: 3780328.2 | Z52: 3780328.2 | AA52: 3907850.6 | AB52: 4062787
A53: 1 | C53: 이자발생자산 | E53: 3821873.1 | F53: 3821873.1 | G53: 3897761.4 | H53: 4214292.1 | I53: 3439378.8 | J53: 3571612.5 | K53: 3571612.5 | L53: 3621406.2 | M53: 3887957.5 | N53: 3860407.7 | O53: 4278876.2 | P53: 4278876.2 | Q53: 4840020.8 | R53: 4557058.9 | S53: 4585312.2 | T53: 3778542.2 | U53: 3778542.2 | V53: 4173497.3 | W53: 5144842.3 | X53: 5662254.3 | Y53: 6689512.5 | Z53: 6689512.5 | AA53: 7068994.3 | AB53: 10418227
A54: 1 | C54: 기타유동금융부채 | O54: 164369.97 | P54: 164369.97 | Q54: 168939.66 | R54: 0 | S54: 0 | X54: 299131.33 | Y54: 275328.61 | Z54: 275328.61 | AA54: 168371.8 | AB54: 136569.19
A55: 1 | C55: 단기금융부채 | O55: 164369.97 | P55: 164369.97 | Q55: 168939.66 | R55: 0 | S55: 0 | X55: 299131.33 | Y55: 275328.61 | Z55: 275328.61 | AA55: 168371.8 | AB55: 136569.19
A56: 1 | C56: 매출액(수익) | E56: 1509740 | G56: 1637578.5 | H56: 1755882.4 | I56: 1740125.2 | J56: 1641207.6 | K56: 6774793.7 | L56: 1564942.8 | M56: 1588344.8 | N56: 1552724.5 | O56: 1582430.5 | P56: 6288442.6 | Q56: 1588371.7 | R56: 1778727.7 | S56: 1634207.7 | T56: 1657455.3 | U56: 6658762.4 | V56: 1599305.3 | W56: 1705264 | X56: 1622832.5 | Y56: 1556417.7 | Z56: 6483819.5 | AA56: 1626399.6 | AB56: 1806019.1
A57: 1 | C57: 매출원가 | E57: 1178077.7 | G57: 1253044.6 | H57: 1341496.8 | I57: 1382013.1 | J57: 1313330.4 | K57: 5289884.9 | L57: 1251543.3 | M57: 1241872.2 | N57: 1223040.4 | O57: 1243487 | P57: 4959942.8 | Q57: 1228576.5 | R57: 1348199.2 | S57: 1195391.8 | T57: 1255874 | U57: 5028041.5 | V57: 1204395.9 | W57: 1267996.2 | X57: 1206254.7 | Y57: 1167703.1 | Z57: 4846349.8 | AA57: 1224311 | AB57: 1348082.2
A58: 1 | C58: 매출총이익 | E58: 331662.29 | G58: 384533.86 | H58: 414385.65 | I58: 358112.1 | J58: 327877.15 | K58: 1484908.8 | L58: 313399.44 | M58: 346472.66 | N58: 329684.19 | O58: 338943.49 | P58: 1328499.8 | Q58: 359795.25 | R58: 430528.47 | S58: 438815.93 | T58: 401581.32 | U58: 1630721 | V58: 394909.4 | W58: 437267.75 | X58: 416577.85 | Y58: 388714.63 | Z58: 1637469.6 | AA58: 402088.56 | AB58: 457936.95
...

Sheet BS별도
B1: (백만원) | C1: 이름: BS별도H | E1: 4Q21 | F1: 2021 | G1: 1Q22 | H1: 2Q22 | I1: 3Q22 | J1: 4Q22 | K1: 2022 | L1: 1Q23 | M1: 2Q23 | N1: 3Q23 | O1: 4Q23 | P1: 2023 | Q1: 1Q24 | R1: 2Q24 | S1: 3Q24 | T1: 4Q24 | U1: 2024 | V1: 1Q25 | W1: 2Q25 | X1: 3Q25 | Y1: 4Q25 | Z1: 2025 | AA1: 1Q26 | AB1: 2Q26 | AC1: 3Q26 | AD1: 4Q26 | AE1: 2026 | AF1: 1Q27 | AG1: 2Q27 | AH1: 3Q27 | AI1: 4Q27 | AJ1: 2027 | AK1: 1Q28 | AL1: 2Q28 | AM1: 3Q28 | AN1: 4Q28 | AO1: 2028
B2: 별도 | D2: fin json(kship_fin.py)
B3: 케이씨씨(별) | C3: UPDATE: 26-10-12 | E3: 1 | F3: 2 | G3: 3 | H3: 4 | I3: 5 | J3: 6 | K3: 7 | L3: 8 | M3: 9 | N3: 10 | O3: 11 | P3: 12 | Q3: 13 | R3: 14 | S3: 15 | T3: 16 | U3: 17 | V3: 18 | W3: 19 | X3: 20 | Y3: 21 | Z3: 22 | AA3: 23 | AB3: 24 | AC3: 25 | AD3: 26 | AE3: 27 | AF3: 28 | AG3: 29 | AH3: 30 | AI3: 31 | AJ3: 32 | AK3: 33 | AL3: 34 | AM3: 35 | AN3: 36 | AO3: 37
B4: Account Code | C4: AccountNAME | E4: 2021.12 | F4: 2021.12A | G4: 2022.03 | H4: 2022.06 | I4: 2022.09 | J4: 2022.12 | K4: 2022.12A | L4: 2023.03 | M4: 2023.06 | N4: 2023.09 | O4: 2023.12 | P4: 2023.12A | Q4: 2024.03 | R4: 2024.06 | S4: 2024.09 | T4: 2024.12 | U4: 2024.12A | V4: 2025.03 | W4: 2025.06 | X4: 2025.09 | Y4: 2025.12 | Z4: 2025.12A | AA4: 2026.03 | AB4: 2026.06 | AC4: 2026.09 | AD4: 2026.12 | AE4: 2026.12A | AF4: 2027.03 | AG4: 2027.06 | AH4: 2027.09 | AI4: 2027.12 | AJ4: 2027.12A | AK4: 2028.03 | AL4: 2028.06 | AM4: 2028.09 | AN4: 2028.12 | AO4: 2028.12A
A5: 1 | C5: 유동자산 | E5: 1704546.3 | F5: 1704546.3 | G5: 2299643.5 | H5: 2395983.2 | I5: 2005126 | J5: 1971791.8 | K5: 1971791.8 | L5: 2158317.3 | M5: 2340728.5 | N5: 2401533.1 | O5: 2349590.5 | P5: 2349590.5 | Q5: 2448592.7 | R5: 2420739.4 | S5: 2467466.7 | T5: 1958625.2 | U5: 1958625.2 | V5: 2401953.5 | W5: 2041442.6 | X5: 2021694.7 | Y5: 1975270.4 | Z5: 1975270.4 | AA5: 2417429.1 | AB5: 1946447
A6: 1 | C6: 현금및현금성자산 | E6: 182739.8 | F6: 182739.8 | G6: 153638.74 | H6: 158022.61 | I6: 227730.27 | J6: 501584.85 | K6: 501584.85 | L6: 555886.47 | M6: 689533.03 | N6: 732684.37 | O6: 724453.17 | P6: 724453.17 | Q6: 730153.27 | R6: 794183.36 | S6: 855245.7 | T6: 276042.67 | U6: 276042.67 | V6: 699444.78 | W6: 561965.16 | X6: 684640.21 | Y6: 886036.62 | Z6: 886036.62 | AA6: 1218978.3 | AB6: 793299.59
A7: 1 | C7: 단기금융상품 | E7: 592331.14 | F7: 592331.14 | G7: 1101441.3 | H7: 1188377.8 | I7: 702058.35 | J7: 390186.83 | K7: 390186.83 | L7: 474572.4 | M7: 518738.49 | N7: 490438.22 | O7: 483239.54 | P7: 483239.54 | Q7: 526750.73 | R7: 415696.81 | S7: 461144.03 | T7: 481477.35 | U7: 481477.35 | V7: 509061.06 | W7: 349562.92 | X7: 194776.67 | Y7: 8501.55 | Z7: 8501.55 | AA7: 29584.01
A8: 1 | C8: 단기금융자산 | E8: 592331.14 | F8: 592331.14 | G8: 1101441.3 | H8: 1188377.8 | I8: 702058.35 | J8: 390186.83 | K8: 390186.83 | L8: 474572.4 | M8: 518738.49 | N8: 490438.22 | O8: 483239.54 | P8: 483239.54 | Q8: 526750.73 | R8: 415696.81 | S8: 461144.03 | T8: 481477.35 | U8: 481477.35 | V8: 509061.06 | W8: 349562.92 | X8: 194776.67 | Y8: 8501.55 | Z8: 8501.55 | AA8: 29584.01
A9: 1 | C9: 매출채권및기타채권 | E9: 501805.77 | F9: 501805.77 | G9: 583506.47 | H9: 563766.88 | I9: 584313.78 | J9: 599834.4 | K9: 599834.4 | L9: 633422.24 | M9: 606209.56 | N9: 622336.22 | O9: 598019.1 | P9: 598019.1 | Q9: 644551.23 | R9: 664776.34 | S9: 598688.34 | T9: 622823.1 | U9: 622823.1 | V9: 647886.29 | W9: 617084.63 | X9: 639817.24 | Y9: 566800.48 | Z9: 566800.48 | AA9: 659046.75 | AB9: 637404.65
A10: 1 | C10: 선급금 | E10: 4242.46 | F10: 4242.46 | G10: 4509.98 | H10: 9807.29 | I10: 5648.42 | J10: 4708.45 | K10: 4708.45 | L10: 5190.49 | M10: 6315.52 | N10: 6107.37 | O10: 6777.41 | P10: 6777.41 | Q10: 8053.49 | R10: 5878.91 | S10: 4082.63 | T10: 3795.33 | U10: 3795.33 | V10: 3157.26 | W10: 2966.02 | X10: 2722.44 | Y10: 2736.59 | Z10: 2736.59 | AA10: 1626.35 | AB10: 3171.69
A11: 1 | C11: 선급금등 | E11: 4242.46 | F11: 4242.46 | G11: 4509.98 | H11: 9807.29 | I11: 5648.42 | J11: 4708.45 | K11: 4708.45 | L11: 5190.49 | M11: 6315.52 | N11: 6107.37 | O11: 6777.41 | P11: 6777.41 | Q11: 8053.49 | R11: 5878.91 | S11: 4082.63 | T11: 3795.33 | U11: 3795.33 | V11: 3157.26 | W11: 2966.02 | X11: 2722.44 | Y11: 2736.59 | Z11: 2736.59 | AA11: 1626.35 | AB11: 3171.69
A12: 1 | C12: 기타유동자산 | E12: 14944.86 | F12: 14944.86 | G12: 21138.61 | H12: 24596.28 | I12: 18544.65 | J12: 19104.74 | K12: 19104.74 | L12: 18768.83 | M12: 18451.82 | N12: 16280.14 | O12: 21500.21 | P12: 21500.21 | Q12: 17557.59 | R12: 16353.17 | S12: 10432.9 | T12: 9863.51 | U12: 9863.51 | V12: 9264.79 | W12: 9035.85 | X12: 8027.34 | Y12: 7842.79 | Z12: 7842.79 | AA12: 7381.64 | AB12: 10453.14
A13: 1 | C13: 기타유동금융자산 | E13: 2441.16 | F13: 2441.16 | G13: 3064.61 | H13: 3882.13 | I13: 2942.33 | J13: 3839.8 | K13: 3839.8 | L13: 3404.55 | M13: 5060.48 | N13: 12529.82 | O13: 9768.36 | P13: 9768.36 | Q13: 21085.95 | R13: 18838.42 | S13: 16384.87 | T13: 21688.98 | U13: 21688.98 | V13: 3303.08 | W13: 2833.72 | X13: 1439.78 | Y13: 96.7 | Z13: 96.7 | AA13: 95.68 | AB13: 37.51
A14: 1 | C14: 재고자산 | E14: 387801.47 | F14: 387801.47 | G14: 414371.65 | H14: 434855.46 | I14: 447054.54 | J14: 457241.18 | K14: 457241.18 | L14: 472262.77 | M14: 502735.1 | N14: 504782.22 | O14: 512610.1 | P14: 512610.1 | Q14: 508493.9 | R14: 510891.27 | S14: 525570.91 | T14: 546729.6 | U14: 546729.6 | V14: 532993.45 | W14: 500960.31 | X14: 492993.48 | Y14: 505992.23 | Z14: 505992.23 | AA14: 502342.73 | AB14: 505252.08
A15: 1 | C15: 비유동자산 | E15: 7105826.2 | F15: 7105826.2 | G15: 6832549.8 | H15: 6961802 | I15: 6565494.5 | J15: 6831287.8 | K15: 6831287.8 | L15: 6802872.1 | M15: 6904157.7 | N15: 6915116.8 | O15: 7307682 | P15: 7307682 | Q15: 7904680.6 | R15: 8068423.9 | S15: 8056915.7 | T15: 8340919.6 | U15: 8340919.6 | V15: 9576913.9 | W15: 10814399 | X15: 12283420 | Y15: 13151278 | Z15: 13151278 | AA15: 13218320 | AB15: 17011650
A16: 1 | C16: 장기매출채권및기타채권 | E16: 46770.47 | F16: 46770.47 | G16: 44587.56 | H16: 43302.93 | I16: 42252.85 | J16: 40543.76 | K16: 40543.76 | L16: 879.82 | M16: 59020.73 | N16: 1529.85 | O16: 56418.12 | P16: 56418.12 | Q16: 189737.13 | R16: 194533.88 | S16: 186485.8 | T16: 197910.67 | U16: 197910.67 | V16: 198194.43 | W16: 189236.85 | X16: 37267.64 | Y16: 47834.76 | Z16: 47834.76 | AA16: 47607.35 | AB16: 45822.1
A17: 1 | C17: 기타비유동자산 | E17: 60933.36 | F17: 60933.36 | G17: 53039.26 | H17: 49310.5 | I17: 41197.55 | J17: 75656.75 | K17: 75656.75 | L17: 67797.53 | M17: 66474.25 | N17: 61613.59 | O17: 35849.4 | P17: 35849.4 | Q17: 28820.77 | R17: 31707.54 | S17: 29851.67 | T17: 43891.26 | U17: 43891.26 | V17: 37309.68 | W17: 32392.54 | X17: 30514.03 | Y17: 34851.46 | Z17: 34851.46 | AA17: 27679.67 | AB17: 24313.6
A18: 1 | C18: 장기금융자산 | E18: 2666973.7 | F18: 2666973.7 | G18: 2384359.1 | H18: 2530953.2 | I18: 2134304.4 | J18: 2287109 | K18: 2287109 | L18: 2220664 | M18: 2306180.1 | N18: 2315995.3 | O18: 2723859.5 | P18: 2723859.5 | Q18: 3207437.8 | R18: 3047759.6 | S18: 3058077.3 | T18: 2767066.4 | U18: 2767066.4 | V18: 2735746 | W18: 3989057.9 | X18: 4530146.4 | Y18: 5455561 | Z18: 5455561 | AA18: 5525797.7 | AB18: 9177343.9
A19: 1 | C19: 투자자산 | E19: 4743334.8 | F19: 4743334.8 | G19: 4486239.7 | H19: 4633222.6 | I19: 4238939 | J19: 4429827.2 | K19: 4429827.2 | L19: 4376954.4 | M19: 4473207.4 | N19: 4486013.4 | O19: 4898276.1 | P19: 4898276.1 | Q19: 5386811.5 | R19: 5548754.4 | S19: 5560133.1 | T19: 5846810.2 | U19: 5846810.2 | V19: 5815489.8 | W19: 7085790.2 | X19: 8731562.4 | Y19: 9656976.9 | Z19: 9656976.9 | AA19: 9728218.4 | AB19: 13535848
A20: 1 | C20: 종속기업및관계기업투자 | E20: 2076361.1 | F20: 2076361.1 | G20: 2101880.6 | H20: 2102269.5 | I20: 2104634.6 | J20: 2142718.2 | K20: 2142718.2 | L20: 2156290.4 | M20: 2167027.3 | N20: 2170018 | O20: 2174416.5 | P20: 2174416.5 | Q20: 2179373.8 | R20: 2500994.8 | S20: 2502055.8 | T20: 3079743.8 | U20: 3079743.8 | V20: 3079743.8 | W20: 3096732.3 | X20: 4201416 | Y20: 4201416 | Z20: 4201416 | AA20: 4202420.7 | AB20: 4358503.8
... A32: 1 | C32: 비유동부채 | E32: 2041225.4 | F32: 2041225.4 | G32: 2164830.5 | H32: 2341735.7 | I32: 2250087.4 | J32: 2018562.7 | K32: 2018562.7 | L32: 1495006.5 | M32: 1579191.9 | N32: 1572846.8 | O32: 1358330.7 | P32: 1358330.7 | Q32: 1916095.7 | R32: 2271867.9 | S32: 2269337 | T32: 2373548.5 | U32: 2373548.5 | V32: 2900929.4 | W32: 2959819.9 | X32: 3056512.6 | Y32: 3140683.5 | Z32: 3140683.5 | AA32: 3203626.8 | AB32: 3433354
A33: 1 | C33: 장기차입금 | E33: 434820.79 | F33: 434820.79 | G33: 807010.15 | H33: 809488.33 | I33: 819149.17 | J33: 809051.14 | K33: 809051.14 | L33: 266587.06 | M33: 228037.34 | N33: 227716.38 | O33: 128268.45 | P33: 128268.45 | Q33: 0 | R33: 644589.99 | S33: 644626.5 | T33: 644663.01 | U33: 644663.01 | V33: 644698.74 | W33: 644734.87 | X33: 644771.41 | Y33: 644807.96 | Z33: 644807.96 | AA33: 644843.73
A34: 1 | C34: 사채 | E34: 1168017.8 | F34: 1168017.8 | G34: 968354.81 | H34: 1117873.4 | I34: 1118099.2 | J34: 798493.51 | K34: 798493.51 | L34: 798672.52 | M34: 918134.68 | N34: 918321.73 | O34: 748637.26 | P34: 748637.26 | Q34: 1327305 | R34: 1057792.4 | S34: 1058013.4 | T34: 1307469.1 | U34: 1307469.1 | V34: 1561826.9 | W34: 1287383.7 | X34: 1287652.9 | Y34: 1128051.6 | Z34: 1128051.6 | AA34: 1147519.8 | AB34: 1117780.9
A35: 1 | C35: 기타비유동금융부채 | E35: 18940.58 | F35: 18940.58 | G35: 8621.14 | H35: 5566.21 | I35: 1607.17 | J35: 57445.32 | K35: 57445.32 | L35: 31577.61 | M35: 20696.72 | N35: 3749.29
A36: 1 | C36: 장기금융부채 | E36: 18940.58 | F36: 18940.58 | G36: 8621.14 | H36: 5566.21 | I36: 1607.17 | J36: 57445.32 | K36: 57445.32 | L36: 31577.61 | M36: 20696.72 | N36: 3749.29
A37: 1 | C37: 확정급여부채 | E37: 3662.09 | F37: 3662.09 | G37: 3663.42 | H37: 3583.57 | I37: 3529.66 | J37: 3850.89 | K37: 3850.89 | L37: 4086.22 | M37: 4137.5 | N37: 4312.39 | O37: 5569.62 | P37: 5569.62 | Q37: 5481.84 | R37: 6144.64 | S37: 11966.1 | T37: 7515.15 | U37: 7515.15 | V37: 7468.03 | W37: 9725.97 | X37: 15543.98 | Y37: 9931.4 | Z37: 9931.4 | AA37: 9862.46 | AB37: 9791.24
A38: 1 | C38: 장기충당부채 | E38: 688.12 | F38: 688.12 | G38: 693.27 | H38: 596.18 | I38: 608.09 | J38: 660.39 | K38: 660.39 | L38: 714.93 | M38: 724.29 | N38: 764.59 | O38: 787.65 | P38: 787.65 | Q38: 833.98 | R38: 856.55 | S38: 909.33 | T38: 923.57 | U38: 923.57 | V38: 967.2 | W38: 951.27 | X38: 1001.14 | Y38: 992.6 | Z38: 992.6 | AA38: 1055.97 | AB38: 1038.89
A39: 1 | C39: 이연법인세부채 | E39: 339243.99 | F39: 339243.99 | G39: 299512.84 | H39: 331373.93 | I39: 235605.99 | J39: 273884.26 | K39: 273884.26 | L39: 296835.38 | M39: 318147.33 | N39: 329454.99 | O39: 388026.54 | P39: 388026.54 | Q39: 484101.22 | R39: 464401.31 | S39: 468071.15 | T39: 323425.27 | U39: 323425.27 | V39: 590666.21 | W39: 931221.71 | X39: 1027604.8 | Y39: 1277184.5 | Z39: 1277184.5 | AA39: 1323531.9 | AB39: 2234715.1
A40: 1 | C40: 부채총계 | E40: 3756748.5 | F40: 3756748.5 | G40: 4244930.4 | H40: 4366626.1 | I40: 3867262.8 | J40: 3891107 | K40: 3891107 | L40: 4043873.3 | M40: 4190372.2 | N40: 4171018.5 | O40: 4298986.3 | P40: 4298986.3 | Q40: 4471412.3 | R40: 4587489.5 | S40: 4593214.2 | T40: 4435298.7 | U40: 4435298.7 | V40: 5080349.1 | W40: 5018778.6 | X40: 6113809.3 | Y40: 6272420 | Z40: 6272420 | AA40: 6661480.6 | AB40: 7153718.3
A41: 1 | C41: 자본금 | E41: 48084.66 | F41: 48084.66 | G41: 48084.66 | H41: 48084.66 | I41: 48084.66 | J41: 48084.66 | K41: 48084.66 | L41: 48084.66 | M41: 48084.66 | N41: 48084.66 | O41: 48084.66 | P41: 48084.66 | Q41: 48084.66 | R41: 48084.66 | S41: 48084.66 | T41: 48084.66 | U41: 48084.66 | V41: 48084.66 | W41: 48084.66 | X41: 48084.66 | Y41: 48084.66 | Z41: 48084.66 | AA41: 48084.66 | AB41: 48084.66
A42: 1 | C42: 자본잉여금 | E42: 553070.81 | F42: 553070.81 | G42: 553070.81 | H42: 553070.81 | I42: 553070.81 | J42: 553070.81 | K42: 553070.81 | L42: 553070.81 | M42: 553070.81 | N42: 553070.81 | O42: 553070.81 | P42: 553070.81 | Q42: 553070.81 | R42: 553070.81 | S42: 553070.81 | T42: 553070.81 | U42: 553070.81 | V42: 553070.81 | W42: 553070.81 | X42: 553070.81 | Y42: 553070.81 | Z42: 553070.81 | AA42: 516415.92 | AB42: 516415.92
A43: 1 | C43: 기타자본 | E43: -204952.84 | F43: -204952.84 | G43: -286379.5 | H43: -304846.77 | I43: -304846.77 | J43: -304846.77 | K43: -304846.77 | L43: -304846.77 | M43: -304846.77 | N43: -304846.77 | O43: -304846.77 | P43: -304846.77 | Q43: -304846.77 | R43: -304846.77 | S43: -304846.77 | T43: -304846.77 | U43: -304846.77 | V43: -304846.77 | W43: -304846.77 | X43: -304846.77 | Y43: -304846.77 | Z43: -304846.77 | AA43: -304846.77 | AB43: -246440.9
A44: 1 | C44: 기타포괄이익누계액 | E44: -22922.71 | F44: -22922.71 | G44: -21421.96 | H44: -27875.2 | I44: -31477 | J44: -33244.08 | K44: -33244.08 | L44: -32073.59 | M44: -29984.94 | N44: -31507.91 | O44: -31464.4 | P44: -31464.4 | Q44: -31972.32 | R44: -32214 | S44: -32214 | T44: -27839.89 | U44: -27839.89 | V44: 647600.41 | W44: 652205.16 | X44: 647316.71 | Y44: 628418.07 | Z44: 628418.07 | AA44: 629641.25 | AB44: 634175.67
A45: 1 | C45: 이익잉여금 | E45: 4680344 | F45: 4680344 | G45: 4593908.9 | H45: 4722725.5 | I45: 4438526 | J45: 4648908 | K45: 4648908 | L45: 4653080.9 | M45: 4788190.2 | N45: 4880830.6 | O45: 5093441.9 | P45: 5093441.9 | Q45: 5617524.6 | R45: 5637579 | S45: 5667073.6 | T45: 5595777.3 | U45: 5595777.3 | V45: 5954609.1 | W45: 6888548.9 | X45: 7247679.8 | Y45: 7929402.1 | Z45: 7929402.1 | AA45: 8084973.7 | AB45: 10852144
A46: 1 | C46: 자본총계 | E46: 5053623.9 | F46: 5053623.9 | G46: 4887262.9 | H46: 4991159.1 | I46: 4703357.7 | J46: 4911972.6 | K46: 4911972.6 | L46: 4917316 | M46: 5054514 | N46: 5145631.4 | O46: 5358286.2 | P46: 5358286.2 | Q46: 5881861 | R46: 5901673.7 | S46: 5931168.3 | T46: 5864246.1 | U46: 5864246.1 | V46: 6898518.2 | W46: 7837062.8 | X46: 8191305.2 | Y46: 8854128.9 | Z46: 8854128.9 | AA46: 8974268.7 | AB46: 11804379
A47: 1 | C47: 부채와자본총계 | E47: 8810372.4 | F47: 8810372.4 | G47: 9132193.3 | H47: 9357785.2 | I47: 8570620.5 | J47: 8803079.6 | K47: 8803079.6 | L47: 8961189.3 | M47: 9244886.2 | N47: 9316649.9 | O47: 9657272.5 | P47: 9657272.5 | Q47: 10353273 | R47: 10489163 | S47: 10524382 | T47: 10299545 | U47: 10299545 | V47: 11978867 | W47: 12855841 | X47: 14305114 | Y47: 15126549 | Z47: 15126549 | AA47: 15635749 | AB47: 18958097
A48: 1 | C48: 지배주주지분 | E48: 5053623.9 | F48: 5053623.9 | G48: 4887262.9 | H48: 4991159.1 | I48: 4703357.7 | J48: 4911972.6 | K48: 4911972.6 | L48: 4917316 | M48: 5054514 | N48: 5145631.4 | O48: 5358286.2 | P48: 5358286.2 | Q48: 5881861 | R48: 5901673.7 | S48: 5931168.3 | T48: 5864246.1 | U48: 5864246.1 | V48: 6898518.2 | W48: 7837062.8 | X48: 8191305.2 | Y48: 8854128.9 | Z48: 8854128.9 | AA48: 8974268.7 | AB48: 11804379
... A51: 1 | C51: 이자발생자산 | E51: 3442044.6 | F51: 3442044.6 | G51: 3639439.2 | H51: 3877353.5 | I51: 3064093.1 | J51: 3178880.7 | K51: 3178880.7 | L51: 3251122.9 | M51: 3514451.6 | N51: 3539117.9 | O51: 3931552.2 | P51: 3931552.2 | Q51: 4464341.8 | R51: 4257639.8 | S51: 4374467 | T51: 3524586.5 | U51: 3524586.5 | V51: 3944251.9 | W51: 4900586 | X51: 5409563.3 | Y51: 6350099.2 | Z51: 6350099.2 | AA51: 6774360 | AB51: 9970643.5
A52: 1 | C52: 기타유동금융부채 | O52: 164369.97 | P52: 164369.97 | Q52: 168939.66 | X52: 299131.33 | Y52: 275328.61 | Z52: 275328.61 | AA52: 168371.8 | AB52: 136569.19
A53: 1 | C53: 단기금융부채 | O53: 164369.97 | P53: 164369.97 | Q53: 168939.66 | X53: 299131.33 | Y53: 275328.61 | Z53: 275328.61 | AA53: 168371.8 | AB53: 136569.19
...

Sheet subQ
A1: YQ | C1: subQ 분기 서브모델(억원, U=100) | E1: 4Q21 | F1: 2021 | G1: 1Q22 | H1: 2Q22 | I1: 3Q22 | J1: 4Q22 | K1: 2022 | L1: 1Q23 | M1: 2Q23 | N1: 3Q23 | O1: 4Q23 | P1: 2023 | Q1: 1Q24 | R1: 2Q24 | S1: 3Q24 | T1: 4Q24 | U1: 2024 | V1: 1Q25 | W1: 2Q25 | X1: 3Q25 | Y1: 4Q25 | Z1: 2025 | AA1: 1Q26 | AB1: 2Q26 | AC1: 3Q26 | AD1: 4Q26 | AE1: 2026 | AF1: 1Q27 | AG1: 2Q27 | AH1: 3Q27 | AI1: 4Q27 | AJ1: 2027 | AK1: 1Q28 | AL1: 2Q28 | AM1: 3Q28 | AN1: 4Q28 | AO1: 2028
A2: A=이름(key) B=그룹 C=단위 D=FnGuide 계정명(VLOOKUP 키). 확정=VLOOKUP(BS), 추정=변수 가정 참조
E3: 1 | F3: 2 | G3: 3 | H3: 4 | I3: 5 | J3: 6 | K3: 7 | L3: 8 | M3: 9 | N3: 10 | O3: 11 | P3: 12 | Q3: 13 | R3: 14 | S3: 15 | T3: 16 | U3: 17 | V3: 18 | W3: 19 | X3: 20 | Y3: 21 | Z3: 22 | AA3: 23 | AB3: 24 | AC3: 25 | AD3: 26 | AE3: 27 | AF3: 28 | AG3: 29 | AH3: 30 | AI3: 31 | AJ3: 32 | AK3: 33 | AL3: 34 | AM3: 35 | AN3: 36 | AO3: 37
E4: 2021.12 | F4: 2021.12A | G4: 2022.03 | H4: 2022.06 | I4: 2022.09 | J4: 2022.12 | K4: 2022.12A | L4: 2023.03 | M4: 2023.06 | N4: 2023.09 | O4: 2023.12 | P4: 2023.12A | Q4: 2024.03 | R4: 2024.06 | S4: 2024.09 | T4: 2024.12 | U4: 2024.12A | V4: 2025.03 | W4: 2025.06 | X4: 2025.09 | Y4: 2025.12 | Z4: 2025.12A | AA4: 2026.03 | AB4: 2026.06 | AC4: 2026.09 | AD4: 2026.12 | AE4: 2026.12A | AF4: 2027.03 | AG4: 2027.06 | AH4: 2027.09 | AI4: 2027.12 | AJ4: 2027.12A | AK4: 2028.03 | AL4: 2028.06 | AM4: 2028.09 | AN4: 2028.12 | AO4: 2028.12A
A5: 매출액 | B5: 손익 | C5: 억원 | D5: 매출액(수익) | E5: =IFERROR(VLOOKUP($D5,BS연결,MATCH(E$1,BS연결H,0),0)/100,"") | G5: =IFERROR(VLOOKUP($D5,BS연결,MATCH(G$1,BS연결H,0),0)/100,"") | H5: =IFERROR(VLOOKUP($D5,BS연결,MATCH(H$1,BS연결H,0),0)/100,"") | I5: =IFERROR(VLOOKUP($D5,BS연결,MATCH(I$1,BS연결H,0),0)/100,"") | J5: =IFERROR(VLOOKUP($D5,BS연결,MATCH(J$1,BS연결H,0),0)/100,"") | K5: =IFERROR(VLOOKUP($D5,BS연결,MATCH(K$1,BS연결H,0),0)/100,"") | L5: =IFERROR(VLOOKUP($D5,BS연결,MATCH(L$1,BS연결H,0),0)/100,"") | M5: =IFERROR(VLOOKUP($D5,BS연결,MATCH(M$1,BS연결H,0),0)/100,"") | N5: =IFERROR(VLOOKUP($D5,BS연결,MATCH(N$1,BS연결H,0),0)/100,"") | ... AB5: =IFERROR(VLOOKUP($D5,BS연결,MATCH(AB$1,BS연결H,0),0)/100,"") | AC5: =IFERROR(X5*(1+변수!AC21),"") | AD5: =IFERROR(Y5*(1+변수!AD21),"") | AE5: =SUM(AA5:AD5) | AF5: =IFERROR(AA5*(1+변수!AF21),"") | AG5: =IFERROR(AB5*(1+변수!AG21),"") | AH5: =IFERROR(AC5*(1+변수!AH21),"") | AI5: =IFERROR(AD5*(1+변수!AI21),"") | AJ5: =SUM(AF5:AI5) | AK5: =IFERROR(AF5*(1+변수!AK21),"") | AL5: =IFERROR(AG5*(1+변수!AL21),"") | AM5: =IFERROR(AH5*(1+변수!AM21),"") | AN5: =IFERROR(AI5*(1+변수!AN21),"") | AO5: =SUM(AK5:AN5)
A6: 매출원가 | B6: 손익 | C6: 억원 | D6: 매출원가 | E6: =IFERROR(VLOOKUP($D6,BS연결,MATCH(E$1,BS연결H,0),0)/100,"") | G6: =IFERROR(VLOOKUP($D6,BS연결,MATCH(G$1,BS연결H,0),0)/100,"") | H6: =IFERROR(VLOOKUP($D6,BS연결,MATCH(H$1,BS연결H,0),0)/100,"") | I6: =IFERROR(VLOOKUP($D6,BS연결,MATCH(I$1,BS연결H,0),0)/100,"") | J6: =IFERROR(VLOOKUP($D6,BS연결,MATCH(J$1,BS연결H,0),0)/100,"") | K6: =IFERROR(VLOOKUP($D6,BS연결,MATCH(K$1,BS연결H,0),0)/100,"") | L6: =IFERROR(VLOOKUP($D6,BS연결,MATCH(L$1,BS연결H,0),0)/100,"") | M6: =IFERROR(VLOOKUP($D6,BS연결,MATCH(M$1,BS연결H,0),0)/100,"") | N6: =IFERROR(VLOOKUP($D6,BS연결,MATCH(N$1,BS연결H,0),0)/100,"") | ... AB6: =IFERROR(VLOOKUP($D6,BS연결,MATCH(AB$1,BS연결H,0),0)/100,"") | AC6: =IFERROR(AC5-AC7,"") | AD6: =IFERROR(AD5-AD7,"") | AE6: =SUM(AA6:AD6) | AF6: =IFERROR(AF5-AF7,"") | AG6: =IFERROR(AG5-AG7,"") | AH6: =IFERROR(AH5-AH7,"") | AI6: =IFERROR(AI5-AI7,"") | AJ6: =SUM(AF6:AI6) | AK6: =IFERROR(AK5-AK7,"") | AL6: =IFERROR(AL5-AL7,"") | AM6: =IFERROR(AM5-AM7,"") | AN6: =IFERROR(AN5-AN7,"") | AO6: =SUM(AK6:AN6)
A7: 매출총이익 | B7: 손익 | C7: 억원 | D7: 매출총이익 | E7: =IFERROR(VLOOKUP($D7,BS연결,MATCH(E$1,BS연결H,0),0)/100,"") | G7: =IFERROR(VLOOKUP($D7,BS연결,MATCH(G$1,BS연결H,0),0)/100,"") | H7: =IFERROR(VLOOKUP($D7,BS연결,MATCH(H$1,BS연결H,0),0)/100,"") | I7: =IFERROR(VLOOKUP($D7,BS연결,MATCH(I$1,BS연결H,0),0)/100,"") | J7: =IFERROR(VLOOKUP($D7,BS연결,MATCH(J$1,BS연결H,0),0)/100,"") | K7: =IFERROR(VLOOKUP($D7,BS연결,MATCH(K$1,BS연결H,0),0)/100,"") | L7: =IFERROR(VLOOKUP($D7,BS연결,MATCH(L$1,BS연결H,0),0)/100,"") | M7: =IFERROR(VLOOKUP($D7,BS연결,MATCH(M$1,BS연결H,0),0)/100,"") | N7: =IFERROR(VLOOKUP($D7,BS연결,MATCH(N$1,BS연결H,0),0)/100,"") | ... AB7: =IFERROR(VLOOKUP($D7,BS연결,MATCH(AB$1,BS연결H,0),0)/100,"") | AC7: =IFERROR(AC9+AC8,"") | AD7: =IFERROR(AD9+AD8,"") | AE7: =SUM(AA7:AD7) | AF7: =IFERROR(AF9+AF8,"") | AG7: =IFERROR(AG9+AG8,"") | AH7: =IFERROR(AH9+AH8,"") | AI7: =IFERROR(AI9+AI8,"") | AJ7: =SUM(AF7:AI7) | AK7: =IFERROR(AK9+AK8,"") | AL7: =IFERROR(AL9+AL8,"") | AM7: =IFERROR(AM9+AM8,"") | AN7: =IFERROR(AN9+AN8,"") | AO7: =SUM(AK7:AN7)
