Workbook
Name 변수H: 변수!$C$1:$AO$1
Name 환율: 변수!$C$6:$AO$13
Name BS연결H: BS연결!$C$1:$AO$1
Name BS연결: BS연결!$C$5:$AO$112
Name BS별도H: BS별도!$C$1:$AO$1
Name BS별도: BS별도!$C$5:$AO$95
Name SUBQH: subQ!$A$1:$AO$1
Name subQ: subQ!$A$5:$AO$43
Name SLS_H: SLS!$A$1:$BH$1

Sheet README
A1: HD한국조선해양(009540) 실적 모델 — ARGUS 한국조선
A2: 기준 분기 2026Q2 · 마지막 실적 2026Q2 · 생성 2026-10-12
A3: 모든 수치는 모델 산출값(DART 공개 재무제표 + 우리 추정)이다 — 목표주가·투자 추천 아님. 참고용 · 투자조언 아님.
A5: 시트
A6: 변수 가정 시계열. 환율 8행(ECB via frankfurter — L2 fx.json; 추정 분기 = 노란 가정), 추정 드라이버(노란 셀 = 모델값에서 역산한 가정, 바꾸면 재계산; 연녹 셀 = 3절 스칼라 참조 수식), 3절 스칼라 가정(세율·판관비율·지배주주비중·이자율·종가·PER 밴드·COE·외화 순노출·헤지비율)
A7: BS연결/BS별도 FnGuide 계정명 × 기간 값 덤프(백만원). 행1 분기라벨, 행4 YYYY.MM / YYYY.12A. 이름정의 BS연결H·BS연결(계정명 C열부터)
A8: subQ 분기 서브모델(억원 = 백만원/100). 확정 행: =IFERROR(VLOOKUP($D행,BS연결,MATCH(E$1,BS연결H,0),0)/100,"") 추정 행: 변수 시트 가정 셀 참조 수식. 외환손익·파생상품손익은 BS 계정 합·차, 기타금융손익은 잔차, OPM·EPS·BPS·PER·PBR 은 파생 수식
A9: SLS 선표(조선사만, sls json 있을 때): 요약 행(sls 저장값) + 계약별 스케줄(백만$) × (헤지비율 × 헤지환율 + (1−헤지비율) × 건조시점 환율[변수 원/달러(평균)]) → 원화 수식 블록 → 합계 행이 subQ 매출조선에 연결
A10: 시나리오 신규수주 보수/기준/낙관(forecast_panel 패널, 모델에 scenarios 가 있을 때만): 매출액·영업이익 = subQ 기준값 ± (시나리오 신규 − base 신규) × OPM. base 만 subQ 행에 포함, 나머지는 합산 안 함
A11: 분기/연간예상 subQ 를 이름(A열 key)으로 VLOOKUP 한 보고서 표(억원)
A12: TP PER 밴드 × 12M fwd EPS, PBR = ROE/COE × BPS — 모델 산출값 구간, 목표주가·추천 아님
A13: 외화 환율 QoQ, 외화 순노출 × Δ기말환율 → 환관련손익 추정
... A36: 백테스트: {"freeze": "2025Q2", "horizon": 4, "revenue_wape_pct": 9.8, "op_wape_pct": 40.8, "n": 4, "note": "단일 회사 4분기 — 통계 아님", "driver_at_freeze": "subsidiary_yard_scaled", "selection_oos_at_freeze": null, "frozen_inputs": "fin(연결/별도)·고객 조선사 모델·지주 자회사 모델은 2025Q2 까지의 분기만; 선표는 체결일 ≤ 2025Q2 말일 계약(원장 최신 금액·코호트 등급, 환산 없음); 잔고는 yards_cache 2025Q2; 시세·환율 forward·prices·forecast_panel 신규수주 미사용. 고객 가중치(suppliers.json 언급 비중)와 합병 체인링크는 현재 지식; 고객 연동 채택은 동결 모델 안에서도 자기 la−4분기 OOS 규칙(selection_oos_at_freeze)", "detail": [{"q": "2025Q3", "rev_pred": 74060.53, "rev_act": 75814.36, "op_pred": 7553.95, "op_act": 10537.75}, {"q": "2025Q4", "rev_pred": 74060.53, "rev_act": 81516.57, "op_pred": 7553.95, "op_act": 10379.19}, {"q": "2026Q1", "rev_pred": 73789.18, "rev_act": 81408.9, "op_pred": 7526.28, "op_act": 13559.7}, {"q": "2026Q2", "rev_pred": 73924.83, "rev_act": 89270.46, "op_pred": 7540.11, "op_act": 16451.46}]}

Sheet 변수
C1: 이름: 변수H | E1: 4Q21 | F1: 2021 | G1: 1Q22 | H1: 2Q22 | I1: 3Q22 | J1: 4Q22 | K1: 2022 | L1: 1Q23 | M1: 2Q23 | N1: 3Q23 | O1: 4Q23 | P1: 2023 | Q1: 1Q24 | R1: 2Q24 | S1: 3Q24 | T1: 4Q24 | U1: 2024 | V1: 1Q25 | W1: 2Q25 | X1: 3Q25 | Y1: 4Q25 | Z1: 2025 | AA1: 1Q26 | AB1: 2Q26 | AC1: 3Q26 | AD1: 4Q26 | AE1: 2026 | AF1: 1Q27 | AG1: 2Q27 | AH1: 3Q27 | AI1: 4Q27 | AJ1: 2027 | AK1: 1Q28 | AL1: 2Q28 | AM1: 3Q28 | AN1: 4Q28 | AO1: 2028
A2: 가정 시계열 — 노란 셀은 추정 가정(모델값에서 역산), 연녹 셀은 3절 스칼라 참조 수식. 바꾸면 subQ·분기·연간예상·TP·시나리오가 재계산됩니다.
E3: 1 | F3: 2 | G3: 3 | H3: 4 | I3: 5 | J3: 6 | K3: 7 | L3: 8 | M3: 9 | N3: 10 | O3: 11 | P3: 12 | Q3: 13 | R3: 14 | S3: 15 | T3: 16 | U3: 17 | V3: 18 | W3: 19 | X3: 20 | Y3: 21 | Z3: 22 | AA3: 23 | AB3: 24 | AC3: 25 | AD3: 26 | AE3: 27 | AF3: 28 | AG3: 29 | AH3: 30 | AI3: 31 | AJ3: 32 | AK3: 33 | AL3: 34 | AM3: 35 | AN3: 36 | AO3: 37
E4: 2021.12 | F4: 2021.12A | G4: 2022.03 | H4: 2022.06 | I4: 2022.09 | J4: 2022.12 | K4: 2022.12A | L4: 2023.03 | M4: 2023.06 | N4: 2023.09 | O4: 2023.12 | P4: 2023.12A | Q4: 2024.03 | R4: 2024.06 | S4: 2024.09 | T4: 2024.12 | U4: 2024.12A | V4: 2025.03 | W4: 2025.06 | X4: 2025.09 | Y4: 2025.12 | Z4: 2025.12A | AA4: 2026.03 | AB4: 2026.06 | AC4: 2026.09 | AD4: 2026.12 | AE4: 2026.12A | AF4: 2027.03 | AG4: 2027.06 | AH4: 2027.09 | AI4: 2027.12 | AJ4: 2027.12A | AK4: 2028.03 | AL4: 2028.06 | AM4: 2028.09 | AN4: 2028.12 | AO4: 2028.12A
B5: 1. FX | C5: 이름: 환율
A6: USDKRW_avg | C6: 원/달러(평균) | E6: 1183.5 | F6: 1145.51 | G6: 1205.78 | H6: 1262.09 | I6: 1341.93 | J6: 1360.12 | K6: 1292.98 | L6: 1276.95 | M6: 1315.69 | N6: 1313.62 | O6: 1322.01 | P6: 1306.85 | Q6: 1330.14 | R6: 1371.28 | S6: 1356.22 | T6: 1396.3 | U6: 1363.53 | V6: 1452.28 | W6: 1398.52 | X6: 1386.95 | Y6: 1449.19 | Z6: 1421.52 | AA6: 1466.12 | AB6: 1501.75 | AC6: 1418.75 | AD6: 1345.14 | AE6: 1457.21 | AF6: 1341.49 | AG6: 1341.49 | AH6: 1341.49 | AI6: 1341.49 | AK6: 1341.49 | AL6: 1341.49 | AM6: 1341.49 | AN6: 1341.49
A7: USDKRW_end | C7: 원/달러(기말) | E7: 1188.75 | F7: 1188.75 | G7: 1213.74 | H7: 1301.24 | I7: 1436.9 | J7: 1260.16 | K7: 1260.16 | L7: 1305.99 | M7: 1321.44 | N7: 1345.35 | O7: 1297.43 | P7: 1297.43 | Q7: 1349.25 | R7: 1377.73 | S7: 1312.17 | T7: 1474.78 | U7: 1474.78 | V7: 1474.54 | W7: 1355.13 | X7: 1403.67 | Y7: 1444.2 | Z7: 1444.2 | AA7: 1524.8 | AB7: 1550.89 | AC7: 1355.4 | AD7: 1341.49 | AE7: 1341.49 | AF7: 1341.49 | AG7: 1341.49 | AH7: 1341.49 | AI7: 1341.49 | AK7: 1341.49 | AL7: 1341.49 | AM7: 1341.49 | AN7: 1341.49
A8: JPY100KRW_avg | C8: 원/100Y(평균) | E8: 1041.02 | F8: 1042.74 | G8: 1036.79 | H8: 972.23 | I8: 970.61 | J8: 961.03 | K8: 985.1 | L8: 964.89 | M8: 957.36 | N8: 909 | O8: 893.22 | P8: 931.11 | Q8: 896.29 | R8: 880.14 | S8: 909.35 | T8: 917.25 | U8: 900.92 | V8: 952.59 | W8: 967.92 | X8: 940.32 | Y8: 940.77 | Z8: 950.17 | AA8: 934.39 | AB8: 942.16 | AC8: 890.41 | AD8: 850.79 | AE8: 919.21 | AF8: 847.7 | AG8: 847.7 | AH8: 847.7 | AI8: 847.7 | AK8: 847.7 | AL8: 847.7 | AM8: 847.7 | AN8: 847.7
A9: JPY100KRW_end | C9: 원/100Y(기말) | E9: 1032.62 | F9: 1032.62 | G9: 996.83 | H9: 954.9 | I9: 993.29 | J9: 955.54 | K9: 955.54 | L9: 980.62 | M9: 913.67 | N9: 901.47 | O9: 917.04 | P9: 917.04 | Q9: 892.42 | R9: 857.76 | S9: 919.21 | T9: 939.65 | U9: 939.65 | V9: 986.84 | W9: 938.85 | X9: 948.49 | Y9: 921.81 | Z9: 921.81 | AA9: 955.99 | AB9: 954.75 | AC9: 863.31 | AD9: 847.7 | AE9: 847.7 | AF9: 847.7 | AG9: 847.7 | AH9: 847.7 | AI9: 847.7 | AK9: 847.7 | AL9: 847.7 | AM9: 847.7 | AN9: 847.7
A10: EURKRW_avg | C10: W/Euro(평균) | E10: 1353.32 | F10: 1354.06 | G10: 1352.29 | H10: 1343.31 | I10: 1350.63 | J10: 1386.07 | K10: 1358.07 | L10: 1369.93 | M10: 1432.41 | N10: 1429.41 | O10: 1420.91 | P10: 1412.88 | Q10: 1444.21 | R10: 1476.42 | S10: 1489.3 | T10: 1490.78 | U10: 1475.4 | V10: 1528.33 | W10: 1585.13 | X10: 1620.04 | Y10: 1686.02 | Z10: 1605.45 | AA10: 1715.47 | AB10: 1746.09 | AC10: 1631.97 | AD10: 1509.74 | AE10: 1689.95 | AF10: 1503.27 | AG10: 1503.27 | AH10: 1503.27 | AI10: 1503.27 | AK10: 1503.27 | AL10: 1503.27 | AM10: 1503.27 | AN10: 1503.27
A11: EURKRW_end | C11: W/Euro(기말) | E11: 1346.38 | F11: 1346.38 | G11: 1347.37 | H11: 1351.6 | I11: 1400.62 | J11: 1344.08 | K11: 1344.08 | L11: 1420.26 | M11: 1435.88 | N11: 1425.26 | O11: 1433.66 | P11: 1433.66 | Q11: 1458.68 | R11: 1474.86 | S11: 1469.1 | T11: 1532.14 | U11: 1532.14 | V11: 1594.72 | W11: 1588.22 | X11: 1648.04 | Y11: 1696.94 | Z11: 1696.94 | AA11: 1753.21 | AB11: 1767.09 | AC11: 1539.06 | AD11: 1503.27 | AE11: 1503.27 | AF11: 1503.27 | AG11: 1503.27 | AH11: 1503.27 | AI11: 1503.27 | AK11: 1503.27 | AL11: 1503.27 | AM11: 1503.27 | AN11: 1503.27
A12: CNYKRW_avg | C12: 원/중국원(평균) | E12: 185.14 | F12: 177.65 | G12: 189.93 | H12: 190.76 | I12: 195.79 | J12: 191.09 | K12: 191.93 | L12: 186.59 | M12: 187.45 | N12: 181.28 | O12: 182.86 | P12: 184.52 | Q12: 185.04 | R12: 189.35 | S12: 189.24 | T12: 194.24 | U12: 189.49 | V12: 199.63 | W12: 193.41 | X12: 193.79 | Y12: 204.38 | Z12: 197.8 | AA12: 211.75 | AB12: 220.8 | AC12: 210.43 | AD12: 200.69 | AE12: 213.75 | AF12: 200.46 | AG12: 200.46 | AH12: 200.46 | AI12: 200.46 | AK12: 200.46 | AL12: 200.46 | AM12: 200.46 | AN12: 200.46
A13: CNYKRW_end | C13: 원/중국원(기말) | E13: 187.13 | F13: 187.13 | G13: 191.38 | H13: 194.13 | I13: 201.92 | J13: 182.67 | K13: 182.67 | L13: 189.97 | M13: 181.8 | N13: 184.26 | O13: 182.61 | P13: 182.61 | Q13: 186.66 | R13: 189.7 | S13: 187.12 | T13: 202.04 | U13: 202.04 | V13: 203.3 | W13: 189.14 | X13: 197.16 | Y13: 206.28 | Z13: 206.28 | AA13: 220.97 | AB13: 228.56 | AC13: 202.16 | AD13: 200.46 | AE13: 200.46 | AF13: 200.46 | AG13: 200.46 | AH13: 200.46 | AI13: 200.46 | AK13: 200.46 | AL13: 200.46 | AM13: 200.46 | AN13: 200.46
B14: 1b. 종가
A15: price_close_end | C15: 종가(기말) | E15: 94600 | G15: 88900 | H15: 93900 | I15: 72900 | J15: 70700 | L15: 77500 | M15: 116500 | N15: 111000 | O15: 120900 | Q15: 118400 | R15: 158800 | S15: 187700 | T15: 228000 | V15: 201000 | W15: 366000 | X15: 411000 | Y15: 407000 | AA15: 344000 | AB15: 350000 | AC15: 326500 | AD15: 279500
A16: price_high | C16: 종가(최고) | E16: 108500 | G16: 103500 | H16: 98200 | I16: 101500 | J16: 81000 | L16: 86500 | M16: 121900 | N16: 130000 | O16: 121400 | Q16: 129000 | R16: 160000 | S16: 213000 | T16: 238000 | V16: 253500 | W16: 398500 | X16: 438000 | Y16: 494500 | AA16: 474000 | AB16: 488000 | AC16: 412500 | AD16: 328500
A17: price_low | C17: 종가(최저) | E17: 87000 | G17: 76900 | H17: 80900 | I17: 72500 | J17: 68600 | L17: 68100 | M17: 75500 | N17: 110200 | O17: 89000 | Q17: 104000 | R17: 110800 | S17: 153600 | T17: 175500 | V17: 194400 | W17: 185700 | X17: 304500 | Y17: 396000 | AA17: 340500 | AB17: 338000 | AC17: 314000 | AD17: 276500
A18: price_avg | C18: 종가(평균) | E18: 97490.5 | G18: 89366.1 | H18: 89929 | I18: 87073 | J18: 74871 | L18: 78014.5 | M18: 94542.6 | N18: 120450 | O18: 103801.7 | Q18: 115870.5 | R18: 131518.3 | S18: 184258.1 | T18: 198872.1 | V18: 225800 | W18: 286443.3 | X18: 370384.6 | Y18: 430364.4 | AA18: 415415.3 | AB18: 412032.8 | AC18: 356596.8 | AD18: 307083.3
B20: 2. 추정 드라이버 | C20: 실적 열 = subQ 실현값(수식), 추정 열 = 가정(노란 = 모델값 역산, 연녹 = 3절 스칼라 참조)
A21: drv:매출액 | B21: yoy | C21: 매출액 YoY | J21: =IFERROR(subQ!J5/subQ!E5-1,"") | L21: =IFERROR(subQ!L5/subQ!G5-1,"") | M21: =IFERROR(subQ!M5/subQ!H5-1,"") | N21: =IFERROR(subQ!N5/subQ!I5-1,"") | O21: =IFERROR(subQ!O5/subQ!J5-1,"") | Q21: =IFERROR(subQ!Q5/subQ!L5-1,"") | R21: =IFERROR(subQ!R5/subQ!M5-1,"") | S21: =IFERROR(subQ!S5/subQ!N5-1,"") | T21: =IFERROR(subQ!T5/subQ!O5-1,"") | V21: =IFERROR(subQ!V5/subQ!Q5-1,"") | W21: =IFERROR(subQ!W5/subQ!R5-1,"") | X21: =IFERROR(subQ!X5/subQ!S5-1,"") | Y21: =IFERROR(subQ!Y5/subQ!T5-1,"") | AA21: =IFERROR(subQ!AA5/subQ!V5-1,"") | AB21: =IFERROR(subQ!AB5/subQ!W5-1,"") | AC21: 0.22636362 | AD21: 0.15508325 | AF21: 0.18688378 | AG21: 0.13838021 | AH21: 0.15339426 | AI21: 0.21060379 | AK21: 0.25269506 | AL21: 0.26398303 | AM21: 0.25295681 | AN21: 0.21587486
A22: drv:판관비 | B22: ratio | C22: 판관비율(/매출) | E22: =IFERROR(subQ!E8/subQ!E5,"") | F22: =IFERROR(subQ!F8/subQ!F5,"") | G22: =IFERROR(subQ!G8/subQ!G5,"") | H22: =IFERROR(subQ!H8/subQ!H5,"") | I22: =IFERROR(subQ!I8/subQ!I5,"") | J22: =IFERROR(subQ!J8/subQ!J5,"") | K22: =IFERROR(subQ!K8/subQ!K5,"") | L22: =IFERROR(subQ!L8/subQ!L5,"") | ... AB22: =IFERROR(subQ!AB8/subQ!AB5,"") | AC22: =$D$52 | AD22: =$D$52 | AE22: =IFERROR(subQ!AE8/subQ!AE5,"") | AF22: =$D$52 | AG22: =$D$52 | AH22: =$D$52 | AI22: =$D$52 | AJ22: =IFERROR(subQ!AJ8/subQ!AJ5,"") | AK22: =$D$52 | AL22: =$D$52 | AM22: =$D$52 | AN22: =$D$52 | AO22: =IFERROR(subQ!AO8/subQ!AO5,"")
A23: drv:영업이익 | B23: ratio | C23: 영업이익률(OPM) | E23: =IFERROR(subQ!E9/subQ!E5,"") | F23: =IFERROR(subQ!F9/subQ!F5,"") | G23: =IFERROR(subQ!G9/subQ!G5,"") | H23: =IFERROR(subQ!H9/subQ!H5,"") | I23: =IFERROR(subQ!I9/subQ!I5,"") | J23: =IFERROR(subQ!J9/subQ!J5,"") | K23: =IFERROR(subQ!K9/subQ!K5,"") | L23: =IFERROR(subQ!L9/subQ!L5,"") | ... AB23: =IFERROR(subQ!AB9/subQ!AB5,"") | AC23: 0.15719965 | AD23: 0.15749967 | AE23: =IFERROR(subQ!AE9/subQ!AE5,"") | AF23: 0.15749972 | AG23: 0.15752827 | AH23: 0.15761034 | AI23: 0.15767032 | AJ23: =IFERROR(subQ!AJ9/subQ!AJ5,"") | AK23: 0.15773036 | AL23: 0.15779038 | AM23: 0.15794199 | AN23: 0.15816302 | AO23: =IFERROR(subQ!AO9/subQ!AO5,"")
A24: drv:외환손익 | B24: abs | C24: 외환손익 (가정, 억원) | E24: =subQ!E13 | F24: =subQ!F13 | G24: =subQ!G13 | H24: =subQ!H13 | I24: =subQ!I13 | J24: =subQ!J13 | K24: =subQ!K13 | L24: =subQ!L13 | ... AB24: =subQ!AB13 | AC24: 0 | AD24: 0 | AE24: =subQ!AE13 | AF24: 0 | AG24: 0 | AH24: 0 | AI24: 0 | AJ24: =subQ!AJ13 | AK24: 0 | AL24: 0 | AM24: 0 | AN24: 0 | AO24: =subQ!AO13
A25: drv:파생상품손익 | B25: abs | C25: 파생상품손익 (가정, 억원) | E25: =subQ!E14 | F25: =subQ!F14 | G25: =subQ!G14 | H25: =subQ!H14 | I25: =subQ!I14 | J25: =subQ!J14 | K25: =subQ!K14 | L25: =subQ!L14 | ... AB25: =subQ!AB14 | AC25: 0 | AD25: 0 | AE25: =subQ!AE14 | AF25: 0 | AG25: 0 | AH25: 0 | AI25: 0 | AJ25: =subQ!AJ14 | AK25: 0 | AL25: 0 | AM25: 0 | AN25: 0 | AO25: =subQ!AO14
A26: drv:기타금융손익 | B26: abs | C26: 기타금융손익 (가정, 억원) | E26: =subQ!E15 | F26: =subQ!F15 | G26: =subQ!G15 | H26: =subQ!H15 | I26: =subQ!I15 | J26: =subQ!J15 | K26: =subQ!K15 | L26: =subQ!L15 | ... AB26: =subQ!AB15 | AC26: 0.85 | AD26: 0.85 | AE26: =subQ!AE15 | AF26: 0.85 | AG26: 0.85 | AH26: 0.85 | AI26: 0.85 | AJ26: =subQ!AJ15 | AK26: 0.85 | AL26: 0.85 | AM26: 0.85 | AN26: 0.85 | AO26: =subQ!AO15
A27: drv:기타영업외손익 | B27: abs | C27: 기타영업외손익 (가정, 억원) | E27: =subQ!E16 | F27: =subQ!F16 | G27: =subQ!G16 | H27: =subQ!H16 | I27: =subQ!I16 | J27: =subQ!J16 | K27: =subQ!K16 | L27: =subQ!L16 | ... AB27: =subQ!AB16 | AC27: 0 | AD27: 0 | AE27: =subQ!AE16 | AF27: 0 | AG27: 0 | AH27: 0 | AI27: 0 | AJ27: =subQ!AJ16 | AK27: 0 | AL27: 0 | AM27: 0 | AN27: 0 | AO27: =subQ!AO16
A28: drv:지분법손익 | B28: abs | C28: 지분법손익 (가정, 억원) | E28: =subQ!E17 | F28: =subQ!F17 | G28: =subQ!G17 | H28: =subQ!H17 | I28: =subQ!I17 | J28: =subQ!J17 | K28: =subQ!K17 | L28: =subQ!L17 | ... AB28: =subQ!AB17 | AC28: 0.11 | AD28: 0.11 | AE28: =subQ!AE17 | AF28: 0.11 | AG28: 0.11 | AH28: 0.11 | AI28: 0.11 | AJ28: =subQ!AJ17 | AK28: 0.11 | AL28: 0.11 | AM28: 0.11 | AN28: 0.11 | AO28: =subQ!AO17
A29: drv:법인세비용 | B29: tax | C29: 법인세율(/세전) — 법인세 = MAX(세전,0) × 세율 | E29: =IFERROR(subQ!E19/subQ!E18,"") | F29: =IFERROR(subQ!F19/subQ!F18,"") | G29: =IFERROR(subQ!G19/subQ!G18,"") | H29: =IFERROR(subQ!H19/subQ!H18,"") | I29: =IFERROR(subQ!I19/subQ!I18,"") | J29: =IFERROR(subQ!J19/subQ!J18,"") | K29: =IFERROR(subQ!K19/subQ!K18,"") | L29: =IFERROR(subQ!L19/subQ!L18,"") | ... AB29: =IFERROR(subQ!AB19/subQ!AB18,"") | AC29: =$D$51 | AD29: =$D$51 | AE29: =IFERROR(subQ!AE19/subQ!AE18,"") | AF29: =$D$51 | AG29: =$D$51 | AH29: =$D$51 | AI29: =$D$51 | AJ29: =IFERROR(subQ!AJ19/subQ!AJ18,"") | AK29: =$D$51 | AL29: =$D$51 | AM29: =$D$51 | AN29: =$D$51 | AO29: =IFERROR(subQ!AO19/subQ!AO18,"")
A30: drv:지배주주순이익 | B30: ratio | C30: 지배주주 비중(/당기순이익) | E30: =IFERROR(subQ!E21/subQ!E20,"") | F30: =IFERROR(subQ!F21/subQ!F20,"") | G30: =IFERROR(subQ!G21/subQ!G20,"") | H30: =IFERROR(subQ!H21/subQ!H20,"") | I30: =IFERROR(subQ!I21/subQ!I20,"") | J30: =IFERROR(subQ!J21/subQ!J20,"") | K30: =IFERROR(subQ!K21/subQ!K20,"") | L30: =IFERROR(subQ!L21/subQ!L20,"") | ... AB30: =IFERROR(subQ!AB21/subQ!AB20,"") | AC30: =$D$53 | AD30: =$D$53 | AE30: =IFERROR(subQ!AE21/subQ!AE20,"") | AF30: =$D$53 | AG30: =$D$53 | AH30: =$D$53 | AI30: =$D$53 | AJ30: =IFERROR(subQ!AJ21/subQ!AJ20,"") | AK30: =$D$53 | AL30: =$D$53 | AM30: =$D$53 | AN30: =$D$53 | AO30: =IFERROR(subQ!AO21/subQ!AO20,"")
A31: drv:부채총계 | B31: qoq | C31: 부채총계 QoQ | G31: =IFERROR(subQ!G23/subQ!E23-1,"") | H31: =IFERROR(subQ!H23/subQ!G23-1,"") | I31: =IFERROR(subQ!I23/subQ!H23-1,"") | J31: =IFERROR(subQ!J23/subQ!I23-1,"") | L31: =IFERROR(subQ!L23/subQ!J23-1,"") | M31: =IFERROR(subQ!M23/subQ!L23-1,"") | N31: =IFERROR(subQ!N23/subQ!M23-1,"") | O31: =IFERROR(subQ!O23/subQ!N23-1,"") | Q31: =IFERROR(subQ!Q23/subQ!O23-1,"") | R31: =IFERROR(subQ!R23/subQ!Q23-1,"") | S31: =IFERROR(subQ!S23/subQ!R23-1,"") | T31: =IFERROR(subQ!T23/subQ!S23-1,"") | V31: =IFERROR(subQ!V23/subQ!T23-1,"") | W31: =IFERROR(subQ!W23/subQ!V23-1,"") | X31: =IFERROR(subQ!X23/subQ!W23-1,"") | Y31: =IFERROR(subQ!Y23/subQ!X23-1,"") | AA31: =IFERROR(subQ!AA23/subQ!Y23-1,"") | AB31: =IFERROR(subQ!AB23/subQ!AA23-1,"") | AC31: -6e-09 | AD31: 0 | AF31: 0 | AG31: 0 | AH31: 0 | AI31: 0 | AK31: 0 | AL31: 0 | AM31: 0 | AN31: 0
A32: drv:자본총계 | B32: roll | C32: 자본총계 기타변동(배당 등, 억원) | G32: =IFERROR(subQ!E24+subQ!G20-subQ!G24,"") | H32: =IFERROR(subQ!G24+subQ!H20-subQ!H24,"") | I32: =IFERROR(subQ!H24+subQ!I20-subQ!I24,"") | J32: =IFERROR(subQ!I24+subQ!J20-subQ!J24,"") | L32: =IFERROR(subQ!J24+subQ!L20-subQ!L24,"") | M32: =IFERROR(subQ!L24+subQ!M20-subQ!M24,"") | N32: =IFERROR(subQ!M24+subQ!N20-subQ!N24,"") | O32: =IFERROR(subQ!N24+subQ!O20-subQ!O24,"") | Q32: =IFERROR(subQ!O24+subQ!Q20-subQ!Q24,"") | R32: =IFERROR(subQ!Q24+subQ!R20-subQ!R24,"") | S32: =IFERROR(subQ!R24+subQ!S20-subQ!S24,"") | T32: =IFERROR(subQ!S24+subQ!T20-subQ!T24,"") | V32: =IFERROR(subQ!T24+subQ!V20-subQ!V24,"") | W32: =IFERROR(subQ!V24+subQ!W20-subQ!W24,"") | X32: =IFERROR(subQ!W24+subQ!X20-subQ!X24,"") | Y32: =IFERROR(subQ!X24+subQ!Y20-subQ!Y24,"") | AA32: =IFERROR(subQ!Y24+subQ!AA20-subQ!AA24,"") | AB32: =IFERROR(subQ!AA24+subQ!AB20-subQ!AB24,"") | AC32: 0.002219706 | AD32: 0.001992804 | AF32: -0.00884461 | AG32: 8697.9045 | AH32: 0.004886995 | AI32: -0.001840368 | AK32: -0.001684756 | AL32: 8697.891 | AM32: -0.006822408 | AN32: 0.002582778
A33: drv:지배주주지분 | B33: roll | C33: 지배주주지분 기타변동(배당 등, 억원) | G33: =IFERROR(subQ!E25+subQ!G21-subQ!G25,"") | H33: =IFERROR(subQ!G25+subQ!H21-subQ!H25,"") | I33: =IFERROR(subQ!H25+subQ!I21-subQ!I25,"") | J33: =IFERROR(subQ!I25+subQ!J21-subQ!J25,"") | L33: =IFERROR(subQ!J25+subQ!L21-subQ!L25,"") | M33: =IFERROR(subQ!L25+subQ!M21-subQ!M25,"") | N33: =IFERROR(subQ!M25+subQ!N21-subQ!N25,"") | O33: =IFERROR(subQ!N25+subQ!O21-subQ!O25,"") | Q33: =IFERROR(subQ!O25+subQ!Q21-subQ!Q25,"") | R33: =IFERROR(subQ!Q25+subQ!R21-subQ!R25,"") | S33: =IFERROR(subQ!R25+subQ!S21-subQ!S25,"") | T33: =IFERROR(subQ!S25+subQ!T21-subQ!T25,"") | V33: =IFERROR(subQ!T25+subQ!V21-subQ!V25,"") | W33: =IFERROR(subQ!V25+subQ!W21-subQ!W25,"") | X33: =IFERROR(subQ!W25+subQ!X21-subQ!X25,"") | Y33: =IFERROR(subQ!X25+subQ!Y21-subQ!Y25,"") | AA33: =IFERROR(subQ!Y25+subQ!AA21-subQ!AA25,"") | AB33: =IFERROR(subQ!AA25+subQ!AB21-subQ!AB25,"") | AC33: 0.006392947 | AD33: -0.000733656 | AF33: 0.003949213 | AG33: 8697.9004 | AH33: -0.000320234 | AI33: 0.004160542 | AK33: -0.001710315 | AL33: 8697.9018 | AM33: 0.00551919 | AN33: -0.002624819
A34: drv:총차입금 | B34: qoq | C34: 총차입금 QoQ | G34: =IFERROR(subQ!G26/subQ!E26-1,"") | H34: =IFERROR(subQ!H26/subQ!G26-1,"") | I34: =IFERROR(subQ!I26/subQ!H26-1,"") | J34: =IFERROR(subQ!J26/subQ!I26-1,"") | L34: =IFERROR(subQ!L26/subQ!J26-1,"") | M34: =IFERROR(subQ!M26/subQ!L26-1,"") | N34: =IFERROR(subQ!N26/subQ!M26-1,"") | O34: =IFERROR(subQ!O26/subQ!N26-1,"") | Q34: =IFERROR(subQ!Q26/subQ!O26-1,"") | R34: =IFERROR(subQ!R26/subQ!Q26-1,"") | S34: =IFERROR(subQ!S26/subQ!R26-1,"") | T34: =IFERROR(subQ!T26/subQ!S26-1,"") | V34: =IFERROR(subQ!V26/subQ!T26-1,"") | W34: =IFERROR(subQ!W26/subQ!V26-1,"") | X34: =IFERROR(subQ!X26/subQ!W26-1,"") | Y34: =IFERROR(subQ!Y26/subQ!X26-1,"") | AA34: =IFERROR(subQ!AA26/subQ!Y26-1,"") | AB34: =IFERROR(subQ!AB26/subQ!AA26-1,"") | AC34: 1.04e-07 | AD34: 0 | AF34: 0 | AG34: 0 | AH34: 0 | AI34: 0 | AK34: 0 | AL34: 0 | AM34: 0 | AN34: 0
A35: drv:순차입금 | B35: qoq | C35: 순차입금 QoQ | G35: =IFERROR(subQ!G27/subQ!E27-1,"") | H35: =IFERROR(subQ!H27/subQ!G27-1,"") | I35: =IFERROR(subQ!I27/subQ!H27-1,"") | J35: =IFERROR(subQ!J27/subQ!I27-1,"") | L35: =IFERROR(subQ!L27/subQ!J27-1,"") | M35: =IFERROR(subQ!M27/subQ!L27-1,"") | N35: =IFERROR(subQ!N27/subQ!M27-1,"") | O35: =IFERROR(subQ!O27/subQ!N27-1,"") | Q35: =IFERROR(subQ!Q27/subQ!O27-1,"") | R35: =IFERROR(subQ!R27/subQ!Q27-1,"") | S35: =IFERROR(subQ!S27/subQ!R27-1,"") | T35: =IFERROR(subQ!T27/subQ!S27-1,"") | V35: =IFERROR(subQ!V27/subQ!T27-1,"") | W35: =IFERROR(subQ!W27/subQ!V27-1,"") | X35: =IFERROR(subQ!X27/subQ!W27-1,"") | Y35: =IFERROR(subQ!Y27/subQ!X27-1,"") | AA35: =IFERROR(subQ!AA27/subQ!Y27-1,"") | AB35: =IFERROR(subQ!AB27/subQ!AA27-1,"") | AC35: 0.098200296 | AD35: 0.091226089 | AF35: 0.086234479 | AG35: 0.028182823 | AH35: 0.08620475 | AI35: 0.084730354 | AK35: 0.083291442 | AL35: 0.039471625 | AM35: 0.082611647 | AN35: 0.079166414
A36: drv:이자발생자산 | B36: qoq | C36: 이자발생자산 QoQ | G36: =IFERROR(subQ!G28/subQ!E28-1,"") | H36: =IFERROR(subQ!H28/subQ!G28-1,"") | I36: =IFERROR(subQ!I28/subQ!H28-1,"") | J36: =IFERROR(subQ!J28/subQ!I28-1,"") | L36: =IFERROR(subQ!L28/subQ!J28-1,"") | M36: =IFERROR(subQ!M28/subQ!L28-1,"") | N36: =IFERROR(subQ!N28/subQ!M28-1,"") | O36: =IFERROR(subQ!O28/subQ!N28-1,"") | Q36: =IFERROR(subQ!Q28/subQ!O28-1,"") | R36: =IFERROR(subQ!R28/subQ!Q28-1,"") | S36: =IFERROR(subQ!S28/subQ!R28-1,"") | T36: =IFERROR(subQ!T28/subQ!S28-1,"") | V36: =IFERROR(subQ!V28/subQ!T28-1,"") | W36: =IFERROR(subQ!W28/subQ!V28-1,"") | X36: =IFERROR(subQ!X28/subQ!W28-1,"") | Y36: =IFERROR(subQ!Y28/subQ!X28-1,"") | AA36: =IFERROR(subQ!AA28/subQ!Y28-1,"") | AB36: =IFERROR(subQ!AB28/subQ!AA28-1,"") | AC36: 0.077852775 | AD36: 0.073688865 | AF36: 0.070794645 | AG36: 0.023470499 | AH36: 0.072121168 | AI36: 0.071818895 | AK36: 0.071449755 | AL36: 0.034234033 | AM36: 0.072012632 | AN36: 0.069691718
A37: drv:현금및현금성자산 | B37: qoq | C37: 현금및현금성자산 QoQ | G37: =IFERROR(subQ!G29/subQ!E29-1,"") | H37: =IFERROR(subQ!H29/subQ!G29-1,"") | I37: =IFERROR(subQ!I29/subQ!H29-1,"") | J37: =IFERROR(subQ!J29/subQ!I29-1,"") | L37: =IFERROR(subQ!L29/subQ!J29-1,"") | M37: =IFERROR(subQ!M29/subQ!L29-1,"") | N37: =IFERROR(subQ!N29/subQ!M29-1,"") | O37: =IFERROR(subQ!O29/subQ!N29-1,"") | Q37: =IFERROR(subQ!Q29/subQ!O29-1,"") | R37: =IFERROR(subQ!R29/subQ!Q29-1,"") | S37: =IFERROR(subQ!S29/subQ!R29-1,"") | T37: =IFERROR(subQ!T29/subQ!S29-1,"") | V37: =IFERROR(subQ!V29/subQ!T29-1,"") | W37: =IFERROR(subQ!W29/subQ!V29-1,"") | X37: =IFERROR(subQ!X29/subQ!W29-1,"") | Y37: =IFERROR(subQ!Y29/subQ!X29-1,"") | AA37: =IFERROR(subQ!AA29/subQ!Y29-1,"") | AB37: =IFERROR(subQ!AB29/subQ!AA29-1,"")
A38: drv:CAPEX | B38: yoy | C38: CAPEX YoY | J38: =IFERROR(subQ!J30/subQ!E30-1,"") | L38: =IFERROR(subQ!L30/subQ!G30-1,"") | M38: =IFERROR(subQ!M30/subQ!H30-1,"") | N38: =IFERROR(subQ!N30/subQ!I30-1,"") | O38: =IFERROR(subQ!O30/subQ!J30-1,"") | Q38: =IFERROR(subQ!Q30/subQ!L30-1,"") | R38: =IFERROR(subQ!R30/subQ!M30-1,"") | S38: =IFERROR(subQ!S30/subQ!N30-1,"") | T38: =IFERROR(subQ!T30/subQ!O30-1,"") | V38: =IFERROR(subQ!V30/subQ!Q30-1,"") | W38: =IFERROR(subQ!W30/subQ!R30-1,"") | X38: =IFERROR(subQ!X30/subQ!S30-1,"") | Y38: =IFERROR(subQ!Y30/subQ!T30-1,"") | AA38: =IFERROR(subQ!AA30/subQ!V30-1,"") | AB38: =IFERROR(subQ!AB30/subQ!W30-1,"") | AC38: -0.051399817 | AD38: -0.1170748 | AF38: 0.14586764 | AG38: 0.057287555 | AH38: 0 | AI38: 0 | AK38: 0 | AL38: 0 | AM38: 0 | AN38: 0
A39: drv:영업활동현금흐름 | B39: yoy | C39: 영업활동현금흐름 YoY | J39: =IFERROR(subQ!J31/subQ!E31-1,"") | L39: =IFERROR(subQ!L31/subQ!G31-1,"") | M39: =IFERROR(subQ!M31/subQ!H31-1,"") | N39: =IFERROR(subQ!N31/subQ!I31-1,"") | O39: =IFERROR(subQ!O31/subQ!J31-1,"") | Q39: =IFERROR(subQ!Q31/subQ!L31-1,"") | R39: =IFERROR(subQ!R31/subQ!M31-1,"") | S39: =IFERROR(subQ!S31/subQ!N31-1,"") | T39: =IFERROR(subQ!T31/subQ!O31-1,"") | V39: =IFERROR(subQ!V31/subQ!Q31-1,"") | W39: =IFERROR(subQ!W31/subQ!R31-1,"") | X39: =IFERROR(subQ!X31/subQ!S31-1,"") | Y39: =IFERROR(subQ!Y31/subQ!T31-1,"") | AA39: =IFERROR(subQ!AA31/subQ!V31-1,"") | AB39: =IFERROR(subQ!AB31/subQ!W31-1,"")
A40: drv:주식수 | B40: qoq | C40: 주식수 QoQ | G40: =IFERROR(subQ!G32/subQ!E32-1,"") | H40: =IFERROR(subQ!H32/subQ!G32-1,"") | I40: =IFERROR(subQ!I32/subQ!H32-1,"") | J40: =IFERROR(subQ!J32/subQ!I32-1,"") | L40: =IFERROR(subQ!L32/subQ!J32-1,"") | M40: =IFERROR(subQ!M32/subQ!L32-1,"") | N40: =IFERROR(subQ!N32/subQ!M32-1,"") | O40: =IFERROR(subQ!O32/subQ!N32-1,"") | Q40: =IFERROR(subQ!Q32/subQ!O32-1,"") | R40: =IFERROR(subQ!R32/subQ!Q32-1,"") | S40: =IFERROR(subQ!S32/subQ!R32-1,"") | T40: =IFERROR(subQ!T32/subQ!S32-1,"") | V40: =IFERROR(subQ!V32/subQ!T32-1,"") | W40: =IFERROR(subQ!W32/subQ!V32-1,"") | X40: =IFERROR(subQ!X32/subQ!W32-1,"") | Y40: =IFERROR(subQ!Y32/subQ!X32-1,"") | AA40: =IFERROR(subQ!AA32/subQ!Y32-1,"") | AB40: =IFERROR(subQ!AB32/subQ!AA32-1,"") | AC40: 0 | AD40: 0 | AF40: 0 | AG40: 0 | AH40: 0 | AI40: 0 | AK40: 0 | AL40: 0 | AM40: 0 | AN40: 0
A41: drv:DPS | B41: abs | C41: DPS (가정, 원) | E41: =subQ!E35 | F41: =subQ!F35 | G41: =subQ!G35 | H41: =subQ!H35 | I41: =subQ!I35 | J41: =subQ!J35 | K41: =subQ!K35 | L41: =subQ!L35 | ... AB41: =subQ!AB35 | AD41: 12300 | AE41: =subQ!AE35 | AI41: 12300 | AJ41: =subQ!AJ35 | AN41: 12300 | AO41: =subQ!AO35
...

Sheet BS연결
B1: (백만원) | C1: 이름: BS연결H | E1: 4Q21 | F1: 2021 | G1: 1Q22 | H1: 2Q22 | I1: 3Q22 | J1: 4Q22 | K1: 2022 | L1: 1Q23 | M1: 2Q23 | N1: 3Q23 | O1: 4Q23 | P1: 2023 | Q1: 1Q24 | R1: 2Q24 | S1: 3Q24 | T1: 4Q24 | U1: 2024 | V1: 1Q25 | W1: 2Q25 | X1: 3Q25 | Y1: 4Q25 | Z1: 2025 | AA1: 1Q26 | AB1: 2Q26 | AC1: 3Q26 | AD1: 4Q26 | AE1: 2026 | AF1: 1Q27 | AG1: 2Q27 | AH1: 3Q27 | AI1: 4Q27 | AJ1: 2027 | AK1: 1Q28 | AL1: 2Q28 | AM1: 3Q28 | AN1: 4Q28 | AO1: 2028
B2: 연결 | D2: fin json(kship_fin.py)
B3: HD한국조선해양(연) | C3: UPDATE: 26-10-12 | E3: 1 | F3: 2 | G3: 3 | H3: 4 | I3: 5 | J3: 6 | K3: 7 | L3: 8 | M3: 9 | N3: 10 | O3: 11 | P3: 12 | Q3: 13 | R3: 14 | S3: 15 | T3: 16 | U3: 17 | V3: 18 | W3: 19 | X3: 20 | Y3: 21 | Z3: 22 | AA3: 23 | AB3: 24 | AC3: 25 | AD3: 26 | AE3: 27 | AF3: 28 | AG3: 29 | AH3: 30 | AI3: 31 | AJ3: 32 | AK3: 33 | AL3: 34 | AM3: 35 | AN3: 36 | AO3: 37
B4: Account Code | C4: AccountNAME | E4: 2021.12 | F4: 2021.12A | G4: 2022.03 | H4: 2022.06 | I4: 2022.09 | J4: 2022.12 | K4: 2022.12A | L4: 2023.03 | M4: 2023.06 | N4: 2023.09 | O4: 2023.12 | P4: 2023.12A | Q4: 2024.03 | R4: 2024.06 | S4: 2024.09 | T4: 2024.12 | U4: 2024.12A | V4: 2025.03 | W4: 2025.06 | X4: 2025.09 | Y4: 2025.12 | Z4: 2025.12A | AA4: 2026.03 | AB4: 2026.06 | AC4: 2026.09 | AD4: 2026.12 | AE4: 2026.12A | AF4: 2027.03 | AG4: 2027.06 | AH4: 2027.09 | AI4: 2027.12 | AJ4: 2027.12A | AK4: 2028.03 | AL4: 2028.06 | AM4: 2028.09 | AN4: 2028.12 | AO4: 2028.12A
A5: 1 | C5: 유동자산 | E5: 14562196 | F5: 14562196 | G5: 15055674 | H5: 16265600 | I5: 18102306 | J5: 15775914 | K5: 15775914 | L5: 16219644 | M5: 17381113 | N5: 18479102 | O5: 17735127 | P5: 17735127 | Q5: 17895153 | R5: 18247451 | S5: 17264688 | T5: 20431356 | U5: 20431356 | V5: 23289377 | W5: 22015176 | X5: 23057853 | Y5: 23424478 | Z5: 23424478 | AA5: 25710146 | AB5: 30170024
A6: 1 | C6: 현금및현금성자산 | E6: 4567468.1 | F6: 4567468.1 | G6: 4532301.5 | H6: 4752961.1 | I6: 3634472.2 | J6: 2697222.9 | K6: 2697222.9 | L6: 2852572.6 | M6: 4270309.7 | N6: 4035501.8 | O6: 3018391 | P6: 3018391 | Q6: 3669603.9 | R6: 3397850.3 | S6: 2543376.7 | T6: 3717319 | U6: 3717319 | V6: 5600443.1 | W6: 5513834 | X6: 4709370.9 | Y6: 3742015.5 | Z6: 3742015.5 | AA6: 6468672.8 | AB6: 10995975
A7: 1 | C7: 단기금융상품 | E7: 660027.77 | F7: 660027.77 | G7: 754500.51 | H7: 628361.61 | I7: 1443706 | J7: 1304041.5 | K7: 1304041.5 | L7: 1170875.3 | M7: 341542.35 | N7: 1057491.3 | O7: 1595618.7 | P7: 1595618.7 | Q7: 983649.16 | R7: 1815275.1 | S7: 1764395.1 | T7: 1922179.2 | U7: 1922179.2 | V7: 2454897.5 | W7: 2705949.6 | Y7: 4434581.4 | Z7: 4434581.4 | AA7: 3267664.3 | AB7: 2596829.4
A8: 1 | C8: 단기금융자산 | E8: 848060.65 | F8: 848060.65 | G8: 1023391.7 | H8: 1212233.1 | I8: 2701185.8 | J8: 1818718 | K8: 1818718 | L8: 1747798.9 | M8: 908706.84 | N8: 1735702.7 | O8: 2025013.7 | P8: 2025013.7 | Q8: 1570842.6 | R8: 2558446.5 | S8: 2204130 | T8: 3115653.6 | U8: 3115653.6 | V8: 3472603.2 | W8: 3153286.3 | Y8: 5125708 | Z8: 5125708 | AA8: 4427782.3 | AB8: 3984024
A9: 1 | C9: 매출채권및기타채권 | E9: 1067698 | F9: 1067698 | G9: 1055271 | H9: 1573082 | I9: 1344506.2 | J9: 1026706.3 | K9: 1026706.3 | L9: 1132897.1 | M9: 1112498.9 | N9: 1320685.2 | O9: 1460128.9 | P9: 1460128.9 | Q9: 1444969.5 | R9: 1458522.8 | S9: 1555797 | T9: 1640342.8 | U9: 1640342.8 | V9: 2061517.4 | W9: 1643448.5 | Y9: 1812029.6 | Z9: 1812029.6 | AA9: 1768844.4 | AB9: 1829787.4
A10: 1 | C10: 계약자산 | E10: 5502878.4 | F10: 5502878.4 | G10: 5712921.8 | H10: 5787753.5 | I10: 6879969.6 | J10: 6435957.2 | K10: 6435957.2 | L10: 6404863.5 | M10: 7005608 | N10: 7080262.7 | O10: 7156818.3 | P10: 7156818.3 | Q10: 6962382.6 | R10: 6693699.4 | S10: 6527921.7 | T10: 7503003.9 | U10: 7503003.9 | V10: 7050616.6 | W10: 6667632.2 | Y10: 7738830.4 | Z10: 7738830.4 | AA10: 8059754 | AB10: 8242620
A11: 1 | C11: 재고자산 | E11: 1554136.7 | F11: 1554136.7 | G11: 1626869.9 | H11: 1750576.8 | I11: 2176607 | J11: 2203316.6 | K11: 2203316.6 | L11: 2229702.4 | M11: 2141559 | N11: 2174245.4 | O11: 2005664.7 | P11: 2005664.7 | Q11: 2216194 | R11: 2128191.8 | S11: 2337487.5 | T11: 2232067 | U11: 2232067 | V11: 2368177.5 | W11: 2477601.5 | Y11: 2765843.2 | Z11: 2765843.2 | AA11: 2943570.7 | AB11: 3168879.3
A12: 1 | C12: 유동파생상품자산 | E12: 14528.49 | F12: 14528.49 | G12: 40303.62 | H12: 69900.57 | I12: 131143.12 | J12: 169837.01 | K12: 169837.01 | L12: 130245.86 | M12: 122965.27 | N12: 112831.45 | O12: 143267.3 | P12: 143267.3 | Q12: 36191.34 | R12: 5407.3 | S12: 98613.01 | T12: 1162.39 | U12: 1162.39 | V12: 2661.44 | W12: 93986.32 | Y12: 13602.67 | Z12: 13602.67 | AA12: 89255.86 | AB12: 99637.62
A13: 1 | C13: 유동확정계약자산 | E13: 173504.39 | F13: 173504.39 | G13: 228587.54 | H13: 513970.96 | I13: 1126336.7 | J13: 344839.51 | K13: 344839.51 | L13: 446677.76 | M13: 444199.22 | N13: 565379.94 | O13: 286127.7 | P13: 286127.7 | Q13: 551002.12 | R13: 737764.03 | S13: 341121.84 | T13: 1192312 | U13: 1192312 | V13: 1015044.2 | W13: 353350.45 | Y13: 677523.87 | Z13: 677523.87 | AA13: 1070862.1 | AB13: 1287557
A14: 1 | C14: 당기법인세자산(선급법인세) | E14: 7762.97 | F14: 7762.97 | G14: 9212.23 | H14: 3680.53 | I14: 6557.67 | J14: 12589.48 | K14: 12589.48 | L14: 18492.13 | M14: 12413.62 | N14: 18160.32 | O14: 22350.22 | P14: 22350.22 | Q14: 29131.28 | R14: 7152.74 | S14: 8924.7 | T14: 6101.77 | U14: 6101.77 | V14: 6733.31 | W14: 1280.41 | X14: 1801.9 | Y14: 657.63 | Z14: 657.63 | AA14: 937.65 | AB14: 4935.35
A15: 1 | C15: 매각예정비유동자산및처분자산 | E15: 13082.98 | F15: 13082.98 | O15: 0 | P15: 0 | T15: 63000.19 | U15: 63000.19 | V15: 0 | W15: 4626.85 | X15: 4626.85 | Y15: 0 | Z15: 0
A16: 1 | C16: 기타유동자산 | E16: 1001108.2 | F16: 1001108.2 | G16: 1095706.1 | H16: 1185313.4 | I16: 1359007.1 | J16: 1581403.8 | K16: 1581403.8 | L16: 1833316.8 | M16: 1930017.4 | N16: 2114544.3 | O16: 2046760.4 | P16: 2046760.4 | Q16: 2002029.1 | R16: 2003587.1 | S16: 2087050.3 | T16: 2153868.2 | U16: 2153868.2 | V16: 2729285.8 | W16: 2553466.2 | X16: 2296629.1 | Y16: 2239393.5 | Z16: 2239393.5 | AA16: 2040584.5 | AB16: 1943802.9
A17: 1 | C17: 비유동자산 | E17: 12730898 | F17: 12730898 | G17: 12885645 | H17: 13656117 | I17: 15015790 | J17: 14107562 | K17: 14107562 | L17: 14226195 | M17: 14255866 | N17: 14754484 | O17: 14507441 | P17: 14507441 | Q17: 14614725 | R17: 14898039 | S17: 14761399 | T17: 16287781 | U17: 16287781 | V17: 16198822 | W17: 15258250 | X17: 15369660 | Y17: 16117735 | Z17: 16117735 | AA17: 16494705 | AB17: 16554812
A18: 1 | C18: 종속기업및관계기업투자 | E18: 321972.07 | F18: 321972.07 | G18: 282267.2 | H18: 281742.73 | I18: 281165.27 | J18: 269723.77 | K18: 269723.77 | L18: 267612.72 | M18: 251483.65 | N18: 264976.49 | O18: 308959.16 | P18: 308959.16 | Q18: 307392.06 | R18: 315049.24 | S18: 298341.77 | T18: 256615.05 | U18: 256615.05 | V18: 255282.18 | W18: 202951.54 | X18: 205915.58 | Y18: 206177.77 | Z18: 206177.77 | AA18: 210058.58 | AB18: 241306.88
A19: 1 | C19: 투자자산 | E19: 801835.8 | F19: 801835.8 | G19: 802175.67 | H19: 1408967.6 | I19: 2676341.8 | J19: 1152709.6 | K19: 1152709.6 | L19: 1197562.3 | M19: 1102008.5 | N19: 1245718.7 | O19: 970881.11 | P19: 970881.11 | Q19: 1076455.8 | R19: 1361295.8 | S19: 872964.91 | T19: 2164452.7 | U19: 2164452.7 | V19: 2109994.4 | W19: 1034095.4 | X19: 1261608.8 | Y19: 1591674.3 | Z19: 1591674.3 | AA19: 2312047.5 | AB19: 2393703.1
A20: 1 | C20: 장기금융자산 | E20: 194920.08 | F20: 194920.08 | G20: 235680.99 | H20: 208361.52 | I20: 177758.22 | J20: 201294.94 | K20: 201294.94 | L20: 215008.15 | M20: 237145.51 | N20: 219067.27 | O20: 232714.3 | P20: 232714.3 | Q20: 137208.8 | R20: 133134.52 | S20: 138455.85 | T20: 141591.46 | U20: 141591.46 | V20: 141428.37 | W20: 147247.45 | X20: 126454.09 | Y20: 139177.02 | Z20: 139177.02 | AA20: 145896.86 | AB20: 148784.66
A21: 1 | C21: 장기매출채권및기타채권 | E21: 150019.08 | F21: 150019.08 | G21: 195653.54 | H21: 236188.38 | I21: 313969.69 | J21: 250490.03 | K21: 250490.03 | L21: 285803.88 | M21: 280599.39 | N21: 302394.19 | O21: 252258.03 | P21: 252258.03 | Q21: 268320.59 | R21: 257891.23 | S21: 225234.83 | T21: 192697.65 | U21: 192697.65 | V21: 161356.45 | W21: 143599.44 | X21: 161208.64 | Y21: 119081.38 | Z21: 119081.38 | AA21: 117875.42 | AB21: 119370.5
A22: 1 | C22: 투자부동산 | E22: 231498.68 | F22: 231498.68 | G22: 225622.29 | H22: 224549.19 | I22: 223488.64 | J22: 222373.89 | K22: 222373.89 | L22: 221330.1 | M22: 220618.67 | N22: 219477.79 | O22: 218330.34 | P22: 218330.34 | Q22: 217398.32 | R22: 218390.88 | S22: 303038.83 | T22: 216566.15 | U22: 216566.15 | V22: 215397.29 | W22: 209622.31 | X22: 208545.68 | Y22: 130204.19 | Z22: 130204.19 | AA22: 129671.2 | AB22: 129057.01
A23: 1 | C23: 유형자산 | E23: 9872012 | F23: 9872012 | G23: 9879817.2 | H23: 9957200 | I23: 10083239 | J23: 10143113 | K23: 10143113 | L23: 10201693 | M23: 10321642 | N23: 10432116 | O23: 10503503 | P23: 10503503 | Q23: 10565402 | R23: 10687802 | S23: 10912699 | T23: 11110890 | U23: 11110890 | V23: 11299189 | W23: 11703121 | X23: 11816084 | Y23: 12025455 | Z23: 12025455 | AA23: 12036472 | AB23: 12153874
A24: 1 | C24: 사용권자산 | E24: 51714.13 | F24: 51714.13 | G24: 51765.05 | H24: 52033.52 | I24: 50187.03 | J24: 108493.82 | K24: 108493.82 | L24: 105249.25 | M24: 101373.99 | N24: 101968.75 | O24: 100432.71 | P24: 100432.71 | Q24: 98673.55 | R24: 93883.53 | S24: 87771.76 | T24: 484619.59 | U24: 484619.59 | V24: 480902.57 | W24: 443820.01 | X24: 449018.49 | Y24: 444896.48 | Z24: 444896.48 | AA24: 466872.33 | AB24: 463343.92
A25: 1 | C25: 기타비유동자산 | E25: 112078.03 | F25: 112078.03 | G25: 132621.87 | H25: 132318.96 | I25: 107703.57 | J25: 674090.26 | K25: 674090.26 | L25: 653237.61 | M25: 665461.79 | N25: 649765.75 | O25: 646909.4 | P25: 646909.4 | Q25: 620001.9 | R25: 623381.95 | S25: 604777.8 | T25: 843653.05 | U25: 843653.05 | V25: 790617.88 | W25: 719843.18 | X25: 692160.01 | Y25: 1012788 | Z25: 1012788 | AA25: 1003419.4 | AB25: 973342.54
A26: 1 | C26: 무형자산 | E26: 133535.87 | F26: 133535.87 | G26: 136254.92 | H26: 138643.79 | I26: 149354.67 | J26: 163697.16 | K26: 163697.16 | L26: 170964.98 | M26: 178935.63 | N26: 193535.36 | O26: 190793.08 | P26: 190793.08 | Q26: 195077.65 | R26: 201972.64 | S26: 322022.47 | T26: 374650.95 | U26: 374650.95 | V26: 384210.88 | W26: 391727.87 | X26: 395543.78 | Y26: 519011.46 | Z26: 519011.46 | AA26: 531927.3 | AB26: 539665.72
A27: 1 | C27: 비유동파생상품자산 | E27: 44764.33 | F27: 44764.33 | G27: 66274.52 | H27: 89606.57 | I27: 168984.18 | J27: 388939.41 | K27: 388939.41 | L27: 191238.26 | M27: 213250.54 | N27: 122759.99 | O27: 250805.05 | P27: 250805.05 | Q27: 84685.04 | R27: 54772.17 | S27: 138915.2 | T27: 64055.7 | U27: 64055.7 | V27: 66263.49 | W27: 316839.19 | X27: 110578.23 | Y27: 102577.92 | Z27: 102577.92 | AA27: 2877.08 | AB27: 8557.09
... A48: 1 | C48: 장기매입채무및기타채무 | E48: 9250.1 | F48: 9250.1 | G48: 8831.59 | H48: 8781.95 | I48: 8858.45 | J48: 9225.66 | K48: 9225.66 | L48: 9211.51 | M48: 9584.18 | N48: 20102.28 | O48: 25747.46 | P48: 25747.46 | Q48: 25232.09 | R48: 26760.8 | S48: 28666.04 | T48: 34511.49 | U48: 34511.49 | V48: 36016.99 | W48: 38222.24 | X48: 39955.89 | Y48: 47062.97 | Z48: 47062.97 | AA48: 51962.92 | AB48: 55137.06
A49: 1 | C49: 확정급여부채 | E49: 59562.11 | F49: 59562.11 | G49: 61543.54 | H49: 63183.42 | I49: 69800.12 | J49: 52628.12 | K49: 52628.12 | L49: 53467.39 | M49: 53546.75 | N49: 55321.96 | O49: 55801.68 | P49: 55801.68 | Q49: 55680.39 | R49: 56114.38 | S49: 57783.47 | T49: 58441.45 | U49: 58441.45 | V49: 49324.45 | X49: 55801.36 | Y49: 44333.5 | Z49: 44333.5 | AA49: 45958.51 | AB49: 46936.6
A50: 1 | C50: 장기충당부채 | E50: 319090.17 | F50: 319090.17 | G50: 331684.26 | H50: 347164.85 | I50: 373963.69 | J50: 321790.6 | K50: 321790.6 | L50: 284280.93 | M50: 305307.22 | N50: 310159.9 | O50: 84658.17 | P50: 84658.17 | Q50: 85260.02 | R50: 96962.37 | S50: 105491.03 | T50: 102619.02 | U50: 102619.02 | V50: 108322.92 | W50: 104717.99 | X50: 103721.5 | Y50: 111316.77 | Z50: 111316.77 | AA50: 116754.78 | AB50: 115934.98
A51: 1 | C51: 장기파생상품부채 | E51: 247054.35 | F51: 247054.35 | G51: 255840.72 | H51: 839810.35 | I51: 2055965.3 | J51: 620301.51 | K51: 620301.51 | L51: 696697.59 | M51: 598464.87 | N51: 737100.8 | O51: 420577.57 | P51: 420577.57 | Q51: 607755.24 | R51: 875928.12 | S51: 411294.18 | T51: 1702277.5 | U51: 1702277.5 | V51: 1650110.6 | W51: 650880.45 | X51: 886912.66 | Y51: 1191846.7 | Z51: 1191846.7 | AA51: 1975136.2 | AB51: 2023765.8
A52: 1 | C52: 이연법인세부채 | E52: 59054.29 | F52: 59054.29 | G52: 66758.77 | H52: 77088.05 | I52: 59882.13 | J52: 1271.5 | K52: 1271.5 | L52: 1275.13 | M52: 1269.4 | N52: 830.74 | O52: 1478.77 | P52: 1478.77 | Q52: 1480.35 | R52: 4856.14 | S52: 20961.24 | T52: 1192.62 | U52: 1192.62 | V52: 1955.34 | W52: 1236.06 | X52: 5608.62 | Y52: 4532.74 | Z52: 4532.74 | AA52: 13819.71 | AB52: 158187.18
A53: 1 | C53: 부채총계 | E53: 14879339 | F53: 14879339 | G53: 15772766 | H53: 17715884 | I53: 20603881 | J53: 17571346 | K53: 17571346 | L53: 18180091 | M53: 19346745 | N53: 20615317 | O53: 19872465 | P53: 19872465 | Q53: 19951678 | R53: 19926316 | S53: 18454669 | T53: 22563324 | U53: 22563324 | V53: 25016945 | W53: 21968154 | X53: 22475233 | Y53: 22633860 | Z53: 22633860 | AA53: 24888295 | AB53: 27800917
A54: 1 | C54: 지배주주지분 | E54: 9856559.1 | F54: 9856559.1 | G54: 9659384.5 | H54: 9587848.4 | I54: 9801730.9 | J54: 9714919.2 | K54: 9714919.2 | L54: 9682086.6 | M54: 9728327.2 | N54: 10048549 | O54: 9903690.5 | P54: 9903690.5 | Q54: 10086862 | R54: 10518174 | S54: 10671554 | T54: 11099427 | U54: 11099427 | V54: 11369215 | W54: 11994279 | X54: 12437819 | Y54: 13286078 | Z54: 13286078 | AA54: 13549753 | AB54: 14829924
A55: 1 | C55: 자본금 | E55: 353865.58 | F55: 353865.58 | G55: 353865.58 | H55: 353865.58 | I55: 353865.58 | J55: 353865.58 | K55: 353865.58 | L55: 353865.58 | M55: 353865.58 | N55: 353865.58 | O55: 353865.58 | P55: 353865.58 | Q55: 353865.58 | R55: 353865.58 | S55: 353865.58 | T55: 353865.58 | U55: 353865.58 | V55: 353865.58 | W55: 353865.58 | X55: 353865.58 | Y55: 353865.58 | Z55: 353865.58 | AA55: 353865.58 | AB55: 353865.58
A56: 1 | C56: 자본잉여금 | E56: 2400507.2 | F56: 2400507.2 | G56: 2400507.2 | H56: 2467505.9 | I56: 2467505.9 | J56: 2467505.9 | K56: 2467505.9 | L56: 2466883.3 | M56: 2461903.5 | N56: 2459463.7 | O56: 2459694.6 | P56: 2459694.6 | Q56: 2458941.5 | R56: 2599805.7 | S56: 2599768.7 | T56: 2599782.4 | U56: 2599782.4 | V56: 2599782.2 | W56: 2722590.6 | X56: 2762402.1 | Y56: 3016775.3 | Z56: 3016775.3 | AA56: 3043385 | AB56: 3026446.4
A57: 1 | C57: 기타자본 | E57: -8697362.6 | F57: -8697362.6 | G57: -8703261.5 | H57: -8703261.5 | I57: -8703261.5 | J57: -8703261.5 | K57: -8703261.5 | L57: -8608510 | M57: -8608510 | N57: -8609897.3 | O57: -8609897.2 | P57: -8609897.2 | Q57: -8609897.2 | R57: -8609897.2 | S57: -8609184.6 | T57: -8609021.4 | U57: -8609021.4 | V57: -8488512.3 | W57: -8526891.1 | X57: -8541364.9 | Y57: -8608784.6 | Z57: -8608784.6 | AA57: -8608763.7 | AB57: -8615335.2
A58: 1 | C58: 기타포괄이익누계액 | E58: 1332378.6 | F58: 1332378.6 | G58: 1340687.2 | H58: 1324023.6 | I58: 1307202.8 | J58: 1296442.4 | K58: 1296442.4 | L58: 1307514.1 | M58: 1329368.2 | N58: 1315646.3 | O58: 1325567.8 | P58: 1325567.8 | Q58: 1652051.9 | R58: 1649300.6 | S58: 1650953.5 | T58: 1670921 | U58: 1670921 | V58: 1684934.6 | W58: 1867347.2 | X58: 1886836.1 | Y58: 1856691.8 | Z58: 1856691.8 | AA58: 1892972.7 | AB58: 1906187.6
A59: 1 | C59: 이익잉여금 | E59: 14467170 | F59: 14467170 | G59: 14267586 | H59: 14145715 | I59: 14376418 | J59: 14300367 | K59: 14300367 | L59: 14162334 | M59: 14191700 | N59: 14529471 | O59: 14374460 | P59: 14374460 | Q59: 14231900 | R59: 14525099 | S59: 14676151 | T59: 15083879 | U59: 15083879 | V59: 15219145 | W59: 15577366 | X59: 15976080 | Y59: 16667530 | Z59: 16667530 | AA59: 16868293 | AB59: 18158759
A60: 1 | C60: 비지배주주지분 | E60: 2557196.2 | F60: 2557196.2 | G60: 2509168 | H60: 2617984.7 | I60: 2712483.6 | J60: 2597210.6 | K60: 2597210.6 | L60: 2583661.1 | M60: 2561907.6 | N60: 2569720.5 | O60: 2466412.4 | P60: 2466412.4 | Q60: 2471338.2 | R60: 2700999.5 | S60: 2899864.4 | T60: 3056386.1 | U60: 3056386.1 | V60: 3102040.3 | W60: 3310993.3 | X60: 3514460.7 | Y60: 3622275.1 | Z60: 3622275.1 | AA60: 3766804.1 | AB60: 4093996.1
...

Sheet BS별도
B1: (백만원) | C1: 이름: BS별도H | E1: 4Q21 | F1: 2021 | G1: 1Q22 | H1: 2Q22 | I1: 3Q22 | J1: 4Q22 | K1: 2022 | L1: 1Q23 | M1: 2Q23 | N1: 3Q23 | O1: 4Q23 | P1: 2023 | Q1: 1Q24 | R1: 2Q24 | S1: 3Q24 | T1: 4Q24 | U1: 2024 | V1: 1Q25 | W1: 2Q25 | X1: 3Q25 | Y1: 4Q25 | Z1: 2025 | AA1: 1Q26 | AB1: 2Q26 | AC1: 3Q26 | AD1: 4Q26 | AE1: 2026 | AF1: 1Q27 | AG1: 2Q27 | AH1: 3Q27 | AI1: 4Q27 | AJ1: 2027 | AK1: 1Q28 | AL1: 2Q28 | AM1: 3Q28 | AN1: 4Q28 | AO1: 2028
B2: 별도 | D2: fin json(kship_fin.py)
B3: HD한국조선해양(별) | C3: UPDATE: 26-10-12 | E3: 1 | F3: 2 | G3: 3 | H3: 4 | I3: 5 | J3: 6 | K3: 7 | L3: 8 | M3: 9 | N3: 10 | O3: 11 | P3: 12 | Q3: 13 | R3: 14 | S3: 15 | T3: 16 | U3: 17 | V3: 18 | W3: 19 | X3: 20 | Y3: 21 | Z3: 22 | AA3: 23 | AB3: 24 | AC3: 25 | AD3: 26 | AE3: 27 | AF3: 28 | AG3: 29 | AH3: 30 | AI3: 31 | AJ3: 32 | AK3: 33 | AL3: 34 | AM3: 35 | AN3: 36 | AO3: 37
B4: Account Code | C4: AccountNAME | E4: 2021.12 | F4: 2021.12A | G4: 2022.03 | H4: 2022.06 | I4: 2022.09 | J4: 2022.12 | K4: 2022.12A | L4: 2023.03 | M4: 2023.06 | N4: 2023.09 | O4: 2023.12 | P4: 2023.12A | Q4: 2024.03 | R4: 2024.06 | S4: 2024.09 | T4: 2024.12 | U4: 2024.12A | V4: 2025.03 | W4: 2025.06 | X4: 2025.09 | Y4: 2025.12 | Z4: 2025.12A | AA4: 2026.03 | AB4: 2026.06 | AC4: 2026.09 | AD4: 2026.12 | AE4: 2026.12A | AF4: 2027.03 | AG4: 2027.06 | AH4: 2027.09 | AI4: 2027.12 | AJ4: 2027.12A | AK4: 2028.03 | AL4: 2028.06 | AM4: 2028.09 | AN4: 2028.12 | AO4: 2028.12A
A5: 1 | C5: 유동자산 | E5: 1840381.4 | F5: 1840381.4 | G5: 1856263.8 | H5: 2050674.6 | I5: 2087178.4 | J5: 2118469.8 | K5: 2118469.8 | L5: 1727843.4 | M5: 1672166.8 | N5: 1677075.3 | O5: 1654502 | P5: 1654502 | Q5: 1712155.7 | R5: 2109640.5 | S5: 1966992.4 | T5: 2027133.8 | U5: 2027133.8 | V5: 3018511.1 | W5: 2817273 | X5: 2882373.3 | Y5: 2835643.6 | Z5: 2835643.6 | AA5: 3338945.9 | AB5: 5422003.5
A6: 1 | C6: 현금및현금성자산 | E6: 1449872.8 | F6: 1449872.8 | G6: 1326479.7 | H6: 1775968.1 | I6: 901998.02 | J6: 987479.94 | K6: 987479.94 | L6: 689692.8 | M6: 1418830.9 | N6: 676696.94 | O6: 505091.26 | P6: 505091.26 | Q6: 1002357.4 | R6: 642852.35 | S6: 512854.16 | T6: 762696.86 | U6: 762696.86 | V6: 1042446.7 | W6: 925455.71 | X6: 781737.44 | Y6: 523688.18 | Z6: 523688.18 | AA6: 761392.15 | AB6: 3145869
A7: 1 | C7: 단기금융상품 | E7: 350500 | F7: 350500 | G7: 490500 | H7: 240500 | I7: 1132793.3 | J7: 1061789.8 | K7: 1061789.8 | L7: 942071.23 | M7: 140500 | N7: 850510.21 | O7: 950500 | P7: 950500 | Q7: 540500 | R7: 1246862.1 | S7: 1249327.4 | T7: 980500 | U7: 980500 | V7: 1230000 | W7: 1420000 | X7: 1610000 | Y7: 1530000 | Z7: 1530000 | AA7: 1050000 | AB7: 1151027
A8: 1 | C8: 단기금융자산 | E8: 350500 | F8: 350500 | G8: 490500 | H8: 240500 | I8: 1132793.3 | J8: 1061789.8 | K8: 1061789.8 | L8: 942071.23 | M8: 140500 | N8: 850510.21 | O8: 950500 | P8: 950500 | Q8: 540500 | R8: 1246862.1 | S8: 1249327.4 | T8: 980500 | U8: 980500 | V8: 1230000 | W8: 1420000 | X8: 1610000 | Y8: 1530000 | Z8: 1530000 | AA8: 1050000 | AB8: 1151027
A9: 1 | C9: 매출채권및기타채권 | E9: 27520.26 | F9: 27520.26 | G9: 25121.81 | H9: 21390.79 | I9: 39034.75 | J9: 52635.81 | K9: 52635.81 | L9: 59789.2 | M9: 57352.16 | N9: 75781.77 | O9: 105934.61 | P9: 105934.61 | Q9: 55247.88 | R9: 110808.05 | S9: 73075.22 | T9: 142205.89 | U9: 142205.89 | V9: 537659.34 | W9: 174536.58 | X9: 158454.22 | Y9: 345911.87 | Z9: 345911.87 | AA9: 912986.66 | AB9: 375257.14
A10: 1 | C10: 계약자산 | E10: 904.65 | F10: 904.65 | G10: 9190 | H10: 10220.26 | I10: 10655.27 | J10: 850.84 | K10: 850.84 | L10: 16121.93 | M10: 15084.44 | N10: 16467.08 | O10: 974.29 | P10: 974.29 | Q10: 17369.15 | R10: 17128.01 | S10: 22643.12 | T10: 556.29 | U10: 556.29 | V10: 22416.01 | W10: 22969.34 | X10: 23422.85 | Y10: 7781.49 | Z10: 7781.49 | AA10: 44341.11 | AB10: 89841.59
A11: 1 | C11: 재고자산 | E11: 729.68 | F11: 729.68 | G11: 774.19 | H11: 780.85 | I11: 992.62 | J11: 2280.75 | K11: 2280.75 | L11: 4144.05 | M11: 7006.13 | N11: 14791.62 | O11: 31510.6 | P11: 31510.6 | Q11: 34155.35 | R11: 45304.64 | S11: 66535.88 | T11: 71499.27 | U11: 71499.27 | V11: 95225.95 | W11: 144353.14 | X11: 166017.02 | Y11: 199477.5 | Z11: 199477.5 | AA11: 253389.6 | AB11: 345137.7
A12: 1 | C12: 당기법인세자산(선급법인세) | E12: 1621.06 | F12: 1621.06 | G12: 1704.74 | I12: 157.42 | J12: 3081.69 | K12: 3081.69 | L12: 5899.01 | M12: 5672.61 | N12: 7752.59 | O12: 9413.78 | P12: 9413.78 | Q12: 12094.7 | R12: 5119.07 | S12: 5991.76 | T12: 2214.65 | U12: 2214.65 | V12: 2305.31 | W12: 0 | X12: 0 | Y12: 0 | Z12: 0
A13: 1 | C13: 매각예정비유동자산및처분자산 | E13: 8363.67 | F13: 8363.67 | J13: 2871.72 | K13: 2871.72 | O13: 8637.81 | P13: 8637.81 | Q13: 0 | R13: 0 | S13: 0 | T13: 0 | U13: 0 | W13: 4626.85 | X13: 4626.85 | Y13: 0 | Z13: 0
A14: 1 | C14: 기타유동자산 | E14: 869.32 | F14: 869.32 | G14: 2493.37 | H14: 1814.55 | I14: 1547.09 | J14: 7479.3 | K14: 7479.3 | L14: 10125.13 | M14: 27720.53 | N14: 35075.1 | O14: 42439.69 | P14: 42439.69 | Q14: 50431.24 | R14: 41566.26 | S14: 36564.88 | T14: 67460.78 | U14: 67460.78 | V14: 88457.83 | W14: 125331.34 | X14: 138114.96 | Y14: 228784.56 | Z14: 228784.56 | AA14: 316836.38 | AB14: 314871.12
A15: 1 | C15: 비유동자산 | E15: 9268756.9 | F15: 9268756.9 | G15: 9307104.2 | H15: 9159581 | I15: 9111342.6 | J15: 9311699.9 | K15: 9311699.9 | L15: 9743843.7 | M15: 9784157.6 | N15: 10054933 | O15: 10119748 | P15: 10119748 | Q15: 10048488 | R15: 9761246 | S15: 9956471.7 | T15: 10030124 | U15: 10030124 | V15: 10085273 | W15: 10011893 | X15: 10009464 | Y15: 10065482 | Z15: 10065482 | AA15: 10067659 | AB15: 10096282
A16: 1 | C16: 종속기업및관계기업투자 | E16: 8298137.4 | F16: 8298137.4 | G16: 8283702.4 | H16: 8165548.3 | I16: 8149415.3 | J16: 8349068.3 | K16: 8349068.3 | L16: 8764495.4 | M16: 8803081.1 | N16: 8832251.2 | O16: 8883881.6 | P16: 8883881.6 | Q16: 8883810.8 | R16: 8694162.6 | S16: 8922041.2 | T16: 9012227.6 | U16: 9012227.6 | V16: 9067495.7 | W16: 9035213.8 | X16: 9065809.2 | Y16: 9235911.6 | Z16: 9235911.6 | AA16: 9260450.7 | AB16: 9290755.9
A17: 1 | C17: 투자자산 | E17: 8423562.8 | F17: 8423562.8 | G17: 8445715.7 | H17: 8307040.2 | I17: 8269787.6 | J17: 8470131 | K17: 8470131 | L17: 8897521.5 | M17: 8938661.1 | N17: 8952660.2 | O17: 9014455.1 | P17: 9014455.1 | Q17: 8946462.1 | R17: 8751453.9 | S17: 8979296.7 | T17: 9068618.7 | U17: 9068618.7 | V17: 9123941.4 | W17: 9091919 | X17: 9100095.8 | Y17: 9275982 | Z17: 9275982 | AA17: 9305361 | AB17: 9343852
A18: 1 | C18: 장기금융자산 | E18: 125425.34 | F18: 125425.34 | G18: 162013.29 | H18: 141491.84 | I18: 120372.33 | J18: 121062.65 | K18: 121062.65 | L18: 133026.02 | M18: 135580 | N18: 120408.96 | O18: 130573.46 | P18: 130573.46 | Q18: 62651.38 | R18: 57291.28 | S18: 57255.52 | T18: 56391.05 | U18: 56391.05 | V18: 56445.74 | W18: 56705.16 | X18: 34286.61 | Y18: 40070.37 | Z18: 40070.37 | AA18: 43682.04 | AB18: 45378.16
A19: 1 | C19: 장기매출채권및기타채권 | E19: 40576.9 | F19: 40576.9 | G19: 63250.05 | H19: 58897.65 | I19: 58967.42 | J19: 16848.99 | K19: 16848.99 | L19: 18713.07 | M19: 19247.17 | N19: 19528.07 | O19: 29452.38 | P19: 29452.38 | Q19: 28081 | R19: 28076.4 | S19: 17927.72 | T19: 5987.56 | U19: 5987.56 | V19: 7906.94 | W19: 8165.59 | X19: 37132.28 | Y19: 8389.86 | Z19: 8389.86 | AA19: 8517.53 | AB19: 8882.35
A20: 1 | C20: 투자부동산 | E20: 145515.41 | F20: 145515.41 | G20: 142410.88 | H20: 141676.9 | I20: 140942.92 | J20: 140208.95 | K20: 140208.95 | L20: 139474.97 | M20: 138740.99 | N20: 138007.01 | O20: 137273.04 | P20: 137273.04 | Q20: 136548.3 | R20: 141233.27 | S20: 140467.35 | T20: 139778.31 | U20: 139778.31 | V20: 139011.7 | W20: 133609.98 | X20: 132877.71 | Y20: 54604.37 | Z20: 54604.37 | AA20: 54397.2 | AB20: 54190.04
A21: 1 | C21: 유형자산 | E21: 623510.77 | F21: 623510.77 | G21: 621545.75 | H21: 621587.14 | I21: 613069.08 | J21: 609038.84 | K21: 609038.84 | L21: 609109.97 | M21: 612731.61 | N21: 613111.7 | O21: 598210.1 | P21: 598210.1 | Q21: 601827.4 | R21: 595607.44 | S21: 595673.04 | T21: 600537.64 | U21: 600537.64 | V21: 600149.91 | W21: 616110.64 | X21: 622059.04 | Y21: 624978.37 | Z21: 624978.37 | AA21: 628318.47 | AB21: 625612.66
A22: 1 | C22: 사용권자산 | E22: 7469.48 | F22: 7469.48 | G22: 6247.36 | H22: 4480.51 | I22: 3511.95 | J22: 24390.29 | K22: 24390.29 | L22: 25860.17 | M22: 23939.56 | N22: 23081.84 | O22: 25116.38 | P22: 25116.38 | Q22: 23706.64 | R22: 22844.83 | S22: 20856.29 | T22: 18740.89 | U22: 18740.89 | V22: 23946.91 | W22: 21401.16 | X22: 18281.39 | Y22: 13586.9 | Z22: 13586.9 | AA22: 11929.53 | AB22: 9761.06
A23: 1 | C23: 기타비유동자산 | E23: 11688.94 | F23: 11688.94 | G23: 9650.11 | H23: 6145.55 | I23: 4248.41 | J23: 29934.92 | K23: 29934.92 | L23: 29555.37 | M23: 25118.39 | N23: 23789.13 | O23: 41687.67 | P23: 41687.67 | Q23: 36587.96 | R23: 33125.45 | S23: 27742.95 | T23: 23578.53 | U23: 23578.53 | V23: 25557.49 | W23: 22057.41 | X23: 18930.35 | Y23: 40237.08 | Z23: 40237.08 | AA23: 32584.82 | AB23: 24445.86
A24: 1 | C24: 무형자산 | E24: 23902.15 | F24: 23902.15 | G24: 24531.72 | H24: 24233.56 | I24: 24327.17 | J24: 24353.83 | K24: 24353.83 | L24: 26026.1 | M24: 28901.46 | N24: 33764.11 | O24: 38762.72 | P24: 38762.72 | Q24: 40452.49 | R24: 42379.58 | S24: 44236.73 | T24: 47459.99 | U24: 47459.99 | V24: 47989.77 | W24: 47650.5 | X24: 48757.85 | Y24: 38422.08 | Z24: 38422.08 | AA24: 38479.53 | AB24: 39299.07
A25: 1 | C25: 자산총계 | E25: 11109138 | F25: 11109138 | G25: 11163368 | H25: 11210256 | I25: 11198521 | J25: 11430170 | K25: 11430170 | L25: 11471687 | M25: 11456324 | N25: 11732008 | O25: 11774250 | P25: 11774250 | Q25: 11760644 | R25: 11870887 | S25: 11923464 | T25: 12057257 | U25: 12057257 | V25: 13103784 | W25: 12829166 | X25: 12891838 | Y25: 12901126 | Z25: 12901126 | AA25: 13406604 | AB25: 15518286
A26: 1 | C26: 유동부채 | E26: 221237.07 | F26: 221237.07 | G26: 208402.63 | H26: 215794.97 | I26: 219455.58 | J26: 258944.57 | K26: 258944.57 | L26: 160027.99 | M26: 127675.02 | N26: 153107.1 | O26: 196119.73 | P26: 196119.73 | Q26: 173854.55 | R26: 177586.86 | S26: 225138 | T26: 331705.96 | U26: 331705.96 | V26: 1312526.8 | W26: 1015876.2 | X26: 990818.33 | Y26: 1116053.7 | Z26: 1116053.7 | AA26: 1677198.3 | AB26: 3431358.8
A27: 1 | C27: 단기차입금 | E27: 170.81 | F27: 170.81 | G27: 174.45 | H27: 186.28 | I27: 206.73 | J27: 4860.97 | K27: 4860.97 | O27: 0 | P27: 0 | R27: 1072.2 | T27: 0 | U27: 0 | V27: 597623.66 | W27: 522979.29 | X27: 495339.36 | Y27: 473565.66 | Z27: 473565.66 | AA27: 427437.86 | AB27: 2549642.4
A28: 1 | C28: 단기금융부채(face) | E28: 170.81 | F28: 170.81 | G28: 174.45 | H28: 186.28 | I28: 206.73 | J28: 4860.97 | K28: 4860.97 | O28: 0 | P28: 0 | R28: 1072.2 | T28: 0 | U28: 0 | V28: 597623.66 | W28: 522979.29 | X28: 495339.36 | Y28: 473565.66 | Z28: 473565.66 | AA28: 427437.86 | AB28: 2549642.4
A29: 1 | C29: 유동리스부채 | E29: 4773.53 | F29: 4773.53 | G29: 4234.11 | H29: 3147.86 | I29: 2477.75 | J29: 7641.23 | K29: 7641.23 | L29: 8853.82 | M29: 8613.49 | N29: 8690.88 | O29: 9005.9 | P29: 9005.9 | Q29: 8912.06 | R29: 9116.42 | S29: 8880.42 | T29: 8601.86 | U29: 8601.86 | V29: 12781.87 | W29: 13013.22 | X29: 12881.53 | Y29: 10330.51 | Z29: 10330.51 | AA29: 8106.05 | AB29: 6121.32
A30: 1 | C30: 리스부채 | E30: 7739.67 | F30: 7739.67 | G30: 6519.27 | H30: 4605.94 | I30: 3649.8 | J30: 23697.51 | K30: 23697.51 | L30: 25284.18 | M30: 23553.35 | N30: 22787.65 | O30: 24874.82 | P30: 24874.82 | Q30: 23583.98 | R30: 22824.64 | S30: 20974.69 | T30: 18929.81 | U30: 18929.81 | V30: 24220.35 | W30: 21790.97 | X30: 18794.22 | Y30: 13946.19 | Z30: 13946.19 | AA30: 12259.1 | AB30: 9995.5
A31: 1 | C31: 단기금융부채 | E31: 4773.53 | F31: 4773.53 | G31: 4234.11 | H31: 3147.86 | I31: 2477.75 | J31: 7641.23 | K31: 7641.23 | L31: 8853.82 | M31: 8613.49 | N31: 8690.88 | O31: 9005.9 | P31: 9005.9 | Q31: 8912.06 | R31: 9116.42 | S31: 8880.42 | T31: 8601.86 | U31: 8601.86 | V31: 12781.87 | W31: 13013.22 | X31: 12881.53 | Y31: 10330.51 | Z31: 10330.51 | AA31: 8106.05 | AB31: 6121.32
A32: 1 | C32: 매입채무및기타채무 | E32: 178306.07 | F32: 178306.07 | G32: 162665.02 | H32: 168161.42 | I32: 167123.34 | J32: 186935.61 | K32: 186935.61 | L32: 96691.03 | M32: 51219.14 | N32: 47192.2 | O32: 85026.14 | P32: 85026.14 | Q32: 49753.04 | R32: 55293.11 | S32: 63751.58 | T32: 113963.38 | U32: 113963.38 | V32: 439385.05 | W32: 127698.87 | X32: 128454.06 | Y32: 230562.83 | Z32: 230562.83 | AA32: 818457.19 | AB32: 204950.33
A33: 1 | C33: 계약부채 | E33: 4827.19 | F33: 4827.19 | G33: 8220.73 | H33: 8347.62 | I33: 17061.47 | J33: 26788.46 | K33: 26788.46 | L33: 49885.1 | M33: 66994.02 | N33: 96563.15 | O33: 101407.84 | P33: 101407.84 | Q33: 114394.6 | R33: 107893.01 | S33: 151121.4 | T33: 207481.7 | U33: 207481.7 | V33: 245980.03 | W33: 319326.78 | X33: 343949.27 | Y33: 380304.5 | Z33: 380304.5 | AA33: 385027.65 | AB33: 638920.62
A34: 1 | C34: 선수금 | E34: 1528.17 | F34: 1528.17 | O34: 0 | P34: 0
A35: 1 | C35: 기타유동부채 | E35: 1567.55 | F35: 1567.55 | G35: 39.38 | H35: 79.38 | I35: 79.38 | J35: 79.38 | K35: 79.38 | L35: 16.48 | M35: 56.48 | N35: 55.21 | O35: 32.04 | P35: 32.04 | Q35: 32.04 | R35: 32.04 | S35: 32.04 | T35: 32.04 | U35: 32.04 | V35: 32.04 | W35: 0 | X35: 0 | Y35: 0 | Z35: 0
A36: 1 | C36: 단기충당부채 | E36: 31591.92 | F36: 31591.92 | G36: 31858.92 | H36: 32112.92 | I36: 32377.92 | J36: 32638.92 | K36: 32638.92 | L36: 4581.57 | M36: 791.89 | N36: 605.66 | O36: 647.8 | P36: 647.8 | Q36: 762.8 | R36: 1134.68 | S36: 1352.55 | T36: 1626.99 | U36: 1626.99 | V36: 1775.15 | W36: 1913.68 | X36: 2360.95 | Y36: 2831.3 | Z36: 2831.3 | AA36: 3345.01 | AB36: 4548.16
A37: 1 | C37: 비유동부채 | E37: 110885.36 | F37: 110885.36 | G37: 116241.82 | H37: 114312.1 | I37: 92741.2 | J37: 46736.42 | K37: 46736.42 | L37: 49537.79 | M37: 51464.86 | N37: 48921.73 | O37: 48531.88 | P37: 48531.88 | Q37: 47544.3 | R37: 45574.45 | S37: 43907.99 | T37: 45017.39 | U37: 45017.39 | V37: 47011.69 | W37: 47028.71 | X37: 49024.36 | Y37: 44084.22 | Z37: 44084.22 | AA37: 62450.17 | AB37: 212795.6
A38: 1 | C38: 장기차입금 | E38: 44141.67 | F38: 44141.67 | G38: 35924.5 | H38: 25931.23 | I38: 21287.71 | J38: 11977.28 | K38: 11977.28 | L38: 14482.59 | M38: 17851.91 | N38: 13932.86 | O38: 12901.87 | P38: 12901.87 | Q38: 12893.13 | R38: 11163.46 | S38: 10604.16 | T38: 11812.76 | U38: 11812.76 | V38: 11784.63 | W38: 10899.88 | X38: 11267.92 | Y38: 11530.7 | Z38: 11530.7 | AA38: 12161.51 | AB38: 12387.32
A39: 1 | C39: 장기금융부채(face) | E39: 44141.67 | F39: 44141.67 | G39: 35924.5 | H39: 25931.23 | I39: 21287.71 | J39: 11977.28 | K39: 11977.28 | L39: 14482.59 | M39: 17851.91 | N39: 13932.86 | O39: 12901.87 | P39: 12901.87 | Q39: 12893.13 | R39: 11163.46 | S39: 10604.16 | T39: 11812.76 | U39: 11812.76 | V39: 11784.63 | W39: 10899.88 | X39: 11267.92 | Y39: 11530.7 | Z39: 11530.7 | AA39: 12161.51 | AB39: 12387.32
A40: 1 | C40: 비유동리스부채 | E40: 2966.14 | F40: 2966.14 | G40: 2285.16 | H40: 1458.08 | I40: 1172.05 | J40: 16056.28 | K40: 16056.28 | L40: 16430.36 | M40: 14939.86 | N40: 14096.77 | O40: 15868.92 | P40: 15868.92 | Q40: 14671.92 | R40: 13708.22 | S40: 12094.27 | T40: 10327.95 | U40: 10327.95 | V40: 11438.48 | W40: 8777.75 | X40: 5912.69 | Y40: 3615.68 | Z40: 3615.68 | AA40: 4153.05 | AB40: 3874.18
...

Sheet subQ
A1: YQ | C1: subQ 분기 서브모델(억원, U=100) | E1: 4Q21 | F1: 2021 | G1: 1Q22 | H1: 2Q22 | I1: 3Q22 | J1: 4Q22 | K1: 2022 | L1: 1Q23 | M1: 2Q23 | N1: 3Q23 | O1: 4Q23 | P1: 2023 | Q1: 1Q24 | R1: 2Q24 | S1: 3Q24 | T1: 4Q24 | U1: 2024 | V1: 1Q25 | W1: 2Q25 | X1: 3Q25 | Y1: 4Q25 | Z1: 2025 | AA1: 1Q26 | AB1: 2Q26 | AC1: 3Q26 | AD1: 4Q26 | AE1: 2026 | AF1: 1Q27 | AG1: 2Q27 | AH1: 3Q27 | AI1: 4Q27 | AJ1: 2027 | AK1: 1Q28 | AL1: 2Q28 | AM1: 3Q28 | AN1: 4Q28 | AO1: 2028
A2: A=이름(key) B=그룹 C=단위 D=FnGuide 계정명(VLOOKUP 키). 확정=VLOOKUP(BS), 추정=변수 가정 참조
E3: 1 | F3: 2 | G3: 3 | H3: 4 | I3: 5 | J3: 6 | K3: 7 | L3: 8 | M3: 9 | N3: 10 | O3: 11 | P3: 12 | Q3: 13 | R3: 14 | S3: 15 | T3: 16 | U3: 17 | V3: 18 | W3: 19 | X3: 20 | Y3: 21 | Z3: 22 | AA3: 23 | AB3: 24 | AC3: 25 | AD3: 26 | AE3: 27 | AF3: 28 | AG3: 29 | AH3: 30 | AI3: 31 | AJ3: 32 | AK3: 33 | AL3: 34 | AM3: 35 | AN3: 36 | AO3: 37
E4: 2021.12 | F4: 2021.12A | G4: 2022.03 | H4: 2022.06 | I4: 2022.09 | J4: 2022.12 | K4: 2022.12A | L4: 2023.03 | M4: 2023.06 | N4: 2023.09 | O4: 2023.12 | P4: 2023.12A | Q4: 2024.03 | R4: 2024.06 | S4: 2024.09 | T4: 2024.12 | U4: 2024.12A | V4: 2025.03 | W4: 2025.06 | X4: 2025.09 | Y4: 2025.12 | Z4: 2025.12A | AA4: 2026.03 | AB4: 2026.06 | AC4: 2026.09 | AD4: 2026.12 | AE4: 2026.12A | AF4: 2027.03 | AG4: 2027.06 | AH4: 2027.09 | AI4: 2027.12 | AJ4: 2027.12A | AK4: 2028.03 | AL4: 2028.06 | AM4: 2028.09 | AN4: 2028.12 | AO4: 2028.12A
A5: 매출액 | B5: 손익 | C5: 억원 | D5: 매출액(수익) | E5: =IFERROR(VLOOKUP($D5,BS연결,MATCH(E$1,BS연결H,0),0)/100,"") | G5: =IFERROR(VLOOKUP($D5,BS연결,MATCH(G$1,BS연결H,0),0)/100,"") | H5: =IFERROR(VLOOKUP($D5,BS연결,MATCH(H$1,BS연결H,0),0)/100,"") | I5: =IFERROR(VLOOKUP($D5,BS연결,MATCH(I$1,BS연결H,0),0)/100,"") | J5: =IFERROR(VLOOKUP($D5,BS연결,MATCH(J$1,BS연결H,0),0)/100,"") | K5: =IFERROR(VLOOKUP($D5,BS연결,MATCH(K$1,BS연결H,0),0)/100,"") | L5: =IFERROR(VLOOKUP($D5,BS연결,MATCH(L$1,BS연결H,0),0)/100,"") | M5: =IFERROR(VLOOKUP($D5,BS연결,MATCH(M$1,BS연결H,0),0)/100,"") | N5: =IFERROR(VLOOKUP($D5,BS연결,MATCH(N$1,BS연결H,0),0)/100,"") | ... AB5: =IFERROR(VLOOKUP($D5,BS연결,MATCH(AB$1,BS연결H,0),0)/100,"") | AC5: =IFERROR(X5*(1+변수!AC21),"") | AD5: =IFERROR(Y5*(1+변수!AD21),"") | AE5: =SUM(AA5:AD5) | AF5: =IFERROR(AA5*(1+변수!AF21),"") | AG5: =IFERROR(AB5*(1+변수!AG21),"") | AH5: =IFERROR(AC5*(1+변수!AH21),"") | AI5: =IFERROR(AD5*(1+변수!AI21),"") | AJ5: =SUM(AF5:AI5) | AK5: =IFERROR(AF5*(1+변수!AK21),"") | AL5: =IFERROR(AG5*(1+변수!AL21),"") | AM5: =IFERROR(AH5*(1+변수!AM21),"") | AN5: =IFERROR(AI5*(1+변수!AN21),"") | AO5: =SUM(AK5:AN5)
A6: 매출원가 | B6: 손익 | C6: 억원 | D6: 매출원가 | E6: =IFERROR(VLOOKUP($D6,BS연결,MATCH(E$1,BS연결H,0),0)/100,"") | G6: =IFERROR(VLOOKUP($D6,BS연결,MATCH(G$1,BS연결H,0),0)/100,"") | H6: =IFERROR(VLOOKUP($D6,BS연결,MATCH(H$1,BS연결H,0),0)/100,"") | I6: =IFERROR(VLOOKUP($D6,BS연결,MATCH(I$1,BS연결H,0),0)/100,"") | J6: =IFERROR(VLOOKUP($D6,BS연결,MATCH(J$1,BS연결H,0),0)/100,"") | K6: =IFERROR(VLOOKUP($D6,BS연결,MATCH(K$1,BS연결H,0),0)/100,"") | L6: =IFERROR(VLOOKUP($D6,BS연결,MATCH(L$1,BS연결H,0),0)/100,"") | M6: =IFERROR(VLOOKUP($D6,BS연결,MATCH(M$1,BS연결H,0),0)/100,"") | N6: =IFERROR(VLOOKUP($D6,BS연결,MATCH(N$1,BS연결H,0),0)/100,"") | ... AB6: =IFERROR(VLOOKUP($D6,BS연결,MATCH(AB$1,BS연결H,0),0)/100,"") | AC6: =IFERROR(AC5-AC7,"") | AD6: =IFERROR(AD5-AD7,"") | AE6: =SUM(AA6:AD6) | AF6: =IFERROR(AF5-AF7,"") | AG6: =IFERROR(AG5-AG7,"") | AH6: =IFERROR(AH5-AH7,"") | AI6: =IFERROR(AI5-AI7,"") | AJ6: =SUM(AF6:AI6) | AK6: =IFERROR(AK5-AK7,"") | AL6: =IFERROR(AL5-AL7,"") | AM6: =IFERROR(AM5-AM7,"") | AN6: =IFERROR(AN5-AN7,"") | AO6: =SUM(AK6:AN6)
A7: 매출총이익 | B7: 손익 | C7: 억원 | D7: 매출총이익 | E7: =IFERROR(VLOOKUP($D7,BS연결,MATCH(E$1,BS연결H,0),0)/100,"") | G7: =IFERROR(VLOOKUP($D7,BS연결,MATCH(G$1,BS연결H,0),0)/100,"") | H7: =IFERROR(VLOOKUP($D7,BS연결,MATCH(H$1,BS연결H,0),0)/100,"") | I7: =IFERROR(VLOOKUP($D7,BS연결,MATCH(I$1,BS연결H,0),0)/100,"") | J7: =IFERROR(VLOOKUP($D7,BS연결,MATCH(J$1,BS연결H,0),0)/100,"") | K7: =IFERROR(VLOOKUP($D7,BS연결,MATCH(K$1,BS연결H,0),0)/100,"") | L7: =IFERROR(VLOOKUP($D7,BS연결,MATCH(L$1,BS연결H,0),0)/100,"") | M7: =IFERROR(VLOOKUP($D7,BS연결,MATCH(M$1,BS연결H,0),0)/100,"") | N7: =IFERROR(VLOOKUP($D7,BS연결,MATCH(N$1,BS연결H,0),0)/100,"") | ... AB7: =IFERROR(VLOOKUP($D7,BS연결,MATCH(AB$1,BS연결H,0),0)/100,"") | AC7: =IFERROR(AC9+AC8,"") | AD7: =IFERROR(AD9+AD8,"") | AE7: =SUM(AA7:AD7) | AF7: =IFERROR(AF9+AF8,"") | AG7: =IFERROR(AG9+AG8,"") | AH7: =IFERROR(AH9+AH8,"") | AI7: =IFERROR(AI9+AI8,"") | AJ7: =SUM(AF7:AI7) | AK7: =IFERROR(AK9+AK8,"") | AL7: =IFERROR(AL9+AL8,"") | AM7: =IFERROR(AM9+AM8,"") | AN7: =IFERROR(AN9+AN8,"") | AO7: =SUM(AK7:AN7)
