Workbook
Name 변수H: 변수!$C$1:$AO$1
Name 환율: 변수!$C$6:$AO$13
Name BS연결H: BS연결!$C$1:$AO$1
Name BS연결: BS연결!$C$5:$AO$122
Name BS별도H: BS별도!$C$1:$AO$1
Name BS별도: BS별도!$C$5:$AO$106
Name SUBQH: subQ!$A$1:$AO$1
Name subQ: subQ!$A$5:$AO$47
Name SLS_H: SLS!$A$1:$AV$1

Sheet README
A1: 삼성중공업(010140) 실적 모델 — ARGUS 한국조선
A2: 기준 분기 2026Q2 · 마지막 실적 2026Q2 · 생성 2026-10-19
A3: 모든 수치는 모델 산출값(DART 공개 재무제표 + 우리 추정)이다 — 목표주가·투자 추천 아님. 참고용 · 투자조언 아님.
A5: 시트
A6: 변수 가정 시계열. 환율 8행(ECB via frankfurter — L2 fx.json; 추정 분기 = 노란 가정), 추정 드라이버(노란 셀 = 모델값에서 역산한 가정, 바꾸면 재계산; 연녹 셀 = 3절 스칼라 참조 수식), 3절 스칼라 가정(세율·판관비율·지배주주비중·이자율·종가·PER 밴드·COE·외화 순노출·헤지비율)
A7: BS연결/BS별도 FnGuide 계정명 × 기간 값 덤프(백만원). 행1 분기라벨, 행4 YYYY.MM / YYYY.12A. 이름정의 BS연결H·BS연결(계정명 C열부터)
A8: subQ 분기 서브모델(억원 = 백만원/100). 확정 행: =IFERROR(VLOOKUP($D행,BS연결,MATCH(E$1,BS연결H,0),0)/100,"") 추정 행: 변수 시트 가정 셀 참조 수식. 외환손익·파생상품손익은 BS 계정 합·차, 기타금융손익은 잔차, OPM·EPS·BPS·PER·PBR 은 파생 수식
A9: SLS 선표(조선사만, sls json 있을 때): 요약 행(sls 저장값) + 계약별 스케줄(백만$) × (헤지비율 × 헤지환율 + (1−헤지비율) × 건조시점 환율[변수 원/달러(평균)]) → 원화 수식 블록 → 합계 행이 subQ 매출조선에 연결
A10: 시나리오 신규수주 보수/기준/낙관(forecast_panel 패널, 모델에 scenarios 가 있을 때만): 매출액·영업이익 = subQ 기준값 ± (시나리오 신규 − base 신규) × OPM. base 만 subQ 행에 포함, 나머지는 합산 안 함
A11: 분기/연간예상 subQ 를 이름(A열 key)으로 VLOOKUP 한 보고서 표(억원)
A12: TP PER 밴드 × 12M fwd EPS, PBR = ROE/COE × BPS — 모델 산출값 구간, 목표주가·추천 아님
A13: 외화 환율 QoQ, 외화 순노출 × Δ기말환율 → 환관련손익 추정
... A36: 백테스트: {"freeze": "2025Q2", "horizon": 4, "revenue_wape_pct": 6.5, "op_wape_pct": 39.7, "n": 4, "note": "단일 회사 4분기 — 통계 아님", "driver_at_freeze": "sls_marine_plus_uncovered_backlog_runoff", "selection_oos_at_freeze": null, "frozen_inputs": "fin(연결/별도)·고객 조선사 모델·지주 자회사 모델은 2025Q2 까지의 분기만; 선표는 체결일 ≤ 2025Q2 말일 계약(원장 최신 금액·코호트 등급, 환산 없음); 잔고는 yards_cache 2025Q2; 시세·환율 forward·prices·forecast_panel 신규수주 미사용. 고객 가중치(suppliers.json 언급 비중)와 합병 체인링크는 현재 지식; 고객 연동 채택은 동결 모델 안에서도 자기 la−4분기 OOS 규칙(selection_oos_at_freeze)", "detail": [{"q": "2025Q3", "rev_pred": 29660.89, "rev_act": 26348.19, "op_pred": 1722.17, "op_act": 2380.82}, {"q": "2025Q4", "rev_pred": 29381.56, "rev_act": 28379.29, "op_pred": 1705.95, "op_act": 2962.35}, {"q": "2026Q1", "rev_pred": 29237.07, "rev_act": 29022.51, "op_pred": 1697.56, "op_act": 2731.18}, {"q": "2026Q2", "rev_pred": 29309.33, "rev_act": 32307.12, "op_pred": 1701.76, "op_act": 3250.24}]}

Sheet 변수
C1: 이름: 변수H | E1: 4Q21 | F1: 2021 | G1: 1Q22 | H1: 2Q22 | I1: 3Q22 | J1: 4Q22 | K1: 2022 | L1: 1Q23 | M1: 2Q23 | N1: 3Q23 | O1: 4Q23 | P1: 2023 | Q1: 1Q24 | R1: 2Q24 | S1: 3Q24 | T1: 4Q24 | U1: 2024 | V1: 1Q25 | W1: 2Q25 | X1: 3Q25 | Y1: 4Q25 | Z1: 2025 | AA1: 1Q26 | AB1: 2Q26 | AC1: 3Q26 | AD1: 4Q26 | AE1: 2026 | AF1: 1Q27 | AG1: 2Q27 | AH1: 3Q27 | AI1: 4Q27 | AJ1: 2027 | AK1: 1Q28 | AL1: 2Q28 | AM1: 3Q28 | AN1: 4Q28 | AO1: 2028
A2: 가정 시계열 — 노란 셀은 추정 가정(모델값에서 역산), 연녹 셀은 3절 스칼라 참조 수식. 바꾸면 subQ·분기·연간예상·TP·시나리오가 재계산됩니다.
E3: 1 | F3: 2 | G3: 3 | H3: 4 | I3: 5 | J3: 6 | K3: 7 | L3: 8 | M3: 9 | N3: 10 | O3: 11 | P3: 12 | Q3: 13 | R3: 14 | S3: 15 | T3: 16 | U3: 17 | V3: 18 | W3: 19 | X3: 20 | Y3: 21 | Z3: 22 | AA3: 23 | AB3: 24 | AC3: 25 | AD3: 26 | AE3: 27 | AF3: 28 | AG3: 29 | AH3: 30 | AI3: 31 | AJ3: 32 | AK3: 33 | AL3: 34 | AM3: 35 | AN3: 36 | AO3: 37
E4: 2021.12 | F4: 2021.12A | G4: 2022.03 | H4: 2022.06 | I4: 2022.09 | J4: 2022.12 | K4: 2022.12A | L4: 2023.03 | M4: 2023.06 | N4: 2023.09 | O4: 2023.12 | P4: 2023.12A | Q4: 2024.03 | R4: 2024.06 | S4: 2024.09 | T4: 2024.12 | U4: 2024.12A | V4: 2025.03 | W4: 2025.06 | X4: 2025.09 | Y4: 2025.12 | Z4: 2025.12A | AA4: 2026.03 | AB4: 2026.06 | AC4: 2026.09 | AD4: 2026.12 | AE4: 2026.12A | AF4: 2027.03 | AG4: 2027.06 | AH4: 2027.09 | AI4: 2027.12 | AJ4: 2027.12A | AK4: 2028.03 | AL4: 2028.06 | AM4: 2028.09 | AN4: 2028.12 | AO4: 2028.12A
B5: 1. FX | C5: 이름: 환율
A6: USDKRW_avg | C6: 원/달러(평균) | E6: 1183.5 | F6: 1145.51 | G6: 1205.78 | H6: 1262.09 | I6: 1341.93 | J6: 1360.12 | K6: 1292.98 | L6: 1276.95 | M6: 1315.69 | N6: 1313.62 | O6: 1322.01 | P6: 1306.85 | Q6: 1330.14 | R6: 1371.28 | S6: 1356.22 | T6: 1396.3 | U6: 1363.53 | V6: 1452.28 | W6: 1398.52 | X6: 1386.95 | Y6: 1449.19 | Z6: 1421.52 | AA6: 1466.12 | AB6: 1501.75 | AC6: 1418.75 | AD6: 1342.11 | AE6: 1454.27 | AF6: 1332.1 | AG6: 1332.1 | AH6: 1332.1 | AI6: 1332.1 | AK6: 1332.1 | AL6: 1332.1 | AM6: 1332.1 | AN6: 1332.1
A7: USDKRW_end | C7: 원/달러(기말) | E7: 1188.75 | F7: 1188.75 | G7: 1213.74 | H7: 1301.24 | I7: 1436.9 | J7: 1260.16 | K7: 1260.16 | L7: 1305.99 | M7: 1321.44 | N7: 1345.35 | O7: 1297.43 | P7: 1297.43 | Q7: 1349.25 | R7: 1377.73 | S7: 1312.17 | T7: 1474.78 | U7: 1474.78 | V7: 1474.54 | W7: 1355.13 | X7: 1403.67 | Y7: 1444.2 | Z7: 1444.2 | AA7: 1524.8 | AB7: 1550.89 | AC7: 1355.4 | AD7: 1332.1 | AE7: 1332.1 | AF7: 1332.1 | AG7: 1332.1 | AH7: 1332.1 | AI7: 1332.1 | AK7: 1332.1 | AL7: 1332.1 | AM7: 1332.1 | AN7: 1332.1
A8: JPY100KRW_avg | C8: 원/100Y(평균) | E8: 1041.02 | F8: 1042.74 | G8: 1036.79 | H8: 972.23 | I8: 970.61 | J8: 961.03 | K8: 985.1 | L8: 964.89 | M8: 957.36 | N8: 909 | O8: 893.22 | P8: 931.11 | Q8: 896.29 | R8: 880.14 | S8: 909.35 | T8: 917.25 | U8: 900.92 | V8: 952.59 | W8: 967.92 | X8: 940.32 | Y8: 940.77 | Z8: 950.17 | AA8: 934.39 | AB8: 942.16 | AC8: 890.41 | AD8: 848.59 | AE8: 917.39 | AF8: 842.99 | AG8: 842.99 | AH8: 842.99 | AI8: 842.99 | AK8: 842.99 | AL8: 842.99 | AM8: 842.99 | AN8: 842.99
A9: JPY100KRW_end | C9: 원/100Y(기말) | E9: 1032.62 | F9: 1032.62 | G9: 996.83 | H9: 954.9 | I9: 993.29 | J9: 955.54 | K9: 955.54 | L9: 980.62 | M9: 913.67 | N9: 901.47 | O9: 917.04 | P9: 917.04 | Q9: 892.42 | R9: 857.76 | S9: 919.21 | T9: 939.65 | U9: 939.65 | V9: 986.84 | W9: 938.85 | X9: 948.49 | Y9: 921.81 | Z9: 921.81 | AA9: 955.99 | AB9: 954.75 | AC9: 863.31 | AD9: 842.99 | AE9: 842.99 | AF9: 842.99 | AG9: 842.99 | AH9: 842.99 | AI9: 842.99 | AK9: 842.99 | AL9: 842.99 | AM9: 842.99 | AN9: 842.99
A10: EURKRW_avg | C10: W/Euro(평균) | E10: 1353.32 | F10: 1354.06 | G10: 1352.29 | H10: 1343.31 | I10: 1350.63 | J10: 1386.07 | K10: 1358.07 | L10: 1369.93 | M10: 1432.41 | N10: 1429.41 | O10: 1420.91 | P10: 1412.88 | Q10: 1444.21 | R10: 1476.42 | S10: 1489.3 | T10: 1490.78 | U10: 1475.4 | V10: 1528.33 | W10: 1585.13 | X10: 1620.04 | Y10: 1686.02 | Z10: 1605.45 | AA10: 1715.47 | AB10: 1746.09 | AC10: 1631.97 | AD10: 1505.3 | AE10: 1685.25 | AF10: 1499.02 | AG10: 1499.02 | AH10: 1499.02 | AI10: 1499.02 | AK10: 1499.02 | AL10: 1499.02 | AM10: 1499.02 | AN10: 1499.02
A11: EURKRW_end | C11: W/Euro(기말) | E11: 1346.38 | F11: 1346.38 | G11: 1347.37 | H11: 1351.6 | I11: 1400.62 | J11: 1344.08 | K11: 1344.08 | L11: 1420.26 | M11: 1435.88 | N11: 1425.26 | O11: 1433.66 | P11: 1433.66 | Q11: 1458.68 | R11: 1474.86 | S11: 1469.1 | T11: 1532.14 | U11: 1532.14 | V11: 1594.72 | W11: 1588.22 | X11: 1648.04 | Y11: 1696.94 | Z11: 1696.94 | AA11: 1753.21 | AB11: 1767.09 | AC11: 1539.06 | AD11: 1499.02 | AE11: 1499.02 | AF11: 1499.02 | AG11: 1499.02 | AH11: 1499.02 | AI11: 1499.02 | AK11: 1499.02 | AL11: 1499.02 | AM11: 1499.02 | AN11: 1499.02
A12: CNYKRW_avg | C12: 원/중국원(평균) | E12: 185.14 | F12: 177.65 | G12: 189.93 | H12: 190.76 | I12: 195.79 | J12: 191.09 | K12: 191.93 | L12: 186.59 | M12: 187.45 | N12: 181.28 | O12: 182.86 | P12: 184.52 | Q12: 185.04 | R12: 189.35 | S12: 189.24 | T12: 194.24 | U12: 189.49 | V12: 199.63 | W12: 193.41 | X12: 193.79 | Y12: 204.38 | Z12: 197.8 | AA12: 211.75 | AB12: 220.8 | AC12: 210.43 | AD12: 200.38 | AE12: 213.41 | AF12: 199.23 | AG12: 199.23 | AH12: 199.23 | AI12: 199.23 | AK12: 199.23 | AL12: 199.23 | AM12: 199.23 | AN12: 199.23
A13: CNYKRW_end | C13: 원/중국원(기말) | E13: 187.13 | F13: 187.13 | G13: 191.38 | H13: 194.13 | I13: 201.92 | J13: 182.67 | K13: 182.67 | L13: 189.97 | M13: 181.8 | N13: 184.26 | O13: 182.61 | P13: 182.61 | Q13: 186.66 | R13: 189.7 | S13: 187.12 | T13: 202.04 | U13: 202.04 | V13: 203.3 | W13: 189.14 | X13: 197.16 | Y13: 206.28 | Z13: 206.28 | AA13: 220.97 | AB13: 228.56 | AC13: 202.16 | AD13: 199.23 | AE13: 199.23 | AF13: 199.23 | AG13: 199.23 | AH13: 199.23 | AI13: 199.23 | AK13: 199.23 | AL13: 199.23 | AM13: 199.23 | AN13: 199.23
B14: 1b. 종가
A15: price_close_end | C15: 종가(기말) | E15: 5670 | G15: 5680 | H15: 6070 | I15: 5310 | J15: 5110 | L15: 5170 | M15: 6670 | N15: 7840 | O15: 7750 | Q15: 8560 | R15: 9350 | S15: 10030 | T15: 11300 | V15: 13480 | W15: 16760 | X15: 21900 | Y15: 24100 | AA15: 24450 | AB15: 23300 | AC15: 19840 | AD15: 18300
A16: price_high | C16: 종가(최고) | E16: 6740 | G16: 6180 | H16: 6450 | I16: 6310 | J16: 5570 | L16: 5950 | M16: 6990 | N16: 9470 | O16: 8300 | Q16: 9390 | R16: 10300 | S16: 12280 | T16: 12290 | V16: 15840 | W16: 18550 | X16: 22800 | Y16: 32500 | AA16: 32000 | AB16: 35350 | AC16: 24500 | AD16: 20150
A17: price_low | C17: 종가(최저) | E17: 5070 | G17: 5020 | H17: 5400 | I17: 5180 | J17: 5000 | L17: 4790 | M17: 5130 | N17: 6600 | O17: 6810 | Q17: 6980 | R17: 8290 | S17: 9290 | T17: 9330 | V17: 11220 | W17: 12650 | X17: 15610 | Y17: 20850 | AA17: 23000 | AB17: 22200 | AC17: 18440 | AD17: 17210
A18: price_avg | C18: 종가(평균) | E18: 5806 | G18: 5619 | H18: 5817.7 | I18: 5694.6 | J18: 5218.2 | L18: 5307.1 | M18: 5952.8 | N18: 8334.2 | O18: 7583.2 | Q18: 7732 | R18: 9306.5 | S18: 10491.9 | T18: 10783 | V18: 13524.5 | W18: 15345.3 | X18: 19674.6 | Y18: 25321.2 | AA18: 28202.5 | AB18: 28704.1 | AC18: 21422.3 | AD18: 18892.7
B20: 2. 추정 드라이버 | C20: 실적 열 = subQ 실현값(수식), 추정 열 = 가정(노란 = 모델값 역산, 연녹 = 3절 스칼라 참조)
A21: drv:판관비 | B21: ratio | C21: 판관비율(/매출) | E21: =IFERROR(subQ!E8/subQ!E5,"") | F21: =IFERROR(subQ!F8/subQ!F5,"") | G21: =IFERROR(subQ!G8/subQ!G5,"") | H21: =IFERROR(subQ!H8/subQ!H5,"") | I21: =IFERROR(subQ!I8/subQ!I5,"") | J21: =IFERROR(subQ!J8/subQ!J5,"") | K21: =IFERROR(subQ!K8/subQ!K5,"") | L21: =IFERROR(subQ!L8/subQ!L5,"") | ... AB21: =IFERROR(subQ!AB8/subQ!AB5,"") | AC21: =$D$55 | AD21: =$D$55 | AE21: =IFERROR(subQ!AE8/subQ!AE5,"") | AF21: =$D$55 | AG21: =$D$55 | AH21: =$D$55 | AI21: =$D$55 | AJ21: =IFERROR(subQ!AJ8/subQ!AJ5,"") | AK21: =$D$55 | AL21: =$D$55 | AM21: =$D$55 | AN21: =$D$55 | AO21: =IFERROR(subQ!AO8/subQ!AO5,"")
A22: drv:외환손익 | B22: abs | C22: 외환손익 (가정, 억원) | E22: =subQ!E13 | F22: =subQ!F13 | G22: =subQ!G13 | H22: =subQ!H13 | I22: =subQ!I13 | J22: =subQ!J13 | K22: =subQ!K13 | L22: =subQ!L13 | ... AB22: =subQ!AB13 | AC22: 0 | AD22: 0 | AE22: =subQ!AE13 | AF22: 0 | AG22: 0 | AH22: 0 | AI22: 0 | AJ22: =subQ!AJ13 | AK22: 0 | AL22: 0 | AM22: 0 | AN22: 0 | AO22: =subQ!AO13
A23: drv:파생상품손익 | B23: abs | C23: 파생상품손익 (가정, 억원) | E23: =subQ!E14 | F23: =subQ!F14 | G23: =subQ!G14 | H23: =subQ!H14 | I23: =subQ!I14 | J23: =subQ!J14 | K23: =subQ!K14 | L23: =subQ!L14 | ... AB23: =subQ!AB14 | AC23: 0 | AD23: 0 | AE23: =subQ!AE14 | AF23: 0 | AG23: 0 | AH23: 0 | AI23: 0 | AJ23: =subQ!AJ14 | AK23: 0 | AL23: 0 | AM23: 0 | AN23: 0 | AO23: =subQ!AO14
A24: drv:기타금융손익 | B24: abs | C24: 기타금융손익 (가정, 억원) | E24: =subQ!E15 | F24: =subQ!F15 | G24: =subQ!G15 | H24: =subQ!H15 | I24: =subQ!I15 | J24: =subQ!J15 | K24: =subQ!K15 | L24: =subQ!L15 | ... AB24: =subQ!AB15 | AC24: -0.01 | AD24: -0.01 | AE24: =subQ!AE15 | AF24: -0.01 | AG24: -0.01 | AH24: -0.01 | AI24: -0.01 | AJ24: =subQ!AJ15 | AK24: -0.01 | AL24: -0.01 | AM24: -0.01 | AN24: -0.01 | AO24: =subQ!AO15
A25: drv:기타영업외손익 | B25: abs | C25: 기타영업외손익 (가정, 억원) | E25: =subQ!E16 | F25: =subQ!F16 | G25: =subQ!G16 | H25: =subQ!H16 | I25: =subQ!I16 | J25: =subQ!J16 | K25: =subQ!K16 | L25: =subQ!L16 | ... AB25: =subQ!AB16 | AC25: 0 | AD25: 0 | AE25: =subQ!AE16 | AF25: 0 | AG25: 0 | AH25: 0 | AI25: 0 | AJ25: =subQ!AJ16 | AK25: 0 | AL25: 0 | AM25: 0 | AN25: 0 | AO25: =subQ!AO16
A26: drv:지분법손익 | B26: abs | C26: 지분법손익 (가정, 억원) | E26: =subQ!E17 | F26: =subQ!F17 | G26: =subQ!G17 | H26: =subQ!H17 | I26: =subQ!I17 | J26: =subQ!J17 | K26: =subQ!K17 | L26: =subQ!L17 | ... AB26: =subQ!AB17 | AC26: 0 | AD26: 0 | AE26: =subQ!AE17 | AF26: 0 | AG26: 0 | AH26: 0 | AI26: 0 | AJ26: =subQ!AJ17 | AK26: 0 | AL26: 0 | AM26: 0 | AN26: 0 | AO26: =subQ!AO17
A27: drv:법인세비용 | B27: tax | C27: 법인세율(/세전) — 법인세 = MAX(세전,0) × 세율 | E27: =IFERROR(subQ!E19/subQ!E18,"") | F27: =IFERROR(subQ!F19/subQ!F18,"") | G27: =IFERROR(subQ!G19/subQ!G18,"") | H27: =IFERROR(subQ!H19/subQ!H18,"") | I27: =IFERROR(subQ!I19/subQ!I18,"") | J27: =IFERROR(subQ!J19/subQ!J18,"") | K27: =IFERROR(subQ!K19/subQ!K18,"") | L27: =IFERROR(subQ!L19/subQ!L18,"") | ... AB27: =IFERROR(subQ!AB19/subQ!AB18,"") | AC27: =$D$54 | AD27: =$D$54 | AE27: =IFERROR(subQ!AE19/subQ!AE18,"") | AF27: =$D$54 | AG27: =$D$54 | AH27: =$D$54 | AI27: =$D$54 | AJ27: =IFERROR(subQ!AJ19/subQ!AJ18,"") | AK27: =$D$54 | AL27: =$D$54 | AM27: =$D$54 | AN27: =$D$54 | AO27: =IFERROR(subQ!AO19/subQ!AO18,"")
A28: drv:지배주주순이익 | B28: ratio | C28: 지배주주 비중(/당기순이익) | E28: =IFERROR(subQ!E21/subQ!E20,"") | F28: =IFERROR(subQ!F21/subQ!F20,"") | G28: =IFERROR(subQ!G21/subQ!G20,"") | H28: =IFERROR(subQ!H21/subQ!H20,"") | I28: =IFERROR(subQ!I21/subQ!I20,"") | J28: =IFERROR(subQ!J21/subQ!J20,"") | K28: =IFERROR(subQ!K21/subQ!K20,"") | L28: =IFERROR(subQ!L21/subQ!L20,"") | ... AB28: =IFERROR(subQ!AB21/subQ!AB20,"") | AC28: =$D$56 | AD28: =$D$56 | AE28: =IFERROR(subQ!AE21/subQ!AE20,"") | AF28: =$D$56 | AG28: =$D$56 | AH28: =$D$56 | AI28: =$D$56 | AJ28: =IFERROR(subQ!AJ21/subQ!AJ20,"") | AK28: =$D$56 | AL28: =$D$56 | AM28: =$D$56 | AN28: =$D$56 | AO28: =IFERROR(subQ!AO21/subQ!AO20,"")
A29: drv:부채총계 | B29: qoq | C29: 부채총계 QoQ | G29: =IFERROR(subQ!G23/subQ!E23-1,"") | H29: =IFERROR(subQ!H23/subQ!G23-1,"") | I29: =IFERROR(subQ!I23/subQ!H23-1,"") | J29: =IFERROR(subQ!J23/subQ!I23-1,"") | L29: =IFERROR(subQ!L23/subQ!J23-1,"") | M29: =IFERROR(subQ!M23/subQ!L23-1,"") | N29: =IFERROR(subQ!N23/subQ!M23-1,"") | O29: =IFERROR(subQ!O23/subQ!N23-1,"") | Q29: =IFERROR(subQ!Q23/subQ!O23-1,"") | R29: =IFERROR(subQ!R23/subQ!Q23-1,"") | S29: =IFERROR(subQ!S23/subQ!R23-1,"") | T29: =IFERROR(subQ!T23/subQ!S23-1,"") | V29: =IFERROR(subQ!V23/subQ!T23-1,"") | W29: =IFERROR(subQ!W23/subQ!V23-1,"") | X29: =IFERROR(subQ!X23/subQ!W23-1,"") | Y29: =IFERROR(subQ!Y23/subQ!X23-1,"") | AA29: =IFERROR(subQ!AA23/subQ!Y23-1,"") | AB29: =IFERROR(subQ!AB23/subQ!AA23-1,"") | AC29: 1.5e-08 | AD29: 0 | AF29: 0 | AG29: 0 | AH29: 0 | AI29: 0 | AK29: 0 | AL29: 0 | AM29: 0 | AN29: 0
A30: drv:자본총계 | B30: roll | C30: 자본총계 기타변동(배당 등, 억원) | G30: =IFERROR(subQ!E24+subQ!G20-subQ!G24,"") | H30: =IFERROR(subQ!G24+subQ!H20-subQ!H24,"") | I30: =IFERROR(subQ!H24+subQ!I20-subQ!I24,"") | J30: =IFERROR(subQ!I24+subQ!J20-subQ!J24,"") | L30: =IFERROR(subQ!J24+subQ!L20-subQ!L24,"") | M30: =IFERROR(subQ!L24+subQ!M20-subQ!M24,"") | N30: =IFERROR(subQ!M24+subQ!N20-subQ!N24,"") | O30: =IFERROR(subQ!N24+subQ!O20-subQ!O24,"") | Q30: =IFERROR(subQ!O24+subQ!Q20-subQ!Q24,"") | R30: =IFERROR(subQ!Q24+subQ!R20-subQ!R24,"") | S30: =IFERROR(subQ!R24+subQ!S20-subQ!S24,"") | T30: =IFERROR(subQ!S24+subQ!T20-subQ!T24,"") | V30: =IFERROR(subQ!T24+subQ!V20-subQ!V24,"") | W30: =IFERROR(subQ!V24+subQ!W20-subQ!W24,"") | X30: =IFERROR(subQ!W24+subQ!X20-subQ!X24,"") | Y30: =IFERROR(subQ!X24+subQ!Y20-subQ!Y24,"") | AA30: =IFERROR(subQ!Y24+subQ!AA20-subQ!AA24,"") | AB30: =IFERROR(subQ!AA24+subQ!AB20-subQ!AB24,"") | AC30: -0.00437145 | AD30: -0.008110109 | AF30: 0.006996103 | AG30: 0.00698306 | AH30: 0.005801761 | AI30: -0.007028072 | AK30: -0.00143717 | AL30: 0.006252531 | AM30: -0.003588791 | AN30: 0.002485498
A31: drv:지배주주지분 | B31: roll | C31: 지배주주지분 기타변동(배당 등, 억원) | G31: =IFERROR(subQ!E25+subQ!G21-subQ!G25,"") | H31: =IFERROR(subQ!G25+subQ!H21-subQ!H25,"") | I31: =IFERROR(subQ!H25+subQ!I21-subQ!I25,"") | J31: =IFERROR(subQ!I25+subQ!J21-subQ!J25,"") | L31: =IFERROR(subQ!J25+subQ!L21-subQ!L25,"") | M31: =IFERROR(subQ!L25+subQ!M21-subQ!M25,"") | N31: =IFERROR(subQ!M25+subQ!N21-subQ!N25,"") | O31: =IFERROR(subQ!N25+subQ!O21-subQ!O25,"") | Q31: =IFERROR(subQ!O25+subQ!Q21-subQ!Q25,"") | R31: =IFERROR(subQ!Q25+subQ!R21-subQ!R25,"") | S31: =IFERROR(subQ!R25+subQ!S21-subQ!S25,"") | T31: =IFERROR(subQ!S25+subQ!T21-subQ!T25,"") | V31: =IFERROR(subQ!T25+subQ!V21-subQ!V25,"") | W31: =IFERROR(subQ!V25+subQ!W21-subQ!W25,"") | X31: =IFERROR(subQ!W25+subQ!X21-subQ!X25,"") | Y31: =IFERROR(subQ!X25+subQ!Y21-subQ!Y25,"") | AA31: =IFERROR(subQ!Y25+subQ!AA21-subQ!AA25,"") | AB31: =IFERROR(subQ!AA25+subQ!AB21-subQ!AB25,"") | AC31: -0.00437145 | AD31: -0.008110109 | AF31: 0.006996103 | AG31: 0.00698306 | AH31: 0.005801761 | AI31: -0.007028072 | AK31: -0.00143717 | AL31: 0.006252531 | AM31: -0.003588791 | AN31: 0.002485498
A32: drv:총차입금 | B32: qoq | C32: 총차입금 QoQ | G32: =IFERROR(subQ!G26/subQ!E26-1,"") | H32: =IFERROR(subQ!H26/subQ!G26-1,"") | I32: =IFERROR(subQ!I26/subQ!H26-1,"") | J32: =IFERROR(subQ!J26/subQ!I26-1,"") | L32: =IFERROR(subQ!L26/subQ!J26-1,"") | M32: =IFERROR(subQ!M26/subQ!L26-1,"") | N32: =IFERROR(subQ!N26/subQ!M26-1,"") | O32: =IFERROR(subQ!O26/subQ!N26-1,"") | Q32: =IFERROR(subQ!Q26/subQ!O26-1,"") | R32: =IFERROR(subQ!R26/subQ!Q26-1,"") | S32: =IFERROR(subQ!S26/subQ!R26-1,"") | T32: =IFERROR(subQ!T26/subQ!S26-1,"") | V32: =IFERROR(subQ!V26/subQ!T26-1,"") | W32: =IFERROR(subQ!W26/subQ!V26-1,"") | X32: =IFERROR(subQ!X26/subQ!W26-1,"") | Y32: =IFERROR(subQ!Y26/subQ!X26-1,"") | AA32: =IFERROR(subQ!AA26/subQ!Y26-1,"") | AB32: =IFERROR(subQ!AB26/subQ!AA26-1,"") | AC32: -2.81e-07 | AD32: 0 | AF32: 0 | AG32: 0 | AH32: 0 | AI32: 0 | AK32: 0 | AL32: 0 | AM32: 0 | AN32: 0
A33: drv:순차입금 | B33: qoq | C33: 순차입금 QoQ | G33: =IFERROR(subQ!G27/subQ!E27-1,"") | H33: =IFERROR(subQ!H27/subQ!G27-1,"") | I33: =IFERROR(subQ!I27/subQ!H27-1,"") | J33: =IFERROR(subQ!J27/subQ!I27-1,"") | L33: =IFERROR(subQ!L27/subQ!J27-1,"") | M33: =IFERROR(subQ!M27/subQ!L27-1,"") | N33: =IFERROR(subQ!N27/subQ!M27-1,"") | O33: =IFERROR(subQ!O27/subQ!N27-1,"") | Q33: =IFERROR(subQ!Q27/subQ!O27-1,"") | R33: =IFERROR(subQ!R27/subQ!Q27-1,"") | S33: =IFERROR(subQ!S27/subQ!R27-1,"") | T33: =IFERROR(subQ!T27/subQ!S27-1,"") | V33: =IFERROR(subQ!V27/subQ!T27-1,"") | W33: =IFERROR(subQ!W27/subQ!V27-1,"") | X33: =IFERROR(subQ!X27/subQ!W27-1,"") | Y33: =IFERROR(subQ!Y27/subQ!X27-1,"") | AA33: =IFERROR(subQ!AA27/subQ!Y27-1,"") | AB33: =IFERROR(subQ!AB27/subQ!AA27-1,"") | AC33: 0.12516996 | AD33: 0.11764612 | AF33: 0.10570743 | AG33: 0.10020086 | AH33: 0.096259049 | AI33: 0.095440652 | AK33: 0.088755933 | AL33: 0.086346121 | AM33: 0.085386994 | AN33: 0.080805279
A34: drv:이자발생자산 | B34: qoq | C34: 이자발생자산 QoQ | G34: =IFERROR(subQ!G28/subQ!E28-1,"") | H34: =IFERROR(subQ!H28/subQ!G28-1,"") | I34: =IFERROR(subQ!I28/subQ!H28-1,"") | J34: =IFERROR(subQ!J28/subQ!I28-1,"") | L34: =IFERROR(subQ!L28/subQ!J28-1,"") | M34: =IFERROR(subQ!M28/subQ!L28-1,"") | N34: =IFERROR(subQ!N28/subQ!M28-1,"") | O34: =IFERROR(subQ!O28/subQ!N28-1,"") | Q34: =IFERROR(subQ!Q28/subQ!O28-1,"") | R34: =IFERROR(subQ!R28/subQ!Q28-1,"") | S34: =IFERROR(subQ!S28/subQ!R28-1,"") | T34: =IFERROR(subQ!T28/subQ!S28-1,"") | V34: =IFERROR(subQ!V28/subQ!T28-1,"") | W34: =IFERROR(subQ!W28/subQ!V28-1,"") | X34: =IFERROR(subQ!X28/subQ!W28-1,"") | Y34: =IFERROR(subQ!Y28/subQ!X28-1,"") | AA34: =IFERROR(subQ!AA28/subQ!Y28-1,"") | AB34: =IFERROR(subQ!AB28/subQ!AA28-1,"") | AC34: 0.077124403 | AD34: 0.075721495 | AF34: 0.070689214 | AG34: 0.06919837 | AH34: 0.068403715 | AI34: 0.069590609 | AK34: 0.066280122 | AL34: 0.065840098 | AM34: 0.066361038 | AN34: 0.06392103
A35: drv:현금및현금성자산 | B35: qoq | C35: 현금및현금성자산 QoQ | G35: =IFERROR(subQ!G29/subQ!E29-1,"") | H35: =IFERROR(subQ!H29/subQ!G29-1,"") | I35: =IFERROR(subQ!I29/subQ!H29-1,"") | J35: =IFERROR(subQ!J29/subQ!I29-1,"") | L35: =IFERROR(subQ!L29/subQ!J29-1,"") | M35: =IFERROR(subQ!M29/subQ!L29-1,"") | N35: =IFERROR(subQ!N29/subQ!M29-1,"") | O35: =IFERROR(subQ!O29/subQ!N29-1,"") | Q35: =IFERROR(subQ!Q29/subQ!O29-1,"") | R35: =IFERROR(subQ!R29/subQ!Q29-1,"") | S35: =IFERROR(subQ!S29/subQ!R29-1,"") | T35: =IFERROR(subQ!T29/subQ!S29-1,"") | V35: =IFERROR(subQ!V29/subQ!T29-1,"") | W35: =IFERROR(subQ!W29/subQ!V29-1,"") | X35: =IFERROR(subQ!X29/subQ!W29-1,"") | Y35: =IFERROR(subQ!Y29/subQ!X29-1,"") | AA35: =IFERROR(subQ!AA29/subQ!Y29-1,"") | AB35: =IFERROR(subQ!AB29/subQ!AA29-1,"")
A36: drv:CAPEX | B36: yoy | C36: CAPEX YoY | J36: =IFERROR(subQ!J30/subQ!E30-1,"") | L36: =IFERROR(subQ!L30/subQ!G30-1,"") | M36: =IFERROR(subQ!M30/subQ!H30-1,"") | N36: =IFERROR(subQ!N30/subQ!I30-1,"") | O36: =IFERROR(subQ!O30/subQ!J30-1,"") | Q36: =IFERROR(subQ!Q30/subQ!L30-1,"") | R36: =IFERROR(subQ!R30/subQ!M30-1,"") | S36: =IFERROR(subQ!S30/subQ!N30-1,"") | T36: =IFERROR(subQ!T30/subQ!O30-1,"") | V36: =IFERROR(subQ!V30/subQ!Q30-1,"") | W36: =IFERROR(subQ!W30/subQ!R30-1,"") | X36: =IFERROR(subQ!X30/subQ!S30-1,"") | Y36: =IFERROR(subQ!Y30/subQ!T30-1,"") | AA36: =IFERROR(subQ!AA30/subQ!V30-1,"") | AB36: =IFERROR(subQ!AB30/subQ!W30-1,"") | AC36: 0.036122998 | AD36: -0.0336799 | AF36: 0.50377999 | AG36: -0.12017348 | AH36: 0 | AI36: 0 | AK36: 0 | AL36: 0 | AM36: 0 | AN36: 0
A37: drv:영업활동현금흐름 | B37: yoy | C37: 영업활동현금흐름 YoY | J37: =IFERROR(subQ!J31/subQ!E31-1,"") | L37: =IFERROR(subQ!L31/subQ!G31-1,"") | M37: =IFERROR(subQ!M31/subQ!H31-1,"") | N37: =IFERROR(subQ!N31/subQ!I31-1,"") | O37: =IFERROR(subQ!O31/subQ!J31-1,"") | Q37: =IFERROR(subQ!Q31/subQ!L31-1,"") | R37: =IFERROR(subQ!R31/subQ!M31-1,"") | S37: =IFERROR(subQ!S31/subQ!N31-1,"") | T37: =IFERROR(subQ!T31/subQ!O31-1,"") | V37: =IFERROR(subQ!V31/subQ!Q31-1,"") | W37: =IFERROR(subQ!W31/subQ!R31-1,"") | X37: =IFERROR(subQ!X31/subQ!S31-1,"") | Y37: =IFERROR(subQ!Y31/subQ!T31-1,"") | AA37: =IFERROR(subQ!AA31/subQ!V31-1,"") | AB37: =IFERROR(subQ!AB31/subQ!W31-1,"")
A38: drv:주식수 | B38: qoq | C38: 주식수 QoQ | G38: =IFERROR(subQ!G32/subQ!E32-1,"") | H38: =IFERROR(subQ!H32/subQ!G32-1,"") | I38: =IFERROR(subQ!I32/subQ!H32-1,"") | J38: =IFERROR(subQ!J32/subQ!I32-1,"") | L38: =IFERROR(subQ!L32/subQ!J32-1,"") | M38: =IFERROR(subQ!M32/subQ!L32-1,"") | N38: =IFERROR(subQ!N32/subQ!M32-1,"") | O38: =IFERROR(subQ!O32/subQ!N32-1,"") | Q38: =IFERROR(subQ!Q32/subQ!O32-1,"") | R38: =IFERROR(subQ!R32/subQ!Q32-1,"") | S38: =IFERROR(subQ!S32/subQ!R32-1,"") | T38: =IFERROR(subQ!T32/subQ!S32-1,"") | V38: =IFERROR(subQ!V32/subQ!T32-1,"") | W38: =IFERROR(subQ!W32/subQ!V32-1,"") | X38: =IFERROR(subQ!X32/subQ!W32-1,"") | Y38: =IFERROR(subQ!Y32/subQ!X32-1,"") | AA38: =IFERROR(subQ!AA32/subQ!Y32-1,"") | AB38: =IFERROR(subQ!AB32/subQ!AA32-1,"") | AC38: 0 | AD38: 0 | AF38: 0 | AG38: 0 | AH38: 0 | AI38: 0 | AK38: 0 | AL38: 0 | AM38: 0 | AN38: 0
A39: drv:DPS | B39: abs | C39: DPS (가정, 원) | E39: =subQ!E35 | F39: =subQ!F35 | G39: =subQ!G35 | H39: =subQ!H35 | I39: =subQ!I35 | J39: =subQ!J35 | K39: =subQ!K35 | L39: =subQ!L35 | ... AB39: =subQ!AB35 | AD39: 0 | AE39: =subQ!AE35 | AI39: 0 | AJ39: =subQ!AJ35 | AN39: 0 | AO39: =subQ!AO35
A40: drv:매출조선 | B40: sls_link | C40: 원장 밖 잔고 소진(억원) — 매출조선 = SLS 원화/100 + 이 행 + 매출조선신규 | G40: =IFERROR(subQ!G38-SLS!E141/100,"") | H40: =IFERROR(subQ!H38-SLS!F141/100,"") | I40: =IFERROR(subQ!I38-SLS!G141/100,"") | J40: =IFERROR(subQ!J38-SLS!H141/100,"") | L40: =IFERROR(subQ!L38-SLS!I141/100,"") | M40: =IFERROR(subQ!M38-SLS!J141/100,"") | N40: =IFERROR(subQ!N38-SLS!K141/100,"") | O40: =IFERROR(subQ!O38-SLS!L141/100,"") | Q40: =IFERROR(subQ!Q38-SLS!M141/100,"") | R40: =IFERROR(subQ!R38-SLS!N141/100,"") | S40: =IFERROR(subQ!S38-SLS!O141/100,"") | T40: =IFERROR(subQ!T38-SLS!P141/100,"") | V40: =IFERROR(subQ!V38-SLS!Q141/100,"") | W40: =IFERROR(subQ!W38-SLS!R141/100,"") | X40: =IFERROR(subQ!X38-SLS!S141/100,"") | Y40: =IFERROR(subQ!Y38-SLS!T141/100,"") | AA40: =IFERROR(subQ!AA38-SLS!U141/100,"") | AB40: =IFERROR(subQ!AB38-SLS!V141/100,"") | AC40: 11046.035 | AD40: 13154.383 | AF40: 13085.926 | AG40: 13120.064 | AH40: 13154.419 | AI40: 13154.433 | AK40: 13120.252 | AL40: 13120.142 | AM40: 13154.505 | AN40: 13133.981
A41: drv:매출조선신규 | B41: abs | C41: 매출조선신규 (forecast_panel base · 공시 상계 신규수주 매출, 억원 — 가정) | E41: =subQ!E39 | F41: =subQ!F39 | G41: =subQ!G39 | H41: =subQ!H39 | I41: =subQ!I39 | J41: =subQ!J39 | K41: =subQ!K39 | L41: =subQ!L39 | ... AB41: =subQ!AB39 | AC41: 0 | AD41: 54.41 | AE41: =subQ!AE39 | AF41: 693.57 | AG41: 2393.86 | AH41: 5034.28 | AI41: 8331.89 | AJ41: =subQ!AJ39 | AK41: 12015.39 | AL41: 15897.92 | AM41: 19805.34 | AN41: 23529.12 | AO41: =subQ!AO39
...

Sheet BS연결
B1: (백만원) | C1: 이름: BS연결H | E1: 4Q21 | F1: 2021 | G1: 1Q22 | H1: 2Q22 | I1: 3Q22 | J1: 4Q22 | K1: 2022 | L1: 1Q23 | M1: 2Q23 | N1: 3Q23 | O1: 4Q23 | P1: 2023 | Q1: 1Q24 | R1: 2Q24 | S1: 3Q24 | T1: 4Q24 | U1: 2024 | V1: 1Q25 | W1: 2Q25 | X1: 3Q25 | Y1: 4Q25 | Z1: 2025 | AA1: 1Q26 | AB1: 2Q26 | AC1: 3Q26 | AD1: 4Q26 | AE1: 2026 | AF1: 1Q27 | AG1: 2Q27 | AH1: 3Q27 | AI1: 4Q27 | AJ1: 2027 | AK1: 1Q28 | AL1: 2Q28 | AM1: 3Q28 | AN1: 4Q28 | AO1: 2028
B2: 연결 | D2: fin json(kship_fin.py)
B3: 삼성중공업(연) | C3: UPDATE: 26-10-19 | E3: 1 | F3: 2 | G3: 3 | H3: 4 | I3: 5 | J3: 6 | K3: 7 | L3: 8 | M3: 9 | N3: 10 | O3: 11 | P3: 12 | Q3: 13 | R3: 14 | S3: 15 | T3: 16 | U3: 17 | V3: 18 | W3: 19 | X3: 20 | Y3: 21 | Z3: 22 | AA3: 23 | AB3: 24 | AC3: 25 | AD3: 26 | AE3: 27 | AF3: 28 | AG3: 29 | AH3: 30 | AI3: 31 | AJ3: 32 | AK3: 33 | AL3: 34 | AM3: 35 | AN3: 36 | AO3: 37
B4: Account Code | C4: AccountNAME | E4: 2021.12 | F4: 2021.12A | G4: 2022.03 | H4: 2022.06 | I4: 2022.09 | J4: 2022.12 | K4: 2022.12A | L4: 2023.03 | M4: 2023.06 | N4: 2023.09 | O4: 2023.12 | P4: 2023.12A | Q4: 2024.03 | R4: 2024.06 | S4: 2024.09 | T4: 2024.12 | U4: 2024.12A | V4: 2025.03 | W4: 2025.06 | X4: 2025.09 | Y4: 2025.12 | Z4: 2025.12A | AA4: 2026.03 | AB4: 2026.06 | AC4: 2026.09 | AD4: 2026.12 | AE4: 2026.12A | AF4: 2027.03 | AG4: 2027.06 | AH4: 2027.09 | AI4: 2027.12 | AJ4: 2027.12A | AK4: 2028.03 | AL4: 2028.06 | AM4: 2028.09 | AN4: 2028.12 | AO4: 2028.12A
A5: 1 | C5: 유동자산 | E5: 5593582.9 | F5: 5593582.9 | G5: 5770158.4 | H5: 7127608.9 | I5: 9502252.7 | J5: 8411943.5 | K5: 8411943.5 | L5: 8604416.6 | M5: 8950612.6 | N5: 10617374 | O5: 9245491.7 | P5: 9245491.7 | Q5: 9803428.6 | R5: 9931850.9 | S5: 8569496 | T5: 9369985.1 | U5: 9369985.1 | V5: 8642748.8 | W5: 7000349.9 | X5: 7324552.7 | Y5: 7407076.8 | Z5: 7407076.8 | AA5: 8264307.3 | AB5: 9684057.2
A6: 1 | C6: 현금및현금성자산 | E6: 571214.29 | F6: 571214.29 | G6: 674797.03 | H6: 915384 | I6: 827177.36 | J6: 919191.7 | K6: 919191.7 | L6: 287073.93 | M6: 651449.18 | N6: 493848.92 | O6: 583811.7 | P6: 583811.7 | Q6: 789036.13 | R6: 325535.34 | S6: 630473.16 | T6: 955961.85 | U6: 955961.85 | V6: 519674.1 | W6: 596771.16 | X6: 1403023 | Y6: 772614.65 | Z6: 772614.65 | AA6: 1038042.8 | AB6: 807415.28
A7: 1 | C7: 단기금융상품 | E7: 599476.18 | F7: 599476.18 | G7: 196247.24 | H7: 349164.39 | I7: 105679.94 | J7: 113168.77 | K7: 113168.77 | L7: 374474.41 | M7: 306317.63 | N7: 179305.37 | O7: 155368.15 | P7: 155368.15 | Q7: 92235.25 | R7: 86844.71 | S7: 52682.26 | T7: 47755.09 | U7: 47755.09 | V7: 45612 | W7: 69708.61 | X7: 266258.93 | Y7: 311797 | Z7: 311797 | AA7: 608399.54 | AB7: 726657.43
A8: 1 | C8: 단기금융자산 | E8: 1037314.2 | F8: 1037314.2 | G8: 886645.09 | H8: 2125512.8 | I8: 3705580.7 | J8: 2026903.3 | K8: 2026903.3 | L8: 2401333.2 | M8: 2223202.4 | N8: 2794106.3 | O8: 1534347.5 | P8: 1534347.5 | Q8: 2087189.8 | R8: 2488058 | S8: 1507853.6 | T8: 2098941.2 | U8: 2098941.2 | V8: 1841864.8 | W8: 1132440.8 | X8: 1159064.8 | Y8: 1356867.8 | Z8: 1356867.8 | AA8: 2056992.8 | AB8: 2356775.7
A9: 1 | C9: 매출채권및기타채권 | E9: 146050.59 | F9: 146050.59 | G9: 206468.68 | H9: 150443.92 | I9: 262997.63 | J9: 770435.61 | K9: 770435.61 | L9: 536078.64 | M9: 408678.54 | N9: 978717.2 | O9: 541144.14 | P9: 541144.14 | Q9: 640813.36 | R9: 531626.93 | S9: 439394.87 | T9: 1185653.6 | U9: 1185653.6 | V9: 976833.49 | W9: 535100.23 | X9: 385245.66 | Y9: 1418753.4 | Z9: 1418753.4 | AA9: 678802.85 | AB9: 678786.06
A10: 1 | C10: 계약자산 | E10: 1532623.8 | F10: 1532623.8 | G10: 1636704.1 | H10: 1652085 | I10: 2296810.5 | J10: 2319153.1 | K10: 2319153.1 | L10: 2369921.3 | M10: 2914358.6 | N10: 3497798.6 | O10: 3783888.8 | P10: 3783888.8 | Q10: 4039461.9 | R10: 4568227.4 | S10: 3916158.6 | T10: 3572702.9 | U10: 3572702.9 | V10: 3461667.3 | W10: 3143533.6 | X10: 2757869.3 | Y10: 2176503 | Z10: 2176503 | AA10: 2673891.9 | AB10: 3335138.2
A11: 1 | C11: 선급금 | E11: 380271.13 | F11: 380271.13 | G11: 414557.9 | H11: 457741.86 | I11: 536309.36 | J11: 546864.92 | K11: 546864.92 | L11: 610370.64 | M11: 683985.56 | N11: 696749.11 | O11: 782581.09 | P11: 782581.09 | Q11: 784169.84 | R11: 824377.36 | S11: 851667.01 | T11: 880646.88 | U11: 880646.88 | V11: 952542.38 | W11: 819761.38 | X11: 859787.58 | Y11: 899488 | Z11: 899488 | AA11: 829881.75 | AB11: 959947.18
A12: 1 | C12: 선급금등 | E12: 380271.13 | F12: 380271.13 | G12: 414557.9 | H12: 457741.86 | I12: 536309.36 | J12: 546864.92 | K12: 546864.92 | L12: 610370.64 | M12: 683985.56 | N12: 696749.11 | O12: 782581.09 | P12: 782581.09 | Q12: 784169.84 | R12: 824377.36 | S12: 851667.01 | T12: 880646.88 | U12: 880646.88 | V12: 952542.38 | W12: 819761.38 | X12: 859787.58 | Y12: 899488 | Z12: 899488 | AA12: 829881.75 | AB12: 959947.18
A13: 1 | C13: 기타유동자산 | E13: 524219.16 | F13: 524219.16 | G13: 572165.86 | H13: 647195.94 | I13: 719448.08 | J13: 713578.07 | K13: 713578.07 | L13: 845765.22 | M13: 900819.2 | N13: 926097.36 | O13: 984183.18 | P13: 984183.18 | Q13: 997444.05 | R13: 1031966.6 | S13: 1076792.6 | T13: 1032127 | U13: 1032127 | V13: 1140212.6 | W13: 1023707.8 | X13: 1085580.9 | Y13: 1121950.9 | Z13: 1121950.9 | AA13: 1067327.3 | AB13: 1201255.2
A14: 1 | C14: 유동파생상품자산 | E14: 157360.32 | F14: 157360.32 | G14: 234481.53 | H14: 449552.93 | I14: 925051.78 | J14: 852661.8 | K14: 852661.8 | L14: 546299.73 | M14: 393147.66 | N14: 499261.69 | O14: 265825.97 | P14: 265825.97 | Q14: 309901.32 | R14: 373077.69 | S14: 237510.23 | T14: 630502.42 | U14: 630502.42 | V14: 428417.24 | W14: 529470.32 | X14: 241363.2 | Y14: 358110.48 | Z14: 358110.48 | AA14: 459157.53 | AB14: 548727.3
A15: 1 | C15: 유동확정계약자산 | E15: 280477.68 | F15: 280477.68 | G15: 455916.32 | H15: 1326795.5 | I15: 2674849 | J15: 1061072.8 | K15: 1061072.8 | L15: 1480559.1 | M15: 1523737.1 | N15: 2115539.2 | O15: 1113153.4 | P15: 1113153.4 | Q15: 1685053.2 | R15: 2028135.6 | S15: 1217661.1 | T15: 1420683.7 | U15: 1420683.7 | V15: 1367835.6 | W15: 533261.85 | X15: 651442.67 | Y15: 686960.31 | Z15: 686960.31 | AA15: 989435.75 | AB15: 1081391
A16: 1 | C16: 재고자산 | E16: 1487633.6 | F16: 1487633.6 | G16: 1549255.3 | H16: 1546715.8 | I16: 1601466.5 | J16: 1573509.7 | K16: 1573509.7 | L16: 1722224.7 | M16: 1763087.5 | N16: 1838285 | O16: 1729150.3 | P16: 1729150.3 | Q16: 1162977.1 | R16: 904171.77 | S16: 919122.63 | T16: 452452.89 | U16: 452452.89 | V16: 499653.81 | W16: 500284.61 | X16: 463223.2 | Y16: 489645.27 | Z16: 489645.27 | AA16: 677272.38 | AB16: 497750.84
... A18: 1 | C18: 기타유동금융자산 | E18: 77503.31 | F18: 77503.31 | G18: 77444.4 | H18: 79162.44 | I18: 76909.37 | J18: 77681.13 | K18: 77681.13 | L18: 77791.29 | M18: 77904.86 | N18: 74737.3 | O18: 74387.67 | P18: 74387.67 | Q18: 72561.05 | R18: 72158.06 | S18: 69561.11 | T18: 62127.39 | U18: 62127.39 | V18: 192678.45 | W18: 63117.63 | X18: 64448.28 | Y18: 66751.36 | Z18: 66751.36 | AA18: 67766.39 | AB18: 802498.99
A19: 1 | C19: 매각예정비유동자산및처분자산 | E19: 190409.1 | F19: 190409.1 | G19: 154397.03
A20: 1 | C20: 비유동자산 | E20: 6545013.1 | F20: 6545013.1 | G20: 6516720.9 | H20: 6668840.5 | I20: 7358807.6 | J20: 6079754.5 | K20: 6079754.5 | L20: 6047471.7 | M20: 6030569.2 | N20: 5981824.8 | O20: 6347897.4 | P20: 6347897.4 | Q20: 6555576.8 | R20: 6846397 | S20: 6506473.1 | T20: 7824652 | U20: 7824652 | V20: 7638407.2 | W20: 6941369.6 | X20: 7214897 | Y20: 7541794.3 | Z20: 7541794.3 | AA20: 8304415.6 | AB20: 8275325
A21: 1 | C21: 장기금융자산 | E21: 45675.73 | F21: 45675.73 | G21: 46431.26 | H21: 46357.6 | I21: 46000.34 | J21: 85746 | K21: 85746 | L21: 85772.36 | M21: 85997.98 | N21: 85924.4 | O21: 87302.1 | P21: 87302.1 | Q21: 87591.22 | R21: 87461.09 | S21: 88424.58 | T21: 102341.44 | U21: 102341.44 | V21: 119960.07 | W21: 119983.32 | X21: 176895.16 | Y21: 168378.3 | Z21: 168378.3 | AA21: 165783.22 | AB21: 182438.21
A22: 1 | C22: 투자자산 | E22: 559853.24 | F22: 559853.24 | G22: 544073 | H22: 835696.1 | I22: 1666349.2 | J22: 384139.02 | K22: 384139.02 | L22: 367452.94 | M22: 365553.34 | N22: 367095.25 | O22: 460924.51 | P22: 460924.51 | Q22: 689950.46 | R22: 1024559.9 | S22: 653424.89 | T22: 1679662.2 | U22: 1679662.2 | V22: 1535372.1 | W22: 768416.09 | X22: 1112203.9 | Y22: 1531860.2 | Z22: 1531860.2 | AA22: 2376022.3 | AB22: 2443685.3
A23: 1 | C23: 종속기업및관계기업투자 | E23: 933.53 | F23: 933.53 | G23: 835.3 | H23: 735.4 | I23: 599.61 | J23: 120.27 | K23: 120.27 | L23: 80.62 | M23: 68.65 | N23: 57.99 | O23: 53.63 | P23: 53.63 | Q23: 62.42 | R23: 63.15 | S23: 54.07 | T23: 51.4 | U23: 51.4 | V23: 66.71 | W23: 66.79 | X23: 65.24 | Y23: 69.76 | Z23: 69.76 | AA23: 71.97 | AB23: 77.38
A24: 1 | C24: 유형자산 | E24: 5613735.2 | F24: 5613735.2 | G24: 5588616.6 | H24: 5551065.3 | I24: 5548467 | J24: 5235398.8 | K24: 5235398.8 | L24: 5232765.6 | M24: 5219108.6 | N24: 5227209.7 | O24: 5208721.7 | P24: 5208721.7 | Q24: 5200152.8 | R24: 5201568.9 | S24: 5184646.3 | T24: 5115872.2 | U24: 5115872.2 | V24: 5082731.5 | W24: 5073650.8 | X24: 5089571.7 | Y24: 5107108.3 | Z24: 5107108.3 | AA24: 5113631.4 | AB24: 5130883.2
A25: 1 | C25: 사용권자산 | E25: 38511.42 | F25: 38511.42 | G25: 55189.54 | H25: 65576.87 | I25: 68785.33 | J25: 100697.39 | K25: 100697.39 | L25: 128057.68 | M25: 116542.37 | N25: 106903.78 | O25: 174483.14 | P25: 174483.14 | Q25: 247877.06 | R25: 262129.67 | S25: 237311.3 | T25: 259254.49 | U25: 259254.49 | V25: 249835.04 | W25: 225889.61 | X25: 214881.42 | Y25: 194996.63 | Z25: 194996.63 | AA25: 206532.19 | AB25: 181398.02
A26: 1 | C26: 기타비유동자산 | E26: 82337.36 | F26: 82337.36 | G26: 102854.14 | H26: 102595.02 | I26: 107414.62 | J26: 228106.95 | K26: 228106.95 | L26: 251804.84 | M26: 244270.25 | N26: 229706.53 | O26: 304846.98 | P26: 304846.98 | Q26: 368345.2 | R26: 373491.22 | S26: 338043.19 | T26: 354214.93 | U26: 354214.93 | V26: 330072.99 | W26: 289107.72 | X26: 261085.6 | Y26: 287174.4 | Z26: 287174.4 | AA26: 289735.71 | AB26: 231607.88
A27: 1 | C27: 투자부동산 | E27: 17616.35 | F27: 17616.35 | G27: 17576.88 | H27: 276.71 | I27: 275.67 | J27: 274.64 | K27: 274.64 | L27: 273.6 | O27: 0 | P27: 0 | T27: 0 | U27: 0
A28: 1 | C28: 무형자산 | E28: 24422.52 | F28: 24422.52 | G28: 24818.85 | H28: 23874.94 | I28: 23889.11 | J28: 26426.7 | K28: 26426.7 | L28: 26800.51 | M28: 26925.69 | N28: 27003.04 | O28: 26973.12 | P28: 26973.12 | Q28: 26864.83 | R28: 26927 | S28: 27782.86 | T28: 27842.41 | U28: 27842.41 | V28: 32982.37 | W28: 32201.14 | X28: 32048.09 | Y28: 32017.07 | Z28: 32017.07 | AA28: 35744.31 | AB28: 38340.32
A29: 1 | C29: 비유동파생상품자산 | E29: 145141.39 | F29: 145141.39 | G29: 139065.54 | H29: 244581.2 | I29: 375130.81 | J29: 83310.77 | K29: 83310.77 | L29: 57634.16 | M29: 51230.65 | N29: 33177.76 | O29: 95504.63 | P29: 95504.63 | Q29: 60902.38 | R29: 114313.77 | S29: 101646.1 | T29: 276472.07 | U29: 276472.07 | V29: 246317.46 | W29: 235830.96 | X29: 156941.09 | Y29: 242790.83 | Z29: 242790.83 | AA29: 436336.76 | AB29: 454061.37
A30: 1 | C30: 비유동확정계약자산 | E30: 368102.59 | F30: 368102.59 | G30: 357740.9 | H30: 544021.9 | I30: 1244618.5 | J30: 214961.98 | K30: 214961.98 | L30: 223965.8 | M30: 228256.06 | N30: 247935.1 | O30: 278064.15 | P30: 278064.15 | Q30: 541394.44 | R30: 822721.89 | S30: 463300.14 | T30: 1300797.3 | U30: 1300797.3 | V30: 1169027.8 | W30: 412535.02 | X30: 778302.39 | Y30: 1120621.3 | Z30: 1120621.3 | AA30: 1773830.4 | AB30: 1807108.3
A31: 1 | C31: 장기매출채권및기타채권 | E31: 10411.32 | F31: 10411.32 | G31: 13418.35
A32: 1 | C32: 이연법인세자산 | E32: 236637.08 | F32: 236637.08 | G32: 225363.02 | H32: 155332.48 | I32: 12412.04 | J32: 205408.47 | K32: 205408.47 | L32: 168374.12 | M32: 174711.38 | N32: 130810.22 | O32: 346431.15 | P32: 346431.15 | Q32: 270263.54 | R32: 219850 | S32: 302575.91 | T32: 647060.27 | U32: 647060.27 | V32: 657248.25 | W32: 777993.91 | X32: 719987.74 | Y32: 583634.39 | Z32: 583634.39 | AA32: 489281.94 | AB32: 430808.32
A33: 1 | C33: 자산총계 | E33: 12138596 | F33: 12138596 | G33: 12286879 | H33: 13796449 | I33: 16861060 | J33: 14491698 | K33: 14491698 | L33: 14651888 | M33: 14981182 | N33: 16599199 | O33: 15593389 | P33: 15593389 | Q33: 16359005 | R33: 16778248 | S33: 15075969 | T33: 17194637 | U33: 17194637 | V33: 16281156 | W33: 13941719 | X33: 14539450 | Y33: 14948871 | Z33: 14948871 | AA33: 16568723 | AB33: 17959382
A34: 1 | C34: 유동부채 | E34: 7058249.8 | F34: 7058249.8 | G34: 7256585.7 | H34: 7863958.3 | I34: 9950723.9 | J34: 9216046.8 | K34: 9216046.8 | L34: 9456073.2 | M34: 9734832.9 | N34: 11443466 | O34: 11231917 | P34: 11231917 | Q34: 11809118 | R34: 11960243 | S34: 10839831 | T34: 12029242 | U34: 12029242 | V34: 11181335 | W34: 9559551.2 | X34: 9474581.3 | Y34: 9422232.4 | Z34: 9422232.4 | AA34: 9998876.3 | AB34: 11034660
A35: 1 | C35: 매입채무및기타채무 | E35: 821003.26 | F35: 821003.26 | G35: 829920.43 | H35: 894953.33 | I35: 951053.57 | J35: 1004203.1 | K35: 1004203.1 | L35: 950845.5 | M35: 1029500 | N35: 1103401.9 | O35: 1147302.2 | P35: 1147302.2 | Q35: 1605934.3 | R35: 1037074.4 | S35: 873392.08 | T35: 945568.69 | U35: 945568.69 | V35: 890592.14 | W35: 887132.56 | X35: 855541.54 | Y35: 1022545 | Z35: 1022545 | AA35: 1121859.6 | AB35: 1435233.3
A36: 1 | C36: 단기차입금 | E36: 922449.41 | F36: 922449.41 | G36: 817743.18 | H36: 744625.3 | I36: 1621413.4 | J36: 1407408.4 | K36: 1407408.4 | L36: 1218289.4 | M36: 1465934.4 | N36: 1664104.8 | O36: 1849594.5 | P36: 1849594.5 | Q36: 2075109.7 | R36: 2190689.1 | S36: 2441203 | T36: 2155829.6 | U36: 2155829.6 | V36: 2122745 | W36: 1860047.3 | X36: 1684765 | Y36: 1454489.6 | Z36: 1454489.6 | AA36: 766450.94 | AB36: 789943.13
A37: 1 | C37: 계약부채 | E37: 2628389.4 | F37: 2628389.4 | G37: 2838350.1 | H37: 2749450.1 | I37: 2797222.5 | J37: 3757436.2 | K37: 3757436.2 | L37: 4213136.7 | M37: 4369453.8 | N37: 5170088.6 | O37: 4992172.5 | P37: 4992172.5 | Q37: 5277724.7 | R37: 5527670.4 | S37: 5309287.3 | T37: 5463032.3 | U37: 5463032.3 | V37: 5510132.1 | W37: 5071009.6 | X37: 5367795.8 | Y37: 4580473.4 | Z37: 4580473.4 | AA37: 4950716.7 | AB37: 5433923.9
A38: 1 | C38: 당기법인세부채(미지급법인세) | E38: 4072.8 | F38: 4072.8 | G38: 3673.81 | H38: 75575.88 | I38: 4637.68 | J38: 5170.17 | K38: 5170.17 | L38: 3019.36 | M38: 3442.46 | N38: 3564.09 | O38: 3967.11 | P38: 3967.11 | Q38: 6475.18 | R38: 3528.17 | S38: 2365.07 | T38: 0 | U38: 0 | V38: 676.47 | W38: 848.35 | X38: 313.97 | Y38: 12159.39 | Z38: 12159.39 | AA38: 20190.34 | AB38: 35968.34
A39: 1 | C39: 단기파생상품부채 | E39: 369828.37 | F39: 369828.37 | G39: 491157.58 | H39: 1102591.1 | I39: 2669046.3 | J39: 1094132.8 | K39: 1094132.8 | L39: 1174517.6 | M39: 1151054.2 | N39: 1720315.3 | O39: 719442.42 | P39: 719442.42 | Q39: 984974.04 | R39: 1272684.3 | S39: 377136.67 | T39: 2065507 | U39: 2065507 | V39: 1236269.9 | W39: 406352.66 | X39: 619570 | Y39: 799606.05 | Z39: 799606.05 | AA39: 1393515.9 | AB39: 1693887
A40: 1 | C40: 단기금융부채 | E40: 383652.73 | F40: 383652.73 | G40: 517621.65 | H40: 1129416.5 | I40: 2684835.9 | J40: 1126732.7 | K40: 1126732.7 | L40: 1224792.3 | M40: 1195801.4 | N40: 1757362.3 | O40: 750762.11 | P40: 750762.11 | Q40: 1070044.9 | R40: 1355767.6 | S40: 454297.35 | T40: 2130546.3 | U40: 2130546.3 | V40: 1317706 | W40: 480261.68 | X40: 693758.54 | Y40: 863773.82 | Z40: 863773.82 | AA40: 1463133 | AB40: 1747334.1
A41: 1 | C41: 유동성장기부채 | E41: 927141.09 | F41: 927141.09 | G41: 856555.67 | H41: 774345.18 | I41: 552595.28 | J41: 519288.55 | K41: 519288.55 | L41: 627235.39 | M41: 593940.55 | N41: 815922.36 | O41: 1185307.4 | P41: 1185307.4 | Q41: 1028629.2 | R41: 1154913.9 | S41: 1203982.3 | T41: 925634.84 | U41: 925634.84 | V41: 901182.55 | W41: 852965.56 | X41: 459548.14 | Y41: 277372.89 | Z41: 277372.89 | AA41: 125060.87 | AB41: 5138.33
...

Sheet BS별도
B1: (백만원) | C1: 이름: BS별도H | E1: 4Q21 | F1: 2021 | G1: 1Q22 | H1: 2Q22 | I1: 3Q22 | J1: 4Q22 | K1: 2022 | L1: 1Q23 | M1: 2Q23 | N1: 3Q23 | O1: 4Q23 | P1: 2023 | Q1: 1Q24 | R1: 2Q24 | S1: 3Q24 | T1: 4Q24 | U1: 2024 | V1: 1Q25 | W1: 2Q25 | X1: 3Q25 | Y1: 4Q25 | Z1: 2025 | AA1: 1Q26 | AB1: 2Q26 | AC1: 3Q26 | AD1: 4Q26 | AE1: 2026 | AF1: 1Q27 | AG1: 2Q27 | AH1: 3Q27 | AI1: 4Q27 | AJ1: 2027 | AK1: 1Q28 | AL1: 2Q28 | AM1: 3Q28 | AN1: 4Q28 | AO1: 2028
B2: 별도 | D2: fin json(kship_fin.py)
B3: 삼성중공업(별) | C3: UPDATE: 26-10-19 | E3: 1 | F3: 2 | G3: 3 | H3: 4 | I3: 5 | J3: 6 | K3: 7 | L3: 8 | M3: 9 | N3: 10 | O3: 11 | P3: 12 | Q3: 13 | R3: 14 | S3: 15 | T3: 16 | U3: 17 | V3: 18 | W3: 19 | X3: 20 | Y3: 21 | Z3: 22 | AA3: 23 | AB3: 24 | AC3: 25 | AD3: 26 | AE3: 27 | AF3: 28 | AG3: 29 | AH3: 30 | AI3: 31 | AJ3: 32 | AK3: 33 | AL3: 34 | AM3: 35 | AN3: 36 | AO3: 37
B4: Account Code | C4: AccountNAME | E4: 2021.12 | F4: 2021.12A | G4: 2022.03 | H4: 2022.06 | I4: 2022.09 | J4: 2022.12 | K4: 2022.12A | L4: 2023.03 | M4: 2023.06 | N4: 2023.09 | O4: 2023.12 | P4: 2023.12A | Q4: 2024.03 | R4: 2024.06 | S4: 2024.09 | T4: 2024.12 | U4: 2024.12A | V4: 2025.03 | W4: 2025.06 | X4: 2025.09 | Y4: 2025.12 | Z4: 2025.12A | AA4: 2026.03 | AB4: 2026.06 | AC4: 2026.09 | AD4: 2026.12 | AE4: 2026.12A | AF4: 2027.03 | AG4: 2027.06 | AH4: 2027.09 | AI4: 2027.12 | AJ4: 2027.12A | AK4: 2028.03 | AL4: 2028.06 | AM4: 2028.09 | AN4: 2028.12 | AO4: 2028.12A
A5: 1 | C5: 유동자산 | E5: 5381314 | F5: 5381314 | G5: 5591731.4 | H5: 6745400 | I5: 9179954.6 | J5: 8080046.7 | K5: 8080046.7 | L5: 8432823.1 | M5: 8816102.5 | N5: 10528799 | O5: 9106451.4 | P5: 9106451.4 | Q5: 9696673.3 | R5: 9876070.3 | S5: 8480249.6 | T5: 9329871 | U5: 9329871 | V5: 8632608.6 | W5: 6961978.7 | X5: 7269760.7 | Y5: 7338656.9 | Z5: 7338656.9 | AA5: 8261589.8 | AB5: 9656586.2
A6: 1 | C6: 현금및현금성자산 | E6: 514394.69 | F6: 514394.69 | G6: 614926.47 | H6: 489414.73 | I6: 419090.75 | J6: 514997.41 | K6: 514997.41 | L6: 212662.85 | M6: 592953.89 | N6: 389818.56 | O6: 519631.73 | P6: 519631.73 | Q6: 765620.16 | R6: 272322.38 | S6: 567800.38 | T6: 888448.68 | U6: 888448.68 | V6: 471581.61 | W6: 566760.97 | X6: 1346737.8 | Y6: 685976.42 | Z6: 685976.42 | AA6: 1004973.8 | AB6: 758888.15
A7: 1 | C7: 단기금융상품 | E7: 569031.92 | F7: 569031.92 | G7: 167199.94 | H7: 318436.04 | I7: 70607.48 | J7: 84557.13 | K7: 84557.13 | L7: 348914.05 | M7: 288916.6 | N7: 163843.33 | O7: 136908.15 | P7: 136908.15 | Q7: 86908.95 | R7: 58774.68 | S7: 33976.92 | T7: 33851.15 | U7: 33851.15 | V7: 36804.68 | W7: 36830.1 | X7: 236937.39 | Y7: 287050.93 | Z7: 287050.93 | AA7: 586672.09 | AB7: 716570.94
A8: 1 | C8: 단기금융자산 | E8: 1006869.9 | F8: 1006869.9 | G8: 857597.79 | H8: 2092704.4 | I8: 3663628.9 | J8: 1993508.2 | K8: 1993508.2 | L8: 2373603 | M8: 2199548.2 | N8: 2772081.9 | O8: 1511350.7 | P8: 1511350.7 | Q8: 2079864 | R8: 2457514.8 | S8: 1488990.9 | T8: 2082031.4 | U8: 2082031.4 | V8: 1832210.6 | W8: 1099234.3 | X8: 1129633.7 | Y8: 1332121.7 | Z8: 1332121.7 | AA8: 2035265.4 | AB8: 2346689.2
A9: 1 | C9: 매출채권및기타채권 | E9: 126417.22 | F9: 126417.22 | G9: 179496 | H9: 226529.09 | I9: 233311.61 | J9: 896928.79 | K9: 896928.79 | L9: 496705.52 | M9: 346862.25 | N9: 998045.75 | O9: 512517.29 | P9: 512517.29 | Q9: 569171.21 | R9: 557381.04 | S9: 439410.15 | T9: 1239581.9 | U9: 1239581.9 | V9: 1024362.4 | W9: 570927.8 | X9: 427663.12 | Y9: 1483387.4 | Z9: 1483387.4 | AA9: 699595.36 | AB9: 692857.16
A10: 1 | C10: 계약자산 | E10: 1626474.6 | F10: 1626474.6 | G10: 1740955.5 | H10: 1749710.4 | I10: 2449946.2 | J10: 2319153.1 | K10: 2319153.1 | L10: 2369921.3 | M10: 2934565.5 | N10: 3497798.6 | O10: 3783888.8 | P10: 3783888.8 | Q10: 4039461.9 | R10: 4568227.4 | S10: 3916158.6 | T10: 3572702.9 | U10: 3572702.9 | V10: 3461667.3 | W10: 3143533.6 | X10: 2757869.3 | Y10: 2176503 | Z10: 2176503 | AA10: 2673891.9 | AB10: 3335138.2
A11: 1 | C11: 선급금 | E11: 383604.15 | F11: 383604.15 | G11: 413476.26 | H11: 477250.63 | I11: 552039.34 | J11: 551406.55 | K11: 551406.55 | L11: 612029.97 | M11: 689282.85 | N11: 700986.09 | O11: 786319.82 | P11: 786319.82 | Q11: 787269.12 | R11: 827461.17 | S11: 854406.76 | T11: 882532.54 | U11: 882532.54 | V11: 962464.18 | W11: 828167.66 | X11: 868252.95 | Y11: 904168.57 | Z11: 904168.57 | AA11: 838022.29 | AB11: 969608.02
A12: 1 | C12: 선급금등 | E12: 383604.15 | F12: 383604.15 | G12: 413476.26 | H12: 477250.63 | I12: 552039.34 | J12: 551406.55 | K12: 551406.55 | L12: 612029.97 | M12: 689282.85 | N12: 700986.09 | O12: 786319.82 | P12: 786319.82 | Q12: 787269.12 | R12: 827461.17 | S12: 854406.76 | T12: 882532.54 | U12: 882532.54 | V12: 962464.18 | W12: 828167.66 | X12: 868252.95 | Y12: 904168.57 | Z12: 904168.57 | AA12: 838022.29 | AB12: 969608.02
A13: 1 | C13: 기타유동자산 | E13: 521869.02 | F13: 521869.02 | G13: 565714.07 | H13: 555998.7 | I13: 725568.98 | J13: 709864.87 | K13: 709864.87 | L13: 829091.86 | M13: 887052.81 | N13: 913515.25 | O13: 971787.39 | P13: 971787.39 | Q13: 984196.96 | R13: 1025482.5 | S13: 1070601.2 | T13: 1029667.2 | U13: 1029667.2 | V13: 1145074.5 | W13: 1025782.2 | X13: 1087759.5 | Y13: 1119489.4 | Z13: 1119489.4 | AA13: 1066424.8 | AB13: 1201568.4
A14: 1 | C14: 유동파생상품자산 | E14: 157360.32 | F14: 157360.32 | G14: 234481.53 | H14: 447472.85 | I14: 918172.42 | J14: 847878.35 | K14: 847878.35 | L14: 544129.89 | M14: 386894.49 | N14: 492699.28 | O14: 261289.15 | P14: 261289.15 | Q14: 307901.87 | R14: 370604.47 | S14: 237352.87 | T14: 627496.48 | U14: 627496.48 | V14: 427570.29 | W14: 529142.31 | X14: 241253.64 | Y14: 358110.48 | Z14: 358110.48 | AA14: 459157.53 | AB14: 548727.3
A15: 1 | C15: 유동확정계약자산 | E15: 280477.68 | F15: 280477.68 | G15: 455916.32 | H15: 1326795.5 | I15: 2674849 | J15: 1061072.8 | K15: 1061072.8 | L15: 1480559.1 | M15: 1523737.1 | N15: 2115539.2 | O15: 1113153.4 | P15: 1113153.4 | Q15: 1685053.2 | R15: 2028135.6 | S15: 1217661.1 | T15: 1420683.7 | U15: 1420683.7 | V15: 1367835.6 | W15: 533261.85 | X15: 651442.67 | Y15: 686960.31 | Z15: 686960.31 | AA15: 989435.75 | AB15: 1081391
A16: 1 | C16: 재고자산 | E16: 1483010.1 | F16: 1483010.1 | G16: 1545048.8 | H16: 1541992.6 | I16: 1596910.3 | J16: 1569405.5 | K16: 1569405.5 | L16: 1718239.3 | M16: 1773731 | N16: 1875278.9 | O16: 1727875.7 | P16: 1727875.7 | Q16: 1178079.2 | R16: 917790.68 | S16: 920617.91 | T16: 450129.4 | U16: 450129.4 | V16: 497313.26 | W16: 486923.95 | X16: 447773.89 | Y16: 474335.77 | Z16: 474335.77 | AA16: 683622.64 | AB16: 496015.75
A17: 1 | C17: 당기법인세자산(선급법인세) | E17: 1725.44 | F17: 1725.44 | G17: 554.37 | H17: 994.23 | I17: 1597.75 | J17: 2316.49 | K17: 2316.49 | L17: 1078.95 | M17: 2066.78 | N17: 3465.43 | O17: 4858.18 | P17: 4858.18 | Q17: 6364.4 | R17: 2746.2 | S17: 3420.95 | T17: 4118.13 | U17: 4118.13 | V17: 4936.12 | W17: 1513.35 | X17: 2116.62 | Y17: 0 | Z17: 0 | AB17: 2.74
A18: 1 | C18: 기타유동금융자산 | E18: 85604.13 | F18: 85604.13 | G18: 87438.35 | H18: 88055.89 | I18: 89900.19 | J18: 73872.21 | K18: 73872.21 | L18: 77522.5 | M18: 79322.07 | N18: 78794.2 | O18: 74541.61 | P18: 74541.61 | Q18: 73915.34 | R18: 74605.3 | S18: 73249.46 | T18: 63191.45 | U18: 63191.45 | V18: 195462.85 | W18: 67302.61 | X18: 70206.74 | Y18: 66843.2 | Z18: 66843.2 | AA18: 97815.82 | AB18: 825426.61
A19: 1 | C19: 매각예정비유동자산및처분자산 | E19: 14948.88 | F19: 14948.88
A20: 1 | C20: 비유동자산 | E20: 6510823.6 | F20: 6510823.6 | G20: 6470973 | H20: 7215958.6 | I20: 7882184.1 | J20: 6659327 | K20: 6659327 | L20: 6450685.2 | M20: 6450084.6 | N20: 6398646.7 | O20: 6785527.3 | P20: 6785527.3 | Q20: 6644185.1 | R20: 6831606 | S20: 6508097.2 | T20: 7667982.7 | U20: 7667982.7 | V20: 7481500.8 | W20: 6855938 | X20: 7118134.9 | Y20: 7436031.5 | Z20: 7436031.5 | AA20: 8174325.3 | AB20: 8141604.9
A21: 1 | C21: 장기금융자산 | E21: 45407.88 | F21: 45407.88 | G21: 46210.92 | H21: 46062.7 | I21: 45702.02 | J21: 85516.68 | K21: 85516.68 | L21: 85540.04 | M21: 85776.98 | N21: 85711.42 | O21: 86920.34 | P21: 86920.34 | Q21: 87199.19 | R21: 108044.74 | S21: 107939.26 | T21: 124061.82 | U21: 124061.82 | V21: 141630.07 | W21: 173935.46 | X21: 232676.82 | Y21: 223462.59 | Z21: 223462.59 | AA21: 224002.96 | AB21: 239773.31
A22: 1 | C22: 투자자산 | E22: 992461.37 | F22: 992461.37 | G22: 976826.87 | H22: 1858475.3 | I22: 2689260.8 | J22: 1405108.9 | K22: 1405108.9 | L22: 1220649.4 | M22: 1218773.1 | N22: 1220333.7 | O22: 1313998.5 | P22: 1313998.5 | Q22: 1207440.3 | R22: 1444273.9 | S22: 1072079 | T22: 1973587.7 | U22: 1973587.7 | V22: 1838323.8 | W22: 1105629.9 | X22: 1451248.7 | Y22: 1872182.5 | Z22: 1872182.5 | AA22: 2719477.9 | AB22: 2789722.6
A23: 1 | C23: 종속기업및관계기업투자 | E23: 433809.51 | F23: 433809.51 | G23: 433809.51 | H23: 1023809.5 | I23: 1023809.5 | J23: 1021319.5 | K23: 1021319.5 | L23: 853509.41 | M23: 853509.41 | N23: 853509.41 | O23: 853509.41 | P23: 853509.41 | Q23: 517944.31 | R23: 399193.53 | S23: 399193.53 | T23: 272256.49 | U23: 272256.49 | V23: 281348.42 | W23: 283328.42 | X23: 283328.42 | Y23: 285307.83 | Z23: 285307.83 | AA23: 285307.83 | AB23: 288779.63
A24: 1 | C24: 유형자산 | E24: 5187279.1 | F24: 5187279.1 | G24: 5160256.6 | H24: 5135923.5 | I24: 5110971 | J24: 4848270.8 | K24: 4848270.8 | L24: 4837204.9 | M24: 4836165.3 | N24: 4841477.5 | O24: 4841052.2 | P24: 4841052.2 | Q24: 4824013.6 | R24: 4819229.6 | S24: 4817534.2 | T24: 4715386.9 | U24: 4715386.9 | V24: 4680159 | W24: 4702737.4 | X24: 4706809.4 | Y24: 4716240.8 | Z24: 4716240.8 | AA24: 4703190.5 | AB24: 4714297.4
A25: 1 | C25: 투자부동산 | E25: 17616.35 | F25: 17616.35 | G25: 17576.88 | H25: 276.71 | I25: 275.67 | J25: 274.64 | K25: 274.64 | L25: 273.6 | O25: 0 | P25: 0 | T25: 0 | U25: 0
A26: 1 | C26: 무형자산 | E26: 22877.29 | F26: 22877.29 | G26: 23260.26 | H26: 23479.77 | I26: 23498.52 | J26: 26088.79 | K26: 26088.79 | L26: 26466.04 | M26: 26622.51 | N26: 26671.9 | O26: 26666.12 | P26: 26666.12 | Q26: 26552.44 | R26: 26626.08 | S26: 27503.76 | T26: 27561.3 | U26: 27561.3 | V26: 32721.26 | W26: 31975.54 | X26: 31833.44 | Y26: 31797.93 | Z26: 31797.93 | AA26: 35329.76 | AB26: 37939.08
A27: 1 | C27: 기타비유동자산 | E27: 43741.81 | F27: 43741.81 | G27: 54472.31 | H27: 42677.2 | I27: 45993.28 | J27: 174372.93 | K27: 174372.93 | L27: 197922.05 | M27: 194296.44 | N27: 180272.29 | O27: 258131.99 | P27: 258131.99 | Q27: 316447.13 | R27: 322110.92 | S27: 288993.02 | T27: 306563.1 | U27: 306563.1 | V27: 275413.13 | W27: 239853.87 | X27: 209866.95 | Y27: 235393.65 | Z27: 235393.65 | AA27: 230184.01 | AB27: 172133.96
A28: 1 | C28: 비유동파생상품자산 | E28: 145141.39 | F28: 145141.39 | G28: 139065.54 | H28: 244581.2 | I28: 375130.81 | J28: 83310.77 | K28: 83310.77 | L28: 57634.16 | M28: 51230.65 | N28: 33177.76 | O28: 95504.63 | P28: 95504.63 | Q28: 60902.38 | R28: 114313.77 | S28: 101646.1 | T28: 276472.07 | U28: 276472.07 | V28: 246317.46 | W28: 235830.96 | X28: 156941.09 | Y28: 242790.83 | Z28: 242790.83 | AA28: 436336.76 | AB28: 454061.37
A29: 1 | C29: 비유동확정계약자산 | E29: 368102.59 | F29: 368102.59 | G29: 357740.9 | H29: 544021.9 | I29: 1244618.5 | J29: 214961.98 | K29: 214961.98 | L29: 223965.8 | M29: 228256.06 | N29: 247935.1 | O29: 278064.15 | P29: 278064.15 | Q29: 541394.44 | R29: 822721.89 | S29: 463300.14 | T29: 1300797.3 | U29: 1300797.3 | V29: 1169027.8 | W29: 412535.02 | X29: 778302.39 | Y29: 1120621.3 | Z29: 1120621.3 | AA29: 1773830.4 | AB29: 1807108.3
A30: 1 | C30: 장기매출채권및기타채권 | E30: 10411.32 | F30: 10411.32 | G30: 13418.35
A31: 1 | C31: 이연법인세자산 | E31: 236436.33 | F31: 236436.33 | G31: 225161.76 | H31: 155126.05 | I31: 12184.82 | J31: 205210.92 | K31: 205210.92 | L31: 168169.22 | M31: 174227.28 | N31: 129891.39 | O31: 345678.47 | P31: 345678.47 | Q31: 269731.65 | R31: 219365.47 | S31: 301987.23 | T31: 644883.75 | U31: 644883.75 | V31: 654883.63 | W31: 775741.34 | X31: 718376.42 | Y31: 580416.56 | Z31: 580416.56 | AA31: 486143.2 | AB31: 427511.9
A32: 1 | C32: 자산총계 | E32: 11892138 | F32: 11892138 | G32: 12062704 | H32: 13961359 | I32: 17062139 | J32: 14739374 | K32: 14739374 | L32: 14883508 | M32: 15266187 | N32: 16927445 | O32: 15891979 | P32: 15891979 | Q32: 16340858 | R32: 16707676 | S32: 14988347 | T32: 16997854 | U32: 16997854 | V32: 16114109 | W32: 13817917 | X32: 14387896 | Y32: 14774688 | Z32: 14774688 | AA32: 16435915 | AB32: 17798191
A33: 1 | C33: 유동부채 | E33: 6731070.9 | F33: 6731070.9 | G33: 6938717.9 | H33: 7603021.1 | I33: 9776618.6 | J33: 9494896.2 | K33: 9494896.2 | L33: 9892309.1 | M33: 9959821.3 | N33: 11936723 | O33: 11659137 | P33: 11659137 | Q33: 11860797 | R33: 11979132 | S33: 10851241 | T33: 11878027 | U33: 11878027 | V33: 11049769 | W33: 9455032.3 | X33: 9345607.2 | Y33: 9295708.1 | Z33: 9295708.1 | AA33: 9899119.7 | AB33: 10914452
A34: 1 | C34: 매입채무및기타채무 | E34: 804437.68 | F34: 804437.68 | G34: 821915.14 | H34: 885826.7 | I34: 947143.77 | J34: 1004306.1 | K34: 1004306.1 | L34: 908956.78 | M34: 1017163.8 | N34: 1093903 | O34: 1120716 | P34: 1120716 | Q34: 1584271.1 | R34: 1017611.5 | S34: 856168.13 | T34: 924606.3 | U34: 924606.3 | V34: 878041.55 | W34: 872010.25 | X34: 830448.09 | Y34: 1017053.7 | Z34: 1017053.7 | AA34: 1099461.9 | AB34: 1408096.6
A35: 1 | C35: 단기차입금 | E35: 802069.76 | F35: 802069.76 | G35: 707074.8 | H35: 637305.8 | I35: 1491442.8 | J35: 1284231.3 | K35: 1284231.3 | L35: 1068100.8 | M35: 1295121.2 | N35: 1540149.7 | O35: 1717150.1 | P35: 1717150.1 | Q35: 1941809.1 | R35: 2092596.7 | S35: 2338458.6 | T35: 2032630.1 | U35: 2032630.1 | V35: 2020967.3 | W35: 1783280.6 | X35: 1587251.7 | Y35: 1343121.6 | Z35: 1343121.6 | AA35: 695805.56 | AB35: 706848.25
A36: 1 | C36: 계약부채 | E36: 2458884.6 | F36: 2458884.6 | G36: 2661272.3 | H36: 2693974.6 | I36: 2783246.6 | J36: 3644426 | K36: 3644426 | L36: 4077260.4 | M36: 4024848.7 | N36: 4776546.2 | O36: 4558317 | P36: 4558317 | Q36: 5001661.2 | R36: 5428904.8 | S36: 5203133.6 | T36: 5462956.8 | U36: 5462956.8 | V36: 5509860.5 | W36: 5070288 | X36: 5367437 | Y36: 4576789.8 | Z36: 4576789.8 | AA36: 4950344.8 | AB36: 5433599.9
A37: 1 | C37: 단기파생상품부채 | E37: 369510.68 | F37: 369510.68 | G37: 489325.36 | H37: 1102591.1 | I37: 2669046.3 | J37: 1094132.8 | K37: 1094132.8 | L37: 1174497.7 | M37: 1151054.2 | N37: 1720295.8 | O37: 719442.42 | P37: 719442.42 | Q37: 984974.04 | R37: 1272684.3 | S37: 377136.67 | T37: 2065507 | U37: 2065507 | V37: 1236269.9 | W37: 406352.66 | X37: 619570 | Y37: 798883.58 | Z37: 798883.58 | AA37: 1393515.9 | AB37: 1693887
A38: 1 | C38: 단기금융부채 | E38: 382945.78 | F38: 382945.78 | G38: 506329.52 | H38: 1119328.8 | I38: 2684562.4 | J38: 1126516.8 | K38: 1126516.8 | L38: 1224772.3 | M38: 1194519.8 | N38: 1756912.8 | O38: 750719.74 | P38: 750719.74 | Q38: 1070044.9 | R38: 1355767.6 | S38: 454297.35 | T38: 2130544.5 | U38: 2130544.5 | V38: 1317704.2 | W38: 480259.99 | X38: 693756.79 | Y38: 863051.35 | Z38: 863051.35 | AA38: 1463133 | AB38: 1747334.1
A39: 1 | C39: 유동성장기부채 | E39: 927141.09 | F39: 927141.09 | G39: 856555.67 | H39: 774345.18 | I39: 552595.28 | J39: 1059424.7 | K39: 1059424.7 | L39: 1417303.4 | M39: 1384008.6 | N39: 1855922.4 | O39: 2225307.4 | P39: 2225307.4 | Q39: 1528493.1 | R39: 1404845.8 | S39: 1453914.3 | T39: 925634.84 | U39: 925634.84 | V39: 901182.55 | W39: 852965.56 | X39: 459548.14 | Y39: 277372.89 | Z39: 277372.89 | AA39: 114971.54 | AB39: 0
A40: 1 | C40: 유동리스부채 | E40: 13435.1 | F40: 13435.1 | G40: 17004.16 | H40: 16737.64 | I40: 15516.04 | J40: 32383.96 | K40: 32383.96 | L40: 50274.64 | M40: 43465.61 | N40: 36616.95 | O40: 31277.32 | P40: 31277.32 | Q40: 85070.84 | R40: 83083.36 | S40: 77160.68 | T40: 65037.53 | U40: 65037.53 | V40: 81434.32 | W40: 73907.33 | X40: 74186.79 | Y40: 64167.77 | Z40: 64167.77 | AA40: 69617.09 | AB40: 53447.08
...

Sheet subQ
A1: YQ | C1: subQ 분기 서브모델(억원, U=100) | E1: 4Q21 | F1: 2021 | G1: 1Q22 | H1: 2Q22 | I1: 3Q22 | J1: 4Q22 | K1: 2022 | L1: 1Q23 | M1: 2Q23 | N1: 3Q23 | O1: 4Q23 | P1: 2023 | Q1: 1Q24 | R1: 2Q24 | S1: 3Q24 | T1: 4Q24 | U1: 2024 | V1: 1Q25 | W1: 2Q25 | X1: 3Q25 | Y1: 4Q25 | Z1: 2025 | AA1: 1Q26 | AB1: 2Q26 | AC1: 3Q26 | AD1: 4Q26 | AE1: 2026 | AF1: 1Q27 | AG1: 2Q27 | AH1: 3Q27 | AI1: 4Q27 | AJ1: 2027 | AK1: 1Q28 | AL1: 2Q28 | AM1: 3Q28 | AN1: 4Q28 | AO1: 2028
A2: A=이름(key) B=그룹 C=단위 D=FnGuide 계정명(VLOOKUP 키). 확정=VLOOKUP(BS), 추정=변수 가정 참조
E3: 1 | F3: 2 | G3: 3 | H3: 4 | I3: 5 | J3: 6 | K3: 7 | L3: 8 | M3: 9 | N3: 10 | O3: 11 | P3: 12 | Q3: 13 | R3: 14 | S3: 15 | T3: 16 | U3: 17 | V3: 18 | W3: 19 | X3: 20 | Y3: 21 | Z3: 22 | AA3: 23 | AB3: 24 | AC3: 25 | AD3: 26 | AE3: 27 | AF3: 28 | AG3: 29 | AH3: 30 | AI3: 31 | AJ3: 32 | AK3: 33 | AL3: 34 | AM3: 35 | AN3: 36 | AO3: 37
E4: 2021.12 | F4: 2021.12A | G4: 2022.03 | H4: 2022.06 | I4: 2022.09 | J4: 2022.12 | K4: 2022.12A | L4: 2023.03 | M4: 2023.06 | N4: 2023.09 | O4: 2023.12 | P4: 2023.12A | Q4: 2024.03 | R4: 2024.06 | S4: 2024.09 | T4: 2024.12 | U4: 2024.12A | V4: 2025.03 | W4: 2025.06 | X4: 2025.09 | Y4: 2025.12 | Z4: 2025.12A | AA4: 2026.03 | AB4: 2026.06 | AC4: 2026.09 | AD4: 2026.12 | AE4: 2026.12A | AF4: 2027.03 | AG4: 2027.06 | AH4: 2027.09 | AI4: 2027.12 | AJ4: 2027.12A | AK4: 2028.03 | AL4: 2028.06 | AM4: 2028.09 | AN4: 2028.12 | AO4: 2028.12A
A5: 매출액 | B5: 손익 | C5: 억원 | D5: 매출액(수익) | E5: =IFERROR(VLOOKUP($D5,BS연결,MATCH(E$1,BS연결H,0),0)/100,"") | G5: =IFERROR(VLOOKUP($D5,BS연결,MATCH(G$1,BS연결H,0),0)/100,"") | H5: =IFERROR(VLOOKUP($D5,BS연결,MATCH(H$1,BS연결H,0),0)/100,"") | I5: =IFERROR(VLOOKUP($D5,BS연결,MATCH(I$1,BS연결H,0),0)/100,"") | J5: =IFERROR(VLOOKUP($D5,BS연결,MATCH(J$1,BS연결H,0),0)/100,"") | K5: =IFERROR(VLOOKUP($D5,BS연결,MATCH(K$1,BS연결H,0),0)/100,"") | L5: =IFERROR(VLOOKUP($D5,BS연결,MATCH(L$1,BS연결H,0),0)/100,"") | M5: =IFERROR(VLOOKUP($D5,BS연결,MATCH(M$1,BS연결H,0),0)/100,"") | N5: =IFERROR(VLOOKUP($D5,BS연결,MATCH(N$1,BS연결H,0),0)/100,"") | ... AB5: =IFERROR(VLOOKUP($D5,BS연결,MATCH(AB$1,BS연결H,0),0)/100,"") | AC5: =IFERROR(AC38+AC42,"") | AD5: =IFERROR(AD38+AD42,"") | AE5: =SUM(AA5:AD5) | AF5: =IFERROR(AF38+AF42,"") | AG5: =IFERROR(AG38+AG42,"") | AH5: =IFERROR(AH38+AH42,"") | AI5: =IFERROR(AI38+AI42,"") | AJ5: =SUM(AF5:AI5) | AK5: =IFERROR(AK38+AK42,"") | AL5: =IFERROR(AL38+AL42,"") | AM5: =IFERROR(AM38+AM42,"") | AN5: =IFERROR(AN38+AN42,"") | AO5: =SUM(AK5:AN5)
A6: 매출원가 | B6: 손익 | C6: 억원 | D6: 매출원가 | E6: =IFERROR(VLOOKUP($D6,BS연결,MATCH(E$1,BS연결H,0),0)/100,"") | G6: =IFERROR(VLOOKUP($D6,BS연결,MATCH(G$1,BS연결H,0),0)/100,"") | H6: =IFERROR(VLOOKUP($D6,BS연결,MATCH(H$1,BS연결H,0),0)/100,"") | I6: =IFERROR(VLOOKUP($D6,BS연결,MATCH(I$1,BS연결H,0),0)/100,"") | J6: =IFERROR(VLOOKUP($D6,BS연결,MATCH(J$1,BS연결H,0),0)/100,"") | K6: =IFERROR(VLOOKUP($D6,BS연결,MATCH(K$1,BS연결H,0),0)/100,"") | L6: =IFERROR(VLOOKUP($D6,BS연결,MATCH(L$1,BS연결H,0),0)/100,"") | M6: =IFERROR(VLOOKUP($D6,BS연결,MATCH(M$1,BS연결H,0),0)/100,"") | N6: =IFERROR(VLOOKUP($D6,BS연결,MATCH(N$1,BS연결H,0),0)/100,"") | ... AB6: =IFERROR(VLOOKUP($D6,BS연결,MATCH(AB$1,BS연결H,0),0)/100,"") | AC6: =IFERROR(AC5-AC7,"") | AD6: =IFERROR(AD5-AD7,"") | AE6: =SUM(AA6:AD6) | AF6: =IFERROR(AF5-AF7,"") | AG6: =IFERROR(AG5-AG7,"") | AH6: =IFERROR(AH5-AH7,"") | AI6: =IFERROR(AI5-AI7,"") | AJ6: =SUM(AF6:AI6) | AK6: =IFERROR(AK5-AK7,"") | AL6: =IFERROR(AL5-AL7,"") | AM6: =IFERROR(AM5-AM7,"") | AN6: =IFERROR(AN5-AN7,"") | AO6: =SUM(AK6:AN6)
A7: 매출총이익 | B7: 손익 | C7: 억원 | D7: 매출총이익 | E7: =IFERROR(VLOOKUP($D7,BS연결,MATCH(E$1,BS연결H,0),0)/100,"") | G7: =IFERROR(VLOOKUP($D7,BS연결,MATCH(G$1,BS연결H,0),0)/100,"") | H7: =IFERROR(VLOOKUP($D7,BS연결,MATCH(H$1,BS연결H,0),0)/100,"") | I7: =IFERROR(VLOOKUP($D7,BS연결,MATCH(I$1,BS연결H,0),0)/100,"") | J7: =IFERROR(VLOOKUP($D7,BS연결,MATCH(J$1,BS연결H,0),0)/100,"") | K7: =IFERROR(VLOOKUP($D7,BS연결,MATCH(K$1,BS연결H,0),0)/100,"") | L7: =IFERROR(VLOOKUP($D7,BS연결,MATCH(L$1,BS연결H,0),0)/100,"") | M7: =IFERROR(VLOOKUP($D7,BS연결,MATCH(M$1,BS연결H,0),0)/100,"") | N7: =IFERROR(VLOOKUP($D7,BS연결,MATCH(N$1,BS연결H,0),0)/100,"") | ... AB7: =IFERROR(VLOOKUP($D7,BS연결,MATCH(AB$1,BS연결H,0),0)/100,"") | AC7: =IFERROR(AC9+AC8,"") | AD7: =IFERROR(AD9+AD8,"") | AE7: =SUM(AA7:AD7) | AF7: =IFERROR(AF9+AF8,"") | AG7: =IFERROR(AG9+AG8,"") | AH7: =IFERROR(AH9+AH8,"") | AI7: =IFERROR(AI9+AI8,"") | AJ7: =SUM(AF7:AI7) | AK7: =IFERROR(AK9+AK8,"") | AL7: =IFERROR(AL9+AL8,"") | AM7: =IFERROR(AM9+AM8,"") | AN7: =IFERROR(AN9+AN8,"") | AO7: =SUM(AK7:AN7)
