Workbook
Name 변수H: 변수!$C$1:$AO$1
Name 환율: 변수!$C$6:$AO$13
Name BS연결H: BS연결!$C$1:$AO$1
Name BS연결: BS연결!$C$5:$AO$104
Name BS별도H: BS별도!$C$1:$AO$1
Name BS별도: BS별도!$C$5:$AO$92
Name SUBQH: subQ!$A$1:$AO$1
Name subQ: subQ!$A$5:$AO$40

Sheet README
A1: HD현대미포(010620) 실적 모델 — ARGUS 한국조선
A2: 기준 분기 2025Q3 · 마지막 실적 2025Q3 · 생성 2026-10-11
A3: 모든 수치는 모델 산출값(DART 공개 재무제표 + 우리 추정)이다 — 목표주가·투자 추천 아님. 참고용 · 투자조언 아님.
A5: 시트
A6: 변수 가정 시계열. 환율 8행(ECB via frankfurter — L2 fx.json; 추정 분기 = 노란 가정), 추정 드라이버(노란 셀 = 모델값에서 역산한 가정, 바꾸면 재계산; 연녹 셀 = 3절 스칼라 참조 수식), 3절 스칼라 가정(세율·판관비율·지배주주비중·이자율·종가·PER 밴드·COE·외화 순노출·헤지비율)
A7: BS연결/BS별도 FnGuide 계정명 × 기간 값 덤프(백만원). 행1 분기라벨, 행4 YYYY.MM / YYYY.12A. 이름정의 BS연결H·BS연결(계정명 C열부터)
A8: subQ 분기 서브모델(억원 = 백만원/100). 확정 행: =IFERROR(VLOOKUP($D행,BS연결,MATCH(E$1,BS연결H,0),0)/100,"") 추정 행: 변수 시트 가정 셀 참조 수식. 외환손익·파생상품손익은 BS 계정 합·차, 기타금융손익은 잔차, OPM·EPS·BPS·PER·PBR 은 파생 수식
A9: SLS 선표(조선사만, sls json 있을 때): 요약 행(sls 저장값) + 계약별 스케줄(백만$) × (헤지비율 × 헤지환율 + (1−헤지비율) × 건조시점 환율[변수 원/달러(평균)]) → 원화 수식 블록 → 합계 행이 subQ 매출조선에 연결
A10: 시나리오 신규수주 보수/기준/낙관(forecast_panel 패널, 모델에 scenarios 가 있을 때만): 매출액·영업이익 = subQ 기준값 ± (시나리오 신규 − base 신규) × OPM. base 만 subQ 행에 포함, 나머지는 합산 안 함
A11: 분기/연간예상 subQ 를 이름(A열 key)으로 VLOOKUP 한 보고서 표(억원)
A12: TP PER 밴드 × 12M fwd EPS, PBR = ROE/COE × BPS — 모델 산출값 구간, 목표주가·추천 아님
A13: 외화 환율 QoQ, 외화 순노출 × Δ기말환율 → 환관련손익 추정
... A34: 백테스트: {"freeze": "2025Q2", "horizon": 4, "revenue_wape_pct": 3.5, "op_wape_pct": 85.0, "n": 1, "note": "실측 1분기만 비교(나머지는 실적 없음 — 추정 vs 추정은 세지 않음) · 단일 회사 — 통계 아님", "driver_at_freeze": "trend_seasonal", "selection_oos_at_freeze": null, "frozen_inputs": "fin(연결/별도)·고객 조선사 모델·지주 자회사 모델은 2025Q2 까지의 분기만; 선표는 체결일 ≤ 2025Q2 말일 계약(원장 최신 금액·코호트 등급, 환산 없음); 잔고는 yards_cache 2025Q2; 시세·환율 forward·prices·forecast_panel 신규수주 미사용. 고객 가중치(suppliers.json 언급 비중)와 합병 체인링크는 현재 지식; 고객 연동 채택은 동결 모델 안에서도 자기 la−4분기 OOS 규칙(selection_oos_at_freeze)", "detail": [{"q": "2025Q3", "rev_pred": 12543.01, "rev_act": 13003.49, "op_pred": 301.93, "op_act": 2008.07}]}

Sheet 변수
C1: 이름: 변수H | E1: 4Q21 | F1: 2021 | G1: 1Q22 | H1: 2Q22 | I1: 3Q22 | J1: 4Q22 | K1: 2022 | L1: 1Q23 | M1: 2Q23 | N1: 3Q23 | O1: 4Q23 | P1: 2023 | Q1: 1Q24 | R1: 2Q24 | S1: 3Q24 | T1: 4Q24 | U1: 2024 | V1: 1Q25 | W1: 2Q25 | X1: 3Q25 | Y1: 4Q25 | Z1: 2025 | AA1: 1Q26 | AB1: 2Q26 | AC1: 3Q26 | AD1: 4Q26 | AE1: 2026 | AF1: 1Q27 | AG1: 2Q27 | AH1: 3Q27 | AI1: 4Q27 | AJ1: 2027 | AK1: 1Q28 | AL1: 2Q28 | AM1: 3Q28 | AN1: 4Q28 | AO1: 2028
A2: 가정 시계열 — 노란 셀은 추정 가정(모델값에서 역산), 연녹 셀은 3절 스칼라 참조 수식. 바꾸면 subQ·분기·연간예상·TP·시나리오가 재계산됩니다.
E3: 1 | F3: 2 | G3: 3 | H3: 4 | I3: 5 | J3: 6 | K3: 7 | L3: 8 | M3: 9 | N3: 10 | O3: 11 | P3: 12 | Q3: 13 | R3: 14 | S3: 15 | T3: 16 | U3: 17 | V3: 18 | W3: 19 | X3: 20 | Y3: 21 | Z3: 22 | AA3: 23 | AB3: 24 | AC3: 25 | AD3: 26 | AE3: 27 | AF3: 28 | AG3: 29 | AH3: 30 | AI3: 31 | AJ3: 32 | AK3: 33 | AL3: 34 | AM3: 35 | AN3: 36 | AO3: 37
E4: 2021.12 | F4: 2021.12A | G4: 2022.03 | H4: 2022.06 | I4: 2022.09 | J4: 2022.12 | K4: 2022.12A | L4: 2023.03 | M4: 2023.06 | N4: 2023.09 | O4: 2023.12 | P4: 2023.12A | Q4: 2024.03 | R4: 2024.06 | S4: 2024.09 | T4: 2024.12 | U4: 2024.12A | V4: 2025.03 | W4: 2025.06 | X4: 2025.09 | Y4: 2025.12 | Z4: 2025.12A | AA4: 2026.03 | AB4: 2026.06 | AC4: 2026.09 | AD4: 2026.12 | AE4: 2026.12A | AF4: 2027.03 | AG4: 2027.06 | AH4: 2027.09 | AI4: 2027.12 | AJ4: 2027.12A | AK4: 2028.03 | AL4: 2028.06 | AM4: 2028.09 | AN4: 2028.12 | AO4: 2028.12A
B5: 1. FX | C5: 이름: 환율
A6: USDKRW_avg | C6: 원/달러(평균) | E6: 1183.5 | F6: 1145.51 | G6: 1205.78 | H6: 1262.09 | I6: 1341.93 | J6: 1360.12 | K6: 1292.98 | L6: 1276.95 | M6: 1315.69 | N6: 1313.62 | O6: 1322.01 | P6: 1306.85 | Q6: 1330.14 | R6: 1371.28 | S6: 1356.22 | T6: 1396.3 | U6: 1363.53 | V6: 1452.28 | W6: 1398.52 | X6: 1386.95 | Y6: 1449.19 | Z6: 1421.52 | AA6: 1466.12 | AB6: 1501.75 | AC6: 1418.75 | AD6: 1345.14 | AE6: 1457.21 | AF6: 1341.49 | AG6: 1341.49 | AH6: 1341.49 | AI6: 1341.49 | AK6: 1341.49 | AL6: 1341.49 | AM6: 1341.49 | AN6: 1341.49
A7: USDKRW_end | C7: 원/달러(기말) | E7: 1188.75 | F7: 1188.75 | G7: 1213.74 | H7: 1301.24 | I7: 1436.9 | J7: 1260.16 | K7: 1260.16 | L7: 1305.99 | M7: 1321.44 | N7: 1345.35 | O7: 1297.43 | P7: 1297.43 | Q7: 1349.25 | R7: 1377.73 | S7: 1312.17 | T7: 1474.78 | U7: 1474.78 | V7: 1474.54 | W7: 1355.13 | X7: 1403.67 | Y7: 1444.2 | Z7: 1444.2 | AA7: 1524.8 | AB7: 1550.89 | AC7: 1355.4 | AD7: 1341.49 | AE7: 1341.49 | AF7: 1341.49 | AG7: 1341.49 | AH7: 1341.49 | AI7: 1341.49 | AK7: 1341.49 | AL7: 1341.49 | AM7: 1341.49 | AN7: 1341.49
A8: JPY100KRW_avg | C8: 원/100Y(평균) | E8: 1041.02 | F8: 1042.74 | G8: 1036.79 | H8: 972.23 | I8: 970.61 | J8: 961.03 | K8: 985.1 | L8: 964.89 | M8: 957.36 | N8: 909 | O8: 893.22 | P8: 931.11 | Q8: 896.29 | R8: 880.14 | S8: 909.35 | T8: 917.25 | U8: 900.92 | V8: 952.59 | W8: 967.92 | X8: 940.32 | Y8: 940.77 | Z8: 950.17 | AA8: 934.39 | AB8: 942.16 | AC8: 890.41 | AD8: 850.79 | AE8: 919.21 | AF8: 847.7 | AG8: 847.7 | AH8: 847.7 | AI8: 847.7 | AK8: 847.7 | AL8: 847.7 | AM8: 847.7 | AN8: 847.7
A9: JPY100KRW_end | C9: 원/100Y(기말) | E9: 1032.62 | F9: 1032.62 | G9: 996.83 | H9: 954.9 | I9: 993.29 | J9: 955.54 | K9: 955.54 | L9: 980.62 | M9: 913.67 | N9: 901.47 | O9: 917.04 | P9: 917.04 | Q9: 892.42 | R9: 857.76 | S9: 919.21 | T9: 939.65 | U9: 939.65 | V9: 986.84 | W9: 938.85 | X9: 948.49 | Y9: 921.81 | Z9: 921.81 | AA9: 955.99 | AB9: 954.75 | AC9: 863.31 | AD9: 847.7 | AE9: 847.7 | AF9: 847.7 | AG9: 847.7 | AH9: 847.7 | AI9: 847.7 | AK9: 847.7 | AL9: 847.7 | AM9: 847.7 | AN9: 847.7
A10: EURKRW_avg | C10: W/Euro(평균) | E10: 1353.32 | F10: 1354.06 | G10: 1352.29 | H10: 1343.31 | I10: 1350.63 | J10: 1386.07 | K10: 1358.07 | L10: 1369.93 | M10: 1432.41 | N10: 1429.41 | O10: 1420.91 | P10: 1412.88 | Q10: 1444.21 | R10: 1476.42 | S10: 1489.3 | T10: 1490.78 | U10: 1475.4 | V10: 1528.33 | W10: 1585.13 | X10: 1620.04 | Y10: 1686.02 | Z10: 1605.45 | AA10: 1715.47 | AB10: 1746.09 | AC10: 1631.97 | AD10: 1509.74 | AE10: 1689.95 | AF10: 1503.27 | AG10: 1503.27 | AH10: 1503.27 | AI10: 1503.27 | AK10: 1503.27 | AL10: 1503.27 | AM10: 1503.27 | AN10: 1503.27
A11: EURKRW_end | C11: W/Euro(기말) | E11: 1346.38 | F11: 1346.38 | G11: 1347.37 | H11: 1351.6 | I11: 1400.62 | J11: 1344.08 | K11: 1344.08 | L11: 1420.26 | M11: 1435.88 | N11: 1425.26 | O11: 1433.66 | P11: 1433.66 | Q11: 1458.68 | R11: 1474.86 | S11: 1469.1 | T11: 1532.14 | U11: 1532.14 | V11: 1594.72 | W11: 1588.22 | X11: 1648.04 | Y11: 1696.94 | Z11: 1696.94 | AA11: 1753.21 | AB11: 1767.09 | AC11: 1539.06 | AD11: 1503.27 | AE11: 1503.27 | AF11: 1503.27 | AG11: 1503.27 | AH11: 1503.27 | AI11: 1503.27 | AK11: 1503.27 | AL11: 1503.27 | AM11: 1503.27 | AN11: 1503.27
A12: CNYKRW_avg | C12: 원/중국원(평균) | E12: 185.14 | F12: 177.65 | G12: 189.93 | H12: 190.76 | I12: 195.79 | J12: 191.09 | K12: 191.93 | L12: 186.59 | M12: 187.45 | N12: 181.28 | O12: 182.86 | P12: 184.52 | Q12: 185.04 | R12: 189.35 | S12: 189.24 | T12: 194.24 | U12: 189.49 | V12: 199.63 | W12: 193.41 | X12: 193.79 | Y12: 204.38 | Z12: 197.8 | AA12: 211.75 | AB12: 220.8 | AC12: 210.43 | AD12: 200.69 | AE12: 213.75 | AF12: 200.46 | AG12: 200.46 | AH12: 200.46 | AI12: 200.46 | AK12: 200.46 | AL12: 200.46 | AM12: 200.46 | AN12: 200.46
A13: CNYKRW_end | C13: 원/중국원(기말) | E13: 187.13 | F13: 187.13 | G13: 191.38 | H13: 194.13 | I13: 201.92 | J13: 182.67 | K13: 182.67 | L13: 189.97 | M13: 181.8 | N13: 184.26 | O13: 182.61 | P13: 182.61 | Q13: 186.66 | R13: 189.7 | S13: 187.12 | T13: 202.04 | U13: 202.04 | V13: 203.3 | W13: 189.14 | X13: 197.16 | Y13: 206.28 | Z13: 206.28 | AA13: 220.97 | AB13: 228.56 | AC13: 202.16 | AD13: 200.46 | AE13: 200.46 | AF13: 200.46 | AG13: 200.46 | AH13: 200.46 | AI13: 200.46 | AK13: 200.46 | AL13: 200.46 | AM13: 200.46 | AN13: 200.46
B15: 2. 추정 드라이버 | C15: 실적 열 = subQ 실현값(수식), 추정 열 = 가정(노란 = 모델값 역산, 연녹 = 3절 스칼라 참조)
A16: drv:매출액 | B16: yoy | C16: 매출액 YoY | J16: =IFERROR(subQ!J5/subQ!E5-1,"") | L16: =IFERROR(subQ!L5/subQ!G5-1,"") | M16: =IFERROR(subQ!M5/subQ!H5-1,"") | N16: =IFERROR(subQ!N5/subQ!I5-1,"") | O16: =IFERROR(subQ!O5/subQ!J5-1,"") | Q16: =IFERROR(subQ!Q5/subQ!L5-1,"") | R16: =IFERROR(subQ!R5/subQ!M5-1,"") | S16: =IFERROR(subQ!S5/subQ!N5-1,"") | T16: =IFERROR(subQ!T5/subQ!O5-1,"") | V16: =IFERROR(subQ!V5/subQ!Q5-1,"") | W16: =IFERROR(subQ!W5/subQ!R5-1,"") | X16: =IFERROR(subQ!X5/subQ!S5-1,"") | Y16: 0.19292305 | AA16: 0.19292325 | AB16: 0.1929231 | AC16: 0.19292266 | AD16: 0.096461424 | AF16: 0.096460866 | AG16: 0.09646123 | AH16: 0.096461744 | AI16: 0.048230378 | AK16: 0.048230695 | AL16: 0.048230856 | AM16: 0.048230619 | AN16: 0.024115673
A17: drv:판관비 | B17: ratio | C17: 판관비율(/매출) | E17: =IFERROR(subQ!E8/subQ!E5,"") | F17: =IFERROR(subQ!F8/subQ!F5,"") | G17: =IFERROR(subQ!G8/subQ!G5,"") | H17: =IFERROR(subQ!H8/subQ!H5,"") | I17: =IFERROR(subQ!I8/subQ!I5,"") | J17: =IFERROR(subQ!J8/subQ!J5,"") | K17: =IFERROR(subQ!K8/subQ!K5,"") | L17: =IFERROR(subQ!L8/subQ!L5,"") | ... X17: =IFERROR(subQ!X8/subQ!X5,"") | Y17: =$D$46 | Z17: =IFERROR(subQ!Z8/subQ!Z5,"") | AA17: =$D$46 | AB17: =$D$46 | AC17: =$D$46 | AD17: =$D$46 | AE17: =IFERROR(subQ!AE8/subQ!AE5,"") | AF17: =$D$46 | AG17: =$D$46 | AH17: =$D$46 | AI17: =$D$46 | AJ17: =IFERROR(subQ!AJ8/subQ!AJ5,"") | AK17: =$D$46 | AL17: =$D$46 | AM17: =$D$46 | AN17: =$D$46 | AO17: =IFERROR(subQ!AO8/subQ!AO5,"")
A18: drv:영업이익 | B18: ratio | C18: 영업이익률(OPM) | E18: =IFERROR(subQ!E9/subQ!E5,"") | F18: =IFERROR(subQ!F9/subQ!F5,"") | G18: =IFERROR(subQ!G9/subQ!G5,"") | H18: =IFERROR(subQ!H9/subQ!H5,"") | I18: =IFERROR(subQ!I9/subQ!I5,"") | J18: =IFERROR(subQ!J9/subQ!J5,"") | K18: =IFERROR(subQ!K9/subQ!K5,"") | L18: =IFERROR(subQ!L9/subQ!L5,"") | ... X18: =IFERROR(subQ!X9/subQ!X5,"") | Y18: 0.032835274 | Z18: =IFERROR(subQ!Z9/subQ!Z5,"") | AA18: 0.03283506 | AB18: 0.032835077 | AC18: 0.03283553 | AD18: 0.03283528 | AE18: =IFERROR(subQ!AE9/subQ!AE5,"") | AF18: 0.032835131 | AG18: 0.032834959 | AH18: 0.032835366 | AI18: 0.032835146 | AJ18: =IFERROR(subQ!AJ9/subQ!AJ5,"") | AK18: 0.032835012 | AL18: 0.032834927 | AM18: 0.032835039 | AN18: 0.032835282 | AO18: =IFERROR(subQ!AO9/subQ!AO5,"")
A19: drv:외환손익 | B19: abs | C19: 외환손익 (가정, 억원) | E19: =subQ!E13 | F19: =subQ!F13 | G19: =subQ!G13 | H19: =subQ!H13 | I19: =subQ!I13 | J19: =subQ!J13 | K19: =subQ!K13 | L19: =subQ!L13 | ... X19: =subQ!X13 | Y19: 0 | Z19: =subQ!Z13 | AA19: 0 | AB19: 0 | AC19: 0 | AD19: 0 | AE19: =subQ!AE13 | AF19: 0 | AG19: 0 | AH19: 0 | AI19: 0 | AJ19: =subQ!AJ13 | AK19: 0 | AL19: 0 | AM19: 0 | AN19: 0 | AO19: =subQ!AO13
A20: drv:파생상품손익 | B20: abs | C20: 파생상품손익 (가정, 억원) | E20: =subQ!E14 | F20: =subQ!F14 | G20: =subQ!G14 | H20: =subQ!H14 | I20: =subQ!I14 | J20: =subQ!J14 | K20: =subQ!K14 | L20: =subQ!L14 | ... X20: =subQ!X14 | Y20: 0 | Z20: =subQ!Z14 | AA20: 0 | AB20: 0 | AC20: 0 | AD20: 0 | AE20: =subQ!AE14 | AF20: 0 | AG20: 0 | AH20: 0 | AI20: 0 | AJ20: =subQ!AJ14 | AK20: 0 | AL20: 0 | AM20: 0 | AN20: 0 | AO20: =subQ!AO14
A21: drv:기타금융손익 | B21: abs | C21: 기타금융손익 (가정, 억원) | E21: =subQ!E15 | F21: =subQ!F15 | G21: =subQ!G15 | H21: =subQ!H15 | I21: =subQ!I15 | J21: =subQ!J15 | K21: =subQ!K15 | L21: =subQ!L15 | ... X21: =subQ!X15 | Y21: 0 | Z21: =subQ!Z15 | AA21: 0 | AB21: 0 | AC21: 0 | AD21: 0 | AE21: =subQ!AE15 | AF21: 0 | AG21: 0 | AH21: 0 | AI21: 0 | AJ21: =subQ!AJ15 | AK21: 0 | AL21: 0 | AM21: 0 | AN21: 0 | AO21: =subQ!AO15
A22: drv:기타영업외손익 | B22: abs | C22: 기타영업외손익 (가정, 억원) | E22: =subQ!E16 | F22: =subQ!F16 | G22: =subQ!G16 | H22: =subQ!H16 | I22: =subQ!I16 | J22: =subQ!J16 | K22: =subQ!K16 | L22: =subQ!L16 | ... X22: =subQ!X16 | Y22: 0 | Z22: =subQ!Z16 | AA22: 0 | AB22: 0 | AC22: 0 | AD22: 0 | AE22: =subQ!AE16 | AF22: 0 | AG22: 0 | AH22: 0 | AI22: 0 | AJ22: =subQ!AJ16 | AK22: 0 | AL22: 0 | AM22: 0 | AN22: 0 | AO22: =subQ!AO16
A23: drv:법인세비용 | B23: tax | C23: 법인세율(/세전) — 법인세 = MAX(세전,0) × 세율 | E23: =IFERROR(subQ!E18/subQ!E17,"") | F23: =IFERROR(subQ!F18/subQ!F17,"") | G23: =IFERROR(subQ!G18/subQ!G17,"") | H23: =IFERROR(subQ!H18/subQ!H17,"") | I23: =IFERROR(subQ!I18/subQ!I17,"") | J23: =IFERROR(subQ!J18/subQ!J17,"") | K23: =IFERROR(subQ!K18/subQ!K17,"") | L23: =IFERROR(subQ!L18/subQ!L17,"") | ... X23: =IFERROR(subQ!X18/subQ!X17,"") | Y23: =$D$45 | Z23: =IFERROR(subQ!Z18/subQ!Z17,"") | AA23: =$D$45 | AB23: =$D$45 | AC23: =$D$45 | AD23: =$D$45 | AE23: =IFERROR(subQ!AE18/subQ!AE17,"") | AF23: =$D$45 | AG23: =$D$45 | AH23: =$D$45 | AI23: =$D$45 | AJ23: =IFERROR(subQ!AJ18/subQ!AJ17,"") | AK23: =$D$45 | AL23: =$D$45 | AM23: =$D$45 | AN23: =$D$45 | AO23: =IFERROR(subQ!AO18/subQ!AO17,"")
A24: drv:지배주주순이익 | B24: ratio | C24: 지배주주 비중(/당기순이익) | E24: =IFERROR(subQ!E20/subQ!E19,"") | F24: =IFERROR(subQ!F20/subQ!F19,"") | G24: =IFERROR(subQ!G20/subQ!G19,"") | H24: =IFERROR(subQ!H20/subQ!H19,"") | I24: =IFERROR(subQ!I20/subQ!I19,"") | J24: =IFERROR(subQ!J20/subQ!J19,"") | K24: =IFERROR(subQ!K20/subQ!K19,"") | L24: =IFERROR(subQ!L20/subQ!L19,"") | ... X24: =IFERROR(subQ!X20/subQ!X19,"") | Y24: =$D$47 | Z24: =IFERROR(subQ!Z20/subQ!Z19,"") | AA24: =$D$47 | AB24: =$D$47 | AC24: =$D$47 | AD24: =$D$47 | AE24: =IFERROR(subQ!AE20/subQ!AE19,"") | AF24: =$D$47 | AG24: =$D$47 | AH24: =$D$47 | AI24: =$D$47 | AJ24: =IFERROR(subQ!AJ20/subQ!AJ19,"") | AK24: =$D$47 | AL24: =$D$47 | AM24: =$D$47 | AN24: =$D$47 | AO24: =IFERROR(subQ!AO20/subQ!AO19,"")
A25: drv:부채총계 | B25: qoq | C25: 부채총계 QoQ | G25: =IFERROR(subQ!G22/subQ!E22-1,"") | H25: =IFERROR(subQ!H22/subQ!G22-1,"") | I25: =IFERROR(subQ!I22/subQ!H22-1,"") | J25: =IFERROR(subQ!J22/subQ!I22-1,"") | L25: =IFERROR(subQ!L22/subQ!J22-1,"") | M25: =IFERROR(subQ!M22/subQ!L22-1,"") | N25: =IFERROR(subQ!N22/subQ!M22-1,"") | O25: =IFERROR(subQ!O22/subQ!N22-1,"") | Q25: =IFERROR(subQ!Q22/subQ!O22-1,"") | R25: =IFERROR(subQ!R22/subQ!Q22-1,"") | S25: =IFERROR(subQ!S22/subQ!R22-1,"") | T25: =IFERROR(subQ!T22/subQ!S22-1,"") | V25: =IFERROR(subQ!V22/subQ!T22-1,"") | W25: =IFERROR(subQ!W22/subQ!V22-1,"") | X25: =IFERROR(subQ!X22/subQ!W22-1,"") | Y25: -2.5e-08 | AA25: 0 | AB25: 0 | AC25: 0 | AD25: 0 | AF25: 0 | AG25: 0 | AH25: 0 | AI25: 0 | AK25: 0 | AL25: 0 | AM25: 0 | AN25: 0
A26: drv:자본총계 | B26: roll | C26: 자본총계 기타변동(배당 등, 억원) | G26: =IFERROR(subQ!E23+subQ!G19-subQ!G23,"") | H26: =IFERROR(subQ!G23+subQ!H19-subQ!H23,"") | I26: =IFERROR(subQ!H23+subQ!I19-subQ!I23,"") | J26: =IFERROR(subQ!I23+subQ!J19-subQ!J23,"") | L26: =IFERROR(subQ!J23+subQ!L19-subQ!L23,"") | M26: =IFERROR(subQ!L23+subQ!M19-subQ!M23,"") | N26: =IFERROR(subQ!M23+subQ!N19-subQ!N23,"") | O26: =IFERROR(subQ!N23+subQ!O19-subQ!O23,"") | Q26: =IFERROR(subQ!O23+subQ!Q19-subQ!Q23,"") | R26: =IFERROR(subQ!Q23+subQ!R19-subQ!R23,"") | S26: =IFERROR(subQ!R23+subQ!S19-subQ!S23,"") | T26: =IFERROR(subQ!S23+subQ!T19-subQ!T23,"") | V26: =IFERROR(subQ!T23+subQ!V19-subQ!V23,"") | W26: =IFERROR(subQ!V23+subQ!W19-subQ!W23,"") | X26: =IFERROR(subQ!W23+subQ!X19-subQ!X23,"") | Y26: 0.002806108 | AA26: -0.001078958 | AB26: 283.17689 | AC26: 0.005629916 | AD26: 0.001086456 | AF26: 0.001173254 | AG26: 283.17455 | AH26: 0.004787964 | AI26: -0.004284398 | AK26: -0.003726089 | AL26: 283.17879 | AM26: -0.006460781 | AN26: 0.002151024
A27: drv:지배주주지분 | B27: roll | C27: 지배주주지분 기타변동(배당 등, 억원) | G27: =IFERROR(subQ!E24+subQ!G20-subQ!G24,"") | H27: =IFERROR(subQ!G24+subQ!H20-subQ!H24,"") | I27: =IFERROR(subQ!H24+subQ!I20-subQ!I24,"") | J27: =IFERROR(subQ!I24+subQ!J20-subQ!J24,"") | L27: =IFERROR(subQ!J24+subQ!L20-subQ!L24,"") | M27: =IFERROR(subQ!L24+subQ!M20-subQ!M24,"") | N27: =IFERROR(subQ!M24+subQ!N20-subQ!N24,"") | O27: =IFERROR(subQ!N24+subQ!O20-subQ!O24,"") | Q27: =IFERROR(subQ!O24+subQ!Q20-subQ!Q24,"") | R27: =IFERROR(subQ!Q24+subQ!R20-subQ!R24,"") | S27: =IFERROR(subQ!R24+subQ!S20-subQ!S24,"") | T27: =IFERROR(subQ!S24+subQ!T20-subQ!T24,"") | V27: =IFERROR(subQ!T24+subQ!V20-subQ!V24,"") | W27: =IFERROR(subQ!V24+subQ!W20-subQ!W24,"") | X27: =IFERROR(subQ!W24+subQ!X20-subQ!X24,"") | Y27: -0.003836385 | AA27: 0.00150822 | AB27: 283.17506 | AC27: -0.003643787 | AD27: 0.002376847 | AF27: -0.000156885 | AG27: 283.1697 | AH27: 0.001394517 | AI27: -0.00070735 | AK27: -0.006595615 | AL27: 283.17535 | AM27: -0.002641363 | AN27: -0.007052824
A28: drv:총차입금 | B28: qoq | C28: 총차입금 QoQ | G28: =IFERROR(subQ!G25/subQ!E25-1,"") | H28: =IFERROR(subQ!H25/subQ!G25-1,"") | I28: =IFERROR(subQ!I25/subQ!H25-1,"") | J28: =IFERROR(subQ!J25/subQ!I25-1,"") | L28: =IFERROR(subQ!L25/subQ!J25-1,"") | M28: =IFERROR(subQ!M25/subQ!L25-1,"") | N28: =IFERROR(subQ!N25/subQ!M25-1,"") | O28: =IFERROR(subQ!O25/subQ!N25-1,"") | Q28: =IFERROR(subQ!Q25/subQ!O25-1,"") | R28: =IFERROR(subQ!R25/subQ!Q25-1,"") | S28: =IFERROR(subQ!S25/subQ!R25-1,"") | T28: =IFERROR(subQ!T25/subQ!S25-1,"") | V28: =IFERROR(subQ!V25/subQ!T25-1,"") | W28: =IFERROR(subQ!W25/subQ!V25-1,"") | X28: =IFERROR(subQ!X25/subQ!W25-1,"") | Y28: 3.766e-06 | AA28: 0 | AB28: 0 | AC28: 0 | AD28: 0 | AF28: 0 | AG28: 0 | AH28: 0 | AI28: 0 | AK28: 0 | AL28: 0 | AM28: 0 | AN28: 0
A29: drv:순차입금 | B29: qoq | C29: 순차입금 QoQ | G29: =IFERROR(subQ!G26/subQ!E26-1,"") | H29: =IFERROR(subQ!H26/subQ!G26-1,"") | I29: =IFERROR(subQ!I26/subQ!H26-1,"") | J29: =IFERROR(subQ!J26/subQ!I26-1,"") | L29: =IFERROR(subQ!L26/subQ!J26-1,"") | M29: =IFERROR(subQ!M26/subQ!L26-1,"") | N29: =IFERROR(subQ!N26/subQ!M26-1,"") | O29: =IFERROR(subQ!O26/subQ!N26-1,"") | Q29: =IFERROR(subQ!Q26/subQ!O26-1,"") | R29: =IFERROR(subQ!R26/subQ!Q26-1,"") | S29: =IFERROR(subQ!S26/subQ!R26-1,"") | T29: =IFERROR(subQ!T26/subQ!S26-1,"") | V29: =IFERROR(subQ!V26/subQ!T26-1,"") | W29: =IFERROR(subQ!W26/subQ!V26-1,"") | X29: =IFERROR(subQ!X26/subQ!W26-1,"") | Y29: 0.1023188 | AA29: 0.078361537 | AB29: 0.025950686 | AC29: 0.077932569 | AD29: 0.086312002 | AF29: 0.067220142 | AG29: 0.026804075 | AH29: 0.067440209 | AI29: 0.072169434 | AK29: 0.057091116 | AL29: 0.024995617 | AM29: 0.057862798 | AN29: 0.061044144
A30: drv:이자발생자산 | B30: qoq | C30: 이자발생자산 QoQ | G30: =IFERROR(subQ!G27/subQ!E27-1,"") | H30: =IFERROR(subQ!H27/subQ!G27-1,"") | I30: =IFERROR(subQ!I27/subQ!H27-1,"") | J30: =IFERROR(subQ!J27/subQ!I27-1,"") | L30: =IFERROR(subQ!L27/subQ!J27-1,"") | M30: =IFERROR(subQ!M27/subQ!L27-1,"") | N30: =IFERROR(subQ!N27/subQ!M27-1,"") | O30: =IFERROR(subQ!O27/subQ!N27-1,"") | Q30: =IFERROR(subQ!Q27/subQ!O27-1,"") | R30: =IFERROR(subQ!R27/subQ!Q27-1,"") | S30: =IFERROR(subQ!S27/subQ!R27-1,"") | T30: =IFERROR(subQ!T27/subQ!S27-1,"") | V30: =IFERROR(subQ!V27/subQ!T27-1,"") | W30: =IFERROR(subQ!W27/subQ!V27-1,"") | X30: =IFERROR(subQ!X27/subQ!W27-1,"") | Y30: 0.079925717 | AA30: 0.062480722 | AB30: 0.021000772 | AC30: 0.063373229 | AD30: 0.071148197 | AF30: 0.056194932 | AG30: 0.022641672 | AH30: 0.057199294 | AI30: 0.061803313 | AK30: 0.049368091 | AL30: 0.021773399 | AM30: 0.050562579 | AN30: 0.053713223
A31: drv:현금및현금성자산 | B31: qoq | C31: 현금및현금성자산 QoQ | G31: =IFERROR(subQ!G28/subQ!E28-1,"") | H31: =IFERROR(subQ!H28/subQ!G28-1,"") | I31: =IFERROR(subQ!I28/subQ!H28-1,"") | J31: =IFERROR(subQ!J28/subQ!I28-1,"") | L31: =IFERROR(subQ!L28/subQ!J28-1,"") | M31: =IFERROR(subQ!M28/subQ!L28-1,"") | N31: =IFERROR(subQ!N28/subQ!M28-1,"") | O31: =IFERROR(subQ!O28/subQ!N28-1,"") | Q31: =IFERROR(subQ!Q28/subQ!O28-1,"") | R31: =IFERROR(subQ!R28/subQ!Q28-1,"") | S31: =IFERROR(subQ!S28/subQ!R28-1,"") | T31: =IFERROR(subQ!T28/subQ!S28-1,"") | V31: =IFERROR(subQ!V28/subQ!T28-1,"") | W31: =IFERROR(subQ!W28/subQ!V28-1,"") | X31: =IFERROR(subQ!X28/subQ!W28-1,"")
A32: drv:CAPEX | B32: yoy | C32: CAPEX YoY | J32: =IFERROR(subQ!J29/subQ!E29-1,"") | L32: =IFERROR(subQ!L29/subQ!G29-1,"") | M32: =IFERROR(subQ!M29/subQ!H29-1,"") | N32: =IFERROR(subQ!N29/subQ!I29-1,"") | O32: =IFERROR(subQ!O29/subQ!J29-1,"") | Q32: =IFERROR(subQ!Q29/subQ!L29-1,"") | R32: =IFERROR(subQ!R29/subQ!M29-1,"") | S32: =IFERROR(subQ!S29/subQ!N29-1,"") | T32: =IFERROR(subQ!T29/subQ!O29-1,"") | V32: =IFERROR(subQ!V29/subQ!Q29-1,"") | W32: =IFERROR(subQ!W29/subQ!R29-1,"") | X32: =IFERROR(subQ!X29/subQ!S29-1,"") | Y32: 0.089245143 | AA32: 0.13968947 | AB32: -0.075724154 | AC32: -0.24308534 | AD32: 0 | AF32: 0 | AG32: 0 | AH32: 0 | AI32: 0 | AK32: 0 | AL32: 0 | AM32: 0 | AN32: 0
A33: drv:영업활동현금흐름 | B33: yoy | C33: 영업활동현금흐름 YoY | J33: =IFERROR(subQ!J30/subQ!E30-1,"") | L33: =IFERROR(subQ!L30/subQ!G30-1,"") | M33: =IFERROR(subQ!M30/subQ!H30-1,"") | N33: =IFERROR(subQ!N30/subQ!I30-1,"") | O33: =IFERROR(subQ!O30/subQ!J30-1,"") | Q33: =IFERROR(subQ!Q30/subQ!L30-1,"") | R33: =IFERROR(subQ!R30/subQ!M30-1,"") | S33: =IFERROR(subQ!S30/subQ!N30-1,"") | T33: =IFERROR(subQ!T30/subQ!O30-1,"") | V33: =IFERROR(subQ!V30/subQ!Q30-1,"") | W33: =IFERROR(subQ!W30/subQ!R30-1,"") | X33: =IFERROR(subQ!X30/subQ!S30-1,"")
A34: drv:주식수 | B34: qoq | C34: 주식수 QoQ | G34: =IFERROR(subQ!G31/subQ!E31-1,"") | H34: =IFERROR(subQ!H31/subQ!G31-1,"") | I34: =IFERROR(subQ!I31/subQ!H31-1,"") | J34: =IFERROR(subQ!J31/subQ!I31-1,"") | L34: =IFERROR(subQ!L31/subQ!J31-1,"") | M34: =IFERROR(subQ!M31/subQ!L31-1,"") | N34: =IFERROR(subQ!N31/subQ!M31-1,"") | O34: =IFERROR(subQ!O31/subQ!N31-1,"") | Q34: =IFERROR(subQ!Q31/subQ!O31-1,"") | R34: =IFERROR(subQ!R31/subQ!Q31-1,"") | S34: =IFERROR(subQ!S31/subQ!R31-1,"") | T34: =IFERROR(subQ!T31/subQ!S31-1,"") | V34: =IFERROR(subQ!V31/subQ!T31-1,"") | W34: =IFERROR(subQ!W31/subQ!V31-1,"") | X34: =IFERROR(subQ!X31/subQ!W31-1,"") | Y34: 0 | AA34: 0 | AB34: 0 | AC34: 0 | AD34: 0 | AF34: 0 | AG34: 0 | AH34: 0 | AI34: 0 | AK34: 0 | AL34: 0 | AM34: 0 | AN34: 0
A35: drv:DPS | B35: abs | C35: DPS (가정, 원) | E35: =subQ!E34 | F35: =subQ!F34 | G35: =subQ!G34 | H35: =subQ!H34 | I35: =subQ!I34 | J35: =subQ!J34 | K35: =subQ!K34 | L35: =subQ!L34 | ... X35: =subQ!X34 | Y35: 710 | Z35: =subQ!Z34 | AD35: 710 | AE35: =subQ!AE34 | AI35: 710 | AJ35: =subQ!AJ34 | AN35: 710 | AO35: =subQ!AO34
B37: 3. 밸류에이션·스칼라 | C37: 노란 셀 = 가정. '연결' 표시는 추정 전 분기 수식이 이 셀을 참조한다는 뜻
A38: sc:종가 | C38: 종가 | E38: 원 — aikstockdata.com(금융위 확정종가 T+1)
A39: sc:기준일 | C39: 기준일 | E39: 종가 기준일
A40: sc:COE | C40: COE | D40: 0.09 | E40: 자기자본비용(가정) — TP 적정 PBR = ROE/COE
A41: sc:PER_lo | C41: PER_lo | D41: 10 | E41: PER 밴드 하단(배) — sector_default(레퍼런스 TP_PE PB 예시 10/15/20배; 과거 양(+)EPS 분기 0개 < 4)
A42: sc:PER_mid | C42: PER_mid | D42: 15 | E42: PER 밴드 중단(배)
...

Sheet BS연결
B1: (백만원) | C1: 이름: BS연결H | E1: 4Q21 | F1: 2021 | G1: 1Q22 | H1: 2Q22 | I1: 3Q22 | J1: 4Q22 | K1: 2022 | L1: 1Q23 | M1: 2Q23 | N1: 3Q23 | O1: 4Q23 | P1: 2023 | Q1: 1Q24 | R1: 2Q24 | S1: 3Q24 | T1: 4Q24 | U1: 2024 | V1: 1Q25 | W1: 2Q25 | X1: 3Q25 | Y1: 4Q25 | Z1: 2025 | AA1: 1Q26 | AB1: 2Q26 | AC1: 3Q26 | AD1: 4Q26 | AE1: 2026 | AF1: 1Q27 | AG1: 2Q27 | AH1: 3Q27 | AI1: 4Q27 | AJ1: 2027 | AK1: 1Q28 | AL1: 2Q28 | AM1: 3Q28 | AN1: 4Q28 | AO1: 2028
B2: 연결 | D2: fin json(kship_fin.py)
B3: HD현대미포(연) | C3: UPDATE: 26-10-11 | E3: 1 | F3: 2 | G3: 3 | H3: 4 | I3: 5 | J3: 6 | K3: 7 | L3: 8 | M3: 9 | N3: 10 | O3: 11 | P3: 12 | Q3: 13 | R3: 14 | S3: 15 | T3: 16 | U3: 17 | V3: 18 | W3: 19 | X3: 20 | Y3: 21 | Z3: 22 | AA3: 23 | AB3: 24 | AC3: 25 | AD3: 26 | AE3: 27 | AF3: 28 | AG3: 29 | AH3: 30 | AI3: 31 | AJ3: 32 | AK3: 33 | AL3: 34 | AM3: 35 | AN3: 36 | AO3: 37
B4: Account Code | C4: AccountNAME | E4: 2021.12 | F4: 2021.12A | G4: 2022.03 | H4: 2022.06 | I4: 2022.09 | J4: 2022.12 | K4: 2022.12A | L4: 2023.03 | M4: 2023.06 | N4: 2023.09 | O4: 2023.12 | P4: 2023.12A | Q4: 2024.03 | R4: 2024.06 | S4: 2024.09 | T4: 2024.12 | U4: 2024.12A | V4: 2025.03 | W4: 2025.06 | X4: 2025.09 | Y4: 2025.12 | Z4: 2025.12A | AA4: 2026.03 | AB4: 2026.06 | AC4: 2026.09 | AD4: 2026.12 | AE4: 2026.12A | AF4: 2027.03 | AG4: 2027.06 | AH4: 2027.09 | AI4: 2027.12 | AJ4: 2027.12A | AK4: 2028.03 | AL4: 2028.06 | AM4: 2028.09 | AN4: 2028.12 | AO4: 2028.12A
A5: 1 | C5: 유동자산 | E5: 2046698.2 | F5: 2046698.2 | G5: 2342578.1 | H5: 2480297.2 | I5: 3049846.1 | J5: 2724476.1 | K5: 2724476.1 | L5: 2698711.6 | M5: 2638052.2 | N5: 2720335.7 | O5: 2799391.8 | P5: 2799391.8 | Q5: 2611902.6 | R5: 2556143.1 | S5: 2410367.3 | T5: 2786547.4 | U5: 2786547.4 | V5: 2898372.1 | W5: 2897881.1 | X5: 2891331.8
A6: 1 | C6: 현금및현금성자산 | E6: 400370.96 | F6: 400370.96 | G6: 615588.03 | H6: 577796.92 | I6: 426258.03 | J6: 490143.85 | K6: 490143.85 | L6: 364792.08 | M6: 381085.43 | N6: 424198.32 | O6: 310040.89 | P6: 310040.89 | Q6: 418212.43 | R6: 420994.36 | S6: 396603.6 | T6: 165096.21 | U6: 165096.21 | V6: 434009.49 | W6: 512816.28 | X6: 473564.11
A7: 1 | C7: 단기금융상품 | E7: 124527.77 | F7: 124527.77 | G7: 84000.51 | H7: 177001.29 | I7: 129001.48 | J7: 53001.73 | K7: 53001.73 | L7: 39554.07 | M7: 43042.35 | N7: 45990.68 | O7: 39080.73 | P7: 39080.73 | Q7: 33696.22 | R7: 38913.03 | S7: 42592.16 | T7: 38367.96 | U7: 38367.96 | V7: 34300.19 | W7: 41949.56 | X7: 47115.45
A8: 1 | C8: 단기금융자산 | E8: 154979.73 | F8: 154979.73 | G8: 125218.75 | H8: 255829.72 | I8: 284390.78 | J8: 125597.49 | K8: 125597.49 | L8: 107822.77 | M8: 101436.31 | N8: 111327.16 | O8: 87872.77 | P8: 87872.77 | Q8: 92807.27 | R8: 125317.45 | S8: 82253.71 | T8: 174224.62 | U8: 174224.62 | V8: 152810.05 | W8: 86446.08 | X8: 121971.47
A9: 1 | C9: 매출채권및기타채권 | E9: 47534.35 | F9: 47534.35 | G9: 189966.36 | H9: 103537.07 | I9: 241966.56 | J9: 87030.57 | K9: 87030.57 | L9: 77889.3 | M9: 49605.65 | N9: 79112.24 | O9: 164823.67 | P9: 164823.67 | Q9: 146455.76 | R9: 117121.82 | S9: 63301.88 | T9: 131232.52 | U9: 131232.52 | V9: 100782.8 | W9: 114511.86 | X9: 110957.5
A10: 1 | C10: 계약자산 | E10: 900692.64 | F10: 900692.64 | G10: 871255.87 | H10: 984525.23 | I10: 1356661.7 | J10: 1301215.9 | K10: 1301215.9 | L10: 1356700 | M10: 1322929.4 | N10: 1318559.9 | O10: 1442687.1 | P10: 1442687.1 | Q10: 1166462 | R10: 1011783.8 | S10: 940068.68 | T10: 1488564 | U10: 1488564 | V10: 1368532.1 | W10: 1249564.2 | X10: 1249293.1
A11: 1 | C11: 유동파생상품자산 | E11: 1664.05 | F11: 1664.05 | G11: 540.83 | H11: 2.69 | I11: 2.57 | J11: 29527.19 | K11: 29527.19 | L11: 11801.01 | M11: 10449.82 | N11: 3789.3 | O11: 15804.99 | P11: 15804.99 | Q11: 2382.6 | R11: 206.53 | S11: 10028.66 | T11: 185.35 | U11: 185.35 | V11: 16.69 | W11: 7654.67 | X11: 2577.2
A12: 1 | C12: 유동확정계약자산 | E12: 28787.91 | F12: 28787.91 | G12: 40677.41 | H12: 78825.74 | I12: 155386.73 | J12: 43068.57 | K12: 43068.57 | L12: 56467.69 | M12: 47944.14 | N12: 61547.18 | O12: 32987.05 | P12: 32987.05 | Q12: 56728.45 | R12: 86197.89 | S12: 29632.89 | T12: 135671.31 | U12: 135671.31 | V12: 118493.17 | W12: 36841.85 | X12: 72278.82
A13: 1 | C13: 재고자산 | E13: 265534.01 | F13: 265534.01 | G13: 268954.88 | H13: 251077.48 | I13: 324082.25 | J13: 292593.55 | K13: 292593.55 | L13: 294033.49 | M13: 276675.46 | N13: 234517.92 | O13: 230175.93 | P13: 230175.93 | Q13: 264411.92 | R13: 281611.38 | S13: 276882.83 | T13: 270834.34 | U13: 270834.34 | V13: 266344.85 | W13: 255118.38 | X13: 277576.08
A14: 1 | C14: 기타유동자산 | E14: 277586.48 | F14: 277586.48 | G14: 271594.23 | H14: 307530.82 | I14: 416486.78 | J14: 427894.77 | K14: 427894.77 | L14: 497474.01 | M14: 506319.97 | N14: 552620.16 | O14: 563791.49 | P14: 563791.49 | Q14: 523553.2 | R14: 599314.26 | S14: 651256.6 | T14: 556595.69 | U14: 556595.69 | V14: 575892.78 | W14: 679424.3 | X14: 657969.54
A15: 1 | C15: 비유동자산 | E15: 1831622.1 | F15: 1831622.1 | G15: 1855833.6 | H15: 1922888.8 | I15: 2019039 | J15: 2023769.4 | K15: 2023769.4 | L15: 2035377.6 | M15: 2068971.2 | N15: 2105433.4 | O15: 2109679.6 | P15: 2109679.6 | Q15: 2136680.4 | R15: 2197709.4 | S15: 2162629.8 | T15: 2322319.9 | U15: 2322319.9 | V15: 2299160.5 | W15: 2247239.1 | X15: 2223214.4
A16: 1 | C16: 장기금융자산 | E16: 13354.46 | F16: 13354.46 | G16: 14125.09 | H16: 14145.49 | I16: 14167.27 | J16: 15458.98 | K16: 15458.98 | L16: 15474.36 | M16: 15486.65 | N16: 15498.59 | O16: 14457.66 | P16: 14457.66 | Q16: 14470.66 | R16: 14484 | S16: 14483.93 | T16: 14001.12 | U16: 14001.12 | V16: 13904.25 | W16: 13894.83 | X16: 13894.3
... A22: 1 | C22: 기타비유동자산 | E22: 22996.01 | F22: 22996.01 | G22: 22829.08 | H22: 18884.61 | I22: 15434.44 | J22: 110317.92 | K22: 110317.92 | L22: 107881.04 | M22: 103882.1 | N22: 104182.19 | O22: 111761.67 | P22: 111761.67 | Q22: 107797.11 | R22: 103592.78 | S22: 97095.67 | T22: 78148.94 | U22: 78148.94 | V22: 71035.39 | W22: 61884.77 | X22: 54831.15
A23: 1 | C23: 비유동파생상품자산 | E23: 1247.58 | F23: 1247.58 | G23: 2856.12 | J23: 19316.97 | K23: 19316.97 | L23: 10750.01 | M23: 13448.73 | N23: 4016.89 | O23: 15623.77 | P23: 15623.77 | Q23: 954.44 | R23: 0 | S23: 14890.81 | T23: 0 | U23: 0 | W23: 47644.26 | X23: 10048.05
A24: 1 | C24: 비유동확정계약자산 | E24: 31692.05 | F24: 31692.05 | G24: 27599.9 | H24: 81004.24 | I24: 174527.51 | J24: 24761.83 | K24: 24761.83 | L24: 35792.49 | M24: 31436.13 | N24: 56188.95 | O24: 13771.64 | P24: 13771.64 | Q24: 43201.07 | R24: 82197.45 | S24: 20269.95 | T24: 187895.67 | U24: 187895.67 | V24: 172863.09 | W24: 29769.79 | X24: 64009.3
A25: 1 | C25: 이연법인세자산 | E25: 117765.29 | F25: 117765.29 | G25: 127290.04 | H25: 114200.15 | I25: 79950.66 | J25: 135722.09 | K25: 135722.09 | L25: 136778.98 | M25: 150403.05 | N25: 146994.7 | O25: 172186.42 | P25: 172186.42 | Q25: 171652.18 | R25: 164867.08 | S25: 165595.9 | T25: 152541.9 | U25: 152541.9 | V25: 146864.09 | W25: 130020.56 | X25: 94883.22
A26: 1 | C26: 자산총계 | E26: 3878320.3 | F26: 3878320.3 | G26: 4198411.7 | H26: 4403186.1 | I26: 5068885.1 | J26: 4748245.5 | K26: 4748245.5 | L26: 4734089.2 | M26: 4707023.4 | N26: 4825769.1 | O26: 4909071.4 | P26: 4909071.4 | Q26: 4748583 | R26: 4753852.6 | S26: 4572997.1 | T26: 5108867.3 | U26: 5108867.3 | V26: 5197532.6 | W26: 5145120.3 | X26: 5114546.1
A27: 1 | C27: 유동부채 | E27: 1612004.4 | F27: 1612004.4 | G27: 1968685.7 | H27: 2080370.4 | I27: 2533506.9 | J27: 2499086.9 | K27: 2499086.9 | L27: 2484394.5 | M27: 2492321.3 | N27: 2580232.9 | O27: 2735399.7 | P27: 2735399.7 | Q27: 2492849.5 | R27: 2448496.6 | S27: 2379286.5 | T27: 2705577.9 | U27: 2705577.9 | V27: 2870461 | W27: 2845940 | X27: 2649454.3
A28: 1 | C28: 단기차입금 | E28: 169155.8 | F28: 169155.8 | G28: 202029.85 | H28: 193066.4 | I28: 163444.1 | J28: 107721.17 | K28: 107721.17 | L28: 173678.08 | M28: 285828.23 | N28: 362946.64 | O28: 478561.15 | P28: 478561.15 | Q28: 276982.09 | R28: 180481.47 | S28: 94568.63 | T28: 159198.21 | U28: 159198.21 | V28: 158819.16 | W28: 121172.19 | X28: 119484.55
A29: 1 | C29: 단기금융부채(face) | E29: 169155.8 | F29: 169155.8 | G29: 202029.85 | H29: 193066.4 | I29: 163444.1 | J29: 107721.17 | K29: 107721.17 | L29: 173678.08 | M29: 285828.23 | N29: 362946.64 | O29: 478561.15 | P29: 478561.15 | Q29: 276982.09 | R29: 180481.47 | S29: 94568.63 | T29: 159198.21 | U29: 159198.21 | V29: 158819.16 | W29: 121172.19 | X29: 119484.55
A30: 1 | C30: 매입채무및기타채무 | E30: 519472.56 | F30: 519472.56 | G30: 435136.91 | H30: 583904.61 | I30: 625537.42 | J30: 687506.08 | K30: 687506.08 | L30: 651644.76 | M30: 614360.64 | N30: 516996.7 | O30: 567411.38 | P30: 567411.38 | Q30: 620815.94 | R30: 669370.09 | S30: 587647.98 | T30: 753608.85 | U30: 753608.85 | V30: 708798.85 | W30: 776124.43 | X30: 731594.83
A31: 1 | C31: 계약부채 | E31: 602513.94 | F31: 602513.94 | G31: 974873.75 | H31: 982481.76 | I31: 1352571.3 | J31: 1454465.3 | K31: 1454465.3 | L31: 1498006.9 | M31: 1463662.1 | N31: 1551498.7 | O31: 1557774.4 | P31: 1557774.4 | Q31: 1479867 | R31: 1455255.7 | S31: 1628960.5 | T31: 1588626.4 | U31: 1588626.4 | V31: 1816119.6 | W31: 1851368.9 | X31: 1662890.3
A32: 1 | C32: 단기충당부채 | E32: 272843.11 | F32: 272843.11 | G32: 288817.34 | H32: 189206.2 | I32: 123756.54 | J32: 144586.98 | K32: 144586.98 | L32: 49742.78 | M32: 29462.42 | N32: 36587.81 | O32: 74195.6 | P32: 74195.6 | Q32: 35945.67 | R32: 26630.11 | S32: 15566.98 | T32: 11216.9 | U32: 11216.9 | V32: 12003.85 | W32: 26936.98 | X32: 12716.65
A33: 1 | C33: 유동리스부채 | E33: 1454.35 | F33: 1454.35 | G33: 1507.08 | H33: 1231.99 | I33: 1151.79 | J33: 1716.81 | K33: 1716.81 | L33: 1932.27 | M33: 2000.36 | N33: 3816.51 | O33: 4239.09 | P33: 4239.09 | Q33: 4577.01 | R33: 4574.83 | S33: 4174.22 | T33: 4870.32 | U33: 4870.32 | V33: 4527.22 | W33: 4644.92 | X33: 4326.21
A34: 1 | C34: 리스부채 | E34: 10008.11 | F34: 10008.11 | G34: 10081.63 | H34: 9788.94 | I34: 9357.15 | J34: 11558.32 | K34: 11558.32 | L34: 11921.09 | M34: 12152.18 | N34: 18224.38 | O34: 18094.16 | P34: 18094.16 | Q34: 18238.25 | R34: 17886.84 | S34: 16630.34 | T34: 16521.33 | U34: 16521.33 | V34: 15765.97 | W34: 15418.18 | X34: 14240.48
A35: 1 | C35: 단기금융부채 | E35: 47931.26 | F35: 47931.26 | G35: 67794.49 | H35: 131670.24 | I35: 268038.57 | J35: 104637.45 | K35: 104637.45 | L35: 111196.55 | M35: 98852.73 | N35: 111814.46 | O35: 57457.06 | P35: 57457.06 | Q35: 78915.3 | R35: 116135.51 | S35: 51140.21 | T35: 190727.97 | U35: 190727.97 | V35: 172545.39 | W35: 67447.54 | X35: 113433.63
... A57: 1 | C57: 이자발생자산 | E57: 568705.15 | F57: 568705.15 | G57: 754931.87 | H57: 847772.13 | I57: 724816.08 | J57: 631200.32 | K57: 631200.32 | L57: 488089.21 | M57: 498008.39 | N57: 551024.07 | O57: 412371.32 | P57: 412371.32 | Q57: 525490.36 | R57: 560795.81 | S57: 493341.24 | T57: 353321.95 | U57: 353321.95 | V57: 600723.79 | W57: 613157.19 | X57: 609429.88
A58: 1 | C58: 이연법인세부채 | M58: 1194.72 | N58: 1194.72 | O58: 1405.56 | P58: 1405.56 | Q58: 1405.56 | R58: 1405.56 | S58: 1405.56 | T58: 910.44 | U58: 910.44 | V58: 910.44 | W58: 0 | X58: 910.44
A59: 1 | C59: 장기차입금 | O59: 95671.5 | P59: 95671.5 | Q59: 160000 | R59: 140000 | S59: 80000 | T59: 80000 | U59: 80000 | V59: 0 | W59: 0 | X59: 0
A60: 1 | C60: 장기금융부채(face) | O60: 95671.5 | P60: 95671.5 | Q60: 160000 | R60: 140000 | S60: 80000 | T60: 80000 | U60: 80000 | V60: 0 | W60: 0 | X60: 0
A61: 1 | C61: 매출액(수익) | E61: 860545.88 | G61: 875958.75 | H61: 935436.14 | I61: 882268.57 | J61: 1023197.5 | K61: 3716860.9 | L61: 909161.3 | M61: 1033370.8 | N61: 993800.53 | O61: 1102733.1 | P61: 4039065.7 | Q61: 1000493.6 | R61: 1129062.9 | S61: 1077667 | T61: 1422825.2 | U61: 4630048.8 | V61: 1183823 | W61: 1234448.4 | X61: 1300349.2
A62: 1 | C62: 매출원가 | E62: 904118.38 | G62: 910119.27 | H62: 912937.13 | I62: 837566.97 | J62: 1043382.9 | K62: 3704006.3 | L62: 916503.53 | M62: 1055211.1 | N62: 968931.18 | O62: 1129092.3 | P62: 4069738.1 | Q62: 973253.53 | R62: 1073429.9 | S62: 1003389.3 | T62: 1332063.9 | U62: 4382136.7 | V62: 1076844.9 | W62: 1101947.6 | X62: 1050007
A63: 1 | C63: 매출총이익 | E63: -43572.51 | G63: -34160.52 | H63: 22499.01 | I63: 44701.59 | J63: -20185.4 | K63: 12854.68 | L63: -7342.24 | M63: -21840.3 | N63: 24869.35 | O63: -26359.17 | P63: -30672.36 | Q63: 27240.1 | R63: 55632.92 | S63: 74277.7 | T63: 90761.35 | U63: 247912.07 | V63: 106978.08 | W63: 132500.75 | X63: 250342.17
A64: 1 | C64: 판관비 | E64: 33434.36 | G64: 27674.49 | H64: 29099.78 | I64: 30633.25 | J64: 34513.27 | K64: 121920.79 | L64: 20070.5 | M64: 30627.65 | N64: 32725.63 | O64: 38820.2 | P64: 122243.98 | Q64: 38284.07 | R64: 38208.52 | S64: 39027.39 | T64: 43864.18 | U64: 159384.16 | V64: 38493.99 | W64: 43081.52 | X64: 49534.75
A65: 1 | C65: 영업이익 | E65: -77006.86 | G65: -61835.01 | H65: -6600.78 | I65: 14068.34 | J65: -54698.67 | K65: -109066.12 | L65: -27412.73 | M65: -52467.95 | N65: -7856.29 | O65: -65179.38 | P65: -152916.35 | Q65: -11043.97 | R65: 17424.4 | S65: 35250.31 | T65: 46897.16 | U65: 88527.9 | V65: 68484.09 | W65: 89419.23 | X65: 200807.42
A66: 1 | C66: 금융수익 | E66: 1195.07 | G66: 53668.16 | H66: 104555.76 | I66: 189143.77 | J66: 15041.13 | K66: 362408.82 | L66: 96006.47 | M66: 58463.62 | N66: 66725.12 | O66: 25449.53 | P66: 246644.74 | Q66: 96732.18 | R66: 75761.3 | S66: 197846.34 | T66: 111172.08 | U66: 481511.9 | V66: 45383.44 | W66: 336070.62 | X66: 126873.65
...

Sheet BS별도
B1: (백만원) | C1: 이름: BS별도H | E1: 4Q21 | F1: 2021 | G1: 1Q22 | H1: 2Q22 | I1: 3Q22 | J1: 4Q22 | K1: 2022 | L1: 1Q23 | M1: 2Q23 | N1: 3Q23 | O1: 4Q23 | P1: 2023 | Q1: 1Q24 | R1: 2Q24 | S1: 3Q24 | T1: 4Q24 | U1: 2024 | V1: 1Q25 | W1: 2Q25 | X1: 3Q25 | Y1: 4Q25 | Z1: 2025 | AA1: 1Q26 | AB1: 2Q26 | AC1: 3Q26 | AD1: 4Q26 | AE1: 2026 | AF1: 1Q27 | AG1: 2Q27 | AH1: 3Q27 | AI1: 4Q27 | AJ1: 2027 | AK1: 1Q28 | AL1: 2Q28 | AM1: 3Q28 | AN1: 4Q28 | AO1: 2028
B2: 별도 | D2: fin json(kship_fin.py)
B3: HD현대미포(별) | C3: UPDATE: 26-10-11 | E3: 1 | F3: 2 | G3: 3 | H3: 4 | I3: 5 | J3: 6 | K3: 7 | L3: 8 | M3: 9 | N3: 10 | O3: 11 | P3: 12 | Q3: 13 | R3: 14 | S3: 15 | T3: 16 | U3: 17 | V3: 18 | W3: 19 | X3: 20 | Y3: 21 | Z3: 22 | AA3: 23 | AB3: 24 | AC3: 25 | AD3: 26 | AE3: 27 | AF3: 28 | AG3: 29 | AH3: 30 | AI3: 31 | AJ3: 32 | AK3: 33 | AL3: 34 | AM3: 35 | AN3: 36 | AO3: 37
B4: Account Code | C4: AccountNAME | E4: 2021.12 | F4: 2021.12A | G4: 2022.03 | H4: 2022.06 | I4: 2022.09 | J4: 2022.12 | K4: 2022.12A | L4: 2023.03 | M4: 2023.06 | N4: 2023.09 | O4: 2023.12 | P4: 2023.12A | Q4: 2024.03 | R4: 2024.06 | S4: 2024.09 | T4: 2024.12 | U4: 2024.12A | V4: 2025.03 | W4: 2025.06 | X4: 2025.09 | Y4: 2025.12 | Z4: 2025.12A | AA4: 2026.03 | AB4: 2026.06 | AC4: 2026.09 | AD4: 2026.12 | AE4: 2026.12A | AF4: 2027.03 | AG4: 2027.06 | AH4: 2027.09 | AI4: 2027.12 | AJ4: 2027.12A | AK4: 2028.03 | AL4: 2028.06 | AM4: 2028.09 | AN4: 2028.12 | AO4: 2028.12A
A5: 1 | C5: 유동자산 | E5: 2158881.4 | F5: 2158881.4 | G5: 2440189.8 | H5: 2661217.7 | I5: 3288166.8 | J5: 2945101.9 | K5: 2945101.9 | L5: 2838712.1 | M5: 2917547.3 | N5: 2948429.7 | O5: 3017901 | P5: 3017901 | Q5: 2820329.5 | R5: 2772843.2 | S5: 2560872.1 | T5: 2972534.5 | U5: 2972534.5 | V5: 3035855 | W5: 3074800.6 | X5: 3049804.9
A6: 1 | C6: 현금및현금성자산 | E6: 372686.92 | F6: 372686.92 | G6: 544188.39 | H6: 515417.73 | I6: 363000.29 | J6: 431836.62 | K6: 431836.62 | L6: 290430.89 | M6: 351336.78 | N6: 396957.6 | O6: 273524.46 | P6: 273524.46 | Q6: 390726.17 | R6: 364074.92 | S6: 288905.78 | T6: 83492.25 | U6: 83492.25 | V6: 283730.83 | W6: 451431.26 | X6: 325015.53
A7: 1 | C7: 단기금융상품 | E7: 123027.77 | F7: 123027.77 | G7: 83000.51 | H7: 173001.29 | I7: 123001.48 | J7: 53001.73 | K7: 53001.73 | L7: 23001.44 | M7: 23001.59 | N7: 23001.83 | O7: 23002.07 | P7: 23002.07 | Q7: 23000.13 | R7: 23000.15 | S7: 23000.17 | T7: 24122.31 | U7: 24122.31 | V7: 24112.89 | W7: 24612.96 | X7: 25107.54
A8: 1 | C8: 단기금융자산 | E8: 153479.73 | F8: 153479.73 | G8: 124218.75 | H8: 251829.72 | I8: 278390.78 | J8: 125597.49 | K8: 125597.49 | L8: 91270.14 | M8: 81395.55 | N8: 88338.31 | O8: 71794.11 | P8: 71794.11 | Q8: 82111.18 | R8: 109404.57 | S8: 62661.72 | T8: 159978.97 | U8: 159978.97 | V8: 142622.75 | W8: 69109.48 | X8: 99963.56
A9: 1 | C9: 매출채권및기타채권 | E9: 198948.55 | F9: 198948.55 | G9: 386967.32 | H9: 362527.03 | I9: 557870.48 | J9: 363163.72 | K9: 363163.72 | L9: 139891.3 | M9: 168468.5 | N9: 180146.63 | O9: 248076.57 | P9: 248076.57 | Q9: 222220.27 | R9: 290569.17 | S9: 122466.39 | T9: 171819.32 | U9: 171819.32 | V9: 147599.3 | W9: 156620.22 | X9: 184845.7
A10: 1 | C10: 계약자산 | E10: 900681.06 | F10: 900681.06 | G10: 871197.85 | H10: 984461.79 | I10: 1356660.9 | J10: 1301185.5 | K10: 1301185.5 | L10: 1356660 | M10: 1337028.8 | N10: 1318559.9 | O10: 1442687.1 | P10: 1442687.1 | Q10: 1166462 | R10: 1011783.8 | S10: 936957.46 | T10: 1488564 | U10: 1488564 | V10: 1368532.1 | W10: 1249564.2 | X10: 1248566.8
A11: 1 | C11: 유동파생상품자산 | E11: 1664.05 | F11: 1664.05 | G11: 540.83 | H11: 2.69 | I11: 2.57 | J11: 29527.19 | K11: 29527.19 | L11: 11801.01 | M11: 10449.82 | N11: 3789.3 | O11: 15804.99 | P11: 15804.99 | Q11: 2382.6 | R11: 206.53 | S11: 10028.66 | T11: 185.35 | U11: 185.35 | V11: 16.69 | W11: 7654.67 | X11: 2577.2
A12: 1 | C12: 유동확정계약자산 | E12: 28787.91 | F12: 28787.91 | G12: 40677.41 | H12: 78825.74 | I12: 155386.73 | J12: 43068.57 | K12: 43068.57 | L12: 56467.69 | M12: 47944.14 | N12: 61547.18 | O12: 32987.05 | P12: 32987.05 | Q12: 56728.45 | R12: 86197.89 | S12: 29632.89 | T12: 135671.31 | U12: 135671.31 | V12: 118493.17 | W12: 36841.85 | X12: 72278.82
A13: 1 | C13: 재고자산 | E13: 198966.89 | F13: 198966.89 | G13: 189257.67 | H13: 187865.86 | I13: 253988.21 | J13: 253733.47 | K13: 253733.47 | L13: 222679.27 | M13: 217087.52 | N13: 167972.41 | O13: 154750.48 | P13: 154750.48 | Q13: 195753.14 | R13: 198279.92 | S13: 201987.08 | T13: 188896.95 | U13: 188896.95 | V13: 165632.48 | W13: 153212.5 | X13: 174826.28
A14: 1 | C14: 기타유동자산 | E14: 334118.22 | F14: 334118.22 | G14: 324359.82 | H14: 359115.61 | I14: 478256.23 | J14: 469585.1 | K14: 469585.1 | L14: 737780.52 | M14: 762230.12 | N14: 796454.86 | O14: 827068.39 | P14: 827068.39 | Q14: 763056.77 | R14: 798730.75 | S14: 947893.7 | T14: 879782.98 | U14: 879782.98 | V14: 927737.52 | W14: 994862.86 | X14: 1016587.1
A15: 1 | C15: 비유동자산 | E15: 1699092 | F15: 1699092 | G15: 1705976.7 | H15: 1756041.7 | I15: 1822221.8 | J15: 1835597.4 | K15: 1835597.4 | L15: 1840141.5 | M15: 1872509.8 | N15: 1904043.4 | O15: 1914824.4 | P15: 1914824.4 | Q15: 1934068.4 | R15: 1985061.9 | S15: 1963877.5 | T15: 2095219.8 | U15: 2095219.8 | V15: 2076619.4 | W15: 2046535.9 | X15: 2015474.4
A16: 1 | C16: 장기금융자산 | E16: 13040.01 | F16: 13040.01 | G16: 13798.02 | H16: 13798.02 | I16: 13797.02 | J16: 15099.67 | K16: 15099.67 | L16: 15099.68 | M16: 15099.69 | N16: 15099.69 | O16: 14212.79 | P16: 14212.79 | Q16: 14212.79 | R16: 14212.79 | S16: 14199.29 | T16: 13702.75 | U16: 13702.75 | V16: 13702.75 | W16: 13700.25 | X16: 13700.25
... A23: 1 | C23: 기타비유동자산 | E23: 17646.82 | F23: 17646.82 | G23: 17394.16 | H23: 13125.07 | I23: 9129.74 | J23: 93639.32 | K23: 93639.32 | L23: 91165.39 | M23: 88605.25 | N23: 91566.21 | O23: 93469.73 | P23: 93469.73 | Q23: 89332.65 | R23: 84881.72 | S23: 79329.12 | T23: 55746.49 | U23: 55746.49 | V23: 49700.72 | W23: 42898.02 | X23: 36867.39
A24: 1 | C24: 비유동파생상품자산 | E24: 1247.58 | F24: 1247.58 | G24: 2856.12 | J24: 19316.97 | K24: 19316.97 | L24: 10750.01 | M24: 13448.73 | N24: 4016.89 | O24: 15623.77 | P24: 15623.77 | Q24: 954.44 | R24: 0 | S24: 14890.81 | T24: 0 | U24: 0 | W24: 47644.26 | X24: 10048.05
A25: 1 | C25: 비유동확정계약자산 | E25: 31692.05 | F25: 31692.05 | G25: 27599.9 | H25: 81004.24 | I25: 174527.51 | J25: 24761.83 | K25: 24761.83 | L25: 35792.49 | M25: 31436.13 | N25: 56188.95 | O25: 13771.64 | P25: 13771.64 | Q25: 43201.07 | R25: 82197.45 | S25: 20269.95 | T25: 187895.67 | U25: 187895.67 | V25: 172863.09 | W25: 29769.79 | X25: 64009.3
A26: 1 | C26: 이연법인세자산 | E26: 124055.97 | F26: 124055.97 | G26: 133345.88 | H26: 119022.48 | I26: 85208.44 | J26: 136572.07 | K26: 136572.07 | L26: 137185.54 | M26: 149466.43 | N26: 145960.6 | O26: 171091.53 | P26: 171091.53 | Q26: 170464.55 | R26: 163676.04 | S26: 164530.1 | T26: 151128.26 | U26: 151128.26 | V26: 145399.14 | W26: 129662.63 | X26: 93668.89
A27: 1 | C27: 자산총계 | E27: 3857973.4 | F27: 3857973.4 | G27: 4146166.5 | H27: 4417259.4 | I27: 5110388.7 | J27: 4780699.2 | K27: 4780699.2 | L27: 4678853.6 | M27: 4790057.1 | N27: 4852473.1 | O27: 4932725.4 | P27: 4932725.4 | Q27: 4754397.9 | R27: 4757905.1 | S27: 4524749.6 | T27: 5067754.2 | U27: 5067754.2 | V27: 5112474.4 | W27: 5121336.5 | X27: 5065279.3
A28: 1 | C28: 유동부채 | E28: 1647347.9 | F28: 1647347.9 | G28: 1963791.4 | H28: 2141888.2 | I28: 2635601.2 | J28: 2592825.6 | K28: 2592825.6 | L28: 2492545.8 | M28: 2643994.8 | N28: 2678281.1 | O28: 2826952.8 | P28: 2826952.8 | Q28: 2570211.4 | R28: 2532025.6 | S28: 2410804.1 | T28: 2759395.9 | U28: 2759395.9 | V28: 2881950.5 | W28: 2916366.4 | X28: 2706436.5
A29: 1 | C29: 단기차입금 | E29: 89727.3 | F29: 89727.3 | G29: 62389.81 | H29: 39303.43 | I29: 9919.74 | M29: 159000 | N29: 209000 | O29: 314328.5 | P29: 314328.5 | Q29: 159818.88 | R29: 45695.78 | S29: 0 | T29: 0 | U29: 0
A30: 1 | C30: 단기금융부채(face) | E30: 89727.3 | F30: 89727.3 | G30: 62389.81 | H30: 39303.43 | I30: 9919.74 | M30: 159000 | N30: 209000 | O30: 314328.5 | P30: 314328.5 | Q30: 159818.88 | R30: 45695.78 | S30: 0 | T30: 0 | U30: 0
A31: 1 | C31: 매입채무및기타채무 | E31: 630994.44 | F31: 630994.44 | G31: 567647.94 | H31: 799312.04 | I31: 878596.62 | J31: 886514.65 | K31: 886514.65 | L31: 831756.1 | M31: 877663.34 | N31: 768766.33 | O31: 822925.57 | P31: 822925.57 | Q31: 815639.32 | R31: 888283.54 | S31: 715189.88 | T31: 968882.14 | U31: 968882.14 | V31: 881053.28 | W31: 969874.49 | X31: 909920.47
A32: 1 | C32: 계약부채 | E32: 602513.94 | F32: 602513.94 | G32: 974873.75 | H32: 982481.76 | I32: 1352571.3 | J32: 1454465.3 | K32: 1454465.3 | L32: 1498006.9 | M32: 1477761.5 | N32: 1551498.7 | O32: 1557774.4 | P32: 1557774.4 | Q32: 1479867 | R32: 1455255.7 | S32: 1628960.5 | T32: 1588626.4 | U32: 1588626.4 | V32: 1816119.6 | W32: 1851368.9 | X32: 1662890.3
A33: 1 | C33: 단기충당부채 | E33: 276008.65 | F33: 276008.65 | G33: 290997.07 | H33: 189012.93 | I33: 126374.79 | J33: 147142.75 | K33: 147142.75 | L33: 51519.43 | M33: 30729.31 | N33: 37230.16 | O33: 74528.12 | P33: 74528.12 | Q33: 36024.12 | R33: 26716.2 | S33: 15566.99 | T33: 11216.9 | U33: 11216.9 | V33: 12003.85 | W33: 26936.98 | X33: 12716.65
A34: 1 | C34: 유동리스부채 | E34: 1434.63 | F34: 1434.63 | G34: 1477.57 | H34: 1194.33 | I34: 1116.17 | J34: 1676.15 | K34: 1676.15 | L34: 1895.6 | M34: 1972.52 | N34: 3787.92 | O34: 4178.21 | P34: 4178.21 | Q34: 4523.78 | R34: 4513.64 | S34: 4120.81 | T34: 4812.8 | U34: 4812.8 | V34: 4470.17 | W34: 4618.03 | X34: 4312.46
A35: 1 | C35: 리스부채 | E35: 9968.53 | F35: 9968.53 | G35: 10012.97 | H35: 9699.1 | I35: 9277.3 | J35: 11465.14 | K35: 11465.14 | L35: 11821.43 | M35: 12061.34 | N35: 18112.81 | O35: 17993.38 | P35: 17993.38 | Q35: 18145.12 | R35: 17751.7 | S35: 16502.98 | T35: 16419.95 | U35: 16419.95 | V35: 15655.16 | W35: 15337.53 | X35: 14172.97
A36: 1 | C36: 단기금융부채 | E36: 47911.54 | F36: 47911.54 | G36: 67764.98 | H36: 131632.58 | I36: 268002.95 | J36: 104596.79 | K36: 104596.79 | L36: 111159.88 | M36: 98824.89 | N36: 111785.87 | O36: 57396.18 | P36: 57396.18 | Q36: 78862.07 | R36: 116074.32 | S36: 51086.8 | T36: 190670.45 | U36: 190670.45 | V36: 172488.34 | W36: 67420.65 | X36: 113419.88
A37: 1 | C37: 단기파생상품부채 | E37: 46476.91 | F37: 46476.91 | G37: 66287.41 | H37: 130438.25 | I37: 266886.78 | J37: 102920.64 | K37: 102920.64 | L37: 109264.28 | M37: 96852.37 | N37: 107997.95 | O37: 53217.97 | P37: 53217.97 | Q37: 74338.29 | R37: 111560.68 | S37: 46965.99 | T37: 185857.65 | U37: 185857.65 | V37: 168018.17 | W37: 62802.62 | X37: 109107.42
A38: 1 | C38: 기타유동부채 | E38: 192.07 | F38: 192.07 | G38: 117.9 | H38: 145.5 | I38: 135.75 | J38: 106.1 | K38: 106.1 | L38: 103.47 | M38: 15.74 | T38: 0 | U38: 0 | V38: 285.51 | W38: 765.42 | X38: 7489.22
A39: 1 | C39: 비유동부채 | E39: 54428.39 | F39: 54428.39 | G39: 53965.21 | H39: 102698.84 | I39: 196722.34 | J39: 66728.11 | K39: 66728.11 | L39: 68791.25 | M39: 67288.15 | N39: 86575.43 | O39: 151512.56 | P39: 151512.56 | Q39: 227995.09 | R39: 245761.62 | S39: 137058.69 | T39: 291443.76 | U39: 291443.76 | V39: 194374.24 | W39: 98374.65 | X39: 95341.31
A40: 1 | C40: 장기매입채무및기타채무 | E40: 41.19 | F40: 41.19 | G40: 5.72 | H40: 5.72 | I40: 5.72 | J40: 5.72 | K40: 5.72 | L40: 3.28 | M40: 1.78 | N40: 1.78 | O40: 71.78 | P40: 71.78 | Q40: 71.78 | R40: 71.78 | S40: 71.78 | T40: 689.3 | U40: 689.3 | V40: 608.18 | W40: 608.18 | X40: 608.18
A41: 1 | C41: 확정급여부채 | E41: 8254.86 | F41: 8254.86 | G41: 8254.86 | H41: 8254.86 | I41: 8952.46 | J41: 7470.24 | K41: 7470.24 | L41: 7470.24 | M41: 7470.24 | N41: 7470.24 | O41: 8288.36 | P41: 8288.36 | Q41: 5946.58 | R41: 5946.58 | S41: 5946.58 | T41: 6289.27 | U41: 6289.27 | V41: 6289.27 | W41: 6289.27 | X41: 7544.59
A42: 1 | C42: 장기충당부채 | E42: 4658.81 | F42: 4658.81 | G42: 6713.2 | H42: 4929.24 | I42: 5075.51 | J42: 5384.36 | K42: 5384.36 | L42: 4849.4 | M42: 4842.46 | N42: 4572.69 | O42: 4270.35 | P42: 4270.35 | Q42: 4199.89 | R42: 4158.85 | S42: 3497.41 | T42: 4962.38 | U42: 4962.38 | V42: 3428.72 | W42: 3343.65 | X42: 3270.68
A43: 1 | C43: 비유동리스부채 | E43: 8533.9 | F43: 8533.9 | G43: 8535.4 | H43: 8504.77 | I43: 8161.13 | J43: 9788.99 | K43: 9788.99 | L43: 9925.83 | M43: 10088.82 | N43: 14324.89 | O43: 13815.17 | P43: 13815.17 | Q43: 13621.34 | R43: 13238.06 | S43: 12382.17 | T43: 11607.15 | U43: 11607.15 | V43: 11184.99 | W43: 10719.5 | X43: 9860.51
A44: 1 | C44: 장기금융부채 | E44: 41473.53 | F44: 41473.53 | G44: 38991.42 | H44: 89509.01 | I44: 182688.64 | J44: 53867.79 | K44: 53867.79 | L44: 56468.33 | M44: 54973.68 | N44: 74530.73 | O44: 43210.58 | P44: 43210.58 | Q44: 57776.85 | R44: 95584.42 | S44: 47542.93 | T44: 199502.82 | U44: 199502.82 | V44: 184048.08 | W44: 88133.55 | X44: 83917.86
A45: 1 | C45: 장기파생상품부채 | E45: 32939.63 | F45: 32939.63 | G45: 30456.02 | H45: 81004.24 | I45: 174527.51 | J45: 44078.8 | K45: 44078.8 | L45: 46542.5 | M45: 44884.86 | N45: 60205.84 | O45: 29395.41 | P45: 29395.41 | Q45: 44155.51 | R45: 82346.36 | S45: 35160.76 | T45: 187895.67 | U45: 187895.67 | V45: 172863.09 | W45: 77414.05 | X45: 74057.35
A46: 1 | C46: 부채총계 | E46: 1701776.3 | F46: 1701776.3 | G46: 2017756.7 | H46: 2244587.1 | I46: 2832323.5 | J46: 2659553.7 | K46: 2659553.7 | L46: 2561337 | M46: 2711283 | N46: 2764856.5 | O46: 2978465.3 | P46: 2978465.3 | Q46: 2798206.5 | R46: 2777787.2 | S46: 2547862.8 | T46: 3050839.7 | U46: 3050839.7 | V46: 3076324.8 | W46: 3014741 | X46: 2801777.8
...

Sheet subQ
A1: YQ | C1: subQ 분기 서브모델(억원, U=100) | E1: 4Q21 | F1: 2021 | G1: 1Q22 | H1: 2Q22 | I1: 3Q22 | J1: 4Q22 | K1: 2022 | L1: 1Q23 | M1: 2Q23 | N1: 3Q23 | O1: 4Q23 | P1: 2023 | Q1: 1Q24 | R1: 2Q24 | S1: 3Q24 | T1: 4Q24 | U1: 2024 | V1: 1Q25 | W1: 2Q25 | X1: 3Q25 | Y1: 4Q25 | Z1: 2025 | AA1: 1Q26 | AB1: 2Q26 | AC1: 3Q26 | AD1: 4Q26 | AE1: 2026 | AF1: 1Q27 | AG1: 2Q27 | AH1: 3Q27 | AI1: 4Q27 | AJ1: 2027 | AK1: 1Q28 | AL1: 2Q28 | AM1: 3Q28 | AN1: 4Q28 | AO1: 2028
A2: A=이름(key) B=그룹 C=단위 D=FnGuide 계정명(VLOOKUP 키). 확정=VLOOKUP(BS), 추정=변수 가정 참조
E3: 1 | F3: 2 | G3: 3 | H3: 4 | I3: 5 | J3: 6 | K3: 7 | L3: 8 | M3: 9 | N3: 10 | O3: 11 | P3: 12 | Q3: 13 | R3: 14 | S3: 15 | T3: 16 | U3: 17 | V3: 18 | W3: 19 | X3: 20 | Y3: 21 | Z3: 22 | AA3: 23 | AB3: 24 | AC3: 25 | AD3: 26 | AE3: 27 | AF3: 28 | AG3: 29 | AH3: 30 | AI3: 31 | AJ3: 32 | AK3: 33 | AL3: 34 | AM3: 35 | AN3: 36 | AO3: 37
E4: 2021.12 | F4: 2021.12A | G4: 2022.03 | H4: 2022.06 | I4: 2022.09 | J4: 2022.12 | K4: 2022.12A | L4: 2023.03 | M4: 2023.06 | N4: 2023.09 | O4: 2023.12 | P4: 2023.12A | Q4: 2024.03 | R4: 2024.06 | S4: 2024.09 | T4: 2024.12 | U4: 2024.12A | V4: 2025.03 | W4: 2025.06 | X4: 2025.09 | Y4: 2025.12 | Z4: 2025.12A | AA4: 2026.03 | AB4: 2026.06 | AC4: 2026.09 | AD4: 2026.12 | AE4: 2026.12A | AF4: 2027.03 | AG4: 2027.06 | AH4: 2027.09 | AI4: 2027.12 | AJ4: 2027.12A | AK4: 2028.03 | AL4: 2028.06 | AM4: 2028.09 | AN4: 2028.12 | AO4: 2028.12A
A5: 매출액 | B5: 손익 | C5: 억원 | D5: 매출액(수익) | E5: =IFERROR(VLOOKUP($D5,BS연결,MATCH(E$1,BS연결H,0),0)/100,"") | G5: =IFERROR(VLOOKUP($D5,BS연결,MATCH(G$1,BS연결H,0),0)/100,"") | H5: =IFERROR(VLOOKUP($D5,BS연결,MATCH(H$1,BS연결H,0),0)/100,"") | I5: =IFERROR(VLOOKUP($D5,BS연결,MATCH(I$1,BS연결H,0),0)/100,"") | J5: =IFERROR(VLOOKUP($D5,BS연결,MATCH(J$1,BS연결H,0),0)/100,"") | K5: =IFERROR(VLOOKUP($D5,BS연결,MATCH(K$1,BS연결H,0),0)/100,"") | L5: =IFERROR(VLOOKUP($D5,BS연결,MATCH(L$1,BS연결H,0),0)/100,"") | M5: =IFERROR(VLOOKUP($D5,BS연결,MATCH(M$1,BS연결H,0),0)/100,"") | N5: =IFERROR(VLOOKUP($D5,BS연결,MATCH(N$1,BS연결H,0),0)/100,"") | ... X5: =IFERROR(VLOOKUP($D5,BS연결,MATCH(X$1,BS연결H,0),0)/100,"") | Y5: =IFERROR(T5*(1+변수!Y16),"") | Z5: =SUM(V5:Y5) | AA5: =IFERROR(V5*(1+변수!AA16),"") | AB5: =IFERROR(W5*(1+변수!AB16),"") | AC5: =IFERROR(X5*(1+변수!AC16),"") | AD5: =IFERROR(Y5*(1+변수!AD16),"") | AE5: =SUM(AA5:AD5) | AF5: =IFERROR(AA5*(1+변수!AF16),"") | AG5: =IFERROR(AB5*(1+변수!AG16),"") | AH5: =IFERROR(AC5*(1+변수!AH16),"") | AI5: =IFERROR(AD5*(1+변수!AI16),"") | AJ5: =SUM(AF5:AI5) | AK5: =IFERROR(AF5*(1+변수!AK16),"") | AL5: =IFERROR(AG5*(1+변수!AL16),"") | AM5: =IFERROR(AH5*(1+변수!AM16),"") | AN5: =IFERROR(AI5*(1+변수!AN16),"") | AO5: =SUM(AK5:AN5)
A6: 매출원가 | B6: 손익 | C6: 억원 | D6: 매출원가 | E6: =IFERROR(VLOOKUP($D6,BS연결,MATCH(E$1,BS연결H,0),0)/100,"") | G6: =IFERROR(VLOOKUP($D6,BS연결,MATCH(G$1,BS연결H,0),0)/100,"") | H6: =IFERROR(VLOOKUP($D6,BS연결,MATCH(H$1,BS연결H,0),0)/100,"") | I6: =IFERROR(VLOOKUP($D6,BS연결,MATCH(I$1,BS연결H,0),0)/100,"") | J6: =IFERROR(VLOOKUP($D6,BS연결,MATCH(J$1,BS연결H,0),0)/100,"") | K6: =IFERROR(VLOOKUP($D6,BS연결,MATCH(K$1,BS연결H,0),0)/100,"") | L6: =IFERROR(VLOOKUP($D6,BS연결,MATCH(L$1,BS연결H,0),0)/100,"") | M6: =IFERROR(VLOOKUP($D6,BS연결,MATCH(M$1,BS연결H,0),0)/100,"") | N6: =IFERROR(VLOOKUP($D6,BS연결,MATCH(N$1,BS연결H,0),0)/100,"") | ... X6: =IFERROR(VLOOKUP($D6,BS연결,MATCH(X$1,BS연결H,0),0)/100,"") | Y6: =IFERROR(Y5-Y7,"") | Z6: =SUM(V6:Y6) | AA6: =IFERROR(AA5-AA7,"") | AB6: =IFERROR(AB5-AB7,"") | AC6: =IFERROR(AC5-AC7,"") | AD6: =IFERROR(AD5-AD7,"") | AE6: =SUM(AA6:AD6) | AF6: =IFERROR(AF5-AF7,"") | AG6: =IFERROR(AG5-AG7,"") | AH6: =IFERROR(AH5-AH7,"") | AI6: =IFERROR(AI5-AI7,"") | AJ6: =SUM(AF6:AI6) | AK6: =IFERROR(AK5-AK7,"") | AL6: =IFERROR(AL5-AL7,"") | AM6: =IFERROR(AM5-AM7,"") | AN6: =IFERROR(AN5-AN7,"") | AO6: =SUM(AK6:AN6)
A7: 매출총이익 | B7: 손익 | C7: 억원 | D7: 매출총이익 | E7: =IFERROR(VLOOKUP($D7,BS연결,MATCH(E$1,BS연결H,0),0)/100,"") | G7: =IFERROR(VLOOKUP($D7,BS연결,MATCH(G$1,BS연결H,0),0)/100,"") | H7: =IFERROR(VLOOKUP($D7,BS연결,MATCH(H$1,BS연결H,0),0)/100,"") | I7: =IFERROR(VLOOKUP($D7,BS연결,MATCH(I$1,BS연결H,0),0)/100,"") | J7: =IFERROR(VLOOKUP($D7,BS연결,MATCH(J$1,BS연결H,0),0)/100,"") | K7: =IFERROR(VLOOKUP($D7,BS연결,MATCH(K$1,BS연결H,0),0)/100,"") | L7: =IFERROR(VLOOKUP($D7,BS연결,MATCH(L$1,BS연결H,0),0)/100,"") | M7: =IFERROR(VLOOKUP($D7,BS연결,MATCH(M$1,BS연결H,0),0)/100,"") | N7: =IFERROR(VLOOKUP($D7,BS연결,MATCH(N$1,BS연결H,0),0)/100,"") | ... X7: =IFERROR(VLOOKUP($D7,BS연결,MATCH(X$1,BS연결H,0),0)/100,"") | Y7: =IFERROR(Y9+Y8,"") | Z7: =SUM(V7:Y7) | AA7: =IFERROR(AA9+AA8,"") | AB7: =IFERROR(AB9+AB8,"") | AC7: =IFERROR(AC9+AC8,"") | AD7: =IFERROR(AD9+AD8,"") | AE7: =SUM(AA7:AD7) | AF7: =IFERROR(AF9+AF8,"") | AG7: =IFERROR(AG9+AG8,"") | AH7: =IFERROR(AH9+AH8,"") | AI7: =IFERROR(AI9+AI8,"") | AJ7: =SUM(AF7:AI7) | AK7: =IFERROR(AK9+AK8,"") | AL7: =IFERROR(AL9+AL8,"") | AM7: =IFERROR(AM9+AM8,"") | AN7: =IFERROR(AN9+AN8,"") | AO7: =SUM(AK7:AN7)
A8: 판관비 | B8: 손익 | C8: 억원 | D8: 판관비 | E8: =IFERROR(VLOOKUP($D8,BS연결,MATCH(E$1,BS연결H,0),0)/100,"") | G8: =IFERROR(VLOOKUP($D8,BS연결,MATCH(G$1,BS연결H,0),0)/100,"") | H8: =IFERROR(VLOOKUP($D8,BS연결,MATCH(H$1,BS연결H,0),0)/100,"") | I8: =IFERROR(VLOOKUP($D8,BS연결,MATCH(I$1,BS연결H,0),0)/100,"") | J8: =IFERROR(VLOOKUP($D8,BS연결,MATCH(J$1,BS연결H,0),0)/100,"") | K8: =IFERROR(VLOOKUP($D8,BS연결,MATCH(K$1,BS연결H,0),0)/100,"") | L8: =IFERROR(VLOOKUP($D8,BS연결,MATCH(L$1,BS연결H,0),0)/100,"") | M8: =IFERROR(VLOOKUP($D8,BS연결,MATCH(M$1,BS연결H,0),0)/100,"") | N8: =IFERROR(VLOOKUP($D8,BS연결,MATCH(N$1,BS연결H,0),0)/100,"") | ... X8: =IFERROR(VLOOKUP($D8,BS연결,MATCH(X$1,BS연결H,0),0)/100,"") | Y8: =IFERROR(Y5*변수!Y17,"") | Z8: =SUM(V8:Y8) | AA8: =IFERROR(AA5*변수!AA17,"") | AB8: =IFERROR(AB5*변수!AB17,"") | AC8: =IFERROR(AC5*변수!AC17,"") | AD8: =IFERROR(AD5*변수!AD17,"") | AE8: =SUM(AA8:AD8) | AF8: =IFERROR(AF5*변수!AF17,"") | AG8: =IFERROR(AG5*변수!AG17,"") | AH8: =IFERROR(AH5*변수!AH17,"") | AI8: =IFERROR(AI5*변수!AI17,"") | AJ8: =SUM(AF8:AI8) | AK8: =IFERROR(AK5*변수!AK17,"") | AL8: =IFERROR(AL5*변수!AL17,"") | AM8: =IFERROR(AM5*변수!AM17,"") | AN8: =IFERROR(AN5*변수!AN17,"") | AO8: =SUM(AK8:AN8)
A9: 영업이익 | B9: 손익 | C9: 억원 | D9: 영업이익 | E9: =IFERROR(VLOOKUP($D9,BS연결,MATCH(E$1,BS연결H,0),0)/100,"") | G9: =IFERROR(VLOOKUP($D9,BS연결,MATCH(G$1,BS연결H,0),0)/100,"") | H9: =IFERROR(VLOOKUP($D9,BS연결,MATCH(H$1,BS연결H,0),0)/100,"") | I9: =IFERROR(VLOOKUP($D9,BS연결,MATCH(I$1,BS연결H,0),0)/100,"") | J9: =IFERROR(VLOOKUP($D9,BS연결,MATCH(J$1,BS연결H,0),0)/100,"") | K9: =IFERROR(VLOOKUP($D9,BS연결,MATCH(K$1,BS연결H,0),0)/100,"") | L9: =IFERROR(VLOOKUP($D9,BS연결,MATCH(L$1,BS연결H,0),0)/100,"") | M9: =IFERROR(VLOOKUP($D9,BS연결,MATCH(M$1,BS연결H,0),0)/100,"") | N9: =IFERROR(VLOOKUP($D9,BS연결,MATCH(N$1,BS연결H,0),0)/100,"") | ... X9: =IFERROR(VLOOKUP($D9,BS연결,MATCH(X$1,BS연결H,0),0)/100,"") | Y9: =IFERROR(Y5*변수!Y18,"") | Z9: =SUM(V9:Y9) | AA9: =IFERROR(AA5*변수!AA18,"") | AB9: =IFERROR(AB5*변수!AB18,"") | AC9: =IFERROR(AC5*변수!AC18,"") | AD9: =IFERROR(AD5*변수!AD18,"") | AE9: =SUM(AA9:AD9) | AF9: =IFERROR(AF5*변수!AF18,"") | AG9: =IFERROR(AG5*변수!AG18,"") | AH9: =IFERROR(AH5*변수!AH18,"") | AI9: =IFERROR(AI5*변수!AI18,"") | AJ9: =SUM(AF9:AI9) | AK9: =IFERROR(AK5*변수!AK18,"") | AL9: =IFERROR(AL5*변수!AL18,"") | AM9: =IFERROR(AM5*변수!AM18,"") | AN9: =IFERROR(AN5*변수!AN18,"") | AO9: =SUM(AK9:AN9)
A10: OPM | B10: 손익 | C10: % | D10: 영업이익률 | E10: =IFERROR(E9/E5,"") | G10: =IFERROR(G9/G5,"") | H10: =IFERROR(H9/H5,"") | I10: =IFERROR(I9/I5,"") | J10: =IFERROR(J9/J5,"") | K10: =IFERROR(K9/K5,"") | L10: =IFERROR(L9/L5,"") | M10: =IFERROR(M9/M5,"") | N10: =IFERROR(N9/N5,"") | ... AO10: =IFERROR(AO9/AO5,"")
A11: 금융손익 | B11: 손익 | C11: 억원 | D11: 금융손익 | E11: =IFERROR(VLOOKUP($D11,BS연결,MATCH(E$1,BS연결H,0),0)/100,"") | G11: =IFERROR(VLOOKUP($D11,BS연결,MATCH(G$1,BS연결H,0),0)/100,"") | H11: =IFERROR(VLOOKUP($D11,BS연결,MATCH(H$1,BS연결H,0),0)/100,"") | I11: =IFERROR(VLOOKUP($D11,BS연결,MATCH(I$1,BS연결H,0),0)/100,"") | J11: =IFERROR(VLOOKUP($D11,BS연결,MATCH(J$1,BS연결H,0),0)/100,"") | K11: =IFERROR(VLOOKUP($D11,BS연결,MATCH(K$1,BS연결H,0),0)/100,"") | L11: =IFERROR(VLOOKUP($D11,BS연결,MATCH(L$1,BS연결H,0),0)/100,"") | M11: =IFERROR(VLOOKUP($D11,BS연결,MATCH(M$1,BS연결H,0),0)/100,"") | N11: =IFERROR(VLOOKUP($D11,BS연결,MATCH(N$1,BS연결H,0),0)/100,"") | ... X11: =IFERROR(VLOOKUP($D11,BS연결,MATCH(X$1,BS연결H,0),0)/100,"") | Y11: =IFERROR(Y12+Y13+Y14+Y15,"") | Z11: =SUM(V11:Y11) | AA11: =IFERROR(AA12+AA13+AA14+AA15,"") | AB11: =IFERROR(AB12+AB13+AB14+AB15,"") | AC11: =IFERROR(AC12+AC13+AC14+AC15,"") | AD11: =IFERROR(AD12+AD13+AD14+AD15,"") | AE11: =SUM(AA11:AD11) | AF11: =IFERROR(AF12+AF13+AF14+AF15,"") | AG11: =IFERROR(AG12+AG13+AG14+AG15,"") | AH11: =IFERROR(AH12+AH13+AH14+AH15,"") | AI11: =IFERROR(AI12+AI13+AI14+AI15,"") | AJ11: =SUM(AF11:AI11) | AK11: =IFERROR(AK12+AK13+AK14+AK15,"") | AL11: =IFERROR(AL12+AL13+AL14+AL15,"") | AM11: =IFERROR(AM12+AM13+AM14+AM15,"") | AN11: =IFERROR(AN12+AN13+AN14+AN15,"") | AO11: =SUM(AK11:AN11)
A12: 이자손익 | B12: 손익 | C12: 억원 | D12: 이자손익 | G12: =IFERROR(VLOOKUP($D12,BS연결,MATCH(G$1,BS연결H,0),0)/100,"") | H12: =IFERROR(VLOOKUP($D12,BS연결,MATCH(H$1,BS연결H,0),0)/100,"") | I12: =IFERROR(VLOOKUP($D12,BS연결,MATCH(I$1,BS연결H,0),0)/100,"") | J12: =IFERROR(VLOOKUP($D12,BS연결,MATCH(J$1,BS연결H,0),0)/100,"") | K12: =IFERROR(VLOOKUP($D12,BS연결,MATCH(K$1,BS연결H,0),0)/100,"") | L12: =IFERROR(VLOOKUP($D12,BS연결,MATCH(L$1,BS연결H,0),0)/100,"") | M12: =IFERROR(VLOOKUP($D12,BS연결,MATCH(M$1,BS연결H,0),0)/100,"") | N12: =IFERROR(VLOOKUP($D12,BS연결,MATCH(N$1,BS연결H,0),0)/100,"") | ... X12: =IFERROR(VLOOKUP($D12,BS연결,MATCH(X$1,BS연결H,0),0)/100,"") | Y12: =IFERROR((X27*변수!$D$48-X25*변수!$D$49)/4,"") | Z12: =SUM(V12:Y12) | AA12: =IFERROR((Y27*변수!$D$48-Y25*변수!$D$49)/4,"") | AB12: =IFERROR((AA27*변수!$D$48-AA25*변수!$D$49)/4,"") | AC12: =IFERROR((AB27*변수!$D$48-AB25*변수!$D$49)/4,"") | AD12: =IFERROR((AC27*변수!$D$48-AC25*변수!$D$49)/4,"") | AE12: =SUM(AA12:AD12) | AF12: =IFERROR((AD27*변수!$D$48-AD25*변수!$D$49)/4,"") | AG12: =IFERROR((AF27*변수!$D$48-AF25*변수!$D$49)/4,"") | AH12: =IFERROR((AG27*변수!$D$48-AG25*변수!$D$49)/4,"") | AI12: =IFERROR((AH27*변수!$D$48-AH25*변수!$D$49)/4,"") | AJ12: =SUM(AF12:AI12) | AK12: =IFERROR((AI27*변수!$D$48-AI25*변수!$D$49)/4,"") | AL12: =IFERROR((AK27*변수!$D$48-AK25*변수!$D$49)/4,"") | AM12: =IFERROR((AL27*변수!$D$48-AL25*변수!$D$49)/4,"") | AN12: =IFERROR((AM27*변수!$D$48-AM25*변수!$D$49)/4,"") | AO12: =SUM(AK12:AN12)
