Workbook
Name 변수H: 변수!$C$1:$AO$1
Name 환율: 변수!$C$6:$AO$13
Name BS연결H: BS연결!$C$1:$AO$1
Name BS연결: BS연결!$C$5:$AO$95
Name BS별도H: BS별도!$C$1:$AO$1
Name BS별도: BS별도!$C$5:$AO$84
Name SUBQH: subQ!$A$1:$AO$1
Name subQ: subQ!$A$5:$AO$39

Sheet README
A1: 한신기계공업(011700) 실적 모델 — ARGUS 한국조선
A2: 기준 분기 2026Q2 · 마지막 실적 2026Q2 · 생성 2026-10-13
A3: 모든 수치는 모델 산출값(DART 공개 재무제표 + 우리 추정)이다 — 목표주가·투자 추천 아님. 참고용 · 투자조언 아님.
A5: 시트
A6: 변수 가정 시계열. 환율 8행(ECB via frankfurter — L2 fx.json; 추정 분기 = 노란 가정), 추정 드라이버(노란 셀 = 모델값에서 역산한 가정, 바꾸면 재계산; 연녹 셀 = 3절 스칼라 참조 수식), 3절 스칼라 가정(세율·판관비율·지배주주비중·이자율·종가·PER 밴드·COE·외화 순노출·헤지비율)
A7: BS연결/BS별도 FnGuide 계정명 × 기간 값 덤프(백만원). 행1 분기라벨, 행4 YYYY.MM / YYYY.12A. 이름정의 BS연결H·BS연결(계정명 C열부터)
A8: subQ 분기 서브모델(억원 = 백만원/100). 확정 행: =IFERROR(VLOOKUP($D행,BS연결,MATCH(E$1,BS연결H,0),0)/100,"") 추정 행: 변수 시트 가정 셀 참조 수식. 외환손익·파생상품손익은 BS 계정 합·차, 기타금융손익은 잔차, OPM·EPS·BPS·PER·PBR 은 파생 수식
A9: SLS 선표(조선사만, sls json 있을 때): 요약 행(sls 저장값) + 계약별 스케줄(백만$) × (헤지비율 × 헤지환율 + (1−헤지비율) × 건조시점 환율[변수 원/달러(평균)]) → 원화 수식 블록 → 합계 행이 subQ 매출조선에 연결
A10: 시나리오 신규수주 보수/기준/낙관(forecast_panel 패널, 모델에 scenarios 가 있을 때만): 매출액·영업이익 = subQ 기준값 ± (시나리오 신규 − base 신규) × OPM. base 만 subQ 행에 포함, 나머지는 합산 안 함
A11: 분기/연간예상 subQ 를 이름(A열 key)으로 VLOOKUP 한 보고서 표(억원)
A12: TP PER 밴드 × 12M fwd EPS, PBR = ROE/COE × BPS — 모델 산출값 구간, 목표주가·추천 아님
A13: 외화 환율 QoQ, 외화 순노출 × Δ기말환율 → 환관련손익 추정
... A34: 백테스트: {"freeze": "2025Q2", "horizon": 4, "revenue_wape_pct": 39.9, "op_wape_pct": 99.1, "n": 4, "note": "단일 회사 4분기 — 통계 아님", "driver_at_freeze": "trend_seasonal", "selection_oos_at_freeze": null, "frozen_inputs": "fin(연결/별도)·고객 조선사 모델·지주 자회사 모델은 2025Q2 까지의 분기만; 선표는 체결일 ≤ 2025Q2 말일 계약(원장 최신 금액·코호트 등급, 환산 없음); 잔고는 yards_cache 2025Q2; 시세·환율 forward·prices·forecast_panel 신규수주 미사용. 고객 가중치(suppliers.json 언급 비중)와 합병 체인링크는 현재 지식; 고객 연동 채택은 동결 모델 안에서도 자기 la−4분기 OOS 규칙(selection_oos_at_freeze)", "detail": [{"q": "2025Q3", "rev_pred": 173.53, "rev_act": 137.05, "op_pred": -1.18, "op_act": 11.6}, {"q": "2025Q4", "rev_pred": 303.02, "rev_act": 165.06, "op_pred": -2.06, "op_act": -18.69}, {"q": "2026Q1", "rev_pred": 100.73, "rev_act": 75.62, "op_pred": -0.68, "op_act": -16.05}, {"q": "2026Q2", "rev_pred": 151.69, "rev_act": 143.5, "op_pred": -1.03, "op_act": 11.18}]}

Sheet 변수
C1: 이름: 변수H | E1: 4Q21 | F1: 2021 | G1: 1Q22 | H1: 2Q22 | I1: 3Q22 | J1: 4Q22 | K1: 2022 | L1: 1Q23 | M1: 2Q23 | N1: 3Q23 | O1: 4Q23 | P1: 2023 | Q1: 1Q24 | R1: 2Q24 | S1: 3Q24 | T1: 4Q24 | U1: 2024 | V1: 1Q25 | W1: 2Q25 | X1: 3Q25 | Y1: 4Q25 | Z1: 2025 | AA1: 1Q26 | AB1: 2Q26 | AC1: 3Q26 | AD1: 4Q26 | AE1: 2026 | AF1: 1Q27 | AG1: 2Q27 | AH1: 3Q27 | AI1: 4Q27 | AJ1: 2027 | AK1: 1Q28 | AL1: 2Q28 | AM1: 3Q28 | AN1: 4Q28 | AO1: 2028
A2: 가정 시계열 — 노란 셀은 추정 가정(모델값에서 역산), 연녹 셀은 3절 스칼라 참조 수식. 바꾸면 subQ·분기·연간예상·TP·시나리오가 재계산됩니다.
E3: 1 | F3: 2 | G3: 3 | H3: 4 | I3: 5 | J3: 6 | K3: 7 | L3: 8 | M3: 9 | N3: 10 | O3: 11 | P3: 12 | Q3: 13 | R3: 14 | S3: 15 | T3: 16 | U3: 17 | V3: 18 | W3: 19 | X3: 20 | Y3: 21 | Z3: 22 | AA3: 23 | AB3: 24 | AC3: 25 | AD3: 26 | AE3: 27 | AF3: 28 | AG3: 29 | AH3: 30 | AI3: 31 | AJ3: 32 | AK3: 33 | AL3: 34 | AM3: 35 | AN3: 36 | AO3: 37
E4: 2021.12 | F4: 2021.12A | G4: 2022.03 | H4: 2022.06 | I4: 2022.09 | J4: 2022.12 | K4: 2022.12A | L4: 2023.03 | M4: 2023.06 | N4: 2023.09 | O4: 2023.12 | P4: 2023.12A | Q4: 2024.03 | R4: 2024.06 | S4: 2024.09 | T4: 2024.12 | U4: 2024.12A | V4: 2025.03 | W4: 2025.06 | X4: 2025.09 | Y4: 2025.12 | Z4: 2025.12A | AA4: 2026.03 | AB4: 2026.06 | AC4: 2026.09 | AD4: 2026.12 | AE4: 2026.12A | AF4: 2027.03 | AG4: 2027.06 | AH4: 2027.09 | AI4: 2027.12 | AJ4: 2027.12A | AK4: 2028.03 | AL4: 2028.06 | AM4: 2028.09 | AN4: 2028.12 | AO4: 2028.12A
B5: 1. FX | C5: 이름: 환율
A6: USDKRW_avg | C6: 원/달러(평균) | E6: 1183.5 | F6: 1145.51 | G6: 1205.78 | H6: 1262.09 | I6: 1341.93 | J6: 1360.12 | K6: 1292.98 | L6: 1276.95 | M6: 1315.69 | N6: 1313.62 | O6: 1322.01 | P6: 1306.85 | Q6: 1330.14 | R6: 1371.28 | S6: 1356.22 | T6: 1396.3 | U6: 1363.53 | V6: 1452.28 | W6: 1398.52 | X6: 1386.95 | Y6: 1449.19 | Z6: 1421.52 | AA6: 1466.12 | AB6: 1501.75 | AC6: 1418.75 | AD6: 1343.63 | AE6: 1456.58 | AF6: 1333.09 | AG6: 1333.09 | AH6: 1333.09 | AI6: 1333.09 | AK6: 1333.09 | AL6: 1333.09 | AM6: 1333.09 | AN6: 1333.09
A7: USDKRW_end | C7: 원/달러(기말) | E7: 1188.75 | F7: 1188.75 | G7: 1213.74 | H7: 1301.24 | I7: 1436.9 | J7: 1260.16 | K7: 1260.16 | L7: 1305.99 | M7: 1321.44 | N7: 1345.35 | O7: 1297.43 | P7: 1297.43 | Q7: 1349.25 | R7: 1377.73 | S7: 1312.17 | T7: 1474.78 | U7: 1474.78 | V7: 1474.54 | W7: 1355.13 | X7: 1403.67 | Y7: 1444.2 | Z7: 1444.2 | AA7: 1524.8 | AB7: 1550.89 | AC7: 1355.4 | AD7: 1333.09 | AE7: 1333.09 | AF7: 1333.09 | AG7: 1333.09 | AH7: 1333.09 | AI7: 1333.09 | AK7: 1333.09 | AL7: 1333.09 | AM7: 1333.09 | AN7: 1333.09
A8: JPY100KRW_avg | C8: 원/100Y(평균) | E8: 1041.02 | F8: 1042.74 | G8: 1036.79 | H8: 972.23 | I8: 970.61 | J8: 961.03 | K8: 985.1 | L8: 964.89 | M8: 957.36 | N8: 909 | O8: 893.22 | P8: 931.11 | Q8: 896.29 | R8: 880.14 | S8: 909.35 | T8: 917.25 | U8: 900.92 | V8: 952.59 | W8: 967.92 | X8: 940.32 | Y8: 940.77 | Z8: 950.17 | AA8: 934.39 | AB8: 942.16 | AC8: 890.41 | AD8: 849.51 | AE8: 918.81 | AF8: 840.54 | AG8: 840.54 | AH8: 840.54 | AI8: 840.54 | AK8: 840.54 | AL8: 840.54 | AM8: 840.54 | AN8: 840.54
A9: JPY100KRW_end | C9: 원/100Y(기말) | E9: 1032.62 | F9: 1032.62 | G9: 996.83 | H9: 954.9 | I9: 993.29 | J9: 955.54 | K9: 955.54 | L9: 980.62 | M9: 913.67 | N9: 901.47 | O9: 917.04 | P9: 917.04 | Q9: 892.42 | R9: 857.76 | S9: 919.21 | T9: 939.65 | U9: 939.65 | V9: 986.84 | W9: 938.85 | X9: 948.49 | Y9: 921.81 | Z9: 921.81 | AA9: 955.99 | AB9: 954.75 | AC9: 863.31 | AD9: 840.54 | AE9: 840.54 | AF9: 840.54 | AG9: 840.54 | AH9: 840.54 | AI9: 840.54 | AK9: 840.54 | AL9: 840.54 | AM9: 840.54 | AN9: 840.54
A10: EURKRW_avg | C10: W/Euro(평균) | E10: 1353.32 | F10: 1354.06 | G10: 1352.29 | H10: 1343.31 | I10: 1350.63 | J10: 1386.07 | K10: 1358.07 | L10: 1369.93 | M10: 1432.41 | N10: 1429.41 | O10: 1420.91 | P10: 1412.88 | Q10: 1444.21 | R10: 1476.42 | S10: 1489.3 | T10: 1490.78 | U10: 1475.4 | V10: 1528.33 | W10: 1585.13 | X10: 1620.04 | Y10: 1686.02 | Z10: 1605.45 | AA10: 1715.47 | AB10: 1746.09 | AC10: 1631.97 | AD10: 1507.34 | AE10: 1688.95 | AF10: 1490.54 | AG10: 1490.54 | AH10: 1490.54 | AI10: 1490.54 | AK10: 1490.54 | AL10: 1490.54 | AM10: 1490.54 | AN10: 1490.54
A11: EURKRW_end | C11: W/Euro(기말) | E11: 1346.38 | F11: 1346.38 | G11: 1347.37 | H11: 1351.6 | I11: 1400.62 | J11: 1344.08 | K11: 1344.08 | L11: 1420.26 | M11: 1435.88 | N11: 1425.26 | O11: 1433.66 | P11: 1433.66 | Q11: 1458.68 | R11: 1474.86 | S11: 1469.1 | T11: 1532.14 | U11: 1532.14 | V11: 1594.72 | W11: 1588.22 | X11: 1648.04 | Y11: 1696.94 | Z11: 1696.94 | AA11: 1753.21 | AB11: 1767.09 | AC11: 1539.06 | AD11: 1490.54 | AE11: 1490.54 | AF11: 1490.54 | AG11: 1490.54 | AH11: 1490.54 | AI11: 1490.54 | AK11: 1490.54 | AL11: 1490.54 | AM11: 1490.54 | AN11: 1490.54
A12: CNYKRW_avg | C12: 원/중국원(평균) | E12: 185.14 | F12: 177.65 | G12: 189.93 | H12: 190.76 | I12: 195.79 | J12: 191.09 | K12: 191.93 | L12: 186.59 | M12: 187.45 | N12: 181.28 | O12: 182.86 | P12: 184.52 | Q12: 185.04 | R12: 189.35 | S12: 189.24 | T12: 194.24 | U12: 189.49 | V12: 199.63 | W12: 193.41 | X12: 193.79 | Y12: 204.38 | Z12: 197.8 | AA12: 211.75 | AB12: 220.8 | AC12: 210.43 | AD12: 200.5 | AE12: 213.68 | AF12: 199.18 | AG12: 199.18 | AH12: 199.18 | AI12: 199.18 | AK12: 199.18 | AL12: 199.18 | AM12: 199.18 | AN12: 199.18
A13: CNYKRW_end | C13: 원/중국원(기말) | E13: 187.13 | F13: 187.13 | G13: 191.38 | H13: 194.13 | I13: 201.92 | J13: 182.67 | K13: 182.67 | L13: 189.97 | M13: 181.8 | N13: 184.26 | O13: 182.61 | P13: 182.61 | Q13: 186.66 | R13: 189.7 | S13: 187.12 | T13: 202.04 | U13: 202.04 | V13: 203.3 | W13: 189.14 | X13: 197.16 | Y13: 206.28 | Z13: 206.28 | AA13: 220.97 | AB13: 228.56 | AC13: 202.16 | AD13: 199.18 | AE13: 199.18 | AF13: 199.18 | AG13: 199.18 | AH13: 199.18 | AI13: 199.18 | AK13: 199.18 | AL13: 199.18 | AM13: 199.18 | AN13: 199.18
B14: 1b. 종가
A15: price_close_end | C15: 종가(기말) | E15: 3640 | G15: 8240 | H15: 9450 | I15: 6320 | J15: 6400 | L15: 6450 | M15: 5550 | N15: 4910 | O15: 4870 | Q15: 4865 | R15: 4500 | S15: 3350 | T15: 2700 | V15: 2735 | W15: 4135 | X15: 3360 | Y15: 3055 | AA15: 4265 | AB15: 2505 | AC15: 2455 | AD15: 2290
A16: price_high | C16: 종가(최고) | E16: 5180 | G16: 9400 | H16: 14950 | I16: 10100 | J16: 8440 | L16: 7640 | M16: 7490 | N16: 6410 | O16: 5480 | Q16: 5950 | R16: 6170 | S16: 5400 | T16: 3975 | V16: 3775 | W16: 5230 | X16: 4140 | Y16: 3895 | AA16: 5910 | AB16: 5880 | AC16: 2960 | AD16: 2850
A17: price_low | C17: 종가(최저) | E17: 2850 | G17: 2995 | H17: 8370 | I17: 6100 | J17: 5690 | L17: 5760 | M17: 5430 | N17: 4140 | O17: 3940 | Q17: 4755 | R17: 4040 | S17: 3030 | T17: 2560 | V17: 2685 | W17: 2360 | X17: 3165 | Y17: 2895 | AA17: 2965 | AB17: 2265 | AC17: 1767 | AD17: 2235
A18: price_avg | C18: 종가(평균) | E18: 3906.9 | G18: 4746.4 | H18: 10852.3 | I18: 8458.7 | J18: 6960.5 | L18: 6529.4 | M18: 6127.7 | N18: 4998.9 | O18: 4462.8 | Q18: 5180.3 | R18: 4725.5 | S18: 3860.9 | T18: 3275.2 | V18: 3154.1 | W18: 3239 | X18: 3631.2 | Y18: 3255 | AA18: 4289 | AB18: 3744.5 | AC18: 2421.5 | AD18: 2474.3
B20: 2. 추정 드라이버 | C20: 실적 열 = subQ 실현값(수식), 추정 열 = 가정(노란 = 모델값 역산, 연녹 = 3절 스칼라 참조)
A21: drv:매출액 | B21: yoy | C21: 매출액 YoY | J21: =IFERROR(subQ!J5/subQ!E5-1,"") | L21: =IFERROR(subQ!L5/subQ!G5-1,"") | M21: =IFERROR(subQ!M5/subQ!H5-1,"") | N21: =IFERROR(subQ!N5/subQ!I5-1,"") | O21: =IFERROR(subQ!O5/subQ!J5-1,"") | Q21: =IFERROR(subQ!Q5/subQ!L5-1,"") | R21: =IFERROR(subQ!R5/subQ!M5-1,"") | S21: =IFERROR(subQ!S5/subQ!N5-1,"") | T21: =IFERROR(subQ!T5/subQ!O5-1,"") | V21: =IFERROR(subQ!V5/subQ!Q5-1,"") | W21: =IFERROR(subQ!W5/subQ!R5-1,"") | X21: =IFERROR(subQ!X5/subQ!S5-1,"") | Y21: =IFERROR(subQ!Y5/subQ!T5-1,"") | AA21: =IFERROR(subQ!AA5/subQ!V5-1,"") | AB21: =IFERROR(subQ!AB5/subQ!W5-1,"") | AC21: -0.19811049 | AD21: -0.19810395 | AF21: -0.19812119 | AG21: -0.19809611 | AH21: -0.099090082 | AI21: -0.099048051 | AK21: -0.099109499 | AL21: -0.099070131 | AM21: -0.049489951 | AN21: -0.049559748
A22: drv:판관비 | B22: ratio | C22: 판관비율(/매출) | E22: =IFERROR(subQ!E8/subQ!E5,"") | F22: =IFERROR(subQ!F8/subQ!F5,"") | G22: =IFERROR(subQ!G8/subQ!G5,"") | H22: =IFERROR(subQ!H8/subQ!H5,"") | I22: =IFERROR(subQ!I8/subQ!I5,"") | J22: =IFERROR(subQ!J8/subQ!J5,"") | K22: =IFERROR(subQ!K8/subQ!K5,"") | L22: =IFERROR(subQ!L8/subQ!L5,"") | ... AB22: =IFERROR(subQ!AB8/subQ!AB5,"") | AC22: =$D$48 | AD22: =$D$48 | AE22: =IFERROR(subQ!AE8/subQ!AE5,"") | AF22: =$D$48 | AG22: =$D$48 | AH22: =$D$48 | AI22: =$D$48 | AJ22: =IFERROR(subQ!AJ8/subQ!AJ5,"") | AK22: =$D$48 | AL22: =$D$48 | AM22: =$D$48 | AN22: =$D$48 | AO22: =IFERROR(subQ!AO8/subQ!AO5,"")
A23: drv:영업이익 | B23: ratio | C23: 영업이익률(OPM) | E23: =IFERROR(subQ!E9/subQ!E5,"") | F23: =IFERROR(subQ!F9/subQ!F5,"") | G23: =IFERROR(subQ!G9/subQ!G5,"") | H23: =IFERROR(subQ!H9/subQ!H5,"") | I23: =IFERROR(subQ!I9/subQ!I5,"") | J23: =IFERROR(subQ!J9/subQ!J5,"") | K23: =IFERROR(subQ!K9/subQ!K5,"") | L23: =IFERROR(subQ!L9/subQ!L5,"") | ... AB23: =IFERROR(subQ!AB9/subQ!AB5,"") | AC23: -0.038307552 | AD23: -0.038304624 | AE23: =IFERROR(subQ!AE9/subQ!AE5,"") | AF23: -0.038258575 | AG23: -0.038324498 | AH23: -0.038278962 | AI23: -0.038322851 | AJ23: =IFERROR(subQ!AJ9/subQ!AJ5,"") | AK23: -0.038257368 | AL23: -0.038294589 | AM23: -0.038253108 | AN23: -0.038291865 | AO23: =IFERROR(subQ!AO9/subQ!AO5,"")
A24: drv:외환손익 | B24: abs | C24: 외환손익 (가정, 억원) | E24: =subQ!E13 | F24: =subQ!F13 | G24: =subQ!G13 | H24: =subQ!H13 | I24: =subQ!I13 | J24: =subQ!J13 | K24: =subQ!K13 | L24: =subQ!L13 | ... AB24: =subQ!AB13 | AC24: 0 | AD24: 0 | AE24: =subQ!AE13 | AF24: 0 | AG24: 0 | AH24: 0 | AI24: 0 | AJ24: =subQ!AJ13 | AK24: 0 | AL24: 0 | AM24: 0 | AN24: 0 | AO24: =subQ!AO13
A25: drv:기타영업외손익 | B25: abs | C25: 기타영업외손익 (가정, 억원) | E25: =subQ!E14 | F25: =subQ!F14 | G25: =subQ!G14 | H25: =subQ!H14 | I25: =subQ!I14 | J25: =subQ!J14 | K25: =subQ!K14 | L25: =subQ!L14 | ... AB25: =subQ!AB14 | AC25: 0 | AD25: 0 | AE25: =subQ!AE14 | AF25: 0 | AG25: 0 | AH25: 0 | AI25: 0 | AJ25: =subQ!AJ14 | AK25: 0 | AL25: 0 | AM25: 0 | AN25: 0 | AO25: =subQ!AO14
A26: drv:법인세비용 | B26: ratio | C26: 법인세율(/세전) | E26: =IFERROR(subQ!E16/subQ!E15,"") | F26: =IFERROR(subQ!F16/subQ!F15,"") | G26: =IFERROR(subQ!G16/subQ!G15,"") | H26: =IFERROR(subQ!H16/subQ!H15,"") | I26: =IFERROR(subQ!I16/subQ!I15,"") | J26: =IFERROR(subQ!J16/subQ!J15,"") | K26: =IFERROR(subQ!K16/subQ!K15,"") | L26: =IFERROR(subQ!L16/subQ!L15,"") | ... AB26: =IFERROR(subQ!AB16/subQ!AB15,"") | AC26: 0 | AD26: 0 | AE26: =IFERROR(subQ!AE16/subQ!AE15,"") | AF26: 0 | AG26: 0 | AH26: 0 | AI26: 0 | AJ26: =IFERROR(subQ!AJ16/subQ!AJ15,"") | AK26: 0 | AL26: 0 | AM26: 0 | AN26: 0 | AO26: =IFERROR(subQ!AO16/subQ!AO15,"")
A27: drv:지배주주순이익 | B27: ratio | C27: 지배주주 비중(/당기순이익) | E27: =IFERROR(subQ!E18/subQ!E17,"") | F27: =IFERROR(subQ!F18/subQ!F17,"") | G27: =IFERROR(subQ!G18/subQ!G17,"") | H27: =IFERROR(subQ!H18/subQ!H17,"") | I27: =IFERROR(subQ!I18/subQ!I17,"") | J27: =IFERROR(subQ!J18/subQ!J17,"") | K27: =IFERROR(subQ!K18/subQ!K17,"") | L27: =IFERROR(subQ!L18/subQ!L17,"") | ... AB27: =IFERROR(subQ!AB18/subQ!AB17,"") | AC27: =$D$49 | AD27: =$D$49 | AE27: =IFERROR(subQ!AE18/subQ!AE17,"") | AF27: =$D$49 | AG27: =$D$49 | AH27: =$D$49 | AI27: =$D$49 | AJ27: =IFERROR(subQ!AJ18/subQ!AJ17,"") | AK27: =$D$49 | AL27: =$D$49 | AM27: =$D$49 | AN27: =$D$49 | AO27: =IFERROR(subQ!AO18/subQ!AO17,"")
A28: drv:부채총계 | B28: qoq | C28: 부채총계 QoQ | G28: =IFERROR(subQ!G20/subQ!E20-1,"") | H28: =IFERROR(subQ!H20/subQ!G20-1,"") | I28: =IFERROR(subQ!I20/subQ!H20-1,"") | J28: =IFERROR(subQ!J20/subQ!I20-1,"") | L28: =IFERROR(subQ!L20/subQ!J20-1,"") | M28: =IFERROR(subQ!M20/subQ!L20-1,"") | N28: =IFERROR(subQ!N20/subQ!M20-1,"") | O28: =IFERROR(subQ!O20/subQ!N20-1,"") | Q28: =IFERROR(subQ!Q20/subQ!O20-1,"") | R28: =IFERROR(subQ!R20/subQ!Q20-1,"") | S28: =IFERROR(subQ!S20/subQ!R20-1,"") | T28: =IFERROR(subQ!T20/subQ!S20-1,"") | V28: =IFERROR(subQ!V20/subQ!T20-1,"") | W28: =IFERROR(subQ!W20/subQ!V20-1,"") | X28: =IFERROR(subQ!X20/subQ!W20-1,"") | Y28: =IFERROR(subQ!Y20/subQ!X20-1,"") | AA28: =IFERROR(subQ!AA20/subQ!Y20-1,"") | AB28: =IFERROR(subQ!AB20/subQ!AA20-1,"") | AC28: -1.1729e-05 | AD28: 0 | AF28: 0 | AG28: 0 | AH28: 0 | AI28: 0 | AK28: 0 | AL28: 0 | AM28: 0 | AN28: 0
A29: drv:자본총계 | B29: roll | C29: 자본총계 기타변동(배당 등, 억원) | G29: =IFERROR(subQ!E21+subQ!G17-subQ!G21,"") | H29: =IFERROR(subQ!G21+subQ!H17-subQ!H21,"") | I29: =IFERROR(subQ!H21+subQ!I17-subQ!I21,"") | J29: =IFERROR(subQ!I21+subQ!J17-subQ!J21,"") | L29: =IFERROR(subQ!J21+subQ!L17-subQ!L21,"") | M29: =IFERROR(subQ!L21+subQ!M17-subQ!M21,"") | N29: =IFERROR(subQ!M21+subQ!N17-subQ!N21,"") | O29: =IFERROR(subQ!N21+subQ!O17-subQ!O21,"") | Q29: =IFERROR(subQ!O21+subQ!Q17-subQ!Q21,"") | R29: =IFERROR(subQ!Q21+subQ!R17-subQ!R21,"") | S29: =IFERROR(subQ!R21+subQ!S17-subQ!S21,"") | T29: =IFERROR(subQ!S21+subQ!T17-subQ!T21,"") | V29: =IFERROR(subQ!T21+subQ!V17-subQ!V21,"") | W29: =IFERROR(subQ!V21+subQ!W17-subQ!W21,"") | X29: =IFERROR(subQ!W21+subQ!X17-subQ!X21,"") | Y29: =IFERROR(subQ!X21+subQ!Y17-subQ!Y21,"") | AA29: =IFERROR(subQ!Y21+subQ!AA17-subQ!AA21,"") | AB29: =IFERROR(subQ!AA21+subQ!AB17-subQ!AB21,"") | AC29: -0.003807554 | AD29: -0.003857632 | AF29: 0.001929552 | AG29: 6.4704115 | AH29: -0.003225667 | AI29: -0.008024344 | AK29: 0.000368462 | AL29: 6.4691866 | AM29: 0.007650895 | AN29: 0.002768129
A30: drv:지배주주지분 | B30: roll | C30: 지배주주지분 기타변동(배당 등, 억원) | G30: =IFERROR(subQ!E22+subQ!G18-subQ!G22,"") | H30: =IFERROR(subQ!G22+subQ!H18-subQ!H22,"") | I30: =IFERROR(subQ!H22+subQ!I18-subQ!I22,"") | J30: =IFERROR(subQ!I22+subQ!J18-subQ!J22,"") | L30: =IFERROR(subQ!J22+subQ!L18-subQ!L22,"") | M30: =IFERROR(subQ!L22+subQ!M18-subQ!M22,"") | N30: =IFERROR(subQ!M22+subQ!N18-subQ!N22,"") | O30: =IFERROR(subQ!N22+subQ!O18-subQ!O22,"") | Q30: =IFERROR(subQ!O22+subQ!Q18-subQ!Q22,"") | R30: =IFERROR(subQ!Q22+subQ!R18-subQ!R22,"") | S30: =IFERROR(subQ!R22+subQ!S18-subQ!S22,"") | T30: =IFERROR(subQ!S22+subQ!T18-subQ!T22,"") | V30: =IFERROR(subQ!T22+subQ!V18-subQ!V22,"") | W30: =IFERROR(subQ!V22+subQ!W18-subQ!W22,"") | X30: =IFERROR(subQ!W22+subQ!X18-subQ!X22,"") | Y30: =IFERROR(subQ!X22+subQ!Y18-subQ!Y22,"") | AA30: =IFERROR(subQ!Y22+subQ!AA18-subQ!AA22,"") | AB30: =IFERROR(subQ!AA22+subQ!AB18-subQ!AB22,"") | AC30: -0.004807554 | AD30: -0.003857632 | AF30: 0.001929552 | AG30: 6.4704115 | AH30: -0.003225667 | AI30: -0.008024344 | AK30: 0.000368462 | AL30: 6.4691866 | AM30: 0.007650895 | AN30: 0.002768129
A31: drv:총차입금 | B31: qoq | C31: 총차입금 QoQ | G31: =IFERROR(subQ!G23/subQ!E23-1,"") | H31: =IFERROR(subQ!H23/subQ!G23-1,"") | I31: =IFERROR(subQ!I23/subQ!H23-1,"") | J31: =IFERROR(subQ!J23/subQ!I23-1,"") | L31: =IFERROR(subQ!L23/subQ!J23-1,"") | M31: =IFERROR(subQ!M23/subQ!L23-1,"") | N31: =IFERROR(subQ!N23/subQ!M23-1,"") | O31: =IFERROR(subQ!O23/subQ!N23-1,"") | Q31: =IFERROR(subQ!Q23/subQ!O23-1,"") | R31: =IFERROR(subQ!R23/subQ!Q23-1,"") | S31: =IFERROR(subQ!S23/subQ!R23-1,"") | T31: =IFERROR(subQ!T23/subQ!S23-1,"") | V31: =IFERROR(subQ!V23/subQ!T23-1,"") | W31: =IFERROR(subQ!W23/subQ!V23-1,"") | X31: =IFERROR(subQ!X23/subQ!W23-1,"") | Y31: =IFERROR(subQ!Y23/subQ!X23-1,"") | AA31: =IFERROR(subQ!AA23/subQ!Y23-1,"") | AB31: =IFERROR(subQ!AB23/subQ!AA23-1,"") | AC31: -1.9221e-05 | AD31: 0 | AF31: 0 | AG31: 0 | AH31: 0 | AI31: 0 | AK31: 0 | AL31: 0 | AM31: 0 | AN31: 0
A32: drv:순차입금 | B32: qoq | C32: 순차입금 QoQ | G32: =IFERROR(subQ!G24/subQ!E24-1,"") | H32: =IFERROR(subQ!H24/subQ!G24-1,"") | I32: =IFERROR(subQ!I24/subQ!H24-1,"") | J32: =IFERROR(subQ!J24/subQ!I24-1,"") | L32: =IFERROR(subQ!L24/subQ!J24-1,"") | M32: =IFERROR(subQ!M24/subQ!L24-1,"") | N32: =IFERROR(subQ!N24/subQ!M24-1,"") | O32: =IFERROR(subQ!O24/subQ!N24-1,"") | Q32: =IFERROR(subQ!Q24/subQ!O24-1,"") | R32: =IFERROR(subQ!R24/subQ!Q24-1,"") | S32: =IFERROR(subQ!S24/subQ!R24-1,"") | T32: =IFERROR(subQ!T24/subQ!S24-1,"") | V32: =IFERROR(subQ!V24/subQ!T24-1,"") | W32: =IFERROR(subQ!W24/subQ!V24-1,"") | X32: =IFERROR(subQ!X24/subQ!W24-1,"") | Y32: =IFERROR(subQ!Y24/subQ!X24-1,"") | AA32: =IFERROR(subQ!AA24/subQ!Y24-1,"") | AB32: =IFERROR(subQ!AB24/subQ!AA24-1,"") | AC32: 0.035566994 | AD32: 0.041407542 | AF32: 0.019351425 | AG32: 0.082610308 | AH32: 0.028358107 | AI32: 0.032971425 | AK32: 0.016249678 | AL32: 0.069098985 | AM32: 0.024630542 | AN32: 0.02849861
A33: drv:이자발생자산 | B33: qoq | C33: 이자발생자산 QoQ | G33: =IFERROR(subQ!G25/subQ!E25-1,"") | H33: =IFERROR(subQ!H25/subQ!G25-1,"") | I33: =IFERROR(subQ!I25/subQ!H25-1,"") | J33: =IFERROR(subQ!J25/subQ!I25-1,"") | L33: =IFERROR(subQ!L25/subQ!J25-1,"") | M33: =IFERROR(subQ!M25/subQ!L25-1,"") | N33: =IFERROR(subQ!N25/subQ!M25-1,"") | O33: =IFERROR(subQ!O25/subQ!N25-1,"") | Q33: =IFERROR(subQ!Q25/subQ!O25-1,"") | R33: =IFERROR(subQ!R25/subQ!Q25-1,"") | S33: =IFERROR(subQ!S25/subQ!R25-1,"") | T33: =IFERROR(subQ!T25/subQ!S25-1,"") | V33: =IFERROR(subQ!V25/subQ!T25-1,"") | W33: =IFERROR(subQ!W25/subQ!V25-1,"") | X33: =IFERROR(subQ!X25/subQ!W25-1,"") | Y33: =IFERROR(subQ!Y25/subQ!X25-1,"") | AA33: =IFERROR(subQ!AA25/subQ!Y25-1,"") | AB33: =IFERROR(subQ!AB25/subQ!AA25-1,"") | AC33: -0.032340794 | AD33: -0.040291076 | AF33: -0.020432596 | AG33: -0.090768353 | AH33: -0.037100099 | AI33: -0.046067939 | AK33: -0.024585366 | AL33: -0.10892178 | AM33: -0.046582108 | AN33: -0.05792324
A34: drv:현금및현금성자산 | B34: qoq | C34: 현금및현금성자산 QoQ | G34: =IFERROR(subQ!G26/subQ!E26-1,"") | H34: =IFERROR(subQ!H26/subQ!G26-1,"") | I34: =IFERROR(subQ!I26/subQ!H26-1,"") | J34: =IFERROR(subQ!J26/subQ!I26-1,"") | L34: =IFERROR(subQ!L26/subQ!J26-1,"") | M34: =IFERROR(subQ!M26/subQ!L26-1,"") | N34: =IFERROR(subQ!N26/subQ!M26-1,"") | O34: =IFERROR(subQ!O26/subQ!N26-1,"") | Q34: =IFERROR(subQ!Q26/subQ!O26-1,"") | R34: =IFERROR(subQ!R26/subQ!Q26-1,"") | S34: =IFERROR(subQ!S26/subQ!R26-1,"") | T34: =IFERROR(subQ!T26/subQ!S26-1,"") | V34: =IFERROR(subQ!V26/subQ!T26-1,"") | W34: =IFERROR(subQ!W26/subQ!V26-1,"") | X34: =IFERROR(subQ!X26/subQ!W26-1,"") | Y34: =IFERROR(subQ!Y26/subQ!X26-1,"") | AA34: =IFERROR(subQ!AA26/subQ!Y26-1,"") | AB34: =IFERROR(subQ!AB26/subQ!AA26-1,"")
A35: drv:영업활동현금흐름 | B35: yoy | C35: 영업활동현금흐름 YoY | J35: =IFERROR(subQ!J27/subQ!E27-1,"") | L35: =IFERROR(subQ!L27/subQ!G27-1,"") | M35: =IFERROR(subQ!M27/subQ!H27-1,"") | N35: =IFERROR(subQ!N27/subQ!I27-1,"") | O35: =IFERROR(subQ!O27/subQ!J27-1,"") | Q35: =IFERROR(subQ!Q27/subQ!L27-1,"") | R35: =IFERROR(subQ!R27/subQ!M27-1,"") | S35: =IFERROR(subQ!S27/subQ!N27-1,"") | T35: =IFERROR(subQ!T27/subQ!O27-1,"") | V35: =IFERROR(subQ!V27/subQ!Q27-1,"") | W35: =IFERROR(subQ!W27/subQ!R27-1,"") | X35: =IFERROR(subQ!X27/subQ!S27-1,"") | Y35: =IFERROR(subQ!Y27/subQ!T27-1,"") | AA35: =IFERROR(subQ!AA27/subQ!V27-1,"") | AB35: =IFERROR(subQ!AB27/subQ!W27-1,"")
A36: drv:주식수 | B36: qoq | C36: 주식수 QoQ | G36: =IFERROR(subQ!G28/subQ!E28-1,"") | H36: =IFERROR(subQ!H28/subQ!G28-1,"") | I36: =IFERROR(subQ!I28/subQ!H28-1,"") | J36: =IFERROR(subQ!J28/subQ!I28-1,"") | L36: =IFERROR(subQ!L28/subQ!J28-1,"") | M36: =IFERROR(subQ!M28/subQ!L28-1,"") | N36: =IFERROR(subQ!N28/subQ!M28-1,"") | O36: =IFERROR(subQ!O28/subQ!N28-1,"") | Q36: =IFERROR(subQ!Q28/subQ!O28-1,"") | R36: =IFERROR(subQ!R28/subQ!Q28-1,"") | S36: =IFERROR(subQ!S28/subQ!R28-1,"") | T36: =IFERROR(subQ!T28/subQ!S28-1,"") | V36: =IFERROR(subQ!V28/subQ!T28-1,"") | W36: =IFERROR(subQ!W28/subQ!V28-1,"") | X36: =IFERROR(subQ!X28/subQ!W28-1,"") | Y36: =IFERROR(subQ!Y28/subQ!X28-1,"") | AA36: =IFERROR(subQ!AA28/subQ!Y28-1,"") | AB36: =IFERROR(subQ!AB28/subQ!AA28-1,"") | AC36: 0 | AD36: 0 | AF36: 0 | AG36: 0 | AH36: 0 | AI36: 0 | AK36: 0 | AL36: 0 | AM36: 0 | AN36: 0
A37: drv:DPS | B37: abs | C37: DPS (가정, 원) | E37: =subQ!E31 | F37: =subQ!F31 | G37: =subQ!G31 | H37: =subQ!H31 | I37: =subQ!I31 | J37: =subQ!J31 | K37: =subQ!K31 | L37: =subQ!L31 | ... AB37: =subQ!AB31 | AD37: 20 | AE37: =subQ!AE31 | AI37: 20 | AJ37: =subQ!AJ31 | AN37: 20 | AO37: =subQ!AO31
B39: 3. 밸류에이션·스칼라 | C39: 노란 셀 = 가정. '연결' 표시는 추정 전 분기 수식이 이 셀을 참조한다는 뜻
A40: sc:종가 | C40: 종가 | D40: 2290 | E40: 원 — 네이버 정규장 종가(aik 확정종가 대조 · aik 2,495원)
A41: sc:기준일 | C41: 기준일 | D41: 20261013 | E41: 종가 기준일
A42: sc:COE | C42: COE | D42: 0.09 | E42: 자기자본비용(가정) — TP 적정 PBR = ROE/COE
...

Sheet BS연결
B1: (백만원) | C1: 이름: BS연결H | E1: 4Q21 | F1: 2021 | G1: 1Q22 | H1: 2Q22 | I1: 3Q22 | J1: 4Q22 | K1: 2022 | L1: 1Q23 | M1: 2Q23 | N1: 3Q23 | O1: 4Q23 | P1: 2023 | Q1: 1Q24 | R1: 2Q24 | S1: 3Q24 | T1: 4Q24 | U1: 2024 | V1: 1Q25 | W1: 2Q25 | X1: 3Q25 | Y1: 4Q25 | Z1: 2025 | AA1: 1Q26 | AB1: 2Q26 | AC1: 3Q26 | AD1: 4Q26 | AE1: 2026 | AF1: 1Q27 | AG1: 2Q27 | AH1: 3Q27 | AI1: 4Q27 | AJ1: 2027 | AK1: 1Q28 | AL1: 2Q28 | AM1: 3Q28 | AN1: 4Q28 | AO1: 2028
B2: 연결 | D2: fin json(kship_fin.py)
B3: 한신기계공업(연) | C3: UPDATE: 26-10-13 | E3: 1 | F3: 2 | G3: 3 | H3: 4 | I3: 5 | J3: 6 | K3: 7 | L3: 8 | M3: 9 | N3: 10 | O3: 11 | P3: 12 | Q3: 13 | R3: 14 | S3: 15 | T3: 16 | U3: 17 | V3: 18 | W3: 19 | X3: 20 | Y3: 21 | Z3: 22 | AA3: 23 | AB3: 24 | AC3: 25 | AD3: 26 | AE3: 27 | AF3: 28 | AG3: 29 | AH3: 30 | AI3: 31 | AJ3: 32 | AK3: 33 | AL3: 34 | AM3: 35 | AN3: 36 | AO3: 37
B4: Account Code | C4: AccountNAME | E4: 2021.12 | F4: 2021.12A | G4: 2022.03 | H4: 2022.06 | I4: 2022.09 | J4: 2022.12 | K4: 2022.12A | L4: 2023.03 | M4: 2023.06 | N4: 2023.09 | O4: 2023.12 | P4: 2023.12A | Q4: 2024.03 | R4: 2024.06 | S4: 2024.09 | T4: 2024.12 | U4: 2024.12A | V4: 2025.03 | W4: 2025.06 | X4: 2025.09 | Y4: 2025.12 | Z4: 2025.12A | AA4: 2026.03 | AB4: 2026.06 | AC4: 2026.09 | AD4: 2026.12 | AE4: 2026.12A | AF4: 2027.03 | AG4: 2027.06 | AH4: 2027.09 | AI4: 2027.12 | AJ4: 2027.12A | AK4: 2028.03 | AL4: 2028.06 | AM4: 2028.09 | AN4: 2028.12 | AO4: 2028.12A
A5: 1 | C5: 유동자산 | E5: 69346.21 | F5: 69346.21 | G5: 67268.15 | H5: 72146.61 | I5: 76362.58 | J5: 68795.51 | K5: 68795.51 | L5: 80482.57 | M5: 73163.48 | N5: 74245.16 | O5: 67028.09 | P5: 67028.09 | Q5: 67082.79 | R5: 70989.6 | S5: 76974.63 | T5: 72877.25 | U5: 72877.25 | V5: 61910.08 | W5: 60003.52 | X5: 60502.46 | Y5: 55070.88 | Z5: 55070.88 | AA5: 50804.8 | AB5: 55398.57
A6: 1 | C6: 현금및현금성자산 | E6: 9854.43 | F6: 9854.43 | G6: 7749.02 | H6: 8628.16 | I6: 18599.67 | J6: 15607.7 | K6: 15607.7 | L6: 16872.49 | M6: 10484.28 | N6: 8225.27 | O6: 8957.04 | P6: 8957.04 | Q6: 7049.78 | R6: 18474.78 | S6: 20872.14 | T6: 32815.56 | U6: 32815.56 | V6: 21293.64 | W6: 17663.54 | X6: 12974.02 | Y6: 17140.3 | Z6: 17140.3 | AA6: 11180.48 | AB6: 8525.98
A7: 1 | C7: 단기금융상품 | E7: 7.82 | F7: 7.82 | G7: 8.18 | H7: 6.78 | I7: 7.24 | J7: 7.69 | K7: 7.69 | L7: 7.7 | M7: 266.78 | N7: 125.24 | O7: 18.24 | P7: 18.24 | Q7: 15.51 | R7: 428.83 | S7: 191.72 | T7: 147.95 | U7: 147.95 | V7: 94.57 | W7: 78.05 | X7: 81.53 | Y7: 83.99 | Z7: 83.99 | AA7: 54.5 | AB7: 59.07
A8: 1 | C8: 단기금융자산 | E8: 3235.58 | F8: 3235.58 | G8: 2042.3 | H8: 7539.13 | I8: 23.46 | J8: 7.69 | K8: 7.69 | L8: 3509.95 | M8: 4593.93 | N8: 125.24 | O8: 18.24 | P8: 18.24 | Q8: 15.51 | R8: 428.83 | S8: 191.72 | T8: 3272.15 | U8: 3272.15 | V8: 3036.97 | W8: 2360.89 | X8: 1235.37 | Y8: 994.48 | Z8: 994.48 | AA8: 404.05 | AB8: 1058.73
A9: 1 | C9: 단기투자자산(공정가치) | E9: 10219.93 | F9: 10219.93 | G9: 10871.41 | H9: 9295.81 | I9: 9581.51 | J9: 9246.79 | K9: 9246.79 | L9: 9831.62 | M9: 10620.17 | N9: 10383.19 | O9: 21056.56 | P9: 21056.56 | Q9: 23676.22 | R9: 14045.48 | S9: 15216.76 | T9: 526.25 | U9: 526.25 | V9: 4374.12 | W9: 7021.18 | X9: 9034.77 | Y9: 4439.93 | Z9: 4439.93 | AA9: 7693.21 | AB9: 10437.67
A10: 1 | C10: 매출채권및기타채권 | E10: 28205 | F10: 28205 | G10: 25350.72 | H10: 26056.56 | I10: 26305.71 | J10: 26123.98 | K10: 26123.98 | L10: 28840.98 | M10: 26957.11 | N10: 27305.72 | O10: 20976.55 | P10: 20976.55 | Q10: 19818.57 | R10: 18838.27 | S10: 20844.55 | T10: 21727.37 | U10: 21727.37 | V10: 15652.76 | W10: 16479.66 | X10: 18366.89 | Y10: 18885.1 | Z10: 18885.1 | AA10: 15409.77 | AB10: 16468.85
A11: 1 | C11: 재고자산 | E11: 16867.71 | F11: 16867.71 | G11: 19418.62 | H11: 18903.37 | I11: 19629.27 | J11: 12752.34 | K11: 12752.34 | L11: 18907.64 | M11: 18478.48 | N11: 20149.39 | O11: 12885.1 | P11: 12885.1 | Q11: 13512.02 | R11: 17446.18 | S11: 16988.14 | T11: 12946.85 | U11: 12946.85 | V11: 15334.13 | W11: 14191.42 | X11: 16280.89 | Y11: 12174.6 | Z11: 12174.6 | AA11: 14533.53 | AB11: 16238.21
A12: 1 | C12: 기타유동자산 | E12: 963.55 | F12: 963.55 | G12: 1836.1 | H12: 1723.57 | I12: 2222.97 | J12: 1554.76 | K12: 1554.76 | L12: 2519.9 | M12: 2029.5 | N12: 1916.25 | O12: 2915.06 | P12: 2915.06 | Q12: 2687.32 | R12: 1536.89 | S12: 2642.14 | T12: 1344.54 | U12: 1344.54 | V12: 688.85 | W12: 738.96 | X12: 1047.17 | Y12: 1417.27 | Z12: 1417.27 | AA12: 1546.71 | AB12: 1840.72
A13: 1 | C13: 비유동자산 | E13: 31802.81 | F13: 31802.81 | G13: 31762.93 | H13: 41433.42 | I13: 41298.57 | J13: 42985.98 | K13: 42985.98 | L13: 41826.29 | M13: 41438.44 | N13: 42402.36 | O13: 48827.45 | P13: 48827.45 | Q13: 49323.29 | R13: 48986.3 | S13: 48886.84 | T13: 53681.88 | U13: 53681.88 | V13: 56172.74 | W13: 56082.5 | X13: 67245.5 | Y13: 65098.19 | Z13: 65098.19 | AA13: 65883.18 | AB13: 64470.16
A14: 1 | C14: 장기금융자산 | E14: 18.25 | F14: 18.25 | G14: 19.91 | H14: 20.66 | I14: 21.56 | J14: 22.46 | K14: 22.46 | L14: 23.66 | M14: 12.43 | N14: 13.48 | O14: 9.8 | P14: 9.8 | Q14: 13.33 | R14: 14.05 | S14: 14.5 | T14: 16.95 | U14: 16.95 | V14: 17.48 | W14: 117.85 | X14: 118.31 | Y14: 118.71 | Z14: 118.71 | AA14: 119.22 | AB14: 3906.61
A15: 1 | C15: 투자자산 | E15: 18.25 | F15: 18.25 | G15: 19.91 | H15: 20.66 | I15: 21.56 | J15: 22.46 | K15: 22.46 | L15: 23.66 | M15: 12.43 | N15: 13.48 | O15: 9.8 | P15: 9.8 | Q15: 13.33 | R15: 14.05 | S15: 14.5 | T15: 16.95 | U15: 16.95 | V15: 17.48 | W15: 117.85 | X15: 118.31 | Y15: 118.71 | Z15: 118.71 | AA15: 119.22 | AB15: 3906.61
A16: 1 | C16: 장기매출채권및기타채권 | E16: 733.38 | F16: 733.38 | G16: 794.23 | H16: 813.41 | I16: 825.8 | L16: 881.16 | M16: 836.98 | N16: 823.53 | AB16: 1110.46
A17: 1 | C17: 투자부동산 | E17: 4093.44 | F17: 4093.44 | G17: 4070.09 | H17: 13742.86 | I17: 13709.75 | J17: 13676.64 | K17: 13676.64 | L17: 13646.79 | M17: 13580.22 | N17: 13585.58 | O17: 13544.21 | P17: 13544.21 | Q17: 13509.81 | R17: 13476.54 | S17: 13442.8 | T17: 13442.8 | U17: 13442.8 | V17: 13409.69 | W17: 13809.16 | X17: 13774.7 | Y17: 31026.91 | Z17: 31026.91 | AA17: 32645.35 | AB17: 32626.52
A18: 1 | C18: 유형자산 | E18: 26370.3 | F18: 26370.3 | G18: 26270.38 | H18: 26232.08 | I18: 26018.07 | J18: 25488.4 | K18: 25488.4 | L18: 25516.5 | M18: 25607.9 | N18: 26749.66 | O18: 33084.92 | P18: 33084.92 | Q18: 33166.67 | R18: 33383.07 | S18: 33676.08 | T18: 33030.49 | U18: 33030.49 | V18: 33244.06 | W18: 32993.17 | X18: 44170.54 | Y18: 26786.27 | Z18: 26786.27 | AA18: 25880.76 | AB18: 25757.28
A19: 1 | C19: 무형자산 | E19: 587.44 | F19: 587.44 | G19: 608.32 | H19: 624.42 | I19: 723.4 | J19: 999.15 | K19: 999.15 | L19: 991.23 | M19: 975.87 | O19: 900.17 | P19: 900.17 | Q19: 852.96 | R19: 1146.35 | S19: 828.3 | T19: 729.31 | U19: 729.31 | V19: 702.94 | W19: 695.34 | X19: 688.81 | Y19: 615.07 | Z19: 615.07 | AA19: 589.09 | AB19: 563.12
A20: 1 | C20: 자산총계 | E20: 101149.02 | F20: 101149.02 | G20: 99031.09 | H20: 113580.03 | I20: 117661.16 | J20: 111781.49 | K20: 111781.49 | L20: 122308.86 | M20: 114601.92 | N20: 116647.51 | O20: 115855.54 | P20: 115855.54 | Q20: 116406.08 | R20: 119975.9 | S20: 125861.48 | T20: 126559.13 | U20: 126559.13 | V20: 118082.82 | W20: 116086.02 | X20: 127747.95 | Y20: 120169.07 | Z20: 120169.07 | AA20: 116687.98 | AB20: 119868.72
A21: 1 | C21: 유동부채 | E21: 10890.43 | F21: 10890.43 | G21: 9775.81 | H21: 11923.85 | I21: 14752.56 | J21: 21936.67 | K21: 21936.67 | L21: 25945.25 | M21: 21695.91 | N21: 21825.37 | O21: 14800.97 | P21: 14800.97 | Q21: 19207.76 | R21: 19686.23 | S21: 23790.5 | T21: 26595.44 | U21: 26595.44 | V21: 17750.88 | W21: 16141.81 | X21: 18585.79 | Y21: 24104.92 | Z21: 24104.92 | AA21: 22559.26 | AB21: 23422.25
A22: 1 | C22: 매입채무및기타채무 | E22: 7599.17 | F22: 7599.17 | G22: 6403.23 | H22: 5841.22 | I22: 5542.57 | J22: 7939.53 | K22: 7939.53 | L22: 12026.89 | M22: 6249.1 | N22: 12603.86 | O22: 5917.89 | P22: 5917.89 | Q22: 5639.84 | R22: 5236.76 | S22: 7961.26 | T22: 7299.6 | U22: 7299.6 | V22: 4314.26 | W22: 5372.66 | X22: 6032.67 | Y22: 7311.37 | Z22: 7311.37 | AA22: 5034.07 | AB22: 6511.6
A23: 1 | C23: 단기차입금 | E23: 230.28 | F23: 230.28 | G23: 280.63 | H23: 384.69 | I23: 3270.05 | J23: 6641.54 | K23: 6641.54 | L23: 6640.13 | M23: 9728.41 | N23: 1040.46 | O23: 7027.72 | P23: 7027.72 | Q23: 8952.37 | R23: 8543.49 | S23: 8658.59 | T23: 12250.08 | U23: 12250.08 | V23: 9867.05 | W23: 7988.32 | X23: 9813.31 | Y23: 7826.07 | Z23: 7826.07 | AA23: 8455.19 | AB23: 7571.72
A24: 1 | C24: 당기법인세부채(미지급법인세) | E24: 891.71 | F24: 891.71 | G24: 500.39 | H24: 2497.93 | I24: 3721.85 | J24: 2322.73 | K24: 2322.73 | L24: 1287.65 | M24: 0 | N24: 0 | O24: 0.1 | P24: 0.1 | Q24: 0 | S24: 1.74 | T24: 2854.76 | U24: 2854.76 | V24: 650.25 | W24: 5.16 | X24: -33.44 | Y24: 449.51 | Z24: 449.51 | AA24: 265.87 | AB24: 446.72
A25: 1 | C25: 기타유동부채 | E25: 2169.27 | F25: 2169.27 | G25: 2591.56 | H25: 3200.01 | I25: 2218.08 | J25: 3782.86 | K25: 3782.86 | L25: 5990.59 | M25: 4818.4 | N25: 7281.04 | O25: 1855.26 | P25: 1855.26 | Q25: 4615.55 | R25: 5905.98 | S25: 7168.91 | T25: 509.05 | U25: 509.05 | V25: 490.49 | W25: 596.94 | X25: 732.46 | Y25: 974.25 | Z25: 974.25 | AA25: 547.42 | AB25: 461.2
A26: 1 | C26: 비유동부채 | E26: 4196.02 | F26: 4196.02 | G26: 4435.31 | H26: 5280.91 | I26: 5556.54 | J26: 838.66 | K26: 838.66 | L26: 2268.66 | M26: 1364.21 | N26: 1364.21 | O26: 8490.27 | P26: 8490.27 | Q26: 8138.33 | R26: 9094.21 | S26: 9789.53 | T26: 10368.13 | U26: 10368.13 | V26: 10983.87 | W26: 10451.04 | X26: 17703 | Y26: 8505.73 | Z26: 8505.73 | AA26: 8789.59 | AB26: 8977.13
A27: 1 | C27: 장기매입채무및기타채무 | E27: 582.4 | F27: 582.4 | G27: 572.9 | H27: 811.77 | I27: 823.95 | J27: 830.46 | K27: 830.46 | L27: 1010.46 | M27: 1010.46 | N27: 1010.46 | O27: 909.96 | P27: 909.96 | Q27: 724.96 | R27: 1337.08 | S27: 1277.14 | T27: 1269.88 | U27: 1269.88 | V27: 1270.95 | W27: 1272.02 | X27: 1156.09 | Y27: 1232.68 | Z27: 1232.68 | AA27: 1228.99 | AB27: 1221.06
A28: 1 | C28: 장기차입금 | E28: 2750 | F28: 2750 | G28: 2750 | H28: 2750 | I28: 2750 | J28: 0 | K28: 0 | L28: 1250 | M28: 350 | N28: 350 | O28: 7580.31 | P28: 7580.31 | Q28: 7413.37 | R28: 7209.38 | S28: 7751.17 | T28: 7852.93 | U28: 7852.93 | V28: 8237.77 | W28: 7524.18 | X28: 14599.5 | Y28: 6515.17 | Z28: 6515.17 | AA28: 6722.4 | AB28: 6759.06
A29: 1 | C29: 기타비유동부채 | E29: 24.05 | F29: 24.05 | G29: 18.85 | H29: 13.61 | I29: 13.49 | J29: 8.2 | K29: 8.2 | L29: 8.2 | M29: 3.75 | N29: 3.75 | O29: 0 | P29: 0 | T29: 0 | U29: 0 | X29: 114.1 | Y29: 104.66 | Z29: 104.66 | AA29: 95.09 | AB29: 85.41
A30: 1 | C30: 이연법인세부채 | E30: 803.23 | F30: 803.23 | G30: 803.23 | H30: 1171.72 | I30: 1171.72 | J30: 0 | K30: 0 | L30: 0 | O30: 0 | P30: 0 | R30: 547.75 | S30: 547.75 | T30: 0 | U30: 0
A31: 1 | C31: 부채총계 | E31: 15086.45 | F31: 15086.45 | G31: 14211.11 | H31: 17204.76 | I31: 20309.1 | J31: 22775.32 | K31: 22775.32 | L31: 28213.91 | M31: 23060.12 | N31: 23189.58 | O31: 23291.24 | P31: 23291.24 | Q31: 27346.09 | R31: 28780.44 | S31: 33580.03 | T31: 36963.57 | U31: 36963.57 | V31: 28734.75 | W31: 26592.85 | X31: 36288.79 | Y31: 32610.65 | Z31: 32610.65 | AA31: 31348.85 | AB31: 32399.38
A32: 1 | C32: 지배주주지분 | E32: 85929.86 | F32: 85929.86 | G32: 84686.56 | H32: 96241.94 | I32: 97218.7 | J32: 88872.56 | K32: 88872.56 | L32: 93961.1 | M32: 91407.95 | N32: 93324.38 | O32: 92430.84 | P32: 92430.84 | Q32: 88926.37 | R32: 91060.61 | S32: 92146.62 | T32: 89460.78 | U32: 89460.78 | V32: 89213.21 | W32: 89358.38 | X32: 91324.38 | Y32: 87423.68 | Z32: 87423.68 | AA32: 85203.87 | AB32: 87334.24
A33: 1 | C33: 자본금 | E33: 16223.08 | F33: 16223.08 | G33: 16223.08 | H33: 16223.08 | I33: 16223.08 | J33: 16223.08 | K33: 16223.08 | L33: 16223.08 | M33: 16223.08 | N33: 16223.08 | O33: 16223.08 | P33: 16223.08 | Q33: 16223.08 | R33: 16223.08 | S33: 16223.08 | T33: 16223.08 | U33: 16223.08 | V33: 16223.08 | W33: 16223.08 | X33: 16223.08 | Y33: 16223.08 | Z33: 16223.08 | AA33: 16223.08 | AB33: 16223.08
A34: 1 | C34: 자본잉여금 | E34: 8439.1 | F34: 8439.1 | G34: 8439.1 | H34: 19275.7 | I34: 19275.7 | J34: 19275.7 | K34: 19275.7 | L34: 19275.7 | M34: 19275.7 | N34: 19275.7 | O34: 19275.7 | P34: 19275.7 | Q34: 19275.7 | R34: 19275.7 | S34: 19275.7 | T34: 19275.7 | U34: 19275.7 | V34: 19275.7 | W34: 19275.7 | X34: 19275.7 | Y34: 19275.7 | Z34: 19275.7 | AA34: 19275.7 | AB34: 19275.7
A35: 1 | C35: 기타자본 | E35: -2088.3 | F35: -2088.3 | G35: -2062.54 | H35: -463.96 | I35: -437.62 | J35: -411.29 | K35: -411.29 | L35: -385.53 | M35: -941.1 | N35: -941.1 | O35: -386.1 | P35: -386.1 | Q35: -386.1 | R35: -836.1 | S35: -836.1 | T35: -836.1 | U35: -836.1 | V35: -836.1 | W35: -836.1 | X35: -836.1 | Y35: -836.1 | Z35: -836.1 | AA35: -836.1 | AB35: -836.1
A36: 1 | C36: 기타포괄이익누계액 | E36: 845.69 | F36: 845.69 | G36: 911.73 | H36: 958.52 | I36: 1078.57 | J36: 792.19 | K36: 792.19 | L36: 909.21 | M36: 780.01 | N36: 827.47 | O36: 784.25 | P36: 784.25 | Q36: 852.91 | R36: 921.27 | S36: 887.46 | T36: 971.2 | U36: 971.2 | V36: 968.73 | W36: 891.91 | X36: 1014.47 | Y36: 680.3 | Z36: 680.3 | AA36: 610.46 | AB36: 593.65
A37: 1 | C37: 이익잉여금 | E37: 62510.3 | F37: 62510.3 | G37: 61175.19 | H37: 60248.59 | I37: 61078.98 | J37: 52992.88 | K37: 52992.88 | L37: 57938.64 | M37: 56070.27 | N37: 57939.23 | O37: 56533.91 | P37: 56533.91 | Q37: 52960.79 | R37: 55476.66 | S37: 56596.49 | T37: 53826.9 | U37: 53826.9 | V37: 53581.81 | W37: 53803.79 | X37: 55647.23 | Y37: 52080.71 | Z37: 52080.71 | AA37: 49930.74 | AB37: 52077.91
A38: 1 | C38: 비지배주주지분 | E38: 132.71 | F38: 132.71 | G38: 133.42 | H38: 133.34 | I38: 133.36 | J38: 133.61 | K38: 133.61 | L38: 133.85 | M38: 133.85 | N38: 133.55 | O38: 133.46 | P38: 133.46 | Q38: 133.62 | R38: 134.85 | S38: 134.82 | T38: 134.78 | U38: 134.78 | V38: 134.86 | W38: 134.78 | X38: 134.78 | Y38: 134.74 | Z38: 134.74 | AA38: 135.25 | AB38: 135.1
A39: 1 | C39: 자본총계 | E39: 86062.57 | F39: 86062.57 | G39: 84819.97 | H39: 96375.28 | I39: 97352.06 | J39: 89006.17 | K39: 89006.17 | L39: 94094.95 | M39: 91541.8 | N39: 93457.93 | O39: 92564.3 | P39: 92564.3 | Q39: 89059.99 | R39: 91195.46 | S39: 92281.44 | T39: 89595.56 | U39: 89595.56 | V39: 89348.07 | W39: 89493.17 | X39: 91459.16 | Y39: 87558.43 | Z39: 87558.43 | AA39: 85339.13 | AB39: 87469.34
A40: 1 | C40: 부채와자본총계 | E40: 101149.02 | F40: 101149.02 | G40: 99031.09 | H40: 113580.03 | I40: 117661.16 | J40: 111781.49 | K40: 111781.49 | L40: 122308.86 | M40: 114601.92 | N40: 116647.51 | O40: 115855.54 | P40: 115855.54 | Q40: 116406.08 | R40: 119975.9 | S40: 125861.48 | T40: 126559.13 | U40: 126559.13 | V40: 118082.82 | W40: 116086.02 | X40: 127747.95 | Y40: 120169.07 | Z40: 120169.07 | AA40: 116687.98 | AB40: 119868.72
...

Sheet BS별도
B1: (백만원) | C1: 이름: BS별도H | E1: 4Q21 | F1: 2021 | G1: 1Q22 | H1: 2Q22 | I1: 3Q22 | J1: 4Q22 | K1: 2022 | L1: 1Q23 | M1: 2Q23 | N1: 3Q23 | O1: 4Q23 | P1: 2023 | Q1: 1Q24 | R1: 2Q24 | S1: 3Q24 | T1: 4Q24 | U1: 2024 | V1: 1Q25 | W1: 2Q25 | X1: 3Q25 | Y1: 4Q25 | Z1: 2025 | AA1: 1Q26 | AB1: 2Q26 | AC1: 3Q26 | AD1: 4Q26 | AE1: 2026 | AF1: 1Q27 | AG1: 2Q27 | AH1: 3Q27 | AI1: 4Q27 | AJ1: 2027 | AK1: 1Q28 | AL1: 2Q28 | AM1: 3Q28 | AN1: 4Q28 | AO1: 2028
B2: 별도 | D2: fin json(kship_fin.py)
B3: 한신기계공업(별) | C3: UPDATE: 26-10-13 | E3: 1 | F3: 2 | G3: 3 | H3: 4 | I3: 5 | J3: 6 | K3: 7 | L3: 8 | M3: 9 | N3: 10 | O3: 11 | P3: 12 | Q3: 13 | R3: 14 | S3: 15 | T3: 16 | U3: 17 | V3: 18 | W3: 19 | X3: 20 | Y3: 21 | Z3: 22 | AA3: 23 | AB3: 24 | AC3: 25 | AD3: 26 | AE3: 27 | AF3: 28 | AG3: 29 | AH3: 30 | AI3: 31 | AJ3: 32 | AK3: 33 | AL3: 34 | AM3: 35 | AN3: 36 | AO3: 37
B4: Account Code | C4: AccountNAME | E4: 2021.12 | F4: 2021.12A | G4: 2022.03 | H4: 2022.06 | I4: 2022.09 | J4: 2022.12 | K4: 2022.12A | L4: 2023.03 | M4: 2023.06 | N4: 2023.09 | O4: 2023.12 | P4: 2023.12A | Q4: 2024.03 | R4: 2024.06 | S4: 2024.09 | T4: 2024.12 | U4: 2024.12A | V4: 2025.03 | W4: 2025.06 | X4: 2025.09 | Y4: 2025.12 | Z4: 2025.12A | AA4: 2026.03 | AB4: 2026.06 | AC4: 2026.09 | AD4: 2026.12 | AE4: 2026.12A | AF4: 2027.03 | AG4: 2027.06 | AH4: 2027.09 | AI4: 2027.12 | AJ4: 2027.12A | AK4: 2028.03 | AL4: 2028.06 | AM4: 2028.09 | AN4: 2028.12 | AO4: 2028.12A
A5: 1 | C5: 유동자산 | E5: 67206.22 | F5: 67206.22 | G5: 64955.68 | H5: 70108.03 | I5: 74855.82 | J5: 65515.27 | K5: 65515.27 | L5: 79412.51 | M5: 72457.97 | N5: 73862.41 | O5: 64828.34 | P5: 64828.34 | Q5: 65532.06 | R5: 68544.4 | S5: 75142.01 | T5: 72257.26 | U5: 72257.26 | V5: 61864.77 | W5: 58766.39 | X5: 58402.47 | Y5: 53948.4 | Z5: 53948.4 | AA5: 49124 | AB5: 54246.57
A6: 1 | C6: 현금및현금성자산 | E6: 9660.35 | F6: 9660.35 | G6: 7502.48 | H6: 8372.32 | I6: 18444.47 | J6: 15007.4 | K6: 15007.4 | L6: 16457.63 | M6: 10077.81 | N6: 7601.12 | O6: 7996.36 | P6: 7996.36 | Q6: 6378.78 | R6: 16493.77 | S6: 19504.4 | T6: 31383.67 | U6: 31383.67 | V6: 20073.74 | W6: 16609.6 | X6: 11034 | Y6: 15452.46 | Z6: 15452.46 | AA6: 9257.89 | AB6: 6649.77
A7: 1 | C7: 단기금융상품 | E7: 6.42 | F7: 6.42 | G7: 6.77 | H7: 5.37 | I7: 5.82 | J7: 6.27 | K7: 6.27 | L7: 6.27 | M7: 13.16 | N7: 13.16 | O7: 16.77 | P7: 16.77 | Q7: 14.04 | R7: 4.37 | S7: 3.4 | T7: 3.55 | U7: 3.55 | V7: 3.65 | W7: 3.65 | X7: 3.65 | Y7: 3.65 | Z7: 3.65 | AA7: 3.65 | AB7: 7.95
A8: 1 | C8: 단기금융자산 | E8: 3234.18 | F8: 3234.18 | G8: 2040.89 | H8: 7537.72 | I8: 22.04 | J8: 6.27 | K8: 6.27 | L8: 3508.52 | M8: 4340.31 | N8: 13.16 | O8: 16.77 | P8: 16.77 | Q8: 14.04 | R8: 4.37 | S8: 3.4 | T8: 3127.75 | U8: 3127.75 | V8: 2946.05 | W8: 2286.49 | X8: 1157.49 | Y8: 914.14 | Z8: 914.14 | AA8: 353.2 | AB8: 1007.61
A9: 1 | C9: 단기투자자산(공정가치) | E9: 10219.93 | F9: 10219.93 | G9: 10871.41 | H9: 9295.81 | I9: 9581.51 | J9: 9246.79 | K9: 9246.79 | L9: 9831.62 | M9: 10620.17 | N9: 10383.19 | O9: 21056.56 | P9: 21056.56 | Q9: 23676.22 | R9: 14045.48 | S9: 15216.76 | T9: 526.25 | U9: 526.25 | V9: 4374.12 | W9: 7021.18 | X9: 9034.77 | Y9: 4439.93 | Z9: 4439.93 | AA9: 7693.21 | AB9: 10437.67
A10: 1 | C10: 매출채권및기타채권 | E10: 29826.94 | F10: 29826.94 | G10: 26603.7 | H10: 27490.9 | I10: 28660.96 | J10: 25860.04 | K10: 25860.04 | L10: 30722.17 | M10: 29774.47 | N10: 30375.24 | O10: 22078.23 | P10: 22078.23 | Q10: 21329.5 | R10: 21107.77 | S10: 22454.2 | T10: 24495.8 | U10: 24495.8 | V10: 18665.93 | W10: 17971.77 | X10: 19855.61 | Y10: 20803.23 | Z10: 20803.23 | AA10: 16847.48 | AB10: 17790.61
A11: 1 | C11: 재고자산 | E11: 13343.8 | F11: 13343.8 | G11: 16142.92 | H11: 15730.32 | I11: 16121.53 | J11: 10282.62 | K11: 10282.62 | L11: 16326.05 | M11: 15609.36 | N11: 17494.75 | O11: 10964.95 | P11: 10964.95 | Q11: 11529.15 | R11: 15242.38 | S11: 15215.46 | T11: 10952.44 | U11: 10952.44 | V11: 13458.86 | W11: 12491.89 | X11: 14687.48 | Y11: 10608.71 | Z11: 10608.71 | AA11: 13091.05 | AB11: 15406
A12: 1 | C12: 기타유동자산 | E12: 921.02 | F12: 921.02 | G12: 1794.28 | H12: 1680.95 | I12: 2025.31 | J12: 1609.9 | K12: 1609.9 | L12: 2544.26 | M12: 2035.85 | N12: 1805.82 | O12: 2426.66 | P12: 2426.66 | Q12: 2190.48 | R12: 1391.3 | S12: 2466.75 | T12: 1528.43 | U12: 1528.43 | V12: 818.24 | W12: 837.8 | X12: 1069.99 | Y12: 1729.94 | Z12: 1729.94 | AA12: 1865.2 | AB12: 2148.33
A13: 1 | C13: 비유동자산 | E13: 34382.87 | F13: 34382.87 | G13: 34126.5 | H13: 43512.49 | I13: 43414.55 | J13: 47680.59 | K13: 47680.59 | L13: 46138.47 | M13: 45796.91 | N13: 46741.88 | O13: 46996.94 | P13: 46996.94 | Q13: 47596.1 | R13: 48229.75 | S13: 47788.06 | T13: 48888.79 | U13: 48888.79 | V13: 51030.52 | W13: 51782.17 | X13: 57266.16 | Y13: 55992.34 | Z13: 55992.34 | AA13: 56367.92 | AB13: 54825.77
A14: 1 | C14: 장기금융자산 | E14: 16.25 | F14: 16.25 | G14: 15.41 | H14: 16.16 | I14: 17.06 | J14: 17.96 | K14: 17.96 | L14: 19.16 | M14: 7.93 | N14: 8.98 | O14: 5.3 | P14: 5.3 | Q14: 8.83 | R14: 9.55 | S14: 10 | T14: 10.45 | U14: 10.45 | V14: 10.9 | W14: 111.35 | X14: 111.8 | Y14: 112.25 | Z14: 112.25 | AA14: 112.7 | AB14: 3900.08
A15: 1 | C15: 투자자산 | E15: 4770.28 | F15: 4770.28 | G15: 4769.44 | H15: 4770.19 | I15: 4771.09 | J15: 4867.7 | K15: 4867.7 | L15: 4868.9 | M15: 5107.67 | N15: 5108.72 | O15: 4855.04 | P15: 4855.04 | Q15: 4858.57 | R15: 5119.29 | S15: 5119.74 | T15: 1311.36 | U15: 1311.36 | V15: 1311.81 | W15: 1412.26 | X15: 6539.59 | Y15: 6540.04 | Z15: 6540.04 | AA15: 6540.49 | AB15: 10327.87
A16: 1 | C16: 장기매출채권및기타채권 | E16: 532.65 | F16: 532.65 | G16: 594.05 | H16: 613.23 | I16: 625.8 | L16: 1481.28 | M16: 1495.64 | N16: 1465.19 | AB16: 4165.23
A17: 1 | C17: 종속기업및관계기업투자 | E17: 4754.03 | F17: 4754.03 | G17: 4754.03 | H17: 4754.03 | I17: 4754.03 | J17: 4849.74 | K17: 4849.74 | L17: 4849.74 | M17: 5099.74 | N17: 5099.74 | O17: 4849.74 | P17: 4849.74 | Q17: 4849.74 | R17: 5109.74 | S17: 5109.74 | T17: 1300.91 | U17: 1300.91 | V17: 1300.91 | W17: 1300.91 | X17: 6427.79 | Y17: 6427.79 | Z17: 6427.79 | AA17: 6427.79 | AB17: 6427.79
A18: 1 | C18: 투자부동산 | E18: 4093.44 | F18: 4093.44 | G18: 4070.09 | H18: 13742.86 | I18: 13709.75 | J18: 13676.64 | K18: 13676.64 | L18: 13646.79 | M18: 13580.22 | N18: 13585.58 | O18: 13544.21 | P18: 13544.21 | Q18: 13509.81 | R18: 13476.54 | S18: 13442.8 | T18: 13442.8 | U18: 13442.8 | V18: 13409.69 | W18: 13809.16 | X18: 13774.7 | Y18: 13740.23 | Z18: 13740.23 | AA18: 14810.47 | AB18: 14769.14
A19: 1 | C19: 유형자산 | E19: 24105.27 | F19: 24105.27 | G19: 24017.61 | H19: 23926.35 | I19: 23854.93 | J19: 23389.4 | K19: 23389.4 | L19: 23357.63 | M19: 23274.66 | N19: 24387.81 | O19: 24162.89 | P19: 24162.89 | Q19: 24410.27 | R19: 24702.15 | S19: 24614.45 | T19: 24374.69 | U19: 24374.69 | V19: 24282.16 | W19: 24288.55 | X19: 24659.29 | Y19: 25093.06 | Z19: 25093.06 | AA19: 24183.81 | AB19: 24063.65
A20: 1 | C20: 무형자산 | E20: 425.26 | F20: 425.26 | G20: 453.36 | H20: 459.87 | I20: 452.99 | L20: 831.27 | M20: 780.37 | R20: 671.27 | AB20: 520.63
A21: 1 | C21: 자산총계 | E21: 101589.09 | F21: 101589.09 | G21: 99082.18 | H21: 113620.52 | I21: 118270.37 | J21: 113195.86 | K21: 113195.86 | L21: 125550.98 | M21: 118254.88 | N21: 120604.3 | O21: 111825.27 | P21: 111825.27 | Q21: 113128.16 | R21: 116774.15 | S21: 122930.07 | T21: 121146.05 | U21: 121146.05 | V21: 112895.29 | W21: 110548.57 | X21: 115668.62 | Y21: 109940.73 | Z21: 109940.73 | AA21: 105491.92 | AB21: 109072.34
A22: 1 | C22: 유동부채 | E22: 11392.97 | F22: 11392.97 | G22: 10204.6 | H22: 12366.13 | I22: 16031.01 | J22: 20913.27 | K22: 20913.27 | L22: 26879.2 | M22: 21758.13 | N22: 22119.12 | O22: 15007.08 | P22: 15007.08 | Q22: 19800.29 | R22: 19412.01 | S22: 23970.95 | T22: 26742.11 | U22: 26742.11 | V22: 18585.49 | W22: 15698.97 | X22: 18371.65 | Y22: 16310.74 | Z22: 16310.74 | AA22: 13983.3 | AB22: 15079.7
A23: 1 | C23: 매입채무및기타채무 | E23: 8477.91 | F23: 8477.91 | G23: 7408.29 | H23: 6861.55 | I23: 7390 | J23: 8715.63 | K23: 8715.63 | L23: 13507.88 | M23: 7940.77 | N23: 14492.12 | O23: 7189.96 | P23: 7189.96 | Q23: 7124 | R23: 5885.66 | S23: 8986.97 | T23: 8674.68 | U23: 8674.68 | V23: 6016.03 | W23: 6291.4 | X23: 6723.15 | Y23: 8037.99 | Z23: 8037.99 | AA23: 5195.24 | AB23: 6955.43
A24: 1 | C24: 단기차입금 | E24: 230.28 | F24: 230.28 | G24: 280.63 | H24: 384.69 | I24: 3270.05 | J24: 6641.54 | K24: 6641.54 | L24: 6640.13 | M24: 9684.67 | N24: 1040.46 | O24: 6127.72 | P24: 6127.72 | Q24: 8051.85 | R24: 7643.49 | S24: 7758.59 | T24: 11350.08 | U24: 11350.08 | V24: 8967.05 | W24: 7638.32 | X24: 8913.31 | Y24: 6573.36 | Z24: 6573.36 | AA24: 7191.04 | AB24: 6310.07
A25: 1 | C25: 당기법인세부채(미지급법인세) | E25: 891.71 | F25: 891.71 | G25: 500.39 | H25: 2497.93 | I25: 3130.47 | J25: 2361.95 | K25: 2361.95 | L25: 1319.03 | M25: 0 | N25: 0 | O25: 0 | P25: 0 | T25: 2851.01 | U25: 2851.01 | V25: 687.02 | W25: 0 | X25: 0 | Y25: 437.65 | Z25: 437.65 | AA25: 265.87 | AB25: 448.98
A26: 1 | C26: 기타유동부채 | E26: 1793.07 | F26: 1793.07 | G26: 2015.28 | H26: 2621.96 | I26: 2240.49 | J26: 3194.14 | K26: 3194.14 | L26: 5412.16 | M26: 4132.68 | N26: 6586.54 | O26: 1689.4 | P26: 1689.4 | Q26: 4624.44 | R26: 5882.86 | S26: 7225.4 | T26: 474.8 | U26: 474.8 | V26: 502.56 | W26: 505.53 | X26: 739.68 | Y26: 967.29 | Z26: 967.29 | AA26: 553.64 | AB26: 461.92
A27: 1 | C27: 비유동부채 | E27: 1409.68 | F27: 1409.68 | G27: 1394.98 | H27: 2024.77 | I27: 2288.23 | J27: 838.66 | K27: 838.66 | L27: 853.11 | M27: 834.21 | N27: 834.21 | O27: 775.84 | P27: 775.84 | Q27: 590.84 | R27: 1750.7 | S27: 1690.76 | T27: 1687.62 | U27: 1687.62 | V27: 1899.61 | W27: 2073.23 | X27: 2233.63 | Y27: 1430.27 | Z27: 1430.27 | AA27: 1593.34 | AB27: 1723.64
A28: 1 | C28: 장기매입채무및기타채무 | E28: 582.4 | F28: 582.4 | G28: 572.9 | H28: 811.77 | I28: 823.95 | J28: 830.46 | K28: 830.46 | L28: 830.46 | M28: 830.46 | N28: 830.46 | O28: 729.96 | P28: 729.96 | Q28: 544.96 | R28: 1157.08 | S28: 1097.14 | T28: 1089.88 | U28: 1089.88 | V28: 1090.95 | W28: 1092.02 | X28: 976.09 | Y28: 961.72 | Z28: 961.72 | AA28: 953.45 | AB28: 954.69
A29: 1 | C29: 확정급여부채 | E29: 0 | F29: 0 | G29: 0 | H29: 27.67 | I29: 279.07 | J29: 0 | K29: 0 | L29: 14.46 | M29: 0 | N29: 0 | T29: 576.25 | U29: 576.25 | V29: 787.17 | W29: 971.68 | X29: 1117.91 | Y29: 281.07 | Z29: 281.07 | AA29: 471.21 | AB29: 621.13
A30: 1 | C30: 이연법인세부채 | E30: 803.23 | F30: 803.23 | G30: 803.23 | H30: 1171.72 | I30: 1171.72 | J30: 0 | K30: 0 | L30: 0 | M30: 0 | N30: 0 | O30: 0 | P30: 0 | R30: 547.75 | S30: 547.75
A31: 1 | C31: 기타비유동부채 | E31: 24.05 | F31: 24.05 | G31: 18.85 | H31: 13.61 | I31: 13.49 | J31: 8.2 | K31: 8.2 | L31: 8.2 | M31: 3.75 | N31: 3.75 | O31: 45.87 | P31: 45.87 | Q31: 45.87 | R31: 45.87 | S31: 45.87 | T31: 21.49 | U31: 21.49 | V31: 21.49 | W31: 9.53 | X31: 139.62 | Y31: 187.48 | Z31: 187.48 | AA31: 168.68 | AB31: 147.83
A32: 1 | C32: 부채총계 | E32: 12802.65 | F32: 12802.65 | G32: 11599.57 | H32: 14390.9 | I32: 18319.24 | J32: 21751.92 | K32: 21751.92 | L32: 27732.31 | M32: 22592.34 | N32: 22953.33 | O32: 15782.91 | P32: 15782.91 | Q32: 20391.13 | R32: 21162.71 | S32: 25661.71 | T32: 28429.74 | U32: 28429.74 | V32: 20485.1 | W32: 17772.2 | X32: 20605.28 | Y32: 17741.01 | Z32: 17741.01 | AA32: 15576.64 | AB32: 16803.34
A33: 1 | C33: 자본금 | E33: 16223.08 | F33: 16223.08 | G33: 16223.08 | H33: 16223.08 | I33: 16223.08 | J33: 16223.08 | K33: 16223.08 | L33: 16223.08 | M33: 16223.08 | N33: 16223.08 | O33: 16223.08 | P33: 16223.08 | Q33: 16223.08 | R33: 16223.08 | S33: 16223.08 | T33: 16223.08 | U33: 16223.08 | V33: 16223.08 | W33: 16223.08 | X33: 16223.08 | Y33: 16223.08 | Z33: 16223.08 | AA33: 16223.08 | AB33: 16223.08
A34: 1 | C34: 자본잉여금 | E34: 8439.1 | F34: 8439.1 | G34: 8439.1 | H34: 19275.7 | I34: 19275.7 | J34: 19275.7 | K34: 19275.7 | L34: 19275.7 | M34: 19275.7 | N34: 19275.7 | O34: 19275.7 | P34: 19275.7 | Q34: 19275.7 | R34: 19275.7 | S34: 19275.7 | T34: 19275.7 | U34: 19275.7 | V34: 19275.7 | W34: 19275.7 | X34: 19275.7 | Y34: 19275.7 | Z34: 19275.7 | AA34: 19275.7 | AB34: 19275.7
A35: 1 | C35: 기타자본 | E35: -739.12 | F35: -739.12 | G35: -713.36 | H35: 885.23 | I35: 911.56 | J35: 937.9 | K35: 937.9 | L35: 963.66 | M35: 963.09 | N35: 963.09 | O35: 963.09 | P35: 963.09 | Q35: 963.09 | R35: 963.09 | S35: 963.09 | T35: 963.09 | U35: 963.09 | V35: 963.09 | W35: 963.09 | X35: 963.09 | Y35: 963.09 | Z35: 963.09 | AA35: 963.09 | AB35: 963.09
A36: 1 | C36: 이익잉여금 | E36: 64863.38 | F36: 64863.38 | G36: 63533.79 | H36: 62845.61 | I36: 63540.79 | J36: 55007.26 | K36: 55007.26 | L36: 61356.23 | M36: 59200.68 | N36: 61189.1 | O36: 59580.49 | P36: 59580.49 | Q36: 56275.17 | R36: 59149.57 | S36: 60806.49 | T36: 56254.45 | U36: 56254.45 | V36: 55948.33 | W36: 56314.5 | X36: 58601.48 | Y36: 56061.67 | Z36: 56061.67 | AA36: 54090.54 | AB36: 56535.91
A37: 1 | C37: 자본총계 | E37: 88786.44 | F37: 88786.44 | G37: 87482.61 | H37: 99229.62 | I37: 99951.13 | J37: 91443.93 | K37: 91443.93 | L37: 97818.67 | M37: 95662.55 | N37: 97650.97 | O37: 96042.36 | P37: 96042.36 | Q37: 92737.03 | R37: 95611.44 | S37: 97268.35 | T37: 92716.31 | U37: 92716.31 | V37: 92410.19 | W37: 92776.36 | X37: 95063.35 | Y37: 92199.73 | Z37: 92199.73 | AA37: 89915.28 | AB37: 92269
A38: 1 | C38: 부채와자본총계 | E38: 101589.09 | F38: 101589.09 | G38: 99082.18 | H38: 113620.52 | I38: 118270.37 | J38: 113195.86 | K38: 113195.86 | L38: 125550.98 | M38: 118254.88 | N38: 120604.3 | O38: 111825.27 | P38: 111825.27 | Q38: 113128.16 | R38: 116774.15 | S38: 122930.07 | T38: 121146.05 | U38: 121146.05 | V38: 112895.29 | W38: 110548.57 | X38: 115668.62 | Y38: 109940.73 | Z38: 109940.73 | AA38: 105491.92 | AB38: 109072.34
A39: 1 | C39: 지배주주지분 | E39: 88786.44 | F39: 88786.44 | G39: 87482.61 | H39: 99229.62 | I39: 99951.13 | J39: 91443.93 | K39: 91443.93 | L39: 97818.67 | M39: 95662.55 | N39: 97650.97 | O39: 96042.36 | P39: 96042.36 | Q39: 92737.03 | R39: 95611.44 | S39: 97268.35 | T39: 92716.31 | U39: 92716.31 | V39: 92410.19 | W39: 92776.36 | X39: 95063.35 | Y39: 92199.73 | Z39: 92199.73 | AA39: 89915.28 | AB39: 92269
A40: 1 | C40: 총차입금 | E40: 230.28 | F40: 230.28 | G40: 280.63 | H40: 384.69 | I40: 3270.05 | J40: 6641.54 | K40: 6641.54 | L40: 7470.59 | M40: 9684.67 | N40: 1040.46 | O40: 6127.72 | P40: 6127.72 | Q40: 8051.85 | R40: 7643.49 | S40: 7758.59 | T40: 11350.08 | U40: 11350.08 | V40: 8967.05 | W40: 7638.32 | X40: 8913.31 | Y40: 6573.36 | Z40: 6573.36 | AA40: 7191.04 | AB40: 6310.07
...

Sheet subQ
A1: YQ | C1: subQ 분기 서브모델(억원, U=100) | E1: 4Q21 | F1: 2021 | G1: 1Q22 | H1: 2Q22 | I1: 3Q22 | J1: 4Q22 | K1: 2022 | L1: 1Q23 | M1: 2Q23 | N1: 3Q23 | O1: 4Q23 | P1: 2023 | Q1: 1Q24 | R1: 2Q24 | S1: 3Q24 | T1: 4Q24 | U1: 2024 | V1: 1Q25 | W1: 2Q25 | X1: 3Q25 | Y1: 4Q25 | Z1: 2025 | AA1: 1Q26 | AB1: 2Q26 | AC1: 3Q26 | AD1: 4Q26 | AE1: 2026 | AF1: 1Q27 | AG1: 2Q27 | AH1: 3Q27 | AI1: 4Q27 | AJ1: 2027 | AK1: 1Q28 | AL1: 2Q28 | AM1: 3Q28 | AN1: 4Q28 | AO1: 2028
A2: A=이름(key) B=그룹 C=단위 D=FnGuide 계정명(VLOOKUP 키). 확정=VLOOKUP(BS), 추정=변수 가정 참조
E3: 1 | F3: 2 | G3: 3 | H3: 4 | I3: 5 | J3: 6 | K3: 7 | L3: 8 | M3: 9 | N3: 10 | O3: 11 | P3: 12 | Q3: 13 | R3: 14 | S3: 15 | T3: 16 | U3: 17 | V3: 18 | W3: 19 | X3: 20 | Y3: 21 | Z3: 22 | AA3: 23 | AB3: 24 | AC3: 25 | AD3: 26 | AE3: 27 | AF3: 28 | AG3: 29 | AH3: 30 | AI3: 31 | AJ3: 32 | AK3: 33 | AL3: 34 | AM3: 35 | AN3: 36 | AO3: 37
E4: 2021.12 | F4: 2021.12A | G4: 2022.03 | H4: 2022.06 | I4: 2022.09 | J4: 2022.12 | K4: 2022.12A | L4: 2023.03 | M4: 2023.06 | N4: 2023.09 | O4: 2023.12 | P4: 2023.12A | Q4: 2024.03 | R4: 2024.06 | S4: 2024.09 | T4: 2024.12 | U4: 2024.12A | V4: 2025.03 | W4: 2025.06 | X4: 2025.09 | Y4: 2025.12 | Z4: 2025.12A | AA4: 2026.03 | AB4: 2026.06 | AC4: 2026.09 | AD4: 2026.12 | AE4: 2026.12A | AF4: 2027.03 | AG4: 2027.06 | AH4: 2027.09 | AI4: 2027.12 | AJ4: 2027.12A | AK4: 2028.03 | AL4: 2028.06 | AM4: 2028.09 | AN4: 2028.12 | AO4: 2028.12A
A5: 매출액 | B5: 손익 | C5: 억원 | D5: 매출액(수익) | E5: =IFERROR(VLOOKUP($D5,BS연결,MATCH(E$1,BS연결H,0),0)/100,"") | G5: =IFERROR(VLOOKUP($D5,BS연결,MATCH(G$1,BS연결H,0),0)/100,"") | H5: =IFERROR(VLOOKUP($D5,BS연결,MATCH(H$1,BS연결H,0),0)/100,"") | I5: =IFERROR(VLOOKUP($D5,BS연결,MATCH(I$1,BS연결H,0),0)/100,"") | J5: =IFERROR(VLOOKUP($D5,BS연결,MATCH(J$1,BS연결H,0),0)/100,"") | K5: =IFERROR(VLOOKUP($D5,BS연결,MATCH(K$1,BS연결H,0),0)/100,"") | L5: =IFERROR(VLOOKUP($D5,BS연결,MATCH(L$1,BS연결H,0),0)/100,"") | M5: =IFERROR(VLOOKUP($D5,BS연결,MATCH(M$1,BS연결H,0),0)/100,"") | N5: =IFERROR(VLOOKUP($D5,BS연결,MATCH(N$1,BS연결H,0),0)/100,"") | ... AB5: =IFERROR(VLOOKUP($D5,BS연결,MATCH(AB$1,BS연결H,0),0)/100,"") | AC5: =IFERROR(X5*(1+변수!AC21),"") | AD5: =IFERROR(Y5*(1+변수!AD21),"") | AE5: =SUM(AA5:AD5) | AF5: =IFERROR(AA5*(1+변수!AF21),"") | AG5: =IFERROR(AB5*(1+변수!AG21),"") | AH5: =IFERROR(AC5*(1+변수!AH21),"") | AI5: =IFERROR(AD5*(1+변수!AI21),"") | AJ5: =SUM(AF5:AI5) | AK5: =IFERROR(AF5*(1+변수!AK21),"") | AL5: =IFERROR(AG5*(1+변수!AL21),"") | AM5: =IFERROR(AH5*(1+변수!AM21),"") | AN5: =IFERROR(AI5*(1+변수!AN21),"") | AO5: =SUM(AK5:AN5)
A6: 매출원가 | B6: 손익 | C6: 억원 | D6: 매출원가 | E6: =IFERROR(VLOOKUP($D6,BS연결,MATCH(E$1,BS연결H,0),0)/100,"") | G6: =IFERROR(VLOOKUP($D6,BS연결,MATCH(G$1,BS연결H,0),0)/100,"") | H6: =IFERROR(VLOOKUP($D6,BS연결,MATCH(H$1,BS연결H,0),0)/100,"") | I6: =IFERROR(VLOOKUP($D6,BS연결,MATCH(I$1,BS연결H,0),0)/100,"") | J6: =IFERROR(VLOOKUP($D6,BS연결,MATCH(J$1,BS연결H,0),0)/100,"") | K6: =IFERROR(VLOOKUP($D6,BS연결,MATCH(K$1,BS연결H,0),0)/100,"") | L6: =IFERROR(VLOOKUP($D6,BS연결,MATCH(L$1,BS연결H,0),0)/100,"") | M6: =IFERROR(VLOOKUP($D6,BS연결,MATCH(M$1,BS연결H,0),0)/100,"") | N6: =IFERROR(VLOOKUP($D6,BS연결,MATCH(N$1,BS연결H,0),0)/100,"") | ... AB6: =IFERROR(VLOOKUP($D6,BS연결,MATCH(AB$1,BS연결H,0),0)/100,"") | AC6: =IFERROR(AC5-AC7,"") | AD6: =IFERROR(AD5-AD7,"") | AE6: =SUM(AA6:AD6) | AF6: =IFERROR(AF5-AF7,"") | AG6: =IFERROR(AG5-AG7,"") | AH6: =IFERROR(AH5-AH7,"") | AI6: =IFERROR(AI5-AI7,"") | AJ6: =SUM(AF6:AI6) | AK6: =IFERROR(AK5-AK7,"") | AL6: =IFERROR(AL5-AL7,"") | AM6: =IFERROR(AM5-AM7,"") | AN6: =IFERROR(AN5-AN7,"") | AO6: =SUM(AK6:AN6)
A7: 매출총이익 | B7: 손익 | C7: 억원 | D7: 매출총이익 | E7: =IFERROR(VLOOKUP($D7,BS연결,MATCH(E$1,BS연결H,0),0)/100,"") | G7: =IFERROR(VLOOKUP($D7,BS연결,MATCH(G$1,BS연결H,0),0)/100,"") | H7: =IFERROR(VLOOKUP($D7,BS연결,MATCH(H$1,BS연결H,0),0)/100,"") | I7: =IFERROR(VLOOKUP($D7,BS연결,MATCH(I$1,BS연결H,0),0)/100,"") | J7: =IFERROR(VLOOKUP($D7,BS연결,MATCH(J$1,BS연결H,0),0)/100,"") | K7: =SUM(G7:J7) | L7: =IFERROR(VLOOKUP($D7,BS연결,MATCH(L$1,BS연결H,0),0)/100,"") | M7: =IFERROR(VLOOKUP($D7,BS연결,MATCH(M$1,BS연결H,0),0)/100,"") | N7: =IFERROR(VLOOKUP($D7,BS연결,MATCH(N$1,BS연결H,0),0)/100,"") | O7: =IFERROR(VLOOKUP($D7,BS연결,MATCH(O$1,BS연결H,0),0)/100,"") | P7: =IFERROR(VLOOKUP($D7,BS연결,MATCH(P$1,BS연결H,0),0)/100,"") | Q7: =IFERROR(VLOOKUP($D7,BS연결,MATCH(Q$1,BS연결H,0),0)/100,"") | R7: =IFERROR(VLOOKUP($D7,BS연결,MATCH(R$1,BS연결H,0),0)/100,"") | S7: =IFERROR(VLOOKUP($D7,BS연결,MATCH(S$1,BS연결H,0),0)/100,"") | ... AB7: =IFERROR(VLOOKUP($D7,BS연결,MATCH(AB$1,BS연결H,0),0)/100,"") | AC7: =IFERROR(AC9+AC8,"") | AD7: =IFERROR(AD9+AD8,"") | AE7: =SUM(AA7:AD7) | AF7: =IFERROR(AF9+AF8,"") | AG7: =IFERROR(AG9+AG8,"") | AH7: =IFERROR(AH9+AH8,"") | AI7: =IFERROR(AI9+AI8,"") | AJ7: =SUM(AF7:AI7) | AK7: =IFERROR(AK9+AK8,"") | AL7: =IFERROR(AL9+AL8,"") | AM7: =IFERROR(AM9+AM8,"") | AN7: =IFERROR(AN9+AN8,"") | AO7: =SUM(AK7:AN7)
A8: 판관비 | B8: 손익 | C8: 억원 | D8: 판관비 | E8: =IFERROR(VLOOKUP($D8,BS연결,MATCH(E$1,BS연결H,0),0)/100,"") | G8: =IFERROR(VLOOKUP($D8,BS연결,MATCH(G$1,BS연결H,0),0)/100,"") | H8: =IFERROR(VLOOKUP($D8,BS연결,MATCH(H$1,BS연결H,0),0)/100,"") | I8: =IFERROR(VLOOKUP($D8,BS연결,MATCH(I$1,BS연결H,0),0)/100,"") | J8: =IFERROR(VLOOKUP($D8,BS연결,MATCH(J$1,BS연결H,0),0)/100,"") | K8: =SUM(G8:J8) | L8: =IFERROR(VLOOKUP($D8,BS연결,MATCH(L$1,BS연결H,0),0)/100,"") | M8: =IFERROR(VLOOKUP($D8,BS연결,MATCH(M$1,BS연결H,0),0)/100,"") | N8: =IFERROR(VLOOKUP($D8,BS연결,MATCH(N$1,BS연결H,0),0)/100,"") | O8: =IFERROR(VLOOKUP($D8,BS연결,MATCH(O$1,BS연결H,0),0)/100,"") | P8: =IFERROR(VLOOKUP($D8,BS연결,MATCH(P$1,BS연결H,0),0)/100,"") | Q8: =IFERROR(VLOOKUP($D8,BS연결,MATCH(Q$1,BS연결H,0),0)/100,"") | R8: =IFERROR(VLOOKUP($D8,BS연결,MATCH(R$1,BS연결H,0),0)/100,"") | S8: =IFERROR(VLOOKUP($D8,BS연결,MATCH(S$1,BS연결H,0),0)/100,"") | ... Y8: =IFERROR(VLOOKUP($D8,BS연결,MATCH(Y$1,BS연결H,0),0)/100,"") | Z8: =SUM(V8:Y8) | AA8: =IFERROR(VLOOKUP($D8,BS연결,MATCH(AA$1,BS연결H,0),0)/100,"") | AB8: =IFERROR(VLOOKUP($D8,BS연결,MATCH(AB$1,BS연결H,0),0)/100,"") | AC8: =IFERROR(AC5*변수!AC22,"") | AD8: =IFERROR(AD5*변수!AD22,"") | AE8: =SUM(AA8:AD8) | AF8: =IFERROR(AF5*변수!AF22,"") | AG8: =IFERROR(AG5*변수!AG22,"") | AH8: =IFERROR(AH5*변수!AH22,"") | AI8: =IFERROR(AI5*변수!AI22,"") | AJ8: =SUM(AF8:AI8) | AK8: =IFERROR(AK5*변수!AK22,"") | AL8: =IFERROR(AL5*변수!AL22,"") | AM8: =IFERROR(AM5*변수!AM22,"") | AN8: =IFERROR(AN5*변수!AN22,"") | AO8: =SUM(AK8:AN8)
A9: 영업이익 | B9: 손익 | C9: 억원 | D9: 영업이익 | E9: =IFERROR(VLOOKUP($D9,BS연결,MATCH(E$1,BS연결H,0),0)/100,"") | G9: =IFERROR(VLOOKUP($D9,BS연결,MATCH(G$1,BS연결H,0),0)/100,"") | H9: =IFERROR(VLOOKUP($D9,BS연결,MATCH(H$1,BS연결H,0),0)/100,"") | I9: =IFERROR(VLOOKUP($D9,BS연결,MATCH(I$1,BS연결H,0),0)/100,"") | J9: =IFERROR(VLOOKUP($D9,BS연결,MATCH(J$1,BS연결H,0),0)/100,"") | K9: =IFERROR(VLOOKUP($D9,BS연결,MATCH(K$1,BS연결H,0),0)/100,"") | L9: =IFERROR(VLOOKUP($D9,BS연결,MATCH(L$1,BS연결H,0),0)/100,"") | M9: =IFERROR(VLOOKUP($D9,BS연결,MATCH(M$1,BS연결H,0),0)/100,"") | N9: =IFERROR(VLOOKUP($D9,BS연결,MATCH(N$1,BS연결H,0),0)/100,"") | ... AB9: =IFERROR(VLOOKUP($D9,BS연결,MATCH(AB$1,BS연결H,0),0)/100,"") | AC9: =IFERROR(AC5*변수!AC23,"") | AD9: =IFERROR(AD5*변수!AD23,"") | AE9: =SUM(AA9:AD9) | AF9: =IFERROR(AF5*변수!AF23,"") | AG9: =IFERROR(AG5*변수!AG23,"") | AH9: =IFERROR(AH5*변수!AH23,"") | AI9: =IFERROR(AI5*변수!AI23,"") | AJ9: =SUM(AF9:AI9) | AK9: =IFERROR(AK5*변수!AK23,"") | AL9: =IFERROR(AL5*변수!AL23,"") | AM9: =IFERROR(AM5*변수!AM23,"") | AN9: =IFERROR(AN5*변수!AN23,"") | AO9: =SUM(AK9:AN9)
A10: OPM | B10: 손익 | C10: % | D10: 영업이익률 | E10: =IFERROR(E9/E5,"") | G10: =IFERROR(G9/G5,"") | H10: =IFERROR(H9/H5,"") | I10: =IFERROR(I9/I5,"") | J10: =IFERROR(J9/J5,"") | K10: =IFERROR(K9/K5,"") | L10: =IFERROR(L9/L5,"") | M10: =IFERROR(M9/M5,"") | N10: =IFERROR(N9/N5,"") | ... AO10: =IFERROR(AO9/AO5,"")
