Workbook
Name 변수H: 변수!$C$1:$AO$1
Name 환율: 변수!$C$6:$AO$13
Name BS연결H: BS연결!$C$1:$AO$1
Name BS연결: BS연결!$C$5:$AO$118
Name BS별도H: BS별도!$C$1:$AO$1
Name BS별도: BS별도!$C$5:$AO$95
Name SUBQH: subQ!$A$1:$AO$1
Name subQ: subQ!$A$5:$AO$45

Sheet README
A1: 영흥(012160) 실적 모델 — ARGUS 한국조선
A2: 기준 분기 2026Q2 · 마지막 실적 2026Q2 · 생성 2026-10-19
A3: 모든 수치는 모델 산출값(DART 공개 재무제표 + 우리 추정)이다 — 목표주가·투자 추천 아님. 참고용 · 투자조언 아님.
A5: 시트
A6: 변수 가정 시계열. 환율 8행(ECB via frankfurter — L2 fx.json; 추정 분기 = 노란 가정), 추정 드라이버(노란 셀 = 모델값에서 역산한 가정, 바꾸면 재계산; 연녹 셀 = 3절 스칼라 참조 수식), 3절 스칼라 가정(세율·판관비율·지배주주비중·이자율·종가·PER 밴드·COE·외화 순노출·헤지비율)
A7: BS연결/BS별도 FnGuide 계정명 × 기간 값 덤프(백만원). 행1 분기라벨, 행4 YYYY.MM / YYYY.12A. 이름정의 BS연결H·BS연결(계정명 C열부터)
A8: subQ 분기 서브모델(억원 = 백만원/100). 확정 행: =IFERROR(VLOOKUP($D행,BS연결,MATCH(E$1,BS연결H,0),0)/100,"") 추정 행: 변수 시트 가정 셀 참조 수식. 외환손익·파생상품손익은 BS 계정 합·차, 기타금융손익은 잔차, OPM·EPS·BPS·PER·PBR 은 파생 수식, 조정EPS 는 EPS 참조(일회성 의심 분기만 산식 셀)
A9: SLS 선표(조선사만, sls json 있을 때): 요약 행(sls 저장값) + 계약별 스케줄(백만$) × (헤지비율 × 헤지환율 + (1−헤지비율) × 건조시점 환율[변수 원/달러(평균)]) → 원화 수식 블록 → 합계 행이 subQ 매출조선에 연결
A10: 시나리오 신규수주 보수/기준/낙관(forecast_panel 패널, 모델에 scenarios 가 있을 때만): 매출액·영업이익 = subQ 기준값 ± (시나리오 신규 − base 신규) × OPM. base 만 subQ 행에 포함, 나머지는 합산 안 함
A11: 분기/연간예상 subQ 를 이름(A열 key)으로 VLOOKUP 한 보고서 표(억원)
A12: TP PER 밴드 × 12M fwd EPS, PBR = ROE/COE × BPS — 모델 산출값 구간, 목표주가·추천 아님
A13: 외화 환율 QoQ, 외화 순노출 × Δ기말환율 → 환관련손익 추정
... A35: 백테스트: {"freeze": "2025Q2", "horizon": 4, "revenue_wape_pct": 2.5, "op_wape_pct": 86.5, "n": 4, "note": "단일 회사 4분기 — 통계 아님", "driver_at_freeze": "trend_seasonal", "selection_oos_at_freeze": null, "frozen_inputs": "fin(연결/별도)·고객 조선사 모델·지주 자회사 모델은 2025Q2 까지의 분기만; 선표는 체결일 ≤ 2025Q2 말일 계약(원장 최신 금액·코호트 등급, 환산 없음); 잔고는 yards_cache 2025Q2; 시세·환율 forward·prices·forecast_panel 신규수주 미사용. 고객 가중치(suppliers.json 언급 비중)와 합병 체인링크는 현재 지식; 고객 연동 채택은 동결 모델 안에서도 자기 la−4분기 OOS 규칙(selection_oos_at_freeze)", "detail": [{"q": "2025Q3", "rev_pred": 1092.86, "rev_act": 1098.95, "op_pred": -9.26, "op_act": -69.66}, {"q": "2025Q4", "rev_pred": 1004.22, "rev_act": 963.22, "op_pred": -8.51, "op_act": -22.38}, {"q": "2026Q1", "rev_pred": 1019.23, "rev_act": 964.25, "op_pred": -8.63, "op_act": -14.39}, {"q": "2026Q2", "rev_pred": 1067.88, "rev_act": 1067.67, "op_pred": -9.05, "op_act": 21.74}]}

Sheet 변수
C1: 이름: 변수H | E1: 4Q21 | F1: 2021 | G1: 1Q22 | H1: 2Q22 | I1: 3Q22 | J1: 4Q22 | K1: 2022 | L1: 1Q23 | M1: 2Q23 | N1: 3Q23 | O1: 4Q23 | P1: 2023 | Q1: 1Q24 | R1: 2Q24 | S1: 3Q24 | T1: 4Q24 | U1: 2024 | V1: 1Q25 | W1: 2Q25 | X1: 3Q25 | Y1: 4Q25 | Z1: 2025 | AA1: 1Q26 | AB1: 2Q26 | AC1: 3Q26 | AD1: 4Q26 | AE1: 2026 | AF1: 1Q27 | AG1: 2Q27 | AH1: 3Q27 | AI1: 4Q27 | AJ1: 2027 | AK1: 1Q28 | AL1: 2Q28 | AM1: 3Q28 | AN1: 4Q28 | AO1: 2028
A2: 가정 시계열 — 노란 셀은 추정 가정(모델값에서 역산), 연녹 셀은 3절 스칼라 참조 수식. 바꾸면 subQ·분기·연간예상·TP·시나리오가 재계산됩니다.
E3: 1 | F3: 2 | G3: 3 | H3: 4 | I3: 5 | J3: 6 | K3: 7 | L3: 8 | M3: 9 | N3: 10 | O3: 11 | P3: 12 | Q3: 13 | R3: 14 | S3: 15 | T3: 16 | U3: 17 | V3: 18 | W3: 19 | X3: 20 | Y3: 21 | Z3: 22 | AA3: 23 | AB3: 24 | AC3: 25 | AD3: 26 | AE3: 27 | AF3: 28 | AG3: 29 | AH3: 30 | AI3: 31 | AJ3: 32 | AK3: 33 | AL3: 34 | AM3: 35 | AN3: 36 | AO3: 37
E4: 2021.12 | F4: 2021.12A | G4: 2022.03 | H4: 2022.06 | I4: 2022.09 | J4: 2022.12 | K4: 2022.12A | L4: 2023.03 | M4: 2023.06 | N4: 2023.09 | O4: 2023.12 | P4: 2023.12A | Q4: 2024.03 | R4: 2024.06 | S4: 2024.09 | T4: 2024.12 | U4: 2024.12A | V4: 2025.03 | W4: 2025.06 | X4: 2025.09 | Y4: 2025.12 | Z4: 2025.12A | AA4: 2026.03 | AB4: 2026.06 | AC4: 2026.09 | AD4: 2026.12 | AE4: 2026.12A | AF4: 2027.03 | AG4: 2027.06 | AH4: 2027.09 | AI4: 2027.12 | AJ4: 2027.12A | AK4: 2028.03 | AL4: 2028.06 | AM4: 2028.09 | AN4: 2028.12 | AO4: 2028.12A
B5: 1. FX | C5: 이름: 환율
A6: USDKRW_avg | C6: 원/달러(평균) | E6: 1183.5 | F6: 1145.51 | G6: 1205.78 | H6: 1262.09 | I6: 1341.93 | J6: 1360.12 | K6: 1292.98 | L6: 1276.95 | M6: 1315.69 | N6: 1313.62 | O6: 1322.01 | P6: 1306.85 | Q6: 1330.14 | R6: 1371.28 | S6: 1356.22 | T6: 1396.3 | U6: 1363.53 | V6: 1452.28 | W6: 1398.52 | X6: 1386.95 | Y6: 1449.19 | Z6: 1421.52 | AA6: 1466.12 | AB6: 1501.75 | AC6: 1418.75 | AD6: 1342.11 | AE6: 1454.27 | AF6: 1332.1 | AG6: 1332.1 | AH6: 1332.1 | AI6: 1332.1 | AK6: 1332.1 | AL6: 1332.1 | AM6: 1332.1 | AN6: 1332.1
A7: USDKRW_end | C7: 원/달러(기말) | E7: 1188.75 | F7: 1188.75 | G7: 1213.74 | H7: 1301.24 | I7: 1436.9 | J7: 1260.16 | K7: 1260.16 | L7: 1305.99 | M7: 1321.44 | N7: 1345.35 | O7: 1297.43 | P7: 1297.43 | Q7: 1349.25 | R7: 1377.73 | S7: 1312.17 | T7: 1474.78 | U7: 1474.78 | V7: 1474.54 | W7: 1355.13 | X7: 1403.67 | Y7: 1444.2 | Z7: 1444.2 | AA7: 1524.8 | AB7: 1550.89 | AC7: 1355.4 | AD7: 1332.1 | AE7: 1332.1 | AF7: 1332.1 | AG7: 1332.1 | AH7: 1332.1 | AI7: 1332.1 | AK7: 1332.1 | AL7: 1332.1 | AM7: 1332.1 | AN7: 1332.1
A8: JPY100KRW_avg | C8: 원/100Y(평균) | E8: 1041.02 | F8: 1042.74 | G8: 1036.79 | H8: 972.23 | I8: 970.61 | J8: 961.03 | K8: 985.1 | L8: 964.89 | M8: 957.36 | N8: 909 | O8: 893.22 | P8: 931.11 | Q8: 896.29 | R8: 880.14 | S8: 909.35 | T8: 917.25 | U8: 900.92 | V8: 952.59 | W8: 967.92 | X8: 940.32 | Y8: 940.77 | Z8: 950.17 | AA8: 934.39 | AB8: 942.16 | AC8: 890.41 | AD8: 848.59 | AE8: 917.39 | AF8: 842.99 | AG8: 842.99 | AH8: 842.99 | AI8: 842.99 | AK8: 842.99 | AL8: 842.99 | AM8: 842.99 | AN8: 842.99
A9: JPY100KRW_end | C9: 원/100Y(기말) | E9: 1032.62 | F9: 1032.62 | G9: 996.83 | H9: 954.9 | I9: 993.29 | J9: 955.54 | K9: 955.54 | L9: 980.62 | M9: 913.67 | N9: 901.47 | O9: 917.04 | P9: 917.04 | Q9: 892.42 | R9: 857.76 | S9: 919.21 | T9: 939.65 | U9: 939.65 | V9: 986.84 | W9: 938.85 | X9: 948.49 | Y9: 921.81 | Z9: 921.81 | AA9: 955.99 | AB9: 954.75 | AC9: 863.31 | AD9: 842.99 | AE9: 842.99 | AF9: 842.99 | AG9: 842.99 | AH9: 842.99 | AI9: 842.99 | AK9: 842.99 | AL9: 842.99 | AM9: 842.99 | AN9: 842.99
A10: EURKRW_avg | C10: W/Euro(평균) | E10: 1353.32 | F10: 1354.06 | G10: 1352.29 | H10: 1343.31 | I10: 1350.63 | J10: 1386.07 | K10: 1358.07 | L10: 1369.93 | M10: 1432.41 | N10: 1429.41 | O10: 1420.91 | P10: 1412.88 | Q10: 1444.21 | R10: 1476.42 | S10: 1489.3 | T10: 1490.78 | U10: 1475.4 | V10: 1528.33 | W10: 1585.13 | X10: 1620.04 | Y10: 1686.02 | Z10: 1605.45 | AA10: 1715.47 | AB10: 1746.09 | AC10: 1631.97 | AD10: 1505.3 | AE10: 1685.25 | AF10: 1499.02 | AG10: 1499.02 | AH10: 1499.02 | AI10: 1499.02 | AK10: 1499.02 | AL10: 1499.02 | AM10: 1499.02 | AN10: 1499.02
A11: EURKRW_end | C11: W/Euro(기말) | E11: 1346.38 | F11: 1346.38 | G11: 1347.37 | H11: 1351.6 | I11: 1400.62 | J11: 1344.08 | K11: 1344.08 | L11: 1420.26 | M11: 1435.88 | N11: 1425.26 | O11: 1433.66 | P11: 1433.66 | Q11: 1458.68 | R11: 1474.86 | S11: 1469.1 | T11: 1532.14 | U11: 1532.14 | V11: 1594.72 | W11: 1588.22 | X11: 1648.04 | Y11: 1696.94 | Z11: 1696.94 | AA11: 1753.21 | AB11: 1767.09 | AC11: 1539.06 | AD11: 1499.02 | AE11: 1499.02 | AF11: 1499.02 | AG11: 1499.02 | AH11: 1499.02 | AI11: 1499.02 | AK11: 1499.02 | AL11: 1499.02 | AM11: 1499.02 | AN11: 1499.02
A12: CNYKRW_avg | C12: 원/중국원(평균) | E12: 185.14 | F12: 177.65 | G12: 189.93 | H12: 190.76 | I12: 195.79 | J12: 191.09 | K12: 191.93 | L12: 186.59 | M12: 187.45 | N12: 181.28 | O12: 182.86 | P12: 184.52 | Q12: 185.04 | R12: 189.35 | S12: 189.24 | T12: 194.24 | U12: 189.49 | V12: 199.63 | W12: 193.41 | X12: 193.79 | Y12: 204.38 | Z12: 197.8 | AA12: 211.75 | AB12: 220.8 | AC12: 210.43 | AD12: 200.38 | AE12: 213.41 | AF12: 199.23 | AG12: 199.23 | AH12: 199.23 | AI12: 199.23 | AK12: 199.23 | AL12: 199.23 | AM12: 199.23 | AN12: 199.23
A13: CNYKRW_end | C13: 원/중국원(기말) | E13: 187.13 | F13: 187.13 | G13: 191.38 | H13: 194.13 | I13: 201.92 | J13: 182.67 | K13: 182.67 | L13: 189.97 | M13: 181.8 | N13: 184.26 | O13: 182.61 | P13: 182.61 | Q13: 186.66 | R13: 189.7 | S13: 187.12 | T13: 202.04 | U13: 202.04 | V13: 203.3 | W13: 189.14 | X13: 197.16 | Y13: 206.28 | Z13: 206.28 | AA13: 220.97 | AB13: 228.56 | AC13: 202.16 | AD13: 199.23 | AE13: 199.23 | AF13: 199.23 | AG13: 199.23 | AH13: 199.23 | AI13: 199.23 | AK13: 199.23 | AL13: 199.23 | AM13: 199.23 | AN13: 199.23
B14: 1b. 종가
A15: price_close_end | C15: 종가(기말) | E15: 5275 | G15: 5050 | H15: 3825 | I15: 3495 | J15: 3545 | L15: 3810 | M15: 3875 | N15: 3065 | O15: 2815 | Q15: 2575 | R15: 2625 | S15: 2430 | T15: 2030 | V15: 1955 | W15: 2715 | X15: 2825 | Y15: 2445 | AA15: 2750 | AB15: 1350 | AC15: 2120 | AD15: 2190
A16: price_high | C16: 종가(최고) | E16: 5900 | G16: 5425 | H16: 5575 | I16: 4470 | J16: 3905 | L16: 4180 | M16: 4065 | N16: 3935 | O16: 3410 | Q16: 2890 | R16: 3050 | S16: 2725 | T16: 2450 | V16: 2175 | W16: 3185 | X16: 3670 | Y16: 3285 | AA16: 4040 | AB16: 2950 | AC16: 3020 | AD16: 2430
A17: price_low | C17: 종가(최저) | E17: 4830 | G17: 4350 | H17: 3330 | I17: 3335 | J17: 3030 | L17: 3370 | M17: 3575 | N17: 3020 | O17: 2590 | Q17: 2550 | R17: 2415 | S17: 2335 | T17: 1795 | V17: 1950 | W17: 1795 | X17: 2435 | Y17: 2410 | AA17: 2235 | AB17: 1281 | AC17: 1284 | AD17: 2020
A18: price_avg | C18: 종가(평균) | E18: 5327.9 | G18: 4851.4 | H18: 4796.3 | I18: 4012.5 | J18: 3587.5 | L18: 3846.2 | M18: 3777.8 | N18: 3423.7 | O18: 2846.2 | Q18: 2714.3 | R18: 2592.8 | S18: 2509.2 | T18: 2191.1 | V18: 2034.6 | W18: 2397 | X18: 2891.5 | Y18: 2732.4 | AA18: 2643.8 | AB18: 2335.4 | AC18: 2271.6 | AD18: 2189.5
B20: 2. 추정 드라이버 | C20: 실적 열 = subQ 실현값(수식), 추정 열 = 가정(노란 = 모델값 역산, 연녹 = 3절 스칼라 참조)
A21: drv:매출액 | B21: yoy | C21: 매출액 YoY | J21: =IFERROR(subQ!J5/subQ!E5-1,"") | L21: =IFERROR(subQ!L5/subQ!G5-1,"") | M21: =IFERROR(subQ!M5/subQ!H5-1,"") | N21: =IFERROR(subQ!N5/subQ!I5-1,"") | O21: =IFERROR(subQ!O5/subQ!J5-1,"") | Q21: =IFERROR(subQ!Q5/subQ!L5-1,"") | R21: =IFERROR(subQ!R5/subQ!M5-1,"") | S21: =IFERROR(subQ!S5/subQ!N5-1,"") | T21: =IFERROR(subQ!T5/subQ!O5-1,"") | V21: =IFERROR(subQ!V5/subQ!Q5-1,"") | W21: =IFERROR(subQ!W5/subQ!R5-1,"") | X21: =IFERROR(subQ!X5/subQ!S5-1,"") | Y21: =IFERROR(subQ!Y5/subQ!T5-1,"") | AA21: =IFERROR(subQ!AA5/subQ!V5-1,"") | AB21: =IFERROR(subQ!AB5/subQ!W5-1,"") | AC21: -0.10141899 | AD21: -0.10141958 | AF21: -0.10142747 | AG21: -0.10142512 | AH21: -0.050713924 | AI21: -0.050720368 | AK21: -0.050701137 | AL21: -0.050709833 | AM21: -0.02535683 | AN21: -0.025352044
A22: drv:판관비 | B22: ratio | C22: 판관비율(/매출) | E22: =IFERROR(subQ!E8/subQ!E5,"") | F22: =IFERROR(subQ!F8/subQ!F5,"") | G22: =IFERROR(subQ!G8/subQ!G5,"") | H22: =IFERROR(subQ!H8/subQ!H5,"") | I22: =IFERROR(subQ!I8/subQ!I5,"") | J22: =IFERROR(subQ!J8/subQ!J5,"") | K22: =IFERROR(subQ!K8/subQ!K5,"") | L22: =IFERROR(subQ!L8/subQ!L5,"") | ... AB22: =IFERROR(subQ!AB8/subQ!AB5,"") | AC22: =$D$53 | AD22: =$D$53 | AE22: =IFERROR(subQ!AE8/subQ!AE5,"") | AF22: =$D$53 | AG22: =$D$53 | AH22: =$D$53 | AI22: =$D$53 | AJ22: =IFERROR(subQ!AJ8/subQ!AJ5,"") | AK22: =$D$53 | AL22: =$D$53 | AM22: =$D$53 | AN22: =$D$53 | AO22: =IFERROR(subQ!AO8/subQ!AO5,"")
A23: drv:영업이익 | B23: ratio | C23: 영업이익률(OPM) | E23: =IFERROR(subQ!E9/subQ!E5,"") | F23: =IFERROR(subQ!F9/subQ!F5,"") | G23: =IFERROR(subQ!G9/subQ!G5,"") | H23: =IFERROR(subQ!H9/subQ!H5,"") | I23: =IFERROR(subQ!I9/subQ!I5,"") | J23: =IFERROR(subQ!J9/subQ!J5,"") | K23: =IFERROR(subQ!K9/subQ!K5,"") | L23: =IFERROR(subQ!L9/subQ!L5,"") | ... AB23: =IFERROR(subQ!AB9/subQ!AB5,"") | AC23: -0.017711392 | AD23: -0.017711691 | AE23: =IFERROR(subQ!AE9/subQ!AE5,"") | AF23: -0.017715967 | AG23: -0.017709354 | AH23: -0.017708178 | AI23: -0.017708701 | AJ23: =IFERROR(subQ!AJ9/subQ!AJ5,"") | AK23: -0.017713855 | AL23: -0.017711067 | AM23: -0.017709188 | AN23: -0.017707293 | AO23: =IFERROR(subQ!AO9/subQ!AO5,"")
A24: drv:외환손익 | B24: abs | C24: 외환손익 (가정, 억원) | E24: =subQ!E13 | F24: =subQ!F13 | G24: =subQ!G13 | H24: =subQ!H13 | I24: =subQ!I13 | J24: =subQ!J13 | K24: =subQ!K13 | L24: =subQ!L13 | ... AB24: =subQ!AB13 | AC24: 0 | AD24: 0 | AE24: =subQ!AE13 | AF24: 0 | AG24: 0 | AH24: 0 | AI24: 0 | AJ24: =subQ!AJ13 | AK24: 0 | AL24: 0 | AM24: 0 | AN24: 0 | AO24: =subQ!AO13
A25: drv:파생상품손익 | B25: abs | C25: 파생상품손익 (가정, 억원) | E25: =subQ!E14 | F25: =subQ!F14 | G25: =subQ!G14 | H25: =subQ!H14 | I25: =subQ!I14 | J25: =subQ!J14 | K25: =subQ!K14 | L25: =subQ!L14 | ... AB25: =subQ!AB14 | AC25: 0 | AD25: 0 | AE25: =subQ!AE14 | AF25: 0 | AG25: 0 | AH25: 0 | AI25: 0 | AJ25: =subQ!AJ14 | AK25: 0 | AL25: 0 | AM25: 0 | AN25: 0 | AO25: =subQ!AO14
A26: drv:기타금융손익 | B26: abs | C26: 기타금융손익 (가정, 억원) | E26: =subQ!E15 | F26: =subQ!F15 | G26: =subQ!G15 | H26: =subQ!H15 | I26: =subQ!I15 | J26: =subQ!J15 | K26: =subQ!K15 | L26: =subQ!L15 | ... AB26: =subQ!AB15 | AC26: 0 | AD26: 0 | AE26: =subQ!AE15 | AF26: 0 | AG26: 0 | AH26: 0 | AI26: 0 | AJ26: =subQ!AJ15 | AK26: 0 | AL26: 0 | AM26: 0 | AN26: 0 | AO26: =subQ!AO15
A27: drv:기타영업외손익 | B27: abs | C27: 기타영업외손익 (가정, 억원) | E27: =subQ!E16 | F27: =subQ!F16 | G27: =subQ!G16 | H27: =subQ!H16 | I27: =subQ!I16 | J27: =subQ!J16 | K27: =subQ!K16 | L27: =subQ!L16 | ... AB27: =subQ!AB16 | AC27: 0 | AD27: 0 | AE27: =subQ!AE16 | AF27: 0 | AG27: 0 | AH27: 0 | AI27: 0 | AJ27: =subQ!AJ16 | AK27: 0 | AL27: 0 | AM27: 0 | AN27: 0 | AO27: =subQ!AO16
A28: drv:지분법손익 | B28: abs | C28: 지분법손익 (가정, 억원) | E28: =subQ!E17 | F28: =subQ!F17 | G28: =subQ!G17 | H28: =subQ!H17 | I28: =subQ!I17 | J28: =subQ!J17 | K28: =subQ!K17 | L28: =subQ!L17 | ... AB28: =subQ!AB17 | AC28: -0.74 | AD28: -0.74 | AE28: =subQ!AE17 | AF28: -0.74 | AG28: -0.74 | AH28: -0.74 | AI28: -0.74 | AJ28: =subQ!AJ17 | AK28: -0.74 | AL28: -0.74 | AM28: -0.74 | AN28: -0.74 | AO28: =subQ!AO17
A29: drv:법인세비용 | B29: ratio | C29: 법인세율(/세전) | E29: =IFERROR(subQ!E19/subQ!E18,"") | F29: =IFERROR(subQ!F19/subQ!F18,"") | G29: =IFERROR(subQ!G19/subQ!G18,"") | H29: =IFERROR(subQ!H19/subQ!H18,"") | I29: =IFERROR(subQ!I19/subQ!I18,"") | J29: =IFERROR(subQ!J19/subQ!J18,"") | K29: =IFERROR(subQ!K19/subQ!K18,"") | L29: =IFERROR(subQ!L19/subQ!L18,"") | ... AB29: =IFERROR(subQ!AB19/subQ!AB18,"") | AC29: 0 | AD29: 0 | AE29: =IFERROR(subQ!AE19/subQ!AE18,"") | AF29: 0 | AG29: 0 | AH29: 0 | AI29: 0 | AJ29: =IFERROR(subQ!AJ19/subQ!AJ18,"") | AK29: 0 | AL29: 0 | AM29: 0 | AN29: 0 | AO29: =IFERROR(subQ!AO19/subQ!AO18,"")
A30: drv:지배주주순이익 | B30: ratio | C30: 지배주주 비중(/당기순이익) | E30: =IFERROR(subQ!E21/subQ!E20,"") | F30: =IFERROR(subQ!F21/subQ!F20,"") | G30: =IFERROR(subQ!G21/subQ!G20,"") | H30: =IFERROR(subQ!H21/subQ!H20,"") | I30: =IFERROR(subQ!I21/subQ!I20,"") | J30: =IFERROR(subQ!J21/subQ!J20,"") | K30: =IFERROR(subQ!K21/subQ!K20,"") | L30: =IFERROR(subQ!L21/subQ!L20,"") | ... AB30: =IFERROR(subQ!AB21/subQ!AB20,"") | AC30: =$D$54 | AD30: =$D$54 | AE30: =IFERROR(subQ!AE21/subQ!AE20,"") | AF30: =$D$54 | AG30: =$D$54 | AH30: =$D$54 | AI30: =$D$54 | AJ30: =IFERROR(subQ!AJ21/subQ!AJ20,"") | AK30: =$D$54 | AL30: =$D$54 | AM30: =$D$54 | AN30: =$D$54 | AO30: =IFERROR(subQ!AO21/subQ!AO20,"")
A31: drv:중단사업이익 | B31: abs | C31: 중단사업이익 (가정, 억원) | E31: =subQ!E22 | F31: =subQ!F22 | G31: =subQ!G22 | H31: =subQ!H22 | I31: =subQ!I22 | J31: =subQ!J22 | K31: =subQ!K22 | L31: =subQ!L22 | ... AB31: =subQ!AB22 | AE31: =subQ!AE22 | AJ31: =subQ!AJ22 | AO31: =subQ!AO22
A32: drv:부채총계 | B32: qoq | C32: 부채총계 QoQ | G32: =IFERROR(subQ!G24/subQ!E24-1,"") | H32: =IFERROR(subQ!H24/subQ!G24-1,"") | I32: =IFERROR(subQ!I24/subQ!H24-1,"") | J32: =IFERROR(subQ!J24/subQ!I24-1,"") | L32: =IFERROR(subQ!L24/subQ!J24-1,"") | M32: =IFERROR(subQ!M24/subQ!L24-1,"") | N32: =IFERROR(subQ!N24/subQ!M24-1,"") | O32: =IFERROR(subQ!O24/subQ!N24-1,"") | Q32: =IFERROR(subQ!Q24/subQ!O24-1,"") | R32: =IFERROR(subQ!R24/subQ!Q24-1,"") | S32: =IFERROR(subQ!S24/subQ!R24-1,"") | T32: =IFERROR(subQ!T24/subQ!S24-1,"") | V32: =IFERROR(subQ!V24/subQ!T24-1,"") | W32: =IFERROR(subQ!W24/subQ!V24-1,"") | X32: =IFERROR(subQ!X24/subQ!W24-1,"") | Y32: =IFERROR(subQ!Y24/subQ!X24-1,"") | AA32: =IFERROR(subQ!AA24/subQ!Y24-1,"") | AB32: =IFERROR(subQ!AB24/subQ!AA24-1,"") | AC32: 9.32e-07 | AD32: 0 | AF32: 0 | AG32: 0 | AH32: 0 | AI32: 0 | AK32: 0 | AL32: 0 | AM32: 0 | AN32: 0
A33: drv:자본총계 | B33: roll | C33: 자본총계 기타변동(배당 등, 억원) | G33: =IFERROR(subQ!E25+subQ!G20-subQ!G25,"") | H33: =IFERROR(subQ!G25+subQ!H20-subQ!H25,"") | I33: =IFERROR(subQ!H25+subQ!I20-subQ!I25,"") | J33: =IFERROR(subQ!I25+subQ!J20-subQ!J25,"") | L33: =IFERROR(subQ!J25+subQ!L20-subQ!L25,"") | M33: =IFERROR(subQ!L25+subQ!M20-subQ!M25,"") | N33: =IFERROR(subQ!M25+subQ!N20-subQ!N25,"") | O33: =IFERROR(subQ!N25+subQ!O20-subQ!O25,"") | Q33: =IFERROR(subQ!O25+subQ!Q20-subQ!Q25,"") | R33: =IFERROR(subQ!Q25+subQ!R20-subQ!R25,"") | S33: =IFERROR(subQ!R25+subQ!S20-subQ!S25,"") | T33: =IFERROR(subQ!S25+subQ!T20-subQ!T25,"") | V33: =IFERROR(subQ!T25+subQ!V20-subQ!V25,"") | W33: =IFERROR(subQ!V25+subQ!W20-subQ!W25,"") | X33: =IFERROR(subQ!W25+subQ!X20-subQ!X25,"") | Y33: =IFERROR(subQ!X25+subQ!Y20-subQ!Y25,"") | AA33: =IFERROR(subQ!Y25+subQ!AA20-subQ!AA25,"") | AB33: =IFERROR(subQ!AA25+subQ!AB20-subQ!AB25,"") | AC33: -0.004607013 | AD33: 0.005532376 | AF33: -0.014077506 | AG33: 0.008403083 | AH33: -0.005168202 | AI33: 0.00102731 | AK33: -0.004402449 | AL33: 0.001096063 | AM33: 0.001008086 | AN33: -0.000711033
A34: drv:지배주주지분 | B34: roll | C34: 지배주주지분 기타변동(배당 등, 억원) | G34: =IFERROR(subQ!E26+subQ!G21-subQ!G26,"") | H34: =IFERROR(subQ!G26+subQ!H21-subQ!H26,"") | I34: =IFERROR(subQ!H26+subQ!I21-subQ!I26,"") | J34: =IFERROR(subQ!I26+subQ!J21-subQ!J26,"") | L34: =IFERROR(subQ!J26+subQ!L21-subQ!L26,"") | M34: =IFERROR(subQ!L26+subQ!M21-subQ!M26,"") | N34: =IFERROR(subQ!M26+subQ!N21-subQ!N26,"") | O34: =IFERROR(subQ!N26+subQ!O21-subQ!O26,"") | Q34: =IFERROR(subQ!O26+subQ!Q21-subQ!Q26,"") | R34: =IFERROR(subQ!Q26+subQ!R21-subQ!R26,"") | S34: =IFERROR(subQ!R26+subQ!S21-subQ!S26,"") | T34: =IFERROR(subQ!S26+subQ!T21-subQ!T26,"") | V34: =IFERROR(subQ!T26+subQ!V21-subQ!V26,"") | W34: =IFERROR(subQ!V26+subQ!W21-subQ!W26,"") | X34: =IFERROR(subQ!W26+subQ!X21-subQ!X26,"") | Y34: =IFERROR(subQ!X26+subQ!Y21-subQ!Y26,"") | AA34: =IFERROR(subQ!Y26+subQ!AA21-subQ!AA26,"") | AB34: =IFERROR(subQ!AA26+subQ!AB21-subQ!AB26,"") | AC34: -0.002307013 | AD34: -0.004467624 | AF34: -0.004077506 | AG34: -0.001596917 | AH34: 0.004831798 | AI34: 0.00102731 | AK34: -0.004402449 | AL34: 0.001096063 | AM34: 0.001008086 | AN34: -0.000711033
A35: drv:총차입금 | B35: qoq | C35: 총차입금 QoQ | G35: =IFERROR(subQ!G27/subQ!E27-1,"") | H35: =IFERROR(subQ!H27/subQ!G27-1,"") | I35: =IFERROR(subQ!I27/subQ!H27-1,"") | J35: =IFERROR(subQ!J27/subQ!I27-1,"") | L35: =IFERROR(subQ!L27/subQ!J27-1,"") | M35: =IFERROR(subQ!M27/subQ!L27-1,"") | N35: =IFERROR(subQ!N27/subQ!M27-1,"") | O35: =IFERROR(subQ!O27/subQ!N27-1,"") | Q35: =IFERROR(subQ!Q27/subQ!O27-1,"") | R35: =IFERROR(subQ!R27/subQ!Q27-1,"") | S35: =IFERROR(subQ!S27/subQ!R27-1,"") | T35: =IFERROR(subQ!T27/subQ!S27-1,"") | V35: =IFERROR(subQ!V27/subQ!T27-1,"") | W35: =IFERROR(subQ!W27/subQ!V27-1,"") | X35: =IFERROR(subQ!X27/subQ!W27-1,"") | Y35: =IFERROR(subQ!Y27/subQ!X27-1,"") | AA35: =IFERROR(subQ!AA27/subQ!Y27-1,"") | AB35: =IFERROR(subQ!AB27/subQ!AA27-1,"") | AC35: 2.27e-06 | AD35: 0 | AF35: 0 | AG35: 0 | AH35: 0 | AI35: 0 | AK35: 0 | AL35: 0 | AM35: 0 | AN35: 0
A36: drv:순차입금 | B36: qoq | C36: 순차입금 QoQ | G36: =IFERROR(subQ!G28/subQ!E28-1,"") | H36: =IFERROR(subQ!H28/subQ!G28-1,"") | I36: =IFERROR(subQ!I28/subQ!H28-1,"") | J36: =IFERROR(subQ!J28/subQ!I28-1,"") | L36: =IFERROR(subQ!L28/subQ!J28-1,"") | M36: =IFERROR(subQ!M28/subQ!L28-1,"") | N36: =IFERROR(subQ!N28/subQ!M28-1,"") | O36: =IFERROR(subQ!O28/subQ!N28-1,"") | Q36: =IFERROR(subQ!Q28/subQ!O28-1,"") | R36: =IFERROR(subQ!R28/subQ!Q28-1,"") | S36: =IFERROR(subQ!S28/subQ!R28-1,"") | T36: =IFERROR(subQ!T28/subQ!S28-1,"") | V36: =IFERROR(subQ!V28/subQ!T28-1,"") | W36: =IFERROR(subQ!W28/subQ!V28-1,"") | X36: =IFERROR(subQ!X28/subQ!W28-1,"") | Y36: =IFERROR(subQ!Y28/subQ!X28-1,"") | AA36: =IFERROR(subQ!AA28/subQ!Y28-1,"") | AB36: =IFERROR(subQ!AB28/subQ!AA28-1,"") | AC36: 0.028858632 | AD36: 0.026897334 | AF36: 0.026818584 | AG36: 0.028025548 | AH36: 0.027600277 | AI36: 0.025944934 | AK36: 0.025887628 | AL36: 0.026935643 | AM36: 0.026873783 | AN36: 0.025427962
A37: drv:이자발생자산 | B37: qoq | C37: 이자발생자산 QoQ | G37: =IFERROR(subQ!G29/subQ!E29-1,"") | H37: =IFERROR(subQ!H29/subQ!G29-1,"") | I37: =IFERROR(subQ!I29/subQ!H29-1,"") | J37: =IFERROR(subQ!J29/subQ!I29-1,"") | L37: =IFERROR(subQ!L29/subQ!J29-1,"") | M37: =IFERROR(subQ!M29/subQ!L29-1,"") | N37: =IFERROR(subQ!N29/subQ!M29-1,"") | O37: =IFERROR(subQ!O29/subQ!N29-1,"") | Q37: =IFERROR(subQ!Q29/subQ!O29-1,"") | R37: =IFERROR(subQ!R29/subQ!Q29-1,"") | S37: =IFERROR(subQ!S29/subQ!R29-1,"") | T37: =IFERROR(subQ!T29/subQ!S29-1,"") | V37: =IFERROR(subQ!V29/subQ!T29-1,"") | W37: =IFERROR(subQ!W29/subQ!V29-1,"") | X37: =IFERROR(subQ!X29/subQ!W29-1,"") | Y37: =IFERROR(subQ!Y29/subQ!X29-1,"") | AA37: =IFERROR(subQ!AA29/subQ!Y29-1,"") | AB37: =IFERROR(subQ!AB29/subQ!AA29-1,"") | AC37: -0.35694972 | AD37: -0.53228737 | AF37: -1.1652542 | AG37: 7.5662393 | AH37: 0.89423796 | AI37: 0.45601791 | AK37: 0.32061138 | AL37: 0.25914258 | AM37: 0.21086696 | AN37: 0.16920451
A38: drv:현금및현금성자산 | B38: qoq | C38: 현금및현금성자산 QoQ | G38: =IFERROR(subQ!G30/subQ!E30-1,"") | H38: =IFERROR(subQ!H30/subQ!G30-1,"") | I38: =IFERROR(subQ!I30/subQ!H30-1,"") | J38: =IFERROR(subQ!J30/subQ!I30-1,"") | L38: =IFERROR(subQ!L30/subQ!J30-1,"") | M38: =IFERROR(subQ!M30/subQ!L30-1,"") | N38: =IFERROR(subQ!N30/subQ!M30-1,"") | O38: =IFERROR(subQ!O30/subQ!N30-1,"") | Q38: =IFERROR(subQ!Q30/subQ!O30-1,"") | R38: =IFERROR(subQ!R30/subQ!Q30-1,"") | S38: =IFERROR(subQ!S30/subQ!R30-1,"") | T38: =IFERROR(subQ!T30/subQ!S30-1,"") | V38: =IFERROR(subQ!V30/subQ!T30-1,"") | W38: =IFERROR(subQ!W30/subQ!V30-1,"") | X38: =IFERROR(subQ!X30/subQ!W30-1,"") | Y38: =IFERROR(subQ!Y30/subQ!X30-1,"") | AA38: =IFERROR(subQ!AA30/subQ!Y30-1,"") | AB38: =IFERROR(subQ!AB30/subQ!AA30-1,"")
A39: drv:CAPEX | B39: yoy | C39: CAPEX YoY | J39: =IFERROR(subQ!J31/subQ!E31-1,"") | L39: =IFERROR(subQ!L31/subQ!G31-1,"") | M39: =IFERROR(subQ!M31/subQ!H31-1,"") | N39: =IFERROR(subQ!N31/subQ!I31-1,"") | O39: =IFERROR(subQ!O31/subQ!J31-1,"") | Q39: =IFERROR(subQ!Q31/subQ!L31-1,"") | R39: =IFERROR(subQ!R31/subQ!M31-1,"") | S39: =IFERROR(subQ!S31/subQ!N31-1,"") | T39: =IFERROR(subQ!T31/subQ!O31-1,"") | V39: =IFERROR(subQ!V31/subQ!Q31-1,"") | W39: =IFERROR(subQ!W31/subQ!R31-1,"") | X39: =IFERROR(subQ!X31/subQ!S31-1,"") | Y39: =IFERROR(subQ!Y31/subQ!T31-1,"") | AA39: =IFERROR(subQ!AA31/subQ!V31-1,"") | AB39: =IFERROR(subQ!AB31/subQ!W31-1,"") | AC39: -0.26462615 | AD39: 0.1634261 | AF39: 3.6239709 | AG39: -0.12307589 | AH39: 0 | AI39: 0 | AK39: 0 | AL39: 0 | AM39: 0 | AN39: 0
A40: drv:영업활동현금흐름 | B40: yoy | C40: 영업활동현금흐름 YoY | J40: =IFERROR(subQ!J32/subQ!E32-1,"") | L40: =IFERROR(subQ!L32/subQ!G32-1,"") | M40: =IFERROR(subQ!M32/subQ!H32-1,"") | N40: =IFERROR(subQ!N32/subQ!I32-1,"") | O40: =IFERROR(subQ!O32/subQ!J32-1,"") | Q40: =IFERROR(subQ!Q32/subQ!L32-1,"") | R40: =IFERROR(subQ!R32/subQ!M32-1,"") | S40: =IFERROR(subQ!S32/subQ!N32-1,"") | T40: =IFERROR(subQ!T32/subQ!O32-1,"") | V40: =IFERROR(subQ!V32/subQ!Q32-1,"") | W40: =IFERROR(subQ!W32/subQ!R32-1,"") | X40: =IFERROR(subQ!X32/subQ!S32-1,"") | Y40: =IFERROR(subQ!Y32/subQ!T32-1,"") | AA40: =IFERROR(subQ!AA32/subQ!V32-1,"") | AB40: =IFERROR(subQ!AB32/subQ!W32-1,"")
A41: drv:주식수 | B41: qoq | C41: 주식수 QoQ | G41: =IFERROR(subQ!G33/subQ!E33-1,"") | H41: =IFERROR(subQ!H33/subQ!G33-1,"") | I41: =IFERROR(subQ!I33/subQ!H33-1,"") | J41: =IFERROR(subQ!J33/subQ!I33-1,"") | L41: =IFERROR(subQ!L33/subQ!J33-1,"") | M41: =IFERROR(subQ!M33/subQ!L33-1,"") | N41: =IFERROR(subQ!N33/subQ!M33-1,"") | O41: =IFERROR(subQ!O33/subQ!N33-1,"") | Q41: =IFERROR(subQ!Q33/subQ!O33-1,"") | R41: =IFERROR(subQ!R33/subQ!Q33-1,"") | S41: =IFERROR(subQ!S33/subQ!R33-1,"") | T41: =IFERROR(subQ!T33/subQ!S33-1,"") | V41: =IFERROR(subQ!V33/subQ!T33-1,"") | W41: =IFERROR(subQ!W33/subQ!V33-1,"") | X41: =IFERROR(subQ!X33/subQ!W33-1,"") | Y41: =IFERROR(subQ!Y33/subQ!X33-1,"") | AA41: =IFERROR(subQ!AA33/subQ!Y33-1,"") | AB41: =IFERROR(subQ!AB33/subQ!AA33-1,"") | AC41: 0 | AD41: 0 | AF41: 0 | AG41: 0 | AH41: 0 | AI41: 0 | AK41: 0 | AL41: 0 | AM41: 0 | AN41: 0
...

Sheet BS연결
B1: (백만원) | C1: 이름: BS연결H | E1: 4Q21 | F1: 2021 | G1: 1Q22 | H1: 2Q22 | I1: 3Q22 | J1: 4Q22 | K1: 2022 | L1: 1Q23 | M1: 2Q23 | N1: 3Q23 | O1: 4Q23 | P1: 2023 | Q1: 1Q24 | R1: 2Q24 | S1: 3Q24 | T1: 4Q24 | U1: 2024 | V1: 1Q25 | W1: 2Q25 | X1: 3Q25 | Y1: 4Q25 | Z1: 2025 | AA1: 1Q26 | AB1: 2Q26 | AC1: 3Q26 | AD1: 4Q26 | AE1: 2026 | AF1: 1Q27 | AG1: 2Q27 | AH1: 3Q27 | AI1: 4Q27 | AJ1: 2027 | AK1: 1Q28 | AL1: 2Q28 | AM1: 3Q28 | AN1: 4Q28 | AO1: 2028
B2: 연결 | D2: fin json(kship_fin.py)
B3: 영흥(연) | C3: UPDATE: 26-10-19 | E3: 1 | F3: 2 | G3: 3 | H3: 4 | I3: 5 | J3: 6 | K3: 7 | L3: 8 | M3: 9 | N3: 10 | O3: 11 | P3: 12 | Q3: 13 | R3: 14 | S3: 15 | T3: 16 | U3: 17 | V3: 18 | W3: 19 | X3: 20 | Y3: 21 | Z3: 22 | AA3: 23 | AB3: 24 | AC3: 25 | AD3: 26 | AE3: 27 | AF3: 28 | AG3: 29 | AH3: 30 | AI3: 31 | AJ3: 32 | AK3: 33 | AL3: 34 | AM3: 35 | AN3: 36 | AO3: 37
B4: Account Code | C4: AccountNAME | E4: 2021.12 | F4: 2021.12A | G4: 2022.03 | H4: 2022.06 | I4: 2022.09 | J4: 2022.12 | K4: 2022.12A | L4: 2023.03 | M4: 2023.06 | N4: 2023.09 | O4: 2023.12 | P4: 2023.12A | Q4: 2024.03 | R4: 2024.06 | S4: 2024.09 | T4: 2024.12 | U4: 2024.12A | V4: 2025.03 | W4: 2025.06 | X4: 2025.09 | Y4: 2025.12 | Z4: 2025.12A | AA4: 2026.03 | AB4: 2026.06 | AC4: 2026.09 | AD4: 2026.12 | AE4: 2026.12A | AF4: 2027.03 | AG4: 2027.06 | AH4: 2027.09 | AI4: 2027.12 | AJ4: 2027.12A | AK4: 2028.03 | AL4: 2028.06 | AM4: 2028.09 | AN4: 2028.12 | AO4: 2028.12A
A5: 1 | C5: 유동자산 | E5: 242197.5 | F5: 242197.5 | G5: 257229.62 | H5: 283835.52 | I5: 266355.06 | J5: 273435.84 | K5: 273435.84 | L5: 267898.7 | M5: 267020.11 | N5: 258764.33 | O5: 262428.63 | P5: 262428.63 | Q5: 282515.78 | R5: 273846.39 | S5: 264994.74 | T5: 243785.08 | U5: 243785.08 | V5: 222758.63 | W5: 245765.39 | X5: 232796.09 | Y5: 250698.06 | Z5: 250698.06 | AA5: 244058.04 | AB5: 243711.53
A6: 1 | C6: 현금및현금성자산 | E6: 12141.94 | F6: 12141.94 | G6: 14196.15 | H6: 20665.07 | I6: 11166.26 | J6: 17308.1 | K6: 17308.1 | L6: 7896 | M6: 12652.42 | N6: 11742.51 | O6: 10693.65 | P6: 10693.65 | Q6: 10977.25 | R6: 8498.27 | S6: 8719.82 | T6: 9952.2 | U6: 9952.2 | V6: 12303.56 | W6: 14386.45 | X6: 11199.33 | Y6: 10981.3 | Z6: 10981.3 | AA6: 8450.55 | AB6: 6889.74
A7: 1 | C7: 매출채권및기타채권 | E7: 103115.2 | F7: 103115.2 | G7: 114459.5 | H7: 118090.8 | I7: 120367.12 | J7: 120372.16 | K7: 120372.16 | L7: 115048.36 | M7: 115923.64 | N7: 113183.25 | O7: 107004.35 | P7: 107004.35 | Q7: 4652.7 | R7: 2720.48 | S7: 98834.18 | T7: 105472.57 | U7: 105472.57 | V7: 104755.85 | W7: 96159.93 | X7: 92355.54 | Y7: 82699.79 | Z7: 82699.79 | AA7: 82708.05 | AB7: 85802.93
A8: 1 | C8: 재고자산 | E8: 123761.31 | F8: 123761.31 | G8: 123535.65 | H8: 140504.73 | I8: 129123.3 | J8: 129965.2 | K8: 129965.2 | L8: 141182.67 | M8: 132090.21 | N8: 127148.85 | O8: 120658.04 | P8: 120658.04 | Q8: 130520.75 | R8: 132701.91 | S8: 126953.67 | T8: 111144.98 | U8: 111144.98 | V8: 92656.48 | W8: 87833.4 | X8: 80213.52 | Y8: 84349.72 | Z8: 84349.72 | AA8: 84020.84 | AB8: 84189.36
A9: 1 | C9: 당기법인세자산(선급법인세) | E9: 54.69 | F9: 54.69 | G9: 75.29 | H9: 37.79 | I9: 71.44 | J9: 180.72 | K9: 180.72 | L9: 180.82 | M9: 11.39 | N9: 13.04 | O9: 13.05 | P9: 13.05 | Q9: 25.48 | R9: 10.2 | S9: 65.89 | T9: 0 | U9: 0 | V9: 23.54 | W9: 46.86 | X9: 89.73 | Y9: 128.81 | Z9: 128.81 | AA9: 62.71 | AB9: 106.1
A10: 1 | C10: 기타유동자산 | E10: 3124.35 | F10: 3124.35 | G10: 4963.03 | H10: 4537.13 | I10: 3000.04 | J10: 2523.38 | K10: 2523.38 | L10: 3496.34 | M10: 2123.46 | N10: 2460.4 | O10: 1636.69 | P10: 1636.69 | Q10: 2662.46 | R10: 1805.61 | S10: 2165.68 | T10: 2468.44 | U10: 2468.44 | V10: 2263.09 | W10: 2084.75 | X10: 3683.96 | Y10: 4685.06 | Z10: 4685.06 | AA10: 9229.79 | AB10: 9313.92
A11: 1 | C11: 비유동자산 | E11: 276763.56 | F11: 276763.56 | G11: 274207.76 | H11: 274008.22 | I11: 269826.5 | J11: 262248.66 | K11: 262248.66 | L11: 260318.99 | M11: 255499.34 | N11: 255463.62 | O11: 281674.2 | P11: 281674.2 | Q11: 279624.19 | R11: 282181.74 | S11: 271154.45 | T11: 269611.03 | U11: 269611.03 | V11: 266348.32 | W11: 203522.89 | X11: 197868.21 | Y11: 149129.23 | Z11: 149129.23 | AA11: 145564.36 | AB11: 146793.08
A12: 1 | C12: 장기금융자산 | E12: 2500.98 | F12: 2500.98 | G12: 2141.85 | H12: 2719.21 | I12: 2169.34 | J12: 1236.1 | K12: 1236.1 | L12: 1149.53 | M12: 1296.68 | N12: 921.19 | O12: 1634.75 | P12: 1634.75 | Q12: 492.46 | R12: 728.25 | S12: 700.17 | T12: 600.15 | U12: 600.15 | V12: -146.2 | W12: 126.22 | X12: 29.65 | Y12: 39.45 | Z12: 39.45 | AA12: 1791.31 | AB12: 2526.32
A13: 1 | C13: 투자자산 | E13: 2707.66 | F13: 2707.66 | G13: 3730.69 | H13: 4814.13 | I13: 5185.22 | J13: 4191.95 | K13: 4191.95 | L13: 4154.73 | M13: 4156.28 | N13: 3744.84 | O13: 4290.52 | P13: 4290.52 | Q13: 3089.78 | R13: 3094.69 | S13: 3164.65 | T13: 2944.87 | U13: 2944.87 | V13: 2263.43 | W13: 2149.89 | X13: 1961.35 | Y13: 1870.66 | Z13: 1870.66 | AA13: 3706.53 | AB13: 4434.8
A14: 1 | C14: 장기매출채권및기타채권 | E14: 383.55 | F14: 383.55 | G14: 363.6 | H14: 343.65 | I14: 323.7 | J14: 303.75 | K14: 303.75 | L14: 283.8 | M14: 90.86 | N14: 59.85 | O14: 39.9 | P14: 39.9 | Q14: 19.95 | Y14: 1921.1 | Z14: 1921.1 | AB14: 2475.96
A15: 1 | C15: 종속기업및관계기업투자 | E15: 206.68 | F15: 206.68 | G15: 1588.84 | H15: 2094.92 | I15: 3015.88 | J15: 2955.85 | K15: 2955.85 | L15: 3005.2 | M15: 2859.6 | N15: 2823.65 | O15: 2655.77 | P15: 2655.77 | Q15: 2597.32 | R15: 2366.44 | S15: 2464.48 | T15: 2344.72 | U15: 2344.72 | V15: 2409.63 | W15: 2023.67 | X15: 1931.7 | Y15: 1831.21 | Z15: 1831.21 | AA15: 1915.22 | AB15: 1908.48
A16: 1 | C16: 유형자산 | E16: 239919.05 | F16: 239919.05 | G16: 237492.95 | H16: 235698.71 | I16: 234487.91 | J16: 230616.32 | K16: 230616.32 | L16: 229419.69 | M16: 227530.58 | N16: 228349.07 | O16: 258636.99 | P16: 258636.99 | Q16: 257152.14 | R16: 256891.35 | S16: 245788.81 | T16: 240474.8 | U16: 240474.8 | V16: 239800.62 | W16: 177882.57 | X16: 173162.02 | Y16: 125591.32 | Z16: 125591.32 | AA16: 123375.54 | AB16: 123100.04
A17: 1 | C17: 투자부동산 | E17: 2640.39 | F17: 2640.39 | G17: 2634.61 | H17: 2628.82 | M17: 1612.98 | N17: 1652.3
A18: 1 | C18: 사용권자산 | E18: 4897.58 | F18: 4897.58 | G18: 4703.51 | H18: 5220.52 | I18: 5336.87 | J18: 4896.03 | K18: 4896.03 | L18: 4965.52 | M18: 1459.7 | N18: 1585.21 | O18: 1528.34 | P18: 1528.34 | Q18: 2160.77 | R18: 1943.9 | S18: 1830.58 | T18: 1349.11 | U18: 1349.11 | V18: 1336.42 | W18: 2079.97 | X18: 2005.94 | Y18: 2087.38 | Z18: 2087.38 | AA18: 1060.61 | AB18: 1147.31
A19: 1 | C19: 기타비유동자산 | E19: 4945.13 | F19: 4945.13 | G19: 4748.53 | H19: 5277.71 | I19: 5398.36 | J19: 7663.76 | K19: 7663.76 | L19: 7525.57 | M19: 3855.9 | N19: 3967.18 | O19: 1773.81 | P19: 1773.81 | Q19: 2212.57 | R19: 1991.1 | S19: 1875.46 | T19: 1349.11 | U19: 1349.11 | V19: 1336.42 | W19: 2079.97 | X19: 2005.94 | Y19: 2099.36 | Z19: 2099.36 | AA19: 1072.59 | AB19: 1147.31
A20: 1 | C20: 무형자산 | E20: 19680.43 | F20: 19680.43 | G20: 19093.78 | H20: 18525.95 | I20: 17980.26 | J20: 17311.7 | K20: 17311.7 | L20: 16735.01 | M20: 16134.7 | N20: 15533.31 | O20: 14666.31 | P20: 14666.31 | Q20: 14082.01 | R20: 16645.74 | S20: 16551.91 | T20: 12662.67 | U20: 12662.67 | V20: 11722.73 | W20: 11352.87 | X20: 10911.51 | Y20: 10541.89 | Z20: 10541.89 | AA20: 10150.24 | AB20: 10143.76
A21: 1 | C21: 이연법인세자산 | E21: 1550.54 | F21: 1550.54 | G21: 1550.54 | H21: 1930.54 | I21: 1936.88 | J21: 26.46 | K21: 26.46 | L21: 27.22 | M21: 27.41 | N21: 28.07 | O21: 22.18 | P21: 22.18 | Q21: 809.66 | R21: 983.74 | S21: 1143.55 | T21: 6029.07 | U21: 6029.07 | V21: 5454.87 | W21: 5409.69 | X21: 4962.87 | Y21: 5559.29 | Z21: 5559.29 | AA21: 5273.01 | AB21: 5491.2
A22: 1 | C22: 자산총계 | E22: 518961.06 | F22: 518961.06 | G22: 531437.39 | H22: 557843.74 | I22: 536181.56 | J22: 535684.5 | K22: 535684.5 | L22: 528217.69 | M22: 522519.45 | N22: 514227.95 | O22: 544102.83 | P22: 544102.83 | Q22: 562139.97 | R22: 556028.14 | S22: 536149.2 | T22: 513396.1 | U22: 513396.1 | V22: 489106.95 | W22: 449288.28 | X22: 430664.3 | Y22: 399827.28 | Z22: 399827.28 | AA22: 389622.4 | AB22: 390504.61
A23: 1 | C23: 유동부채 | E23: 227367.77 | F23: 227367.77 | G23: 234813.89 | H23: 267634.17 | I23: 247355.69 | J23: 258920.5 | K23: 258920.5 | L23: 258290.3 | M23: 267833.21 | N23: 262558.71 | O23: 250149.72 | P23: 250149.72 | Q23: 272901.88 | R23: 267104.06 | S23: 252114.67 | T23: 239390.59 | U23: 239390.59 | V23: 217873.28 | W23: 218537.12 | X23: 213078.4 | Y23: 199657.31 | Z23: 199657.31 | AA23: 191560.33 | AB23: 184929.31
A24: 1 | C24: 매입채무및기타채무 | E24: 69523.35 | F24: 69523.35 | G24: 75572.47 | H24: 74602.98 | I24: 61280.35 | J24: 63763.3 | K24: 63763.3 | L24: 74497.36 | M24: 71402.85 | N24: 72070.14 | O24: 68812.44 | P24: 68812.44 | Q24: 79723.95 | R24: 79941.61 | S24: 69233.21 | T24: 68145.15 | U24: 68145.15 | V24: 59402.17 | W24: 67871.6 | X24: 64564.06 | Y24: 60123.73 | Z24: 60123.73 | AA24: 60397.11 | AB24: 68704.56
A25: 1 | C25: 단기차입금 | E25: 128047.99 | F25: 128047.99 | G25: 129056.26 | H25: 147198.76 | I25: 149378.34 | J25: 160834.85 | K25: 160834.85 | L25: 152352.87 | M25: 148524.7 | N25: 152031.34 | O25: 139635.63 | P25: 139635.63 | Q25: 146250.37 | R25: 144594.32 | S25: 142311.23 | T25: 143242.68 | U25: 143242.68 | V25: 144739.88 | W25: 118033.41 | X25: 115935.86 | Y25: 96735.11 | Z25: 96735.11 | AA25: 106190 | AB25: 97273.93
A26: 1 | C26: 유동성장기부채 | E26: 24055.28 | F26: 24055.28 | G26: 24609.3 | H26: 38684.7 | I26: 29953.32 | J26: 27062.47 | K26: 27062.47 | L26: 25903.52 | M26: 40868.81 | N26: 32462.14 | O26: 34106.92 | P26: 34106.92 | Q26: 43891.77 | R26: 37711.63 | S26: 35843.8 | T26: 19730.81 | U26: 19730.81 | V26: 10572.6 | W26: 16000 | X26: 16000 | Y26: 26484.18 | Z26: 26484.18 | AA26: 16000
A27: 1 | C27: 단기파생상품부채 | E27: 2188.07 | F27: 2188.07 | G27: 2575.9 | H27: 3155.03 | I27: 3352.05 | J27: 4151.77 | K27: 4151.77 | L27: 3509.91 | M27: 2703.54 | N27: 1638.14 | O27: 1479.47 | P27: 1479.47 | Q27: 1285.4 | R27: 889.57 | S27: 711.8 | T27: 999.33 | U27: 999.33 | V27: 69.71
A28: 1 | C28: 단기금융부채 | E28: 2831.8 | F28: 2831.8 | G28: 3121.86 | H28: 3681.33 | I28: 3821.52 | J28: 4705.52 | K28: 4705.52 | L28: 4095.61 | M28: 3171.72 | N28: 2067.68 | O28: 1934.94 | P28: 1934.94 | Q28: 1886.17 | R28: 1342.1 | S28: 1209.34 | T28: 1566.53 | U28: 1566.53 | V28: 672.03 | W28: 729.55 | X28: 712.37 | Y28: 860.43 | Z28: 860.43 | AA28: 578.22 | AB28: 629.17
A29: 1 | C29: 유동리스부채 | E29: 643.73 | F29: 643.73 | G29: 545.96 | H29: 526.3 | I29: 469.47 | J29: 553.75 | K29: 553.75 | L29: 585.7 | M29: 468.18 | N29: 429.54 | O29: 455.47 | P29: 455.47 | Q29: 600.77 | R29: 452.53 | S29: 497.54 | T29: 567.2 | U29: 567.2 | V29: 602.32 | W29: 729.55 | X29: 712.37 | Y29: 860.43 | Z29: 860.43 | AA29: 578.22 | AB29: 629.17
A30: 1 | C30: 리스부채 | E30: 1183.41 | F30: 1183.41 | G30: 986.04 | H30: 1208.14 | I30: 1078.99 | J30: 1148.65 | K30: 1148.65 | L30: 1161.74 | M30: 844.82 | N30: 994.54 | O30: 982.66 | P30: 982.66 | Q30: 1629.48 | R30: 1266.65 | S30: 1183.79 | T30: 1218.7 | U30: 1218.7 | V30: 1216.17 | W30: 1838.53 | X30: 1821.37 | Y30: 1931.05 | Z30: 1931.05 | AA30: 1024.27 | AB30: 1018.65
A31: 1 | C31: 단기충당부채 | E31: 424.66 | F31: 424.66 | G31: 346.21 | H31: 474.72 | I31: 448.26 | J31: 315.29 | K31: 315.29 | L31: 284.49 | M31: 366.45 | N31: 316.34 | O31: 408.27 | P31: 408.27 | Q31: 415.33 | R31: 428.57 | S31: 426.15 | T31: 383.37 | U31: 383.37 | V31: 377.41 | W31: 401.32 | X31: 409.98 | Y31: 397.68 | Z31: 397.68 | AA31: 409.42 | AB31: 434.33
A32: 1 | C32: 당기법인세부채(미지급법인세) | E32: 1190.17 | F32: 1190.17 | G32: 1084.6 | H32: 1082.67 | I32: 783.07 | J32: 648.12 | K32: 648.12 | L32: 433.92 | M32: 4.74 | N32: 4.85 | O32: 4.67 | P32: 4.67 | R32: 824.05 | S32: 156.2 | T32: 392.84 | U32: 392.84 | V32: 188.53 | W32: 0.9 | X32: 1.13 | Y32: 25.46 | Z32: 25.46 | AA32: 24.48 | AB32: 0.31
A33: 1 | C33: 기타유동부채 | E33: 1294.52 | F33: 1294.52 | G33: 1023.19 | H33: 1909.02 | I33: 1690.84 | J33: 1590.94 | K33: 1590.94 | L33: 722.52 | M33: 2994.8 | N33: 3517.63 | O33: 4220.43 | P33: 4220.43 | Q33: 386.87 | R33: 1780.18 | S33: 1867.79 | T33: 5037.37 | U33: 5037.37 | V33: 1625.44 | W33: 15295.68 | X33: 15397.7 | Y33: 15025.92 | Z33: 15025.92 | AA33: 7814.56 | AB33: 9778.52
A34: 1 | C34: 비유동부채 | E34: 93667.56 | F34: 93667.56 | G34: 99885.5 | H34: 87206.58 | I34: 83941.14 | J34: 78607.7 | K34: 78607.7 | L34: 75569.69 | M34: 64616.2 | N34: 61901.4 | O34: 64081.94 | P34: 64081.94 | Q34: 58739.31 | R34: 56521.96 | S34: 55881 | T34: 57168.43 | U34: 57168.43 | V34: 54885.02 | W34: 39445.14 | X34: 43996.47 | Y34: 35839.12 | Z34: 35839.12 | AA34: 34218.16 | AB34: 40470.48
A35: 1 | C35: 장기매입채무및기타채무 | E35: 1207.4 | F35: 1207.4 | G35: 1207.4 | H35: 1329.12 | I35: 1389.98 | J35: 1505.18 | K35: 1505.18 | L35: 1464.32 | O35: 1334.13 | P35: 1334.13 | Q35: 1327.16 | R35: 1709.54 | S35: 1764.28 | T35: 2114.96 | U35: 2114.96 | V35: 1981.33 | W35: 2190.52 | X35: 2262.04 | Y35: 2817.46 | Z35: 2817.46 | AA35: 2666.29 | AB35: 2583.03
A36: 1 | C36: 장기차입금 | E36: 40847.07 | F36: 40847.07 | G36: 38884.67 | H36: 34813.41 | I36: 31619.57 | J36: 29722.01 | K36: 29722.01 | L36: 26847.65 | M36: 35700.62 | N36: 28203.59 | O36: 25039.89 | P36: 25039.89 | Q36: 17992.86 | R36: 10071.17 | S36: 8200.36 | T36: 7416.94 | U36: 7416.94 | V36: 5268.97 | W36: 3160.82 | X36: 2494.73 | Y36: 2042.92 | Z36: 2042.92 | AA36: 1568.71 | AB36: 1399.23
A37: 1 | C37: 사채 | E37: 29296.23 | F37: 29296.23 | G37: 35716.05 | H37: 30000 | I37: 30000 | J37: 30000 | K37: 30000 | L37: 30000 | M37: 10000 | O37: 10000 | P37: 10000 | Q37: 10000 | R37: 16000 | S37: 16000 | T37: 16000 | U37: 16000 | V37: 16000 | W37: 8000 | X37: 8000 | Y37: 10594.46 | Z37: 10594.46 | AA37: 10184.36 | AB37: 16681.56
A38: 1 | C38: 장기파생상품부채 | E38: 1927.74 | F38: 1927.74 | G38: 3940.54 | Y38: 2091.1 | Z38: 2091.1 | AA38: 1760.05 | AB38: 1985.46
A39: 1 | C39: 장기금융부채 | E39: 2467.42 | F39: 2467.42 | G39: 4380.62 | H39: 681.84 | I39: 609.52 | J39: 594.9 | K39: 594.9 | L39: 576.04 | M39: 376.64 | N39: 565 | O39: 527.19 | P39: 527.19 | Q39: 1028.71 | R39: 814.12 | S39: 686.25 | T39: 651.5 | U39: 651.5 | V39: 613.85 | W39: 1108.98 | X39: 1109 | Y39: 3161.72 | Z39: 3161.72 | AA39: 2206.1 | AB39: 2374.94
A40: 1 | C40: 비유동리스부채 | E40: 539.68 | F40: 539.68 | G40: 440.08 | H40: 681.84 | I40: 609.52 | J40: 594.9 | K40: 594.9 | L40: 576.04 | M40: 376.64 | N40: 565 | O40: 527.19 | P40: 527.19 | Q40: 1028.71 | R40: 814.12 | S40: 686.25 | T40: 651.5 | U40: 651.5 | V40: 613.85 | W40: 1108.98 | X40: 1109 | Y40: 1070.62 | Z40: 1070.62 | AA40: 446.05 | AB40: 389.48
...

Sheet BS별도
B1: (백만원) | C1: 이름: BS별도H | E1: 4Q21 | F1: 2021 | G1: 1Q22 | H1: 2Q22 | I1: 3Q22 | J1: 4Q22 | K1: 2022 | L1: 1Q23 | M1: 2Q23 | N1: 3Q23 | O1: 4Q23 | P1: 2023 | Q1: 1Q24 | R1: 2Q24 | S1: 3Q24 | T1: 4Q24 | U1: 2024 | V1: 1Q25 | W1: 2Q25 | X1: 3Q25 | Y1: 4Q25 | Z1: 2025 | AA1: 1Q26 | AB1: 2Q26 | AC1: 3Q26 | AD1: 4Q26 | AE1: 2026 | AF1: 1Q27 | AG1: 2Q27 | AH1: 3Q27 | AI1: 4Q27 | AJ1: 2027 | AK1: 1Q28 | AL1: 2Q28 | AM1: 3Q28 | AN1: 4Q28 | AO1: 2028
B2: 별도 | D2: fin json(kship_fin.py)
B3: 영흥(별) | C3: UPDATE: 26-10-19 | E3: 1 | F3: 2 | G3: 3 | H3: 4 | I3: 5 | J3: 6 | K3: 7 | L3: 8 | M3: 9 | N3: 10 | O3: 11 | P3: 12 | Q3: 13 | R3: 14 | S3: 15 | T3: 16 | U3: 17 | V3: 18 | W3: 19 | X3: 20 | Y3: 21 | Z3: 22 | AA3: 23 | AB3: 24 | AC3: 25 | AD3: 26 | AE3: 27 | AF3: 28 | AG3: 29 | AH3: 30 | AI3: 31 | AJ3: 32 | AK3: 33 | AL3: 34 | AM3: 35 | AN3: 36 | AO3: 37
B4: Account Code | C4: AccountNAME | E4: 2021.12 | F4: 2021.12A | G4: 2022.03 | H4: 2022.06 | I4: 2022.09 | J4: 2022.12 | K4: 2022.12A | L4: 2023.03 | M4: 2023.06 | N4: 2023.09 | O4: 2023.12 | P4: 2023.12A | Q4: 2024.03 | R4: 2024.06 | S4: 2024.09 | T4: 2024.12 | U4: 2024.12A | V4: 2025.03 | W4: 2025.06 | X4: 2025.09 | Y4: 2025.12 | Z4: 2025.12A | AA4: 2026.03 | AB4: 2026.06 | AC4: 2026.09 | AD4: 2026.12 | AE4: 2026.12A | AF4: 2027.03 | AG4: 2027.06 | AH4: 2027.09 | AI4: 2027.12 | AJ4: 2027.12A | AK4: 2028.03 | AL4: 2028.06 | AM4: 2028.09 | AN4: 2028.12 | AO4: 2028.12A
A5: 1 | C5: 유동자산 | E5: 127901.24 | F5: 127901.24 | G5: 164885.18 | H5: 145861.32 | I5: 154932.85 | J5: 141742.41 | K5: 141742.41 | L5: 140617.91 | M5: 142277.94 | N5: 132883.29 | O5: 125139.44 | P5: 125139.44 | Q5: 94166.33 | R5: 88928.81 | S5: 94051.99 | T5: 96273.6 | U5: 96273.6 | V5: 82867.17 | W5: 107130.33 | X5: 95354.6 | Y5: 115943.86 | Z5: 115943.86 | AA5: 107329.74 | AB5: 107038.24
A6: 1 | C6: 현금및현금성자산 | E6: 3360.57 | F6: 3360.57 | G6: 7012.23 | H6: 5687.75 | I6: 3351.63 | J6: 6845.4 | K6: 6845.4 | L6: 4845.63 | M6: 8431.54 | N6: 6766.95 | O6: 6645.99 | P6: 6645.99 | Q6: 6439.27 | R6: 3477.55 | S6: 2431.1 | T6: 5449.63 | U6: 5449.63 | V6: 8557.64 | W6: 6558.62 | X6: 6266.19 | Y6: 6799.46 | Z6: 6799.46 | AA6: 3460.11 | AB6: 2785.19
A7: 1 | C7: 매출채권및기타채권 | E7: 61029.82 | F7: 61029.82 | G7: 87025.47 | H7: 60190.68 | I7: 69955.76 | J7: 57049.32 | K7: 57049.32 | L7: 59458.06 | M7: 53663.29 | N7: 49552.02 | O7: 45480.96 | P7: 45480.96 | Q7: 41939.39 | R7: 39168.92 | S7: 37525.73 | T7: 36993.54 | U7: 36993.54 | V7: 30325.52 | W7: 29243.14 | X7: 27296.55 | Y7: 24742.12 | Z7: 24742.12 | AA7: 16472.27 | AB7: 23359.13
A8: 1 | C8: 재고자산 | E8: 62453.75 | F8: 62453.75 | G8: 69119.13 | H8: 78099.51 | I8: 77480.31 | J8: 74229.77 | K8: 74229.77 | L8: 74947.19 | M8: 72206.44 | N8: 68554.08 | O8: 65897.36 | P8: 65897.36 | Q8: 44203.07 | R8: 44908.39 | S8: 42164.5 | T8: 37654.88 | U8: 37654.88 | V8: 32695.89 | W8: 25064.08 | X8: 14497.97 | Y8: 12947.24 | Z8: 12947.24 | AA8: 14445.84 | AB8: 15118.11
A9: 1 | C9: 기타유동자산 | E9: 1057.1 | F9: 1057.1 | G9: 1728.36 | H9: 1883.38 | I9: 1518.25 | J9: 965.31 | K9: 965.31 | L9: 1351.9 | M9: 1863.84 | N9: 1975.53 | O9: 1287.33 | P9: 1287.33 | Q9: 1572.08 | R9: 1373.94 | S9: 1454.08 | T9: 2025.46 | U9: 2025.46 | V9: 839.28 | W9: 1312.18 | X9: 2321.34 | AA9: 7254.34
A10: 1 | C10: 비유동자산 | E10: 217848.15 | F10: 217848.15 | G10: 219495.62 | H10: 220410.14 | I10: 218293.54 | J10: 212406.83 | K10: 212406.83 | L10: 210319.27 | M10: 203174.07 | N10: 203641.3 | O10: 251420.99 | P10: 251420.99 | Q10: 253032.35 | R10: 251803.19 | S10: 239006.39 | T10: 233754.28 | U10: 233754.28 | V10: 230950.42 | W10: 170468.29 | X10: 166163.42 | Y10: 118525.69 | Z10: 118525.69 | AA10: 116357.85 | AB10: 116464.28
A11: 1 | C11: 장기금융자산 | E11: 1669.98 | F11: 1669.98 | G11: 1307.85 | H11: 1552.21 | I11: 999.34 | J11: 1053.1 | K11: 1053.1 | L11: 963.53 | M11: 1107.68 | N11: 917.19 | O11: 1632.75 | P11: 1632.75 | Q11: 475.13 | R11: 710.36 | S11: 680.97 | T11: 576.45 | U11: 576.45 | V11: -173.48 | W11: 97.05 | X11: -2.96 | Y11: 3.5 | Z11: 3.5 | AA11: 1751.02 | AB11: 3.5
A12: 1 | C12: 투자자산 | E12: 51031.11 | F12: 51031.11 | G12: 54391.27 | H12: 56551.56 | I12: 57762.42 | J12: 54465.77 | K12: 54465.77 | L12: 53116.52 | M12: 47004.12 | N12: 47155.38 | O12: 49607.17 | P12: 49607.17 | Q12: 78921.45 | R12: 78482.68 | S12: 76968.77 | T12: 72148.96 | U12: 72148.96 | V12: 70042.65 | W12: 69767.28 | X12: 69971.61 | Y12: 69360.91 | Z12: 69360.91 | AA12: 69902.03 | AB12: 1186.35
A13: 1 | C13: 장기매출채권및기타채권 | E13: 383.55 | F13: 383.55 | G13: 363.6 | H13: 343.65 | I13: 323.7 | J13: 303.75 | K13: 303.75 | L13: 283.8 | M13: 90.86 | N13: 59.85 | O13: 39.9 | P13: 39.9 | Q13: 19.95 | Y13: 1376.35 | Z13: 1376.35 | AB13: 1334.57
A14: 1 | C14: 종속기업및관계기업투자 | E14: 49361.13 | F14: 49361.13 | G14: 53083.42 | H14: 54999.35 | I14: 56763.08 | J14: 53412.67 | K14: 53412.67 | L14: 52152.99 | M14: 45896.44 | N14: 46238.19 | O14: 47974.42 | P14: 47974.42 | Q14: 78446.32 | R14: 77772.32 | S14: 76287.8 | T14: 71572.51 | U14: 71572.51 | V14: 70216.13 | W14: 69670.23 | X14: 69974.57 | Y14: 69357.41 | Z14: 69357.41 | AA14: 68151.01 | AB14: 1182.85
A15: 1 | C15: 유형자산 | E15: 158538.58 | F15: 158538.58 | G15: 156913 | H15: 155045.38 | I15: 154136.5 | J15: 151895.47 | K15: 151895.47 | L15: 151092.29 | M15: 150350.6 | N15: 150378.8 | O15: 196221.28 | P15: 196221.28 | Q15: 168460.71 | R15: 167716.38 | S15: 156588.62 | T15: 155822.43 | U15: 155822.43 | V15: 155181.74 | W15: 94595.84 | X15: 90062.63 | Y15: 44349.98 | Z15: 44349.98 | AA15: 44125.33 | AB15: 44075.83
A16: 1 | C16: 투자부동산 | E16: 2640.39 | F16: 2640.39 | G16: 2634.61 | H16: 2628.82
A17: 1 | C17: 사용권자산 | E17: 588.19 | F17: 588.19 | G17: 465.1 | H17: 938.1 | I17: 828.68 | J17: 906.3 | K17: 906.3 | L17: 904.16 | M17: 789.05 | N17: 990.23 | O17: 993.18 | P17: 993.18 | Q17: 947.8 | R17: 879.51 | S17: 854.39 | T17: 819.75 | U17: 819.75 | V17: 765.19 | W17: 1430.01 | X17: 1360.87 | Y17: 1446.58 | Z17: 1446.58 | AA17: 494.26 | AB17: 572.45
A18: 1 | C18: 기타비유동자산 | E18: 588.19 | F18: 588.19 | G18: 465.1 | H18: 938.1 | I18: 828.68 | J18: 906.3 | K18: 906.3 | L18: 904.16 | M18: 789.05 | N18: 990.23 | O18: 993.18 | P18: 993.18 | Q18: 947.8 | R18: 879.51 | S18: 854.39 | T18: 819.75 | U18: 819.75 | V18: 765.19 | W18: 1430.01 | X18: 1360.87 | Y18: 1446.58 | Z18: 1446.58 | AA18: 494.26 | AB18: 572.45
A19: 1 | C19: 무형자산 | E19: 865.13 | F19: 865.13 | G19: 859.85 | H19: 854.58 | I19: 849.31 | J19: 844.03 | K19: 844.03 | L19: 838.76 | M19: 829.78 | N19: 824.63 | O19: 569.48 | P19: 569.48 | Q19: 547.71 | R19: 543.43 | S19: 539.15 | T19: 534.88 | U19: 534.88 | V19: 530.6 | W19: 526.32 | X19: 450.55 | Y19: 446.27 | Z19: 446.27 | AA19: 442 | AB19: 437.72
A20: 1 | C20: 자산총계 | E20: 345749.39 | F20: 345749.39 | G20: 384380.8 | H20: 366271.45 | I20: 373226.39 | J20: 354149.24 | K20: 354149.24 | L20: 350937.17 | M20: 345452.01 | N20: 336524.6 | O20: 376560.43 | P20: 376560.43 | Q20: 347198.68 | R20: 340732 | S20: 333058.38 | T20: 330027.88 | U20: 330027.88 | V20: 313817.59 | W20: 277598.62 | X20: 261518.02 | Y20: 234469.55 | Z20: 234469.55 | AA20: 223687.59 | AB20: 223502.53
A21: 1 | C21: 유동부채 | E21: 130296.6 | F21: 130296.6 | G21: 160202.96 | H21: 147182.86 | I21: 150830.49 | J21: 141008.46 | K21: 141008.46 | L21: 141086.61 | M21: 138958.89 | N21: 132392.72 | O21: 126842.33 | P21: 126842.33 | Q21: 106003.09 | R21: 102103.74 | S21: 98521.2 | T21: 99935.53 | U21: 99935.53 | V21: 85385.22 | W21: 79901.85 | X21: 76283.43 | Y21: 66219.35 | Z21: 66219.35 | AA21: 56785.88 | AB21: 55933.12
A22: 1 | C22: 매입채무및기타채무 | E22: 29031.44 | F22: 29031.44 | G22: 53510.93 | H22: 28875.12 | I22: 32416.48 | J22: 21967.6 | K22: 21967.6 | L22: 27230.36 | M22: 23350.21 | N22: 27008.4 | O22: 26884.98 | P22: 26884.98 | Q22: 22199.57 | R22: 22804.77 | S22: 22141.54 | T22: 18933.99 | U22: 18933.99 | V22: 15913.82 | W22: 12780.83 | X22: 12896.18 | Y22: 1628.13 | Z22: 1628.13 | AA22: 10379.15 | AB22: 1724.34
A23: 1 | C23: 단기차입금 | E23: 84636.25 | F23: 84636.25 | G23: 89193.14 | H23: 96257.78 | I23: 96179.3 | J23: 98707.12 | K23: 98707.12 | L23: 94612.33 | M23: 96758.42 | N23: 96768.68 | O23: 90823.85 | P23: 90823.85 | Q23: 79509.35 | R23: 76160.89 | S23: 74341.05 | T23: 74617.37 | U23: 74617.37 | V23: 67182.87 | W23: 51367.21 | X23: 47928.97 | Y23: 41853.93 | Z23: 41853.93 | AA23: 39011.9 | AB23: 36479.76
A24: 1 | C24: 유동성장기부채 | E24: 12891.14 | F24: 12891.14 | G24: 13536.56 | H24: 17716.09 | I24: 18097.83 | J24: 15564.94 | K24: 15564.94 | L24: 15927.26 | M24: 14465.55 | N24: 5839.97 | O24: 3771.31 | P24: 3771.31 | Q24: 2986.46 | R24: 970
A25: 1 | C25: 단기파생상품부채 | E25: 2133.55 | F25: 2133.55 | G25: 2521.39 | H25: 1946.64 | I25: 1909.67 | J25: 2453.74 | K25: 2453.74 | L25: 2220.78 | M25: 1872.54 | N25: 771.33 | O25: 503.38 | P25: 503.38 | Q25: 273.08 | R25: 53.47
A26: 1 | C26: 단기금융부채 | E26: 2432.95 | F26: 2432.95 | G26: 2762.06 | H26: 2238.9 | I26: 2151.86 | J26: 2779.12 | K26: 2779.12 | L26: 2581.58 | M26: 2189.53 | N26: 1108.22 | O26: 906.3 | P26: 906.3 | Q26: 718.27 | R26: 278.6 | S26: 340.22 | T26: 378.21 | U26: 378.21 | V26: 399.18 | W26: 496.57 | X26: 456.7 | Y26: 591.46 | Z26: 591.46 | AA26: 325.87 | AB26: 391.41
A27: 1 | C27: 유동리스부채 | E27: 299.4 | F27: 299.4 | G27: 240.67 | H27: 292.26 | I27: 242.19 | J27: 325.38 | K27: 325.38 | L27: 360.8 | M27: 316.99 | N27: 336.89 | O27: 402.92 | P27: 402.92 | Q27: 445.19 | R27: 225.13 | S27: 340.22 | T27: 378.21 | U27: 378.21 | V27: 399.18 | W27: 496.57 | X27: 456.7 | Y27: 591.46 | Z27: 591.46 | AA27: 325.87 | AB27: 391.41
A28: 1 | C28: 리스부채 | E28: 519.11 | F28: 519.11 | G28: 432.37 | H28: 788.86 | I28: 716.84 | J28: 829.05 | K28: 829.05 | L28: 867.86 | M28: 671.21 | N28: 897.29 | O28: 929.31 | P28: 929.31 | Q28: 928.23 | R28: 708.67 | S28: 700.19 | T28: 699.25 | U28: 699.25 | V28: 691.55 | W28: 1230.13 | X28: 1204.58 | Y28: 1324.16 | Z28: 1324.16 | AA28: 482.71 | AB28: 516.51
A29: 1 | C29: 단기충당부채 | E29: 69.08 | F29: 69.08 | G29: 55.5 | H29: 51.71 | I29: 49.78 | J29: 46.98 | K29: 46.98 | L29: 39.79 | M29: 34.45 | N29: 30.76 | O29: 29.09 | P29: 29.09
A30: 1 | C30: 당기법인세부채(미지급법인세) | E30: 559.53 | F30: 559.53 | G30: 741.19 | H30: 912.1 | I30: 761.01 | J30: 648.12 | K30: 648.12 | L30: 433.92 | R30: 698.06 | T30: 198.01 | U30: 198.01 | V30: 91.12
A31: 1 | C31: 기타유동부채 | E31: 676.19 | F31: 676.19 | G31: 403.58 | H31: 1131.17 | I31: 1174.24 | J31: 1294.58 | K31: 1294.58 | L31: 261.37 | M31: 1058.79 | N31: 1061.46 | O31: 3877.98 | P31: 3877.98 | Q31: -4.84 | R31: 215.48 | S31: 218.12 | T31: 4552.33 | U31: 4552.33 | V31: 1354.07 | W31: 14900.51 | X31: 14821.54 | Y31: 14429.11 | Z31: 14429.11 | AA31: 7012.71 | AB31: 9134.11
A32: 1 | C32: 비유동부채 | E32: 43195.1 | F32: 43195.1 | G32: 49728.91 | H32: 40083.93 | I32: 41943.38 | J32: 36057.4 | K32: 36057.4 | L32: 33858.02 | M32: 32385.53 | N32: 30605.64 | O32: 38705.32 | P32: 38705.32 | Q32: 29630.41 | R32: 27768.75 | S32: 26842.97 | T32: 28479.69 | U32: 28479.69 | V32: 26919.31 | W32: 20919.77 | X32: 25669.92 | Y32: 16986.03 | Z32: 16986.03 | AA32: 15382.86 | AB32: 14976.72
A33: 1 | C33: 장기매입채무및기타채무 | E33: 142.56 | F33: 142.56 | G33: 142.56 | H33: 153.09 | I33: 158.36 | J33: 163.18 | K33: 163.18 | L33: 169.67 | Q33: 129.66 | R33: 134.49 | S33: 139.32 | T33: 146.3 | U33: 146.3 | V33: 151.14 | W33: 155.99 | X33: 160.62 | Y33: 44.54 | Z33: 44.54 | AA33: 46.59 | AB33: 48.63
A34: 1 | C34: 장기차입금 | E34: 25583.84 | F34: 25583.84 | G34: 24757.06 | H34: 21423.14 | I34: 23196.36 | J34: 20586.25 | K34: 20586.25 | L34: 18392.8 | M34: 16199.35 | N34: 14005.91 | O34: 11812.46 | P34: 11812.46 | Q34: 5833.33 | R34: 4166.67 | S34: 2500 | T34: 1250 | U34: 1250
A35: 1 | C35: 비유동리스부채 | E35: 219.71 | F35: 219.71 | G35: 191.7 | H35: 496.6 | I35: 474.65 | J35: 503.67 | K35: 503.67 | L35: 507.06 | M35: 354.22 | N35: 560.4 | O35: 526.39 | P35: 526.39 | Q35: 483.04 | R35: 483.54 | S35: 359.97 | T35: 321.04 | U35: 321.04 | V35: 292.37 | W35: 733.56 | X35: 747.88 | Y35: 732.7 | Z35: 732.7 | AA35: 156.84 | AB35: 125.1
A36: 1 | C36: 장기금융부채 | E36: 219.71 | F36: 219.71 | G36: 1531.81 | H36: 496.6 | I36: 474.65 | J36: 503.67 | K36: 503.67 | L36: 507.06 | M36: 354.22 | N36: 560.4 | O36: 526.39 | P36: 526.39 | Q36: 483.04 | R36: 483.54 | S36: 359.97 | T36: 321.04 | U36: 321.04 | V36: 292.37 | W36: 733.56 | X36: 747.88 | Y36: 2823.8 | Z36: 2823.8 | AA36: 1916.89 | AB36: 2110.56
A37: 1 | C37: 확정급여부채 | E37: 6132.63 | F37: 6132.63 | G37: 6637.91 | H37: 7171.06 | I37: 7482.27 | J37: 4775.05 | K37: 4775.05 | L37: 4739.98 | M37: 4868.53 | N37: 5146.41 | O37: 5863.45 | P37: 5863.45 | Q37: 2135.54 | R37: 2423.84 | S37: 2725.84 | T37: 5638.04 | U37: 5638.04 | V37: 5441.07 | W37: 5080.83 | X37: 3778.42 | Y37: 2474.33 | Z37: 2474.33 | AA37: 2186.12 | AB37: 2339.13
A38: 1 | C38: 이연법인세부채 | E38: 11116.36 | F38: 11116.36 | G38: 10576.49 | H38: 10840.04 | I38: 10631.75 | J38: 10029.25 | K38: 10029.25 | L38: 10048.51 | M38: 10546.53 | N38: 10528.54 | O38: 20117.68 | P38: 20117.68 | Q38: 20904.17 | R38: 20265.25 | S38: 20904.17 | T38: 20983.01 | U38: 20983.01 | V38: 20983.01 | W38: 14949.4 | X38: 20983.01 | Y38: 9048.91 | Z38: 9048.91 | AA38: 9048.91 | AB38: 8196.84
A39: 1 | C39: 부채총계 | E39: 173491.69 | F39: 173491.69 | G39: 209931.87 | H39: 187266.79 | I39: 192773.87 | J39: 177065.86 | K39: 177065.86 | L39: 174944.64 | M39: 171344.41 | N39: 162998.36 | O39: 165547.65 | P39: 165547.65 | Q39: 135633.5 | R39: 129872.49 | S39: 125364.17 | T39: 128415.21 | U39: 128415.21 | V39: 112304.53 | W39: 100821.62 | X39: 101953.35 | Y39: 83205.39 | Z39: 83205.39 | AA39: 72168.74 | AB39: 70909.85
A40: 1 | C40: 자본금 | E40: 50655.19 | F40: 50655.19 | G40: 50655.19 | H40: 50655.19 | I40: 50655.19 | J40: 50655.19 | K40: 50655.19 | L40: 50655.19 | M40: 50655.19 | N40: 50655.19 | O40: 50655.19 | P40: 50655.19 | Q40: 50655.19 | R40: 50655.19 | S40: 50655.19 | T40: 50655.19 | U40: 50655.19 | V40: 50655.19 | W40: 50655.19 | X40: 50655.19 | Y40: 50655.19 | Z40: 50655.19 | AA40: 50655.19 | AB40: 39051.76
...

Sheet subQ
A1: YQ | C1: subQ 분기 서브모델(억원, U=100) | E1: 4Q21 | F1: 2021 | G1: 1Q22 | H1: 2Q22 | I1: 3Q22 | J1: 4Q22 | K1: 2022 | L1: 1Q23 | M1: 2Q23 | N1: 3Q23 | O1: 4Q23 | P1: 2023 | Q1: 1Q24 | R1: 2Q24 | S1: 3Q24 | T1: 4Q24 | U1: 2024 | V1: 1Q25 | W1: 2Q25 | X1: 3Q25 | Y1: 4Q25 | Z1: 2025 | AA1: 1Q26 | AB1: 2Q26 | AC1: 3Q26 | AD1: 4Q26 | AE1: 2026 | AF1: 1Q27 | AG1: 2Q27 | AH1: 3Q27 | AI1: 4Q27 | AJ1: 2027 | AK1: 1Q28 | AL1: 2Q28 | AM1: 3Q28 | AN1: 4Q28 | AO1: 2028
A2: A=이름(key) B=그룹 C=단위 D=FnGuide 계정명(VLOOKUP 키). 확정=VLOOKUP(BS), 추정=변수 가정 참조
E3: 1 | F3: 2 | G3: 3 | H3: 4 | I3: 5 | J3: 6 | K3: 7 | L3: 8 | M3: 9 | N3: 10 | O3: 11 | P3: 12 | Q3: 13 | R3: 14 | S3: 15 | T3: 16 | U3: 17 | V3: 18 | W3: 19 | X3: 20 | Y3: 21 | Z3: 22 | AA3: 23 | AB3: 24 | AC3: 25 | AD3: 26 | AE3: 27 | AF3: 28 | AG3: 29 | AH3: 30 | AI3: 31 | AJ3: 32 | AK3: 33 | AL3: 34 | AM3: 35 | AN3: 36 | AO3: 37
E4: 2021.12 | F4: 2021.12A | G4: 2022.03 | H4: 2022.06 | I4: 2022.09 | J4: 2022.12 | K4: 2022.12A | L4: 2023.03 | M4: 2023.06 | N4: 2023.09 | O4: 2023.12 | P4: 2023.12A | Q4: 2024.03 | R4: 2024.06 | S4: 2024.09 | T4: 2024.12 | U4: 2024.12A | V4: 2025.03 | W4: 2025.06 | X4: 2025.09 | Y4: 2025.12 | Z4: 2025.12A | AA4: 2026.03 | AB4: 2026.06 | AC4: 2026.09 | AD4: 2026.12 | AE4: 2026.12A | AF4: 2027.03 | AG4: 2027.06 | AH4: 2027.09 | AI4: 2027.12 | AJ4: 2027.12A | AK4: 2028.03 | AL4: 2028.06 | AM4: 2028.09 | AN4: 2028.12 | AO4: 2028.12A
A5: 매출액 | B5: 손익 | C5: 억원 | D5: 매출액(수익) | E5: =IFERROR(VLOOKUP($D5,BS연결,MATCH(E$1,BS연결H,0),0)/100,"") | G5: =IFERROR(VLOOKUP($D5,BS연결,MATCH(G$1,BS연결H,0),0)/100,"") | H5: =IFERROR(VLOOKUP($D5,BS연결,MATCH(H$1,BS연결H,0),0)/100,"") | I5: =IFERROR(VLOOKUP($D5,BS연결,MATCH(I$1,BS연결H,0),0)/100,"") | J5: =IFERROR(VLOOKUP($D5,BS연결,MATCH(J$1,BS연결H,0),0)/100,"") | K5: =IFERROR(VLOOKUP($D5,BS연결,MATCH(K$1,BS연결H,0),0)/100,"") | L5: =IFERROR(VLOOKUP($D5,BS연결,MATCH(L$1,BS연결H,0),0)/100,"") | M5: =IFERROR(VLOOKUP($D5,BS연결,MATCH(M$1,BS연결H,0),0)/100,"") | N5: =IFERROR(VLOOKUP($D5,BS연결,MATCH(N$1,BS연결H,0),0)/100,"") | ... AB5: =IFERROR(VLOOKUP($D5,BS연결,MATCH(AB$1,BS연결H,0),0)/100,"") | AC5: =IFERROR(X5*(1+변수!AC21),"") | AD5: =IFERROR(Y5*(1+변수!AD21),"") | AE5: =SUM(AA5:AD5) | AF5: =IFERROR(AA5*(1+변수!AF21),"") | AG5: =IFERROR(AB5*(1+변수!AG21),"") | AH5: =IFERROR(AC5*(1+변수!AH21),"") | AI5: =IFERROR(AD5*(1+변수!AI21),"") | AJ5: =SUM(AF5:AI5) | AK5: =IFERROR(AF5*(1+변수!AK21),"") | AL5: =IFERROR(AG5*(1+변수!AL21),"") | AM5: =IFERROR(AH5*(1+변수!AM21),"") | AN5: =IFERROR(AI5*(1+변수!AN21),"") | AO5: =SUM(AK5:AN5)
A6: 매출원가 | B6: 손익 | C6: 억원 | D6: 매출원가 | E6: =IFERROR(VLOOKUP($D6,BS연결,MATCH(E$1,BS연결H,0),0)/100,"") | G6: =IFERROR(VLOOKUP($D6,BS연결,MATCH(G$1,BS연결H,0),0)/100,"") | H6: =IFERROR(VLOOKUP($D6,BS연결,MATCH(H$1,BS연결H,0),0)/100,"") | I6: =IFERROR(VLOOKUP($D6,BS연결,MATCH(I$1,BS연결H,0),0)/100,"") | J6: =IFERROR(VLOOKUP($D6,BS연결,MATCH(J$1,BS연결H,0),0)/100,"") | K6: =IFERROR(VLOOKUP($D6,BS연결,MATCH(K$1,BS연결H,0),0)/100,"") | L6: =IFERROR(VLOOKUP($D6,BS연결,MATCH(L$1,BS연결H,0),0)/100,"") | M6: =IFERROR(VLOOKUP($D6,BS연결,MATCH(M$1,BS연결H,0),0)/100,"") | N6: =IFERROR(VLOOKUP($D6,BS연결,MATCH(N$1,BS연결H,0),0)/100,"") | ... AB6: =IFERROR(VLOOKUP($D6,BS연결,MATCH(AB$1,BS연결H,0),0)/100,"") | AC6: =IFERROR(AC5-AC7,"") | AD6: =IFERROR(AD5-AD7,"") | AE6: =SUM(AA6:AD6) | AF6: =IFERROR(AF5-AF7,"") | AG6: =IFERROR(AG5-AG7,"") | AH6: =IFERROR(AH5-AH7,"") | AI6: =IFERROR(AI5-AI7,"") | AJ6: =SUM(AF6:AI6) | AK6: =IFERROR(AK5-AK7,"") | AL6: =IFERROR(AL5-AL7,"") | AM6: =IFERROR(AM5-AM7,"") | AN6: =IFERROR(AN5-AN7,"") | AO6: =SUM(AK6:AN6)
A7: 매출총이익 | B7: 손익 | C7: 억원 | D7: 매출총이익 | E7: =IFERROR(VLOOKUP($D7,BS연결,MATCH(E$1,BS연결H,0),0)/100,"") | G7: =IFERROR(VLOOKUP($D7,BS연결,MATCH(G$1,BS연결H,0),0)/100,"") | H7: =IFERROR(VLOOKUP($D7,BS연결,MATCH(H$1,BS연결H,0),0)/100,"") | I7: =IFERROR(VLOOKUP($D7,BS연결,MATCH(I$1,BS연결H,0),0)/100,"") | J7: =IFERROR(VLOOKUP($D7,BS연결,MATCH(J$1,BS연결H,0),0)/100,"") | K7: =IFERROR(VLOOKUP($D7,BS연결,MATCH(K$1,BS연결H,0),0)/100,"") | L7: =IFERROR(VLOOKUP($D7,BS연결,MATCH(L$1,BS연결H,0),0)/100,"") | M7: =IFERROR(VLOOKUP($D7,BS연결,MATCH(M$1,BS연결H,0),0)/100,"") | N7: =IFERROR(VLOOKUP($D7,BS연결,MATCH(N$1,BS연결H,0),0)/100,"") | ... AB7: =IFERROR(VLOOKUP($D7,BS연결,MATCH(AB$1,BS연결H,0),0)/100,"") | AC7: =IFERROR(AC9+AC8,"") | AD7: =IFERROR(AD9+AD8,"") | AE7: =SUM(AA7:AD7) | AF7: =IFERROR(AF9+AF8,"") | AG7: =IFERROR(AG9+AG8,"") | AH7: =IFERROR(AH9+AH8,"") | AI7: =IFERROR(AI9+AI8,"") | AJ7: =SUM(AF7:AI7) | AK7: =IFERROR(AK9+AK8,"") | AL7: =IFERROR(AL9+AL8,"") | AM7: =IFERROR(AM9+AM8,"") | AN7: =IFERROR(AN9+AN8,"") | AO7: =SUM(AK7:AN7)
A8: 판관비 | B8: 손익 | C8: 억원 | D8: 판관비 | E8: =IFERROR(VLOOKUP($D8,BS연결,MATCH(E$1,BS연결H,0),0)/100,"") | G8: =IFERROR(VLOOKUP($D8,BS연결,MATCH(G$1,BS연결H,0),0)/100,"") | H8: =IFERROR(VLOOKUP($D8,BS연결,MATCH(H$1,BS연결H,0),0)/100,"") | I8: =IFERROR(VLOOKUP($D8,BS연결,MATCH(I$1,BS연결H,0),0)/100,"") | J8: =IFERROR(VLOOKUP($D8,BS연결,MATCH(J$1,BS연결H,0),0)/100,"") | K8: =IFERROR(VLOOKUP($D8,BS연결,MATCH(K$1,BS연결H,0),0)/100,"") | L8: =IFERROR(VLOOKUP($D8,BS연결,MATCH(L$1,BS연결H,0),0)/100,"") | M8: =IFERROR(VLOOKUP($D8,BS연결,MATCH(M$1,BS연결H,0),0)/100,"") | N8: =IFERROR(VLOOKUP($D8,BS연결,MATCH(N$1,BS연결H,0),0)/100,"") | ... Y8: =IFERROR(VLOOKUP($D8,BS연결,MATCH(Y$1,BS연결H,0),0)/100,"") | Z8: =SUM(V8:Y8) | AA8: =IFERROR(VLOOKUP($D8,BS연결,MATCH(AA$1,BS연결H,0),0)/100,"") | AB8: =IFERROR(VLOOKUP($D8,BS연결,MATCH(AB$1,BS연결H,0),0)/100,"") | AC8: =IFERROR(AC5*변수!AC22,"") | AD8: =IFERROR(AD5*변수!AD22,"") | AE8: =SUM(AA8:AD8) | AF8: =IFERROR(AF5*변수!AF22,"") | AG8: =IFERROR(AG5*변수!AG22,"") | AH8: =IFERROR(AH5*변수!AH22,"") | AI8: =IFERROR(AI5*변수!AI22,"") | AJ8: =SUM(AF8:AI8) | AK8: =IFERROR(AK5*변수!AK22,"") | AL8: =IFERROR(AL5*변수!AL22,"") | AM8: =IFERROR(AM5*변수!AM22,"") | AN8: =IFERROR(AN5*변수!AN22,"") | AO8: =SUM(AK8:AN8)
A9: 영업이익 | B9: 손익 | C9: 억원 | D9: 영업이익 | E9: =IFERROR(VLOOKUP($D9,BS연결,MATCH(E$1,BS연결H,0),0)/100,"") | G9: =IFERROR(VLOOKUP($D9,BS연결,MATCH(G$1,BS연결H,0),0)/100,"") | H9: =IFERROR(VLOOKUP($D9,BS연결,MATCH(H$1,BS연결H,0),0)/100,"") | I9: =IFERROR(VLOOKUP($D9,BS연결,MATCH(I$1,BS연결H,0),0)/100,"") | J9: =IFERROR(VLOOKUP($D9,BS연결,MATCH(J$1,BS연결H,0),0)/100,"") | K9: =IFERROR(VLOOKUP($D9,BS연결,MATCH(K$1,BS연결H,0),0)/100,"") | L9: =IFERROR(VLOOKUP($D9,BS연결,MATCH(L$1,BS연결H,0),0)/100,"") | M9: =IFERROR(VLOOKUP($D9,BS연결,MATCH(M$1,BS연결H,0),0)/100,"") | N9: =IFERROR(VLOOKUP($D9,BS연결,MATCH(N$1,BS연결H,0),0)/100,"") | ... AB9: =IFERROR(VLOOKUP($D9,BS연결,MATCH(AB$1,BS연결H,0),0)/100,"") | AC9: =IFERROR(AC5*변수!AC23,"") | AD9: =IFERROR(AD5*변수!AD23,"") | AE9: =SUM(AA9:AD9) | AF9: =IFERROR(AF5*변수!AF23,"") | AG9: =IFERROR(AG5*변수!AG23,"") | AH9: =IFERROR(AH5*변수!AH23,"") | AI9: =IFERROR(AI5*변수!AI23,"") | AJ9: =SUM(AF9:AI9) | AK9: =IFERROR(AK5*변수!AK23,"") | AL9: =IFERROR(AL5*변수!AL23,"") | AM9: =IFERROR(AM5*변수!AM23,"") | AN9: =IFERROR(AN5*변수!AN23,"") | AO9: =SUM(AK9:AN9)
A10: OPM | B10: 손익 | C10: % | D10: 영업이익률 | E10: =IFERROR(E9/E5,"") | G10: =IFERROR(G9/G5,"") | H10: =IFERROR(H9/H5,"") | I10: =IFERROR(I9/I5,"") | J10: =IFERROR(J9/J5,"") | K10: =IFERROR(K9/K5,"") | L10: =IFERROR(L9/L5,"") | M10: =IFERROR(M9/M5,"") | N10: =IFERROR(N9/N5,"") | ... AO10: =IFERROR(AO9/AO5,"")
