Workbook
Name 변수H: 변수!$C$1:$AJ$1
Name 환율: 변수!$C$6:$AJ$13
Name BS연결H: BS연결!$C$1:$AJ$1
Name BS연결: BS연결!$C$5:$AJ$5
Name BS별도H: BS별도!$C$1:$AJ$1
Name BS별도: BS별도!$C$5:$AJ$87
Name SUBQH: subQ!$A$1:$AJ$1
Name subQ: subQ!$A$5:$AJ$42

Sheet README
A1: 삼미금속(012210) 실적 모델 — ARGUS 한국조선
A2: 기준 분기 2026Q2 · 마지막 실적 2026Q2 · 생성 2026-10-13
A3: 모든 수치는 모델 산출값(DART 공개 재무제표 + 우리 추정)이다 — 목표주가·투자 추천 아님. 참고용 · 투자조언 아님.
A5: 시트
A6: 변수 가정 시계열. 환율 8행(ECB via frankfurter — L2 fx.json; 추정 분기 = 노란 가정), 추정 드라이버(노란 셀 = 모델값에서 역산한 가정, 바꾸면 재계산; 연녹 셀 = 3절 스칼라 참조 수식), 3절 스칼라 가정(세율·판관비율·지배주주비중·이자율·종가·PER 밴드·COE·외화 순노출·헤지비율)
A7: BS연결/BS별도 FnGuide 계정명 × 기간 값 덤프(백만원). 행1 분기라벨, 행4 YYYY.MM / YYYY.12A. 이름정의 BS연결H·BS연결(계정명 C열부터)
A8: subQ 분기 서브모델(억원 = 백만원/100). 확정 행: =IFERROR(VLOOKUP($D행,BS연결,MATCH(E$1,BS연결H,0),0)/100,"") 추정 행: 변수 시트 가정 셀 참조 수식. 외환손익·파생상품손익은 BS 계정 합·차, 기타금융손익은 잔차, OPM·EPS·BPS·PER·PBR 은 파생 수식, 조정EPS 는 EPS 참조(일회성 의심 분기만 산식 셀)
A9: SLS 선표(조선사만, sls json 있을 때): 요약 행(sls 저장값) + 계약별 스케줄(백만$) × (헤지비율 × 헤지환율 + (1−헤지비율) × 건조시점 환율[변수 원/달러(평균)]) → 원화 수식 블록 → 합계 행이 subQ 매출조선에 연결
A10: 시나리오 신규수주 보수/기준/낙관(forecast_panel 패널, 모델에 scenarios 가 있을 때만): 매출액·영업이익 = subQ 기준값 ± (시나리오 신규 − base 신규) × OPM. base 만 subQ 행에 포함, 나머지는 합산 안 함
A11: 분기/연간예상 subQ 를 이름(A열 key)으로 VLOOKUP 한 보고서 표(억원)
A12: TP PER 밴드 × 12M fwd EPS, PBR = ROE/COE × BPS — 모델 산출값 구간, 목표주가·추천 아님
A13: 외화 환율 QoQ, 외화 순노출 × Δ기말환율 → 환관련손익 추정
... A35: 백테스트: {"freeze": "2025Q2", "horizon": 4, "revenue_wape_pct": 10.5, "op_wape_pct": 36.8, "n": 4, "note": "단일 회사 4분기 — 통계 아님", "driver_at_freeze": "trend_seasonal", "selection_oos_at_freeze": null, "frozen_inputs": "fin(연결/별도)·고객 조선사 모델·지주 자회사 모델은 2025Q2 까지의 분기만; 선표는 체결일 ≤ 2025Q2 말일 계약(원장 최신 금액·코호트 등급, 환산 없음); 잔고는 yards_cache 2025Q2; 시세·환율 forward·prices·forecast_panel 신규수주 미사용. 고객 가중치(suppliers.json 언급 비중)와 합병 체인링크는 현재 지식; 고객 연동 채택은 동결 모델 안에서도 자기 la−4분기 OOS 규칙(selection_oos_at_freeze)", "detail": [{"q": "2025Q3", "rev_pred": 204.6, "rev_act": 175.5, "op_pred": 11.58, "op_act": 9.26}, {"q": "2025Q4", "rev_pred": 183.54, "rev_act": 160.11, "op_pred": 10.39, "op_act": 14.58}, {"q": "2026Q1", "rev_pred": 204.6, "rev_act": 182.59, "op_pred": 11.58, "op_act": 16.02}, {"q": "2026Q2", "rev_pred": 225.66, "rev_act": 222.59, "op_pred": 12.77, "op_act": 26.07}]}

Sheet 변수
C1: 이름: 변수H | E1: 4Q22 | F1: 2022 | G1: 1Q23 | H1: 2Q23 | I1: 3Q23 | J1: 4Q23 | K1: 2023 | L1: 1Q24 | M1: 2Q24 | N1: 3Q24 | O1: 4Q24 | P1: 2024 | Q1: 1Q25 | R1: 2Q25 | S1: 3Q25 | T1: 4Q25 | U1: 2025 | V1: 1Q26 | W1: 2Q26 | X1: 3Q26 | Y1: 4Q26 | Z1: 2026 | AA1: 1Q27 | AB1: 2Q27 | AC1: 3Q27 | AD1: 4Q27 | AE1: 2027 | AF1: 1Q28 | AG1: 2Q28 | AH1: 3Q28 | AI1: 4Q28 | AJ1: 2028
A2: 가정 시계열 — 노란 셀은 추정 가정(모델값에서 역산), 연녹 셀은 3절 스칼라 참조 수식. 바꾸면 subQ·분기·연간예상·TP·시나리오가 재계산됩니다.
E3: 1 | F3: 2 | G3: 3 | H3: 4 | I3: 5 | J3: 6 | K3: 7 | L3: 8 | M3: 9 | N3: 10 | O3: 11 | P3: 12 | Q3: 13 | R3: 14 | S3: 15 | T3: 16 | U3: 17 | V3: 18 | W3: 19 | X3: 20 | Y3: 21 | Z3: 22 | AA3: 23 | AB3: 24 | AC3: 25 | AD3: 26 | AE3: 27 | AF3: 28 | AG3: 29 | AH3: 30 | AI3: 31 | AJ3: 32
E4: 2022.12 | F4: 2022.12A | G4: 2023.03 | H4: 2023.06 | I4: 2023.09 | J4: 2023.12 | K4: 2023.12A | L4: 2024.03 | M4: 2024.06 | N4: 2024.09 | O4: 2024.12 | P4: 2024.12A | Q4: 2025.03 | R4: 2025.06 | S4: 2025.09 | T4: 2025.12 | U4: 2025.12A | V4: 2026.03 | W4: 2026.06 | X4: 2026.09 | Y4: 2026.12 | Z4: 2026.12A | AA4: 2027.03 | AB4: 2027.06 | AC4: 2027.09 | AD4: 2027.12 | AE4: 2027.12A | AF4: 2028.03 | AG4: 2028.06 | AH4: 2028.09 | AI4: 2028.12 | AJ4: 2028.12A
B5: 1. FX | C5: 이름: 환율
A6: USDKRW_avg | C6: 원/달러(평균) | E6: 1360.12 | F6: 1292.98 | G6: 1276.95 | H6: 1315.69 | I6: 1313.62 | J6: 1322.01 | K6: 1306.85 | L6: 1330.14 | M6: 1371.28 | N6: 1356.22 | O6: 1396.3 | P6: 1363.53 | Q6: 1452.28 | R6: 1398.52 | S6: 1386.95 | T6: 1449.19 | U6: 1421.52 | V6: 1466.12 | W6: 1501.75 | X6: 1418.75 | Y6: 1343.63 | Z6: 1456.58 | AA6: 1333.09 | AB6: 1333.09 | AC6: 1333.09 | AD6: 1333.09 | AF6: 1333.09 | AG6: 1333.09 | AH6: 1333.09 | AI6: 1333.09
A7: USDKRW_end | C7: 원/달러(기말) | E7: 1260.16 | F7: 1260.16 | G7: 1305.99 | H7: 1321.44 | I7: 1345.35 | J7: 1297.43 | K7: 1297.43 | L7: 1349.25 | M7: 1377.73 | N7: 1312.17 | O7: 1474.78 | P7: 1474.78 | Q7: 1474.54 | R7: 1355.13 | S7: 1403.67 | T7: 1444.2 | U7: 1444.2 | V7: 1524.8 | W7: 1550.89 | X7: 1355.4 | Y7: 1333.09 | Z7: 1333.09 | AA7: 1333.09 | AB7: 1333.09 | AC7: 1333.09 | AD7: 1333.09 | AF7: 1333.09 | AG7: 1333.09 | AH7: 1333.09 | AI7: 1333.09
A8: JPY100KRW_avg | C8: 원/100Y(평균) | E8: 961.03 | F8: 985.1 | G8: 964.89 | H8: 957.36 | I8: 909 | J8: 893.22 | K8: 931.11 | L8: 896.29 | M8: 880.14 | N8: 909.35 | O8: 917.25 | P8: 900.92 | Q8: 952.59 | R8: 967.92 | S8: 940.32 | T8: 940.77 | U8: 950.17 | V8: 934.39 | W8: 942.16 | X8: 890.41 | Y8: 849.51 | Z8: 918.81 | AA8: 840.54 | AB8: 840.54 | AC8: 840.54 | AD8: 840.54 | AF8: 840.54 | AG8: 840.54 | AH8: 840.54 | AI8: 840.54
A9: JPY100KRW_end | C9: 원/100Y(기말) | E9: 955.54 | F9: 955.54 | G9: 980.62 | H9: 913.67 | I9: 901.47 | J9: 917.04 | K9: 917.04 | L9: 892.42 | M9: 857.76 | N9: 919.21 | O9: 939.65 | P9: 939.65 | Q9: 986.84 | R9: 938.85 | S9: 948.49 | T9: 921.81 | U9: 921.81 | V9: 955.99 | W9: 954.75 | X9: 863.31 | Y9: 840.54 | Z9: 840.54 | AA9: 840.54 | AB9: 840.54 | AC9: 840.54 | AD9: 840.54 | AF9: 840.54 | AG9: 840.54 | AH9: 840.54 | AI9: 840.54
A10: EURKRW_avg | C10: W/Euro(평균) | E10: 1386.07 | F10: 1358.07 | G10: 1369.93 | H10: 1432.41 | I10: 1429.41 | J10: 1420.91 | K10: 1412.88 | L10: 1444.21 | M10: 1476.42 | N10: 1489.3 | O10: 1490.78 | P10: 1475.4 | Q10: 1528.33 | R10: 1585.13 | S10: 1620.04 | T10: 1686.02 | U10: 1605.45 | V10: 1715.47 | W10: 1746.09 | X10: 1631.97 | Y10: 1507.34 | Z10: 1688.95 | AA10: 1490.54 | AB10: 1490.54 | AC10: 1490.54 | AD10: 1490.54 | AF10: 1490.54 | AG10: 1490.54 | AH10: 1490.54 | AI10: 1490.54
A11: EURKRW_end | C11: W/Euro(기말) | E11: 1344.08 | F11: 1344.08 | G11: 1420.26 | H11: 1435.88 | I11: 1425.26 | J11: 1433.66 | K11: 1433.66 | L11: 1458.68 | M11: 1474.86 | N11: 1469.1 | O11: 1532.14 | P11: 1532.14 | Q11: 1594.72 | R11: 1588.22 | S11: 1648.04 | T11: 1696.94 | U11: 1696.94 | V11: 1753.21 | W11: 1767.09 | X11: 1539.06 | Y11: 1490.54 | Z11: 1490.54 | AA11: 1490.54 | AB11: 1490.54 | AC11: 1490.54 | AD11: 1490.54 | AF11: 1490.54 | AG11: 1490.54 | AH11: 1490.54 | AI11: 1490.54
A12: CNYKRW_avg | C12: 원/중국원(평균) | E12: 191.09 | F12: 191.93 | G12: 186.59 | H12: 187.45 | I12: 181.28 | J12: 182.86 | K12: 184.52 | L12: 185.04 | M12: 189.35 | N12: 189.24 | O12: 194.24 | P12: 189.49 | Q12: 199.63 | R12: 193.41 | S12: 193.79 | T12: 204.38 | U12: 197.8 | V12: 211.75 | W12: 220.8 | X12: 210.43 | Y12: 200.5 | Z12: 213.68 | AA12: 199.18 | AB12: 199.18 | AC12: 199.18 | AD12: 199.18 | AF12: 199.18 | AG12: 199.18 | AH12: 199.18 | AI12: 199.18
A13: CNYKRW_end | C13: 원/중국원(기말) | E13: 182.67 | F13: 182.67 | G13: 189.97 | H13: 181.8 | I13: 184.26 | J13: 182.61 | K13: 182.61 | L13: 186.66 | M13: 189.7 | N13: 187.12 | O13: 202.04 | P13: 202.04 | Q13: 203.3 | R13: 189.14 | S13: 197.16 | T13: 206.28 | U13: 206.28 | V13: 220.97 | W13: 228.56 | X13: 202.16 | Y13: 199.18 | Z13: 199.18 | AA13: 199.18 | AB13: 199.18 | AC13: 199.18 | AD13: 199.18 | AF13: 199.18 | AG13: 199.18 | AH13: 199.18 | AI13: 199.18
B14: 1b. 종가
A15: price_close_end | C15: 종가(기말) | H15: 1679 | I15: 1360 | J15: 990 | L15: 1549 | M15: 2280 | N15: 2300 | O15: 1995 | Q15: 2005 | R15: 4110 | S15: 5050 | T15: 10630 | V15: 13140 | W15: 7510 | X15: 12270 | Y15: 10110
A16: price_high | C16: 종가(최고) | H16: 2500 | I16: 1943 | J16: 1300 | L16: 1588 | M16: 2440 | N16: 3780 | O16: 3300 | Q16: 2780 | R16: 5000 | S16: 5430 | T16: 15980 | V16: 20850 | W16: 16190 | X16: 14140 | Y16: 14260
A17: price_low | C17: 종가(최저) | H17: 1095 | I17: 1148 | J17: 816 | L17: 865 | M17: 1261 | N17: 1900 | O17: 1517 | Q17: 1721 | R17: 1900 | S17: 4110 | T17: 5000 | V17: 7350 | W17: 6390 | X17: 4020 | Y17: 9480
A18: price_avg | C18: 종가(평균) | H18: 1654.2 | I18: 1561.5 | J18: 1022.7 | L18: 1259.2 | M18: 1926.5 | N18: 2493.9 | O18: 2125.4 | Q18: 2200.1 | R18: 3827.5 | S18: 4851.7 | T18: 10098.6 | V18: 13342.4 | W18: 11960.3 | X18: 8267.3 | Y18: 11780
B20: 2. 추정 드라이버 | C20: 실적 열 = subQ 실현값(수식), 추정 열 = 가정(노란 = 모델값 역산, 연녹 = 3절 스칼라 참조)
A21: drv:매출액 | B21: yoy | C21: 매출액 YoY | J21: =IFERROR(subQ!J5/subQ!E5-1,"") | L21: =IFERROR(subQ!L5/subQ!G5-1,"") | M21: =IFERROR(subQ!M5/subQ!H5-1,"") | N21: =IFERROR(subQ!N5/subQ!I5-1,"") | O21: =IFERROR(subQ!O5/subQ!J5-1,"") | Q21: =IFERROR(subQ!Q5/subQ!L5-1,"") | R21: =IFERROR(subQ!R5/subQ!M5-1,"") | S21: =IFERROR(subQ!S5/subQ!N5-1,"") | T21: =IFERROR(subQ!T5/subQ!O5-1,"") | V21: =IFERROR(subQ!V5/subQ!Q5-1,"") | W21: =IFERROR(subQ!W5/subQ!R5-1,"") | X21: -2.735e-05 | Y21: 8.119e-06 | AA21: 1.6431e-05 | AB21: 1.5275e-05 | AC21: 0 | AD21: 0 | AF21: 0 | AG21: 0 | AH21: 0 | AI21: 0
A22: drv:판관비 | B22: ratio | C22: 판관비율(/매출) | E22: =IFERROR(subQ!E8/subQ!E5,"") | F22: =IFERROR(subQ!F8/subQ!F5,"") | G22: =IFERROR(subQ!G8/subQ!G5,"") | H22: =IFERROR(subQ!H8/subQ!H5,"") | I22: =IFERROR(subQ!I8/subQ!I5,"") | J22: =IFERROR(subQ!J8/subQ!J5,"") | K22: =IFERROR(subQ!K8/subQ!K5,"") | L22: =IFERROR(subQ!L8/subQ!L5,"") | ... W22: =IFERROR(subQ!W8/subQ!W5,"") | X22: =$D$50 | Y22: =$D$50 | Z22: =IFERROR(subQ!Z8/subQ!Z5,"") | AA22: =$D$50 | AB22: =$D$50 | AC22: =$D$50 | AD22: =$D$50 | AE22: =IFERROR(subQ!AE8/subQ!AE5,"") | AF22: =$D$50 | AG22: =$D$50 | AH22: =$D$50 | AI22: =$D$50 | AJ22: =IFERROR(subQ!AJ8/subQ!AJ5,"")
A23: drv:영업이익 | B23: ratio | C23: 영업이익률(OPM) | E23: =IFERROR(subQ!E9/subQ!E5,"") | F23: =IFERROR(subQ!F9/subQ!F5,"") | G23: =IFERROR(subQ!G9/subQ!G5,"") | H23: =IFERROR(subQ!H9/subQ!H5,"") | I23: =IFERROR(subQ!I9/subQ!I5,"") | J23: =IFERROR(subQ!J9/subQ!J5,"") | K23: =IFERROR(subQ!K9/subQ!K5,"") | L23: =IFERROR(subQ!L9/subQ!L5,"") | ... W23: =IFERROR(subQ!W9/subQ!W5,"") | X23: 0.089401709 | Y23: 0.089376054 | Z23: =IFERROR(subQ!Z9/subQ!Z5,"") | AA23: 0.089380579 | AB23: 0.08940204 | AC23: 0.089401709 | AD23: 0.089376054 | AE23: =IFERROR(subQ!AE9/subQ!AE5,"") | AF23: 0.089380579 | AG23: 0.08940204 | AH23: 0.089401709 | AI23: 0.089376054 | AJ23: =IFERROR(subQ!AJ9/subQ!AJ5,"")
A24: drv:파생상품손익 | B24: abs | C24: 파생상품손익 (가정, 억원) | E24: =subQ!E13 | F24: =subQ!F13 | G24: =subQ!G13 | H24: =subQ!H13 | I24: =subQ!I13 | J24: =subQ!J13 | K24: =subQ!K13 | L24: =subQ!L13 | ... W24: =subQ!W13 | X24: 0 | Y24: 0 | Z24: =subQ!Z13 | AA24: 0 | AB24: 0 | AC24: 0 | AD24: 0 | AE24: =subQ!AE13 | AF24: 0 | AG24: 0 | AH24: 0 | AI24: 0 | AJ24: =subQ!AJ13
A25: drv:기타금융손익 | B25: abs | C25: 기타금융손익 (가정, 억원) | E25: =subQ!E14 | F25: =subQ!F14 | G25: =subQ!G14 | H25: =subQ!H14 | I25: =subQ!I14 | J25: =subQ!J14 | K25: =subQ!K14 | L25: =subQ!L14 | ... W25: =subQ!W14 | X25: 0 | Y25: 0 | Z25: =subQ!Z14 | AA25: 0 | AB25: 0 | AC25: 0 | AD25: 0 | AE25: =subQ!AE14 | AF25: 0 | AG25: 0 | AH25: 0 | AI25: 0 | AJ25: =subQ!AJ14
A26: drv:기타영업외손익 | B26: abs | C26: 기타영업외손익 (가정, 억원) | E26: =subQ!E15 | F26: =subQ!F15 | G26: =subQ!G15 | H26: =subQ!H15 | I26: =subQ!I15 | J26: =subQ!J15 | K26: =subQ!K15 | L26: =subQ!L15 | ... W26: =subQ!W15 | X26: 0 | Y26: 0 | Z26: =subQ!Z15 | AA26: 0 | AB26: 0 | AC26: 0 | AD26: 0 | AE26: =subQ!AE15 | AF26: 0 | AG26: 0 | AH26: 0 | AI26: 0 | AJ26: =subQ!AJ15
A27: drv:법인세비용 | B27: tax | C27: 법인세율(/세전) — 법인세 = MAX(세전,0) × 분기별 세율(이월결손 램프, assumptions.tax_schedule) | E27: =IFERROR(subQ!E17/subQ!E16,"") | F27: =IFERROR(subQ!F17/subQ!F16,"") | G27: =IFERROR(subQ!G17/subQ!G16,"") | H27: =IFERROR(subQ!H17/subQ!H16,"") | I27: =IFERROR(subQ!I17/subQ!I16,"") | J27: =IFERROR(subQ!J17/subQ!J16,"") | K27: =IFERROR(subQ!K17/subQ!K16,"") | L27: =IFERROR(subQ!L17/subQ!L16,"") | ... W27: =IFERROR(subQ!W17/subQ!W16,"") | X27: 0 | Y27: 0 | Z27: =IFERROR(subQ!Z17/subQ!Z16,"") | AA27: 0.027139875 | AB27: 0.05538695 | AC27: 0.082130966 | AD27: 0.10966057 | AE27: =IFERROR(subQ!AE17/subQ!AE16,"") | AF27: 0.1372549 | AG27: 0.16478555 | AH27: 0.19298246 | AI27: 0.22036083 | AJ27: =IFERROR(subQ!AJ17/subQ!AJ16,"")
A28: drv:지배주주순이익 | B28: ratio | C28: 지배주주 비중(/당기순이익) | E28: =IFERROR(subQ!E19/subQ!E18,"") | F28: =IFERROR(subQ!F19/subQ!F18,"") | G28: =IFERROR(subQ!G19/subQ!G18,"") | H28: =IFERROR(subQ!H19/subQ!H18,"") | I28: =IFERROR(subQ!I19/subQ!I18,"") | J28: =IFERROR(subQ!J19/subQ!J18,"") | K28: =IFERROR(subQ!K19/subQ!K18,"") | L28: =IFERROR(subQ!L19/subQ!L18,"") | ... W28: =IFERROR(subQ!W19/subQ!W18,"") | X28: =$D$51 | Y28: =$D$51 | Z28: =IFERROR(subQ!Z19/subQ!Z18,"") | AA28: =$D$51 | AB28: =$D$51 | AC28: =$D$51 | AD28: =$D$51 | AE28: =IFERROR(subQ!AE19/subQ!AE18,"") | AF28: =$D$51 | AG28: =$D$51 | AH28: =$D$51 | AI28: =$D$51 | AJ28: =IFERROR(subQ!AJ19/subQ!AJ18,"")
A29: drv:부채총계 | B29: qoq | C29: 부채총계 QoQ | G29: =IFERROR(subQ!G21/subQ!E21-1,"") | H29: =IFERROR(subQ!H21/subQ!G21-1,"") | I29: =IFERROR(subQ!I21/subQ!H21-1,"") | J29: =IFERROR(subQ!J21/subQ!I21-1,"") | L29: =IFERROR(subQ!L21/subQ!J21-1,"") | M29: =IFERROR(subQ!M21/subQ!L21-1,"") | N29: =IFERROR(subQ!N21/subQ!M21-1,"") | O29: =IFERROR(subQ!O21/subQ!N21-1,"") | Q29: =IFERROR(subQ!Q21/subQ!O21-1,"") | R29: =IFERROR(subQ!R21/subQ!Q21-1,"") | S29: =IFERROR(subQ!S21/subQ!R21-1,"") | T29: =IFERROR(subQ!T21/subQ!S21-1,"") | V29: =IFERROR(subQ!V21/subQ!T21-1,"") | W29: =IFERROR(subQ!W21/subQ!V21-1,"") | X29: -1.63e-06 | Y29: 0 | AA29: 0 | AB29: 0 | AC29: 0 | AD29: 0 | AF29: 0 | AG29: 0 | AH29: 0 | AI29: 0
A30: drv:자본총계 | B30: roll | C30: 자본총계 기타변동(배당 등, 억원) | G30: =IFERROR(subQ!E22+subQ!G18-subQ!G22,"") | H30: =IFERROR(subQ!G22+subQ!H18-subQ!H22,"") | I30: =IFERROR(subQ!H22+subQ!I18-subQ!I22,"") | J30: =IFERROR(subQ!I22+subQ!J18-subQ!J22,"") | L30: =IFERROR(subQ!J22+subQ!L18-subQ!L22,"") | M30: =IFERROR(subQ!L22+subQ!M18-subQ!M22,"") | N30: =IFERROR(subQ!M22+subQ!N18-subQ!N22,"") | O30: =IFERROR(subQ!N22+subQ!O18-subQ!O22,"") | Q30: =IFERROR(subQ!O22+subQ!Q18-subQ!Q22,"") | R30: =IFERROR(subQ!Q22+subQ!R18-subQ!R22,"") | S30: =IFERROR(subQ!R22+subQ!S18-subQ!S22,"") | T30: =IFERROR(subQ!S22+subQ!T18-subQ!T22,"") | V30: =IFERROR(subQ!T22+subQ!V18-subQ!V22,"") | W30: =IFERROR(subQ!V22+subQ!W18-subQ!W22,"") | X30: -0.003266798 | Y30: -0.011594581 | AA30: 0.002246888 | AB30: -0.008834981 | AC30: 0.000251835 | AD30: 0.006605165 | AF30: -0.002135393 | AG30: 0.003106683 | AH30: -0.011211051 | AI30: 0.001241192
A31: drv:지배주주지분 | B31: roll | C31: 지배주주지분 기타변동(배당 등, 억원) | G31: =IFERROR(subQ!E23+subQ!G19-subQ!G23,"") | H31: =IFERROR(subQ!G23+subQ!H19-subQ!H23,"") | I31: =IFERROR(subQ!H23+subQ!I19-subQ!I23,"") | J31: =IFERROR(subQ!I23+subQ!J19-subQ!J23,"") | L31: =IFERROR(subQ!J23+subQ!L19-subQ!L23,"") | M31: =IFERROR(subQ!L23+subQ!M19-subQ!M23,"") | N31: =IFERROR(subQ!M23+subQ!N19-subQ!N23,"") | O31: =IFERROR(subQ!N23+subQ!O19-subQ!O23,"") | Q31: =IFERROR(subQ!O23+subQ!Q19-subQ!Q23,"") | R31: =IFERROR(subQ!Q23+subQ!R19-subQ!R23,"") | S31: =IFERROR(subQ!R23+subQ!S19-subQ!S23,"") | T31: =IFERROR(subQ!S23+subQ!T19-subQ!T23,"") | V31: =IFERROR(subQ!T23+subQ!V19-subQ!V23,"") | W31: =IFERROR(subQ!V23+subQ!W19-subQ!W23,"") | X31: -0.003266798 | Y31: -0.011594581 | AA31: 0.002246888 | AB31: -0.008834981 | AC31: 0.000251835 | AD31: 0.006605165 | AF31: -0.002135393 | AG31: 0.003106683 | AH31: -0.011211051 | AI31: 0.001241192
A32: drv:총차입금 | B32: qoq | C32: 총차입금 QoQ | G32: =IFERROR(subQ!G24/subQ!E24-1,"") | H32: =IFERROR(subQ!H24/subQ!G24-1,"") | I32: =IFERROR(subQ!I24/subQ!H24-1,"") | J32: =IFERROR(subQ!J24/subQ!I24-1,"") | L32: =IFERROR(subQ!L24/subQ!J24-1,"") | M32: =IFERROR(subQ!M24/subQ!L24-1,"") | N32: =IFERROR(subQ!N24/subQ!M24-1,"") | O32: =IFERROR(subQ!O24/subQ!N24-1,"") | Q32: =IFERROR(subQ!Q24/subQ!O24-1,"") | R32: =IFERROR(subQ!R24/subQ!Q24-1,"") | S32: =IFERROR(subQ!S24/subQ!R24-1,"") | T32: =IFERROR(subQ!T24/subQ!S24-1,"") | V32: =IFERROR(subQ!V24/subQ!T24-1,"") | W32: =IFERROR(subQ!W24/subQ!V24-1,"") | X32: -2.32e-07 | Y32: 0 | AA32: 0 | AB32: 0 | AC32: 0 | AD32: 0 | AF32: 0 | AG32: 0 | AH32: 0 | AI32: 0
A33: drv:순차입금 | B33: qoq | C33: 순차입금 QoQ | G33: =IFERROR(subQ!G25/subQ!E25-1,"") | H33: =IFERROR(subQ!H25/subQ!G25-1,"") | I33: =IFERROR(subQ!I25/subQ!H25-1,"") | J33: =IFERROR(subQ!J25/subQ!I25-1,"") | L33: =IFERROR(subQ!L25/subQ!J25-1,"") | M33: =IFERROR(subQ!M25/subQ!L25-1,"") | N33: =IFERROR(subQ!N25/subQ!M25-1,"") | O33: =IFERROR(subQ!O25/subQ!N25-1,"") | Q33: =IFERROR(subQ!Q25/subQ!O25-1,"") | R33: =IFERROR(subQ!R25/subQ!Q25-1,"") | S33: =IFERROR(subQ!S25/subQ!R25-1,"") | T33: =IFERROR(subQ!T25/subQ!S25-1,"") | V33: =IFERROR(subQ!V25/subQ!T25-1,"") | W33: =IFERROR(subQ!W25/subQ!V25-1,"") | X33: -0.018745292 | Y33: -0.016221907 | AA33: -0.020333282 | AB33: -0.027777778 | AC33: -0.01896354 | AD33: -0.015940911 | AF33: -0.019857011 | AG33: -0.026899309 | AH33: -0.018328975 | AI33: -0.015373297
A34: drv:이자발생자산 | B34: qoq | C34: 이자발생자산 QoQ | G34: =IFERROR(subQ!G26/subQ!E26-1,"") | H34: =IFERROR(subQ!H26/subQ!G26-1,"") | I34: =IFERROR(subQ!I26/subQ!H26-1,"") | J34: =IFERROR(subQ!J26/subQ!I26-1,"") | L34: =IFERROR(subQ!L26/subQ!J26-1,"") | M34: =IFERROR(subQ!M26/subQ!L26-1,"") | N34: =IFERROR(subQ!N26/subQ!M26-1,"") | O34: =IFERROR(subQ!O26/subQ!N26-1,"") | Q34: =IFERROR(subQ!Q26/subQ!O26-1,"") | R34: =IFERROR(subQ!R26/subQ!Q26-1,"") | S34: =IFERROR(subQ!S26/subQ!R26-1,"") | T34: =IFERROR(subQ!T26/subQ!S26-1,"") | V34: =IFERROR(subQ!V26/subQ!T26-1,"") | W34: =IFERROR(subQ!W26/subQ!V26-1,"") | X34: 0.022838498 | Y34: 0.018927603 | AA34: 0.022961321 | AB34: 0.030008188 | AC34: 0.019336887 | AD34: 0.015621057 | AF34: 0.018881561 | AG34: 0.024605426 | AH34: 0.015944788 | AI34: 0.012883579
A35: drv:현금및현금성자산 | B35: qoq | C35: 현금및현금성자산 QoQ | G35: =IFERROR(subQ!G27/subQ!E27-1,"") | H35: =IFERROR(subQ!H27/subQ!G27-1,"") | I35: =IFERROR(subQ!I27/subQ!H27-1,"") | J35: =IFERROR(subQ!J27/subQ!I27-1,"") | L35: =IFERROR(subQ!L27/subQ!J27-1,"") | M35: =IFERROR(subQ!M27/subQ!L27-1,"") | N35: =IFERROR(subQ!N27/subQ!M27-1,"") | O35: =IFERROR(subQ!O27/subQ!N27-1,"") | Q35: =IFERROR(subQ!Q27/subQ!O27-1,"") | R35: =IFERROR(subQ!R27/subQ!Q27-1,"") | S35: =IFERROR(subQ!S27/subQ!R27-1,"") | T35: =IFERROR(subQ!T27/subQ!S27-1,"") | V35: =IFERROR(subQ!V27/subQ!T27-1,"") | W35: =IFERROR(subQ!W27/subQ!V27-1,"")
A36: drv:CAPEX | B36: yoy | C36: CAPEX YoY | J36: =IFERROR(subQ!J28/subQ!E28-1,"") | L36: =IFERROR(subQ!L28/subQ!G28-1,"") | M36: =IFERROR(subQ!M28/subQ!H28-1,"") | N36: =IFERROR(subQ!N28/subQ!I28-1,"") | O36: =IFERROR(subQ!O28/subQ!J28-1,"") | Q36: =IFERROR(subQ!Q28/subQ!L28-1,"") | R36: =IFERROR(subQ!R28/subQ!M28-1,"") | S36: =IFERROR(subQ!S28/subQ!N28-1,"") | T36: =IFERROR(subQ!T28/subQ!O28-1,"") | V36: =IFERROR(subQ!V28/subQ!Q28-1,"") | W36: =IFERROR(subQ!W28/subQ!R28-1,"") | X36: -0.040567081 | Y36: 0 | AA36: 0.04400984 | AB36: -0.040567081 | AC36: 0 | AD36: 0 | AF36: 0 | AG36: 0 | AH36: 0 | AI36: 0
A37: drv:영업활동현금흐름 | B37: yoy | C37: 영업활동현금흐름 YoY | J37: =IFERROR(subQ!J29/subQ!E29-1,"") | L37: =IFERROR(subQ!L29/subQ!G29-1,"") | M37: =IFERROR(subQ!M29/subQ!H29-1,"") | N37: =IFERROR(subQ!N29/subQ!I29-1,"") | O37: =IFERROR(subQ!O29/subQ!J29-1,"") | Q37: =IFERROR(subQ!Q29/subQ!L29-1,"") | R37: =IFERROR(subQ!R29/subQ!M29-1,"") | S37: =IFERROR(subQ!S29/subQ!N29-1,"") | T37: =IFERROR(subQ!T29/subQ!O29-1,"") | V37: =IFERROR(subQ!V29/subQ!Q29-1,"") | W37: =IFERROR(subQ!W29/subQ!R29-1,"")
A38: drv:주식수 | B38: qoq | C38: 주식수 QoQ | G38: =IFERROR(subQ!G30/subQ!E30-1,"") | H38: =IFERROR(subQ!H30/subQ!G30-1,"") | I38: =IFERROR(subQ!I30/subQ!H30-1,"") | J38: =IFERROR(subQ!J30/subQ!I30-1,"") | L38: =IFERROR(subQ!L30/subQ!J30-1,"") | M38: =IFERROR(subQ!M30/subQ!L30-1,"") | N38: =IFERROR(subQ!N30/subQ!M30-1,"") | O38: =IFERROR(subQ!O30/subQ!N30-1,"") | Q38: =IFERROR(subQ!Q30/subQ!O30-1,"") | R38: =IFERROR(subQ!R30/subQ!Q30-1,"") | S38: =IFERROR(subQ!S30/subQ!R30-1,"") | T38: =IFERROR(subQ!T30/subQ!S30-1,"") | V38: =IFERROR(subQ!V30/subQ!T30-1,"") | W38: =IFERROR(subQ!W30/subQ!V30-1,"") | X38: 0 | Y38: 0 | AA38: 0 | AB38: 0 | AC38: 0 | AD38: 0 | AF38: 0 | AG38: 0 | AH38: 0 | AI38: 0
A39: drv:DPS | B39: abs | C39: DPS (가정, 원) | E39: =subQ!E34 | F39: =subQ!F34 | G39: =subQ!G34 | H39: =subQ!H34 | I39: =subQ!I34 | J39: =subQ!J34 | K39: =subQ!K34 | L39: =subQ!L34 | ... W39: =subQ!W34 | Y39: 0 | Z39: =subQ!Z34 | AD39: 0 | AE39: =subQ!AE34 | AI39: 0 | AJ39: =subQ!AJ34
B41: 3. 밸류에이션·스칼라 | C41: 노란 셀 = 가정. '연결' 표시는 추정 전 분기 수식이 이 셀을 참조한다는 뜻
A42: sc:종가 | C42: 종가 | D42: 10110 | E42: 원 — 네이버 정규장 종가(aik 확정종가 대조 · aik 12,170원)
...

Sheet BS연결
B1: (백만원) | C1: 이름: BS연결H | E1: 4Q22 | F1: 2022 | G1: 1Q23 | H1: 2Q23 | I1: 3Q23 | J1: 4Q23 | K1: 2023 | L1: 1Q24 | M1: 2Q24 | N1: 3Q24 | O1: 4Q24 | P1: 2024 | Q1: 1Q25 | R1: 2Q25 | S1: 3Q25 | T1: 4Q25 | U1: 2025 | V1: 1Q26 | W1: 2Q26 | X1: 3Q26 | Y1: 4Q26 | Z1: 2026 | AA1: 1Q27 | AB1: 2Q27 | AC1: 3Q27 | AD1: 4Q27 | AE1: 2027 | AF1: 1Q28 | AG1: 2Q28 | AH1: 3Q28 | AI1: 4Q28 | AJ1: 2028
B2: 연결 | D2: fin json(kship_fin.py)
B3: 삼미금속(연) | C3: UPDATE: 26-10-13 | E3: 1 | F3: 2 | G3: 3 | H3: 4 | I3: 5 | J3: 6 | K3: 7 | L3: 8 | M3: 9 | N3: 10 | O3: 11 | P3: 12 | Q3: 13 | R3: 14 | S3: 15 | T3: 16 | U3: 17 | V3: 18 | W3: 19 | X3: 20 | Y3: 21 | Z3: 22 | AA3: 23 | AB3: 24 | AC3: 25 | AD3: 26 | AE3: 27 | AF3: 28 | AG3: 29 | AH3: 30 | AI3: 31 | AJ3: 32
B4: Account Code | C4: AccountNAME | E4: 2022.12 | F4: 2022.12A | G4: 2023.03 | H4: 2023.06 | I4: 2023.09 | J4: 2023.12 | K4: 2023.12A | L4: 2024.03 | M4: 2024.06 | N4: 2024.09 | O4: 2024.12 | P4: 2024.12A | Q4: 2025.03 | R4: 2025.06 | S4: 2025.09 | T4: 2025.12 | U4: 2025.12A | V4: 2026.03 | W4: 2026.06 | X4: 2026.09 | Y4: 2026.12 | Z4: 2026.12A | AA4: 2027.03 | AB4: 2027.06 | AC4: 2027.09 | AD4: 2027.12 | AE4: 2027.12A | AF4: 2028.03 | AG4: 2028.06 | AH4: 2028.09 | AI4: 2028.12 | AJ4: 2028.12A

Sheet BS별도
B1: (백만원) | C1: 이름: BS별도H | E1: 4Q22 | F1: 2022 | G1: 1Q23 | H1: 2Q23 | I1: 3Q23 | J1: 4Q23 | K1: 2023 | L1: 1Q24 | M1: 2Q24 | N1: 3Q24 | O1: 4Q24 | P1: 2024 | Q1: 1Q25 | R1: 2Q25 | S1: 3Q25 | T1: 4Q25 | U1: 2025 | V1: 1Q26 | W1: 2Q26 | X1: 3Q26 | Y1: 4Q26 | Z1: 2026 | AA1: 1Q27 | AB1: 2Q27 | AC1: 3Q27 | AD1: 4Q27 | AE1: 2027 | AF1: 1Q28 | AG1: 2Q28 | AH1: 3Q28 | AI1: 4Q28 | AJ1: 2028
B2: 별도 | D2: fin json(kship_fin.py)
B3: 삼미금속(별) | C3: UPDATE: 26-10-13 | E3: 1 | F3: 2 | G3: 3 | H3: 4 | I3: 5 | J3: 6 | K3: 7 | L3: 8 | M3: 9 | N3: 10 | O3: 11 | P3: 12 | Q3: 13 | R3: 14 | S3: 15 | T3: 16 | U3: 17 | V3: 18 | W3: 19 | X3: 20 | Y3: 21 | Z3: 22 | AA3: 23 | AB3: 24 | AC3: 25 | AD3: 26 | AE3: 27 | AF3: 28 | AG3: 29 | AH3: 30 | AI3: 31 | AJ3: 32
B4: Account Code | C4: AccountNAME | E4: 2022.12 | F4: 2022.12A | G4: 2023.03 | H4: 2023.06 | I4: 2023.09 | J4: 2023.12 | K4: 2023.12A | L4: 2024.03 | M4: 2024.06 | N4: 2024.09 | O4: 2024.12 | P4: 2024.12A | Q4: 2025.03 | R4: 2025.06 | S4: 2025.09 | T4: 2025.12 | U4: 2025.12A | V4: 2026.03 | W4: 2026.06 | X4: 2026.09 | Y4: 2026.12 | Z4: 2026.12A | AA4: 2027.03 | AB4: 2027.06 | AC4: 2027.09 | AD4: 2027.12 | AE4: 2027.12A | AF4: 2028.03 | AG4: 2028.06 | AH4: 2028.09 | AI4: 2028.12 | AJ4: 2028.12A
A5: 1 | C5: 유동자산 | E5: 23158.43 | F5: 23158.43 | J5: 27225.45 | K5: 27225.45 | O5: 27316.07 | P5: 27316.07 | R5: 33388.3 | S5: 29688.02 | T5: 42752.44 | U5: 42752.44 | V5: 53597.74 | W5: 82354.72
A6: 1 | C6: 현금및현금성자산 | E6: 1005.99 | F6: 1005.99 | J6: 133.06 | K6: 133.06 | O6: 1621.95 | P6: 1621.95 | R6: 3008.14 | S6: 1020.53 | T6: 11601.86 | U6: 11601.86 | V6: 16229.04 | W6: 38940.91
A7: 1 | C7: 재고자산 | E7: 10854.25 | F7: 10854.25 | J7: 12548.61 | K7: 12548.61 | O7: 12175.07 | P7: 12175.07 | R7: 14852.83 | S7: 15820.87 | T7: 19040.47 | U7: 19040.47 | V7: 21250.02 | W7: 21390.1
A8: 1 | C8: 기타유동자산 | E8: 25.72 | F8: 25.72 | J8: 21.78 | K8: 21.78 | O8: 120.19 | P8: 120.19 | R8: 8.65 | S8: 108.7 | T8: 54.8 | U8: 54.8 | V8: 49.8 | W8: 116.26
A9: 1 | C9: 당기법인세자산(선급법인세) | E9: 0.05 | F9: 0.05 | J9: 0.09 | K9: 0.09 | O9: 49.11 | P9: 49.11 | R9: 4.18 | S9: 26.14 | T9: 54.46 | U9: 54.46 | V9: 65.55 | W9: 26.66
A10: 1 | C10: 비유동자산 | E10: 126342.63 | F10: 126342.63 | J10: 124960.87 | K10: 124960.87 | O10: 145431.42 | P10: 145431.42 | R10: 146536.67 | S10: 146531.1 | T10: 146022.99 | U10: 146022.99 | V10: 149065.95 | W10: 151516.12
A11: 1 | C11: 장기금융자산 | E11: 5.61 | F11: 5.61 | J11: 5.61 | K11: 5.61 | O11: 5.61 | P11: 5.61 | R11: 5.61 | S11: 5.61 | T11: 5.61 | U11: 5.61 | V11: 5.61 | W11: 5.61
A12: 1 | C12: 투자자산 | E12: 5.61 | F12: 5.61 | J12: 5.61 | K12: 5.61 | O12: 5.61 | P12: 5.61 | R12: 5.61 | S12: 5.61 | T12: 5.61 | U12: 5.61 | V12: 5.61 | W12: 5.61
A13: 1 | C13: 투자부동산 | E13: 7.56 | F13: 7.56 | J13: 7.56 | K13: 7.56 | O13: 7.56 | P13: 7.56 | R13: 7.56 | S13: 7.56 | T13: 7.56 | U13: 7.56 | V13: 7.56 | W13: 7.56
A14: 1 | C14: 유형자산 | E14: 126227.27 | F14: 126227.27 | J14: 124864.03 | K14: 124864.03 | O14: 145244.95 | P14: 145244.95 | R14: 146354.77 | S14: 146351.41 | T14: 145912.32 | U14: 145912.32 | V14: 148959.07 | W14: 151401.41
A15: 1 | C15: 자산총계 | E15: 149501.06 | F15: 149501.06 | J15: 152186.32 | K15: 152186.32 | O15: 172747.49 | P15: 172747.49 | R15: 179924.97 | S15: 176219.12 | T15: 188775.42 | U15: 188775.42 | V15: 202663.69 | W15: 233870.84
A16: 1 | C16: 유동부채 | E16: 60973.31 | F16: 60973.31 | J16: 60338.96 | K16: 60338.96 | O16: 49938.53 | P16: 49938.53 | R16: 58973.52 | S16: 39463.34 | T16: 41944.08 | U16: 41944.08 | V16: 44245.4 | W16: 41400.05
... A27: 1 | C27: 장기차입금 | E27: 16500 | F27: 16500 | J27: 12800 | K27: 12800 | O27: 22050 | P27: 22050 | R27: 12000 | S27: 28000 | T27: 28000 | U27: 28000 | V27: 38000 | W27: 37000
A28: 1 | C28: 장기금융부채(face) | E28: 16500 | F28: 16500 | O28: 22050 | P28: 22050 | R28: 12000 | S28: 28000 | T28: 28000 | U28: 28000 | V28: 38000
A29: 1 | C29: 이연법인세부채 | E29: 20730.94 | F29: 20730.94 | J29: 21264.93 | K29: 21264.93 | O29: 25037.14 | P29: 25037.14 | R29: 25037.14 | S29: 25037.14 | T29: 24447.99 | U29: 24447.99 | V29: 24447.99 | W29: 25992.78
A30: 1 | C30: 부채총계 | E30: 98848.02 | F30: 98848.02 | J30: 95247.24 | K30: 95247.24 | O30: 98926.58 | P30: 98926.58 | R30: 98433.38 | S30: 93486.54 | T30: 96071.68 | U30: 96071.68 | V30: 108595.29 | W30: 128822.21
A31: 1 | C31: 자본금 | E31: 15799.94 | F31: 15799.94 | J31: 17799.94 | K31: 17799.94 | O31: 17799.94 | P31: 17799.94 | R31: 19766.61 | S31: 19766.61 | T31: 22192.01 | U31: 22192.01 | V31: 22192.01 | W31: 23051.58
A32: 1 | C32: 자본잉여금 | E32: 40735.37 | F32: 40735.37 | J32: 44724.06 | K32: 44724.06 | O32: 44724.06 | P32: 44724.06 | R32: 48644.81 | S32: 48644.81 | T32: 57621.88 | U32: 57621.88 | V32: 57621.88 | W32: 66654.6
A33: 1 | C33: 기타자본 | E33: -46522.61 | F33: -46522.61 | J33: -46522.61 | K33: -46522.61 | O33: -46522.61 | P33: -46522.61 | R33: -46522.73 | S33: -46522.73 | T33: -46542.06 | U33: -46542.06 | V33: -46542.06 | W33: -46542.06
A34: 1 | C34: 기타포괄이익누계액 | E34: 23623.57 | F34: 23623.57 | J34: 23623.57 | K34: 23623.57 | O34: 37370.56 | P34: 37370.56 | R34: 37370.56 | S34: 37370.56 | T34: 36835.57 | U34: 36835.57 | V34: 36835.57 | W34: 36835.57
A35: 1 | C35: 이익잉여금 | E35: 17016.77 | F35: 17016.77 | J35: 17314.12 | K35: 17314.12 | O35: 20448.96 | P35: 20448.96 | R35: 22232.35 | S35: 23473.35 | T35: 22596.33 | U35: 22596.33 | V35: 23961 | W35: 25048.93
A36: 1 | C36: 자본총계 | E36: 50653.04 | F36: 50653.04 | J36: 56939.08 | K36: 56939.08 | O36: 73820.91 | P36: 73820.91 | R36: 81491.59 | S36: 82732.59 | T36: 92703.74 | U36: 92703.74 | V36: 94068.41 | W36: 105048.62
A37: 1 | C37: 부채와자본총계 | E37: 149501.06 | F37: 149501.06 | J37: 152186.32 | K37: 152186.32 | O37: 172747.49 | P37: 172747.49 | R37: 179924.97 | S37: 176219.12 | T37: 188775.42 | U37: 188775.42 | V37: 202663.69 | W37: 233870.84
A38: 1 | C38: 지배주주지분 | E38: 50653.04 | F38: 50653.04 | J38: 56939.08 | K38: 56939.08 | O38: 73820.91 | P38: 73820.91 | R38: 81491.59 | S38: 82732.59 | T38: 92703.74 | U38: 92703.74 | V38: 94068.41 | W38: 105048.62
A39: 1 | C39: 총차입금 | E39: 67265.91 | F39: 67265.91 | J39: 64293.4 | K39: 64293.4 | O39: 63888.26 | P39: 63888.26 | R39: 63156.35 | S39: 60208.32 | T39: 63916.27 | U39: 63916.27 | V39: 74392.4 | W39: 86372.02
A40: 1 | C40: 순차입금 | E40: 66259.92 | F40: 66259.92 | J40: 64160.34 | K40: 64160.34 | O40: 62266.31 | P40: 62266.31 | R40: 60148.21 | S40: 59187.79 | T40: 52314.41 | U40: 52314.41 | V40: 58163.36 | W40: 47431.11
A41: 1 | C41: 이자발생자산 | E41: 1011.6 | F41: 1011.6 | J41: 138.67 | K41: 138.67 | O41: 1627.56 | P41: 1627.56 | R41: 3013.75 | S41: 1026.14 | T41: 11607.47 | U41: 11607.47 | V41: 16234.65 | W41: 38946.52
A42: 1 | C42: 비유동리스부채 | J42: 13.63 | K42: 13.63 | O42: 6.35 | P42: 6.35 | R42: 2.4 | S42: 0 | T42: 3.5 | U42: 3.5 | V42: 2.21 | W42: 0.89
A43: 1 | C43: 장기금융부채 | J43: 13.63 | K43: 13.63 | O43: 6.35 | P43: 6.35 | R43: 2.4 | S43: 0 | T43: 3.5 | U43: 3.5 | V43: 2.21 | W43: 5604.21
A44: 1 | C44: 무형자산 | O44: 81.58 | P44: 81.58 | R44: 72.68 | S44: 68.23 | T44: 63.78 | U44: 63.78 | V44: 59.33 | W44: 66.48
A45: 1 | C45: 기타유동금융부채 | O45: 70.99 | P45: 70.99 | R45: 0 | S45: 0 | T45: 0 | U45: 0
A46: 1 | C46: 당기법인세부채(미지급법인세) | O46: 6.25 | P46: 6.25 | R46: 0 | S46: 0 | T46: 2.12 | U46: 2.12 | V46: 2.12 | W46: 0
A47: 1 | C47: 기타비유동부채 | O47: 15.91 | P47: 15.91 | R47: 28.92 | S47: 42.29 | T47: 54.54 | U47: 54.54 | V47: 59.8 | W47: 65.33
A48: 1 | C48: 사채 | T48: 1366.27 | U48: 1366.27 | V48: 1392.4 | W48: 18372.02
A49: 1 | C49: 단기투자자산(공정가치) | W49: 3272.11
A50: 1 | C50: 기타비유동금융부채 | W50: 5603.32
...

Sheet subQ
A1: YQ | C1: subQ 분기 서브모델(억원, U=100) | E1: 4Q22 | F1: 2022 | G1: 1Q23 | H1: 2Q23 | I1: 3Q23 | J1: 4Q23 | K1: 2023 | L1: 1Q24 | M1: 2Q24 | N1: 3Q24 | O1: 4Q24 | P1: 2024 | Q1: 1Q25 | R1: 2Q25 | S1: 3Q25 | T1: 4Q25 | U1: 2025 | V1: 1Q26 | W1: 2Q26 | X1: 3Q26 | Y1: 4Q26 | Z1: 2026 | AA1: 1Q27 | AB1: 2Q27 | AC1: 3Q27 | AD1: 4Q27 | AE1: 2027 | AF1: 1Q28 | AG1: 2Q28 | AH1: 3Q28 | AI1: 4Q28 | AJ1: 2028
A2: A=이름(key) B=그룹 C=단위 D=FnGuide 계정명(VLOOKUP 키). 확정=VLOOKUP(BS), 추정=변수 가정 참조
E3: 1 | F3: 2 | G3: 3 | H3: 4 | I3: 5 | J3: 6 | K3: 7 | L3: 8 | M3: 9 | N3: 10 | O3: 11 | P3: 12 | Q3: 13 | R3: 14 | S3: 15 | T3: 16 | U3: 17 | V3: 18 | W3: 19 | X3: 20 | Y3: 21 | Z3: 22 | AA3: 23 | AB3: 24 | AC3: 25 | AD3: 26 | AE3: 27 | AF3: 28 | AG3: 29 | AH3: 30 | AI3: 31 | AJ3: 32
E4: 2022.12 | F4: 2022.12A | G4: 2023.03 | H4: 2023.06 | I4: 2023.09 | J4: 2023.12 | K4: 2023.12A | L4: 2024.03 | M4: 2024.06 | N4: 2024.09 | O4: 2024.12 | P4: 2024.12A | Q4: 2025.03 | R4: 2025.06 | S4: 2025.09 | T4: 2025.12 | U4: 2025.12A | V4: 2026.03 | W4: 2026.06 | X4: 2026.09 | Y4: 2026.12 | Z4: 2026.12A | AA4: 2027.03 | AB4: 2027.06 | AC4: 2027.09 | AD4: 2027.12 | AE4: 2027.12A | AF4: 2028.03 | AG4: 2028.06 | AH4: 2028.09 | AI4: 2028.12 | AJ4: 2028.12A
A5: 매출액 | B5: 손익 | C5: 억원 | D5: 매출액(수익) | K5: =SUM(G5:J5) | O5: =IFERROR(VLOOKUP($D5,BS별도,MATCH(O$1,BS별도H,0),0)/100,"") | P5: =SUM(L5:O5) | R5: =IFERROR(VLOOKUP($D5,BS별도,MATCH(R$1,BS별도H,0),0)/100,"") | S5: =IFERROR(VLOOKUP($D5,BS별도,MATCH(S$1,BS별도H,0),0)/100,"") | T5: =IFERROR(VLOOKUP($D5,BS별도,MATCH(T$1,BS별도H,0),0)/100,"") | U5: =SUM(Q5:T5) | V5: =IFERROR(VLOOKUP($D5,BS별도,MATCH(V$1,BS별도H,0),0)/100,"") | W5: =IFERROR(VLOOKUP($D5,BS별도,MATCH(W$1,BS별도H,0),0)/100,"") | X5: =IFERROR(S5*(1+변수!X21),"") | Y5: =IFERROR(T5*(1+변수!Y21),"") | Z5: =SUM(V5:Y5) | AA5: =IFERROR(V5*(1+변수!AA21),"") | AB5: =IFERROR(W5*(1+변수!AB21),"") | AC5: =IFERROR(X5*(1+변수!AC21),"") | AD5: =IFERROR(Y5*(1+변수!AD21),"") | AE5: =SUM(AA5:AD5) | AF5: =IFERROR(AA5*(1+변수!AF21),"") | AG5: =IFERROR(AB5*(1+변수!AG21),"") | AH5: =IFERROR(AC5*(1+변수!AH21),"") | AI5: =IFERROR(AD5*(1+변수!AI21),"") | AJ5: =SUM(AF5:AI5)
A6: 매출원가 | B6: 손익 | C6: 억원 | D6: 매출원가 | K6: =SUM(G6:J6) | O6: =IFERROR(VLOOKUP($D6,BS별도,MATCH(O$1,BS별도H,0),0)/100,"") | P6: =SUM(L6:O6) | R6: =IFERROR(VLOOKUP($D6,BS별도,MATCH(R$1,BS별도H,0),0)/100,"") | S6: =IFERROR(VLOOKUP($D6,BS별도,MATCH(S$1,BS별도H,0),0)/100,"") | T6: =IFERROR(VLOOKUP($D6,BS별도,MATCH(T$1,BS별도H,0),0)/100,"") | U6: =SUM(Q6:T6) | V6: =IFERROR(VLOOKUP($D6,BS별도,MATCH(V$1,BS별도H,0),0)/100,"") | W6: =IFERROR(VLOOKUP($D6,BS별도,MATCH(W$1,BS별도H,0),0)/100,"") | X6: =IFERROR(X5-X7,"") | Y6: =IFERROR(Y5-Y7,"") | Z6: =SUM(V6:Y6) | AA6: =IFERROR(AA5-AA7,"") | AB6: =IFERROR(AB5-AB7,"") | AC6: =IFERROR(AC5-AC7,"") | AD6: =IFERROR(AD5-AD7,"") | AE6: =SUM(AA6:AD6) | AF6: =IFERROR(AF5-AF7,"") | AG6: =IFERROR(AG5-AG7,"") | AH6: =IFERROR(AH5-AH7,"") | AI6: =IFERROR(AI5-AI7,"") | AJ6: =SUM(AF6:AI6)
A7: 매출총이익 | B7: 손익 | C7: 억원 | D7: 매출총이익 | K7: =SUM(G7:J7) | O7: =IFERROR(VLOOKUP($D7,BS별도,MATCH(O$1,BS별도H,0),0)/100,"") | P7: =SUM(L7:O7) | R7: =IFERROR(VLOOKUP($D7,BS별도,MATCH(R$1,BS별도H,0),0)/100,"") | S7: =IFERROR(VLOOKUP($D7,BS별도,MATCH(S$1,BS별도H,0),0)/100,"") | T7: =IFERROR(VLOOKUP($D7,BS별도,MATCH(T$1,BS별도H,0),0)/100,"") | U7: =SUM(Q7:T7) | V7: =IFERROR(VLOOKUP($D7,BS별도,MATCH(V$1,BS별도H,0),0)/100,"") | W7: =IFERROR(VLOOKUP($D7,BS별도,MATCH(W$1,BS별도H,0),0)/100,"") | X7: =IFERROR(X9+X8,"") | Y7: =IFERROR(Y9+Y8,"") | Z7: =SUM(V7:Y7) | AA7: =IFERROR(AA9+AA8,"") | AB7: =IFERROR(AB9+AB8,"") | AC7: =IFERROR(AC9+AC8,"") | AD7: =IFERROR(AD9+AD8,"") | AE7: =SUM(AA7:AD7) | AF7: =IFERROR(AF9+AF8,"") | AG7: =IFERROR(AG9+AG8,"") | AH7: =IFERROR(AH9+AH8,"") | AI7: =IFERROR(AI9+AI8,"") | AJ7: =SUM(AF7:AI7)
A8: 판관비 | B8: 손익 | C8: 억원 | D8: 판관비 | K8: =SUM(G8:J8) | O8: =IFERROR(VLOOKUP($D8,BS별도,MATCH(O$1,BS별도H,0),0)/100,"") | P8: =SUM(L8:O8) | R8: =IFERROR(VLOOKUP($D8,BS별도,MATCH(R$1,BS별도H,0),0)/100,"") | S8: =IFERROR(VLOOKUP($D8,BS별도,MATCH(S$1,BS별도H,0),0)/100,"") | T8: =IFERROR(VLOOKUP($D8,BS별도,MATCH(T$1,BS별도H,0),0)/100,"") | U8: =SUM(Q8:T8) | V8: =IFERROR(VLOOKUP($D8,BS별도,MATCH(V$1,BS별도H,0),0)/100,"") | W8: =IFERROR(VLOOKUP($D8,BS별도,MATCH(W$1,BS별도H,0),0)/100,"") | X8: =IFERROR(X5*변수!X22,"") | Y8: =IFERROR(Y5*변수!Y22,"") | Z8: =SUM(V8:Y8) | AA8: =IFERROR(AA5*변수!AA22,"") | AB8: =IFERROR(AB5*변수!AB22,"") | AC8: =IFERROR(AC5*변수!AC22,"") | AD8: =IFERROR(AD5*변수!AD22,"") | AE8: =SUM(AA8:AD8) | AF8: =IFERROR(AF5*변수!AF22,"") | AG8: =IFERROR(AG5*변수!AG22,"") | AH8: =IFERROR(AH5*변수!AH22,"") | AI8: =IFERROR(AI5*변수!AI22,"") | AJ8: =SUM(AF8:AI8)
A9: 영업이익 | B9: 손익 | C9: 억원 | D9: 영업이익 | K9: =SUM(G9:J9) | O9: =IFERROR(VLOOKUP($D9,BS별도,MATCH(O$1,BS별도H,0),0)/100,"") | P9: =SUM(L9:O9) | R9: =IFERROR(VLOOKUP($D9,BS별도,MATCH(R$1,BS별도H,0),0)/100,"") | S9: =IFERROR(VLOOKUP($D9,BS별도,MATCH(S$1,BS별도H,0),0)/100,"") | T9: =IFERROR(VLOOKUP($D9,BS별도,MATCH(T$1,BS별도H,0),0)/100,"") | U9: =SUM(Q9:T9) | V9: =IFERROR(VLOOKUP($D9,BS별도,MATCH(V$1,BS별도H,0),0)/100,"") | W9: =IFERROR(VLOOKUP($D9,BS별도,MATCH(W$1,BS별도H,0),0)/100,"") | X9: =IFERROR(X5*변수!X23,"") | Y9: =IFERROR(Y5*변수!Y23,"") | Z9: =SUM(V9:Y9) | AA9: =IFERROR(AA5*변수!AA23,"") | AB9: =IFERROR(AB5*변수!AB23,"") | AC9: =IFERROR(AC5*변수!AC23,"") | AD9: =IFERROR(AD5*변수!AD23,"") | AE9: =SUM(AA9:AD9) | AF9: =IFERROR(AF5*변수!AF23,"") | AG9: =IFERROR(AG5*변수!AG23,"") | AH9: =IFERROR(AH5*변수!AH23,"") | AI9: =IFERROR(AI5*변수!AI23,"") | AJ9: =SUM(AF9:AI9)
A10: OPM | B10: 손익 | C10: % | D10: 영업이익률 | K10: =IFERROR(K9/K5,"") | O10: =IFERROR(O9/O5,"") | P10: =IFERROR(P9/P5,"") | R10: =IFERROR(R9/R5,"") | S10: =IFERROR(S9/S5,"") | T10: =IFERROR(T9/T5,"") | U10: =IFERROR(U9/U5,"") | V10: =IFERROR(V9/V5,"") | W10: =IFERROR(W9/W5,"") | X10: =IFERROR(X9/X5,"") | Y10: =IFERROR(Y9/Y5,"") | ... AJ10: =IFERROR(AJ9/AJ5,"")
A11: 금융손익 | B11: 손익 | C11: 억원 | D11: 금융손익 | K11: =SUM(G11:J11) | O11: =IFERROR(VLOOKUP($D11,BS별도,MATCH(O$1,BS별도H,0),0)/100,"") | P11: =SUM(L11:O11) | R11: =IFERROR(VLOOKUP($D11,BS별도,MATCH(R$1,BS별도H,0),0)/100,"") | S11: =IFERROR(VLOOKUP($D11,BS별도,MATCH(S$1,BS별도H,0),0)/100,"") | T11: =IFERROR(VLOOKUP($D11,BS별도,MATCH(T$1,BS별도H,0),0)/100,"") | U11: =SUM(Q11:T11) | V11: =IFERROR(VLOOKUP($D11,BS별도,MATCH(V$1,BS별도H,0),0)/100,"") | W11: =IFERROR(VLOOKUP($D11,BS별도,MATCH(W$1,BS별도H,0),0)/100,"") | X11: =IFERROR(X12+X13+X14,"") | Y11: =IFERROR(Y12+Y13+Y14,"") | Z11: =SUM(V11:Y11) | AA11: =IFERROR(AA12+AA13+AA14,"") | AB11: =IFERROR(AB12+AB13+AB14,"") | AC11: =IFERROR(AC12+AC13+AC14,"") | AD11: =IFERROR(AD12+AD13+AD14,"") | AE11: =SUM(AA11:AD11) | AF11: =IFERROR(AF12+AF13+AF14,"") | AG11: =IFERROR(AG12+AG13+AG14,"") | AH11: =IFERROR(AH12+AH13+AH14,"") | AI11: =IFERROR(AI12+AI13+AI14,"") | AJ11: =SUM(AF11:AI11)
A12: 이자손익 | B12: 손익 | C12: 억원 | D12: 이자손익 | K12: =SUM(G12:J12) | O12: =IFERROR(VLOOKUP($D12,BS별도,MATCH(O$1,BS별도H,0),0)/100,"") | P12: =SUM(L12:O12) | R12: =IFERROR(VLOOKUP($D12,BS별도,MATCH(R$1,BS별도H,0),0)/100,"") | S12: =IFERROR(VLOOKUP($D12,BS별도,MATCH(S$1,BS별도H,0),0)/100,"") | T12: =IFERROR(VLOOKUP($D12,BS별도,MATCH(T$1,BS별도H,0),0)/100,"") | U12: =SUM(Q12:T12) | V12: =IFERROR(VLOOKUP($D12,BS별도,MATCH(V$1,BS별도H,0),0)/100,"") | W12: =IFERROR(VLOOKUP($D12,BS별도,MATCH(W$1,BS별도H,0),0)/100,"") | X12: =IFERROR((W26*변수!$D$52-W24*변수!$D$53)/4,"") | Y12: =IFERROR((X26*변수!$D$52-X24*변수!$D$53)/4,"") | Z12: =SUM(V12:Y12) | AA12: =IFERROR((Y26*변수!$D$52-Y24*변수!$D$53)/4,"") | AB12: =IFERROR((AA26*변수!$D$52-AA24*변수!$D$53)/4,"") | AC12: =IFERROR((AB26*변수!$D$52-AB24*변수!$D$53)/4,"") | AD12: =IFERROR((AC26*변수!$D$52-AC24*변수!$D$53)/4,"") | AE12: =SUM(AA12:AD12) | AF12: =IFERROR((AD26*변수!$D$52-AD24*변수!$D$53)/4,"") | AG12: =IFERROR((AF26*변수!$D$52-AF24*변수!$D$53)/4,"") | AH12: =IFERROR((AG26*변수!$D$52-AG24*변수!$D$53)/4,"") | AI12: =IFERROR((AH26*변수!$D$52-AH24*변수!$D$53)/4,"") | AJ12: =SUM(AF12:AI12)
A13: 파생상품손익 | B13: 손익 | C13: 억원 | D13: 파생상품손익 | K13: =SUM(G13:J13) | P13: =SUM(L13:O13) | U13: =SUM(Q13:T13) | W13: =IFERROR((VLOOKUP("파생상품이익",BS별도,MATCH(W$1,BS별도H,0),0)-VLOOKUP("파생상품손실",BS별도,MATCH(W$1,BS별도H,0),0))/100,"") | X13: =변수!X24 | Y13: =변수!Y24 | Z13: =SUM(V13:Y13) | AA13: =변수!AA24 | AB13: =변수!AB24 | AC13: =변수!AC24 | AD13: =변수!AD24 | AE13: =SUM(AA13:AD13) | AF13: =변수!AF24 | AG13: =변수!AG24 | AH13: =변수!AH24 | AI13: =변수!AI24 | AJ13: =SUM(AF13:AI13)
A14: 기타금융손익 | B14: 손익 | C14: 억원 | D14: 기타금융손익(금융손익 잔차) | K14: =SUM(G14:J14) | P14: =SUM(L14:O14) | U14: =SUM(Q14:T14) | W14: -0.01 | X14: =변수!X25 | Y14: =변수!Y25 | Z14: =SUM(V14:Y14) | AA14: =변수!AA25 | AB14: =변수!AB25 | AC14: =변수!AC25 | AD14: =변수!AD25 | AE14: =SUM(AA14:AD14) | AF14: =변수!AF25 | AG14: =변수!AG25 | AH14: =변수!AH25 | AI14: =변수!AI25 | AJ14: =SUM(AF14:AI14)
A15: 기타영업외손익 | B15: 손익 | C15: 억원 | D15: 기타영업외손익 | K15: =SUM(G15:J15) | O15: =IFERROR(VLOOKUP($D15,BS별도,MATCH(O$1,BS별도H,0),0)/100,"") | P15: =SUM(L15:O15) | R15: =IFERROR(VLOOKUP($D15,BS별도,MATCH(R$1,BS별도H,0),0)/100,"") | S15: =IFERROR(VLOOKUP($D15,BS별도,MATCH(S$1,BS별도H,0),0)/100,"") | T15: =IFERROR(VLOOKUP($D15,BS별도,MATCH(T$1,BS별도H,0),0)/100,"") | U15: =SUM(Q15:T15) | V15: =IFERROR(VLOOKUP($D15,BS별도,MATCH(V$1,BS별도H,0),0)/100,"") | W15: =IFERROR(VLOOKUP($D15,BS별도,MATCH(W$1,BS별도H,0),0)/100,"") | X15: =변수!X26 | Y15: =변수!Y26 | Z15: =SUM(V15:Y15) | AA15: =변수!AA26 | AB15: =변수!AB26 | AC15: =변수!AC26 | AD15: =변수!AD26 | AE15: =SUM(AA15:AD15) | AF15: =변수!AF26 | AG15: =변수!AG26 | AH15: =변수!AH26 | AI15: =변수!AI26 | AJ15: =SUM(AF15:AI15)
A16: 세전이익 | B16: 손익 | C16: 억원 | D16: 법인세비용차감전계속사업이익 | K16: =SUM(G16:J16) | O16: =IFERROR(VLOOKUP($D16,BS별도,MATCH(O$1,BS별도H,0),0)/100,"") | P16: =SUM(L16:O16) | R16: =IFERROR(VLOOKUP($D16,BS별도,MATCH(R$1,BS별도H,0),0)/100,"") | S16: =IFERROR(VLOOKUP($D16,BS별도,MATCH(S$1,BS별도H,0),0)/100,"") | T16: =IFERROR(VLOOKUP($D16,BS별도,MATCH(T$1,BS별도H,0),0)/100,"") | U16: =SUM(Q16:T16) | V16: =IFERROR(VLOOKUP($D16,BS별도,MATCH(V$1,BS별도H,0),0)/100,"") | W16: =IFERROR(VLOOKUP($D16,BS별도,MATCH(W$1,BS별도H,0),0)/100,"") | X16: =IFERROR(X9+X11+X15,"") | Y16: =IFERROR(Y9+Y11+Y15,"") | Z16: =SUM(V16:Y16) | AA16: =IFERROR(AA9+AA11+AA15,"") | AB16: =IFERROR(AB9+AB11+AB15,"") | AC16: =IFERROR(AC9+AC11+AC15,"") | AD16: =IFERROR(AD9+AD11+AD15,"") | AE16: =SUM(AA16:AD16) | AF16: =IFERROR(AF9+AF11+AF15,"") | AG16: =IFERROR(AG9+AG11+AG15,"") | AH16: =IFERROR(AH9+AH11+AH15,"") | AI16: =IFERROR(AI9+AI11+AI15,"") | AJ16: =SUM(AF16:AI16)
A17: 법인세비용 | B17: 손익 | C17: 억원 | D17: 법인세비용 | K17: =SUM(G17:J17) | O17: =IFERROR(VLOOKUP($D17,BS별도,MATCH(O$1,BS별도H,0),0)/100,"") | P17: =SUM(L17:O17) | R17: =IFERROR(VLOOKUP($D17,BS별도,MATCH(R$1,BS별도H,0),0)/100,"") | S17: =IFERROR(VLOOKUP($D17,BS별도,MATCH(S$1,BS별도H,0),0)/100,"") | T17: =IFERROR(VLOOKUP($D17,BS별도,MATCH(T$1,BS별도H,0),0)/100,"") | U17: =SUM(Q17:T17) | V17: =IFERROR(VLOOKUP($D17,BS별도,MATCH(V$1,BS별도H,0),0)/100,"") | W17: =IFERROR(VLOOKUP($D17,BS별도,MATCH(W$1,BS별도H,0),0)/100,"") | X17: =IFERROR(MAX(X16,0)*변수!X27,"") | Y17: =IFERROR(MAX(Y16,0)*변수!Y27,"") | Z17: =SUM(V17:Y17) | AA17: =IFERROR(MAX(AA16,0)*변수!AA27,"") | AB17: =IFERROR(MAX(AB16,0)*변수!AB27,"") | AC17: =IFERROR(MAX(AC16,0)*변수!AC27,"") | AD17: =IFERROR(MAX(AD16,0)*변수!AD27,"") | AE17: =SUM(AA17:AD17) | AF17: =IFERROR(MAX(AF16,0)*변수!AF27,"") | AG17: =IFERROR(MAX(AG16,0)*변수!AG27,"") | AH17: =IFERROR(MAX(AH16,0)*변수!AH27,"") | AI17: =IFERROR(MAX(AI16,0)*변수!AI27,"") | AJ17: =SUM(AF17:AI17)
A18: 당기순이익 | B18: 손익 | C18: 억원 | D18: 당기순이익 | K18: =SUM(G18:J18) | O18: =IFERROR(VLOOKUP($D18,BS별도,MATCH(O$1,BS별도H,0),0)/100,"") | P18: =SUM(L18:O18) | R18: =IFERROR(VLOOKUP($D18,BS별도,MATCH(R$1,BS별도H,0),0)/100,"") | S18: =IFERROR(VLOOKUP($D18,BS별도,MATCH(S$1,BS별도H,0),0)/100,"") | T18: =IFERROR(VLOOKUP($D18,BS별도,MATCH(T$1,BS별도H,0),0)/100,"") | U18: =SUM(Q18:T18) | V18: =IFERROR(VLOOKUP($D18,BS별도,MATCH(V$1,BS별도H,0),0)/100,"") | W18: =IFERROR(VLOOKUP($D18,BS별도,MATCH(W$1,BS별도H,0),0)/100,"") | X18: =IFERROR(X16-X17,"") | Y18: =IFERROR(Y16-Y17,"") | Z18: =SUM(V18:Y18) | AA18: =IFERROR(AA16-AA17,"") | AB18: =IFERROR(AB16-AB17,"") | AC18: =IFERROR(AC16-AC17,"") | AD18: =IFERROR(AD16-AD17,"") | AE18: =SUM(AA18:AD18) | AF18: =IFERROR(AF16-AF17,"") | AG18: =IFERROR(AG16-AG17,"") | AH18: =IFERROR(AH16-AH17,"") | AI18: =IFERROR(AI16-AI17,"") | AJ18: =SUM(AF18:AI18)
A19: 지배주주순이익 | B19: 손익 | C19: 억원 | D19: (지배주주지분)당기순이익 | K19: =SUM(G19:J19) | O19: =IFERROR(VLOOKUP($D19,BS별도,MATCH(O$1,BS별도H,0),0)/100,"") | P19: =SUM(L19:O19) | R19: =IFERROR(VLOOKUP($D19,BS별도,MATCH(R$1,BS별도H,0),0)/100,"") | S19: =IFERROR(VLOOKUP($D19,BS별도,MATCH(S$1,BS별도H,0),0)/100,"") | T19: =IFERROR(VLOOKUP($D19,BS별도,MATCH(T$1,BS별도H,0),0)/100,"") | U19: =SUM(Q19:T19) | V19: =IFERROR(VLOOKUP($D19,BS별도,MATCH(V$1,BS별도H,0),0)/100,"") | W19: =IFERROR(VLOOKUP($D19,BS별도,MATCH(W$1,BS별도H,0),0)/100,"") | X19: =IFERROR(X18*변수!X28,"") | Y19: =IFERROR(Y18*변수!Y28,"") | Z19: =SUM(V19:Y19) | AA19: =IFERROR(AA18*변수!AA28,"") | AB19: =IFERROR(AB18*변수!AB28,"") | AC19: =IFERROR(AC18*변수!AC28,"") | AD19: =IFERROR(AD18*변수!AD28,"") | AE19: =SUM(AA19:AD19) | AF19: =IFERROR(AF18*변수!AF28,"") | AG19: =IFERROR(AG18*변수!AG28,"") | AH19: =IFERROR(AH18*변수!AH28,"") | AI19: =IFERROR(AI18*변수!AI28,"") | AJ19: =SUM(AF19:AI19)
A20: 자산총계 | B20: 재무상태 | C20: 억원 | D20: 자산총계 | E20: =IFERROR(VLOOKUP($D20,BS별도,MATCH(E$1,BS별도H,0),0)/100,"") | F20: 1495.01 | J20: =IFERROR(VLOOKUP($D20,BS별도,MATCH(J$1,BS별도H,0),0)/100,"") | K20: =J20 | O20: =IFERROR(VLOOKUP($D20,BS별도,MATCH(O$1,BS별도H,0),0)/100,"") | P20: =O20 | R20: =IFERROR(VLOOKUP($D20,BS별도,MATCH(R$1,BS별도H,0),0)/100,"") | S20: =IFERROR(VLOOKUP($D20,BS별도,MATCH(S$1,BS별도H,0),0)/100,"") | T20: =IFERROR(VLOOKUP($D20,BS별도,MATCH(T$1,BS별도H,0),0)/100,"") | U20: =T20 | V20: =IFERROR(VLOOKUP($D20,BS별도,MATCH(V$1,BS별도H,0),0)/100,"") | W20: =IFERROR(VLOOKUP($D20,BS별도,MATCH(W$1,BS별도H,0),0)/100,"") | X20: =IFERROR(X21+X22,"") | Y20: =IFERROR(Y21+Y22,"") | Z20: =Y20 | AA20: =IFERROR(AA21+AA22,"") | AB20: =IFERROR(AB21+AB22,"") | AC20: =IFERROR(AC21+AC22,"") | AD20: =IFERROR(AD21+AD22,"") | AE20: =AD20 | AF20: =IFERROR(AF21+AF22,"") | AG20: =IFERROR(AG21+AG22,"") | AH20: =IFERROR(AH21+AH22,"") | AI20: =IFERROR(AI21+AI22,"") | AJ20: =AI20
A21: 부채총계 | B21: 재무상태 | C21: 억원 | D21: 부채총계 | E21: =IFERROR(VLOOKUP($D21,BS별도,MATCH(E$1,BS별도H,0),0)/100,"") | F21: 988.48 | J21: =IFERROR(VLOOKUP($D21,BS별도,MATCH(J$1,BS별도H,0),0)/100,"") | K21: =J21 | O21: =IFERROR(VLOOKUP($D21,BS별도,MATCH(O$1,BS별도H,0),0)/100,"") | P21: =O21 | R21: =IFERROR(VLOOKUP($D21,BS별도,MATCH(R$1,BS별도H,0),0)/100,"") | S21: =IFERROR(VLOOKUP($D21,BS별도,MATCH(S$1,BS별도H,0),0)/100,"") | T21: =IFERROR(VLOOKUP($D21,BS별도,MATCH(T$1,BS별도H,0),0)/100,"") | U21: =T21 | V21: =IFERROR(VLOOKUP($D21,BS별도,MATCH(V$1,BS별도H,0),0)/100,"") | W21: =IFERROR(VLOOKUP($D21,BS별도,MATCH(W$1,BS별도H,0),0)/100,"") | X21: =IFERROR(W21*(1+변수!X29),"") | Y21: =IFERROR(X21*(1+변수!Y29),"") | Z21: =Y21 | AA21: =IFERROR(Y21*(1+변수!AA29),"") | AB21: =IFERROR(AA21*(1+변수!AB29),"") | AC21: =IFERROR(AB21*(1+변수!AC29),"") | AD21: =IFERROR(AC21*(1+변수!AD29),"") | AE21: =AD21 | AF21: =IFERROR(AD21*(1+변수!AF29),"") | AG21: =IFERROR(AF21*(1+변수!AG29),"") | AH21: =IFERROR(AG21*(1+변수!AH29),"") | AI21: =IFERROR(AH21*(1+변수!AI29),"") | AJ21: =AI21
A22: 자본총계 | B22: 재무상태 | C22: 억원 | D22: 자본총계 | E22: =IFERROR(VLOOKUP($D22,BS별도,MATCH(E$1,BS별도H,0),0)/100,"") | F22: 506.53 | J22: =IFERROR(VLOOKUP($D22,BS별도,MATCH(J$1,BS별도H,0),0)/100,"") | K22: =J22 | O22: =IFERROR(VLOOKUP($D22,BS별도,MATCH(O$1,BS별도H,0),0)/100,"") | P22: =O22 | R22: =IFERROR(VLOOKUP($D22,BS별도,MATCH(R$1,BS별도H,0),0)/100,"") | S22: =IFERROR(VLOOKUP($D22,BS별도,MATCH(S$1,BS별도H,0),0)/100,"") | T22: =IFERROR(VLOOKUP($D22,BS별도,MATCH(T$1,BS별도H,0),0)/100,"") | U22: =T22 | V22: =IFERROR(VLOOKUP($D22,BS별도,MATCH(V$1,BS별도H,0),0)/100,"") | W22: =IFERROR(VLOOKUP($D22,BS별도,MATCH(W$1,BS별도H,0),0)/100,"") | X22: =IFERROR(W22+X18-변수!X30,"") | Y22: =IFERROR(X22+Y18-변수!Y30,"") | Z22: =Y22 | AA22: =IFERROR(Y22+AA18-변수!AA30,"") | AB22: =IFERROR(AA22+AB18-변수!AB30,"") | AC22: =IFERROR(AB22+AC18-변수!AC30,"") | AD22: =IFERROR(AC22+AD18-변수!AD30,"") | AE22: =AD22 | AF22: =IFERROR(AD22+AF18-변수!AF30,"") | AG22: =IFERROR(AF22+AG18-변수!AG30,"") | AH22: =IFERROR(AG22+AH18-변수!AH30,"") | AI22: =IFERROR(AH22+AI18-변수!AI30,"") | AJ22: =AI22
A23: 지배주주지분 | B23: 재무상태 | C23: 억원 | D23: 지배주주지분 | E23: =IFERROR(VLOOKUP($D23,BS별도,MATCH(E$1,BS별도H,0),0)/100,"") | F23: 506.53 | J23: =IFERROR(VLOOKUP($D23,BS별도,MATCH(J$1,BS별도H,0),0)/100,"") | K23: =J23 | O23: =IFERROR(VLOOKUP($D23,BS별도,MATCH(O$1,BS별도H,0),0)/100,"") | P23: =O23 | R23: =IFERROR(VLOOKUP($D23,BS별도,MATCH(R$1,BS별도H,0),0)/100,"") | S23: =IFERROR(VLOOKUP($D23,BS별도,MATCH(S$1,BS별도H,0),0)/100,"") | T23: =IFERROR(VLOOKUP($D23,BS별도,MATCH(T$1,BS별도H,0),0)/100,"") | U23: =T23 | V23: =IFERROR(VLOOKUP($D23,BS별도,MATCH(V$1,BS별도H,0),0)/100,"") | W23: =IFERROR(VLOOKUP($D23,BS별도,MATCH(W$1,BS별도H,0),0)/100,"") | X23: =IFERROR(W23+X19-변수!X31,"") | Y23: =IFERROR(X23+Y19-변수!Y31,"") | Z23: =Y23 | AA23: =IFERROR(Y23+AA19-변수!AA31,"") | AB23: =IFERROR(AA23+AB19-변수!AB31,"") | AC23: =IFERROR(AB23+AC19-변수!AC31,"") | AD23: =IFERROR(AC23+AD19-변수!AD31,"") | AE23: =AD23 | AF23: =IFERROR(AD23+AF19-변수!AF31,"") | AG23: =IFERROR(AF23+AG19-변수!AG31,"") | AH23: =IFERROR(AG23+AH19-변수!AH31,"") | AI23: =IFERROR(AH23+AI19-변수!AI31,"") | AJ23: =AI23
A24: 총차입금 | B24: 재무상태 | C24: 억원 | D24: 총차입금 | E24: =IFERROR(VLOOKUP($D24,BS별도,MATCH(E$1,BS별도H,0),0)/100,"") | F24: 672.66 | J24: =IFERROR(VLOOKUP($D24,BS별도,MATCH(J$1,BS별도H,0),0)/100,"") | K24: =J24 | O24: =IFERROR(VLOOKUP($D24,BS별도,MATCH(O$1,BS별도H,0),0)/100,"") | P24: =O24 | R24: =IFERROR(VLOOKUP($D24,BS별도,MATCH(R$1,BS별도H,0),0)/100,"") | S24: =IFERROR(VLOOKUP($D24,BS별도,MATCH(S$1,BS별도H,0),0)/100,"") | T24: =IFERROR(VLOOKUP($D24,BS별도,MATCH(T$1,BS별도H,0),0)/100,"") | U24: =T24 | V24: =IFERROR(VLOOKUP($D24,BS별도,MATCH(V$1,BS별도H,0),0)/100,"") | W24: =IFERROR(VLOOKUP($D24,BS별도,MATCH(W$1,BS별도H,0),0)/100,"") | X24: =IFERROR(W24*(1+변수!X32),"") | Y24: =IFERROR(X24*(1+변수!Y32),"") | Z24: =Y24 | AA24: =IFERROR(Y24*(1+변수!AA32),"") | AB24: =IFERROR(AA24*(1+변수!AB32),"") | AC24: =IFERROR(AB24*(1+변수!AC32),"") | AD24: =IFERROR(AC24*(1+변수!AD32),"") | AE24: =AD24 | AF24: =IFERROR(AD24*(1+변수!AF32),"") | AG24: =IFERROR(AF24*(1+변수!AG32),"") | AH24: =IFERROR(AG24*(1+변수!AH32),"") | AI24: =IFERROR(AH24*(1+변수!AI32),"") | AJ24: =AI24
A25: 순차입금 | B25: 재무상태 | C25: 억원 | D25: 순차입금 | E25: =IFERROR(VLOOKUP($D25,BS별도,MATCH(E$1,BS별도H,0),0)/100,"") | F25: 662.6 | J25: =IFERROR(VLOOKUP($D25,BS별도,MATCH(J$1,BS별도H,0),0)/100,"") | K25: =J25 | O25: =IFERROR(VLOOKUP($D25,BS별도,MATCH(O$1,BS별도H,0),0)/100,"") | P25: =O25 | R25: =IFERROR(VLOOKUP($D25,BS별도,MATCH(R$1,BS별도H,0),0)/100,"") | S25: =IFERROR(VLOOKUP($D25,BS별도,MATCH(S$1,BS별도H,0),0)/100,"") | T25: =IFERROR(VLOOKUP($D25,BS별도,MATCH(T$1,BS별도H,0),0)/100,"") | U25: =T25 | V25: =IFERROR(VLOOKUP($D25,BS별도,MATCH(V$1,BS별도H,0),0)/100,"") | W25: =IFERROR(VLOOKUP($D25,BS별도,MATCH(W$1,BS별도H,0),0)/100,"") | X25: =IFERROR(W25*(1+변수!X33),"") | Y25: =IFERROR(X25*(1+변수!Y33),"") | Z25: =Y25 | AA25: =IFERROR(Y25*(1+변수!AA33),"") | AB25: =IFERROR(AA25*(1+변수!AB33),"") | AC25: =IFERROR(AB25*(1+변수!AC33),"") | AD25: =IFERROR(AC25*(1+변수!AD33),"") | AE25: =AD25 | AF25: =IFERROR(AD25*(1+변수!AF33),"") | AG25: =IFERROR(AF25*(1+변수!AG33),"") | AH25: =IFERROR(AG25*(1+변수!AH33),"") | AI25: =IFERROR(AH25*(1+변수!AI33),"") | AJ25: =AI25
A26: 이자발생자산 | B26: 재무상태 | C26: 억원 | D26: 이자발생자산 | E26: =IFERROR(VLOOKUP($D26,BS별도,MATCH(E$1,BS별도H,0),0)/100,"") | F26: 10.12 | J26: =IFERROR(VLOOKUP($D26,BS별도,MATCH(J$1,BS별도H,0),0)/100,"") | K26: =J26 | O26: =IFERROR(VLOOKUP($D26,BS별도,MATCH(O$1,BS별도H,0),0)/100,"") | P26: =O26 | R26: =IFERROR(VLOOKUP($D26,BS별도,MATCH(R$1,BS별도H,0),0)/100,"") | S26: =IFERROR(VLOOKUP($D26,BS별도,MATCH(S$1,BS별도H,0),0)/100,"") | T26: =IFERROR(VLOOKUP($D26,BS별도,MATCH(T$1,BS별도H,0),0)/100,"") | U26: =T26 | V26: =IFERROR(VLOOKUP($D26,BS별도,MATCH(V$1,BS별도H,0),0)/100,"") | W26: =IFERROR(VLOOKUP($D26,BS별도,MATCH(W$1,BS별도H,0),0)/100,"") | X26: =IFERROR(W26*(1+변수!X34),"") | Y26: =IFERROR(X26*(1+변수!Y34),"") | Z26: =Y26 | AA26: =IFERROR(Y26*(1+변수!AA34),"") | AB26: =IFERROR(AA26*(1+변수!AB34),"") | AC26: =IFERROR(AB26*(1+변수!AC34),"") | AD26: =IFERROR(AC26*(1+변수!AD34),"") | AE26: =AD26 | AF26: =IFERROR(AD26*(1+변수!AF34),"") | AG26: =IFERROR(AF26*(1+변수!AG34),"") | AH26: =IFERROR(AG26*(1+변수!AH34),"") | AI26: =IFERROR(AH26*(1+변수!AI34),"") | AJ26: =AI26
A27: 현금및현금성자산 | B27: 재무상태 | C27: 억원 | D27: 현금및현금성자산 | E27: =IFERROR(VLOOKUP($D27,BS별도,MATCH(E$1,BS별도H,0),0)/100,"") | F27: 10.06 | J27: =IFERROR(VLOOKUP($D27,BS별도,MATCH(J$1,BS별도H,0),0)/100,"") | K27: =J27 | O27: =IFERROR(VLOOKUP($D27,BS별도,MATCH(O$1,BS별도H,0),0)/100,"") | P27: =O27 | R27: =IFERROR(VLOOKUP($D27,BS별도,MATCH(R$1,BS별도H,0),0)/100,"") | S27: =IFERROR(VLOOKUP($D27,BS별도,MATCH(S$1,BS별도H,0),0)/100,"") | T27: =IFERROR(VLOOKUP($D27,BS별도,MATCH(T$1,BS별도H,0),0)/100,"") | U27: =T27 | V27: =IFERROR(VLOOKUP($D27,BS별도,MATCH(V$1,BS별도H,0),0)/100,"") | W27: =IFERROR(VLOOKUP($D27,BS별도,MATCH(W$1,BS별도H,0),0)/100,"") | Z27: =Y27 | AE27: =AD27 | AJ27: =AI27
A28: CAPEX | B28: 현금흐름 | C28: 억원 | D28: CAPEX | K28: =SUM(G28:J28) | P28: =SUM(L28:O28) | U28: =SUM(Q28:T28) | V28: =IFERROR(VLOOKUP($D28,BS별도,MATCH(V$1,BS별도H,0),0)/100,"") | W28: =IFERROR(VLOOKUP($D28,BS별도,MATCH(W$1,BS별도H,0),0)/100,"") | X28: =IFERROR(W28*(1+변수!X36),"") | Y28: =IFERROR(X28*(1+변수!Y36),"") | Z28: =SUM(V28:Y28) | AA28: =IFERROR(V28*(1+변수!AA36),"") | AB28: =IFERROR(W28*(1+변수!AB36),"") | AC28: =IFERROR(X28*(1+변수!AC36),"") | AD28: =IFERROR(Y28*(1+변수!AD36),"") | AE28: =SUM(AA28:AD28) | AF28: =IFERROR(AA28*(1+변수!AF36),"") | AG28: =IFERROR(AB28*(1+변수!AG36),"") | AH28: =IFERROR(AC28*(1+변수!AH36),"") | AI28: =IFERROR(AD28*(1+변수!AI36),"") | AJ28: =SUM(AF28:AI28)
A29: 영업활동현금흐름 | B29: 현금흐름 | C29: 억원 | D29: 영업활동으로인한현금흐름 | K29: =SUM(G29:J29) | O29: =IFERROR(VLOOKUP($D29,BS별도,MATCH(O$1,BS별도H,0),0)/100,"") | P29: =SUM(L29:O29) | R29: =IFERROR(VLOOKUP($D29,BS별도,MATCH(R$1,BS별도H,0),0)/100,"") | S29: =IFERROR(VLOOKUP($D29,BS별도,MATCH(S$1,BS별도H,0),0)/100,"") | T29: =IFERROR(VLOOKUP($D29,BS별도,MATCH(T$1,BS별도H,0),0)/100,"") | U29: =SUM(Q29:T29) | V29: =IFERROR(VLOOKUP($D29,BS별도,MATCH(V$1,BS별도H,0),0)/100,"") | W29: =IFERROR(VLOOKUP($D29,BS별도,MATCH(W$1,BS별도H,0),0)/100,"") | Z29: =SUM(V29:Y29) | AE29: =SUM(AA29:AD29) | AJ29: =SUM(AF29:AI29)
A30: 주식수 | B30: 주당 | C30: 백만주 | D30: 유통주식수 | E30: 15.799943 | F30: =E30 | G30: 15.799943 | H30: 15.799943 | I30: 15.799943 | J30: 17.799943 | K30: =J30 | L30: 17.799943 | M30: 17.799943 | N30: 17.799943 | O30: 17.799943 | P30: =O30 | Q30: 17.799943 | R30: 19.767 | S30: 19.767 | T30: 22.19 | U30: =T30 | V30: 22.19 | W30: 23.05 | X30: =IFERROR(W30*(1+변수!X38),"") | Y30: =IFERROR(X30*(1+변수!Y38),"") | Z30: =Y30 | AA30: =IFERROR(Y30*(1+변수!AA38),"") | AB30: =IFERROR(AA30*(1+변수!AB38),"") | AC30: =IFERROR(AB30*(1+변수!AC38),"") | AD30: =IFERROR(AC30*(1+변수!AD38),"") | AE30: =AD30 | AF30: =IFERROR(AD30*(1+변수!AF38),"") | AG30: =IFERROR(AF30*(1+변수!AG38),"") | AH30: =IFERROR(AG30*(1+변수!AH38),"") | AI30: =IFERROR(AH30*(1+변수!AI38),"") | AJ30: =AI30
A31: EPS | B31: 주당 | C31: 원 | D31: EPS | K31: =SUM(G31:J31) | O31: =IFERROR(O19*100/O30,"") | P31: =SUM(L31:O31) | R31: =IFERROR(R19*100/R30,"") | S31: =IFERROR(S19*100/S30,"") | T31: =IFERROR(T19*100/T30,"") | U31: =SUM(Q31:T31) | V31: =IFERROR(V19*100/V30,"") | W31: =IFERROR(W19*100/W30,"") | X31: =IFERROR(X19*100/X30,"") | Y31: =IFERROR(Y19*100/Y30,"") | Z31: =SUM(V31:Y31) | AA31: =IFERROR(AA19*100/AA30,"") | AB31: =IFERROR(AB19*100/AB30,"") | AC31: =IFERROR(AC19*100/AC30,"") | AD31: =IFERROR(AD19*100/AD30,"") | AE31: =SUM(AA31:AD31) | AF31: =IFERROR(AF19*100/AF30,"") | AG31: =IFERROR(AG19*100/AG30,"") | AH31: =IFERROR(AH19*100/AH30,"") | AI31: =IFERROR(AI19*100/AI30,"") | AJ31: =SUM(AF31:AI31)
A32: 조정EPS | B32: 주당 | C32: 원 | D32: 조정 EPS(일회성 의심 분기의 초과 비영업손익 세후 차감 — 모델 추정) | K32: =SUM(G32:J32) | O32: =IFERROR(O31,"") | P32: =SUM(L32:O32) | R32: =IFERROR(R31,"") | S32: =IFERROR(S31,"") | T32: =IFERROR((T19-(-28.47)*(1.0))*100/T30,"") | U32: =SUM(Q32:T32) | V32: =IFERROR(V31,"") | W32: =IFERROR(W31,"") | X32: =IFERROR(X31,"") | Y32: =IFERROR(Y31,"") | Z32: =SUM(V32:Y32) | AA32: =IFERROR(AA31,"") | AB32: =IFERROR(AB31,"") | AC32: =IFERROR(AC31,"") | AD32: =IFERROR(AD31,"") | AE32: =SUM(AA32:AD32) | AF32: =IFERROR(AF31,"") | AG32: =IFERROR(AG31,"") | AH32: =IFERROR(AH31,"") | AI32: =IFERROR(AI31,"") | AJ32: =SUM(AF32:AI32)
A33: BPS | B33: 주당 | C33: 원 | D33: BPS | E33: =IFERROR(E23*100/E30,"") | F33: =E33 | J33: =IFERROR(J23*100/J30,"") | K33: =J33 | O33: =IFERROR(O23*100/O30,"") | P33: =O33 | R33: =IFERROR(R23*100/R30,"") | S33: =IFERROR(S23*100/S30,"") | T33: =IFERROR(T23*100/T30,"") | U33: =T33 | V33: =IFERROR(V23*100/V30,"") | W33: =IFERROR(W23*100/W30,"") | X33: =IFERROR(X23*100/X30,"") | Y33: =IFERROR(Y23*100/Y30,"") | Z33: =Y33 | AA33: =IFERROR(AA23*100/AA30,"") | AB33: =IFERROR(AB23*100/AB30,"") | AC33: =IFERROR(AC23*100/AC30,"") | AD33: =IFERROR(AD23*100/AD30,"") | AE33: =AD33 | AF33: =IFERROR(AF23*100/AF30,"") | AG33: =IFERROR(AG23*100/AG30,"") | AH33: =IFERROR(AH23*100/AH30,"") | AI33: =IFERROR(AI23*100/AI30,"") | AJ33: =AI33
A34: DPS | B34: 주당 | C34: 원 | D34: DPS(보통주) | E34: 0 | F34: 0 | J34: 0 | K34: =SUM(G34:J34) | O34: 0 | P34: =SUM(L34:O34) | T34: 0 | U34: =SUM(Q34:T34) | Y34: =변수!Y39 | Z34: =SUM(V34:Y34) | AD34: =변수!AD39 | AE34: =SUM(AA34:AD34) | AI34: =변수!AI39 | AJ34: =SUM(AF34:AI34)
A35: PER | B35: 주당 | C35: 배 | D35: PER | F35: =E35 | K35: =J35 | P35: =O35 | U35: =T35 | V35: =IFERROR(변수!V18/(R31+S31+T31+V31),"") | W35: =IFERROR(변수!W18/(S31+T31+V31+W31),"") | X35: =IFERROR(변수!$D$42/(T31+V31+W31+X31),"") | Y35: =IFERROR(변수!$D$42/(V31+W31+X31+Y31),"") | Z35: =Y35 | AA35: =IFERROR(변수!$D$42/(W31+X31+Y31+AA31),"") | AB35: =IFERROR(변수!$D$42/(X31+Y31+AA31+AB31),"") | AC35: =IFERROR(변수!$D$42/(Y31+AA31+AB31+AC31),"") | AD35: =IFERROR(변수!$D$42/(AA31+AB31+AC31+AD31),"") | AE35: =AD35 | AF35: =IFERROR(변수!$D$42/(AB31+AC31+AD31+AF31),"") | AG35: =IFERROR(변수!$D$42/(AC31+AD31+AF31+AG31),"") | AH35: =IFERROR(변수!$D$42/(AD31+AF31+AG31+AH31),"") | AI35: =IFERROR(변수!$D$42/(AF31+AG31+AH31+AI31),"") | AJ35: =AI35
A36: PBR | B36: 주당 | C36: 배 | D36: PBR | F36: =E36 | J36: =IFERROR(변수!J18/J33,"") | K36: =J36 | O36: =IFERROR(변수!O18/O33,"") | P36: =O36 | R36: =IFERROR(변수!R18/R33,"") | S36: =IFERROR(변수!S18/S33,"") | T36: =IFERROR(변수!T18/T33,"") | U36: =T36 | V36: =IFERROR(변수!V18/V33,"") | W36: =IFERROR(변수!W18/W33,"") | X36: =IFERROR(변수!$D$42/X33,"") | Y36: =IFERROR(변수!$D$42/Y33,"") | Z36: =Y36 | AA36: =IFERROR(변수!$D$42/AA33,"") | AB36: =IFERROR(변수!$D$42/AB33,"") | AC36: =IFERROR(변수!$D$42/AC33,"") | AD36: =IFERROR(변수!$D$42/AD33,"") | AE36: =AD36 | AF36: =IFERROR(변수!$D$42/AF33,"") | AG36: =IFERROR(변수!$D$42/AG33,"") | AH36: =IFERROR(변수!$D$42/AH33,"") | AI36: =IFERROR(변수!$D$42/AI33,"") | AJ36: =AI36
A37: 매출전사 | B37: 사업부 | C37: 억원 | D37: 매출 전사(부문 미분리) | K37: =SUM(G37:J37) | O37: 183.54 | P37: =SUM(L37:O37) | R37: 225.66 | S37: 175.5 | T37: 160.11 | U37: =SUM(Q37:T37) | V37: 182.59 | W37: 222.59 | X37: =IFERROR(X5,"") | Y37: =IFERROR(Y5,"") | Z37: =SUM(V37:Y37) | AA37: =IFERROR(AA5,"") | AB37: =IFERROR(AB5,"") | AC37: =IFERROR(AC5,"") | AD37: =IFERROR(AD5,"") | AE37: =SUM(AA37:AD37) | AF37: =IFERROR(AF5,"") | AG37: =IFERROR(AG5,"") | AH37: =IFERROR(AH5,"") | AI37: =IFERROR(AI5,"") | AJ37: =SUM(AF37:AI37)
A38: OP전사 | B38: 사업부 | C38: 억원 | D38: OP 전사(부문 미분리) | K38: =SUM(G38:J38) | O38: 0.89 | P38: =SUM(L38:O38) | R38: 24.44 | S38: 9.26 | T38: 14.58 | U38: =SUM(Q38:T38) | V38: 16.02 | W38: 26.07 | X38: =IFERROR(X9,"") | Y38: =IFERROR(Y9,"") | Z38: =SUM(V38:Y38) | AA38: =IFERROR(AA9,"") | AB38: =IFERROR(AB9,"") | AC38: =IFERROR(AC9,"") | AD38: =IFERROR(AD9,"") | AE38: =SUM(AA38:AD38) | AF38: =IFERROR(AF9,"") | AG38: =IFERROR(AG9,"") | AH38: =IFERROR(AH9,"") | AI38: =IFERROR(AI9,"") | AJ38: =SUM(AF38:AI38)
B39: 비율(참고)
A40: NPM | C40: % | D40: 지배주주순이익 / 매출액 | E40: =IFERROR(E19/E5,"") | F40: =IFERROR(F19/F5,"") | G40: =IFERROR(G19/G5,"") | H40: =IFERROR(H19/H5,"") | I40: =IFERROR(I19/I5,"") | J40: =IFERROR(J19/J5,"") | K40: =IFERROR(K19/K5,"") | L40: =IFERROR(L19/L5,"") | ... AJ40: =IFERROR(AJ19/AJ5,"")
...

Sheet 분기
C1: 이름: 분기H — subQ 를 이름으로 VLOOKUP(억원) | E1: 4Q22 | F1: 1Q23 | G1: 2Q23 | H1: 3Q23 | I1: 4Q23 | J1: 1Q24 | K1: 2Q24 | L1: 3Q24 | M1: 4Q24 | N1: 1Q25 | O1: 2Q25 | P1: 3Q25 | Q1: 4Q25 | R1: 1Q26 | S1: 2Q26 | T1: 3Q26 | U1: 4Q26 | V1: 1Q27 | W1: 2Q27 | X1: 3Q27 | Y1: 4Q27 | Z1: 1Q28 | AA1: 2Q28 | AB1: 3Q28 | AC1: 4Q28
C2: 종가: | D2: =변수!D42
C3: 기준일: | D3: 20261013 | E3: 1 | F3: 2 | G3: 3 | H3: 4 | I3: 5 | J3: 6 | K3: 7 | L3: 8 | M3: 9 | N3: 10 | O3: 11 | P3: 12 | Q3: 13 | R3: 14 | S3: 15 | T3: 16 | U3: 17 | V3: 18 | W3: 19 | X3: 20 | Y3: 21 | Z3: 22 | AA3: 23 | AB3: 24 | AC3: 25
E4: 2022.12 | F4: 2023.03 | G4: 2023.06 | H4: 2023.09 | I4: 2023.12 | J4: 2024.03 | K4: 2024.06 | L4: 2024.09 | M4: 2024.12 | N4: 2025.03 | O4: 2025.06 | P4: 2025.09 | Q4: 2025.12 | R4: 2026.03 | S4: 2026.06 | T4: 2026.09 | U4: 2026.12 | V4: 2027.03 | W4: 2027.06 | X4: 2027.09 | Y4: 2027.12 | Z4: 2028.03 | AA4: 2028.06 | AB4: 2028.09 | AC4: 2028.12
A5: 매출액 | D5: 매출액 | E5: =IFERROR(VLOOKUP($A5,subQ,MATCH(E$1,SUBQH,0),0),"") | F5: =IFERROR(VLOOKUP($A5,subQ,MATCH(F$1,SUBQH,0),0),"") | G5: =IFERROR(VLOOKUP($A5,subQ,MATCH(G$1,SUBQH,0),0),"") | H5: =IFERROR(VLOOKUP($A5,subQ,MATCH(H$1,SUBQH,0),0),"") | I5: =IFERROR(VLOOKUP($A5,subQ,MATCH(I$1,SUBQH,0),0),"") | J5: =IFERROR(VLOOKUP($A5,subQ,MATCH(J$1,SUBQH,0),0),"") | K5: =IFERROR(VLOOKUP($A5,subQ,MATCH(K$1,SUBQH,0),0),"") | L5: =IFERROR(VLOOKUP($A5,subQ,MATCH(L$1,SUBQH,0),0),"") | ... AC5: =IFERROR(VLOOKUP($A5,subQ,MATCH(AC$1,SUBQH,0),0),"")
A6: 매출원가 | D6: 매출원가 | E6: =IFERROR(VLOOKUP($A6,subQ,MATCH(E$1,SUBQH,0),0),"") | F6: =IFERROR(VLOOKUP($A6,subQ,MATCH(F$1,SUBQH,0),0),"") | G6: =IFERROR(VLOOKUP($A6,subQ,MATCH(G$1,SUBQH,0),0),"") | H6: =IFERROR(VLOOKUP($A6,subQ,MATCH(H$1,SUBQH,0),0),"") | I6: =IFERROR(VLOOKUP($A6,subQ,MATCH(I$1,SUBQH,0),0),"") | J6: =IFERROR(VLOOKUP($A6,subQ,MATCH(J$1,SUBQH,0),0),"") | K6: =IFERROR(VLOOKUP($A6,subQ,MATCH(K$1,SUBQH,0),0),"") | L6: =IFERROR(VLOOKUP($A6,subQ,MATCH(L$1,SUBQH,0),0),"") | ... AC6: =IFERROR(VLOOKUP($A6,subQ,MATCH(AC$1,SUBQH,0),0),"")
A7: 매출총이익 | D7: 매출총이익 | E7: =IFERROR(VLOOKUP($A7,subQ,MATCH(E$1,SUBQH,0),0),"") | F7: =IFERROR(VLOOKUP($A7,subQ,MATCH(F$1,SUBQH,0),0),"") | G7: =IFERROR(VLOOKUP($A7,subQ,MATCH(G$1,SUBQH,0),0),"") | H7: =IFERROR(VLOOKUP($A7,subQ,MATCH(H$1,SUBQH,0),0),"") | I7: =IFERROR(VLOOKUP($A7,subQ,MATCH(I$1,SUBQH,0),0),"") | J7: =IFERROR(VLOOKUP($A7,subQ,MATCH(J$1,SUBQH,0),0),"") | K7: =IFERROR(VLOOKUP($A7,subQ,MATCH(K$1,SUBQH,0),0),"") | L7: =IFERROR(VLOOKUP($A7,subQ,MATCH(L$1,SUBQH,0),0),"") | ... AC7: =IFERROR(VLOOKUP($A7,subQ,MATCH(AC$1,SUBQH,0),0),"")
A8: 판관비 | D8: 판매비와관리비 | E8: =IFERROR(VLOOKUP($A8,subQ,MATCH(E$1,SUBQH,0),0),"") | F8: =IFERROR(VLOOKUP($A8,subQ,MATCH(F$1,SUBQH,0),0),"") | G8: =IFERROR(VLOOKUP($A8,subQ,MATCH(G$1,SUBQH,0),0),"") | H8: =IFERROR(VLOOKUP($A8,subQ,MATCH(H$1,SUBQH,0),0),"") | I8: =IFERROR(VLOOKUP($A8,subQ,MATCH(I$1,SUBQH,0),0),"") | J8: =IFERROR(VLOOKUP($A8,subQ,MATCH(J$1,SUBQH,0),0),"") | K8: =IFERROR(VLOOKUP($A8,subQ,MATCH(K$1,SUBQH,0),0),"") | L8: =IFERROR(VLOOKUP($A8,subQ,MATCH(L$1,SUBQH,0),0),"") | ... AC8: =IFERROR(VLOOKUP($A8,subQ,MATCH(AC$1,SUBQH,0),0),"")
