Workbook
Name 변수H: 변수!$C$1:$AO$1
Name 환율: 변수!$C$6:$AO$13
Name BS연결H: BS연결!$C$1:$AO$1
Name BS연결: BS연결!$C$5:$AO$69
Name BS별도H: BS별도!$C$1:$AO$1
Name BS별도: BS별도!$C$5:$AO$67
Name SUBQH: subQ!$A$1:$AO$1
Name subQ: subQ!$A$5:$AO$37

Sheet README
A1: 하이록코리아(013030) 실적 모델 — ARGUS 한국조선
A2: 기준 분기 2026Q2 · 마지막 실적 2026Q2 · 생성 2026-10-12
A3: 모든 수치는 모델 산출값(DART 공개 재무제표 + 우리 추정)이다 — 목표주가·투자 추천 아님. 참고용 · 투자조언 아님.
A5: 시트
A6: 변수 가정 시계열. 환율 8행(ECB via frankfurter — L2 fx.json; 추정 분기 = 노란 가정), 추정 드라이버(노란 셀 = 모델값에서 역산한 가정, 바꾸면 재계산; 연녹 셀 = 3절 스칼라 참조 수식), 3절 스칼라 가정(세율·판관비율·지배주주비중·이자율·종가·PER 밴드·COE·외화 순노출·헤지비율)
A7: BS연결/BS별도 FnGuide 계정명 × 기간 값 덤프(백만원). 행1 분기라벨, 행4 YYYY.MM / YYYY.12A. 이름정의 BS연결H·BS연결(계정명 C열부터)
A8: subQ 분기 서브모델(억원 = 백만원/100). 확정 행: =IFERROR(VLOOKUP($D행,BS연결,MATCH(E$1,BS연결H,0),0)/100,"") 추정 행: 변수 시트 가정 셀 참조 수식. 외환손익·파생상품손익은 BS 계정 합·차, 기타금융손익은 잔차, OPM·EPS·BPS·PER·PBR 은 파생 수식
A9: SLS 선표(조선사만, sls json 있을 때): 요약 행(sls 저장값) + 계약별 스케줄(백만$) × (헤지비율 × 헤지환율 + (1−헤지비율) × 건조시점 환율[변수 원/달러(평균)]) → 원화 수식 블록 → 합계 행이 subQ 매출조선에 연결
A10: 시나리오 신규수주 보수/기준/낙관(forecast_panel 패널, 모델에 scenarios 가 있을 때만): 매출액·영업이익 = subQ 기준값 ± (시나리오 신규 − base 신규) × OPM. base 만 subQ 행에 포함, 나머지는 합산 안 함
A11: 분기/연간예상 subQ 를 이름(A열 key)으로 VLOOKUP 한 보고서 표(억원)
A12: TP PER 밴드 × 12M fwd EPS, PBR = ROE/COE × BPS — 모델 산출값 구간, 목표주가·추천 아님
A13: 외화 환율 QoQ, 외화 순노출 × Δ기말환율 → 환관련손익 추정
... A34: 백테스트: {"freeze": "2025Q2", "horizon": 4, "revenue_wape_pct": 7.8, "op_wape_pct": 0.8, "n": 4, "note": "단일 회사 4분기 — 통계 아님", "driver_at_freeze": "trend_seasonal", "selection_oos_at_freeze": null, "frozen_inputs": "fin(연결/별도)·고객 조선사 모델·지주 자회사 모델은 2025Q2 까지의 분기만; 선표는 체결일 ≤ 2025Q2 말일 계약(원장 최신 금액·코호트 등급, 환산 없음); 잔고는 yards_cache 2025Q2; 시세·환율 forward·prices·forecast_panel 신규수주 미사용. 고객 가중치(suppliers.json 언급 비중)와 합병 체인링크는 현재 지식; 고객 연동 채택은 동결 모델 안에서도 자기 la−4분기 OOS 규칙(selection_oos_at_freeze)", "detail": [{"q": "2025Q3", "rev_pred": 473.52, "rev_act": 538.45, "op_pred": 142.99, "op_act": 141.98}, {"q": "2025Q4", "rev_pred": 516.21, "rev_act": 573.52, "op_pred": 155.87, "op_act": 155.81}, {"q": "2026Q1", "rev_pred": 512.74, "rev_act": 541.46, "op_pred": 154.83, "op_act": 156.86}, {"q": "2026Q2", "rev_pred": 568.14, "rev_act": 592.51, "op_pred": 171.56, "op_act": 169.91}]}

Sheet 변수
C1: 이름: 변수H | E1: 4Q21 | F1: 2021 | G1: 1Q22 | H1: 2Q22 | I1: 3Q22 | J1: 4Q22 | K1: 2022 | L1: 1Q23 | M1: 2Q23 | N1: 3Q23 | O1: 4Q23 | P1: 2023 | Q1: 1Q24 | R1: 2Q24 | S1: 3Q24 | T1: 4Q24 | U1: 2024 | V1: 1Q25 | W1: 2Q25 | X1: 3Q25 | Y1: 4Q25 | Z1: 2025 | AA1: 1Q26 | AB1: 2Q26 | AC1: 3Q26 | AD1: 4Q26 | AE1: 2026 | AF1: 1Q27 | AG1: 2Q27 | AH1: 3Q27 | AI1: 4Q27 | AJ1: 2027 | AK1: 1Q28 | AL1: 2Q28 | AM1: 3Q28 | AN1: 4Q28 | AO1: 2028
A2: 가정 시계열 — 노란 셀은 추정 가정(모델값에서 역산), 연녹 셀은 3절 스칼라 참조 수식. 바꾸면 subQ·분기·연간예상·TP·시나리오가 재계산됩니다.
E3: 1 | F3: 2 | G3: 3 | H3: 4 | I3: 5 | J3: 6 | K3: 7 | L3: 8 | M3: 9 | N3: 10 | O3: 11 | P3: 12 | Q3: 13 | R3: 14 | S3: 15 | T3: 16 | U3: 17 | V3: 18 | W3: 19 | X3: 20 | Y3: 21 | Z3: 22 | AA3: 23 | AB3: 24 | AC3: 25 | AD3: 26 | AE3: 27 | AF3: 28 | AG3: 29 | AH3: 30 | AI3: 31 | AJ3: 32 | AK3: 33 | AL3: 34 | AM3: 35 | AN3: 36 | AO3: 37
E4: 2021.12 | F4: 2021.12A | G4: 2022.03 | H4: 2022.06 | I4: 2022.09 | J4: 2022.12 | K4: 2022.12A | L4: 2023.03 | M4: 2023.06 | N4: 2023.09 | O4: 2023.12 | P4: 2023.12A | Q4: 2024.03 | R4: 2024.06 | S4: 2024.09 | T4: 2024.12 | U4: 2024.12A | V4: 2025.03 | W4: 2025.06 | X4: 2025.09 | Y4: 2025.12 | Z4: 2025.12A | AA4: 2026.03 | AB4: 2026.06 | AC4: 2026.09 | AD4: 2026.12 | AE4: 2026.12A | AF4: 2027.03 | AG4: 2027.06 | AH4: 2027.09 | AI4: 2027.12 | AJ4: 2027.12A | AK4: 2028.03 | AL4: 2028.06 | AM4: 2028.09 | AN4: 2028.12 | AO4: 2028.12A
B5: 1. FX | C5: 이름: 환율
A6: USDKRW_avg | C6: 원/달러(평균) | E6: 1183.5 | F6: 1145.51 | G6: 1205.78 | H6: 1262.09 | I6: 1341.93 | J6: 1360.12 | K6: 1292.98 | L6: 1276.95 | M6: 1315.69 | N6: 1313.62 | O6: 1322.01 | P6: 1306.85 | Q6: 1330.14 | R6: 1371.28 | S6: 1356.22 | T6: 1396.3 | U6: 1363.53 | V6: 1452.28 | W6: 1398.52 | X6: 1386.95 | Y6: 1449.19 | Z6: 1421.52 | AA6: 1466.12 | AB6: 1501.75 | AC6: 1418.75 | AD6: 1345.14 | AE6: 1457.21 | AF6: 1341.49 | AG6: 1341.49 | AH6: 1341.49 | AI6: 1341.49 | AK6: 1341.49 | AL6: 1341.49 | AM6: 1341.49 | AN6: 1341.49
A7: USDKRW_end | C7: 원/달러(기말) | E7: 1188.75 | F7: 1188.75 | G7: 1213.74 | H7: 1301.24 | I7: 1436.9 | J7: 1260.16 | K7: 1260.16 | L7: 1305.99 | M7: 1321.44 | N7: 1345.35 | O7: 1297.43 | P7: 1297.43 | Q7: 1349.25 | R7: 1377.73 | S7: 1312.17 | T7: 1474.78 | U7: 1474.78 | V7: 1474.54 | W7: 1355.13 | X7: 1403.67 | Y7: 1444.2 | Z7: 1444.2 | AA7: 1524.8 | AB7: 1550.89 | AC7: 1355.4 | AD7: 1341.49 | AE7: 1341.49 | AF7: 1341.49 | AG7: 1341.49 | AH7: 1341.49 | AI7: 1341.49 | AK7: 1341.49 | AL7: 1341.49 | AM7: 1341.49 | AN7: 1341.49
A8: JPY100KRW_avg | C8: 원/100Y(평균) | E8: 1041.02 | F8: 1042.74 | G8: 1036.79 | H8: 972.23 | I8: 970.61 | J8: 961.03 | K8: 985.1 | L8: 964.89 | M8: 957.36 | N8: 909 | O8: 893.22 | P8: 931.11 | Q8: 896.29 | R8: 880.14 | S8: 909.35 | T8: 917.25 | U8: 900.92 | V8: 952.59 | W8: 967.92 | X8: 940.32 | Y8: 940.77 | Z8: 950.17 | AA8: 934.39 | AB8: 942.16 | AC8: 890.41 | AD8: 850.79 | AE8: 919.21 | AF8: 847.7 | AG8: 847.7 | AH8: 847.7 | AI8: 847.7 | AK8: 847.7 | AL8: 847.7 | AM8: 847.7 | AN8: 847.7
A9: JPY100KRW_end | C9: 원/100Y(기말) | E9: 1032.62 | F9: 1032.62 | G9: 996.83 | H9: 954.9 | I9: 993.29 | J9: 955.54 | K9: 955.54 | L9: 980.62 | M9: 913.67 | N9: 901.47 | O9: 917.04 | P9: 917.04 | Q9: 892.42 | R9: 857.76 | S9: 919.21 | T9: 939.65 | U9: 939.65 | V9: 986.84 | W9: 938.85 | X9: 948.49 | Y9: 921.81 | Z9: 921.81 | AA9: 955.99 | AB9: 954.75 | AC9: 863.31 | AD9: 847.7 | AE9: 847.7 | AF9: 847.7 | AG9: 847.7 | AH9: 847.7 | AI9: 847.7 | AK9: 847.7 | AL9: 847.7 | AM9: 847.7 | AN9: 847.7
A10: EURKRW_avg | C10: W/Euro(평균) | E10: 1353.32 | F10: 1354.06 | G10: 1352.29 | H10: 1343.31 | I10: 1350.63 | J10: 1386.07 | K10: 1358.07 | L10: 1369.93 | M10: 1432.41 | N10: 1429.41 | O10: 1420.91 | P10: 1412.88 | Q10: 1444.21 | R10: 1476.42 | S10: 1489.3 | T10: 1490.78 | U10: 1475.4 | V10: 1528.33 | W10: 1585.13 | X10: 1620.04 | Y10: 1686.02 | Z10: 1605.45 | AA10: 1715.47 | AB10: 1746.09 | AC10: 1631.97 | AD10: 1509.74 | AE10: 1689.95 | AF10: 1503.27 | AG10: 1503.27 | AH10: 1503.27 | AI10: 1503.27 | AK10: 1503.27 | AL10: 1503.27 | AM10: 1503.27 | AN10: 1503.27
A11: EURKRW_end | C11: W/Euro(기말) | E11: 1346.38 | F11: 1346.38 | G11: 1347.37 | H11: 1351.6 | I11: 1400.62 | J11: 1344.08 | K11: 1344.08 | L11: 1420.26 | M11: 1435.88 | N11: 1425.26 | O11: 1433.66 | P11: 1433.66 | Q11: 1458.68 | R11: 1474.86 | S11: 1469.1 | T11: 1532.14 | U11: 1532.14 | V11: 1594.72 | W11: 1588.22 | X11: 1648.04 | Y11: 1696.94 | Z11: 1696.94 | AA11: 1753.21 | AB11: 1767.09 | AC11: 1539.06 | AD11: 1503.27 | AE11: 1503.27 | AF11: 1503.27 | AG11: 1503.27 | AH11: 1503.27 | AI11: 1503.27 | AK11: 1503.27 | AL11: 1503.27 | AM11: 1503.27 | AN11: 1503.27
A12: CNYKRW_avg | C12: 원/중국원(평균) | E12: 185.14 | F12: 177.65 | G12: 189.93 | H12: 190.76 | I12: 195.79 | J12: 191.09 | K12: 191.93 | L12: 186.59 | M12: 187.45 | N12: 181.28 | O12: 182.86 | P12: 184.52 | Q12: 185.04 | R12: 189.35 | S12: 189.24 | T12: 194.24 | U12: 189.49 | V12: 199.63 | W12: 193.41 | X12: 193.79 | Y12: 204.38 | Z12: 197.8 | AA12: 211.75 | AB12: 220.8 | AC12: 210.43 | AD12: 200.69 | AE12: 213.75 | AF12: 200.46 | AG12: 200.46 | AH12: 200.46 | AI12: 200.46 | AK12: 200.46 | AL12: 200.46 | AM12: 200.46 | AN12: 200.46
A13: CNYKRW_end | C13: 원/중국원(기말) | E13: 187.13 | F13: 187.13 | G13: 191.38 | H13: 194.13 | I13: 201.92 | J13: 182.67 | K13: 182.67 | L13: 189.97 | M13: 181.8 | N13: 184.26 | O13: 182.61 | P13: 182.61 | Q13: 186.66 | R13: 189.7 | S13: 187.12 | T13: 202.04 | U13: 202.04 | V13: 203.3 | W13: 189.14 | X13: 197.16 | Y13: 206.28 | Z13: 206.28 | AA13: 220.97 | AB13: 228.56 | AC13: 202.16 | AD13: 200.46 | AE13: 200.46 | AF13: 200.46 | AG13: 200.46 | AH13: 200.46 | AI13: 200.46 | AK13: 200.46 | AL13: 200.46 | AM13: 200.46 | AN13: 200.46
B14: 1b. 종가
A15: price_close_end | C15: 종가(기말) | E15: 16750 | G15: 17950 | H15: 18650 | I15: 21000 | J15: 20500 | L15: 23050 | M15: 26350 | N15: 27250 | O15: 26650 | Q15: 25950 | R15: 27900 | S15: 25100 | T15: 25150 | V15: 26600 | W15: 30150 | X15: 34650 | Y15: 30750 | AA15: 34950 | AB15: 31550 | AC15: 36650 | AD15: 33350
A16: price_high | C16: 종가(최고) | E16: 19600 | G16: 18550 | H16: 19550 | I16: 26900 | J16: 23700 | L16: 25450 | M16: 26650 | N16: 31600 | O16: 28550 | Q16: 28100 | R16: 30250 | S16: 29350 | T16: 27550 | V16: 32450 | W16: 32200 | X16: 41500 | Y16: 39600 | AA16: 41800 | AB16: 48100 | AC16: 39150 | AD16: 37200
A17: price_low | C17: 종가(최저) | E17: 15100 | G17: 14950 | H17: 16100 | I17: 16550 | J17: 18750 | L17: 18750 | M17: 20200 | N17: 24950 | O17: 22950 | Q17: 23250 | R17: 24100 | S17: 23400 | T17: 22400 | V17: 24700 | W17: 25050 | X17: 28250 | Y17: 30400 | AA17: 29550 | AB17: 29150 | AC17: 27550 | AD17: 33000
A18: price_avg | C18: 종가(평균) | E18: 17332.5 | G18: 17076.3 | H18: 18184.7 | I18: 20820.6 | J18: 21030.6 | L18: 22295.2 | M18: 22935.2 | N18: 27416.1 | O18: 26108.3 | Q18: 25520.5 | R18: 27053.3 | S18: 26740.3 | T18: 24737.7 | V18: 28184.5 | W18: 28673.3 | X18: 31993.8 | Y18: 34214.4 | AA18: 34394.9 | AB18: 38186.1 | AC18: 32882.3 | AD18: 35216.7
B20: 2. 추정 드라이버 | C20: 실적 열 = subQ 실현값(수식), 추정 열 = 가정(노란 = 모델값 역산, 연녹 = 3절 스칼라 참조)
A21: drv:매출액 | B21: yoy | C21: 매출액 YoY | J21: =IFERROR(subQ!J5/subQ!E5-1,"") | L21: =IFERROR(subQ!L5/subQ!G5-1,"") | M21: =IFERROR(subQ!M5/subQ!H5-1,"") | N21: =IFERROR(subQ!N5/subQ!I5-1,"") | O21: =IFERROR(subQ!O5/subQ!J5-1,"") | Q21: =IFERROR(subQ!Q5/subQ!L5-1,"") | R21: =IFERROR(subQ!R5/subQ!M5-1,"") | S21: =IFERROR(subQ!S5/subQ!N5-1,"") | T21: =IFERROR(subQ!T5/subQ!O5-1,"") | V21: =IFERROR(subQ!V5/subQ!Q5-1,"") | W21: =IFERROR(subQ!W5/subQ!R5-1,"") | X21: =IFERROR(subQ!X5/subQ!S5-1,"") | Y21: =IFERROR(subQ!Y5/subQ!T5-1,"") | AA21: =IFERROR(subQ!AA5/subQ!V5-1,"") | AB21: =IFERROR(subQ!AB5/subQ!W5-1,"") | AC21: 0.1341977 | AD21: 0.13420195 | AF21: 0.13419567 | AG21: 0.13419527 | AH21: 0.067102225 | AI21: 0.067103261 | AK21: 0.067104149 | AL21: 0.067111098 | AM21: 0.033543556 | AN21: 0.033537903
A22: drv:판관비 | B22: ratio | C22: 판관비율(/매출) | E22: =IFERROR(subQ!E8/subQ!E5,"") | F22: =IFERROR(subQ!F8/subQ!F5,"") | G22: =IFERROR(subQ!G8/subQ!G5,"") | H22: =IFERROR(subQ!H8/subQ!H5,"") | I22: =IFERROR(subQ!I8/subQ!I5,"") | J22: =IFERROR(subQ!J8/subQ!J5,"") | K22: =IFERROR(subQ!K8/subQ!K5,"") | L22: =IFERROR(subQ!L8/subQ!L5,"") | ... AB22: =IFERROR(subQ!AB8/subQ!AB5,"") | AC22: =$D$46 | AD22: =$D$46 | AE22: =IFERROR(subQ!AE8/subQ!AE5,"") | AF22: =$D$46 | AG22: =$D$46 | AH22: =$D$46 | AI22: =$D$46 | AJ22: =IFERROR(subQ!AJ8/subQ!AJ5,"") | AK22: =$D$46 | AL22: =$D$46 | AM22: =$D$46 | AN22: =$D$46 | AO22: =IFERROR(subQ!AO8/subQ!AO5,"")
A23: drv:영업이익 | B23: ratio | C23: 영업이익률(OPM) | E23: =IFERROR(subQ!E9/subQ!E5,"") | F23: =IFERROR(subQ!F9/subQ!F5,"") | G23: =IFERROR(subQ!G9/subQ!G5,"") | H23: =IFERROR(subQ!H9/subQ!H5,"") | I23: =IFERROR(subQ!I9/subQ!I5,"") | J23: =IFERROR(subQ!J9/subQ!J5,"") | K23: =IFERROR(subQ!K9/subQ!K5,"") | L23: =IFERROR(subQ!L9/subQ!L5,"") | ... AB23: =IFERROR(subQ!AB9/subQ!AB5,"") | AC23: 0.27921599 | AD23: 0.27922028 | AE23: =IFERROR(subQ!AE9/subQ!AE5,"") | AF23: 0.27921253 | AG23: 0.27921788 | AH23: 0.27921251 | AI23: 0.27920881 | AJ23: =IFERROR(subQ!AJ9/subQ!AJ5,"") | AK23: 0.2792181 | AL23: 0.27921408 | AM23: 0.27922203 | AN23: 0.27920883 | AO23: =IFERROR(subQ!AO9/subQ!AO5,"")
A24: drv:기타영업외손익 | B24: abs | C24: 기타영업외손익 (가정, 억원) | E24: =subQ!E13 | F24: =subQ!F13 | G24: =subQ!G13 | H24: =subQ!H13 | I24: =subQ!I13 | J24: =subQ!J13 | K24: =subQ!K13 | L24: =subQ!L13 | ... AB24: =subQ!AB13 | AC24: 0 | AD24: 0 | AE24: =subQ!AE13 | AF24: 0 | AG24: 0 | AH24: 0 | AI24: 0 | AJ24: =subQ!AJ13 | AK24: 0 | AL24: 0 | AM24: 0 | AN24: 0 | AO24: =subQ!AO13
A25: drv:법인세비용 | B25: tax | C25: 법인세율(/세전) — 법인세 = MAX(세전,0) × 세율 | E25: =IFERROR(subQ!E15/subQ!E14,"") | F25: =IFERROR(subQ!F15/subQ!F14,"") | G25: =IFERROR(subQ!G15/subQ!G14,"") | H25: =IFERROR(subQ!H15/subQ!H14,"") | I25: =IFERROR(subQ!I15/subQ!I14,"") | J25: =IFERROR(subQ!J15/subQ!J14,"") | K25: =IFERROR(subQ!K15/subQ!K14,"") | L25: =IFERROR(subQ!L15/subQ!L14,"") | ... AB25: =IFERROR(subQ!AB15/subQ!AB14,"") | AC25: =$D$45 | AD25: =$D$45 | AE25: =IFERROR(subQ!AE15/subQ!AE14,"") | AF25: =$D$45 | AG25: =$D$45 | AH25: =$D$45 | AI25: =$D$45 | AJ25: =IFERROR(subQ!AJ15/subQ!AJ14,"") | AK25: =$D$45 | AL25: =$D$45 | AM25: =$D$45 | AN25: =$D$45 | AO25: =IFERROR(subQ!AO15/subQ!AO14,"")
A26: drv:지배주주순이익 | B26: ratio | C26: 지배주주 비중(/당기순이익) | E26: =IFERROR(subQ!E17/subQ!E16,"") | F26: =IFERROR(subQ!F17/subQ!F16,"") | G26: =IFERROR(subQ!G17/subQ!G16,"") | H26: =IFERROR(subQ!H17/subQ!H16,"") | I26: =IFERROR(subQ!I17/subQ!I16,"") | J26: =IFERROR(subQ!J17/subQ!J16,"") | K26: =IFERROR(subQ!K17/subQ!K16,"") | L26: =IFERROR(subQ!L17/subQ!L16,"") | ... AB26: =IFERROR(subQ!AB17/subQ!AB16,"") | AC26: =$D$47 | AD26: =$D$47 | AE26: =IFERROR(subQ!AE17/subQ!AE16,"") | AF26: =$D$47 | AG26: =$D$47 | AH26: =$D$47 | AI26: =$D$47 | AJ26: =IFERROR(subQ!AJ17/subQ!AJ16,"") | AK26: =$D$47 | AL26: =$D$47 | AM26: =$D$47 | AN26: =$D$47 | AO26: =IFERROR(subQ!AO17/subQ!AO16,"")
A27: drv:부채총계 | B27: qoq | C27: 부채총계 QoQ | G27: =IFERROR(subQ!G19/subQ!E19-1,"") | H27: =IFERROR(subQ!H19/subQ!G19-1,"") | I27: =IFERROR(subQ!I19/subQ!H19-1,"") | J27: =IFERROR(subQ!J19/subQ!I19-1,"") | L27: =IFERROR(subQ!L19/subQ!J19-1,"") | M27: =IFERROR(subQ!M19/subQ!L19-1,"") | N27: =IFERROR(subQ!N19/subQ!M19-1,"") | O27: =IFERROR(subQ!O19/subQ!N19-1,"") | Q27: =IFERROR(subQ!Q19/subQ!O19-1,"") | R27: =IFERROR(subQ!R19/subQ!Q19-1,"") | S27: =IFERROR(subQ!S19/subQ!R19-1,"") | T27: =IFERROR(subQ!T19/subQ!S19-1,"") | V27: =IFERROR(subQ!V19/subQ!T19-1,"") | W27: =IFERROR(subQ!W19/subQ!V19-1,"") | X27: =IFERROR(subQ!X19/subQ!W19-1,"") | Y27: =IFERROR(subQ!Y19/subQ!X19-1,"") | AA27: =IFERROR(subQ!AA19/subQ!Y19-1,"") | AB27: =IFERROR(subQ!AB19/subQ!AA19-1,"") | AC27: -2.127e-06 | AD27: 0 | AF27: 0 | AG27: 0 | AH27: 0 | AI27: 0 | AK27: 0 | AL27: 0 | AM27: 0 | AN27: 0
A28: drv:자본총계 | B28: roll | C28: 자본총계 기타변동(배당 등, 억원) | G28: =IFERROR(subQ!E20+subQ!G16-subQ!G20,"") | H28: =IFERROR(subQ!G20+subQ!H16-subQ!H20,"") | I28: =IFERROR(subQ!H20+subQ!I16-subQ!I20,"") | J28: =IFERROR(subQ!I20+subQ!J16-subQ!J20,"") | L28: =IFERROR(subQ!J20+subQ!L16-subQ!L20,"") | M28: =IFERROR(subQ!L20+subQ!M16-subQ!M20,"") | N28: =IFERROR(subQ!M20+subQ!N16-subQ!N20,"") | O28: =IFERROR(subQ!N20+subQ!O16-subQ!O20,"") | Q28: =IFERROR(subQ!O20+subQ!Q16-subQ!Q20,"") | R28: =IFERROR(subQ!Q20+subQ!R16-subQ!R20,"") | S28: =IFERROR(subQ!R20+subQ!S16-subQ!S20,"") | T28: =IFERROR(subQ!S20+subQ!T16-subQ!T20,"") | V28: =IFERROR(subQ!T20+subQ!V16-subQ!V20,"") | W28: =IFERROR(subQ!V20+subQ!W16-subQ!W20,"") | X28: =IFERROR(subQ!W20+subQ!X16-subQ!X20,"") | Y28: =IFERROR(subQ!X20+subQ!Y16-subQ!Y20,"") | AA28: =IFERROR(subQ!Y20+subQ!AA16-subQ!AA20,"") | AB28: =IFERROR(subQ!AA20+subQ!AB16-subQ!AB20,"") | AC28: -0.002346933 | AD28: 0.005715422 | AF28: -0.006041907 | AG28: 158.87151 | AH28: -0.003835376 | AI28: 0.001961256 | AK28: 0.005321881 | AL28: 158.86933 | AM28: 0.000615718 | AN28: -0.007601597
A29: drv:지배주주지분 | B29: roll | C29: 지배주주지분 기타변동(배당 등, 억원) | G29: =IFERROR(subQ!E21+subQ!G17-subQ!G21,"") | H29: =IFERROR(subQ!G21+subQ!H17-subQ!H21,"") | I29: =IFERROR(subQ!H21+subQ!I17-subQ!I21,"") | J29: =IFERROR(subQ!I21+subQ!J17-subQ!J21,"") | L29: =IFERROR(subQ!J21+subQ!L17-subQ!L21,"") | M29: =IFERROR(subQ!L21+subQ!M17-subQ!M21,"") | N29: =IFERROR(subQ!M21+subQ!N17-subQ!N21,"") | O29: =IFERROR(subQ!N21+subQ!O17-subQ!O21,"") | Q29: =IFERROR(subQ!O21+subQ!Q17-subQ!Q21,"") | R29: =IFERROR(subQ!Q21+subQ!R17-subQ!R21,"") | S29: =IFERROR(subQ!R21+subQ!S17-subQ!S21,"") | T29: =IFERROR(subQ!S21+subQ!T17-subQ!T21,"") | V29: =IFERROR(subQ!T21+subQ!V17-subQ!V21,"") | W29: =IFERROR(subQ!V21+subQ!W17-subQ!W21,"") | X29: =IFERROR(subQ!W21+subQ!X17-subQ!X21,"") | Y29: =IFERROR(subQ!X21+subQ!Y17-subQ!Y21,"") | AA29: =IFERROR(subQ!Y21+subQ!AA17-subQ!AA21,"") | AB29: =IFERROR(subQ!AA21+subQ!AB17-subQ!AB21,"") | AC29: -0.002538333 | AD29: 0.007758576 | AF29: -0.000785841 | AG29: 158.86857 | AH29: 0.002561779 | AI29: -0.01042137 | AK29: 0.010241391 | AL29: 158.86809 | AM29: 0.002876781 | AN29: -0.007140706
A30: drv:이자발생자산 | B30: qoq | C30: 이자발생자산 QoQ | G30: =IFERROR(subQ!G22/subQ!E22-1,"") | H30: =IFERROR(subQ!H22/subQ!G22-1,"") | I30: =IFERROR(subQ!I22/subQ!H22-1,"") | J30: =IFERROR(subQ!J22/subQ!I22-1,"") | L30: =IFERROR(subQ!L22/subQ!J22-1,"") | M30: =IFERROR(subQ!M22/subQ!L22-1,"") | N30: =IFERROR(subQ!N22/subQ!M22-1,"") | O30: =IFERROR(subQ!O22/subQ!N22-1,"") | Q30: =IFERROR(subQ!Q22/subQ!O22-1,"") | R30: =IFERROR(subQ!R22/subQ!Q22-1,"") | S30: =IFERROR(subQ!S22/subQ!R22-1,"") | T30: =IFERROR(subQ!T22/subQ!S22-1,"") | V30: =IFERROR(subQ!V22/subQ!T22-1,"") | W30: =IFERROR(subQ!W22/subQ!V22-1,"") | X30: =IFERROR(subQ!X22/subQ!W22-1,"") | Y30: =IFERROR(subQ!Y22/subQ!X22-1,"") | AA30: =IFERROR(subQ!AA22/subQ!Y22-1,"") | AB30: =IFERROR(subQ!AB22/subQ!AA22-1,"") | AC30: 0.073799417 | AD30: 0.073249606 | AF30: 0.065046016 | AG30: -0.00120087 | AH30: 0.064903558 | AI30: 0.064913514 | AK30: 0.058134402 | AL30: 0.003294717 | AM30: 0.056444648 | AN30: 0.056863636
A31: drv:현금및현금성자산 | B31: qoq | C31: 현금및현금성자산 QoQ | G31: =IFERROR(subQ!G23/subQ!E23-1,"") | H31: =IFERROR(subQ!H23/subQ!G23-1,"") | I31: =IFERROR(subQ!I23/subQ!H23-1,"") | J31: =IFERROR(subQ!J23/subQ!I23-1,"") | L31: =IFERROR(subQ!L23/subQ!J23-1,"") | M31: =IFERROR(subQ!M23/subQ!L23-1,"") | N31: =IFERROR(subQ!N23/subQ!M23-1,"") | O31: =IFERROR(subQ!O23/subQ!N23-1,"") | Q31: =IFERROR(subQ!Q23/subQ!O23-1,"") | R31: =IFERROR(subQ!R23/subQ!Q23-1,"") | S31: =IFERROR(subQ!S23/subQ!R23-1,"") | T31: =IFERROR(subQ!T23/subQ!S23-1,"") | V31: =IFERROR(subQ!V23/subQ!T23-1,"") | W31: =IFERROR(subQ!W23/subQ!V23-1,"") | X31: =IFERROR(subQ!X23/subQ!W23-1,"") | Y31: =IFERROR(subQ!Y23/subQ!X23-1,"") | AA31: =IFERROR(subQ!AA23/subQ!Y23-1,"") | AB31: =IFERROR(subQ!AB23/subQ!AA23-1,"")
A32: drv:CAPEX | B32: yoy | C32: CAPEX YoY | J32: =IFERROR(subQ!J24/subQ!E24-1,"") | L32: =IFERROR(subQ!L24/subQ!G24-1,"") | M32: =IFERROR(subQ!M24/subQ!H24-1,"") | N32: =IFERROR(subQ!N24/subQ!I24-1,"") | O32: =IFERROR(subQ!O24/subQ!J24-1,"") | Q32: =IFERROR(subQ!Q24/subQ!L24-1,"") | R32: =IFERROR(subQ!R24/subQ!M24-1,"") | S32: =IFERROR(subQ!S24/subQ!N24-1,"") | T32: =IFERROR(subQ!T24/subQ!O24-1,"") | V32: =IFERROR(subQ!V24/subQ!Q24-1,"") | W32: =IFERROR(subQ!W24/subQ!R24-1,"") | X32: =IFERROR(subQ!X24/subQ!S24-1,"") | Y32: =IFERROR(subQ!Y24/subQ!T24-1,"") | AA32: =IFERROR(subQ!AA24/subQ!V24-1,"") | AB32: =IFERROR(subQ!AB24/subQ!W24-1,"") | AC32: 0.028872616 | AD32: -0.72881947 | AF32: -0.026884836 | AG32: 0.030425805 | AH32: 0 | AI32: 0 | AK32: 0 | AL32: 0 | AM32: 0 | AN32: 0
A33: drv:영업활동현금흐름 | B33: yoy | C33: 영업활동현금흐름 YoY | J33: =IFERROR(subQ!J25/subQ!E25-1,"") | L33: =IFERROR(subQ!L25/subQ!G25-1,"") | M33: =IFERROR(subQ!M25/subQ!H25-1,"") | N33: =IFERROR(subQ!N25/subQ!I25-1,"") | O33: =IFERROR(subQ!O25/subQ!J25-1,"") | Q33: =IFERROR(subQ!Q25/subQ!L25-1,"") | R33: =IFERROR(subQ!R25/subQ!M25-1,"") | S33: =IFERROR(subQ!S25/subQ!N25-1,"") | T33: =IFERROR(subQ!T25/subQ!O25-1,"") | V33: =IFERROR(subQ!V25/subQ!Q25-1,"") | W33: =IFERROR(subQ!W25/subQ!R25-1,"") | X33: =IFERROR(subQ!X25/subQ!S25-1,"") | Y33: =IFERROR(subQ!Y25/subQ!T25-1,"") | AA33: =IFERROR(subQ!AA25/subQ!V25-1,"") | AB33: =IFERROR(subQ!AB25/subQ!W25-1,"")
A34: drv:주식수 | B34: qoq | C34: 주식수 QoQ | G34: =IFERROR(subQ!G26/subQ!E26-1,"") | H34: =IFERROR(subQ!H26/subQ!G26-1,"") | I34: =IFERROR(subQ!I26/subQ!H26-1,"") | J34: =IFERROR(subQ!J26/subQ!I26-1,"") | L34: =IFERROR(subQ!L26/subQ!J26-1,"") | M34: =IFERROR(subQ!M26/subQ!L26-1,"") | N34: =IFERROR(subQ!N26/subQ!M26-1,"") | O34: =IFERROR(subQ!O26/subQ!N26-1,"") | Q34: =IFERROR(subQ!Q26/subQ!O26-1,"") | R34: =IFERROR(subQ!R26/subQ!Q26-1,"") | S34: =IFERROR(subQ!S26/subQ!R26-1,"") | T34: =IFERROR(subQ!T26/subQ!S26-1,"") | V34: =IFERROR(subQ!V26/subQ!T26-1,"") | W34: =IFERROR(subQ!W26/subQ!V26-1,"") | X34: =IFERROR(subQ!X26/subQ!W26-1,"") | Y34: =IFERROR(subQ!Y26/subQ!X26-1,"") | AA34: =IFERROR(subQ!AA26/subQ!Y26-1,"") | AB34: =IFERROR(subQ!AB26/subQ!AA26-1,"") | AC34: 0 | AD34: 0 | AF34: 0 | AG34: 0 | AH34: 0 | AI34: 0 | AK34: 0 | AL34: 0 | AM34: 0 | AN34: 0
A35: drv:DPS | B35: abs | C35: DPS (가정, 원) | E35: =subQ!E29 | F35: =subQ!F29 | G35: =subQ!G29 | H35: =subQ!H29 | I35: =subQ!I29 | J35: =subQ!J29 | K35: =subQ!K29 | L35: =subQ!L29 | ... AB35: =subQ!AB29 | AD35: 1350 | AE35: =subQ!AE29 | AI35: 1350 | AJ35: =subQ!AJ29 | AN35: 1350 | AO35: =subQ!AO29
B37: 3. 밸류에이션·스칼라 | C37: 노란 셀 = 가정. '연결' 표시는 추정 전 분기 수식이 이 셀을 참조한다는 뜻
A38: sc:종가 | C38: 종가 | D38: 33350 | E38: 원 — 네이버 정규장 종가(aik 확정종가 대조 · aik 34,800원)
A39: sc:기준일 | C39: 기준일 | D39: 20261012 | E39: 종가 기준일
A40: sc:COE | C40: COE | D40: 0.09 | E40: 자기자본비용(가정) — TP 적정 PBR = ROE/COE
A41: sc:PER_lo | C41: PER_lo | D41: 7 | E41: PER 밴드 하단(배) — hist_quarterly(분기 평균가 ÷ TTM EPS, 16분기, 25/50/75 백분위)
A42: sc:PER_mid | C42: PER_mid | D42: 7.6 | E42: PER 밴드 중단(배)
...

Sheet BS연결
B1: (백만원) | C1: 이름: BS연결H | E1: 4Q21 | F1: 2021 | G1: 1Q22 | H1: 2Q22 | I1: 3Q22 | J1: 4Q22 | K1: 2022 | L1: 1Q23 | M1: 2Q23 | N1: 3Q23 | O1: 4Q23 | P1: 2023 | Q1: 1Q24 | R1: 2Q24 | S1: 3Q24 | T1: 4Q24 | U1: 2024 | V1: 1Q25 | W1: 2Q25 | X1: 3Q25 | Y1: 4Q25 | Z1: 2025 | AA1: 1Q26 | AB1: 2Q26 | AC1: 3Q26 | AD1: 4Q26 | AE1: 2026 | AF1: 1Q27 | AG1: 2Q27 | AH1: 3Q27 | AI1: 4Q27 | AJ1: 2027 | AK1: 1Q28 | AL1: 2Q28 | AM1: 3Q28 | AN1: 4Q28 | AO1: 2028
B2: 연결 | D2: fin json(kship_fin.py)
B3: 하이록코리아(연) | C3: UPDATE: 26-10-12 | E3: 1 | F3: 2 | G3: 3 | H3: 4 | I3: 5 | J3: 6 | K3: 7 | L3: 8 | M3: 9 | N3: 10 | O3: 11 | P3: 12 | Q3: 13 | R3: 14 | S3: 15 | T3: 16 | U3: 17 | V3: 18 | W3: 19 | X3: 20 | Y3: 21 | Z3: 22 | AA3: 23 | AB3: 24 | AC3: 25 | AD3: 26 | AE3: 27 | AF3: 28 | AG3: 29 | AH3: 30 | AI3: 31 | AJ3: 32 | AK3: 33 | AL3: 34 | AM3: 35 | AN3: 36 | AO3: 37
B4: Account Code | C4: AccountNAME | E4: 2021.12 | F4: 2021.12A | G4: 2022.03 | H4: 2022.06 | I4: 2022.09 | J4: 2022.12 | K4: 2022.12A | L4: 2023.03 | M4: 2023.06 | N4: 2023.09 | O4: 2023.12 | P4: 2023.12A | Q4: 2024.03 | R4: 2024.06 | S4: 2024.09 | T4: 2024.12 | U4: 2024.12A | V4: 2025.03 | W4: 2025.06 | X4: 2025.09 | Y4: 2025.12 | Z4: 2025.12A | AA4: 2026.03 | AB4: 2026.06 | AC4: 2026.09 | AD4: 2026.12 | AE4: 2026.12A | AF4: 2027.03 | AG4: 2027.06 | AH4: 2027.09 | AI4: 2027.12 | AJ4: 2027.12A | AK4: 2028.03 | AL4: 2028.06 | AM4: 2028.09 | AN4: 2028.12 | AO4: 2028.12A
A5: 1 | C5: 유동자산 | E5: 281619.18 | F5: 281619.18 | G5: 286421.34 | H5: 294536.08 | I5: 308862.51 | J5: 314733.92 | K5: 314733.92 | L5: 316829.87 | M5: 323301.44 | N5: 333748.8 | O5: 334758.95 | P5: 334758.95 | Q5: 347512.9 | R5: 337258.02 | S5: 343202.16 | T5: 367167.1 | U5: 367167.1 | V5: 371111.62 | W5: 358155.42 | X5: 370909.77 | Y5: 385627.56 | Z5: 385627.56 | AA5: 399220.69 | AB5: 401405.86
A6: 1 | C6: 현금및현금성자산 | E6: 66056.91 | F6: 66056.91 | G6: 44596.12 | H6: 20050.32 | I6: 61310.63 | J6: 55323.48 | K6: 55323.48 | L6: 151900.84 | M6: 131988.86 | N6: 137429.09 | O6: 170178.98 | P6: 170178.98 | Q6: 182205.41 | R6: 170730.41 | S6: 187871.31 | T6: 194323.89 | U6: 194323.89 | V6: 188946.26 | W6: 179720.53 | X6: 183944.34 | Y6: 191225.63 | Z6: 191225.63 | AA6: 174520.6 | AB6: 185542.5
A7: 1 | C7: 단기금융상품 | E7: 109904.35 | F7: 109904.35 | G7: 132104.35 | H7: 153906.83 | I7: 113200 | J7: 128500 | K7: 128500 | L7: 25500 | M7: 46000 | N7: 43500 | O7: 10000 | P7: 10000 | R7: 9000 | S7: 5000 | T7: 5000 | U7: 5000 | V7: 7500 | W7: 5000 | X7: 5000 | Y7: 5000 | Z7: 5000 | AA7: 5000 | AB7: 5000
A8: 1 | C8: 단기금융자산 | E8: 109904.35 | F8: 109904.35 | G8: 132104.35 | H8: 153906.83 | I8: 113200 | J8: 128500 | K8: 128500 | L8: 25500 | M8: 46000 | N8: 43500 | O8: 10000 | P8: 10000 | R8: 9000 | S8: 5000 | T8: 5000 | U8: 5000 | V8: 7500 | W8: 5000 | X8: 5000 | Y8: 5000 | Z8: 5000 | AA8: 5000 | AB8: 5000
A9: 1 | C9: 단기투자자산(공정가치) | E9: 124.75 | F9: 124.75 | G9: 126.91 | H9: 136.24 | I9: 145.93 | J9: 134.27 | K9: 134.27 | L9: 137.01 | M9: 91.56 | N9: 1.2 | O9: 2558.21 | P9: 2558.21 | Q9: 9808.8 | R9: 4709.36 | S9: 1218.76 | T9: 4975.66 | U9: 4975.66 | V9: 9310.51 | W9: 7910.79 | X9: 14837.55 | Y9: 16200.91 | Z9: 16200.91 | AA9: 46435.24 | AB9: 32533.51
A10: 1 | C10: 매출채권및기타채권 | E10: 36779.87 | F10: 36779.87 | G10: 34215.23 | H10: 45343.79 | I10: 49684.05 | J10: 44786.84 | K10: 44786.84 | L10: 45129.22 | M10: 44882.93 | N10: 45735.73 | O10: 45108.43 | P10: 45108.43 | Q10: 47611.21 | R10: 44851.87 | S10: 40532.3 | T10: 50132.07 | U10: 50132.07 | V10: 53122.05 | W10: 51185.79 | X10: 47665.27 | Y10: 50228.88 | Z10: 50228.88 | AA10: 50537.27 | AB10: 47757.47
A11: 1 | C11: 재고자산 | E11: 68129.9 | F11: 68129.9 | G11: 73821.13 | H11: 73836.1 | I11: 82816.31 | J11: 84949.91 | K11: 84949.91 | L11: 92045.32 | M11: 98803.29 | N11: 105199.41 | O11: 106226.17 | P11: 106226.17 | Q11: 106607.54 | R11: 105818.39 | S11: 106072.33 | T11: 110715 | U11: 110715 | V11: 110205.92 | W11: 112398.52 | X11: 115738.64 | Y11: 119523.26 | Z11: 119523.26 | AA11: 118091.45 | AB11: 121885.95
A12: 1 | C12: 비유동자산 | E12: 98176.95 | F12: 98176.95 | G12: 98059.45 | H12: 97688.57 | I12: 98083.3 | J12: 97188.51 | K12: 97188.51 | L12: 108187.38 | M12: 107750.34 | N12: 108009.29 | O12: 108396.37 | P12: 108396.37 | Q12: 108206.89 | R12: 106260.15 | S12: 105354.27 | T12: 105513.12 | U12: 105513.12 | V12: 107830.91 | W12: 109078.74 | X12: 108981.28 | Y12: 112464.64 | Z12: 112464.64 | AA12: 111984.24 | AB12: 112549.54
A13: 1 | C13: 장기금융자산 | E13: 99.25 | F13: 99.25 | G13: 99.25 | H13: 99.25 | I13: 99.25 | J13: 99.25 | K13: 99.25 | L13: 99.25 | M13: 99.25 | N13: 99.25 | O13: 99.25 | P13: 99.25 | Q13: 99.25 | R13: 99.25 | S13: 99.25 | T13: 99.25 | U13: 99.25 | V13: 99.25 | W13: 99.25 | X13: 99.25 | Y13: 99.25 | Z13: 99.25 | AA13: 99.25 | AB13: 99.25
A14: 1 | C14: 투자자산 | E14: 99.25 | F14: 99.25 | G14: 99.25 | H14: 99.25 | I14: 99.25 | J14: 99.25 | K14: 99.25 | L14: 99.25 | M14: 99.25 | N14: 99.25 | O14: 99.25 | P14: 99.25 | Q14: 99.25 | R14: 99.25 | S14: 99.25 | T14: 99.25 | U14: 99.25 | V14: 99.25 | W14: 99.25 | X14: 99.25 | Y14: 99.25 | Z14: 99.25 | AA14: 99.25 | AB14: 99.25
A15: 1 | C15: 장기매출채권및기타채권 | E15: 2871.74 | F15: 2871.74 | G15: 2929.54 | H15: 2720.39 | I15: 2618.18 | J15: 2999.18 | K15: 2999.18 | L15: 2879.46 | M15: 2739.56 | N15: 2611.66 | O15: 2507.16 | P15: 2507.16 | Q15: 2414.13 | R15: 2300.03 | S15: 2203.03 | T15: 2158.19 | U15: 2158.19 | V15: 2082.19 | W15: 1993.69 | X15: 2269.37 | Y15: 3262.6 | Z15: 3262.6 | AA15: 3456.25 | AB15: 3473.37
A16: 1 | C16: 유형자산 | E16: 70810 | F16: 70810 | G16: 70630.94 | H16: 70722.95 | I16: 71325.34 | J16: 70697.66 | K16: 70697.66 | L16: 71017.01 | M16: 70960.39 | N16: 72033.67 | O16: 72739.39 | P16: 72739.39 | Q16: 72364.76 | R16: 71634.49 | S16: 71994.74 | T16: 72243.01 | U16: 72243.01 | V16: 74088.38 | W16: 75213.59 | X16: 75104.17 | Y16: 78151.09 | Z16: 78151.09 | AA16: 78034.75 | AB16: 78016.61
A17: 1 | C17: 투자부동산 | E17: 11837.8 | F17: 11837.8 | G17: 11803.01 | H17: 11768.21 | I17: 11733.42 | J17: 11698.62 | K17: 11698.62 | L17: 19292.73 | M17: 19236.98 | N17: 19181.22 | O17: 19125.47 | P17: 19125.47 | Q17: 19069.72 | R17: 19013.96 | S17: 18958.21 | T17: 18902.46 | U17: 18902.46 | V17: 18846.7 | W17: 18790.95 | X17: 18735.19 | Y17: 18679.44 | Z17: 18679.44 | AA17: 18623.69 | AB17: 18567.93
A18: 1 | C18: 무형자산 | E18: 8114.46 | F18: 8114.46 | G18: 8114.46 | H18: 8105.72 | I18: 7806.51 | J18: 7777.76 | K18: 7777.76 | L18: 7805.26 | M18: 7811.51 | N18: 7803.38 | O18: 7787.76 | P18: 7787.76 | Q18: 7787.76 | R18: 7777.76 | S18: 7782.76 | T18: 7749.01 | U18: 7749.01 | V18: 7750.26 | W18: 7765.26 | X18: 7825.93 | Y18: 7823.26 | Z18: 7823.26 | AA18: 7816.07 | AB18: 7801.63
A19: 1 | C19: 이연법인세자산 | E19: 4443.7 | F19: 4443.7 | G19: 4482.25 | H19: 4272.06 | I19: 4500.6 | J19: 3916.04 | K19: 3916.04 | L19: 7093.67 | M19: 6902.65 | N19: 6280.09 | O19: 6137.34 | P19: 6137.34 | Q19: 6471.28 | R19: 5434.66 | S19: 4316.29 | T19: 4361.2 | U19: 4361.2 | V19: 4964.13 | W19: 5216 | X19: 4947.37 | Y19: 4449 | Z19: 4449 | AA19: 3954.23 | AB19: 4590.74
A20: 1 | C20: 자산총계 | E20: 379796.14 | F20: 379796.14 | G20: 384480.79 | H20: 392224.65 | I20: 406945.81 | J20: 411922.43 | K20: 411922.43 | L20: 425017.25 | M20: 431051.78 | N20: 441758.08 | O20: 443155.32 | P20: 443155.32 | Q20: 455719.79 | R20: 443518.17 | S20: 448556.43 | T20: 472680.21 | U20: 472680.21 | V20: 478942.53 | W20: 467234.16 | X20: 479891.05 | Y20: 498092.2 | Z20: 498092.2 | AA20: 511204.94 | AB20: 513955.4
... A29: 1 | C29: 자본잉여금 | E29: 23843.6 | F29: 23843.6 | G29: 23843.6 | H29: 23843.6 | I29: 23843.6 | J29: 23843.6 | K29: 23843.6 | L29: 23843.6 | M29: 23843.6 | N29: 23843.6 | O29: 23843.6 | P29: 23843.6 | Q29: 23843.6 | R29: 23843.6 | S29: 23843.6 | T29: 23843.6 | U29: 23843.6 | V29: 23843.6 | W29: 23843.6 | X29: 23843.6 | Y29: 23843.6 | Z29: 23843.6 | AA29: 23843.6 | AB29: 23843.6
A30: 1 | C30: 기타자본 | E30: -9932.83 | F30: -9932.83 | G30: -9932.83 | H30: -9932.83 | I30: -9932.83 | J30: -9932.83 | K30: -9932.83 | O30: -7927.92 | P30: -7927.92 | Q30: -16043.95 | R30: -19948.59 | S30: -19948.59 | T30: -203.16 | U30: -203.16 | V30: -5053.73 | W30: -12633.81 | X30: -203.16 | Y30: -203.16 | Z30: -203.16 | AA30: -203.16 | AB30: -203.16
A31: 1 | C31: 기타포괄이익누계액 | E31: 525.03 | F31: 525.03 | G31: 700.45 | H31: 1049.3 | I31: 1984.8 | J31: 597.77 | K31: 597.77 | L31: 1175.19 | M31: 1045.61 | N31: 1306.21 | O31: 866.16 | P31: 866.16 | Q31: 1499.52 | R31: 2083.06 | S31: 1417.05 | T31: 3234.57 | U31: 3234.57 | V31: 3436.13 | W31: 2063.56 | X31: 2950.87 | Y31: 3676.46 | Z31: 3676.46 | AA31: 5183.97 | AB31: 5900.24
A32: 1 | C32: 이익잉여금 | E32: 323415.91 | F32: 323415.91 | G32: 323400.13 | H32: 335019.4 | I32: 348262.06 | J32: 355842.12 | K32: 355842.12 | L32: 343880.95 | M32: 358419.69 | N32: 372685.43 | O32: 379920.74 | P32: 379920.74 | Q32: 381815.47 | R32: 394787.62 | S32: 402985.26 | T32: 398006.84 | U32: 398006.84 | V32: 393555.06 | W32: 404962.49 | X32: 404213.49 | Y32: 420235.33 | Z32: 420235.33 | AA32: 422131.77 | AB32: 434752.49
A33: 1 | C33: 비지배주주지분 | E33: 3439.79 | F33: 3439.79 | G33: 3492.04 | H33: 3720.49 | I33: 3084.38 | J33: 2968.68 | K33: 2968.68 | L33: 3097.45 | M33: 3011.66 | N33: 3332.24 | O33: 3350.26 | P33: 3350.26 | Q33: 3626.61 | R33: 3850.21 | S33: 4021.46 | T33: 4274.79 | U33: 4274.79 | V33: 4291.21 | W33: 4040.01 | X33: 4419.79 | Y33: 4789.12 | Z33: 4789.12 | AA33: 5224.16 | AB33: 5235.54
A34: 1 | C34: 자본총계 | E34: 348098.11 | F34: 348098.11 | G34: 348310 | H34: 360506.58 | I34: 374048.62 | J34: 380125.96 | K34: 380125.96 | L34: 378803.8 | M34: 393127.17 | N34: 407974.09 | O34: 406859.46 | P34: 406859.46 | Q34: 401547.87 | R34: 411422.5 | S34: 419125.4 | T34: 435963.25 | U34: 435963.25 | V34: 426878.88 | W34: 429082.46 | X34: 442031.2 | Y34: 459147.96 | Z34: 459147.96 | AA34: 462986.95 | AB34: 476335.32
A35: 1 | C35: 부채와자본총계 | E35: 379796.14 | F35: 379796.14 | G35: 384480.79 | H35: 392224.65 | I35: 406945.81 | J35: 411922.43 | K35: 411922.43 | L35: 425017.25 | M35: 431051.78 | N35: 441758.08 | O35: 443155.32 | P35: 443155.32 | Q35: 455719.79 | R35: 443518.17 | S35: 448556.43 | T35: 472680.21 | U35: 472680.21 | V35: 478942.53 | W35: 467234.16 | X35: 479891.05 | Y35: 498092.2 | Z35: 498092.2 | AA35: 511204.94 | AB35: 513955.4
A36: 1 | C36: 이자발생자산 | E36: 176060.51 | F36: 176060.51 | G36: 176799.72 | H36: 174056.4 | I36: 174609.88 | J36: 183922.73 | K36: 183922.73 | L36: 177500.09 | M36: 178088.11 | N36: 181028.34 | O36: 180278.23 | P36: 180278.23 | Q36: 182304.66 | R36: 179829.66 | S36: 192970.56 | T36: 199423.14 | U36: 199423.14 | V36: 196545.51 | W36: 184819.78 | X36: 189043.59 | Y36: 196324.88 | Z36: 196324.88 | AA36: 179619.85 | AB36: 190641.75
A37: 1 | C37: 단기충당부채 | J37: 261.25 | K37: 261.25 | L37: 261.25 | M37: 261.25 | N37: 261.25 | O37: 261.25 | P37: 261.25 | Q37: 261.25 | R37: 261.25
A38: 1 | C38: 매출액(수익) | E38: 35876.12 | G38: 34257.14 | H38: 51159.73 | I38: 43444.64 | J38: 53989.58 | K38: 182851.09 | L38: 45703.71 | M38: 49622.98 | N38: 46591.97 | O38: 46920.48 | P38: 188839.14 | Q38: 49774 | R38: 46087.07 | S38: 45284.68 | T38: 49366.58 | U38: 190512.33 | V38: 49035.49 | W38: 54333.03 | X38: 53845.11 | Y38: 57352.22 | Z38: 214565.85 | AA38: 54145.86 | AB38: 59250.82
A39: 1 | C39: 매출원가 | E39: 25478.83 | G39: 23457.07 | H39: 35198.68 | I39: 27324.64 | J39: 33254.62 | K39: 119235.01 | L39: 27927.65 | M39: 28207.59 | N39: 26766.38 | O39: 29188.34 | P39: 112089.96 | Q39: 28542.45 | R39: 26464.79 | S39: 25886.53 | T39: 33847.13 | U39: 114740.9 | V39: 29531.82 | W39: 31122.07 | X39: 34124.43 | Y39: 33987.46 | Z39: 128765.78 | AA39: 31707.67 | AB39: 35109.82
A40: 1 | C40: 매출총이익 | E40: 10397.3 | G40: 10800.06 | H40: 15961.05 | I40: 16120 | J40: 20734.96 | K40: 63616.07 | L40: 17776.06 | M40: 21415.39 | N40: 19825.6 | O40: 17732.14 | P40: 76749.19 | Q40: 21231.55 | R40: 19622.28 | S40: 19398.15 | T40: 15519.44 | U40: 75771.42 | V40: 19503.67 | W40: 23210.96 | X40: 19720.68 | Y40: 23364.76 | Z40: 85800.07 | AA40: 22438.19 | AB40: 24141
A41: 1 | C41: 판관비 | E41: 6441 | G41: 5558.45 | H41: 5577.27 | I41: 5882.89 | J41: 5901.28 | K41: 22919.89 | L41: 6558.38 | M41: 6043.1 | N41: 5679.81 | O41: 6576.36 | P41: 24857.65 | Q41: 5839.79 | R41: 4923.06 | S41: 5742.6 | T41: 9135.26 | U41: 25640.71 | V41: 6800.79 | W41: 6781.94 | X41: 5522.49 | Y41: 7784.01 | Z41: 26889.23 | AA41: 6752.59 | AB41: 7150.26
A42: 1 | C42: 영업이익 | E42: 3956.31 | G42: 5241.61 | H42: 10383.78 | I42: 10237.11 | J42: 14833.68 | K42: 40696.18 | L42: 11217.68 | M42: 15372.29 | N42: 14145.79 | O42: 11155.77 | P42: 51891.53 | Q42: 15391.76 | R42: 14699.21 | S42: 13655.55 | T42: 6384.18 | U42: 50130.7 | V42: 12702.89 | W42: 16429.01 | X42: 14198.19 | Y42: 15580.75 | Z42: 58910.84 | AA42: 15685.6 | AB42: 16990.74
A43: 1 | C43: 기타영업외수익 | E43: 392.06 | G43: 91.63 | H43: 336.14 | I43: 83.77 | J43: 62.61 | K43: 574.15 | L43: 242.66 | M43: 152.56 | N43: 240.37 | O43: 126.65 | P43: 762.24 | Q43: 122.24 | R43: 118.25 | S43: 178.15 | T43: 193.4 | U43: 612.04 | V43: 126.68 | W43: 677.87 | X43: 303.51 | Y43: 164.92 | Z43: 1272.98 | AA43: 151.95 | AB43: 170.17
A44: 1 | C44: 기타영업외비용 | E44: 17.64 | G44: 2.31 | H44: 8.75 | I44: 357.54 | J44: 31.83 | K44: 400.43 | L44: 18.53 | M44: 0.35 | N44: 689.05 | O44: 4.82 | P44: 712.75 | Q44: 0.01 | R44: 11.17 | S44: -4.85 | T44: 54.11 | U44: 60.44 | V44: 3.03 | W44: 256.01 | X44: 90.17 | Y44: 96.69 | Z44: 445.9 | AA44: 127.06 | AB44: 43.08
A45: 1 | C45: 금융수익 | E45: 1652.44 | G45: 1552.76 | H45: 2950.73 | I45: 5794.22 | J45: -3054.72 | K45: 7242.99 | L45: 4363.16 | M45: 2703.62 | N45: 2936.71 | O45: 878.11 | P45: 10881.6 | Q45: 3983.81 | R45: 2866.37 | S45: 1938.31 | T45: 5731.61 | U45: 14520.1 | V45: 2286.78 | W45: 1378.55 | X45: 4005.52 | Y45: 2598.97 | Z45: 10269.82 | AA45: 4399.07 | AB45: 2456.41
A46: 1 | C46: 금융비용 | E46: 59.7 | G46: 52.56 | H46: 60.51 | I46: 35.87 | J46: 2378 | K46: 2526.94 | L46: 284.02 | M46: 652.95 | N46: 291.85 | O46: 863.68 | P46: 2092.5 | Q46: 33.44 | R46: 99.66 | S46: 2480.4 | T46: -502.08 | U46: 2111.42 | V46: 316.28 | W46: 3356.74 | X46: 674.51 | Y46: 1.06 | Z46: 4348.59 | AA46: 101.4 | AB46: 45.45
A47: 1 | C47: 법인세비용차감전계속사업이익 | E47: 5923.46 | G47: 6831.14 | H47: 13601.39 | I47: 15721.69 | J47: 9431.73 | K47: 45585.95 | L47: 15520.95 | M47: 17575.18 | N47: 16341.96 | O47: 11292.03 | P47: 60730.12 | Q47: 19464.37 | R47: 17573 | S47: 13296.46 | T47: 12757.17 | U47: 63091 | V47: 14797.04 | W47: 14872.68 | X47: 17742.55 | Y47: 18246.88 | Z47: 65659.15 | AA47: 20008.17 | AB47: 19528.8
A48: 1 | C48: 법인세비용 | E48: 1216.61 | G48: 1681.92 | H48: 3396.19 | I48: 3886.99 | J48: 2259.66 | K48: 11224.76 | L48: 3010.26 | M48: 3872.31 | N48: 3538.23 | O48: 2579.06 | P48: 12999.86 | Q48: 4215.78 | R48: 4513.54 | S48: 4146.68 | T48: 2191.1 | U48: 15067.1 | V48: 3252.82 | W48: 3719.58 | X48: 4026.53 | Y48: 3888.09 | Z48: 14887.02 | AA48: 4744.97 | AB48: 4680.07
...

Sheet BS별도
B1: (백만원) | C1: 이름: BS별도H | E1: 4Q21 | F1: 2021 | G1: 1Q22 | H1: 2Q22 | I1: 3Q22 | J1: 4Q22 | K1: 2022 | L1: 1Q23 | M1: 2Q23 | N1: 3Q23 | O1: 4Q23 | P1: 2023 | Q1: 1Q24 | R1: 2Q24 | S1: 3Q24 | T1: 4Q24 | U1: 2024 | V1: 1Q25 | W1: 2Q25 | X1: 3Q25 | Y1: 4Q25 | Z1: 2025 | AA1: 1Q26 | AB1: 2Q26 | AC1: 3Q26 | AD1: 4Q26 | AE1: 2026 | AF1: 1Q27 | AG1: 2Q27 | AH1: 3Q27 | AI1: 4Q27 | AJ1: 2027 | AK1: 1Q28 | AL1: 2Q28 | AM1: 3Q28 | AN1: 4Q28 | AO1: 2028
B2: 별도 | D2: fin json(kship_fin.py)
B3: 하이록코리아(별) | C3: UPDATE: 26-10-12 | E3: 1 | F3: 2 | G3: 3 | H3: 4 | I3: 5 | J3: 6 | K3: 7 | L3: 8 | M3: 9 | N3: 10 | O3: 11 | P3: 12 | Q3: 13 | R3: 14 | S3: 15 | T3: 16 | U3: 17 | V3: 18 | W3: 19 | X3: 20 | Y3: 21 | Z3: 22 | AA3: 23 | AB3: 24 | AC3: 25 | AD3: 26 | AE3: 27 | AF3: 28 | AG3: 29 | AH3: 30 | AI3: 31 | AJ3: 32 | AK3: 33 | AL3: 34 | AM3: 35 | AN3: 36 | AO3: 37
B4: Account Code | C4: AccountNAME | E4: 2021.12 | F4: 2021.12A | G4: 2022.03 | H4: 2022.06 | I4: 2022.09 | J4: 2022.12 | K4: 2022.12A | L4: 2023.03 | M4: 2023.06 | N4: 2023.09 | O4: 2023.12 | P4: 2023.12A | Q4: 2024.03 | R4: 2024.06 | S4: 2024.09 | T4: 2024.12 | U4: 2024.12A | V4: 2025.03 | W4: 2025.06 | X4: 2025.09 | Y4: 2025.12 | Z4: 2025.12A | AA4: 2026.03 | AB4: 2026.06 | AC4: 2026.09 | AD4: 2026.12 | AE4: 2026.12A | AF4: 2027.03 | AG4: 2027.06 | AH4: 2027.09 | AI4: 2027.12 | AJ4: 2027.12A | AK4: 2028.03 | AL4: 2028.06 | AM4: 2028.09 | AN4: 2028.12 | AO4: 2028.12A
A5: 1 | C5: 유동자산 | E5: 269252.97 | F5: 269252.97 | G5: 273287.15 | H5: 278984.03 | I5: 293466.33 | J5: 301326.52 | K5: 301326.52 | L5: 303886.44 | M5: 309360.49 | N5: 317630.72 | O5: 317372.83 | P5: 317372.83 | Q5: 327895 | R5: 316356.75 | S5: 321709.4 | T5: 344315.3 | U5: 344315.3 | V5: 347264.67 | W5: 335046.06 | X5: 347231.62 | Y5: 359917.88 | Z5: 359917.88 | AA5: 371209.13 | AB5: 372743.64
A6: 1 | C6: 현금및현금성자산 | E6: 60920.57 | F6: 60920.57 | G6: 39981.9 | H6: 15122.06 | I6: 56332.91 | J6: 50487.95 | K6: 50487.95 | L6: 147038.35 | M6: 125193.44 | N6: 131739.1 | O6: 163686.85 | P6: 163686.85 | Q6: 174114.05 | R6: 161380.9 | S6: 178116.77 | T6: 186382.42 | U6: 186382.42 | V6: 179764.7 | W6: 168299.79 | X6: 173960.47 | Y6: 181244.21 | Z6: 181244.21 | AA6: 161582.79 | AB6: 173273.18
A7: 1 | C7: 단기금융상품 | E7: 108400 | F7: 108400 | G7: 130600 | H7: 152400 | I7: 113200 | J7: 128500 | K7: 128500 | L7: 25500 | M7: 46000 | N7: 43500 | O7: 10000 | P7: 10000 | R7: 9000 | S7: 5000 | T7: 5000 | U7: 5000 | V7: 7500 | W7: 5000 | X7: 5000 | Y7: 5000 | Z7: 5000 | AA7: 5000 | AB7: 5000
A8: 1 | C8: 단기금융자산 | E8: 108400 | F8: 108400 | G8: 130600 | H8: 152400 | I8: 113200 | J8: 128500 | K8: 128500 | L8: 25500 | M8: 46000 | N8: 43500 | O8: 10000 | P8: 10000 | R8: 9000 | S8: 5000 | T8: 5000 | U8: 5000 | V8: 7500 | W8: 5000 | X8: 5000 | Y8: 5000 | Z8: 5000 | AA8: 5000 | AB8: 5000
A9: 1 | C9: 단기투자자산(공정가치) | E9: 124.75 | F9: 124.75 | G9: 126.91 | H9: 136.24 | I9: 145.93 | J9: 134.27 | K9: 134.27 | L9: 137.01 | M9: 91.56 | N9: 1.2 | O9: 2558.21 | P9: 2558.21 | Q9: 9808.8 | R9: 4709.36 | S9: 1218.76 | T9: 4975.66 | U9: 4975.66 | V9: 9310.51 | W9: 7910.79 | X9: 14837.55 | Y9: 16200.91 | Z9: 16200.91 | AA9: 46435.24 | AB9: 32533.51
A10: 1 | C10: 매출채권및기타채권 | E10: 41839.73 | F10: 41839.73 | G10: 37253.85 | H10: 47853.51 | I10: 53334.04 | J10: 48763.58 | K10: 48763.58 | L10: 48800.46 | M10: 49918.95 | N10: 48147.15 | O10: 45980.52 | P10: 45980.52 | Q10: 47439.19 | R10: 44889.97 | S10: 39695.52 | T10: 48112.73 | U10: 48112.73 | V10: 49977.84 | W10: 51101.71 | X10: 47398.37 | Y10: 50486.13 | Z10: 50486.13 | AA10: 49987.02 | AB10: 46939.94
A11: 1 | C11: 재고자산 | E11: 57804.82 | F11: 57804.82 | G11: 64351.97 | H11: 62569.85 | I11: 69192.88 | J11: 72597.66 | K11: 72597.66 | L11: 80687.2 | M11: 87186.42 | N11: 93208.32 | O11: 95070.68 | P11: 95070.68 | Q11: 95728.63 | R11: 94812.02 | S11: 95927.44 | T11: 98596.52 | U11: 98596.52 | V11: 99429.94 | W11: 101587.14 | X11: 104638.44 | Y11: 106021.01 | Z11: 106021.01 | AA11: 106071.11 | AB11: 109070.18
A12: 1 | C12: 비유동자산 | E12: 100590.4 | F12: 100590.4 | G12: 100318.3 | H12: 99814.65 | I12: 99034.4 | J12: 98359.46 | K12: 98359.46 | L12: 108826.95 | M12: 108396.94 | N12: 108580.94 | O12: 109412.73 | P12: 109412.73 | Q12: 109020.67 | R12: 107816.31 | S12: 107120.3 | T12: 107185.49 | U12: 107185.49 | V12: 109602.51 | W12: 110786.67 | X12: 110292.21 | Y12: 113000.07 | Z12: 113000.07 | AA12: 112208.41 | AB12: 112685.21
A13: 1 | C13: 장기금융자산 | E13: 99.25 | F13: 99.25 | G13: 99.25 | H13: 99.25 | I13: 99.25 | J13: 99.25 | K13: 99.25 | L13: 99.25 | M13: 99.25 | N13: 99.25 | O13: 99.25 | P13: 99.25 | Q13: 99.25 | R13: 99.25 | S13: 99.25 | T13: 99.25 | U13: 99.25 | V13: 99.25 | W13: 99.25 | X13: 99.25 | Y13: 99.25 | Z13: 99.25 | AA13: 99.25 | AB13: 99.25
A14: 1 | C14: 투자자산 | E14: 6009.05 | F14: 6009.05 | G14: 6009.05 | H14: 6009.05 | I14: 5109.05 | J14: 5109.05 | K14: 5109.05 | L14: 5109.05 | M14: 5109.05 | N14: 5109.05 | O14: 5109.05 | P14: 5109.05 | Q14: 5109.05 | R14: 5109.05 | S14: 5109.05 | T14: 5109.05 | U14: 5109.05 | V14: 5109.05 | W14: 5109.05 | X14: 5109.05 | Y14: 5109.05 | Z14: 5109.05 | AA14: 5109.05 | AB14: 5109.05
A15: 1 | C15: 장기매출채권및기타채권 | E15: 2842.39 | F15: 2842.39 | G15: 2900.19 | H15: 2710.39 | I15: 2618.18 | J15: 2999.18 | K15: 2999.18 | L15: 2879.46 | M15: 2739.56 | N15: 2611.66 | O15: 2507.16 | P15: 2507.16 | Q15: 2414.13 | R15: 2300.03 | S15: 2203.03 | T15: 2158.19 | U15: 2158.19 | V15: 2082.19 | W15: 1993.69 | X15: 1848.71 | Y15: 1777.48 | Z15: 1777.48 | AA15: 1889.88 | AB15: 1871.75
A16: 1 | C16: 종속기업및관계기업투자 | E16: 5909.8 | F16: 5909.8 | G16: 5909.8 | H16: 5909.8 | I16: 5009.8 | J16: 5009.8 | K16: 5009.8 | L16: 5009.8 | M16: 5009.8 | N16: 5009.8 | O16: 5009.8 | P16: 5009.8 | Q16: 5009.8 | R16: 5009.8 | S16: 5009.8 | T16: 5009.8 | U16: 5009.8 | V16: 5009.8 | W16: 5009.8 | X16: 5009.8 | Y16: 5009.8 | Z16: 5009.8 | AA16: 5009.8 | AB16: 5009.8
A17: 1 | C17: 유형자산 | E17: 70064.45 | F17: 70064.45 | G17: 69825.25 | H17: 69942.11 | I17: 70546.13 | J17: 70027.8 | K17: 70027.8 | L17: 70399.08 | M17: 70370.36 | N17: 71484.74 | O17: 72282.67 | P17: 72282.67 | Q17: 71914.72 | R17: 71142.14 | S17: 71546.16 | T17: 71742.35 | U17: 71742.35 | V17: 73571.33 | W17: 74768.13 | X17: 74680.67 | Y17: 77767.58 | Z17: 77767.58 | AA17: 77675.81 | AB17: 77688.65
A18: 1 | C18: 투자부동산 | E18: 11837.8 | F18: 11837.8 | G18: 11803.01 | H18: 11768.21 | I18: 11733.42 | J18: 11698.62 | K18: 11698.62 | L18: 19292.73 | M18: 19236.98 | N18: 19181.22 | O18: 19125.47 | P18: 19125.47 | Q18: 19069.72 | R18: 19013.96 | S18: 18958.21 | T18: 18902.46 | U18: 18902.46 | V18: 18846.7 | W18: 18790.95 | X18: 18735.19 | Y18: 18679.44 | Z18: 18679.44 | AA18: 18623.69 | AB18: 18567.93
A19: 1 | C19: 무형자산 | E19: 6429.13 | F19: 6429.13 | G19: 6429.13 | H19: 6420.38 | I19: 6399.13 | J19: 6370.38 | K19: 6370.38 | L19: 6397.88 | M19: 6404.13 | N19: 6396.01 | O19: 6380.38 | P19: 6380.38 | Q19: 6380.38 | R19: 6370.38 | S19: 6375.38 | T19: 6341.63 | U19: 6341.63 | V19: 6342.88 | W19: 6357.88 | X19: 6418.55 | Y19: 6415.88 | Z19: 6415.88 | AA19: 6408.7 | AB19: 6394.26
A20: 1 | C20: 이연법인세자산 | E20: 3407.57 | F20: 3407.57 | G20: 3351.67 | H20: 2964.5 | I20: 2628.49 | J20: 2154.41 | K20: 2154.41 | L20: 4748.74 | M20: 4536.86 | N20: 3798.25 | O20: 4007.99 | P20: 4007.99 | Q20: 4132.66 | R20: 3880.74 | S20: 2928.46 | T20: 2931.81 | U20: 2931.81 | V20: 3650.34 | W20: 3766.96 | X20: 3500.03 | Y20: 3250.63 | Z20: 3250.63 | AA20: 2501.28 | AB20: 3053.56
... A29: 1 | C29: 자본잉여금 | E29: 23843.6 | F29: 23843.6 | G29: 23843.6 | H29: 23843.6 | I29: 23843.6 | J29: 23843.6 | K29: 23843.6 | L29: 23843.6 | M29: 23843.6 | N29: 23843.6 | O29: 23843.6 | P29: 23843.6 | Q29: 23843.6 | R29: 23843.6 | S29: 23843.6 | T29: 23843.6 | U29: 23843.6 | V29: 23843.6 | W29: 23843.6 | X29: 23843.6 | Y29: 23843.6 | Z29: 23843.6 | AA29: 23843.6 | AB29: 23843.6
A30: 1 | C30: 기타자본 | E30: -9932.83 | F30: -9932.83 | G30: -9932.83 | H30: -9932.83 | I30: -9932.83 | J30: -9932.83 | K30: -9932.83 | O30: -7927.92 | P30: -7927.92 | Q30: -16043.95 | R30: -19948.59 | S30: -19948.59 | T30: -203.16 | U30: -203.16 | V30: -5053.73 | W30: -12633.81 | X30: -203.16 | Y30: -203.16 | Z30: -203.16 | AA30: -203.16 | AB30: -203.16
A31: 1 | C31: 이익잉여금 | E31: 318982.64 | F31: 318982.64 | G31: 318656.23 | H31: 329706.39 | I31: 343011.69 | J31: 349711.49 | K31: 349711.49 | L31: 338384.85 | M31: 351419.69 | N31: 364671.78 | O31: 370133.68 | P31: 370133.68 | Q31: 371324.03 | R31: 383767.23 | S31: 390290.84 | T31: 386152.03 | U31: 386152.03 | V31: 380531.22 | W31: 391546.46 | X31: 390955.53 | Y31: 405788.59 | Z31: 405788.59 | AA31: 407267.1 | AB31: 419440.6
A32: 1 | C32: 자본총계 | E32: 339700.02 | F32: 339700.02 | G32: 339373.61 | H32: 350423.78 | I32: 363729.07 | J32: 370428.87 | K32: 370428.87 | L32: 369035.06 | M32: 382069.91 | N32: 395322 | O32: 392855.97 | P32: 392855.97 | Q32: 385930.3 | R32: 394468.85 | S32: 400992.46 | T32: 416599.08 | U32: 416599.08 | V32: 406127.7 | W32: 409562.86 | X32: 421402.58 | Y32: 436235.64 | Z32: 436235.64 | AA32: 437714.15 | AB32: 449887.65
A33: 1 | C33: 부채와자본총계 | E33: 369843.36 | F33: 369843.36 | G33: 373605.45 | H33: 378798.67 | I33: 392500.73 | J33: 399685.98 | K33: 399685.98 | L33: 412713.38 | M33: 417757.44 | N33: 426211.66 | O33: 426785.55 | P33: 426785.55 | Q33: 436915.68 | R33: 424173.06 | S33: 428829.7 | T33: 451500.79 | U33: 451500.79 | V33: 456867.17 | W33: 445832.73 | X33: 457523.83 | Y33: 472917.95 | Z33: 472917.95 | AA33: 483417.54 | AB33: 485428.85
A34: 1 | C34: 지배주주지분 | E34: 339700.02 | F34: 339700.02 | G34: 339373.61 | H34: 350423.78 | I34: 363729.07 | J34: 370428.87 | K34: 370428.87 | L34: 369035.06 | M34: 382069.91 | N34: 395322 | O34: 392855.97 | P34: 392855.97 | Q34: 385930.3 | R34: 394468.85 | S34: 400992.46 | T34: 416599.08 | U34: 416599.08 | V34: 406127.7 | W34: 409562.86 | X34: 421402.58 | Y34: 436235.64 | Z34: 436235.64 | AA34: 437714.15 | AB34: 449887.65
A35: 1 | C35: 이자발생자산 | E35: 169419.82 | F35: 169419.82 | G35: 170681.15 | H35: 167621.31 | I35: 169632.16 | J35: 179087.2 | K35: 179087.2 | L35: 172637.6 | M35: 171292.69 | N35: 175338.35 | O35: 173786.1 | P35: 173786.1 | Q35: 174213.3 | R35: 170480.15 | S35: 183216.02 | T35: 191481.67 | U35: 191481.67 | V35: 187363.95 | W35: 173399.04 | X35: 179059.72 | Y35: 186343.46 | Z35: 186343.46 | AA35: 166682.04 | AB35: 178372.43
A36: 1 | C36: 단기충당부채 | J36: 261.25 | K36: 261.25 | L36: 261.25 | M36: 261.25 | N36: 261.25 | O36: 261.25 | P36: 261.25 | Q36: 261.25 | R36: 261.25
A37: 1 | C37: 매출액(수익) | E37: 34655.05 | G37: 30747.71 | H37: 47329.85 | I37: 41115.63 | J37: 50907.54 | K37: 170100.73 | L37: 42705.67 | M37: 45307.32 | N37: 41285.69 | O37: 41449.81 | P37: 170748.49 | Q37: 44733.62 | R37: 41013.87 | S37: 40272.22 | T37: 46711.18 | U37: 172730.89 | V37: 43463.96 | W37: 51212.54 | X37: 46998 | Y37: 51405.51 | Z37: 193080.01 | AA37: 46232.51 | AB37: 52980.77
A38: 1 | C38: 매출원가 | E38: 26135 | G38: 21810.86 | H38: 34135.95 | I38: 26898.42 | J38: 33768.92 | K38: 116614.15 | L38: 25762.16 | M38: 27957.63 | N38: 24808.85 | O38: 28069.13 | P38: 106597.77 | Q38: 26568.84 | R38: 25421.75 | S38: 25235.6 | T38: 33565.02 | U38: 110791.21 | V38: 27530.87 | W38: 30402.43 | X38: 29486.21 | Y38: 33315.98 | Z38: 120735.49 | AA38: 26985.69 | AB38: 32978.78
A39: 1 | C39: 매출총이익 | E39: 8520.05 | G39: 8936.85 | H39: 13193.9 | I39: 14217.21 | J39: 17138.62 | K39: 53486.58 | L39: 16943.51 | M39: 17349.68 | N39: 16476.84 | O39: 13380.67 | P39: 64150.7 | Q39: 18164.78 | R39: 15592.12 | S39: 15036.62 | T39: 13146.17 | U39: 61939.69 | V39: 15933.09 | W39: 20810.11 | X39: 17511.79 | Y39: 18089.53 | Z39: 72344.52 | AA39: 19246.82 | AB39: 20001.99
A40: 1 | C40: 판관비 | E40: 4535.46 | G40: 3998.26 | H40: 3570.14 | I40: 3988.31 | J40: 3812.21 | K40: 15368.92 | L40: 4659.43 | M40: 3916.31 | N40: 3812.99 | O40: 4787.13 | P40: 17175.86 | Q40: 3828.11 | R40: 2741.4 | S40: 3831.89 | T40: 6779.98 | U40: 17181.38 | V40: 4730.68 | W40: 4923.61 | X40: 3515.74 | Y40: 5356.99 | Z40: 18527.02 | AA40: 4291.3 | AB40: 4346.06
A41: 1 | C41: 영업이익 | E41: 3984.58 | G41: 4938.59 | H41: 9623.76 | I41: 10228.89 | J41: 13326.42 | K41: 38117.66 | L41: 12284.08 | M41: 13433.37 | N41: 12663.85 | O41: 8593.54 | P41: 46974.84 | Q41: 14336.67 | R41: 12850.72 | S41: 11204.74 | T41: 6366.19 | U41: 44758.32 | V41: 11202.41 | W41: 15886.49 | X41: 13996.06 | Y41: 12732.53 | Z41: 53817.49 | AA41: 14955.52 | AB41: 15655.93
A42: 1 | C42: 기타영업외수익 | E42: 67.62 | G42: 90.97 | H42: 306.87 | I42: 72.83 | J42: 62.65 | K42: 533.32 | L42: 221.91 | M42: 153.14 | N42: 120.08 | O42: 126.46 | P42: 621.59 | Q42: 121.17 | R42: 118.92 | S42: 139.13 | T42: 1073.27 | U42: 1452.49 | V42: 125.17 | W42: 674.77 | X42: 338.48 | Y42: 824.69 | Z42: 1963.11 | AA42: 151.48 | AB42: 632.48
A43: 1 | C43: 기타영업외비용 | E43: 8.77 | G43: 2.31 | H43: 8.75 | I43: 87 | J43: 28.81 | K43: 126.87 | L43: 3.44 | M43: 0 | N43: 688.9 | O43: 0.02 | P43: 692.36 | Q43: 0.01 | R43: 10 | S43: -5 | T43: 54.1 | U43: 59.11 | V43: 3.03 | W43: 254.3 | X43: 90.18 | Y43: 91.35 | Z43: 438.86 | AA43: 127.06 | AB43: 43.08
A44: 1 | C44: 금융수익 | E44: 1652.04 | G44: 1552.69 | H44: 2864.48 | I44: 5716.5 | J44: -3040.71 | K44: 7092.96 | L44: 4361.64 | M44: 2670.4 | N44: 2934.52 | O44: 877.15 | P44: 10843.71 | Q44: 3977.06 | R44: 2855.29 | S44: 1929.61 | T44: 5618.65 | U44: 14380.61 | V44: 2278.32 | W44: 1377.78 | X44: 4005.08 | Y44: 2597.59 | Z44: 10258.77 | AA44: 4398.8 | AB44: 2456.01
A45: 1 | C45: 금융비용 | E45: 36.07 | G45: 34.44 | H45: 73.71 | I45: 33.99 | J45: 2374.41 | K45: 2516.55 | L45: 278.76 | M45: 649.83 | N45: 269.92 | O45: 834.65 | P45: 2033.16 | Q45: 17.4 | R45: 6.89 | S45: 2379.89 | T45: -506.33 | U45: 1897.85 | V45: 291.68 | W45: 3345.54 | X45: 645.41 | Y45: -40.12 | Z45: 4242.51 | AA45: 65.99 | AB45: 30.78
A46: 1 | C46: 법인세비용차감전계속사업이익 | E46: 5659.4 | G46: 6545.51 | H46: 12712.66 | I46: 15897.23 | J46: 7945.14 | K46: 43100.54 | L46: 16585.42 | M46: 15607.09 | N46: 14759.64 | O46: 8762.49 | P46: 55714.64 | Q46: 18417.49 | R46: 15808.04 | S46: 10898.59 | T46: 13510.33 | U46: 58634.45 | V46: 13311.18 | W46: 14339.21 | X46: 17604.03 | Y46: 16103.58 | Z46: 61358 | AA46: 19312.75 | AB46: 18670.56
A47: 1 | C47: 법인세비용 | E47: 1221.41 | G47: 1707.96 | H47: 3264.85 | I47: 4134.73 | J47: 1827.85 | K47: 10935.39 | L47: 3443.1 | M47: 3454.55 | N47: 3238.35 | O47: 1903.51 | P47: 12039.51 | Q47: 4057.48 | R47: 3409.34 | S47: 3628.42 | T47: 2096.36 | U47: 13191.6 | V47: 2943.62 | W47: 3593.98 | X47: 4000.84 | Y47: 3121.49 | Z47: 13659.93 | AA47: 4572.95 | AB47: 4388.81
A48: 1 | C48: 당기순이익 | E48: 4438 | G48: 4837.54 | H48: 9447.82 | I48: 11762.5 | J48: 6117.3 | K48: 32165.16 | L48: 13142.32 | M48: 12152.54 | N48: 11521.29 | O48: 6858.97 | P48: 43675.12 | Q48: 14360.01 | R48: 12398.7 | S48: 7270.17 | T48: 11413.97 | U48: 45442.85 | V48: 10367.56 | W48: 10745.23 | X48: 13603.2 | Y48: 12982.1 | Z48: 47698.09 | AA48: 14739.8 | AB48: 14281.75
...

Sheet subQ
A1: YQ | C1: subQ 분기 서브모델(억원, U=100) | E1: 4Q21 | F1: 2021 | G1: 1Q22 | H1: 2Q22 | I1: 3Q22 | J1: 4Q22 | K1: 2022 | L1: 1Q23 | M1: 2Q23 | N1: 3Q23 | O1: 4Q23 | P1: 2023 | Q1: 1Q24 | R1: 2Q24 | S1: 3Q24 | T1: 4Q24 | U1: 2024 | V1: 1Q25 | W1: 2Q25 | X1: 3Q25 | Y1: 4Q25 | Z1: 2025 | AA1: 1Q26 | AB1: 2Q26 | AC1: 3Q26 | AD1: 4Q26 | AE1: 2026 | AF1: 1Q27 | AG1: 2Q27 | AH1: 3Q27 | AI1: 4Q27 | AJ1: 2027 | AK1: 1Q28 | AL1: 2Q28 | AM1: 3Q28 | AN1: 4Q28 | AO1: 2028
A2: A=이름(key) B=그룹 C=단위 D=FnGuide 계정명(VLOOKUP 키). 확정=VLOOKUP(BS), 추정=변수 가정 참조
E3: 1 | F3: 2 | G3: 3 | H3: 4 | I3: 5 | J3: 6 | K3: 7 | L3: 8 | M3: 9 | N3: 10 | O3: 11 | P3: 12 | Q3: 13 | R3: 14 | S3: 15 | T3: 16 | U3: 17 | V3: 18 | W3: 19 | X3: 20 | Y3: 21 | Z3: 22 | AA3: 23 | AB3: 24 | AC3: 25 | AD3: 26 | AE3: 27 | AF3: 28 | AG3: 29 | AH3: 30 | AI3: 31 | AJ3: 32 | AK3: 33 | AL3: 34 | AM3: 35 | AN3: 36 | AO3: 37
E4: 2021.12 | F4: 2021.12A | G4: 2022.03 | H4: 2022.06 | I4: 2022.09 | J4: 2022.12 | K4: 2022.12A | L4: 2023.03 | M4: 2023.06 | N4: 2023.09 | O4: 2023.12 | P4: 2023.12A | Q4: 2024.03 | R4: 2024.06 | S4: 2024.09 | T4: 2024.12 | U4: 2024.12A | V4: 2025.03 | W4: 2025.06 | X4: 2025.09 | Y4: 2025.12 | Z4: 2025.12A | AA4: 2026.03 | AB4: 2026.06 | AC4: 2026.09 | AD4: 2026.12 | AE4: 2026.12A | AF4: 2027.03 | AG4: 2027.06 | AH4: 2027.09 | AI4: 2027.12 | AJ4: 2027.12A | AK4: 2028.03 | AL4: 2028.06 | AM4: 2028.09 | AN4: 2028.12 | AO4: 2028.12A
A5: 매출액 | B5: 손익 | C5: 억원 | D5: 매출액(수익) | E5: =IFERROR(VLOOKUP($D5,BS연결,MATCH(E$1,BS연결H,0),0)/100,"") | G5: =IFERROR(VLOOKUP($D5,BS연결,MATCH(G$1,BS연결H,0),0)/100,"") | H5: =IFERROR(VLOOKUP($D5,BS연결,MATCH(H$1,BS연결H,0),0)/100,"") | I5: =IFERROR(VLOOKUP($D5,BS연결,MATCH(I$1,BS연결H,0),0)/100,"") | J5: =IFERROR(VLOOKUP($D5,BS연결,MATCH(J$1,BS연결H,0),0)/100,"") | K5: =IFERROR(VLOOKUP($D5,BS연결,MATCH(K$1,BS연결H,0),0)/100,"") | L5: =IFERROR(VLOOKUP($D5,BS연결,MATCH(L$1,BS연결H,0),0)/100,"") | M5: =IFERROR(VLOOKUP($D5,BS연결,MATCH(M$1,BS연결H,0),0)/100,"") | N5: =IFERROR(VLOOKUP($D5,BS연결,MATCH(N$1,BS연결H,0),0)/100,"") | ... AB5: =IFERROR(VLOOKUP($D5,BS연결,MATCH(AB$1,BS연결H,0),0)/100,"") | AC5: =IFERROR(X5*(1+변수!AC21),"") | AD5: =IFERROR(Y5*(1+변수!AD21),"") | AE5: =SUM(AA5:AD5) | AF5: =IFERROR(AA5*(1+변수!AF21),"") | AG5: =IFERROR(AB5*(1+변수!AG21),"") | AH5: =IFERROR(AC5*(1+변수!AH21),"") | AI5: =IFERROR(AD5*(1+변수!AI21),"") | AJ5: =SUM(AF5:AI5) | AK5: =IFERROR(AF5*(1+변수!AK21),"") | AL5: =IFERROR(AG5*(1+변수!AL21),"") | AM5: =IFERROR(AH5*(1+변수!AM21),"") | AN5: =IFERROR(AI5*(1+변수!AN21),"") | AO5: =SUM(AK5:AN5)
A6: 매출원가 | B6: 손익 | C6: 억원 | D6: 매출원가 | E6: =IFERROR(VLOOKUP($D6,BS연결,MATCH(E$1,BS연결H,0),0)/100,"") | G6: =IFERROR(VLOOKUP($D6,BS연결,MATCH(G$1,BS연결H,0),0)/100,"") | H6: =IFERROR(VLOOKUP($D6,BS연결,MATCH(H$1,BS연결H,0),0)/100,"") | I6: =IFERROR(VLOOKUP($D6,BS연결,MATCH(I$1,BS연결H,0),0)/100,"") | J6: =IFERROR(VLOOKUP($D6,BS연결,MATCH(J$1,BS연결H,0),0)/100,"") | K6: =IFERROR(VLOOKUP($D6,BS연결,MATCH(K$1,BS연결H,0),0)/100,"") | L6: =IFERROR(VLOOKUP($D6,BS연결,MATCH(L$1,BS연결H,0),0)/100,"") | M6: =IFERROR(VLOOKUP($D6,BS연결,MATCH(M$1,BS연결H,0),0)/100,"") | N6: =IFERROR(VLOOKUP($D6,BS연결,MATCH(N$1,BS연결H,0),0)/100,"") | ... AB6: =IFERROR(VLOOKUP($D6,BS연결,MATCH(AB$1,BS연결H,0),0)/100,"") | AC6: =IFERROR(AC5-AC7,"") | AD6: =IFERROR(AD5-AD7,"") | AE6: =SUM(AA6:AD6) | AF6: =IFERROR(AF5-AF7,"") | AG6: =IFERROR(AG5-AG7,"") | AH6: =IFERROR(AH5-AH7,"") | AI6: =IFERROR(AI5-AI7,"") | AJ6: =SUM(AF6:AI6) | AK6: =IFERROR(AK5-AK7,"") | AL6: =IFERROR(AL5-AL7,"") | AM6: =IFERROR(AM5-AM7,"") | AN6: =IFERROR(AN5-AN7,"") | AO6: =SUM(AK6:AN6)
A7: 매출총이익 | B7: 손익 | C7: 억원 | D7: 매출총이익 | E7: =IFERROR(VLOOKUP($D7,BS연결,MATCH(E$1,BS연결H,0),0)/100,"") | G7: =IFERROR(VLOOKUP($D7,BS연결,MATCH(G$1,BS연결H,0),0)/100,"") | H7: =IFERROR(VLOOKUP($D7,BS연결,MATCH(H$1,BS연결H,0),0)/100,"") | I7: =IFERROR(VLOOKUP($D7,BS연결,MATCH(I$1,BS연결H,0),0)/100,"") | J7: =IFERROR(VLOOKUP($D7,BS연결,MATCH(J$1,BS연결H,0),0)/100,"") | K7: =IFERROR(VLOOKUP($D7,BS연결,MATCH(K$1,BS연결H,0),0)/100,"") | L7: =IFERROR(VLOOKUP($D7,BS연결,MATCH(L$1,BS연결H,0),0)/100,"") | M7: =IFERROR(VLOOKUP($D7,BS연결,MATCH(M$1,BS연결H,0),0)/100,"") | N7: =IFERROR(VLOOKUP($D7,BS연결,MATCH(N$1,BS연결H,0),0)/100,"") | ... AB7: =IFERROR(VLOOKUP($D7,BS연결,MATCH(AB$1,BS연결H,0),0)/100,"") | AC7: =IFERROR(AC9+AC8,"") | AD7: =IFERROR(AD9+AD8,"") | AE7: =SUM(AA7:AD7) | AF7: =IFERROR(AF9+AF8,"") | AG7: =IFERROR(AG9+AG8,"") | AH7: =IFERROR(AH9+AH8,"") | AI7: =IFERROR(AI9+AI8,"") | AJ7: =SUM(AF7:AI7) | AK7: =IFERROR(AK9+AK8,"") | AL7: =IFERROR(AL9+AL8,"") | AM7: =IFERROR(AM9+AM8,"") | AN7: =IFERROR(AN9+AN8,"") | AO7: =SUM(AK7:AN7)
A8: 판관비 | B8: 손익 | C8: 억원 | D8: 판관비 | E8: =IFERROR(VLOOKUP($D8,BS연결,MATCH(E$1,BS연결H,0),0)/100,"") | G8: =IFERROR(VLOOKUP($D8,BS연결,MATCH(G$1,BS연결H,0),0)/100,"") | H8: =IFERROR(VLOOKUP($D8,BS연결,MATCH(H$1,BS연결H,0),0)/100,"") | I8: =IFERROR(VLOOKUP($D8,BS연결,MATCH(I$1,BS연결H,0),0)/100,"") | J8: =IFERROR(VLOOKUP($D8,BS연결,MATCH(J$1,BS연결H,0),0)/100,"") | K8: =IFERROR(VLOOKUP($D8,BS연결,MATCH(K$1,BS연결H,0),0)/100,"") | L8: =IFERROR(VLOOKUP($D8,BS연결,MATCH(L$1,BS연결H,0),0)/100,"") | M8: =IFERROR(VLOOKUP($D8,BS연결,MATCH(M$1,BS연결H,0),0)/100,"") | N8: =IFERROR(VLOOKUP($D8,BS연결,MATCH(N$1,BS연결H,0),0)/100,"") | ... AB8: =IFERROR(VLOOKUP($D8,BS연결,MATCH(AB$1,BS연결H,0),0)/100,"") | AC8: =IFERROR(AC5*변수!AC22,"") | AD8: =IFERROR(AD5*변수!AD22,"") | AE8: =SUM(AA8:AD8) | AF8: =IFERROR(AF5*변수!AF22,"") | AG8: =IFERROR(AG5*변수!AG22,"") | AH8: =IFERROR(AH5*변수!AH22,"") | AI8: =IFERROR(AI5*변수!AI22,"") | AJ8: =SUM(AF8:AI8) | AK8: =IFERROR(AK5*변수!AK22,"") | AL8: =IFERROR(AL5*변수!AL22,"") | AM8: =IFERROR(AM5*변수!AM22,"") | AN8: =IFERROR(AN5*변수!AN22,"") | AO8: =SUM(AK8:AN8)
A9: 영업이익 | B9: 손익 | C9: 억원 | D9: 영업이익 | E9: =IFERROR(VLOOKUP($D9,BS연결,MATCH(E$1,BS연결H,0),0)/100,"") | G9: =IFERROR(VLOOKUP($D9,BS연결,MATCH(G$1,BS연결H,0),0)/100,"") | H9: =IFERROR(VLOOKUP($D9,BS연결,MATCH(H$1,BS연결H,0),0)/100,"") | I9: =IFERROR(VLOOKUP($D9,BS연결,MATCH(I$1,BS연결H,0),0)/100,"") | J9: =IFERROR(VLOOKUP($D9,BS연결,MATCH(J$1,BS연결H,0),0)/100,"") | K9: =IFERROR(VLOOKUP($D9,BS연결,MATCH(K$1,BS연결H,0),0)/100,"") | L9: =IFERROR(VLOOKUP($D9,BS연결,MATCH(L$1,BS연결H,0),0)/100,"") | M9: =IFERROR(VLOOKUP($D9,BS연결,MATCH(M$1,BS연결H,0),0)/100,"") | N9: =IFERROR(VLOOKUP($D9,BS연결,MATCH(N$1,BS연결H,0),0)/100,"") | ... AB9: =IFERROR(VLOOKUP($D9,BS연결,MATCH(AB$1,BS연결H,0),0)/100,"") | AC9: =IFERROR(AC5*변수!AC23,"") | AD9: =IFERROR(AD5*변수!AD23,"") | AE9: =SUM(AA9:AD9) | AF9: =IFERROR(AF5*변수!AF23,"") | AG9: =IFERROR(AG5*변수!AG23,"") | AH9: =IFERROR(AH5*변수!AH23,"") | AI9: =IFERROR(AI5*변수!AI23,"") | AJ9: =SUM(AF9:AI9) | AK9: =IFERROR(AK5*변수!AK23,"") | AL9: =IFERROR(AL5*변수!AL23,"") | AM9: =IFERROR(AM5*변수!AM23,"") | AN9: =IFERROR(AN5*변수!AN23,"") | AO9: =SUM(AK9:AN9)
A10: OPM | B10: 손익 | C10: % | D10: 영업이익률 | E10: =IFERROR(E9/E5,"") | G10: =IFERROR(G9/G5,"") | H10: =IFERROR(H9/H5,"") | I10: =IFERROR(I9/I5,"") | J10: =IFERROR(J9/J5,"") | K10: =IFERROR(K9/K5,"") | L10: =IFERROR(L9/L5,"") | M10: =IFERROR(M9/M5,"") | N10: =IFERROR(N9/N5,"") | ... AO10: =IFERROR(AO9/AO5,"")
A11: 금융손익 | B11: 손익 | C11: 억원 | D11: 금융손익 | E11: =IFERROR(VLOOKUP($D11,BS연결,MATCH(E$1,BS연결H,0),0)/100,"") | G11: =IFERROR(VLOOKUP($D11,BS연결,MATCH(G$1,BS연결H,0),0)/100,"") | H11: =IFERROR(VLOOKUP($D11,BS연결,MATCH(H$1,BS연결H,0),0)/100,"") | I11: =IFERROR(VLOOKUP($D11,BS연결,MATCH(I$1,BS연결H,0),0)/100,"") | J11: =IFERROR(VLOOKUP($D11,BS연결,MATCH(J$1,BS연결H,0),0)/100,"") | K11: =IFERROR(VLOOKUP($D11,BS연결,MATCH(K$1,BS연결H,0),0)/100,"") | L11: =IFERROR(VLOOKUP($D11,BS연결,MATCH(L$1,BS연결H,0),0)/100,"") | M11: =IFERROR(VLOOKUP($D11,BS연결,MATCH(M$1,BS연결H,0),0)/100,"") | N11: =IFERROR(VLOOKUP($D11,BS연결,MATCH(N$1,BS연결H,0),0)/100,"") | ... AB11: =IFERROR(VLOOKUP($D11,BS연결,MATCH(AB$1,BS연결H,0),0)/100,"") | AC11: =IFERROR(AC12,"") | AD11: =IFERROR(AD12,"") | AE11: =SUM(AA11:AD11) | AF11: =IFERROR(AF12,"") | AG11: =IFERROR(AG12,"") | AH11: =IFERROR(AH12,"") | AI11: =IFERROR(AI12,"") | AJ11: =SUM(AF11:AI11) | AK11: =IFERROR(AK12,"") | AL11: =IFERROR(AL12,"") | AM11: =IFERROR(AM12,"") | AN11: =IFERROR(AN12,"") | AO11: =SUM(AK11:AN11)
A12: 이자손익 | B12: 손익 | C12: 억원 | D12: 이자손익 | K12: =SUM(G12:J12) | P12: =SUM(L12:O12) | U12: =SUM(Q12:T12) | Z12: =SUM(V12:Y12) | AC12: =IFERROR((AB22*변수!$D$48)/4,"") | AD12: =IFERROR((AC22*변수!$D$48)/4,"") | AE12: =SUM(AA12:AD12) | AF12: =IFERROR((AD22*변수!$D$48)/4,"") | AG12: =IFERROR((AF22*변수!$D$48)/4,"") | AH12: =IFERROR((AG22*변수!$D$48)/4,"") | AI12: =IFERROR((AH22*변수!$D$48)/4,"") | AJ12: =SUM(AF12:AI12) | AK12: =IFERROR((AI22*변수!$D$48)/4,"") | AL12: =IFERROR((AK22*변수!$D$48)/4,"") | AM12: =IFERROR((AL22*변수!$D$48)/4,"") | AN12: =IFERROR((AM22*변수!$D$48)/4,"") | AO12: =SUM(AK12:AN12)
