Workbook
Name 변수H: 변수!$C$1:$AO$1
Name 환율: 변수!$C$6:$AO$13
Name BS연결H: BS연결!$C$1:$AO$1
Name BS연결: BS연결!$C$5:$AO$104
Name BS별도H: BS별도!$C$1:$AO$1
Name BS별도: BS별도!$C$5:$AO$92
Name SUBQH: subQ!$A$1:$AO$1
Name subQ: subQ!$A$5:$AO$44

Sheet README
A1: 금강공업(014280) 실적 모델 — ARGUS 한국조선
A2: 기준 분기 2026Q2 · 마지막 실적 2026Q2 · 생성 2026-10-26
A3: 모든 수치는 모델 산출값(DART 공개 재무제표 + 우리 추정)이다 — 목표주가·투자 추천 아님. 참고용 · 투자조언 아님.
A5: 시트
A6: 변수 가정 시계열. 환율 8행(ECB via frankfurter — L2 fx.json; 추정 분기 = 노란 가정), 추정 드라이버(노란 셀 = 모델값에서 역산한 가정, 바꾸면 재계산; 연녹 셀 = 3절 스칼라 참조 수식), 3절 스칼라 가정(세율·판관비율·지배주주비중·이자율·종가·PER 밴드·COE·외화 순노출·헤지비율)
A7: BS연결/BS별도 FnGuide 계정명 × 기간 값 덤프(백만원). 행1 분기라벨, 행4 YYYY.MM / YYYY.12A. 이름정의 BS연결H·BS연결(계정명 C열부터)
A8: subQ 분기 서브모델(억원 = 백만원/100). 확정 행: =IFERROR(VLOOKUP($D행,BS연결,MATCH(E$1,BS연결H,0),0)/100,"") 추정 행: 변수 시트 가정 셀 참조 수식. 외환손익·파생상품손익은 BS 계정 합·차, 기타금융손익은 잔차, OPM·EPS·BPS·PER·PBR 은 파생 수식, 조정EPS 는 EPS 참조(일회성 의심 분기만 산식 셀)
A9: SLS 선표(조선사만, sls json 있을 때): 요약 행(sls 저장값) + 계약별 스케줄(백만$) × (헤지비율 × 헤지환율 + (1−헤지비율) × 건조시점 환율[변수 원/달러(평균)]) → 원화 수식 블록 → 합계 행이 subQ 매출조선에 연결
A10: 시나리오 신규수주 보수/기준/낙관(forecast_panel 패널, 모델에 scenarios 가 있을 때만): 매출액·영업이익 = subQ 기준값 ± (시나리오 신규 − base 신규) × OPM. base 만 subQ 행에 포함, 나머지는 합산 안 함
A11: 분기/연간예상 subQ 를 이름(A열 key)으로 VLOOKUP 한 보고서 표(억원)
A12: TP PER 밴드 × 12M fwd EPS, PBR = ROE/COE × BPS — 모델 산출값 구간, 목표주가·추천 아님
A13: 외화 환율 QoQ, 외화 순노출 × Δ기말환율 → 환관련손익 추정
... A35: 백테스트: {"freeze": "2025Q2", "horizon": 4, "revenue_wape_pct": 7.1, "op_wape_pct": 99.1, "n": 4, "note": "단일 회사 4분기 — 통계 아님", "driver_at_freeze": "trend_seasonal", "selection_oos_at_freeze": null, "frozen_inputs": "fin(연결/별도)·고객 조선사 모델·지주 자회사 모델은 2025Q2 까지의 분기만; 선표는 체결일 ≤ 2025Q2 말일 계약(원장 최신 금액·코호트 등급, 환산 없음); 잔고는 yards_cache 2025Q2; 시세·환율 forward·prices·forecast_panel 신규수주 미사용. 고객 가중치(suppliers.json 언급 비중)와 합병 체인링크는 현재 지식; 고객 연동 채택은 동결 모델 안에서도 자기 la−4분기 OOS 규칙(selection_oos_at_freeze)", "detail": [{"q": "2025Q3", "rev_pred": 1894.0, "rev_act": 2052.74, "op_pred": 77.15, "op_act": -0.39}, {"q": "2025Q4", "rev_pred": 2042.29, "rev_act": 1871.9, "op_pred": 83.19, "op_act": -5.64}, {"q": "2026Q1", "rev_pred": 1934.7, "rev_act": 1966.68, "op_pred": 78.8, "op_act": 132.39}, {"q": "2026Q2", "rev_pred": 2071.1, "rev_act": 2290.92, "op_pred": 84.36, "op_act": 179.9}]}

Sheet 변수
C1: 이름: 변수H | E1: 4Q21 | F1: 2021 | G1: 1Q22 | H1: 2Q22 | I1: 3Q22 | J1: 4Q22 | K1: 2022 | L1: 1Q23 | M1: 2Q23 | N1: 3Q23 | O1: 4Q23 | P1: 2023 | Q1: 1Q24 | R1: 2Q24 | S1: 3Q24 | T1: 4Q24 | U1: 2024 | V1: 1Q25 | W1: 2Q25 | X1: 3Q25 | Y1: 4Q25 | Z1: 2025 | AA1: 1Q26 | AB1: 2Q26 | AC1: 3Q26 | AD1: 4Q26 | AE1: 2026 | AF1: 1Q27 | AG1: 2Q27 | AH1: 3Q27 | AI1: 4Q27 | AJ1: 2027 | AK1: 1Q28 | AL1: 2Q28 | AM1: 3Q28 | AN1: 4Q28 | AO1: 2028
A2: 가정 시계열 — 노란 셀은 추정 가정(모델값에서 역산), 연녹 셀은 3절 스칼라 참조 수식. 바꾸면 subQ·분기·연간예상·TP·시나리오가 재계산됩니다.
E3: 1 | F3: 2 | G3: 3 | H3: 4 | I3: 5 | J3: 6 | K3: 7 | L3: 8 | M3: 9 | N3: 10 | O3: 11 | P3: 12 | Q3: 13 | R3: 14 | S3: 15 | T3: 16 | U3: 17 | V3: 18 | W3: 19 | X3: 20 | Y3: 21 | Z3: 22 | AA3: 23 | AB3: 24 | AC3: 25 | AD3: 26 | AE3: 27 | AF3: 28 | AG3: 29 | AH3: 30 | AI3: 31 | AJ3: 32 | AK3: 33 | AL3: 34 | AM3: 35 | AN3: 36 | AO3: 37
E4: 2021.12 | F4: 2021.12A | G4: 2022.03 | H4: 2022.06 | I4: 2022.09 | J4: 2022.12 | K4: 2022.12A | L4: 2023.03 | M4: 2023.06 | N4: 2023.09 | O4: 2023.12 | P4: 2023.12A | Q4: 2024.03 | R4: 2024.06 | S4: 2024.09 | T4: 2024.12 | U4: 2024.12A | V4: 2025.03 | W4: 2025.06 | X4: 2025.09 | Y4: 2025.12 | Z4: 2025.12A | AA4: 2026.03 | AB4: 2026.06 | AC4: 2026.09 | AD4: 2026.12 | AE4: 2026.12A | AF4: 2027.03 | AG4: 2027.06 | AH4: 2027.09 | AI4: 2027.12 | AJ4: 2027.12A | AK4: 2028.03 | AL4: 2028.06 | AM4: 2028.09 | AN4: 2028.12 | AO4: 2028.12A
B5: 1. FX | C5: 이름: 환율
A6: USDKRW_avg | C6: 원/달러(평균) | E6: 1183.5 | F6: 1145.51 | G6: 1205.78 | H6: 1262.09 | I6: 1341.93 | J6: 1360.12 | K6: 1292.98 | L6: 1276.95 | M6: 1315.69 | N6: 1313.62 | O6: 1322.01 | P6: 1306.85 | Q6: 1330.14 | R6: 1371.28 | S6: 1356.22 | T6: 1396.3 | U6: 1363.53 | V6: 1452.28 | W6: 1398.52 | X6: 1386.95 | Y6: 1449.19 | Z6: 1421.52 | AA6: 1466.12 | AB6: 1501.75 | AC6: 1418.75 | AD6: 1337.49 | AE6: 1451.19 | AF6: 1324.45 | AG6: 1324.45 | AH6: 1324.45 | AI6: 1324.45 | AK6: 1324.45 | AL6: 1324.45 | AM6: 1324.45 | AN6: 1324.45
A7: USDKRW_end | C7: 원/달러(기말) | E7: 1188.75 | F7: 1188.75 | G7: 1213.74 | H7: 1301.24 | I7: 1436.9 | J7: 1260.16 | K7: 1260.16 | L7: 1305.99 | M7: 1321.44 | N7: 1345.35 | O7: 1297.43 | P7: 1297.43 | Q7: 1349.25 | R7: 1377.73 | S7: 1312.17 | T7: 1474.78 | U7: 1474.78 | V7: 1474.54 | W7: 1355.13 | X7: 1403.67 | Y7: 1444.2 | Z7: 1444.2 | AA7: 1524.8 | AB7: 1550.89 | AC7: 1355.4 | AD7: 1324.45 | AE7: 1324.45 | AF7: 1324.45 | AG7: 1324.45 | AH7: 1324.45 | AI7: 1324.45 | AK7: 1324.45 | AL7: 1324.45 | AM7: 1324.45 | AN7: 1324.45
A8: JPY100KRW_avg | C8: 원/100Y(평균) | E8: 1041.02 | F8: 1042.74 | G8: 1036.79 | H8: 972.23 | I8: 970.61 | J8: 961.03 | K8: 985.1 | L8: 964.89 | M8: 957.36 | N8: 909 | O8: 893.22 | P8: 931.11 | Q8: 896.29 | R8: 880.14 | S8: 909.35 | T8: 917.25 | U8: 900.92 | V8: 952.59 | W8: 967.92 | X8: 940.32 | Y8: 940.77 | Z8: 950.17 | AA8: 934.39 | AB8: 942.16 | AC8: 890.41 | AD8: 846.51 | AE8: 915.57 | AF8: 844.67 | AG8: 844.67 | AH8: 844.67 | AI8: 844.67 | AK8: 844.67 | AL8: 844.67 | AM8: 844.67 | AN8: 844.67
A9: JPY100KRW_end | C9: 원/100Y(기말) | E9: 1032.62 | F9: 1032.62 | G9: 996.83 | H9: 954.9 | I9: 993.29 | J9: 955.54 | K9: 955.54 | L9: 980.62 | M9: 913.67 | N9: 901.47 | O9: 917.04 | P9: 917.04 | Q9: 892.42 | R9: 857.76 | S9: 919.21 | T9: 939.65 | U9: 939.65 | V9: 986.84 | W9: 938.85 | X9: 948.49 | Y9: 921.81 | Z9: 921.81 | AA9: 955.99 | AB9: 954.75 | AC9: 863.31 | AD9: 844.67 | AE9: 844.67 | AF9: 844.67 | AG9: 844.67 | AH9: 844.67 | AI9: 844.67 | AK9: 844.67 | AL9: 844.67 | AM9: 844.67 | AN9: 844.67
A10: EURKRW_avg | C10: W/Euro(평균) | E10: 1353.32 | F10: 1354.06 | G10: 1352.29 | H10: 1343.31 | I10: 1350.63 | J10: 1386.07 | K10: 1358.07 | L10: 1369.93 | M10: 1432.41 | N10: 1429.41 | O10: 1420.91 | P10: 1412.88 | Q10: 1444.21 | R10: 1476.42 | S10: 1489.3 | T10: 1490.78 | U10: 1475.4 | V10: 1528.33 | W10: 1585.13 | X10: 1620.04 | Y10: 1686.02 | Z10: 1605.45 | AA10: 1715.47 | AB10: 1746.09 | AC10: 1631.97 | AD10: 1500.06 | AE10: 1680.5 | AF10: 1482.45 | AG10: 1482.45 | AH10: 1482.45 | AI10: 1482.45 | AK10: 1482.45 | AL10: 1482.45 | AM10: 1482.45 | AN10: 1482.45
A11: EURKRW_end | C11: W/Euro(기말) | E11: 1346.38 | F11: 1346.38 | G11: 1347.37 | H11: 1351.6 | I11: 1400.62 | J11: 1344.08 | K11: 1344.08 | L11: 1420.26 | M11: 1435.88 | N11: 1425.26 | O11: 1433.66 | P11: 1433.66 | Q11: 1458.68 | R11: 1474.86 | S11: 1469.1 | T11: 1532.14 | U11: 1532.14 | V11: 1594.72 | W11: 1588.22 | X11: 1648.04 | Y11: 1696.94 | Z11: 1696.94 | AA11: 1753.21 | AB11: 1767.09 | AC11: 1539.06 | AD11: 1482.45 | AE11: 1482.45 | AF11: 1482.45 | AG11: 1482.45 | AH11: 1482.45 | AI11: 1482.45 | AK11: 1482.45 | AL11: 1482.45 | AM11: 1482.45 | AN11: 1482.45
A12: CNYKRW_avg | C12: 원/중국원(평균) | E12: 185.14 | F12: 177.65 | G12: 189.93 | H12: 190.76 | I12: 195.79 | J12: 191.09 | K12: 191.93 | L12: 186.59 | M12: 187.45 | N12: 181.28 | O12: 182.86 | P12: 184.52 | Q12: 185.04 | R12: 189.35 | S12: 189.24 | T12: 194.24 | U12: 189.49 | V12: 199.63 | W12: 193.41 | X12: 193.79 | Y12: 204.38 | Z12: 197.8 | AA12: 211.75 | AB12: 220.8 | AC12: 210.43 | AD12: 199.88 | AE12: 213.06 | AF12: 198.56 | AG12: 198.56 | AH12: 198.56 | AI12: 198.56 | AK12: 198.56 | AL12: 198.56 | AM12: 198.56 | AN12: 198.56
A13: CNYKRW_end | C13: 원/중국원(기말) | E13: 187.13 | F13: 187.13 | G13: 191.38 | H13: 194.13 | I13: 201.92 | J13: 182.67 | K13: 182.67 | L13: 189.97 | M13: 181.8 | N13: 184.26 | O13: 182.61 | P13: 182.61 | Q13: 186.66 | R13: 189.7 | S13: 187.12 | T13: 202.04 | U13: 202.04 | V13: 203.3 | W13: 189.14 | X13: 197.16 | Y13: 206.28 | Z13: 206.28 | AA13: 220.97 | AB13: 228.56 | AC13: 202.16 | AD13: 198.56 | AE13: 198.56 | AF13: 198.56 | AG13: 198.56 | AH13: 198.56 | AI13: 198.56 | AK13: 198.56 | AL13: 198.56 | AM13: 198.56 | AN13: 198.56
B14: 1b. 종가
A15: price_close_end | C15: 종가(기말) | E15: 7820 | G15: 9730 | H15: 6980 | I15: 5170 | J15: 6190 | L15: 5370 | M15: 7310 | N15: 5590 | O15: 5680 | Q15: 5680 | R15: 4970 | S15: 4330 | T15: 3900 | V15: 4300 | W15: 4590 | X15: 4770 | Y15: 6060 | AA15: 4720 | AB15: 4080 | AC15: 4850 | AD15: 4015
A16: price_high | C16: 종가(최고) | E16: 8360 | G16: 10200 | H16: 10800 | I16: 8000 | J16: 8440 | L16: 6600 | M16: 8230 | N16: 7930 | O16: 6120 | Q16: 6540 | R16: 5730 | S16: 5270 | T16: 5150 | V16: 5640 | W16: 5120 | X16: 6280 | Y16: 8470 | AA16: 6730 | AB16: 6590 | AC16: 5450 | AD16: 5040
A17: price_low | C17: 종가(최저) | E17: 7500 | G17: 7520 | H17: 6480 | I17: 4995 | J17: 4795 | L17: 4990 | M17: 4990 | N17: 5410 | O17: 5220 | Q17: 5560 | R17: 4945 | S17: 3985 | T17: 3800 | V17: 3860 | W17: 3910 | X17: 4080 | Y17: 4640 | AA17: 4630 | AB17: 3700 | AC17: 3420 | AD17: 3940
A18: price_avg | C18: 종가(평균) | E18: 7937.3 | G18: 8495.3 | H18: 8934.7 | I18: 6809.2 | J18: 6044.1 | L18: 5873.9 | M18: 5608.7 | N18: 6340.2 | O18: 5610 | Q18: 6043.4 | R18: 5328.6 | S18: 4714.3 | T18: 4248.3 | V18: 4115.6 | W18: 4586.2 | X18: 4743.5 | Y18: 6017.2 | AA18: 5625.4 | AB18: 4864.8 | AC18: 4234.7 | AD18: 4361.2
B20: 2. 추정 드라이버 | C20: 실적 열 = subQ 실현값(수식), 추정 열 = 가정(노란 = 모델값 역산, 연녹 = 3절 스칼라 참조)
A21: drv:매출액 | B21: yoy | C21: 매출액 YoY | J21: =IFERROR(subQ!J5/subQ!E5-1,"") | L21: =IFERROR(subQ!L5/subQ!G5-1,"") | M21: =IFERROR(subQ!M5/subQ!H5-1,"") | N21: =IFERROR(subQ!N5/subQ!I5-1,"") | O21: =IFERROR(subQ!O5/subQ!J5-1,"") | Q21: =IFERROR(subQ!Q5/subQ!L5-1,"") | R21: =IFERROR(subQ!R5/subQ!M5-1,"") | S21: =IFERROR(subQ!S5/subQ!N5-1,"") | T21: =IFERROR(subQ!T5/subQ!O5-1,"") | V21: =IFERROR(subQ!V5/subQ!Q5-1,"") | W21: =IFERROR(subQ!W5/subQ!R5-1,"") | X21: =IFERROR(subQ!X5/subQ!S5-1,"") | Y21: =IFERROR(subQ!Y5/subQ!T5-1,"") | AA21: =IFERROR(subQ!AA5/subQ!V5-1,"") | AB21: =IFERROR(subQ!AB5/subQ!W5-1,"") | AC21: 0.007322264 | AD21: 0.007324486 | AF21: 0.007323828 | AG21: 0.007323205 | AH21: 0.003660949 | AI21: 0.003659293 | AK21: 0.00365962 | AL21: 0.003661654 | AM21: 0.001831025 | AN21: 0.001833544
A22: drv:판관비 | B22: ratio | C22: 판관비율(/매출) | E22: =IFERROR(subQ!E8/subQ!E5,"") | F22: =IFERROR(subQ!F8/subQ!F5,"") | G22: =IFERROR(subQ!G8/subQ!G5,"") | H22: =IFERROR(subQ!H8/subQ!H5,"") | I22: =IFERROR(subQ!I8/subQ!I5,"") | J22: =IFERROR(subQ!J8/subQ!J5,"") | K22: =IFERROR(subQ!K8/subQ!K5,"") | L22: =IFERROR(subQ!L8/subQ!L5,"") | ... AB22: =IFERROR(subQ!AB8/subQ!AB5,"") | AC22: =$D$51 | AD22: =$D$51 | AE22: =IFERROR(subQ!AE8/subQ!AE5,"") | AF22: =$D$51 | AG22: =$D$51 | AH22: =$D$51 | AI22: =$D$51 | AJ22: =IFERROR(subQ!AJ8/subQ!AJ5,"") | AK22: =$D$51 | AL22: =$D$51 | AM22: =$D$51 | AN22: =$D$51 | AO22: =IFERROR(subQ!AO8/subQ!AO5,"")
A23: drv:영업이익 | B23: ratio | C23: 영업이익률(OPM) | E23: =IFERROR(subQ!E9/subQ!E5,"") | F23: =IFERROR(subQ!F9/subQ!F5,"") | G23: =IFERROR(subQ!G9/subQ!G5,"") | H23: =IFERROR(subQ!H9/subQ!H5,"") | I23: =IFERROR(subQ!I9/subQ!I5,"") | J23: =IFERROR(subQ!J9/subQ!J5,"") | K23: =IFERROR(subQ!K9/subQ!K5,"") | L23: =IFERROR(subQ!L9/subQ!L5,"") | ... AB23: =IFERROR(subQ!AB9/subQ!AB5,"") | AC23: 0.026772804 | AD23: 0.026771177 | AE23: =IFERROR(subQ!AE9/subQ!AE5,"") | AF23: 0.026773275 | AG23: 0.026771244 | AH23: 0.026771517 | AI23: 0.026773967 | AJ23: =IFERROR(subQ!AJ9/subQ!AJ5,"") | AK23: 0.02677121 | AL23: 0.026772877 | AM23: 0.026770684 | AN23: 0.026772434 | AO23: =IFERROR(subQ!AO9/subQ!AO5,"")
A24: drv:기타영업외손익 | B24: abs | C24: 기타영업외손익 (가정, 억원) | E24: =subQ!E13 | F24: =subQ!F13 | G24: =subQ!G13 | H24: =subQ!H13 | I24: =subQ!I13 | J24: =subQ!J13 | K24: =subQ!K13 | L24: =subQ!L13 | ... AB24: =subQ!AB13 | AC24: 0 | AD24: 0 | AE24: =subQ!AE13 | AF24: 0 | AG24: 0 | AH24: 0 | AI24: 0 | AJ24: =subQ!AJ13 | AK24: 0 | AL24: 0 | AM24: 0 | AN24: 0 | AO24: =subQ!AO13
A25: drv:지분법손익 | B25: abs | C25: 지분법손익 (가정, 억원) | E25: =subQ!E14 | F25: =subQ!F14 | G25: =subQ!G14 | H25: =subQ!H14 | I25: =subQ!I14 | J25: =subQ!J14 | K25: =subQ!K14 | L25: =subQ!L14 | ... AB25: =subQ!AB14 | AC25: 10.37 | AD25: 10.37 | AE25: =subQ!AE14 | AF25: 10.37 | AG25: 10.37 | AH25: 10.37 | AI25: 10.37 | AJ25: =subQ!AJ14 | AK25: 10.37 | AL25: 10.37 | AM25: 10.37 | AN25: 10.37 | AO25: =subQ!AO14
A26: drv:법인세비용 | B26: tax | C26: 법인세율(/세전) — 법인세 = MAX(세전,0) × 세율 | E26: =IFERROR(subQ!E16/subQ!E15,"") | F26: =IFERROR(subQ!F16/subQ!F15,"") | G26: =IFERROR(subQ!G16/subQ!G15,"") | H26: =IFERROR(subQ!H16/subQ!H15,"") | I26: =IFERROR(subQ!I16/subQ!I15,"") | J26: =IFERROR(subQ!J16/subQ!J15,"") | K26: =IFERROR(subQ!K16/subQ!K15,"") | L26: =IFERROR(subQ!L16/subQ!L15,"") | ... AB26: =IFERROR(subQ!AB16/subQ!AB15,"") | AC26: =$D$50 | AD26: =$D$50 | AE26: =IFERROR(subQ!AE16/subQ!AE15,"") | AF26: =$D$50 | AG26: =$D$50 | AH26: =$D$50 | AI26: =$D$50 | AJ26: =IFERROR(subQ!AJ16/subQ!AJ15,"") | AK26: =$D$50 | AL26: =$D$50 | AM26: =$D$50 | AN26: =$D$50 | AO26: =IFERROR(subQ!AO16/subQ!AO15,"")
A27: drv:지배주주순이익 | B27: ratio | C27: 지배주주 비중(/당기순이익) | E27: =IFERROR(subQ!E18/subQ!E17,"") | F27: =IFERROR(subQ!F18/subQ!F17,"") | G27: =IFERROR(subQ!G18/subQ!G17,"") | H27: =IFERROR(subQ!H18/subQ!H17,"") | I27: =IFERROR(subQ!I18/subQ!I17,"") | J27: =IFERROR(subQ!J18/subQ!J17,"") | K27: =IFERROR(subQ!K18/subQ!K17,"") | L27: =IFERROR(subQ!L18/subQ!L17,"") | ... AB27: =IFERROR(subQ!AB18/subQ!AB17,"") | AC27: =$D$52 | AD27: =$D$52 | AE27: =IFERROR(subQ!AE18/subQ!AE17,"") | AF27: =$D$52 | AG27: =$D$52 | AH27: =$D$52 | AI27: =$D$52 | AJ27: =IFERROR(subQ!AJ18/subQ!AJ17,"") | AK27: =$D$52 | AL27: =$D$52 | AM27: =$D$52 | AN27: =$D$52 | AO27: =IFERROR(subQ!AO18/subQ!AO17,"")
A28: drv:중단사업이익 | B28: abs | C28: 중단사업이익 (가정, 억원) | E28: =subQ!E19 | F28: =subQ!F19 | G28: =subQ!G19 | H28: =subQ!H19 | I28: =subQ!I19 | J28: =subQ!J19 | K28: =subQ!K19 | L28: =subQ!L19 | ... AB28: =subQ!AB19 | AE28: =subQ!AE19 | AJ28: =subQ!AJ19 | AO28: =subQ!AO19
A29: drv:감가상각비 | B29: abs | C29: 감가상각비 (가정, 억원) | E29: =subQ!E20 | F29: =subQ!F20 | G29: =subQ!G20 | H29: =subQ!H20 | I29: =subQ!I20 | J29: =subQ!J20 | K29: =subQ!K20 | L29: =subQ!L20 | ... AB29: =subQ!AB20 | AC29: 157.74 | AD29: 157.74 | AE29: =subQ!AE20 | AF29: 157.74 | AG29: 157.74 | AH29: 157.74 | AI29: 157.74 | AJ29: =subQ!AJ20 | AK29: 157.74 | AL29: 157.74 | AM29: 157.74 | AN29: 157.74 | AO29: =subQ!AO20
A30: drv:부채총계 | B30: qoq | C30: 부채총계 QoQ | G30: =IFERROR(subQ!G23/subQ!E23-1,"") | H30: =IFERROR(subQ!H23/subQ!G23-1,"") | I30: =IFERROR(subQ!I23/subQ!H23-1,"") | J30: =IFERROR(subQ!J23/subQ!I23-1,"") | L30: =IFERROR(subQ!L23/subQ!J23-1,"") | M30: =IFERROR(subQ!M23/subQ!L23-1,"") | N30: =IFERROR(subQ!N23/subQ!M23-1,"") | O30: =IFERROR(subQ!O23/subQ!N23-1,"") | Q30: =IFERROR(subQ!Q23/subQ!O23-1,"") | R30: =IFERROR(subQ!R23/subQ!Q23-1,"") | S30: =IFERROR(subQ!S23/subQ!R23-1,"") | T30: =IFERROR(subQ!T23/subQ!S23-1,"") | V30: =IFERROR(subQ!V23/subQ!T23-1,"") | W30: =IFERROR(subQ!W23/subQ!V23-1,"") | X30: =IFERROR(subQ!X23/subQ!W23-1,"") | Y30: =IFERROR(subQ!Y23/subQ!X23-1,"") | AA30: =IFERROR(subQ!AA23/subQ!Y23-1,"") | AB30: =IFERROR(subQ!AB23/subQ!AA23-1,"") | AC30: -3.7e-07 | AD30: 0 | AF30: 0 | AG30: 0 | AH30: 0 | AI30: 0 | AK30: 0 | AL30: 0 | AM30: 0 | AN30: 0
A31: drv:자본총계 | B31: roll | C31: 자본총계 기타변동(배당 등, 억원) | G31: =IFERROR(subQ!E24+subQ!G17-subQ!G24,"") | H31: =IFERROR(subQ!G24+subQ!H17-subQ!H24,"") | I31: =IFERROR(subQ!H24+subQ!I17-subQ!I24,"") | J31: =IFERROR(subQ!I24+subQ!J17-subQ!J24,"") | L31: =IFERROR(subQ!J24+subQ!L17-subQ!L24,"") | M31: =IFERROR(subQ!L24+subQ!M17-subQ!M24,"") | N31: =IFERROR(subQ!M24+subQ!N17-subQ!N24,"") | O31: =IFERROR(subQ!N24+subQ!O17-subQ!O24,"") | Q31: =IFERROR(subQ!O24+subQ!Q17-subQ!Q24,"") | R31: =IFERROR(subQ!Q24+subQ!R17-subQ!R24,"") | S31: =IFERROR(subQ!R24+subQ!S17-subQ!S24,"") | T31: =IFERROR(subQ!S24+subQ!T17-subQ!T24,"") | V31: =IFERROR(subQ!T24+subQ!V17-subQ!V24,"") | W31: =IFERROR(subQ!V24+subQ!W17-subQ!W24,"") | X31: =IFERROR(subQ!W24+subQ!X17-subQ!X24,"") | Y31: =IFERROR(subQ!X24+subQ!Y17-subQ!Y24,"") | AA31: =IFERROR(subQ!Y24+subQ!AA17-subQ!AA24,"") | AB31: =IFERROR(subQ!AA24+subQ!AB17-subQ!AB24,"") | AC31: -0.003270729 | AD31: -0.003910465 | AF31: 0.002227486 | AG31: 34.001436 | AH31: -0.002805422 | AI31: -0.001083468 | AK31: 0.002059293 | AL31: 33.998753 | AM31: -0.007099827 | AN31: 0.003702807
A32: drv:지배주주지분 | B32: roll | C32: 지배주주지분 기타변동(배당 등, 억원) | G32: =IFERROR(subQ!E25+subQ!G18-subQ!G25,"") | H32: =IFERROR(subQ!G25+subQ!H18-subQ!H25,"") | I32: =IFERROR(subQ!H25+subQ!I18-subQ!I25,"") | J32: =IFERROR(subQ!I25+subQ!J18-subQ!J25,"") | L32: =IFERROR(subQ!J25+subQ!L18-subQ!L25,"") | M32: =IFERROR(subQ!L25+subQ!M18-subQ!M25,"") | N32: =IFERROR(subQ!M25+subQ!N18-subQ!N25,"") | O32: =IFERROR(subQ!N25+subQ!O18-subQ!O25,"") | Q32: =IFERROR(subQ!O25+subQ!Q18-subQ!Q25,"") | R32: =IFERROR(subQ!Q25+subQ!R18-subQ!R25,"") | S32: =IFERROR(subQ!R25+subQ!S18-subQ!S25,"") | T32: =IFERROR(subQ!S25+subQ!T18-subQ!T25,"") | V32: =IFERROR(subQ!T25+subQ!V18-subQ!V25,"") | W32: =IFERROR(subQ!V25+subQ!W18-subQ!W25,"") | X32: =IFERROR(subQ!W25+subQ!X18-subQ!X25,"") | Y32: =IFERROR(subQ!X25+subQ!Y18-subQ!Y25,"") | AA32: =IFERROR(subQ!Y25+subQ!AA18-subQ!AA25,"") | AB32: =IFERROR(subQ!AA25+subQ!AB18-subQ!AB25,"") | AC32: 0.001629271 | AD32: -0.003910465 | AF32: 0.002227486 | AG32: 33.991436 | AH32: -0.002805422 | AI32: 0.008916532 | AK32: -0.007940707 | AL32: 33.998753 | AM32: 0.002900173 | AN32: -0.006297193
A33: drv:총차입금 | B33: qoq | C33: 총차입금 QoQ | G33: =IFERROR(subQ!G26/subQ!E26-1,"") | H33: =IFERROR(subQ!H26/subQ!G26-1,"") | I33: =IFERROR(subQ!I26/subQ!H26-1,"") | J33: =IFERROR(subQ!J26/subQ!I26-1,"") | L33: =IFERROR(subQ!L26/subQ!J26-1,"") | M33: =IFERROR(subQ!M26/subQ!L26-1,"") | N33: =IFERROR(subQ!N26/subQ!M26-1,"") | O33: =IFERROR(subQ!O26/subQ!N26-1,"") | Q33: =IFERROR(subQ!Q26/subQ!O26-1,"") | R33: =IFERROR(subQ!R26/subQ!Q26-1,"") | S33: =IFERROR(subQ!S26/subQ!R26-1,"") | T33: =IFERROR(subQ!T26/subQ!S26-1,"") | V33: =IFERROR(subQ!V26/subQ!T26-1,"") | W33: =IFERROR(subQ!W26/subQ!V26-1,"") | X33: =IFERROR(subQ!X26/subQ!W26-1,"") | Y33: =IFERROR(subQ!Y26/subQ!X26-1,"") | AA33: =IFERROR(subQ!AA26/subQ!Y26-1,"") | AB33: =IFERROR(subQ!AB26/subQ!AA26-1,"") | AC33: 2.8e-07 | AD33: 0 | AF33: 0 | AG33: 0 | AH33: 0 | AI33: 0 | AK33: 0 | AL33: 0 | AM33: 0 | AN33: 0
A34: drv:순차입금 | B34: qoq | C34: 순차입금 QoQ | G34: =IFERROR(subQ!G27/subQ!E27-1,"") | H34: =IFERROR(subQ!H27/subQ!G27-1,"") | I34: =IFERROR(subQ!I27/subQ!H27-1,"") | J34: =IFERROR(subQ!J27/subQ!I27-1,"") | L34: =IFERROR(subQ!L27/subQ!J27-1,"") | M34: =IFERROR(subQ!M27/subQ!L27-1,"") | N34: =IFERROR(subQ!N27/subQ!M27-1,"") | O34: =IFERROR(subQ!O27/subQ!N27-1,"") | Q34: =IFERROR(subQ!Q27/subQ!O27-1,"") | R34: =IFERROR(subQ!R27/subQ!Q27-1,"") | S34: =IFERROR(subQ!S27/subQ!R27-1,"") | T34: =IFERROR(subQ!T27/subQ!S27-1,"") | V34: =IFERROR(subQ!V27/subQ!T27-1,"") | W34: =IFERROR(subQ!W27/subQ!V27-1,"") | X34: =IFERROR(subQ!X27/subQ!W27-1,"") | Y34: =IFERROR(subQ!Y27/subQ!X27-1,"") | AA34: =IFERROR(subQ!AA27/subQ!Y27-1,"") | AB34: =IFERROR(subQ!AB27/subQ!AA27-1,"") | AC34: 0.007063276 | AD34: 0.007852913 | AF34: 0.007409057 | AG34: 0.013258393 | AH34: 0.006946989 | AI34: 0.00771517 | AK34: 0.007282481 | AL34: 0.012928319 | AM34: 0.006855242 | AN34: 0.007594875
A35: drv:이자발생자산 | B35: qoq | C35: 이자발생자산 QoQ | G35: =IFERROR(subQ!G28/subQ!E28-1,"") | H35: =IFERROR(subQ!H28/subQ!G28-1,"") | I35: =IFERROR(subQ!I28/subQ!H28-1,"") | J35: =IFERROR(subQ!J28/subQ!I28-1,"") | L35: =IFERROR(subQ!L28/subQ!J28-1,"") | M35: =IFERROR(subQ!M28/subQ!L28-1,"") | N35: =IFERROR(subQ!N28/subQ!M28-1,"") | O35: =IFERROR(subQ!O28/subQ!N28-1,"") | Q35: =IFERROR(subQ!Q28/subQ!O28-1,"") | R35: =IFERROR(subQ!R28/subQ!Q28-1,"") | S35: =IFERROR(subQ!S28/subQ!R28-1,"") | T35: =IFERROR(subQ!T28/subQ!S28-1,"") | V35: =IFERROR(subQ!V28/subQ!T28-1,"") | W35: =IFERROR(subQ!W28/subQ!V28-1,"") | X35: =IFERROR(subQ!X28/subQ!W28-1,"") | Y35: =IFERROR(subQ!Y28/subQ!X28-1,"") | AA35: =IFERROR(subQ!AA28/subQ!Y28-1,"") | AB35: =IFERROR(subQ!AB28/subQ!AA28-1,"") | AC35: -0.018469417 | AD35: -0.021067769 | AF35: -0.020464222 | AG35: -0.037662464 | AH35: -0.020778168 | AI35: -0.023729121 | AK35: -0.02311974 | AL35: -0.042320972 | AM35: -0.02373532 | AN35: -0.027120169
A36: drv:현금및현금성자산 | B36: qoq | C36: 현금및현금성자산 QoQ | G36: =IFERROR(subQ!G29/subQ!E29-1,"") | H36: =IFERROR(subQ!H29/subQ!G29-1,"") | I36: =IFERROR(subQ!I29/subQ!H29-1,"") | J36: =IFERROR(subQ!J29/subQ!I29-1,"") | L36: =IFERROR(subQ!L29/subQ!J29-1,"") | M36: =IFERROR(subQ!M29/subQ!L29-1,"") | N36: =IFERROR(subQ!N29/subQ!M29-1,"") | O36: =IFERROR(subQ!O29/subQ!N29-1,"") | Q36: =IFERROR(subQ!Q29/subQ!O29-1,"") | R36: =IFERROR(subQ!R29/subQ!Q29-1,"") | S36: =IFERROR(subQ!S29/subQ!R29-1,"") | T36: =IFERROR(subQ!T29/subQ!S29-1,"") | V36: =IFERROR(subQ!V29/subQ!T29-1,"") | W36: =IFERROR(subQ!W29/subQ!V29-1,"") | X36: =IFERROR(subQ!X29/subQ!W29-1,"") | Y36: =IFERROR(subQ!Y29/subQ!X29-1,"") | AA36: =IFERROR(subQ!AA29/subQ!Y29-1,"") | AB36: =IFERROR(subQ!AB29/subQ!AA29-1,"")
A37: drv:CAPEX | B37: yoy | C37: CAPEX YoY | J37: =IFERROR(subQ!J30/subQ!E30-1,"") | L37: =IFERROR(subQ!L30/subQ!G30-1,"") | M37: =IFERROR(subQ!M30/subQ!H30-1,"") | N37: =IFERROR(subQ!N30/subQ!I30-1,"") | O37: =IFERROR(subQ!O30/subQ!J30-1,"") | Q37: =IFERROR(subQ!Q30/subQ!L30-1,"") | R37: =IFERROR(subQ!R30/subQ!M30-1,"") | S37: =IFERROR(subQ!S30/subQ!N30-1,"") | T37: =IFERROR(subQ!T30/subQ!O30-1,"") | V37: =IFERROR(subQ!V30/subQ!Q30-1,"") | W37: =IFERROR(subQ!W30/subQ!R30-1,"") | X37: =IFERROR(subQ!X30/subQ!S30-1,"") | Y37: =IFERROR(subQ!Y30/subQ!T30-1,"") | AA37: =IFERROR(subQ!AA30/subQ!V30-1,"") | AB37: =IFERROR(subQ!AB30/subQ!W30-1,"") | AC37: 0.18643839 | AD37: -0.1525655 | AF37: 1.2216524 | AG37: -0.13578498 | AH37: 0 | AI37: 0 | AK37: 0 | AL37: 0 | AM37: 0 | AN37: 0
A38: drv:영업활동현금흐름 | B38: yoy | C38: 영업활동현금흐름 YoY | J38: =IFERROR(subQ!J31/subQ!E31-1,"") | L38: =IFERROR(subQ!L31/subQ!G31-1,"") | M38: =IFERROR(subQ!M31/subQ!H31-1,"") | N38: =IFERROR(subQ!N31/subQ!I31-1,"") | O38: =IFERROR(subQ!O31/subQ!J31-1,"") | Q38: =IFERROR(subQ!Q31/subQ!L31-1,"") | R38: =IFERROR(subQ!R31/subQ!M31-1,"") | S38: =IFERROR(subQ!S31/subQ!N31-1,"") | T38: =IFERROR(subQ!T31/subQ!O31-1,"") | V38: =IFERROR(subQ!V31/subQ!Q31-1,"") | W38: =IFERROR(subQ!W31/subQ!R31-1,"") | X38: =IFERROR(subQ!X31/subQ!S31-1,"") | Y38: =IFERROR(subQ!Y31/subQ!T31-1,"") | AA38: =IFERROR(subQ!AA31/subQ!V31-1,"") | AB38: =IFERROR(subQ!AB31/subQ!W31-1,"")
A39: drv:주식수 | B39: qoq | C39: 주식수 QoQ | G39: =IFERROR(subQ!G32/subQ!E32-1,"") | H39: =IFERROR(subQ!H32/subQ!G32-1,"") | I39: =IFERROR(subQ!I32/subQ!H32-1,"") | J39: =IFERROR(subQ!J32/subQ!I32-1,"") | L39: =IFERROR(subQ!L32/subQ!J32-1,"") | M39: =IFERROR(subQ!M32/subQ!L32-1,"") | N39: =IFERROR(subQ!N32/subQ!M32-1,"") | O39: =IFERROR(subQ!O32/subQ!N32-1,"") | Q39: =IFERROR(subQ!Q32/subQ!O32-1,"") | R39: =IFERROR(subQ!R32/subQ!Q32-1,"") | S39: =IFERROR(subQ!S32/subQ!R32-1,"") | T39: =IFERROR(subQ!T32/subQ!S32-1,"") | V39: =IFERROR(subQ!V32/subQ!T32-1,"") | W39: =IFERROR(subQ!W32/subQ!V32-1,"") | X39: =IFERROR(subQ!X32/subQ!W32-1,"") | Y39: =IFERROR(subQ!Y32/subQ!X32-1,"") | AA39: =IFERROR(subQ!AA32/subQ!Y32-1,"") | AB39: =IFERROR(subQ!AB32/subQ!AA32-1,"") | AC39: 0 | AD39: 0 | AF39: 0 | AG39: 0 | AH39: 0 | AI39: 0 | AK39: 0 | AL39: 0 | AM39: 0 | AN39: 0
A40: drv:DPS | B40: abs | C40: DPS (가정, 원) | E40: =subQ!E36 | F40: =subQ!F36 | G40: =subQ!G36 | H40: =subQ!H36 | I40: =subQ!I36 | J40: =subQ!J36 | K40: =subQ!K36 | L40: =subQ!L36 | ... AB40: =subQ!AB36 | AD40: 120 | AE40: =subQ!AE36 | AI40: 120 | AJ40: =subQ!AJ36 | AN40: 120 | AO40: =subQ!AO36
B42: 3. 밸류에이션·스칼라 | C42: 노란 셀 = 가정. '연결' 표시는 추정 전 분기 수식이 이 셀을 참조한다는 뜻
...

Sheet BS연결
B1: (백만원) | C1: 이름: BS연결H | E1: 4Q21 | F1: 2021 | G1: 1Q22 | H1: 2Q22 | I1: 3Q22 | J1: 4Q22 | K1: 2022 | L1: 1Q23 | M1: 2Q23 | N1: 3Q23 | O1: 4Q23 | P1: 2023 | Q1: 1Q24 | R1: 2Q24 | S1: 3Q24 | T1: 4Q24 | U1: 2024 | V1: 1Q25 | W1: 2Q25 | X1: 3Q25 | Y1: 4Q25 | Z1: 2025 | AA1: 1Q26 | AB1: 2Q26 | AC1: 3Q26 | AD1: 4Q26 | AE1: 2026 | AF1: 1Q27 | AG1: 2Q27 | AH1: 3Q27 | AI1: 4Q27 | AJ1: 2027 | AK1: 1Q28 | AL1: 2Q28 | AM1: 3Q28 | AN1: 4Q28 | AO1: 2028
B2: 연결 | D2: fin json(kship_fin.py)
B3: 금강공업(연) | C3: UPDATE: 26-10-26 | E3: 1 | F3: 2 | G3: 3 | H3: 4 | I3: 5 | J3: 6 | K3: 7 | L3: 8 | M3: 9 | N3: 10 | O3: 11 | P3: 12 | Q3: 13 | R3: 14 | S3: 15 | T3: 16 | U3: 17 | V3: 18 | W3: 19 | X3: 20 | Y3: 21 | Z3: 22 | AA3: 23 | AB3: 24 | AC3: 25 | AD3: 26 | AE3: 27 | AF3: 28 | AG3: 29 | AH3: 30 | AI3: 31 | AJ3: 32 | AK3: 33 | AL3: 34 | AM3: 35 | AN3: 36 | AO3: 37
B4: Account Code | C4: AccountNAME | E4: 2021.12 | F4: 2021.12A | G4: 2022.03 | H4: 2022.06 | I4: 2022.09 | J4: 2022.12 | K4: 2022.12A | L4: 2023.03 | M4: 2023.06 | N4: 2023.09 | O4: 2023.12 | P4: 2023.12A | Q4: 2024.03 | R4: 2024.06 | S4: 2024.09 | T4: 2024.12 | U4: 2024.12A | V4: 2025.03 | W4: 2025.06 | X4: 2025.09 | Y4: 2025.12 | Z4: 2025.12A | AA4: 2026.03 | AB4: 2026.06 | AC4: 2026.09 | AD4: 2026.12 | AE4: 2026.12A | AF4: 2027.03 | AG4: 2027.06 | AH4: 2027.09 | AI4: 2027.12 | AJ4: 2027.12A | AK4: 2028.03 | AL4: 2028.06 | AM4: 2028.09 | AN4: 2028.12 | AO4: 2028.12A
A5: 1 | C5: 유동자산 | E5: 355324.57 | F5: 355324.57 | G5: 364344.68 | H5: 401523.23 | I5: 449359.38 | J5: 443511.16 | K5: 443511.16 | L5: 450494.2 | M5: 473426.88 | N5: 466982.73 | O5: 455179.4 | P5: 455179.4 | Q5: 468915.29 | R5: 469530.85 | S5: 461818.41 | T5: 453123.57 | U5: 453123.57 | V5: 469424.27 | W5: 509681.05 | X5: 507015.82 | Y5: 461072.94 | Z5: 461072.94 | AA5: 491973.77 | AB5: 528803.02
A6: 1 | C6: 현금및현금성자산 | E6: 95812.34 | F6: 95812.34 | G6: 98416.71 | H6: 99546.1 | I6: 100497.59 | J6: 90140.29 | K6: 90140.29 | L6: 97265.77 | M6: 109737.87 | N6: 97769.93 | O6: 102115.48 | P6: 102115.48 | Q6: 107072.44 | R6: 78957.63 | S6: 91068.04 | T6: 87456.76 | U6: 87456.76 | V6: 121129.8 | W6: 114887.68 | X6: 136169.92 | Y6: 107221.32 | Z6: 107221.32 | AA6: 134973.03 | AB6: 152322.7
A7: 1 | C7: 매출채권및기타채권 | E7: 116584.12 | F7: 116584.12 | G7: 128662.14 | H7: 121899.93 | I7: 136679.1 | J7: 132121.79 | K7: 132121.79 | L7: 143238.06 | M7: 146995.96 | N7: 143414.21 | O7: 142179.68 | P7: 142179.68 | Q7: 149710.13 | R7: 154090.61 | S7: 142551.94 | T7: 161581.55 | U7: 161581.55 | V7: 159856.55 | W7: 181839.38 | X7: 154329.02 | Y7: 139018.71 | Z7: 139018.71 | AA7: 143411.89 | AB7: 151946.29
A8: 1 | C8: 재고자산 | E8: 126845.81 | F8: 126845.81 | G8: 119602.29 | H8: 160295.17 | I8: 189091.75 | J8: 189876.69 | K8: 189876.69 | L8: 178476.11 | M8: 196207.83 | N8: 202528.38 | O8: 186757.6 | P8: 186757.6 | Q8: 188271.57 | R8: 191234.32 | S8: 186077.54 | T8: 165316.92 | U8: 165316.92 | V8: 168424.43 | W8: 178822.42 | X8: 180596.85 | Y8: 176610.81 | Z8: 176610.81 | AA8: 193133.4 | AB8: 204973.52
A9: 1 | C9: 기타유동자산 | E9: 4318.65 | F9: 4318.65 | G9: 5047.3 | H9: 4257.5 | I9: 4470.48 | J9: 3655.29 | K9: 3655.29 | L9: 6028.95 | M9: 4689.67 | N9: 6347.48 | O9: 4648.13 | P9: 4648.13 | Q9: 5341.25 | R9: 6868.74 | S9: 7249.52 | T9: 5919.34 | U9: 5919.34 | V9: 6963.42 | W9: 8749.54 | X9: 9994.04 | Y9: 10347.11 | Z9: 10347.11 | AA9: 11284.78 | AB9: 8946.28
A10: 1 | C10: 당기법인세자산(선급법인세) | E10: 2028.59 | F10: 2028.59 | G10: 2279.65 | H10: 2165.94 | I10: 2659.41 | J10: 2170.41 | K10: 2170.41 | L10: 2323.05 | M10: 2300.81 | N10: 2561.42 | O10: 2457.48 | P10: 2457.48 | Q10: 1531.49 | R10: 1488.84 | S10: 2159.25 | T10: 2773.7 | U10: 2773.7 | V10: 1726.53 | W10: 1552.2 | X10: 1679.11 | Y10: 1875.33 | Z10: 1875.33 | AA10: 662.37 | AB10: 328.12
A11: 1 | C11: 비유동자산 | E11: 513334.18 | F11: 513334.18 | G11: 530372.8 | H11: 542969.35 | I11: 666721.39 | J11: 651290.64 | K11: 651290.64 | L11: 662261.62 | M11: 670731.41 | N11: 671464.62 | O11: 675288.31 | P11: 675288.31 | Q11: 679565.66 | R11: 689860.88 | S11: 705225.43 | T11: 708775.68 | U11: 708775.68 | V11: 720090.89 | W11: 697203.21 | X11: 712713.69 | Y11: 726918.64 | Z11: 726918.64 | AA11: 751863.06 | AB11: 786511.55
A12: 1 | C12: 유형자산 | E12: 421857.81 | F12: 421857.81 | G12: 432432.42 | H12: 442043.01 | I12: 568288.15 | J12: 559968.68 | K12: 559968.68 | L12: 568275.74 | M12: 577159.88 | N12: 576276.88 | O12: 557986.09 | P12: 557986.09 | Q12: 569249.12 | R12: 577502.94 | S12: 557638.19 | T12: 560881.99 | U12: 560881.99 | V12: 565978.92 | W12: 561531.97 | X12: 572807.53 | Y12: 580014.8 | Z12: 580014.8 | AA12: 608547.39 | AB12: 639688.31
A13: 1 | C13: 무형자산 | E13: 8904.19 | F13: 8904.19 | G13: 8689.87 | H13: 8662.35 | I13: 8641.14 | J13: 9002.32 | K13: 9002.32 | L13: 9044.54 | M13: 8034.59 | N13: 8098.3 | O13: 8097.81 | P13: 8097.81 | Q13: 7911.34 | R13: 8407.57 | S13: 8513.16 | T13: 8484.65 | U13: 8484.65 | V13: 9186.83 | W13: 9163.15 | X13: 11167.36 | Y13: 11145.66 | Z13: 11145.66 | AA13: 15263.86 | AB13: 14873.04
A14: 1 | C14: 투자부동산 | E14: 15342.8 | F14: 15342.8 | G14: 16524.27 | H14: 16516.17 | I14: 16563.44 | J14: 17639.57 | K14: 17639.57 | L14: 21026.12 | M14: 20926.2 | N14: 20911.45 | O14: 39545.56 | P14: 39545.56 | Q14: 36299.16 | R14: 36661.48 | S14: 71432.72 | T14: 72426.69 | U14: 72426.69 | V14: 72376.43 | W14: 54056.45 | X14: 53946.85 | Y14: 55366.08 | Z14: 55366.08 | AA14: 55272.84 | AB14: 55129
A15: 1 | C15: 종속기업및관계기업투자 | E15: 19283.43 | F15: 19283.43 | G15: 19947.6 | H15: 21008.37 | I15: 21621.51 | J15: 20160.96 | K15: 20160.96 | L15: 19596.58 | M15: 19545.38 | N15: 19539.27 | O15: 19719.57 | P15: 19719.57 | Q15: 18979.21 | R15: 19698.05 | S15: 19617.06 | X15: 26630.6 | AA15: 29386.82 | AB15: 31662.4
A16: 1 | C16: 투자자산 | E16: 29496.17 | F16: 29496.17 | G16: 30808.03 | H16: 30528.69 | I16: 30887.06 | J16: 29660.05 | K16: 29660.05 | L16: 29462.58 | M16: 29416.43 | N16: 30158.33 | O16: 32002.99 | P16: 32002.99 | Q16: 30925.71 | R16: 31533.26 | S16: 29714.77 | T16: 9563.47 | U16: 9563.47 | V16: 9714.85 | W16: 10278.84 | X16: 39320.84 | Y16: 25154.29 | Z16: 25154.29 | AA16: 51715.98 | AB16: 53625.66
A17: 1 | C17: 장기금융자산 | E17: 10212.74 | F17: 10212.74 | G17: 10860.43 | H17: 9520.32 | I17: 9265.55 | J17: 9499.09 | K17: 9499.09 | L17: 9866 | M17: 9871.05 | N17: 10619.06 | O17: 12283.42 | P17: 12283.42 | Q17: 11946.5 | R17: 11835.21 | S17: 10097.71 | T17: 9563.47 | U17: 9563.47 | V17: 9714.85 | W17: 10278.84 | X17: 12690.24 | Y17: 25154.29 | Z17: 25154.29 | AA17: 22329.16 | AB17: 21963.26
A18: 1 | C18: 장기매출채권및기타채권 | E18: 30105.88 | F18: 30105.88 | J18: 26407.08 | K18: 26407.08 | T18: 26725.86 | U18: 26725.86 | V18: 29380.51 | W18: 29821.75 | Y18: 17811.52 | Z18: 17811.52
A19: 1 | C19: 기타비유동자산 | E19: 5539.22 | F19: 5539.22 | G19: 5315.94 | H19: 4535.88 | I19: 4188.09 | J19: 5568.06 | K19: 5568.06 | L19: 3723.05 | M19: 3717.04 | N19: 3619.77 | O19: 6741.64 | P19: 6741.64 | Q19: 3575.48 | R19: 3531.64 | S19: 3402.68 | T19: 3640.13 | U19: 3640.13 | V19: 3550.97 | W19: 3170.39 | X19: 3338.75 | Y19: 3605.94 | Z19: 3605.94 | AA19: 4516.77 | AB19: 7665.34
A20: 1 | C20: 이연법인세자산 | E20: 1992.21 | F20: 1992.21 | G20: 2083.67 | H20: 2001.29 | I20: 2282.61 | J20: 2780.22 | K20: 2780.22 | L20: 2963.13 | M20: 3091.88 | N20: 2825.83 | O20: 2877.72 | P20: 2877.72 | Q20: 3015.76 | R20: 2727.3 | S20: 2829.31 | T20: 3113.73 | U20: 3113.73 | V20: 2690.64 | W20: 2259.12 | X20: 1855.97 | Y20: 686.79 | Z20: 686.79 | AA20: 658.35 | AB20: 655.42
A21: 1 | C21: 자산총계 | E21: 868658.75 | F21: 868658.75 | G21: 894717.47 | H21: 944492.58 | I21: 1116080.8 | J21: 1094801.8 | K21: 1094801.8 | L21: 1112755.8 | M21: 1144158.3 | N21: 1138447.4 | O21: 1130467.7 | P21: 1130467.7 | Q21: 1148481 | R21: 1159391.7 | S21: 1167043.9 | T21: 1161899.2 | U21: 1161899.2 | V21: 1189515.2 | W21: 1206884.3 | X21: 1219729.5 | Y21: 1187991.6 | Z21: 1187991.6 | AA21: 1243836.8 | AB21: 1315314.6
A22: 1 | C22: 유동부채 | E22: 405262.57 | F22: 405262.57 | G22: 413517.96 | H22: 469980.87 | I22: 535220.67 | J22: 523650.51 | K22: 523650.51 | L22: 531881.92 | M22: 551277.57 | N22: 539718.5 | O22: 529800.87 | P22: 529800.87 | Q22: 565836.39 | R22: 524887.4 | S22: 533069.79 | T22: 512506.28 | U22: 512506.28 | V22: 514526.13 | W22: 560079 | X22: 504626.65 | Y22: 481770.63 | Z22: 481770.63 | AA22: 510531.7 | AB22: 526544.64
A23: 1 | C23: 매입채무및기타채무 | E23: 72400.52 | F23: 72400.52 | G23: 80966.17 | H23: 69928.17 | I23: 93629.64 | J23: 92300.42 | K23: 92300.42 | L23: 83547.49 | M23: 95266.64 | N23: 86621 | O23: 97968.59 | P23: 97968.59 | Q23: 98981.67 | R23: 75941.28 | S23: 77568.12 | T23: 82297.53 | U23: 82297.53 | V23: 82750.33 | W23: 79150.88 | X23: 78834.72 | Y23: 75981.81 | Z23: 75981.81 | AA23: 88284.23 | AB23: 78372.94
A24: 1 | C24: 단기차입금 | E24: 286819.44 | F24: 286819.44 | G24: 278438.88 | H24: 325283.63 | I24: 367192.63 | J24: 390288.61 | K24: 390288.61 | L24: 410737.3 | M24: 406193.92 | N24: 394319.97 | O24: 368173.96 | P24: 368173.96 | Q24: 421487.33 | R24: 400806.67 | S24: 416152.66 | T24: 318960.27 | U24: 318960.27 | V24: 331423.72 | W24: 344850.02 | X24: 315836.81 | Y24: 304530.9 | Z24: 304530.9 | AA24: 331099.6 | AB24: 392878.52
A25: 1 | C25: 기타유동부채 | E25: 27910.06 | F25: 27910.06 | G25: 24353.47 | H25: 24648.4 | I25: 28339.34 | J25: 28995.82 | K25: 28995.82 | L25: 28035.25 | M25: 42788.28 | N25: 50414.24 | O25: 41993.2 | P25: 41993.2 | Q25: 38538.89 | R25: 44457.64 | S25: 36102.92 | T25: 35183.47 | U25: 35183.47 | V25: 34717.63 | W25: 50101.16 | X25: 55714.48 | Y25: 54589.97 | Z25: 54589.97 | AA25: 49711.36 | AB25: 50328.79
A26: 1 | C26: 당기법인세부채(미지급법인세) | E26: 3786.62 | F26: 3786.62 | G26: 5537.07 | H26: 5742.62 | I26: 7035.13 | J26: 9037.21 | K26: 9037.21 | L26: 6005.04 | M26: 4117.92 | N26: 5694.06 | O26: 4087.7 | P26: 4087.7 | Q26: 4549.18 | R26: 1379.86 | S26: 1048.77 | T26: 1444.45 | U26: 1444.45 | V26: 1526.37 | W26: 1572.58 | X26: 1548.36 | Y26: 2604.49 | Z26: 2604.49 | AA26: 2162.81 | AB26: 2290.91
A27: 1 | C27: 유동리스부채 | E27: 2131.97 | F27: 2131.97 | G27: 2295.95 | H27: 2262.4 | I27: 2228.94 | J27: 2010.33 | K27: 2010.33 | L27: 2180.86 | M27: 2126.1 | N27: 1939.13 | O27: 2070.85 | P27: 2070.85 | Q27: 2063.58 | R27: 2013.65 | S27: 1959.8 | T27: 2203.98 | U27: 2203.98 | V27: 2318.32 | W27: 2519.21 | X27: 2198.56 | Y27: 1981.23 | Z27: 1981.23 | AA27: 2013.6 | AB27: 2009.39
A28: 1 | C28: 리스부채 | E28: 10569.52 | F28: 10569.52 | G28: 11175.41 | H28: 13485.52 | I28: 13381.93 | J28: 12888.58 | K28: 12888.58 | L28: 12766.09 | M28: 12346.06 | N28: 11743.01 | O28: 11259.76 | P28: 11259.76 | Q28: 10844.55 | R28: 10146.38 | S28: 10294.72 | T28: 10119.11 | U28: 10119.11 | V28: 10005.1 | W28: 9531.7 | X28: 9026.07 | Y28: 8484.4 | Z28: 8484.4 | AA28: 8609.92 | AB28: 8757.82
A29: 1 | C29: 단기금융부채 | E29: 2131.97 | F29: 2131.97 | G29: 2295.95 | H29: 2262.4 | I29: 2228.94 | J29: 2010.33 | K29: 2010.33 | L29: 2180.86 | M29: 2126.1 | N29: 1939.13 | O29: 2070.85 | P29: 2070.85 | Q29: 2063.58 | R29: 2013.65 | S29: 1959.8 | T29: 2203.98 | U29: 2203.98 | V29: 2318.32 | W29: 2519.21 | X29: 2198.56 | Y29: 1981.23 | Z29: 1981.23 | AA29: 2013.6 | AB29: 2009.39
A30: 1 | C30: 비유동부채 | E30: 76725.39 | F30: 76725.39 | G30: 86683.29 | H30: 73796.94 | I30: 128845.13 | J30: 122936.98 | K30: 122936.98 | L30: 128635.34 | M30: 128009.2 | N30: 125814.39 | O30: 123172.89 | P30: 123172.89 | Q30: 102439.6 | R30: 142039.24 | S30: 137422.15 | T30: 150054.62 | U30: 150054.62 | V30: 168756.12 | W30: 147832.18 | X30: 210418.44 | Y30: 208069.42 | Z30: 208069.42 | AA30: 220536.48 | AB30: 256221.65
A31: 1 | C31: 장기차입금 | E31: 46214.49 | F31: 46214.49 | G31: 55079.55 | H31: 40173.32 | I31: 73636.48 | J31: 72314.73 | K31: 72314.73 | L31: 76116.6 | M31: 78591.6 | N31: 80566.61 | O31: 82131.08 | P31: 82131.08 | Q31: 61557.44 | R31: 101492.78 | S31: 97705.83 | T31: 91283.42 | U31: 91283.42 | V31: 127659.57 | W31: 106939 | X31: 171166.66 | Y31: 172591.76 | Z31: 172591.76 | AA31: 182655.89 | AB31: 215163.31
A32: 1 | C32: 장기매입채무및기타채무 | E32: 1475.59 | F32: 1475.59 | H32: 1716.84 | I32: 1716.91 | J32: 1870.28 | K32: 1870.28 | L32: 2017.65 | M32: 1942.82 | N32: 1974.54 | O32: 1743.85 | P32: 1743.85 | Q32: 1617.13 | T32: 1003.03 | U32: 1003.03 | V32: 1071.82 | W32: 1184.44
A33: 1 | C33: 이연법인세부채 | E33: 18730.14 | F33: 18730.14 | G33: 19315.92 | H33: 19107.62 | I33: 38750.86 | J33: 36177.81 | K33: 36177.81 | L33: 36618.6 | M33: 34566.21 | N33: 31806.04 | O33: 28450.91 | P33: 28450.91 | Q33: 28663.09 | R33: 27897.25 | S33: 26863.34 | T33: 28048.24 | U33: 28048.24 | V33: 28681.25 | W33: 27721.24 | X33: 28159.86 | Y33: 26252.87 | Z33: 26252.87 | AA33: 28691.21 | AB33: 31720.8
A34: 1 | C34: 장기충당부채 | E34: 1194.7 | F34: 1194.7 | G34: 1140.91 | H34: 1093.04 | I34: 1066.47 | J34: 1280.86 | K34: 1280.86 | L34: 1365.25 | M34: 1457.78 | N34: 1445.29 | O34: 1658.13 | P34: 1658.13 | Q34: 1752.04 | R34: 1821.61 | S34: 1846.1 | T34: 1837.54 | U34: 1837.54 | V34: 1776.03 | W34: 1789.66 | X34: 1753.93 | Y34: 1538.96 | Z34: 1538.96 | AA34: 1421.22 | AB34: 1409.59
A35: 1 | C35: 비유동리스부채 | E35: 8437.55 | F35: 8437.55 | G35: 8879.46 | H35: 11223.12 | I35: 11152.99 | J35: 10878.25 | K35: 10878.25 | L35: 10585.23 | M35: 10219.96 | N35: 9803.88 | O35: 9188.91 | P35: 9188.91 | Q35: 8780.97 | R35: 8132.73 | S35: 8334.92 | T35: 7915.13 | U35: 7915.13 | V35: 7686.78 | W35: 7012.49 | X35: 6827.51 | Y35: 6503.17 | Z35: 6503.17 | AA35: 6596.32 | AB35: 6748.43
A36: 1 | C36: 장기금융부채 | E36: 8437.55 | F36: 8437.55 | G36: 10548.94 | H36: 11223.12 | I36: 11152.99 | J36: 10878.25 | K36: 10878.25 | L36: 10585.23 | M36: 10219.96 | N36: 9803.88 | O36: 9188.91 | P36: 9188.91 | Q36: 8780.97 | R36: 8132.73 | S36: 8334.92 | T36: 7915.13 | U36: 7915.13 | V36: 7686.78 | W36: 7012.49 | X36: 6827.51 | Y36: 6503.17 | Z36: 6503.17 | AA36: 6596.32 | AB36: 6748.43
A37: 1 | C37: 부채총계 | E37: 481987.96 | F37: 481987.96 | G37: 500201.25 | H37: 543777.8 | I37: 664065.8 | J37: 646587.48 | K37: 646587.48 | L37: 660517.26 | M37: 679286.76 | N37: 665532.89 | O37: 652973.75 | P37: 652973.75 | Q37: 668275.99 | R37: 666926.64 | S37: 670491.94 | T37: 662560.9 | U37: 662560.9 | V37: 683282.25 | W37: 707911.17 | X37: 715045.1 | Y37: 689840.04 | Z37: 689840.04 | AA37: 731068.19 | AB37: 782766.29
A38: 1 | C38: 지배주주지분 | E38: 310567.99 | F38: 310567.99 | G38: 318287.19 | H38: 324686.41 | I38: 372143.2 | J38: 367103.96 | K38: 367103.96 | L38: 371032.61 | M38: 382410.85 | N38: 392089.67 | O38: 393555.16 | P38: 393555.16 | Q38: 388983.67 | R38: 396499.27 | S38: 397339.04 | T38: 396522.12 | U38: 396522.12 | V38: 389534.89 | W38: 379639.62 | X38: 374876.44 | Y38: 359968.05 | Z38: 359968.05 | AA38: 371954 | AB38: 376768.77
A39: 1 | C39: 자본금 | E39: 63101.14 | F39: 63101.14 | G39: 63101.14 | H39: 63101.14 | I39: 63101.14 | J39: 63101.14 | K39: 63101.14 | L39: 63101.14 | M39: 63101.14 | N39: 63101.14 | O39: 63101.14 | P39: 63101.14 | Q39: 63101.14 | R39: 63101.14 | S39: 63101.14 | T39: 93020.37 | U39: 93020.37 | V39: 93020.37 | W39: 93020.37 | X39: 93020.37 | Y39: 93020.37 | Z39: 93020.37 | AA39: 93020.37 | AB39: 93020.37
A40: 1 | C40: 자본잉여금 | E40: 1069.8 | F40: 1069.8 | G40: 1069.8 | H40: 1173.36 | I40: 7132.85 | J40: 7971.36 | K40: 7971.36 | L40: 7971.36 | M40: 7971.36 | N40: 1772.95 | O40: 1772.95 | P40: 1772.95 | Q40: -3518.65 | R40: 2158.03 | S40: 2158.03 | T40: 35339.94 | U40: 35339.94 | V40: 31031.25 | W40: 31030.83 | X40: 31024.43 | Y40: 43348.05 | Z40: 43348.05 | AA40: 42248.59 | AB40: 40978.84
...

Sheet BS별도
B1: (백만원) | C1: 이름: BS별도H | E1: 4Q21 | F1: 2021 | G1: 1Q22 | H1: 2Q22 | I1: 3Q22 | J1: 4Q22 | K1: 2022 | L1: 1Q23 | M1: 2Q23 | N1: 3Q23 | O1: 4Q23 | P1: 2023 | Q1: 1Q24 | R1: 2Q24 | S1: 3Q24 | T1: 4Q24 | U1: 2024 | V1: 1Q25 | W1: 2Q25 | X1: 3Q25 | Y1: 4Q25 | Z1: 2025 | AA1: 1Q26 | AB1: 2Q26 | AC1: 3Q26 | AD1: 4Q26 | AE1: 2026 | AF1: 1Q27 | AG1: 2Q27 | AH1: 3Q27 | AI1: 4Q27 | AJ1: 2027 | AK1: 1Q28 | AL1: 2Q28 | AM1: 3Q28 | AN1: 4Q28 | AO1: 2028
B2: 별도 | D2: fin json(kship_fin.py)
B3: 금강공업(별) | C3: UPDATE: 26-10-26 | E3: 1 | F3: 2 | G3: 3 | H3: 4 | I3: 5 | J3: 6 | K3: 7 | L3: 8 | M3: 9 | N3: 10 | O3: 11 | P3: 12 | Q3: 13 | R3: 14 | S3: 15 | T3: 16 | U3: 17 | V3: 18 | W3: 19 | X3: 20 | Y3: 21 | Z3: 22 | AA3: 23 | AB3: 24 | AC3: 25 | AD3: 26 | AE3: 27 | AF3: 28 | AG3: 29 | AH3: 30 | AI3: 31 | AJ3: 32 | AK3: 33 | AL3: 34 | AM3: 35 | AN3: 36 | AO3: 37
B4: Account Code | C4: AccountNAME | E4: 2021.12 | F4: 2021.12A | G4: 2022.03 | H4: 2022.06 | I4: 2022.09 | J4: 2022.12 | K4: 2022.12A | L4: 2023.03 | M4: 2023.06 | N4: 2023.09 | O4: 2023.12 | P4: 2023.12A | Q4: 2024.03 | R4: 2024.06 | S4: 2024.09 | T4: 2024.12 | U4: 2024.12A | V4: 2025.03 | W4: 2025.06 | X4: 2025.09 | Y4: 2025.12 | Z4: 2025.12A | AA4: 2026.03 | AB4: 2026.06 | AC4: 2026.09 | AD4: 2026.12 | AE4: 2026.12A | AF4: 2027.03 | AG4: 2027.06 | AH4: 2027.09 | AI4: 2027.12 | AJ4: 2027.12A | AK4: 2028.03 | AL4: 2028.06 | AM4: 2028.09 | AN4: 2028.12 | AO4: 2028.12A
A5: 1 | C5: 유동자산 | E5: 209804.88 | F5: 209804.88 | G5: 215678.53 | H5: 224761.49 | I5: 241616.91 | J5: 245761.04 | K5: 245761.04 | L5: 258121.09 | M5: 249644.28 | N5: 255305.18 | O5: 240073.91 | P5: 240073.91 | Q5: 235792.78 | R5: 234155.8 | S5: 219303.76 | T5: 212980.97 | U5: 212980.97 | V5: 227391.71 | W5: 257422.85 | X5: 242310.98 | Y5: 221265.79 | Z5: 221265.79 | AA5: 229562.6 | AB5: 229613.23
A6: 1 | C6: 현금및현금성자산 | E6: 56211.33 | F6: 56211.33 | G6: 63068.22 | H6: 62557.03 | I6: 56924.15 | J6: 55482.4 | K6: 55482.4 | L6: 64060.89 | M6: 65878.19 | N6: 67317.26 | O6: 65114.07 | P6: 65114.07 | Q6: 60951.95 | R6: 35699.06 | S6: 42500.15 | T6: 33620.07 | U6: 33620.07 | V6: 62478.35 | W6: 59097.04 | X6: 58387.56 | Y6: 40936.31 | Z6: 40936.31 | AA6: 50895.72 | AB6: 45502.92
A7: 1 | C7: 매출채권및기타채권 | E7: 71051.36 | F7: 71051.36 | G7: 79382.2 | H7: 69682.08 | I7: 84677.8 | J7: 74994.59 | K7: 74994.59 | L7: 82500.21 | M7: 84019.33 | N7: 82443.28 | O7: 73396.25 | P7: 73396.25 | Q7: 76068.99 | R7: 78023.41 | S7: 72561.45 | T7: 84044.5 | U7: 84044.5 | V7: 88622.19 | W7: 105606.95 | X7: 91253.55 | Y7: 85068.99 | Z7: 85068.99 | AA7: 95848.02 | AB7: 97010.21
A8: 1 | C8: 재고자산 | E8: 80588.22 | F8: 80588.22 | G8: 70907.32 | H8: 89762.15 | I8: 97390.51 | J8: 102324.65 | K8: 102324.65 | L8: 96626.5 | M8: 96980.85 | N8: 102160.01 | O8: 98639.76 | P8: 98639.76 | Q8: 91494.71 | R8: 92500.4 | S8: 80782.31 | T8: 72328.67 | U8: 72328.67 | V8: 74642.29 | W8: 72485.39 | X8: 71923.61 | Y8: 72945.22 | Z8: 72945.22 | AA8: 74058.06 | AB8: 79671.95
A9: 1 | C9: 기타유동자산 | E9: 1859.83 | F9: 1859.83 | G9: 2184.43 | H9: 2674.5 | I9: 2581.61 | J9: 2690.45 | K9: 2690.45 | L9: 4804.86 | M9: 2675.12 | N9: 3302.72 | O9: 2680.36 | P9: 2680.36 | Q9: 2168.45 | R9: 2845.12 | S9: 2728.3 | T9: 1780.97 | U9: 1780.97 | V9: 1479.11 | W9: 1728.94 | X9: 2668.58 | Y9: 4203.56 | Z9: 4203.56 | AA9: 8252.03 | AB9: 7239.77
A10: 1 | C10: 비유동자산 | E10: 375938.79 | F10: 375938.79 | G10: 389084.43 | H10: 391450.92 | I10: 400681.81 | J10: 405052.28 | K10: 405052.28 | L10: 415104.05 | M10: 423923.12 | N10: 425979.99 | O10: 427836.99 | P10: 427836.99 | Q10: 426795.35 | R10: 425554.37 | S10: 435035.78 | T10: 421179.7 | U10: 421179.7 | V10: 417168.43 | W10: 393786.91 | X10: 401727.3 | Y10: 403158.61 | Z10: 403158.61 | AA10: 407470.17 | AB10: 427437.85
A11: 1 | C11: 유형자산 | E11: 287539.8 | F11: 287539.8 | G11: 298478.59 | H11: 301386.04 | I11: 293651.66 | J11: 291985.25 | K11: 291985.25 | L11: 296473.66 | M11: 305655.06 | N11: 302494.24 | O11: 302714 | P11: 302714 | Q11: 301399.87 | R11: 301639.11 | S11: 274533.63 | T11: 270613.11 | U11: 270613.11 | V11: 262070.53 | W11: 257806.17 | X11: 263163.56 | Y11: 237870.35 | Z11: 237870.35 | AA11: 246856.51 | AB11: 266179.05
A12: 1 | C12: 무형자산 | E12: 6286.68 | F12: 6286.68 | G12: 6278.78 | H12: 6270.88 | I12: 6262.99 | J12: 6255.09 | K12: 6255.09 | L12: 6294.89 | M12: 5291.22 | N12: 5356.35 | O12: 5392.37 | P12: 5392.37 | Q12: 5207.31 | R12: 5259.44 | S12: 5252.74 | T12: 5238.88 | U12: 5238.88 | V12: 5225.02 | W12: 5211.16 | X12: 5176.94 | Y12: 5125.47 | Z12: 5125.47 | AA12: 5124.12 | AB12: 5109.8
A13: 1 | C13: 투자부동산 | E13: 4457.39 | F13: 4457.39 | G13: 5196.9 | H13: 5189.5 | I13: 5182.1 | J13: 5040.37 | K13: 5040.37 | L13: 8261.9 | M13: 8251.85 | N13: 8241.81 | O13: 8231.77 | P13: 8231.77 | Q13: 5005.86 | R13: 4998.96 | S13: 38883.16 | T13: 39841.93 | U13: 39841.93 | V13: 39821.77 | W13: 21995.46 | X13: 21877.13 | Y13: 22452.16 | Z13: 22452.16 | AA13: 22333.83 | AB13: 22215.49
A14: 1 | C14: 종속기업및관계기업투자 | E14: 49728.36 | F14: 49728.36 | G14: 49728.36 | H14: 49728.36 | I14: 59955.64 | J14: 64958.85 | K14: 64958.85 | L14: 64958.85 | M14: 64958.85 | N14: 79987.37 | O14: 79991.03 | P14: 79991.03 | Q14: 85694.32 | R14: 84699.47 | S14: 84699.47 | T14: 84699.47 | U14: 84699.47 | V14: 87978.14 | W14: 87978.14 | X14: 87978.14 | Y14: 97976.33 | Z14: 97976.33 | AA14: 98476.33 | AB14: 98476.33
A15: 1 | C15: 투자자산 | E15: 57841.34 | F15: 57841.34 | G15: 58566.77 | H15: 57365.29 | I15: 81950.28 | J15: 87327.19 | K15: 87327.19 | L15: 87607.65 | M15: 87747.11 | N15: 97531.61 | O15: 98980.51 | P15: 98980.51 | Q15: 104199.5 | R15: 103019.28 | S15: 103214.28 | T15: 92633.31 | U15: 92633.31 | V15: 96046.91 | W15: 96587.83 | X15: 98967.01 | Y15: 97976.33 | Z15: 97976.33 | AA15: 118213.02 | AB15: 117733.89
A16: 1 | C16: 장기금융자산 | E16: 8112.98 | F16: 8112.98 | G16: 8838.41 | H16: 7636.93 | I16: 21994.64 | J16: 22368.34 | K16: 22368.34 | L16: 22648.8 | M16: 22788.26 | N16: 17544.24 | O16: 18989.48 | P16: 18989.48 | Q16: 18505.18 | R16: 18319.81 | S16: 18514.81 | T16: 7933.84 | U16: 7933.84 | V16: 8068.77 | W16: 8609.69 | X16: 10988.87 | AA16: 19736.69 | AB16: 19257.56
A17: 1 | C17: 장기매출채권및기타채권 | E17: 18420.87 | F17: 18420.87 | J17: 12590.51 | K17: 12590.51 | N17: 11023.46 | O17: 9061.46 | P17: 9061.46 | Q17: 8896.46 | R17: 9111.46 | S17: 11571.68 | T17: 7930.14 | U17: 7930.14 | V17: 10933.92 | W17: 11160.92 | Y17: 12557.58 | Z17: 12557.58
A18: 1 | C18: 자산총계 | E18: 585743.67 | F18: 585743.67 | G18: 604762.97 | H18: 616212.41 | I18: 642298.72 | J18: 650813.32 | K18: 650813.32 | L18: 673225.14 | M18: 673567.4 | N18: 681285.17 | O18: 667910.9 | P18: 667910.9 | Q18: 662588.12 | R18: 659710.17 | S18: 654339.55 | T18: 634160.67 | U18: 634160.67 | V18: 644560.14 | W18: 651209.76 | X18: 644038.27 | Y18: 624424.39 | Z18: 624424.39 | AA18: 637032.77 | AB18: 657051.08
A19: 1 | C19: 유동부채 | E19: 251120.2 | F19: 251120.2 | G19: 250479.75 | H19: 273211.41 | I19: 256792.41 | J19: 272536.84 | K19: 272536.84 | L19: 288907.37 | M19: 280743.04 | N19: 278123.45 | O19: 270344.62 | P19: 270344.62 | Q19: 289148.2 | R19: 255963.78 | S19: 259920 | T19: 241410.79 | U19: 241410.79 | V19: 237169.31 | W19: 265352.67 | X19: 231448.49 | Y19: 225633.33 | Z19: 225633.33 | AA19: 228237.1 | AB19: 238542.16
A20: 1 | C20: 매입채무및기타채무 | E20: 45755.8 | F20: 45755.8 | G20: 46994.27 | H20: 43989.62 | I20: 42192.48 | J20: 48879.89 | K20: 48879.89 | L20: 48014.59 | M20: 51967.66 | N20: 43883.99 | O20: 49255.25 | P20: 49255.25 | Q20: 43473.81 | R20: 37727.75 | S20: 34473.1 | T20: 36936.36 | U20: 36936.36 | V20: 40598.54 | W20: 38631.93 | X20: 36595.06 | Y20: 35328.19 | Z20: 35328.19 | AA20: 40135.9 | AB20: 39054.88
A21: 1 | C21: 단기차입금 | E21: 186541.72 | F21: 186541.72 | G21: 183406.9 | H21: 209688.93 | I21: 195582.02 | J21: 201942.54 | K21: 201942.54 | L21: 219652.69 | M21: 202627.24 | N21: 201585.73 | O21: 197800.36 | P21: 197800.36 | Q21: 224297.37 | R21: 196802.4 | S21: 210373.39 | T21: 193318.2 | U21: 193318.2 | V21: 183555.52 | W21: 201257.65 | X21: 164524.23 | Y21: 166598.57 | Z21: 166598.57 | AA21: 166093.77 | AB21: 178567.68
A22: 1 | C22: 단기금융부채(face) | E22: 186541.72 | F22: 186541.72 | G22: 183406.9 | H22: 209688.93 | I22: 195582.02 | J22: 201942.54 | K22: 201942.54 | L22: 219652.69 | M22: 202627.24 | N22: 201585.73 | O22: 197800.36 | P22: 197800.36 | Q22: 224297.37 | R22: 196802.4 | S22: 210373.39 | T22: 193318.2 | U22: 193318.2 | V22: 183555.52 | W22: 201257.65 | X22: 164524.23 | Y22: 166598.57 | Z22: 166598.57 | AA22: 166093.77 | AB22: 178567.68
A23: 1 | C23: 기타유동부채 | E23: 14228.54 | F23: 14228.54 | G23: 13490.4 | H23: 13096.15 | I23: 11333.51 | J23: 12340.31 | K23: 12340.31 | L23: 14492.16 | M23: 21400.4 | N23: 26297.08 | O23: 19350.99 | P23: 19350.99 | Q23: 17136.23 | R23: 19508.88 | S23: 14056.02 | T23: 10250.68 | U23: 10250.68 | V23: 12080.39 | W23: 24246.83 | X23: 29308.22 | Y23: 22908.39 | Z23: 22908.39 | AA23: 21120.19 | AB23: 19826.69
A24: 1 | C24: 당기법인세부채(미지급법인세) | E24: 3605.79 | F24: 3605.79 | G24: 5456.55 | H24: 5295.69 | I24: 6509.69 | J24: 8317.87 | K24: 8317.87 | L24: 5565.28 | M24: 3630.1 | N24: 5240.05 | O24: 2866.99 | P24: 2866.99 | Q24: 3029.23 | R24: 775.16 | T24: 0 | U24: 0 | Y24: 0 | Z24: 0
A25: 1 | C25: 유동리스부채 | E25: 988.35 | F25: 988.35 | G25: 1131.63 | H25: 1141.03 | I25: 1174.71 | J25: 1056.23 | K25: 1056.23 | L25: 1182.66 | M25: 1117.63 | N25: 1116.6 | O25: 1071.03 | P25: 1071.03 | Q25: 1211.56 | R25: 1149.59 | S25: 1017.49 | T25: 905.54 | U25: 905.54 | V25: 934.85 | W25: 1216.26 | X25: 1020.99 | Y25: 798.17 | Z25: 798.17 | AA25: 887.24 | AB25: 1092.91
A26: 1 | C26: 리스부채 | E26: 6639.93 | F26: 6639.93 | G26: 7421.46 | H26: 8726.64 | I26: 8835.65 | J26: 8560.65 | K26: 8560.65 | L26: 8548.42 | M26: 8241.09 | N26: 8252.53 | O26: 7959 | P26: 7959 | Q26: 7810.63 | R26: 6762.82 | S26: 6483.86 | T26: 6244.93 | U26: 6244.93 | V26: 6098.61 | W26: 6077.98 | X26: 5739.46 | Y26: 5389.7 | Z26: 5389.7 | AA26: 5353.17 | AB26: 5441.83
A27: 1 | C27: 단기금융부채 | E27: 988.35 | F27: 988.35 | G27: 1131.63 | H27: 1141.03 | I27: 1174.71 | J27: 1056.23 | K27: 1056.23 | L27: 1182.66 | M27: 1117.63 | N27: 1116.6 | O27: 1071.03 | P27: 1071.03 | Q27: 1211.56 | R27: 1149.59 | S27: 1017.49 | T27: 905.54 | U27: 905.54 | V27: 934.85 | W27: 1216.26 | X27: 1020.99 | Y27: 798.17 | Z27: 798.17 | AA27: 887.24 | AB27: 1092.91
A28: 1 | C28: 비유동부채 | E28: 52668.28 | F28: 52668.28 | G28: 63079.03 | H28: 44536.3 | I28: 75143.5 | J28: 71627.11 | K28: 71627.11 | L28: 75112.85 | M28: 74744.61 | N28: 74470.47 | O28: 73357.35 | P28: 73357.35 | Q28: 50693.98 | R28: 79440.13 | S28: 78921.66 | T28: 80086.42 | U28: 80086.42 | V28: 99313.64 | W28: 88416.49 | X28: 122692.89 | Y28: 120262.57 | Z28: 120262.57 | AA28: 122082.92 | AB28: 131905.04
A29: 1 | C29: 장기차입금 | E29: 42842.13 | F29: 42842.13 | G29: 52879.93 | H29: 32854.42 | I29: 62827.74 | J29: 59952.73 | K29: 59952.73 | L29: 63902.86 | M29: 62960.6 | N29: 63915.87 | O29: 62970.37 | P29: 62970.37 | Q29: 39988.45 | R29: 69951.06 | S29: 69964.09 | T29: 69967.26 | U29: 69967.26 | V29: 89930.32 | W29: 79936.69 | X29: 113943.2 | Y29: 113949.77 | Z29: 113949.77 | AA29: 113956.26 | AB29: 122975.88
A30: 1 | C30: 장기금융부채(face) | E30: 877.63 | F30: 877.63 | G30: 953.64 | H30: 901.43 | I30: 868.26 | L30: 948.26 | N30: 949.26
A31: 1 | C31: 이연법인세부채 | E31: 3037.01 | F31: 3037.01 | G31: 2828.8 | H31: 3065.13 | I31: 3654.28 | J31: 2126.99 | K31: 2126.99 | L31: 2595.5 | M31: 2340.99 | N31: 2110.44 | O31: 1046.56 | P31: 1046.56 | Q31: 1544.24 | R31: 1278.97 | S31: 1352.07 | T31: 2692.49 | U31: 2692.49 | V31: 2100.8 | W31: 1520.69 | X31: 1996.33 | AA31: 1995.07 | AB31: 2976.09
A32: 1 | C32: 장기충당부채 | E32: 1137.56 | F32: 1137.56 | G32: 1080.48 | H32: 1031.15 | I32: 1000.55 | J32: 1174.71 | K32: 1174.71 | L32: 1248.72 | M32: 1330.03 | N32: 1308.23 | O32: 1494.19 | P32: 1494.19 | Q32: 1578.3 | R32: 1635.6 | S32: 1655.25 | T32: 1562.97 | U32: 1562.97 | V32: 1570.39 | W32: 1585.33 | X32: 1547.83 | Y32: 1278.33 | Z32: 1278.33 | AA32: 1222.71 | AB32: 1203.41
A33: 1 | C33: 비유동리스부채 | E33: 5651.58 | F33: 5651.58 | G33: 6289.83 | H33: 7585.61 | I33: 7660.94 | J33: 7504.42 | K33: 7504.42 | L33: 7365.76 | M33: 7123.46 | N33: 7135.93 | O33: 6887.97 | P33: 6887.97 | Q33: 6599.07 | R33: 5613.23 | S33: 5466.37 | T33: 5339.39 | U33: 5339.39 | V33: 5163.76 | W33: 4861.72 | X33: 4718.47 | Y33: 4591.53 | Z33: 4591.53 | AA33: 4465.93 | AB33: 4348.92
A34: 1 | C34: 장기금융부채 | E34: 5651.58 | F34: 5651.58 | G34: 6289.83 | H34: 7585.61 | I34: 7660.94 | J34: 7504.42 | K34: 7504.42 | L34: 7365.76 | M34: 7123.46 | N34: 7135.93 | O34: 6887.97 | P34: 6887.97 | Q34: 6599.07 | R34: 5613.23 | S34: 5466.37 | T34: 5339.39 | U34: 5339.39 | V34: 5163.76 | W34: 4861.72 | X34: 4718.47 | Y34: 4591.53 | Z34: 4591.53 | AA34: 4465.93 | AB34: 4348.92
A35: 1 | C35: 부채총계 | E35: 303788.48 | F35: 303788.48 | G35: 313558.78 | H35: 317747.71 | I35: 331935.91 | J35: 344163.96 | K35: 344163.96 | L35: 364020.22 | M35: 355487.65 | N35: 352593.92 | O35: 343701.96 | P35: 343701.96 | Q35: 339842.18 | R35: 335403.91 | S35: 338841.66 | T35: 321497.21 | U35: 321497.21 | V35: 336482.95 | W35: 353769.17 | X35: 354141.37 | Y35: 345895.89 | Z35: 345895.89 | AA35: 350320.01 | AB35: 370447.2
A36: 1 | C36: 자본금 | E36: 93020.37 | F36: 93020.37 | G36: 93020.37 | H36: 93020.37 | I36: 93020.37 | J36: 93020.37 | K36: 93020.37 | L36: 93020.37 | M36: 93020.37 | N36: 93020.37 | O36: 93020.37 | P36: 93020.37 | Q36: 93020.37 | R36: 93020.37 | S36: 93020.37 | T36: 93020.37 | U36: 93020.37 | V36: 93020.37 | W36: 93020.37 | X36: 93020.37 | Y36: 93020.37 | Z36: 93020.37 | AA36: 93020.37 | AB36: 93020.37
A37: 1 | C37: 자본잉여금 | E37: 49143.43 | F37: 49143.43 | G37: 49143.43 | H37: 49143.43 | I37: 49143.43 | J37: 49143.43 | K37: 49143.43 | L37: 49143.43 | M37: 49143.43 | N37: 49143.43 | O37: 49143.43 | P37: 49143.43 | Q37: 49143.43 | R37: 49143.43 | S37: 49143.43 | T37: 49143.43 | U37: 49143.43 | V37: 49143.43 | W37: 49143.43 | X37: 49143.43 | Y37: 59499.36 | Z37: 59499.36 | AA37: 59499.36 | AB37: 59499.36
A38: 1 | C38: 기타자본 | E38: 246.37 | F38: 246.37 | G38: 795.37 | H38: 57.9 | I38: -94.38 | J38: 163.38 | K38: 163.38 | L38: 332.33 | M38: 390.46 | N38: 767.29 | O38: 846.62 | P38: 846.62 | Q38: 344.84 | R38: 132.31 | S38: -31.92 | T38: -526.34 | U38: -526.34 | V38: -471.5 | W38: -164.58 | X38: -180.87 | Y38: 243.01 | Z38: 243.01 | AA38: -1050.22 | AB38: -3166.14
A39: 1 | C39: 이익잉여금 | E39: 202646.16 | F39: 202646.16 | G39: 211346.15 | H39: 219344.14 | I39: 231394.54 | J39: 227423.32 | K39: 227423.32 | L39: 229809.92 | M39: 238626.62 | N39: 248861.3 | O39: 244299.66 | P39: 244299.66 | Q39: 243338.44 | R39: 245111.29 | S39: 236467.14 | T39: 234127.14 | U39: 234127.14 | V39: 229486.02 | W39: 218542.51 | X39: 211015.11 | Y39: 188866.9 | Z39: 188866.9 | AA39: 198344.38 | AB39: 200351.43
A40: 1 | C40: 자본총계 | E40: 281955.19 | F40: 281955.19 | G40: 291204.18 | H40: 298464.7 | I40: 310362.82 | J40: 306649.36 | K40: 306649.36 | L40: 309204.92 | M40: 318079.75 | N40: 328691.25 | O40: 324208.94 | P40: 324208.94 | Q40: 322745.94 | R40: 324306.26 | S40: 315497.89 | T40: 312663.46 | U40: 312663.46 | V40: 308077.19 | W40: 297440.59 | X40: 289896.9 | Y40: 278528.5 | Z40: 278528.5 | AA40: 286712.75 | AB40: 286603.88
...

Sheet subQ
A1: YQ | C1: subQ 분기 서브모델(억원, U=100) | E1: 4Q21 | F1: 2021 | G1: 1Q22 | H1: 2Q22 | I1: 3Q22 | J1: 4Q22 | K1: 2022 | L1: 1Q23 | M1: 2Q23 | N1: 3Q23 | O1: 4Q23 | P1: 2023 | Q1: 1Q24 | R1: 2Q24 | S1: 3Q24 | T1: 4Q24 | U1: 2024 | V1: 1Q25 | W1: 2Q25 | X1: 3Q25 | Y1: 4Q25 | Z1: 2025 | AA1: 1Q26 | AB1: 2Q26 | AC1: 3Q26 | AD1: 4Q26 | AE1: 2026 | AF1: 1Q27 | AG1: 2Q27 | AH1: 3Q27 | AI1: 4Q27 | AJ1: 2027 | AK1: 1Q28 | AL1: 2Q28 | AM1: 3Q28 | AN1: 4Q28 | AO1: 2028
A2: A=이름(key) B=그룹 C=단위 D=FnGuide 계정명(VLOOKUP 키). 확정=VLOOKUP(BS), 추정=변수 가정 참조
E3: 1 | F3: 2 | G3: 3 | H3: 4 | I3: 5 | J3: 6 | K3: 7 | L3: 8 | M3: 9 | N3: 10 | O3: 11 | P3: 12 | Q3: 13 | R3: 14 | S3: 15 | T3: 16 | U3: 17 | V3: 18 | W3: 19 | X3: 20 | Y3: 21 | Z3: 22 | AA3: 23 | AB3: 24 | AC3: 25 | AD3: 26 | AE3: 27 | AF3: 28 | AG3: 29 | AH3: 30 | AI3: 31 | AJ3: 32 | AK3: 33 | AL3: 34 | AM3: 35 | AN3: 36 | AO3: 37
E4: 2021.12 | F4: 2021.12A | G4: 2022.03 | H4: 2022.06 | I4: 2022.09 | J4: 2022.12 | K4: 2022.12A | L4: 2023.03 | M4: 2023.06 | N4: 2023.09 | O4: 2023.12 | P4: 2023.12A | Q4: 2024.03 | R4: 2024.06 | S4: 2024.09 | T4: 2024.12 | U4: 2024.12A | V4: 2025.03 | W4: 2025.06 | X4: 2025.09 | Y4: 2025.12 | Z4: 2025.12A | AA4: 2026.03 | AB4: 2026.06 | AC4: 2026.09 | AD4: 2026.12 | AE4: 2026.12A | AF4: 2027.03 | AG4: 2027.06 | AH4: 2027.09 | AI4: 2027.12 | AJ4: 2027.12A | AK4: 2028.03 | AL4: 2028.06 | AM4: 2028.09 | AN4: 2028.12 | AO4: 2028.12A
A5: 매출액 | B5: 손익 | C5: 억원 | D5: 매출액(수익) | E5: =IFERROR(VLOOKUP($D5,BS연결,MATCH(E$1,BS연결H,0),0)/100,"") | G5: =IFERROR(VLOOKUP($D5,BS연결,MATCH(G$1,BS연결H,0),0)/100,"") | H5: =IFERROR(VLOOKUP($D5,BS연결,MATCH(H$1,BS연결H,0),0)/100,"") | I5: =IFERROR(VLOOKUP($D5,BS연결,MATCH(I$1,BS연결H,0),0)/100,"") | J5: =IFERROR(VLOOKUP($D5,BS연결,MATCH(J$1,BS연결H,0),0)/100,"") | K5: =IFERROR(VLOOKUP($D5,BS연결,MATCH(K$1,BS연결H,0),0)/100,"") | L5: =IFERROR(VLOOKUP($D5,BS연결,MATCH(L$1,BS연결H,0),0)/100,"") | M5: =IFERROR(VLOOKUP($D5,BS연결,MATCH(M$1,BS연결H,0),0)/100,"") | N5: =IFERROR(VLOOKUP($D5,BS연결,MATCH(N$1,BS연결H,0),0)/100,"") | ... AB5: =IFERROR(VLOOKUP($D5,BS연결,MATCH(AB$1,BS연결H,0),0)/100,"") | AC5: =IFERROR(X5*(1+변수!AC21),"") | AD5: =IFERROR(Y5*(1+변수!AD21),"") | AE5: =SUM(AA5:AD5) | AF5: =IFERROR(AA5*(1+변수!AF21),"") | AG5: =IFERROR(AB5*(1+변수!AG21),"") | AH5: =IFERROR(AC5*(1+변수!AH21),"") | AI5: =IFERROR(AD5*(1+변수!AI21),"") | AJ5: =SUM(AF5:AI5) | AK5: =IFERROR(AF5*(1+변수!AK21),"") | AL5: =IFERROR(AG5*(1+변수!AL21),"") | AM5: =IFERROR(AH5*(1+변수!AM21),"") | AN5: =IFERROR(AI5*(1+변수!AN21),"") | AO5: =SUM(AK5:AN5)
A6: 매출원가 | B6: 손익 | C6: 억원 | D6: 매출원가 | E6: =IFERROR(VLOOKUP($D6,BS연결,MATCH(E$1,BS연결H,0),0)/100,"") | G6: =IFERROR(VLOOKUP($D6,BS연결,MATCH(G$1,BS연결H,0),0)/100,"") | H6: =IFERROR(VLOOKUP($D6,BS연결,MATCH(H$1,BS연결H,0),0)/100,"") | I6: =IFERROR(VLOOKUP($D6,BS연결,MATCH(I$1,BS연결H,0),0)/100,"") | J6: =IFERROR(VLOOKUP($D6,BS연결,MATCH(J$1,BS연결H,0),0)/100,"") | K6: =IFERROR(VLOOKUP($D6,BS연결,MATCH(K$1,BS연결H,0),0)/100,"") | L6: =IFERROR(VLOOKUP($D6,BS연결,MATCH(L$1,BS연결H,0),0)/100,"") | M6: =IFERROR(VLOOKUP($D6,BS연결,MATCH(M$1,BS연결H,0),0)/100,"") | N6: =IFERROR(VLOOKUP($D6,BS연결,MATCH(N$1,BS연결H,0),0)/100,"") | ... AB6: =IFERROR(VLOOKUP($D6,BS연결,MATCH(AB$1,BS연결H,0),0)/100,"") | AC6: =IFERROR(AC5-AC7,"") | AD6: =IFERROR(AD5-AD7,"") | AE6: =SUM(AA6:AD6) | AF6: =IFERROR(AF5-AF7,"") | AG6: =IFERROR(AG5-AG7,"") | AH6: =IFERROR(AH5-AH7,"") | AI6: =IFERROR(AI5-AI7,"") | AJ6: =SUM(AF6:AI6) | AK6: =IFERROR(AK5-AK7,"") | AL6: =IFERROR(AL5-AL7,"") | AM6: =IFERROR(AM5-AM7,"") | AN6: =IFERROR(AN5-AN7,"") | AO6: =SUM(AK6:AN6)
A7: 매출총이익 | B7: 손익 | C7: 억원 | D7: 매출총이익 | E7: =IFERROR(VLOOKUP($D7,BS연결,MATCH(E$1,BS연결H,0),0)/100,"") | G7: =IFERROR(VLOOKUP($D7,BS연결,MATCH(G$1,BS연결H,0),0)/100,"") | H7: =IFERROR(VLOOKUP($D7,BS연결,MATCH(H$1,BS연결H,0),0)/100,"") | I7: =IFERROR(VLOOKUP($D7,BS연결,MATCH(I$1,BS연결H,0),0)/100,"") | J7: =IFERROR(VLOOKUP($D7,BS연결,MATCH(J$1,BS연결H,0),0)/100,"") | K7: =IFERROR(VLOOKUP($D7,BS연결,MATCH(K$1,BS연결H,0),0)/100,"") | L7: =IFERROR(VLOOKUP($D7,BS연결,MATCH(L$1,BS연결H,0),0)/100,"") | M7: =IFERROR(VLOOKUP($D7,BS연결,MATCH(M$1,BS연결H,0),0)/100,"") | N7: =IFERROR(VLOOKUP($D7,BS연결,MATCH(N$1,BS연결H,0),0)/100,"") | ... AB7: =IFERROR(VLOOKUP($D7,BS연결,MATCH(AB$1,BS연결H,0),0)/100,"") | AC7: =IFERROR(AC9+AC8,"") | AD7: =IFERROR(AD9+AD8,"") | AE7: =SUM(AA7:AD7) | AF7: =IFERROR(AF9+AF8,"") | AG7: =IFERROR(AG9+AG8,"") | AH7: =IFERROR(AH9+AH8,"") | AI7: =IFERROR(AI9+AI8,"") | AJ7: =SUM(AF7:AI7) | AK7: =IFERROR(AK9+AK8,"") | AL7: =IFERROR(AL9+AL8,"") | AM7: =IFERROR(AM9+AM8,"") | AN7: =IFERROR(AN9+AN8,"") | AO7: =SUM(AK7:AN7)
A8: 판관비 | B8: 손익 | C8: 억원 | D8: 판관비 | E8: =IFERROR(VLOOKUP($D8,BS연결,MATCH(E$1,BS연결H,0),0)/100,"") | G8: =IFERROR(VLOOKUP($D8,BS연결,MATCH(G$1,BS연결H,0),0)/100,"") | H8: =IFERROR(VLOOKUP($D8,BS연결,MATCH(H$1,BS연결H,0),0)/100,"") | I8: =IFERROR(VLOOKUP($D8,BS연결,MATCH(I$1,BS연결H,0),0)/100,"") | J8: =IFERROR(VLOOKUP($D8,BS연결,MATCH(J$1,BS연결H,0),0)/100,"") | K8: =IFERROR(VLOOKUP($D8,BS연결,MATCH(K$1,BS연결H,0),0)/100,"") | L8: =IFERROR(VLOOKUP($D8,BS연결,MATCH(L$1,BS연결H,0),0)/100,"") | M8: =IFERROR(VLOOKUP($D8,BS연결,MATCH(M$1,BS연결H,0),0)/100,"") | N8: =IFERROR(VLOOKUP($D8,BS연결,MATCH(N$1,BS연결H,0),0)/100,"") | ... AB8: =IFERROR(VLOOKUP($D8,BS연결,MATCH(AB$1,BS연결H,0),0)/100,"") | AC8: =IFERROR(AC5*변수!AC22,"") | AD8: =IFERROR(AD5*변수!AD22,"") | AE8: =SUM(AA8:AD8) | AF8: =IFERROR(AF5*변수!AF22,"") | AG8: =IFERROR(AG5*변수!AG22,"") | AH8: =IFERROR(AH5*변수!AH22,"") | AI8: =IFERROR(AI5*변수!AI22,"") | AJ8: =SUM(AF8:AI8) | AK8: =IFERROR(AK5*변수!AK22,"") | AL8: =IFERROR(AL5*변수!AL22,"") | AM8: =IFERROR(AM5*변수!AM22,"") | AN8: =IFERROR(AN5*변수!AN22,"") | AO8: =SUM(AK8:AN8)
