Workbook
Name 변수H: 변수!$C$1:$AO$1
Name 환율: 변수!$C$6:$AO$13
Name BS연결H: BS연결!$C$1:$AO$1
Name BS연결: BS연결!$C$5:$AO$113
Name BS별도H: BS별도!$C$1:$AO$1
Name BS별도: BS별도!$C$5:$AO$99
Name SUBQH: subQ!$A$1:$AO$1
Name subQ: subQ!$A$5:$AO$44

Sheet README
A1: 한국카본(017960) 실적 모델 — ARGUS 한국조선
A2: 기준 분기 2026Q2 · 마지막 실적 2026Q2 · 생성 2026-10-11
A3: 모든 수치는 모델 산출값(DART 공개 재무제표 + 우리 추정)이다 — 목표주가·투자 추천 아님. 참고용 · 투자조언 아님.
A5: 시트
A6: 변수 가정 시계열. 환율 8행(ECB via frankfurter — L2 fx.json; 추정 분기 = 노란 가정), 추정 드라이버(노란 셀 = 모델값에서 역산한 가정, 바꾸면 재계산; 연녹 셀 = 3절 스칼라 참조 수식), 3절 스칼라 가정(세율·판관비율·지배주주비중·이자율·종가·PER 밴드·COE·외화 순노출·헤지비율)
A7: BS연결/BS별도 FnGuide 계정명 × 기간 값 덤프(백만원). 행1 분기라벨, 행4 YYYY.MM / YYYY.12A. 이름정의 BS연결H·BS연결(계정명 C열부터)
A8: subQ 분기 서브모델(억원 = 백만원/100). 확정 행: =IFERROR(VLOOKUP($D행,BS연결,MATCH(E$1,BS연결H,0),0)/100,"") 추정 행: 변수 시트 가정 셀 참조 수식. 외환손익·파생상품손익은 BS 계정 합·차, 기타금융손익은 잔차, OPM·EPS·BPS·PER·PBR 은 파생 수식
A9: SLS 선표(조선사만, sls json 있을 때): 요약 행(sls 저장값) + 계약별 스케줄(백만$) × (헤지비율 × 헤지환율 + (1−헤지비율) × 건조시점 환율[변수 원/달러(평균)]) → 원화 수식 블록 → 합계 행이 subQ 매출조선에 연결
A10: 시나리오 신규수주 보수/기준/낙관(forecast_panel 패널, 모델에 scenarios 가 있을 때만): 매출액·영업이익 = subQ 기준값 ± (시나리오 신규 − base 신규) × OPM. base 만 subQ 행에 포함, 나머지는 합산 안 함
A11: 분기/연간예상 subQ 를 이름(A열 key)으로 VLOOKUP 한 보고서 표(억원)
A12: TP PER 밴드 × 12M fwd EPS, PBR = ROE/COE × BPS — 모델 산출값 구간, 목표주가·추천 아님
A13: 외화 환율 QoQ, 외화 순노출 × Δ기말환율 → 환관련손익 추정
... A34: 백테스트: {"freeze": "2025Q2", "horizon": 4, "revenue_wape_pct": 11.1, "op_wape_pct": 63.7, "n": 4, "note": "단일 회사 4분기 — 통계 아님", "driver_at_freeze": "customer_yard_revenue_weighted", "selection_oos_at_freeze": {"freeze": "2024Q2", "n": 4, "wape_link": 27.5, "wape_trend": 34.3, "adopted": true, "decision": "adopted"}, "frozen_inputs": "fin(연결/별도)·고객 조선사 모델·지주 자회사 모델은 2025Q2 까지의 분기만; 선표는 체결일 ≤ 2025Q2 말일 계약(원장 최신 금액·코호트 등급, 환산 없음); 잔고는 yards_cache 2025Q2; 시세·환율 forward·prices·forecast_panel 신규수주 미사용. 고객 가중치(suppliers.json 언급 비중)와 합병 체인링크는 현재 지식; 고객 연동 채택은 동결 모델 안에서도 자기 la−4분기 OOS 규칙(selection_oos_at_freeze)", "detail": [{"q": "2025Q3", "rev_pred": 2265.3, "rev_act": 2211.32, "op_pred": 152.37, "op_act": 298.63}, {"q": "2025Q4", "rev_pred": 2533.53, "rev_act": 2318.43, "op_pred": 170.41, "op_act": 383.37}, {"q": "2026Q1", "rev_pred": 1831.63, "rev_act": 2118.22, "op_pred": 123.2, "op_act": 410.66}, {"q": "2026Q2", "rev_pred": 1982.74, "rev_act": 2433.78, "op_pred": 133.36, "op_act": 504.0}]}

Sheet 변수
C1: 이름: 변수H | E1: 4Q21 | F1: 2021 | G1: 1Q22 | H1: 2Q22 | I1: 3Q22 | J1: 4Q22 | K1: 2022 | L1: 1Q23 | M1: 2Q23 | N1: 3Q23 | O1: 4Q23 | P1: 2023 | Q1: 1Q24 | R1: 2Q24 | S1: 3Q24 | T1: 4Q24 | U1: 2024 | V1: 1Q25 | W1: 2Q25 | X1: 3Q25 | Y1: 4Q25 | Z1: 2025 | AA1: 1Q26 | AB1: 2Q26 | AC1: 3Q26 | AD1: 4Q26 | AE1: 2026 | AF1: 1Q27 | AG1: 2Q27 | AH1: 3Q27 | AI1: 4Q27 | AJ1: 2027 | AK1: 1Q28 | AL1: 2Q28 | AM1: 3Q28 | AN1: 4Q28 | AO1: 2028
A2: 가정 시계열 — 노란 셀은 추정 가정(모델값에서 역산), 연녹 셀은 3절 스칼라 참조 수식. 바꾸면 subQ·분기·연간예상·TP·시나리오가 재계산됩니다.
E3: 1 | F3: 2 | G3: 3 | H3: 4 | I3: 5 | J3: 6 | K3: 7 | L3: 8 | M3: 9 | N3: 10 | O3: 11 | P3: 12 | Q3: 13 | R3: 14 | S3: 15 | T3: 16 | U3: 17 | V3: 18 | W3: 19 | X3: 20 | Y3: 21 | Z3: 22 | AA3: 23 | AB3: 24 | AC3: 25 | AD3: 26 | AE3: 27 | AF3: 28 | AG3: 29 | AH3: 30 | AI3: 31 | AJ3: 32 | AK3: 33 | AL3: 34 | AM3: 35 | AN3: 36 | AO3: 37
E4: 2021.12 | F4: 2021.12A | G4: 2022.03 | H4: 2022.06 | I4: 2022.09 | J4: 2022.12 | K4: 2022.12A | L4: 2023.03 | M4: 2023.06 | N4: 2023.09 | O4: 2023.12 | P4: 2023.12A | Q4: 2024.03 | R4: 2024.06 | S4: 2024.09 | T4: 2024.12 | U4: 2024.12A | V4: 2025.03 | W4: 2025.06 | X4: 2025.09 | Y4: 2025.12 | Z4: 2025.12A | AA4: 2026.03 | AB4: 2026.06 | AC4: 2026.09 | AD4: 2026.12 | AE4: 2026.12A | AF4: 2027.03 | AG4: 2027.06 | AH4: 2027.09 | AI4: 2027.12 | AJ4: 2027.12A | AK4: 2028.03 | AL4: 2028.06 | AM4: 2028.09 | AN4: 2028.12 | AO4: 2028.12A
B5: 1. FX | C5: 이름: 환율
A6: USDKRW_avg | C6: 원/달러(평균) | E6: 1183.5 | F6: 1145.51 | G6: 1205.78 | H6: 1262.09 | I6: 1341.93 | J6: 1360.12 | K6: 1292.98 | L6: 1276.95 | M6: 1315.69 | N6: 1313.62 | O6: 1322.01 | P6: 1306.85 | Q6: 1330.14 | R6: 1371.28 | S6: 1356.22 | T6: 1396.3 | U6: 1363.53 | V6: 1452.28 | W6: 1398.52 | X6: 1386.95 | Y6: 1449.19 | Z6: 1421.52 | AA6: 1466.12 | AB6: 1501.75 | AC6: 1418.75 | AD6: 1345.14 | AE6: 1457.21 | AF6: 1341.49 | AG6: 1341.49 | AH6: 1341.49 | AI6: 1341.49 | AK6: 1341.49 | AL6: 1341.49 | AM6: 1341.49 | AN6: 1341.49
A7: USDKRW_end | C7: 원/달러(기말) | E7: 1188.75 | F7: 1188.75 | G7: 1213.74 | H7: 1301.24 | I7: 1436.9 | J7: 1260.16 | K7: 1260.16 | L7: 1305.99 | M7: 1321.44 | N7: 1345.35 | O7: 1297.43 | P7: 1297.43 | Q7: 1349.25 | R7: 1377.73 | S7: 1312.17 | T7: 1474.78 | U7: 1474.78 | V7: 1474.54 | W7: 1355.13 | X7: 1403.67 | Y7: 1444.2 | Z7: 1444.2 | AA7: 1524.8 | AB7: 1550.89 | AC7: 1355.4 | AD7: 1341.49 | AE7: 1341.49 | AF7: 1341.49 | AG7: 1341.49 | AH7: 1341.49 | AI7: 1341.49 | AK7: 1341.49 | AL7: 1341.49 | AM7: 1341.49 | AN7: 1341.49
A8: JPY100KRW_avg | C8: 원/100Y(평균) | E8: 1041.02 | F8: 1042.74 | G8: 1036.79 | H8: 972.23 | I8: 970.61 | J8: 961.03 | K8: 985.1 | L8: 964.89 | M8: 957.36 | N8: 909 | O8: 893.22 | P8: 931.11 | Q8: 896.29 | R8: 880.14 | S8: 909.35 | T8: 917.25 | U8: 900.92 | V8: 952.59 | W8: 967.92 | X8: 940.32 | Y8: 940.77 | Z8: 950.17 | AA8: 934.39 | AB8: 942.16 | AC8: 890.41 | AD8: 850.79 | AE8: 919.21 | AF8: 847.7 | AG8: 847.7 | AH8: 847.7 | AI8: 847.7 | AK8: 847.7 | AL8: 847.7 | AM8: 847.7 | AN8: 847.7
A9: JPY100KRW_end | C9: 원/100Y(기말) | E9: 1032.62 | F9: 1032.62 | G9: 996.83 | H9: 954.9 | I9: 993.29 | J9: 955.54 | K9: 955.54 | L9: 980.62 | M9: 913.67 | N9: 901.47 | O9: 917.04 | P9: 917.04 | Q9: 892.42 | R9: 857.76 | S9: 919.21 | T9: 939.65 | U9: 939.65 | V9: 986.84 | W9: 938.85 | X9: 948.49 | Y9: 921.81 | Z9: 921.81 | AA9: 955.99 | AB9: 954.75 | AC9: 863.31 | AD9: 847.7 | AE9: 847.7 | AF9: 847.7 | AG9: 847.7 | AH9: 847.7 | AI9: 847.7 | AK9: 847.7 | AL9: 847.7 | AM9: 847.7 | AN9: 847.7
A10: EURKRW_avg | C10: W/Euro(평균) | E10: 1353.32 | F10: 1354.06 | G10: 1352.29 | H10: 1343.31 | I10: 1350.63 | J10: 1386.07 | K10: 1358.07 | L10: 1369.93 | M10: 1432.41 | N10: 1429.41 | O10: 1420.91 | P10: 1412.88 | Q10: 1444.21 | R10: 1476.42 | S10: 1489.3 | T10: 1490.78 | U10: 1475.4 | V10: 1528.33 | W10: 1585.13 | X10: 1620.04 | Y10: 1686.02 | Z10: 1605.45 | AA10: 1715.47 | AB10: 1746.09 | AC10: 1631.97 | AD10: 1509.74 | AE10: 1689.95 | AF10: 1503.27 | AG10: 1503.27 | AH10: 1503.27 | AI10: 1503.27 | AK10: 1503.27 | AL10: 1503.27 | AM10: 1503.27 | AN10: 1503.27
A11: EURKRW_end | C11: W/Euro(기말) | E11: 1346.38 | F11: 1346.38 | G11: 1347.37 | H11: 1351.6 | I11: 1400.62 | J11: 1344.08 | K11: 1344.08 | L11: 1420.26 | M11: 1435.88 | N11: 1425.26 | O11: 1433.66 | P11: 1433.66 | Q11: 1458.68 | R11: 1474.86 | S11: 1469.1 | T11: 1532.14 | U11: 1532.14 | V11: 1594.72 | W11: 1588.22 | X11: 1648.04 | Y11: 1696.94 | Z11: 1696.94 | AA11: 1753.21 | AB11: 1767.09 | AC11: 1539.06 | AD11: 1503.27 | AE11: 1503.27 | AF11: 1503.27 | AG11: 1503.27 | AH11: 1503.27 | AI11: 1503.27 | AK11: 1503.27 | AL11: 1503.27 | AM11: 1503.27 | AN11: 1503.27
A12: CNYKRW_avg | C12: 원/중국원(평균) | E12: 185.14 | F12: 177.65 | G12: 189.93 | H12: 190.76 | I12: 195.79 | J12: 191.09 | K12: 191.93 | L12: 186.59 | M12: 187.45 | N12: 181.28 | O12: 182.86 | P12: 184.52 | Q12: 185.04 | R12: 189.35 | S12: 189.24 | T12: 194.24 | U12: 189.49 | V12: 199.63 | W12: 193.41 | X12: 193.79 | Y12: 204.38 | Z12: 197.8 | AA12: 211.75 | AB12: 220.8 | AC12: 210.43 | AD12: 200.69 | AE12: 213.75 | AF12: 200.46 | AG12: 200.46 | AH12: 200.46 | AI12: 200.46 | AK12: 200.46 | AL12: 200.46 | AM12: 200.46 | AN12: 200.46
A13: CNYKRW_end | C13: 원/중국원(기말) | E13: 187.13 | F13: 187.13 | G13: 191.38 | H13: 194.13 | I13: 201.92 | J13: 182.67 | K13: 182.67 | L13: 189.97 | M13: 181.8 | N13: 184.26 | O13: 182.61 | P13: 182.61 | Q13: 186.66 | R13: 189.7 | S13: 187.12 | T13: 202.04 | U13: 202.04 | V13: 203.3 | W13: 189.14 | X13: 197.16 | Y13: 206.28 | Z13: 206.28 | AA13: 220.97 | AB13: 228.56 | AC13: 202.16 | AD13: 200.46 | AE13: 200.46 | AF13: 200.46 | AG13: 200.46 | AH13: 200.46 | AI13: 200.46 | AK13: 200.46 | AL13: 200.46 | AM13: 200.46 | AN13: 200.46
B14: 1b. 종가
A15: price_close_end | C15: 종가(기말) | E15: 10750 | G15: 11750 | H15: 14600 | I15: 11900 | J15: 11050 | L15: 12280 | M15: 11650 | N15: 12550 | O15: 11640 | Q15: 10730 | R15: 10730 | S15: 10810 | T15: 11750 | V15: 13540 | W15: 26000 | X15: 32700 | Y15: 29850 | AA15: 38850 | AB15: 26700 | AC15: 20100 | AD15: 19260
A16: price_high | C16: 종가(최고) | E16: 13500 | G16: 12900 | H16: 15350 | I16: 16200 | J16: 12800 | L16: 12380 | M16: 12980 | N16: 15240 | O16: 12840 | Q16: 11760 | R16: 11940 | S16: 13350 | T16: 11930 | V16: 16930 | W16: 26850 | X16: 35850 | Y16: 39300 | AA16: 50800 | AB16: 54100 | AC16: 27950 | AD16: 21100
A17: price_low | C17: 종가(최저) | E17: 9100 | G17: 9950 | H17: 10750 | I17: 11450 | J17: 10450 | L17: 10300 | M17: 10820 | N17: 11540 | O17: 11000 | Q17: 9870 | R17: 10050 | S17: 10230 | T17: 9400 | V17: 11600 | W17: 13870 | X17: 22200 | Y17: 25800 | AA17: 27450 | AB17: 25050 | AC17: 18530 | AD17: 19150
A18: price_avg | C18: 종가(평균) | E18: 11223.7 | G18: 11368.1 | H18: 13100.8 | I18: 13811.9 | J18: 11543.5 | L18: 11282.3 | M18: 11674.8 | N18: 13436.3 | O18: 11875.5 | Q18: 10720 | R18: 10857 | S18: 11507.3 | T18: 10811.5 | V18: 14238.3 | W18: 20896.3 | X18: 29762.3 | Y18: 32022 | AA18: 38489 | AB18: 39775.4 | AC18: 22833.4 | AD18: 20212
B20: 2. 추정 드라이버 | C20: 실적 열 = subQ 실현값(수식), 추정 열 = 가정(노란 = 모델값 역산, 연녹 = 3절 스칼라 참조)
A21: drv:매출액 | B21: yoy | C21: 매출액 YoY | J21: =IFERROR(subQ!J5/subQ!E5-1,"") | L21: =IFERROR(subQ!L5/subQ!G5-1,"") | M21: =IFERROR(subQ!M5/subQ!H5-1,"") | N21: =IFERROR(subQ!N5/subQ!I5-1,"") | O21: =IFERROR(subQ!O5/subQ!J5-1,"") | Q21: =IFERROR(subQ!Q5/subQ!L5-1,"") | R21: =IFERROR(subQ!R5/subQ!M5-1,"") | S21: =IFERROR(subQ!S5/subQ!N5-1,"") | T21: =IFERROR(subQ!T5/subQ!O5-1,"") | V21: =IFERROR(subQ!V5/subQ!Q5-1,"") | W21: =IFERROR(subQ!W5/subQ!R5-1,"") | X21: =IFERROR(subQ!X5/subQ!S5-1,"") | Y21: =IFERROR(subQ!Y5/subQ!T5-1,"") | AA21: =IFERROR(subQ!AA5/subQ!V5-1,"") | AB21: =IFERROR(subQ!AB5/subQ!W5-1,"") | AC21: 0.20311785 | AD21: 0.44822143 | AF21: 0.30638744 | AG21: 0.32217969 | AH21: 0.20329038 | AI21: 0.14746247 | AK21: 0.13146454 | AL21: 0.14057659 | AM21: 0.17888503 | AN21: 0.16527804
A22: drv:판관비 | B22: ratio | C22: 판관비율(/매출) | E22: =IFERROR(subQ!E8/subQ!E5,"") | F22: =IFERROR(subQ!F8/subQ!F5,"") | G22: =IFERROR(subQ!G8/subQ!G5,"") | H22: =IFERROR(subQ!H8/subQ!H5,"") | I22: =IFERROR(subQ!I8/subQ!I5,"") | J22: =IFERROR(subQ!J8/subQ!J5,"") | K22: =IFERROR(subQ!K8/subQ!K5,"") | L22: =IFERROR(subQ!L8/subQ!L5,"") | ... AB22: =IFERROR(subQ!AB8/subQ!AB5,"") | AC22: =$D$53 | AD22: =$D$53 | AE22: =IFERROR(subQ!AE8/subQ!AE5,"") | AF22: =$D$53 | AG22: =$D$53 | AH22: =$D$53 | AI22: =$D$53 | AJ22: =IFERROR(subQ!AJ8/subQ!AJ5,"") | AK22: =$D$53 | AL22: =$D$53 | AM22: =$D$53 | AN22: =$D$53 | AO22: =IFERROR(subQ!AO8/subQ!AO5,"")
A23: drv:영업이익 | B23: ratio | C23: 영업이익률(OPM) | E23: =IFERROR(subQ!E9/subQ!E5,"") | F23: =IFERROR(subQ!F9/subQ!F5,"") | G23: =IFERROR(subQ!G9/subQ!G5,"") | H23: =IFERROR(subQ!H9/subQ!H5,"") | I23: =IFERROR(subQ!I9/subQ!I5,"") | J23: =IFERROR(subQ!J9/subQ!J5,"") | K23: =IFERROR(subQ!K9/subQ!K5,"") | L23: =IFERROR(subQ!L9/subQ!L5,"") | ... AB23: =IFERROR(subQ!AB9/subQ!AB5,"") | AC23: 0.1376744 | AD23: 0.13767274 | AE23: =IFERROR(subQ!AE9/subQ!AE5,"") | AF23: 0.13767296 | AG23: 0.13767407 | AH23: 0.13767403 | AI23: 0.13767416 | AJ23: =IFERROR(subQ!AJ9/subQ!AJ5,"") | AK23: 0.13767486 | AL23: 0.13767455 | AM23: 0.13767356 | AN23: 0.13767488 | AO23: =IFERROR(subQ!AO9/subQ!AO5,"")
A24: drv:외환손익 | B24: abs | C24: 외환손익 (가정, 억원) | E24: =subQ!E13 | F24: =subQ!F13 | G24: =subQ!G13 | H24: =subQ!H13 | I24: =subQ!I13 | J24: =subQ!J13 | K24: =subQ!K13 | L24: =subQ!L13 | ... AB24: =subQ!AB13 | AC24: 0 | AD24: 0 | AE24: =subQ!AE13 | AF24: 0 | AG24: 0 | AH24: 0 | AI24: 0 | AJ24: =subQ!AJ13 | AK24: 0 | AL24: 0 | AM24: 0 | AN24: 0 | AO24: =subQ!AO13
A25: drv:파생상품손익 | B25: abs | C25: 파생상품손익 (가정, 억원) | E25: =subQ!E14 | F25: =subQ!F14 | G25: =subQ!G14 | H25: =subQ!H14 | I25: =subQ!I14 | J25: =subQ!J14 | K25: =subQ!K14 | L25: =subQ!L14 | ... AB25: =subQ!AB14 | AC25: 0 | AD25: 0 | AE25: =subQ!AE14 | AF25: 0 | AG25: 0 | AH25: 0 | AI25: 0 | AJ25: =subQ!AJ14 | AK25: 0 | AL25: 0 | AM25: 0 | AN25: 0 | AO25: =subQ!AO14
A26: drv:기타금융손익 | B26: abs | C26: 기타금융손익 (가정, 억원) | E26: =subQ!E15 | F26: =subQ!F15 | G26: =subQ!G15 | H26: =subQ!H15 | I26: =subQ!I15 | J26: =subQ!J15 | K26: =subQ!K15 | L26: =subQ!L15 | ... AB26: =subQ!AB15 | AC26: 0 | AD26: 0 | AE26: =subQ!AE15 | AF26: 0 | AG26: 0 | AH26: 0 | AI26: 0 | AJ26: =subQ!AJ15 | AK26: 0 | AL26: 0 | AM26: 0 | AN26: 0 | AO26: =subQ!AO15
A27: drv:기타영업외손익 | B27: abs | C27: 기타영업외손익 (가정, 억원) | E27: =subQ!E16 | F27: =subQ!F16 | G27: =subQ!G16 | H27: =subQ!H16 | I27: =subQ!I16 | J27: =subQ!J16 | K27: =subQ!K16 | L27: =subQ!L16 | ... AB27: =subQ!AB16 | AC27: 0 | AD27: 0 | AE27: =subQ!AE16 | AF27: 0 | AG27: 0 | AH27: 0 | AI27: 0 | AJ27: =subQ!AJ16 | AK27: 0 | AL27: 0 | AM27: 0 | AN27: 0 | AO27: =subQ!AO16
A28: drv:지분법손익 | B28: abs | C28: 지분법손익 (가정, 억원) | E28: =subQ!E17 | F28: =subQ!F17 | G28: =subQ!G17 | H28: =subQ!H17 | I28: =subQ!I17 | J28: =subQ!J17 | K28: =subQ!K17 | L28: =subQ!L17 | ... AB28: =subQ!AB17 | AC28: 0.13 | AD28: 0.13 | AE28: =subQ!AE17 | AF28: 0.13 | AG28: 0.13 | AH28: 0.13 | AI28: 0.13 | AJ28: =subQ!AJ17 | AK28: 0.13 | AL28: 0.13 | AM28: 0.13 | AN28: 0.13 | AO28: =subQ!AO17
A29: drv:법인세비용 | B29: tax | C29: 법인세율(/세전) — 법인세 = MAX(세전,0) × 세율 | E29: =IFERROR(subQ!E19/subQ!E18,"") | F29: =IFERROR(subQ!F19/subQ!F18,"") | G29: =IFERROR(subQ!G19/subQ!G18,"") | H29: =IFERROR(subQ!H19/subQ!H18,"") | I29: =IFERROR(subQ!I19/subQ!I18,"") | J29: =IFERROR(subQ!J19/subQ!J18,"") | K29: =IFERROR(subQ!K19/subQ!K18,"") | L29: =IFERROR(subQ!L19/subQ!L18,"") | ... AB29: =IFERROR(subQ!AB19/subQ!AB18,"") | AC29: =$D$52 | AD29: =$D$52 | AE29: =IFERROR(subQ!AE19/subQ!AE18,"") | AF29: =$D$52 | AG29: =$D$52 | AH29: =$D$52 | AI29: =$D$52 | AJ29: =IFERROR(subQ!AJ19/subQ!AJ18,"") | AK29: =$D$52 | AL29: =$D$52 | AM29: =$D$52 | AN29: =$D$52 | AO29: =IFERROR(subQ!AO19/subQ!AO18,"")
A30: drv:지배주주순이익 | B30: ratio | C30: 지배주주 비중(/당기순이익) | E30: =IFERROR(subQ!E21/subQ!E20,"") | F30: =IFERROR(subQ!F21/subQ!F20,"") | G30: =IFERROR(subQ!G21/subQ!G20,"") | H30: =IFERROR(subQ!H21/subQ!H20,"") | I30: =IFERROR(subQ!I21/subQ!I20,"") | J30: =IFERROR(subQ!J21/subQ!J20,"") | K30: =IFERROR(subQ!K21/subQ!K20,"") | L30: =IFERROR(subQ!L21/subQ!L20,"") | ... AB30: =IFERROR(subQ!AB21/subQ!AB20,"") | AC30: =$D$54 | AD30: =$D$54 | AE30: =IFERROR(subQ!AE21/subQ!AE20,"") | AF30: =$D$54 | AG30: =$D$54 | AH30: =$D$54 | AI30: =$D$54 | AJ30: =IFERROR(subQ!AJ21/subQ!AJ20,"") | AK30: =$D$54 | AL30: =$D$54 | AM30: =$D$54 | AN30: =$D$54 | AO30: =IFERROR(subQ!AO21/subQ!AO20,"")
A31: drv:중단사업이익 | B31: abs | C31: 중단사업이익 (가정, 억원) | E31: =subQ!E22 | F31: =subQ!F22 | G31: =subQ!G22 | H31: =subQ!H22 | I31: =subQ!I22 | J31: =subQ!J22 | K31: =subQ!K22 | L31: =subQ!L22 | ... AB31: =subQ!AB22 | AE31: =subQ!AE22 | AJ31: =subQ!AJ22 | AO31: =subQ!AO22
A32: drv:부채총계 | B32: qoq | C32: 부채총계 QoQ | G32: =IFERROR(subQ!G24/subQ!E24-1,"") | H32: =IFERROR(subQ!H24/subQ!G24-1,"") | I32: =IFERROR(subQ!I24/subQ!H24-1,"") | J32: =IFERROR(subQ!J24/subQ!I24-1,"") | L32: =IFERROR(subQ!L24/subQ!J24-1,"") | M32: =IFERROR(subQ!M24/subQ!L24-1,"") | N32: =IFERROR(subQ!N24/subQ!M24-1,"") | O32: =IFERROR(subQ!O24/subQ!N24-1,"") | Q32: =IFERROR(subQ!Q24/subQ!O24-1,"") | R32: =IFERROR(subQ!R24/subQ!Q24-1,"") | S32: =IFERROR(subQ!S24/subQ!R24-1,"") | T32: =IFERROR(subQ!T24/subQ!S24-1,"") | V32: =IFERROR(subQ!V24/subQ!T24-1,"") | W32: =IFERROR(subQ!W24/subQ!V24-1,"") | X32: =IFERROR(subQ!X24/subQ!W24-1,"") | Y32: =IFERROR(subQ!Y24/subQ!X24-1,"") | AA32: =IFERROR(subQ!AA24/subQ!Y24-1,"") | AB32: =IFERROR(subQ!AB24/subQ!AA24-1,"") | AC32: -1.29e-07 | AD32: 0 | AF32: 0 | AG32: 0 | AH32: 0 | AI32: 0 | AK32: 0 | AL32: 0 | AM32: 0 | AN32: 0
A33: drv:자본총계 | B33: roll | C33: 자본총계 기타변동(배당 등, 억원) | G33: =IFERROR(subQ!E25+subQ!G20-subQ!G25,"") | H33: =IFERROR(subQ!G25+subQ!H20-subQ!H25,"") | I33: =IFERROR(subQ!H25+subQ!I20-subQ!I25,"") | J33: =IFERROR(subQ!I25+subQ!J20-subQ!J25,"") | L33: =IFERROR(subQ!J25+subQ!L20-subQ!L25,"") | M33: =IFERROR(subQ!L25+subQ!M20-subQ!M25,"") | N33: =IFERROR(subQ!M25+subQ!N20-subQ!N25,"") | O33: =IFERROR(subQ!N25+subQ!O20-subQ!O25,"") | Q33: =IFERROR(subQ!O25+subQ!Q20-subQ!Q25,"") | R33: =IFERROR(subQ!Q25+subQ!R20-subQ!R25,"") | S33: =IFERROR(subQ!R25+subQ!S20-subQ!S25,"") | T33: =IFERROR(subQ!S25+subQ!T20-subQ!T25,"") | V33: =IFERROR(subQ!T25+subQ!V20-subQ!V25,"") | W33: =IFERROR(subQ!V25+subQ!W20-subQ!W25,"") | X33: =IFERROR(subQ!W25+subQ!X20-subQ!X25,"") | Y33: =IFERROR(subQ!X25+subQ!Y20-subQ!Y25,"") | AA33: =IFERROR(subQ!Y25+subQ!AA20-subQ!AA25,"") | AB33: =IFERROR(subQ!AA25+subQ!AB20-subQ!AB25,"") | AC33: -0.004330132 | AD33: 0.001043259 | AF33: -0.001711291 | AG33: 165.36151 | AH33: 0.004605395 | AI33: -0.006652731 | AK33: 0.002243721 | AL33: 165.36435 | AM33: 0.007007229 | AN33: -0.004456199
A34: drv:지배주주지분 | B34: roll | C34: 지배주주지분 기타변동(배당 등, 억원) | G34: =IFERROR(subQ!E26+subQ!G21-subQ!G26,"") | H34: =IFERROR(subQ!G26+subQ!H21-subQ!H26,"") | I34: =IFERROR(subQ!H26+subQ!I21-subQ!I26,"") | J34: =IFERROR(subQ!I26+subQ!J21-subQ!J26,"") | L34: =IFERROR(subQ!J26+subQ!L21-subQ!L26,"") | M34: =IFERROR(subQ!L26+subQ!M21-subQ!M26,"") | N34: =IFERROR(subQ!M26+subQ!N21-subQ!N26,"") | O34: =IFERROR(subQ!N26+subQ!O21-subQ!O26,"") | Q34: =IFERROR(subQ!O26+subQ!Q21-subQ!Q26,"") | R34: =IFERROR(subQ!Q26+subQ!R21-subQ!R26,"") | S34: =IFERROR(subQ!R26+subQ!S21-subQ!S26,"") | T34: =IFERROR(subQ!S26+subQ!T21-subQ!T26,"") | V34: =IFERROR(subQ!T26+subQ!V21-subQ!V26,"") | W34: =IFERROR(subQ!V26+subQ!W21-subQ!W26,"") | X34: =IFERROR(subQ!W26+subQ!X21-subQ!X26,"") | Y34: =IFERROR(subQ!X26+subQ!Y21-subQ!Y26,"") | AA34: =IFERROR(subQ!Y26+subQ!AA21-subQ!AA26,"") | AB34: =IFERROR(subQ!AA26+subQ!AB21-subQ!AB26,"") | AC34: -0.004330132 | AD34: 0.001043259 | AF34: -0.001711291 | AG34: 165.36151 | AH34: 0.004605395 | AI34: -0.006652731 | AK34: 0.002243721 | AL34: 165.36435 | AM34: 0.007007229 | AN34: -0.004456199
A35: drv:총차입금 | B35: qoq | C35: 총차입금 QoQ | G35: =IFERROR(subQ!G27/subQ!E27-1,"") | H35: =IFERROR(subQ!H27/subQ!G27-1,"") | I35: =IFERROR(subQ!I27/subQ!H27-1,"") | J35: =IFERROR(subQ!J27/subQ!I27-1,"") | L35: =IFERROR(subQ!L27/subQ!J27-1,"") | M35: =IFERROR(subQ!M27/subQ!L27-1,"") | N35: =IFERROR(subQ!N27/subQ!M27-1,"") | O35: =IFERROR(subQ!O27/subQ!N27-1,"") | Q35: =IFERROR(subQ!Q27/subQ!O27-1,"") | R35: =IFERROR(subQ!R27/subQ!Q27-1,"") | S35: =IFERROR(subQ!S27/subQ!R27-1,"") | T35: =IFERROR(subQ!T27/subQ!S27-1,"") | V35: =IFERROR(subQ!V27/subQ!T27-1,"") | W35: =IFERROR(subQ!W27/subQ!V27-1,"") | X35: =IFERROR(subQ!X27/subQ!W27-1,"") | Y35: =IFERROR(subQ!Y27/subQ!X27-1,"") | AA35: =IFERROR(subQ!AA27/subQ!Y27-1,"") | AB35: =IFERROR(subQ!AB27/subQ!AA27-1,"") | AC35: 7.1e-08 | AD35: 0 | AF35: 0 | AG35: 0 | AH35: 0 | AI35: 0 | AK35: 0 | AL35: 0 | AM35: 0 | AN35: 0
A36: drv:순차입금 | B36: qoq | C36: 순차입금 QoQ | G36: =IFERROR(subQ!G28/subQ!E28-1,"") | H36: =IFERROR(subQ!H28/subQ!G28-1,"") | I36: =IFERROR(subQ!I28/subQ!H28-1,"") | J36: =IFERROR(subQ!J28/subQ!I28-1,"") | L36: =IFERROR(subQ!L28/subQ!J28-1,"") | M36: =IFERROR(subQ!M28/subQ!L28-1,"") | N36: =IFERROR(subQ!N28/subQ!M28-1,"") | O36: =IFERROR(subQ!O28/subQ!N28-1,"") | Q36: =IFERROR(subQ!Q28/subQ!O28-1,"") | R36: =IFERROR(subQ!R28/subQ!Q28-1,"") | S36: =IFERROR(subQ!S28/subQ!R28-1,"") | T36: =IFERROR(subQ!T28/subQ!S28-1,"") | V36: =IFERROR(subQ!V28/subQ!T28-1,"") | W36: =IFERROR(subQ!W28/subQ!V28-1,"") | X36: =IFERROR(subQ!X28/subQ!W28-1,"") | Y36: =IFERROR(subQ!Y28/subQ!X28-1,"") | AA36: =IFERROR(subQ!AA28/subQ!Y28-1,"") | AB36: =IFERROR(subQ!AB28/subQ!AA28-1,"") | AC36: -17.576424 | AD36: 1.3500197 | AF36: 0.47364102 | AG36: 0.18801777 | AH36: 0.31539477 | AI36: 0.28999229 | AK36: 0.18327208 | AL36: 0.10343826 | AM36: 0.17015306 | AN36: 0.17344525
A37: drv:이자발생자산 | B37: qoq | C37: 이자발생자산 QoQ | G37: =IFERROR(subQ!G29/subQ!E29-1,"") | H37: =IFERROR(subQ!H29/subQ!G29-1,"") | I37: =IFERROR(subQ!I29/subQ!H29-1,"") | J37: =IFERROR(subQ!J29/subQ!I29-1,"") | L37: =IFERROR(subQ!L29/subQ!J29-1,"") | M37: =IFERROR(subQ!M29/subQ!L29-1,"") | N37: =IFERROR(subQ!N29/subQ!M29-1,"") | O37: =IFERROR(subQ!O29/subQ!N29-1,"") | Q37: =IFERROR(subQ!Q29/subQ!O29-1,"") | R37: =IFERROR(subQ!R29/subQ!Q29-1,"") | S37: =IFERROR(subQ!S29/subQ!R29-1,"") | T37: =IFERROR(subQ!T29/subQ!S29-1,"") | V37: =IFERROR(subQ!V29/subQ!T29-1,"") | W37: =IFERROR(subQ!W29/subQ!V29-1,"") | X37: =IFERROR(subQ!X29/subQ!W29-1,"") | Y37: =IFERROR(subQ!Y29/subQ!X29-1,"") | AA37: =IFERROR(subQ!AA29/subQ!Y29-1,"") | AB37: =IFERROR(subQ!AB29/subQ!AA29-1,"") | AC37: 0.16424919 | AD37: 0.17962278 | AF37: 0.12554487 | AG37: 0.065253485 | AH37: 0.12206463 | AI37: 0.13157495 | AK37: 0.094795311 | AL37: 0.057826037 | AM37: 0.099223783 | AN37: 0.10767007
A38: drv:현금및현금성자산 | B38: qoq | C38: 현금및현금성자산 QoQ | G38: =IFERROR(subQ!G30/subQ!E30-1,"") | H38: =IFERROR(subQ!H30/subQ!G30-1,"") | I38: =IFERROR(subQ!I30/subQ!H30-1,"") | J38: =IFERROR(subQ!J30/subQ!I30-1,"") | L38: =IFERROR(subQ!L30/subQ!J30-1,"") | M38: =IFERROR(subQ!M30/subQ!L30-1,"") | N38: =IFERROR(subQ!N30/subQ!M30-1,"") | O38: =IFERROR(subQ!O30/subQ!N30-1,"") | Q38: =IFERROR(subQ!Q30/subQ!O30-1,"") | R38: =IFERROR(subQ!R30/subQ!Q30-1,"") | S38: =IFERROR(subQ!S30/subQ!R30-1,"") | T38: =IFERROR(subQ!T30/subQ!S30-1,"") | V38: =IFERROR(subQ!V30/subQ!T30-1,"") | W38: =IFERROR(subQ!W30/subQ!V30-1,"") | X38: =IFERROR(subQ!X30/subQ!W30-1,"") | Y38: =IFERROR(subQ!Y30/subQ!X30-1,"") | AA38: =IFERROR(subQ!AA30/subQ!Y30-1,"") | AB38: =IFERROR(subQ!AB30/subQ!AA30-1,"")
A39: drv:CAPEX | B39: yoy | C39: CAPEX YoY | J39: =IFERROR(subQ!J31/subQ!E31-1,"") | L39: =IFERROR(subQ!L31/subQ!G31-1,"") | M39: =IFERROR(subQ!M31/subQ!H31-1,"") | N39: =IFERROR(subQ!N31/subQ!I31-1,"") | O39: =IFERROR(subQ!O31/subQ!J31-1,"") | Q39: =IFERROR(subQ!Q31/subQ!L31-1,"") | R39: =IFERROR(subQ!R31/subQ!M31-1,"") | S39: =IFERROR(subQ!S31/subQ!N31-1,"") | T39: =IFERROR(subQ!T31/subQ!O31-1,"") | V39: =IFERROR(subQ!V31/subQ!Q31-1,"") | W39: =IFERROR(subQ!W31/subQ!R31-1,"") | X39: =IFERROR(subQ!X31/subQ!S31-1,"") | Y39: =IFERROR(subQ!Y31/subQ!T31-1,"") | AA39: =IFERROR(subQ!AA31/subQ!V31-1,"") | AB39: =IFERROR(subQ!AB31/subQ!W31-1,"") | AC39: 0.67084079 | AD39: 0 | AF39: 92.587174 | AG39: -0.28594364 | AH39: 0 | AI39: 0 | AK39: 0 | AL39: 0 | AM39: 0 | AN39: 0
A40: drv:영업활동현금흐름 | B40: yoy | C40: 영업활동현금흐름 YoY | J40: =IFERROR(subQ!J32/subQ!E32-1,"") | L40: =IFERROR(subQ!L32/subQ!G32-1,"") | M40: =IFERROR(subQ!M32/subQ!H32-1,"") | N40: =IFERROR(subQ!N32/subQ!I32-1,"") | O40: =IFERROR(subQ!O32/subQ!J32-1,"") | Q40: =IFERROR(subQ!Q32/subQ!L32-1,"") | R40: =IFERROR(subQ!R32/subQ!M32-1,"") | S40: =IFERROR(subQ!S32/subQ!N32-1,"") | T40: =IFERROR(subQ!T32/subQ!O32-1,"") | V40: =IFERROR(subQ!V32/subQ!Q32-1,"") | W40: =IFERROR(subQ!W32/subQ!R32-1,"") | X40: =IFERROR(subQ!X32/subQ!S32-1,"") | Y40: =IFERROR(subQ!Y32/subQ!T32-1,"") | AA40: =IFERROR(subQ!AA32/subQ!V32-1,"") | AB40: =IFERROR(subQ!AB32/subQ!W32-1,"")
A41: drv:주식수 | B41: qoq | C41: 주식수 QoQ | G41: =IFERROR(subQ!G33/subQ!E33-1,"") | H41: =IFERROR(subQ!H33/subQ!G33-1,"") | I41: =IFERROR(subQ!I33/subQ!H33-1,"") | J41: =IFERROR(subQ!J33/subQ!I33-1,"") | L41: =IFERROR(subQ!L33/subQ!J33-1,"") | M41: =IFERROR(subQ!M33/subQ!L33-1,"") | N41: =IFERROR(subQ!N33/subQ!M33-1,"") | O41: =IFERROR(subQ!O33/subQ!N33-1,"") | Q41: =IFERROR(subQ!Q33/subQ!O33-1,"") | R41: =IFERROR(subQ!R33/subQ!Q33-1,"") | S41: =IFERROR(subQ!S33/subQ!R33-1,"") | T41: =IFERROR(subQ!T33/subQ!S33-1,"") | V41: =IFERROR(subQ!V33/subQ!T33-1,"") | W41: =IFERROR(subQ!W33/subQ!V33-1,"") | X41: =IFERROR(subQ!X33/subQ!W33-1,"") | Y41: =IFERROR(subQ!Y33/subQ!X33-1,"") | AA41: =IFERROR(subQ!AA33/subQ!Y33-1,"") | AB41: =IFERROR(subQ!AB33/subQ!AA33-1,"") | AC41: 0 | AD41: 0 | AF41: 0 | AG41: 0 | AH41: 0 | AI41: 0 | AK41: 0 | AL41: 0 | AM41: 0 | AN41: 0
...

Sheet BS연결
B1: (백만원) | C1: 이름: BS연결H | E1: 4Q21 | F1: 2021 | G1: 1Q22 | H1: 2Q22 | I1: 3Q22 | J1: 4Q22 | K1: 2022 | L1: 1Q23 | M1: 2Q23 | N1: 3Q23 | O1: 4Q23 | P1: 2023 | Q1: 1Q24 | R1: 2Q24 | S1: 3Q24 | T1: 4Q24 | U1: 2024 | V1: 1Q25 | W1: 2Q25 | X1: 3Q25 | Y1: 4Q25 | Z1: 2025 | AA1: 1Q26 | AB1: 2Q26 | AC1: 3Q26 | AD1: 4Q26 | AE1: 2026 | AF1: 1Q27 | AG1: 2Q27 | AH1: 3Q27 | AI1: 4Q27 | AJ1: 2027 | AK1: 1Q28 | AL1: 2Q28 | AM1: 3Q28 | AN1: 4Q28 | AO1: 2028
B2: 연결 | D2: fin json(kship_fin.py)
B3: 한국카본(연) | C3: UPDATE: 26-10-11 | E3: 1 | F3: 2 | G3: 3 | H3: 4 | I3: 5 | J3: 6 | K3: 7 | L3: 8 | M3: 9 | N3: 10 | O3: 11 | P3: 12 | Q3: 13 | R3: 14 | S3: 15 | T3: 16 | U3: 17 | V3: 18 | W3: 19 | X3: 20 | Y3: 21 | Z3: 22 | AA3: 23 | AB3: 24 | AC3: 25 | AD3: 26 | AE3: 27 | AF3: 28 | AG3: 29 | AH3: 30 | AI3: 31 | AJ3: 32 | AK3: 33 | AL3: 34 | AM3: 35 | AN3: 36 | AO3: 37
B4: Account Code | C4: AccountNAME | E4: 2021.12 | F4: 2021.12A | G4: 2022.03 | H4: 2022.06 | I4: 2022.09 | J4: 2022.12 | K4: 2022.12A | L4: 2023.03 | M4: 2023.06 | N4: 2023.09 | O4: 2023.12 | P4: 2023.12A | Q4: 2024.03 | R4: 2024.06 | S4: 2024.09 | T4: 2024.12 | U4: 2024.12A | V4: 2025.03 | W4: 2025.06 | X4: 2025.09 | Y4: 2025.12 | Z4: 2025.12A | AA4: 2026.03 | AB4: 2026.06 | AC4: 2026.09 | AD4: 2026.12 | AE4: 2026.12A | AF4: 2027.03 | AG4: 2027.06 | AH4: 2027.09 | AI4: 2027.12 | AJ4: 2027.12A | AK4: 2028.03 | AL4: 2028.06 | AM4: 2028.09 | AN4: 2028.12 | AO4: 2028.12A
A5: 1 | C5: 유동자산 | E5: 247791.87 | F5: 247791.87 | G5: 255393.39 | H5: 230238.29 | I5: 264928.44 | J5: 289163.54 | K5: 289163.54 | L5: 315524.09 | M5: 355804.32 | N5: 400684.73 | O5: 398231.47 | P5: 398231.47 | Q5: 381207.48 | R5: 403917.09 | S5: 430381.52 | T5: 460860.28 | U5: 460860.28 | V5: 500085.88 | W5: 502890.88 | X5: 514786.25 | Y5: 607406.72 | Z5: 607406.72 | AA5: 639843.94 | AB5: 681631.77
A6: 1 | C6: 현금및현금성자산 | E6: 49048.03 | F6: 49048.03 | G6: 55331.27 | H6: 13926.27 | I6: 33955.6 | J6: 53576.76 | K6: 53576.76 | L6: 26157.63 | M6: 20147.7 | N6: 46967.12 | O6: 66697.91 | P6: 66697.91 | Q6: 37198.61 | R6: 81861.13 | S6: 79766.91 | T6: 57565.06 | U6: 57565.06 | V6: 111782.73 | W6: 93232.67 | X6: 102472.41 | Y6: 57866.93 | Z6: 57866.93 | AA6: 81410.23 | AB6: 110991.2
A7: 1 | C7: 단기금융상품 | E7: 15572.82 | F7: 15572.82 | G7: 15064.68 | H7: 13889.3 | I7: 13035.65 | J7: 13165.04 | K7: 13165.04 | L7: 12386.95 | M7: 10759.94 | N7: 17128.44 | O7: 13022.45 | P7: 13022.45 | Q7: 17707.35 | R7: 8729.77 | S7: 9567.13 | T7: 8598.21 | U7: 8598.21 | V7: 8340.84 | W7: 8240.64 | X7: 8149.11 | Y7: 27093.22 | Z7: 27093.22 | AA7: 27408.82 | AB7: 27562.68
A8: 1 | C8: 단기금융자산 | E8: 26206.73 | F8: 26206.73 | G8: 22838.73 | H8: 16474.68 | I8: 13035.65 | J8: 13169.65 | K8: 13169.65 | L8: 14399.7 | M8: 10759.94 | N8: 17128.44 | O8: 13022.45 | P8: 13022.45 | Q8: 17707.35 | R8: 8729.77 | S8: 9567.13 | T8: 8598.21 | U8: 8598.21 | V8: 8340.84 | W8: 16435.73 | X8: 19642.88 | Y8: 36967.87 | Z8: 36967.87 | AA8: 29491.88 | AB8: 28812.89
A9: 1 | C9: 매출채권및기타채권 | E9: 34456.94 | F9: 34456.94 | G9: 36331.24 | H9: 43570.72 | I9: 53976.75 | J9: 39272.3 | K9: 39272.3 | L9: 58037.62 | M9: 74541.64 | N9: 83221.65 | O9: 101111.57 | P9: 101111.57 | Q9: 110410.89 | R9: 85661.03 | S9: 75401.15
A10: 1 | C10: 재고자산 | E10: 90813.55 | F10: 90813.55 | G10: 102484.78 | H10: 134818.99 | I10: 139265.44 | J10: 156268.22 | K10: 156268.22 | L10: 186248.38 | M10: 193333.2 | N10: 220871.23 | O10: 180213.74 | P10: 180213.74 | Q10: 183181.59 | R10: 183391.46 | S10: 195244.82 | T10: 197476.02 | U10: 197476.02 | V10: 190637.47 | W10: 187215.75 | X10: 190217.71 | Y10: 197614.58 | Z10: 197614.58 | AA10: 204378.89 | AB10: 211457.85
A11: 1 | C11: 당기법인세자산(선급법인세) | E11: 1.5 | F11: 1.5 | G11: 2.02 | H11: 0.87 | I11: 1.03 | J11: 1.49 | K11: 1.49 | L11: 1.65 | M11: 0.73 | N11: 1.37 | O11: 2.91 | P11: 2.91 | Q11: 3.35 | R11: 3.5 | S11: 4.6 | T11: 6 | U11: 6 | V11: 7.29 | W11: 2.32 | X11: 4.79 | Y11: 15.32 | Z11: 15.32 | AA11: 15.02 | AB11: 2.17
A12: 1 | C12: 기타유동자산 | E12: 4638.21 | F12: 4638.21 | G12: 3281.96 | H12: 5579.23 | I12: 6464.49 | J12: 7442.53 | K12: 7442.53 | L12: 8361.44 | M12: 12632.03 | N12: 16787.66 | O12: 12638.85 | P12: 12638.85 | Q12: 15366.64 | R12: 18008.01 | S12: 15415.61 | T12: 15033.64 | U12: 15033.64 | V12: 18208.04 | W12: 21927.4 | X12: 22418.53 | Y12: 18096.17 | Z12: 18096.17 | AA12: 32566.7 | AB12: 29001.05
A13: 1 | C13: 매각예정비유동자산및처분자산 | E13: 17.52 | F13: 17.52 | G13: 17.64 | H13: 18.1 | I13: 18.93 | J13: 17.98 | K13: 17.98 | L13: 7.08 | M13: 7.14 | N13: 7.33 | O13: 4.47 | P13: 4.47 | Q13: 4.66 | R13: 4.81 | S13: 4.59
A14: 1 | C14: 비유동자산 | E14: 250546.52 | F14: 250546.52 | G14: 249980.14 | H14: 288907.99 | I14: 292458.61 | J14: 296152.11 | K14: 296152.11 | L14: 296653.95 | M14: 299876.49 | N14: 394313.91 | O14: 394192.2 | P14: 394192.2 | Q14: 407449.62 | R14: 417050.3 | S14: 405736 | T14: 418106.15 | U14: 418106.15 | V14: 421740.83 | W14: 428551.6 | X14: 433794.09 | Y14: 435813.92 | Z14: 435813.92 | AA14: 450490.95 | AB14: 455571.8
A15: 1 | C15: 장기금융자산 | E15: 8603.48 | F15: 8603.48 | G15: 8619.14 | H15: 8633.3 | I15: 6786.97 | J15: 7011.4 | K15: 7011.4 | L15: 4999.55 | M15: 4555.42 | N15: 484 | O15: 352 | P15: 352 | Q15: 352 | R15: 352 | S15: 352 | T15: 28160.62 | U15: 28160.62 | V15: 25462.51 | W15: 27550.69 | X15: 25693.83 | Y15: 24350.66 | Z15: 24350.66 | AA15: 25244.97 | AB15: 24231.24
A16: 1 | C16: 투자자산 | E16: 8603.48 | F16: 8603.48 | G16: 8619.14 | H16: 8633.3 | I16: 6786.97 | J16: 7011.4 | K16: 7011.4 | L16: 4999.55 | M16: 4555.42 | N16: 484 | O16: 352 | P16: 352 | Q16: 352 | R16: 2459.17 | S16: 2201.34 | T16: 30034.34 | U16: 30034.34 | V16: 27223.22 | W16: 29120.98 | X16: 27105.07 | Y16: 26378.47 | Z16: 26378.47 | AA16: 27284.42 | AB16: 24448.87
A17: 1 | C17: 유형자산 | E17: 184644.78 | F17: 184644.78 | G17: 188799.2 | H17: 203871.73 | I17: 210828.11 | J17: 212463.84 | K17: 212463.84 | L17: 216939.52 | M17: 220144.48 | N17: 272351.99 | O17: 271300.75 | P17: 271300.75 | Q17: 282316.44 | R17: 293636.26 | S17: 304656.7 | T17: 312075.75 | U17: 312075.75 | V17: 319612.24 | W17: 330343.11 | X17: 333503.58 | Y17: 335053.95 | Z17: 335053.95 | AA17: 344413.76 | AB17: 352503.89
A18: 1 | C18: 사용권자산 | E18: 4645.89 | F18: 4645.89 | G18: 5065.46 | H18: 5000.07 | I18: 5450.99 | J18: 5837.24 | K18: 5837.24 | L18: 5723.6 | M18: 5853.86 | N18: 5875.01 | O18: 6090.91 | P18: 6090.91 | Q18: 9756.11 | R18: 15708.52 | S18: 8986.02 | T18: 9518.71 | U18: 9518.71 | V18: 9170.11 | W18: 8680.7 | X18: 12931.26 | Y18: 9752.51 | Z18: 9752.51 | AA18: 10981.77 | AB18: 11831.01
A19: 1 | C19: 기타비유동자산 | E19: 5525.31 | F19: 5525.31 | G19: 5927.03 | H19: 5860.87 | I19: 6378.43 | J19: 9312.02 | K19: 9312.02 | L19: 9305.07 | M19: 9392.12 | N19: 9509.02 | O19: 8941.31 | P19: 8941.31 | Q19: 11742.4 | R19: 18659.96 | S19: 11660.56 | T19: 10447.46 | U19: 10447.46 | V19: 10078.95 | W19: 9602.07 | X19: 13910.28 | Y19: 10834.44 | Z19: 10834.44 | AA19: 11388.72 | AB19: 12331.47
A20: 1 | C20: 무형자산 | E20: 2288.39 | F20: 2288.39 | G20: 2267.03 | H20: 2296.01 | I20: 2268.27 | J20: 2254.49 | K20: 2254.49 | L20: 2227.83 | M20: 2203.03 | N20: 37272.64 | O20: 39710.47 | P20: 39710.47 | Q20: 39007.07 | R20: 38318.23 | S20: 38121.11 | T20: 42412.51 | U20: 42412.51 | V20: 41821.46 | W20: 40877.61 | X20: 40040.88 | Y20: 39341.74 | Z20: 39341.74 | AA20: 39145.24 | AB20: 42032.88
A21: 1 | C21: 이연법인세자산 | E21: 1569.61 | F21: 1569.61 | G21: 1430.64 | H21: 1595.32 | I21: 1879.55 | J21: 2866.8 | K21: 2866.8 | L21: 3569.43 | M21: 2562.05 | N21: 1781.31 | O21: 1768.48 | P21: 1768.48 | Q21: 1938.86 | R21: 1840.37 | S21: 565.82
A22: 1 | C22: 자산총계 | E22: 498355.91 | F22: 498355.91 | G22: 505391.17 | H22: 519164.39 | I22: 557405.98 | J22: 585333.64 | K22: 585333.64 | L22: 612185.13 | M22: 655687.95 | N22: 795005.97 | O22: 792428.14 | P22: 792428.14 | Q22: 788661.75 | R22: 820972.2 | S22: 836122.12 | T22: 878968.66 | U22: 878968.66 | V22: 921828.93 | W22: 931444.35 | X22: 948582.27 | Y22: 1043222.6 | Z22: 1043222.6 | AA22: 1090337 | AB22: 1137205.7
A23: 1 | C23: 유동부채 | E23: 93991.13 | F23: 93991.13 | G23: 98508.84 | H23: 100289.98 | I23: 124167.55 | J23: 156336.84 | K23: 156336.84 | L23: 190631.59 | M23: 229480.38 | N23: 267544.14 | O23: 297365.08 | P23: 297365.08 | Q23: 294892.91 | R23: 318477.21 | S23: 326698.75 | T23: 369168.31 | U23: 369168.31 | V23: 400337.98 | W23: 360072.68 | X23: 357565.87 | Y23: 424075.43 | Z23: 424075.43 | AA23: 476206.81 | AB23: 418873.44
A24: 1 | C24: 단기차입금 | E24: 7098 | F24: 7098 | G24: 6933 | H24: 11426 | I24: 34463 | J24: 44318 | K24: 44318 | L24: 56129.22 | M24: 73859.41 | N24: 89467.44 | O24: 89232.02 | P24: 89232.02 | Q24: 68025.21 | R24: 64811.33 | S24: 64507.15 | T24: 47232.3 | U24: 47232.3 | V24: 42758 | W24: 25210.4 | X24: 15969.34 | Y24: 81871.44 | Z24: 81871.44 | AA24: 99511.75 | AB24: 117889.05
A25: 1 | C25: 유동성장기부채 | E25: 15948.57 | F25: 15948.57 | G25: 12166.91 | H25: 939.1 | I25: 4619.33 | J25: 853.42 | K25: 853.42 | L25: 1398.73 | M25: 2046.89 | N25: 4376.03 | O25: 15250.36 | P25: 15250.36 | Q25: 17018.06 | R25: 16697.2 | S25: 6367.2 | T25: 5930.95 | U25: 5930.95 | V25: 4724.7 | W25: 5518.45 | X25: 16312.2 | Y25: 3912.2 | Z25: 3912.2 | AA25: 18462.28 | AB25: 2826.27
A26: 1 | C26: 기타유동금융부채 | E26: 391.38 | F26: 391.38 | G26: 489.57 | H26: 2557.35 | I26: 8009.58 | J26: 1801.08 | K26: 1801.08 | L26: 2916.01 | M26: 2856.94 | N26: 3516.42 | O26: 1059.06 | P26: 1059.06 | Q26: 2527.98 | R26: 3985.62 | S26: 815.26 | T26: 8836.29 | U26: 8836.29 | V26: 8348.9 | W26: 1965.76 | X26: 3812.27 | Y26: 5320.45 | Z26: 5320.45 | AA26: 10209.77 | AB26: 12596.44
A27: 1 | C27: 단기금융부채 | E27: 1067.03 | F27: 1067.03 | G27: 1418.08 | H27: 10499.6 | I27: 9034.81 | J27: 3325.52 | K27: 3325.52 | L27: 4438.28 | M27: 4480.29 | N27: 5228.28 | O27: 2619.86 | P27: 2619.86 | Q27: 4404.86 | R27: 5641.69 | S27: 2014.88 | T27: 10483.33 | U27: 10483.33 | V27: 9889.72 | W27: 28628.7 | X27: 39215.6 | Y27: 35816.73 | Z27: 35816.73 | AA27: 53605.11 | AB27: 18289.54
A28: 1 | C28: 당기법인세부채(미지급법인세) | E28: 6891.83 | F28: 6891.83 | G28: 5705.33 | H28: 3596.05 | I28: 5480.23 | J28: 5749.73 | K28: 5749.73 | L28: 4736.86 | M28: 2115.17 | N28: 5702.61 | O28: 3077.95 | P28: 3077.95 | Q28: 4661.3 | R28: 14146.44 | S28: 10233.25 | T28: 11687.15 | U28: 11687.15 | V28: 11689.01 | W28: 9771.83 | X28: 13253.1 | Y28: 31494.08 | Z28: 31494.08 | AA28: 28404.72 | AB28: 16973.66
A29: 1 | C29: 유동리스부채 | E29: 675.65 | F29: 675.65 | G29: 928.51 | H29: 7942.25 | I29: 1025.23 | J29: 1524.44 | K29: 1524.44 | L29: 1522.27 | M29: 1623.35 | N29: 1711.86 | O29: 1560.8 | P29: 1560.8 | Q29: 1876.88 | R29: 1656.07 | S29: 1199.62 | T29: 1647.04 | U29: 1647.04 | V29: 1540.82 | W29: 1468.82 | X29: 3630.41 | Y29: 2361.39 | Z29: 2361.39 | AA29: 3309.38 | AB29: 4237.91
A30: 1 | C30: 리스부채 | E30: 1583.48 | F30: 1583.48 | G30: 1879.25 | H30: 8737.03 | I30: 1980.98 | J30: 2768.12 | K30: 2768.12 | L30: 2616.72 | M30: 2730.01 | N30: 2843.57 | O30: 2552.46 | P30: 2552.46 | Q30: 5490.17 | R30: 5030.76 | S30: 4899.76 | T30: 5174.05 | U30: 5174.05 | V30: 4934.68 | W30: 4825.87 | X30: 9049.57 | Y30: 5851.97 | Z30: 5851.97 | AA30: 7165.51 | AB30: 7975.5
A31: 1 | C31: 기타유동부채 | E31: 10935.17 | F31: 10935.17 | G31: 10639.42 | H31: 13223.41 | I31: 13219.04 | J31: 30617.17 | K31: 30617.17 | L31: 42970.94 | M31: 55786.23 | N31: 72129.8 | O31: 84883.34 | P31: 84883.34 | Q31: 79767.12 | R31: 105771.63 | S31: 122438.8 | T31: 173791.2 | U31: 173791.2 | V31: 186654.78 | W31: 164353.86 | X31: 150325.64 | Y31: 140999.44 | Z31: 140999.44 | AA31: 140563.77 | AB31: 136649.23
A32: 1 | C32: 비유동부채 | E32: 15359.35 | F32: 15359.35 | G32: 21323.69 | H32: 21749.84 | I32: 33045.29 | J32: 24822.46 | K32: 24822.46 | L32: 23782.36 | M32: 21483.22 | N32: 51148.94 | O32: 40402.35 | P32: 40402.35 | Q32: 44481.94 | R32: 43256.4 | S32: 39192.19 | T32: 35506.43 | U32: 35506.43 | V32: 32798.44 | W32: 45717.67 | X32: 50672.82 | Y32: 38969.49 | Z32: 38969.49 | AA32: 33529.84 | AB32: 44865.76
A33: 1 | C33: 장기차입금 | E33: 2281.09 | F33: 2281.09 | G33: 8372.85 | H33: 8358.7 | I33: 16091.73 | J33: 15953.5 | K33: 15953.5 | L33: 15499.95 | M33: 16725 | N33: 33348.7 | O33: 21104.8 | P33: 21104.8 | Q33: 22895.5 | R33: 21311.2 | S33: 19348.9 | T33: 18062.85 | U33: 18062.85 | V33: 13984.8 | W33: 17406.75 | X33: 15793.34 | Y33: 11400.65 | Z33: 11400.65 | AA33: 10422.6 | AB33: 20621.67
... A36: 1 | C36: 확정급여부채 | E36: 2737.01 | F36: 2737.01 | G36: 3110.59 | H36: 480.06 | I36: 979.05 | J36: 404.81 | K36: 404.81 | L36: 568.32 | M36: 585.99 | N36: 707.52 | O36: 737.4 | P36: 737.4 | Q36: 712.26 | R36: 903.85 | S36: 525.21 | T36: 349.23 | U36: 349.23 | V36: 363.25 | W36: 3026.23 | X36: 7734.72 | Y36: 590.61 | Z36: 590.61 | AA36: 1435.39 | AB36: 677.97
A37: 1 | C37: 이연법인세부채 | E37: 4153.83 | F37: 4153.83 | G37: 3393.59 | H37: 3179.71 | I37: 1288.92 | N37: 1103.74 | O37: 4981.12 | P37: 4981.12 | Q37: 4404.5 | R37: 3666.58 | S37: 4796.24 | T37: 2618.95 | U37: 2618.95 | V37: 4550.25 | W37: 8841.01 | X37: 4484.65 | Y37: 0 | Z37: 0 | AA37: 0
A38: 1 | C38: 기타비유동부채 | E38: 1510.58 | F38: 1510.58 | G38: 1510.58 | H38: 2213.47 | I38: 2213.47 | J38: 6784.07 | K38: 6784.07 | L38: 5972.26 | M38: 2764.98 | N38: 3473.65 | O38: 2113.34 | P38: 2113.34 | Q38: 1309.25 | R38: 1309.25 | S38: 181.82 | T38: 696.44 | U38: 696.44 | V38: 696.44 | W38: 696.44 | X38: 696.44 | Y38: 4137 | Z38: 4137 | AA38: 8701.89 | AB38: 11693.41
A39: 1 | C39: 부채총계 | E39: 109356.56 | F39: 109356.56 | G39: 119832.53 | H39: 122039.82 | I39: 157212.84 | J39: 181165.8 | K39: 181165.8 | L39: 214413.95 | M39: 250963.59 | N39: 318693.07 | O39: 337774.04 | P39: 337774.04 | Q39: 339381.73 | R39: 361740.73 | S39: 365897.73 | T39: 404682.31 | U39: 404682.31 | V39: 433143.96 | W39: 405797.27 | X39: 408245.89 | Y39: 463052.31 | Z39: 463052.31 | AA39: 509744.37 | AB39: 463747.06
A40: 1 | C40: 지배주주지분 | E40: 388999.34 | F40: 388999.34 | G40: 385558.64 | H40: 397124.57 | I40: 400193.14 | J40: 404167.83 | K40: 404167.83 | L40: 397771.18 | M40: 404724.35 | N40: 476312.89 | O40: 454654.11 | P40: 454654.11 | Q40: 449280.03 | R40: 459231.48 | S40: 470224.38 | T40: 474286.35 | U40: 474286.35 | V40: 488684.96 | W40: 525647.07 | X40: 540336.38 | Y40: 580170.31 | Z40: 580170.31 | AA40: 580592.59 | AB40: 673458.63
A41: 1 | C41: 자본금 | E41: 21980.38 | F41: 21980.38 | G41: 21980.38 | H41: 21980.38 | I41: 21980.38 | J41: 21980.38 | K41: 21980.38 | L41: 21980.38 | M41: 21980.38 | N41: 21980.38 | O41: 25954.23 | P41: 25954.23 | Q41: 25954.23 | R41: 25954.23 | S41: 25954.23 | T41: 192789.69 | U41: 192789.69 | V41: 192789.69 | W41: 192789.69 | X41: 192789.69 | Y41: 122789.69 | Z41: 122789.69 | AA41: 122789.69 | AB41: 177321.71
A42: 1 | C42: 자본잉여금 | E42: 74960.11 | F42: 74960.11 | G42: 74960.11 | H42: 74960.11 | I42: 74960.11 | J42: 74960.11 | K42: 74960.11 | L42: 74960.11 | M42: 74960.11 | N42: 74960.11 | O42: 166835.46 | P42: 166835.46 | Q42: 166835.46 | R42: 166835.46 | S42: 166835.46 | T42: 166835.46 | U42: 166835.46 | V42: 166835.46 | W42: 166835.46 | X42: 166835.46 | Y42: 96835.46 | Z42: 96835.46 | AA42: 96835.46 | AB42: 151014.17
...

Sheet BS별도
B1: (백만원) | C1: 이름: BS별도H | E1: 4Q21 | F1: 2021 | G1: 1Q22 | H1: 2Q22 | I1: 3Q22 | J1: 4Q22 | K1: 2022 | L1: 1Q23 | M1: 2Q23 | N1: 3Q23 | O1: 4Q23 | P1: 2023 | Q1: 1Q24 | R1: 2Q24 | S1: 3Q24 | T1: 4Q24 | U1: 2024 | V1: 1Q25 | W1: 2Q25 | X1: 3Q25 | Y1: 4Q25 | Z1: 2025 | AA1: 1Q26 | AB1: 2Q26 | AC1: 3Q26 | AD1: 4Q26 | AE1: 2026 | AF1: 1Q27 | AG1: 2Q27 | AH1: 3Q27 | AI1: 4Q27 | AJ1: 2027 | AK1: 1Q28 | AL1: 2Q28 | AM1: 3Q28 | AN1: 4Q28 | AO1: 2028
B2: 별도 | D2: fin json(kship_fin.py)
B3: 한국카본(별) | C3: UPDATE: 26-10-11 | E3: 1 | F3: 2 | G3: 3 | H3: 4 | I3: 5 | J3: 6 | K3: 7 | L3: 8 | M3: 9 | N3: 10 | O3: 11 | P3: 12 | Q3: 13 | R3: 14 | S3: 15 | T3: 16 | U3: 17 | V3: 18 | W3: 19 | X3: 20 | Y3: 21 | Z3: 22 | AA3: 23 | AB3: 24 | AC3: 25 | AD3: 26 | AE3: 27 | AF3: 28 | AG3: 29 | AH3: 30 | AI3: 31 | AJ3: 32 | AK3: 33 | AL3: 34 | AM3: 35 | AN3: 36 | AO3: 37
B4: Account Code | C4: AccountNAME | E4: 2021.12 | F4: 2021.12A | G4: 2022.03 | H4: 2022.06 | I4: 2022.09 | J4: 2022.12 | K4: 2022.12A | L4: 2023.03 | M4: 2023.06 | N4: 2023.09 | O4: 2023.12 | P4: 2023.12A | Q4: 2024.03 | R4: 2024.06 | S4: 2024.09 | T4: 2024.12 | U4: 2024.12A | V4: 2025.03 | W4: 2025.06 | X4: 2025.09 | Y4: 2025.12 | Z4: 2025.12A | AA4: 2026.03 | AB4: 2026.06 | AC4: 2026.09 | AD4: 2026.12 | AE4: 2026.12A | AF4: 2027.03 | AG4: 2027.06 | AH4: 2027.09 | AI4: 2027.12 | AJ4: 2027.12A | AK4: 2028.03 | AL4: 2028.06 | AM4: 2028.09 | AN4: 2028.12 | AO4: 2028.12A
A5: 1 | C5: 유동자산 | E5: 248746.45 | F5: 248746.45 | G5: 257896.46 | H5: 218944.53 | I5: 253621.5 | J5: 280713.61 | K5: 280713.61 | L5: 306166.07 | M5: 339276.94 | N5: 373051.38 | O5: 367149.03 | P5: 367149.03 | Q5: 353683.87 | R5: 376731.18 | S5: 403039.96 | T5: 432718.6 | U5: 432718.6 | V5: 471861.71 | W5: 477678.27 | X5: 480158.59 | Y5: 555940.26 | Z5: 555940.26 | AA5: 581644.71 | AB5: 597758.17
A6: 1 | C6: 현금및현금성자산 | E6: 46080.64 | F6: 46080.64 | G6: 54670.01 | H6: 9739.52 | I6: 29000.13 | J6: 48142.19 | K6: 48142.19 | L6: 24372.65 | M6: 13701.82 | N6: 44846.31 | O6: 62936.33 | P6: 62936.33 | Q6: 35649.73 | R6: 77744.43 | S6: 75571.99 | T6: 53016.07 | U6: 53016.07 | V6: 103891.63 | W6: 87948.27 | X6: 87587.06 | Y6: 49811.98 | Z6: 49811.98 | AA6: 70042.16 | AB6: 74739.82
A7: 1 | C7: 단기금융상품 | E7: 14719.76 | F7: 14719.76 | G7: 14219.76 | H7: 13727.47 | I7: 12727.47 | J7: 13150.11 | K7: 13150.11 | L7: 11502.62 | M7: 10344.85 | N7: 10044.85 | O7: 10520 | P7: 10520 | Q7: 13520 | R7: 8234 | S7: 7834 | T7: 7600 | U7: 7600 | V7: 7100 | W7: 7100 | X7: 7100 | Y7: 5500 | Z7: 5500 | AA7: 5000 | AB7: 5150
A8: 1 | C8: 단기금융자산 | E8: 25353.67 | F8: 25353.67 | G8: 21993.81 | H8: 16312.85 | I8: 12727.47 | J8: 13154.72 | K8: 13154.72 | L8: 13515.37 | M8: 10344.85 | N8: 10044.85 | O8: 10520 | P8: 10520 | Q8: 13520 | R8: 8234 | S8: 7834 | T8: 7600 | U8: 7600 | V8: 7100 | W8: 15295.09 | X8: 18593.77 | Y8: 15374.65 | Z8: 15374.65 | AA8: 7083.06 | AB8: 6400.21
A9: 1 | C9: 매출채권및기타채권 | E9: 32524.46 | F9: 32524.46 | G9: 34702.48 | H9: 37535.83 | I9: 46786.29 | J9: 35262.81 | K9: 35262.81 | L9: 54868.91 | M9: 70167.13 | N9: 76449.1 | O9: 94009.52 | P9: 94009.52 | Q9: 105242.86 | R9: 78377.46 | S9: 68769.26
A10: 1 | C10: 재고자산 | E10: 85499.77 | F10: 85499.77 | G10: 92992.14 | H10: 123394.54 | I10: 128635.18 | J10: 147190.92 | K10: 147190.92 | L10: 172634.95 | M10: 180981.37 | N10: 201213.14 | O10: 163568.6 | P10: 163568.6 | Q10: 167932.89 | R10: 169678.73 | S10: 180748.87 | T10: 182171.9 | U10: 182171.9 | V10: 176804.66 | W10: 174801.55 | X10: 176997.82 | Y10: 182288.52 | Z10: 182288.52 | AA10: 186964.1 | AB10: 189634.93
A11: 1 | C11: 기타유동자산 | E11: 2215.81 | F11: 2215.81 | G11: 2390.22 | H11: 4887.9 | I11: 4875.78 | J11: 5826.38 | K11: 5826.38 | L11: 7190.99 | M11: 8892.45 | N11: 13114.42 | O11: 9022.23 | P11: 9022.23 | Q11: 11395.21 | R11: 13116.5 | S11: 11168.74 | T11: 11697.65 | U11: 11697.65 | V11: 15563.66 | W11: 18886.01 | X11: 19227.14 | Y11: 14684.72 | Z11: 14684.72 | AA11: 22663.69 | AB11: 23608.04
A12: 1 | C12: 매각예정비유동자산및처분자산 | E12: 10.54 | F12: 10.54 | J12: 10.54 | K12: 10.54 | T12: 0 | U12: 0
A13: 1 | C13: 비유동자산 | E13: 243781.11 | F13: 243781.11 | G13: 242478.9 | H13: 290951.43 | I13: 301983.51 | J13: 293067.35 | K13: 293067.35 | L13: 294236.72 | M13: 301788.82 | N13: 410245.08 | O13: 417173.4 | P13: 417173.4 | Q13: 432534 | R13: 443492.06 | S13: 439172.51 | T13: 437275.81 | U13: 437275.81 | V13: 446343.88 | W13: 456644.18 | X13: 470798.85 | Y13: 477082.48 | Z13: 477082.48 | AA13: 493642.7 | AB13: 524513.85
A14: 1 | C14: 장기금융자산 | E14: 8584.58 | F14: 8584.58 | G14: 73978.96 | H14: 107417.31 | I14: 107465.07 | J14: 6999.42 | K14: 6999.42 | L14: 4987.57 | M14: 4543.44 | N14: 484 | O14: 350 | P14: 350 | Q14: 350 | R14: 350 | S14: 350 | T14: 27523.57 | U14: 27523.57 | V14: 24682.26 | W14: 26827.15 | X14: 24945.72 | Y14: 23586.7 | Z14: 23586.7 | AA14: 24440.57 | AB14: 23412.37
A15: 1 | C15: 투자자산 | E15: 12532.01 | F15: 12532.01 | G15: 99581.24 | H15: 188034.21 | I15: 200650.36 | J15: 21792.81 | K15: 21792.81 | L15: 19780.96 | M15: 40622.01 | N15: 56816.71 | O15: 45799.16 | P15: 45799.16 | Q15: 47353.47 | R15: 1401.38 | S15: 1401.38 | T15: 64241.24 | U15: 64241.24 | V15: 68225.39 | W15: 70370.28 | X15: 78469.32 | Y15: 81011.58 | Z15: 81011.58 | AA15: 89516.62 | AB15: 23412.37
A16: 1 | C16: 종속기업및관계기업투자 | E16: 3947.43 | F16: 3947.43 | G16: 7894.86 | H16: 32988.78 | I16: 39323.88 | J16: 14793.39 | K16: 14793.39 | L16: 14793.39 | M16: 36078.57 | N16: 56332.71 | O16: 45449.16 | P16: 45449.16 | Q16: 47003.47 | R16: 1051.38 | S16: 1051.38 | T16: 36717.67 | U16: 36717.67 | V16: 43543.13 | W16: 43543.13 | X16: 53523.6 | Y16: 57424.88 | Z16: 57424.88 | AA16: 65076.05
A17: 1 | C17: 유형자산 | E17: 165615.79 | F17: 165615.79 | G17: 168139.11 | H17: 170828.77 | I17: 176590.04 | J17: 183353.36 | K17: 183353.36 | L17: 186215.93 | M17: 189963.46 | N17: 228162.59 | O17: 243360.55 | P17: 243360.55 | Q17: 255029.94 | R17: 267278.82 | S17: 280062.19 | T17: 287326.5 | U17: 287326.5 | V17: 294531.33 | W17: 308117.49 | X17: 310938.03 | Y17: 313132.91 | Z17: 313132.91 | AA17: 313735.48 | AB17: 322609.85
A18: 1 | C18: 사용권자산 | E18: 1732.77 | F18: 1732.77 | G18: 2122.97 | H18: 1935.21 | I18: 2155.97 | J18: 2915.76 | K18: 2915.76 | L18: 2714.91 | M18: 2855.7 | N18: 2761.39 | O18: 2428.69 | P18: 2428.69 | Q18: 6066.96 | R18: 5631.85 | S18: 5458.32 | T18: 5708.11 | U18: 5708.11 | V18: 5281.24 | W18: 5187.47 | X18: 9404.63 | Y18: 6102.41 | Z18: 6102.41 | AA18: 7156.09 | AB18: 7886.45
A19: 1 | C19: 기타비유동자산 | E19: 2449.14 | F19: 2449.14 | G19: 2839.34 | H19: 2651.58 | I19: 2872.34 | J19: 6249.36 | K19: 6249.36 | L19: 6161.08 | M19: 6283.8 | N19: 6241.68 | O19: 5106.94 | P19: 5106.94 | Q19: 7783.44 | R19: 8320.79 | S19: 7902.6 | T19: 6424.48 | U19: 6424.48 | V19: 5997.61 | W19: 5903.84 | X19: 10121 | Y19: 6818.78 | Z19: 6818.78 | AA19: 7156.09 | AB19: 7886.45
A20: 1 | C20: 무형자산 | E20: 2184.22 | F20: 2184.22 | G20: 2174.31 | H20: 2173.79 | I20: 2162.19 | J20: 2156.19 | K20: 2156.19 | L20: 2146.74 | M20: 2135.36 | N20: 37987.56 | O20: 41796.7 | P20: 41796.7 | Q20: 41100.43 | R20: 40417.4 | S20: 40230.45 | T20: 44496.83 | U20: 44496.83 | V20: 43914.07 | W20: 42974.18 | X20: 42142.16 | Y20: 41415.16 | Z20: 41415.16 | AA20: 41216.51 | AB20: 40374.84
A21: 1 | C21: 자산총계 | E21: 492538.1 | F21: 492538.1 | G21: 500385.9 | H21: 509906.49 | I21: 555615.55 | J21: 573791.49 | K21: 573791.49 | L21: 600402.79 | M21: 641065.76 | N21: 783296.46 | O21: 784322.42 | P21: 784322.42 | Q21: 786217.86 | R21: 820223.24 | S21: 842212.47 | T21: 869994.41 | U21: 869994.41 | V21: 918205.59 | W21: 934322.44 | X21: 950957.45 | Y21: 1033022.7 | Z21: 1033022.7 | AA21: 1075287.4 | AB21: 1122272
A22: 1 | C22: 유동부채 | E22: 78851.69 | F22: 78851.69 | G22: 83967.9 | H22: 88690.98 | I22: 113909.44 | J22: 149013.55 | K22: 149013.55 | L22: 181495.52 | M22: 214975.25 | N22: 249700.03 | O22: 280286.67 | P22: 280286.67 | Q22: 279433.35 | R22: 302629.05 | S22: 312526.45 | T22: 354900.49 | U22: 354900.49 | V22: 387482.26 | W22: 348751.57 | X22: 344603.09 | Y22: 409857.46 | Z22: 409857.46 | AA22: 457223.22 | AB22: 400651.83
A23: 1 | C23: 기타유동금융부채 | E23: 391.38 | F23: 391.38 | G23: 514.31 | H23: 2591.2 | I23: 8041.3 | J23: 1801.08 | K23: 1801.08 | L23: 2916.01 | M23: 2856.94 | N23: 3516.42 | O23: 1059.06 | P23: 1059.06 | Q23: 2527.98 | R23: 3985.62 | S23: 815.26 | T23: 8836.29 | U23: 8836.29 | V23: 8348.9 | W23: 1965.76 | X23: 3812.27 | Y23: 5320.45 | Z23: 5320.45 | AA23: 10209.77 | AB23: 12596.44
A24: 1 | C24: 단기금융부채 | E24: 1055.2 | F24: 1055.2 | G24: 1434.95 | H24: 3525.58 | I24: 9065.83 | J24: 3325.52 | K24: 3325.52 | L24: 4431.17 | M24: 4476.72 | N24: 5132.7 | O24: 2509.84 | P24: 2509.84 | Q24: 4293.27 | R24: 5527.96 | S24: 1969.97 | T24: 10433.1 | U24: 10433.1 | V24: 9781.18 | W24: 28514.07 | X24: 39100.14 | Y24: 35702.37 | Z24: 35702.37 | AA24: 53488.96 | AB24: 18180.41
A25: 1 | C25: 당기법인세부채(미지급법인세) | E25: 6264.54 | F25: 6264.54 | G25: 5263.87 | H25: 2853.42 | I25: 4146.91 | J25: 5247.03 | K25: 5247.03 | L25: 4126.83 | M25: 1598.55 | N25: 5135.61 | O25: 2841.17 | P25: 2841.17 | Q25: 3941.08 | R25: 13396.71 | S25: 9700.45 | T25: 10435.32 | U25: 10435.32 | V25: 10812.47 | W25: 9771.88 | X25: 12877.18 | Y25: 30700.86 | Z25: 30700.86 | AA25: 27257.11 | AB25: 16261.52
A26: 1 | C26: 유동리스부채 | E26: 663.82 | F26: 663.82 | G26: 920.64 | H26: 934.38 | I26: 1024.53 | J26: 1524.44 | K26: 1524.44 | L26: 1515.16 | M26: 1619.78 | N26: 1616.28 | O26: 1450.78 | P26: 1450.78 | Q26: 1765.29 | R26: 1542.34 | S26: 1154.71 | T26: 1596.81 | U26: 1596.81 | V26: 1432.28 | W26: 1354.19 | X26: 3514.95 | Y26: 2247.03 | Z26: 2247.03 | AA26: 3193.23 | AB26: 4128.78
A27: 1 | C27: 리스부채 | E27: 1570.81 | F27: 1570.81 | G27: 1870.55 | H27: 1729.16 | I27: 1980.28 | J27: 2768.12 | K27: 2768.12 | L27: 2609.61 | M27: 2726.44 | N27: 2679.6 | O27: 2387.63 | P27: 2387.63 | Q27: 5350.15 | R27: 4914.51 | S27: 4828.08 | T27: 5076.4 | U27: 5076.4 | V27: 4706.69 | W27: 4618.57 | X27: 8857.69 | Y27: 5611.94 | Z27: 5611.94 | AA27: 6901.19 | AB27: 7627.75
A28: 1 | C28: 유동성장기부채 | E28: 15056.6 | F28: 15056.6 | G28: 11306.6 | H28: 7556.6 | I28: 3822.35 | J28: 88.1 | K28: 88.1 | L28: 633.41 | M28: 1467.56 | N28: 3755.06 | O28: 14623.96 | P28: 14623.96 | Q28: 16433.3 | R28: 16397.2 | S28: 6067.2 | T28: 5930.95 | U28: 5930.95 | V28: 4724.7 | W28: 5518.45 | X28: 16312.2 | Y28: 3912.2 | Z28: 3912.2 | AA28: 18462.28 | AB28: 2826.27
... A33: 1 | C33: 장기금융부채 | E33: 906.99 | F33: 906.99 | G33: 1072.32 | H33: 3582.68 | I33: 12316.15 | J33: 1514.73 | K33: 1514.73 | L33: 1571.92 | M33: 1203.89 | N33: 1992.89 | O33: 936.85 | P33: 936.85 | Q33: 4637.51 | R33: 5542.57 | S33: 4045.73 | T33: 13453.19 | U33: 13453.19 | V33: 12795.36 | W33: 3775.6 | X33: 9002.35 | Y33: 8814.34 | Z33: 8814.34 | AA33: 12108.75 | AB33: 10177.23
A34: 1 | C34: 확정급여부채 | E34: 1664.66 | F34: 1664.66 | G34: 1954.98 | H34: 172 | I34: 549.94 | O34: 45.16 | P34: 45.16 | Q34: 45.16 | R34: 348.22 | S34: 525.21 | T34: 349.23 | U34: 349.23 | V34: 363.25 | W34: 625.03 | X34: 705.76 | Y34: 590.61 | Z34: 590.61 | AA34: 677.44 | AB34: 761.36
A35: 1 | C35: 이연법인세부채 | E35: 4153.83 | F35: 4153.83 | G35: 3393.59 | H35: 3179.71 | I35: 1288.92 | N35: 1103.74 | O35: 4981.12 | P35: 4981.12 | Q35: 4404.5 | R35: 3666.58 | S35: 4796.24
A36: 1 | C36: 기타비유동부채 | E36: 1510.58 | F36: 1510.58 | G36: 1510.58 | H36: 2213.47 | I36: 2213.47 | J36: 6784.07 | K36: 6784.07 | L36: 5972.26 | M36: 2764.98 | N36: 3473.65 | O36: 2113.34 | P36: 2113.34 | Q36: 1309.25 | R36: 1309.25 | S36: 181.82 | T36: 696.44 | U36: 696.44 | V36: 696.44 | W36: 696.44 | X36: 696.44 | Y36: 4137 | Z36: 4137 | AA36: 8701.89 | AB36: 11693.41
A37: 1 | C37: 부채총계 | E37: 88046.53 | F37: 88046.53 | G37: 98949.91 | H37: 104875.22 | I37: 145490.31 | J37: 172708.85 | K37: 172708.85 | L37: 203982.65 | M37: 235369.12 | N37: 298249.62 | O37: 318467.94 | P37: 318467.94 | Q37: 321725.27 | R37: 343806.87 | S37: 351324.34 | T37: 390081.16 | U37: 390081.16 | V37: 419872.35 | W37: 394074.04 | X37: 394917.62 | Y37: 448358.94 | Z37: 448358.94 | AA37: 490241.86 | AB37: 444883.47
A38: 1 | C38: 자본금 | E38: 21980.38 | F38: 21980.38 | G38: 21980.38 | H38: 21980.38 | I38: 21980.38 | J38: 21980.38 | K38: 21980.38 | L38: 21980.38 | M38: 21980.38 | N38: 21980.38 | O38: 25954.23 | P38: 25954.23 | Q38: 25954.23 | R38: 25954.23 | S38: 25954.23 | T38: 192789.69 | U38: 192789.69 | V38: 192789.69 | W38: 192789.69 | X38: 192789.69 | Y38: 122789.69 | Z38: 122789.69 | AA38: 122789.69 | AB38: 177321.71
A39: 1 | C39: 자본잉여금 | E39: 74960.11 | F39: 74960.11 | G39: 74960.11 | H39: 74960.11 | I39: 74960.11 | J39: 74960.11 | K39: 74960.11 | L39: 74960.11 | M39: 74960.11 | N39: 74960.11 | O39: 166835.46 | P39: 166835.46 | Q39: 166835.46 | R39: 166835.46 | S39: 166835.46 | T39: 166835.46 | U39: 166835.46 | V39: 166835.46 | W39: 166835.46 | X39: 166835.46 | Y39: 96835.46 | Z39: 96835.46 | AA39: 96835.46 | AB39: 151014.17
A40: 1 | C40: 이익잉여금 | E40: 302311.08 | F40: 302311.08 | G40: 299390.5 | H40: 302985.78 | I40: 308079.74 | J40: 299038.94 | K40: 299038.94 | L40: 294376.44 | M40: 303652.93 | N40: 308292.13 | O40: 289114.7 | P40: 289114.7 | Q40: 287756.44 | R40: 299680.2 | S40: 314151.81 | T40: 303177 | U40: 303177 | V40: 321596.98 | W40: 346144.09 | X40: 361935.51 | Y40: 460409.17 | Z40: 460409.17 | AA40: 449602.89 | AB40: 487112.81
A41: 1 | C41: 기타포괄이익누계액 | E41: -3298.12 | F41: -3298.12 | G41: -3433.13 | H41: -3433.13 | I41: -3433.13 | J41: -3434.91 | K41: -3434.91 | L41: -3434.91 | M41: -3434.91 | N41: -3434.91 | O41: -2266.08 | P41: -2266.08 | Q41: -2269.71 | R41: -2269.69 | S41: -2269.55 | T41: -2264.91 | U41: -2264.91 | V41: -2264.91 | W41: -2264.91 | X41: -2264.91 | Y41: -704.91 | Z41: -704.91 | AA41: -704.91 | AB41: -704.91
A42: 1 | C42: 기타자본 | E42: 8538.13 | F42: 8538.13 | G42: 13643.13 | H42: 13643.13 | I42: 13643.13 | J42: 8538.13 | K42: 8538.13 | L42: 8538.13 | M42: 8538.13 | N42: 83249.12 | O42: -13783.82 | P42: -13783.82 | Q42: -13783.82 | R42: -13783.82 | S42: -13783.82 | T42: -13788.53 | U42: -13788.53 | V42: -13788.53 | W42: 3579.53 | X42: 3579.53 | Y42: 2169.86 | Z42: 2169.86 | AA42: 13357.88 | AB42: 13658.93
A43: 1 | C43: 자본총계 | E43: 404491.57 | F43: 404491.57 | G43: 401435.99 | H43: 405031.27 | I43: 410125.23 | J43: 401082.64 | K43: 401082.64 | L43: 396420.15 | M43: 405696.64 | N43: 485046.84 | O43: 465854.48 | P43: 465854.48 | Q43: 464492.6 | R43: 476416.37 | S43: 490888.13 | T43: 479913.25 | U43: 479913.25 | V43: 498333.24 | W43: 540248.4 | X43: 556039.82 | Y43: 584663.8 | Z43: 584663.8 | AA43: 585045.55 | AB43: 677388.55
A44: 1 | C44: 부채와자본총계 | E44: 492538.1 | F44: 492538.1 | G44: 500385.9 | H44: 509906.49 | I44: 555615.55 | J44: 573791.49 | K44: 573791.49 | L44: 600402.79 | M44: 641065.76 | N44: 783296.46 | O44: 784322.42 | P44: 784322.42 | Q44: 786217.86 | R44: 820223.24 | S44: 842212.47 | T44: 869994.41 | U44: 869994.41 | V44: 918205.59 | W44: 934322.44 | X44: 950957.45 | Y44: 1033022.7 | Z44: 1033022.7 | AA44: 1075287.4 | AB44: 1122272
...

Sheet subQ
A1: YQ | C1: subQ 분기 서브모델(억원, U=100) | E1: 4Q21 | F1: 2021 | G1: 1Q22 | H1: 2Q22 | I1: 3Q22 | J1: 4Q22 | K1: 2022 | L1: 1Q23 | M1: 2Q23 | N1: 3Q23 | O1: 4Q23 | P1: 2023 | Q1: 1Q24 | R1: 2Q24 | S1: 3Q24 | T1: 4Q24 | U1: 2024 | V1: 1Q25 | W1: 2Q25 | X1: 3Q25 | Y1: 4Q25 | Z1: 2025 | AA1: 1Q26 | AB1: 2Q26 | AC1: 3Q26 | AD1: 4Q26 | AE1: 2026 | AF1: 1Q27 | AG1: 2Q27 | AH1: 3Q27 | AI1: 4Q27 | AJ1: 2027 | AK1: 1Q28 | AL1: 2Q28 | AM1: 3Q28 | AN1: 4Q28 | AO1: 2028
A2: A=이름(key) B=그룹 C=단위 D=FnGuide 계정명(VLOOKUP 키). 확정=VLOOKUP(BS), 추정=변수 가정 참조
E3: 1 | F3: 2 | G3: 3 | H3: 4 | I3: 5 | J3: 6 | K3: 7 | L3: 8 | M3: 9 | N3: 10 | O3: 11 | P3: 12 | Q3: 13 | R3: 14 | S3: 15 | T3: 16 | U3: 17 | V3: 18 | W3: 19 | X3: 20 | Y3: 21 | Z3: 22 | AA3: 23 | AB3: 24 | AC3: 25 | AD3: 26 | AE3: 27 | AF3: 28 | AG3: 29 | AH3: 30 | AI3: 31 | AJ3: 32 | AK3: 33 | AL3: 34 | AM3: 35 | AN3: 36 | AO3: 37
E4: 2021.12 | F4: 2021.12A | G4: 2022.03 | H4: 2022.06 | I4: 2022.09 | J4: 2022.12 | K4: 2022.12A | L4: 2023.03 | M4: 2023.06 | N4: 2023.09 | O4: 2023.12 | P4: 2023.12A | Q4: 2024.03 | R4: 2024.06 | S4: 2024.09 | T4: 2024.12 | U4: 2024.12A | V4: 2025.03 | W4: 2025.06 | X4: 2025.09 | Y4: 2025.12 | Z4: 2025.12A | AA4: 2026.03 | AB4: 2026.06 | AC4: 2026.09 | AD4: 2026.12 | AE4: 2026.12A | AF4: 2027.03 | AG4: 2027.06 | AH4: 2027.09 | AI4: 2027.12 | AJ4: 2027.12A | AK4: 2028.03 | AL4: 2028.06 | AM4: 2028.09 | AN4: 2028.12 | AO4: 2028.12A
A5: 매출액 | B5: 손익 | C5: 억원 | D5: 매출액(수익) | E5: =IFERROR(VLOOKUP($D5,BS연결,MATCH(E$1,BS연결H,0),0)/100,"") | G5: =IFERROR(VLOOKUP($D5,BS연결,MATCH(G$1,BS연결H,0),0)/100,"") | H5: =IFERROR(VLOOKUP($D5,BS연결,MATCH(H$1,BS연결H,0),0)/100,"") | I5: =IFERROR(VLOOKUP($D5,BS연결,MATCH(I$1,BS연결H,0),0)/100,"") | J5: =IFERROR(VLOOKUP($D5,BS연결,MATCH(J$1,BS연결H,0),0)/100,"") | K5: =IFERROR(VLOOKUP($D5,BS연결,MATCH(K$1,BS연결H,0),0)/100,"") | L5: =IFERROR(VLOOKUP($D5,BS연결,MATCH(L$1,BS연결H,0),0)/100,"") | M5: =IFERROR(VLOOKUP($D5,BS연결,MATCH(M$1,BS연결H,0),0)/100,"") | N5: =IFERROR(VLOOKUP($D5,BS연결,MATCH(N$1,BS연결H,0),0)/100,"") | ... AB5: =IFERROR(VLOOKUP($D5,BS연결,MATCH(AB$1,BS연결H,0),0)/100,"") | AC5: =IFERROR(X5*(1+변수!AC21),"") | AD5: =IFERROR(Y5*(1+변수!AD21),"") | AE5: =SUM(AA5:AD5) | AF5: =IFERROR(AA5*(1+변수!AF21),"") | AG5: =IFERROR(AB5*(1+변수!AG21),"") | AH5: =IFERROR(AC5*(1+변수!AH21),"") | AI5: =IFERROR(AD5*(1+변수!AI21),"") | AJ5: =SUM(AF5:AI5) | AK5: =IFERROR(AF5*(1+변수!AK21),"") | AL5: =IFERROR(AG5*(1+변수!AL21),"") | AM5: =IFERROR(AH5*(1+변수!AM21),"") | AN5: =IFERROR(AI5*(1+변수!AN21),"") | AO5: =SUM(AK5:AN5)
A6: 매출원가 | B6: 손익 | C6: 억원 | D6: 매출원가 | E6: =IFERROR(VLOOKUP($D6,BS연결,MATCH(E$1,BS연결H,0),0)/100,"") | G6: =IFERROR(VLOOKUP($D6,BS연결,MATCH(G$1,BS연결H,0),0)/100,"") | H6: =IFERROR(VLOOKUP($D6,BS연결,MATCH(H$1,BS연결H,0),0)/100,"") | I6: =IFERROR(VLOOKUP($D6,BS연결,MATCH(I$1,BS연결H,0),0)/100,"") | J6: =IFERROR(VLOOKUP($D6,BS연결,MATCH(J$1,BS연결H,0),0)/100,"") | K6: =IFERROR(VLOOKUP($D6,BS연결,MATCH(K$1,BS연결H,0),0)/100,"") | L6: =IFERROR(VLOOKUP($D6,BS연결,MATCH(L$1,BS연결H,0),0)/100,"") | M6: =IFERROR(VLOOKUP($D6,BS연결,MATCH(M$1,BS연결H,0),0)/100,"") | N6: =IFERROR(VLOOKUP($D6,BS연결,MATCH(N$1,BS연결H,0),0)/100,"") | ... AB6: =IFERROR(VLOOKUP($D6,BS연결,MATCH(AB$1,BS연결H,0),0)/100,"") | AC6: =IFERROR(AC5-AC7,"") | AD6: =IFERROR(AD5-AD7,"") | AE6: =SUM(AA6:AD6) | AF6: =IFERROR(AF5-AF7,"") | AG6: =IFERROR(AG5-AG7,"") | AH6: =IFERROR(AH5-AH7,"") | AI6: =IFERROR(AI5-AI7,"") | AJ6: =SUM(AF6:AI6) | AK6: =IFERROR(AK5-AK7,"") | AL6: =IFERROR(AL5-AL7,"") | AM6: =IFERROR(AM5-AM7,"") | AN6: =IFERROR(AN5-AN7,"") | AO6: =SUM(AK6:AN6)
A7: 매출총이익 | B7: 손익 | C7: 억원 | D7: 매출총이익 | E7: =IFERROR(VLOOKUP($D7,BS연결,MATCH(E$1,BS연결H,0),0)/100,"") | G7: =IFERROR(VLOOKUP($D7,BS연결,MATCH(G$1,BS연결H,0),0)/100,"") | H7: =IFERROR(VLOOKUP($D7,BS연결,MATCH(H$1,BS연결H,0),0)/100,"") | I7: =IFERROR(VLOOKUP($D7,BS연결,MATCH(I$1,BS연결H,0),0)/100,"") | J7: =IFERROR(VLOOKUP($D7,BS연결,MATCH(J$1,BS연결H,0),0)/100,"") | K7: =IFERROR(VLOOKUP($D7,BS연결,MATCH(K$1,BS연결H,0),0)/100,"") | L7: =IFERROR(VLOOKUP($D7,BS연결,MATCH(L$1,BS연결H,0),0)/100,"") | M7: =IFERROR(VLOOKUP($D7,BS연결,MATCH(M$1,BS연결H,0),0)/100,"") | N7: =IFERROR(VLOOKUP($D7,BS연결,MATCH(N$1,BS연결H,0),0)/100,"") | ... AB7: =IFERROR(VLOOKUP($D7,BS연결,MATCH(AB$1,BS연결H,0),0)/100,"") | AC7: =IFERROR(AC9+AC8,"") | AD7: =IFERROR(AD9+AD8,"") | AE7: =SUM(AA7:AD7) | AF7: =IFERROR(AF9+AF8,"") | AG7: =IFERROR(AG9+AG8,"") | AH7: =IFERROR(AH9+AH8,"") | AI7: =IFERROR(AI9+AI8,"") | AJ7: =SUM(AF7:AI7) | AK7: =IFERROR(AK9+AK8,"") | AL7: =IFERROR(AL9+AL8,"") | AM7: =IFERROR(AM9+AM8,"") | AN7: =IFERROR(AN9+AN8,"") | AO7: =SUM(AK7:AN7)
A8: 판관비 | B8: 손익 | C8: 억원 | D8: 판관비 | E8: =IFERROR(VLOOKUP($D8,BS연결,MATCH(E$1,BS연결H,0),0)/100,"") | G8: =IFERROR(VLOOKUP($D8,BS연결,MATCH(G$1,BS연결H,0),0)/100,"") | H8: =IFERROR(VLOOKUP($D8,BS연결,MATCH(H$1,BS연결H,0),0)/100,"") | I8: =IFERROR(VLOOKUP($D8,BS연결,MATCH(I$1,BS연결H,0),0)/100,"") | J8: =IFERROR(VLOOKUP($D8,BS연결,MATCH(J$1,BS연결H,0),0)/100,"") | K8: =IFERROR(VLOOKUP($D8,BS연결,MATCH(K$1,BS연결H,0),0)/100,"") | L8: =IFERROR(VLOOKUP($D8,BS연결,MATCH(L$1,BS연결H,0),0)/100,"") | M8: =IFERROR(VLOOKUP($D8,BS연결,MATCH(M$1,BS연결H,0),0)/100,"") | N8: =IFERROR(VLOOKUP($D8,BS연결,MATCH(N$1,BS연결H,0),0)/100,"") | ... AB8: =IFERROR(VLOOKUP($D8,BS연결,MATCH(AB$1,BS연결H,0),0)/100,"") | AC8: =IFERROR(AC5*변수!AC22,"") | AD8: =IFERROR(AD5*변수!AD22,"") | AE8: =SUM(AA8:AD8) | AF8: =IFERROR(AF5*변수!AF22,"") | AG8: =IFERROR(AG5*변수!AG22,"") | AH8: =IFERROR(AH5*변수!AH22,"") | AI8: =IFERROR(AI5*변수!AI22,"") | AJ8: =SUM(AF8:AI8) | AK8: =IFERROR(AK5*변수!AK22,"") | AL8: =IFERROR(AL5*변수!AL22,"") | AM8: =IFERROR(AM5*변수!AM22,"") | AN8: =IFERROR(AN5*변수!AN22,"") | AO8: =SUM(AK8:AN8)
