Workbook
Name 변수H: 변수!$C$1:$AO$1
Name 환율: 변수!$C$6:$AO$13
Name BS연결H: BS연결!$C$1:$AO$1
Name BS연결: BS연결!$C$5:$AO$103
Name BS별도H: BS별도!$C$1:$AO$1
Name BS별도: BS별도!$C$5:$AO$82
Name SUBQH: subQ!$A$1:$AO$1
Name subQ: subQ!$A$5:$AO$43

Sheet README
A1: 태광(023160) 실적 모델 — ARGUS 한국조선
A2: 기준 분기 2026Q2 · 마지막 실적 2026Q2 · 생성 2026-10-11
A3: 모든 수치는 모델 산출값(DART 공개 재무제표 + 우리 추정)이다 — 목표주가·투자 추천 아님. 참고용 · 투자조언 아님.
A5: 시트
A6: 변수 가정 시계열. 환율 8행(ECB via frankfurter — L2 fx.json; 추정 분기 = 노란 가정), 추정 드라이버(노란 셀 = 모델값에서 역산한 가정, 바꾸면 재계산; 연녹 셀 = 3절 스칼라 참조 수식), 3절 스칼라 가정(세율·판관비율·지배주주비중·이자율·종가·PER 밴드·COE·외화 순노출·헤지비율)
A7: BS연결/BS별도 FnGuide 계정명 × 기간 값 덤프(백만원). 행1 분기라벨, 행4 YYYY.MM / YYYY.12A. 이름정의 BS연결H·BS연결(계정명 C열부터)
A8: subQ 분기 서브모델(억원 = 백만원/100). 확정 행: =IFERROR(VLOOKUP($D행,BS연결,MATCH(E$1,BS연결H,0),0)/100,"") 추정 행: 변수 시트 가정 셀 참조 수식. 외환손익·파생상품손익은 BS 계정 합·차, 기타금융손익은 잔차, OPM·EPS·BPS·PER·PBR 은 파생 수식, 조정EPS 는 EPS 참조(일회성 의심 분기만 산식 셀)
A9: SLS 선표(조선사만, sls json 있을 때): 요약 행(sls 저장값) + 계약별 스케줄(백만$) × (헤지비율 × 헤지환율 + (1−헤지비율) × 건조시점 환율[변수 원/달러(평균)]) → 원화 수식 블록 → 합계 행이 subQ 매출조선에 연결
A10: 시나리오 신규수주 보수/기준/낙관(forecast_panel 패널, 모델에 scenarios 가 있을 때만): 매출액·영업이익 = subQ 기준값 ± (시나리오 신규 − base 신규) × OPM. base 만 subQ 행에 포함, 나머지는 합산 안 함
A11: 분기/연간예상 subQ 를 이름(A열 key)으로 VLOOKUP 한 보고서 표(억원)
A12: TP PER 밴드 × 12M fwd EPS, PBR = ROE/COE × BPS — 모델 산출값 구간, 목표주가·추천 아님
A13: 외화 환율 QoQ, 외화 순노출 × Δ기말환율 → 환관련손익 추정
... A35: 백테스트: {"freeze": "2025Q2", "horizon": 4, "revenue_wape_pct": 26.1, "op_wape_pct": 27.8, "n": 4, "note": "단일 회사 4분기 — 통계 아님", "driver_at_freeze": "trend_seasonal", "selection_oos_at_freeze": null, "frozen_inputs": "fin(연결/별도)·고객 조선사 모델·지주 자회사 모델은 2025Q2 까지의 분기만; 선표는 체결일 ≤ 2025Q2 말일 계약(원장 최신 금액·코호트 등급, 환산 없음); 잔고는 yards_cache 2025Q2; 시세·환율 forward·prices·forecast_panel 신규수주 미사용. 고객 가중치(suppliers.json 언급 비중)와 합병 체인링크는 현재 지식; 고객 연동 채택은 동결 모델 안에서도 자기 la−4분기 OOS 규칙(selection_oos_at_freeze)", "detail": [{"q": "2025Q3", "rev_pred": 569.88, "rev_act": 814.15, "op_pred": 76.42, "op_act": 115.69}, {"q": "2025Q4", "rev_pred": 610.49, "rev_act": 806.0, "op_pred": 81.87, "op_act": 121.05}, {"q": "2026Q1", "rev_pred": 578.02, "rev_act": 822.75, "op_pred": 77.51, "op_act": 93.5}, {"q": "2026Q2", "rev_pred": 667.36, "rev_act": 837.46, "op_pred": 89.49, "op_act": 72.12}]}

Sheet 변수
C1: 이름: 변수H | E1: 4Q21 | F1: 2021 | G1: 1Q22 | H1: 2Q22 | I1: 3Q22 | J1: 4Q22 | K1: 2022 | L1: 1Q23 | M1: 2Q23 | N1: 3Q23 | O1: 4Q23 | P1: 2023 | Q1: 1Q24 | R1: 2Q24 | S1: 3Q24 | T1: 4Q24 | U1: 2024 | V1: 1Q25 | W1: 2Q25 | X1: 3Q25 | Y1: 4Q25 | Z1: 2025 | AA1: 1Q26 | AB1: 2Q26 | AC1: 3Q26 | AD1: 4Q26 | AE1: 2026 | AF1: 1Q27 | AG1: 2Q27 | AH1: 3Q27 | AI1: 4Q27 | AJ1: 2027 | AK1: 1Q28 | AL1: 2Q28 | AM1: 3Q28 | AN1: 4Q28 | AO1: 2028
A2: 가정 시계열 — 노란 셀은 추정 가정(모델값에서 역산), 연녹 셀은 3절 스칼라 참조 수식. 바꾸면 subQ·분기·연간예상·TP·시나리오가 재계산됩니다.
E3: 1 | F3: 2 | G3: 3 | H3: 4 | I3: 5 | J3: 6 | K3: 7 | L3: 8 | M3: 9 | N3: 10 | O3: 11 | P3: 12 | Q3: 13 | R3: 14 | S3: 15 | T3: 16 | U3: 17 | V3: 18 | W3: 19 | X3: 20 | Y3: 21 | Z3: 22 | AA3: 23 | AB3: 24 | AC3: 25 | AD3: 26 | AE3: 27 | AF3: 28 | AG3: 29 | AH3: 30 | AI3: 31 | AJ3: 32 | AK3: 33 | AL3: 34 | AM3: 35 | AN3: 36 | AO3: 37
E4: 2021.12 | F4: 2021.12A | G4: 2022.03 | H4: 2022.06 | I4: 2022.09 | J4: 2022.12 | K4: 2022.12A | L4: 2023.03 | M4: 2023.06 | N4: 2023.09 | O4: 2023.12 | P4: 2023.12A | Q4: 2024.03 | R4: 2024.06 | S4: 2024.09 | T4: 2024.12 | U4: 2024.12A | V4: 2025.03 | W4: 2025.06 | X4: 2025.09 | Y4: 2025.12 | Z4: 2025.12A | AA4: 2026.03 | AB4: 2026.06 | AC4: 2026.09 | AD4: 2026.12 | AE4: 2026.12A | AF4: 2027.03 | AG4: 2027.06 | AH4: 2027.09 | AI4: 2027.12 | AJ4: 2027.12A | AK4: 2028.03 | AL4: 2028.06 | AM4: 2028.09 | AN4: 2028.12 | AO4: 2028.12A
B5: 1. FX | C5: 이름: 환율
A6: USDKRW_avg | C6: 원/달러(평균) | E6: 1183.5 | F6: 1145.51 | G6: 1205.78 | H6: 1262.09 | I6: 1341.93 | J6: 1360.12 | K6: 1292.98 | L6: 1276.95 | M6: 1315.69 | N6: 1313.62 | O6: 1322.01 | P6: 1306.85 | Q6: 1330.14 | R6: 1371.28 | S6: 1356.22 | T6: 1396.3 | U6: 1363.53 | V6: 1452.28 | W6: 1398.52 | X6: 1386.95 | Y6: 1449.19 | Z6: 1421.52 | AA6: 1466.12 | AB6: 1501.75 | AC6: 1418.75 | AD6: 1345.14 | AE6: 1457.21 | AF6: 1341.49 | AG6: 1341.49 | AH6: 1341.49 | AI6: 1341.49 | AK6: 1341.49 | AL6: 1341.49 | AM6: 1341.49 | AN6: 1341.49
A7: USDKRW_end | C7: 원/달러(기말) | E7: 1188.75 | F7: 1188.75 | G7: 1213.74 | H7: 1301.24 | I7: 1436.9 | J7: 1260.16 | K7: 1260.16 | L7: 1305.99 | M7: 1321.44 | N7: 1345.35 | O7: 1297.43 | P7: 1297.43 | Q7: 1349.25 | R7: 1377.73 | S7: 1312.17 | T7: 1474.78 | U7: 1474.78 | V7: 1474.54 | W7: 1355.13 | X7: 1403.67 | Y7: 1444.2 | Z7: 1444.2 | AA7: 1524.8 | AB7: 1550.89 | AC7: 1355.4 | AD7: 1341.49 | AE7: 1341.49 | AF7: 1341.49 | AG7: 1341.49 | AH7: 1341.49 | AI7: 1341.49 | AK7: 1341.49 | AL7: 1341.49 | AM7: 1341.49 | AN7: 1341.49
A8: JPY100KRW_avg | C8: 원/100Y(평균) | E8: 1041.02 | F8: 1042.74 | G8: 1036.79 | H8: 972.23 | I8: 970.61 | J8: 961.03 | K8: 985.1 | L8: 964.89 | M8: 957.36 | N8: 909 | O8: 893.22 | P8: 931.11 | Q8: 896.29 | R8: 880.14 | S8: 909.35 | T8: 917.25 | U8: 900.92 | V8: 952.59 | W8: 967.92 | X8: 940.32 | Y8: 940.77 | Z8: 950.17 | AA8: 934.39 | AB8: 942.16 | AC8: 890.41 | AD8: 850.79 | AE8: 919.21 | AF8: 847.7 | AG8: 847.7 | AH8: 847.7 | AI8: 847.7 | AK8: 847.7 | AL8: 847.7 | AM8: 847.7 | AN8: 847.7
A9: JPY100KRW_end | C9: 원/100Y(기말) | E9: 1032.62 | F9: 1032.62 | G9: 996.83 | H9: 954.9 | I9: 993.29 | J9: 955.54 | K9: 955.54 | L9: 980.62 | M9: 913.67 | N9: 901.47 | O9: 917.04 | P9: 917.04 | Q9: 892.42 | R9: 857.76 | S9: 919.21 | T9: 939.65 | U9: 939.65 | V9: 986.84 | W9: 938.85 | X9: 948.49 | Y9: 921.81 | Z9: 921.81 | AA9: 955.99 | AB9: 954.75 | AC9: 863.31 | AD9: 847.7 | AE9: 847.7 | AF9: 847.7 | AG9: 847.7 | AH9: 847.7 | AI9: 847.7 | AK9: 847.7 | AL9: 847.7 | AM9: 847.7 | AN9: 847.7
A10: EURKRW_avg | C10: W/Euro(평균) | E10: 1353.32 | F10: 1354.06 | G10: 1352.29 | H10: 1343.31 | I10: 1350.63 | J10: 1386.07 | K10: 1358.07 | L10: 1369.93 | M10: 1432.41 | N10: 1429.41 | O10: 1420.91 | P10: 1412.88 | Q10: 1444.21 | R10: 1476.42 | S10: 1489.3 | T10: 1490.78 | U10: 1475.4 | V10: 1528.33 | W10: 1585.13 | X10: 1620.04 | Y10: 1686.02 | Z10: 1605.45 | AA10: 1715.47 | AB10: 1746.09 | AC10: 1631.97 | AD10: 1509.74 | AE10: 1689.95 | AF10: 1503.27 | AG10: 1503.27 | AH10: 1503.27 | AI10: 1503.27 | AK10: 1503.27 | AL10: 1503.27 | AM10: 1503.27 | AN10: 1503.27
A11: EURKRW_end | C11: W/Euro(기말) | E11: 1346.38 | F11: 1346.38 | G11: 1347.37 | H11: 1351.6 | I11: 1400.62 | J11: 1344.08 | K11: 1344.08 | L11: 1420.26 | M11: 1435.88 | N11: 1425.26 | O11: 1433.66 | P11: 1433.66 | Q11: 1458.68 | R11: 1474.86 | S11: 1469.1 | T11: 1532.14 | U11: 1532.14 | V11: 1594.72 | W11: 1588.22 | X11: 1648.04 | Y11: 1696.94 | Z11: 1696.94 | AA11: 1753.21 | AB11: 1767.09 | AC11: 1539.06 | AD11: 1503.27 | AE11: 1503.27 | AF11: 1503.27 | AG11: 1503.27 | AH11: 1503.27 | AI11: 1503.27 | AK11: 1503.27 | AL11: 1503.27 | AM11: 1503.27 | AN11: 1503.27
A12: CNYKRW_avg | C12: 원/중국원(평균) | E12: 185.14 | F12: 177.65 | G12: 189.93 | H12: 190.76 | I12: 195.79 | J12: 191.09 | K12: 191.93 | L12: 186.59 | M12: 187.45 | N12: 181.28 | O12: 182.86 | P12: 184.52 | Q12: 185.04 | R12: 189.35 | S12: 189.24 | T12: 194.24 | U12: 189.49 | V12: 199.63 | W12: 193.41 | X12: 193.79 | Y12: 204.38 | Z12: 197.8 | AA12: 211.75 | AB12: 220.8 | AC12: 210.43 | AD12: 200.69 | AE12: 213.75 | AF12: 200.46 | AG12: 200.46 | AH12: 200.46 | AI12: 200.46 | AK12: 200.46 | AL12: 200.46 | AM12: 200.46 | AN12: 200.46
A13: CNYKRW_end | C13: 원/중국원(기말) | E13: 187.13 | F13: 187.13 | G13: 191.38 | H13: 194.13 | I13: 201.92 | J13: 182.67 | K13: 182.67 | L13: 189.97 | M13: 181.8 | N13: 184.26 | O13: 182.61 | P13: 182.61 | Q13: 186.66 | R13: 189.7 | S13: 187.12 | T13: 202.04 | U13: 202.04 | V13: 203.3 | W13: 189.14 | X13: 197.16 | Y13: 206.28 | Z13: 206.28 | AA13: 220.97 | AB13: 228.56 | AC13: 202.16 | AD13: 200.46 | AE13: 200.46 | AF13: 200.46 | AG13: 200.46 | AH13: 200.46 | AI13: 200.46 | AK13: 200.46 | AL13: 200.46 | AM13: 200.46 | AN13: 200.46
B14: 1b. 종가
A15: price_close_end | C15: 종가(기말) | E15: 10850 | G15: 10450 | H15: 13700 | I15: 16400 | J15: 16100 | L15: 16920 | M15: 18430 | N15: 17990 | O15: 14730 | Q15: 12280 | R15: 12980 | S15: 13660 | T15: 17660 | V15: 20650 | W15: 21100 | X15: 25800 | Y15: 21700 | AA15: 35000 | AB15: 24650 | AC15: 28150 | AD15: 26200
A16: price_high | C16: 종가(최고) | E16: 13000 | G16: 12000 | H16: 14200 | I16: 20200 | J16: 19200 | L16: 17950 | M16: 19920 | N16: 22650 | O16: 18100 | Q16: 14750 | R16: 16050 | S16: 17920 | T16: 18650 | V16: 27000 | W16: 23700 | X16: 32300 | Y16: 30200 | AA16: 38650 | AB16: 51300 | AC16: 29650 | AD16: 29250
A17: price_low | C17: 종가(최저) | E17: 9960 | G17: 9330 | H17: 9810 | I17: 11350 | J17: 14250 | L17: 14500 | M17: 15870 | N17: 17580 | O17: 13810 | Q17: 11440 | R17: 11130 | S17: 12270 | T17: 11880 | V17: 17100 | W17: 17700 | X17: 18660 | Y17: 21500 | AA17: 20750 | AB17: 22900 | AC17: 19420 | AD17: 26100
A18: price_avg | C18: 종가(평균) | E18: 10849.2 | G18: 10539.5 | H18: 11707.9 | I18: 15465.9 | J18: 16645.2 | L18: 15899.7 | M18: 17783.6 | N18: 19757.7 | O18: 15427.2 | Q18: 12963.8 | R18: 12421.7 | S18: 14479.7 | T18: 14842 | V18: 21949.8 | W18: 20637 | X18: 23374 | Y18: 24900 | AA18: 28277.1 | AB18: 36761.5 | AC18: 24219.4 | AD18: 27320
B20: 2. 추정 드라이버 | C20: 실적 열 = subQ 실현값(수식), 추정 열 = 가정(노란 = 모델값 역산, 연녹 = 3절 스칼라 참조)
A21: drv:매출액 | B21: yoy | C21: 매출액 YoY | J21: =IFERROR(subQ!J5/subQ!E5-1,"") | L21: =IFERROR(subQ!L5/subQ!G5-1,"") | M21: =IFERROR(subQ!M5/subQ!H5-1,"") | N21: =IFERROR(subQ!N5/subQ!I5-1,"") | O21: =IFERROR(subQ!O5/subQ!J5-1,"") | Q21: =IFERROR(subQ!Q5/subQ!L5-1,"") | R21: =IFERROR(subQ!R5/subQ!M5-1,"") | S21: =IFERROR(subQ!S5/subQ!N5-1,"") | T21: =IFERROR(subQ!T5/subQ!O5-1,"") | V21: =IFERROR(subQ!V5/subQ!Q5-1,"") | W21: =IFERROR(subQ!W5/subQ!R5-1,"") | X21: =IFERROR(subQ!X5/subQ!S5-1,"") | Y21: =IFERROR(subQ!Y5/subQ!T5-1,"") | AA21: =IFERROR(subQ!AA5/subQ!V5-1,"") | AB21: =IFERROR(subQ!AB5/subQ!W5-1,"") | AC21: 0.24797059 | AD21: 0.24796402 | AF21: 0.24796916 | AG21: 0.24797049 | AH21: 0.12398134 | AI21: 0.12398346 | AK21: 0.12398103 | AL21: 0.12397619 | AM21: 0.061987198 | AN21: 0.061995277
A22: drv:판관비 | B22: ratio | C22: 판관비율(/매출) | E22: =IFERROR(subQ!E8/subQ!E5,"") | F22: =IFERROR(subQ!F8/subQ!F5,"") | G22: =IFERROR(subQ!G8/subQ!G5,"") | H22: =IFERROR(subQ!H8/subQ!H5,"") | I22: =IFERROR(subQ!I8/subQ!I5,"") | J22: =IFERROR(subQ!J8/subQ!J5,"") | K22: =IFERROR(subQ!K8/subQ!K5,"") | L22: =IFERROR(subQ!L8/subQ!L5,"") | ... AB22: =IFERROR(subQ!AB8/subQ!AB5,"") | AC22: =$D$51 | AD22: =$D$51 | AE22: =IFERROR(subQ!AE8/subQ!AE5,"") | AF22: =$D$51 | AG22: =$D$51 | AH22: =$D$51 | AI22: =$D$51 | AJ22: =IFERROR(subQ!AJ8/subQ!AJ5,"") | AK22: =$D$51 | AL22: =$D$51 | AM22: =$D$51 | AN22: =$D$51 | AO22: =IFERROR(subQ!AO8/subQ!AO5,"")
A23: drv:영업이익 | B23: ratio | C23: 영업이익률(OPM) | E23: =IFERROR(subQ!E9/subQ!E5,"") | F23: =IFERROR(subQ!F9/subQ!F5,"") | G23: =IFERROR(subQ!G9/subQ!G5,"") | H23: =IFERROR(subQ!H9/subQ!H5,"") | I23: =IFERROR(subQ!I9/subQ!I5,"") | J23: =IFERROR(subQ!J9/subQ!J5,"") | K23: =IFERROR(subQ!K9/subQ!K5,"") | L23: =IFERROR(subQ!L9/subQ!L5,"") | ... AB23: =IFERROR(subQ!AB9/subQ!AB5,"") | AC23: 0.12045786 | AD23: 0.12046408 | AE23: =IFERROR(subQ!AE9/subQ!AE5,"") | AF23: 0.12046515 | AG23: 0.12046464 | AH23: 0.12046304 | AI23: 0.12046136 | AJ23: =IFERROR(subQ!AJ9/subQ!AJ5,"") | AK23: 0.12046063 | AL23: 0.12045731 | AM23: 0.12046504 | AN23: 0.12045875 | AO23: =IFERROR(subQ!AO9/subQ!AO5,"")
A24: drv:외환손익 | B24: abs | C24: 외환손익 (가정, 억원) | E24: =subQ!E13 | F24: =subQ!F13 | G24: =subQ!G13 | H24: =subQ!H13 | I24: =subQ!I13 | J24: =subQ!J13 | K24: =subQ!K13 | L24: =subQ!L13 | ... AB24: =subQ!AB13 | AC24: 0 | AD24: 0 | AE24: =subQ!AE13 | AF24: 0 | AG24: 0 | AH24: 0 | AI24: 0 | AJ24: =subQ!AJ13 | AK24: 0 | AL24: 0 | AM24: 0 | AN24: 0 | AO24: =subQ!AO13
A25: drv:파생상품손익 | B25: abs | C25: 파생상품손익 (가정, 억원) | E25: =subQ!E14 | F25: =subQ!F14 | G25: =subQ!G14 | H25: =subQ!H14 | I25: =subQ!I14 | J25: =subQ!J14 | K25: =subQ!K14 | L25: =subQ!L14 | ... AB25: =subQ!AB14 | AC25: 0 | AD25: 0 | AE25: =subQ!AE14 | AF25: 0 | AG25: 0 | AH25: 0 | AI25: 0 | AJ25: =subQ!AJ14 | AK25: 0 | AL25: 0 | AM25: 0 | AN25: 0 | AO25: =subQ!AO14
A26: drv:기타금융손익 | B26: abs | C26: 기타금융손익 (가정, 억원) | E26: =subQ!E15 | F26: =subQ!F15 | G26: =subQ!G15 | H26: =subQ!H15 | I26: =subQ!I15 | J26: =subQ!J15 | K26: =subQ!K15 | L26: =subQ!L15 | ... AB26: =subQ!AB15 | AC26: 0 | AD26: 0 | AE26: =subQ!AE15 | AF26: 0 | AG26: 0 | AH26: 0 | AI26: 0 | AJ26: =subQ!AJ15 | AK26: 0 | AL26: 0 | AM26: 0 | AN26: 0 | AO26: =subQ!AO15
A27: drv:기타영업외손익 | B27: abs | C27: 기타영업외손익 (가정, 억원) | E27: =subQ!E16 | F27: =subQ!F16 | G27: =subQ!G16 | H27: =subQ!H16 | I27: =subQ!I16 | J27: =subQ!J16 | K27: =subQ!K16 | L27: =subQ!L16 | ... AB27: =subQ!AB16 | AC27: 0 | AD27: 0 | AE27: =subQ!AE16 | AF27: 0 | AG27: 0 | AH27: 0 | AI27: 0 | AJ27: =subQ!AJ16 | AK27: 0 | AL27: 0 | AM27: 0 | AN27: 0 | AO27: =subQ!AO16
A28: drv:법인세비용 | B28: tax | C28: 법인세율(/세전) — 법인세 = MAX(세전,0) × 세율 | E28: =IFERROR(subQ!E18/subQ!E17,"") | F28: =IFERROR(subQ!F18/subQ!F17,"") | G28: =IFERROR(subQ!G18/subQ!G17,"") | H28: =IFERROR(subQ!H18/subQ!H17,"") | I28: =IFERROR(subQ!I18/subQ!I17,"") | J28: =IFERROR(subQ!J18/subQ!J17,"") | K28: =IFERROR(subQ!K18/subQ!K17,"") | L28: =IFERROR(subQ!L18/subQ!L17,"") | ... AB28: =IFERROR(subQ!AB18/subQ!AB17,"") | AC28: =$D$50 | AD28: =$D$50 | AE28: =IFERROR(subQ!AE18/subQ!AE17,"") | AF28: =$D$50 | AG28: =$D$50 | AH28: =$D$50 | AI28: =$D$50 | AJ28: =IFERROR(subQ!AJ18/subQ!AJ17,"") | AK28: =$D$50 | AL28: =$D$50 | AM28: =$D$50 | AN28: =$D$50 | AO28: =IFERROR(subQ!AO18/subQ!AO17,"")
A29: drv:지배주주순이익 | B29: ratio | C29: 지배주주 비중(/당기순이익) | E29: =IFERROR(subQ!E20/subQ!E19,"") | F29: =IFERROR(subQ!F20/subQ!F19,"") | G29: =IFERROR(subQ!G20/subQ!G19,"") | H29: =IFERROR(subQ!H20/subQ!H19,"") | I29: =IFERROR(subQ!I20/subQ!I19,"") | J29: =IFERROR(subQ!J20/subQ!J19,"") | K29: =IFERROR(subQ!K20/subQ!K19,"") | L29: =IFERROR(subQ!L20/subQ!L19,"") | ... AB29: =IFERROR(subQ!AB20/subQ!AB19,"") | AC29: =$D$52 | AD29: =$D$52 | AE29: =IFERROR(subQ!AE20/subQ!AE19,"") | AF29: =$D$52 | AG29: =$D$52 | AH29: =$D$52 | AI29: =$D$52 | AJ29: =IFERROR(subQ!AJ20/subQ!AJ19,"") | AK29: =$D$52 | AL29: =$D$52 | AM29: =$D$52 | AN29: =$D$52 | AO29: =IFERROR(subQ!AO20/subQ!AO19,"")
A30: drv:부채총계 | B30: qoq | C30: 부채총계 QoQ | G30: =IFERROR(subQ!G22/subQ!E22-1,"") | H30: =IFERROR(subQ!H22/subQ!G22-1,"") | I30: =IFERROR(subQ!I22/subQ!H22-1,"") | J30: =IFERROR(subQ!J22/subQ!I22-1,"") | L30: =IFERROR(subQ!L22/subQ!J22-1,"") | M30: =IFERROR(subQ!M22/subQ!L22-1,"") | N30: =IFERROR(subQ!N22/subQ!M22-1,"") | O30: =IFERROR(subQ!O22/subQ!N22-1,"") | Q30: =IFERROR(subQ!Q22/subQ!O22-1,"") | R30: =IFERROR(subQ!R22/subQ!Q22-1,"") | S30: =IFERROR(subQ!S22/subQ!R22-1,"") | T30: =IFERROR(subQ!T22/subQ!S22-1,"") | V30: =IFERROR(subQ!V22/subQ!T22-1,"") | W30: =IFERROR(subQ!W22/subQ!V22-1,"") | X30: =IFERROR(subQ!X22/subQ!W22-1,"") | Y30: =IFERROR(subQ!Y22/subQ!X22-1,"") | AA30: =IFERROR(subQ!AA22/subQ!Y22-1,"") | AB30: =IFERROR(subQ!AB22/subQ!AA22-1,"") | AC30: -2.697e-06 | AD30: 0 | AF30: 0 | AG30: 0 | AH30: 0 | AI30: 0 | AK30: 0 | AL30: 0 | AM30: 0 | AN30: 0
A31: drv:자본총계 | B31: roll | C31: 자본총계 기타변동(배당 등, 억원) | G31: =IFERROR(subQ!E23+subQ!G19-subQ!G23,"") | H31: =IFERROR(subQ!G23+subQ!H19-subQ!H23,"") | I31: =IFERROR(subQ!H23+subQ!I19-subQ!I23,"") | J31: =IFERROR(subQ!I23+subQ!J19-subQ!J23,"") | L31: =IFERROR(subQ!J23+subQ!L19-subQ!L23,"") | M31: =IFERROR(subQ!L23+subQ!M19-subQ!M23,"") | N31: =IFERROR(subQ!M23+subQ!N19-subQ!N23,"") | O31: =IFERROR(subQ!N23+subQ!O19-subQ!O23,"") | Q31: =IFERROR(subQ!O23+subQ!Q19-subQ!Q23,"") | R31: =IFERROR(subQ!Q23+subQ!R19-subQ!R23,"") | S31: =IFERROR(subQ!R23+subQ!S19-subQ!S23,"") | T31: =IFERROR(subQ!S23+subQ!T19-subQ!T23,"") | V31: =IFERROR(subQ!T23+subQ!V19-subQ!V23,"") | W31: =IFERROR(subQ!V23+subQ!W19-subQ!W23,"") | X31: =IFERROR(subQ!W23+subQ!X19-subQ!X23,"") | Y31: =IFERROR(subQ!X23+subQ!Y19-subQ!Y23,"") | AA31: =IFERROR(subQ!Y23+subQ!AA19-subQ!AA23,"") | AB31: =IFERROR(subQ!AA23+subQ!AB19-subQ!AB23,"") | AC31: 0.001426637 | AD31: -0.006432463 | AF31: 0.005158254 | AG31: 137.41641 | AH31: 0.001358742 | AI31: -0.002688399 | AK31: -0.003877286 | AL31: 137.41489 | AM31: -0.001249449 | AN31: 0.000347983
A32: drv:지배주주지분 | B32: roll | C32: 지배주주지분 기타변동(배당 등, 억원) | G32: =IFERROR(subQ!E24+subQ!G20-subQ!G24,"") | H32: =IFERROR(subQ!G24+subQ!H20-subQ!H24,"") | I32: =IFERROR(subQ!H24+subQ!I20-subQ!I24,"") | J32: =IFERROR(subQ!I24+subQ!J20-subQ!J24,"") | L32: =IFERROR(subQ!J24+subQ!L20-subQ!L24,"") | M32: =IFERROR(subQ!L24+subQ!M20-subQ!M24,"") | N32: =IFERROR(subQ!M24+subQ!N20-subQ!N24,"") | O32: =IFERROR(subQ!N24+subQ!O20-subQ!O24,"") | Q32: =IFERROR(subQ!O24+subQ!Q20-subQ!Q24,"") | R32: =IFERROR(subQ!Q24+subQ!R20-subQ!R24,"") | S32: =IFERROR(subQ!R24+subQ!S20-subQ!S24,"") | T32: =IFERROR(subQ!S24+subQ!T20-subQ!T24,"") | V32: =IFERROR(subQ!T24+subQ!V20-subQ!V24,"") | W32: =IFERROR(subQ!V24+subQ!W20-subQ!W24,"") | X32: =IFERROR(subQ!W24+subQ!X20-subQ!X24,"") | Y32: =IFERROR(subQ!X24+subQ!Y20-subQ!Y24,"") | AA32: =IFERROR(subQ!Y24+subQ!AA20-subQ!AA24,"") | AB32: =IFERROR(subQ!AA24+subQ!AB20-subQ!AB24,"") | AC32: -0.002710044 | AD32: -0.002047167 | AF32: 0.006312485 | AG32: 137.41185 | AH32: 0.000648768 | AI32: 0.001121743 | AK32: -0.007415714 | AL32: 137.41378 | AM32: -0.001036902 | AN32: -0.003067668
A33: drv:총차입금 | B33: qoq | C33: 총차입금 QoQ | G33: =IFERROR(subQ!G25/subQ!E25-1,"") | H33: =IFERROR(subQ!H25/subQ!G25-1,"") | I33: =IFERROR(subQ!I25/subQ!H25-1,"") | J33: =IFERROR(subQ!J25/subQ!I25-1,"") | L33: =IFERROR(subQ!L25/subQ!J25-1,"") | M33: =IFERROR(subQ!M25/subQ!L25-1,"") | N33: =IFERROR(subQ!N25/subQ!M25-1,"") | O33: =IFERROR(subQ!O25/subQ!N25-1,"") | Q33: =IFERROR(subQ!Q25/subQ!O25-1,"") | R33: =IFERROR(subQ!R25/subQ!Q25-1,"") | S33: =IFERROR(subQ!S25/subQ!R25-1,"") | T33: =IFERROR(subQ!T25/subQ!S25-1,"") | V33: =IFERROR(subQ!V25/subQ!T25-1,"") | W33: =IFERROR(subQ!W25/subQ!V25-1,"") | X33: =IFERROR(subQ!X25/subQ!W25-1,"") | Y33: =IFERROR(subQ!Y25/subQ!X25-1,"") | AA33: =IFERROR(subQ!AA25/subQ!Y25-1,"") | AB33: =IFERROR(subQ!AB25/subQ!AA25-1,"")
A34: drv:순차입금 | B34: qoq | C34: 순차입금 QoQ | G34: =IFERROR(subQ!G26/subQ!E26-1,"") | H34: =IFERROR(subQ!H26/subQ!G26-1,"") | I34: =IFERROR(subQ!I26/subQ!H26-1,"") | J34: =IFERROR(subQ!J26/subQ!I26-1,"") | L34: =IFERROR(subQ!L26/subQ!J26-1,"") | M34: =IFERROR(subQ!M26/subQ!L26-1,"") | N34: =IFERROR(subQ!N26/subQ!M26-1,"") | O34: =IFERROR(subQ!O26/subQ!N26-1,"") | Q34: =IFERROR(subQ!Q26/subQ!O26-1,"") | R34: =IFERROR(subQ!R26/subQ!Q26-1,"") | S34: =IFERROR(subQ!S26/subQ!R26-1,"") | T34: =IFERROR(subQ!T26/subQ!S26-1,"") | V34: =IFERROR(subQ!V26/subQ!T26-1,"") | W34: =IFERROR(subQ!W26/subQ!V26-1,"") | X34: =IFERROR(subQ!X26/subQ!W26-1,"") | Y34: =IFERROR(subQ!Y26/subQ!X26-1,"") | AA34: =IFERROR(subQ!AA26/subQ!Y26-1,"") | AB34: =IFERROR(subQ!AB26/subQ!AA26-1,"")
A35: drv:이자발생자산 | B35: qoq | C35: 이자발생자산 QoQ | G35: =IFERROR(subQ!G27/subQ!E27-1,"") | H35: =IFERROR(subQ!H27/subQ!G27-1,"") | I35: =IFERROR(subQ!I27/subQ!H27-1,"") | J35: =IFERROR(subQ!J27/subQ!I27-1,"") | L35: =IFERROR(subQ!L27/subQ!J27-1,"") | M35: =IFERROR(subQ!M27/subQ!L27-1,"") | N35: =IFERROR(subQ!N27/subQ!M27-1,"") | O35: =IFERROR(subQ!O27/subQ!N27-1,"") | Q35: =IFERROR(subQ!Q27/subQ!O27-1,"") | R35: =IFERROR(subQ!R27/subQ!Q27-1,"") | S35: =IFERROR(subQ!S27/subQ!R27-1,"") | T35: =IFERROR(subQ!T27/subQ!S27-1,"") | V35: =IFERROR(subQ!V27/subQ!T27-1,"") | W35: =IFERROR(subQ!W27/subQ!V27-1,"") | X35: =IFERROR(subQ!X27/subQ!W27-1,"") | Y35: =IFERROR(subQ!Y27/subQ!X27-1,"") | AA35: =IFERROR(subQ!AA27/subQ!Y27-1,"") | AB35: =IFERROR(subQ!AB27/subQ!AA27-1,"") | AC35: 0.088846424 | AD35: 0.081284272 | AF35: 0.077033324 | AG35: -0.020670265 | AH35: 0.080935126 | AI35: 0.074585012 | AK35: 0.071123909 | AL35: -0.009106642 | AM35: 0.07047619 | AN35: 0.065582859
A36: drv:현금및현금성자산 | B36: qoq | C36: 현금및현금성자산 QoQ | G36: =IFERROR(subQ!G28/subQ!E28-1,"") | H36: =IFERROR(subQ!H28/subQ!G28-1,"") | I36: =IFERROR(subQ!I28/subQ!H28-1,"") | J36: =IFERROR(subQ!J28/subQ!I28-1,"") | L36: =IFERROR(subQ!L28/subQ!J28-1,"") | M36: =IFERROR(subQ!M28/subQ!L28-1,"") | N36: =IFERROR(subQ!N28/subQ!M28-1,"") | O36: =IFERROR(subQ!O28/subQ!N28-1,"") | Q36: =IFERROR(subQ!Q28/subQ!O28-1,"") | R36: =IFERROR(subQ!R28/subQ!Q28-1,"") | S36: =IFERROR(subQ!S28/subQ!R28-1,"") | T36: =IFERROR(subQ!T28/subQ!S28-1,"") | V36: =IFERROR(subQ!V28/subQ!T28-1,"") | W36: =IFERROR(subQ!W28/subQ!V28-1,"") | X36: =IFERROR(subQ!X28/subQ!W28-1,"") | Y36: =IFERROR(subQ!Y28/subQ!X28-1,"") | AA36: =IFERROR(subQ!AA28/subQ!Y28-1,"") | AB36: =IFERROR(subQ!AB28/subQ!AA28-1,"")
A37: drv:CAPEX | B37: yoy | C37: CAPEX YoY | J37: =IFERROR(subQ!J29/subQ!E29-1,"") | L37: =IFERROR(subQ!L29/subQ!G29-1,"") | M37: =IFERROR(subQ!M29/subQ!H29-1,"") | N37: =IFERROR(subQ!N29/subQ!I29-1,"") | O37: =IFERROR(subQ!O29/subQ!J29-1,"") | Q37: =IFERROR(subQ!Q29/subQ!L29-1,"") | R37: =IFERROR(subQ!R29/subQ!M29-1,"") | S37: =IFERROR(subQ!S29/subQ!N29-1,"") | T37: =IFERROR(subQ!T29/subQ!O29-1,"") | V37: =IFERROR(subQ!V29/subQ!Q29-1,"") | W37: =IFERROR(subQ!W29/subQ!R29-1,"") | X37: =IFERROR(subQ!X29/subQ!S29-1,"") | Y37: =IFERROR(subQ!Y29/subQ!T29-1,"") | AA37: =IFERROR(subQ!AA29/subQ!V29-1,"") | AB37: =IFERROR(subQ!AB29/subQ!W29-1,"") | AC37: -0.51739673 | AD37: -0.17378461 | AF37: 0.26701409 | AG37: 1.2566078 | AH37: 0 | AI37: 0 | AK37: 0 | AL37: 0 | AM37: 0 | AN37: 0
A38: drv:영업활동현금흐름 | B38: yoy | C38: 영업활동현금흐름 YoY | J38: =IFERROR(subQ!J30/subQ!E30-1,"") | L38: =IFERROR(subQ!L30/subQ!G30-1,"") | M38: =IFERROR(subQ!M30/subQ!H30-1,"") | N38: =IFERROR(subQ!N30/subQ!I30-1,"") | O38: =IFERROR(subQ!O30/subQ!J30-1,"") | Q38: =IFERROR(subQ!Q30/subQ!L30-1,"") | R38: =IFERROR(subQ!R30/subQ!M30-1,"") | S38: =IFERROR(subQ!S30/subQ!N30-1,"") | T38: =IFERROR(subQ!T30/subQ!O30-1,"") | V38: =IFERROR(subQ!V30/subQ!Q30-1,"") | W38: =IFERROR(subQ!W30/subQ!R30-1,"") | X38: =IFERROR(subQ!X30/subQ!S30-1,"") | Y38: =IFERROR(subQ!Y30/subQ!T30-1,"") | AA38: =IFERROR(subQ!AA30/subQ!V30-1,"") | AB38: =IFERROR(subQ!AB30/subQ!W30-1,"")
A39: drv:주식수 | B39: qoq | C39: 주식수 QoQ | G39: =IFERROR(subQ!G31/subQ!E31-1,"") | H39: =IFERROR(subQ!H31/subQ!G31-1,"") | I39: =IFERROR(subQ!I31/subQ!H31-1,"") | J39: =IFERROR(subQ!J31/subQ!I31-1,"") | L39: =IFERROR(subQ!L31/subQ!J31-1,"") | M39: =IFERROR(subQ!M31/subQ!L31-1,"") | N39: =IFERROR(subQ!N31/subQ!M31-1,"") | O39: =IFERROR(subQ!O31/subQ!N31-1,"") | Q39: =IFERROR(subQ!Q31/subQ!O31-1,"") | R39: =IFERROR(subQ!R31/subQ!Q31-1,"") | S39: =IFERROR(subQ!S31/subQ!R31-1,"") | T39: =IFERROR(subQ!T31/subQ!S31-1,"") | V39: =IFERROR(subQ!V31/subQ!T31-1,"") | W39: =IFERROR(subQ!W31/subQ!V31-1,"") | X39: =IFERROR(subQ!X31/subQ!W31-1,"") | Y39: =IFERROR(subQ!Y31/subQ!X31-1,"") | AA39: =IFERROR(subQ!AA31/subQ!Y31-1,"") | AB39: =IFERROR(subQ!AB31/subQ!AA31-1,"") | AC39: 0 | AD39: 0 | AF39: 0 | AG39: 0 | AH39: 0 | AI39: 0 | AK39: 0 | AL39: 0 | AM39: 0 | AN39: 0
A40: drv:DPS | B40: abs | C40: DPS (가정, 원) | E40: =subQ!E35 | F40: =subQ!F35 | G40: =subQ!G35 | H40: =subQ!H35 | I40: =subQ!I35 | J40: =subQ!J35 | K40: =subQ!K35 | L40: =subQ!L35 | ... AB40: =subQ!AB35 | AD40: 535 | AE40: =subQ!AE35 | AI40: 535 | AJ40: =subQ!AJ35 | AN40: 535 | AO40: =subQ!AO35
B42: 3. 밸류에이션·스칼라 | C42: 노란 셀 = 가정. '연결' 표시는 추정 전 분기 수식이 이 셀을 참조한다는 뜻
...

Sheet BS연결
B1: (백만원) | C1: 이름: BS연결H | E1: 4Q21 | F1: 2021 | G1: 1Q22 | H1: 2Q22 | I1: 3Q22 | J1: 4Q22 | K1: 2022 | L1: 1Q23 | M1: 2Q23 | N1: 3Q23 | O1: 4Q23 | P1: 2023 | Q1: 1Q24 | R1: 2Q24 | S1: 3Q24 | T1: 4Q24 | U1: 2024 | V1: 1Q25 | W1: 2Q25 | X1: 3Q25 | Y1: 4Q25 | Z1: 2025 | AA1: 1Q26 | AB1: 2Q26 | AC1: 3Q26 | AD1: 4Q26 | AE1: 2026 | AF1: 1Q27 | AG1: 2Q27 | AH1: 3Q27 | AI1: 4Q27 | AJ1: 2027 | AK1: 1Q28 | AL1: 2Q28 | AM1: 3Q28 | AN1: 4Q28 | AO1: 2028
B2: 연결 | D2: fin json(kship_fin.py)
B3: 태광(연) | C3: UPDATE: 26-10-11 | E3: 1 | F3: 2 | G3: 3 | H3: 4 | I3: 5 | J3: 6 | K3: 7 | L3: 8 | M3: 9 | N3: 10 | O3: 11 | P3: 12 | Q3: 13 | R3: 14 | S3: 15 | T3: 16 | U3: 17 | V3: 18 | W3: 19 | X3: 20 | Y3: 21 | Z3: 22 | AA3: 23 | AB3: 24 | AC3: 25 | AD3: 26 | AE3: 27 | AF3: 28 | AG3: 29 | AH3: 30 | AI3: 31 | AJ3: 32 | AK3: 33 | AL3: 34 | AM3: 35 | AN3: 36 | AO3: 37
B4: Account Code | C4: AccountNAME | E4: 2021.12 | F4: 2021.12A | G4: 2022.03 | H4: 2022.06 | I4: 2022.09 | J4: 2022.12 | K4: 2022.12A | L4: 2023.03 | M4: 2023.06 | N4: 2023.09 | O4: 2023.12 | P4: 2023.12A | Q4: 2024.03 | R4: 2024.06 | S4: 2024.09 | T4: 2024.12 | U4: 2024.12A | V4: 2025.03 | W4: 2025.06 | X4: 2025.09 | Y4: 2025.12 | Z4: 2025.12A | AA4: 2026.03 | AB4: 2026.06 | AC4: 2026.09 | AD4: 2026.12 | AE4: 2026.12A | AF4: 2027.03 | AG4: 2027.06 | AH4: 2027.09 | AI4: 2027.12 | AJ4: 2027.12A | AK4: 2028.03 | AL4: 2028.06 | AM4: 2028.09 | AN4: 2028.12 | AO4: 2028.12A
A5: 1 | C5: 유동자산 | E5: 234559.23 | F5: 234559.23 | G5: 234461.35 | H5: 248409.7 | I5: 296899.58 | J5: 312707.86 | K5: 312707.86 | L5: 317108.74 | M5: 305897.59 | N5: 314132.32 | O5: 303514.7 | P5: 303514.7 | Q5: 311867.18 | R5: 297125.07 | S5: 295044.38 | T5: 308837.75 | U5: 308837.75 | V5: 315184.15 | W5: 324760.5 | X5: 380332.7 | Y5: 415239.28 | Z5: 415239.28 | AA5: 443932.37 | AB5: 514576.86
A6: 1 | C6: 현금및현금성자산 | E6: 42139.37 | F6: 42139.37 | G6: 33900.03 | H6: 32641.44 | I6: 57472.58 | J6: 47228.3 | K6: 47228.3 | L6: 37151.72 | M6: 39634.42 | N6: 26507.16 | O6: 30872.63 | P6: 30872.63 | Q6: 52296.02 | R6: 28421.61 | S6: 39473.29 | T6: 32062.22 | U6: 32062.22 | V6: 34806.43 | W6: 29598.46 | X6: 31977.01 | Y6: 35596.04 | Z6: 35596.04 | AA6: 42988.67 | AB6: 50147.66
A7: 1 | C7: 단기금융상품 | E7: 6736.71 | F7: 6736.71 | G7: 7094.19 | H7: 7032.87 | I7: 17356.18 | J7: 28793.26 | K7: 28793.26 | L7: 36508.73 | M7: 32853.19 | N7: 33011.18 | O7: 35738.28 | P7: 35738.28 | Q7: 32047.84 | R7: 28494.54 | S7: 28311.97
A8: 1 | C8: 단기금융자산 | E8: 6736.71 | F8: 6736.71 | G8: 7094.19 | H8: 7032.87 | I8: 17356.18 | J8: 28793.26 | K8: 28793.26 | L8: 36508.73 | M8: 32853.19 | N8: 33011.18 | O8: 35738.28 | P8: 35738.28 | Q8: 32047.84 | R8: 28494.54 | S8: 28311.97
A9: 1 | C9: 매출채권및기타채권 | E9: 57041.18 | F9: 57041.18 | G9: 64324.36 | H9: 75387.68 | I9: 78509.07 | J9: 73647.2 | K9: 73647.2 | L9: 77759.23 | M9: 77482.26 | N9: 68301.3 | O9: 65341.43 | P9: 65341.43 | Q9: 63864.4 | R9: 60247.78 | S9: 60615.72 | T9: 64451.52 | U9: 64451.52 | V9: 58913.1 | W9: 66205.99 | X9: 74405.79 | Y9: 74455.91 | Z9: 74455.91 | AA9: 80960.6 | AB9: 85500.51
A10: 1 | C10: 기타유동금융자산 | E10: 5737.56 | F10: 5737.56 | G10: 9786.47 | H10: 11722.97 | I10: 18801.63 | J10: 30546.47 | K10: 30546.47 | L10: 37066.72 | M10: 25616.97 | N10: 58087.69 | O10: 45942.23 | P10: 45942.23 | Q10: 47987.12 | R10: 61403.64 | S10: 46312.56 | T10: 33518.65 | U10: 33518.65 | V10: 34723.19 | W10: 31218 | X10: 21483.62 | Y10: 20314.31 | Z10: 20314.31 | AA10: 10429.69 | AB10: 14781.62
A11: 1 | C11: 재고자산 | E11: 122174.85 | F11: 122174.85 | G11: 117897.08 | H11: 121314.95 | I11: 124299.44 | J11: 130243.16 | K11: 130243.16 | L11: 126389.4 | M11: 127834.67 | N11: 126588.77 | O11: 124326.72 | P11: 124326.72 | Q11: 114121.3 | R11: 117077.86 | S11: 117995.25 | T11: 123155.71 | U11: 123155.71 | V11: 130072.66 | W11: 136654.07 | X11: 141510.26 | Y11: 151819.31 | Z11: 151819.31 | AA11: 147274.39 | AB11: 143956.53
A12: 1 | C12: 당기법인세자산(선급법인세) | E12: 10.19 | F12: 10.19 | G12: 11.34 | H12: 2.14 | I12: 25.11 | J12: 55.66 | K12: 55.66 | L12: 155 | M12: 59.45 | N12: 118.85 | O12: 218.11 | P12: 218.11 | Q12: 71.13 | R12: 109.7 | S12: 317.5 | T12: 238.3 | U12: 238.3 | V12: 132.56 | W12: 121.87 | X12: 212.83 | Y12: 168.88 | Z12: 168.88 | AA12: 184.81 | AB12: 13.88
A13: 1 | C13: 기타유동자산 | E13: 719.37 | F13: 719.37 | G13: 1447.88 | H13: 307.67 | I13: 435.56 | J13: 2193.82 | K13: 2193.82 | L13: 2077.94 | M13: 2416.64 | N13: 1517.37 | O13: 1075.3 | P13: 1075.3 | Q13: 1479.37 | R13: 1369.95 | S13: 2018.09 | T13: 1797.78 | U13: 1797.78 | V13: 2038.1 | W13: 1917.27 | X13: 1119.27 | Y13: 2511.37 | Z13: 2511.37 | AA13: 3220.61 | AB13: 2608.11
A14: 1 | C14: 비유동자산 | E14: 270627.22 | F14: 270627.22 | G14: 276409.66 | H14: 277859.66 | I14: 284433.96 | J14: 281287.28 | K14: 281287.28 | L14: 287071.83 | M14: 314264.96 | N14: 312130.68 | O14: 322780.54 | P14: 322780.54 | Q14: 333320.8 | R14: 347620.24 | S14: 357396.91 | T14: 351501.26 | U14: 351501.26 | V14: 359518.24 | W14: 358904.68 | X14: 344413.25 | Y14: 325576.34 | Z14: 325576.34 | AA14: 329624.68 | AB14: 336171.02
A15: 1 | C15: 장기금융자산 | E15: 34968.87 | F15: 34968.87 | G15: 38753.09 | H15: 38717.62 | I15: 43840.98 | J15: 39393.47 | K15: 39393.47 | L15: 43361.21 | M15: 64872.87 | N15: 53124.15 | O15: 61385.61 | P15: 61385.61 | Q15: 69983.71 | R15: 78473.29 | S15: 88736.93 | T15: 85142.68 | U15: 85142.68 | V15: 90382.97 | W15: 87844.72 | X15: 69426.81 | Y15: 61379.9 | Z15: 61379.9 | AA15: 62413.27 | AB15: 65415.01
A16: 1 | C16: 투자자산 | E16: 34968.87 | F16: 34968.87 | G16: 38753.09 | H16: 38717.62 | I16: 43840.98 | J16: 39393.47 | K16: 39393.47 | L16: 43361.21 | M16: 64872.87 | N16: 53124.15 | O16: 61385.61 | P16: 61385.61 | Q16: 69983.71 | R16: 78473.29 | S16: 88736.93 | T16: 85142.68 | U16: 85142.68 | V16: 90382.97 | W16: 87844.72 | X16: 69426.81 | Y16: 61379.9 | Z16: 61379.9 | AA16: 62413.27 | AB16: 65415.01
A17: 1 | C17: 장기매출채권및기타채권 | E17: 6156.67 | F17: 6156.67 | G17: 8439.22 | H17: 9500.55 | I17: 11343.51 | J17: 11196.11 | K17: 11196.11 | L17: 12100.51 | M17: 12410.27 | N17: 14298.23 | O17: 14756.87 | P17: 14756.87 | Q17: 15578.71 | R17: 15657.48 | T17: 12049.29 | U17: 12049.29 | V17: 11402.09 | W17: 11874.94 | X17: 2413.68 | Y17: 2363.25 | Z17: 2363.25 | AA17: 4190.46 | AB17: 4486.77
A18: 1 | C18: 기타비유동자산 | E18: 1822.24 | F18: 1822.24 | G18: 1812.25 | H18: 1644.93 | I18: 1922.29 | J18: 2336.88 | K18: 2336.88 | L18: 2412.8 | M18: 2233.42 | N18: 2706.12 | O18: 2721.28 | P18: 2721.28 | Q18: 2555.58 | R18: 2996.53 | S18: 2740.72 | T18: 2638.79 | U18: 2638.79 | V18: 3439.48 | W18: 3126.72 | X18: 6875.37 | Y18: 6903.09 | Z18: 6903.09 | AA18: 4604.31 | AB18: 4734.63
A19: 1 | C19: 투자부동산 | E19: 26782.55 | F19: 26782.55 | G19: 26724.92 | H19: 26667.3 | I19: 26609.67 | J19: 26552.04 | K19: 26552.04 | L19: 26494.42 | M19: 24778.67 | N19: 24726.7 | O19: 24674.74 | P19: 24674.74 | Q19: 24622.78 | R19: 24570.81 | S19: 24518.85 | T19: 24466.88 | U19: 24466.88 | V19: 24414.92 | W19: 24362.96 | X19: 24310.99 | Y19: 24259.03 | Z19: 24259.03 | AA19: 24207.06 | AB19: 24155.1
A20: 1 | C20: 유형자산 | E20: 163478.05 | F20: 163478.05 | G20: 163482 | H20: 164376.76 | I20: 163978.77 | J20: 163675.49 | K20: 163675.49 | L20: 164925.56 | M20: 170587.84 | N20: 174684.98 | O20: 177399.55 | P20: 177399.55 | Q20: 178775.5 | R20: 181371.68 | S20: 182149.92 | T20: 183237.06 | U20: 183237.06 | V20: 186121.92 | W20: 188118.35 | X20: 189383.65 | Y20: 188572.56 | Z20: 188572.56 | AA20: 187801.61 | AB20: 185998.35
A21: 1 | C21: 무형자산 | E21: 42730.96 | F21: 42730.96 | G21: 42510.3 | H21: 42264.64 | I21: 42050.87 | J21: 41838.63 | K21: 41838.63 | L21: 41573.76 | M21: 41379.7 | N21: 41138.17 | O21: 40907.54 | P21: 40907.54 | Q21: 40671.7 | R21: 40622.55 | S21: 40392.66 | T21: 40155.42 | U21: 40155.42 | V21: 39945.73 | W21: 39765.88 | X21: 39584.04 | Y21: 31927.35 | Z21: 31927.35 | AA21: 31711.17 | AB21: 31503.12
A22: 1 | C22: 자산총계 | E22: 505186.45 | F22: 505186.45 | G22: 510871.01 | H22: 526269.36 | I22: 581333.54 | J22: 593995.15 | K22: 593995.15 | L22: 604180.57 | M22: 620162.54 | N22: 626263 | O22: 626295.25 | P22: 626295.25 | Q22: 645187.97 | R22: 644745.31 | S22: 652441.28 | T22: 660339.01 | U22: 660339.01 | V22: 674702.39 | W22: 683665.18 | X22: 724745.95 | Y22: 740815.62 | Z22: 740815.62 | AA22: 773557.05 | AB22: 850747.88
A23: 1 | C23: 유동부채 | E23: 28727.05 | F23: 28727.05 | G23: 28559.27 | H23: 30571.49 | I23: 45894.25 | J23: 52478.26 | K23: 52478.26 | L23: 45856.33 | M23: 43508.34 | N23: 37939.96 | O23: 34017.82 | P23: 34017.82 | Q23: 40906.49 | R23: 32954.27 | S23: 34086.74 | T23: 34503.12 | U23: 34503.12 | V23: 44281.74 | W23: 38558.26 | X23: 45159.42 | Y23: 52715.81 | Z23: 52715.81 | AA23: 57364.13 | AB23: 54116.73
A24: 1 | C24: 매입채무및기타채무 | E24: 21968 | F24: 21968 | G24: 18247.04 | H24: 21711.69 | I24: 22470.82 | J24: 33860.15 | K24: 33860.15 | L24: 26398.45 | M24: 29852.57 | N24: 23885.79 | O24: 21914.11 | P24: 21914.11 | Q24: 21403.45 | R24: 23884.22 | S24: 25314.71 | T24: 24807.98 | U24: 24807.98 | V24: 28613.05 | W24: 30089.72 | X24: 30841 | Y24: 34255.56 | Z24: 34255.56 | AA24: 29119.31 | AB24: 28973.14
A25: 1 | C25: 기타유동부채 | E25: 1883.29 | F25: 1883.29 | G25: 2673.48 | H25: 1978.62 | I25: 6509.83 | J25: 7796.78 | K25: 7796.78 | L25: 3061.06 | M25: 2734.96 | N25: 1500.98 | O25: 2076.72 | P25: 2076.72 | Q25: 1673.58 | R25: 1372.41 | S25: 2236.45 | T25: 2927.15 | U25: 2927.15 | V25: 1663.87 | W25: 1455.05 | X25: 537.53 | Y25: 1688.85 | Z25: 1688.85 | AA25: 1146.16 | AB25: 1225.62
A26: 1 | C26: 기타유동금융부채 | E26: 1776.87 | F26: 1776.87 | G26: 4323.71 | H26: 1679.95 | I26: 3033.46 | J26: 1886.38 | K26: 1886.38 | L26: 6362.99 | M26: 1859.09 | N26: 1986.89 | O26: 1960.99 | P26: 1960.99 | Q26: 6385.69 | R26: 2173.13 | S26: 2112.34 | T26: 992.96 | U26: 992.96 | V26: 7471.13 | W26: 1015.93 | X26: 1027.81 | Y26: 5678.54 | Z26: 5678.54 | AA26: 12298.8 | AB26: 5809.91
A27: 1 | C27: 단기금융부채 | E27: 1776.87 | F27: 1776.87 | G27: 4323.71 | H27: 1679.95 | I27: 3033.46 | J27: 1886.38 | K27: 1886.38 | L27: 6362.99 | M27: 1859.09 | N27: 1986.89 | O27: 1960.99 | P27: 1960.99 | Q27: 6385.69 | R27: 2173.13 | S27: 2112.34 | T27: 2144.4 | U27: 2144.4 | V27: 8885.42 | W27: 2343.38 | X27: 2388.46 | Y27: 7031.24 | Z27: 7031.24 | AA27: 13942.91 | AB27: 7515.57
A28: 1 | C28: 당기법인세부채(미지급법인세) | E28: 2991.41 | F28: 2991.41 | G28: 3201.2 | H28: 5089.41 | I28: 13776.68 | J28: 8868.96 | K28: 8868.96 | L28: 9949.18 | M28: 8973.91 | N28: 10479.06 | O28: 8007.92 | P28: 8007.92 | Q28: 11390.68 | R28: 5473.88 | S28: 4376.71 | T28: 4533.84 | U28: 4533.84 | V28: 5036.41 | W28: 4597.18 | X28: 9991.77 | Y28: 8810.54 | Z28: 8810.54 | AA28: 11117.3 | AB28: 14729.48
A29: 1 | C29: 단기충당부채 | E29: 107.48 | F29: 107.48 | G29: 113.85 | H29: 111.83 | I29: 103.47 | J29: 65.98 | K29: 65.98 | L29: 84.66 | M29: 87.81 | N29: 87.23 | O29: 58.08 | P29: 58.08 | Q29: 53.1 | R29: 50.63 | S29: 46.53 | T29: 89.74 | U29: 89.74 | V29: 82.99 | W29: 72.92 | X29: 80.53 | Y29: 127.87 | Z29: 127.87 | AA29: 142.83 | AB29: 168.74
A30: 1 | C30: 비유동부채 | E30: 23378.56 | F30: 23378.56 | G30: 23427.62 | H30: 23188.85 | I30: 19605.29 | J30: 17284.15 | K30: 17284.15 | L30: 17428.54 | M30: 18086.74 | N30: 18102.98 | O30: 16885.99 | P30: 16885.99 | Q30: 17381.88 | R30: 18858.68 | S30: 18457.42 | T30: 16348.53 | U30: 16348.53 | V30: 16951.65 | W30: 18272.56 | X30: 23065.38 | Y30: 18483.09 | Z30: 18483.09 | AA30: 22672.67 | AB30: 34882.51
A31: 1 | C31: 기타비유동부채 | E31: 45.73 | F31: 45.73 | G31: 48.47 | H31: 51.21 | I31: 53.94 | J31: 51.52 | K31: 51.52 | L31: 55.27 | M31: 58.5 | N31: 62 | O31: 58.93 | P31: 58.93 | Q31: 62.61 | R31: 66.29 | S31: 69.98
A32: 1 | C32: 장기매입채무및기타채무 | E32: 5000 | F32: 5000 | G32: 4750 | H32: 4500 | T32: 60.91 | U32: 60.91 | V32: 64.62 | W32: 68.32 | X32: 72.03 | Y32: 64.95 | Z32: 64.95 | AA32: 68.78 | AB32: 72.61
A33: 1 | C33: 확정급여부채 | E33: 2363.97 | F33: 2363.97 | G33: 2734.89 | H33: 2424.78 | I33: 3032.34 | L33: 31.52
A34: 1 | C34: 이연법인세부채 | E34: 5218.06 | F34: 5218.06 | G34: 4959.19 | H34: 5040.6 | I34: 4636.07 | J34: 5590.98 | K34: 5590.98 | L34: 5866.77 | M34: 6306.13 | N34: 5755.8 | O34: 5394.84 | P34: 5394.84 | Q34: 6262.42 | R34: 6682.58 | S34: 6534.5 | T34: 5398.7 | U34: 5398.7 | V34: 5697.33 | W34: 7038.16 | X34: 11748.2 | Y34: 12654.86 | Z34: 12654.86 | AA34: 15975.27 | AB34: 27930.19
A35: 1 | C35: 장기충당부채 | E35: 2272.36 | F35: 2272.36 | G35: 2322.13 | H35: 2569.93 | I35: 2985.97 | J35: 3334.05 | K35: 3334.05 | L35: 3038.86 | M35: 3336.33 | N35: 3455.91 | O35: 3455.41 | P35: 3455.41 | Q35: 3184.91 | R35: 3901.36 | S35: 3747.9 | T35: 3642.15 | U35: 3642.15 | V35: 3146.15 | W35: 3346.25 | X35: 3513.43 | Y35: 3797.78 | Z35: 3797.78 | AA35: 3405.83 | AB35: 3609.07
A36: 1 | C36: 기타비유동금융부채 | E36: 8478.44 | F36: 8478.44 | G36: 8612.94 | H36: 8602.32 | I36: 8896.97 | J36: 8307.6 | K36: 8307.6 | L36: 8436.11 | M36: 8385.77 | N36: 8829.27 | O36: 7976.81 | P36: 7976.81 | Q36: 7871.94 | R36: 8208.44 | S36: 8105.05 | T36: 5484.4 | U36: 5484.4 | V36: 5546.41 | W36: 5609.84 | X36: 5674.71 | Y36: 61.8 | Z36: 61.8 | AA36: 61.8 | AB36: 61.8
A37: 1 | C37: 장기금융부채 | E37: 8478.44 | F37: 8478.44 | G37: 8612.94 | H37: 8602.32 | I37: 8896.97 | J37: 8307.6 | K37: 8307.6 | L37: 8436.11 | M37: 8385.77 | N37: 8829.27 | O37: 7976.81 | P37: 7976.81 | Q37: 7871.94 | R37: 8208.44 | S37: 8105.05 | T37: 7099.41 | U37: 7099.41 | V37: 7716.46 | W37: 7565.77 | X37: 7731.71 | Y37: 1965.49 | Z37: 1965.49 | AA37: 3222.79 | AB37: 3270.64
A38: 1 | C38: 부채총계 | E38: 52105.61 | F38: 52105.61 | G38: 51986.89 | H38: 53760.34 | I38: 65499.54 | J38: 69762.41 | K38: 69762.41 | L38: 63284.87 | M38: 61595.08 | N38: 56042.94 | O38: 50903.81 | P38: 50903.81 | Q38: 58288.38 | R38: 51812.95 | S38: 52544.16 | T38: 50851.65 | U38: 50851.65 | V38: 61233.39 | W38: 56830.82 | X38: 68224.79 | Y38: 71198.89 | Z38: 71198.89 | AA38: 80036.8 | AB38: 88999.24
A39: 1 | C39: 지배주주지분 | E39: 436133.57 | F39: 436133.57 | G39: 441042.44 | H39: 453310.34 | I39: 472915.85 | J39: 480089.17 | K39: 480089.17 | L39: 495190.25 | M39: 512255.34 | N39: 523726.08 | O39: 528792.38 | P39: 528792.38 | Q39: 540739.24 | R39: 550003.28 | S39: 557094.14 | T39: 566047.08 | U39: 566047.08 | V39: 570009.76 | W39: 584929.49 | X39: 613745.74 | Y39: 624576.99 | Z39: 624576.99 | AA39: 646534.42 | AB39: 706581.84
A40: 1 | C40: 자본금 | E40: 13250 | F40: 13250 | G40: 13250 | H40: 13250 | I40: 13250 | J40: 13250 | K40: 13250 | L40: 13250 | M40: 13250 | N40: 13250 | O40: 13250 | P40: 13250 | Q40: 13250 | R40: 13250 | S40: 13250 | T40: 13250 | U40: 13250 | V40: 13250 | W40: 13250 | X40: 13250 | Y40: 13250 | Z40: 13250 | AA40: 13250 | AB40: 13250
...

Sheet BS별도
B1: (백만원) | C1: 이름: BS별도H | E1: 4Q21 | F1: 2021 | G1: 1Q22 | H1: 2Q22 | I1: 3Q22 | J1: 4Q22 | K1: 2022 | L1: 1Q23 | M1: 2Q23 | N1: 3Q23 | O1: 4Q23 | P1: 2023 | Q1: 1Q24 | R1: 2Q24 | S1: 3Q24 | T1: 4Q24 | U1: 2024 | V1: 1Q25 | W1: 2Q25 | X1: 3Q25 | Y1: 4Q25 | Z1: 2025 | AA1: 1Q26 | AB1: 2Q26 | AC1: 3Q26 | AD1: 4Q26 | AE1: 2026 | AF1: 1Q27 | AG1: 2Q27 | AH1: 3Q27 | AI1: 4Q27 | AJ1: 2027 | AK1: 1Q28 | AL1: 2Q28 | AM1: 3Q28 | AN1: 4Q28 | AO1: 2028
B2: 별도 | D2: fin json(kship_fin.py)
B3: 태광(별) | C3: UPDATE: 26-10-11 | E3: 1 | F3: 2 | G3: 3 | H3: 4 | I3: 5 | J3: 6 | K3: 7 | L3: 8 | M3: 9 | N3: 10 | O3: 11 | P3: 12 | Q3: 13 | R3: 14 | S3: 15 | T3: 16 | U3: 17 | V3: 18 | W3: 19 | X3: 20 | Y3: 21 | Z3: 22 | AA3: 23 | AB3: 24 | AC3: 25 | AD3: 26 | AE3: 27 | AF3: 28 | AG3: 29 | AH3: 30 | AI3: 31 | AJ3: 32 | AK3: 33 | AL3: 34 | AM3: 35 | AN3: 36 | AO3: 37
B4: Account Code | C4: AccountNAME | E4: 2021.12 | F4: 2021.12A | G4: 2022.03 | H4: 2022.06 | I4: 2022.09 | J4: 2022.12 | K4: 2022.12A | L4: 2023.03 | M4: 2023.06 | N4: 2023.09 | O4: 2023.12 | P4: 2023.12A | Q4: 2024.03 | R4: 2024.06 | S4: 2024.09 | T4: 2024.12 | U4: 2024.12A | V4: 2025.03 | W4: 2025.06 | X4: 2025.09 | Y4: 2025.12 | Z4: 2025.12A | AA4: 2026.03 | AB4: 2026.06 | AC4: 2026.09 | AD4: 2026.12 | AE4: 2026.12A | AF4: 2027.03 | AG4: 2027.06 | AH4: 2027.09 | AI4: 2027.12 | AJ4: 2027.12A | AK4: 2028.03 | AL4: 2028.06 | AM4: 2028.09 | AN4: 2028.12 | AO4: 2028.12A
A5: 1 | C5: 유동자산 | E5: 216266.88 | F5: 216266.88 | G5: 214975.2 | H5: 228355.5 | I5: 253029.84 | J5: 269367.92 | K5: 269367.92 | L5: 266800.19 | M5: 254925.99 | N5: 263511.68 | O5: 252239.34 | P5: 252239.34 | Q5: 260332.03 | R5: 246927.63 | S5: 244137.34 | T5: 261536.48 | U5: 261536.48 | V5: 268912.84 | W5: 280361.68 | X5: 335292.26 | Y5: 368106.62 | Z5: 368106.62 | AA5: 393664.84 | AB5: 440749.32
A6: 1 | C6: 현금및현금성자산 | E6: 37489.7 | F6: 37489.7 | G6: 29916.02 | H6: 25450.98 | I6: 36545.66 | J6: 39788.18 | K6: 39788.18 | L6: 29508.58 | M6: 31670.32 | N6: 19613.33 | O6: 20700.49 | P6: 20700.49 | Q6: 35597.96 | R6: 15490.5 | S6: 22021.93 | T6: 21625.67 | U6: 21625.67 | V6: 23963.95 | W6: 19334.72 | X6: 24067.15 | Y6: 28880.08 | Z6: 28880.08 | AA6: 37649.52 | AB6: 39460.64
A7: 1 | C7: 단기금융상품 | E7: 6585.65 | F7: 6585.65 | G7: 6529.55 | H7: 6457.87 | I7: 6956.18 | J7: 6375.6 | K7: 6375.6 | L7: 16504.43 | M7: 16536.09 | N7: 16648.66 | O7: 16634.68 | P7: 16634.68 | Q7: 16862.13 | R7: 17017.16 | S7: 16762.67
A8: 1 | C8: 단기금융자산 | E8: 6585.65 | F8: 6585.65 | G8: 6529.55 | H8: 6457.87 | I8: 6956.18 | J8: 6375.6 | K8: 6375.6 | L8: 16504.43 | M8: 16536.09 | N8: 16648.66 | O8: 16634.68 | P8: 16634.68 | Q8: 16862.13 | R8: 17017.16 | S8: 16762.67
A9: 1 | C9: 매출채권및기타채권 | E9: 45948.44 | F9: 45948.44 | G9: 52738.11 | H9: 65252.23 | I9: 68804.29 | J9: 62842.59 | K9: 62842.59 | L9: 65893.48 | M9: 64984.57 | N9: 57663.87 | O9: 51334.22 | P9: 51334.22 | Q9: 54386.89 | R9: 48870.27 | S9: 52314.45 | T9: 52927.05 | U9: 52927.05 | V9: 49379.11 | W9: 57833.43 | X9: 65071.86 | Y9: 64161.59 | Z9: 64161.59 | AA9: 68792.58 | AB9: 71044.57
A10: 1 | C10: 기타유동금융자산 | E10: 5737.56 | F10: 5737.56 | G10: 9786.47 | H10: 11722.97 | I10: 18801.63 | J10: 30546.47 | K10: 30546.47 | L10: 29866.72 | M10: 15575.32 | N10: 45056.97 | O10: 41655.73 | P10: 41655.73 | Q10: 42016.51 | R10: 51298.44 | S10: 37568.32 | T10: 16933.52 | U10: 16933.52 | V10: 18494.5 | W10: 18120.16 | X10: 18275.88 | Y10: 17008.4 | Z10: 17008.4 | AA10: 9008.4 | AB10: 9008.4
A11: 1 | C11: 재고자산 | E11: 120039.24 | F11: 120039.24 | G11: 115498.07 | H11: 119253.71 | I11: 121721.79 | J11: 127844.22 | K11: 127844.22 | L11: 123341.21 | M11: 124651.95 | N11: 123665.12 | O11: 121315.29 | P11: 121315.29 | Q11: 110644.13 | R11: 113427.13 | S11: 113797.91 | T11: 119159.76 | U11: 119159.76 | V11: 125225.5 | W11: 132493.72 | X11: 137226.58 | Y11: 147949.81 | Z11: 147949.81 | AA11: 142619.85 | AB11: 137098.48
A12: 1 | C12: 기타유동자산 | E12: 466.3 | F12: 466.3 | G12: 506.98 | H12: 217.75 | I12: 200.29 | J12: 1970.86 | K12: 1970.86 | L12: 1685.76 | M12: 1507.74 | N12: 863.74 | O12: 598.93 | P12: 598.93 | Q12: 824.42 | R12: 824.14 | S12: 1672.06 | T12: 1653.28 | U12: 1653.28 | V12: 1874.39 | W12: 1607.05 | X12: 899.23 | Y12: 2080.87 | Z12: 2080.87 | AA12: 2740.17 | AB12: 2132.1
A13: 1 | C13: 비유동자산 | E13: 246467.93 | F13: 246467.93 | G13: 252380.03 | H13: 252842.58 | I13: 254228.23 | J13: 251200.6 | K13: 251200.6 | L13: 262434.85 | M13: 288830.9 | N13: 286843.69 | O13: 298038.31 | P13: 298038.31 | Q13: 308984.17 | R13: 326067.52 | S13: 336956.34 | T13: 326436.28 | U13: 326436.28 | V13: 332729.75 | W13: 332718.52 | X13: 316392.82 | Y13: 305286.45 | Z13: 305286.45 | AA13: 307690.72 | AB13: 316830.95
A14: 1 | C14: 장기금융자산 | E14: 33277.24 | F14: 33277.24 | G14: 37556.45 | H14: 37415.98 | I14: 37424.34 | J14: 32837.94 | K14: 32837.94 | L14: 41708.87 | M14: 63100.53 | N14: 51231.81 | O14: 59953.28 | P14: 59953.28 | Q14: 68501.38 | R14: 77323.76 | S14: 87997.4 | T14: 79403.15 | U14: 79403.15 | V14: 83343.44 | W14: 80805.19 | X14: 60404.52 | Y14: 52357.61 | Z14: 52357.61 | AA14: 53390.98 | AB14: 58335.37
A15: 1 | C15: 투자자산 | E15: 103316.89 | F15: 103316.89 | G15: 107596.1 | H15: 107455.63 | I15: 107463.99 | J15: 102877.59 | K15: 102877.59 | L15: 111748.52 | M15: 133140.18 | N15: 121271.46 | O15: 129992.93 | P15: 129992.93 | Q15: 138541.03 | R15: 151063.41 | S15: 161737.05 | T15: 153142.8 | U15: 153142.8 | V15: 157083.09 | W15: 154544.84 | X15: 134144.17 | Y15: 126097.26 | Z15: 126097.26 | AA15: 127130.63 | AB15: 58335.37
A16: 1 | C16: 장기매출채권및기타채권 | E16: 5889.27 | F16: 5889.27 | G16: 8043.78 | H16: 8941.51 | I16: 10721.97 | J16: 10504.61 | K16: 10504.61 | L16: 11348.22 | M16: 11599.63 | N16: 13513.58 | O16: 13952.92 | P16: 13952.92 | Q16: 14738.07 | R16: 14754.24 | T16: 11255.92 | U16: 11255.92 | V16: 10655.96 | W16: 11252 | X16: 1761.31 | Y16: 1720.51 | Z16: 1720.51 | AA16: 3454.27 | AB16: 3709.83
A17: 1 | C17: 기타비유동자산 | E17: 1164.57 | F17: 1164.57 | G17: 1196.62 | H17: 1066.56 | I17: 995.42 | J17: 1255.51 | K17: 1255.51 | L17: 1524.25 | M17: 1479.78 | N17: 1979 | O17: 1944.23 | P17: 1944.23 | Q17: 1860.68 | R17: 2011.91 | S17: 1911.07 | T17: 1829.93 | U17: 1829.93 | V17: 1907.94 | W17: 1848.08 | X17: 5739.76 | Y17: 5759.79 | Z17: 5759.79 | AA17: 1911.23 | AB17: 1981.67
A18: 1 | C18: 유형자산 | E18: 139708.68 | F18: 139708.68 | G18: 139166.76 | H18: 139038.85 | I18: 138743.56 | J18: 138613.55 | K18: 138613.55 | L18: 140027.41 | M18: 143002.93 | N18: 147055.07 | O18: 149674.51 | P18: 149674.51 | Q18: 151213.23 | R18: 152845.27 | S18: 153867.02 | T18: 155040.96 | U18: 155040.96 | V18: 157950.18 | W18: 159916.59 | X18: 160993.62 | Y18: 160098.52 | Z18: 160098.52 | AA18: 158984.2 | AB18: 157675.49
A19: 1 | C19: 무형자산 | E19: 1700.65 | F19: 1700.65 | G19: 1688.9 | H19: 1652.16 | I19: 1615.41 | J19: 1610.98 | K19: 1610.98 | L19: 1572.18 | M19: 1568.85 | N19: 1530.55 | O19: 1493.51 | P19: 1493.51 | Q19: 1456.48 | R19: 1420.14 | S19: 1387.81 | T19: 1355.55 | U19: 1355.55 | V19: 1321.45 | W19: 1345.9 | X19: 1335.27 | Y19: 1439.21 | Z19: 1439.21 | AA19: 1430.15 | AB19: 1422.09
A20: 1 | C20: 종속기업및관계기업투자 | E20: 70039.65 | F20: 70039.65 | G20: 70039.65 | H20: 70039.65 | I20: 70039.65 | J20: 70039.65 | K20: 70039.65 | L20: 70039.65 | M20: 70039.65 | N20: 70039.65 | O20: 70039.65 | P20: 70039.65 | Q20: 70039.65 | R20: 73739.65 | S20: 73739.65 | T20: 73739.65 | U20: 73739.65 | V20: 73739.65 | W20: 73739.65 | X20: 73739.65 | Y20: 73739.65 | Z20: 73739.65 | AA20: 73739.65
A21: 1 | C21: 자산총계 | E21: 462734.81 | F21: 462734.81 | G21: 467355.24 | H21: 481198.08 | I21: 507258.07 | J21: 520568.52 | K21: 520568.52 | L21: 529235.03 | M21: 543756.89 | N21: 550355.37 | O21: 550277.65 | P21: 550277.65 | Q21: 569316.2 | R21: 572995.16 | S21: 581093.68 | T21: 587972.75 | U21: 587972.75 | V21: 601642.59 | W21: 613080.2 | X21: 651685.08 | Y21: 673393.07 | Z21: 673393.07 | AA21: 701355.56 | AB21: 757580.27
A22: 1 | C22: 유동부채 | E22: 21820.91 | F22: 21820.91 | G22: 22046.69 | H22: 24592.52 | I22: 40546.26 | J22: 46500.55 | K22: 46500.55 | L22: 40621.84 | M22: 37465.71 | N22: 32707.27 | O22: 28354.97 | P22: 28354.97 | Q22: 35050.96 | R22: 27670.93 | S22: 28846.86 | T22: 28308.13 | U22: 28308.13 | V22: 37927.34 | W22: 32084.26 | X22: 37364.16 | Y22: 41007.91 | Z22: 41007.91 | AA22: 45146.79 | AB22: 40554.04
A23: 1 | C23: 매입채무및기타채무 | E23: 17163.12 | F23: 17163.12 | G23: 14271.6 | H23: 17556.15 | I23: 19129.69 | J23: 29964.03 | K23: 29964.03 | L23: 23355.93 | M23: 25733.33 | N23: 20576.96 | O23: 17996.19 | P23: 17996.19 | Q23: 17134.08 | R23: 20388.99 | S23: 21861.23 | T23: 20573 | U23: 20573 | V23: 24350.96 | W23: 25541.23 | X23: 25467.13 | Y23: 29743.51 | Z23: 29743.51 | AA23: 24389.23 | AB23: 23188.75
A24: 1 | C24: 기타유동부채 | E24: 1210.53 | F24: 1210.53 | G24: 1564.26 | H24: 1558.96 | I24: 5978.7 | J24: 7177.35 | K24: 7177.35 | L24: 2625.22 | M24: 2370.4 | N24: 1155.36 | O24: 1732 | P24: 1732 | Q24: 1494.8 | R24: 1175.51 | S24: 1996.9 | T24: 2603.54 | U24: 2603.54 | V24: 1367 | W24: 1233.83 | X24: 401.76 | Y24: 919.69 | Z24: 919.69 | AA24: 510.79 | AB24: 413.62
A25: 1 | C25: 기타유동금융부채 | E25: 455.86 | F25: 455.86 | G25: 3009.64 | H25: 388 | I25: 1661.19 | J25: 494.33 | K25: 494.33 | L25: 4988.85 | M25: 524.07 | N25: 614.18 | O25: 620.55 | P25: 620.55 | Q25: 5052.12 | R25: 665.35 | S25: 631.84 | V25: 6466.81 | X25: 0 | Y25: 0 | Z25: 0 | AA25: 6466.81 | AB25: 0
A26: 1 | C26: 단기금융부채 | E26: 455.86 | F26: 455.86 | G26: 3009.64 | H26: 388 | I26: 1661.19 | J26: 494.33 | K26: 494.33 | L26: 4988.85 | M26: 524.07 | N26: 614.18 | O26: 620.55 | P26: 620.55 | Q26: 5052.12 | R26: 665.35 | S26: 631.84 | T26: 622.36 | U26: 622.36 | V26: 7201.84 | W26: 736.9 | X26: 796.45 | Y26: 757.32 | Z26: 757.32 | AA26: 7253.06 | AB26: 815.84
A27: 1 | C27: 당기법인세부채(미지급법인세) | E27: 2991.41 | F27: 2991.41 | G27: 3201.2 | H27: 5089.41 | I27: 13776.68 | J27: 8864.84 | K27: 8864.84 | L27: 9651.84 | M27: 8837.91 | N27: 10360.76 | O27: 8006.24 | P27: 8006.24 | Q27: 11369.96 | R27: 5441.08 | S27: 4356.89 | T27: 4509.24 | U27: 4509.24 | V27: 5007.54 | W27: 4572.31 | X27: 9973.39 | Y27: 8798.62 | Z27: 8798.62 | AA27: 11116.2 | AB27: 14632.3
A28: 1 | C28: 비유동부채 | E28: 7414.36 | F28: 7414.36 | G28: 7855.92 | H28: 7788.83 | I28: 8454.73 | J28: 7133.64 | K28: 7133.64 | L28: 7388.12 | M28: 8172.4 | N28: 8185.14 | O28: 7833.07 | P28: 7833.07 | Q28: 8396.91 | R28: 9706.86 | S28: 9396.1 | T28: 8232.3 | U28: 8232.3 | V28: 8238.82 | W28: 9663.77 | X28: 14580.9 | Y28: 15606.95 | Z28: 15606.95 | AA28: 18629.5 | AB28: 26699.32
A29: 1 | C29: 확정급여부채 | E29: 2327.44 | F29: 2327.44 | G29: 2695.59 | H29: 2380.25 | I29: 2982.58 | V29: 259.86 | W29: 181.27 | X29: 0 | Y29: 0 | Z29: 0
A30: 1 | C30: 이연법인세부채 | E30: 2045.55 | F30: 2045.55 | G30: 1997.64 | H30: 2089 | I30: 1816.58 | J30: 2919.57 | K30: 2919.57 | L30: 3255.76 | M30: 3791.65 | N30: 3267.46 | O30: 2947.94 | P30: 2947.94 | Q30: 3899.14 | R30: 4347.81 | S30: 4254.8 | T30: 3174.24 | U30: 3174.24 | V30: 3537.16 | W30: 4899.83 | X30: 9690.28 | Y30: 10569.41 | Z30: 10569.41 | AA30: 13977.54 | AB30: 21831.48
A31: 1 | C31: 장기충당부채 | E31: 2272.36 | F31: 2272.36 | G31: 2322.13 | H31: 2569.93 | I31: 2985.97 | J31: 3334.05 | K31: 3334.05 | L31: 3038.86 | M31: 3336.33 | N31: 3455.91 | O31: 3455.41 | P31: 3455.41 | Q31: 3184.91 | R31: 3901.36 | S31: 3747.9 | T31: 3642.15 | U31: 3642.15 | V31: 3146.15 | W31: 3346.25 | X31: 3513.43 | Y31: 3797.78 | Z31: 3797.78 | AA31: 3405.83 | AB31: 3609.07
A32: 1 | C32: 기타비유동금융부채 | E32: 769 | F32: 769 | G32: 840.57 | H32: 749.65 | I32: 669.6 | J32: 880.01 | K32: 880.01 | L32: 1093.5 | M32: 1044.41 | N32: 1461.77 | O32: 1429.72 | P32: 1429.72 | Q32: 1312.86 | R32: 1457.68 | S32: 1393.41
A33: 1 | C33: 장기금융부채 | E33: 769 | F33: 769 | G33: 840.57 | H33: 749.65 | I33: 669.6 | J33: 880.01 | K33: 880.01 | L33: 1093.5 | M33: 1044.41 | N33: 1461.77 | O33: 1429.72 | P33: 1429.72 | Q33: 1312.86 | R33: 1457.68 | S33: 1393.41 | T33: 1326.13 | U33: 1326.13 | V33: 1295.66 | W33: 1236.42 | X33: 1377.19 | Y33: 1239.75 | Z33: 1239.75 | AA33: 1246.13 | AB33: 1258.77
A34: 1 | C34: 부채총계 | E34: 29235.27 | F34: 29235.27 | G34: 29902.62 | H34: 32381.35 | I34: 49000.98 | J34: 53634.18 | K34: 53634.18 | L34: 48009.96 | M34: 45638.1 | N34: 40892.41 | O34: 36188.05 | P34: 36188.05 | Q34: 43447.87 | R34: 37377.78 | S34: 38242.96 | T34: 36540.43 | U34: 36540.43 | V34: 46166.16 | W34: 41748.03 | X34: 51945.06 | Y34: 56614.86 | Z34: 56614.86 | AA34: 63776.29 | AB34: 67253.36
A35: 1 | C35: 자본금 | E35: 13250 | F35: 13250 | G35: 13250 | H35: 13250 | I35: 13250 | J35: 13250 | K35: 13250 | L35: 13250 | M35: 13250 | N35: 13250 | O35: 13250 | P35: 13250 | Q35: 13250 | R35: 13250 | S35: 13250 | T35: 13250 | U35: 13250 | V35: 13250 | W35: 13250 | X35: 13250 | Y35: 13250 | Z35: 13250 | AA35: 13250 | AB35: 13250
A36: 1 | C36: 자본잉여금 | E36: 34425.4 | F36: 34425.4 | G36: 34425.4 | H36: 34425.4 | I36: 34425.4 | J36: 34425.4 | K36: 34425.4 | L36: 34425.4 | M36: 34425.4 | N36: 34425.4 | O36: 34425.4 | P36: 34425.4 | Q36: 34425.4 | R36: 34425.4 | S36: 34425.4 | T36: 34425.4 | U36: 34425.4 | V36: 34425.4 | W36: 17425.4 | X36: 17425.4 | Y36: 17425.4 | Z36: 17425.4 | AA36: 17425.4 | AB36: 17425.4
A37: 1 | C37: 기타자본 | E37: -11222.62 | F37: -11222.62 | G37: -11222.62 | H37: -11222.62 | I37: -11222.62 | J37: -11222.62 | K37: -11222.62 | L37: -11222.62 | M37: -11222.62 | N37: -11222.62 | O37: -11222.62 | P37: -11222.62 | Q37: -11222.62 | R37: -11222.62 | S37: -11222.62 | T37: -11222.62 | U37: -11222.62 | V37: -11222.62 | W37: -11222.62 | X37: -11222.62 | Y37: -11222.62 | Z37: -11222.62 | AA37: 0 | AB37: -4658.56
A38: 1 | C38: 기타포괄이익누계액 | E38: -1541.77 | F38: -1541.77 | G38: -1541.77 | H38: -1541.77 | I38: -1541.77 | J38: -1554.05 | K38: -1554.05 | L38: -1554.05 | M38: -1554.05 | N38: -1554.05 | O38: -1874.26 | P38: -1874.26 | Q38: -1874.26 | R38: -1874.26 | S38: -1874.26 | T38: -1644.6 | U38: -1644.6 | V38: -1644.6 | W38: -1644.6 | X38: -1644.6 | Y38: -1437.67 | Z38: -1437.67 | AA38: -1437.67 | AB38: -1437.67
A39: 1 | C39: 이익잉여금 | E39: 398588.53 | F39: 398588.53 | G39: 402541.61 | H39: 413905.71 | I39: 423346.08 | J39: 432035.61 | K39: 432035.61 | L39: 446326.35 | M39: 463220.06 | N39: 474564.24 | O39: 479511.08 | P39: 479511.08 | Q39: 491289.81 | R39: 501038.85 | S39: 508272.2 | T39: 516624.14 | U39: 516624.14 | V39: 520668.25 | W39: 553523.99 | X39: 581931.85 | Y39: 598763.1 | Z39: 598763.1 | AA39: 608341.53 | AB39: 665747.73
A40: 1 | C40: 자본총계 | E40: 433499.54 | F40: 433499.54 | G40: 437452.62 | H40: 448816.73 | I40: 458257.09 | J40: 466934.34 | K40: 466934.34 | L40: 481225.08 | M40: 498118.79 | N40: 509462.96 | O40: 514089.6 | P40: 514089.6 | Q40: 525868.33 | R40: 535617.37 | S40: 542850.72 | T40: 551432.32 | U40: 551432.32 | V40: 555476.42 | W40: 571332.17 | X40: 599740.02 | Y40: 616778.21 | Z40: 616778.21 | AA40: 637579.26 | AB40: 690326.91
...

Sheet subQ
A1: YQ | C1: subQ 분기 서브모델(억원, U=100) | E1: 4Q21 | F1: 2021 | G1: 1Q22 | H1: 2Q22 | I1: 3Q22 | J1: 4Q22 | K1: 2022 | L1: 1Q23 | M1: 2Q23 | N1: 3Q23 | O1: 4Q23 | P1: 2023 | Q1: 1Q24 | R1: 2Q24 | S1: 3Q24 | T1: 4Q24 | U1: 2024 | V1: 1Q25 | W1: 2Q25 | X1: 3Q25 | Y1: 4Q25 | Z1: 2025 | AA1: 1Q26 | AB1: 2Q26 | AC1: 3Q26 | AD1: 4Q26 | AE1: 2026 | AF1: 1Q27 | AG1: 2Q27 | AH1: 3Q27 | AI1: 4Q27 | AJ1: 2027 | AK1: 1Q28 | AL1: 2Q28 | AM1: 3Q28 | AN1: 4Q28 | AO1: 2028
A2: A=이름(key) B=그룹 C=단위 D=FnGuide 계정명(VLOOKUP 키). 확정=VLOOKUP(BS), 추정=변수 가정 참조
E3: 1 | F3: 2 | G3: 3 | H3: 4 | I3: 5 | J3: 6 | K3: 7 | L3: 8 | M3: 9 | N3: 10 | O3: 11 | P3: 12 | Q3: 13 | R3: 14 | S3: 15 | T3: 16 | U3: 17 | V3: 18 | W3: 19 | X3: 20 | Y3: 21 | Z3: 22 | AA3: 23 | AB3: 24 | AC3: 25 | AD3: 26 | AE3: 27 | AF3: 28 | AG3: 29 | AH3: 30 | AI3: 31 | AJ3: 32 | AK3: 33 | AL3: 34 | AM3: 35 | AN3: 36 | AO3: 37
E4: 2021.12 | F4: 2021.12A | G4: 2022.03 | H4: 2022.06 | I4: 2022.09 | J4: 2022.12 | K4: 2022.12A | L4: 2023.03 | M4: 2023.06 | N4: 2023.09 | O4: 2023.12 | P4: 2023.12A | Q4: 2024.03 | R4: 2024.06 | S4: 2024.09 | T4: 2024.12 | U4: 2024.12A | V4: 2025.03 | W4: 2025.06 | X4: 2025.09 | Y4: 2025.12 | Z4: 2025.12A | AA4: 2026.03 | AB4: 2026.06 | AC4: 2026.09 | AD4: 2026.12 | AE4: 2026.12A | AF4: 2027.03 | AG4: 2027.06 | AH4: 2027.09 | AI4: 2027.12 | AJ4: 2027.12A | AK4: 2028.03 | AL4: 2028.06 | AM4: 2028.09 | AN4: 2028.12 | AO4: 2028.12A
A5: 매출액 | B5: 손익 | C5: 억원 | D5: 매출액(수익) | E5: =IFERROR(VLOOKUP($D5,BS연결,MATCH(E$1,BS연결H,0),0)/100,"") | G5: =IFERROR(VLOOKUP($D5,BS연결,MATCH(G$1,BS연결H,0),0)/100,"") | H5: =IFERROR(VLOOKUP($D5,BS연결,MATCH(H$1,BS연결H,0),0)/100,"") | I5: =IFERROR(VLOOKUP($D5,BS연결,MATCH(I$1,BS연결H,0),0)/100,"") | J5: =IFERROR(VLOOKUP($D5,BS연결,MATCH(J$1,BS연결H,0),0)/100,"") | K5: =IFERROR(VLOOKUP($D5,BS연결,MATCH(K$1,BS연결H,0),0)/100,"") | L5: =IFERROR(VLOOKUP($D5,BS연결,MATCH(L$1,BS연결H,0),0)/100,"") | M5: =IFERROR(VLOOKUP($D5,BS연결,MATCH(M$1,BS연결H,0),0)/100,"") | N5: =IFERROR(VLOOKUP($D5,BS연결,MATCH(N$1,BS연결H,0),0)/100,"") | ... AB5: =IFERROR(VLOOKUP($D5,BS연결,MATCH(AB$1,BS연결H,0),0)/100,"") | AC5: =IFERROR(X5*(1+변수!AC21),"") | AD5: =IFERROR(Y5*(1+변수!AD21),"") | AE5: =SUM(AA5:AD5) | AF5: =IFERROR(AA5*(1+변수!AF21),"") | AG5: =IFERROR(AB5*(1+변수!AG21),"") | AH5: =IFERROR(AC5*(1+변수!AH21),"") | AI5: =IFERROR(AD5*(1+변수!AI21),"") | AJ5: =SUM(AF5:AI5) | AK5: =IFERROR(AF5*(1+변수!AK21),"") | AL5: =IFERROR(AG5*(1+변수!AL21),"") | AM5: =IFERROR(AH5*(1+변수!AM21),"") | AN5: =IFERROR(AI5*(1+변수!AN21),"") | AO5: =SUM(AK5:AN5)
A6: 매출원가 | B6: 손익 | C6: 억원 | D6: 매출원가 | E6: =IFERROR(VLOOKUP($D6,BS연결,MATCH(E$1,BS연결H,0),0)/100,"") | G6: =IFERROR(VLOOKUP($D6,BS연결,MATCH(G$1,BS연결H,0),0)/100,"") | H6: =IFERROR(VLOOKUP($D6,BS연결,MATCH(H$1,BS연결H,0),0)/100,"") | I6: =IFERROR(VLOOKUP($D6,BS연결,MATCH(I$1,BS연결H,0),0)/100,"") | J6: =IFERROR(VLOOKUP($D6,BS연결,MATCH(J$1,BS연결H,0),0)/100,"") | K6: =IFERROR(VLOOKUP($D6,BS연결,MATCH(K$1,BS연결H,0),0)/100,"") | L6: =IFERROR(VLOOKUP($D6,BS연결,MATCH(L$1,BS연결H,0),0)/100,"") | M6: =IFERROR(VLOOKUP($D6,BS연결,MATCH(M$1,BS연결H,0),0)/100,"") | N6: =IFERROR(VLOOKUP($D6,BS연결,MATCH(N$1,BS연결H,0),0)/100,"") | ... AB6: =IFERROR(VLOOKUP($D6,BS연결,MATCH(AB$1,BS연결H,0),0)/100,"") | AC6: =IFERROR(AC5-AC7,"") | AD6: =IFERROR(AD5-AD7,"") | AE6: =SUM(AA6:AD6) | AF6: =IFERROR(AF5-AF7,"") | AG6: =IFERROR(AG5-AG7,"") | AH6: =IFERROR(AH5-AH7,"") | AI6: =IFERROR(AI5-AI7,"") | AJ6: =SUM(AF6:AI6) | AK6: =IFERROR(AK5-AK7,"") | AL6: =IFERROR(AL5-AL7,"") | AM6: =IFERROR(AM5-AM7,"") | AN6: =IFERROR(AN5-AN7,"") | AO6: =SUM(AK6:AN6)
A7: 매출총이익 | B7: 손익 | C7: 억원 | D7: 매출총이익 | E7: =IFERROR(VLOOKUP($D7,BS연결,MATCH(E$1,BS연결H,0),0)/100,"") | G7: =IFERROR(VLOOKUP($D7,BS연결,MATCH(G$1,BS연결H,0),0)/100,"") | H7: =IFERROR(VLOOKUP($D7,BS연결,MATCH(H$1,BS연결H,0),0)/100,"") | I7: =IFERROR(VLOOKUP($D7,BS연결,MATCH(I$1,BS연결H,0),0)/100,"") | J7: =IFERROR(VLOOKUP($D7,BS연결,MATCH(J$1,BS연결H,0),0)/100,"") | K7: =IFERROR(VLOOKUP($D7,BS연결,MATCH(K$1,BS연결H,0),0)/100,"") | L7: =IFERROR(VLOOKUP($D7,BS연결,MATCH(L$1,BS연결H,0),0)/100,"") | M7: =IFERROR(VLOOKUP($D7,BS연결,MATCH(M$1,BS연결H,0),0)/100,"") | N7: =IFERROR(VLOOKUP($D7,BS연결,MATCH(N$1,BS연결H,0),0)/100,"") | ... AB7: =IFERROR(VLOOKUP($D7,BS연결,MATCH(AB$1,BS연결H,0),0)/100,"") | AC7: =IFERROR(AC9+AC8,"") | AD7: =IFERROR(AD9+AD8,"") | AE7: =SUM(AA7:AD7) | AF7: =IFERROR(AF9+AF8,"") | AG7: =IFERROR(AG9+AG8,"") | AH7: =IFERROR(AH9+AH8,"") | AI7: =IFERROR(AI9+AI8,"") | AJ7: =SUM(AF7:AI7) | AK7: =IFERROR(AK9+AK8,"") | AL7: =IFERROR(AL9+AL8,"") | AM7: =IFERROR(AM9+AM8,"") | AN7: =IFERROR(AN9+AN8,"") | AO7: =SUM(AK7:AN7)
A8: 판관비 | B8: 손익 | C8: 억원 | D8: 판관비 | E8: =IFERROR(VLOOKUP($D8,BS연결,MATCH(E$1,BS연결H,0),0)/100,"") | G8: =IFERROR(VLOOKUP($D8,BS연결,MATCH(G$1,BS연결H,0),0)/100,"") | H8: =IFERROR(VLOOKUP($D8,BS연결,MATCH(H$1,BS연결H,0),0)/100,"") | I8: =IFERROR(VLOOKUP($D8,BS연결,MATCH(I$1,BS연결H,0),0)/100,"") | J8: =IFERROR(VLOOKUP($D8,BS연결,MATCH(J$1,BS연결H,0),0)/100,"") | K8: =IFERROR(VLOOKUP($D8,BS연결,MATCH(K$1,BS연결H,0),0)/100,"") | L8: =IFERROR(VLOOKUP($D8,BS연결,MATCH(L$1,BS연결H,0),0)/100,"") | M8: =IFERROR(VLOOKUP($D8,BS연결,MATCH(M$1,BS연결H,0),0)/100,"") | N8: =IFERROR(VLOOKUP($D8,BS연결,MATCH(N$1,BS연결H,0),0)/100,"") | ... AB8: =IFERROR(VLOOKUP($D8,BS연결,MATCH(AB$1,BS연결H,0),0)/100,"") | AC8: =IFERROR(AC5*변수!AC22,"") | AD8: =IFERROR(AD5*변수!AD22,"") | AE8: =SUM(AA8:AD8) | AF8: =IFERROR(AF5*변수!AF22,"") | AG8: =IFERROR(AG5*변수!AG22,"") | AH8: =IFERROR(AH5*변수!AH22,"") | AI8: =IFERROR(AI5*변수!AI22,"") | AJ8: =SUM(AF8:AI8) | AK8: =IFERROR(AK5*변수!AK22,"") | AL8: =IFERROR(AL5*변수!AL22,"") | AM8: =IFERROR(AM5*변수!AM22,"") | AN8: =IFERROR(AN5*변수!AN22,"") | AO8: =SUM(AK8:AN8)
A9: 영업이익 | B9: 손익 | C9: 억원 | D9: 영업이익 | E9: =IFERROR(VLOOKUP($D9,BS연결,MATCH(E$1,BS연결H,0),0)/100,"") | G9: =IFERROR(VLOOKUP($D9,BS연결,MATCH(G$1,BS연결H,0),0)/100,"") | H9: =IFERROR(VLOOKUP($D9,BS연결,MATCH(H$1,BS연결H,0),0)/100,"") | I9: =IFERROR(VLOOKUP($D9,BS연결,MATCH(I$1,BS연결H,0),0)/100,"") | J9: =IFERROR(VLOOKUP($D9,BS연결,MATCH(J$1,BS연결H,0),0)/100,"") | K9: =IFERROR(VLOOKUP($D9,BS연결,MATCH(K$1,BS연결H,0),0)/100,"") | L9: =IFERROR(VLOOKUP($D9,BS연결,MATCH(L$1,BS연결H,0),0)/100,"") | M9: =IFERROR(VLOOKUP($D9,BS연결,MATCH(M$1,BS연결H,0),0)/100,"") | N9: =IFERROR(VLOOKUP($D9,BS연결,MATCH(N$1,BS연결H,0),0)/100,"") | ... AB9: =IFERROR(VLOOKUP($D9,BS연결,MATCH(AB$1,BS연결H,0),0)/100,"") | AC9: =IFERROR(AC5*변수!AC23,"") | AD9: =IFERROR(AD5*변수!AD23,"") | AE9: =SUM(AA9:AD9) | AF9: =IFERROR(AF5*변수!AF23,"") | AG9: =IFERROR(AG5*변수!AG23,"") | AH9: =IFERROR(AH5*변수!AH23,"") | AI9: =IFERROR(AI5*변수!AI23,"") | AJ9: =SUM(AF9:AI9) | AK9: =IFERROR(AK5*변수!AK23,"") | AL9: =IFERROR(AL5*변수!AL23,"") | AM9: =IFERROR(AM5*변수!AM23,"") | AN9: =IFERROR(AN5*변수!AN23,"") | AO9: =SUM(AK9:AN9)
A10: OPM | B10: 손익 | C10: % | D10: 영업이익률 | E10: =IFERROR(E9/E5,"") | G10: =IFERROR(G9/G5,"") | H10: =IFERROR(H9/H5,"") | I10: =IFERROR(I9/I5,"") | J10: =IFERROR(J9/J5,"") | K10: =IFERROR(K9/K5,"") | L10: =IFERROR(L9/L5,"") | M10: =IFERROR(M9/M5,"") | N10: =IFERROR(N9/N5,"") | ... AO10: =IFERROR(AO9/AO5,"")
