Workbook
Name 변수H: 변수!$C$1:$AO$1
Name 환율: 변수!$C$6:$AO$13
Name BS연결H: BS연결!$C$1:$AO$1
Name BS연결: BS연결!$C$5:$AO$104
Name BS별도H: BS별도!$C$1:$AO$1
Name BS별도: BS별도!$C$5:$AO$89
Name SUBQH: subQ!$A$1:$AO$1
Name subQ: subQ!$A$5:$AO$44

Sheet README
A1: 한국선재(025550) 실적 모델 — ARGUS 한국조선
A2: 기준 분기 2026Q2 · 마지막 실적 2026Q2 · 생성 2026-10-13
A3: 모든 수치는 모델 산출값(DART 공개 재무제표 + 우리 추정)이다 — 목표주가·투자 추천 아님. 참고용 · 투자조언 아님.
A5: 시트
A6: 변수 가정 시계열. 환율 8행(ECB via frankfurter — L2 fx.json; 추정 분기 = 노란 가정), 추정 드라이버(노란 셀 = 모델값에서 역산한 가정, 바꾸면 재계산; 연녹 셀 = 3절 스칼라 참조 수식), 3절 스칼라 가정(세율·판관비율·지배주주비중·이자율·종가·PER 밴드·COE·외화 순노출·헤지비율)
A7: BS연결/BS별도 FnGuide 계정명 × 기간 값 덤프(백만원). 행1 분기라벨, 행4 YYYY.MM / YYYY.12A. 이름정의 BS연결H·BS연결(계정명 C열부터)
A8: subQ 분기 서브모델(억원 = 백만원/100). 확정 행: =IFERROR(VLOOKUP($D행,BS연결,MATCH(E$1,BS연결H,0),0)/100,"") 추정 행: 변수 시트 가정 셀 참조 수식. 외환손익·파생상품손익은 BS 계정 합·차, 기타금융손익은 잔차, OPM·EPS·BPS·PER·PBR 은 파생 수식
A9: SLS 선표(조선사만, sls json 있을 때): 요약 행(sls 저장값) + 계약별 스케줄(백만$) × (헤지비율 × 헤지환율 + (1−헤지비율) × 건조시점 환율[변수 원/달러(평균)]) → 원화 수식 블록 → 합계 행이 subQ 매출조선에 연결
A10: 시나리오 신규수주 보수/기준/낙관(forecast_panel 패널, 모델에 scenarios 가 있을 때만): 매출액·영업이익 = subQ 기준값 ± (시나리오 신규 − base 신규) × OPM. base 만 subQ 행에 포함, 나머지는 합산 안 함
A11: 분기/연간예상 subQ 를 이름(A열 key)으로 VLOOKUP 한 보고서 표(억원)
A12: TP PER 밴드 × 12M fwd EPS, PBR = ROE/COE × BPS — 모델 산출값 구간, 목표주가·추천 아님
A13: 외화 환율 QoQ, 외화 순노출 × Δ기말환율 → 환관련손익 추정
... A34: 백테스트: {"freeze": "2025Q2", "horizon": 4, "revenue_wape_pct": 16.4, "op_wape_pct": 90.2, "n": 4, "note": "단일 회사 4분기 — 통계 아님", "driver_at_freeze": "trend_seasonal", "selection_oos_at_freeze": {"wape_link": null, "wape_trend": null, "adopted": false, "decision": "rejected", "note": "유의성 조건 미달 → OOS 비교 전 기각"}, "frozen_inputs": "fin(연결/별도)·고객 조선사 모델·지주 자회사 모델은 2025Q2 까지의 분기만; 선표는 체결일 ≤ 2025Q2 말일 계약(원장 최신 금액·코호트 등급, 환산 없음); 잔고는 yards_cache 2025Q2; 시세·환율 forward·prices·forecast_panel 신규수주 미사용. 고객 가중치(suppliers.json 언급 비중)와 합병 체인링크는 현재 지식; 고객 연동 채택은 동결 모델 안에서도 자기 la−4분기 OOS 규칙(selection_oos_at_freeze)", "detail": [{"q": "2025Q3", "rev_pred": 501.41, "rev_act": 560.09, "op_pred": 10.02, "op_act": 27.88}, {"q": "2025Q4", "rev_pred": 542.95, "rev_act": 539.23, "op_pred": 10.85, "op_act": -0.36}, {"q": "2026Q1", "rev_pred": 503.83, "rev_act": 661.2, "op_pred": 10.07, "op_act": 81.6}, {"q": "2026Q2", "rev_pred": 529.64, "rev_act": 717.21, "op_pred": 10.59, "op_act": 92.26}]}

Sheet 변수
C1: 이름: 변수H | E1: 4Q21 | F1: 2021 | G1: 1Q22 | H1: 2Q22 | I1: 3Q22 | J1: 4Q22 | K1: 2022 | L1: 1Q23 | M1: 2Q23 | N1: 3Q23 | O1: 4Q23 | P1: 2023 | Q1: 1Q24 | R1: 2Q24 | S1: 3Q24 | T1: 4Q24 | U1: 2024 | V1: 1Q25 | W1: 2Q25 | X1: 3Q25 | Y1: 4Q25 | Z1: 2025 | AA1: 1Q26 | AB1: 2Q26 | AC1: 3Q26 | AD1: 4Q26 | AE1: 2026 | AF1: 1Q27 | AG1: 2Q27 | AH1: 3Q27 | AI1: 4Q27 | AJ1: 2027 | AK1: 1Q28 | AL1: 2Q28 | AM1: 3Q28 | AN1: 4Q28 | AO1: 2028
A2: 가정 시계열 — 노란 셀은 추정 가정(모델값에서 역산), 연녹 셀은 3절 스칼라 참조 수식. 바꾸면 subQ·분기·연간예상·TP·시나리오가 재계산됩니다.
E3: 1 | F3: 2 | G3: 3 | H3: 4 | I3: 5 | J3: 6 | K3: 7 | L3: 8 | M3: 9 | N3: 10 | O3: 11 | P3: 12 | Q3: 13 | R3: 14 | S3: 15 | T3: 16 | U3: 17 | V3: 18 | W3: 19 | X3: 20 | Y3: 21 | Z3: 22 | AA3: 23 | AB3: 24 | AC3: 25 | AD3: 26 | AE3: 27 | AF3: 28 | AG3: 29 | AH3: 30 | AI3: 31 | AJ3: 32 | AK3: 33 | AL3: 34 | AM3: 35 | AN3: 36 | AO3: 37
E4: 2021.12 | F4: 2021.12A | G4: 2022.03 | H4: 2022.06 | I4: 2022.09 | J4: 2022.12 | K4: 2022.12A | L4: 2023.03 | M4: 2023.06 | N4: 2023.09 | O4: 2023.12 | P4: 2023.12A | Q4: 2024.03 | R4: 2024.06 | S4: 2024.09 | T4: 2024.12 | U4: 2024.12A | V4: 2025.03 | W4: 2025.06 | X4: 2025.09 | Y4: 2025.12 | Z4: 2025.12A | AA4: 2026.03 | AB4: 2026.06 | AC4: 2026.09 | AD4: 2026.12 | AE4: 2026.12A | AF4: 2027.03 | AG4: 2027.06 | AH4: 2027.09 | AI4: 2027.12 | AJ4: 2027.12A | AK4: 2028.03 | AL4: 2028.06 | AM4: 2028.09 | AN4: 2028.12 | AO4: 2028.12A
B5: 1. FX | C5: 이름: 환율
A6: USDKRW_avg | C6: 원/달러(평균) | E6: 1183.5 | F6: 1145.51 | G6: 1205.78 | H6: 1262.09 | I6: 1341.93 | J6: 1360.12 | K6: 1292.98 | L6: 1276.95 | M6: 1315.69 | N6: 1313.62 | O6: 1322.01 | P6: 1306.85 | Q6: 1330.14 | R6: 1371.28 | S6: 1356.22 | T6: 1396.3 | U6: 1363.53 | V6: 1452.28 | W6: 1398.52 | X6: 1386.95 | Y6: 1449.19 | Z6: 1421.52 | AA6: 1466.12 | AB6: 1501.75 | AC6: 1418.75 | AD6: 1343.63 | AE6: 1456.58 | AF6: 1333.09 | AG6: 1333.09 | AH6: 1333.09 | AI6: 1333.09 | AK6: 1333.09 | AL6: 1333.09 | AM6: 1333.09 | AN6: 1333.09
A7: USDKRW_end | C7: 원/달러(기말) | E7: 1188.75 | F7: 1188.75 | G7: 1213.74 | H7: 1301.24 | I7: 1436.9 | J7: 1260.16 | K7: 1260.16 | L7: 1305.99 | M7: 1321.44 | N7: 1345.35 | O7: 1297.43 | P7: 1297.43 | Q7: 1349.25 | R7: 1377.73 | S7: 1312.17 | T7: 1474.78 | U7: 1474.78 | V7: 1474.54 | W7: 1355.13 | X7: 1403.67 | Y7: 1444.2 | Z7: 1444.2 | AA7: 1524.8 | AB7: 1550.89 | AC7: 1355.4 | AD7: 1333.09 | AE7: 1333.09 | AF7: 1333.09 | AG7: 1333.09 | AH7: 1333.09 | AI7: 1333.09 | AK7: 1333.09 | AL7: 1333.09 | AM7: 1333.09 | AN7: 1333.09
A8: JPY100KRW_avg | C8: 원/100Y(평균) | E8: 1041.02 | F8: 1042.74 | G8: 1036.79 | H8: 972.23 | I8: 970.61 | J8: 961.03 | K8: 985.1 | L8: 964.89 | M8: 957.36 | N8: 909 | O8: 893.22 | P8: 931.11 | Q8: 896.29 | R8: 880.14 | S8: 909.35 | T8: 917.25 | U8: 900.92 | V8: 952.59 | W8: 967.92 | X8: 940.32 | Y8: 940.77 | Z8: 950.17 | AA8: 934.39 | AB8: 942.16 | AC8: 890.41 | AD8: 849.51 | AE8: 918.81 | AF8: 840.54 | AG8: 840.54 | AH8: 840.54 | AI8: 840.54 | AK8: 840.54 | AL8: 840.54 | AM8: 840.54 | AN8: 840.54
A9: JPY100KRW_end | C9: 원/100Y(기말) | E9: 1032.62 | F9: 1032.62 | G9: 996.83 | H9: 954.9 | I9: 993.29 | J9: 955.54 | K9: 955.54 | L9: 980.62 | M9: 913.67 | N9: 901.47 | O9: 917.04 | P9: 917.04 | Q9: 892.42 | R9: 857.76 | S9: 919.21 | T9: 939.65 | U9: 939.65 | V9: 986.84 | W9: 938.85 | X9: 948.49 | Y9: 921.81 | Z9: 921.81 | AA9: 955.99 | AB9: 954.75 | AC9: 863.31 | AD9: 840.54 | AE9: 840.54 | AF9: 840.54 | AG9: 840.54 | AH9: 840.54 | AI9: 840.54 | AK9: 840.54 | AL9: 840.54 | AM9: 840.54 | AN9: 840.54
A10: EURKRW_avg | C10: W/Euro(평균) | E10: 1353.32 | F10: 1354.06 | G10: 1352.29 | H10: 1343.31 | I10: 1350.63 | J10: 1386.07 | K10: 1358.07 | L10: 1369.93 | M10: 1432.41 | N10: 1429.41 | O10: 1420.91 | P10: 1412.88 | Q10: 1444.21 | R10: 1476.42 | S10: 1489.3 | T10: 1490.78 | U10: 1475.4 | V10: 1528.33 | W10: 1585.13 | X10: 1620.04 | Y10: 1686.02 | Z10: 1605.45 | AA10: 1715.47 | AB10: 1746.09 | AC10: 1631.97 | AD10: 1507.34 | AE10: 1688.95 | AF10: 1490.54 | AG10: 1490.54 | AH10: 1490.54 | AI10: 1490.54 | AK10: 1490.54 | AL10: 1490.54 | AM10: 1490.54 | AN10: 1490.54
A11: EURKRW_end | C11: W/Euro(기말) | E11: 1346.38 | F11: 1346.38 | G11: 1347.37 | H11: 1351.6 | I11: 1400.62 | J11: 1344.08 | K11: 1344.08 | L11: 1420.26 | M11: 1435.88 | N11: 1425.26 | O11: 1433.66 | P11: 1433.66 | Q11: 1458.68 | R11: 1474.86 | S11: 1469.1 | T11: 1532.14 | U11: 1532.14 | V11: 1594.72 | W11: 1588.22 | X11: 1648.04 | Y11: 1696.94 | Z11: 1696.94 | AA11: 1753.21 | AB11: 1767.09 | AC11: 1539.06 | AD11: 1490.54 | AE11: 1490.54 | AF11: 1490.54 | AG11: 1490.54 | AH11: 1490.54 | AI11: 1490.54 | AK11: 1490.54 | AL11: 1490.54 | AM11: 1490.54 | AN11: 1490.54
A12: CNYKRW_avg | C12: 원/중국원(평균) | E12: 185.14 | F12: 177.65 | G12: 189.93 | H12: 190.76 | I12: 195.79 | J12: 191.09 | K12: 191.93 | L12: 186.59 | M12: 187.45 | N12: 181.28 | O12: 182.86 | P12: 184.52 | Q12: 185.04 | R12: 189.35 | S12: 189.24 | T12: 194.24 | U12: 189.49 | V12: 199.63 | W12: 193.41 | X12: 193.79 | Y12: 204.38 | Z12: 197.8 | AA12: 211.75 | AB12: 220.8 | AC12: 210.43 | AD12: 200.5 | AE12: 213.68 | AF12: 199.18 | AG12: 199.18 | AH12: 199.18 | AI12: 199.18 | AK12: 199.18 | AL12: 199.18 | AM12: 199.18 | AN12: 199.18
A13: CNYKRW_end | C13: 원/중국원(기말) | E13: 187.13 | F13: 187.13 | G13: 191.38 | H13: 194.13 | I13: 201.92 | J13: 182.67 | K13: 182.67 | L13: 189.97 | M13: 181.8 | N13: 184.26 | O13: 182.61 | P13: 182.61 | Q13: 186.66 | R13: 189.7 | S13: 187.12 | T13: 202.04 | U13: 202.04 | V13: 203.3 | W13: 189.14 | X13: 197.16 | Y13: 206.28 | Z13: 206.28 | AA13: 220.97 | AB13: 228.56 | AC13: 202.16 | AD13: 199.18 | AE13: 199.18 | AF13: 199.18 | AG13: 199.18 | AH13: 199.18 | AI13: 199.18 | AK13: 199.18 | AL13: 199.18 | AM13: 199.18 | AN13: 199.18
B14: 1b. 종가
A15: price_close_end | C15: 종가(기말) | E15: 5250 | G15: 7080 | H15: 4255 | I15: 3700 | J15: 4010 | L15: 4050 | M15: 4340 | N15: 4010 | O15: 3820 | Q15: 3590 | R15: 3495 | S15: 2980 | T15: 4010 | V15: 3130 | W15: 3540 | X15: 4015 | Y15: 3380 | AA15: 3120 | AB15: 2225 | AC15: 2320 | AD15: 2200
A16: price_high | C16: 종가(최고) | E16: 11150 | G16: 8400 | H16: 7270 | I16: 5260 | J16: 5700 | L16: 4690 | M16: 4945 | N16: 4420 | O16: 4300 | Q16: 3835 | R16: 4115 | S16: 3520 | T16: 5220 | V16: 5020 | W16: 6150 | X16: 5050 | Y16: 4380 | AA16: 3645 | AB16: 4855 | AC16: 2870 | AD16: 2410
A17: price_low | C17: 종가(최저) | E17: 3990 | G17: 3680 | H17: 3760 | I17: 3550 | J17: 3470 | L17: 3755 | M17: 3995 | N17: 3545 | O17: 3750 | Q17: 3345 | R17: 3420 | S17: 2720 | T17: 2740 | V17: 3130 | W17: 3140 | X17: 3110 | Y17: 3220 | AA17: 2865 | AB17: 2015 | AC17: 1801 | AD17: 2150
A18: price_avg | C18: 종가(평균) | E18: 6188.4 | G18: 5326.4 | H18: 5585.7 | I18: 4452.3 | J18: 4333.3 | L18: 4184.4 | M18: 4282.6 | N18: 4059.5 | O18: 3940.5 | Q18: 3647.5 | R18: 3581 | S18: 3135.2 | T18: 3178 | V18: 3817.8 | W18: 3917.4 | X18: 3593 | Y18: 3669.1 | AA18: 3322.5 | AB18: 3268.5 | AC18: 2177.3 | AD18: 2314.3
B20: 2. 추정 드라이버 | C20: 실적 열 = subQ 실현값(수식), 추정 열 = 가정(노란 = 모델값 역산, 연녹 = 3절 스칼라 참조)
A21: drv:매출액 | B21: yoy | C21: 매출액 YoY | J21: =IFERROR(subQ!J5/subQ!E5-1,"") | L21: =IFERROR(subQ!L5/subQ!G5-1,"") | M21: =IFERROR(subQ!M5/subQ!H5-1,"") | N21: =IFERROR(subQ!N5/subQ!I5-1,"") | O21: =IFERROR(subQ!O5/subQ!J5-1,"") | Q21: =IFERROR(subQ!Q5/subQ!L5-1,"") | R21: =IFERROR(subQ!R5/subQ!M5-1,"") | S21: =IFERROR(subQ!S5/subQ!N5-1,"") | T21: =IFERROR(subQ!T5/subQ!O5-1,"") | V21: =IFERROR(subQ!V5/subQ!Q5-1,"") | W21: =IFERROR(subQ!W5/subQ!R5-1,"") | X21: =IFERROR(subQ!X5/subQ!S5-1,"") | Y21: =IFERROR(subQ!Y5/subQ!T5-1,"") | AA21: =IFERROR(subQ!AA5/subQ!V5-1,"") | AB21: =IFERROR(subQ!AB5/subQ!W5-1,"") | AC21: 0.49232759 | AD21: 0.61441075 | AF21: 0.33321557 | AG21: 0.26068862 | AH21: 0.13775364 | AI21: 0.15273279 | AK21: 0.210103 | AL21: 0.25280365 | AM21: 0.26413805 | AN21: 0.25319382
A22: drv:판관비 | B22: ratio | C22: 판관비율(/매출) | E22: =IFERROR(subQ!E8/subQ!E5,"") | F22: =IFERROR(subQ!F8/subQ!F5,"") | G22: =IFERROR(subQ!G8/subQ!G5,"") | H22: =IFERROR(subQ!H8/subQ!H5,"") | I22: =IFERROR(subQ!I8/subQ!I5,"") | J22: =IFERROR(subQ!J8/subQ!J5,"") | K22: =IFERROR(subQ!K8/subQ!K5,"") | L22: =IFERROR(subQ!L8/subQ!L5,"") | ... AB22: =IFERROR(subQ!AB8/subQ!AB5,"") | AC22: =$D$52 | AD22: =$D$52 | AE22: =IFERROR(subQ!AE8/subQ!AE5,"") | AF22: =$D$52 | AG22: =$D$52 | AH22: =$D$52 | AI22: =$D$52 | AJ22: =IFERROR(subQ!AJ8/subQ!AJ5,"") | AK22: =$D$52 | AL22: =$D$52 | AM22: =$D$52 | AN22: =$D$52 | AO22: =IFERROR(subQ!AO8/subQ!AO5,"")
A23: drv:영업이익 | B23: ratio | C23: 영업이익률(OPM) | E23: =IFERROR(subQ!E9/subQ!E5,"") | F23: =IFERROR(subQ!F9/subQ!F5,"") | G23: =IFERROR(subQ!G9/subQ!G5,"") | H23: =IFERROR(subQ!H9/subQ!H5,"") | I23: =IFERROR(subQ!I9/subQ!I5,"") | J23: =IFERROR(subQ!J9/subQ!J5,"") | K23: =IFERROR(subQ!K9/subQ!K5,"") | L23: =IFERROR(subQ!L9/subQ!L5,"") | ... AB23: =IFERROR(subQ!AB9/subQ!AB5,"") | AC23: 0.03688505 | AD23: 0.036885152 | AE23: =IFERROR(subQ!AE9/subQ!AE5,"") | AF23: 0.036879481 | AG23: 0.036884249 | AH23: 0.036888263 | AI23: 0.036880917 | AJ23: =IFERROR(subQ!AJ9/subQ!AJ5,"") | AK23: 0.036888435 | AL23: 0.036883365 | AM23: 0.036883303 | AN23: 0.036888309 | AO23: =IFERROR(subQ!AO9/subQ!AO5,"")
A24: drv:외환손익 | B24: abs | C24: 외환손익 (가정, 억원) | E24: =subQ!E13 | F24: =subQ!F13 | G24: =subQ!G13 | H24: =subQ!H13 | I24: =subQ!I13 | J24: =subQ!J13 | K24: =subQ!K13 | L24: =subQ!L13 | ... AB24: =subQ!AB13 | AC24: 0 | AD24: 0 | AE24: =subQ!AE13 | AF24: 0 | AG24: 0 | AH24: 0 | AI24: 0 | AJ24: =subQ!AJ13 | AK24: 0 | AL24: 0 | AM24: 0 | AN24: 0 | AO24: =subQ!AO13
A25: drv:파생상품손익 | B25: abs | C25: 파생상품손익 (가정, 억원) | E25: =subQ!E14 | F25: =subQ!F14 | G25: =subQ!G14 | H25: =subQ!H14 | I25: =subQ!I14 | J25: =subQ!J14 | K25: =subQ!K14 | L25: =subQ!L14 | ... AB25: =subQ!AB14 | AC25: 0 | AD25: 0 | AE25: =subQ!AE14 | AF25: 0 | AG25: 0 | AH25: 0 | AI25: 0 | AJ25: =subQ!AJ14 | AK25: 0 | AL25: 0 | AM25: 0 | AN25: 0 | AO25: =subQ!AO14
A26: drv:기타금융손익 | B26: abs | C26: 기타금융손익 (가정, 억원) | E26: =subQ!E15 | F26: =subQ!F15 | G26: =subQ!G15 | H26: =subQ!H15 | I26: =subQ!I15 | J26: =subQ!J15 | K26: =subQ!K15 | L26: =subQ!L15 | ... AB26: =subQ!AB15 | AC26: -0.87 | AD26: -0.87 | AE26: =subQ!AE15 | AF26: -0.87 | AG26: -0.87 | AH26: -0.87 | AI26: -0.87 | AJ26: =subQ!AJ15 | AK26: -0.87 | AL26: -0.87 | AM26: -0.87 | AN26: -0.87 | AO26: =subQ!AO15
A27: drv:기타영업외손익 | B27: abs | C27: 기타영업외손익 (가정, 억원) | E27: =subQ!E16 | F27: =subQ!F16 | G27: =subQ!G16 | H27: =subQ!H16 | I27: =subQ!I16 | J27: =subQ!J16 | K27: =subQ!K16 | L27: =subQ!L16 | ... AB27: =subQ!AB16 | AC27: 0 | AD27: 0 | AE27: =subQ!AE16 | AF27: 0 | AG27: 0 | AH27: 0 | AI27: 0 | AJ27: =subQ!AJ16 | AK27: 0 | AL27: 0 | AM27: 0 | AN27: 0 | AO27: =subQ!AO16
A28: drv:법인세비용 | B28: tax | C28: 법인세율(/세전) — 법인세 = MAX(세전,0) × 세율 | E28: =IFERROR(subQ!E18/subQ!E17,"") | F28: =IFERROR(subQ!F18/subQ!F17,"") | G28: =IFERROR(subQ!G18/subQ!G17,"") | H28: =IFERROR(subQ!H18/subQ!H17,"") | I28: =IFERROR(subQ!I18/subQ!I17,"") | J28: =IFERROR(subQ!J18/subQ!J17,"") | K28: =IFERROR(subQ!K18/subQ!K17,"") | L28: =IFERROR(subQ!L18/subQ!L17,"") | ... AB28: =IFERROR(subQ!AB18/subQ!AB17,"") | AC28: =$D$51 | AD28: =$D$51 | AE28: =IFERROR(subQ!AE18/subQ!AE17,"") | AF28: =$D$51 | AG28: =$D$51 | AH28: =$D$51 | AI28: =$D$51 | AJ28: =IFERROR(subQ!AJ18/subQ!AJ17,"") | AK28: =$D$51 | AL28: =$D$51 | AM28: =$D$51 | AN28: =$D$51 | AO28: =IFERROR(subQ!AO18/subQ!AO17,"")
A29: drv:지배주주순이익 | B29: ratio | C29: 지배주주 비중(/당기순이익) | E29: =IFERROR(subQ!E20/subQ!E19,"") | F29: =IFERROR(subQ!F20/subQ!F19,"") | G29: =IFERROR(subQ!G20/subQ!G19,"") | H29: =IFERROR(subQ!H20/subQ!H19,"") | I29: =IFERROR(subQ!I20/subQ!I19,"") | J29: =IFERROR(subQ!J20/subQ!J19,"") | K29: =IFERROR(subQ!K20/subQ!K19,"") | L29: =IFERROR(subQ!L20/subQ!L19,"") | ... AB29: =IFERROR(subQ!AB20/subQ!AB19,"") | AC29: =$D$53 | AD29: =$D$53 | AE29: =IFERROR(subQ!AE20/subQ!AE19,"") | AF29: =$D$53 | AG29: =$D$53 | AH29: =$D$53 | AI29: =$D$53 | AJ29: =IFERROR(subQ!AJ20/subQ!AJ19,"") | AK29: =$D$53 | AL29: =$D$53 | AM29: =$D$53 | AN29: =$D$53 | AO29: =IFERROR(subQ!AO20/subQ!AO19,"")
A30: drv:감가상각비 | B30: abs | C30: 감가상각비 (가정, 억원) | E30: =subQ!E21 | F30: =subQ!F21 | G30: =subQ!G21 | H30: =subQ!H21 | I30: =subQ!I21 | J30: =subQ!J21 | K30: =subQ!K21 | L30: =subQ!L21 | ... AB30: =subQ!AB21 | AC30: 8.59 | AD30: 8.59 | AE30: =subQ!AE21 | AF30: 8.59 | AG30: 8.59 | AH30: 8.59 | AI30: 8.59 | AJ30: =subQ!AJ21 | AK30: 8.59 | AL30: 8.59 | AM30: 8.59 | AN30: 8.59 | AO30: =subQ!AO21
A31: drv:부채총계 | B31: qoq | C31: 부채총계 QoQ | G31: =IFERROR(subQ!G24/subQ!E24-1,"") | H31: =IFERROR(subQ!H24/subQ!G24-1,"") | I31: =IFERROR(subQ!I24/subQ!H24-1,"") | J31: =IFERROR(subQ!J24/subQ!I24-1,"") | L31: =IFERROR(subQ!L24/subQ!J24-1,"") | M31: =IFERROR(subQ!M24/subQ!L24-1,"") | N31: =IFERROR(subQ!N24/subQ!M24-1,"") | O31: =IFERROR(subQ!O24/subQ!N24-1,"") | Q31: =IFERROR(subQ!Q24/subQ!O24-1,"") | R31: =IFERROR(subQ!R24/subQ!Q24-1,"") | S31: =IFERROR(subQ!S24/subQ!R24-1,"") | T31: =IFERROR(subQ!T24/subQ!S24-1,"") | V31: =IFERROR(subQ!V24/subQ!T24-1,"") | W31: =IFERROR(subQ!W24/subQ!V24-1,"") | X31: =IFERROR(subQ!X24/subQ!W24-1,"") | Y31: =IFERROR(subQ!Y24/subQ!X24-1,"") | AA31: =IFERROR(subQ!AA24/subQ!Y24-1,"") | AB31: =IFERROR(subQ!AB24/subQ!AA24-1,"") | AC31: -1.982e-06 | AD31: 0 | AF31: 0 | AG31: 0 | AH31: 0 | AI31: 0 | AK31: 0 | AL31: 0 | AM31: 0 | AN31: 0
A32: drv:자본총계 | B32: roll | C32: 자본총계 기타변동(배당 등, 억원) | G32: =IFERROR(subQ!E25+subQ!G19-subQ!G25,"") | H32: =IFERROR(subQ!G25+subQ!H19-subQ!H25,"") | I32: =IFERROR(subQ!H25+subQ!I19-subQ!I25,"") | J32: =IFERROR(subQ!I25+subQ!J19-subQ!J25,"") | L32: =IFERROR(subQ!J25+subQ!L19-subQ!L25,"") | M32: =IFERROR(subQ!L25+subQ!M19-subQ!M25,"") | N32: =IFERROR(subQ!M25+subQ!N19-subQ!N25,"") | O32: =IFERROR(subQ!N25+subQ!O19-subQ!O25,"") | Q32: =IFERROR(subQ!O25+subQ!Q19-subQ!Q25,"") | R32: =IFERROR(subQ!Q25+subQ!R19-subQ!R25,"") | S32: =IFERROR(subQ!R25+subQ!S19-subQ!S25,"") | T32: =IFERROR(subQ!S25+subQ!T19-subQ!T25,"") | V32: =IFERROR(subQ!T25+subQ!V19-subQ!V25,"") | W32: =IFERROR(subQ!V25+subQ!W19-subQ!W25,"") | X32: =IFERROR(subQ!W25+subQ!X19-subQ!X25,"") | Y32: =IFERROR(subQ!X25+subQ!Y19-subQ!Y25,"") | AA32: =IFERROR(subQ!Y25+subQ!AA19-subQ!AA25,"") | AB32: =IFERROR(subQ!AA25+subQ!AB19-subQ!AB25,"") | AC32: -0.005551127 | AD32: 0.005336598 | AF32: -0.009519283 | AG32: 0.003707072 | AH32: 0.001647216 | AI32: -0.009140911 | AK32: 0.007801071 | AL32: -0.009596813 | AM32: 0.000538047 | AN32: 0.002579829
A33: drv:지배주주지분 | B33: roll | C33: 지배주주지분 기타변동(배당 등, 억원) | G33: =IFERROR(subQ!E26+subQ!G20-subQ!G26,"") | H33: =IFERROR(subQ!G26+subQ!H20-subQ!H26,"") | I33: =IFERROR(subQ!H26+subQ!I20-subQ!I26,"") | J33: =IFERROR(subQ!I26+subQ!J20-subQ!J26,"") | L33: =IFERROR(subQ!J26+subQ!L20-subQ!L26,"") | M33: =IFERROR(subQ!L26+subQ!M20-subQ!M26,"") | N33: =IFERROR(subQ!M26+subQ!N20-subQ!N26,"") | O33: =IFERROR(subQ!N26+subQ!O20-subQ!O26,"") | Q33: =IFERROR(subQ!O26+subQ!Q20-subQ!Q26,"") | R33: =IFERROR(subQ!Q26+subQ!R20-subQ!R26,"") | S33: =IFERROR(subQ!R26+subQ!S20-subQ!S26,"") | T33: =IFERROR(subQ!S26+subQ!T20-subQ!T26,"") | V33: =IFERROR(subQ!T26+subQ!V20-subQ!V26,"") | W33: =IFERROR(subQ!V26+subQ!W20-subQ!W26,"") | X33: =IFERROR(subQ!W26+subQ!X20-subQ!X26,"") | Y33: =IFERROR(subQ!X26+subQ!Y20-subQ!Y26,"") | AA33: =IFERROR(subQ!Y26+subQ!AA20-subQ!AA26,"") | AB33: =IFERROR(subQ!AA26+subQ!AB20-subQ!AB26,"") | AC33: 0.003500113 | AD33: -0.001194358 | AF33: -0.001133734 | AG33: -0.001826434 | AH33: -0.000605712 | AI33: 0.005130087 | AK33: 0.001970908 | AL33: -0.000921222 | AM33: -0.000795995 | AN33: 7.6235e-05
A34: drv:총차입금 | B34: qoq | C34: 총차입금 QoQ | G34: =IFERROR(subQ!G27/subQ!E27-1,"") | H34: =IFERROR(subQ!H27/subQ!G27-1,"") | I34: =IFERROR(subQ!I27/subQ!H27-1,"") | J34: =IFERROR(subQ!J27/subQ!I27-1,"") | L34: =IFERROR(subQ!L27/subQ!J27-1,"") | M34: =IFERROR(subQ!M27/subQ!L27-1,"") | N34: =IFERROR(subQ!N27/subQ!M27-1,"") | O34: =IFERROR(subQ!O27/subQ!N27-1,"") | Q34: =IFERROR(subQ!Q27/subQ!O27-1,"") | R34: =IFERROR(subQ!R27/subQ!Q27-1,"") | S34: =IFERROR(subQ!S27/subQ!R27-1,"") | T34: =IFERROR(subQ!T27/subQ!S27-1,"") | V34: =IFERROR(subQ!V27/subQ!T27-1,"") | W34: =IFERROR(subQ!W27/subQ!V27-1,"") | X34: =IFERROR(subQ!X27/subQ!W27-1,"") | Y34: =IFERROR(subQ!Y27/subQ!X27-1,"") | AA34: =IFERROR(subQ!AA27/subQ!Y27-1,"") | AB34: =IFERROR(subQ!AB27/subQ!AA27-1,"") | AC34: -2.135e-06 | AD34: 0 | AF34: 0 | AG34: 0 | AH34: 0 | AI34: 0 | AK34: 0 | AL34: 0 | AM34: 0 | AN34: 0
A35: drv:순차입금 | B35: qoq | C35: 순차입금 QoQ | G35: =IFERROR(subQ!G28/subQ!E28-1,"") | H35: =IFERROR(subQ!H28/subQ!G28-1,"") | I35: =IFERROR(subQ!I28/subQ!H28-1,"") | J35: =IFERROR(subQ!J28/subQ!I28-1,"") | L35: =IFERROR(subQ!L28/subQ!J28-1,"") | M35: =IFERROR(subQ!M28/subQ!L28-1,"") | N35: =IFERROR(subQ!N28/subQ!M28-1,"") | O35: =IFERROR(subQ!O28/subQ!N28-1,"") | Q35: =IFERROR(subQ!Q28/subQ!O28-1,"") | R35: =IFERROR(subQ!R28/subQ!Q28-1,"") | S35: =IFERROR(subQ!S28/subQ!R28-1,"") | T35: =IFERROR(subQ!T28/subQ!S28-1,"") | V35: =IFERROR(subQ!V28/subQ!T28-1,"") | W35: =IFERROR(subQ!W28/subQ!V28-1,"") | X35: =IFERROR(subQ!X28/subQ!W28-1,"") | Y35: =IFERROR(subQ!Y28/subQ!X28-1,"") | AA35: =IFERROR(subQ!AA28/subQ!Y28-1,"") | AB35: =IFERROR(subQ!AB28/subQ!AA28-1,"") | AC35: 0.065743088 | AD35: 0.061136272 | AF35: 0.057567068 | AG35: 0.054167406 | AH35: 0.050704953 | AI35: 0.047514457 | AK35: 0.044485579 | AL35: 0.041702172 | AM35: 0.039129387 | AN35: 0.036979798
A36: drv:이자발생자산 | B36: qoq | C36: 이자발생자산 QoQ | G36: =IFERROR(subQ!G29/subQ!E29-1,"") | H36: =IFERROR(subQ!H29/subQ!G29-1,"") | I36: =IFERROR(subQ!I29/subQ!H29-1,"") | J36: =IFERROR(subQ!J29/subQ!I29-1,"") | L36: =IFERROR(subQ!L29/subQ!J29-1,"") | M36: =IFERROR(subQ!M29/subQ!L29-1,"") | N36: =IFERROR(subQ!N29/subQ!M29-1,"") | O36: =IFERROR(subQ!O29/subQ!N29-1,"") | Q36: =IFERROR(subQ!Q29/subQ!O29-1,"") | R36: =IFERROR(subQ!R29/subQ!Q29-1,"") | S36: =IFERROR(subQ!S29/subQ!R29-1,"") | T36: =IFERROR(subQ!T29/subQ!S29-1,"") | V36: =IFERROR(subQ!V29/subQ!T29-1,"") | W36: =IFERROR(subQ!W29/subQ!V29-1,"") | X36: =IFERROR(subQ!X29/subQ!W29-1,"") | Y36: =IFERROR(subQ!Y29/subQ!X29-1,"") | AA36: =IFERROR(subQ!AA29/subQ!Y29-1,"") | AB36: =IFERROR(subQ!AB29/subQ!AA29-1,"") | AC36: -0.35512549 | AD36: -0.54585846 | AF36: -1.2006988 | AG36: 5.954039 | AH36: 0.84488284 | AI36: 0.45095804 | AK36: 0.30477722 | AL36: 0.22871151 | AM36: 0.18191576 | AN36: 0.15119149
A37: drv:현금및현금성자산 | B37: qoq | C37: 현금및현금성자산 QoQ | G37: =IFERROR(subQ!G30/subQ!E30-1,"") | H37: =IFERROR(subQ!H30/subQ!G30-1,"") | I37: =IFERROR(subQ!I30/subQ!H30-1,"") | J37: =IFERROR(subQ!J30/subQ!I30-1,"") | L37: =IFERROR(subQ!L30/subQ!J30-1,"") | M37: =IFERROR(subQ!M30/subQ!L30-1,"") | N37: =IFERROR(subQ!N30/subQ!M30-1,"") | O37: =IFERROR(subQ!O30/subQ!N30-1,"") | Q37: =IFERROR(subQ!Q30/subQ!O30-1,"") | R37: =IFERROR(subQ!R30/subQ!Q30-1,"") | S37: =IFERROR(subQ!S30/subQ!R30-1,"") | T37: =IFERROR(subQ!T30/subQ!S30-1,"") | V37: =IFERROR(subQ!V30/subQ!T30-1,"") | W37: =IFERROR(subQ!W30/subQ!V30-1,"") | X37: =IFERROR(subQ!X30/subQ!W30-1,"") | Y37: =IFERROR(subQ!Y30/subQ!X30-1,"") | AA37: =IFERROR(subQ!AA30/subQ!Y30-1,"") | AB37: =IFERROR(subQ!AB30/subQ!AA30-1,"")
A38: drv:CAPEX | B38: yoy | C38: CAPEX YoY | J38: =IFERROR(subQ!J31/subQ!E31-1,"") | L38: =IFERROR(subQ!L31/subQ!G31-1,"") | M38: =IFERROR(subQ!M31/subQ!H31-1,"") | N38: =IFERROR(subQ!N31/subQ!I31-1,"") | O38: =IFERROR(subQ!O31/subQ!J31-1,"") | Q38: =IFERROR(subQ!Q31/subQ!L31-1,"") | R38: =IFERROR(subQ!R31/subQ!M31-1,"") | S38: =IFERROR(subQ!S31/subQ!N31-1,"") | T38: =IFERROR(subQ!T31/subQ!O31-1,"") | V38: =IFERROR(subQ!V31/subQ!Q31-1,"") | W38: =IFERROR(subQ!W31/subQ!R31-1,"") | X38: =IFERROR(subQ!X31/subQ!S31-1,"") | Y38: =IFERROR(subQ!Y31/subQ!T31-1,"") | AA38: =IFERROR(subQ!AA31/subQ!V31-1,"") | AB38: =IFERROR(subQ!AB31/subQ!W31-1,"") | AC38: 0.025046689 | AD38: 0.047030472 | AF38: -0.46821319 | AG38: -0.023896293 | AH38: 0 | AI38: 0 | AK38: 0 | AL38: 0 | AM38: 0 | AN38: 0
A39: drv:영업활동현금흐름 | B39: yoy | C39: 영업활동현금흐름 YoY | J39: =IFERROR(subQ!J32/subQ!E32-1,"") | L39: =IFERROR(subQ!L32/subQ!G32-1,"") | M39: =IFERROR(subQ!M32/subQ!H32-1,"") | N39: =IFERROR(subQ!N32/subQ!I32-1,"") | O39: =IFERROR(subQ!O32/subQ!J32-1,"") | Q39: =IFERROR(subQ!Q32/subQ!L32-1,"") | R39: =IFERROR(subQ!R32/subQ!M32-1,"") | S39: =IFERROR(subQ!S32/subQ!N32-1,"") | T39: =IFERROR(subQ!T32/subQ!O32-1,"") | V39: =IFERROR(subQ!V32/subQ!Q32-1,"") | W39: =IFERROR(subQ!W32/subQ!R32-1,"") | X39: =IFERROR(subQ!X32/subQ!S32-1,"") | Y39: =IFERROR(subQ!Y32/subQ!T32-1,"") | AA39: =IFERROR(subQ!AA32/subQ!V32-1,"") | AB39: =IFERROR(subQ!AB32/subQ!W32-1,"")
A40: drv:주식수 | B40: qoq | C40: 주식수 QoQ | G40: =IFERROR(subQ!G33/subQ!E33-1,"") | H40: =IFERROR(subQ!H33/subQ!G33-1,"") | I40: =IFERROR(subQ!I33/subQ!H33-1,"") | J40: =IFERROR(subQ!J33/subQ!I33-1,"") | L40: =IFERROR(subQ!L33/subQ!J33-1,"") | M40: =IFERROR(subQ!M33/subQ!L33-1,"") | N40: =IFERROR(subQ!N33/subQ!M33-1,"") | O40: =IFERROR(subQ!O33/subQ!N33-1,"") | Q40: =IFERROR(subQ!Q33/subQ!O33-1,"") | R40: =IFERROR(subQ!R33/subQ!Q33-1,"") | S40: =IFERROR(subQ!S33/subQ!R33-1,"") | T40: =IFERROR(subQ!T33/subQ!S33-1,"") | V40: =IFERROR(subQ!V33/subQ!T33-1,"") | W40: =IFERROR(subQ!W33/subQ!V33-1,"") | X40: =IFERROR(subQ!X33/subQ!W33-1,"") | Y40: =IFERROR(subQ!Y33/subQ!X33-1,"") | AA40: =IFERROR(subQ!AA33/subQ!Y33-1,"") | AB40: =IFERROR(subQ!AB33/subQ!AA33-1,"") | AC40: 0 | AD40: 0 | AF40: 0 | AG40: 0 | AH40: 0 | AI40: 0 | AK40: 0 | AL40: 0 | AM40: 0 | AN40: 0
A41: drv:DPS | B41: abs | C41: DPS (가정, 원) | E41: =subQ!E36 | F41: =subQ!F36 | G41: =subQ!G36 | H41: =subQ!H36 | I41: =subQ!I36 | J41: =subQ!J36 | K41: =subQ!K36 | L41: =subQ!L36 | ... AB41: =subQ!AB36 | AD41: 0 | AE41: =subQ!AE36 | AI41: 0 | AJ41: =subQ!AJ36 | AN41: 0 | AO41: =subQ!AO36
...

Sheet BS연결
B1: (백만원) | C1: 이름: BS연결H | E1: 4Q21 | F1: 2021 | G1: 1Q22 | H1: 2Q22 | I1: 3Q22 | J1: 4Q22 | K1: 2022 | L1: 1Q23 | M1: 2Q23 | N1: 3Q23 | O1: 4Q23 | P1: 2023 | Q1: 1Q24 | R1: 2Q24 | S1: 3Q24 | T1: 4Q24 | U1: 2024 | V1: 1Q25 | W1: 2Q25 | X1: 3Q25 | Y1: 4Q25 | Z1: 2025 | AA1: 1Q26 | AB1: 2Q26 | AC1: 3Q26 | AD1: 4Q26 | AE1: 2026 | AF1: 1Q27 | AG1: 2Q27 | AH1: 3Q27 | AI1: 4Q27 | AJ1: 2027 | AK1: 1Q28 | AL1: 2Q28 | AM1: 3Q28 | AN1: 4Q28 | AO1: 2028
B2: 연결 | D2: fin json(kship_fin.py)
B3: 한국선재(연) | C3: UPDATE: 26-10-13 | E3: 1 | F3: 2 | G3: 3 | H3: 4 | I3: 5 | J3: 6 | K3: 7 | L3: 8 | M3: 9 | N3: 10 | O3: 11 | P3: 12 | Q3: 13 | R3: 14 | S3: 15 | T3: 16 | U3: 17 | V3: 18 | W3: 19 | X3: 20 | Y3: 21 | Z3: 22 | AA3: 23 | AB3: 24 | AC3: 25 | AD3: 26 | AE3: 27 | AF3: 28 | AG3: 29 | AH3: 30 | AI3: 31 | AJ3: 32 | AK3: 33 | AL3: 34 | AM3: 35 | AN3: 36 | AO3: 37
B4: Account Code | C4: AccountNAME | E4: 2021.12 | F4: 2021.12A | G4: 2022.03 | H4: 2022.06 | I4: 2022.09 | J4: 2022.12 | K4: 2022.12A | L4: 2023.03 | M4: 2023.06 | N4: 2023.09 | O4: 2023.12 | P4: 2023.12A | Q4: 2024.03 | R4: 2024.06 | S4: 2024.09 | T4: 2024.12 | U4: 2024.12A | V4: 2025.03 | W4: 2025.06 | X4: 2025.09 | Y4: 2025.12 | Z4: 2025.12A | AA4: 2026.03 | AB4: 2026.06 | AC4: 2026.09 | AD4: 2026.12 | AE4: 2026.12A | AF4: 2027.03 | AG4: 2027.06 | AH4: 2027.09 | AI4: 2027.12 | AJ4: 2027.12A | AK4: 2028.03 | AL4: 2028.06 | AM4: 2028.09 | AN4: 2028.12 | AO4: 2028.12A
A5: 1 | C5: 유동자산 | E5: 128783.58 | F5: 128783.58 | G5: 120306.92 | H5: 131396.07 | I5: 134033.31 | J5: 133702.02 | K5: 133702.02 | L5: 141614.08 | M5: 145407.39 | N5: 142787.04 | O5: 136603.81 | P5: 136603.81 | Q5: 142221.05 | R5: 140110.2 | S5: 126204.84 | T5: 135071.57 | U5: 135071.57 | V5: 139396.69 | W5: 136584.72 | X5: 136085.34 | Y5: 159679.18 | Z5: 159679.18 | AA5: 168118.69 | AB5: 158387.87
A6: 1 | C6: 현금및현금성자산 | E6: 13747.89 | F6: 13747.89 | G6: 15481.2 | H6: 6807.06 | I6: 8409.03 | J6: 10624.64 | K6: 10624.64 | L6: 5378.3 | M6: 6760.54 | N6: 8304.65 | O6: 17625.28 | P6: 17625.28 | Q6: 14072.42 | R6: 12155.05 | S6: 12829.42 | T6: 11545.19 | U6: 11545.19 | V6: 13828.71 | W6: 7134.25 | X6: 6909.09 | Y6: 30670.84 | Z6: 30670.84 | AA6: 19668.35 | AB6: 22556.87
A7: 1 | C7: 매출채권및기타채권 | E7: 30020.98 | F7: 30020.98 | G7: 34467.9 | H7: 33354.23 | I7: 37882.07 | J7: 37004.14 | K7: 37004.14 | L7: 40241.39 | M7: 38813.57 | N7: 42333.99 | O7: 37036.62 | P7: 37036.62 | Q7: 34665.73 | R7: 39956.6 | S7: 34878.15 | T7: 38211.65 | U7: 38211.65 | V7: 35341.44 | W7: 35732.61 | X7: 36441.44 | Y7: 37383.56 | Z7: 37383.56 | AA7: 42704.15 | AB7: 46207
A8: 1 | C8: 재고자산 | E8: 67720.78 | F8: 67720.78 | G8: 68763.07 | H8: 87510.11 | I8: 84232.85 | J8: 83764.55 | K8: 83764.55 | L8: 93458.61 | M8: 97535.85 | N8: 90942.65 | O8: 80846.32 | P8: 80846.32 | Q8: 90196.25 | R8: 87004.8 | S8: 77560.77 | T8: 84041.37 | U8: 84041.37 | V8: 72455.68 | W8: 80046.91 | X8: 86785.69 | Y8: 86092.85 | Z8: 86092.85 | AA8: 86684.45 | AB8: 87679.63
A9: 1 | C9: 기타유동금융자산 | E9: 297.98 | F9: 297.98 | G9: 298.73 | H9: 299.72 | I9: 2069.66 | J9: 409.71 | K9: 409.71 | L9: 389.79 | M9: 392.66 | Y9: 2441.98 | Z9: 2441.98 | AA9: 8331.42
A10: 1 | C10: 기타유동자산 | E10: 1046.73 | F10: 1046.73 | G10: 1296.03 | H10: 3424.94 | I10: 1439.7 | J10: 1898.97 | K10: 1898.97 | L10: 2146 | M10: 1904.77 | N10: 1205.75 | O10: 1005.78 | P10: 1005.78 | Q10: 1835.77 | R10: 993.76 | S10: 936.5 | T10: 1273.36 | U10: 1273.36 | V10: 651.12 | W10: 1371.05 | X10: 2649.64 | Y10: 2804.92 | Z10: 2804.92 | AA10: 2561.4 | AB10: 1819.38
A11: 1 | C11: 매각예정비유동자산및처분자산 | E11: 15949.22 | F11: 15949.22 | I11: 0
A12: 1 | C12: 비유동자산 | E12: 120984.81 | F12: 120984.81 | G12: 122279 | H12: 123202.95 | I12: 123038.23 | J12: 121157.68 | K12: 121157.68 | L12: 120394.59 | M12: 124522.46 | N12: 130532.16 | O12: 134117.46 | P12: 134117.46 | Q12: 132563.48 | R12: 133097.98 | S12: 132563.46 | T12: 146356.79 | U12: 146356.79 | V12: 154123.63 | W12: 158729.62 | X12: 178527.47 | Y12: 175661.2 | Z12: 175661.2 | AA12: 201330.87 | AB12: 207817.27
A13: 1 | C13: 장기금융자산 | E13: 1431.33 | F13: 1431.33 | G13: 1100.32 | H13: 1100.32 | I13: 1100.32 | J13: 1100.32 | K13: 1100.32 | L13: 1100.32 | M13: 1100.32 | N13: 1100.32 | O13: 824.43 | P13: 824.43 | Q13: 824.43 | R13: 232.43 | S13: 328.01 | T13: 13244.31 | U13: 13244.31 | V13: 13343.48 | W13: 11797.35 | X13: 19306.18 | Y13: 847.86 | Z13: 847.86 | AA13: 1753.08 | AB13: 1874.24
A14: 1 | C14: 투자자산 | E14: 3232.7 | F14: 3232.7 | G14: 3627.75 | H14: 2451.16 | I14: 2200.37 | J14: 2300.91 | K14: 2300.91 | L14: 2300.65 | M14: 2460.67 | N14: 2328.31 | O14: 4078.78 | P14: 4078.78 | Q14: 3334.56 | R14: 3832.53 | S14: 3648.66 | T14: 15356.23 | U14: 15356.23 | V14: 13343.48 | W14: 11797.35 | X14: 19306.18 | Y14: 847.86 | Z14: 847.86 | AA14: 1753.08 | AB14: 1874.24
A15: 1 | C15: 장기매출채권및기타채권 | E15: 2289.28 | F15: 2289.28 | G15: 2326.96 | H15: 2676.74 | I15: 3235.92 | J15: 2234.53 | K15: 2234.53 | L15: 2264.74 | M15: 2326.5 | N15: 2478.5 | O15: 1839.79 | P15: 1839.79 | Q15: 1893.07 | R15: 1827.05 | S15: 1744.11 | T15: 1501.59 | U15: 1501.59 | V15: 1420.68 | W15: 1175.67 | X15: 726.91 | Y15: 723.1 | Z15: 723.1 | AA15: 735.62 | AB15: 554.44
A16: 1 | C16: 종속기업및관계기업투자 | E16: 1801.37 | F16: 1801.37 | G16: 2527.43 | H16: 1350.84 | I16: 1100.05 | J16: 1200.59 | K16: 1200.59 | L16: 1200.33 | M16: 1360.35 | N16: 1227.99 | O16: 3254.35 | P16: 3254.35 | Q16: 2510.13 | R16: 3600.1 | S16: 3320.65 | T16: 2111.92 | U16: 2111.92 | V16: 0 | W16: 0 | X16: 0
A17: 1 | C17: 유형자산 | E17: 102120.29 | F17: 102120.29 | G17: 102657.56 | H17: 104484.87 | I17: 104156.19 | J17: 103055.01 | K17: 103055.01 | L17: 102290.88 | M17: 101453.37 | N17: 107463.27 | O17: 110158.06 | P17: 110158.06 | Q17: 109447.74 | R17: 109158.98 | S17: 106962.36 | T17: 109022.01 | U17: 109022.01 | V17: 116055.02 | W17: 121928.53 | X17: 133061.24 | Y17: 143859.13 | Z17: 143859.13 | AA17: 167857.02 | AB17: 178990.5
A18: 1 | C18: 사용권자산 | E18: 1148.29 | F18: 1148.29 | G18: 1151.83 | H18: 1120.97 | I18: 1015.99 | J18: 1078.31 | K18: 1078.31 | L18: 1058.42 | M18: 1074.2 | N18: 1065.28 | O18: 886.72 | P18: 886.72 | Q18: 763.3 | R18: 1074.51 | S18: 1093.72 | T18: 858.9 | U18: 858.9 | V18: 850.91 | W18: 810.54 | X18: 690.55 | Y18: 658.08 | Z18: 658.08 | AA18: 1097.31 | AB18: 1031.44
A19: 1 | C19: 기타비유동자산 | E19: 1148.29 | F19: 1148.29 | G19: 1151.83 | H19: 1120.97 | I19: 1015.99 | J19: 1078.31 | K19: 1078.31 | L19: 1058.42 | M19: 1074.2 | N19: 1065.28 | O19: 886.72 | P19: 886.72 | Q19: 763.3 | R19: 1074.51 | S19: 1093.72 | T19: 858.9 | U19: 858.9 | V19: 850.91 | W19: 810.54 | X19: 690.55 | Y19: 658.08 | Z19: 658.08 | AA19: 1097.31 | AB19: 1031.44
A20: 1 | C20: 투자부동산 | E20: 11754.61 | F20: 11754.61 | G20: 11734.68 | H20: 11707 | I20: 11679.31 | J20: 11651.62 | K20: 11651.62 | L20: 11623.94 | M20: 16362.66 | N20: 16317.16 | O20: 16290.49 | P20: 16290.49 | Q20: 16254.41 | R20: 16218.32 | S20: 18088.71 | T20: 18512.27 | U20: 18512.27 | V20: 18443.07 | W20: 19358.9 | X20: 21145.94 | Y20: 22230.49 | Z20: 22230.49 | AA20: 24162.53 | AB20: 18964.52
A21: 1 | C21: 무형자산 | E21: 439.65 | F21: 439.65 | G21: 422.31 | H21: 404.54 | I21: 390.46 | J21: 472.6 | K21: 472.6 | L21: 491.27 | M21: 480.36 | N21: 467.97 | O21: 457.76 | P21: 457.76 | Q21: 449.13 | R21: 441.54 | S21: 453.35 | T21: 483.46 | U21: 483.46 | V21: 501.32 | W21: 1209.68 | X21: 1241.76 | Y21: 1233.54 | Z21: 1233.54 | AA21: 1809.38
A22: 1 | C22: 자산총계 | E22: 249768.39 | F22: 249768.39 | G22: 242585.92 | H22: 254599.01 | I22: 257071.54 | J22: 254859.7 | K22: 254859.7 | L22: 262008.67 | M22: 269929.85 | N22: 273319.2 | O22: 270721.26 | P22: 270721.26 | Q22: 274784.53 | R22: 273208.18 | S22: 258768.3 | T22: 281428.37 | U22: 281428.37 | V22: 293520.32 | W22: 295314.34 | X22: 314612.81 | Y22: 335340.38 | Z22: 335340.38 | AA22: 369449.56 | AB22: 366205.15
A23: 1 | C23: 유동부채 | E23: 124211.41 | F23: 124211.41 | G23: 106730.32 | H23: 118229.07 | I23: 120270.61 | J23: 118720.1 | K23: 118720.1 | L23: 131576.39 | M23: 120991.69 | N23: 117267.56 | O23: 93290.64 | P23: 93290.64 | Q23: 96323.7 | R23: 93227.88 | S23: 79210.86 | T23: 104619.01 | U23: 104619.01 | V23: 116134.8 | W23: 120900.32 | X23: 147396.47 | Y23: 145819.15 | Z23: 145819.15 | AA23: 143724.43 | AB23: 135250.28
A24: 1 | C24: 매입채무및기타채무 | E24: 15074.21 | F24: 15074.21 | G24: 13642.42 | H24: 16353.03 | I24: 15553.65 | J24: 19019.15 | K24: 19019.15 | L24: 15745 | M24: 17635.75 | N24: 12073.89 | O24: 17346.73 | P24: 17346.73 | Q24: 17382.61 | R24: 15785.18 | S24: 7584.09 | T24: 13610.57 | U24: 13610.57 | V24: 8917.89 | W24: 9528.06 | X24: 12880.57 | Y24: 8559.39 | Z24: 8559.39 | AA24: 17953.61 | AB24: 13383.58
A25: 1 | C25: 단기차입금 | E25: 97761.46 | F25: 97761.46 | G25: 69200 | H25: 76300 | I25: 81300 | J25: 73070 | K25: 73070 | L25: 82753 | M25: 86214 | N25: 92360 | O25: 62062.14 | P25: 62062.14 | Q25: 73100 | R25: 70400 | S25: 64850 | T25: 84150 | U25: 84150 | V25: 81450 | W25: 83140 | X25: 89100 | Y25: 105814.67 | Z25: 105814.67 | AA25: 104670.17 | AB25: 111400
A26: 1 | C26: 당기법인세부채(미지급법인세) | E26: 3118.85 | F26: 3118.85 | G26: 1714.12 | H26: 4276.54 | I26: 2775.19 | J26: 3198.36 | K26: 3198.36 | L26: 1805.35 | M26: 1529.14 | N26: 766.29 | R26: 909.62 | S26: 554.96 | T26: 870 | U26: 870 | V26: 563.29 | W26: 832.14 | X26: 407.83 | Y26: 891.68 | Z26: 891.68 | AA26: 516.16 | AB26: 3886.64
A27: 1 | C27: 유동리스부채 | E27: 359.83 | F27: 359.83 | G27: 370.78 | H27: 384.94 | I27: 366.59 | J27: 383.35 | K27: 383.35 | L27: 391.6 | M27: 440.86 | N27: 517.5 | O27: 477.32 | P27: 477.32 | Q27: 428.91 | R27: 594.49 | S27: 666.15 | T27: 641.51 | U27: 641.51 | V27: 1020.1 | W27: 586.89 | X27: 481.46 | Y27: 379.18 | Z27: 379.18 | AA27: 522.92 | AB27: 565.89
A28: 1 | C28: 리스부채 | E28: 1220.25 | F28: 1220.25 | G28: 1225.99 | H28: 1195.39 | I28: 1091.02 | J28: 1155.82 | K28: 1155.82 | L28: 1135.56 | M28: 1150.76 | N28: 1138.43 | O28: 1000.41 | P28: 1000.41 | Q28: 861.17 | R28: 1153.8 | S28: 1167.26 | T28: 1126.03 | U28: 1126.03 | V28: 1060.81 | W28: 972.14 | X28: 800.16 | Y28: 729.78 | Z28: 729.78 | AA28: 1110.21 | AB28: 1044.55
A29: 1 | C29: 단기금융부채 | E29: 3608.91 | F29: 3608.91 | G29: 3599.05 | H29: 3764.4 | I29: 3545.22 | J29: 4211.84 | K29: 4211.84 | L29: 4171.71 | M29: 4180.49 | N29: 4304.32 | O29: 4552.81 | P29: 4552.81 | Q29: 3891.94 | R29: 4692.11 | S29: 4113.58 | T29: 4873.31 | U29: 4873.31 | V29: 14693.01 | W29: 11196.87 | X29: 11248.74 | Y29: 17906.2 | Z29: 17906.2 | AA29: 15371.27 | AB29: 5544.4
A30: 1 | C30: 기타유동금융부채 | E30: 3249.08 | F30: 3249.08 | G30: 3228.27 | H30: 3379.46 | I30: 3178.63 | J30: 3828.49 | K30: 3828.49 | L30: 3780.11 | M30: 3739.63 | N30: 3786.82 | O30: 4075.49 | P30: 4075.49 | Q30: 3463.03 | R30: 4097.62 | S30: 3447.43 | T30: 4231.8 | U30: 4231.8 | V30: 13672.91 | W30: 10609.98 | X30: 10767.28 | Y30: 17527.02 | Z30: 17527.02 | AA30: 14848.35 | AB30: 4978.51
A31: 1 | C31: 기타유동부채 | E31: 4647.99 | F31: 4647.99 | G31: 1097.86 | H31: 856.54 | I31: 596.55 | J31: 2120.74 | K31: 2120.74 | L31: 4001.33 | M31: 1932.31 | N31: 1763.05 | O31: 3328.95 | P31: 3328.95 | Q31: 1949.16 | R31: 1440.98 | S31: 2108.22 | T31: 1115.12 | U31: 1115.12 | V31: 850.67 | W31: 344.57 | X31: 485.47 | Y31: 1742.26 | Z31: 1742.26 | AA31: 1807.83 | AB31: 1035.66
A32: 1 | C32: 비유동부채 | E32: 21639.56 | F32: 21639.56 | G32: 19682.05 | H32: 19430.75 | I32: 19588.83 | J32: 18862.77 | K32: 18862.77 | L32: 13023.26 | M32: 29377.71 | N32: 37094.7 | O32: 33402.75 | P32: 33402.75 | Q32: 33856.67 | R32: 33735.03 | S32: 33570.18 | T32: 31119.03 | U32: 31119.03 | V32: 36590.66 | W32: 29750.8 | X32: 12888.96 | Y32: 40031.84 | Z32: 40031.84 | AA32: 50437.97 | AB32: 51461.09
A33: 1 | C33: 장기차입금 | E33: 8321.4 | F33: 8321.4 | G33: 6000 | H33: 6000 | I33: 6000 | J33: 7000 | K33: 7000 | L33: 1000 | M33: 18600 | N33: 26100 | O33: 23600 | P33: 23600 | Q33: 23600 | R33: 23600 | S33: 23200 | T33: 23200 | U33: 23200 | V33: 23200 | W33: 17000 | Y33: 31760.11 | Z33: 31760.11 | AA33: 41604.61 | AB33: 43133.33
A34: 1 | C34: 확정급여부채 | E34: 3210.15 | F34: 3210.15 | G34: 3576.07 | H34: 3283.56 | I34: 3580.49 | J34: 2990.2 | K34: 2990.2 | L34: 3136.35 | M34: 4623.58 | N34: 4849.93 | O34: 3273.5 | P34: 3273.5 | Q34: 3778.67 | R34: 4533.27 | S34: 4767.03 | T34: 3623.76 | U34: 3623.76 | V34: 4164.49 | W34: 4063.93 | X34: 4275.38
A35: 1 | C35: 이연법인세부채 | E35: 8697.59 | F35: 8697.59 | G35: 8694.76 | H35: 8780.74 | I35: 8777.91 | J35: 7594.1 | K35: 7594.1 | L35: 7586.94 | M35: 4868.24 | N35: 4867.83 | O35: 5270.16 | P35: 5270.16 | Q35: 5269.75 | R35: 4226.45 | S35: 4226.04 | T35: 3594.74 | U35: 3594.74 | V35: 4173.79 | W35: 4303.17 | X35: 4302.43 | Y35: 5519.38 | Z35: 5519.38 | AA35: 5518.99 | AB35: 4699.41
A36: 1 | C36: 비유동리스부채 | E36: 860.42 | F36: 860.42 | G36: 855.21 | H36: 810.45 | I36: 724.43 | J36: 772.47 | K36: 772.47 | L36: 743.96 | M36: 709.9 | N36: 620.93 | O36: 523.09 | P36: 523.09 | Q36: 432.26 | R36: 559.31 | S36: 501.11 | T36: 484.52 | U36: 484.52 | V36: 40.71 | W36: 385.25 | X36: 318.7 | Y36: 350.6 | Z36: 350.6 | AA36: 587.29 | AB36: 478.66
A37: 1 | C37: 장기금융부채 | E37: 1410.42 | F37: 1410.42 | G37: 1411.21 | H37: 1366.45 | I37: 1230.43 | J37: 1278.47 | K37: 1278.47 | L37: 1299.96 | M37: 1285.9 | N37: 1276.93 | O37: 1259.09 | P37: 1259.09 | Q37: 1208.26 | R37: 1375.31 | S37: 1377.11 | T37: 700.52 | U37: 700.52 | V37: 5052.37 | W37: 4383.7 | X37: 4311.15 | Y37: 570.6 | Z37: 570.6 | AA37: 757.29 | AB37: 698.66
A38: 1 | C38: 기타비유동금융부채 | E38: 550 | F38: 550 | G38: 556 | H38: 556 | I38: 506 | J38: 506 | K38: 506 | L38: 556 | M38: 576 | N38: 656 | O38: 736 | P38: 736 | Q38: 776 | R38: 816 | S38: 876 | T38: 216 | U38: 216 | V38: 5011.66 | W38: 3998.45 | X38: 3992.45 | Y38: 220 | Z38: 220 | AA38: 170 | AB38: 220
A39: 1 | C39: 부채총계 | E39: 145850.97 | F39: 145850.97 | G39: 126412.36 | H39: 137659.82 | I39: 139859.45 | J39: 137582.87 | K39: 137582.87 | L39: 144599.65 | M39: 150369.4 | N39: 154362.25 | O39: 126693.39 | P39: 126693.39 | Q39: 130180.38 | R39: 126962.91 | S39: 112781.04 | T39: 135738.03 | U39: 135738.03 | V39: 152725.46 | W39: 150651.12 | X39: 160285.43 | Y39: 185850.99 | Z39: 185850.99 | AA39: 194162.39 | AB39: 186711.37
A40: 1 | C40: 지배주주지분 | E40: 100842.48 | F40: 100842.48 | G40: 112807.35 | H40: 113283.86 | I40: 113018 | J40: 113006.48 | K40: 113006.48 | L40: 112744.65 | M40: 114401.32 | N40: 113558.67 | O40: 121170.84 | P40: 121170.84 | Q40: 121035.37 | R40: 122242.98 | S40: 121814.37 | T40: 120932.72 | U40: 120932.72 | V40: 117914.45 | W40: 120198.15 | X40: 128801.65 | Y40: 123786.51 | Z40: 123786.51 | AA40: 134708.38 | AB40: 137784.22
...

Sheet BS별도
B1: (백만원) | C1: 이름: BS별도H | E1: 4Q21 | F1: 2021 | G1: 1Q22 | H1: 2Q22 | I1: 3Q22 | J1: 4Q22 | K1: 2022 | L1: 1Q23 | M1: 2Q23 | N1: 3Q23 | O1: 4Q23 | P1: 2023 | Q1: 1Q24 | R1: 2Q24 | S1: 3Q24 | T1: 4Q24 | U1: 2024 | V1: 1Q25 | W1: 2Q25 | X1: 3Q25 | Y1: 4Q25 | Z1: 2025 | AA1: 1Q26 | AB1: 2Q26 | AC1: 3Q26 | AD1: 4Q26 | AE1: 2026 | AF1: 1Q27 | AG1: 2Q27 | AH1: 3Q27 | AI1: 4Q27 | AJ1: 2027 | AK1: 1Q28 | AL1: 2Q28 | AM1: 3Q28 | AN1: 4Q28 | AO1: 2028
B2: 별도 | D2: fin json(kship_fin.py)
B3: 한국선재(별) | C3: UPDATE: 26-10-13 | E3: 1 | F3: 2 | G3: 3 | H3: 4 | I3: 5 | J3: 6 | K3: 7 | L3: 8 | M3: 9 | N3: 10 | O3: 11 | P3: 12 | Q3: 13 | R3: 14 | S3: 15 | T3: 16 | U3: 17 | V3: 18 | W3: 19 | X3: 20 | Y3: 21 | Z3: 22 | AA3: 23 | AB3: 24 | AC3: 25 | AD3: 26 | AE3: 27 | AF3: 28 | AG3: 29 | AH3: 30 | AI3: 31 | AJ3: 32 | AK3: 33 | AL3: 34 | AM3: 35 | AN3: 36 | AO3: 37
B4: Account Code | C4: AccountNAME | E4: 2021.12 | F4: 2021.12A | G4: 2022.03 | H4: 2022.06 | I4: 2022.09 | J4: 2022.12 | K4: 2022.12A | L4: 2023.03 | M4: 2023.06 | N4: 2023.09 | O4: 2023.12 | P4: 2023.12A | Q4: 2024.03 | R4: 2024.06 | S4: 2024.09 | T4: 2024.12 | U4: 2024.12A | V4: 2025.03 | W4: 2025.06 | X4: 2025.09 | Y4: 2025.12 | Z4: 2025.12A | AA4: 2026.03 | AB4: 2026.06 | AC4: 2026.09 | AD4: 2026.12 | AE4: 2026.12A | AF4: 2027.03 | AG4: 2027.06 | AH4: 2027.09 | AI4: 2027.12 | AJ4: 2027.12A | AK4: 2028.03 | AL4: 2028.06 | AM4: 2028.09 | AN4: 2028.12 | AO4: 2028.12A
A5: 1 | C5: 유동자산 | E5: 97719.53 | F5: 97719.53 | G5: 88231.89 | H5: 95391.35 | I5: 94799.4 | J5: 87637.58 | K5: 87637.58 | L5: 96808.09 | M5: 91197.88 | N5: 87701.19 | O5: 85208.2 | P5: 85208.2 | Q5: 88559.27 | R5: 84293.41 | S5: 76381.12 | T5: 84323.96 | U5: 84323.96 | V5: 74398.52 | W5: 75022.79 | X5: 80277.02 | Y5: 81554.69 | Z5: 81554.69 | AA5: 87292.76 | AB5: 81965.92
A6: 1 | C6: 현금및현금성자산 | E6: 10427.2 | F6: 10427.2 | G6: 13271.53 | H6: 5347.44 | I6: 7330.43 | J6: 7472.62 | K6: 7472.62 | L6: 5155.65 | M6: 6274.97 | N6: 3847.51 | O6: 9787.74 | P6: 9787.74 | Q6: 5041.55 | R6: 2907.23 | S6: 5625.18 | T6: 2079.07 | U6: 2079.07 | V6: 3761.92 | W6: 1391.17 | X6: 2893.17 | Y6: 7462.46 | Z6: 7462.46 | AA6: 11996.52 | AB6: 6209.11
A7: 1 | C7: 매출채권및기타채권 | E7: 25052.42 | F7: 25052.42 | G7: 28932.23 | H7: 26720.63 | I7: 30797.85 | J7: 28469.57 | K7: 28469.57 | L7: 34784.14 | M7: 26029.65 | N7: 30064.29 | O7: 26184.68 | P7: 26184.68 | Q7: 25105.07 | R7: 28181.72 | S7: 26126.19 | T7: 28460.31 | U7: 28460.31 | V7: 27441.1 | W7: 25662.96 | X7: 24458.93 | Y7: 21538.61 | Z7: 21538.61 | AA7: 23922.37 | AB7: 26729.94
A8: 1 | C8: 재고자산 | E8: 45458.24 | F8: 45458.24 | G8: 45200.41 | H8: 61121.07 | I8: 54037.53 | J8: 50697.87 | K8: 50697.87 | L8: 55911.08 | M8: 57205.28 | N8: 53234.33 | O8: 48371.88 | P8: 48371.88 | Q8: 57155.34 | R8: 52699.56 | S8: 44080.18 | T8: 53338.73 | U8: 53338.73 | V8: 43144.01 | W8: 47883.59 | X8: 52070.32 | Y8: 52017.25 | Z8: 52017.25 | AA8: 51308.39 | AB8: 48997.23
A9: 1 | C9: 기타유동금융자산 | E9: 297.98 | F9: 297.98 | G9: 298.73 | H9: 299.72 | I9: 2069.66 | J9: 409.71 | K9: 409.71 | L9: 389.79 | M9: 392.66
A10: 1 | C10: 기타유동자산 | E10: 534.47 | F10: 534.47 | G10: 529 | H10: 1902.5 | I10: 563.94 | J10: 587.81 | K10: 587.81 | L10: 567.43 | M10: 1295.32 | N10: 555.05 | O10: 576.72 | P10: 576.72 | Q10: 958.64 | R10: 504.9 | S10: 549.57 | T10: 445.84 | U10: 445.84 | V10: 51.49 | W10: 85.08 | X10: 827.04 | Y10: 501.31 | Z10: 501.31 | AA10: 65.48 | AB10: 29.64
A11: 1 | C11: 매각예정비유동자산및처분자산 | E11: 15949.22 | F11: 15949.22 | I11: 0
A12: 1 | C12: 비유동자산 | E12: 95091.21 | F12: 95091.21 | G12: 95722.74 | H12: 96657.31 | I12: 97908.56 | J12: 95475.76 | K12: 95475.76 | L12: 95151.24 | M12: 120279.94 | N12: 119734.06 | O12: 128314.85 | P12: 128314.85 | Q12: 127326.53 | R12: 128401.52 | S12: 127175.27 | T12: 137566.02 | U12: 137566.02 | V12: 137905.17 | W12: 139397.88 | X12: 151472.56 | Y12: 140727.52 | Z12: 140727.52 | AA12: 162673.48 | AB12: 168214.53
A13: 1 | C13: 장기금융자산 | E13: 1377.01 | F13: 1377.01 | G13: 1006.5 | H13: 1006.5 | I13: 1006.5 | J13: 1006.5 | K13: 1006.5 | L13: 1006.5 | M13: 1006.5 | N13: 1006.5 | O13: 730.61 | P13: 730.61 | Q13: 730.61 | R13: 138.61 | S13: 257.46 | T13: 12826.84 | U13: 12826.84 | V13: 12926.84 | W13: 11406.69 | X13: 18904.71 | Y13: 300.62 | Z13: 300.62 | AA13: 300.62 | AB13: 300.62
A14: 1 | C14: 투자자산 | E14: 28729.26 | F14: 28729.26 | G14: 29615.21 | H14: 29312.9 | I14: 30839.95 | J14: 29567.85 | K14: 29567.85 | L14: 30346.95 | M14: 32431.12 | N14: 32491.67 | O14: 41639.6 | P14: 41639.6 | Q14: 41230.39 | R14: 42650.64 | S14: 41614.07 | T14: 52658.62 | U14: 52658.62 | V14: 52878.7 | W14: 55109.33 | X14: 64014.38 | Y14: 46609.35 | Z14: 46609.35 | AA14: 57210.77 | AB14: 300.62
A15: 1 | C15: 종속기업및관계기업투자 | E15: 27352.25 | F15: 27352.25 | G15: 28608.71 | H15: 28306.4 | I15: 29833.45 | J15: 28561.35 | K15: 28561.35 | L15: 29340.45 | M15: 31424.62 | N15: 31485.17 | O15: 40908.99 | P15: 40908.99 | Q15: 40499.78 | R15: 42512.03 | S15: 41356.61 | T15: 39831.78 | U15: 39831.78 | V15: 39951.86 | W15: 43702.64 | X15: 45109.67 | Y15: 46308.73 | Z15: 46308.73 | AA15: 56910.15
A16: 1 | C16: 유형자산 | E16: 50780.77 | F16: 50780.77 | G16: 50293.77 | H16: 51643.36 | I16: 51505.09 | J16: 50383.36 | K16: 50383.36 | L16: 49828.77 | M16: 50965.9 | N16: 50520.77 | O16: 50107.9 | P16: 50107.9 | Q16: 49681.82 | R16: 49401.37 | S16: 49263.82 | T16: 48249.93 | U16: 48249.93 | V16: 48524.98 | W16: 48535.4 | X16: 49942.98 | Y16: 49825.87 | Z16: 49825.87 | AA16: 61390.1 | AB16: 61242.27
A17: 1 | C17: 사용권자산 | E17: 1541.63 | F17: 1541.63 | G17: 1440.85 | H17: 1366.37 | I17: 1265.04 | J17: 1164.09 | K17: 1164.09 | L17: 703.06 | M17: 653.31 | N17: 580.07 | O17: 506.83 | P17: 506.83 | Q17: 433.59 | R17: 447.6 | S17: 471.95 | T17: 347.58 | U17: 347.58 | V17: 314.89 | W17: 352.3 | X17: 351.69 | Y17: 353.89 | Z17: 353.89 | AA17: 653.48 | AB17: 577.42
A18: 1 | C18: 기타비유동자산 | E18: 1541.63 | F18: 1541.63 | G18: 1440.85 | H18: 1366.37 | I18: 1265.04 | J18: 1164.09 | K18: 1164.09 | L18: 703.06 | M18: 653.31 | N18: 580.07 | O18: 506.83 | P18: 506.83 | Q18: 433.59 | R18: 447.6 | S18: 471.95 | T18: 347.58 | U18: 347.58 | V18: 314.89 | W18: 352.3 | X18: 351.69 | Y18: 353.89 | Z18: 353.89 | AA18: 653.48 | AB18: 577.42
A19: 1 | C19: 투자부동산 | E19: 13704.73 | F19: 13704.73 | G19: 13673.78 | H19: 13642.83 | I19: 13611.89 | J19: 13580.94 | K19: 13580.94 | L19: 13549.99 | M19: 35514.02 | N19: 35437.82 | O19: 35361.62 | P19: 35361.62 | Q19: 35285.43 | R19: 35209.23 | S19: 35133.04 | T19: 35547.19 | U19: 35547.19 | V19: 35468.58 | W19: 34683.63 | X19: 36462.88 | Y19: 37493.46 | Z19: 37493.46 | AA19: 39417.7 | AB19: 40588
A20: 1 | C20: 무형자산 | E20: 334.81 | F20: 334.81 | G20: 328.62 | H20: 321.56 | I20: 314.5 | J20: 407.44 | K20: 407.44 | L20: 400.38 | M20: 393.49 | N20: 386.63 | O20: 381.94 | P20: 381.94 | Q20: 378.34 | R20: 375.74 | S20: 375.44 | T20: 373.35 | U20: 373.35 | V20: 371.3 | W20: 370.63 | X20: 406.52 | Y20: 404.48 | Z20: 404.48 | AA20: 154.04 | AB20: 131.58
A21: 1 | C21: 자산총계 | E21: 192810.75 | F21: 192810.75 | G21: 183954.63 | H21: 192048.66 | I21: 192707.97 | J21: 183113.34 | K21: 183113.34 | L21: 191959.33 | M21: 211477.81 | N21: 207435.24 | O21: 213523.05 | P21: 213523.05 | Q21: 215885.8 | R21: 212694.93 | S21: 203556.39 | T21: 221889.97 | U21: 221889.97 | V21: 212303.69 | W21: 214420.68 | X21: 231749.58 | Y21: 222282.21 | Z21: 222282.21 | AA21: 249966.24 | AB21: 250180.45
A22: 1 | C22: 유동부채 | E22: 75727.66 | F22: 75727.66 | G22: 57093.91 | H22: 64734.03 | I22: 65611.24 | J22: 57832.64 | K22: 57832.64 | L22: 73241.08 | M22: 73242.14 | N22: 70092.89 | O22: 68593.18 | P22: 68593.18 | Q22: 70893.5 | R22: 65914.65 | S22: 57013.57 | T22: 77859.88 | U22: 77859.88 | V22: 70451.67 | W22: 71389.48 | X22: 96875.04 | Y22: 92044.98 | Z22: 92044.98 | AA22: 98486.4 | AB22: 96179.2
A23: 1 | C23: 매입채무및기타채무 | E23: 8893.52 | F23: 8893.52 | G23: 8497.53 | H23: 12001.68 | I23: 11729.8 | J23: 10068.92 | K23: 10068.92 | L23: 10991.58 | M23: 10213.83 | N23: 6551.38 | O23: 11608.2 | P23: 11608.2 | Q23: 10392.24 | R23: 7836.15 | S23: 4128.56 | T23: 10477.3 | U23: 10477.3 | V23: 5219.2 | W23: 4916.5 | X23: 7754.14 | Y23: 3475.43 | Z23: 3475.43 | AA23: 10234.27 | AB23: 7103.53
A24: 1 | C24: 단기차입금 | E24: 57421.96 | F24: 57421.96 | G24: 43357.12 | H24: 46278.56 | I24: 49100 | J24: 42770 | K24: 42770 | L24: 56250 | M24: 60200 | N24: 60960 | O24: 53162.14 | P24: 53162.14 | Q24: 58200 | R24: 55500 | S24: 50000 | T24: 64700 | U24: 64700 | V24: 62000 | W24: 63690 | X24: 86700 | Y24: 86000 | Z24: 86000 | AA24: 85000 | AB24: 85000
A25: 1 | C25: 당기법인세부채(미지급법인세) | E25: 2806.15 | F25: 2806.15 | G25: 1529.45 | H25: 3438.1 | I25: 2091.36 | J25: 2047.28 | K25: 2047.28 | L25: 1156.78 | M25: 296.86 | N25: 144.55 | R25: 72.85 | S25: 54.43 | T25: 296.41 | U25: 296.41 | V25: 251.24 | W25: 0 | X25: 0 | AA25: -39.56 | AB25: 1011.5
A26: 1 | C26: 유동리스부채 | E26: 396.21 | F26: 396.21 | G26: 400.13 | H26: 404.33 | I26: 408.25 | J26: 412.28 | K26: 412.28 | L26: 300.01 | M26: 308.07 | N26: 303.22 | O26: 294.76 | P26: 294.76 | Q26: 277.97 | R26: 281.67 | S26: 290.57 | T26: 301.61 | U26: 301.61 | V26: 278.21 | W26: 235.33 | X26: 187.49 | Y26: 145.6 | Z26: 145.6 | AA26: 288.92 | AB26: 284.12
A27: 1 | C27: 리스부채 | E27: 1615.94 | F27: 1615.94 | G27: 1518.44 | H27: 1445.06 | I27: 1345.09 | J27: 1244.72 | K27: 1244.72 | L27: 773.71 | M27: 721.89 | N27: 645.93 | O27: 569.37 | P27: 569.37 | Q27: 491.88 | R27: 500.98 | S27: 520.68 | T27: 581.75 | U27: 581.75 | V27: 503.37 | W27: 494.45 | X27: 445.76 | Y27: 401.57 | Z27: 401.57 | AA27: 669.36 | AB27: 592.46
A28: 1 | C28: 단기금융부채 | E28: 2285.61 | F28: 2285.61 | G28: 2266.28 | H28: 2452.76 | I28: 2227.76 | J28: 2472.95 | K28: 2472.95 | L28: 2442.39 | M28: 2392.93 | N28: 2261.9 | O28: 2289.06 | P28: 2289.06 | Q28: 2182.55 | R28: 2262.82 | S28: 1883.44 | T28: 2200.53 | U28: 2200.53 | V28: 1978.52 | W28: 2185.84 | X28: 2071.44 | Y28: 2024.04 | Z28: 2024.04 | AA28: 1999.69 | AB28: 2290.45
A29: 1 | C29: 기타유동금융부채 | E29: 1889.4 | F29: 1889.4 | G29: 1866.15 | H29: 2048.43 | I29: 1819.51 | J29: 2060.67 | K29: 2060.67 | L29: 2142.38 | M29: 2084.86 | N29: 1958.68 | O29: 1994.3 | P29: 1994.3 | Q29: 1904.58 | R29: 1981.15 | S29: 1592.87 | T29: 1898.92 | U29: 1898.92 | V29: 1700.31 | W29: 1950.51 | X29: 1883.95 | Y29: 1878.44 | Z29: 1878.44 | AA29: 1710.77 | AB29: 2006.33
A30: 1 | C30: 기타유동부채 | E30: 4320.44 | F30: 4320.44 | G30: 1443.53 | H30: 562.93 | I30: 462.32 | J30: 473.49 | K30: 473.49 | L30: 2400.34 | M30: 138.52 | N30: 175.06 | O30: 1533.78 | P30: 1533.78 | Q30: 118.71 | R30: 242.83 | S30: 947.14 | T30: 185.64 | U30: 185.64 | V30: 1002.71 | W30: 597.15 | X30: 349.46 | Y30: 545.51 | Z30: 545.51 | AA30: 1291.99 | AB30: 773.71
A31: 1 | C31: 비유동부채 | E31: 16240.61 | F31: 16240.61 | G31: 14053.37 | H31: 14030.77 | I31: 14078.72 | J31: 12415.25 | K31: 12415.25 | L31: 6114.63 | M31: 24070.24 | N31: 24019.58 | O31: 23864.4 | P31: 23864.4 | Q31: 24062.31 | R31: 24564.24 | S31: 24755.39 | T31: 23137.72 | U31: 23137.72 | V31: 23977.91 | W31: 22862.71 | X31: 6102.54 | Y31: 6455.86 | Z31: 6455.86 | AA31: 16776.61 | AB31: 16244.05
A32: 1 | C32: 장기차입금 | E32: 8321.4 | F32: 8321.4 | G32: 6000 | H32: 6000 | I32: 6000 | J32: 6000 | K32: 6000 | M32: 17000 | N32: 17000 | O32: 17000 | P32: 17000 | Q32: 17000 | R32: 17000 | S32: 17000 | T32: 17000 | U32: 17000 | V32: 17000 | W32: 17000 | X32: 0 | AA32: 10000 | AB32: 10000
A33: 1 | C33: 확정급여부채 | E33: 777.71 | F33: 777.71 | G33: 1007.29 | H33: 906.48 | I33: 1108.33 | J33: 407.94 | K33: 407.94 | L33: 436.06 | M33: 1396.25 | N33: 1416.7 | O33: 656.32 | P33: 656.32 | Q33: 914.92 | R33: 1494.88 | S33: 1689.23 | T33: 1059.96 | U33: 1059.96 | V33: 1390.68 | W33: 841.25 | X33: 1087.93
A34: 1 | C34: 이연법인세부채 | E34: 5717.77 | F34: 5717.77 | G34: 5717.77 | H34: 5873.56 | I34: 5873.56 | J34: 5014.87 | K34: 5014.87 | L34: 5014.87 | M34: 4855.17 | N34: 4855.17 | O34: 5508.48 | P34: 5508.48 | Q34: 5508.48 | R34: 5425.05 | S34: 5425.05 | T34: 4386.61 | U34: 4386.61 | V34: 4966.07 | W34: 4366.33 | X34: 4366.33 | Y34: 5687.72 | Z34: 5687.72 | AA34: 5687.72 | AB34: 5035.45
A35: 1 | C35: 비유동리스부채 | E35: 1219.73 | F35: 1219.73 | G35: 1118.31 | H35: 1040.73 | I35: 936.84 | J35: 832.44 | K35: 832.44 | L35: 473.7 | M35: 413.82 | N35: 342.71 | O35: 274.61 | P35: 274.61 | Q35: 213.91 | R35: 219.31 | S35: 230.11 | T35: 280.14 | U35: 280.14 | V35: 225.16 | W35: 259.12 | X35: 258.27 | Y35: 255.97 | Z35: 255.97 | AA35: 380.44 | AB35: 308.34
A36: 1 | C36: 장기금융부채 | E36: 1423.73 | F36: 1423.73 | G36: 1328.31 | H36: 1250.73 | I36: 1096.84 | J36: 992.44 | K36: 992.44 | L36: 663.7 | M36: 818.82 | N36: 747.71 | O36: 699.61 | P36: 699.61 | Q36: 638.91 | R36: 644.31 | S36: 641.11 | T36: 691.14 | U36: 691.14 | V36: 621.16 | W36: 655.12 | X36: 648.27 | Y36: 655.97 | Z36: 655.97 | AA36: 730.44 | AB36: 708.34
A37: 1 | C37: 기타비유동금융부채 | E37: 204 | F37: 204 | G37: 210 | H37: 210 | I37: 160 | J37: 160 | K37: 160 | L37: 190 | M37: 405 | N37: 405 | O37: 425 | P37: 425 | Q37: 425 | R37: 425 | S37: 411 | T37: 411 | U37: 411 | V37: 396 | W37: 396 | X37: 390 | Y37: 400 | Z37: 400 | AA37: 350 | AB37: 400
A38: 1 | C38: 부채총계 | E38: 91968.27 | F38: 91968.27 | G38: 71147.28 | H38: 78764.8 | I38: 79689.96 | J38: 70247.89 | K38: 70247.89 | L38: 79355.7 | M38: 97312.39 | N38: 94112.47 | O38: 92457.59 | P38: 92457.59 | Q38: 94955.81 | R38: 90478.89 | S38: 81768.96 | T38: 100997.6 | U38: 100997.6 | V38: 94429.58 | W38: 94252.18 | X38: 102977.59 | Y38: 98500.84 | Z38: 98500.84 | AA38: 115263 | AB38: 112423.24
A39: 1 | C39: 자본금 | E39: 12261.13 | F39: 12261.13 | G39: 12261.13 | H39: 12261.13 | I39: 12261.13 | J39: 12261.13 | K39: 12261.13 | L39: 12261.13 | M39: 12261.13 | N39: 12261.13 | O39: 12261.13 | P39: 12261.13 | Q39: 12261.13 | R39: 12261.13 | S39: 12261.13 | T39: 12261.13 | U39: 12261.13 | V39: 13368.13 | W39: 13368.13 | X39: 13368.13 | Y39: 13368.13 | Z39: 13368.13 | AA39: 13368.13 | AB39: 13368.13
A40: 1 | C40: 자본잉여금 | E40: 19928.82 | F40: 19928.82 | G40: 19928.82 | H40: 19928.82 | I40: 19692.75 | J40: 18226.23 | K40: 18226.23 | L40: 18203.39 | M40: 18203.39 | N40: 17851.98 | O40: 19432.24 | P40: 19432.24 | Q40: 19432.24 | R40: 19432.24 | S40: 19432.24 | T40: 23055.03 | U40: 23055.03 | V40: 19657.17 | W40: 23145.32 | X40: 23145.32 | Y40: 23092.83 | Z40: 23092.83 | AA40: 23092.83 | AB40: 23700.94
...

Sheet subQ
A1: YQ | C1: subQ 분기 서브모델(억원, U=100) | E1: 4Q21 | F1: 2021 | G1: 1Q22 | H1: 2Q22 | I1: 3Q22 | J1: 4Q22 | K1: 2022 | L1: 1Q23 | M1: 2Q23 | N1: 3Q23 | O1: 4Q23 | P1: 2023 | Q1: 1Q24 | R1: 2Q24 | S1: 3Q24 | T1: 4Q24 | U1: 2024 | V1: 1Q25 | W1: 2Q25 | X1: 3Q25 | Y1: 4Q25 | Z1: 2025 | AA1: 1Q26 | AB1: 2Q26 | AC1: 3Q26 | AD1: 4Q26 | AE1: 2026 | AF1: 1Q27 | AG1: 2Q27 | AH1: 3Q27 | AI1: 4Q27 | AJ1: 2027 | AK1: 1Q28 | AL1: 2Q28 | AM1: 3Q28 | AN1: 4Q28 | AO1: 2028
A2: A=이름(key) B=그룹 C=단위 D=FnGuide 계정명(VLOOKUP 키). 확정=VLOOKUP(BS), 추정=변수 가정 참조
E3: 1 | F3: 2 | G3: 3 | H3: 4 | I3: 5 | J3: 6 | K3: 7 | L3: 8 | M3: 9 | N3: 10 | O3: 11 | P3: 12 | Q3: 13 | R3: 14 | S3: 15 | T3: 16 | U3: 17 | V3: 18 | W3: 19 | X3: 20 | Y3: 21 | Z3: 22 | AA3: 23 | AB3: 24 | AC3: 25 | AD3: 26 | AE3: 27 | AF3: 28 | AG3: 29 | AH3: 30 | AI3: 31 | AJ3: 32 | AK3: 33 | AL3: 34 | AM3: 35 | AN3: 36 | AO3: 37
E4: 2021.12 | F4: 2021.12A | G4: 2022.03 | H4: 2022.06 | I4: 2022.09 | J4: 2022.12 | K4: 2022.12A | L4: 2023.03 | M4: 2023.06 | N4: 2023.09 | O4: 2023.12 | P4: 2023.12A | Q4: 2024.03 | R4: 2024.06 | S4: 2024.09 | T4: 2024.12 | U4: 2024.12A | V4: 2025.03 | W4: 2025.06 | X4: 2025.09 | Y4: 2025.12 | Z4: 2025.12A | AA4: 2026.03 | AB4: 2026.06 | AC4: 2026.09 | AD4: 2026.12 | AE4: 2026.12A | AF4: 2027.03 | AG4: 2027.06 | AH4: 2027.09 | AI4: 2027.12 | AJ4: 2027.12A | AK4: 2028.03 | AL4: 2028.06 | AM4: 2028.09 | AN4: 2028.12 | AO4: 2028.12A
A5: 매출액 | B5: 손익 | C5: 억원 | D5: 매출액(수익) | E5: =IFERROR(VLOOKUP($D5,BS연결,MATCH(E$1,BS연결H,0),0)/100,"") | G5: =IFERROR(VLOOKUP($D5,BS연결,MATCH(G$1,BS연결H,0),0)/100,"") | H5: =IFERROR(VLOOKUP($D5,BS연결,MATCH(H$1,BS연결H,0),0)/100,"") | I5: =IFERROR(VLOOKUP($D5,BS연결,MATCH(I$1,BS연결H,0),0)/100,"") | J5: =IFERROR(VLOOKUP($D5,BS연결,MATCH(J$1,BS연결H,0),0)/100,"") | K5: =IFERROR(VLOOKUP($D5,BS연결,MATCH(K$1,BS연결H,0),0)/100,"") | L5: =IFERROR(VLOOKUP($D5,BS연결,MATCH(L$1,BS연결H,0),0)/100,"") | M5: =IFERROR(VLOOKUP($D5,BS연결,MATCH(M$1,BS연결H,0),0)/100,"") | N5: =IFERROR(VLOOKUP($D5,BS연결,MATCH(N$1,BS연결H,0),0)/100,"") | ... AB5: =IFERROR(VLOOKUP($D5,BS연결,MATCH(AB$1,BS연결H,0),0)/100,"") | AC5: =IFERROR(X5*(1+변수!AC21),"") | AD5: =IFERROR(Y5*(1+변수!AD21),"") | AE5: =SUM(AA5:AD5) | AF5: =IFERROR(AA5*(1+변수!AF21),"") | AG5: =IFERROR(AB5*(1+변수!AG21),"") | AH5: =IFERROR(AC5*(1+변수!AH21),"") | AI5: =IFERROR(AD5*(1+변수!AI21),"") | AJ5: =SUM(AF5:AI5) | AK5: =IFERROR(AF5*(1+변수!AK21),"") | AL5: =IFERROR(AG5*(1+변수!AL21),"") | AM5: =IFERROR(AH5*(1+변수!AM21),"") | AN5: =IFERROR(AI5*(1+변수!AN21),"") | AO5: =SUM(AK5:AN5)
A6: 매출원가 | B6: 손익 | C6: 억원 | D6: 매출원가 | E6: =IFERROR(VLOOKUP($D6,BS연결,MATCH(E$1,BS연결H,0),0)/100,"") | G6: =IFERROR(VLOOKUP($D6,BS연결,MATCH(G$1,BS연결H,0),0)/100,"") | H6: =IFERROR(VLOOKUP($D6,BS연결,MATCH(H$1,BS연결H,0),0)/100,"") | I6: =IFERROR(VLOOKUP($D6,BS연결,MATCH(I$1,BS연결H,0),0)/100,"") | J6: =IFERROR(VLOOKUP($D6,BS연결,MATCH(J$1,BS연결H,0),0)/100,"") | K6: =IFERROR(VLOOKUP($D6,BS연결,MATCH(K$1,BS연결H,0),0)/100,"") | L6: =IFERROR(VLOOKUP($D6,BS연결,MATCH(L$1,BS연결H,0),0)/100,"") | M6: =IFERROR(VLOOKUP($D6,BS연결,MATCH(M$1,BS연결H,0),0)/100,"") | N6: =IFERROR(VLOOKUP($D6,BS연결,MATCH(N$1,BS연결H,0),0)/100,"") | ... AB6: =IFERROR(VLOOKUP($D6,BS연결,MATCH(AB$1,BS연결H,0),0)/100,"") | AC6: =IFERROR(AC5-AC7,"") | AD6: =IFERROR(AD5-AD7,"") | AE6: =SUM(AA6:AD6) | AF6: =IFERROR(AF5-AF7,"") | AG6: =IFERROR(AG5-AG7,"") | AH6: =IFERROR(AH5-AH7,"") | AI6: =IFERROR(AI5-AI7,"") | AJ6: =SUM(AF6:AI6) | AK6: =IFERROR(AK5-AK7,"") | AL6: =IFERROR(AL5-AL7,"") | AM6: =IFERROR(AM5-AM7,"") | AN6: =IFERROR(AN5-AN7,"") | AO6: =SUM(AK6:AN6)
A7: 매출총이익 | B7: 손익 | C7: 억원 | D7: 매출총이익 | E7: =IFERROR(VLOOKUP($D7,BS연결,MATCH(E$1,BS연결H,0),0)/100,"") | G7: =IFERROR(VLOOKUP($D7,BS연결,MATCH(G$1,BS연결H,0),0)/100,"") | H7: =IFERROR(VLOOKUP($D7,BS연결,MATCH(H$1,BS연결H,0),0)/100,"") | I7: =IFERROR(VLOOKUP($D7,BS연결,MATCH(I$1,BS연결H,0),0)/100,"") | J7: =IFERROR(VLOOKUP($D7,BS연결,MATCH(J$1,BS연결H,0),0)/100,"") | K7: =IFERROR(VLOOKUP($D7,BS연결,MATCH(K$1,BS연결H,0),0)/100,"") | L7: =IFERROR(VLOOKUP($D7,BS연결,MATCH(L$1,BS연결H,0),0)/100,"") | M7: =IFERROR(VLOOKUP($D7,BS연결,MATCH(M$1,BS연결H,0),0)/100,"") | N7: =IFERROR(VLOOKUP($D7,BS연결,MATCH(N$1,BS연결H,0),0)/100,"") | ... AB7: =IFERROR(VLOOKUP($D7,BS연결,MATCH(AB$1,BS연결H,0),0)/100,"") | AC7: =IFERROR(AC9+AC8,"") | AD7: =IFERROR(AD9+AD8,"") | AE7: =SUM(AA7:AD7) | AF7: =IFERROR(AF9+AF8,"") | AG7: =IFERROR(AG9+AG8,"") | AH7: =IFERROR(AH9+AH8,"") | AI7: =IFERROR(AI9+AI8,"") | AJ7: =SUM(AF7:AI7) | AK7: =IFERROR(AK9+AK8,"") | AL7: =IFERROR(AL9+AL8,"") | AM7: =IFERROR(AM9+AM8,"") | AN7: =IFERROR(AN9+AN8,"") | AO7: =SUM(AK7:AN7)
A8: 판관비 | B8: 손익 | C8: 억원 | D8: 판관비 | E8: =IFERROR(VLOOKUP($D8,BS연결,MATCH(E$1,BS연결H,0),0)/100,"") | G8: =IFERROR(VLOOKUP($D8,BS연결,MATCH(G$1,BS연결H,0),0)/100,"") | H8: =IFERROR(VLOOKUP($D8,BS연결,MATCH(H$1,BS연결H,0),0)/100,"") | I8: =IFERROR(VLOOKUP($D8,BS연결,MATCH(I$1,BS연결H,0),0)/100,"") | J8: =IFERROR(VLOOKUP($D8,BS연결,MATCH(J$1,BS연결H,0),0)/100,"") | K8: =IFERROR(VLOOKUP($D8,BS연결,MATCH(K$1,BS연결H,0),0)/100,"") | L8: =IFERROR(VLOOKUP($D8,BS연결,MATCH(L$1,BS연결H,0),0)/100,"") | M8: =IFERROR(VLOOKUP($D8,BS연결,MATCH(M$1,BS연결H,0),0)/100,"") | N8: =IFERROR(VLOOKUP($D8,BS연결,MATCH(N$1,BS연결H,0),0)/100,"") | ... AB8: =IFERROR(VLOOKUP($D8,BS연결,MATCH(AB$1,BS연결H,0),0)/100,"") | AC8: =IFERROR(AC5*변수!AC22,"") | AD8: =IFERROR(AD5*변수!AD22,"") | AE8: =SUM(AA8:AD8) | AF8: =IFERROR(AF5*변수!AF22,"") | AG8: =IFERROR(AG5*변수!AG22,"") | AH8: =IFERROR(AH5*변수!AH22,"") | AI8: =IFERROR(AI5*변수!AI22,"") | AJ8: =SUM(AF8:AI8) | AK8: =IFERROR(AK5*변수!AK22,"") | AL8: =IFERROR(AL5*변수!AL22,"") | AM8: =IFERROR(AM5*변수!AM22,"") | AN8: =IFERROR(AN5*변수!AN22,"") | AO8: =SUM(AK8:AN8)
A9: 영업이익 | B9: 손익 | C9: 억원 | D9: 영업이익 | E9: =IFERROR(VLOOKUP($D9,BS연결,MATCH(E$1,BS연결H,0),0)/100,"") | G9: =IFERROR(VLOOKUP($D9,BS연결,MATCH(G$1,BS연결H,0),0)/100,"") | H9: =IFERROR(VLOOKUP($D9,BS연결,MATCH(H$1,BS연결H,0),0)/100,"") | I9: =IFERROR(VLOOKUP($D9,BS연결,MATCH(I$1,BS연결H,0),0)/100,"") | J9: =IFERROR(VLOOKUP($D9,BS연결,MATCH(J$1,BS연결H,0),0)/100,"") | K9: =IFERROR(VLOOKUP($D9,BS연결,MATCH(K$1,BS연결H,0),0)/100,"") | L9: =IFERROR(VLOOKUP($D9,BS연결,MATCH(L$1,BS연결H,0),0)/100,"") | M9: =IFERROR(VLOOKUP($D9,BS연결,MATCH(M$1,BS연결H,0),0)/100,"") | N9: =IFERROR(VLOOKUP($D9,BS연결,MATCH(N$1,BS연결H,0),0)/100,"") | ... AB9: =IFERROR(VLOOKUP($D9,BS연결,MATCH(AB$1,BS연결H,0),0)/100,"") | AC9: =IFERROR(AC5*변수!AC23,"") | AD9: =IFERROR(AD5*변수!AD23,"") | AE9: =SUM(AA9:AD9) | AF9: =IFERROR(AF5*변수!AF23,"") | AG9: =IFERROR(AG5*변수!AG23,"") | AH9: =IFERROR(AH5*변수!AH23,"") | AI9: =IFERROR(AI5*변수!AI23,"") | AJ9: =SUM(AF9:AI9) | AK9: =IFERROR(AK5*변수!AK23,"") | AL9: =IFERROR(AL5*변수!AL23,"") | AM9: =IFERROR(AM5*변수!AM23,"") | AN9: =IFERROR(AN5*변수!AN23,"") | AO9: =SUM(AK9:AN9)
A10: OPM | B10: 손익 | C10: % | D10: 영업이익률 | E10: =IFERROR(E9/E5,"") | G10: =IFERROR(G9/G5,"") | H10: =IFERROR(H9/H5,"") | I10: =IFERROR(I9/I5,"") | J10: =IFERROR(J9/J5,"") | K10: =IFERROR(K9/K5,"") | L10: =IFERROR(L9/L5,"") | M10: =IFERROR(M9/M5,"") | N10: =IFERROR(N9/N5,"") | ... AO10: =IFERROR(AO9/AO5,"")
