Workbook
Name 변수H: 변수!$C$1:$AO$1
Name 환율: 변수!$C$6:$AO$13
Name BS연결H: BS연결!$C$1:$AO$1
Name BS연결: BS연결!$C$5:$AO$5
Name BS별도H: BS별도!$C$1:$AO$1
Name BS별도: BS별도!$C$5:$AO$90
Name SUBQH: subQ!$A$1:$AO$1
Name subQ: subQ!$A$5:$AO$41

Sheet README
A1: 한국주강(025890) 실적 모델 — ARGUS 한국조선
A2: 기준 분기 2026Q2 · 마지막 실적 2026Q2 · 생성 2026-10-14
A3: 모든 수치는 모델 산출값(DART 공개 재무제표 + 우리 추정)이다 — 목표주가·투자 추천 아님. 참고용 · 투자조언 아님.
A5: 시트
A6: 변수 가정 시계열. 환율 8행(ECB via frankfurter — L2 fx.json; 추정 분기 = 노란 가정), 추정 드라이버(노란 셀 = 모델값에서 역산한 가정, 바꾸면 재계산; 연녹 셀 = 3절 스칼라 참조 수식), 3절 스칼라 가정(세율·판관비율·지배주주비중·이자율·종가·PER 밴드·COE·외화 순노출·헤지비율)
A7: BS연결/BS별도 FnGuide 계정명 × 기간 값 덤프(백만원). 행1 분기라벨, 행4 YYYY.MM / YYYY.12A. 이름정의 BS연결H·BS연결(계정명 C열부터)
A8: subQ 분기 서브모델(억원 = 백만원/100). 확정 행: =IFERROR(VLOOKUP($D행,BS연결,MATCH(E$1,BS연결H,0),0)/100,"") 추정 행: 변수 시트 가정 셀 참조 수식. 외환손익·파생상품손익은 BS 계정 합·차, 기타금융손익은 잔차, OPM·EPS·BPS·PER·PBR 은 파생 수식
A9: SLS 선표(조선사만, sls json 있을 때): 요약 행(sls 저장값) + 계약별 스케줄(백만$) × (헤지비율 × 헤지환율 + (1−헤지비율) × 건조시점 환율[변수 원/달러(평균)]) → 원화 수식 블록 → 합계 행이 subQ 매출조선에 연결
A10: 시나리오 신규수주 보수/기준/낙관(forecast_panel 패널, 모델에 scenarios 가 있을 때만): 매출액·영업이익 = subQ 기준값 ± (시나리오 신규 − base 신규) × OPM. base 만 subQ 행에 포함, 나머지는 합산 안 함
A11: 분기/연간예상 subQ 를 이름(A열 key)으로 VLOOKUP 한 보고서 표(억원)
A12: TP PER 밴드 × 12M fwd EPS, PBR = ROE/COE × BPS — 모델 산출값 구간, 목표주가·추천 아님
A13: 외화 환율 QoQ, 외화 순노출 × Δ기말환율 → 환관련손익 추정
... A34: 백테스트: {"freeze": "2025Q2", "horizon": 4, "revenue_wape_pct": 16.0, "op_wape_pct": 180.2, "n": 4, "note": "단일 회사 4분기 — 통계 아님", "driver_at_freeze": "trend_seasonal", "selection_oos_at_freeze": null, "frozen_inputs": "fin(연결/별도)·고객 조선사 모델·지주 자회사 모델은 2025Q2 까지의 분기만; 선표는 체결일 ≤ 2025Q2 말일 계약(원장 최신 금액·코호트 등급, 환산 없음); 잔고는 yards_cache 2025Q2; 시세·환율 forward·prices·forecast_panel 신규수주 미사용. 고객 가중치(suppliers.json 언급 비중)와 합병 체인링크는 현재 지식; 고객 연동 채택은 동결 모델 안에서도 자기 la−4분기 OOS 규칙(selection_oos_at_freeze)", "detail": [{"q": "2025Q3", "rev_pred": 83.53, "rev_act": 97.77, "op_pred": 2.39, "op_act": -3.27}, {"q": "2025Q4", "rev_pred": 115.84, "rev_act": 89.99, "op_pred": 3.32, "op_act": -2.78}, {"q": "2026Q1", "rev_pred": 79.11, "rev_act": 88.26, "op_pred": 2.27, "op_act": 0.59}, {"q": "2026Q2", "rev_pred": 97.99, "rev_act": 110.76, "op_pred": 2.81, "op_act": 1.53}]}

Sheet 변수
C1: 이름: 변수H | E1: 4Q21 | F1: 2021 | G1: 1Q22 | H1: 2Q22 | I1: 3Q22 | J1: 4Q22 | K1: 2022 | L1: 1Q23 | M1: 2Q23 | N1: 3Q23 | O1: 4Q23 | P1: 2023 | Q1: 1Q24 | R1: 2Q24 | S1: 3Q24 | T1: 4Q24 | U1: 2024 | V1: 1Q25 | W1: 2Q25 | X1: 3Q25 | Y1: 4Q25 | Z1: 2025 | AA1: 1Q26 | AB1: 2Q26 | AC1: 3Q26 | AD1: 4Q26 | AE1: 2026 | AF1: 1Q27 | AG1: 2Q27 | AH1: 3Q27 | AI1: 4Q27 | AJ1: 2027 | AK1: 1Q28 | AL1: 2Q28 | AM1: 3Q28 | AN1: 4Q28 | AO1: 2028
A2: 가정 시계열 — 노란 셀은 추정 가정(모델값에서 역산), 연녹 셀은 3절 스칼라 참조 수식. 바꾸면 subQ·분기·연간예상·TP·시나리오가 재계산됩니다.
E3: 1 | F3: 2 | G3: 3 | H3: 4 | I3: 5 | J3: 6 | K3: 7 | L3: 8 | M3: 9 | N3: 10 | O3: 11 | P3: 12 | Q3: 13 | R3: 14 | S3: 15 | T3: 16 | U3: 17 | V3: 18 | W3: 19 | X3: 20 | Y3: 21 | Z3: 22 | AA3: 23 | AB3: 24 | AC3: 25 | AD3: 26 | AE3: 27 | AF3: 28 | AG3: 29 | AH3: 30 | AI3: 31 | AJ3: 32 | AK3: 33 | AL3: 34 | AM3: 35 | AN3: 36 | AO3: 37
E4: 2021.12 | F4: 2021.12A | G4: 2022.03 | H4: 2022.06 | I4: 2022.09 | J4: 2022.12 | K4: 2022.12A | L4: 2023.03 | M4: 2023.06 | N4: 2023.09 | O4: 2023.12 | P4: 2023.12A | Q4: 2024.03 | R4: 2024.06 | S4: 2024.09 | T4: 2024.12 | U4: 2024.12A | V4: 2025.03 | W4: 2025.06 | X4: 2025.09 | Y4: 2025.12 | Z4: 2025.12A | AA4: 2026.03 | AB4: 2026.06 | AC4: 2026.09 | AD4: 2026.12 | AE4: 2026.12A | AF4: 2027.03 | AG4: 2027.06 | AH4: 2027.09 | AI4: 2027.12 | AJ4: 2027.12A | AK4: 2028.03 | AL4: 2028.06 | AM4: 2028.09 | AN4: 2028.12 | AO4: 2028.12A
B5: 1. FX | C5: 이름: 환율
A6: USDKRW_avg | C6: 원/달러(평균) | E6: 1183.5 | F6: 1145.51 | G6: 1205.78 | H6: 1262.09 | I6: 1341.93 | J6: 1360.12 | K6: 1292.98 | L6: 1276.95 | M6: 1315.69 | N6: 1313.62 | O6: 1322.01 | P6: 1306.85 | Q6: 1330.14 | R6: 1371.28 | S6: 1356.22 | T6: 1396.3 | U6: 1363.53 | V6: 1452.28 | W6: 1398.52 | X6: 1386.95 | Y6: 1449.19 | Z6: 1421.52 | AA6: 1466.12 | AB6: 1501.75 | AC6: 1418.75 | AD6: 1343.39 | AE6: 1456.01 | AF6: 1341.45 | AG6: 1341.45 | AH6: 1341.45 | AI6: 1341.45 | AK6: 1341.45 | AL6: 1341.45 | AM6: 1341.45 | AN6: 1341.45
A7: USDKRW_end | C7: 원/달러(기말) | E7: 1188.75 | F7: 1188.75 | G7: 1213.74 | H7: 1301.24 | I7: 1436.9 | J7: 1260.16 | K7: 1260.16 | L7: 1305.99 | M7: 1321.44 | N7: 1345.35 | O7: 1297.43 | P7: 1297.43 | Q7: 1349.25 | R7: 1377.73 | S7: 1312.17 | T7: 1474.78 | U7: 1474.78 | V7: 1474.54 | W7: 1355.13 | X7: 1403.67 | Y7: 1444.2 | Z7: 1444.2 | AA7: 1524.8 | AB7: 1550.89 | AC7: 1355.4 | AD7: 1341.45 | AE7: 1341.45 | AF7: 1341.45 | AG7: 1341.45 | AH7: 1341.45 | AI7: 1341.45 | AK7: 1341.45 | AL7: 1341.45 | AM7: 1341.45 | AN7: 1341.45
A8: JPY100KRW_avg | C8: 원/100Y(평균) | E8: 1041.02 | F8: 1042.74 | G8: 1036.79 | H8: 972.23 | I8: 970.61 | J8: 961.03 | K8: 985.1 | L8: 964.89 | M8: 957.36 | N8: 909 | O8: 893.22 | P8: 931.11 | Q8: 896.29 | R8: 880.14 | S8: 909.35 | T8: 917.25 | U8: 900.92 | V8: 952.59 | W8: 967.92 | X8: 940.32 | Y8: 940.77 | Z8: 950.17 | AA8: 934.39 | AB8: 942.16 | AC8: 890.41 | AD8: 849.39 | AE8: 918.46 | AF8: 848.37 | AG8: 848.37 | AH8: 848.37 | AI8: 848.37 | AK8: 848.37 | AL8: 848.37 | AM8: 848.37 | AN8: 848.37
A9: JPY100KRW_end | C9: 원/100Y(기말) | E9: 1032.62 | F9: 1032.62 | G9: 996.83 | H9: 954.9 | I9: 993.29 | J9: 955.54 | K9: 955.54 | L9: 980.62 | M9: 913.67 | N9: 901.47 | O9: 917.04 | P9: 917.04 | Q9: 892.42 | R9: 857.76 | S9: 919.21 | T9: 939.65 | U9: 939.65 | V9: 986.84 | W9: 938.85 | X9: 948.49 | Y9: 921.81 | Z9: 921.81 | AA9: 955.99 | AB9: 954.75 | AC9: 863.31 | AD9: 848.37 | AE9: 848.37 | AF9: 848.37 | AG9: 848.37 | AH9: 848.37 | AI9: 848.37 | AK9: 848.37 | AL9: 848.37 | AM9: 848.37 | AN9: 848.37
A10: EURKRW_avg | C10: W/Euro(평균) | E10: 1353.32 | F10: 1354.06 | G10: 1352.29 | H10: 1343.31 | I10: 1350.63 | J10: 1386.07 | K10: 1358.07 | L10: 1369.93 | M10: 1432.41 | N10: 1429.41 | O10: 1420.91 | P10: 1412.88 | Q10: 1444.21 | R10: 1476.42 | S10: 1489.3 | T10: 1490.78 | U10: 1475.4 | V10: 1528.33 | W10: 1585.13 | X10: 1620.04 | Y10: 1686.02 | Z10: 1605.45 | AA10: 1715.47 | AB10: 1746.09 | AC10: 1631.97 | AD10: 1506.62 | AE10: 1688.01 | AF10: 1500.82 | AG10: 1500.82 | AH10: 1500.82 | AI10: 1500.82 | AK10: 1500.82 | AL10: 1500.82 | AM10: 1500.82 | AN10: 1500.82
A11: EURKRW_end | C11: W/Euro(기말) | E11: 1346.38 | F11: 1346.38 | G11: 1347.37 | H11: 1351.6 | I11: 1400.62 | J11: 1344.08 | K11: 1344.08 | L11: 1420.26 | M11: 1435.88 | N11: 1425.26 | O11: 1433.66 | P11: 1433.66 | Q11: 1458.68 | R11: 1474.86 | S11: 1469.1 | T11: 1532.14 | U11: 1532.14 | V11: 1594.72 | W11: 1588.22 | X11: 1648.04 | Y11: 1696.94 | Z11: 1696.94 | AA11: 1753.21 | AB11: 1767.09 | AC11: 1539.06 | AD11: 1500.82 | AE11: 1500.82 | AF11: 1500.82 | AG11: 1500.82 | AH11: 1500.82 | AI11: 1500.82 | AK11: 1500.82 | AL11: 1500.82 | AM11: 1500.82 | AN11: 1500.82
A12: CNYKRW_avg | C12: 원/중국원(평균) | E12: 185.14 | F12: 177.65 | G12: 189.93 | H12: 190.76 | I12: 195.79 | J12: 191.09 | K12: 191.93 | L12: 186.59 | M12: 187.45 | N12: 181.28 | O12: 182.86 | P12: 184.52 | Q12: 185.04 | R12: 189.35 | S12: 189.24 | T12: 194.24 | U12: 189.49 | V12: 199.63 | W12: 193.41 | X12: 193.79 | Y12: 204.38 | Z12: 197.8 | AA12: 211.75 | AB12: 220.8 | AC12: 210.43 | AD12: 200.49 | AE12: 213.61 | AF12: 200.4 | AG12: 200.4 | AH12: 200.4 | AI12: 200.4 | AK12: 200.4 | AL12: 200.4 | AM12: 200.4 | AN12: 200.4
A13: CNYKRW_end | C13: 원/중국원(기말) | E13: 187.13 | F13: 187.13 | G13: 191.38 | H13: 194.13 | I13: 201.92 | J13: 182.67 | K13: 182.67 | L13: 189.97 | M13: 181.8 | N13: 184.26 | O13: 182.61 | P13: 182.61 | Q13: 186.66 | R13: 189.7 | S13: 187.12 | T13: 202.04 | U13: 202.04 | V13: 203.3 | W13: 189.14 | X13: 197.16 | Y13: 206.28 | Z13: 206.28 | AA13: 220.97 | AB13: 228.56 | AC13: 202.16 | AD13: 200.4 | AE13: 200.4 | AF13: 200.4 | AG13: 200.4 | AH13: 200.4 | AI13: 200.4 | AK13: 200.4 | AL13: 200.4 | AM13: 200.4 | AN13: 200.4
B14: 1b. 종가
A15: price_close_end | C15: 종가(기말) | E15: 5320 | G15: 4260 | H15: 2710 | I15: 2410 | J15: 2560 | L15: 3390 | M15: 3355 | N15: 2775 | O15: 3035 | Q15: 2550 | R15: 2085 | S15: 1981 | T15: 1879 | V15: 1727 | W15: 1856 | X15: 1882 | Y15: 1805 | AA15: 1956 | AB15: 2180 | AC15: 2680 | AD15: 2500
A16: price_high | C16: 종가(최고) | E16: 8580 | G16: 5640 | H16: 4465 | I16: 4170 | J16: 3260 | L16: 4170 | M16: 4705 | N16: 3375 | O16: 3185 | Q16: 3205 | R16: 2565 | S16: 2865 | T16: 2525 | V16: 1969 | W16: 1952 | X16: 2300 | Y16: 2235 | AA16: 2155 | AB16: 2340 | AC16: 2790 | AD16: 2780
A17: price_low | C17: 종가(최저) | E17: 3150 | G17: 3990 | H17: 2420 | I17: 2355 | J17: 2295 | L17: 2490 | M17: 2970 | N17: 2540 | O17: 2300 | Q17: 2450 | R17: 2060 | S17: 1850 | T17: 1747 | V17: 1715 | W17: 1715 | X17: 1780 | Y17: 1638 | AA17: 1494 | AB17: 1772 | AC17: 2130 | AD17: 2450
A18: price_avg | C18: 종가(평균) | E18: 6118.8 | G18: 4601.7 | H18: 3655.8 | I18: 2809.9 | J18: 2565.4 | L18: 3426.5 | M18: 3367.5 | N18: 2833.7 | O18: 2793.8 | Q18: 2734.1 | R18: 2292.9 | S18: 2079.9 | T18: 1971.1 | V18: 1809.4 | W18: 1836.2 | X18: 1905 | Y18: 1790.6 | AA18: 1732.8 | AB18: 2055.9 | AC18: 2432.7 | AD18: 2609.4
B20: 2. 추정 드라이버 | C20: 실적 열 = subQ 실현값(수식), 추정 열 = 가정(노란 = 모델값 역산, 연녹 = 3절 스칼라 참조)
A21: drv:매출액 | B21: yoy | C21: 매출액 YoY | J21: =IFERROR(subQ!J5/subQ!E5-1,"") | L21: =IFERROR(subQ!L5/subQ!G5-1,"") | M21: =IFERROR(subQ!M5/subQ!H5-1,"") | N21: =IFERROR(subQ!N5/subQ!I5-1,"") | O21: =IFERROR(subQ!O5/subQ!J5-1,"") | Q21: =IFERROR(subQ!Q5/subQ!L5-1,"") | R21: =IFERROR(subQ!R5/subQ!M5-1,"") | S21: =IFERROR(subQ!S5/subQ!N5-1,"") | T21: =IFERROR(subQ!T5/subQ!O5-1,"") | V21: =IFERROR(subQ!V5/subQ!Q5-1,"") | W21: =IFERROR(subQ!W5/subQ!R5-1,"") | X21: =IFERROR(subQ!X5/subQ!S5-1,"") | Y21: =IFERROR(subQ!Y5/subQ!T5-1,"") | AA21: =IFERROR(subQ!AA5/subQ!V5-1,"") | AB21: =IFERROR(subQ!AB5/subQ!W5-1,"") | AC21: -0.13754306 | AD21: -0.1375373 | AF21: -0.13758822 | AG21: -0.13758001 | AH21: -0.068785579 | AI21: -0.068805566 | AK21: -0.068707304 | AL21: -0.068781407 | AM21: -0.034386144 | AN21: -0.03445413
A22: drv:판관비 | B22: ratio | C22: 판관비율(/매출) | E22: =IFERROR(subQ!E8/subQ!E5,"") | F22: =IFERROR(subQ!F8/subQ!F5,"") | G22: =IFERROR(subQ!G8/subQ!G5,"") | H22: =IFERROR(subQ!H8/subQ!H5,"") | I22: =IFERROR(subQ!I8/subQ!I5,"") | J22: =IFERROR(subQ!J8/subQ!J5,"") | K22: =IFERROR(subQ!K8/subQ!K5,"") | L22: =IFERROR(subQ!L8/subQ!L5,"") | ... AB22: =IFERROR(subQ!AB8/subQ!AB5,"") | AC22: =$D$50 | AD22: =$D$50 | AE22: =IFERROR(subQ!AE8/subQ!AE5,"") | AF22: =$D$50 | AG22: =$D$50 | AH22: =$D$50 | AI22: =$D$50 | AJ22: =IFERROR(subQ!AJ8/subQ!AJ5,"") | AK22: =$D$50 | AL22: =$D$50 | AM22: =$D$50 | AN22: =$D$50 | AO22: =IFERROR(subQ!AO8/subQ!AO5,"")
A23: drv:영업이익 | B23: ratio | C23: 영업이익률(OPM) | E23: =IFERROR(subQ!E9/subQ!E5,"") | F23: =IFERROR(subQ!F9/subQ!F5,"") | G23: =IFERROR(subQ!G9/subQ!G5,"") | H23: =IFERROR(subQ!H9/subQ!H5,"") | I23: =IFERROR(subQ!I9/subQ!I5,"") | J23: =IFERROR(subQ!J9/subQ!J5,"") | K23: =IFERROR(subQ!K9/subQ!K5,"") | L23: =IFERROR(subQ!L9/subQ!L5,"") | ... AB23: =IFERROR(subQ!AB9/subQ!AB5,"") | AC23: 0.007234345 | AD23: 0.007344414 | AE23: =IFERROR(subQ!AE9/subQ!AE5,"") | AF23: 0.007225434 | AG23: 0.007328308 | AH23: 0.007259297 | AI23: 0.00733361 | AJ23: =IFERROR(subQ!AJ9/subQ!AJ5,"") | AK23: 0.007335308 | AL23: 0.007307476 | AM23: 0.007254023 | AN23: 0.007308684 | AO23: =IFERROR(subQ!AO9/subQ!AO5,"")
A24: drv:외환손익 | B24: abs | C24: 외환손익 (가정, 억원) | E24: =subQ!E13 | F24: =subQ!F13 | G24: =subQ!G13 | H24: =subQ!H13 | I24: =subQ!I13 | J24: =subQ!J13 | K24: =subQ!K13 | L24: =subQ!L13 | ... AB24: =subQ!AB13 | AC24: 0 | AD24: 0 | AE24: =subQ!AE13 | AF24: 0 | AG24: 0 | AH24: 0 | AI24: 0 | AJ24: =subQ!AJ13 | AK24: 0 | AL24: 0 | AM24: 0 | AN24: 0 | AO24: =subQ!AO13
A25: drv:기타영업외손익 | B25: abs | C25: 기타영업외손익 (가정, 억원) | E25: =subQ!E14 | F25: =subQ!F14 | G25: =subQ!G14 | H25: =subQ!H14 | I25: =subQ!I14 | J25: =subQ!J14 | K25: =subQ!K14 | L25: =subQ!L14 | ... AB25: =subQ!AB14 | AC25: 0 | AD25: 0 | AE25: =subQ!AE14 | AF25: 0 | AG25: 0 | AH25: 0 | AI25: 0 | AJ25: =subQ!AJ14 | AK25: 0 | AL25: 0 | AM25: 0 | AN25: 0 | AO25: =subQ!AO14
A26: drv:지분법손익 | B26: abs | C26: 지분법손익 (가정, 억원) | E26: =subQ!E15 | F26: =subQ!F15 | G26: =subQ!G15 | H26: =subQ!H15 | I26: =subQ!I15 | J26: =subQ!J15 | K26: =subQ!K15 | L26: =subQ!L15 | ... AB26: =subQ!AB15 | AC26: 0 | AD26: 0 | AE26: =subQ!AE15 | AF26: 0 | AG26: 0 | AH26: 0 | AI26: 0 | AJ26: =subQ!AJ15 | AK26: 0 | AL26: 0 | AM26: 0 | AN26: 0 | AO26: =subQ!AO15
A27: drv:법인세비용 | B27: tax | C27: 법인세율(/세전) — 법인세 = MAX(세전,0) × 세율 | E27: =IFERROR(subQ!E17/subQ!E16,"") | F27: =IFERROR(subQ!F17/subQ!F16,"") | G27: =IFERROR(subQ!G17/subQ!G16,"") | H27: =IFERROR(subQ!H17/subQ!H16,"") | I27: =IFERROR(subQ!I17/subQ!I16,"") | J27: =IFERROR(subQ!J17/subQ!J16,"") | K27: =IFERROR(subQ!K17/subQ!K16,"") | L27: =IFERROR(subQ!L17/subQ!L16,"") | ... AB27: =IFERROR(subQ!AB17/subQ!AB16,"") | AC27: =$D$49 | AD27: =$D$49 | AE27: =IFERROR(subQ!AE17/subQ!AE16,"") | AF27: =$D$49 | AG27: =$D$49 | AH27: =$D$49 | AI27: =$D$49 | AJ27: =IFERROR(subQ!AJ17/subQ!AJ16,"") | AK27: =$D$49 | AL27: =$D$49 | AM27: =$D$49 | AN27: =$D$49 | AO27: =IFERROR(subQ!AO17/subQ!AO16,"")
A28: drv:지배주주순이익 | B28: ratio | C28: 지배주주 비중(/당기순이익) | E28: =IFERROR(subQ!E19/subQ!E18,"") | F28: =IFERROR(subQ!F19/subQ!F18,"") | G28: =IFERROR(subQ!G19/subQ!G18,"") | H28: =IFERROR(subQ!H19/subQ!H18,"") | I28: =IFERROR(subQ!I19/subQ!I18,"") | J28: =IFERROR(subQ!J19/subQ!J18,"") | K28: =IFERROR(subQ!K19/subQ!K18,"") | L28: =IFERROR(subQ!L19/subQ!L18,"") | ... AB28: =IFERROR(subQ!AB19/subQ!AB18,"") | AC28: =$D$51 | AD28: =$D$51 | AE28: =IFERROR(subQ!AE19/subQ!AE18,"") | AF28: =$D$51 | AG28: =$D$51 | AH28: =$D$51 | AI28: =$D$51 | AJ28: =IFERROR(subQ!AJ19/subQ!AJ18,"") | AK28: =$D$51 | AL28: =$D$51 | AM28: =$D$51 | AN28: =$D$51 | AO28: =IFERROR(subQ!AO19/subQ!AO18,"")
A29: drv:부채총계 | B29: qoq | C29: 부채총계 QoQ | G29: =IFERROR(subQ!G21/subQ!E21-1,"") | H29: =IFERROR(subQ!H21/subQ!G21-1,"") | I29: =IFERROR(subQ!I21/subQ!H21-1,"") | J29: =IFERROR(subQ!J21/subQ!I21-1,"") | L29: =IFERROR(subQ!L21/subQ!J21-1,"") | M29: =IFERROR(subQ!M21/subQ!L21-1,"") | N29: =IFERROR(subQ!N21/subQ!M21-1,"") | O29: =IFERROR(subQ!O21/subQ!N21-1,"") | Q29: =IFERROR(subQ!Q21/subQ!O21-1,"") | R29: =IFERROR(subQ!R21/subQ!Q21-1,"") | S29: =IFERROR(subQ!S21/subQ!R21-1,"") | T29: =IFERROR(subQ!T21/subQ!S21-1,"") | V29: =IFERROR(subQ!V21/subQ!T21-1,"") | W29: =IFERROR(subQ!W21/subQ!V21-1,"") | X29: =IFERROR(subQ!X21/subQ!W21-1,"") | Y29: =IFERROR(subQ!Y21/subQ!X21-1,"") | AA29: =IFERROR(subQ!AA21/subQ!Y21-1,"") | AB29: =IFERROR(subQ!AB21/subQ!AA21-1,"") | AC29: -1.5125e-05 | AD29: 0 | AF29: 0 | AG29: 0 | AH29: 0 | AI29: 0 | AK29: 0 | AL29: 0 | AM29: 0 | AN29: 0
A30: drv:자본총계 | B30: roll | C30: 자본총계 기타변동(배당 등, 억원) | G30: =IFERROR(subQ!E22+subQ!G18-subQ!G22,"") | H30: =IFERROR(subQ!G22+subQ!H18-subQ!H22,"") | I30: =IFERROR(subQ!H22+subQ!I18-subQ!I22,"") | J30: =IFERROR(subQ!I22+subQ!J18-subQ!J22,"") | L30: =IFERROR(subQ!J22+subQ!L18-subQ!L22,"") | M30: =IFERROR(subQ!L22+subQ!M18-subQ!M22,"") | N30: =IFERROR(subQ!M22+subQ!N18-subQ!N22,"") | O30: =IFERROR(subQ!N22+subQ!O18-subQ!O22,"") | Q30: =IFERROR(subQ!O22+subQ!Q18-subQ!Q22,"") | R30: =IFERROR(subQ!Q22+subQ!R18-subQ!R22,"") | S30: =IFERROR(subQ!R22+subQ!S18-subQ!S22,"") | T30: =IFERROR(subQ!S22+subQ!T18-subQ!T22,"") | V30: =IFERROR(subQ!T22+subQ!V18-subQ!V22,"") | W30: =IFERROR(subQ!V22+subQ!W18-subQ!W22,"") | X30: =IFERROR(subQ!W22+subQ!X18-subQ!X22,"") | Y30: =IFERROR(subQ!X22+subQ!Y18-subQ!Y22,"") | AA30: =IFERROR(subQ!Y22+subQ!AA18-subQ!AA22,"") | AB30: =IFERROR(subQ!AA22+subQ!AB18-subQ!AB22,"") | AC30: 0.000649977 | AD30: 0.003249978 | AF30: -0.002249972 | AG30: 0.003999985 | AH30: -0.00675 | AI30: 0.009999995 | AK30: 0.009999985 | AL30: -0.004750008 | AM30: -0.002249981 | AN30: 0.00999997
A31: drv:지배주주지분 | B31: roll | C31: 지배주주지분 기타변동(배당 등, 억원) | G31: =IFERROR(subQ!E23+subQ!G19-subQ!G23,"") | H31: =IFERROR(subQ!G23+subQ!H19-subQ!H23,"") | I31: =IFERROR(subQ!H23+subQ!I19-subQ!I23,"") | J31: =IFERROR(subQ!I23+subQ!J19-subQ!J23,"") | L31: =IFERROR(subQ!J23+subQ!L19-subQ!L23,"") | M31: =IFERROR(subQ!L23+subQ!M19-subQ!M23,"") | N31: =IFERROR(subQ!M23+subQ!N19-subQ!N23,"") | O31: =IFERROR(subQ!N23+subQ!O19-subQ!O23,"") | Q31: =IFERROR(subQ!O23+subQ!Q19-subQ!Q23,"") | R31: =IFERROR(subQ!Q23+subQ!R19-subQ!R23,"") | S31: =IFERROR(subQ!R23+subQ!S19-subQ!S23,"") | T31: =IFERROR(subQ!S23+subQ!T19-subQ!T23,"") | V31: =IFERROR(subQ!T23+subQ!V19-subQ!V23,"") | W31: =IFERROR(subQ!V23+subQ!W19-subQ!W23,"") | X31: =IFERROR(subQ!W23+subQ!X19-subQ!X23,"") | Y31: =IFERROR(subQ!X23+subQ!Y19-subQ!Y23,"") | AA31: =IFERROR(subQ!Y23+subQ!AA19-subQ!AA23,"") | AB31: =IFERROR(subQ!AA23+subQ!AB19-subQ!AB23,"") | AC31: 0.000649977 | AD31: 0.003249978 | AF31: -0.002249972 | AG31: 0.003999985 | AH31: -0.00675 | AI31: 0.009999995 | AK31: 0.009999985 | AL31: -0.004750008 | AM31: -0.002249981 | AN31: 0.00999997
A32: drv:총차입금 | B32: qoq | C32: 총차입금 QoQ | G32: =IFERROR(subQ!G24/subQ!E24-1,"") | H32: =IFERROR(subQ!H24/subQ!G24-1,"") | I32: =IFERROR(subQ!I24/subQ!H24-1,"") | J32: =IFERROR(subQ!J24/subQ!I24-1,"") | L32: =IFERROR(subQ!L24/subQ!J24-1,"") | M32: =IFERROR(subQ!M24/subQ!L24-1,"") | N32: =IFERROR(subQ!N24/subQ!M24-1,"") | O32: =IFERROR(subQ!O24/subQ!N24-1,"") | Q32: =IFERROR(subQ!Q24/subQ!O24-1,"") | R32: =IFERROR(subQ!R24/subQ!Q24-1,"") | S32: =IFERROR(subQ!S24/subQ!R24-1,"") | T32: =IFERROR(subQ!T24/subQ!S24-1,"") | V32: =IFERROR(subQ!V24/subQ!T24-1,"") | W32: =IFERROR(subQ!W24/subQ!V24-1,"") | X32: =IFERROR(subQ!X24/subQ!W24-1,"") | Y32: =IFERROR(subQ!Y24/subQ!X24-1,"") | AA32: =IFERROR(subQ!AA24/subQ!Y24-1,"") | AB32: =IFERROR(subQ!AB24/subQ!AA24-1,"") | AC32: 0 | AD32: 0 | AF32: 0 | AG32: 0 | AH32: 0 | AI32: 0 | AK32: 0 | AL32: 0 | AM32: 0 | AN32: 0
A33: drv:순차입금 | B33: qoq | C33: 순차입금 QoQ | G33: =IFERROR(subQ!G25/subQ!E25-1,"") | H33: =IFERROR(subQ!H25/subQ!G25-1,"") | I33: =IFERROR(subQ!I25/subQ!H25-1,"") | J33: =IFERROR(subQ!J25/subQ!I25-1,"") | L33: =IFERROR(subQ!L25/subQ!J25-1,"") | M33: =IFERROR(subQ!M25/subQ!L25-1,"") | N33: =IFERROR(subQ!N25/subQ!M25-1,"") | O33: =IFERROR(subQ!O25/subQ!N25-1,"") | Q33: =IFERROR(subQ!Q25/subQ!O25-1,"") | R33: =IFERROR(subQ!R25/subQ!Q25-1,"") | S33: =IFERROR(subQ!S25/subQ!R25-1,"") | T33: =IFERROR(subQ!T25/subQ!S25-1,"") | V33: =IFERROR(subQ!V25/subQ!T25-1,"") | W33: =IFERROR(subQ!W25/subQ!V25-1,"") | X33: =IFERROR(subQ!X25/subQ!W25-1,"") | Y33: =IFERROR(subQ!Y25/subQ!X25-1,"") | AA33: =IFERROR(subQ!AA25/subQ!Y25-1,"") | AB33: =IFERROR(subQ!AB25/subQ!AA25-1,"") | AC33: -0.001020109 | AD33: -0.000346741 | AF33: -0.00017343 | AG33: -0.002081526 | AH33: -0.000347645 | AI33: 0.000347766 | AK33: 0.000347645 | AL33: -0.001390096 | AM33: -0.000174004 | AN33: 0.000522102
A34: drv:이자발생자산 | B34: qoq | C34: 이자발생자산 QoQ | G34: =IFERROR(subQ!G26/subQ!E26-1,"") | H34: =IFERROR(subQ!H26/subQ!G26-1,"") | I34: =IFERROR(subQ!I26/subQ!H26-1,"") | J34: =IFERROR(subQ!J26/subQ!I26-1,"") | L34: =IFERROR(subQ!L26/subQ!J26-1,"") | M34: =IFERROR(subQ!M26/subQ!L26-1,"") | N34: =IFERROR(subQ!N26/subQ!M26-1,"") | O34: =IFERROR(subQ!O26/subQ!N26-1,"") | Q34: =IFERROR(subQ!Q26/subQ!O26-1,"") | R34: =IFERROR(subQ!R26/subQ!Q26-1,"") | S34: =IFERROR(subQ!S26/subQ!R26-1,"") | T34: =IFERROR(subQ!T26/subQ!S26-1,"") | V34: =IFERROR(subQ!V26/subQ!T26-1,"") | W34: =IFERROR(subQ!W26/subQ!V26-1,"") | X34: =IFERROR(subQ!X26/subQ!W26-1,"") | Y34: =IFERROR(subQ!Y26/subQ!X26-1,"") | AA34: =IFERROR(subQ!AA26/subQ!Y26-1,"") | AB34: =IFERROR(subQ!AB26/subQ!AA26-1,"") | AC34: 0.015604337 | AD34: 0.005208333 | AF34: 0.002590674 | AG34: 0.031007752 | AH34: 0.005012531 | AI34: -0.004987531 | AK34: -0.005012531 | AL34: 0.020151134 | AM34: 0.002469136 | AN34: -0.007389163
A35: drv:현금및현금성자산 | B35: qoq | C35: 현금및현금성자산 QoQ | G35: =IFERROR(subQ!G27/subQ!E27-1,"") | H35: =IFERROR(subQ!H27/subQ!G27-1,"") | I35: =IFERROR(subQ!I27/subQ!H27-1,"") | J35: =IFERROR(subQ!J27/subQ!I27-1,"") | L35: =IFERROR(subQ!L27/subQ!J27-1,"") | M35: =IFERROR(subQ!M27/subQ!L27-1,"") | N35: =IFERROR(subQ!N27/subQ!M27-1,"") | O35: =IFERROR(subQ!O27/subQ!N27-1,"") | Q35: =IFERROR(subQ!Q27/subQ!O27-1,"") | R35: =IFERROR(subQ!R27/subQ!Q27-1,"") | S35: =IFERROR(subQ!S27/subQ!R27-1,"") | T35: =IFERROR(subQ!T27/subQ!S27-1,"") | V35: =IFERROR(subQ!V27/subQ!T27-1,"") | W35: =IFERROR(subQ!W27/subQ!V27-1,"") | X35: =IFERROR(subQ!X27/subQ!W27-1,"") | Y35: =IFERROR(subQ!Y27/subQ!X27-1,"") | AA35: =IFERROR(subQ!AA27/subQ!Y27-1,"") | AB35: =IFERROR(subQ!AB27/subQ!AA27-1,"")
A36: drv:CAPEX | B36: yoy | C36: CAPEX YoY | J36: =IFERROR(subQ!J28/subQ!E28-1,"") | L36: =IFERROR(subQ!L28/subQ!G28-1,"") | M36: =IFERROR(subQ!M28/subQ!H28-1,"") | N36: =IFERROR(subQ!N28/subQ!I28-1,"") | O36: =IFERROR(subQ!O28/subQ!J28-1,"") | Q36: =IFERROR(subQ!Q28/subQ!L28-1,"") | R36: =IFERROR(subQ!R28/subQ!M28-1,"") | S36: =IFERROR(subQ!S28/subQ!N28-1,"") | T36: =IFERROR(subQ!T28/subQ!O28-1,"") | V36: =IFERROR(subQ!V28/subQ!Q28-1,"") | W36: =IFERROR(subQ!W28/subQ!R28-1,"") | X36: =IFERROR(subQ!X28/subQ!S28-1,"") | Y36: =IFERROR(subQ!Y28/subQ!T28-1,"") | AA36: =IFERROR(subQ!AA28/subQ!V28-1,"") | AB36: =IFERROR(subQ!AB28/subQ!W28-1,"") | AC36: -0.3777764 | AD36: 1.5613253 | AF36: 3.4513343 | AG36: -0.70565623 | AH36: 0 | AI36: 0 | AK36: 0 | AL36: 0 | AM36: 0 | AN36: 0
A37: drv:영업활동현금흐름 | B37: yoy | C37: 영업활동현금흐름 YoY | J37: =IFERROR(subQ!J29/subQ!E29-1,"") | L37: =IFERROR(subQ!L29/subQ!G29-1,"") | M37: =IFERROR(subQ!M29/subQ!H29-1,"") | N37: =IFERROR(subQ!N29/subQ!I29-1,"") | O37: =IFERROR(subQ!O29/subQ!J29-1,"") | Q37: =IFERROR(subQ!Q29/subQ!L29-1,"") | R37: =IFERROR(subQ!R29/subQ!M29-1,"") | S37: =IFERROR(subQ!S29/subQ!N29-1,"") | T37: =IFERROR(subQ!T29/subQ!O29-1,"") | V37: =IFERROR(subQ!V29/subQ!Q29-1,"") | W37: =IFERROR(subQ!W29/subQ!R29-1,"") | X37: =IFERROR(subQ!X29/subQ!S29-1,"") | Y37: =IFERROR(subQ!Y29/subQ!T29-1,"") | AA37: =IFERROR(subQ!AA29/subQ!V29-1,"") | AB37: =IFERROR(subQ!AB29/subQ!W29-1,"")
A38: drv:주식수 | B38: qoq | C38: 주식수 QoQ | G38: =IFERROR(subQ!G30/subQ!E30-1,"") | H38: =IFERROR(subQ!H30/subQ!G30-1,"") | I38: =IFERROR(subQ!I30/subQ!H30-1,"") | J38: =IFERROR(subQ!J30/subQ!I30-1,"") | L38: =IFERROR(subQ!L30/subQ!J30-1,"") | M38: =IFERROR(subQ!M30/subQ!L30-1,"") | N38: =IFERROR(subQ!N30/subQ!M30-1,"") | O38: =IFERROR(subQ!O30/subQ!N30-1,"") | Q38: =IFERROR(subQ!Q30/subQ!O30-1,"") | R38: =IFERROR(subQ!R30/subQ!Q30-1,"") | S38: =IFERROR(subQ!S30/subQ!R30-1,"") | T38: =IFERROR(subQ!T30/subQ!S30-1,"") | V38: =IFERROR(subQ!V30/subQ!T30-1,"") | W38: =IFERROR(subQ!W30/subQ!V30-1,"") | X38: =IFERROR(subQ!X30/subQ!W30-1,"") | Y38: =IFERROR(subQ!Y30/subQ!X30-1,"") | AA38: =IFERROR(subQ!AA30/subQ!Y30-1,"") | AB38: =IFERROR(subQ!AB30/subQ!AA30-1,"") | AC38: 0 | AD38: 0 | AF38: 0 | AG38: 0 | AH38: 0 | AI38: 0 | AK38: 0 | AL38: 0 | AM38: 0 | AN38: 0
A39: drv:DPS | B39: abs | C39: DPS (가정, 원) | E39: =subQ!E33 | F39: =subQ!F33 | G39: =subQ!G33 | H39: =subQ!H33 | I39: =subQ!I33 | J39: =subQ!J33 | K39: =subQ!K33 | L39: =subQ!L33 | ... AB39: =subQ!AB33 | AD39: 0 | AE39: =subQ!AE33 | AI39: 0 | AJ39: =subQ!AJ33 | AN39: 0 | AO39: =subQ!AO33
B41: 3. 밸류에이션·스칼라 | C41: 노란 셀 = 가정. '연결' 표시는 추정 전 분기 수식이 이 셀을 참조한다는 뜻
A42: sc:종가 | C42: 종가 | D42: 2500 | E42: 원 — 네이버 정규장 종가(aik 확정종가 대조 · aik 2,560원)
...

Sheet BS연결
B1: (백만원) | C1: 이름: BS연결H | E1: 4Q21 | F1: 2021 | G1: 1Q22 | H1: 2Q22 | I1: 3Q22 | J1: 4Q22 | K1: 2022 | L1: 1Q23 | M1: 2Q23 | N1: 3Q23 | O1: 4Q23 | P1: 2023 | Q1: 1Q24 | R1: 2Q24 | S1: 3Q24 | T1: 4Q24 | U1: 2024 | V1: 1Q25 | W1: 2Q25 | X1: 3Q25 | Y1: 4Q25 | Z1: 2025 | AA1: 1Q26 | AB1: 2Q26 | AC1: 3Q26 | AD1: 4Q26 | AE1: 2026 | AF1: 1Q27 | AG1: 2Q27 | AH1: 3Q27 | AI1: 4Q27 | AJ1: 2027 | AK1: 1Q28 | AL1: 2Q28 | AM1: 3Q28 | AN1: 4Q28 | AO1: 2028
B2: 연결 | D2: fin json(kship_fin.py)
B3: 한국주강(연) | C3: UPDATE: 26-10-14 | E3: 1 | F3: 2 | G3: 3 | H3: 4 | I3: 5 | J3: 6 | K3: 7 | L3: 8 | M3: 9 | N3: 10 | O3: 11 | P3: 12 | Q3: 13 | R3: 14 | S3: 15 | T3: 16 | U3: 17 | V3: 18 | W3: 19 | X3: 20 | Y3: 21 | Z3: 22 | AA3: 23 | AB3: 24 | AC3: 25 | AD3: 26 | AE3: 27 | AF3: 28 | AG3: 29 | AH3: 30 | AI3: 31 | AJ3: 32 | AK3: 33 | AL3: 34 | AM3: 35 | AN3: 36 | AO3: 37
B4: Account Code | C4: AccountNAME | E4: 2021.12 | F4: 2021.12A | G4: 2022.03 | H4: 2022.06 | I4: 2022.09 | J4: 2022.12 | K4: 2022.12A | L4: 2023.03 | M4: 2023.06 | N4: 2023.09 | O4: 2023.12 | P4: 2023.12A | Q4: 2024.03 | R4: 2024.06 | S4: 2024.09 | T4: 2024.12 | U4: 2024.12A | V4: 2025.03 | W4: 2025.06 | X4: 2025.09 | Y4: 2025.12 | Z4: 2025.12A | AA4: 2026.03 | AB4: 2026.06 | AC4: 2026.09 | AD4: 2026.12 | AE4: 2026.12A | AF4: 2027.03 | AG4: 2027.06 | AH4: 2027.09 | AI4: 2027.12 | AJ4: 2027.12A | AK4: 2028.03 | AL4: 2028.06 | AM4: 2028.09 | AN4: 2028.12 | AO4: 2028.12A

Sheet BS별도
B1: (백만원) | C1: 이름: BS별도H | E1: 4Q21 | F1: 2021 | G1: 1Q22 | H1: 2Q22 | I1: 3Q22 | J1: 4Q22 | K1: 2022 | L1: 1Q23 | M1: 2Q23 | N1: 3Q23 | O1: 4Q23 | P1: 2023 | Q1: 1Q24 | R1: 2Q24 | S1: 3Q24 | T1: 4Q24 | U1: 2024 | V1: 1Q25 | W1: 2Q25 | X1: 3Q25 | Y1: 4Q25 | Z1: 2025 | AA1: 1Q26 | AB1: 2Q26 | AC1: 3Q26 | AD1: 4Q26 | AE1: 2026 | AF1: 1Q27 | AG1: 2Q27 | AH1: 3Q27 | AI1: 4Q27 | AJ1: 2027 | AK1: 1Q28 | AL1: 2Q28 | AM1: 3Q28 | AN1: 4Q28 | AO1: 2028
B2: 별도 | D2: fin json(kship_fin.py)
B3: 한국주강(별) | C3: UPDATE: 26-10-14 | E3: 1 | F3: 2 | G3: 3 | H3: 4 | I3: 5 | J3: 6 | K3: 7 | L3: 8 | M3: 9 | N3: 10 | O3: 11 | P3: 12 | Q3: 13 | R3: 14 | S3: 15 | T3: 16 | U3: 17 | V3: 18 | W3: 19 | X3: 20 | Y3: 21 | Z3: 22 | AA3: 23 | AB3: 24 | AC3: 25 | AD3: 26 | AE3: 27 | AF3: 28 | AG3: 29 | AH3: 30 | AI3: 31 | AJ3: 32 | AK3: 33 | AL3: 34 | AM3: 35 | AN3: 36 | AO3: 37
B4: Account Code | C4: AccountNAME | E4: 2021.12 | F4: 2021.12A | G4: 2022.03 | H4: 2022.06 | I4: 2022.09 | J4: 2022.12 | K4: 2022.12A | L4: 2023.03 | M4: 2023.06 | N4: 2023.09 | O4: 2023.12 | P4: 2023.12A | Q4: 2024.03 | R4: 2024.06 | S4: 2024.09 | T4: 2024.12 | U4: 2024.12A | V4: 2025.03 | W4: 2025.06 | X4: 2025.09 | Y4: 2025.12 | Z4: 2025.12A | AA4: 2026.03 | AB4: 2026.06 | AC4: 2026.09 | AD4: 2026.12 | AE4: 2026.12A | AF4: 2027.03 | AG4: 2027.06 | AH4: 2027.09 | AI4: 2027.12 | AJ4: 2027.12A | AK4: 2028.03 | AL4: 2028.06 | AM4: 2028.09 | AN4: 2028.12 | AO4: 2028.12A
A5: 1 | C5: 유동자산 | E5: 19645.63 | F5: 19645.63 | G5: 22931.95 | H5: 22828.71 | I5: 19870.34 | J5: 19844.24 | K5: 19844.24 | L5: 18645.58 | M5: 17736.31 | N5: 17885.42 | O5: 15572.79 | P5: 15572.79 | Q5: 14976.06 | R5: 15130.63 | S5: 13951.38 | T5: 12638.31 | U5: 12638.31 | V5: 12547.46 | W5: 11618.59 | X5: 11929.24 | Y5: 10043.6 | Z5: 10043.6 | AA5: 13996.42 | AB5: 14320.99
A6: 1 | C6: 현금및현금성자산 | E6: 65.03 | F6: 65.03 | G6: 737.38 | H6: 154.42 | I6: 377.37 | J6: 280.39 | K6: 280.39 | L6: 439.97 | M6: 384.23 | N6: 79.82 | O6: 1372.91 | P6: 1372.91 | Q6: 1625.64 | R6: 98.54 | S6: 1057.16 | T6: 1046.79 | U6: 1046.79 | V6: 155.94 | W6: 11.57 | X6: 101.11 | Y6: 420.12 | Z6: 420.12 | AA6: 14.36 | AB6: 264.11
A7: 1 | C7: 단기금융상품 | E7: 3000 | F7: 3000 | G7: 3000 | H7: 3000 | I7: 3000 | J7: 3456.01 | K7: 3456.01 | L7: 459.47 | M7: 0 | N7: 0 | O7: 0 | P7: 0 | Q7: 500 | R7: 2000 | S7: 1500 | T7: 500 | U7: 500 | V7: 500 | W7: 0 | X7: 0 | Y7: 0 | Z7: 0 | AA7: 0 | AB7: 0
A8: 1 | C8: 단기금융자산 | E8: 3000 | F8: 3000 | G8: 3000 | H8: 3000 | I8: 3000 | J8: 3456.01 | K8: 3456.01 | L8: 459.47 | M8: 0 | N8: 0 | O8: 0 | P8: 0 | Q8: 500 | R8: 2000 | S8: 1500 | T8: 500 | U8: 500 | V8: 500 | W8: 0 | X8: 0 | Y8: 0 | Z8: 0 | AA8: 0 | AB8: 0
A9: 1 | C9: 매출채권및기타채권 | E9: 9529.65 | F9: 9529.65 | G9: 9760.39 | H9: 9554.88 | I9: 6619.81 | J9: 7587.65 | K9: 7587.65 | L9: 7381.91 | M9: 5265.44 | N9: 7121.86 | O9: 7349.03 | P9: 7349.03 | Q9: 6242.03 | R9: 6195.95 | S9: 3831.77 | T9: 5125.8 | U9: 5125.8 | V9: 4532.29 | W9: 4220.87 | X9: 4063.69 | Y9: 1611.99 | Z9: 1611.99 | AA9: 3597.46 | AB9: 3463.49
A10: 1 | C10: 재고자산 | E10: 6832.02 | F10: 6832.02 | G10: 8271.7 | H10: 10027.89 | I10: 9810.5 | J10: 8385.32 | K10: 8385.32 | L10: 9919.93 | M10: 11741.47 | N10: 10387.04 | O10: 6588.36 | P10: 6588.36 | Q10: 6467.87 | R10: 6668.86 | S10: 7130.5 | T10: 5925.59 | U10: 5925.59 | V10: 7287.1 | W10: 7313.98 | X10: 7636.83 | Y10: 7871.67 | Z10: 7871.67 | AA10: 10230.91 | AB10: 10488.31
A11: 1 | C11: 기타유동자산 | E11: 156.74 | F11: 156.74 | G11: 113.34 | H11: 60.81 | I11: 26.74 | J11: 43.39 | K11: 43.39 | L11: 365.64 | M11: 344.17 | N11: 294.38 | O11: 200.52 | P11: 200.52 | Q11: 77.12 | R11: 105.02 | S11: 135.78 | T11: 9.39 | U11: 9.39 | V11: 38.01 | W11: 59.41 | X11: 116.22 | Y11: 130.51 | Z11: 130.51 | AA11: 147.58 | AB11: 104.99
A12: 1 | C12: 비유동자산 | E12: 30549.15 | F12: 30549.15 | G12: 30171.65 | H12: 29449.18 | I12: 29088.47 | J12: 28200.98 | K12: 28200.98 | L12: 31115.79 | M12: 30620.5 | N12: 28724.33 | O12: 28614.14 | P12: 28614.14 | Q12: 28774.93 | R12: 28462.44 | S12: 28733.04 | T12: 28860.06 | U12: 28860.06 | V12: 28332.37 | W12: 27935.44 | X12: 28400.01 | Y12: 28263.21 | Z12: 28263.21 | AA12: 28723.52 | AB12: 29039.8
A13: 1 | C13: 장기금융자산 | E13: 1100.26 | F13: 1100.26 | G13: 1123.69 | H13: 802.42 | I13: 810.37 | J13: 362.62 | K13: 362.62 | L13: 367.63 | M13: 1.33 | N13: 0.44 | O13: 6.46 | P13: 6.46 | Q13: 13.43 | R13: 20.44 | S13: 28.37 | T13: 39.97 | U13: 39.97 | V13: 51.83 | W13: 63.85 | X13: 76.3 | Y13: 88.81 | Z13: 88.81 | AA13: 101.38 | AB13: 113.99
A14: 1 | C14: 투자자산 | E14: 1100.26 | F14: 1100.26 | G14: 1123.69 | H14: 802.42 | I14: 810.37 | J14: 362.62 | K14: 362.62 | L14: 367.63 | M14: 1.33 | N14: 0.44 | O14: 6.46 | P14: 6.46 | Q14: 13.43 | R14: 20.44 | S14: 28.37 | T14: 39.97 | U14: 39.97 | V14: 51.83 | W14: 63.85 | X14: 76.3 | Y14: 88.81 | Z14: 88.81 | AA14: 101.38 | AB14: 113.99
A15: 1 | C15: 투자부동산 | E15: 1927.84 | F15: 1927.84 | G15: 1910.87 | H15: 1893.89 | I15: 1876.92 | J15: 5034.69 | K15: 5034.69 | L15: 5017.71 | M15: 5000.74 | N15: 4983.76 | O15: 4966.79 | P15: 4966.79 | Q15: 4949.81 | R15: 4932.84 | S15: 4915.86 | T15: 4898.89 | U15: 4898.89 | V15: 4881.91 | W15: 4864.94 | X15: 4895.16 | Y15: 4877.77 | Z15: 4877.77 | AA15: 4860.39 | AB15: 4843
A16: 1 | C16: 유형자산 | E16: 25428.81 | F16: 25428.81 | G16: 25062.96 | H16: 24696.83 | I16: 24309.93 | J16: 20824.75 | K16: 20824.75 | L16: 20791.57 | M16: 20673.97 | N16: 20458.68 | O16: 20450.46 | P16: 20450.46 | Q16: 20453.75 | R16: 20508.36 | S16: 20348.88 | T16: 20324.77 | U16: 20324.77 | V16: 20305.71 | W16: 20175.24 | X16: 20512.36 | Y16: 20452.36 | Z16: 20452.36 | AA16: 20351.92 | AB16: 21522.69
... A27: 1 | C27: 비유동부채 | E27: 1944.33 | F27: 1944.33 | G27: 6295.67 | H27: 6317.23 | I27: 5788.29 | J27: 5486.13 | K27: 5486.13 | L27: 5534.82 | M27: 6146.57 | N27: 5787.93 | O27: 5107.64 | P27: 5107.64 | Q27: 734.42 | R27: 773.54 | S27: 866.72 | T27: 642.29 | U27: 642.29 | V27: 721.96 | W27: 683.16 | X27: 704.6 | Y27: 518.33 | Z27: 518.33 | AA27: 487.49 | AB27: 323.02
A28: 1 | C28: 장기차입금 | E28: 800 | F28: 800 | G28: 5200 | H28: 5200 | I28: 4700 | J28: 4400 | K28: 4400 | L28: 4400 | M28: 4400 | N28: 4400 | O28: 4400 | P28: 4400 | Q28: 0 | R28: 0 | S28: 0 | T28: 0 | U28: 0 | Y28: 0 | Z28: 0
A29: 1 | C29: 비유동리스부채 | E29: 324.52 | F29: 324.52 | G29: 312.62 | H29: 312.34 | I29: 323.47 | J29: 310.05 | K29: 310.05 | L29: 296.33 | M29: 399.44 | N29: 399.79 | O29: 375.52 | P29: 375.52 | Q29: 357.41 | R29: 325.28 | S29: 302.68 | T29: 281.29 | U29: 281.29 | V29: 259.39 | W29: 236.98 | X29: 247 | Y29: 279.95 | Z29: 279.95 | AA29: 257.12 | AB29: 102.71
A30: 1 | C30: 장기금융부채 | E30: 324.52 | F30: 324.52 | G30: 312.62 | H30: 312.34 | I30: 323.47 | J30: 310.05 | K30: 310.05 | L30: 296.33 | M30: 399.44 | N30: 399.79 | O30: 375.52 | P30: 375.52 | Q30: 357.41 | R30: 325.28 | S30: 302.68 | T30: 281.29 | U30: 281.29 | V30: 259.39 | W30: 236.98 | X30: 247 | Y30: 279.95 | Z30: 279.95 | AA30: 257.12 | AB30: 102.71
A31: 1 | C31: 확정급여부채 | E31: 819.81 | F31: 819.81 | G31: 783.05 | H31: 804.89 | I31: 764.82 | J31: 776.08 | K31: 776.08 | L31: 838.49 | M31: 767.17 | N31: 758.78 | O31: 324.73 | P31: 324.73 | Q31: 369.62 | R31: 440.88 | S31: 519.82 | T31: 288.17 | U31: 288.17 | V31: 389.74 | W31: 446.18 | X31: 457.6 | Y31: 238.38 | Z31: 238.38 | AA31: 230.37 | AB31: 220.31
A32: 1 | C32: 부채총계 | E32: 22132.88 | F32: 22132.88 | G32: 23014.3 | H32: 22202.98 | I32: 19112.3 | J32: 18273.22 | K32: 18273.22 | L32: 16941.12 | M32: 15801.91 | N32: 14141.48 | O32: 11207.43 | P32: 11207.43 | Q32: 10590.17 | R32: 10582.19 | S32: 9670.09 | T32: 7363.07 | U32: 7363.07 | V32: 7165.98 | W32: 5667.47 | X32: 6689.54 | Y32: 5025.88 | Z32: 5025.88 | AA32: 8763.54 | AB32: 9917.15
A33: 1 | C33: 자본금 | E33: 5654.63 | F33: 5654.63 | G33: 5654.63 | H33: 5654.63 | I33: 5654.63 | J33: 5654.63 | K33: 5654.63 | L33: 5654.63 | M33: 5654.63 | N33: 5654.63 | O33: 5654.63 | P33: 5654.63 | Q33: 5654.63 | R33: 5654.63 | S33: 5654.63 | T33: 5654.63 | U33: 5654.63 | V33: 5654.63 | W33: 5654.63 | X33: 5654.63 | Y33: 5654.63 | Z33: 5654.63 | AA33: 5654.63 | AB33: 5654.63
A34: 1 | C34: 자본잉여금 | E34: 4409.7 | F34: 4409.7 | G34: 4409.7 | H34: 4409.7 | I34: 4409.7 | J34: 4409.7 | K34: 4409.7 | L34: 4409.7 | M34: 4409.7 | N34: 4409.7 | O34: 4409.7 | P34: 4409.7 | Q34: 4409.7 | R34: 4409.7 | S34: 4409.7 | T34: 4409.7 | U34: 4409.7 | V34: 4409.7 | W34: 4409.7 | X34: 4409.7 | Y34: 4409.7 | Z34: 4409.7 | AA34: 4409.7 | AB34: 4409.7
A35: 1 | C35: 기타자본 | E35: -922.91 | F35: -922.91 | G35: -922.91 | H35: -922.91 | I35: -922.91 | J35: -922.91 | K35: -922.91 | L35: -922.91 | M35: -922.91 | N35: -922.91 | O35: -922.91 | P35: -922.91 | Q35: -922.91 | R35: -922.91 | S35: -922.91 | T35: -922.91 | U35: -922.91 | V35: -922.91 | W35: -922.91 | X35: -922.91 | Y35: -922.91 | Z35: -922.91 | AA35: -922.91 | AB35: 0
A36: 1 | C36: 기타포괄이익누계액 | E36: -914.76 | F36: -914.76 | G36: -914.76 | H36: -914.76 | I36: -914.76 | J36: -1009.36 | K36: -1009.36 | L36: 1968.34 | M36: 1278.38 | N36: -48.53 | O36: -125.4 | P36: -125.4 | Q36: 67.1 | R36: -213.84 | S36: 155.95 | T36: 299.51 | U36: 299.51 | V36: -178.99 | W36: -266.05 | X36: -222.55 | Y36: -305.25 | Z36: -305.25 | AA36: 288.75 | AB36: -393.25
A37: 1 | C37: 이익잉여금 | E37: 19835.24 | F37: 19835.24 | G37: 21862.64 | H37: 21848.25 | I37: 21619.85 | J37: 21639.94 | K37: 21639.94 | L37: 21710.5 | M37: 22135.1 | N37: 23375.37 | O37: 23963.49 | P37: 23963.49 | Q37: 23952.31 | R37: 24083.3 | S37: 23716.96 | T37: 24694.36 | U37: 24694.36 | V37: 24751.41 | W37: 25011.19 | X37: 24720.84 | Y37: 24444.77 | Z37: 24444.77 | AA37: 24526.23 | AB37: 23772.56
A38: 1 | C38: 자본총계 | E38: 28061.9 | F38: 28061.9 | G38: 30089.3 | H38: 30074.91 | I38: 29846.51 | J38: 29772.01 | K38: 29772.01 | L38: 32820.26 | M38: 32554.9 | N38: 32468.26 | O38: 32979.51 | P38: 32979.51 | Q38: 33160.83 | R38: 33010.88 | S38: 33014.33 | T38: 34135.29 | U38: 34135.29 | V38: 33713.85 | W38: 33886.56 | X38: 33639.72 | Y38: 33280.94 | Z38: 33280.94 | AA38: 33956.4 | AB38: 33443.64
A39: 1 | C39: 부채와자본총계 | E39: 50194.78 | F39: 50194.78 | G39: 53103.6 | H39: 52277.89 | I39: 48958.81 | J39: 48045.22 | K39: 48045.22 | L39: 49761.38 | M39: 48356.81 | N39: 46609.75 | O39: 44186.93 | P39: 44186.93 | Q39: 43751 | R39: 43593.07 | S39: 42684.42 | T39: 41498.37 | U39: 41498.37 | V39: 40879.83 | W39: 39554.03 | X39: 40329.26 | Y39: 38306.81 | Z39: 38306.81 | AA39: 42719.94 | AB39: 43360.79
A40: 1 | C40: 지배주주지분 | E40: 28061.9 | F40: 28061.9 | G40: 30089.3 | H40: 30074.91 | I40: 29846.51 | J40: 29772.01 | K40: 29772.01 | L40: 32820.26 | M40: 32554.9 | N40: 32468.26 | O40: 32979.51 | P40: 32979.51 | Q40: 33160.83 | R40: 33010.88 | S40: 33014.33 | T40: 34135.29 | U40: 34135.29 | V40: 33713.85 | W40: 33886.56 | X40: 33639.72 | Y40: 33280.94 | Z40: 33280.94 | AA40: 33956.4 | AB40: 33443.64
... A43: 1 | C43: 이자발생자산 | E43: 4165.29 | F43: 4165.29 | G43: 4861.07 | H43: 3956.84 | I43: 4187.74 | J43: 4099.02 | K43: 4099.02 | L43: 1267.07 | M43: 385.56 | N43: 80.26 | O43: 1379.37 | P43: 1379.37 | Q43: 2139.07 | R43: 2118.98 | S43: 2585.53 | T43: 1586.76 | U43: 1586.76 | V43: 707.77 | W43: 75.42 | X43: 177.41 | Y43: 508.93 | Z43: 508.93 | AA43: 115.74 | AB43: 378.1
A44: 1 | C44: 유동성장기부채 | I44: 500 | J44: 800 | K44: 800 | L44: 800 | M44: 300 | N44: 300 | O44: 0 | P44: 0 | Q44: 4400 | R44: 4000 | S44: 2500 | T44: 1000 | U44: 1000 | V44: 0 | W44: 0 | X44: 0 | Y44: 0 | Z44: 0 | AA44: 0 | AB44: 0
A45: 1 | C45: 당기법인세자산(선급법인세) | L45: 0
A46: 1 | C46: 이연법인세부채 | M46: 579.96 | N46: 229.36 | O46: 7.38 | P46: 7.38 | Q46: 7.38 | R46: 7.38 | S46: 44.22 | T46: 72.83 | U46: 72.83 | V46: 72.83 | W46: 0 | X46: 0 | Y46: 0 | Z46: 0 | AA46: 0 | AB46: 0
A47: 1 | C47: 당기법인세부채(미지급법인세) | Q47: 0.62 | R47: 0 | S47: -3.26 | T47: 8.69 | U47: 8.69 | V47: 1.09 | W47: 5.45 | X47: 0 | Y47: 0 | Z47: 0 | AA47: 0 | AB47: 0
A48: 1 | C48: 단기파생상품부채 | T48: 18.74 | U48: 18.74 | V48: 0 | W48: 0 | X48: 0 | Y48: 0 | Z48: 0 | AA48: 0 | AB48: 0
A49: 1 | C49: 매출액(수익) | E49: 13539.08 | G49: 13295.39 | H49: 13675.13 | I49: 11800.98 | J49: 15599.61 | K49: 54371.11 | L49: 12447.67 | M49: 11473.4 | N49: 13682.34 | O49: 16207.82 | P49: 53811.23 | Q49: 11670.52 | R49: 11863.49 | S49: 9950.07 | T49: 13799.66 | U49: 47283.74 | V49: 9423.76 | W49: 11673.15 | X49: 9776.72 | Y49: 8998.65 | Z49: 39872.28 | AA49: 8826.41 | AB49: 11075.81
A50: 1 | C50: 매출원가 | E50: 13479.8 | G50: 13324.39 | H50: 13030.46 | I50: 11361.06 | J50: 14756.26 | K50: 52472.17 | L50: 11622.53 | M50: 10398.59 | N50: 12182.33 | O50: 15007.37 | P50: 49210.82 | Q50: 11083.31 | R50: 10962.74 | S50: 9743.61 | T50: 12176.45 | U50: 43966.11 | V50: 8797.89 | W50: 10816.16 | X50: 9646.74 | Y50: 8822.51 | Z50: 38083.3 | AA50: 8311.54 | AB50: 10445.85
A51: 1 | C51: 매출총이익 | E51: 59.29 | G51: -29.01 | H51: 644.67 | I51: 439.92 | J51: 843.34 | K51: 1898.92 | L51: 825.14 | M51: 1074.82 | N51: 1500 | O51: 1200.45 | P51: 4600.41 | Q51: 587.21 | R51: 900.75 | S51: 206.46 | T51: 1623.22 | U51: 3317.64 | V51: 625.88 | W51: 856.99 | X51: 129.97 | Y51: 176.14 | Z51: 1788.98 | AA51: 514.88 | AB51: 629.95
A52: 1 | C52: 판관비 | E52: 478.32 | G52: 654.77 | H52: 578.68 | I52: 560.02 | J52: 623.11 | K52: 2416.58 | L52: 566.99 | M52: 504.33 | N52: 580.31 | O52: 530.3 | P52: 2181.93 | Q52: 525.21 | R52: 581.22 | S52: 521.2 | T52: 615.04 | U52: 2242.67 | V52: 551.52 | W52: 502.65 | X52: 457.07 | Y52: 454.41 | Z52: 1965.65 | AA52: 455.94 | AB52: 477.17
...

Sheet subQ
A1: YQ | C1: subQ 분기 서브모델(억원, U=100) | E1: 4Q21 | F1: 2021 | G1: 1Q22 | H1: 2Q22 | I1: 3Q22 | J1: 4Q22 | K1: 2022 | L1: 1Q23 | M1: 2Q23 | N1: 3Q23 | O1: 4Q23 | P1: 2023 | Q1: 1Q24 | R1: 2Q24 | S1: 3Q24 | T1: 4Q24 | U1: 2024 | V1: 1Q25 | W1: 2Q25 | X1: 3Q25 | Y1: 4Q25 | Z1: 2025 | AA1: 1Q26 | AB1: 2Q26 | AC1: 3Q26 | AD1: 4Q26 | AE1: 2026 | AF1: 1Q27 | AG1: 2Q27 | AH1: 3Q27 | AI1: 4Q27 | AJ1: 2027 | AK1: 1Q28 | AL1: 2Q28 | AM1: 3Q28 | AN1: 4Q28 | AO1: 2028
A2: A=이름(key) B=그룹 C=단위 D=FnGuide 계정명(VLOOKUP 키). 확정=VLOOKUP(BS), 추정=변수 가정 참조
E3: 1 | F3: 2 | G3: 3 | H3: 4 | I3: 5 | J3: 6 | K3: 7 | L3: 8 | M3: 9 | N3: 10 | O3: 11 | P3: 12 | Q3: 13 | R3: 14 | S3: 15 | T3: 16 | U3: 17 | V3: 18 | W3: 19 | X3: 20 | Y3: 21 | Z3: 22 | AA3: 23 | AB3: 24 | AC3: 25 | AD3: 26 | AE3: 27 | AF3: 28 | AG3: 29 | AH3: 30 | AI3: 31 | AJ3: 32 | AK3: 33 | AL3: 34 | AM3: 35 | AN3: 36 | AO3: 37
E4: 2021.12 | F4: 2021.12A | G4: 2022.03 | H4: 2022.06 | I4: 2022.09 | J4: 2022.12 | K4: 2022.12A | L4: 2023.03 | M4: 2023.06 | N4: 2023.09 | O4: 2023.12 | P4: 2023.12A | Q4: 2024.03 | R4: 2024.06 | S4: 2024.09 | T4: 2024.12 | U4: 2024.12A | V4: 2025.03 | W4: 2025.06 | X4: 2025.09 | Y4: 2025.12 | Z4: 2025.12A | AA4: 2026.03 | AB4: 2026.06 | AC4: 2026.09 | AD4: 2026.12 | AE4: 2026.12A | AF4: 2027.03 | AG4: 2027.06 | AH4: 2027.09 | AI4: 2027.12 | AJ4: 2027.12A | AK4: 2028.03 | AL4: 2028.06 | AM4: 2028.09 | AN4: 2028.12 | AO4: 2028.12A
A5: 매출액 | B5: 손익 | C5: 억원 | D5: 매출액(수익) | E5: =IFERROR(VLOOKUP($D5,BS별도,MATCH(E$1,BS별도H,0),0)/100,"") | G5: =IFERROR(VLOOKUP($D5,BS별도,MATCH(G$1,BS별도H,0),0)/100,"") | H5: =IFERROR(VLOOKUP($D5,BS별도,MATCH(H$1,BS별도H,0),0)/100,"") | I5: =IFERROR(VLOOKUP($D5,BS별도,MATCH(I$1,BS별도H,0),0)/100,"") | J5: =IFERROR(VLOOKUP($D5,BS별도,MATCH(J$1,BS별도H,0),0)/100,"") | K5: =SUM(G5:J5) | L5: =IFERROR(VLOOKUP($D5,BS별도,MATCH(L$1,BS별도H,0),0)/100,"") | M5: =IFERROR(VLOOKUP($D5,BS별도,MATCH(M$1,BS별도H,0),0)/100,"") | N5: =IFERROR(VLOOKUP($D5,BS별도,MATCH(N$1,BS별도H,0),0)/100,"") | O5: =IFERROR(VLOOKUP($D5,BS별도,MATCH(O$1,BS별도H,0),0)/100,"") | P5: =SUM(L5:O5) | Q5: =IFERROR(VLOOKUP($D5,BS별도,MATCH(Q$1,BS별도H,0),0)/100,"") | R5: =IFERROR(VLOOKUP($D5,BS별도,MATCH(R$1,BS별도H,0),0)/100,"") | S5: =IFERROR(VLOOKUP($D5,BS별도,MATCH(S$1,BS별도H,0),0)/100,"") | T5: =IFERROR(VLOOKUP($D5,BS별도,MATCH(T$1,BS별도H,0),0)/100,"") | U5: =SUM(Q5:T5) | V5: =IFERROR(VLOOKUP($D5,BS별도,MATCH(V$1,BS별도H,0),0)/100,"") | W5: =IFERROR(VLOOKUP($D5,BS별도,MATCH(W$1,BS별도H,0),0)/100,"") | X5: =IFERROR(VLOOKUP($D5,BS별도,MATCH(X$1,BS별도H,0),0)/100,"") | Y5: =IFERROR(VLOOKUP($D5,BS별도,MATCH(Y$1,BS별도H,0),0)/100,"") | Z5: =SUM(V5:Y5) | AA5: =IFERROR(VLOOKUP($D5,BS별도,MATCH(AA$1,BS별도H,0),0)/100,"") | AB5: =IFERROR(VLOOKUP($D5,BS별도,MATCH(AB$1,BS별도H,0),0)/100,"") | AC5: =IFERROR(X5*(1+변수!AC21),"") | AD5: =IFERROR(Y5*(1+변수!AD21),"") | AE5: =SUM(AA5:AD5) | AF5: =IFERROR(AA5*(1+변수!AF21),"") | AG5: =IFERROR(AB5*(1+변수!AG21),"") | AH5: =IFERROR(AC5*(1+변수!AH21),"") | AI5: =IFERROR(AD5*(1+변수!AI21),"") | AJ5: =SUM(AF5:AI5) | AK5: =IFERROR(AF5*(1+변수!AK21),"") | AL5: =IFERROR(AG5*(1+변수!AL21),"") | AM5: =IFERROR(AH5*(1+변수!AM21),"") | AN5: =IFERROR(AI5*(1+변수!AN21),"") | AO5: =SUM(AK5:AN5)
A6: 매출원가 | B6: 손익 | C6: 억원 | D6: 매출원가 | E6: =IFERROR(VLOOKUP($D6,BS별도,MATCH(E$1,BS별도H,0),0)/100,"") | G6: =IFERROR(VLOOKUP($D6,BS별도,MATCH(G$1,BS별도H,0),0)/100,"") | H6: =IFERROR(VLOOKUP($D6,BS별도,MATCH(H$1,BS별도H,0),0)/100,"") | I6: =IFERROR(VLOOKUP($D6,BS별도,MATCH(I$1,BS별도H,0),0)/100,"") | J6: =IFERROR(VLOOKUP($D6,BS별도,MATCH(J$1,BS별도H,0),0)/100,"") | K6: =SUM(G6:J6) | L6: =IFERROR(VLOOKUP($D6,BS별도,MATCH(L$1,BS별도H,0),0)/100,"") | M6: =IFERROR(VLOOKUP($D6,BS별도,MATCH(M$1,BS별도H,0),0)/100,"") | N6: =IFERROR(VLOOKUP($D6,BS별도,MATCH(N$1,BS별도H,0),0)/100,"") | O6: =IFERROR(VLOOKUP($D6,BS별도,MATCH(O$1,BS별도H,0),0)/100,"") | P6: =SUM(L6:O6) | Q6: =IFERROR(VLOOKUP($D6,BS별도,MATCH(Q$1,BS별도H,0),0)/100,"") | R6: =IFERROR(VLOOKUP($D6,BS별도,MATCH(R$1,BS별도H,0),0)/100,"") | S6: =IFERROR(VLOOKUP($D6,BS별도,MATCH(S$1,BS별도H,0),0)/100,"") | T6: =IFERROR(VLOOKUP($D6,BS별도,MATCH(T$1,BS별도H,0),0)/100,"") | U6: =SUM(Q6:T6) | V6: =IFERROR(VLOOKUP($D6,BS별도,MATCH(V$1,BS별도H,0),0)/100,"") | W6: =IFERROR(VLOOKUP($D6,BS별도,MATCH(W$1,BS별도H,0),0)/100,"") | X6: =IFERROR(VLOOKUP($D6,BS별도,MATCH(X$1,BS별도H,0),0)/100,"") | Y6: =IFERROR(VLOOKUP($D6,BS별도,MATCH(Y$1,BS별도H,0),0)/100,"") | Z6: =SUM(V6:Y6) | AA6: =IFERROR(VLOOKUP($D6,BS별도,MATCH(AA$1,BS별도H,0),0)/100,"") | AB6: =IFERROR(VLOOKUP($D6,BS별도,MATCH(AB$1,BS별도H,0),0)/100,"") | AC6: =IFERROR(AC5-AC7,"") | AD6: =IFERROR(AD5-AD7,"") | AE6: =SUM(AA6:AD6) | AF6: =IFERROR(AF5-AF7,"") | AG6: =IFERROR(AG5-AG7,"") | AH6: =IFERROR(AH5-AH7,"") | AI6: =IFERROR(AI5-AI7,"") | AJ6: =SUM(AF6:AI6) | AK6: =IFERROR(AK5-AK7,"") | AL6: =IFERROR(AL5-AL7,"") | AM6: =IFERROR(AM5-AM7,"") | AN6: =IFERROR(AN5-AN7,"") | AO6: =SUM(AK6:AN6)
A7: 매출총이익 | B7: 손익 | C7: 억원 | D7: 매출총이익 | E7: =IFERROR(VLOOKUP($D7,BS별도,MATCH(E$1,BS별도H,0),0)/100,"") | G7: =IFERROR(VLOOKUP($D7,BS별도,MATCH(G$1,BS별도H,0),0)/100,"") | H7: =IFERROR(VLOOKUP($D7,BS별도,MATCH(H$1,BS별도H,0),0)/100,"") | I7: =IFERROR(VLOOKUP($D7,BS별도,MATCH(I$1,BS별도H,0),0)/100,"") | J7: =IFERROR(VLOOKUP($D7,BS별도,MATCH(J$1,BS별도H,0),0)/100,"") | K7: =SUM(G7:J7) | L7: =IFERROR(VLOOKUP($D7,BS별도,MATCH(L$1,BS별도H,0),0)/100,"") | M7: =IFERROR(VLOOKUP($D7,BS별도,MATCH(M$1,BS별도H,0),0)/100,"") | N7: =IFERROR(VLOOKUP($D7,BS별도,MATCH(N$1,BS별도H,0),0)/100,"") | O7: =IFERROR(VLOOKUP($D7,BS별도,MATCH(O$1,BS별도H,0),0)/100,"") | P7: =SUM(L7:O7) | Q7: =IFERROR(VLOOKUP($D7,BS별도,MATCH(Q$1,BS별도H,0),0)/100,"") | R7: =IFERROR(VLOOKUP($D7,BS별도,MATCH(R$1,BS별도H,0),0)/100,"") | S7: =IFERROR(VLOOKUP($D7,BS별도,MATCH(S$1,BS별도H,0),0)/100,"") | T7: =IFERROR(VLOOKUP($D7,BS별도,MATCH(T$1,BS별도H,0),0)/100,"") | U7: =SUM(Q7:T7) | V7: =IFERROR(VLOOKUP($D7,BS별도,MATCH(V$1,BS별도H,0),0)/100,"") | W7: =IFERROR(VLOOKUP($D7,BS별도,MATCH(W$1,BS별도H,0),0)/100,"") | X7: =IFERROR(VLOOKUP($D7,BS별도,MATCH(X$1,BS별도H,0),0)/100,"") | Y7: =IFERROR(VLOOKUP($D7,BS별도,MATCH(Y$1,BS별도H,0),0)/100,"") | Z7: =SUM(V7:Y7) | AA7: =IFERROR(VLOOKUP($D7,BS별도,MATCH(AA$1,BS별도H,0),0)/100,"") | AB7: =IFERROR(VLOOKUP($D7,BS별도,MATCH(AB$1,BS별도H,0),0)/100,"") | AC7: =IFERROR(AC9+AC8,"") | AD7: =IFERROR(AD9+AD8,"") | AE7: =SUM(AA7:AD7) | AF7: =IFERROR(AF9+AF8,"") | AG7: =IFERROR(AG9+AG8,"") | AH7: =IFERROR(AH9+AH8,"") | AI7: =IFERROR(AI9+AI8,"") | AJ7: =SUM(AF7:AI7) | AK7: =IFERROR(AK9+AK8,"") | AL7: =IFERROR(AL9+AL8,"") | AM7: =IFERROR(AM9+AM8,"") | AN7: =IFERROR(AN9+AN8,"") | AO7: =SUM(AK7:AN7)
A8: 판관비 | B8: 손익 | C8: 억원 | D8: 판관비 | E8: =IFERROR(VLOOKUP($D8,BS별도,MATCH(E$1,BS별도H,0),0)/100,"") | G8: =IFERROR(VLOOKUP($D8,BS별도,MATCH(G$1,BS별도H,0),0)/100,"") | H8: =IFERROR(VLOOKUP($D8,BS별도,MATCH(H$1,BS별도H,0),0)/100,"") | I8: =IFERROR(VLOOKUP($D8,BS별도,MATCH(I$1,BS별도H,0),0)/100,"") | J8: =IFERROR(VLOOKUP($D8,BS별도,MATCH(J$1,BS별도H,0),0)/100,"") | K8: =SUM(G8:J8) | L8: =IFERROR(VLOOKUP($D8,BS별도,MATCH(L$1,BS별도H,0),0)/100,"") | M8: =IFERROR(VLOOKUP($D8,BS별도,MATCH(M$1,BS별도H,0),0)/100,"") | N8: =IFERROR(VLOOKUP($D8,BS별도,MATCH(N$1,BS별도H,0),0)/100,"") | O8: =IFERROR(VLOOKUP($D8,BS별도,MATCH(O$1,BS별도H,0),0)/100,"") | P8: =SUM(L8:O8) | Q8: =IFERROR(VLOOKUP($D8,BS별도,MATCH(Q$1,BS별도H,0),0)/100,"") | R8: =IFERROR(VLOOKUP($D8,BS별도,MATCH(R$1,BS별도H,0),0)/100,"") | S8: =IFERROR(VLOOKUP($D8,BS별도,MATCH(S$1,BS별도H,0),0)/100,"") | T8: =IFERROR(VLOOKUP($D8,BS별도,MATCH(T$1,BS별도H,0),0)/100,"") | U8: =SUM(Q8:T8) | V8: =IFERROR(VLOOKUP($D8,BS별도,MATCH(V$1,BS별도H,0),0)/100,"") | W8: =IFERROR(VLOOKUP($D8,BS별도,MATCH(W$1,BS별도H,0),0)/100,"") | X8: =IFERROR(VLOOKUP($D8,BS별도,MATCH(X$1,BS별도H,0),0)/100,"") | Y8: =IFERROR(VLOOKUP($D8,BS별도,MATCH(Y$1,BS별도H,0),0)/100,"") | Z8: =SUM(V8:Y8) | AA8: =IFERROR(VLOOKUP($D8,BS별도,MATCH(AA$1,BS별도H,0),0)/100,"") | AB8: =IFERROR(VLOOKUP($D8,BS별도,MATCH(AB$1,BS별도H,0),0)/100,"") | AC8: =IFERROR(AC5*변수!AC22,"") | AD8: =IFERROR(AD5*변수!AD22,"") | AE8: =SUM(AA8:AD8) | AF8: =IFERROR(AF5*변수!AF22,"") | AG8: =IFERROR(AG5*변수!AG22,"") | AH8: =IFERROR(AH5*변수!AH22,"") | AI8: =IFERROR(AI5*변수!AI22,"") | AJ8: =SUM(AF8:AI8) | AK8: =IFERROR(AK5*변수!AK22,"") | AL8: =IFERROR(AL5*변수!AL22,"") | AM8: =IFERROR(AM5*변수!AM22,"") | AN8: =IFERROR(AN5*변수!AN22,"") | AO8: =SUM(AK8:AN8)
A9: 영업이익 | B9: 손익 | C9: 억원 | D9: 영업이익 | E9: =IFERROR(VLOOKUP($D9,BS별도,MATCH(E$1,BS별도H,0),0)/100,"") | G9: =IFERROR(VLOOKUP($D9,BS별도,MATCH(G$1,BS별도H,0),0)/100,"") | H9: =IFERROR(VLOOKUP($D9,BS별도,MATCH(H$1,BS별도H,0),0)/100,"") | I9: =IFERROR(VLOOKUP($D9,BS별도,MATCH(I$1,BS별도H,0),0)/100,"") | J9: =IFERROR(VLOOKUP($D9,BS별도,MATCH(J$1,BS별도H,0),0)/100,"") | K9: =SUM(G9:J9) | L9: =IFERROR(VLOOKUP($D9,BS별도,MATCH(L$1,BS별도H,0),0)/100,"") | M9: =IFERROR(VLOOKUP($D9,BS별도,MATCH(M$1,BS별도H,0),0)/100,"") | N9: =IFERROR(VLOOKUP($D9,BS별도,MATCH(N$1,BS별도H,0),0)/100,"") | O9: =IFERROR(VLOOKUP($D9,BS별도,MATCH(O$1,BS별도H,0),0)/100,"") | P9: =SUM(L9:O9) | Q9: =IFERROR(VLOOKUP($D9,BS별도,MATCH(Q$1,BS별도H,0),0)/100,"") | R9: =IFERROR(VLOOKUP($D9,BS별도,MATCH(R$1,BS별도H,0),0)/100,"") | S9: =IFERROR(VLOOKUP($D9,BS별도,MATCH(S$1,BS별도H,0),0)/100,"") | T9: =IFERROR(VLOOKUP($D9,BS별도,MATCH(T$1,BS별도H,0),0)/100,"") | U9: =SUM(Q9:T9) | V9: =IFERROR(VLOOKUP($D9,BS별도,MATCH(V$1,BS별도H,0),0)/100,"") | W9: =IFERROR(VLOOKUP($D9,BS별도,MATCH(W$1,BS별도H,0),0)/100,"") | X9: =IFERROR(VLOOKUP($D9,BS별도,MATCH(X$1,BS별도H,0),0)/100,"") | Y9: =IFERROR(VLOOKUP($D9,BS별도,MATCH(Y$1,BS별도H,0),0)/100,"") | Z9: =SUM(V9:Y9) | AA9: =IFERROR(VLOOKUP($D9,BS별도,MATCH(AA$1,BS별도H,0),0)/100,"") | AB9: =IFERROR(VLOOKUP($D9,BS별도,MATCH(AB$1,BS별도H,0),0)/100,"") | AC9: =IFERROR(AC5*변수!AC23,"") | AD9: =IFERROR(AD5*변수!AD23,"") | AE9: =SUM(AA9:AD9) | AF9: =IFERROR(AF5*변수!AF23,"") | AG9: =IFERROR(AG5*변수!AG23,"") | AH9: =IFERROR(AH5*변수!AH23,"") | AI9: =IFERROR(AI5*변수!AI23,"") | AJ9: =SUM(AF9:AI9) | AK9: =IFERROR(AK5*변수!AK23,"") | AL9: =IFERROR(AL5*변수!AL23,"") | AM9: =IFERROR(AM5*변수!AM23,"") | AN9: =IFERROR(AN5*변수!AN23,"") | AO9: =SUM(AK9:AN9)
A10: OPM | B10: 손익 | C10: % | D10: 영업이익률 | E10: =IFERROR(E9/E5,"") | G10: =IFERROR(G9/G5,"") | H10: =IFERROR(H9/H5,"") | I10: =IFERROR(I9/I5,"") | J10: =IFERROR(J9/J5,"") | K10: =IFERROR(K9/K5,"") | L10: =IFERROR(L9/L5,"") | M10: =IFERROR(M9/M5,"") | N10: =IFERROR(N9/N5,"") | ... AO10: =IFERROR(AO9/AO5,"")
A11: 금융손익 | B11: 손익 | C11: 억원 | D11: 금융손익 | E11: =IFERROR(VLOOKUP($D11,BS별도,MATCH(E$1,BS별도H,0),0)/100,"") | G11: =IFERROR(VLOOKUP($D11,BS별도,MATCH(G$1,BS별도H,0),0)/100,"") | H11: =IFERROR(VLOOKUP($D11,BS별도,MATCH(H$1,BS별도H,0),0)/100,"") | I11: =IFERROR(VLOOKUP($D11,BS별도,MATCH(I$1,BS별도H,0),0)/100,"") | J11: =IFERROR(VLOOKUP($D11,BS별도,MATCH(J$1,BS별도H,0),0)/100,"") | K11: =SUM(G11:J11) | L11: =IFERROR(VLOOKUP($D11,BS별도,MATCH(L$1,BS별도H,0),0)/100,"") | M11: =IFERROR(VLOOKUP($D11,BS별도,MATCH(M$1,BS별도H,0),0)/100,"") | N11: =IFERROR(VLOOKUP($D11,BS별도,MATCH(N$1,BS별도H,0),0)/100,"") | O11: =IFERROR(VLOOKUP($D11,BS별도,MATCH(O$1,BS별도H,0),0)/100,"") | P11: =SUM(L11:O11) | Q11: =IFERROR(VLOOKUP($D11,BS별도,MATCH(Q$1,BS별도H,0),0)/100,"") | R11: =IFERROR(VLOOKUP($D11,BS별도,MATCH(R$1,BS별도H,0),0)/100,"") | S11: =IFERROR(VLOOKUP($D11,BS별도,MATCH(S$1,BS별도H,0),0)/100,"") | T11: =IFERROR(VLOOKUP($D11,BS별도,MATCH(T$1,BS별도H,0),0)/100,"") | U11: =SUM(Q11:T11) | V11: =IFERROR(VLOOKUP($D11,BS별도,MATCH(V$1,BS별도H,0),0)/100,"") | W11: =IFERROR(VLOOKUP($D11,BS별도,MATCH(W$1,BS별도H,0),0)/100,"") | X11: =IFERROR(VLOOKUP($D11,BS별도,MATCH(X$1,BS별도H,0),0)/100,"") | Y11: =IFERROR(VLOOKUP($D11,BS별도,MATCH(Y$1,BS별도H,0),0)/100,"") | Z11: =SUM(V11:Y11) | AA11: =IFERROR(VLOOKUP($D11,BS별도,MATCH(AA$1,BS별도H,0),0)/100,"") | AB11: =IFERROR(VLOOKUP($D11,BS별도,MATCH(AB$1,BS별도H,0),0)/100,"") | AC11: =IFERROR(AC12+AC13,"") | AD11: =IFERROR(AD12+AD13,"") | AE11: =SUM(AA11:AD11) | AF11: =IFERROR(AF12+AF13,"") | AG11: =IFERROR(AG12+AG13,"") | AH11: =IFERROR(AH12+AH13,"") | AI11: =IFERROR(AI12+AI13,"") | AJ11: =SUM(AF11:AI11) | AK11: =IFERROR(AK12+AK13,"") | AL11: =IFERROR(AL12+AL13,"") | AM11: =IFERROR(AM12+AM13,"") | AN11: =IFERROR(AN12+AN13,"") | AO11: =SUM(AK11:AN11)
A12: 이자손익 | B12: 손익 | C12: 억원 | D12: 이자손익 | G12: =IFERROR(VLOOKUP($D12,BS별도,MATCH(G$1,BS별도H,0),0)/100,"") | H12: =IFERROR(VLOOKUP($D12,BS별도,MATCH(H$1,BS별도H,0),0)/100,"") | I12: =IFERROR(VLOOKUP($D12,BS별도,MATCH(I$1,BS별도H,0),0)/100,"") | J12: =IFERROR(VLOOKUP($D12,BS별도,MATCH(J$1,BS별도H,0),0)/100,"") | K12: =SUM(G12:J12) | L12: =IFERROR(VLOOKUP($D12,BS별도,MATCH(L$1,BS별도H,0),0)/100,"") | M12: =IFERROR(VLOOKUP($D12,BS별도,MATCH(M$1,BS별도H,0),0)/100,"") | N12: =IFERROR(VLOOKUP($D12,BS별도,MATCH(N$1,BS별도H,0),0)/100,"") | O12: =IFERROR(VLOOKUP($D12,BS별도,MATCH(O$1,BS별도H,0),0)/100,"") | P12: =SUM(L12:O12) | Q12: =IFERROR(VLOOKUP($D12,BS별도,MATCH(Q$1,BS별도H,0),0)/100,"") | R12: =IFERROR(VLOOKUP($D12,BS별도,MATCH(R$1,BS별도H,0),0)/100,"") | S12: =IFERROR(VLOOKUP($D12,BS별도,MATCH(S$1,BS별도H,0),0)/100,"") | T12: =IFERROR(VLOOKUP($D12,BS별도,MATCH(T$1,BS별도H,0),0)/100,"") | U12: =SUM(Q12:T12) | V12: =IFERROR(VLOOKUP($D12,BS별도,MATCH(V$1,BS별도H,0),0)/100,"") | W12: =IFERROR(VLOOKUP($D12,BS별도,MATCH(W$1,BS별도H,0),0)/100,"") | X12: =IFERROR(VLOOKUP($D12,BS별도,MATCH(X$1,BS별도H,0),0)/100,"") | Y12: =IFERROR(VLOOKUP($D12,BS별도,MATCH(Y$1,BS별도H,0),0)/100,"") | Z12: =SUM(V12:Y12) | AA12: =IFERROR(VLOOKUP($D12,BS별도,MATCH(AA$1,BS별도H,0),0)/100,"") | AB12: =IFERROR(VLOOKUP($D12,BS별도,MATCH(AB$1,BS별도H,0),0)/100,"") | AC12: =IFERROR((AB26*변수!$D$52-AB24*변수!$D$53)/4,"") | AD12: =IFERROR((AC26*변수!$D$52-AC24*변수!$D$53)/4,"") | AE12: =SUM(AA12:AD12) | AF12: =IFERROR((AD26*변수!$D$52-AD24*변수!$D$53)/4,"") | AG12: =IFERROR((AF26*변수!$D$52-AF24*변수!$D$53)/4,"") | AH12: =IFERROR((AG26*변수!$D$52-AG24*변수!$D$53)/4,"") | AI12: =IFERROR((AH26*변수!$D$52-AH24*변수!$D$53)/4,"") | AJ12: =SUM(AF12:AI12) | AK12: =IFERROR((AI26*변수!$D$52-AI24*변수!$D$53)/4,"") | AL12: =IFERROR((AK26*변수!$D$52-AK24*변수!$D$53)/4,"") | AM12: =IFERROR((AL26*변수!$D$52-AL24*변수!$D$53)/4,"") | AN12: =IFERROR((AM26*변수!$D$52-AM24*변수!$D$53)/4,"") | AO12: =SUM(AK12:AN12)
A13: 외환손익 | B13: 손익 | C13: 억원 | D13: 외환손익(실적만; 추정 환효과는 환관련손익) | K13: =SUM(G13:J13) | P13: =SUM(L13:O13) | R13: =IFERROR((VLOOKUP("외환차익",BS별도,MATCH(R$1,BS별도H,0),0)-VLOOKUP("외환차손",BS별도,MATCH(R$1,BS별도H,0),0)+VLOOKUP("외화환산이익",BS별도,MATCH(R$1,BS별도H,0),0)-VLOOKUP("외화환산손실",BS별도,MATCH(R$1,BS별도H,0),0))/100,"") | U13: =SUM(Q13:T13) | Z13: =SUM(V13:Y13) | AC13: =변수!AC24 | AD13: =변수!AD24 | AE13: =SUM(AA13:AD13) | AF13: =변수!AF24 | AG13: =변수!AG24 | AH13: =변수!AH24 | AI13: =변수!AI24 | AJ13: =SUM(AF13:AI13) | AK13: =변수!AK24 | AL13: =변수!AL24 | AM13: =변수!AM24 | AN13: =변수!AN24 | AO13: =SUM(AK13:AN13)
A14: 기타영업외손익 | B14: 손익 | C14: 억원 | D14: 기타영업외손익 | E14: =IFERROR(VLOOKUP($D14,BS별도,MATCH(E$1,BS별도H,0),0)/100,"") | G14: =IFERROR(VLOOKUP($D14,BS별도,MATCH(G$1,BS별도H,0),0)/100,"") | H14: =IFERROR(VLOOKUP($D14,BS별도,MATCH(H$1,BS별도H,0),0)/100,"") | I14: =IFERROR(VLOOKUP($D14,BS별도,MATCH(I$1,BS별도H,0),0)/100,"") | J14: =IFERROR(VLOOKUP($D14,BS별도,MATCH(J$1,BS별도H,0),0)/100,"") | K14: =SUM(G14:J14) | L14: =IFERROR(VLOOKUP($D14,BS별도,MATCH(L$1,BS별도H,0),0)/100,"") | M14: =IFERROR(VLOOKUP($D14,BS별도,MATCH(M$1,BS별도H,0),0)/100,"") | N14: =IFERROR(VLOOKUP($D14,BS별도,MATCH(N$1,BS별도H,0),0)/100,"") | O14: =IFERROR(VLOOKUP($D14,BS별도,MATCH(O$1,BS별도H,0),0)/100,"") | P14: =SUM(L14:O14) | Q14: =IFERROR(VLOOKUP($D14,BS별도,MATCH(Q$1,BS별도H,0),0)/100,"") | R14: =IFERROR(VLOOKUP($D14,BS별도,MATCH(R$1,BS별도H,0),0)/100,"") | S14: =IFERROR(VLOOKUP($D14,BS별도,MATCH(S$1,BS별도H,0),0)/100,"") | T14: =IFERROR(VLOOKUP($D14,BS별도,MATCH(T$1,BS별도H,0),0)/100,"") | U14: =SUM(Q14:T14) | V14: =IFERROR(VLOOKUP($D14,BS별도,MATCH(V$1,BS별도H,0),0)/100,"") | W14: =IFERROR(VLOOKUP($D14,BS별도,MATCH(W$1,BS별도H,0),0)/100,"") | X14: =IFERROR(VLOOKUP($D14,BS별도,MATCH(X$1,BS별도H,0),0)/100,"") | Y14: =IFERROR(VLOOKUP($D14,BS별도,MATCH(Y$1,BS별도H,0),0)/100,"") | Z14: =SUM(V14:Y14) | AA14: =IFERROR(VLOOKUP($D14,BS별도,MATCH(AA$1,BS별도H,0),0)/100,"") | AB14: =IFERROR(VLOOKUP($D14,BS별도,MATCH(AB$1,BS별도H,0),0)/100,"") | AC14: =변수!AC25 | AD14: =변수!AD25 | AE14: =SUM(AA14:AD14) | AF14: =변수!AF25 | AG14: =변수!AG25 | AH14: =변수!AH25 | AI14: =변수!AI25 | AJ14: =SUM(AF14:AI14) | AK14: =변수!AK25 | AL14: =변수!AL25 | AM14: =변수!AM25 | AN14: =변수!AN25 | AO14: =SUM(AK14:AN14)
A15: 지분법손익 | B15: 손익 | C15: 억원 | D15: 종속기업,공동지배기업및관계기업관련손익 | E15: =IFERROR(VLOOKUP($D15,BS별도,MATCH(E$1,BS별도H,0),0)/100,"") | I15: =IFERROR(VLOOKUP($D15,BS별도,MATCH(I$1,BS별도H,0),0)/100,"") | J15: =IFERROR(VLOOKUP($D15,BS별도,MATCH(J$1,BS별도H,0),0)/100,"") | K15: =SUM(G15:J15) | P15: =SUM(L15:O15) | U15: =SUM(Q15:T15) | Z15: =SUM(V15:Y15) | AC15: =변수!AC26 | AD15: =변수!AD26 | AE15: =SUM(AA15:AD15) | AF15: =변수!AF26 | AG15: =변수!AG26 | AH15: =변수!AH26 | AI15: =변수!AI26 | AJ15: =SUM(AF15:AI15) | AK15: =변수!AK26 | AL15: =변수!AL26 | AM15: =변수!AM26 | AN15: =변수!AN26 | AO15: =SUM(AK15:AN15)
A16: 세전이익 | B16: 손익 | C16: 억원 | D16: 법인세비용차감전계속사업이익 | E16: =IFERROR(VLOOKUP($D16,BS별도,MATCH(E$1,BS별도H,0),0)/100,"") | G16: =IFERROR(VLOOKUP($D16,BS별도,MATCH(G$1,BS별도H,0),0)/100,"") | H16: =IFERROR(VLOOKUP($D16,BS별도,MATCH(H$1,BS별도H,0),0)/100,"") | I16: =IFERROR(VLOOKUP($D16,BS별도,MATCH(I$1,BS별도H,0),0)/100,"") | J16: =IFERROR(VLOOKUP($D16,BS별도,MATCH(J$1,BS별도H,0),0)/100,"") | K16: =SUM(G16:J16) | L16: =IFERROR(VLOOKUP($D16,BS별도,MATCH(L$1,BS별도H,0),0)/100,"") | M16: =IFERROR(VLOOKUP($D16,BS별도,MATCH(M$1,BS별도H,0),0)/100,"") | N16: =IFERROR(VLOOKUP($D16,BS별도,MATCH(N$1,BS별도H,0),0)/100,"") | O16: =IFERROR(VLOOKUP($D16,BS별도,MATCH(O$1,BS별도H,0),0)/100,"") | P16: =SUM(L16:O16) | Q16: =IFERROR(VLOOKUP($D16,BS별도,MATCH(Q$1,BS별도H,0),0)/100,"") | R16: =IFERROR(VLOOKUP($D16,BS별도,MATCH(R$1,BS별도H,0),0)/100,"") | S16: =IFERROR(VLOOKUP($D16,BS별도,MATCH(S$1,BS별도H,0),0)/100,"") | T16: =IFERROR(VLOOKUP($D16,BS별도,MATCH(T$1,BS별도H,0),0)/100,"") | U16: =SUM(Q16:T16) | V16: =IFERROR(VLOOKUP($D16,BS별도,MATCH(V$1,BS별도H,0),0)/100,"") | W16: =IFERROR(VLOOKUP($D16,BS별도,MATCH(W$1,BS별도H,0),0)/100,"") | X16: =IFERROR(VLOOKUP($D16,BS별도,MATCH(X$1,BS별도H,0),0)/100,"") | Y16: =IFERROR(VLOOKUP($D16,BS별도,MATCH(Y$1,BS별도H,0),0)/100,"") | Z16: =SUM(V16:Y16) | AA16: =IFERROR(VLOOKUP($D16,BS별도,MATCH(AA$1,BS별도H,0),0)/100,"") | AB16: =IFERROR(VLOOKUP($D16,BS별도,MATCH(AB$1,BS별도H,0),0)/100,"") | AC16: =IFERROR(AC9+AC11+AC14+AC15,"") | AD16: =IFERROR(AD9+AD11+AD14+AD15,"") | AE16: =SUM(AA16:AD16) | AF16: =IFERROR(AF9+AF11+AF14+AF15,"") | AG16: =IFERROR(AG9+AG11+AG14+AG15,"") | AH16: =IFERROR(AH9+AH11+AH14+AH15,"") | AI16: =IFERROR(AI9+AI11+AI14+AI15,"") | AJ16: =SUM(AF16:AI16) | AK16: =IFERROR(AK9+AK11+AK14+AK15,"") | AL16: =IFERROR(AL9+AL11+AL14+AL15,"") | AM16: =IFERROR(AM9+AM11+AM14+AM15,"") | AN16: =IFERROR(AN9+AN11+AN14+AN15,"") | AO16: =SUM(AK16:AN16)
A17: 법인세비용 | B17: 손익 | C17: 억원 | D17: 법인세비용 | E17: =IFERROR(VLOOKUP($D17,BS별도,MATCH(E$1,BS별도H,0),0)/100,"") | G17: =IFERROR(VLOOKUP($D17,BS별도,MATCH(G$1,BS별도H,0),0)/100,"") | H17: =IFERROR(VLOOKUP($D17,BS별도,MATCH(H$1,BS별도H,0),0)/100,"") | I17: =IFERROR(VLOOKUP($D17,BS별도,MATCH(I$1,BS별도H,0),0)/100,"") | J17: =IFERROR(VLOOKUP($D17,BS별도,MATCH(J$1,BS별도H,0),0)/100,"") | K17: =SUM(G17:J17) | L17: =IFERROR(VLOOKUP($D17,BS별도,MATCH(L$1,BS별도H,0),0)/100,"") | M17: =IFERROR(VLOOKUP($D17,BS별도,MATCH(M$1,BS별도H,0),0)/100,"") | P17: =SUM(L17:O17) | S17: =IFERROR(VLOOKUP($D17,BS별도,MATCH(S$1,BS별도H,0),0)/100,"") | T17: =IFERROR(VLOOKUP($D17,BS별도,MATCH(T$1,BS별도H,0),0)/100,"") | U17: =SUM(Q17:T17) | X17: =IFERROR(VLOOKUP($D17,BS별도,MATCH(X$1,BS별도H,0),0)/100,"") | Y17: =IFERROR(VLOOKUP($D17,BS별도,MATCH(Y$1,BS별도H,0),0)/100,"") | Z17: =SUM(V17:Y17) | AC17: =IFERROR(MAX(AC16,0)*변수!AC27,"") | AD17: =IFERROR(MAX(AD16,0)*변수!AD27,"") | AE17: =SUM(AA17:AD17) | AF17: =IFERROR(MAX(AF16,0)*변수!AF27,"") | AG17: =IFERROR(MAX(AG16,0)*변수!AG27,"") | AH17: =IFERROR(MAX(AH16,0)*변수!AH27,"") | AI17: =IFERROR(MAX(AI16,0)*변수!AI27,"") | AJ17: =SUM(AF17:AI17) | AK17: =IFERROR(MAX(AK16,0)*변수!AK27,"") | AL17: =IFERROR(MAX(AL16,0)*변수!AL27,"") | AM17: =IFERROR(MAX(AM16,0)*변수!AM27,"") | AN17: =IFERROR(MAX(AN16,0)*변수!AN27,"") | AO17: =SUM(AK17:AN17)
A18: 당기순이익 | B18: 손익 | C18: 억원 | D18: 당기순이익 | E18: =IFERROR(VLOOKUP($D18,BS별도,MATCH(E$1,BS별도H,0),0)/100,"") | G18: =IFERROR(VLOOKUP($D18,BS별도,MATCH(G$1,BS별도H,0),0)/100,"") | H18: =IFERROR(VLOOKUP($D18,BS별도,MATCH(H$1,BS별도H,0),0)/100,"") | I18: =IFERROR(VLOOKUP($D18,BS별도,MATCH(I$1,BS별도H,0),0)/100,"") | J18: =IFERROR(VLOOKUP($D18,BS별도,MATCH(J$1,BS별도H,0),0)/100,"") | K18: =SUM(G18:J18) | L18: =IFERROR(VLOOKUP($D18,BS별도,MATCH(L$1,BS별도H,0),0)/100,"") | M18: =IFERROR(VLOOKUP($D18,BS별도,MATCH(M$1,BS별도H,0),0)/100,"") | N18: =IFERROR(VLOOKUP($D18,BS별도,MATCH(N$1,BS별도H,0),0)/100,"") | O18: =IFERROR(VLOOKUP($D18,BS별도,MATCH(O$1,BS별도H,0),0)/100,"") | P18: =SUM(L18:O18) | Q18: =IFERROR(VLOOKUP($D18,BS별도,MATCH(Q$1,BS별도H,0),0)/100,"") | R18: =IFERROR(VLOOKUP($D18,BS별도,MATCH(R$1,BS별도H,0),0)/100,"") | S18: =IFERROR(VLOOKUP($D18,BS별도,MATCH(S$1,BS별도H,0),0)/100,"") | T18: =IFERROR(VLOOKUP($D18,BS별도,MATCH(T$1,BS별도H,0),0)/100,"") | U18: =SUM(Q18:T18) | V18: =IFERROR(VLOOKUP($D18,BS별도,MATCH(V$1,BS별도H,0),0)/100,"") | W18: =IFERROR(VLOOKUP($D18,BS별도,MATCH(W$1,BS별도H,0),0)/100,"") | X18: =IFERROR(VLOOKUP($D18,BS별도,MATCH(X$1,BS별도H,0),0)/100,"") | Y18: =IFERROR(VLOOKUP($D18,BS별도,MATCH(Y$1,BS별도H,0),0)/100,"") | Z18: =SUM(V18:Y18) | AA18: =IFERROR(VLOOKUP($D18,BS별도,MATCH(AA$1,BS별도H,0),0)/100,"") | AB18: =IFERROR(VLOOKUP($D18,BS별도,MATCH(AB$1,BS별도H,0),0)/100,"") | AC18: =IFERROR(AC16-AC17,"") | AD18: =IFERROR(AD16-AD17,"") | AE18: =SUM(AA18:AD18) | AF18: =IFERROR(AF16-AF17,"") | AG18: =IFERROR(AG16-AG17,"") | AH18: =IFERROR(AH16-AH17,"") | AI18: =IFERROR(AI16-AI17,"") | AJ18: =SUM(AF18:AI18) | AK18: =IFERROR(AK16-AK17,"") | AL18: =IFERROR(AL16-AL17,"") | AM18: =IFERROR(AM16-AM17,"") | AN18: =IFERROR(AN16-AN17,"") | AO18: =SUM(AK18:AN18)
