Workbook
Name 변수H: 변수!$C$1:$AO$1
Name 환율: 변수!$C$6:$AO$13
Name BS연결H: BS연결!$C$1:$AO$1
Name BS연결: BS연결!$C$5:$AO$122
Name BS별도H: BS별도!$C$1:$AO$1
Name BS별도: BS별도!$C$5:$AO$104
Name SUBQH: subQ!$A$1:$AO$1
Name subQ: subQ!$A$5:$AO$44

Sheet README
A1: 두산에너빌리티(034020) 실적 모델 — ARGUS 한국조선
A2: 기준 분기 2026Q2 · 마지막 실적 2026Q2 · 생성 2026-10-19
A3: 모든 수치는 모델 산출값(DART 공개 재무제표 + 우리 추정)이다 — 목표주가·투자 추천 아님. 참고용 · 투자조언 아님.
A5: 시트
A6: 변수 가정 시계열. 환율 8행(ECB via frankfurter — L2 fx.json; 추정 분기 = 노란 가정), 추정 드라이버(노란 셀 = 모델값에서 역산한 가정, 바꾸면 재계산; 연녹 셀 = 3절 스칼라 참조 수식), 3절 스칼라 가정(세율·판관비율·지배주주비중·이자율·종가·PER 밴드·COE·외화 순노출·헤지비율)
A7: BS연결/BS별도 FnGuide 계정명 × 기간 값 덤프(백만원). 행1 분기라벨, 행4 YYYY.MM / YYYY.12A. 이름정의 BS연결H·BS연결(계정명 C열부터)
A8: subQ 분기 서브모델(억원 = 백만원/100). 확정 행: =IFERROR(VLOOKUP($D행,BS연결,MATCH(E$1,BS연결H,0),0)/100,"") 추정 행: 변수 시트 가정 셀 참조 수식. 외환손익·파생상품손익은 BS 계정 합·차, 기타금융손익은 잔차, OPM·EPS·BPS·PER·PBR 은 파생 수식
A9: SLS 선표(조선사만, sls json 있을 때): 요약 행(sls 저장값) + 계약별 스케줄(백만$) × (헤지비율 × 헤지환율 + (1−헤지비율) × 건조시점 환율[변수 원/달러(평균)]) → 원화 수식 블록 → 합계 행이 subQ 매출조선에 연결
A10: 시나리오 신규수주 보수/기준/낙관(forecast_panel 패널, 모델에 scenarios 가 있을 때만): 매출액·영업이익 = subQ 기준값 ± (시나리오 신규 − base 신규) × OPM. base 만 subQ 행에 포함, 나머지는 합산 안 함
A11: 분기/연간예상 subQ 를 이름(A열 key)으로 VLOOKUP 한 보고서 표(억원)
A12: TP PER 밴드 × 12M fwd EPS, PBR = ROE/COE × BPS — 모델 산출값 구간, 목표주가·추천 아님
A13: 외화 환율 QoQ, 외화 순노출 × Δ기말환율 → 환관련손익 추정
... A34: 백테스트: {"freeze": "2025Q2", "horizon": 4, "revenue_wape_pct": 13.1, "op_wape_pct": 20.0, "n": 4, "note": "단일 회사 4분기 — 통계 아님", "driver_at_freeze": "trend_seasonal", "selection_oos_at_freeze": null, "frozen_inputs": "fin(연결/별도)·고객 조선사 모델·지주 자회사 모델은 2025Q2 까지의 분기만; 선표는 체결일 ≤ 2025Q2 말일 계약(원장 최신 금액·코호트 등급, 환산 없음); 잔고는 yards_cache 2025Q2; 시세·환율 forward·prices·forecast_panel 신규수주 미사용. 고객 가중치(suppliers.json 언급 비중)와 합병 체인링크는 현재 지식; 고객 연동 채택은 동결 모델 안에서도 자기 la−4분기 OOS 규칙(selection_oos_at_freeze)", "detail": [{"q": "2025Q3", "rev_pred": 32075.61, "rev_act": 38803.5, "op_pred": 1931.83, "op_act": 1370.59}, {"q": "2025Q4", "rev_pred": 43350.38, "rev_act": 48599.31, "op_pred": 2610.89, "op_act": 2120.72}, {"q": "2026Q1", "rev_pred": 35410.21, "rev_act": 42611.3, "op_pred": 2132.67, "op_act": 2335.14}, {"q": "2026Q2", "rev_pred": 43160.41, "rev_act": 47248.08, "op_pred": 2599.44, "op_act": 3142.6}]}

Sheet 변수
C1: 이름: 변수H | E1: 4Q21 | F1: 2021 | G1: 1Q22 | H1: 2Q22 | I1: 3Q22 | J1: 4Q22 | K1: 2022 | L1: 1Q23 | M1: 2Q23 | N1: 3Q23 | O1: 4Q23 | P1: 2023 | Q1: 1Q24 | R1: 2Q24 | S1: 3Q24 | T1: 4Q24 | U1: 2024 | V1: 1Q25 | W1: 2Q25 | X1: 3Q25 | Y1: 4Q25 | Z1: 2025 | AA1: 1Q26 | AB1: 2Q26 | AC1: 3Q26 | AD1: 4Q26 | AE1: 2026 | AF1: 1Q27 | AG1: 2Q27 | AH1: 3Q27 | AI1: 4Q27 | AJ1: 2027 | AK1: 1Q28 | AL1: 2Q28 | AM1: 3Q28 | AN1: 4Q28 | AO1: 2028
A2: 가정 시계열 — 노란 셀은 추정 가정(모델값에서 역산), 연녹 셀은 3절 스칼라 참조 수식. 바꾸면 subQ·분기·연간예상·TP·시나리오가 재계산됩니다.
E3: 1 | F3: 2 | G3: 3 | H3: 4 | I3: 5 | J3: 6 | K3: 7 | L3: 8 | M3: 9 | N3: 10 | O3: 11 | P3: 12 | Q3: 13 | R3: 14 | S3: 15 | T3: 16 | U3: 17 | V3: 18 | W3: 19 | X3: 20 | Y3: 21 | Z3: 22 | AA3: 23 | AB3: 24 | AC3: 25 | AD3: 26 | AE3: 27 | AF3: 28 | AG3: 29 | AH3: 30 | AI3: 31 | AJ3: 32 | AK3: 33 | AL3: 34 | AM3: 35 | AN3: 36 | AO3: 37
E4: 2021.12 | F4: 2021.12A | G4: 2022.03 | H4: 2022.06 | I4: 2022.09 | J4: 2022.12 | K4: 2022.12A | L4: 2023.03 | M4: 2023.06 | N4: 2023.09 | O4: 2023.12 | P4: 2023.12A | Q4: 2024.03 | R4: 2024.06 | S4: 2024.09 | T4: 2024.12 | U4: 2024.12A | V4: 2025.03 | W4: 2025.06 | X4: 2025.09 | Y4: 2025.12 | Z4: 2025.12A | AA4: 2026.03 | AB4: 2026.06 | AC4: 2026.09 | AD4: 2026.12 | AE4: 2026.12A | AF4: 2027.03 | AG4: 2027.06 | AH4: 2027.09 | AI4: 2027.12 | AJ4: 2027.12A | AK4: 2028.03 | AL4: 2028.06 | AM4: 2028.09 | AN4: 2028.12 | AO4: 2028.12A
B5: 1. FX | C5: 이름: 환율
A6: USDKRW_avg | C6: 원/달러(평균) | E6: 1183.5 | F6: 1145.51 | G6: 1205.78 | H6: 1262.09 | I6: 1341.93 | J6: 1360.12 | K6: 1292.98 | L6: 1276.95 | M6: 1315.69 | N6: 1313.62 | O6: 1322.01 | P6: 1306.85 | Q6: 1330.14 | R6: 1371.28 | S6: 1356.22 | T6: 1396.3 | U6: 1363.53 | V6: 1452.28 | W6: 1398.52 | X6: 1386.95 | Y6: 1449.19 | Z6: 1421.52 | AA6: 1466.12 | AB6: 1501.75 | AC6: 1418.75 | AD6: 1342.11 | AE6: 1454.27 | AF6: 1332.1 | AG6: 1332.1 | AH6: 1332.1 | AI6: 1332.1 | AK6: 1332.1 | AL6: 1332.1 | AM6: 1332.1 | AN6: 1332.1
A7: USDKRW_end | C7: 원/달러(기말) | E7: 1188.75 | F7: 1188.75 | G7: 1213.74 | H7: 1301.24 | I7: 1436.9 | J7: 1260.16 | K7: 1260.16 | L7: 1305.99 | M7: 1321.44 | N7: 1345.35 | O7: 1297.43 | P7: 1297.43 | Q7: 1349.25 | R7: 1377.73 | S7: 1312.17 | T7: 1474.78 | U7: 1474.78 | V7: 1474.54 | W7: 1355.13 | X7: 1403.67 | Y7: 1444.2 | Z7: 1444.2 | AA7: 1524.8 | AB7: 1550.89 | AC7: 1355.4 | AD7: 1332.1 | AE7: 1332.1 | AF7: 1332.1 | AG7: 1332.1 | AH7: 1332.1 | AI7: 1332.1 | AK7: 1332.1 | AL7: 1332.1 | AM7: 1332.1 | AN7: 1332.1
A8: JPY100KRW_avg | C8: 원/100Y(평균) | E8: 1041.02 | F8: 1042.74 | G8: 1036.79 | H8: 972.23 | I8: 970.61 | J8: 961.03 | K8: 985.1 | L8: 964.89 | M8: 957.36 | N8: 909 | O8: 893.22 | P8: 931.11 | Q8: 896.29 | R8: 880.14 | S8: 909.35 | T8: 917.25 | U8: 900.92 | V8: 952.59 | W8: 967.92 | X8: 940.32 | Y8: 940.77 | Z8: 950.17 | AA8: 934.39 | AB8: 942.16 | AC8: 890.41 | AD8: 848.59 | AE8: 917.39 | AF8: 842.99 | AG8: 842.99 | AH8: 842.99 | AI8: 842.99 | AK8: 842.99 | AL8: 842.99 | AM8: 842.99 | AN8: 842.99
A9: JPY100KRW_end | C9: 원/100Y(기말) | E9: 1032.62 | F9: 1032.62 | G9: 996.83 | H9: 954.9 | I9: 993.29 | J9: 955.54 | K9: 955.54 | L9: 980.62 | M9: 913.67 | N9: 901.47 | O9: 917.04 | P9: 917.04 | Q9: 892.42 | R9: 857.76 | S9: 919.21 | T9: 939.65 | U9: 939.65 | V9: 986.84 | W9: 938.85 | X9: 948.49 | Y9: 921.81 | Z9: 921.81 | AA9: 955.99 | AB9: 954.75 | AC9: 863.31 | AD9: 842.99 | AE9: 842.99 | AF9: 842.99 | AG9: 842.99 | AH9: 842.99 | AI9: 842.99 | AK9: 842.99 | AL9: 842.99 | AM9: 842.99 | AN9: 842.99
A10: EURKRW_avg | C10: W/Euro(평균) | E10: 1353.32 | F10: 1354.06 | G10: 1352.29 | H10: 1343.31 | I10: 1350.63 | J10: 1386.07 | K10: 1358.07 | L10: 1369.93 | M10: 1432.41 | N10: 1429.41 | O10: 1420.91 | P10: 1412.88 | Q10: 1444.21 | R10: 1476.42 | S10: 1489.3 | T10: 1490.78 | U10: 1475.4 | V10: 1528.33 | W10: 1585.13 | X10: 1620.04 | Y10: 1686.02 | Z10: 1605.45 | AA10: 1715.47 | AB10: 1746.09 | AC10: 1631.97 | AD10: 1505.3 | AE10: 1685.25 | AF10: 1499.02 | AG10: 1499.02 | AH10: 1499.02 | AI10: 1499.02 | AK10: 1499.02 | AL10: 1499.02 | AM10: 1499.02 | AN10: 1499.02
A11: EURKRW_end | C11: W/Euro(기말) | E11: 1346.38 | F11: 1346.38 | G11: 1347.37 | H11: 1351.6 | I11: 1400.62 | J11: 1344.08 | K11: 1344.08 | L11: 1420.26 | M11: 1435.88 | N11: 1425.26 | O11: 1433.66 | P11: 1433.66 | Q11: 1458.68 | R11: 1474.86 | S11: 1469.1 | T11: 1532.14 | U11: 1532.14 | V11: 1594.72 | W11: 1588.22 | X11: 1648.04 | Y11: 1696.94 | Z11: 1696.94 | AA11: 1753.21 | AB11: 1767.09 | AC11: 1539.06 | AD11: 1499.02 | AE11: 1499.02 | AF11: 1499.02 | AG11: 1499.02 | AH11: 1499.02 | AI11: 1499.02 | AK11: 1499.02 | AL11: 1499.02 | AM11: 1499.02 | AN11: 1499.02
A12: CNYKRW_avg | C12: 원/중국원(평균) | E12: 185.14 | F12: 177.65 | G12: 189.93 | H12: 190.76 | I12: 195.79 | J12: 191.09 | K12: 191.93 | L12: 186.59 | M12: 187.45 | N12: 181.28 | O12: 182.86 | P12: 184.52 | Q12: 185.04 | R12: 189.35 | S12: 189.24 | T12: 194.24 | U12: 189.49 | V12: 199.63 | W12: 193.41 | X12: 193.79 | Y12: 204.38 | Z12: 197.8 | AA12: 211.75 | AB12: 220.8 | AC12: 210.43 | AD12: 200.38 | AE12: 213.41 | AF12: 199.23 | AG12: 199.23 | AH12: 199.23 | AI12: 199.23 | AK12: 199.23 | AL12: 199.23 | AM12: 199.23 | AN12: 199.23
A13: CNYKRW_end | C13: 원/중국원(기말) | E13: 187.13 | F13: 187.13 | G13: 191.38 | H13: 194.13 | I13: 201.92 | J13: 182.67 | K13: 182.67 | L13: 189.97 | M13: 181.8 | N13: 184.26 | O13: 182.61 | P13: 182.61 | Q13: 186.66 | R13: 189.7 | S13: 187.12 | T13: 202.04 | U13: 202.04 | V13: 203.3 | W13: 189.14 | X13: 197.16 | Y13: 206.28 | Z13: 206.28 | AA13: 220.97 | AB13: 228.56 | AC13: 202.16 | AD13: 199.23 | AE13: 199.23 | AF13: 199.23 | AG13: 199.23 | AH13: 199.23 | AI13: 199.23 | AK13: 199.23 | AL13: 199.23 | AM13: 199.23 | AN13: 199.23
B14: 1b. 종가
A15: price_close_end | C15: 종가(기말) | E15: 20400 | G15: 20450 | H15: 19400 | I15: 14250 | J15: 15400 | L15: 17000 | M15: 18110 | N15: 16430 | O15: 15900 | Q15: 17220 | R15: 20100 | S15: 17910 | T15: 17550 | V15: 23450 | W15: 68400 | X15: 62700 | Y15: 75300 | AA15: 91800 | AB15: 86800 | AC15: 81900 | AD15: 66600
A16: price_high | C16: 종가(최고) | E16: 26687 | G16: 23900 | H16: 22200 | I16: 23050 | J16: 17500 | L16: 18370 | M16: 20200 | N16: 19180 | O16: 16380 | Q16: 18920 | R16: 22000 | S16: 25000 | T16: 22800 | V16: 30900 | W16: 72200 | X16: 70600 | Y16: 97400 | AA16: 112100 | AB16: 139200 | AC16: 94400 | AD16: 84300
A17: price_low | C17: 종가(최저) | E17: 17421 | G17: 15200 | H17: 16000 | I17: 13950 | J17: 12450 | L17: 14750 | M17: 15060 | N17: 15940 | O17: 13350 | Q17: 14300 | R17: 14320 | S17: 15150 | T17: 16910 | V17: 17600 | W17: 19960 | X17: 51100 | Y17: 62700 | AA17: 74600 | AB17: 79300 | AC17: 57000 | AD17: 61300
A18: price_avg | C18: 종가(평균) | E18: 21812.5 | G18: 19779.7 | H18: 19798.4 | I18: 18645.2 | J18: 15288.7 | L18: 16365 | M18: 17236.7 | N18: 17161.6 | O18: 14864.7 | Q18: 15996.9 | R18: 18054.8 | S18: 18635 | T18: 19717.7 | V18: 24437.1 | W18: 38210 | X18: 63169.2 | Y18: 78511.9 | AA18: 95247.5 | AB18: 106186.9 | AC18: 78645.2 | AD18: 73100
B20: 2. 추정 드라이버 | C20: 실적 열 = subQ 실현값(수식), 추정 열 = 가정(노란 = 모델값 역산, 연녹 = 3절 스칼라 참조)
A21: drv:매출액 | B21: yoy | C21: 매출액 YoY | J21: =IFERROR(subQ!J5/subQ!E5-1,"") | L21: =IFERROR(subQ!L5/subQ!G5-1,"") | M21: =IFERROR(subQ!M5/subQ!H5-1,"") | N21: =IFERROR(subQ!N5/subQ!I5-1,"") | O21: =IFERROR(subQ!O5/subQ!J5-1,"") | Q21: =IFERROR(subQ!Q5/subQ!L5-1,"") | R21: =IFERROR(subQ!R5/subQ!M5-1,"") | S21: =IFERROR(subQ!S5/subQ!N5-1,"") | T21: =IFERROR(subQ!T5/subQ!O5-1,"") | V21: =IFERROR(subQ!V5/subQ!Q5-1,"") | W21: =IFERROR(subQ!W5/subQ!R5-1,"") | X21: =IFERROR(subQ!X5/subQ!S5-1,"") | Y21: =IFERROR(subQ!Y5/subQ!T5-1,"") | AA21: =IFERROR(subQ!AA5/subQ!V5-1,"") | AB21: =IFERROR(subQ!AB5/subQ!W5-1,"") | AC21: 0.087344956 | AD21: 0.087344861 | AF21: 0.087344906 | AG21: 0.087344925 | AH21: 0.04367239 | AI21: 0.043672523 | AK21: 0.043672591 | AL21: 0.043672443 | AM21: 0.021836271 | AN21: 0.021836178
A22: drv:판관비 | B22: ratio | C22: 판관비율(/매출) | E22: =IFERROR(subQ!E8/subQ!E5,"") | F22: =IFERROR(subQ!F8/subQ!F5,"") | G22: =IFERROR(subQ!G8/subQ!G5,"") | H22: =IFERROR(subQ!H8/subQ!H5,"") | I22: =IFERROR(subQ!I8/subQ!I5,"") | J22: =IFERROR(subQ!J8/subQ!J5,"") | K22: =IFERROR(subQ!K8/subQ!K5,"") | L22: =IFERROR(subQ!L8/subQ!L5,"") | ... AB22: =IFERROR(subQ!AB8/subQ!AB5,"") | AC22: =$D$53 | AD22: =$D$53 | AE22: =IFERROR(subQ!AE8/subQ!AE5,"") | AF22: =$D$53 | AG22: =$D$53 | AH22: =$D$53 | AI22: =$D$53 | AJ22: =IFERROR(subQ!AJ8/subQ!AJ5,"") | AK22: =$D$53 | AL22: =$D$53 | AM22: =$D$53 | AN22: =$D$53 | AO22: =IFERROR(subQ!AO8/subQ!AO5,"")
A23: drv:영업이익 | B23: ratio | C23: 영업이익률(OPM) | E23: =IFERROR(subQ!E9/subQ!E5,"") | F23: =IFERROR(subQ!F9/subQ!F5,"") | G23: =IFERROR(subQ!G9/subQ!G5,"") | H23: =IFERROR(subQ!H9/subQ!H5,"") | I23: =IFERROR(subQ!I9/subQ!I5,"") | J23: =IFERROR(subQ!J9/subQ!J5,"") | K23: =IFERROR(subQ!K9/subQ!K5,"") | L23: =IFERROR(subQ!L9/subQ!L5,"") | ... AB23: =IFERROR(subQ!AB9/subQ!AB5,"") | AC23: 0.047416869 | AD23: 0.047416926 | AE23: =IFERROR(subQ!AE9/subQ!AE5,"") | AF23: 0.047416776 | AG23: 0.047416874 | AH23: 0.047416797 | AI23: 0.047416914 | AJ23: =IFERROR(subQ!AJ9/subQ!AJ5,"") | AK23: 0.04741683 | AL23: 0.047416915 | AM23: 0.047416918 | AN23: 0.047416831 | AO23: =IFERROR(subQ!AO9/subQ!AO5,"")
A24: drv:외환손익 | B24: abs | C24: 외환손익 (가정, 억원) | E24: =subQ!E13 | F24: =subQ!F13 | G24: =subQ!G13 | H24: =subQ!H13 | I24: =subQ!I13 | J24: =subQ!J13 | K24: =subQ!K13 | L24: =subQ!L13 | ... AB24: =subQ!AB13 | AC24: 0 | AD24: 0 | AE24: =subQ!AE13 | AF24: 0 | AG24: 0 | AH24: 0 | AI24: 0 | AJ24: =subQ!AJ13 | AK24: 0 | AL24: 0 | AM24: 0 | AN24: 0 | AO24: =subQ!AO13
A25: drv:파생상품손익 | B25: abs | C25: 파생상품손익 (가정, 억원) | E25: =subQ!E14 | F25: =subQ!F14 | G25: =subQ!G14 | H25: =subQ!H14 | I25: =subQ!I14 | J25: =subQ!J14 | K25: =subQ!K14 | L25: =subQ!L14 | ... AB25: =subQ!AB14 | AC25: 0 | AD25: 0 | AE25: =subQ!AE14 | AF25: 0 | AG25: 0 | AH25: 0 | AI25: 0 | AJ25: =subQ!AJ14 | AK25: 0 | AL25: 0 | AM25: 0 | AN25: 0 | AO25: =subQ!AO14
A26: drv:기타금융손익 | B26: abs | C26: 기타금융손익 (가정, 억원) | E26: =subQ!E15 | F26: =subQ!F15 | G26: =subQ!G15 | H26: =subQ!H15 | I26: =subQ!I15 | J26: =subQ!J15 | K26: =subQ!K15 | L26: =subQ!L15 | ... AB26: =subQ!AB15 | AC26: 0 | AD26: 0 | AE26: =subQ!AE15 | AF26: 0 | AG26: 0 | AH26: 0 | AI26: 0 | AJ26: =subQ!AJ15 | AK26: 0 | AL26: 0 | AM26: 0 | AN26: 0 | AO26: =subQ!AO15
A27: drv:기타영업외손익 | B27: abs | C27: 기타영업외손익 (가정, 억원) | E27: =subQ!E16 | F27: =subQ!F16 | G27: =subQ!G16 | H27: =subQ!H16 | I27: =subQ!I16 | J27: =subQ!J16 | K27: =subQ!K16 | L27: =subQ!L16 | ... AB27: =subQ!AB16 | AC27: 0 | AD27: 0 | AE27: =subQ!AE16 | AF27: 0 | AG27: 0 | AH27: 0 | AI27: 0 | AJ27: =subQ!AJ16 | AK27: 0 | AL27: 0 | AM27: 0 | AN27: 0 | AO27: =subQ!AO16
A28: drv:지분법손익 | B28: abs | C28: 지분법손익 (가정, 억원) | E28: =subQ!E17 | F28: =subQ!F17 | G28: =subQ!G17 | H28: =subQ!H17 | I28: =subQ!I17 | J28: =subQ!J17 | K28: =subQ!K17 | L28: =subQ!L17 | ... AB28: =subQ!AB17 | AC28: 143.3 | AD28: 143.3 | AE28: =subQ!AE17 | AF28: 143.3 | AG28: 143.3 | AH28: 143.3 | AI28: 143.3 | AJ28: =subQ!AJ17 | AK28: 143.3 | AL28: 143.3 | AM28: 143.3 | AN28: 143.3 | AO28: =subQ!AO17
A29: drv:법인세비용 | B29: tax | C29: 법인세율(/세전) — 법인세 = MAX(세전,0) × 세율 | E29: =IFERROR(subQ!E19/subQ!E18,"") | F29: =IFERROR(subQ!F19/subQ!F18,"") | G29: =IFERROR(subQ!G19/subQ!G18,"") | H29: =IFERROR(subQ!H19/subQ!H18,"") | I29: =IFERROR(subQ!I19/subQ!I18,"") | J29: =IFERROR(subQ!J19/subQ!J18,"") | K29: =IFERROR(subQ!K19/subQ!K18,"") | L29: =IFERROR(subQ!L19/subQ!L18,"") | ... AB29: =IFERROR(subQ!AB19/subQ!AB18,"") | AC29: =$D$52 | AD29: =$D$52 | AE29: =IFERROR(subQ!AE19/subQ!AE18,"") | AF29: =$D$52 | AG29: =$D$52 | AH29: =$D$52 | AI29: =$D$52 | AJ29: =IFERROR(subQ!AJ19/subQ!AJ18,"") | AK29: =$D$52 | AL29: =$D$52 | AM29: =$D$52 | AN29: =$D$52 | AO29: =IFERROR(subQ!AO19/subQ!AO18,"")
A30: drv:지배주주순이익 | B30: ratio | C30: 지배주주 비중(/당기순이익) | E30: =IFERROR(subQ!E21/subQ!E20,"") | F30: =IFERROR(subQ!F21/subQ!F20,"") | G30: =IFERROR(subQ!G21/subQ!G20,"") | H30: =IFERROR(subQ!H21/subQ!H20,"") | I30: =IFERROR(subQ!I21/subQ!I20,"") | J30: =IFERROR(subQ!J21/subQ!J20,"") | K30: =IFERROR(subQ!K21/subQ!K20,"") | L30: =IFERROR(subQ!L21/subQ!L20,"") | ... AB30: =IFERROR(subQ!AB21/subQ!AB20,"") | AC30: =$D$54 | AD30: =$D$54 | AE30: =IFERROR(subQ!AE21/subQ!AE20,"") | AF30: =$D$54 | AG30: =$D$54 | AH30: =$D$54 | AI30: =$D$54 | AJ30: =IFERROR(subQ!AJ21/subQ!AJ20,"") | AK30: =$D$54 | AL30: =$D$54 | AM30: =$D$54 | AN30: =$D$54 | AO30: =IFERROR(subQ!AO21/subQ!AO20,"")
A31: drv:중단사업이익 | B31: abs | C31: 중단사업이익 (가정, 억원) | E31: =subQ!E22 | F31: =subQ!F22 | G31: =subQ!G22 | H31: =subQ!H22 | I31: =subQ!I22 | J31: =subQ!J22 | K31: =subQ!K22 | L31: =subQ!L22 | ... AB31: =subQ!AB22 | AE31: =subQ!AE22 | AJ31: =subQ!AJ22 | AO31: =subQ!AO22
A32: drv:부채총계 | B32: qoq | C32: 부채총계 QoQ | G32: =IFERROR(subQ!G24/subQ!E24-1,"") | H32: =IFERROR(subQ!H24/subQ!G24-1,"") | I32: =IFERROR(subQ!I24/subQ!H24-1,"") | J32: =IFERROR(subQ!J24/subQ!I24-1,"") | L32: =IFERROR(subQ!L24/subQ!J24-1,"") | M32: =IFERROR(subQ!M24/subQ!L24-1,"") | N32: =IFERROR(subQ!N24/subQ!M24-1,"") | O32: =IFERROR(subQ!O24/subQ!N24-1,"") | Q32: =IFERROR(subQ!Q24/subQ!O24-1,"") | R32: =IFERROR(subQ!R24/subQ!Q24-1,"") | S32: =IFERROR(subQ!S24/subQ!R24-1,"") | T32: =IFERROR(subQ!T24/subQ!S24-1,"") | V32: =IFERROR(subQ!V24/subQ!T24-1,"") | W32: =IFERROR(subQ!W24/subQ!V24-1,"") | X32: =IFERROR(subQ!X24/subQ!W24-1,"") | Y32: =IFERROR(subQ!Y24/subQ!X24-1,"") | AA32: =IFERROR(subQ!AA24/subQ!Y24-1,"") | AB32: =IFERROR(subQ!AB24/subQ!AA24-1,"") | AC32: 0 | AD32: 0 | AF32: 0 | AG32: 0 | AH32: 0 | AI32: 0 | AK32: 0 | AL32: 0 | AM32: 0 | AN32: 0
A33: drv:자본총계 | B33: roll | C33: 자본총계 기타변동(배당 등, 억원) | G33: =IFERROR(subQ!E25+subQ!G20-subQ!G25,"") | H33: =IFERROR(subQ!G25+subQ!H20-subQ!H25,"") | I33: =IFERROR(subQ!H25+subQ!I20-subQ!I25,"") | J33: =IFERROR(subQ!I25+subQ!J20-subQ!J25,"") | L33: =IFERROR(subQ!J25+subQ!L20-subQ!L25,"") | M33: =IFERROR(subQ!L25+subQ!M20-subQ!M25,"") | N33: =IFERROR(subQ!M25+subQ!N20-subQ!N25,"") | O33: =IFERROR(subQ!N25+subQ!O20-subQ!O25,"") | Q33: =IFERROR(subQ!O25+subQ!Q20-subQ!Q25,"") | R33: =IFERROR(subQ!Q25+subQ!R20-subQ!R25,"") | S33: =IFERROR(subQ!R25+subQ!S20-subQ!S25,"") | T33: =IFERROR(subQ!S25+subQ!T20-subQ!T25,"") | V33: =IFERROR(subQ!T25+subQ!V20-subQ!V25,"") | W33: =IFERROR(subQ!V25+subQ!W20-subQ!W25,"") | X33: =IFERROR(subQ!W25+subQ!X20-subQ!X25,"") | Y33: =IFERROR(subQ!X25+subQ!Y20-subQ!Y25,"") | AA33: =IFERROR(subQ!Y25+subQ!AA20-subQ!AA25,"") | AB33: =IFERROR(subQ!AA25+subQ!AB20-subQ!AB25,"") | AC33: 0.001784146 | AD33: 0.002733647 | AF33: 0.000334227 | AG33: 0.006426239 | AH33: -0.005099701 | AI33: 0.006238169 | AK33: 0.004711386 | AL33: 0.002967662 | AM33: 0.004180576 | AN33: -0.003043825
A34: drv:지배주주지분 | B34: roll | C34: 지배주주지분 기타변동(배당 등, 억원) | G34: =IFERROR(subQ!E26+subQ!G21-subQ!G26,"") | H34: =IFERROR(subQ!G26+subQ!H21-subQ!H26,"") | I34: =IFERROR(subQ!H26+subQ!I21-subQ!I26,"") | J34: =IFERROR(subQ!I26+subQ!J21-subQ!J26,"") | L34: =IFERROR(subQ!J26+subQ!L21-subQ!L26,"") | M34: =IFERROR(subQ!L26+subQ!M21-subQ!M26,"") | N34: =IFERROR(subQ!M26+subQ!N21-subQ!N26,"") | O34: =IFERROR(subQ!N26+subQ!O21-subQ!O26,"") | Q34: =IFERROR(subQ!O26+subQ!Q21-subQ!Q26,"") | R34: =IFERROR(subQ!Q26+subQ!R21-subQ!R26,"") | S34: =IFERROR(subQ!R26+subQ!S21-subQ!S26,"") | T34: =IFERROR(subQ!S26+subQ!T21-subQ!T26,"") | V34: =IFERROR(subQ!T26+subQ!V21-subQ!V26,"") | W34: =IFERROR(subQ!V26+subQ!W21-subQ!W26,"") | X34: =IFERROR(subQ!W26+subQ!X21-subQ!X26,"") | Y34: =IFERROR(subQ!X26+subQ!Y21-subQ!Y26,"") | AA34: =IFERROR(subQ!Y26+subQ!AA21-subQ!AA26,"") | AB34: =IFERROR(subQ!AA26+subQ!AB21-subQ!AB26,"")
A35: drv:총차입금 | B35: qoq | C35: 총차입금 QoQ | G35: =IFERROR(subQ!G27/subQ!E27-1,"") | H35: =IFERROR(subQ!H27/subQ!G27-1,"") | I35: =IFERROR(subQ!I27/subQ!H27-1,"") | J35: =IFERROR(subQ!J27/subQ!I27-1,"") | L35: =IFERROR(subQ!L27/subQ!J27-1,"") | M35: =IFERROR(subQ!M27/subQ!L27-1,"") | N35: =IFERROR(subQ!N27/subQ!M27-1,"") | O35: =IFERROR(subQ!O27/subQ!N27-1,"") | Q35: =IFERROR(subQ!Q27/subQ!O27-1,"") | R35: =IFERROR(subQ!R27/subQ!Q27-1,"") | S35: =IFERROR(subQ!S27/subQ!R27-1,"") | T35: =IFERROR(subQ!T27/subQ!S27-1,"") | V35: =IFERROR(subQ!V27/subQ!T27-1,"") | W35: =IFERROR(subQ!W27/subQ!V27-1,"") | X35: =IFERROR(subQ!X27/subQ!W27-1,"") | Y35: =IFERROR(subQ!Y27/subQ!X27-1,"") | AA35: =IFERROR(subQ!AA27/subQ!Y27-1,"") | AB35: =IFERROR(subQ!AB27/subQ!AA27-1,"") | AC35: 0 | AD35: 0 | AF35: 0 | AG35: 0 | AH35: 0 | AI35: 0 | AK35: 0 | AL35: 0 | AM35: 0 | AN35: 0
A36: drv:순차입금 | B36: qoq | C36: 순차입금 QoQ | G36: =IFERROR(subQ!G28/subQ!E28-1,"") | H36: =IFERROR(subQ!H28/subQ!G28-1,"") | I36: =IFERROR(subQ!I28/subQ!H28-1,"") | J36: =IFERROR(subQ!J28/subQ!I28-1,"") | L36: =IFERROR(subQ!L28/subQ!J28-1,"") | M36: =IFERROR(subQ!M28/subQ!L28-1,"") | N36: =IFERROR(subQ!N28/subQ!M28-1,"") | O36: =IFERROR(subQ!O28/subQ!N28-1,"") | Q36: =IFERROR(subQ!Q28/subQ!O28-1,"") | R36: =IFERROR(subQ!R28/subQ!Q28-1,"") | S36: =IFERROR(subQ!S28/subQ!R28-1,"") | T36: =IFERROR(subQ!T28/subQ!S28-1,"") | V36: =IFERROR(subQ!V28/subQ!T28-1,"") | W36: =IFERROR(subQ!W28/subQ!V28-1,"") | X36: =IFERROR(subQ!X28/subQ!W28-1,"") | Y36: =IFERROR(subQ!Y28/subQ!X28-1,"") | AA36: =IFERROR(subQ!AA28/subQ!Y28-1,"") | AB36: =IFERROR(subQ!AB28/subQ!AA28-1,"") | AC36: -0.029576887 | AD36: -0.04114798 | AF36: -0.036400565 | AG36: -0.043344324 | AH36: -0.037310784 | AI36: -0.05184946 | AK36: -0.046612876 | AL36: -0.055880439 | AM36: -0.047727226 | AN36: -0.066587778
A37: drv:이자발생자산 | B37: qoq | C37: 이자발생자산 QoQ | G37: =IFERROR(subQ!G29/subQ!E29-1,"") | H37: =IFERROR(subQ!H29/subQ!G29-1,"") | I37: =IFERROR(subQ!I29/subQ!H29-1,"") | J37: =IFERROR(subQ!J29/subQ!I29-1,"") | L37: =IFERROR(subQ!L29/subQ!J29-1,"") | M37: =IFERROR(subQ!M29/subQ!L29-1,"") | N37: =IFERROR(subQ!N29/subQ!M29-1,"") | O37: =IFERROR(subQ!O29/subQ!N29-1,"") | Q37: =IFERROR(subQ!Q29/subQ!O29-1,"") | R37: =IFERROR(subQ!R29/subQ!Q29-1,"") | S37: =IFERROR(subQ!S29/subQ!R29-1,"") | T37: =IFERROR(subQ!T29/subQ!S29-1,"") | V37: =IFERROR(subQ!V29/subQ!T29-1,"") | W37: =IFERROR(subQ!W29/subQ!V29-1,"") | X37: =IFERROR(subQ!X29/subQ!W29-1,"") | Y37: =IFERROR(subQ!Y29/subQ!X29-1,"") | AA37: =IFERROR(subQ!AA29/subQ!Y29-1,"") | AB37: =IFERROR(subQ!AB29/subQ!AA29-1,"") | AC37: 0.032228 | AD37: 0.042151681 | AF37: 0.034307981 | AG37: 0.03805975 | AH37: 0.03019266 | AI37: 0.03920838 | AK37: 0.032159938 | AL37: 0.035611593 | AM37: 0.027728596 | AN37: 0.035845871
A38: drv:현금및현금성자산 | B38: qoq | C38: 현금및현금성자산 QoQ | G38: =IFERROR(subQ!G30/subQ!E30-1,"") | H38: =IFERROR(subQ!H30/subQ!G30-1,"") | I38: =IFERROR(subQ!I30/subQ!H30-1,"") | J38: =IFERROR(subQ!J30/subQ!I30-1,"") | L38: =IFERROR(subQ!L30/subQ!J30-1,"") | M38: =IFERROR(subQ!M30/subQ!L30-1,"") | N38: =IFERROR(subQ!N30/subQ!M30-1,"") | O38: =IFERROR(subQ!O30/subQ!N30-1,"") | Q38: =IFERROR(subQ!Q30/subQ!O30-1,"") | R38: =IFERROR(subQ!R30/subQ!Q30-1,"") | S38: =IFERROR(subQ!S30/subQ!R30-1,"") | T38: =IFERROR(subQ!T30/subQ!S30-1,"") | V38: =IFERROR(subQ!V30/subQ!T30-1,"") | W38: =IFERROR(subQ!W30/subQ!V30-1,"") | X38: =IFERROR(subQ!X30/subQ!W30-1,"") | Y38: =IFERROR(subQ!Y30/subQ!X30-1,"") | AA38: =IFERROR(subQ!AA30/subQ!Y30-1,"") | AB38: =IFERROR(subQ!AB30/subQ!AA30-1,"")
A39: drv:CAPEX | B39: yoy | C39: CAPEX YoY | J39: =IFERROR(subQ!J31/subQ!E31-1,"") | L39: =IFERROR(subQ!L31/subQ!G31-1,"") | M39: =IFERROR(subQ!M31/subQ!H31-1,"") | N39: =IFERROR(subQ!N31/subQ!I31-1,"") | O39: =IFERROR(subQ!O31/subQ!J31-1,"") | Q39: =IFERROR(subQ!Q31/subQ!L31-1,"") | R39: =IFERROR(subQ!R31/subQ!M31-1,"") | S39: =IFERROR(subQ!S31/subQ!N31-1,"") | T39: =IFERROR(subQ!T31/subQ!O31-1,"") | V39: =IFERROR(subQ!V31/subQ!Q31-1,"") | W39: =IFERROR(subQ!W31/subQ!R31-1,"") | X39: =IFERROR(subQ!X31/subQ!S31-1,"") | Y39: =IFERROR(subQ!Y31/subQ!T31-1,"") | AA39: =IFERROR(subQ!AA31/subQ!V31-1,"") | AB39: =IFERROR(subQ!AB31/subQ!W31-1,"") | AC39: -0.22409699 | AD39: -0.050420653 | AF39: 0.056069206 | AG39: 0.74366506 | AH39: 0 | AI39: 0 | AK39: 0 | AL39: 0 | AM39: 0 | AN39: 0
A40: drv:영업활동현금흐름 | B40: yoy | C40: 영업활동현금흐름 YoY | J40: =IFERROR(subQ!J32/subQ!E32-1,"") | L40: =IFERROR(subQ!L32/subQ!G32-1,"") | M40: =IFERROR(subQ!M32/subQ!H32-1,"") | N40: =IFERROR(subQ!N32/subQ!I32-1,"") | O40: =IFERROR(subQ!O32/subQ!J32-1,"") | Q40: =IFERROR(subQ!Q32/subQ!L32-1,"") | R40: =IFERROR(subQ!R32/subQ!M32-1,"") | S40: =IFERROR(subQ!S32/subQ!N32-1,"") | T40: =IFERROR(subQ!T32/subQ!O32-1,"") | V40: =IFERROR(subQ!V32/subQ!Q32-1,"") | W40: =IFERROR(subQ!W32/subQ!R32-1,"") | X40: =IFERROR(subQ!X32/subQ!S32-1,"") | Y40: =IFERROR(subQ!Y32/subQ!T32-1,"") | AA40: =IFERROR(subQ!AA32/subQ!V32-1,"") | AB40: =IFERROR(subQ!AB32/subQ!W32-1,"")
A41: drv:주식수 | B41: qoq | C41: 주식수 QoQ | G41: =IFERROR(subQ!G33/subQ!E33-1,"") | H41: =IFERROR(subQ!H33/subQ!G33-1,"") | I41: =IFERROR(subQ!I33/subQ!H33-1,"") | J41: =IFERROR(subQ!J33/subQ!I33-1,"") | L41: =IFERROR(subQ!L33/subQ!J33-1,"") | M41: =IFERROR(subQ!M33/subQ!L33-1,"") | N41: =IFERROR(subQ!N33/subQ!M33-1,"") | O41: =IFERROR(subQ!O33/subQ!N33-1,"") | Q41: =IFERROR(subQ!Q33/subQ!O33-1,"") | R41: =IFERROR(subQ!R33/subQ!Q33-1,"") | S41: =IFERROR(subQ!S33/subQ!R33-1,"") | T41: =IFERROR(subQ!T33/subQ!S33-1,"") | V41: =IFERROR(subQ!V33/subQ!T33-1,"") | W41: =IFERROR(subQ!W33/subQ!V33-1,"") | X41: =IFERROR(subQ!X33/subQ!W33-1,"") | Y41: =IFERROR(subQ!Y33/subQ!X33-1,"") | AA41: =IFERROR(subQ!AA33/subQ!Y33-1,"") | AB41: =IFERROR(subQ!AB33/subQ!AA33-1,"") | AC41: 0 | AD41: 0 | AF41: 0 | AG41: 0 | AH41: 0 | AI41: 0 | AK41: 0 | AL41: 0 | AM41: 0 | AN41: 0
...

Sheet BS연결
B1: (백만원) | C1: 이름: BS연결H | E1: 4Q21 | F1: 2021 | G1: 1Q22 | H1: 2Q22 | I1: 3Q22 | J1: 4Q22 | K1: 2022 | L1: 1Q23 | M1: 2Q23 | N1: 3Q23 | O1: 4Q23 | P1: 2023 | Q1: 1Q24 | R1: 2Q24 | S1: 3Q24 | T1: 4Q24 | U1: 2024 | V1: 1Q25 | W1: 2Q25 | X1: 3Q25 | Y1: 4Q25 | Z1: 2025 | AA1: 1Q26 | AB1: 2Q26 | AC1: 3Q26 | AD1: 4Q26 | AE1: 2026 | AF1: 1Q27 | AG1: 2Q27 | AH1: 3Q27 | AI1: 4Q27 | AJ1: 2027 | AK1: 1Q28 | AL1: 2Q28 | AM1: 3Q28 | AN1: 4Q28 | AO1: 2028
B2: 연결 | D2: fin json(kship_fin.py)
B3: 두산에너빌리티(연) | C3: UPDATE: 26-10-19 | E3: 1 | F3: 2 | G3: 3 | H3: 4 | I3: 5 | J3: 6 | K3: 7 | L3: 8 | M3: 9 | N3: 10 | O3: 11 | P3: 12 | Q3: 13 | R3: 14 | S3: 15 | T3: 16 | U3: 17 | V3: 18 | W3: 19 | X3: 20 | Y3: 21 | Z3: 22 | AA3: 23 | AB3: 24 | AC3: 25 | AD3: 26 | AE3: 27 | AF3: 28 | AG3: 29 | AH3: 30 | AI3: 31 | AJ3: 32 | AK3: 33 | AL3: 34 | AM3: 35 | AN3: 36 | AO3: 37
B4: Account Code | C4: AccountNAME | E4: 2021.12 | F4: 2021.12A | G4: 2022.03 | H4: 2022.06 | I4: 2022.09 | J4: 2022.12 | K4: 2022.12A | L4: 2023.03 | M4: 2023.06 | N4: 2023.09 | O4: 2023.12 | P4: 2023.12A | Q4: 2024.03 | R4: 2024.06 | S4: 2024.09 | T4: 2024.12 | U4: 2024.12A | V4: 2025.03 | W4: 2025.06 | X4: 2025.09 | Y4: 2025.12 | Z4: 2025.12A | AA4: 2026.03 | AB4: 2026.06 | AC4: 2026.09 | AD4: 2026.12 | AE4: 2026.12A | AF4: 2027.03 | AG4: 2027.06 | AH4: 2027.09 | AI4: 2027.12 | AJ4: 2027.12A | AK4: 2028.03 | AL4: 2028.06 | AM4: 2028.09 | AN4: 2028.12 | AO4: 2028.12A
A5: 1 | C5: 유동자산 | E5: 8417624.1 | F5: 8417624.1 | G5: 8671301.2 | H5: 8759163.8 | I5: 8917729 | J5: 8098893.7 | K5: 8098893.7 | L5: 8606257.3 | M5: 10004790 | N5: 9550625.1 | O5: 9641568.2 | P5: 9641568.2 | Q5: 10332148 | R5: 10355218 | S5: 9675110 | T5: 10049022 | U5: 10049022 | V5: 10508418 | W5: 9989814 | X5: 10510110 | Y5: 10771711 | Z5: 10771711 | AA5: 11598608 | AB5: 12466920
A6: 1 | C6: 현금및현금성자산 | E6: 1908604 | F6: 1908604 | G6: 1588251 | H6: 1097413.5 | I6: 1467025 | J6: 1395837.6 | K6: 1395837.6 | L6: 1591895.4 | M6: 2724522.5 | N6: 2270177.3 | O6: 2620187 | P6: 2620187 | Q6: 2920099.8 | R6: 2585775.2 | S6: 2287606.9 | T6: 2898298 | U6: 2898298 | V6: 2609660 | W6: 2274305 | X6: 2404201 | Y6: 3080997 | Z6: 3080997 | AA6: 3090530 | AB6: 2541888
A7: 1 | C7: 단기금융상품 | E7: 519150.03 | F7: 519150.03 | G7: 307771.09 | H7: 146932.43 | I7: 160221.94 | J7: 105780.37 | K7: 105780.37 | L7: 77697.17 | M7: 78595.5 | N7: 102386.09 | O7: 118271.68 | P7: 118271.68 | Q7: 135114.04 | R7: 101225.77 | S7: 100781.04 | T7: 143577 | U7: 143577 | V7: 151970 | W7: 120126 | X7: 111532 | Y7: 107870 | Z7: 107870 | AA7: 108861 | AB7: 276246
A8: 1 | C8: 단기금융자산 | E8: 627154.23 | F8: 627154.23 | G8: 417385.52 | H8: 298653.58 | I8: 381714.59 | J8: 234608.48 | K8: 234608.48 | L8: 212411.69 | M8: 230469.24 | N8: 280614.4 | O8: 202997.84 | P8: 202997.84 | Q8: 252855.81 | R8: 254431.49 | S8: 173669.12 | T8: 285438 | U8: 285438 | V8: 289516 | W8: 170366 | X8: 178197 | Y8: 186426 | Z8: 186426 | AA8: 267810 | AB8: 493666
A9: 1 | C9: 단기투자자산(공정가치) | E9: 197197.2 | F9: 197197.2 | G9: 159405.42 | H9: 64795.04 | I9: 23717.09 | J9: 23775.91 | K9: 23775.91 | L9: 23140.21 | M9: 76853.67 | N9: 77122.42 | O9: 84976.78 | P9: 84976.78 | Q9: 80576.85 | R9: 351.19 | S9: 353.11 | T9: 0 | U9: 0 | V9: 0 | AB9: 75014
A10: 1 | C10: 매출채권및기타채권 | E10: 1128705.6 | F10: 1128705.6 | G10: 1340359.6 | H10: 1669760.6 | I10: 1716473.6 | J10: 1827688 | K10: 1827688 | L10: 1965339 | M10: 2077400.5 | N10: 1973318.3 | O10: 1812811 | P10: 1812811 | Q10: 1982359.7 | R10: 1951260 | S10: 1815503.5 | T10: 1767747 | U10: 1767747 | V10: 1990236 | W10: 2080255 | X10: 2255515 | Y10: 2279608 | Z10: 2279608 | AA10: 2393923 | AB10: 2787121
A11: 1 | C11: 계약자산 | E11: 1632887.6 | F11: 1632887.6 | G11: 1684090.4 | H11: 1470566.8 | I11: 1435796.9 | J11: 1156934.2 | K11: 1156934.2 | L11: 1126730.3 | M11: 1158383.4 | N11: 1307173.3 | O11: 1485570.4 | P11: 1485570.4 | Q11: 1456205 | R11: 1616743.1 | S11: 1586905.5 | T11: 1594506 | U11: 1594506 | V11: 1785013 | W11: 1890548 | X11: 1721431 | Y11: 1713692 | Z11: 1713692 | AA11: 1980736 | AB11: 2455840
A12: 1 | C12: 선급금 | E12: 499609.56 | F12: 499609.56 | G12: 601993.48 | H12: 699551.83 | I12: 667630.39 | J12: 609869.21 | K12: 609869.21 | L12: 582950.49 | M12: 613369.11 | N12: 564148.43 | O12: 508209.82 | P12: 508209.82 | Q12: 454596.04 | R12: 530718.51 | S12: 368887.7 | T12: 360750 | U12: 360750 | V12: 377116 | W12: 372830 | X12: 454337 | Y12: 510532 | Z12: 510532 | AA12: 469171 | AB12: 451081
A13: 1 | C13: 선급금등 | E13: 499609.56 | F13: 499609.56 | G13: 601993.48 | H13: 699551.83 | I13: 667630.39 | J13: 609869.21 | K13: 609869.21 | L13: 582950.49 | M13: 613369.11 | N13: 564148.43 | O13: 508209.82 | P13: 508209.82 | Q13: 454596.04 | R13: 530718.51 | S13: 368887.7 | T13: 360750 | U13: 360750 | V13: 377116 | W13: 372830 | X13: 454337 | Y13: 510532 | Z13: 510532 | AA13: 469171 | AB13: 451081
A14: 1 | C14: 기타유동자산 | E14: 784772.44 | F14: 784772.44 | G14: 915231.71 | H14: 1002515.8 | I14: 995620.14 | J14: 923853.7 | K14: 923853.7 | L14: 951495.08 | M14: 977095.05 | N14: 914075.95 | O14: 831622.46 | P14: 831622.46 | Q14: 790035.44 | R14: 878485.5 | S14: 721963.24 | T14: 729689 | U14: 729689 | V14: 777171 | W14: 773824 | X14: 868614 | Y14: 936872 | Z14: 936872 | AA14: 915781 | AB14: 915499
A15: 1 | C15: 단기대여금 | E15: 62126.81 | F15: 62126.81 | G15: 57901.48 | H15: 61196.01 | I15: 59057.92 | J15: 73900.53 | K15: 73900.53 | L15: 69759.04 | M15: 89995.93 | N15: 102701.8 | O15: 47332.37 | P15: 47332.37 | Q15: 49839.12 | R15: 67987.83 | S15: 24364.08 | T15: 27611 | U15: 27611 | V15: 28796 | W15: 13192 | X15: 12937 | Y15: 12699 | Z15: 12699 | AA15: 28254 | AB15: 38866
A16: 1 | C16: 유동확정계약자산 | E16: 45877.39 | F16: 45877.39 | G16: 51712.95 | H16: 90525.14 | I16: 162434.73 | J16: 54927.58 | K16: 54927.58 | L16: 64955.48 | M16: 61877.81 | N16: 75526.51 | O16: 37393.79 | P16: 37393.79 | Q16: 67902.65 | R16: 85217.89 | S16: 48524 | T16: 114250 | U16: 114250 | V16: 108750 | W16: 37048 | X16: 53728 | Y16: 65857 | Z16: 65857 | AA16: 130695 | AB16: 178554
A17: 1 | C17: 재고자산 | E17: 1788420.2 | F17: 1788420.2 | G17: 2203137 | H17: 2327838.6 | I17: 2660766 | J17: 2459026 | K17: 2459026 | L17: 2653226.1 | M17: 2679270.3 | N17: 2691408.4 | O17: 2539004.4 | P17: 2539004.4 | Q17: 2790504.7 | R17: 3049889.2 | S17: 3071098.3 | T17: 2733933 | U17: 2733933 | V17: 3037819 | W17: 2719745 | X17: 2771060 | Y17: 2544025 | Z17: 2544025 | AA17: 2828194 | AB17: 3144625
A18: 1 | C18: 매각예정비유동자산및처분자산 | E18: 319607.73 | F18: 319607.73 | G18: 329114.59 | H18: 759705.53 | I18: 30644.74 | J18: 4684.77 | K18: 4684.77 | L18: 15238.93 | M18: 14265.03 | N18: 14265.03 | O18: 44183.59 | P18: 44183.59 | Q18: 44188.19 | R18: 1505.81 | S18: 1505.81 | T18: 1506 | U18: 1506 | V18: 1291 | W18: 0 | X18: 264654 | Y18: 0 | Z18: 0 | AA18: 84218
A19: 1 | C19: 비유동자산 | E19: 15302922 | F19: 15302922 | G19: 15474502 | H19: 15512187 | I19: 16253183 | J19: 14950888 | K19: 14950888 | L19: 15392072 | M19: 15302681 | N19: 15389294 | O19: 14999266 | P19: 14999266 | Q19: 15324973 | R19: 15758886 | S19: 15589487 | T19: 16265813 | U19: 16265813 | V19: 16388575 | W19: 16315382 | X19: 16517793 | Y19: 16741512 | Z19: 16741512 | AA19: 17096447 | AB19: 17480822
A20: 1 | C20: 장기금융자산 | E20: 330981.78 | F20: 330981.78 | G20: 341610.11 | H20: 361434.62 | I20: 387940.7 | J20: 352607.3 | K20: 352607.3 | L20: 358710.15 | M20: 274444.31 | N20: 270458.36 | O20: 247214.42 | P20: 247214.42 | Q20: 262341.07 | R20: 381874.22 | S20: 367362.09 | T20: 461718 | U20: 461718 | V20: 479843 | W20: 600020 | X20: 628449 | Y20: 491644 | Z20: 491644 | AA20: 487980 | AB20: 503046
A21: 1 | C21: 투자자산 | E21: 978622.22 | F21: 978622.22 | G21: 1014080.6 | H21: 1088113.3 | I21: 1242709.5 | J21: 790337.32 | K21: 790337.32 | L21: 975412.05 | M21: 910037.28 | N21: 887378.2 | O21: 774812.07 | P21: 774812.07 | Q21: 854459.2 | R21: 1029268 | S21: 1054127.1 | T21: 994606 | U21: 994606 | V21: 987513 | W21: 1151603 | X21: 1190482 | Y21: 1025298 | Z21: 1025298 | AA21: 1056140 | AB21: 1238382
A22: 1 | C22: 종속기업및관계기업투자 | E22: 582045.11 | F22: 582045.11 | G22: 600360.64 | H22: 610282.45 | I22: 683056.03 | J22: 355954.92 | K22: 355954.92 | L22: 377073.95 | M22: 394718.45 | N22: 370318.2 | O22: 316869.59 | P22: 316869.59 | Q22: 362439.33 | R22: 403890.58 | S22: 416340.43 | T22: 347660 | U22: 347660 | V22: 348456 | W22: 358134 | X22: 382629 | Y22: 352647 | Z22: 352647 | AA22: 372988 | AB22: 394865
A23: 1 | C23: 장기대여금 | E23: 44703.08 | F23: 44703.08 | G23: 46690.4 | H23: 53226.25 | I23: 53326.31 | J23: 41235.87 | K23: 41235.87 | L23: 193743.84 | M23: 198198.25 | N23: 200100.13 | O23: 184879.26 | P23: 184879.26 | Q23: 209128.49 | R23: 216572.23 | S23: 260807.85 | T23: 171691 | U23: 171691 | V23: 148235 | W23: 164398 | X23: 134483 | Y23: 118354 | Z23: 118354 | AA23: 103326 | AB23: 102065
A24: 1 | C24: 유형자산 | E24: 5436969.4 | F24: 5436969.4 | G24: 5442606.2 | H24: 5232674.8 | I24: 5342548.8 | J24: 5022147.6 | K24: 5022147.6 | L24: 5082049.5 | M24: 5070278.1 | N24: 5106593.6 | O24: 5225149.3 | P24: 5225149.3 | Q24: 5262427.7 | R24: 5359626.9 | S24: 5376205.8 | T24: 5703049 | U24: 5703049 | V24: 5716936 | W24: 5681822 | X24: 5658171 | Y24: 5776625 | Z24: 5776625 | AA24: 5822454 | AB24: 5916940
A25: 1 | C25: 무형자산 | E25: 8015980.1 | F25: 8015980.1 | G25: 8112119.7 | H25: 8282884.8 | I25: 8732222.8 | J25: 7772723.6 | K25: 7772723.6 | L25: 8009456 | M25: 8063006.7 | N25: 8158771.5 | O25: 7892981.7 | P25: 7892981.7 | Q25: 8080508.8 | R25: 8268439.5 | S25: 8088419.9 | T25: 8397290 | U25: 8397290 | V25: 8515804 | W25: 8360155 | X25: 8574522 | Y25: 8723585 | Z25: 8723585 | AA25: 8986009 | AB25: 9102599
A26: 1 | C26: 투자부동산 | E26: 72920.33 | F26: 72920.33 | G26: 72447.44 | H26: 71430.68 | I26: 79680.81 | J26: 274446.28 | K26: 274446.28 | L26: 251276.15 | M26: 282378.93 | N26: 280931.12 | O26: 208608.26 | P26: 208608.26 | Q26: 208380.54 | R26: 206782.51 | S26: 205891.8 | T26: 228288 | U26: 228288 | V26: 226689 | W26: 225138 | X26: 223511 | Y26: 219139 | Z26: 219139 | AA26: 217719 | AB26: 211745
A27: 1 | C27: 비유동확정계약자산 | E27: 20892.25 | F27: 20892.25 | G27: 25419.48 | H27: 63169.94 | I27: 118386.42 | J27: 40539.23 | K27: 40539.23 | L27: 45884.11 | M27: 42676.27 | N27: 46501.51 | O27: 25848.8 | P27: 25848.8 | Q27: 20550.31 | R27: 26930.95 | S27: 9616.76 | T27: 13537 | U27: 13537 | V27: 10979 | W27: 29051 | X27: 44921 | Y27: 62653 | Z27: 62653 | AA27: 91846 | AB27: 238406
A28: 1 | C28: 기타비유동자산 | E28: 454215.34 | F28: 454215.34 | G28: 483260.24 | H28: 452160.73 | I28: 486929.83 | J28: 553730.24 | K28: 553730.24 | L28: 558265.53 | M28: 555786.9 | N28: 517524.53 | O28: 377623.09 | P28: 377623.09 | Q28: 400187.15 | R28: 402710.11 | S28: 395090.56 | T28: 368647 | U28: 368647 | V28: 357835 | W28: 344944 | X28: 327561 | Y28: 317311 | Z28: 317311 | AA28: 351759 | AB28: 356551
A29: 1 | C29: 이연법인세자산 | E29: 232791.07 | F29: 232791.07 | G29: 234520.85 | H29: 241882.48 | I29: 241047.78 | J29: 416706.17 | K29: 416706.17 | L29: 402249.29 | M29: 406413.55 | N29: 412826.67 | O29: 502987.74 | P29: 502987.74 | Q29: 497080.61 | R29: 482406.48 | S29: 462161.1 | T29: 556161 | U29: 556161 | V29: 557815 | W29: 508774 | X29: 517775 | Y29: 628403 | Z29: 628403 | AA29: 616930 | AB29: 611231
A30: 1 | C30: 자산총계 | E30: 23720546 | F30: 23720546 | G30: 24145803 | H30: 24271351 | I30: 25170912 | J30: 23049782 | K30: 23049782 | L30: 23998329 | M30: 25307471 | N30: 24939919 | O30: 24640834 | P30: 24640834 | Q30: 25657121 | R30: 26114105 | S30: 25264597 | T30: 26314835 | U30: 26314835 | V30: 26896993 | W30: 26305196 | X30: 27027903 | Y30: 27513223 | Z30: 27513223 | AA30: 28695055 | AB30: 29947742
... A41: 1 | C41: 단기충당부채 | E41: 320457.9 | F41: 320457.9 | G41: 313783.96 | H41: 300348.18 | I41: 318120.64 | J41: 319218.54 | K41: 319218.54 | L41: 323242.45 | M41: 300733.1 | N41: 283930.45 | O41: 257968.84 | P41: 257968.84 | Q41: 219131.3 | R41: 211200.26 | S41: 204355.35 | T41: 241923 | U41: 241923 | V41: 236405 | W41: 229223 | X41: 247369 | Y41: 270809 | Z41: 270809 | AA41: 272614 | AB41: 300035
A42: 1 | C42: 유동리스부채 | E42: 64880.16 | F42: 64880.16 | G42: 66229.69 | J42: 76193.14 | K42: 76193.14 | L42: 79664.02 | M42: 82753.51 | O42: 78987.4 | P42: 78987.4 | Q42: 88399.96 | R42: 90060.74 | S42: 92513.56 | T42: 102853 | U42: 102853 | V42: 101479 | W42: 97964 | X42: 100433 | Y42: 100745 | Z42: 100745 | AA42: 103703 | AB42: 108847
A43: 1 | C43: 리스부채 | E43: 381187.32 | F43: 381187.32 | G43: 368071.26 | H43: 322162.05 | I43: 332673.62 | J43: 393893.74 | K43: 393893.74 | L43: 395706.2 | M43: 404843.26 | N43: 313951.82 | O43: 388067.78 | P43: 388067.78 | Q43: 390867.73 | R43: 383803.83 | S43: 379226.34 | T43: 404885 | U43: 404885 | V43: 389848 | W43: 374716 | X43: 373218 | Y43: 361872 | Z43: 361872 | AA43: 402794 | AB43: 405593
A44: 1 | C44: 비유동부채 | E44: 4787184.4 | F44: 4787184.4 | G44: 5355238.7 | H44: 5124973.6 | I44: 5089208.5 | J44: 4910036 | K44: 4910036 | L44: 4769842.5 | M44: 4667291.7 | N44: 4580739.4 | O44: 4202575.4 | P44: 4202575.4 | Q44: 4781204.6 | R44: 4945377.1 | S44: 4991623.2 | T44: 5707923 | U44: 5707923 | V44: 5643218 | W44: 5843723 | X44: 5591781 | Y44: 5396786 | Z44: 5396786 | AA44: 5084121 | AB44: 5209227
A45: 1 | C45: 사채 | E45: 848257.26 | F45: 848257.26 | G45: 918636.53 | H45: 649547 | I45: 329192.22 | J45: 356347.78 | K45: 356347.78 | L45: 313840.25 | M45: 296303.17 | N45: 528632.16 | O45: 493916.91 | P45: 493916.91 | Q45: 646739.73 | R45: 667920.12 | S45: 863778.79 | T45: 906758 | U45: 906758 | V45: 818317 | W45: 908843 | X45: 456865 | Y45: 499127 | Z45: 499127 | AA45: 438536 | AB45: 328608
A46: 1 | C46: 장기차입금 | E46: 1516918.5 | F46: 1516918.5 | G46: 2024704.1 | H46: 2118759.4 | I46: 2154106.3 | J46: 2350867.6 | K46: 2350867.6 | L46: 2176489.5 | M46: 2041640.3 | N46: 1747865.3 | O46: 1457749.4 | P46: 1457749.4 | Q46: 1865275.8 | R46: 1947862.4 | S46: 1927284.6 | T46: 2434534 | U46: 2434534 | V46: 2513424 | W46: 2554775 | X46: 2721533 | Y46: 2336139 | Z46: 2336139 | AA46: 2060904 | AB46: 2068141
A47: 1 | C47: 장기매입채무및기타채무 | E47: 14522.4 | F47: 14522.4 | G47: 9276.7 | H47: 9718.71 | I47: 10424.75 | J47: 11278.27 | K47: 11278.27 | L47: 10687.17 | M47: 11238.29 | N47: 11254.27 | O47: 11673.97 | P47: 11673.97 | Q47: 11753.55 | R47: 11764.76 | S47: 11970.31 | T47: 11189 | U47: 11189 | V47: 12016 | W47: 13650 | X47: 14649 | Y47: 22940 | Z47: 22940 | AA47: 25389 | AB47: 29250
A48: 1 | C48: 확정급여부채 | E48: 540496.54 | F48: 540496.54 | G48: 586394.6 | H48: 590166.73 | I48: 643844.69 | J48: 452352.77 | K48: 452352.77 | L48: 472131.68 | M48: 412889.2 | N48: 395807.59 | O48: 472216.38 | P48: 472216.38 | Q48: 498560.1 | R48: 509380.95 | S48: 499092.33 | T48: 570726 | U48: 570726 | V48: 573151 | W48: 566941 | X48: 574016 | Y48: 581488 | Z48: 581488 | AA48: 584972 | AB48: 594613
A49: 1 | C49: 장기파생상품부채 | E49: 5651.86 | F49: 5651.86 | G49: 5537.29 | H49: 4033.03 | I49: 4322.3 | J49: 6307.16 | K49: 6307.16 | L49: 6270.63 | M49: 11607.48 | N49: 3801.75 | O49: 13447.73 | P49: 13447.73 | Q49: 3646.17 | R49: 3511.97 | S49: 3169.65 | T49: 2457 | U49: 2457 | V49: 4173 | W49: 20834 | X49: 11345 | Y49: 35233 | Z49: 35233 | AA49: 3093 | AB49: 2593
A50: 1 | C50: 장기금융부채 | E50: 321959.02 | F50: 321959.02 | G50: 307378.86 | H50: 326195.08 | I50: 336995.92 | J50: 324007.76 | K50: 324007.76 | L50: 322312.81 | M50: 333697.23 | N50: 317753.57 | O50: 322528.11 | P50: 322528.11 | Q50: 306113.94 | R50: 297255.06 | S50: 289882.43 | T50: 304489 | U50: 304489 | V50: 292542 | W50: 297586 | X50: 284130 | Y50: 296360 | Z50: 296360 | AA50: 302184 | AB50: 299339
...

Sheet BS별도
B1: (백만원) | C1: 이름: BS별도H | E1: 4Q21 | F1: 2021 | G1: 1Q22 | H1: 2Q22 | I1: 3Q22 | J1: 4Q22 | K1: 2022 | L1: 1Q23 | M1: 2Q23 | N1: 3Q23 | O1: 4Q23 | P1: 2023 | Q1: 1Q24 | R1: 2Q24 | S1: 3Q24 | T1: 4Q24 | U1: 2024 | V1: 1Q25 | W1: 2Q25 | X1: 3Q25 | Y1: 4Q25 | Z1: 2025 | AA1: 1Q26 | AB1: 2Q26 | AC1: 3Q26 | AD1: 4Q26 | AE1: 2026 | AF1: 1Q27 | AG1: 2Q27 | AH1: 3Q27 | AI1: 4Q27 | AJ1: 2027 | AK1: 1Q28 | AL1: 2Q28 | AM1: 3Q28 | AN1: 4Q28 | AO1: 2028
B2: 별도 | D2: fin json(kship_fin.py)
B3: 두산에너빌리티(별) | C3: UPDATE: 26-10-19 | E3: 1 | F3: 2 | G3: 3 | H3: 4 | I3: 5 | J3: 6 | K3: 7 | L3: 8 | M3: 9 | N3: 10 | O3: 11 | P3: 12 | Q3: 13 | R3: 14 | S3: 15 | T3: 16 | U3: 17 | V3: 18 | W3: 19 | X3: 20 | Y3: 21 | Z3: 22 | AA3: 23 | AB3: 24 | AC3: 25 | AD3: 26 | AE3: 27 | AF3: 28 | AG3: 29 | AH3: 30 | AI3: 31 | AJ3: 32 | AK3: 33 | AL3: 34 | AM3: 35 | AN3: 36 | AO3: 37
B4: Account Code | C4: AccountNAME | E4: 2021.12 | F4: 2021.12A | G4: 2022.03 | H4: 2022.06 | I4: 2022.09 | J4: 2022.12 | K4: 2022.12A | L4: 2023.03 | M4: 2023.06 | N4: 2023.09 | O4: 2023.12 | P4: 2023.12A | Q4: 2024.03 | R4: 2024.06 | S4: 2024.09 | T4: 2024.12 | U4: 2024.12A | V4: 2025.03 | W4: 2025.06 | X4: 2025.09 | Y4: 2025.12 | Z4: 2025.12A | AA4: 2026.03 | AB4: 2026.06 | AC4: 2026.09 | AD4: 2026.12 | AE4: 2026.12A | AF4: 2027.03 | AG4: 2027.06 | AH4: 2027.09 | AI4: 2027.12 | AJ4: 2027.12A | AK4: 2028.03 | AL4: 2028.06 | AM4: 2028.09 | AN4: 2028.12 | AO4: 2028.12A
A5: 1 | C5: 유동자산 | E5: 3683979.6 | F5: 3683979.6 | G5: 3731421.5 | H5: 4024955.2 | I5: 4155125.6 | J5: 3537609.7 | K5: 3537609.7 | L5: 3623666.7 | M5: 4377781.4 | N5: 4034350.5 | O5: 4051761.9 | P5: 4051761.9 | Q5: 4186297.7 | R5: 4024291.9 | S5: 3961773.5 | T5: 4048371 | U5: 4048371 | V5: 4306084 | W5: 4154258 | X5: 4582507 | Y5: 4910318 | Z5: 4910318 | AA5: 5146742 | AB5: 5543025
A6: 1 | C6: 현금및현금성자산 | E6: 423695.21 | F6: 423695.21 | G6: 193962.04 | H6: 270131.74 | I6: 458471.13 | J6: 307351.16 | K6: 307351.16 | L6: 251008.89 | M6: 1079473.7 | N6: 472850.36 | O6: 733013.69 | P6: 733013.69 | Q6: 666934.56 | R6: 434503.47 | S6: 260735.4 | T6: 645087 | U6: 645087 | V6: 306065 | W6: 127071 | X6: 184653 | Y6: 760602 | Z6: 760602 | AA6: 543226 | AB6: 319656
A7: 1 | C7: 단기금융상품 | E7: 446816.82 | F7: 446816.82 | G7: 236859.26 | H7: 119564.84 | I7: 124044.9 | J7: 84578.98 | K7: 84578.98 | L7: 55589.3 | M7: 57458.24 | N7: 75108.84 | O7: 72594.87 | P7: 72594.87 | Q7: 73710.74 | R7: 48997.39 | S7: 49558.82 | T7: 49400 | U7: 49400 | V7: 44316 | W7: 46256 | X7: 45954 | Y7: 41745 | Z7: 41745 | AA7: 42782 | AB7: 43006
A8: 1 | C8: 단기금융자산 | E8: 637724.61 | F8: 637724.61 | G8: 635193.27 | H8: 564747.9 | I8: 655686.54 | J8: 516617.55 | K8: 516617.55 | L8: 513929.88 | M8: 273077.84 | N8: 363369 | O8: 204461.71 | P8: 204461.71 | Q8: 282374.36 | R8: 349494.83 | S8: 325140.31 | T8: 248012 | U8: 248012 | V8: 230313 | W8: 147838 | X8: 171246 | Y8: 119634 | Z8: 119634 | AA8: 204269 | AB8: 259233
A9: 1 | C9: 매출채권및기타채권 | E9: 418825.89 | F9: 418825.89 | G9: 615432.65 | H9: 740555.69 | I9: 677392.46 | J9: 757107.42 | K9: 757107.42 | L9: 931859.2 | M9: 1035261.7 | N9: 1184692.5 | O9: 978610.81 | P9: 978610.81 | Q9: 1143138 | R9: 923528.95 | S9: 1127886.3 | T9: 990147 | U9: 990147 | V9: 1072607 | W9: 1216499 | X9: 1383541 | Y9: 1452042 | Z9: 1452042 | AA9: 1507459 | AB9: 1612515
A10: 1 | C10: 계약자산 | E10: 1297216.4 | F10: 1297216.4 | G10: 1347622.8 | H10: 1290134.4 | I10: 1222346.4 | J10: 970226.75 | K10: 970226.75 | L10: 938454.18 | M10: 963461.19 | N10: 1079691.6 | O10: 1259649.8 | P10: 1259649.8 | Q10: 1241807.1 | R10: 1387780.9 | S10: 1355902.4 | T10: 1345091 | U10: 1345091 | V10: 1539245 | W10: 1662052 | X10: 1552255 | Y10: 1524720 | Z10: 1524720 | AA10: 1762128 | AB10: 2221080
A11: 1 | C11: 선급금 | E11: 373337.56 | F11: 373337.56 | G11: 460509.05 | H11: 580780.91 | I11: 532117.26 | J11: 501387.14 | K11: 501387.14 | L11: 476453.35 | M11: 506059.44 | N11: 472044.98 | O11: 429084.44 | P11: 429084.44 | Q11: 381822.07 | R11: 430762.23 | S11: 383172.01 | T11: 328694 | U11: 328694 | V11: 338158 | W11: 335549 | X11: 425905 | Y11: 485334 | Z11: 485334 | AA11: 447490 | AB11: 429122
A12: 1 | C12: 선급금등 | E12: 373337.56 | F12: 373337.56 | G12: 460509.05 | H12: 580780.91 | I12: 532117.26 | J12: 501387.14 | K12: 501387.14 | L12: 476453.35 | M12: 506059.44 | N12: 472044.98 | O12: 429084.44 | P12: 429084.44 | Q12: 381822.07 | R12: 430762.23 | S12: 383172.01 | T12: 328694 | U12: 328694 | V12: 338158 | W12: 335549 | X12: 425905 | Y12: 485334 | Z12: 485334 | AA12: 447490 | AB12: 429122
A13: 1 | C13: 기타유동자산 | E13: 482562.41 | F13: 482562.41 | G13: 565702.37 | H13: 691902.47 | I13: 640899.52 | J13: 596080.05 | K13: 596080.05 | L13: 587745.56 | M13: 624744.31 | N13: 585743.75 | O13: 533538.69 | P13: 533538.69 | Q13: 498249.17 | R13: 548427.23 | S13: 505566.08 | T13: 446076 | U13: 446076 | V13: 480267 | W13: 470065 | X13: 557517 | Y13: 601669 | Z13: 601669 | AA13: 583747 | AB13: 560660
A14: 1 | C14: 단기대여금 | E14: 146163.47 | F14: 146163.47 | G14: 348292.85 | H14: 354657.92 | I14: 369206.91 | J14: 377110.99 | K14: 377110.99 | L14: 393385.1 | M14: 153741.79 | N14: 212733.65 | O14: 94473.05 | P14: 94473.05 | Q14: 140760.97 | R14: 215279.55 | S14: 227057.49 | T14: 84362 | U14: 84362 | V14: 77247 | W14: 64534 | X14: 71564 | Y14: 12032 | Z14: 12032 | AA14: 30792 | AB14: 37673
A15: 1 | C15: 유동확정계약자산 | E15: 44744.32 | F15: 44744.32 | G15: 50041.16 | H15: 90525.14 | I15: 162434.73 | J15: 54927.58 | K15: 54927.58 | L15: 64955.48 | M15: 61877.81 | N15: 75526.51 | O15: 37393.79 | P15: 37393.79 | Q15: 67902.65 | R15: 85217.89 | S15: 48524 | T15: 114250 | U15: 114250 | V15: 108750 | W15: 37048 | X15: 53728 | Y15: 65857 | Z15: 65857 | AA15: 130695 | AB15: 178554
A16: 1 | C16: 재고자산 | E16: 361059.87 | F16: 361059.87 | G16: 336326.98 | H16: 278501.23 | I16: 298286.37 | J16: 326311.36 | K16: 326311.36 | L16: 327472.95 | M16: 325100.34 | N16: 303856.78 | O16: 290947.64 | P16: 290947.64 | Q16: 331144.94 | R16: 364262.25 | S16: 370871.45 | T16: 335840 | U16: 335840 | V16: 660725 | W16: 457186 | X16: 493306 | Y16: 429105 | Z16: 429105 | AA16: 514031 | AB16: 529928
A17: 1 | C17: 매각예정비유동자산및처분자산 | E17: 42569.44 | F17: 42569.44 | G17: 12169.44 | H17: 127245.5 | I17: 11545.16 | J17: 1967.25 | K17: 1967.25 | L17: 23642.86 | M17: 23642.86 | N17: 23642.86 | O17: 33587.41 | P17: 33587.41 | Q17: 8456.05 | R17: 1505.81 | S17: 1505.81 | T17: 1506 | U17: 1506 | V17: 1291 | W17: 0 | X17: 203038 | Y17: 0 | Z17: 0
A18: 1 | C18: 비유동자산 | E18: 10347891 | F18: 10347891 | G18: 10393594 | H18: 10192249 | I18: 10493476 | J18: 9651930.8 | K18: 9651930.8 | L18: 9838058.8 | M18: 9768162.7 | N18: 9766515.8 | O18: 9632747.1 | P18: 9632747.1 | Q18: 9711131.4 | R18: 9770506.5 | S18: 9777250.2 | T18: 9708503 | U18: 9708503 | V18: 9624371 | W18: 9799013 | X18: 9643867 | Y18: 9956057 | Z18: 9956057 | AA18: 9989650 | AB18: 10227684
A19: 1 | C19: 장기금융자산 | E19: 199368.29 | F19: 199368.29 | G19: 205019.86 | H19: 219017.65 | I19: 238082.12 | J19: 209318.25 | K19: 209318.25 | L19: 212123.57 | M19: 201299.88 | N19: 193491.94 | O19: 176082.93 | P19: 176082.93 | Q19: 188575.48 | R19: 227775.77 | S19: 218576.27 | T19: 301918 | U19: 301918 | V19: 321554 | W19: 447841 | X19: 474434 | Y19: 346555 | Z19: 346555 | AA19: 339668 | AB19: 354175
A20: 1 | C20: 투자자산 | E20: 5614808.3 | F20: 5614808.3 | G20: 5650814.1 | H20: 5460625.4 | I20: 5752141.5 | J20: 4788334.2 | K20: 4788334.2 | L20: 4994808.2 | M20: 5001156.9 | N20: 4963556.4 | O20: 4772350.3 | P20: 4772350.3 | Q20: 4843861.4 | R20: 4910078.8 | S20: 4923755.7 | T20: 4708227 | U20: 4708227 | V20: 4617892 | W20: 4791270 | X20: 4614472 | Y20: 4747740 | Z20: 4747740 | AA20: 4755685 | AB20: 4972683
A21: 1 | C21: 종속기업및관계기업투자 | E21: 5349988.2 | F21: 5349988.2 | G21: 5374338.8 | H21: 5126704.3 | I21: 5343994.6 | J21: 4499041.8 | K21: 4499041.8 | L21: 4545014.9 | M21: 4561073 | N21: 4525296.4 | O21: 4302259.4 | P21: 4302259.4 | Q21: 4335337.6 | R21: 4346737.6 | S21: 4347997.6 | T21: 4071935 | U21: 4071935 | V21: 4072795 | W21: 4074435 | X21: 3869105 | Y21: 4216247 | Z21: 4216247 | AA21: 4218027 | AB21: 4221287
A22: 1 | C22: 장기대여금 | E22: 44758.9 | F22: 44758.9 | G22: 46249.15 | H22: 51733.54 | I22: 51678.33 | J22: 39434.96 | K22: 39434.96 | L22: 191785.65 | M22: 196107.76 | N22: 198266.57 | O22: 268159.19 | P22: 268159.19 | Q22: 299397.97 | R22: 308634.46 | S22: 347565.01 | T22: 320837 | U22: 320837 | V22: 212564 | W22: 239943 | X22: 226012 | Y22: 122285 | Z22: 122285 | AA22: 106144 | AB22: 158815
A23: 1 | C23: 유형자산 | E23: 3309494.9 | F23: 3309494.9 | G23: 3287673.2 | H23: 3272493 | I23: 3258987.2 | J23: 3152146.6 | K23: 3152146.6 | L23: 3148703.9 | M23: 3141078.2 | N23: 3131315.6 | O23: 3151464.9 | P23: 3151464.9 | Q23: 3140276.5 | R23: 3135273.9 | S23: 3139029.8 | T23: 3152671 | U23: 3152671 | V23: 3138421 | W23: 3135148 | X23: 3145939 | Y23: 3171422 | Z23: 3171422 | AA23: 3211132 | AB23: 3226375
A24: 1 | C24: 무형자산 | E24: 974589.54 | F24: 974589.54 | G24: 992294.43 | H24: 1013556.3 | I24: 1029539.2 | J24: 1002660.8 | K24: 1002660.8 | L24: 1024189.8 | M24: 1055101.7 | N24: 1086660 | O24: 1113633.7 | P24: 1113633.7 | Q24: 1135970.5 | R24: 1158327.3 | S24: 1169356.7 | T24: 1214831 | U24: 1214831 | V24: 1235632 | W24: 1262229 | X24: 1275193 | Y24: 1287875 | Z24: 1287875 | AA24: 1292723 | AB24: 1302982
A25: 1 | C25: 투자부동산 | E25: 79533.76 | F25: 79533.76 | G25: 79113.72 | H25: 78150.69 | I25: 86455.41 | J25: 159698.02 | K25: 159698.02 | L25: 136652.59 | M25: 135289.01 | N25: 133894.23 | O25: 93373.2 | P25: 93373.2 | Q25: 94091.78 | R25: 92634.99 | S25: 91162.37 | T25: 113710 | U25: 113710 | V25: 112269 | W25: 110812 | X25: 109340 | Y25: 104282 | Z25: 104282 | AA25: 103017 | AB25: 97230
A26: 1 | C26: 비유동확정계약자산 | E26: 20692.91 | F26: 20692.91 | G26: 25206.32 | H26: 63169.94 | I26: 118386.42 | J26: 40539.23 | K26: 40539.23 | L26: 45884.11 | M26: 42676.27 | N26: 46501.51 | O26: 25848.8 | P26: 25848.8 | Q26: 20550.31 | R26: 26930.95 | S26: 9616.76 | T26: 13537 | U26: 13537 | V26: 10979 | W26: 29051 | X26: 44921 | Y26: 62653 | Z26: 62653 | AA26: 91846 | AB26: 238406
A27: 1 | C27: 이연법인세자산 | E27: 180001.25 | F27: 180001.25 | G27: 180001.25 | H27: 180001.25 | I27: 180001.25 | J27: 345731.25 | K27: 345731.25 | L27: 345731.25 | M27: 345731.25 | N27: 345731.25 | O27: 427399.45 | P27: 427399.45 | Q27: 416544.7 | R27: 405715.93 | S27: 385598.09 | T27: 448269 | U27: 448269 | V27: 448269 | W27: 408192 | X27: 424011 | Y27: 547449 | Z27: 547449 | AA27: 533814 | AB27: 514926
A28: 1 | C28: 기타비유동자산 | E28: 78983.6 | F28: 78983.6 | G28: 88828.19 | H28: 39441.36 | I28: 43547.84 | J28: 36690.65 | K28: 36690.65 | L28: 34045.87 | M28: 39404.31 | N28: 43824.72 | O28: 47239.1 | P28: 47239.1 | Q28: 48490.68 | R28: 54105.63 | S28: 53132.36 | T28: 45985 | U28: 45985 | V28: 39617 | W28: 40712 | X28: 41625 | Y28: 40014 | Z28: 40014 | AA28: 46227 | AB28: 63064
A29: 1 | C29: 자산총계 | E29: 14031871 | F29: 14031871 | G29: 14125015 | H29: 14217204 | I29: 14648601 | J29: 13189540 | K29: 13189540 | L29: 13461725 | M29: 14145944 | N29: 13800866 | O29: 13684509 | P29: 13684509 | Q29: 13897429 | R29: 13794798 | S29: 13739024 | T29: 13756874 | U29: 13756874 | V29: 13930455 | W29: 13953271 | X29: 14226374 | Y29: 14866375 | Z29: 14866375 | AA29: 15136392 | AB29: 15770709
... A36: 1 | C36: 유동성장기부채 | E36: 899500.41 | F36: 899500.41 | G36: 672291.56 | H36: 586147.99 | I36: 1055267 | J36: 641666.91 | K36: 641666.91 | L36: 1113477.9 | M36: 1369171.1 | N36: 1104494.6 | O36: 1403847.4 | P36: 1403847.4 | Q36: 703673.73 | R36: 684076.67 | S36: 521799.68 | T36: 222000 | U36: 222000 | V36: 223000 | W36: 158000 | X36: 661660 | Y36: 721470 | Z36: 721470 | AA36: 1239020 | AB36: 1273450
A37: 1 | C37: 유동리스부채 | E37: 26140.81 | F37: 26140.81 | G37: 26949.05 | J37: 29843.9 | K37: 29843.9 | L37: 29268.62 | M37: 27258.28 | O37: 26198.91 | P37: 26198.91 | Q37: 33867.26 | R37: 34046.18
A38: 1 | C38: 리스부채 | E38: 183629.45 | F38: 183629.45 | G38: 180297.89 | H38: 152199.19 | I38: 147410.71 | J38: 172304.34 | K38: 172304.34 | L38: 168751.41 | M38: 162200.93 | N38: 130592.16 | O38: 155411.79 | P38: 155411.79 | Q38: 157127.98 | R38: 153580.31 | S38: 114815.78 | T38: 116086 | U38: 116086 | V38: 110908 | W38: 107323 | X38: 105084 | Y38: 94869 | Z38: 94869 | AA38: 124718 | AB38: 123839
A39: 1 | C39: 단기금융부채 | E39: 35276.16 | F39: 35276.16 | G39: 34101.89 | H39: 7777.93 | I39: 6516.6 | J39: 46379.59 | K39: 46379.59 | L39: 40145.96 | M39: 39794.09 | N39: 6521.49 | O39: 37860.17 | P39: 37860.17 | Q39: 39463.89 | R39: 39876.85 | S39: 6932.58 | T39: 5893 | U39: 5893 | V39: 2796 | W39: 35143 | X39: 14597 | Y39: 17107 | Z39: 17107 | AA39: 2750 | AB39: 2640
A40: 1 | C40: 단기파생상품부채 | E40: 9135.35 | F40: 9135.35 | G40: 7152.84 | H40: 7777.93 | I40: 6516.6 | J40: 16535.69 | K40: 16535.69 | L40: 10877.34 | M40: 12535.81 | N40: 6521.49 | O40: 11661.26 | P40: 11661.26 | Q40: 5596.63 | R40: 5830.67 | S40: 6932.58 | T40: 5893 | U40: 5893 | V40: 2796 | W40: 35143 | X40: 14597 | Y40: 17107 | Z40: 17107 | AA40: 2750 | AB40: 2640
A41: 1 | C41: 단기충당부채 | E41: 196415.92 | F41: 196415.92 | G41: 189121.64 | H41: 175199.44 | I41: 185611.17 | J41: 182202.92 | K41: 182202.92 | L41: 176357.54 | M41: 158405.05 | N41: 147174.01 | O41: 122643.67 | P41: 122643.67 | Q41: 71551.42 | R41: 64678.15 | S41: 55535.43 | T41: 72200 | U41: 72200 | V41: 58553 | W41: 49079 | X41: 50997 | Y41: 151935 | Z41: 151935 | AA41: 63637 | AB41: 68269
A42: 1 | C42: 비유동부채 | E42: 1186291.2 | F42: 1186291.2 | G42: 1683175.7 | H42: 1934363.5 | I42: 1709006.4 | J42: 2016603.6 | K42: 2016603.6 | L42: 1768978.7 | M42: 1560075.6 | N42: 1722730.5 | O42: 1441867.6 | P42: 1441867.6 | Q42: 1913283.6 | R42: 1891793 | S42: 2042534.2 | T42: 2332951 | U42: 2332951 | V42: 2387149 | W42: 2743709 | X42: 2402318 | Y42: 2272402 | Z42: 2272402 | AA42: 1894927 | AB42: 1970710
A43: 1 | C43: 사채 | E43: 422363.43 | F43: 422363.43 | G43: 484881.46 | H43: 574722.91 | I43: 259433.67 | J43: 259132.25 | K43: 259132.25 | L43: 216581.52 | M43: 136799.07 | N43: 438935.51 | O43: 423103.27 | P43: 423103.27 | Q43: 498191.63 | R43: 511361.75 | S43: 640768.93 | T43: 686148 | U43: 686148 | V43: 642843 | W43: 738737 | X43: 269574 | Y43: 270349 | Z43: 270349 | AA43: 214044 | AB43: 168873
A44: 1 | C44: 장기차입금 | E44: 122492.71 | F44: 122492.71 | G44: 567663.36 | H44: 667663.36 | I44: 667663.36 | J44: 1113279.5 | K44: 1113279.5 | L44: 893331.12 | M44: 751806.76 | N44: 592331.94 | O44: 287188.57 | P44: 287188.57 | Q44: 700000 | R44: 639351.45 | S44: 679593.85 | T44: 819840 | U44: 819840 | V44: 950000 | W44: 1145000 | X44: 1271250 | Y44: 1057500 | Z44: 1057500 | AA44: 733750 | AB44: 730000
A45: 1 | C45: 장기매입채무및기타채무 | E45: 13601.34 | F45: 13601.34 | G45: 8184.91 | H45: 8647.52 | I45: 9147.45 | J45: 9509.9 | K45: 9509.9 | L45: 9472.1 | M45: 9809.38 | N45: 9894.42 | O45: 10016.33 | P45: 10016.33 | Q45: 10052.26 | R45: 10052.16 | S45: 10133.04 | T45: 9451 | U45: 9451 | V45: 10169 | W45: 11694 | X45: 12798 | Y45: 20951 | Z45: 20951 | AA45: 22900 | AB45: 24896
A46: 1 | C46: 확정급여부채 | E46: 105513.44 | F46: 105513.44 | G46: 137883.95 | H46: 136960.01 | I46: 143514.13 | J46: 113117.1 | K46: 113117.1 | L46: 121330.02 | M46: 127198.83 | N46: 134108.87 | O46: 192863.55 | P46: 192863.55 | Q46: 204259.37 | R46: 213065.26 | S46: 220903.31 | T46: 298291 | U46: 298291 | V46: 304253 | W46: 314071 | X46: 322670 | Y46: 341458 | Z46: 341458 | AA46: 354804 | AB46: 366938
...

Sheet subQ
A1: YQ | C1: subQ 분기 서브모델(억원, U=100) | E1: 4Q21 | F1: 2021 | G1: 1Q22 | H1: 2Q22 | I1: 3Q22 | J1: 4Q22 | K1: 2022 | L1: 1Q23 | M1: 2Q23 | N1: 3Q23 | O1: 4Q23 | P1: 2023 | Q1: 1Q24 | R1: 2Q24 | S1: 3Q24 | T1: 4Q24 | U1: 2024 | V1: 1Q25 | W1: 2Q25 | X1: 3Q25 | Y1: 4Q25 | Z1: 2025 | AA1: 1Q26 | AB1: 2Q26 | AC1: 3Q26 | AD1: 4Q26 | AE1: 2026 | AF1: 1Q27 | AG1: 2Q27 | AH1: 3Q27 | AI1: 4Q27 | AJ1: 2027 | AK1: 1Q28 | AL1: 2Q28 | AM1: 3Q28 | AN1: 4Q28 | AO1: 2028
A2: A=이름(key) B=그룹 C=단위 D=FnGuide 계정명(VLOOKUP 키). 확정=VLOOKUP(BS), 추정=변수 가정 참조
E3: 1 | F3: 2 | G3: 3 | H3: 4 | I3: 5 | J3: 6 | K3: 7 | L3: 8 | M3: 9 | N3: 10 | O3: 11 | P3: 12 | Q3: 13 | R3: 14 | S3: 15 | T3: 16 | U3: 17 | V3: 18 | W3: 19 | X3: 20 | Y3: 21 | Z3: 22 | AA3: 23 | AB3: 24 | AC3: 25 | AD3: 26 | AE3: 27 | AF3: 28 | AG3: 29 | AH3: 30 | AI3: 31 | AJ3: 32 | AK3: 33 | AL3: 34 | AM3: 35 | AN3: 36 | AO3: 37
E4: 2021.12 | F4: 2021.12A | G4: 2022.03 | H4: 2022.06 | I4: 2022.09 | J4: 2022.12 | K4: 2022.12A | L4: 2023.03 | M4: 2023.06 | N4: 2023.09 | O4: 2023.12 | P4: 2023.12A | Q4: 2024.03 | R4: 2024.06 | S4: 2024.09 | T4: 2024.12 | U4: 2024.12A | V4: 2025.03 | W4: 2025.06 | X4: 2025.09 | Y4: 2025.12 | Z4: 2025.12A | AA4: 2026.03 | AB4: 2026.06 | AC4: 2026.09 | AD4: 2026.12 | AE4: 2026.12A | AF4: 2027.03 | AG4: 2027.06 | AH4: 2027.09 | AI4: 2027.12 | AJ4: 2027.12A | AK4: 2028.03 | AL4: 2028.06 | AM4: 2028.09 | AN4: 2028.12 | AO4: 2028.12A
A5: 매출액 | B5: 손익 | C5: 억원 | D5: 매출액(수익) | E5: =IFERROR(VLOOKUP($D5,BS연결,MATCH(E$1,BS연결H,0),0)/100,"") | G5: =IFERROR(VLOOKUP($D5,BS연결,MATCH(G$1,BS연결H,0),0)/100,"") | H5: =IFERROR(VLOOKUP($D5,BS연결,MATCH(H$1,BS연결H,0),0)/100,"") | I5: =IFERROR(VLOOKUP($D5,BS연결,MATCH(I$1,BS연결H,0),0)/100,"") | J5: =IFERROR(VLOOKUP($D5,BS연결,MATCH(J$1,BS연결H,0),0)/100,"") | K5: =IFERROR(VLOOKUP($D5,BS연결,MATCH(K$1,BS연결H,0),0)/100,"") | L5: =IFERROR(VLOOKUP($D5,BS연결,MATCH(L$1,BS연결H,0),0)/100,"") | M5: =IFERROR(VLOOKUP($D5,BS연결,MATCH(M$1,BS연결H,0),0)/100,"") | N5: =IFERROR(VLOOKUP($D5,BS연결,MATCH(N$1,BS연결H,0),0)/100,"") | ... AB5: =IFERROR(VLOOKUP($D5,BS연결,MATCH(AB$1,BS연결H,0),0)/100,"") | AC5: =IFERROR(X5*(1+변수!AC21),"") | AD5: =IFERROR(Y5*(1+변수!AD21),"") | AE5: =SUM(AA5:AD5) | AF5: =IFERROR(AA5*(1+변수!AF21),"") | AG5: =IFERROR(AB5*(1+변수!AG21),"") | AH5: =IFERROR(AC5*(1+변수!AH21),"") | AI5: =IFERROR(AD5*(1+변수!AI21),"") | AJ5: =SUM(AF5:AI5) | AK5: =IFERROR(AF5*(1+변수!AK21),"") | AL5: =IFERROR(AG5*(1+변수!AL21),"") | AM5: =IFERROR(AH5*(1+변수!AM21),"") | AN5: =IFERROR(AI5*(1+변수!AN21),"") | AO5: =SUM(AK5:AN5)
A6: 매출원가 | B6: 손익 | C6: 억원 | D6: 매출원가 | E6: =IFERROR(VLOOKUP($D6,BS연결,MATCH(E$1,BS연결H,0),0)/100,"") | G6: =IFERROR(VLOOKUP($D6,BS연결,MATCH(G$1,BS연결H,0),0)/100,"") | H6: =IFERROR(VLOOKUP($D6,BS연결,MATCH(H$1,BS연결H,0),0)/100,"") | I6: =IFERROR(VLOOKUP($D6,BS연결,MATCH(I$1,BS연결H,0),0)/100,"") | J6: =IFERROR(VLOOKUP($D6,BS연결,MATCH(J$1,BS연결H,0),0)/100,"") | K6: =IFERROR(VLOOKUP($D6,BS연결,MATCH(K$1,BS연결H,0),0)/100,"") | L6: =IFERROR(VLOOKUP($D6,BS연결,MATCH(L$1,BS연결H,0),0)/100,"") | M6: =IFERROR(VLOOKUP($D6,BS연결,MATCH(M$1,BS연결H,0),0)/100,"") | N6: =IFERROR(VLOOKUP($D6,BS연결,MATCH(N$1,BS연결H,0),0)/100,"") | ... AB6: =IFERROR(VLOOKUP($D6,BS연결,MATCH(AB$1,BS연결H,0),0)/100,"") | AC6: =IFERROR(AC5-AC7,"") | AD6: =IFERROR(AD5-AD7,"") | AE6: =SUM(AA6:AD6) | AF6: =IFERROR(AF5-AF7,"") | AG6: =IFERROR(AG5-AG7,"") | AH6: =IFERROR(AH5-AH7,"") | AI6: =IFERROR(AI5-AI7,"") | AJ6: =SUM(AF6:AI6) | AK6: =IFERROR(AK5-AK7,"") | AL6: =IFERROR(AL5-AL7,"") | AM6: =IFERROR(AM5-AM7,"") | AN6: =IFERROR(AN5-AN7,"") | AO6: =SUM(AK6:AN6)
A7: 매출총이익 | B7: 손익 | C7: 억원 | D7: 매출총이익 | E7: =IFERROR(VLOOKUP($D7,BS연결,MATCH(E$1,BS연결H,0),0)/100,"") | G7: =IFERROR(VLOOKUP($D7,BS연결,MATCH(G$1,BS연결H,0),0)/100,"") | H7: =IFERROR(VLOOKUP($D7,BS연결,MATCH(H$1,BS연결H,0),0)/100,"") | I7: =IFERROR(VLOOKUP($D7,BS연결,MATCH(I$1,BS연결H,0),0)/100,"") | J7: =IFERROR(VLOOKUP($D7,BS연결,MATCH(J$1,BS연결H,0),0)/100,"") | K7: =IFERROR(VLOOKUP($D7,BS연결,MATCH(K$1,BS연결H,0),0)/100,"") | L7: =IFERROR(VLOOKUP($D7,BS연결,MATCH(L$1,BS연결H,0),0)/100,"") | M7: =IFERROR(VLOOKUP($D7,BS연결,MATCH(M$1,BS연결H,0),0)/100,"") | N7: =IFERROR(VLOOKUP($D7,BS연결,MATCH(N$1,BS연결H,0),0)/100,"") | ... AB7: =IFERROR(VLOOKUP($D7,BS연결,MATCH(AB$1,BS연결H,0),0)/100,"") | AC7: =IFERROR(AC9+AC8,"") | AD7: =IFERROR(AD9+AD8,"") | AE7: =SUM(AA7:AD7) | AF7: =IFERROR(AF9+AF8,"") | AG7: =IFERROR(AG9+AG8,"") | AH7: =IFERROR(AH9+AH8,"") | AI7: =IFERROR(AI9+AI8,"") | AJ7: =SUM(AF7:AI7) | AK7: =IFERROR(AK9+AK8,"") | AL7: =IFERROR(AL9+AL8,"") | AM7: =IFERROR(AM9+AM8,"") | AN7: =IFERROR(AN9+AN8,"") | AO7: =SUM(AK7:AN7)
