Workbook
Name 변수H: 변수!$C$1:$AO$1
Name 환율: 변수!$C$6:$AO$13
Name BS연결H: BS연결!$C$1:$AO$1
Name BS연결: BS연결!$C$5:$AO$119
Name BS별도H: BS별도!$C$1:$AO$1
Name BS별도: BS별도!$C$5:$AO$103
Name SUBQH: subQ!$A$1:$AO$1
Name subQ: subQ!$A$5:$AO$47
Name SLS_H: SLS!$A$1:$BS$1

Sheet README
A1: 한화오션(042660) 실적 모델 — ARGUS 한국조선
A2: 기준 분기 2026Q2 · 마지막 실적 2026Q2 · 생성 2026-10-12
A3: 모든 수치는 모델 산출값(DART 공개 재무제표 + 우리 추정)이다 — 목표주가·투자 추천 아님. 참고용 · 투자조언 아님.
A5: 시트
A6: 변수 가정 시계열. 환율 8행(ECB via frankfurter — L2 fx.json; 추정 분기 = 노란 가정), 추정 드라이버(노란 셀 = 모델값에서 역산한 가정, 바꾸면 재계산; 연녹 셀 = 3절 스칼라 참조 수식), 3절 스칼라 가정(세율·판관비율·지배주주비중·이자율·종가·PER 밴드·COE·외화 순노출·헤지비율)
A7: BS연결/BS별도 FnGuide 계정명 × 기간 값 덤프(백만원). 행1 분기라벨, 행4 YYYY.MM / YYYY.12A. 이름정의 BS연결H·BS연결(계정명 C열부터)
A8: subQ 분기 서브모델(억원 = 백만원/100). 확정 행: =IFERROR(VLOOKUP($D행,BS연결,MATCH(E$1,BS연결H,0),0)/100,"") 추정 행: 변수 시트 가정 셀 참조 수식. 외환손익·파생상품손익은 BS 계정 합·차, 기타금융손익은 잔차, OPM·EPS·BPS·PER·PBR 은 파생 수식
A9: SLS 선표(조선사만, sls json 있을 때): 요약 행(sls 저장값) + 계약별 스케줄(백만$) × (헤지비율 × 헤지환율 + (1−헤지비율) × 건조시점 환율[변수 원/달러(평균)]) → 원화 수식 블록 → 합계 행이 subQ 매출조선에 연결
A10: 시나리오 신규수주 보수/기준/낙관(forecast_panel 패널, 모델에 scenarios 가 있을 때만): 매출액·영업이익 = subQ 기준값 ± (시나리오 신규 − base 신규) × OPM. base 만 subQ 행에 포함, 나머지는 합산 안 함
A11: 분기/연간예상 subQ 를 이름(A열 key)으로 VLOOKUP 한 보고서 표(억원)
A12: TP PER 밴드 × 12M fwd EPS, PBR = ROE/COE × BPS — 모델 산출값 구간, 목표주가·추천 아님
A13: 외화 환율 QoQ, 외화 순노출 × Δ기말환율 → 환관련손익 추정
... A36: 백테스트: {"freeze": "2025Q2", "horizon": 4, "revenue_wape_pct": 17.8, "op_wape_pct": 51.2, "n": 4, "note": "단일 회사 4분기 — 통계 아님", "driver_at_freeze": "sls_marine_plus_uncovered_backlog_runoff", "selection_oos_at_freeze": null, "frozen_inputs": "fin(연결/별도)·고객 조선사 모델·지주 자회사 모델은 2025Q2 까지의 분기만; 선표는 체결일 ≤ 2025Q2 말일 계약(원장 최신 금액·코호트 등급, 환산 없음); 잔고는 yards_cache 2025Q2; 시세·환율 forward·prices·forecast_panel 신규수주 미사용. 고객 가중치(suppliers.json 언급 비중)와 합병 체인링크는 현재 지식; 고객 연동 채택은 동결 모델 안에서도 자기 la−4분기 OOS 규칙(selection_oos_at_freeze)", "detail": [{"q": "2025Q3", "rev_pred": 31776.86, "rev_act": 30233.58, "op_pred": 2132.75, "op_act": 2897.59}, {"q": "2025Q4", "rev_pred": 31776.86, "rev_act": 33229.51, "op_pred": 2132.75, "op_act": 2475.19}, {"q": "2026Q1", "rev_pred": 31609.47, "rev_act": 32099.4, "op_pred": 2103.87, "op_act": 4410.65}, {"q": "2026Q2", "rev_pred": 31245.58, "rev_act": 54431.71, "op_pred": 2005.63, "op_act": 7361.14}]}

Sheet 변수
C1: 이름: 변수H | E1: 4Q21 | F1: 2021 | G1: 1Q22 | H1: 2Q22 | I1: 3Q22 | J1: 4Q22 | K1: 2022 | L1: 1Q23 | M1: 2Q23 | N1: 3Q23 | O1: 4Q23 | P1: 2023 | Q1: 1Q24 | R1: 2Q24 | S1: 3Q24 | T1: 4Q24 | U1: 2024 | V1: 1Q25 | W1: 2Q25 | X1: 3Q25 | Y1: 4Q25 | Z1: 2025 | AA1: 1Q26 | AB1: 2Q26 | AC1: 3Q26 | AD1: 4Q26 | AE1: 2026 | AF1: 1Q27 | AG1: 2Q27 | AH1: 3Q27 | AI1: 4Q27 | AJ1: 2027 | AK1: 1Q28 | AL1: 2Q28 | AM1: 3Q28 | AN1: 4Q28 | AO1: 2028
A2: 가정 시계열 — 노란 셀은 추정 가정(모델값에서 역산), 연녹 셀은 3절 스칼라 참조 수식. 바꾸면 subQ·분기·연간예상·TP·시나리오가 재계산됩니다.
E3: 1 | F3: 2 | G3: 3 | H3: 4 | I3: 5 | J3: 6 | K3: 7 | L3: 8 | M3: 9 | N3: 10 | O3: 11 | P3: 12 | Q3: 13 | R3: 14 | S3: 15 | T3: 16 | U3: 17 | V3: 18 | W3: 19 | X3: 20 | Y3: 21 | Z3: 22 | AA3: 23 | AB3: 24 | AC3: 25 | AD3: 26 | AE3: 27 | AF3: 28 | AG3: 29 | AH3: 30 | AI3: 31 | AJ3: 32 | AK3: 33 | AL3: 34 | AM3: 35 | AN3: 36 | AO3: 37
E4: 2021.12 | F4: 2021.12A | G4: 2022.03 | H4: 2022.06 | I4: 2022.09 | J4: 2022.12 | K4: 2022.12A | L4: 2023.03 | M4: 2023.06 | N4: 2023.09 | O4: 2023.12 | P4: 2023.12A | Q4: 2024.03 | R4: 2024.06 | S4: 2024.09 | T4: 2024.12 | U4: 2024.12A | V4: 2025.03 | W4: 2025.06 | X4: 2025.09 | Y4: 2025.12 | Z4: 2025.12A | AA4: 2026.03 | AB4: 2026.06 | AC4: 2026.09 | AD4: 2026.12 | AE4: 2026.12A | AF4: 2027.03 | AG4: 2027.06 | AH4: 2027.09 | AI4: 2027.12 | AJ4: 2027.12A | AK4: 2028.03 | AL4: 2028.06 | AM4: 2028.09 | AN4: 2028.12 | AO4: 2028.12A
B5: 1. FX | C5: 이름: 환율
A6: USDKRW_avg | C6: 원/달러(평균) | E6: 1183.5 | F6: 1145.51 | G6: 1205.78 | H6: 1262.09 | I6: 1341.93 | J6: 1360.12 | K6: 1292.98 | L6: 1276.95 | M6: 1315.69 | N6: 1313.62 | O6: 1322.01 | P6: 1306.85 | Q6: 1330.14 | R6: 1371.28 | S6: 1356.22 | T6: 1396.3 | U6: 1363.53 | V6: 1452.28 | W6: 1398.52 | X6: 1386.95 | Y6: 1449.19 | Z6: 1421.52 | AA6: 1466.12 | AB6: 1501.75 | AC6: 1418.75 | AD6: 1345.14 | AE6: 1457.21 | AF6: 1341.49 | AG6: 1341.49 | AH6: 1341.49 | AI6: 1341.49 | AK6: 1341.49 | AL6: 1341.49 | AM6: 1341.49 | AN6: 1341.49
A7: USDKRW_end | C7: 원/달러(기말) | E7: 1188.75 | F7: 1188.75 | G7: 1213.74 | H7: 1301.24 | I7: 1436.9 | J7: 1260.16 | K7: 1260.16 | L7: 1305.99 | M7: 1321.44 | N7: 1345.35 | O7: 1297.43 | P7: 1297.43 | Q7: 1349.25 | R7: 1377.73 | S7: 1312.17 | T7: 1474.78 | U7: 1474.78 | V7: 1474.54 | W7: 1355.13 | X7: 1403.67 | Y7: 1444.2 | Z7: 1444.2 | AA7: 1524.8 | AB7: 1550.89 | AC7: 1355.4 | AD7: 1341.49 | AE7: 1341.49 | AF7: 1341.49 | AG7: 1341.49 | AH7: 1341.49 | AI7: 1341.49 | AK7: 1341.49 | AL7: 1341.49 | AM7: 1341.49 | AN7: 1341.49
A8: JPY100KRW_avg | C8: 원/100Y(평균) | E8: 1041.02 | F8: 1042.74 | G8: 1036.79 | H8: 972.23 | I8: 970.61 | J8: 961.03 | K8: 985.1 | L8: 964.89 | M8: 957.36 | N8: 909 | O8: 893.22 | P8: 931.11 | Q8: 896.29 | R8: 880.14 | S8: 909.35 | T8: 917.25 | U8: 900.92 | V8: 952.59 | W8: 967.92 | X8: 940.32 | Y8: 940.77 | Z8: 950.17 | AA8: 934.39 | AB8: 942.16 | AC8: 890.41 | AD8: 850.79 | AE8: 919.21 | AF8: 847.7 | AG8: 847.7 | AH8: 847.7 | AI8: 847.7 | AK8: 847.7 | AL8: 847.7 | AM8: 847.7 | AN8: 847.7
A9: JPY100KRW_end | C9: 원/100Y(기말) | E9: 1032.62 | F9: 1032.62 | G9: 996.83 | H9: 954.9 | I9: 993.29 | J9: 955.54 | K9: 955.54 | L9: 980.62 | M9: 913.67 | N9: 901.47 | O9: 917.04 | P9: 917.04 | Q9: 892.42 | R9: 857.76 | S9: 919.21 | T9: 939.65 | U9: 939.65 | V9: 986.84 | W9: 938.85 | X9: 948.49 | Y9: 921.81 | Z9: 921.81 | AA9: 955.99 | AB9: 954.75 | AC9: 863.31 | AD9: 847.7 | AE9: 847.7 | AF9: 847.7 | AG9: 847.7 | AH9: 847.7 | AI9: 847.7 | AK9: 847.7 | AL9: 847.7 | AM9: 847.7 | AN9: 847.7
A10: EURKRW_avg | C10: W/Euro(평균) | E10: 1353.32 | F10: 1354.06 | G10: 1352.29 | H10: 1343.31 | I10: 1350.63 | J10: 1386.07 | K10: 1358.07 | L10: 1369.93 | M10: 1432.41 | N10: 1429.41 | O10: 1420.91 | P10: 1412.88 | Q10: 1444.21 | R10: 1476.42 | S10: 1489.3 | T10: 1490.78 | U10: 1475.4 | V10: 1528.33 | W10: 1585.13 | X10: 1620.04 | Y10: 1686.02 | Z10: 1605.45 | AA10: 1715.47 | AB10: 1746.09 | AC10: 1631.97 | AD10: 1509.74 | AE10: 1689.95 | AF10: 1503.27 | AG10: 1503.27 | AH10: 1503.27 | AI10: 1503.27 | AK10: 1503.27 | AL10: 1503.27 | AM10: 1503.27 | AN10: 1503.27
A11: EURKRW_end | C11: W/Euro(기말) | E11: 1346.38 | F11: 1346.38 | G11: 1347.37 | H11: 1351.6 | I11: 1400.62 | J11: 1344.08 | K11: 1344.08 | L11: 1420.26 | M11: 1435.88 | N11: 1425.26 | O11: 1433.66 | P11: 1433.66 | Q11: 1458.68 | R11: 1474.86 | S11: 1469.1 | T11: 1532.14 | U11: 1532.14 | V11: 1594.72 | W11: 1588.22 | X11: 1648.04 | Y11: 1696.94 | Z11: 1696.94 | AA11: 1753.21 | AB11: 1767.09 | AC11: 1539.06 | AD11: 1503.27 | AE11: 1503.27 | AF11: 1503.27 | AG11: 1503.27 | AH11: 1503.27 | AI11: 1503.27 | AK11: 1503.27 | AL11: 1503.27 | AM11: 1503.27 | AN11: 1503.27
A12: CNYKRW_avg | C12: 원/중국원(평균) | E12: 185.14 | F12: 177.65 | G12: 189.93 | H12: 190.76 | I12: 195.79 | J12: 191.09 | K12: 191.93 | L12: 186.59 | M12: 187.45 | N12: 181.28 | O12: 182.86 | P12: 184.52 | Q12: 185.04 | R12: 189.35 | S12: 189.24 | T12: 194.24 | U12: 189.49 | V12: 199.63 | W12: 193.41 | X12: 193.79 | Y12: 204.38 | Z12: 197.8 | AA12: 211.75 | AB12: 220.8 | AC12: 210.43 | AD12: 200.69 | AE12: 213.75 | AF12: 200.46 | AG12: 200.46 | AH12: 200.46 | AI12: 200.46 | AK12: 200.46 | AL12: 200.46 | AM12: 200.46 | AN12: 200.46
A13: CNYKRW_end | C13: 원/중국원(기말) | E13: 187.13 | F13: 187.13 | G13: 191.38 | H13: 194.13 | I13: 201.92 | J13: 182.67 | K13: 182.67 | L13: 189.97 | M13: 181.8 | N13: 184.26 | O13: 182.61 | P13: 182.61 | Q13: 186.66 | R13: 189.7 | S13: 187.12 | T13: 202.04 | U13: 202.04 | V13: 203.3 | W13: 189.14 | X13: 197.16 | Y13: 206.28 | Z13: 206.28 | AA13: 220.97 | AB13: 228.56 | AC13: 202.16 | AD13: 200.46 | AE13: 200.46 | AF13: 200.46 | AG13: 200.46 | AH13: 200.46 | AI13: 200.46 | AK13: 200.46 | AL13: 200.46 | AM13: 200.46 | AN13: 200.46
B14: 1b. 종가
A15: price_close_end | C15: 종가(기말) | E15: 20478 | G15: 22032 | H15: 21322 | I15: 16835 | J15: 16835 | L15: 21766 | M15: 33493 | N15: 30950 | O15: 25100 | Q15: 27600 | R15: 30550 | S15: 30550 | T15: 37350 | V15: 67100 | W15: 79400 | X15: 110300 | Y15: 113600 | AA15: 120200 | AB15: 100300 | AC15: 78800 | AD15: 67100
A16: price_high | C16: 종가(최고) | E16: 24298 | G16: 25453 | H16: 25764 | I16: 23098 | J16: 18923 | L16: 24164 | M16: 35980 | N16: 44332 | O16: 30900 | Q16: 30900 | R16: 36400 | S16: 35300 | T16: 41050 | V16: 87200 | W16: 95800 | X16: 123800 | Y16: 151600 | AA16: 154800 | AB16: 141900 | AC16: 123000 | AD16: 79200
A17: price_low | C17: 종가(최저) | E17: 19856 | G17: 16258 | H17: 17412 | I17: 16169 | J17: 15325 | L17: 15636 | M17: 21677 | N17: 29000 | O17: 21900 | Q17: 21050 | R17: 24850 | S17: 25400 | T17: 26100 | V17: 36300 | W17: 62350 | X17: 71500 | Y17: 99600 | AA17: 108500 | AB17: 95500 | AC17: 71300 | AD17: 67000
A18: price_avg | C18: 종가(평균) | E18: 21658.5 | G18: 20964 | H18: 20935.4 | I18: 18116.1 | J18: 16754.1 | L18: 20254.7 | M18: 25770.2 | N18: 35815.9 | O18: 25825.8 | Q18: 24048.4 | R18: 30870 | S18: 31184.7 | T18: 33018 | V18: 64850 | W18: 79135 | X18: 101701.5 | Y18: 118854.2 | AA18: 133781.4 | AB18: 121616.4 | AC18: 86733.9 | AD18: 74650
B20: 2. 추정 드라이버 | C20: 실적 열 = subQ 실현값(수식), 추정 열 = 가정(노란 = 모델값 역산, 연녹 = 3절 스칼라 참조)
A21: drv:판관비 | B21: ratio | C21: 판관비율(/매출) | E21: =IFERROR(subQ!E8/subQ!E5,"") | F21: =IFERROR(subQ!F8/subQ!F5,"") | G21: =IFERROR(subQ!G8/subQ!G5,"") | H21: =IFERROR(subQ!H8/subQ!H5,"") | I21: =IFERROR(subQ!I8/subQ!I5,"") | J21: =IFERROR(subQ!J8/subQ!J5,"") | K21: =IFERROR(subQ!K8/subQ!K5,"") | L21: =IFERROR(subQ!L8/subQ!L5,"") | ... AB21: =IFERROR(subQ!AB8/subQ!AB5,"") | AC21: =$D$55 | AD21: =$D$55 | AE21: =IFERROR(subQ!AE8/subQ!AE5,"") | AF21: =$D$55 | AG21: =$D$55 | AH21: =$D$55 | AI21: =$D$55 | AJ21: =IFERROR(subQ!AJ8/subQ!AJ5,"") | AK21: =$D$55 | AL21: =$D$55 | AM21: =$D$55 | AN21: =$D$55 | AO21: =IFERROR(subQ!AO8/subQ!AO5,"")
A22: drv:외환손익 | B22: abs | C22: 외환손익 (가정, 억원) | E22: =subQ!E13 | F22: =subQ!F13 | G22: =subQ!G13 | H22: =subQ!H13 | I22: =subQ!I13 | J22: =subQ!J13 | K22: =subQ!K13 | L22: =subQ!L13 | ... AB22: =subQ!AB13 | AC22: 0 | AD22: 0 | AE22: =subQ!AE13 | AF22: 0 | AG22: 0 | AH22: 0 | AI22: 0 | AJ22: =subQ!AJ13 | AK22: 0 | AL22: 0 | AM22: 0 | AN22: 0 | AO22: =subQ!AO13
A23: drv:파생상품손익 | B23: abs | C23: 파생상품손익 (가정, 억원) | E23: =subQ!E14 | F23: =subQ!F14 | G23: =subQ!G14 | H23: =subQ!H14 | I23: =subQ!I14 | J23: =subQ!J14 | K23: =subQ!K14 | L23: =subQ!L14 | ... AB23: =subQ!AB14 | AC23: 0 | AD23: 0 | AE23: =subQ!AE14 | AF23: 0 | AG23: 0 | AH23: 0 | AI23: 0 | AJ23: =subQ!AJ14 | AK23: 0 | AL23: 0 | AM23: 0 | AN23: 0 | AO23: =subQ!AO14
A24: drv:기타금융손익 | B24: abs | C24: 기타금융손익 (가정, 억원) | E24: =subQ!E15 | F24: =subQ!F15 | G24: =subQ!G15 | H24: =subQ!H15 | I24: =subQ!I15 | J24: =subQ!J15 | K24: =subQ!K15 | L24: =subQ!L15 | ... AB24: =subQ!AB15 | AC24: 2.92 | AD24: 2.92 | AE24: =subQ!AE15 | AF24: 2.92 | AG24: 2.92 | AH24: 2.92 | AI24: 2.92 | AJ24: =subQ!AJ15 | AK24: 2.92 | AL24: 2.92 | AM24: 2.92 | AN24: 2.92 | AO24: =subQ!AO15
A25: drv:기타영업외손익 | B25: abs | C25: 기타영업외손익 (가정, 억원) | E25: =subQ!E16 | F25: =subQ!F16 | G25: =subQ!G16 | H25: =subQ!H16 | I25: =subQ!I16 | J25: =subQ!J16 | K25: =subQ!K16 | L25: =subQ!L16 | ... AB25: =subQ!AB16 | AC25: 0 | AD25: 0 | AE25: =subQ!AE16 | AF25: 0 | AG25: 0 | AH25: 0 | AI25: 0 | AJ25: =subQ!AJ16 | AK25: 0 | AL25: 0 | AM25: 0 | AN25: 0 | AO25: =subQ!AO16
A26: drv:지분법손익 | B26: abs | C26: 지분법손익 (가정, 억원) | E26: =subQ!E17 | F26: =subQ!F17 | G26: =subQ!G17 | H26: =subQ!H17 | I26: =subQ!I17 | J26: =subQ!J17 | K26: =subQ!K17 | L26: =subQ!L17 | ... AB26: =subQ!AB17 | AC26: -447.53 | AD26: -447.53 | AE26: =subQ!AE17 | AF26: -447.53 | AG26: -447.53 | AH26: -447.53 | AI26: -447.53 | AJ26: =subQ!AJ17 | AK26: -447.53 | AL26: -447.53 | AM26: -447.53 | AN26: -447.53 | AO26: =subQ!AO17
A27: drv:법인세비용 | B27: tax | C27: 법인세율(/세전) — 법인세 = MAX(세전,0) × 분기별 세율(이월결손 램프, assumptions.tax_schedule) | E27: =IFERROR(subQ!E19/subQ!E18,"") | F27: =IFERROR(subQ!F19/subQ!F18,"") | G27: =IFERROR(subQ!G19/subQ!G18,"") | H27: =IFERROR(subQ!H19/subQ!H18,"") | I27: =IFERROR(subQ!I19/subQ!I18,"") | J27: =IFERROR(subQ!J19/subQ!J18,"") | K27: =IFERROR(subQ!K19/subQ!K18,"") | L27: =IFERROR(subQ!L19/subQ!L18,"") | ... AB27: =IFERROR(subQ!AB19/subQ!AB18,"") | AC27: 0.006752619 | AD27: 0.006754059 | AE27: =IFERROR(subQ!AE19/subQ!AE18,"") | AF27: 0.033408819 | AG27: 0.060065587 | AH27: 0.086720205 | AI27: 0.11337725 | AJ27: =IFERROR(subQ!AJ19/subQ!AJ18,"") | AK27: 0.14003202 | AL27: 0.16668801 | AM27: 0.19334419 | AN27: 0.21999949 | AO27: =IFERROR(subQ!AO19/subQ!AO18,"")
A28: drv:지배주주순이익 | B28: ratio | C28: 지배주주 비중(/당기순이익) | E28: =IFERROR(subQ!E21/subQ!E20,"") | F28: =IFERROR(subQ!F21/subQ!F20,"") | G28: =IFERROR(subQ!G21/subQ!G20,"") | H28: =IFERROR(subQ!H21/subQ!H20,"") | I28: =IFERROR(subQ!I21/subQ!I20,"") | J28: =IFERROR(subQ!J21/subQ!J20,"") | K28: =IFERROR(subQ!K21/subQ!K20,"") | L28: =IFERROR(subQ!L21/subQ!L20,"") | ... AB28: =IFERROR(subQ!AB21/subQ!AB20,"") | AC28: =$D$56 | AD28: =$D$56 | AE28: =IFERROR(subQ!AE21/subQ!AE20,"") | AF28: =$D$56 | AG28: =$D$56 | AH28: =$D$56 | AI28: =$D$56 | AJ28: =IFERROR(subQ!AJ21/subQ!AJ20,"") | AK28: =$D$56 | AL28: =$D$56 | AM28: =$D$56 | AN28: =$D$56 | AO28: =IFERROR(subQ!AO21/subQ!AO20,"")
A29: drv:부채총계 | B29: qoq | C29: 부채총계 QoQ | G29: =IFERROR(subQ!G23/subQ!E23-1,"") | H29: =IFERROR(subQ!H23/subQ!G23-1,"") | I29: =IFERROR(subQ!I23/subQ!H23-1,"") | J29: =IFERROR(subQ!J23/subQ!I23-1,"") | L29: =IFERROR(subQ!L23/subQ!J23-1,"") | M29: =IFERROR(subQ!M23/subQ!L23-1,"") | N29: =IFERROR(subQ!N23/subQ!M23-1,"") | O29: =IFERROR(subQ!O23/subQ!N23-1,"") | Q29: =IFERROR(subQ!Q23/subQ!O23-1,"") | R29: =IFERROR(subQ!R23/subQ!Q23-1,"") | S29: =IFERROR(subQ!S23/subQ!R23-1,"") | T29: =IFERROR(subQ!T23/subQ!S23-1,"") | V29: =IFERROR(subQ!V23/subQ!T23-1,"") | W29: =IFERROR(subQ!W23/subQ!V23-1,"") | X29: =IFERROR(subQ!X23/subQ!W23-1,"") | Y29: =IFERROR(subQ!Y23/subQ!X23-1,"") | AA29: =IFERROR(subQ!AA23/subQ!Y23-1,"") | AB29: =IFERROR(subQ!AB23/subQ!AA23-1,"") | AC29: 3.9e-08 | AD29: 0 | AF29: 0 | AG29: 0 | AH29: 0 | AI29: 0 | AK29: 0 | AL29: 0 | AM29: 0 | AN29: 0
A30: drv:자본총계 | B30: roll | C30: 자본총계 기타변동(배당 등, 억원) | G30: =IFERROR(subQ!E24+subQ!G20-subQ!G24,"") | H30: =IFERROR(subQ!G24+subQ!H20-subQ!H24,"") | I30: =IFERROR(subQ!H24+subQ!I20-subQ!I24,"") | J30: =IFERROR(subQ!I24+subQ!J20-subQ!J24,"") | L30: =IFERROR(subQ!J24+subQ!L20-subQ!L24,"") | M30: =IFERROR(subQ!L24+subQ!M20-subQ!M24,"") | N30: =IFERROR(subQ!M24+subQ!N20-subQ!N24,"") | O30: =IFERROR(subQ!N24+subQ!O20-subQ!O24,"") | Q30: =IFERROR(subQ!O24+subQ!Q20-subQ!Q24,"") | R30: =IFERROR(subQ!Q24+subQ!R20-subQ!R24,"") | S30: =IFERROR(subQ!R24+subQ!S20-subQ!S24,"") | T30: =IFERROR(subQ!S24+subQ!T20-subQ!T24,"") | V30: =IFERROR(subQ!T24+subQ!V20-subQ!V24,"") | W30: =IFERROR(subQ!V24+subQ!W20-subQ!W24,"") | X30: =IFERROR(subQ!W24+subQ!X20-subQ!X24,"") | Y30: =IFERROR(subQ!X24+subQ!Y20-subQ!Y24,"") | AA30: =IFERROR(subQ!Y24+subQ!AA20-subQ!AA24,"") | AB30: =IFERROR(subQ!AA24+subQ!AB20-subQ!AB24,"") | AC30: -0.01662006 | AD30: -0.010357283 | AF30: 0.004744529 | AG30: -0.015303061 | AH30: -0.008136676 | AI30: -0.006513659 | AK30: -0.003354116 | AL30: 0.001469314 | AM30: 3.5952e-05 | AN30: -0.001256641
A31: drv:지배주주지분 | B31: roll | C31: 지배주주지분 기타변동(배당 등, 억원) | G31: =IFERROR(subQ!E25+subQ!G21-subQ!G25,"") | H31: =IFERROR(subQ!G25+subQ!H21-subQ!H25,"") | I31: =IFERROR(subQ!H25+subQ!I21-subQ!I25,"") | J31: =IFERROR(subQ!I25+subQ!J21-subQ!J25,"") | L31: =IFERROR(subQ!J25+subQ!L21-subQ!L25,"") | M31: =IFERROR(subQ!L25+subQ!M21-subQ!M25,"") | N31: =IFERROR(subQ!M25+subQ!N21-subQ!N25,"") | O31: =IFERROR(subQ!N25+subQ!O21-subQ!O25,"") | Q31: =IFERROR(subQ!O25+subQ!Q21-subQ!Q25,"") | R31: =IFERROR(subQ!Q25+subQ!R21-subQ!R25,"") | S31: =IFERROR(subQ!R25+subQ!S21-subQ!S25,"") | T31: =IFERROR(subQ!S25+subQ!T21-subQ!T25,"") | V31: =IFERROR(subQ!T25+subQ!V21-subQ!V25,"") | W31: =IFERROR(subQ!V25+subQ!W21-subQ!W25,"") | X31: =IFERROR(subQ!W25+subQ!X21-subQ!X25,"") | Y31: =IFERROR(subQ!X25+subQ!Y21-subQ!Y25,"") | AA31: =IFERROR(subQ!Y25+subQ!AA21-subQ!AA25,"") | AB31: =IFERROR(subQ!AA25+subQ!AB21-subQ!AB25,"") | AC31: -0.009763957 | AD31: -0.0078098 | AF31: -0.000155394 | AG31: -0.013661483 | AH31: -0.003030048 | AI31: 0.001194955 | AK31: -0.003740682 | AL31: 0.002175579 | AM31: 0.004347552 | AN31: 0.004252885
A32: drv:총차입금 | B32: qoq | C32: 총차입금 QoQ | G32: =IFERROR(subQ!G26/subQ!E26-1,"") | H32: =IFERROR(subQ!H26/subQ!G26-1,"") | I32: =IFERROR(subQ!I26/subQ!H26-1,"") | J32: =IFERROR(subQ!J26/subQ!I26-1,"") | L32: =IFERROR(subQ!L26/subQ!J26-1,"") | M32: =IFERROR(subQ!M26/subQ!L26-1,"") | N32: =IFERROR(subQ!N26/subQ!M26-1,"") | O32: =IFERROR(subQ!O26/subQ!N26-1,"") | Q32: =IFERROR(subQ!Q26/subQ!O26-1,"") | R32: =IFERROR(subQ!R26/subQ!Q26-1,"") | S32: =IFERROR(subQ!S26/subQ!R26-1,"") | T32: =IFERROR(subQ!T26/subQ!S26-1,"") | V32: =IFERROR(subQ!V26/subQ!T26-1,"") | W32: =IFERROR(subQ!W26/subQ!V26-1,"") | X32: =IFERROR(subQ!X26/subQ!W26-1,"") | Y32: =IFERROR(subQ!Y26/subQ!X26-1,"") | AA32: =IFERROR(subQ!AA26/subQ!Y26-1,"") | AB32: =IFERROR(subQ!AB26/subQ!AA26-1,"") | AC32: 8e-09 | AD32: 0 | AF32: 0 | AG32: 0 | AH32: 0 | AI32: 0 | AK32: 0 | AL32: 0 | AM32: 0 | AN32: 0
A33: drv:순차입금 | B33: qoq | C33: 순차입금 QoQ | G33: =IFERROR(subQ!G27/subQ!E27-1,"") | H33: =IFERROR(subQ!H27/subQ!G27-1,"") | I33: =IFERROR(subQ!I27/subQ!H27-1,"") | J33: =IFERROR(subQ!J27/subQ!I27-1,"") | L33: =IFERROR(subQ!L27/subQ!J27-1,"") | M33: =IFERROR(subQ!M27/subQ!L27-1,"") | N33: =IFERROR(subQ!N27/subQ!M27-1,"") | O33: =IFERROR(subQ!O27/subQ!N27-1,"") | Q33: =IFERROR(subQ!Q27/subQ!O27-1,"") | R33: =IFERROR(subQ!R27/subQ!Q27-1,"") | S33: =IFERROR(subQ!S27/subQ!R27-1,"") | T33: =IFERROR(subQ!T27/subQ!S27-1,"") | V33: =IFERROR(subQ!V27/subQ!T27-1,"") | W33: =IFERROR(subQ!W27/subQ!V27-1,"") | X33: =IFERROR(subQ!X27/subQ!W27-1,"") | Y33: =IFERROR(subQ!Y27/subQ!X27-1,"") | AA33: =IFERROR(subQ!AA27/subQ!Y27-1,"") | AB33: =IFERROR(subQ!AB27/subQ!AA27-1,"") | AC33: -0.091654624 | AD33: -0.10459747 | AF33: -0.11479349 | AG33: -0.13277575 | AH33: -0.159848 | AI33: -0.19934754 | AK33: -0.26140158 | AL33: -0.26855885 | AM33: -0.27173449 | AN33: -0.40744694
A34: drv:이자발생자산 | B34: qoq | C34: 이자발생자산 QoQ | G34: =IFERROR(subQ!G28/subQ!E28-1,"") | H34: =IFERROR(subQ!H28/subQ!G28-1,"") | I34: =IFERROR(subQ!I28/subQ!H28-1,"") | J34: =IFERROR(subQ!J28/subQ!I28-1,"") | L34: =IFERROR(subQ!L28/subQ!J28-1,"") | M34: =IFERROR(subQ!M28/subQ!L28-1,"") | N34: =IFERROR(subQ!N28/subQ!M28-1,"") | O34: =IFERROR(subQ!O28/subQ!N28-1,"") | Q34: =IFERROR(subQ!Q28/subQ!O28-1,"") | R34: =IFERROR(subQ!R28/subQ!Q28-1,"") | S34: =IFERROR(subQ!S28/subQ!R28-1,"") | T34: =IFERROR(subQ!T28/subQ!S28-1,"") | V34: =IFERROR(subQ!V28/subQ!T28-1,"") | W34: =IFERROR(subQ!W28/subQ!V28-1,"") | X34: =IFERROR(subQ!X28/subQ!W28-1,"") | Y34: =IFERROR(subQ!Y28/subQ!X28-1,"") | AA34: =IFERROR(subQ!AA28/subQ!Y28-1,"") | AB34: =IFERROR(subQ!AB28/subQ!AA28-1,"") | AC34: 0.23515572 | AD34: 0.19735658 | AF34: 0.16197297 | AG34: 0.14272255 | AH34: 0.13039822 | AI34: 0.12086533 | AK34: 0.11321104 | AL34: 0.077170791 | AM34: 0.053021488 | AN34: 0.054983289
A35: drv:현금및현금성자산 | B35: qoq | C35: 현금및현금성자산 QoQ | G35: =IFERROR(subQ!G29/subQ!E29-1,"") | H35: =IFERROR(subQ!H29/subQ!G29-1,"") | I35: =IFERROR(subQ!I29/subQ!H29-1,"") | J35: =IFERROR(subQ!J29/subQ!I29-1,"") | L35: =IFERROR(subQ!L29/subQ!J29-1,"") | M35: =IFERROR(subQ!M29/subQ!L29-1,"") | N35: =IFERROR(subQ!N29/subQ!M29-1,"") | O35: =IFERROR(subQ!O29/subQ!N29-1,"") | Q35: =IFERROR(subQ!Q29/subQ!O29-1,"") | R35: =IFERROR(subQ!R29/subQ!Q29-1,"") | S35: =IFERROR(subQ!S29/subQ!R29-1,"") | T35: =IFERROR(subQ!T29/subQ!S29-1,"") | V35: =IFERROR(subQ!V29/subQ!T29-1,"") | W35: =IFERROR(subQ!W29/subQ!V29-1,"") | X35: =IFERROR(subQ!X29/subQ!W29-1,"") | Y35: =IFERROR(subQ!Y29/subQ!X29-1,"") | AA35: =IFERROR(subQ!AA29/subQ!Y29-1,"") | AB35: =IFERROR(subQ!AB29/subQ!AA29-1,"")
A36: drv:CAPEX | B36: yoy | C36: CAPEX YoY | J36: =IFERROR(subQ!J30/subQ!E30-1,"") | L36: =IFERROR(subQ!L30/subQ!G30-1,"") | M36: =IFERROR(subQ!M30/subQ!H30-1,"") | N36: =IFERROR(subQ!N30/subQ!I30-1,"") | O36: =IFERROR(subQ!O30/subQ!J30-1,"") | Q36: =IFERROR(subQ!Q30/subQ!L30-1,"") | R36: =IFERROR(subQ!R30/subQ!M30-1,"") | S36: =IFERROR(subQ!S30/subQ!N30-1,"") | T36: =IFERROR(subQ!T30/subQ!O30-1,"") | V36: =IFERROR(subQ!V30/subQ!Q30-1,"") | W36: =IFERROR(subQ!W30/subQ!R30-1,"") | X36: =IFERROR(subQ!X30/subQ!S30-1,"") | Y36: =IFERROR(subQ!Y30/subQ!T30-1,"") | AA36: =IFERROR(subQ!AA30/subQ!V30-1,"") | AB36: =IFERROR(subQ!AB30/subQ!W30-1,"") | AC36: -0.078054236 | AD36: -0.32138768 | AF36: 1.0178982 | AG36: 0.092489521 | AH36: 0 | AI36: 0 | AK36: 0 | AL36: 0 | AM36: 0 | AN36: 0
A37: drv:영업활동현금흐름 | B37: yoy | C37: 영업활동현금흐름 YoY | J37: =IFERROR(subQ!J31/subQ!E31-1,"") | L37: =IFERROR(subQ!L31/subQ!G31-1,"") | M37: =IFERROR(subQ!M31/subQ!H31-1,"") | N37: =IFERROR(subQ!N31/subQ!I31-1,"") | O37: =IFERROR(subQ!O31/subQ!J31-1,"") | Q37: =IFERROR(subQ!Q31/subQ!L31-1,"") | R37: =IFERROR(subQ!R31/subQ!M31-1,"") | S37: =IFERROR(subQ!S31/subQ!N31-1,"") | T37: =IFERROR(subQ!T31/subQ!O31-1,"") | V37: =IFERROR(subQ!V31/subQ!Q31-1,"") | W37: =IFERROR(subQ!W31/subQ!R31-1,"") | X37: =IFERROR(subQ!X31/subQ!S31-1,"") | Y37: =IFERROR(subQ!Y31/subQ!T31-1,"") | AA37: =IFERROR(subQ!AA31/subQ!V31-1,"") | AB37: =IFERROR(subQ!AB31/subQ!W31-1,"")
A38: drv:주식수 | B38: qoq | C38: 주식수 QoQ | G38: =IFERROR(subQ!G32/subQ!E32-1,"") | H38: =IFERROR(subQ!H32/subQ!G32-1,"") | I38: =IFERROR(subQ!I32/subQ!H32-1,"") | J38: =IFERROR(subQ!J32/subQ!I32-1,"") | L38: =IFERROR(subQ!L32/subQ!J32-1,"") | M38: =IFERROR(subQ!M32/subQ!L32-1,"") | N38: =IFERROR(subQ!N32/subQ!M32-1,"") | O38: =IFERROR(subQ!O32/subQ!N32-1,"") | Q38: =IFERROR(subQ!Q32/subQ!O32-1,"") | R38: =IFERROR(subQ!R32/subQ!Q32-1,"") | S38: =IFERROR(subQ!S32/subQ!R32-1,"") | T38: =IFERROR(subQ!T32/subQ!S32-1,"") | V38: =IFERROR(subQ!V32/subQ!T32-1,"") | W38: =IFERROR(subQ!W32/subQ!V32-1,"") | X38: =IFERROR(subQ!X32/subQ!W32-1,"") | Y38: =IFERROR(subQ!Y32/subQ!X32-1,"") | AA38: =IFERROR(subQ!AA32/subQ!Y32-1,"") | AB38: =IFERROR(subQ!AB32/subQ!AA32-1,"") | AC38: 0 | AD38: 0 | AF38: 0 | AG38: 0 | AH38: 0 | AI38: 0 | AK38: 0 | AL38: 0 | AM38: 0 | AN38: 0
A39: drv:DPS | B39: abs | C39: DPS (가정, 원) | E39: =subQ!E35 | F39: =subQ!F35 | G39: =subQ!G35 | H39: =subQ!H35 | I39: =subQ!I35 | J39: =subQ!J35 | K39: =subQ!K35 | L39: =subQ!L35 | ... AB39: =subQ!AB35 | AD39: 0 | AE39: =subQ!AE35 | AI39: 0 | AJ39: =subQ!AJ35 | AN39: 0 | AO39: =subQ!AO35
A40: drv:매출조선 | B40: sls_link | C40: 원장 밖 잔고 소진(억원) — 매출조선 = SLS 원화/100 + 이 행 + 매출조선신규 | E40: =IFERROR(subQ!E38-SLS!O107/100,"") | G40: =IFERROR(subQ!G38-SLS!P107/100,"") | H40: =IFERROR(subQ!H38-SLS!Q107/100,"") | I40: =IFERROR(subQ!I38-SLS!R107/100,"") | J40: =IFERROR(subQ!J38-SLS!S107/100,"") | L40: =IFERROR(subQ!L38-SLS!T107/100,"") | M40: =IFERROR(subQ!M38-SLS!U107/100,"") | N40: =IFERROR(subQ!N38-SLS!V107/100,"") | O40: =IFERROR(subQ!O38-SLS!W107/100,"") | Q40: =IFERROR(subQ!Q38-SLS!X107/100,"") | R40: =IFERROR(subQ!R38-SLS!Y107/100,"") | S40: =IFERROR(subQ!S38-SLS!Z107/100,"") | T40: =IFERROR(subQ!T38-SLS!AA107/100,"") | V40: =IFERROR(subQ!V38-SLS!AB107/100,"") | W40: =IFERROR(subQ!W38-SLS!AC107/100,"") | X40: =IFERROR(subQ!X38-SLS!AD107/100,"") | Y40: =IFERROR(subQ!Y38-SLS!AE107/100,"") | AA40: =IFERROR(subQ!AA38-SLS!AF107/100,"") | AB40: =IFERROR(subQ!AB38-SLS!AG107/100,"") | AC40: 27459.151 | AD40: 29203.284 | AF40: 29130.658 | AG40: 29163.549 | AH40: 29196.571 | AI40: 29196.566 | AK40: 29163.558 | AL40: 15338.36 | AM40: 3035.4749 | AN40: 3035.5571
A41: drv:매출조선신규 | B41: abs | C41: 매출조선신규 (forecast_panel base · 공시 상계 신규수주 매출, 억원 — 가정) | E41: =subQ!E39 | F41: =subQ!F39 | G41: =subQ!G39 | H41: =subQ!H39 | I41: =subQ!I39 | J41: =subQ!J39 | K41: =subQ!K39 | L41: =subQ!L39 | ... AB41: =subQ!AB39 | AC41: 0 | AD41: 0 | AE41: =subQ!AE39 | AF41: 525.42 | AG41: 1989.58 | AH41: 4224.28 | AI41: 7061.37 | AJ41: =subQ!AJ39 | AK41: 10332.65 | AL41: 13869.95 | AM41: 17505.09 | AN41: 21069.91 | AO41: =subQ!AO39
...

Sheet BS연결
B1: (백만원) | C1: 이름: BS연결H | E1: 4Q21 | F1: 2021 | G1: 1Q22 | H1: 2Q22 | I1: 3Q22 | J1: 4Q22 | K1: 2022 | L1: 1Q23 | M1: 2Q23 | N1: 3Q23 | O1: 4Q23 | P1: 2023 | Q1: 1Q24 | R1: 2Q24 | S1: 3Q24 | T1: 4Q24 | U1: 2024 | V1: 1Q25 | W1: 2Q25 | X1: 3Q25 | Y1: 4Q25 | Z1: 2025 | AA1: 1Q26 | AB1: 2Q26 | AC1: 3Q26 | AD1: 4Q26 | AE1: 2026 | AF1: 1Q27 | AG1: 2Q27 | AH1: 3Q27 | AI1: 4Q27 | AJ1: 2027 | AK1: 1Q28 | AL1: 2Q28 | AM1: 3Q28 | AN1: 4Q28 | AO1: 2028
B2: 연결 | D2: fin json(kship_fin.py)
B3: 한화오션(연) | C3: UPDATE: 26-10-12 | E3: 1 | F3: 2 | G3: 3 | H3: 4 | I3: 5 | J3: 6 | K3: 7 | L3: 8 | M3: 9 | N3: 10 | O3: 11 | P3: 12 | Q3: 13 | R3: 14 | S3: 15 | T3: 16 | U3: 17 | V3: 18 | W3: 19 | X3: 20 | Y3: 21 | Z3: 22 | AA3: 23 | AB3: 24 | AC3: 25 | AD3: 26 | AE3: 27 | AF3: 28 | AG3: 29 | AH3: 30 | AI3: 31 | AJ3: 32 | AK3: 33 | AL3: 34 | AM3: 35 | AN3: 36 | AO3: 37
B4: Account Code | C4: AccountNAME | E4: 2021.12 | F4: 2021.12A | G4: 2022.03 | H4: 2022.06 | I4: 2022.09 | J4: 2022.12 | K4: 2022.12A | L4: 2023.03 | M4: 2023.06 | N4: 2023.09 | O4: 2023.12 | P4: 2023.12A | Q4: 2024.03 | R4: 2024.06 | S4: 2024.09 | T4: 2024.12 | U4: 2024.12A | V4: 2025.03 | W4: 2025.06 | X4: 2025.09 | Y4: 2025.12 | Z4: 2025.12A | AA4: 2026.03 | AB4: 2026.06 | AC4: 2026.09 | AD4: 2026.12 | AE4: 2026.12A | AF4: 2027.03 | AG4: 2027.06 | AH4: 2027.09 | AI4: 2027.12 | AJ4: 2027.12A | AK4: 2028.03 | AL4: 2028.06 | AM4: 2028.09 | AN4: 2028.12 | AO4: 2028.12A
A5: 1 | C5: 유동자산 | E5: 6481079.2 | F5: 6481079.2 | G5: 6529546.2 | H5: 7600539.7 | I5: 7609361.8 | J5: 7822464.5 | K5: 7822464.5 | L5: 7842922.3 | M5: 9286501.9 | N5: 8707670.1 | O5: 9217523.9 | P5: 9217523.9 | Q5: 9983392.9 | R5: 10812814 | S5: 10676937 | T5: 11246034 | U5: 11246034 | V5: 11568534 | W5: 11517407 | X5: 11387275 | Y5: 12082155 | Z5: 12082155 | AA5: 12289555 | AB5: 11356552
A6: 1 | C6: 현금및현금성자산 | E6: 1778939.7 | F6: 1778939.7 | G6: 1174446.6 | H6: 1106062.7 | I6: 684185.72 | J6: 659721.35 | K6: 659721.35 | L6: 270117.31 | M6: 1564490.4 | N6: 978618.34 | O6: 1799307.8 | P6: 1799307.8 | Q6: 1648803.9 | R6: 1824756.8 | S6: 1016613.3 | T6: 588259.74 | U6: 588259.74 | V6: 973241.31 | W6: 1037648.5 | X6: 429500.56 | Y6: 778471.16 | Z6: 778471.16 | AA6: 1058396.7 | AB6: 1446204.4
A7: 1 | C7: 단기금융상품 | E7: 310692.72 | F7: 310692.72 | G7: 266882.64 | H7: 169595.43 | I7: 466379.27 | J7: 492238.3 | K7: 492238.3
A8: 1 | C8: 단기금융자산 | E8: 310692.72 | F8: 310692.72 | G8: 266882.64 | H8: 169611.58 | I8: 466395.42 | J8: 492254.45 | K8: 492254.45 | AA8: 11835.59 | AB8: 60826.78
A9: 1 | C9: 매출채권및기타채권 | E9: 345121.59 | F9: 345121.59 | G9: 445003 | H9: 401269.91 | I9: 205292.22 | J9: 404741.92 | K9: 404741.92 | L9: 234682.14 | M9: 191888.47 | N9: 257126.78 | O9: 332546.69 | P9: 332546.69 | Q9: 158647.11 | R9: 320681.34 | S9: 714442.7 | T9: 894491.36 | U9: 894491.36 | V9: 1088908.1 | W9: 737068.29 | X9: 869273.09 | Y9: 965182.46 | Z9: 965182.46 | AA9: 849821.3 | AB9: 621607.55
A10: 1 | C10: 계약자산 | E10: 1936517.1 | F10: 1936517.1 | G10: 2295770.7 | H10: 2788096.1 | I10: 2705615 | J10: 2566075 | K10: 2566075 | L10: 2799855.6 | M10: 2587496.3 | N10: 2607014.9 | O10: 2517851.3 | P10: 2517851.3 | Q10: 3463023.3 | R10: 4172601.8 | S10: 4406915 | T10: 4986595.9 | U10: 4986595.9 | V10: 5049134.2 | W10: 5448042.5 | X10: 5457909.1 | Y10: 5506124.9 | Z10: 5506124.9 | AA10: 5455115.3 | AB10: 5899780.6
A11: 1 | C11: 재고자산 | E11: 1139095.9 | F11: 1139095.9 | G11: 1124060.9 | H11: 1711064.1 | I11: 1985849 | J11: 2202075.9 | K11: 2202075.9 | L11: 2509502.7 | M11: 2780399.2 | N11: 3041200 | O11: 2890783.3 | P11: 2890783.3 | Q11: 2977779 | R11: 2834661.6 | S11: 2843596.8 | T11: 2779695.4 | U11: 2779695.4 | V11: 2653888.7 | W11: 2620480.6 | X11: 2781920.6 | Y11: 3040398.5 | Z11: 3040398.5 | AA11: 3103900.7 | AB11: 1583621.9
A12: 1 | C12: 당기법인세자산(선급법인세) | E12: 90.46 | F12: 90.46 | G12: 1024.23 | H12: 3876.31 | I12: 4899 | J12: 5831.76 | K12: 5831.76 | L12: 6660.63 | M12: 2473.87 | N12: 3938.08 | O12: 5494.68 | P12: 5494.68 | Q12: 8246.49 | R12: 5897.16 | S12: 7711.05 | T12: 8632.12 | U12: 8632.12 | V12: 9478.41 | W12: 1977.06 | X12: 2624.95 | Y12: 2126.1 | Z12: 2126.1 | AA12: 1488.07 | AB12: 5511.81
A13: 1 | C13: 기타유동자산 | E13: 773335.85 | F13: 773335.85 | G13: 989546.24 | H13: 1107041.4 | I13: 1255423 | J13: 1288871.6 | K13: 1288871.6 | L13: 1358136.7 | M13: 1439825.9 | N13: 1359720.7 | O13: 1315290.5 | P13: 1315290.5 | Q13: 1337389.5 | R13: 1371864.5 | S13: 1480128.6 | T13: 1597417.1 | U13: 1597417.1 | V13: 1547557.5 | W13: 1579496.4 | X13: 1784388.6 | Y13: 1719764.4 | Z13: 1719764.4 | AA13: 1739483.8 | AB13: 1713534.9
A14: 1 | C14: 매각예정비유동자산및처분자산 | E14: 161964.11 | F14: 161964.11 | G14: 161964.11 | H14: 161964.11 | I14: 282.96 | J14: 282.96 | K14: 282.96
A15: 1 | C15: 비유동자산 | E15: 4142130.3 | F15: 4142130.3 | G15: 4229720 | H15: 4421919.2 | I15: 4889807.6 | J15: 4413200.8 | K15: 4413200.8 | L15: 4476180.1 | M15: 4354243.7 | N15: 4562093 | O15: 4727248.8 | P15: 4727248.8 | Q15: 4911047.2 | R15: 5415567.9 | S15: 5690065.4 | T15: 6597774.8 | U15: 6597774.8 | V15: 6609139.1 | W15: 6786305.9 | X15: 7146651.2 | Y15: 8058758.5 | Z15: 8058758.5 | AA15: 8506992.4 | AB15: 8789634.7
A16: 1 | C16: 장기금융자산 | E16: 233164.7 | F16: 233164.7 | G16: 228342.2 | H16: 78023.41 | I16: 40222.99 | J16: 40246.06 | K16: 40246.06 | M16: 39272.25 | N16: 40704.47 | O16: 39489.68 | P16: 39489.68 | Q16: 41142.97 | R16: 80916.18 | S16: 189040.92 | T16: 254635.47 | U16: 254635.47 | V16: 254224.05 | W16: 268713.11 | X16: 224837.95 | Y16: 190795.74 | Z16: 190795.74 | AA16: 258426.71 | AB16: 258768.03
A17: 1 | C17: 투자자산 | E17: 467405.5 | F17: 467405.5 | G17: 469626.43 | H17: 675758.42 | I17: 1089919.4 | J17: 277304.56 | K17: 277304.56 | L17: 312265.32 | M17: 280519.73 | N17: 247708.23 | O17: 130942.13 | P17: 130942.13 | Q17: 188202.4 | R17: 344053.4 | S17: 354794.18 | T17: 616573.29 | U17: 616573.29 | V17: 594718.5 | W17: 665236.01 | X17: 712876.88 | Y17: 1196058.2 | Z17: 1196058.2 | AA17: 1537413.4 | AB17: 1603017.3
A18: 1 | C18: 종속기업및관계기업투자 | E18: 3989.4 | F18: 3989.4 | G18: 3317.45 | H18: 3151.38 | I18: 3426.68 | J18: 3694.66 | K18: 3694.66 | L18: 3117.16 | M18: 3514.45 | N18: 4021.53 | O18: 4243.08 | P18: 4243.08 | Q18: 3734.04 | R18: 102014.56 | S18: 109742.37 | T18: 324219.32 | U18: 324219.32 | V18: 340494.45 | W18: 396510.09 | X18: 486620.43 | Y18: 1000398.2 | Z18: 1000398.2 | AA18: 1203439.3 | AB18: 1235379.4
A19: 1 | C19: 장기매출채권및기타채권 | E19: 103932.42 | F19: 103932.42 | G19: 189282.71 | H19: 181675.85 | I19: 228283.68 | J19: 203539.47 | K19: 203539.47 | L19: 206740.99 | M19: 204543.59 | N19: 207471.46 | O19: 273802.16 | P19: 273802.16 | Q19: 280814.74 | R19: 294202.34 | S19: 300864.12 | T19: 267215.33 | U19: 267215.33 | V19: 224199.73 | W19: 228172.29 | X19: 356635.77 | Y19: 96905.28 | Z19: 96905.28 | AA19: 95044.24 | AB19: 97716.52
A20: 1 | C20: 비유동확정계약자산 | E20: 230251.4 | F20: 230251.4 | G20: 237966.78 | H20: 594583.63 | I20: 1046269.8 | J20: 233363.84 | K20: 233363.84 | L20: 309148.16 | M20: 237733.03 | N20: 202982.23 | O20: 87209.37 | P20: 87209.37 | Q20: 143325.39 | R20: 161122.66 | S20: 56010.89 | T20: 37718.5 | U20: 37718.5 | AA20: 75547.43 | AB20: 108869.93
A21: 1 | C21: 유형자산 | E21: 3469402.8 | F21: 3469402.8 | G21: 3462311.1 | H21: 3460717.6 | I21: 3477467.3 | J21: 3786679.5 | K21: 3786679.5 | L21: 3779589.1 | M21: 3771452.5 | N21: 4006438.4 | O21: 4062170.7 | P21: 4062170.7 | Q21: 4178534.9 | R21: 4521690.6 | S21: 4555285.7 | T21: 4648353.7 | U21: 4648353.7 | V21: 4721666.7 | W21: 4845759.8 | X21: 5025252.8 | Y21: 5273172.8 | Z21: 5273172.8 | AA21: 5385181.5 | AB21: 5546064.2
A22: 1 | C22: 무형자산 | E22: 1207.78 | F22: 1207.78 | G22: 1549.95 | H22: 1887.38 | I22: 2626.9 | J22: 1532.33 | K22: 1532.33 | L22: 2247.37 | M22: 2482.89 | N22: 3200.92 | O22: 4343.85 | P22: 4343.85 | Q22: 4945.74 | R22: 5828.69 | S22: 236920.02 | T22: 394140.1 | U22: 394140.1 | V22: 393622.22 | W22: 378103.51 | X22: 376918.67 | Y22: 362397.28 | Z22: 362397.28 | AA22: 357671.72 | AB22: 352438.93
A23: 1 | C23: 이연법인세자산 | E23: 352.58 | F23: 352.58 | G23: 62.68 | H23: 419.38 | I23: 193.04 | J23: 267.52 | K23: 267.52 | L23: 90.96 | O23: 164100.77 | P23: 164100.77 | Q23: 164039.62 | R23: 154280.07 | S23: 154367.13 | T23: 506573.93 | U23: 506573.93 | V23: 506573.93 | W23: 498189.16 | X23: 502055.36 | Y23: 949984.61 | Z23: 949984.61 | AA23: 950011.75 | AB23: 965854.76
A24: 1 | C24: 사용권자산 | E24: 82802.61 | F24: 82802.61 | G24: 86151.07 | H24: 81146.6 | I24: 79715.49 | J24: 71585.23 | K24: 71585.23 | L24: 68282.44 | M24: 82580.83 | N24: 84122.07 | O24: 76561.76 | P24: 76561.76 | Q24: 78875.74 | R24: 81362.69 | S24: 73177 | T24: 133041.57 | U24: 133041.57 | V24: 136787.44 | W24: 138515.32 | X24: 140716.69 | Y24: 138173.29 | Z24: 138173.29 | AA24: 124078.23 | AB24: 151508.55
A25: 1 | C25: 기타비유동자산 | E25: 98307.42 | F25: 98307.42 | G25: 105091.93 | H25: 99962.44 | I25: 91317.26 | J25: 143085.17 | K25: 143085.17 | L25: 133912.79 | M25: 95245.03 | N25: 97274.02 | O25: 91889.12 | P25: 91889.12 | Q25: 94509.77 | R25: 95512.76 | S25: 87083.08 | T25: 164918.56 | U25: 164918.56 | V25: 168358.06 | W25: 170845.13 | X25: 172911.7 | Y25: 180240.37 | Z25: 180240.37 | AA25: 181669.77 | AB25: 224542.98
A26: 1 | C26: 자산총계 | E26: 10623210 | F26: 10623210 | G26: 10759266 | H26: 12022459 | I26: 12499169 | J26: 12235665 | K26: 12235665 | L26: 12319102 | M26: 13640746 | N26: 13269763 | O26: 13944773 | P26: 13944773 | Q26: 14894440 | R26: 16228382 | S26: 16367003 | T26: 17843809 | U26: 17843809 | V26: 18177673 | W26: 18303713 | X26: 18533926 | Y26: 20140914 | Z26: 20140914 | AA26: 20796547 | AB26: 20146187
A27: 1 | C27: 유동부채 | E27: 7464467.9 | F27: 7464467.9 | G27: 8148435.4 | H27: 9288994.3 | I27: 10028905 | J27: 10672486 | K27: 10672486 | L27: 10837186 | M27: 8882481.6 | N27: 8104192.6 | O27: 7459444.1 | P27: 7459444.1 | Q27: 8240962.1 | R27: 9540282.7 | S27: 9904381.8 | T27: 10346614 | U27: 10346614 | V27: 10339707 | W27: 10456875 | X27: 10274686 | Y27: 11200499 | Z27: 11200499 | AA27: 10825510 | AB27: 9364479.7
A28: 1 | C28: 단기차입금 | E28: 1137945.7 | F28: 1137945.7 | G28: 1347185.3 | H28: 1424089.7 | I28: 1411648.9 | J28: 1283430.9 | K28: 1283430.9 | L28: 1707126.5 | M28: 713220.26 | N28: 576236.23 | O28: 526449.92 | P28: 526449.92 | Q28: 1713714.7 | R28: 2519938.4 | S28: 3179562.5 | T28: 3237744 | U28: 3237744 | V28: 3371868.6 | W28: 3030820.2 | X28: 3051187.3 | Y28: 3300054.5 | Z28: 3300054.5 | AA28: 3529081.7 | AB28: 3387397.6
A29: 1 | C29: 매입채무및기타채무 | E29: 669851.32 | F29: 669851.32 | G29: 649354.86 | H29: 690954.1 | I29: 720459.37 | J29: 921458.49 | K29: 921458.49 | L29: 919163.14 | M29: 985040.94 | N29: 953132.56 | O29: 1176410.9 | P29: 1176410.9 | Q29: 1152124.3 | R29: 1285395.1 | S29: 1254663.3 | T29: 1671989.5 | U29: 1671989.5 | V29: 1350338.1 | W29: 1525558.9 | X29: 1619500.6 | Y29: 1856322.3 | Z29: 1856322.3 | AA29: 1693852.1 | AB29: 1626179.9
A30: 1 | C30: 유동성장기부채 | E30: 1329495.2 | F30: 1329495.2 | G30: 1360748.2 | H30: 1443944.3 | I30: 1506874 | J30: 1304098.3 | K30: 1304098.3 | L30: 1276920.8
A31: 1 | C31: 계약부채 | E31: 2094172.3 | F31: 2094172.3 | G31: 2277141.9 | H31: 3168104.7 | I31: 3538940 | J31: 4681596.5 | K31: 4681596.5 | L31: 4662527.2 | M31: 5037872.4 | N31: 4631146.7 | O31: 4366249.5 | P31: 4366249.5 | Q31: 4101558.4 | R31: 4552346.1 | S31: 4498055.9 | T31: 4315343.9 | U31: 4315343.9 | V31: 4682275.5 | W31: 5211566 | X31: 4921540 | Y31: 5195941.5 | Z31: 5195941.5 | AA31: 5010726.1 | AB31: 3747953.8
A32: 1 | C32: 단기충당부채 | E32: 1758206.8 | F32: 1758206.8 | G32: 1945101.9 | H32: 1639502.9 | I32: 1738772.5 | J32: 1570254.8 | K32: 1570254.8 | L32: 1295722.6 | M32: 1131567.3 | N32: 817880.83 | O32: 715250.6 | P32: 715250.6 | Q32: 479182.01 | R32: 367066.55 | S32: 314386.63 | T32: 364183.97 | U32: 364183.97 | V32: 242337.4 | W32: 220674.22 | X32: 215275.04 | Y32: 416851.88 | Z32: 416851.88 | AA32: 144786 | AB32: 140709.67
A33: 1 | C33: 당기법인세부채(미지급법인세) | E33: 2336.39 | F33: 2336.39 | G33: 2444.39 | H33: 1045.1 | I33: 1134.74 | J33: 1386.7 | K33: 1386.7 | L33: 1425.36 | M33: 891.6 | N33: 711.69 | O33: 837.31 | P33: 837.31 | Q33: 2559.42 | R33: 2416.28 | S33: 1180.4 | T33: 3007.76 | U33: 3007.76 | V33: 1774.07 | W33: 2184.69 | X33: 3600.88 | Y33: 4896.14 | Z33: 4896.14 | AA33: 4913.69 | AB33: 2854.65
A34: 1 | C34: 기타유동부채 | E34: 402287.76 | F34: 402287.76 | G34: 431136.91 | H34: 601537.43 | I34: 551816.25 | J34: 565985.94 | K34: 565985.94 | L34: 580939.25 | M34: 585268.81 | N34: 591927.09 | O34: 422464.75 | P34: 422464.75 | Q34: 432172.3 | R34: 458795.92 | S34: 491527.18 | T34: 376263.58 | U34: 376263.58 | V34: 297043.49 | W34: 272295.45 | X34: 283238.69 | Y34: 319985.15 | Z34: 319985.15 | AA34: 334609.54 | AB34: 314600.48
A35: 1 | C35: 비유동부채 | E35: 941158.24 | F35: 941158.24 | G35: 884271.99 | H35: 1185083.6 | I35: 1571579 | J35: 818206.99 | K35: 818206.99 | L35: 852856.75 | M35: 2426056.9 | N35: 2491792.8 | O35: 2173171.5 | P35: 2173171.5 | Q35: 2290157.1 | R35: 2350442.5 | S35: 2281849.1 | T35: 2633844.8 | U35: 2633844.8 | V35: 2749394.4 | W35: 2621061.4 | X35: 2783182.8 | Y35: 2765407.8 | Z35: 2765407.8 | AA35: 3145064.3 | AB35: 3253494.8
A36: 1 | C36: 사채 | E36: 111743.39 | F36: 111743.39 | G36: 56393.11
A37: 1 | C37: 장기차입금 | E37: 122512.94 | F37: 122512.94 | G37: 116822.03 | H37: 111833.68 | I37: 116209.29 | J37: 99715.36 | K37: 99715.36 | L37: 93931.58 | M37: 1626788.7 | N37: 1738732.9 | O37: 1664742.4 | P37: 1664742.4 | Q37: 1714421.2 | R37: 1749480.7 | S37: 1708893.8 | T37: 2028126 | U37: 2028126 | V37: 2148801.1 | W37: 1997395.7 | X37: 2121094.7 | Y37: 2346290.4 | Z37: 2346290.4 | AA37: 2613874.1 | AB37: 2650095.3
A38: 1 | C38: 장기매입채무및기타채무 | E38: 6993.08 | F38: 6993.08 | G38: 7112.83 | H38: 4888.31 | I38: 5429.07 | J38: 5244.47 | K38: 5244.47 | L38: 5401.6 | M38: 5431.72 | N38: 5552.15 | O38: 5234.39 | P38: 5234.39 | Q38: 7873 | R38: 11510.58 | S38: 12468.92 | T38: 15320.02 | U38: 15320.02 | V38: 45782.77 | W38: 48419.3 | X38: 68685.18 | Y38: 72938.29 | Z38: 72938.29 | AA38: 80988.66 | AB38: 72323.77
A39: 1 | C39: 장기충당부채 | E39: 334794.55 | F39: 334794.55 | G39: 322340.27 | H39: 360892.5 | I39: 362692.78 | J39: 328991.34 | K39: 328991.34 | L39: 305459.49 | M39: 288476.34 | N39: 244465.91 | O39: 229959.7 | P39: 229959.7 | Q39: 230121.95 | R39: 234804.46 | S39: 232901.09 | T39: 187901.66 | U39: 187901.66 | V39: 188013.52 | W39: 190682.12 | X39: 195341.35 | Y39: 80308.65 | Z39: 80308.65 | AA39: 80927.94 | AB39: 84805.87
A40: 1 | C40: 비유동리스부채 | E40: 61166.93 | F40: 61166.93 | G40: 61499.05 | H40: 56743.12 | I40: 53365.03 | J40: 48605.25 | K40: 48605.25 | L40: 44450.98 | M40: 55958.79 | N40: 55011.27 | O40: 51346.2 | P40: 51346.2 | Q40: 50602.76 | R40: 42414.97 | S40: 37540.68 | T40: 98270.13 | U40: 98270.13 | V40: 100806.86 | W40: 97641.45 | X40: 94814.23 | Y40: 93427.17 | Z40: 93427.17 | AA40: 89058.33 | AB40: 109164.2
...

Sheet BS별도
B1: (백만원) | C1: 이름: BS별도H | E1: 4Q21 | F1: 2021 | G1: 1Q22 | H1: 2Q22 | I1: 3Q22 | J1: 4Q22 | K1: 2022 | L1: 1Q23 | M1: 2Q23 | N1: 3Q23 | O1: 4Q23 | P1: 2023 | Q1: 1Q24 | R1: 2Q24 | S1: 3Q24 | T1: 4Q24 | U1: 2024 | V1: 1Q25 | W1: 2Q25 | X1: 3Q25 | Y1: 4Q25 | Z1: 2025 | AA1: 1Q26 | AB1: 2Q26 | AC1: 3Q26 | AD1: 4Q26 | AE1: 2026 | AF1: 1Q27 | AG1: 2Q27 | AH1: 3Q27 | AI1: 4Q27 | AJ1: 2027 | AK1: 1Q28 | AL1: 2Q28 | AM1: 3Q28 | AN1: 4Q28 | AO1: 2028
B2: 별도 | D2: fin json(kship_fin.py)
B3: 한화오션(별) | C3: UPDATE: 26-10-12 | E3: 1 | F3: 2 | G3: 3 | H3: 4 | I3: 5 | J3: 6 | K3: 7 | L3: 8 | M3: 9 | N3: 10 | O3: 11 | P3: 12 | Q3: 13 | R3: 14 | S3: 15 | T3: 16 | U3: 17 | V3: 18 | W3: 19 | X3: 20 | Y3: 21 | Z3: 22 | AA3: 23 | AB3: 24 | AC3: 25 | AD3: 26 | AE3: 27 | AF3: 28 | AG3: 29 | AH3: 30 | AI3: 31 | AJ3: 32 | AK3: 33 | AL3: 34 | AM3: 35 | AN3: 36 | AO3: 37
B4: Account Code | C4: AccountNAME | E4: 2021.12 | F4: 2021.12A | G4: 2022.03 | H4: 2022.06 | I4: 2022.09 | J4: 2022.12 | K4: 2022.12A | L4: 2023.03 | M4: 2023.06 | N4: 2023.09 | O4: 2023.12 | P4: 2023.12A | Q4: 2024.03 | R4: 2024.06 | S4: 2024.09 | T4: 2024.12 | U4: 2024.12A | V4: 2025.03 | W4: 2025.06 | X4: 2025.09 | Y4: 2025.12 | Z4: 2025.12A | AA4: 2026.03 | AB4: 2026.06 | AC4: 2026.09 | AD4: 2026.12 | AE4: 2026.12A | AF4: 2027.03 | AG4: 2027.06 | AH4: 2027.09 | AI4: 2027.12 | AJ4: 2027.12A | AK4: 2028.03 | AL4: 2028.06 | AM4: 2028.09 | AN4: 2028.12 | AO4: 2028.12A
A5: 1 | C5: 유동자산 | E5: 6419034.5 | F5: 6419034.5 | G5: 6471133.1 | H5: 7533299.2 | I5: 7530412.8 | J5: 7738158.4 | K5: 7738158.4 | L5: 7747259.5 | M5: 9179285.2 | N5: 8572249.7 | O5: 9096135.8 | P5: 9096135.8 | Q5: 9801677.7 | R5: 11012667 | S5: 10776728 | T5: 11238634 | U5: 11238634 | V5: 11610034 | W5: 11198945 | X5: 11068721 | Y5: 11799386 | Z5: 11799386 | AA5: 11997575 | AB5: 11119990
A6: 1 | C6: 현금및현금성자산 | E6: 1748494.8 | F6: 1748494.8 | G6: 1151228.9 | H6: 1087001.7 | I6: 657427.68 | J6: 633463.93 | K6: 633463.93 | L6: 237007.28 | M6: 1534482.3 | N6: 954975.09 | O6: 1770497 | P6: 1770497 | Q6: 1588821.7 | R6: 1725153.8 | S6: 887993.05 | T6: 414334.46 | U6: 414334.46 | V6: 762712.6 | W6: 818753.66 | X6: 219142.42 | Y6: 602024.39 | Z6: 602024.39 | AA6: 884912.28 | AB6: 1231282.7
A7: 1 | C7: 단기금융상품 | E7: 291503.12 | F7: 291503.12 | G7: 247348.39 | H7: 152490.45 | I7: 451006.79 | J7: 479194.05 | K7: 479194.05
A8: 1 | C8: 단기금융자산 | E8: 291503.12 | F8: 291503.12 | G8: 247348.39 | H8: 152506.6 | I8: 451022.94 | J8: 479210.2 | K8: 479210.2 | AA8: 11835.59 | AB8: 14682.83
A9: 1 | C9: 매출채권및기타채권 | E9: 345269.04 | F9: 345269.04 | G9: 445066.21 | H9: 402475.13 | I9: 204727.96 | J9: 403485.85 | K9: 403485.85 | L9: 235303.52 | M9: 191266.95 | N9: 254729.22 | O9: 334564.92 | P9: 334564.92 | Q9: 160761.3 | R9: 433357.79 | S9: 700923.3 | T9: 897795.51 | U9: 897795.51 | V9: 1095379.7 | W9: 741005.15 | X9: 832147.03 | Y9: 977825.54 | Z9: 977825.54 | AA9: 859187.67 | AB9: 749539.27
A10: 1 | C10: 계약자산 | E10: 1919963 | F10: 1919963 | G10: 2269458.8 | H10: 2745622 | I10: 2658816.7 | J10: 2515400.1 | K10: 2515400.1 | L10: 2748256.9 | M10: 2536190.1 | N10: 2558208.5 | O10: 2481791.4 | P10: 2481791.4 | Q10: 3396193.3 | R10: 4107241.3 | S10: 4358647 | T10: 4933931.2 | U10: 4933931.2 | V10: 5010517.7 | W10: 5413984 | X10: 5437949.5 | Y10: 5488624.9 | Z10: 5488624.9 | AA10: 5423702.4 | AB10: 5838294.1
A11: 1 | C11: 재고자산 | E11: 1128875.9 | F11: 1128875.9 | G11: 1112559.9 | H11: 1699608 | I11: 1971772.1 | J11: 2190744.4 | K11: 2190744.4 | L11: 2496506 | M11: 2767691.8 | N11: 3007566.7 | O11: 2852678.4 | P11: 2852678.4 | Q11: 2957415.9 | R11: 3128696.1 | S11: 3149764.7 | T11: 3045973.2 | U11: 3045973.2 | V11: 2968494.8 | W11: 2599463.7 | X11: 2753035.8 | Y11: 3021715.7 | Z11: 3021715.7 | AA11: 3093619.9 | AB11: 1592827
A12: 1 | C12: 기타유동자산 | E12: 787642.55 | F12: 787642.55 | G12: 1011710.6 | H12: 1128772.5 | I12: 1280124.5 | J12: 1307209.9 | K12: 1307209.9 | L12: 1372088.2 | M12: 1440032.1 | N12: 1353992.4 | O12: 1311734.4 | P12: 1311734.4 | Q12: 1327728.7 | R12: 1367952.7 | S12: 1474452.9 | T12: 1582054.3 | U12: 1582054.3 | V12: 1521410.4 | W12: 1535558.9 | X12: 1768944.7 | Y12: 1644907.5 | Z12: 1644907.5 | AA12: 1664678.6 | AB12: 1630873.5
A13: 1 | C13: 매각예정비유동자산및처분자산 | E13: 161964.11 | F13: 161964.11 | G13: 161964.11 | H13: 161964.11 | I13: 282.96 | J13: 282.96 | K13: 282.96
A14: 1 | C14: 비유동자산 | E14: 4021762.5 | F14: 4021762.5 | G14: 4107310 | H14: 4297169.3 | I14: 4757264.6 | J14: 4308672 | K14: 4308672 | L14: 4364667.4 | M14: 4248653.8 | N14: 4260477 | O14: 4407021.4 | P14: 4407021.4 | Q14: 4632772.3 | R14: 4834004.9 | S14: 5282975.7 | T14: 6168576.2 | U14: 6168576.2 | V14: 6145995 | W14: 6683540.7 | X14: 7028521.8 | Y14: 7925260.3 | Z14: 7925260.3 | AA14: 8242357 | AB14: 8444164.2
A15: 1 | C15: 장기금융자산 | E15: 233164.7 | F15: 233164.7 | G15: 228342.2 | H15: 78023.41 | I15: 40222.99 | J15: 40246.06 | K15: 40246.06 | M15: 39272.25 | N15: 40653.63 | O15: 39438.84 | P15: 39438.84 | Q15: 40492.13 | R15: 51092.14 | S15: 51684.41 | T15: 55154.82 | U15: 55154.82 | V15: 53416.43 | W15: 53394.9 | X15: 54493.26 | Y15: 54797.44 | Z15: 54797.44 | AA15: 54997.5 | AB15: 54808.07
A16: 1 | C16: 투자자산 | E16: 467092.83 | F16: 467092.83 | G16: 469985.71 | H16: 675996.63 | I16: 1089754.6 | J16: 276540.52 | K16: 276540.52 | L16: 312078.78 | M16: 277005.28 | N16: 243635.86 | O16: 126648.21 | P16: 126648.21 | Q16: 183817.52 | R16: 212214.8 | S16: 107695.3 | T16: 92873.32 | U16: 92873.32 | V16: 53416.43 | W16: 53407.71 | X16: 55911.76 | Y16: 59661.7 | Z16: 59661.7 | AA16: 130544.93 | AB16: 163678
A17: 1 | C17: 종속기업및관계기업투자 | E17: 3676.73 | F17: 3676.73 | G17: 3676.73 | H17: 3389.59 | I17: 3261.85 | J17: 2930.62 | K17: 2930.62 | L17: 2930.62
A18: 1 | C18: 장기매출채권및기타채권 | E18: 103840.03 | F18: 103840.03 | G18: 189211.28 | H18: 181603.42 | I18: 228208.7 | J18: 201864.23 | K18: 201864.23 | L18: 205033.07 | M18: 202868.35 | N18: 205730.54 | O18: 272708.61 | P18: 272708.61 | Q18: 279721.19 | R18: 293002.15 | S18: 299657.43 | T18: 276375.56 | U18: 276375.56 | V18: 233909.93 | W18: 667579.9 | X18: 823921.34 | Y18: 533759.12 | Z18: 533759.12 | AA18: 555503.72 | AB18: 571401.21
A19: 1 | C19: 비유동확정계약자산 | E19: 230251.4 | F19: 230251.4 | G19: 237966.78 | H19: 594583.63 | I19: 1046269.8 | J19: 233363.84 | K19: 233363.84 | L19: 309148.16 | M19: 237733.03 | N19: 202982.23 | O19: 87209.37 | P19: 87209.37 | Q19: 143325.39 | R19: 161122.66 | S19: 56010.89 | T19: 37718.5 | U19: 37718.5 | AA19: 75547.43 | AB19: 108869.93
A20: 1 | C20: 유형자산 | E20: 3375716 | F20: 3375716 | G20: 3365911.8 | H20: 3362698.6 | I20: 3372984.2 | J20: 3709724.7 | K20: 3709724.7 | L20: 3696116.5 | M20: 3693149.4 | N20: 3720090 | O20: 3755171.6 | P20: 3755171.6 | Q20: 3764663.5 | R20: 3785538.1 | S20: 3809674.9 | T20: 3903542.2 | U20: 3903542.2 | V20: 3937946.9 | W20: 4011494.1 | X20: 4099370.9 | Y20: 4273894.1 | Z20: 4273894.1 | AA20: 4298682.2 | AB20: 4357892.4
A21: 1 | C21: 사용권자산 | E21: 59107.24 | F21: 59107.24 | G21: 62155.11 | H21: 56986.19 | I21: 54875.71 | J21: 49181.93 | K21: 49181.93 | L21: 45106.53 | M21: 60260.87 | N21: 55460.18 | O21: 50059.79 | P21: 50059.79 | Q21: 48834.6 | R21: 47343.23 | S21: 41430.49 | T21: 101723.7 | U21: 101723.7 | V21: 99560.12 | W21: 100534.77 | X21: 103592.44 | Y21: 95455.46 | Z21: 95455.46 | AA21: 81419.3 | AB21: 102886.33
A22: 1 | C22: 기타비유동자산 | E22: 72921.31 | F22: 72921.31 | G22: 79388.94 | H22: 74088.56 | I22: 64721.32 | J22: 119102.99 | K22: 119102.99 | L22: 109108.84 | M22: 71383.57 | N22: 66345.52 | O22: 62792.95 | P22: 62792.95 | Q22: 62028.47 | R22: 59493.22 | S22: 53508.65 | T22: 130595.97 | U22: 130595.97 | V22: 129368.88 | W22: 132814.96 | X22: 136472.19 | Y22: 138313.72 | Z22: 138313.72 | AA22: 139965.68 | AB22: 174253.38
A23: 1 | C23: 무형자산 | E23: 670.53 | F23: 670.53 | G23: 1017.11 | H23: 1284.03 | I23: 1595.82 | J23: 647.28 | K23: 647.28 | L23: 996.67 | M23: 1316.61 | N23: 1744.43 | O23: 2877 | P23: 2877 | Q23: 3518.57 | R23: 4277.35 | S23: 235292.98 | T23: 390391.94 | U23: 390391.94 | V23: 389944.2 | W23: 374480.63 | X23: 371858.37 | Y23: 358470.04 | Z23: 358470.04 | AA23: 353394.45 | AB23: 348093.24
A24: 1 | C24: 자산총계 | E24: 10440797 | F24: 10440797 | G24: 10578443 | H24: 11830469 | I24: 12287677 | J24: 12046830 | K24: 12046830 | L24: 12111927 | M24: 13427939 | N24: 12832727 | O24: 13503157 | P24: 13503157 | Q24: 14434450 | R24: 15846672 | S24: 16059704 | T24: 17407210 | U24: 17407210 | V24: 17756029 | W24: 17882486 | X24: 18097243 | Y24: 19724646 | Z24: 19724646 | AA24: 20239932 | AB24: 19564154
A25: 1 | C25: 유동부채 | E25: 7375443.8 | F25: 7375443.8 | G25: 8061432.7 | H25: 9194975.1 | I25: 9919624.2 | J25: 10586129 | K25: 10586129 | L25: 10739485 | M25: 8793766.2 | N25: 8006557.3 | O25: 7382284.1 | P25: 7382284.1 | Q25: 8156375.4 | R25: 9553757.1 | S25: 9924653.3 | T25: 10350506 | U25: 10350506 | V25: 10369622 | W25: 10414427 | X25: 10188854 | Y25: 11074709 | Z25: 11074709 | AA25: 10698134 | AB25: 9247942.2
A26: 1 | C26: 단기차입금 | E26: 1073379.9 | F26: 1073379.9 | G26: 1281417.6 | H26: 1356016.2 | I26: 1339627.5 | J26: 1218458.8 | K26: 1218458.8 | L26: 1639742.1 | M26: 647468.41 | N26: 544631.12 | O26: 494162.6 | P26: 494162.6 | Q26: 1679649.3 | R26: 2485199 | S26: 3145042.2 | T26: 3201449.9 | U26: 3201449.9 | V26: 3335499.9 | W26: 2983414.4 | X26: 2978045.8 | Y26: 3220177.3 | Z26: 3220177.3 | AA26: 3443704.2 | AB26: 3292402.7
A27: 1 | C27: 매입채무및기타채무 | E27: 651183.86 | F27: 651183.86 | G27: 636868.02 | H27: 668798.62 | I27: 687454.28 | J27: 903964.73 | K27: 903964.73 | L27: 895991.44 | M27: 968038.14 | N27: 923584.96 | O27: 1150433.9 | P27: 1150433.9 | Q27: 1121404.3 | R27: 1251719.7 | S27: 1223413.3 | T27: 1630444.3 | U27: 1630444.3 | V27: 1324943.1 | W27: 1491765.5 | X27: 1574282.2 | Y27: 1804696.1 | Z27: 1804696.1 | AA27: 1643941.2 | AB27: 1555708.4
A28: 1 | C28: 당기법인세부채(미지급법인세) | E28: 982.56 | F28: 982.56 | G28: 982.56 | Y28: 3408.6 | Z28: 3408.6 | AA28: 3408.6
A29: 1 | C29: 유동성장기부채 | E29: 1329495.2 | F29: 1329495.2 | G29: 1360748.2 | H29: 1443944.3 | I29: 1506874 | J29: 1304098.3 | K29: 1304098.3 | L29: 1276920.8
A30: 1 | C30: 계약부채 | E30: 2094094.5 | F30: 2094094.5 | G30: 2277142.8 | H30: 3169024.5 | I30: 3540061.2 | J30: 4682119.5 | K30: 4682119.5 | L30: 4662523.2 | M30: 5037881.6 | N30: 4604437.1 | O30: 4365449.7 | P30: 4365449.7 | Q30: 4101018.2 | R30: 4657647.4 | S30: 4605264.6 | T30: 4422479.9 | U30: 4422479.9 | V30: 4788895.1 | W30: 5269693.3 | X30: 4974156.5 | Y30: 5254126.4 | Z30: 5254126.4 | AA30: 5069368.6 | AB30: 3822369.3
A31: 1 | C31: 단기충당부채 | E31: 1755561 | F31: 1755561 | G31: 1943149.9 | H31: 1638583.2 | I31: 1738772.5 | J31: 1569847.1 | K31: 1569847.1 | L31: 1295297.6 | M31: 1131374.1 | N31: 816777.92 | O31: 705053.76 | P31: 705053.76 | Q31: 468667.71 | R31: 356247.77 | S31: 303744.34 | T31: 349740.72 | U31: 349740.72 | V31: 237274.54 | W31: 214217.13 | X31: 208556.47 | Y31: 409292.06 | Z31: 409292.06 | AA31: 136711.52 | AB31: 132329.85
A32: 1 | C32: 기타유동부채 | E32: 400574.43 | F32: 400574.43 | G32: 425801.55 | H32: 598792.01 | I32: 547575.95 | J32: 563366.29 | K32: 563366.29 | L32: 575649.55 | M32: 580588.11 | N32: 588072.2 | O32: 418231.06 | P32: 418231.06 | Q32: 429188.77 | R32: 456027.45 | S32: 488216.65 | T32: 373077.27 | U32: 373077.27 | V32: 293049.35 | W32: 269478.75 | X32: 280364.57 | Y32: 283425.42 | Z32: 283425.42 | AA32: 298717.24 | AB32: 309857
A33: 1 | C33: 비유동부채 | E33: 937703.48 | F33: 937703.48 | G33: 881022.85 | H33: 1180996.4 | I33: 1566807.2 | J33: 816841.24 | K33: 816841.24 | L33: 851316.64 | M33: 2423628.5 | N33: 2398275.8 | O33: 2075932.7 | P33: 2075932.7 | Q33: 2192625.3 | R33: 2255314.1 | S33: 2189934 | T33: 2541510.2 | U33: 2541510.2 | V33: 2651736.6 | W33: 2529937 | X33: 2690677.4 | Y33: 2655619.5 | Z33: 2655619.5 | AA33: 3027660.1 | AB33: 3123003.8
A34: 1 | C34: 사채 | E34: 111743.39 | F34: 111743.39 | G34: 56393.11
A35: 1 | C35: 장기차입금 | E35: 122512.94 | F35: 122512.94 | G35: 116822.03 | H35: 111833.68 | I35: 116209.29 | J35: 99715.36 | K35: 99715.36 | L35: 93931.58 | M35: 1626788.7 | N35: 1662132.4 | O35: 1589951.4 | P35: 1589951.4 | Q35: 1642727.8 | R35: 1679814.5 | S35: 1641248.3 | T35: 1962264.7 | U35: 1962264.7 | V35: 2084982 | W35: 1939124.9 | X35: 2061122 | Y35: 2286006.4 | Z35: 2286006.4 | AA35: 2555723.6 | AB35: 2578512.4
A36: 1 | C36: 장기매입채무및기타채무 | E36: 6993.08 | F36: 6993.08 | G36: 7112.83 | H36: 4888.31 | I36: 5429.07 | J36: 4853.78 | K36: 4853.78 | L36: 5010.91 | M36: 5041.04 | N36: 5156.47 | O36: 4956.63 | P36: 4956.63 | Q36: 7207.96 | R36: 10850.1 | S36: 11861.16 | T36: 15320.02 | U36: 15320.02 | V36: 45782.77 | W36: 48212.9 | X36: 68427 | Y36: 72279.87 | Z36: 72279.87 | AA36: 78307.42 | AB36: 68000.37
A37: 1 | C37: 장기충당부채 | E37: 334794.55 | F37: 334794.55 | G37: 322340.27 | H37: 360892.5 | I37: 362692.78 | J37: 328991.34 | K37: 328991.34 | L37: 305459.49 | M37: 288476.34 | N37: 244465.91 | O37: 229959.7 | P37: 229959.7 | Q37: 230121.95 | R37: 234804.46 | S37: 232901.09 | T37: 187901.66 | U37: 187901.66 | V37: 188013.52 | W37: 190682.12 | X37: 195341.35 | Y37: 80308.65 | Z37: 80308.65 | AA37: 80927.94 | AB37: 84805.87
A38: 1 | C38: 비유동리스부채 | E38: 61166.93 | F38: 61166.93 | G38: 61499.05 | H38: 56743.12 | I38: 53365.03 | J38: 48605.25 | K38: 48605.25 | L38: 44450.98 | M38: 55851.5 | N38: 52719 | O38: 49361.21 | P38: 49361.21 | Q38: 45868.28 | R38: 38284.48 | S38: 33941.18 | T38: 95156.12 | U38: 95156.12 | V38: 91238.04 | W38: 89698.49 | X38: 87190.03 | Y38: 80584.42 | Z38: 80584.42 | AA38: 75718.56 | AB38: 95057.7
A39: 1 | C39: 리스부채 | E39: 61166.93 | F39: 61166.93 | G39: 61499.05 | H39: 56743.12 | I39: 53365.03 | J39: 48605.25 | K39: 48605.25 | L39: 44450.98 | M39: 55851.5 | N39: 52719 | O39: 49361.21 | P39: 49361.21 | Q39: 45868.28 | R39: 38284.48 | S39: 33941.18 | T39: 95156.12 | U39: 95156.12 | V39: 91238.04 | W39: 89698.49 | X39: 87190.03 | Y39: 110804.24 | Z39: 110804.24 | AA39: 75718.56 | AB39: 126350.75
A40: 1 | C40: 장기금융부채 | E40: 62229.92 | F40: 62229.92 | G40: 61892.28 | H40: 57027.47 | I40: 53365.03 | J40: 48674.54 | K40: 48674.54 | L40: 44602.83 | M40: 55851.5 | N40: 52719 | O40: 49361.21 | P40: 49361.21 | Q40: 45868.28 | R40: 38284.48 | S40: 36227.02 | T40: 95156.12 | U40: 95156.12 | V40: 91238.04 | W40: 89698.49 | X40: 87190.03 | Y40: 85462.45 | Z40: 85462.45 | AA40: 149494.21 | AB40: 207821.55
...

Sheet subQ
A1: YQ | C1: subQ 분기 서브모델(억원, U=100) | E1: 4Q21 | F1: 2021 | G1: 1Q22 | H1: 2Q22 | I1: 3Q22 | J1: 4Q22 | K1: 2022 | L1: 1Q23 | M1: 2Q23 | N1: 3Q23 | O1: 4Q23 | P1: 2023 | Q1: 1Q24 | R1: 2Q24 | S1: 3Q24 | T1: 4Q24 | U1: 2024 | V1: 1Q25 | W1: 2Q25 | X1: 3Q25 | Y1: 4Q25 | Z1: 2025 | AA1: 1Q26 | AB1: 2Q26 | AC1: 3Q26 | AD1: 4Q26 | AE1: 2026 | AF1: 1Q27 | AG1: 2Q27 | AH1: 3Q27 | AI1: 4Q27 | AJ1: 2027 | AK1: 1Q28 | AL1: 2Q28 | AM1: 3Q28 | AN1: 4Q28 | AO1: 2028
A2: A=이름(key) B=그룹 C=단위 D=FnGuide 계정명(VLOOKUP 키). 확정=VLOOKUP(BS), 추정=변수 가정 참조
E3: 1 | F3: 2 | G3: 3 | H3: 4 | I3: 5 | J3: 6 | K3: 7 | L3: 8 | M3: 9 | N3: 10 | O3: 11 | P3: 12 | Q3: 13 | R3: 14 | S3: 15 | T3: 16 | U3: 17 | V3: 18 | W3: 19 | X3: 20 | Y3: 21 | Z3: 22 | AA3: 23 | AB3: 24 | AC3: 25 | AD3: 26 | AE3: 27 | AF3: 28 | AG3: 29 | AH3: 30 | AI3: 31 | AJ3: 32 | AK3: 33 | AL3: 34 | AM3: 35 | AN3: 36 | AO3: 37
E4: 2021.12 | F4: 2021.12A | G4: 2022.03 | H4: 2022.06 | I4: 2022.09 | J4: 2022.12 | K4: 2022.12A | L4: 2023.03 | M4: 2023.06 | N4: 2023.09 | O4: 2023.12 | P4: 2023.12A | Q4: 2024.03 | R4: 2024.06 | S4: 2024.09 | T4: 2024.12 | U4: 2024.12A | V4: 2025.03 | W4: 2025.06 | X4: 2025.09 | Y4: 2025.12 | Z4: 2025.12A | AA4: 2026.03 | AB4: 2026.06 | AC4: 2026.09 | AD4: 2026.12 | AE4: 2026.12A | AF4: 2027.03 | AG4: 2027.06 | AH4: 2027.09 | AI4: 2027.12 | AJ4: 2027.12A | AK4: 2028.03 | AL4: 2028.06 | AM4: 2028.09 | AN4: 2028.12 | AO4: 2028.12A
A5: 매출액 | B5: 손익 | C5: 억원 | D5: 매출액(수익) | E5: =IFERROR(VLOOKUP($D5,BS연결,MATCH(E$1,BS연결H,0),0)/100,"") | G5: =IFERROR(VLOOKUP($D5,BS연결,MATCH(G$1,BS연결H,0),0)/100,"") | H5: =IFERROR(VLOOKUP($D5,BS연결,MATCH(H$1,BS연결H,0),0)/100,"") | I5: =IFERROR(VLOOKUP($D5,BS연결,MATCH(I$1,BS연결H,0),0)/100,"") | J5: =IFERROR(VLOOKUP($D5,BS연결,MATCH(J$1,BS연결H,0),0)/100,"") | K5: =IFERROR(VLOOKUP($D5,BS연결,MATCH(K$1,BS연결H,0),0)/100,"") | L5: =IFERROR(VLOOKUP($D5,BS연결,MATCH(L$1,BS연결H,0),0)/100,"") | M5: =IFERROR(VLOOKUP($D5,BS연결,MATCH(M$1,BS연결H,0),0)/100,"") | N5: =IFERROR(VLOOKUP($D5,BS연결,MATCH(N$1,BS연결H,0),0)/100,"") | ... AB5: =IFERROR(VLOOKUP($D5,BS연결,MATCH(AB$1,BS연결H,0),0)/100,"") | AC5: =IFERROR(AC38+AC42,"") | AD5: =IFERROR(AD38+AD42,"") | AE5: =SUM(AA5:AD5) | AF5: =IFERROR(AF38+AF42,"") | AG5: =IFERROR(AG38+AG42,"") | AH5: =IFERROR(AH38+AH42,"") | AI5: =IFERROR(AI38+AI42,"") | AJ5: =SUM(AF5:AI5) | AK5: =IFERROR(AK38+AK42,"") | AL5: =IFERROR(AL38+AL42,"") | AM5: =IFERROR(AM38+AM42,"") | AN5: =IFERROR(AN38+AN42,"") | AO5: =SUM(AK5:AN5)
A6: 매출원가 | B6: 손익 | C6: 억원 | D6: 매출원가 | E6: =IFERROR(VLOOKUP($D6,BS연결,MATCH(E$1,BS연결H,0),0)/100,"") | G6: =IFERROR(VLOOKUP($D6,BS연결,MATCH(G$1,BS연결H,0),0)/100,"") | H6: =IFERROR(VLOOKUP($D6,BS연결,MATCH(H$1,BS연결H,0),0)/100,"") | I6: =IFERROR(VLOOKUP($D6,BS연결,MATCH(I$1,BS연결H,0),0)/100,"") | J6: =IFERROR(VLOOKUP($D6,BS연결,MATCH(J$1,BS연결H,0),0)/100,"") | K6: =IFERROR(VLOOKUP($D6,BS연결,MATCH(K$1,BS연결H,0),0)/100,"") | L6: =IFERROR(VLOOKUP($D6,BS연결,MATCH(L$1,BS연결H,0),0)/100,"") | M6: =IFERROR(VLOOKUP($D6,BS연결,MATCH(M$1,BS연결H,0),0)/100,"") | N6: =IFERROR(VLOOKUP($D6,BS연결,MATCH(N$1,BS연결H,0),0)/100,"") | ... AB6: =IFERROR(VLOOKUP($D6,BS연결,MATCH(AB$1,BS연결H,0),0)/100,"") | AC6: =IFERROR(AC5-AC7,"") | AD6: =IFERROR(AD5-AD7,"") | AE6: =SUM(AA6:AD6) | AF6: =IFERROR(AF5-AF7,"") | AG6: =IFERROR(AG5-AG7,"") | AH6: =IFERROR(AH5-AH7,"") | AI6: =IFERROR(AI5-AI7,"") | AJ6: =SUM(AF6:AI6) | AK6: =IFERROR(AK5-AK7,"") | AL6: =IFERROR(AL5-AL7,"") | AM6: =IFERROR(AM5-AM7,"") | AN6: =IFERROR(AN5-AN7,"") | AO6: =SUM(AK6:AN6)
A7: 매출총이익 | B7: 손익 | C7: 억원 | D7: 매출총이익 | E7: =IFERROR(VLOOKUP($D7,BS연결,MATCH(E$1,BS연결H,0),0)/100,"") | G7: =IFERROR(VLOOKUP($D7,BS연결,MATCH(G$1,BS연결H,0),0)/100,"") | H7: =IFERROR(VLOOKUP($D7,BS연결,MATCH(H$1,BS연결H,0),0)/100,"") | I7: =IFERROR(VLOOKUP($D7,BS연결,MATCH(I$1,BS연결H,0),0)/100,"") | J7: =IFERROR(VLOOKUP($D7,BS연결,MATCH(J$1,BS연결H,0),0)/100,"") | K7: =IFERROR(VLOOKUP($D7,BS연결,MATCH(K$1,BS연결H,0),0)/100,"") | L7: =IFERROR(VLOOKUP($D7,BS연결,MATCH(L$1,BS연결H,0),0)/100,"") | M7: =IFERROR(VLOOKUP($D7,BS연결,MATCH(M$1,BS연결H,0),0)/100,"") | N7: =IFERROR(VLOOKUP($D7,BS연결,MATCH(N$1,BS연결H,0),0)/100,"") | ... AB7: =IFERROR(VLOOKUP($D7,BS연결,MATCH(AB$1,BS연결H,0),0)/100,"") | AC7: =IFERROR(AC9+AC8,"") | AD7: =IFERROR(AD9+AD8,"") | AE7: =SUM(AA7:AD7) | AF7: =IFERROR(AF9+AF8,"") | AG7: =IFERROR(AG9+AG8,"") | AH7: =IFERROR(AH9+AH8,"") | AI7: =IFERROR(AI9+AI8,"") | AJ7: =SUM(AF7:AI7) | AK7: =IFERROR(AK9+AK8,"") | AL7: =IFERROR(AL9+AL8,"") | AM7: =IFERROR(AM9+AM8,"") | AN7: =IFERROR(AN9+AN8,"") | AO7: =SUM(AK7:AN7)
A8: 판관비 | B8: 손익 | C8: 억원 | D8: 판관비 | E8: =IFERROR(VLOOKUP($D8,BS연결,MATCH(E$1,BS연결H,0),0)/100,"") | G8: =IFERROR(VLOOKUP($D8,BS연결,MATCH(G$1,BS연결H,0),0)/100,"") | H8: =IFERROR(VLOOKUP($D8,BS연결,MATCH(H$1,BS연결H,0),0)/100,"") | I8: =IFERROR(VLOOKUP($D8,BS연결,MATCH(I$1,BS연결H,0),0)/100,"") | J8: =IFERROR(VLOOKUP($D8,BS연결,MATCH(J$1,BS연결H,0),0)/100,"") | K8: =IFERROR(VLOOKUP($D8,BS연결,MATCH(K$1,BS연결H,0),0)/100,"") | L8: =IFERROR(VLOOKUP($D8,BS연결,MATCH(L$1,BS연결H,0),0)/100,"") | M8: =IFERROR(VLOOKUP($D8,BS연결,MATCH(M$1,BS연결H,0),0)/100,"") | N8: =IFERROR(VLOOKUP($D8,BS연결,MATCH(N$1,BS연결H,0),0)/100,"") | ... AB8: =IFERROR(VLOOKUP($D8,BS연결,MATCH(AB$1,BS연결H,0),0)/100,"") | AC8: =IFERROR(AC5*변수!AC21,"") | AD8: =IFERROR(AD5*변수!AD21,"") | AE8: =SUM(AA8:AD8) | AF8: =IFERROR(AF5*변수!AF21,"") | AG8: =IFERROR(AG5*변수!AG21,"") | AH8: =IFERROR(AH5*변수!AH21,"") | AI8: =IFERROR(AI5*변수!AI21,"") | AJ8: =SUM(AF8:AI8) | AK8: =IFERROR(AK5*변수!AK21,"") | AL8: =IFERROR(AL5*변수!AL21,"") | AM8: =IFERROR(AM5*변수!AM21,"") | AN8: =IFERROR(AN5*변수!AN21,"") | AO8: =SUM(AK8:AN8)
