Workbook
Name 변수H: 변수!$C$1:$AO$1
Name 환율: 변수!$C$6:$AO$13
Name BS연결H: BS연결!$C$1:$AO$1
Name BS연결: BS연결!$C$5:$AO$100
Name BS별도H: BS별도!$C$1:$AO$1
Name BS별도: BS별도!$C$5:$AO$85
Name SUBQH: subQ!$A$1:$AO$1
Name subQ: subQ!$A$5:$AO$41

Sheet README
A1: 메디콕스(054180) 실적 모델 — ARGUS 한국조선
A2: 기준 분기 2026Q2 · 마지막 실적 2026Q2 · 생성 2026-10-11
A3: 모든 수치는 모델 산출값(DART 공개 재무제표 + 우리 추정)이다 — 목표주가·투자 추천 아님. 참고용 · 투자조언 아님.
A5: 시트
A6: 변수 가정 시계열. 환율 8행(ECB via frankfurter — L2 fx.json; 추정 분기 = 노란 가정), 추정 드라이버(노란 셀 = 모델값에서 역산한 가정, 바꾸면 재계산; 연녹 셀 = 3절 스칼라 참조 수식), 3절 스칼라 가정(세율·판관비율·지배주주비중·이자율·종가·PER 밴드·COE·외화 순노출·헤지비율)
A7: BS연결/BS별도 FnGuide 계정명 × 기간 값 덤프(백만원). 행1 분기라벨, 행4 YYYY.MM / YYYY.12A. 이름정의 BS연결H·BS연결(계정명 C열부터)
A8: subQ 분기 서브모델(억원 = 백만원/100). 확정 행: =IFERROR(VLOOKUP($D행,BS연결,MATCH(E$1,BS연결H,0),0)/100,"") 추정 행: 변수 시트 가정 셀 참조 수식. 외환손익·파생상품손익은 BS 계정 합·차, 기타금융손익은 잔차, OPM·EPS·BPS·PER·PBR 은 파생 수식
A9: SLS 선표(조선사만, sls json 있을 때): 요약 행(sls 저장값) + 계약별 스케줄(백만$) × (헤지비율 × 헤지환율 + (1−헤지비율) × 건조시점 환율[변수 원/달러(평균)]) → 원화 수식 블록 → 합계 행이 subQ 매출조선에 연결
A10: 시나리오 신규수주 보수/기준/낙관(forecast_panel 패널, 모델에 scenarios 가 있을 때만): 매출액·영업이익 = subQ 기준값 ± (시나리오 신규 − base 신규) × OPM. base 만 subQ 행에 포함, 나머지는 합산 안 함
A11: 분기/연간예상 subQ 를 이름(A열 key)으로 VLOOKUP 한 보고서 표(억원)
A12: TP PER 밴드 × 12M fwd EPS, PBR = ROE/COE × BPS — 모델 산출값 구간, 목표주가·추천 아님
A13: 외화 환율 QoQ, 외화 순노출 × Δ기말환율 → 환관련손익 추정
... A34: 백테스트: {"freeze": "2025Q2", "horizon": 4, "revenue_wape_pct": 32.3, "op_wape_pct": 58.4, "n": 4, "note": "단일 회사 4분기 — 통계 아님", "driver_at_freeze": "customer_yard_revenue_weighted", "selection_oos_at_freeze": {"freeze": "2024Q2", "n": 4, "wape_link": 4.2, "wape_trend": 9.9, "adopted": true, "decision": "adopted"}, "frozen_inputs": "fin(연결/별도)·고객 조선사 모델·지주 자회사 모델은 2025Q2 까지의 분기만; 선표는 체결일 ≤ 2025Q2 말일 계약(원장 최신 금액·코호트 등급, 환산 없음); 잔고는 yards_cache 2025Q2; 시세·환율 forward·prices·forecast_panel 신규수주 미사용. 고객 가중치(suppliers.json 언급 비중)와 합병 체인링크는 현재 지식; 고객 연동 채택은 동결 모델 안에서도 자기 la−4분기 OOS 규칙(selection_oos_at_freeze)", "detail": [{"q": "2025Q3", "rev_pred": 87.78, "rev_act": 66.85, "op_pred": -17.56, "op_act": -9.23}, {"q": "2025Q4", "rev_pred": 92.29, "rev_act": 69.81, "op_pred": -18.46, "op_act": -13.47}, {"q": "2026Q1", "rev_pred": 77.47, "rev_act": 63.29, "op_pred": -15.49, "op_act": -10.33}, {"q": "2026Q2", "rev_pred": 92.3, "rev_act": 64.43, "op_pred": -18.46, "op_act": -11.14}]}

Sheet 변수
C1: 이름: 변수H | E1: 4Q21 | F1: 2021 | G1: 1Q22 | H1: 2Q22 | I1: 3Q22 | J1: 4Q22 | K1: 2022 | L1: 1Q23 | M1: 2Q23 | N1: 3Q23 | O1: 4Q23 | P1: 2023 | Q1: 1Q24 | R1: 2Q24 | S1: 3Q24 | T1: 4Q24 | U1: 2024 | V1: 1Q25 | W1: 2Q25 | X1: 3Q25 | Y1: 4Q25 | Z1: 2025 | AA1: 1Q26 | AB1: 2Q26 | AC1: 3Q26 | AD1: 4Q26 | AE1: 2026 | AF1: 1Q27 | AG1: 2Q27 | AH1: 3Q27 | AI1: 4Q27 | AJ1: 2027 | AK1: 1Q28 | AL1: 2Q28 | AM1: 3Q28 | AN1: 4Q28 | AO1: 2028
A2: 가정 시계열 — 노란 셀은 추정 가정(모델값에서 역산), 연녹 셀은 3절 스칼라 참조 수식. 바꾸면 subQ·분기·연간예상·TP·시나리오가 재계산됩니다.
E3: 1 | F3: 2 | G3: 3 | H3: 4 | I3: 5 | J3: 6 | K3: 7 | L3: 8 | M3: 9 | N3: 10 | O3: 11 | P3: 12 | Q3: 13 | R3: 14 | S3: 15 | T3: 16 | U3: 17 | V3: 18 | W3: 19 | X3: 20 | Y3: 21 | Z3: 22 | AA3: 23 | AB3: 24 | AC3: 25 | AD3: 26 | AE3: 27 | AF3: 28 | AG3: 29 | AH3: 30 | AI3: 31 | AJ3: 32 | AK3: 33 | AL3: 34 | AM3: 35 | AN3: 36 | AO3: 37
E4: 2021.12 | F4: 2021.12A | G4: 2022.03 | H4: 2022.06 | I4: 2022.09 | J4: 2022.12 | K4: 2022.12A | L4: 2023.03 | M4: 2023.06 | N4: 2023.09 | O4: 2023.12 | P4: 2023.12A | Q4: 2024.03 | R4: 2024.06 | S4: 2024.09 | T4: 2024.12 | U4: 2024.12A | V4: 2025.03 | W4: 2025.06 | X4: 2025.09 | Y4: 2025.12 | Z4: 2025.12A | AA4: 2026.03 | AB4: 2026.06 | AC4: 2026.09 | AD4: 2026.12 | AE4: 2026.12A | AF4: 2027.03 | AG4: 2027.06 | AH4: 2027.09 | AI4: 2027.12 | AJ4: 2027.12A | AK4: 2028.03 | AL4: 2028.06 | AM4: 2028.09 | AN4: 2028.12 | AO4: 2028.12A
B5: 1. FX | C5: 이름: 환율
A6: USDKRW_avg | C6: 원/달러(평균) | E6: 1183.5 | F6: 1145.51 | G6: 1205.78 | H6: 1262.09 | I6: 1341.93 | J6: 1360.12 | K6: 1292.98 | L6: 1276.95 | M6: 1315.69 | N6: 1313.62 | O6: 1322.01 | P6: 1306.85 | Q6: 1330.14 | R6: 1371.28 | S6: 1356.22 | T6: 1396.3 | U6: 1363.53 | V6: 1452.28 | W6: 1398.52 | X6: 1386.95 | Y6: 1449.19 | Z6: 1421.52 | AA6: 1466.12 | AB6: 1501.75 | AC6: 1418.75 | AD6: 1345.14 | AE6: 1457.21 | AF6: 1341.49 | AG6: 1341.49 | AH6: 1341.49 | AI6: 1341.49 | AK6: 1341.49 | AL6: 1341.49 | AM6: 1341.49 | AN6: 1341.49
A7: USDKRW_end | C7: 원/달러(기말) | E7: 1188.75 | F7: 1188.75 | G7: 1213.74 | H7: 1301.24 | I7: 1436.9 | J7: 1260.16 | K7: 1260.16 | L7: 1305.99 | M7: 1321.44 | N7: 1345.35 | O7: 1297.43 | P7: 1297.43 | Q7: 1349.25 | R7: 1377.73 | S7: 1312.17 | T7: 1474.78 | U7: 1474.78 | V7: 1474.54 | W7: 1355.13 | X7: 1403.67 | Y7: 1444.2 | Z7: 1444.2 | AA7: 1524.8 | AB7: 1550.89 | AC7: 1355.4 | AD7: 1341.49 | AE7: 1341.49 | AF7: 1341.49 | AG7: 1341.49 | AH7: 1341.49 | AI7: 1341.49 | AK7: 1341.49 | AL7: 1341.49 | AM7: 1341.49 | AN7: 1341.49
A8: JPY100KRW_avg | C8: 원/100Y(평균) | E8: 1041.02 | F8: 1042.74 | G8: 1036.79 | H8: 972.23 | I8: 970.61 | J8: 961.03 | K8: 985.1 | L8: 964.89 | M8: 957.36 | N8: 909 | O8: 893.22 | P8: 931.11 | Q8: 896.29 | R8: 880.14 | S8: 909.35 | T8: 917.25 | U8: 900.92 | V8: 952.59 | W8: 967.92 | X8: 940.32 | Y8: 940.77 | Z8: 950.17 | AA8: 934.39 | AB8: 942.16 | AC8: 890.41 | AD8: 850.79 | AE8: 919.21 | AF8: 847.7 | AG8: 847.7 | AH8: 847.7 | AI8: 847.7 | AK8: 847.7 | AL8: 847.7 | AM8: 847.7 | AN8: 847.7
A9: JPY100KRW_end | C9: 원/100Y(기말) | E9: 1032.62 | F9: 1032.62 | G9: 996.83 | H9: 954.9 | I9: 993.29 | J9: 955.54 | K9: 955.54 | L9: 980.62 | M9: 913.67 | N9: 901.47 | O9: 917.04 | P9: 917.04 | Q9: 892.42 | R9: 857.76 | S9: 919.21 | T9: 939.65 | U9: 939.65 | V9: 986.84 | W9: 938.85 | X9: 948.49 | Y9: 921.81 | Z9: 921.81 | AA9: 955.99 | AB9: 954.75 | AC9: 863.31 | AD9: 847.7 | AE9: 847.7 | AF9: 847.7 | AG9: 847.7 | AH9: 847.7 | AI9: 847.7 | AK9: 847.7 | AL9: 847.7 | AM9: 847.7 | AN9: 847.7
A10: EURKRW_avg | C10: W/Euro(평균) | E10: 1353.32 | F10: 1354.06 | G10: 1352.29 | H10: 1343.31 | I10: 1350.63 | J10: 1386.07 | K10: 1358.07 | L10: 1369.93 | M10: 1432.41 | N10: 1429.41 | O10: 1420.91 | P10: 1412.88 | Q10: 1444.21 | R10: 1476.42 | S10: 1489.3 | T10: 1490.78 | U10: 1475.4 | V10: 1528.33 | W10: 1585.13 | X10: 1620.04 | Y10: 1686.02 | Z10: 1605.45 | AA10: 1715.47 | AB10: 1746.09 | AC10: 1631.97 | AD10: 1509.74 | AE10: 1689.95 | AF10: 1503.27 | AG10: 1503.27 | AH10: 1503.27 | AI10: 1503.27 | AK10: 1503.27 | AL10: 1503.27 | AM10: 1503.27 | AN10: 1503.27
A11: EURKRW_end | C11: W/Euro(기말) | E11: 1346.38 | F11: 1346.38 | G11: 1347.37 | H11: 1351.6 | I11: 1400.62 | J11: 1344.08 | K11: 1344.08 | L11: 1420.26 | M11: 1435.88 | N11: 1425.26 | O11: 1433.66 | P11: 1433.66 | Q11: 1458.68 | R11: 1474.86 | S11: 1469.1 | T11: 1532.14 | U11: 1532.14 | V11: 1594.72 | W11: 1588.22 | X11: 1648.04 | Y11: 1696.94 | Z11: 1696.94 | AA11: 1753.21 | AB11: 1767.09 | AC11: 1539.06 | AD11: 1503.27 | AE11: 1503.27 | AF11: 1503.27 | AG11: 1503.27 | AH11: 1503.27 | AI11: 1503.27 | AK11: 1503.27 | AL11: 1503.27 | AM11: 1503.27 | AN11: 1503.27
A12: CNYKRW_avg | C12: 원/중국원(평균) | E12: 185.14 | F12: 177.65 | G12: 189.93 | H12: 190.76 | I12: 195.79 | J12: 191.09 | K12: 191.93 | L12: 186.59 | M12: 187.45 | N12: 181.28 | O12: 182.86 | P12: 184.52 | Q12: 185.04 | R12: 189.35 | S12: 189.24 | T12: 194.24 | U12: 189.49 | V12: 199.63 | W12: 193.41 | X12: 193.79 | Y12: 204.38 | Z12: 197.8 | AA12: 211.75 | AB12: 220.8 | AC12: 210.43 | AD12: 200.69 | AE12: 213.75 | AF12: 200.46 | AG12: 200.46 | AH12: 200.46 | AI12: 200.46 | AK12: 200.46 | AL12: 200.46 | AM12: 200.46 | AN12: 200.46
A13: CNYKRW_end | C13: 원/중국원(기말) | E13: 187.13 | F13: 187.13 | G13: 191.38 | H13: 194.13 | I13: 201.92 | J13: 182.67 | K13: 182.67 | L13: 189.97 | M13: 181.8 | N13: 184.26 | O13: 182.61 | P13: 182.61 | Q13: 186.66 | R13: 189.7 | S13: 187.12 | T13: 202.04 | U13: 202.04 | V13: 203.3 | W13: 189.14 | X13: 197.16 | Y13: 206.28 | Z13: 206.28 | AA13: 220.97 | AB13: 228.56 | AC13: 202.16 | AD13: 200.46 | AE13: 200.46 | AF13: 200.46 | AG13: 200.46 | AH13: 200.46 | AI13: 200.46 | AK13: 200.46 | AL13: 200.46 | AM13: 200.46 | AN13: 200.46
B14: 1b. 종가
A15: price_close_end | C15: 종가(기말) | E15: 74625 | G15: 64755 | H15: 40620 | I15: 79965 | J15: 50625 | L15: 22425 | M15: 21225 | N15: 13770 | O15: 16575 | Q15: 11550 | R15: 7860 | S15: 6165 | T15: 4800 | V15: 4155 | W15: 2220 | X15: 2295
A16: price_high | C16: 종가(최고) | E16: 99282 | G16: 80099 | H16: 71010 | I16: 112260 | J16: 85980 | L16: 52050 | M16: 33150 | N16: 32400 | O16: 23400 | Q16: 16980 | R16: 11925 | S16: 12690 | T16: 7650 | V16: 6195 | W16: 5355 | X16: 2835
A17: price_low | C17: 종가(최저) | E17: 67006 | G17: 57975 | H17: 38355 | I17: 40320 | J17: 44925 | L17: 18450 | M17: 19620 | N17: 13485 | O17: 9750 | Q17: 10275 | R17: 6255 | S17: 6060 | T17: 4035 | V17: 3240 | W17: 1545 | X17: 2235
A18: price_avg | C18: 종가(평균) | E18: 77024.5 | G18: 64962.7 | H18: 54767.9 | I18: 70696.4 | J18: 62443.5 | L18: 28652.2 | M18: 24994.4 | N18: 21750.5 | O18: 15252.2 | Q18: 12587.2 | R18: 9094.2 | S18: 8530.6 | T18: 5222.5 | V18: 4258.2 | W18: 3177 | X18: 2430
B20: 2. 추정 드라이버 | C20: 실적 열 = subQ 실현값(수식), 추정 열 = 가정(노란 = 모델값 역산, 연녹 = 3절 스칼라 참조)
A21: drv:매출액 | B21: yoy | C21: 매출액 YoY | J21: =IFERROR(subQ!J5/subQ!E5-1,"") | L21: =IFERROR(subQ!L5/subQ!G5-1,"") | M21: =IFERROR(subQ!M5/subQ!H5-1,"") | N21: =IFERROR(subQ!N5/subQ!I5-1,"") | O21: =IFERROR(subQ!O5/subQ!J5-1,"") | Q21: =IFERROR(subQ!Q5/subQ!L5-1,"") | R21: =IFERROR(subQ!R5/subQ!M5-1,"") | S21: =IFERROR(subQ!S5/subQ!N5-1,"") | T21: =IFERROR(subQ!T5/subQ!O5-1,"") | V21: =IFERROR(subQ!V5/subQ!Q5-1,"") | W21: =IFERROR(subQ!W5/subQ!R5-1,"") | X21: =IFERROR(subQ!X5/subQ!S5-1,"") | Y21: =IFERROR(subQ!Y5/subQ!T5-1,"") | AA21: =IFERROR(subQ!AA5/subQ!V5-1,"") | AB21: =IFERROR(subQ!AB5/subQ!W5-1,"") | AC21: -0.12671725 | AD21: -0.12672513 | AF21: -0.12668102 | AG21: -0.1268097 | AH21: -0.063377869 | AI21: -0.06332021 | AK21: -0.063506423 | AL21: -0.06327764 | AM21: -0.031638625 | AN21: -0.031698774
A22: drv:판관비 | B22: ratio | C22: 판관비율(/매출) | E22: =IFERROR(subQ!E8/subQ!E5,"") | F22: =IFERROR(subQ!F8/subQ!F5,"") | G22: =IFERROR(subQ!G8/subQ!G5,"") | H22: =IFERROR(subQ!H8/subQ!H5,"") | I22: =IFERROR(subQ!I8/subQ!I5,"") | J22: =IFERROR(subQ!J8/subQ!J5,"") | K22: =IFERROR(subQ!K8/subQ!K5,"") | L22: =IFERROR(subQ!L8/subQ!L5,"") | ... AB22: =IFERROR(subQ!AB8/subQ!AB5,"") | AC22: =$D$51 | AD22: =$D$51 | AE22: =IFERROR(subQ!AE8/subQ!AE5,"") | AF22: =$D$51 | AG22: =$D$51 | AH22: =$D$51 | AI22: =$D$51 | AJ22: =IFERROR(subQ!AJ8/subQ!AJ5,"") | AK22: =$D$51 | AL22: =$D$51 | AM22: =$D$51 | AN22: =$D$51 | AO22: =IFERROR(subQ!AO8/subQ!AO5,"")
A23: drv:영업이익 | B23: ratio | C23: 영업이익률(OPM) | E23: =IFERROR(subQ!E9/subQ!E5,"") | F23: =IFERROR(subQ!F9/subQ!F5,"") | G23: =IFERROR(subQ!G9/subQ!G5,"") | H23: =IFERROR(subQ!H9/subQ!H5,"") | I23: =IFERROR(subQ!I9/subQ!I5,"") | J23: =IFERROR(subQ!J9/subQ!J5,"") | K23: =IFERROR(subQ!K9/subQ!K5,"") | L23: =IFERROR(subQ!L9/subQ!L5,"") | ... AB23: =IFERROR(subQ!AB9/subQ!AB5,"") | AC23: -0.19116136 | AD23: -0.19110892 | AE23: =IFERROR(subQ!AE9/subQ!AE5,"") | AF23: -0.19124299 | AG23: -0.19125489 | AH23: -0.19111192 | AI23: -0.19124343 | AJ23: =IFERROR(subQ!AJ9/subQ!AJ5,"") | AK23: -0.19126739 | AL23: -0.19127135 | AM23: -0.1911237 | AN23: -0.19117381 | AO23: =IFERROR(subQ!AO9/subQ!AO5,"")
A24: drv:파생상품손익 | B24: abs | C24: 파생상품손익 (가정, 억원) | E24: =subQ!E13 | F24: =subQ!F13 | G24: =subQ!G13 | H24: =subQ!H13 | I24: =subQ!I13 | J24: =subQ!J13 | K24: =subQ!K13 | L24: =subQ!L13 | ... AB24: =subQ!AB13 | AC24: 0 | AD24: 0 | AE24: =subQ!AE13 | AF24: 0 | AG24: 0 | AH24: 0 | AI24: 0 | AJ24: =subQ!AJ13 | AK24: 0 | AL24: 0 | AM24: 0 | AN24: 0 | AO24: =subQ!AO13
A25: drv:기타영업외손익 | B25: abs | C25: 기타영업외손익 (가정, 억원) | E25: =subQ!E14 | F25: =subQ!F14 | G25: =subQ!G14 | H25: =subQ!H14 | I25: =subQ!I14 | J25: =subQ!J14 | K25: =subQ!K14 | L25: =subQ!L14 | ... AB25: =subQ!AB14 | AC25: 0 | AD25: 0 | AE25: =subQ!AE14 | AF25: 0 | AG25: 0 | AH25: 0 | AI25: 0 | AJ25: =subQ!AJ14 | AK25: 0 | AL25: 0 | AM25: 0 | AN25: 0 | AO25: =subQ!AO14
A26: drv:지분법손익 | B26: abs | C26: 지분법손익 (가정, 억원) | E26: =subQ!E15 | F26: =subQ!F15 | G26: =subQ!G15 | H26: =subQ!H15 | I26: =subQ!I15 | J26: =subQ!J15 | K26: =subQ!K15 | L26: =subQ!L15 | ... AB26: =subQ!AB15 | AC26: 1.71 | AD26: 1.71 | AE26: =subQ!AE15 | AF26: 1.71 | AG26: 1.71 | AH26: 1.71 | AI26: 1.71 | AJ26: =subQ!AJ15 | AK26: 1.71 | AL26: 1.71 | AM26: 1.71 | AN26: 1.71 | AO26: =subQ!AO15
A27: drv:법인세비용 | B27: ratio | C27: 법인세율(/세전) | E27: =IFERROR(subQ!E17/subQ!E16,"") | F27: =IFERROR(subQ!F17/subQ!F16,"") | G27: =IFERROR(subQ!G17/subQ!G16,"") | H27: =IFERROR(subQ!H17/subQ!H16,"") | I27: =IFERROR(subQ!I17/subQ!I16,"") | J27: =IFERROR(subQ!J17/subQ!J16,"") | K27: =IFERROR(subQ!K17/subQ!K16,"") | L27: =IFERROR(subQ!L17/subQ!L16,"") | ... AB27: =IFERROR(subQ!AB17/subQ!AB16,"") | AC27: 0 | AD27: 0 | AE27: =IFERROR(subQ!AE17/subQ!AE16,"") | AF27: 0 | AG27: 0 | AH27: 0 | AI27: 0 | AJ27: =IFERROR(subQ!AJ17/subQ!AJ16,"") | AK27: 0 | AL27: 0 | AM27: 0 | AN27: 0 | AO27: =IFERROR(subQ!AO17/subQ!AO16,"")
A28: drv:지배주주순이익 | B28: ratio | C28: 지배주주 비중(/당기순이익) | E28: =IFERROR(subQ!E19/subQ!E18,"") | F28: =IFERROR(subQ!F19/subQ!F18,"") | G28: =IFERROR(subQ!G19/subQ!G18,"") | H28: =IFERROR(subQ!H19/subQ!H18,"") | I28: =IFERROR(subQ!I19/subQ!I18,"") | J28: =IFERROR(subQ!J19/subQ!J18,"") | K28: =IFERROR(subQ!K19/subQ!K18,"") | L28: =IFERROR(subQ!L19/subQ!L18,"") | ... AB28: =IFERROR(subQ!AB19/subQ!AB18,"") | AC28: =$D$52 | AD28: =$D$52 | AE28: =IFERROR(subQ!AE19/subQ!AE18,"") | AF28: =$D$52 | AG28: =$D$52 | AH28: =$D$52 | AI28: =$D$52 | AJ28: =IFERROR(subQ!AJ19/subQ!AJ18,"") | AK28: =$D$52 | AL28: =$D$52 | AM28: =$D$52 | AN28: =$D$52 | AO28: =IFERROR(subQ!AO19/subQ!AO18,"")
A29: drv:중단사업이익 | B29: abs | C29: 중단사업이익 (가정, 억원) | E29: =subQ!E20 | F29: =subQ!F20 | G29: =subQ!G20 | H29: =subQ!H20 | I29: =subQ!I20 | J29: =subQ!J20 | K29: =subQ!K20 | L29: =subQ!L20 | ... AB29: =subQ!AB20 | AE29: =subQ!AE20 | AJ29: =subQ!AJ20 | AO29: =subQ!AO20
A30: drv:부채총계 | B30: qoq | C30: 부채총계 QoQ | G30: =IFERROR(subQ!G22/subQ!E22-1,"") | H30: =IFERROR(subQ!H22/subQ!G22-1,"") | I30: =IFERROR(subQ!I22/subQ!H22-1,"") | J30: =IFERROR(subQ!J22/subQ!I22-1,"") | L30: =IFERROR(subQ!L22/subQ!J22-1,"") | M30: =IFERROR(subQ!M22/subQ!L22-1,"") | N30: =IFERROR(subQ!N22/subQ!M22-1,"") | O30: =IFERROR(subQ!O22/subQ!N22-1,"") | Q30: =IFERROR(subQ!Q22/subQ!O22-1,"") | R30: =IFERROR(subQ!R22/subQ!Q22-1,"") | S30: =IFERROR(subQ!S22/subQ!R22-1,"") | T30: =IFERROR(subQ!T22/subQ!S22-1,"") | V30: =IFERROR(subQ!V22/subQ!T22-1,"") | W30: =IFERROR(subQ!W22/subQ!V22-1,"") | X30: =IFERROR(subQ!X22/subQ!W22-1,"") | Y30: =IFERROR(subQ!Y22/subQ!X22-1,"") | AA30: =IFERROR(subQ!AA22/subQ!Y22-1,"") | AB30: =IFERROR(subQ!AB22/subQ!AA22-1,"") | AC30: -1.8154e-05 | AD30: 0 | AF30: 0 | AG30: 0 | AH30: 0 | AI30: 0 | AK30: 0 | AL30: 0 | AM30: 0 | AN30: 0
A31: drv:자본총계 | B31: roll | C31: 자본총계 기타변동(배당 등, 억원) | G31: =IFERROR(subQ!E23+subQ!G18-subQ!G23,"") | H31: =IFERROR(subQ!G23+subQ!H18-subQ!H23,"") | I31: =IFERROR(subQ!H23+subQ!I18-subQ!I23,"") | J31: =IFERROR(subQ!I23+subQ!J18-subQ!J23,"") | L31: =IFERROR(subQ!J23+subQ!L18-subQ!L23,"") | M31: =IFERROR(subQ!L23+subQ!M18-subQ!M23,"") | N31: =IFERROR(subQ!M23+subQ!N18-subQ!N23,"") | O31: =IFERROR(subQ!N23+subQ!O18-subQ!O23,"") | Q31: =IFERROR(subQ!O23+subQ!Q18-subQ!Q23,"") | R31: =IFERROR(subQ!Q23+subQ!R18-subQ!R23,"") | S31: =IFERROR(subQ!R23+subQ!S18-subQ!S23,"") | T31: =IFERROR(subQ!S23+subQ!T18-subQ!T23,"") | V31: =IFERROR(subQ!T23+subQ!V18-subQ!V23,"") | W31: =IFERROR(subQ!V23+subQ!W18-subQ!W23,"") | X31: =IFERROR(subQ!W23+subQ!X18-subQ!X23,"") | Y31: =IFERROR(subQ!X23+subQ!Y18-subQ!Y23,"") | AA31: =IFERROR(subQ!Y23+subQ!AA18-subQ!AA23,"") | AB31: =IFERROR(subQ!AA23+subQ!AB18-subQ!AB23,"") | AC31: 0.006608144 | AD31: 0.005593092 | AF31: -0.005400047 | AG31: 0.003723751 | AH31: -0.000524779 | AI31: -0.00277102 | AK31: -0.001340295 | AL31: -0.000319556 | AM31: -0.002565808 | AN31: 0.003396439
A32: drv:지배주주지분 | B32: roll | C32: 지배주주지분 기타변동(배당 등, 억원) | G32: =IFERROR(subQ!E24+subQ!G19-subQ!G24,"") | H32: =IFERROR(subQ!G24+subQ!H19-subQ!H24,"") | I32: =IFERROR(subQ!H24+subQ!I19-subQ!I24,"") | J32: =IFERROR(subQ!I24+subQ!J19-subQ!J24,"") | L32: =IFERROR(subQ!J24+subQ!L19-subQ!L24,"") | M32: =IFERROR(subQ!L24+subQ!M19-subQ!M24,"") | N32: =IFERROR(subQ!M24+subQ!N19-subQ!N24,"") | O32: =IFERROR(subQ!N24+subQ!O19-subQ!O24,"") | Q32: =IFERROR(subQ!O24+subQ!Q19-subQ!Q24,"") | R32: =IFERROR(subQ!Q24+subQ!R19-subQ!R24,"") | S32: =IFERROR(subQ!R24+subQ!S19-subQ!S24,"") | T32: =IFERROR(subQ!S24+subQ!T19-subQ!T24,"") | V32: =IFERROR(subQ!T24+subQ!V19-subQ!V24,"") | W32: =IFERROR(subQ!V24+subQ!W19-subQ!W24,"") | X32: =IFERROR(subQ!W24+subQ!X19-subQ!X24,"") | Y32: =IFERROR(subQ!X24+subQ!Y19-subQ!Y24,"") | AA32: =IFERROR(subQ!Y24+subQ!AA19-subQ!AA24,"") | AB32: =IFERROR(subQ!AA24+subQ!AB19-subQ!AB24,"") | AC32: 0.006608144 | AD32: 0.005593092 | AF32: -0.005400047 | AG32: 0.003723751 | AH32: -0.000524779 | AI32: -0.00277102 | AK32: -0.001340295 | AL32: -0.000319556 | AM32: -0.002565808 | AN32: 0.003396439
A33: drv:총차입금 | B33: qoq | C33: 총차입금 QoQ | G33: =IFERROR(subQ!G25/subQ!E25-1,"") | H33: =IFERROR(subQ!H25/subQ!G25-1,"") | I33: =IFERROR(subQ!I25/subQ!H25-1,"") | J33: =IFERROR(subQ!J25/subQ!I25-1,"") | L33: =IFERROR(subQ!L25/subQ!J25-1,"") | M33: =IFERROR(subQ!M25/subQ!L25-1,"") | N33: =IFERROR(subQ!N25/subQ!M25-1,"") | O33: =IFERROR(subQ!O25/subQ!N25-1,"") | Q33: =IFERROR(subQ!Q25/subQ!O25-1,"") | R33: =IFERROR(subQ!R25/subQ!Q25-1,"") | S33: =IFERROR(subQ!S25/subQ!R25-1,"") | T33: =IFERROR(subQ!T25/subQ!S25-1,"") | V33: =IFERROR(subQ!V25/subQ!T25-1,"") | W33: =IFERROR(subQ!W25/subQ!V25-1,"") | X33: =IFERROR(subQ!X25/subQ!W25-1,"") | Y33: =IFERROR(subQ!Y25/subQ!X25-1,"") | AA33: =IFERROR(subQ!AA25/subQ!Y25-1,"") | AB33: =IFERROR(subQ!AB25/subQ!AA25-1,"") | AC33: 4.5884e-05 | AD33: 0 | AF33: 0 | AG33: 0 | AH33: 0 | AI33: 0 | AK33: 0 | AL33: 0 | AM33: 0 | AN33: 0
A34: drv:순차입금 | B34: qoq | C34: 순차입금 QoQ | G34: =IFERROR(subQ!G26/subQ!E26-1,"") | H34: =IFERROR(subQ!H26/subQ!G26-1,"") | I34: =IFERROR(subQ!I26/subQ!H26-1,"") | J34: =IFERROR(subQ!J26/subQ!I26-1,"") | L34: =IFERROR(subQ!L26/subQ!J26-1,"") | M34: =IFERROR(subQ!M26/subQ!L26-1,"") | N34: =IFERROR(subQ!N26/subQ!M26-1,"") | O34: =IFERROR(subQ!O26/subQ!N26-1,"") | Q34: =IFERROR(subQ!Q26/subQ!O26-1,"") | R34: =IFERROR(subQ!R26/subQ!Q26-1,"") | S34: =IFERROR(subQ!S26/subQ!R26-1,"") | T34: =IFERROR(subQ!T26/subQ!S26-1,"") | V34: =IFERROR(subQ!V26/subQ!T26-1,"") | W34: =IFERROR(subQ!W26/subQ!V26-1,"") | X34: =IFERROR(subQ!X26/subQ!W26-1,"") | Y34: =IFERROR(subQ!Y26/subQ!X26-1,"") | AA34: =IFERROR(subQ!AA26/subQ!Y26-1,"") | AB34: =IFERROR(subQ!AB26/subQ!AA26-1,"") | AC34: 0.14142322 | AD34: 0.1303755 | AF34: 0.10652315 | AG34: 0.098784067 | AH34: 0.088605663 | AI34: 0.085459899 | AK34: 0.072983272 | AL34: 0.069764642 | AM34: 0.066227774 | AN34: 0.06512217
A35: drv:이자발생자산 | B35: qoq | C35: 이자발생자산 QoQ | G35: =IFERROR(subQ!G27/subQ!E27-1,"") | H35: =IFERROR(subQ!H27/subQ!G27-1,"") | I35: =IFERROR(subQ!I27/subQ!H27-1,"") | J35: =IFERROR(subQ!J27/subQ!I27-1,"") | L35: =IFERROR(subQ!L27/subQ!J27-1,"") | M35: =IFERROR(subQ!M27/subQ!L27-1,"") | N35: =IFERROR(subQ!N27/subQ!M27-1,"") | O35: =IFERROR(subQ!O27/subQ!N27-1,"") | Q35: =IFERROR(subQ!Q27/subQ!O27-1,"") | R35: =IFERROR(subQ!R27/subQ!Q27-1,"") | S35: =IFERROR(subQ!S27/subQ!R27-1,"") | T35: =IFERROR(subQ!T27/subQ!S27-1,"") | V35: =IFERROR(subQ!V27/subQ!T27-1,"") | W35: =IFERROR(subQ!W27/subQ!V27-1,"") | X35: =IFERROR(subQ!X27/subQ!W27-1,"") | Y35: =IFERROR(subQ!Y27/subQ!X27-1,"") | AA35: =IFERROR(subQ!AA27/subQ!Y27-1,"") | AB35: =IFERROR(subQ!AB27/subQ!AA27-1,"") | AC35: -0.89405096 | AD35: -8.8785714 | AF35: 1.0398912 | AG35: 0.524 | AH35: 0.33829105 | AI35: 0.26585313 | AK35: 0.19435359 | AL35: 0.16719516 | AM35: 0.14534453 | AN35: 0.132938
A36: drv:현금및현금성자산 | B36: qoq | C36: 현금및현금성자산 QoQ | G36: =IFERROR(subQ!G28/subQ!E28-1,"") | H36: =IFERROR(subQ!H28/subQ!G28-1,"") | I36: =IFERROR(subQ!I28/subQ!H28-1,"") | J36: =IFERROR(subQ!J28/subQ!I28-1,"") | L36: =IFERROR(subQ!L28/subQ!J28-1,"") | M36: =IFERROR(subQ!M28/subQ!L28-1,"") | N36: =IFERROR(subQ!N28/subQ!M28-1,"") | O36: =IFERROR(subQ!O28/subQ!N28-1,"") | Q36: =IFERROR(subQ!Q28/subQ!O28-1,"") | R36: =IFERROR(subQ!R28/subQ!Q28-1,"") | S36: =IFERROR(subQ!S28/subQ!R28-1,"") | T36: =IFERROR(subQ!T28/subQ!S28-1,"") | V36: =IFERROR(subQ!V28/subQ!T28-1,"") | W36: =IFERROR(subQ!W28/subQ!V28-1,"") | X36: =IFERROR(subQ!X28/subQ!W28-1,"") | Y36: =IFERROR(subQ!Y28/subQ!X28-1,"") | AA36: =IFERROR(subQ!AA28/subQ!Y28-1,"") | AB36: =IFERROR(subQ!AB28/subQ!AA28-1,"")
A37: drv:CAPEX | B37: yoy | C37: CAPEX YoY | J37: =IFERROR(subQ!J29/subQ!E29-1,"") | L37: =IFERROR(subQ!L29/subQ!G29-1,"") | M37: =IFERROR(subQ!M29/subQ!H29-1,"") | N37: =IFERROR(subQ!N29/subQ!I29-1,"") | O37: =IFERROR(subQ!O29/subQ!J29-1,"") | Q37: =IFERROR(subQ!Q29/subQ!L29-1,"") | R37: =IFERROR(subQ!R29/subQ!M29-1,"") | S37: =IFERROR(subQ!S29/subQ!N29-1,"") | T37: =IFERROR(subQ!T29/subQ!O29-1,"") | V37: =IFERROR(subQ!V29/subQ!Q29-1,"") | W37: =IFERROR(subQ!W29/subQ!R29-1,"") | X37: =IFERROR(subQ!X29/subQ!S29-1,"") | Y37: =IFERROR(subQ!Y29/subQ!T29-1,"") | AA37: =IFERROR(subQ!AA29/subQ!V29-1,"") | AB37: =IFERROR(subQ!AB29/subQ!W29-1,"") | AC37: -0.35615206 | AD37: 2.4412955 | AF37: 1.2331691 | AG37: -0.4374819 | AH37: 0 | AI37: 0 | AK37: 0 | AL37: 0 | AM37: 0 | AN37: 0
A38: drv:영업활동현금흐름 | B38: yoy | C38: 영업활동현금흐름 YoY | J38: =IFERROR(subQ!J30/subQ!E30-1,"") | L38: =IFERROR(subQ!L30/subQ!G30-1,"") | M38: =IFERROR(subQ!M30/subQ!H30-1,"") | N38: =IFERROR(subQ!N30/subQ!I30-1,"") | O38: =IFERROR(subQ!O30/subQ!J30-1,"") | Q38: =IFERROR(subQ!Q30/subQ!L30-1,"") | R38: =IFERROR(subQ!R30/subQ!M30-1,"") | S38: =IFERROR(subQ!S30/subQ!N30-1,"") | T38: =IFERROR(subQ!T30/subQ!O30-1,"") | V38: =IFERROR(subQ!V30/subQ!Q30-1,"") | W38: =IFERROR(subQ!W30/subQ!R30-1,"") | X38: =IFERROR(subQ!X30/subQ!S30-1,"") | Y38: =IFERROR(subQ!Y30/subQ!T30-1,"") | AA38: =IFERROR(subQ!AA30/subQ!V30-1,"") | AB38: =IFERROR(subQ!AB30/subQ!W30-1,"")
A39: drv:주식수 | B39: qoq | C39: 주식수 QoQ | G39: =IFERROR(subQ!G31/subQ!E31-1,"") | H39: =IFERROR(subQ!H31/subQ!G31-1,"") | I39: =IFERROR(subQ!I31/subQ!H31-1,"") | J39: =IFERROR(subQ!J31/subQ!I31-1,"") | L39: =IFERROR(subQ!L31/subQ!J31-1,"") | M39: =IFERROR(subQ!M31/subQ!L31-1,"") | N39: =IFERROR(subQ!N31/subQ!M31-1,"") | O39: =IFERROR(subQ!O31/subQ!N31-1,"") | Q39: =IFERROR(subQ!Q31/subQ!O31-1,"") | R39: =IFERROR(subQ!R31/subQ!Q31-1,"") | S39: =IFERROR(subQ!S31/subQ!R31-1,"") | T39: =IFERROR(subQ!T31/subQ!S31-1,"") | V39: =IFERROR(subQ!V31/subQ!T31-1,"") | W39: =IFERROR(subQ!W31/subQ!V31-1,"") | X39: =IFERROR(subQ!X31/subQ!W31-1,"") | Y39: =IFERROR(subQ!Y31/subQ!X31-1,"") | AA39: =IFERROR(subQ!AA31/subQ!Y31-1,"") | AB39: =IFERROR(subQ!AB31/subQ!AA31-1,"") | AC39: 0 | AD39: 0 | AF39: 0 | AG39: 0 | AH39: 0 | AI39: 0 | AK39: 0 | AL39: 0 | AM39: 0 | AN39: 0
A40: drv:DPS | B40: abs | C40: DPS (가정, 원) | E40: =subQ!E34 | F40: =subQ!F34 | G40: =subQ!G34 | H40: =subQ!H34 | I40: =subQ!I34 | J40: =subQ!J34 | K40: =subQ!K34 | L40: =subQ!L34 | ... AB40: =subQ!AB34 | AD40: 0 | AE40: =subQ!AE34 | AI40: 0 | AJ40: =subQ!AJ34 | AN40: 0 | AO40: =subQ!AO34
B42: 3. 밸류에이션·스칼라 | C42: 노란 셀 = 가정. '연결' 표시는 추정 전 분기 수식이 이 셀을 참조한다는 뜻
...

Sheet BS연결
B1: (백만원) | C1: 이름: BS연결H | E1: 4Q21 | F1: 2021 | G1: 1Q22 | H1: 2Q22 | I1: 3Q22 | J1: 4Q22 | K1: 2022 | L1: 1Q23 | M1: 2Q23 | N1: 3Q23 | O1: 4Q23 | P1: 2023 | Q1: 1Q24 | R1: 2Q24 | S1: 3Q24 | T1: 4Q24 | U1: 2024 | V1: 1Q25 | W1: 2Q25 | X1: 3Q25 | Y1: 4Q25 | Z1: 2025 | AA1: 1Q26 | AB1: 2Q26 | AC1: 3Q26 | AD1: 4Q26 | AE1: 2026 | AF1: 1Q27 | AG1: 2Q27 | AH1: 3Q27 | AI1: 4Q27 | AJ1: 2027 | AK1: 1Q28 | AL1: 2Q28 | AM1: 3Q28 | AN1: 4Q28 | AO1: 2028
B2: 연결 | D2: fin json(kship_fin.py)
B3: 메디콕스(연) | C3: UPDATE: 26-10-11 | E3: 1 | F3: 2 | G3: 3 | H3: 4 | I3: 5 | J3: 6 | K3: 7 | L3: 8 | M3: 9 | N3: 10 | O3: 11 | P3: 12 | Q3: 13 | R3: 14 | S3: 15 | T3: 16 | U3: 17 | V3: 18 | W3: 19 | X3: 20 | Y3: 21 | Z3: 22 | AA3: 23 | AB3: 24 | AC3: 25 | AD3: 26 | AE3: 27 | AF3: 28 | AG3: 29 | AH3: 30 | AI3: 31 | AJ3: 32 | AK3: 33 | AL3: 34 | AM3: 35 | AN3: 36 | AO3: 37
B4: Account Code | C4: AccountNAME | E4: 2021.12 | F4: 2021.12A | G4: 2022.03 | H4: 2022.06 | I4: 2022.09 | J4: 2022.12 | K4: 2022.12A | L4: 2023.03 | M4: 2023.06 | N4: 2023.09 | O4: 2023.12 | P4: 2023.12A | Q4: 2024.03 | R4: 2024.06 | S4: 2024.09 | T4: 2024.12 | U4: 2024.12A | V4: 2025.03 | W4: 2025.06 | X4: 2025.09 | Y4: 2025.12 | Z4: 2025.12A | AA4: 2026.03 | AB4: 2026.06 | AC4: 2026.09 | AD4: 2026.12 | AE4: 2026.12A | AF4: 2027.03 | AG4: 2027.06 | AH4: 2027.09 | AI4: 2027.12 | AJ4: 2027.12A | AK4: 2028.03 | AL4: 2028.06 | AM4: 2028.09 | AN4: 2028.12 | AO4: 2028.12A
A5: 1 | C5: 유동자산 | E5: 26272.5 | F5: 26272.5 | G5: 25703.45 | H5: 26466.24 | I5: 32117.9 | J5: 43389.2 | K5: 43389.2 | L5: 42227.6 | M5: 51848.17 | N5: 38767.23 | O5: 30036.83 | P5: 30036.83 | Q5: 26330.28 | R5: 20475.61 | S5: 17267.64 | T5: 13255.67 | U5: 13255.67 | V5: 16443.99 | W5: 12188.47 | X5: 9412.37 | Y5: 7493.7 | Z5: 7493.7 | AA5: 8879.12 | AB5: 8317.05
A6: 1 | C6: 현금및현금성자산 | E6: 4191.05 | F6: 4191.05 | G6: 6343.7 | H6: 1677.26 | I6: 3218.69 | J6: 2979.33 | K6: 2979.33 | L6: 1884.8 | M6: 7374.47 | N6: 2140.85 | O6: 1809.98 | P6: 1809.98 | Q6: 4506.62 | R6: 1017.41 | S6: 435.9 | T6: 1228.46 | U6: 1228.46 | V6: 4618.99 | W6: 588.85 | X6: 585 | Y6: 376.6 | Z6: 376.6 | AA6: 35.59 | AB6: 40.2
A7: 1 | C7: 단기금융상품 | E7: 300 | F7: 300 | G7: 300 | H7: 300 | I7: 300 | J7: 1800 | K7: 1800 | L7: 1800 | M7: 1800 | N7: 1800 | O7: 300 | P7: 300 | Q7: 300 | R7: 2803.82 | S7: 2809.74 | T7: 3015.02 | U7: 3015.02 | V7: 2833.56 | W7: 1415.55 | X7: 50 | Y7: 100 | Z7: 100 | AA7: 100 | AB7: 106.68
A8: 1 | C8: 단기금융자산 | E8: 4011.57 | F8: 4011.57 | G8: 4011.57 | H8: 3010.05 | I8: 890.93 | J8: 10344.72 | K8: 10344.72 | L8: 10344.72 | M8: 8182.91 | N8: 4324.13 | O8: 4664.26 | P8: 4664.26 | Q8: 300 | R8: 2803.82 | S8: 2809.74 | T8: 3015.02 | U8: 3015.02 | V8: 2833.56 | W8: 1415.55 | X8: 50 | Y8: 100 | Z8: 100 | AA8: 100 | AB8: 106.68
A9: 1 | C9: 매출채권및기타채권 | E9: 2653.92 | F9: 2653.92 | G9: 2870.06 | H9: 2355 | I9: 4230.06 | J9: 6508.25 | K9: 6508.25 | L9: 5690.23 | M9: 4483.85 | N9: 4204.54 | O9: 5082.8 | P9: 5082.8 | Q9: 5441.03 | R9: 3865.23 | S9: 3895.13 | T9: 5271.27 | U9: 5271.27 | V9: 5233.61 | W9: 5004.16 | X9: 3042.81 | Y9: 2558.08 | Z9: 2558.08 | AA9: 4180.9 | AB9: 3987.68
A10: 1 | C10: 기타유동금융자산 | E10: 14250.75 | F10: 14250.75 | G10: 11450.75 | H10: 11452.33 | I10: 13745.49 | J10: 19988.79 | K10: 19988.79 | L10: 21894.39 | M10: 22134.87 | N10: 22945.92 | O10: 15578.98 | P10: 15578.98 | Q10: 13479.55 | R10: 10091.9 | S10: 7651.64
A11: 1 | C11: 유동파생상품자산 | E11: 3711.57 | F11: 3711.57 | G11: 3711.57 | H11: 2710.05 | I11: 590.93 | J11: 8544.72 | K11: 8544.72 | L11: 8544.72 | M11: 6382.91 | N11: 2524.13 | O11: 4364.26 | P11: 4364.26
A12: 1 | C12: 재고자산 | E12: 918.56 | F12: 918.56 | G12: 808.44 | H12: 1732.74 | I12: 1382.07 | J12: 1437.6 | K12: 1437.6 | L12: 1853.22 | M12: 1811.1 | N12: 2318.89 | O12: 1772.09 | P12: 1772.09 | Q12: 1795.61 | R12: 1837.04 | S12: 2076.32 | T12: 1053.93 | U12: 1053.93 | V12: 1212.42 | W12: 1115.09 | X12: 1288.83 | Y12: 1178.42 | Z12: 1178.42 | AA12: 1188.2 | AB12: 802.91
A13: 1 | C13: 기타유동자산 | E13: 235.63 | F13: 235.63 | G13: 204.42 | H13: 1214.7 | I13: 3614.26 | J13: 558.77 | K13: 558.77 | L13: 463.12 | M13: 518.68 | N13: 577.81 | O13: 1043.02 | P13: 1043.02 | Q13: 692.66 | R13: 759.28 | S13: 242.15 | T13: 689.44 | U13: 689.44 | V13: 650.11 | W13: 737.51 | X13: 1192.39 | Y13: 123.69 | Z13: 123.69 | AA13: 153.79 | AB13: 257.84
A14: 1 | C14: 당기법인세자산(선급법인세) | E14: 11.03 | F14: 11.03 | G14: 14.51 | H14: 39.96 | I14: 52.19 | J14: 71.75 | K14: 71.75 | L14: 97.12 | M14: 47.09 | N14: 63.37 | O14: 85.71 | P14: 85.71 | Q14: 114.81 | R14: 100.93 | S14: 156.78 | T14: 212.88 | U14: 212.88 | V14: 267.3 | W14: 186.71 | X14: 236.11 | Y14: 140.05 | Z14: 140.05 | AA14: 203.79 | AB14: 104.88
A15: 1 | C15: 비유동자산 | E15: 76206.74 | F15: 76206.74 | G15: 78180.61 | H15: 77491.46 | I15: 74533.26 | J15: 67044.93 | K15: 67044.93 | L15: 65576.49 | M15: 53695.88 | N15: 53000.98 | O15: 67722.71 | P15: 67722.71 | Q15: 67850.23 | R15: 63262.3 | S15: 62084.39 | T15: 68163.5 | U15: 68163.5 | V15: 67112.73 | W15: 65307.88 | X15: 62782.27 | Y15: 60760.94 | Z15: 60760.94 | AA15: 60376.72 | AB15: 60422.04
A16: 1 | C16: 장기금융자산 | E16: 5476.76 | F16: 5476.76 | G16: 5480.56 | H16: 5502.04 | I16: 4322.57 | J16: 11093.65 | K16: 11093.65 | L16: 11093.65 | M16: 4283.22 | N16: 4282.93 | O16: 6604.08 | P16: 6604.08 | Q16: 7216.1 | R16: 1113.21 | S16: 1834.25 | T16: 5968.38 | U16: 5968.38 | V16: 5548.37 | W16: 900.46 | X16: 800.46 | Y16: 1174.44 | Z16: 1174.44 | AA16: 1174.44 | AB16: 1174.51
A17: 1 | C17: 투자자산 | E17: 27974.43 | F17: 27974.43 | G17: 29107.19 | H17: 19752.38 | I17: 18281.45 | J17: 12793.65 | K17: 12793.65 | L17: 12793.65 | M17: 5071.18 | N17: 5070.89 | O17: 16020.2 | P17: 16020.2 | Q17: 16762.67 | R17: 8647.96 | S17: 8484.25 | T17: 16010.52 | U17: 16010.52 | V17: 15159.47 | W17: 10583.28 | X17: 10935.99 | Y17: 9502.52 | Z17: 9502.52 | AA17: 9502.52 | AB17: 9696.92
A18: 1 | C18: 장기매출채권및기타채권 | E18: 1264.33 | F18: 1264.33 | G18: 2072.55 | H18: 6081.85 | I18: 4464.82 | J18: 3584.91 | K18: 3584.91 | L18: 2516.12 | M18: 849.92 | N18: 819.27 | O18: 174.52 | P18: 174.52 | Q18: 82.88 | R18: 70.78 | S18: 72.23 | T18: 73.55 | U18: 73.55 | V18: 75.03 | W18: 425.44 | X18: 607.29 | Y18: 541.88 | Z18: 541.88 | AA18: 552.03 | AB18: 658.64
A19: 1 | C19: 유형자산 | E19: 46959.77 | F19: 46959.77 | G19: 46993.26 | H19: 49529.19 | I19: 49659.56 | J19: 48516.4 | K19: 48516.4 | L19: 48138.82 | M19: 47729.6 | N19: 47102.95 | O19: 51476.39 | P19: 51476.39 | Q19: 50982.53 | R19: 50868.08 | S19: 50438.62 | T19: 52063.18 | U19: 52063.18 | V19: 51864.04 | W19: 49157.06 | X19: 44799 | Y19: 44278.59 | Z19: 44278.59 | AA19: 43886.13 | AB19: 43632.37
A20: 1 | C20: 무형자산 | E20: 8.21 | F20: 8.21 | G20: 7.61 | H20: 2128.03 | I20: 2127.42 | J20: 2129.12 | K20: 2129.12 | L20: 2127.9 | M20: 45.18 | N20: 7.86 | O20: 24.22 | P20: 24.22 | Q20: 22.15 | R20: 20.46 | S20: 18.36 | T20: 16.25 | U20: 16.25 | V20: 14.18 | W20: 12.1 | X20: 9.99 | Y20: 7.94 | Z20: 7.94 | AA20: 6.03 | AB20: 4.11
A21: 1 | C21: 종속기업및관계기업투자 | E21: 22497.67 | F21: 22497.67 | G21: 23626.63 | H21: 14250.34 | I21: 13958.88 | J21: 1700 | K21: 1700 | L21: 1700 | M21: 787.96 | N21: 787.96 | O21: 9416.12 | P21: 9416.12 | Q21: 9546.57 | R21: 7534.75 | S21: 6650 | T21: 10042.14 | U21: 10042.14 | V21: 9611.1 | W21: 9682.82 | X21: 10135.53 | Y21: 8328.08 | Z21: 8328.08 | AA21: 8328.08 | AB21: 8522.41
A22: 1 | C22: 자산총계 | E22: 102479.25 | F22: 102479.25 | G22: 103884.06 | H22: 103957.69 | I22: 106651.16 | J22: 110434.13 | K22: 110434.13 | L22: 107804.09 | M22: 105544.05 | N22: 91768.21 | O22: 97759.54 | P22: 97759.54 | Q22: 94180.51 | R22: 83737.91 | S22: 79352.03 | T22: 81419.17 | U22: 81419.17 | V22: 83556.72 | W22: 77496.35 | X22: 72194.63 | Y22: 68254.63 | Z22: 68254.63 | AA22: 69255.84 | AB22: 68739.09
A23: 1 | C23: 유동부채 | E23: 33417.43 | F23: 33417.43 | G23: 34807.63 | H23: 40650.36 | I23: 27975.57 | J23: 44154.04 | K23: 44154.04 | L23: 44007.38 | M23: 42815.02 | N23: 34107.97 | O23: 30638.94 | P23: 30638.94 | Q23: 26019.19 | R23: 25258.78 | S23: 24170.21 | T23: 23801.5 | U23: 23801.5 | V23: 22267.13 | W23: 19239.74 | X23: 15750.18 | Y23: 15978.57 | Z23: 15978.57 | AA23: 18744.63 | AB23: 19472.3
... A25: 1 | C25: 기타유동부채 | E25: 822.88 | F25: 822.88 | G25: 5194.24 | H25: 5379.29 | I25: 5669.03 | J25: 3807.59 | K25: 3807.59 | L25: 2838.87 | M25: 2993.82 | N25: 965.08 | O25: 442.86 | P25: 442.86 | Q25: 288 | R25: 238.11 | S25: 272.34 | T25: 610.98 | U25: 610.98 | V25: 1221.4 | W25: 1283.37 | X25: 570.12 | Y25: 721.24 | Z25: 721.24 | AA25: 916.17 | AB25: 995.26
A26: 1 | C26: 단기차입금 | E26: 3000 | F26: 3000 | H26: 1185 | I26: 12016.58 | J26: 104 | K26: 104 | L26: 428 | M26: 115 | N26: 118 | O26: 3063 | P26: 3063 | Q26: 15946.72 | R26: 16705.78 | S26: 16352.76 | T26: 15095.09 | U26: 15095.09 | V26: 13056.42 | W26: 9992.75 | X26: 8467.49 | Y26: 8461.69 | Z26: 8461.69 | AA26: 8499.42 | AB26: 8499.61
A27: 1 | C27: 유동성장기부채 | E27: 15470.8 | F27: 15470.8 | G27: 15901.13 | H27: 20515.56 | I27: 4277.9 | J27: 16166.14 | K27: 16166.14 | L27: 16968.91 | M27: 18473.85 | N27: 18984.81 | O27: 12188.88 | P27: 12188.88 | Q27: 2135.45 | R27: 2245.27 | S27: 2362.48 | T27: 2486.27 | U27: 2486.27 | V27: 2614.1 | W27: 1475.63 | X27: 251.31
A28: 1 | C28: 단기파생상품부채 | E28: 10610.06 | F28: 10610.06 | G28: 10439.73 | H28: 9943.32 | I28: 2698.77 | J28: 18271.59 | K28: 18271.59 | L28: 18271.59 | M28: 15503.61 | N28: 8374.35 | O28: 9308.32 | P28: 9308.32 | Q28: 1647.31 | R28: 314.57 | S28: 314.57 | T28: 186.56 | U28: 186.56 | V28: 186.56 | W28: 52.49 | X28: 8.49
A29: 1 | C29: 단기금융부채 | E29: 10610.06 | F29: 10610.06 | G29: 10439.73 | H29: 9943.32 | I29: 2698.77 | J29: 18271.59 | K29: 18271.59 | L29: 18271.59 | M29: 15503.61 | N29: 8374.35 | O29: 9308.32 | P29: 9308.32 | Q29: 1647.31 | R29: 314.57 | S29: 314.57 | T29: 186.56 | U29: 186.56 | V29: 186.56 | W29: 52.49 | X29: 8.49
A30: 1 | C30: 단기충당부채 | E30: 617.11 | F30: 617.11 | G30: 667.94 | H30: 696.72 | I30: 22.78 | J30: 22.92 | K30: 22.92 | M30: 28.16 | N30: 45.41 | O30: 45.64 | P30: 45.64 | Q30: 28.6 | R30: 27.22 | S30: 27.62 | T30: 28.03 | U30: 28.03 | V30: 28.43 | W30: 28.7 | X30: 28.7
A31: 1 | C31: 비유동부채 | E31: 2861.15 | F31: 2861.15 | G31: 3018.01 | H31: 3087.72 | I31: 2997.21 | J31: 3040.32 | K31: 3040.32 | L31: 3209.05 | M31: 3152.33 | N31: 3237.46 | O31: 3816.15 | P31: 3816.15 | Q31: 3817.06 | R31: 4036 | S31: 4141.63 | T31: 5172.28 | U31: 5172.28 | V31: 5071.09 | W31: 5946.8 | X31: 5803.04 | Y31: 5167.31 | Z31: 5167.31 | AA31: 4875.3 | AB31: 4765.14
A32: 1 | C32: 비유동리스부채 | E32: 325.47 | F32: 325.47 | G32: 434.43 | H32: 595.62 | I32: 483.24 | J32: 612.97 | K32: 612.97 | L32: 588.11 | M32: 562.01 | N32: 606.32 | O32: 428.68 | P32: 428.68 | Q32: 335.54 | R32: 445.04 | S32: 408.81 | T32: 481.21 | U32: 481.21 | V32: 526.32 | W32: 1357.26 | X32: 1942.65 | Y32: 1112.32 | Z32: 1112.32 | AA32: 853.02 | AB32: 697.05
A33: 1 | C33: 리스부채 | E33: 325.47 | F33: 325.47 | G33: 434.43 | H33: 595.62 | I33: 483.24 | J33: 612.97 | K33: 612.97 | L33: 588.11 | M33: 562.01 | N33: 606.32 | O33: 428.68 | P33: 428.68 | Q33: 335.54 | R33: 445.04 | S33: 408.81 | T33: 481.21 | U33: 481.21 | V33: 526.32 | W33: 1357.26 | X33: 1942.65 | Y33: 1112.32 | Z33: 1112.32 | AA33: 853.02 | AB33: 697.05
A34: 1 | C34: 장기금융부채 | E34: 325.47 | F34: 325.47 | G34: 434.43 | H34: 595.62 | I34: 483.24 | J34: 612.97 | K34: 612.97 | L34: 588.11 | M34: 562.01 | N34: 606.32 | O34: 428.68 | P34: 428.68 | Q34: 335.54 | R34: 445.04 | S34: 408.81 | T34: 481.21 | U34: 481.21 | V34: 526.32 | W34: 1357.26 | X34: 1942.65 | Y34: 1112.32 | Z34: 1112.32 | AA34: 853.02 | AB34: 697.05
A35: 1 | C35: 확정급여부채 | E35: 141.72 | F35: 141.72 | G35: 212.01 | H35: 92.94 | I35: 97.89 | J35: 39.38 | K35: 39.38 | L35: 233.07 | M35: 230.67 | N35: 288.73 | Q35: 94.19 | R35: 203.71 | S35: 345.6 | T35: 595.61 | U35: 595.61 | V35: 449.31 | W35: 469.04 | X35: 503.66 | Y35: 509.22 | Z35: 509.22 | AA35: 475.74 | AB35: 520.77
A36: 1 | C36: 장기충당부채 | E36: 22.38 | F36: 22.38 | H36: 27.59 | I36: 44.51 | J36: 44.74 | K36: 44.74 | L36: 44.96 | M36: 17.02 | W36: 25.03 | X36: 61.89 | Y36: 65.75 | Z36: 65.75 | AA36: 66.51 | AB36: 67.3
A37: 1 | C37: 이연법인세부채 | E37: 2371.58 | F37: 2371.58 | G37: 2371.58 | H37: 2371.58 | I37: 2371.58 | J37: 2263.78 | K37: 2263.78 | L37: 2263.78 | M37: 2263.78 | N37: 2263.78 | O37: 3309 | P37: 3309 | Q37: 3309 | R37: 3309 | S37: 3309 | T37: 4095.46 | U37: 4095.46 | V37: 4095.46 | W37: 4095.46 | X37: 3294.14 | Y37: 3473.02 | Z37: 3473.02 | AA37: 3473.02 | AB37: 3473.02
A38: 1 | C38: 부채총계 | E38: 36278.58 | F38: 36278.58 | G38: 37825.64 | H38: 43738.08 | I38: 30972.79 | J38: 47194.37 | K38: 47194.37 | L38: 47216.43 | M38: 45967.34 | N38: 37345.43 | O38: 34455.09 | P38: 34455.09 | Q38: 29836.25 | R38: 29294.78 | S38: 28311.85 | T38: 28973.78 | U38: 28973.78 | V38: 27338.23 | W38: 25186.54 | X38: 21553.22 | Y38: 21145.88 | Z38: 21145.88 | AA38: 23619.92 | AB38: 24237.44
A39: 1 | C39: 지배주주지분 | E39: 66203.82 | F39: 66203.82 | G39: 66058.42 | H39: 60219.61 | I39: 75678.37 | J39: 63239.76 | K39: 63239.76 | L39: 60587.65 | M39: 59576.71 | N39: 54422.78 | O39: 63304.44 | P39: 63304.44 | Q39: 64344.26 | R39: 54443.13 | S39: 51040.19 | T39: 52445.39 | U39: 52445.39 | V39: 56218.5 | W39: 52309.81 | X39: 50641.42 | Y39: 47108.75 | Z39: 47108.75 | AA39: 45635.92 | AB39: 44501.64
A40: 1 | C40: 자본금 | E40: 47303.95 | F40: 47303.95 | G40: 48143.08 | H40: 4814.31 | I40: 6052.83 | J40: 12773.66 | K40: 12773.66 | L40: 13092.34 | M40: 14858.61 | N40: 15038.73 | O40: 26138.72 | P40: 26138.72 | Q40: 28575.58 | R40: 28575.58 | S40: 29439.14 | T40: 34439.14 | U40: 34439.14 | V40: 41439.14 | W40: 41439.14 | X40: 2763.99 | Y40: 2763.99 | Z40: 2763.99 | AA40: 2763.99 | AB40: 2763.99
A41: 1 | C41: 기타자본 | E41: 59933.08 | F41: 59933.08 | G41: 60546.18 | H41: 103679.84 | I41: 132585.7 | J41: 133907.81 | K41: 133907.81 | L41: 134582.99 | M41: 141313.24 | N41: 98599.01 | O41: 111811.54 | P41: 111811.54 | Q41: 111321.28 | R41: 108861 | S41: 108406.91 | T41: 114203.1 | U41: 114203.1 | V41: 113709.54 | W41: 113425.7 | X41: 113728.15 | Y41: 113574.78 | Z41: 113574.78 | AA41: 113574.78 | AB41: 113574.78
...

Sheet BS별도
B1: (백만원) | C1: 이름: BS별도H | E1: 4Q21 | F1: 2021 | G1: 1Q22 | H1: 2Q22 | I1: 3Q22 | J1: 4Q22 | K1: 2022 | L1: 1Q23 | M1: 2Q23 | N1: 3Q23 | O1: 4Q23 | P1: 2023 | Q1: 1Q24 | R1: 2Q24 | S1: 3Q24 | T1: 4Q24 | U1: 2024 | V1: 1Q25 | W1: 2Q25 | X1: 3Q25 | Y1: 4Q25 | Z1: 2025 | AA1: 1Q26 | AB1: 2Q26 | AC1: 3Q26 | AD1: 4Q26 | AE1: 2026 | AF1: 1Q27 | AG1: 2Q27 | AH1: 3Q27 | AI1: 4Q27 | AJ1: 2027 | AK1: 1Q28 | AL1: 2Q28 | AM1: 3Q28 | AN1: 4Q28 | AO1: 2028
B2: 별도 | D2: fin json(kship_fin.py)
B3: 메디콕스(별) | C3: UPDATE: 26-10-11 | E3: 1 | F3: 2 | G3: 3 | H3: 4 | I3: 5 | J3: 6 | K3: 7 | L3: 8 | M3: 9 | N3: 10 | O3: 11 | P3: 12 | Q3: 13 | R3: 14 | S3: 15 | T3: 16 | U3: 17 | V3: 18 | W3: 19 | X3: 20 | Y3: 21 | Z3: 22 | AA3: 23 | AB3: 24 | AC3: 25 | AD3: 26 | AE3: 27 | AF3: 28 | AG3: 29 | AH3: 30 | AI3: 31 | AJ3: 32 | AK3: 33 | AL3: 34 | AM3: 35 | AN3: 36 | AO3: 37
B4: Account Code | C4: AccountNAME | E4: 2021.12 | F4: 2021.12A | G4: 2022.03 | H4: 2022.06 | I4: 2022.09 | J4: 2022.12 | K4: 2022.12A | L4: 2023.03 | M4: 2023.06 | N4: 2023.09 | O4: 2023.12 | P4: 2023.12A | Q4: 2024.03 | R4: 2024.06 | S4: 2024.09 | T4: 2024.12 | U4: 2024.12A | V4: 2025.03 | W4: 2025.06 | X4: 2025.09 | Y4: 2025.12 | Z4: 2025.12A | AA4: 2026.03 | AB4: 2026.06 | AC4: 2026.09 | AD4: 2026.12 | AE4: 2026.12A | AF4: 2027.03 | AG4: 2027.06 | AH4: 2027.09 | AI4: 2027.12 | AJ4: 2027.12A | AK4: 2028.03 | AL4: 2028.06 | AM4: 2028.09 | AN4: 2028.12 | AO4: 2028.12A
A5: 1 | C5: 유동자산 | E5: 18368.91 | F5: 18368.91 | G5: 20649.05 | H5: 25559.66 | I5: 30567.02 | J5: 41186.85 | K5: 41186.85 | L5: 39273.29 | M5: 50490.19 | N5: 38680.6 | O5: 29911 | P5: 29911 | Q5: 26308.96 | R5: 20353.79 | S5: 17155.19 | T5: 13097.94 | U5: 13097.94 | V5: 15998.95 | W5: 11889.02 | X5: 9201.47 | Y5: 6904.69 | Z5: 6904.69 | AA5: 8206.17 | AB5: 7710.19
A6: 1 | C6: 현금및현금성자산 | E6: 4109.15 | F6: 4109.15 | G6: 6316.21 | H6: 1418.3 | I6: 2938.17 | J6: 2775.6 | K6: 2775.6 | L6: 1741.41 | M6: 7364.88 | N6: 2134.24 | O6: 1776.74 | P6: 1776.74 | Q6: 4500.85 | R6: 1013.72 | S6: 432.05 | T6: 1224.83 | U6: 1224.83 | V6: 4377.78 | W6: 462.07 | X6: 569.84 | Y6: 316.63 | Z6: 316.63 | AA6: 35.09 | AB6: 39.81
A7: 1 | C7: 단기금융상품 | E7: 300 | F7: 300 | G7: 300 | H7: 300 | I7: 300 | J7: 1800 | K7: 1800 | L7: 1800 | M7: 1800 | N7: 1800 | O7: 300 | P7: 300 | Q7: 300 | R7: 2803.82 | S7: 2809.74 | T7: 3015.02 | U7: 3015.02 | V7: 2833.56 | W7: 1415.55 | X7: 50 | Y7: 100 | Z7: 100 | AA7: 100 | AB7: 106.68
A8: 1 | C8: 단기금융자산 | E8: 4011.57 | F8: 4011.57 | G8: 4011.57 | H8: 3010.05 | I8: 890.93 | J8: 10344.72 | K8: 10344.72 | L8: 10344.72 | M8: 8182.91 | N8: 4324.13 | O8: 4664.26 | P8: 4664.26 | Q8: 300 | R8: 2803.82 | S8: 2809.74 | T8: 3015.02 | U8: 3015.02 | V8: 2833.56 | W8: 1415.55 | X8: 50 | Y8: 100 | Z8: 100 | AA8: 100 | AB8: 106.68
A9: 1 | C9: 매출채권및기타채권 | E9: 2633.48 | F9: 2633.48 | G9: 2843.19 | H9: 3758.86 | I9: 5009.55 | J9: 6670.75 | K9: 6670.75 | L9: 5086.97 | M9: 6036.58 | N9: 4469.06 | O9: 4995.83 | P9: 4995.83 | Q9: 5440.88 | R9: 3809.49 | S9: 3894.98 | T9: 5271.12 | U9: 5271.12 | V9: 5233.46 | W9: 5004.01 | X9: 3022.62 | Y9: 2196.4 | Z9: 2196.4 | AA9: 3774.76 | AB9: 3579.03
A10: 1 | C10: 기타유동금융자산 | E10: 6452.33 | F10: 6452.33 | G10: 6452.33 | H10: 9452.33 | I10: 11745.49 | J10: 17988.79 | K10: 17988.79 | L10: 19894.39 | M10: 22134.87 | N10: 22945.92 | O10: 15578.98 | P10: 15578.98 | Q10: 13479.55 | R10: 10091.9 | S10: 7651.64
A11: 1 | C11: 유동파생상품자산 | E11: 3711.57 | F11: 3711.57 | G11: 3711.57 | H11: 2710.05 | I11: 590.93 | J11: 8544.72 | K11: 8544.72 | L11: 8544.72 | M11: 6382.91 | N11: 2524.13 | O11: 4364.26 | P11: 4364.26
A12: 1 | C12: 재고자산 | E12: 918.56 | F12: 918.56 | G12: 808.44 | H12: 1732.74 | I12: 1382.07 | J12: 1437.6 | K12: 1437.6 | L12: 1853.22 | M12: 1811.1 | N12: 2318.89 | O12: 1772.09 | P12: 1772.09 | Q12: 1795.61 | R12: 1837.04 | S12: 2076.32 | T12: 1053.93 | U12: 1053.93 | V12: 1212.42 | W12: 1115.09 | X12: 1288.83 | Y12: 1178.42 | Z12: 1178.42 | AA12: 1188.2 | AB12: 802.91
A13: 1 | C13: 기타유동자산 | E13: 232.79 | F13: 232.79 | G13: 202.8 | H13: 1151.4 | I13: 3552.64 | J13: 401.17 | K13: 401.17 | L13: 259.01 | M13: 341.14 | N13: 425.79 | O13: 1038.76 | P13: 1038.76 | Q13: 692.08 | R13: 758.51 | S13: 241.75 | T13: 689.09 | U13: 689.09 | V13: 649.87 | W13: 678.75 | X13: 1172.98 | Y13: 67.67 | Z13: 67.67 | AA13: 61.46 | AB13: 161.18
A14: 1 | C14: 당기법인세자산(선급법인세) | E14: 11.03 | F14: 11.03 | G14: 14.5 | H14: 36.47 | I14: 48.66 | J14: 68.22 | K14: 68.22 | L14: 93.58 | M14: 46.28 | N14: 62.57 | O14: 84.34 | P14: 84.34 | Q14: 99.99 | R14: 39.31 | S14: 48.73 | T14: 59.28 | U14: 59.28 | V14: 63.86 | W14: 72.95 | X14: 79.97 | Y14: 28.71 | Z14: 28.71 | AA14: 29.81 | AB14: 3.73
A15: 1 | C15: 비유동자산 | E15: 83605.21 | F15: 83605.21 | G15: 79541.94 | H15: 74570.55 | I15: 73537.04 | J15: 66250.11 | K15: 66250.11 | L15: 65878.21 | M15: 53103.71 | N15: 52618.57 | O15: 66539.02 | P15: 66539.02 | Q15: 67402.24 | R15: 63622.92 | S15: 62700.25 | T15: 68190.76 | U15: 68190.76 | V15: 67646.59 | W15: 65465.26 | X15: 62924.84 | Y15: 61353.27 | Z15: 61353.27 | AA15: 61125.19 | AB15: 60943.72
A16: 1 | C16: 장기금융자산 | E16: 2476.76 | F16: 2476.76 | G16: 2480.56 | H16: 2427.04 | I16: 1322.57 | J16: 8093.65 | K16: 8093.65 | L16: 8093.65 | M16: 4283.22 | N16: 4282.93 | O16: 6604.08 | P16: 6604.08 | Q16: 7216.1 | R16: 1113.21 | S16: 1834.25 | T16: 5968.38 | U16: 5968.38 | V16: 5548.37 | W16: 900.46 | X16: 800.46 | Y16: 1174.44 | Z16: 1174.44 | AA16: 1174.44 | AB16: 1174.51
A17: 1 | C17: 투자자산 | E17: 35407.98 | F17: 35407.98 | G17: 30495.55 | H17: 22286.72 | I17: 21181.82 | J17: 15923.23 | K17: 15923.23 | L17: 15922.74 | M17: 5071.18 | N17: 5070.89 | O17: 14951.59 | P17: 14951.59 | Q17: 16316.1 | R17: 9009.71 | S17: 9100.95 | T17: 16038.32 | U17: 16038.32 | V17: 15693.58 | W17: 10635.72 | X17: 10973.61 | Y17: 9551.58 | Z17: 9551.58 | AA17: 9551.58 | AB17: 9513.53
A18: 1 | C18: 장기매출채권및기타채권 | E18: 1264.24 | F18: 1264.24 | G18: 2072.46 | H18: 2881.76 | I18: 3087.28 | J18: 2306.58 | K18: 2306.58 | L18: 2337.43 | M18: 670.85 | N18: 718.67 | O18: 173.92 | P18: 173.92 | Q18: 82.83 | R18: 70.73 | S18: 72.18 | T18: 73.5 | U18: 73.5 | V18: 74.98 | W18: 1660.39 | X18: 2142.24 | Y18: 2557.83 | Z18: 2557.83 | AA18: 2721.98 | AB18: 2832.09
A19: 1 | C19: 유형자산 | E19: 46924.78 | F19: 46924.78 | G19: 46966.32 | H19: 49392.79 | I19: 49259.27 | J19: 47991.38 | K19: 47991.38 | L19: 47610.59 | M19: 47354.82 | N19: 46821.14 | O19: 51361.9 | P19: 51361.9 | Q19: 50981.16 | R19: 50867 | S19: 50437.84 | T19: 52062.69 | U19: 52062.69 | V19: 51863.83 | W19: 49157.06 | X19: 44799 | Y19: 44235.92 | Z19: 44235.92 | AA19: 43845.59 | AB19: 43593.99
A20: 1 | C20: 무형자산 | E20: 8.21 | F20: 8.21 | G20: 7.61 | H20: 9.27 | I20: 8.66 | J20: 8.06 | K20: 8.06 | L20: 7.46 | M20: 6.86 | N20: 7.86 | O20: 24.22 | P20: 24.22 | Q20: 22.15 | R20: 20.46 | S20: 18.36 | T20: 16.25 | U20: 16.25 | V20: 14.18 | W20: 12.1 | X20: 9.99 | Y20: 7.94 | Z20: 7.94 | AA20: 6.03 | AB20: 4.11
A21: 1 | C21: 종속기업및관계기업투자 | E21: 32931.22 | F21: 32931.22 | G21: 28014.99 | H21: 19859.68 | I21: 19859.25 | J21: 7829.58 | K21: 7829.58 | L21: 7829.09 | M21: 787.96 | N21: 787.96 | O21: 8347.51 | P21: 8347.51 | Q21: 9100 | R21: 7896.5 | S21: 7266.7 | T21: 10069.94 | U21: 10069.94 | V21: 10145.21 | W21: 9735.26 | X21: 10173.15 | Y21: 8377.14 | Z21: 8377.14 | AA21: 8377.14 | AB21: 8339.02
A22: 1 | C22: 자산총계 | E22: 101974.12 | F22: 101974.12 | G22: 100190.99 | H22: 100130.2 | I22: 104104.06 | J22: 107436.95 | K22: 107436.95 | L22: 105151.51 | M22: 103593.9 | N22: 91299.16 | O22: 96450.02 | P22: 96450.02 | Q22: 93711.2 | R22: 83976.71 | S22: 79855.44 | T22: 81288.7 | U22: 81288.7 | V22: 83645.53 | W22: 77354.28 | X22: 72126.3 | Y22: 68257.96 | Z22: 68257.96 | AA22: 69331.36 | AB22: 68653.91
A23: 1 | C23: 유동부채 | E23: 32910.78 | F23: 32910.78 | G23: 32363.17 | H23: 36702.27 | I23: 24819.29 | J23: 41015.24 | K23: 41015.24 | L23: 40622.62 | M23: 39739.2 | N23: 33353.16 | O23: 30354.98 | P23: 30354.98 | Q23: 25804.51 | R23: 24992.32 | S23: 23849.55 | T23: 23426.13 | U23: 23426.13 | V23: 21861.59 | W23: 19060.5 | X23: 15678.44 | Y23: 15733.17 | Z23: 15733.17 | AA23: 18427.35 | AB23: 18968.87
... A25: 1 | C25: 기타유동부채 | E25: 349.72 | F25: 349.72 | G25: 2772.38 | H25: 2704.78 | I25: 2987.02 | J25: 1274.21 | K25: 1274.21 | L25: 186.92 | M25: 492.96 | N25: 899.02 | O25: 442.86 | P25: 442.86 | Q25: 288 | R25: 238.11 | S25: 272.34 | T25: 610.98 | U25: 610.98 | V25: 1221.4 | W25: 1283.19 | X25: 569.76 | Y25: 710.18 | Z25: 710.18 | AA25: 886.5 | AB25: 940.99
A26: 1 | C26: 단기차입금 | E26: 3000 | F26: 3000 | I26: 11876.58 | O26: 3000 | P26: 3000 | Q26: 15734.06 | R26: 16440.05 | S26: 16032.97 | T26: 14720.85 | U26: 14720.85 | V26: 12643.12 | W26: 9809.46 | X26: 8309.2 | Y26: 8268.39 | Z26: 8268.39 | AA26: 8285.22 | AB26: 8281.51
A27: 1 | C27: 유동성장기부채 | E27: 15470.8 | F27: 15470.8 | G27: 15901.13 | H27: 20515.56 | I27: 4277.9 | J27: 16166.14 | K27: 16166.14 | L27: 16968.91 | M27: 18473.85 | N27: 18984.81 | O27: 12188.88 | P27: 12188.88 | Q27: 2135.45 | R27: 2245.27 | S27: 2362.48 | T27: 2486.27 | U27: 2486.27 | V27: 2614.1 | W27: 1475.63 | X27: 251.31
A28: 1 | C28: 단기파생상품부채 | E28: 10610.06 | F28: 10610.06 | G28: 10439.73 | H28: 9943.32 | I28: 2698.77 | J28: 18271.59 | K28: 18271.59 | L28: 18271.59 | M28: 15503.61 | N28: 8374.35 | O28: 9308.32 | P28: 9308.32 | Q28: 1647.31 | R28: 314.57 | S28: 314.57 | T28: 186.56 | U28: 186.56 | V28: 186.56 | W28: 52.49 | X28: 8.49
A29: 1 | C29: 단기금융부채 | E29: 10610.06 | F29: 10610.06 | G29: 10439.73 | H29: 9943.32 | I29: 2698.77 | J29: 18271.59 | K29: 18271.59 | L29: 18271.59 | M29: 15503.61 | N29: 8374.35 | O29: 9308.32 | P29: 9308.32 | Q29: 1647.31 | R29: 314.57 | S29: 314.57 | T29: 186.56 | U29: 186.56 | V29: 186.56 | W29: 52.49 | X29: 8.49
A30: 1 | C30: 단기충당부채 | E30: 617.11 | F30: 617.11 | G30: 667.94 | H30: 696.72 | I30: 22.78 | J30: 22.92 | K30: 22.92 | M30: 28.16 | N30: 28.31 | O30: 28.46 | P30: 28.46 | Q30: 28.6 | R30: 27.22 | S30: 27.62 | T30: 28.03 | U30: 28.03 | V30: 28.43 | W30: 28.7 | X30: 28.7
A31: 1 | C31: 비유동부채 | E31: 2861.15 | F31: 2861.15 | G31: 3018.01 | H31: 3056.04 | I31: 2881.51 | J31: 2807.62 | K31: 2807.62 | L31: 2996.86 | M31: 3013.48 | N31: 3122.95 | O31: 3777.86 | P31: 3777.86 | Q31: 3817.06 | R31: 4036 | S31: 4141.63 | T31: 5172.28 | U31: 5172.28 | V31: 5071.09 | W31: 5946.8 | X31: 5803.04 | Y31: 5127.18 | Z31: 5127.18 | AA31: 4837.21 | AB31: 4716.35
A32: 1 | C32: 비유동리스부채 | E32: 325.47 | F32: 325.47 | G32: 434.43 | H32: 589.05 | I32: 415.04 | J32: 436.49 | K32: 436.49 | L32: 438.87 | M32: 440.19 | N32: 499.08 | O32: 390.39 | P32: 390.39 | Q32: 335.54 | R32: 445.04 | S32: 408.81 | T32: 481.21 | U32: 481.21 | V32: 526.32 | W32: 1357.26 | X32: 1942.65 | Y32: 1077.54 | Z32: 1077.54 | AA32: 820.29 | AB32: 666.38
A33: 1 | C33: 리스부채 | E33: 325.47 | F33: 325.47 | G33: 434.43 | H33: 589.05 | I33: 415.04 | J33: 436.49 | K33: 436.49 | L33: 438.87 | M33: 440.19 | N33: 499.08 | O33: 390.39 | P33: 390.39 | Q33: 335.54 | R33: 445.04 | S33: 408.81 | T33: 481.21 | U33: 481.21 | V33: 526.32 | W33: 1357.26 | X33: 1942.65 | Y33: 1077.54 | Z33: 1077.54 | AA33: 820.29 | AB33: 666.38
A34: 1 | C34: 장기금융부채 | E34: 325.47 | F34: 325.47 | G34: 434.43 | H34: 589.05 | I34: 415.04 | J34: 436.49 | K34: 436.49 | L34: 438.87 | M34: 440.19 | N34: 499.08 | O34: 390.39 | P34: 390.39 | Q34: 335.54 | R34: 445.04 | S34: 408.81 | T34: 481.21 | U34: 481.21 | V34: 526.32 | W34: 1357.26 | X34: 1942.65 | Y34: 1077.54 | Z34: 1077.54 | AA34: 820.29 | AB34: 666.38
A35: 1 | C35: 확정급여부채 | E35: 141.72 | F35: 141.72 | G35: 212.01 | H35: 67.83 | I35: 67.15 | L35: 187.07 | M35: 230.67 | N35: 281.46 | Q35: 94.19 | R35: 203.71 | S35: 345.6 | T35: 595.61 | U35: 595.61 | V35: 449.31 | W35: 469.04 | X35: 503.66 | Y35: 503.87 | Z35: 503.87 | AA35: 470.39 | AB35: 502.65
A36: 1 | C36: 장기충당부채 | E36: 22.38 | F36: 22.38 | H36: 27.59 | I36: 27.73 | J36: 27.88 | K36: 27.88 | L36: 28.02 | W36: 25.03 | X36: 61.89 | Y36: 65.75 | Z36: 65.75 | AA36: 66.51 | AB36: 67.3
A37: 1 | C37: 이연법인세부채 | E37: 2371.58 | F37: 2371.58 | G37: 2371.58 | H37: 2371.58 | I37: 2371.58 | J37: 2263.78 | K37: 2263.78 | L37: 2263.78 | M37: 2263.78 | N37: 2263.78 | O37: 3309 | P37: 3309 | Q37: 3309 | R37: 3309 | S37: 3309 | T37: 4095.46 | U37: 4095.46 | V37: 4095.46 | W37: 4095.46 | X37: 3294.14 | Y37: 3473.02 | Z37: 3473.02 | AA37: 3473.02 | AB37: 3473.02
A38: 1 | C38: 부채총계 | E38: 35771.93 | F38: 35771.93 | G38: 35381.18 | H38: 39758.31 | I38: 27700.79 | J38: 43822.86 | K38: 43822.86 | L38: 43619.48 | M38: 42752.68 | N38: 36476.11 | O38: 34132.84 | P38: 34132.84 | Q38: 29621.57 | R38: 29028.31 | S38: 27991.18 | T38: 28598.41 | U38: 28598.41 | V38: 26932.68 | W38: 25007.3 | X38: 21481.48 | Y38: 20860.36 | Z38: 20860.36 | AA38: 23264.55 | AB38: 23685.22
A39: 1 | C39: 자본금 | E39: 47303.95 | F39: 47303.95 | G39: 48143.08 | H39: 4814.31 | I39: 6052.83 | J39: 12773.66 | K39: 12773.66 | L39: 13092.34 | M39: 14858.61 | N39: 15038.73 | O39: 26138.72 | P39: 26138.72 | Q39: 28575.58 | R39: 28575.58 | S39: 29439.14 | T39: 34439.14 | U39: 34439.14 | V39: 41439.14 | W39: 41439.14 | X39: 2763.99 | Y39: 2763.99 | Z39: 2763.99 | AA39: 2763.99 | AB39: 2763.99
A40: 1 | C40: 기타자본 | E40: 58753.15 | F40: 58753.15 | G40: 59331.29 | H40: 102617.43 | I40: 131512.25 | J40: 132626.24 | K40: 132626.24 | L40: 133301.42 | M40: 140031.66 | N40: 97317.44 | O40: 110529.97 | P40: 110529.97 | Q40: 110039.7 | R40: 107579.43 | S40: 107125.33 | T40: 112921.53 | U40: 112921.53 | V40: 112427.96 | W40: 112144.13 | X40: 112446.57 | Y40: 112293.2 | Z40: 112293.2 | AA40: 112293.2 | AB40: 112293.2
A41: 1 | C41: 이익잉여금 | E41: -39854.91 | F41: -39854.91 | G41: -42664.56 | H41: -47059.84 | I41: -61161.82 | J41: -81785.81 | K41: -81785.81 | L41: -84861.73 | M41: -94049.05 | N41: -57533.11 | O41: -74351.51 | P41: -74351.51 | Q41: -74525.65 | R41: -81206.61 | S41: -84700.21 | T41: -94670.38 | U41: -94670.38 | V41: -97154.25 | W41: -101236.29 | X41: -64565.74 | Y41: -67659.59 | Z41: -67659.59 | AA41: -68990.38 | AB41: -70088.5
...

Sheet subQ
A1: YQ | C1: subQ 분기 서브모델(억원, U=100) | E1: 4Q21 | F1: 2021 | G1: 1Q22 | H1: 2Q22 | I1: 3Q22 | J1: 4Q22 | K1: 2022 | L1: 1Q23 | M1: 2Q23 | N1: 3Q23 | O1: 4Q23 | P1: 2023 | Q1: 1Q24 | R1: 2Q24 | S1: 3Q24 | T1: 4Q24 | U1: 2024 | V1: 1Q25 | W1: 2Q25 | X1: 3Q25 | Y1: 4Q25 | Z1: 2025 | AA1: 1Q26 | AB1: 2Q26 | AC1: 3Q26 | AD1: 4Q26 | AE1: 2026 | AF1: 1Q27 | AG1: 2Q27 | AH1: 3Q27 | AI1: 4Q27 | AJ1: 2027 | AK1: 1Q28 | AL1: 2Q28 | AM1: 3Q28 | AN1: 4Q28 | AO1: 2028
A2: A=이름(key) B=그룹 C=단위 D=FnGuide 계정명(VLOOKUP 키). 확정=VLOOKUP(BS), 추정=변수 가정 참조
E3: 1 | F3: 2 | G3: 3 | H3: 4 | I3: 5 | J3: 6 | K3: 7 | L3: 8 | M3: 9 | N3: 10 | O3: 11 | P3: 12 | Q3: 13 | R3: 14 | S3: 15 | T3: 16 | U3: 17 | V3: 18 | W3: 19 | X3: 20 | Y3: 21 | Z3: 22 | AA3: 23 | AB3: 24 | AC3: 25 | AD3: 26 | AE3: 27 | AF3: 28 | AG3: 29 | AH3: 30 | AI3: 31 | AJ3: 32 | AK3: 33 | AL3: 34 | AM3: 35 | AN3: 36 | AO3: 37
E4: 2021.12 | F4: 2021.12A | G4: 2022.03 | H4: 2022.06 | I4: 2022.09 | J4: 2022.12 | K4: 2022.12A | L4: 2023.03 | M4: 2023.06 | N4: 2023.09 | O4: 2023.12 | P4: 2023.12A | Q4: 2024.03 | R4: 2024.06 | S4: 2024.09 | T4: 2024.12 | U4: 2024.12A | V4: 2025.03 | W4: 2025.06 | X4: 2025.09 | Y4: 2025.12 | Z4: 2025.12A | AA4: 2026.03 | AB4: 2026.06 | AC4: 2026.09 | AD4: 2026.12 | AE4: 2026.12A | AF4: 2027.03 | AG4: 2027.06 | AH4: 2027.09 | AI4: 2027.12 | AJ4: 2027.12A | AK4: 2028.03 | AL4: 2028.06 | AM4: 2028.09 | AN4: 2028.12 | AO4: 2028.12A
A5: 매출액 | B5: 손익 | C5: 억원 | D5: 매출액(수익) | E5: =IFERROR(VLOOKUP($D5,BS연결,MATCH(E$1,BS연결H,0),0)/100,"") | G5: =IFERROR(VLOOKUP($D5,BS연결,MATCH(G$1,BS연결H,0),0)/100,"") | H5: =IFERROR(VLOOKUP($D5,BS연결,MATCH(H$1,BS연결H,0),0)/100,"") | I5: =IFERROR(VLOOKUP($D5,BS연결,MATCH(I$1,BS연결H,0),0)/100,"") | J5: =IFERROR(VLOOKUP($D5,BS연결,MATCH(J$1,BS연결H,0),0)/100,"") | K5: =IFERROR(VLOOKUP($D5,BS연결,MATCH(K$1,BS연결H,0),0)/100,"") | L5: =IFERROR(VLOOKUP($D5,BS연결,MATCH(L$1,BS연결H,0),0)/100,"") | M5: =IFERROR(VLOOKUP($D5,BS연결,MATCH(M$1,BS연결H,0),0)/100,"") | N5: =IFERROR(VLOOKUP($D5,BS연결,MATCH(N$1,BS연결H,0),0)/100,"") | ... AB5: =IFERROR(VLOOKUP($D5,BS연결,MATCH(AB$1,BS연결H,0),0)/100,"") | AC5: =IFERROR(X5*(1+변수!AC21),"") | AD5: =IFERROR(Y5*(1+변수!AD21),"") | AE5: =SUM(AA5:AD5) | AF5: =IFERROR(AA5*(1+변수!AF21),"") | AG5: =IFERROR(AB5*(1+변수!AG21),"") | AH5: =IFERROR(AC5*(1+변수!AH21),"") | AI5: =IFERROR(AD5*(1+변수!AI21),"") | AJ5: =SUM(AF5:AI5) | AK5: =IFERROR(AF5*(1+변수!AK21),"") | AL5: =IFERROR(AG5*(1+변수!AL21),"") | AM5: =IFERROR(AH5*(1+변수!AM21),"") | AN5: =IFERROR(AI5*(1+변수!AN21),"") | AO5: =SUM(AK5:AN5)
A6: 매출원가 | B6: 손익 | C6: 억원 | D6: 매출원가 | E6: =IFERROR(VLOOKUP($D6,BS연결,MATCH(E$1,BS연결H,0),0)/100,"") | G6: =IFERROR(VLOOKUP($D6,BS연결,MATCH(G$1,BS연결H,0),0)/100,"") | H6: =IFERROR(VLOOKUP($D6,BS연결,MATCH(H$1,BS연결H,0),0)/100,"") | I6: =IFERROR(VLOOKUP($D6,BS연결,MATCH(I$1,BS연결H,0),0)/100,"") | J6: =IFERROR(VLOOKUP($D6,BS연결,MATCH(J$1,BS연결H,0),0)/100,"") | K6: =IFERROR(VLOOKUP($D6,BS연결,MATCH(K$1,BS연결H,0),0)/100,"") | L6: =IFERROR(VLOOKUP($D6,BS연결,MATCH(L$1,BS연결H,0),0)/100,"") | M6: =IFERROR(VLOOKUP($D6,BS연결,MATCH(M$1,BS연결H,0),0)/100,"") | N6: =IFERROR(VLOOKUP($D6,BS연결,MATCH(N$1,BS연결H,0),0)/100,"") | ... AB6: =IFERROR(VLOOKUP($D6,BS연결,MATCH(AB$1,BS연결H,0),0)/100,"") | AC6: =IFERROR(AC5-AC7,"") | AD6: =IFERROR(AD5-AD7,"") | AE6: =SUM(AA6:AD6) | AF6: =IFERROR(AF5-AF7,"") | AG6: =IFERROR(AG5-AG7,"") | AH6: =IFERROR(AH5-AH7,"") | AI6: =IFERROR(AI5-AI7,"") | AJ6: =SUM(AF6:AI6) | AK6: =IFERROR(AK5-AK7,"") | AL6: =IFERROR(AL5-AL7,"") | AM6: =IFERROR(AM5-AM7,"") | AN6: =IFERROR(AN5-AN7,"") | AO6: =SUM(AK6:AN6)
A7: 매출총이익 | B7: 손익 | C7: 억원 | D7: 매출총이익 | E7: =IFERROR(VLOOKUP($D7,BS연결,MATCH(E$1,BS연결H,0),0)/100,"") | G7: =IFERROR(VLOOKUP($D7,BS연결,MATCH(G$1,BS연결H,0),0)/100,"") | H7: =IFERROR(VLOOKUP($D7,BS연결,MATCH(H$1,BS연결H,0),0)/100,"") | I7: =IFERROR(VLOOKUP($D7,BS연결,MATCH(I$1,BS연결H,0),0)/100,"") | J7: =IFERROR(VLOOKUP($D7,BS연결,MATCH(J$1,BS연결H,0),0)/100,"") | K7: =IFERROR(VLOOKUP($D7,BS연결,MATCH(K$1,BS연결H,0),0)/100,"") | L7: =IFERROR(VLOOKUP($D7,BS연결,MATCH(L$1,BS연결H,0),0)/100,"") | M7: =IFERROR(VLOOKUP($D7,BS연결,MATCH(M$1,BS연결H,0),0)/100,"") | N7: =IFERROR(VLOOKUP($D7,BS연결,MATCH(N$1,BS연결H,0),0)/100,"") | ... Y7: =IFERROR(VLOOKUP($D7,BS연결,MATCH(Y$1,BS연결H,0),0)/100,"") | Z7: =SUM(V7:Y7) | AA7: =IFERROR(VLOOKUP($D7,BS연결,MATCH(AA$1,BS연결H,0),0)/100,"") | AB7: =IFERROR(VLOOKUP($D7,BS연결,MATCH(AB$1,BS연결H,0),0)/100,"") | AC7: =IFERROR(AC9+AC8,"") | AD7: =IFERROR(AD9+AD8,"") | AE7: =SUM(AA7:AD7) | AF7: =IFERROR(AF9+AF8,"") | AG7: =IFERROR(AG9+AG8,"") | AH7: =IFERROR(AH9+AH8,"") | AI7: =IFERROR(AI9+AI8,"") | AJ7: =SUM(AF7:AI7) | AK7: =IFERROR(AK9+AK8,"") | AL7: =IFERROR(AL9+AL8,"") | AM7: =IFERROR(AM9+AM8,"") | AN7: =IFERROR(AN9+AN8,"") | AO7: =SUM(AK7:AN7)
A8: 판관비 | B8: 손익 | C8: 억원 | D8: 판관비 | E8: =IFERROR(VLOOKUP($D8,BS연결,MATCH(E$1,BS연결H,0),0)/100,"") | G8: =IFERROR(VLOOKUP($D8,BS연결,MATCH(G$1,BS연결H,0),0)/100,"") | H8: =IFERROR(VLOOKUP($D8,BS연결,MATCH(H$1,BS연결H,0),0)/100,"") | I8: =IFERROR(VLOOKUP($D8,BS연결,MATCH(I$1,BS연결H,0),0)/100,"") | J8: =IFERROR(VLOOKUP($D8,BS연결,MATCH(J$1,BS연결H,0),0)/100,"") | K8: =IFERROR(VLOOKUP($D8,BS연결,MATCH(K$1,BS연결H,0),0)/100,"") | L8: =IFERROR(VLOOKUP($D8,BS연결,MATCH(L$1,BS연결H,0),0)/100,"") | M8: =IFERROR(VLOOKUP($D8,BS연결,MATCH(M$1,BS연결H,0),0)/100,"") | N8: =IFERROR(VLOOKUP($D8,BS연결,MATCH(N$1,BS연결H,0),0)/100,"") | ... AB8: =IFERROR(VLOOKUP($D8,BS연결,MATCH(AB$1,BS연결H,0),0)/100,"") | AC8: =IFERROR(AC5*변수!AC22,"") | AD8: =IFERROR(AD5*변수!AD22,"") | AE8: =SUM(AA8:AD8) | AF8: =IFERROR(AF5*변수!AF22,"") | AG8: =IFERROR(AG5*변수!AG22,"") | AH8: =IFERROR(AH5*변수!AH22,"") | AI8: =IFERROR(AI5*변수!AI22,"") | AJ8: =SUM(AF8:AI8) | AK8: =IFERROR(AK5*변수!AK22,"") | AL8: =IFERROR(AL5*변수!AL22,"") | AM8: =IFERROR(AM5*변수!AM22,"") | AN8: =IFERROR(AN5*변수!AN22,"") | AO8: =SUM(AK8:AN8)
A9: 영업이익 | B9: 손익 | C9: 억원 | D9: 영업이익 | E9: =IFERROR(VLOOKUP($D9,BS연결,MATCH(E$1,BS연결H,0),0)/100,"") | G9: =IFERROR(VLOOKUP($D9,BS연결,MATCH(G$1,BS연결H,0),0)/100,"") | H9: =IFERROR(VLOOKUP($D9,BS연결,MATCH(H$1,BS연결H,0),0)/100,"") | I9: =IFERROR(VLOOKUP($D9,BS연결,MATCH(I$1,BS연결H,0),0)/100,"") | J9: =IFERROR(VLOOKUP($D9,BS연결,MATCH(J$1,BS연결H,0),0)/100,"") | K9: =IFERROR(VLOOKUP($D9,BS연결,MATCH(K$1,BS연결H,0),0)/100,"") | L9: =IFERROR(VLOOKUP($D9,BS연결,MATCH(L$1,BS연결H,0),0)/100,"") | M9: =IFERROR(VLOOKUP($D9,BS연결,MATCH(M$1,BS연결H,0),0)/100,"") | N9: =IFERROR(VLOOKUP($D9,BS연결,MATCH(N$1,BS연결H,0),0)/100,"") | ... AB9: =IFERROR(VLOOKUP($D9,BS연결,MATCH(AB$1,BS연결H,0),0)/100,"") | AC9: =IFERROR(AC5*변수!AC23,"") | AD9: =IFERROR(AD5*변수!AD23,"") | AE9: =SUM(AA9:AD9) | AF9: =IFERROR(AF5*변수!AF23,"") | AG9: =IFERROR(AG5*변수!AG23,"") | AH9: =IFERROR(AH5*변수!AH23,"") | AI9: =IFERROR(AI5*변수!AI23,"") | AJ9: =SUM(AF9:AI9) | AK9: =IFERROR(AK5*변수!AK23,"") | AL9: =IFERROR(AL5*변수!AL23,"") | AM9: =IFERROR(AM5*변수!AM23,"") | AN9: =IFERROR(AN5*변수!AN23,"") | AO9: =SUM(AK9:AN9)
A10: OPM | B10: 손익 | C10: % | D10: 영업이익률 | E10: =IFERROR(E9/E5,"") | G10: =IFERROR(G9/G5,"") | H10: =IFERROR(H9/H5,"") | I10: =IFERROR(I9/I5,"") | J10: =IFERROR(J9/J5,"") | K10: =IFERROR(K9/K5,"") | L10: =IFERROR(L9/L5,"") | M10: =IFERROR(M9/M5,"") | N10: =IFERROR(N9/N5,"") | ... AO10: =IFERROR(AO9/AO5,"")
A11: 금융손익 | B11: 손익 | C11: 억원 | D11: 금융손익 | E11: =IFERROR(VLOOKUP($D11,BS연결,MATCH(E$1,BS연결H,0),0)/100,"") | G11: =IFERROR(VLOOKUP($D11,BS연결,MATCH(G$1,BS연결H,0),0)/100,"") | H11: =IFERROR(VLOOKUP($D11,BS연결,MATCH(H$1,BS연결H,0),0)/100,"") | I11: =IFERROR(VLOOKUP($D11,BS연결,MATCH(I$1,BS연결H,0),0)/100,"") | J11: =IFERROR(VLOOKUP($D11,BS연결,MATCH(J$1,BS연결H,0),0)/100,"") | K11: =SUM(G11:J11) | L11: =IFERROR(VLOOKUP($D11,BS연결,MATCH(L$1,BS연결H,0),0)/100,"") | M11: =IFERROR(VLOOKUP($D11,BS연결,MATCH(M$1,BS연결H,0),0)/100,"") | N11: =IFERROR(VLOOKUP($D11,BS연결,MATCH(N$1,BS연결H,0),0)/100,"") | O11: =IFERROR(VLOOKUP($D11,BS연결,MATCH(O$1,BS연결H,0),0)/100,"") | P11: =IFERROR(VLOOKUP($D11,BS연결,MATCH(P$1,BS연결H,0),0)/100,"") | Q11: =IFERROR(VLOOKUP($D11,BS연결,MATCH(Q$1,BS연결H,0),0)/100,"") | R11: =IFERROR(VLOOKUP($D11,BS연결,MATCH(R$1,BS연결H,0),0)/100,"") | S11: =IFERROR(VLOOKUP($D11,BS연결,MATCH(S$1,BS연결H,0),0)/100,"") | ... AB11: =IFERROR(VLOOKUP($D11,BS연결,MATCH(AB$1,BS연결H,0),0)/100,"") | AC11: =IFERROR(AC12+AC13,"") | AD11: =IFERROR(AD12+AD13,"") | AE11: =SUM(AA11:AD11) | AF11: =IFERROR(AF12+AF13,"") | AG11: =IFERROR(AG12+AG13,"") | AH11: =IFERROR(AH12+AH13,"") | AI11: =IFERROR(AI12+AI13,"") | AJ11: =SUM(AF11:AI11) | AK11: =IFERROR(AK12+AK13,"") | AL11: =IFERROR(AL12+AL13,"") | AM11: =IFERROR(AM12+AM13,"") | AN11: =IFERROR(AN12+AN13,"") | AO11: =SUM(AK11:AN11)
