Workbook
Name 변수H: 변수!$C$1:$AO$1
Name 환율: 변수!$C$6:$AO$13
Name BS연결H: BS연결!$C$1:$AO$1
Name BS연결: BS연결!$C$5:$AO$106
Name BS별도H: BS별도!$C$1:$AO$1
Name BS별도: BS별도!$C$5:$AO$96
Name SUBQH: subQ!$A$1:$AO$1
Name subQ: subQ!$A$5:$AO$42

Sheet README
A1: 삼영엠텍(054540) 실적 모델 — ARGUS 한국조선
A2: 기준 분기 2026Q2 · 마지막 실적 2026Q2 · 생성 2026-10-12
A3: 모든 수치는 모델 산출값(DART 공개 재무제표 + 우리 추정)이다 — 목표주가·투자 추천 아님. 참고용 · 투자조언 아님.
A5: 시트
A6: 변수 가정 시계열. 환율 8행(ECB via frankfurter — L2 fx.json; 추정 분기 = 노란 가정), 추정 드라이버(노란 셀 = 모델값에서 역산한 가정, 바꾸면 재계산; 연녹 셀 = 3절 스칼라 참조 수식), 3절 스칼라 가정(세율·판관비율·지배주주비중·이자율·종가·PER 밴드·COE·외화 순노출·헤지비율)
A7: BS연결/BS별도 FnGuide 계정명 × 기간 값 덤프(백만원). 행1 분기라벨, 행4 YYYY.MM / YYYY.12A. 이름정의 BS연결H·BS연결(계정명 C열부터)
A8: subQ 분기 서브모델(억원 = 백만원/100). 확정 행: =IFERROR(VLOOKUP($D행,BS연결,MATCH(E$1,BS연결H,0),0)/100,"") 추정 행: 변수 시트 가정 셀 참조 수식. 외환손익·파생상품손익은 BS 계정 합·차, 기타금융손익은 잔차, OPM·EPS·BPS·PER·PBR 은 파생 수식
A9: SLS 선표(조선사만, sls json 있을 때): 요약 행(sls 저장값) + 계약별 스케줄(백만$) × (헤지비율 × 헤지환율 + (1−헤지비율) × 건조시점 환율[변수 원/달러(평균)]) → 원화 수식 블록 → 합계 행이 subQ 매출조선에 연결
A10: 시나리오 신규수주 보수/기준/낙관(forecast_panel 패널, 모델에 scenarios 가 있을 때만): 매출액·영업이익 = subQ 기준값 ± (시나리오 신규 − base 신규) × OPM. base 만 subQ 행에 포함, 나머지는 합산 안 함
A11: 분기/연간예상 subQ 를 이름(A열 key)으로 VLOOKUP 한 보고서 표(억원)
A12: TP PER 밴드 × 12M fwd EPS, PBR = ROE/COE × BPS — 모델 산출값 구간, 목표주가·추천 아님
A13: 외화 환율 QoQ, 외화 순노출 × Δ기말환율 → 환관련손익 추정
... A34: 백테스트: {"freeze": "2025Q2", "horizon": 4, "revenue_wape_pct": 62.3, "op_wape_pct": 35.9, "n": 4, "note": "단일 회사 4분기 — 통계 아님", "driver_at_freeze": "customer_yard_revenue_weighted", "selection_oos_at_freeze": {"freeze": "2024Q2", "n": 4, "wape_link": 5.6, "wape_trend": 19.9, "adopted": true, "decision": "adopted"}, "frozen_inputs": "fin(연결/별도)·고객 조선사 모델·지주 자회사 모델은 2025Q2 까지의 분기만; 선표는 체결일 ≤ 2025Q2 말일 계약(원장 최신 금액·코호트 등급, 환산 없음); 잔고는 yards_cache 2025Q2; 시세·환율 forward·prices·forecast_panel 신규수주 미사용. 고객 가중치(suppliers.json 언급 비중)와 합병 체인링크는 현재 지식; 고객 연동 채택은 동결 모델 안에서도 자기 la−4분기 OOS 규칙(selection_oos_at_freeze)", "detail": [{"q": "2025Q3", "rev_pred": 348.44, "rev_act": 294.69, "op_pred": 34.47, "op_act": 34.11}, {"q": "2025Q4", "rev_pred": 345.4, "rev_act": 330.21, "op_pred": 34.17, "op_act": 15.02}, {"q": "2026Q1", "rev_pred": 307.05, "rev_act": 1309.1, "op_pred": 30.38, "op_act": 56.09}, {"q": "2026Q2", "rev_pred": 361.15, "rev_act": 1313.93, "op_pred": 35.73, "op_act": 31.76}]}

Sheet 변수
C1: 이름: 변수H | E1: 4Q21 | F1: 2021 | G1: 1Q22 | H1: 2Q22 | I1: 3Q22 | J1: 4Q22 | K1: 2022 | L1: 1Q23 | M1: 2Q23 | N1: 3Q23 | O1: 4Q23 | P1: 2023 | Q1: 1Q24 | R1: 2Q24 | S1: 3Q24 | T1: 4Q24 | U1: 2024 | V1: 1Q25 | W1: 2Q25 | X1: 3Q25 | Y1: 4Q25 | Z1: 2025 | AA1: 1Q26 | AB1: 2Q26 | AC1: 3Q26 | AD1: 4Q26 | AE1: 2026 | AF1: 1Q27 | AG1: 2Q27 | AH1: 3Q27 | AI1: 4Q27 | AJ1: 2027 | AK1: 1Q28 | AL1: 2Q28 | AM1: 3Q28 | AN1: 4Q28 | AO1: 2028
A2: 가정 시계열 — 노란 셀은 추정 가정(모델값에서 역산), 연녹 셀은 3절 스칼라 참조 수식. 바꾸면 subQ·분기·연간예상·TP·시나리오가 재계산됩니다.
E3: 1 | F3: 2 | G3: 3 | H3: 4 | I3: 5 | J3: 6 | K3: 7 | L3: 8 | M3: 9 | N3: 10 | O3: 11 | P3: 12 | Q3: 13 | R3: 14 | S3: 15 | T3: 16 | U3: 17 | V3: 18 | W3: 19 | X3: 20 | Y3: 21 | Z3: 22 | AA3: 23 | AB3: 24 | AC3: 25 | AD3: 26 | AE3: 27 | AF3: 28 | AG3: 29 | AH3: 30 | AI3: 31 | AJ3: 32 | AK3: 33 | AL3: 34 | AM3: 35 | AN3: 36 | AO3: 37
E4: 2021.12 | F4: 2021.12A | G4: 2022.03 | H4: 2022.06 | I4: 2022.09 | J4: 2022.12 | K4: 2022.12A | L4: 2023.03 | M4: 2023.06 | N4: 2023.09 | O4: 2023.12 | P4: 2023.12A | Q4: 2024.03 | R4: 2024.06 | S4: 2024.09 | T4: 2024.12 | U4: 2024.12A | V4: 2025.03 | W4: 2025.06 | X4: 2025.09 | Y4: 2025.12 | Z4: 2025.12A | AA4: 2026.03 | AB4: 2026.06 | AC4: 2026.09 | AD4: 2026.12 | AE4: 2026.12A | AF4: 2027.03 | AG4: 2027.06 | AH4: 2027.09 | AI4: 2027.12 | AJ4: 2027.12A | AK4: 2028.03 | AL4: 2028.06 | AM4: 2028.09 | AN4: 2028.12 | AO4: 2028.12A
B5: 1. FX | C5: 이름: 환율
A6: USDKRW_avg | C6: 원/달러(평균) | E6: 1183.5 | F6: 1145.51 | G6: 1205.78 | H6: 1262.09 | I6: 1341.93 | J6: 1360.12 | K6: 1292.98 | L6: 1276.95 | M6: 1315.69 | N6: 1313.62 | O6: 1322.01 | P6: 1306.85 | Q6: 1330.14 | R6: 1371.28 | S6: 1356.22 | T6: 1396.3 | U6: 1363.53 | V6: 1452.28 | W6: 1398.52 | X6: 1386.95 | Y6: 1449.19 | Z6: 1421.52 | AA6: 1466.12 | AB6: 1501.75 | AC6: 1418.75 | AD6: 1345.14 | AE6: 1457.21 | AF6: 1341.49 | AG6: 1341.49 | AH6: 1341.49 | AI6: 1341.49 | AK6: 1341.49 | AL6: 1341.49 | AM6: 1341.49 | AN6: 1341.49
A7: USDKRW_end | C7: 원/달러(기말) | E7: 1188.75 | F7: 1188.75 | G7: 1213.74 | H7: 1301.24 | I7: 1436.9 | J7: 1260.16 | K7: 1260.16 | L7: 1305.99 | M7: 1321.44 | N7: 1345.35 | O7: 1297.43 | P7: 1297.43 | Q7: 1349.25 | R7: 1377.73 | S7: 1312.17 | T7: 1474.78 | U7: 1474.78 | V7: 1474.54 | W7: 1355.13 | X7: 1403.67 | Y7: 1444.2 | Z7: 1444.2 | AA7: 1524.8 | AB7: 1550.89 | AC7: 1355.4 | AD7: 1341.49 | AE7: 1341.49 | AF7: 1341.49 | AG7: 1341.49 | AH7: 1341.49 | AI7: 1341.49 | AK7: 1341.49 | AL7: 1341.49 | AM7: 1341.49 | AN7: 1341.49
A8: JPY100KRW_avg | C8: 원/100Y(평균) | E8: 1041.02 | F8: 1042.74 | G8: 1036.79 | H8: 972.23 | I8: 970.61 | J8: 961.03 | K8: 985.1 | L8: 964.89 | M8: 957.36 | N8: 909 | O8: 893.22 | P8: 931.11 | Q8: 896.29 | R8: 880.14 | S8: 909.35 | T8: 917.25 | U8: 900.92 | V8: 952.59 | W8: 967.92 | X8: 940.32 | Y8: 940.77 | Z8: 950.17 | AA8: 934.39 | AB8: 942.16 | AC8: 890.41 | AD8: 850.79 | AE8: 919.21 | AF8: 847.7 | AG8: 847.7 | AH8: 847.7 | AI8: 847.7 | AK8: 847.7 | AL8: 847.7 | AM8: 847.7 | AN8: 847.7
A9: JPY100KRW_end | C9: 원/100Y(기말) | E9: 1032.62 | F9: 1032.62 | G9: 996.83 | H9: 954.9 | I9: 993.29 | J9: 955.54 | K9: 955.54 | L9: 980.62 | M9: 913.67 | N9: 901.47 | O9: 917.04 | P9: 917.04 | Q9: 892.42 | R9: 857.76 | S9: 919.21 | T9: 939.65 | U9: 939.65 | V9: 986.84 | W9: 938.85 | X9: 948.49 | Y9: 921.81 | Z9: 921.81 | AA9: 955.99 | AB9: 954.75 | AC9: 863.31 | AD9: 847.7 | AE9: 847.7 | AF9: 847.7 | AG9: 847.7 | AH9: 847.7 | AI9: 847.7 | AK9: 847.7 | AL9: 847.7 | AM9: 847.7 | AN9: 847.7
A10: EURKRW_avg | C10: W/Euro(평균) | E10: 1353.32 | F10: 1354.06 | G10: 1352.29 | H10: 1343.31 | I10: 1350.63 | J10: 1386.07 | K10: 1358.07 | L10: 1369.93 | M10: 1432.41 | N10: 1429.41 | O10: 1420.91 | P10: 1412.88 | Q10: 1444.21 | R10: 1476.42 | S10: 1489.3 | T10: 1490.78 | U10: 1475.4 | V10: 1528.33 | W10: 1585.13 | X10: 1620.04 | Y10: 1686.02 | Z10: 1605.45 | AA10: 1715.47 | AB10: 1746.09 | AC10: 1631.97 | AD10: 1509.74 | AE10: 1689.95 | AF10: 1503.27 | AG10: 1503.27 | AH10: 1503.27 | AI10: 1503.27 | AK10: 1503.27 | AL10: 1503.27 | AM10: 1503.27 | AN10: 1503.27
A11: EURKRW_end | C11: W/Euro(기말) | E11: 1346.38 | F11: 1346.38 | G11: 1347.37 | H11: 1351.6 | I11: 1400.62 | J11: 1344.08 | K11: 1344.08 | L11: 1420.26 | M11: 1435.88 | N11: 1425.26 | O11: 1433.66 | P11: 1433.66 | Q11: 1458.68 | R11: 1474.86 | S11: 1469.1 | T11: 1532.14 | U11: 1532.14 | V11: 1594.72 | W11: 1588.22 | X11: 1648.04 | Y11: 1696.94 | Z11: 1696.94 | AA11: 1753.21 | AB11: 1767.09 | AC11: 1539.06 | AD11: 1503.27 | AE11: 1503.27 | AF11: 1503.27 | AG11: 1503.27 | AH11: 1503.27 | AI11: 1503.27 | AK11: 1503.27 | AL11: 1503.27 | AM11: 1503.27 | AN11: 1503.27
A12: CNYKRW_avg | C12: 원/중국원(평균) | E12: 185.14 | F12: 177.65 | G12: 189.93 | H12: 190.76 | I12: 195.79 | J12: 191.09 | K12: 191.93 | L12: 186.59 | M12: 187.45 | N12: 181.28 | O12: 182.86 | P12: 184.52 | Q12: 185.04 | R12: 189.35 | S12: 189.24 | T12: 194.24 | U12: 189.49 | V12: 199.63 | W12: 193.41 | X12: 193.79 | Y12: 204.38 | Z12: 197.8 | AA12: 211.75 | AB12: 220.8 | AC12: 210.43 | AD12: 200.69 | AE12: 213.75 | AF12: 200.46 | AG12: 200.46 | AH12: 200.46 | AI12: 200.46 | AK12: 200.46 | AL12: 200.46 | AM12: 200.46 | AN12: 200.46
A13: CNYKRW_end | C13: 원/중국원(기말) | E13: 187.13 | F13: 187.13 | G13: 191.38 | H13: 194.13 | I13: 201.92 | J13: 182.67 | K13: 182.67 | L13: 189.97 | M13: 181.8 | N13: 184.26 | O13: 182.61 | P13: 182.61 | Q13: 186.66 | R13: 189.7 | S13: 187.12 | T13: 202.04 | U13: 202.04 | V13: 203.3 | W13: 189.14 | X13: 197.16 | Y13: 206.28 | Z13: 206.28 | AA13: 220.97 | AB13: 228.56 | AC13: 202.16 | AD13: 200.46 | AE13: 200.46 | AF13: 200.46 | AG13: 200.46 | AH13: 200.46 | AI13: 200.46 | AK13: 200.46 | AL13: 200.46 | AM13: 200.46 | AN13: 200.46
B14: 1b. 종가
A15: price_close_end | C15: 종가(기말) | E15: 4480 | G15: 4985 | H15: 4380 | I15: 4100 | J15: 3650 | L15: 3735 | M15: 4120 | N15: 3965 | O15: 4215 | Q15: 3960 | R15: 4695 | S15: 4150 | T15: 4605 | V15: 4420 | W15: 5850 | X15: 11590 | Y15: 13750 | AA15: 10480 | AB15: 7330 | AC15: 6800 | AD15: 6290
A16: price_high | C16: 종가(최고) | E16: 5460 | G16: 5610 | H16: 6810 | I16: 6170 | J16: 4340 | L16: 4550 | M16: 4320 | N16: 4720 | O16: 4670 | Q16: 4860 | R16: 4745 | S16: 6110 | T16: 4825 | V16: 5430 | W16: 6270 | X16: 16400 | Y16: 22800 | AA16: 16820 | AB16: 15840 | AC16: 8170 | AD16: 7470
A17: price_low | C17: 종가(최저) | E17: 3925 | G17: 3930 | H17: 3735 | I17: 3930 | J17: 3620 | L17: 3390 | M17: 3540 | N17: 3800 | O17: 3580 | Q17: 3860 | R17: 3575 | S17: 3830 | T17: 3575 | V17: 4420 | W17: 4310 | X17: 5000 | Y17: 10760 | AA17: 10300 | AB17: 6750 | AC17: 5160 | AD17: 6250
A18: price_avg | C18: 종가(평균) | E18: 4685.2 | G18: 4567.9 | H18: 4971.8 | I18: 5121.1 | J18: 4022.3 | L18: 3852.3 | M18: 3907.4 | N18: 4167.3 | O18: 4048.8 | Q18: 4004 | R18: 4221.4 | S18: 4674.1 | T18: 4204 | V18: 4864 | W18: 5246.2 | X18: 8077.4 | Y18: 15289.7 | AA18: 13559.5 | AB18: 10661.1 | AC18: 6596.1 | AD18: 6911.7
B20: 2. 추정 드라이버 | C20: 실적 열 = subQ 실현값(수식), 추정 열 = 가정(노란 = 모델값 역산, 연녹 = 3절 스칼라 참조)
A21: drv:매출액 | B21: yoy | C21: 매출액 YoY | J21: =IFERROR(subQ!J5/subQ!E5-1,"") | L21: =IFERROR(subQ!L5/subQ!G5-1,"") | M21: =IFERROR(subQ!M5/subQ!H5-1,"") | N21: =IFERROR(subQ!N5/subQ!I5-1,"") | O21: =IFERROR(subQ!O5/subQ!J5-1,"") | Q21: =IFERROR(subQ!Q5/subQ!L5-1,"") | R21: =IFERROR(subQ!R5/subQ!M5-1,"") | S21: =IFERROR(subQ!S5/subQ!N5-1,"") | T21: =IFERROR(subQ!T5/subQ!O5-1,"") | V21: =IFERROR(subQ!V5/subQ!Q5-1,"") | W21: =IFERROR(subQ!W5/subQ!R5-1,"") | X21: =IFERROR(subQ!X5/subQ!S5-1,"") | Y21: =IFERROR(subQ!Y5/subQ!T5-1,"") | AA21: =IFERROR(subQ!AA5/subQ!V5-1,"") | AB21: =IFERROR(subQ!AB5/subQ!W5-1,"") | AC21: 1.9437884 | AD21: 1.7361903 | AF21: -0.30103781 | AG21: -0.28538882 | AH21: 0.13837305 | AI21: 0.15340173 | AK21: 0.21059879 | AL21: 0.25269716 | AM21: 0.26398663 | AN21: 0.25295794
A22: drv:판관비 | B22: ratio | C22: 판관비율(/매출) | E22: =IFERROR(subQ!E8/subQ!E5,"") | F22: =IFERROR(subQ!F8/subQ!F5,"") | G22: =IFERROR(subQ!G8/subQ!G5,"") | H22: =IFERROR(subQ!H8/subQ!H5,"") | I22: =IFERROR(subQ!I8/subQ!I5,"") | J22: =IFERROR(subQ!J8/subQ!J5,"") | K22: =IFERROR(subQ!K8/subQ!K5,"") | L22: =IFERROR(subQ!L8/subQ!L5,"") | ... AB22: =IFERROR(subQ!AB8/subQ!AB5,"") | AC22: =$D$51 | AD22: =$D$51 | AE22: =IFERROR(subQ!AE8/subQ!AE5,"") | AF22: =$D$51 | AG22: =$D$51 | AH22: =$D$51 | AI22: =$D$51 | AJ22: =IFERROR(subQ!AJ8/subQ!AJ5,"") | AK22: =$D$51 | AL22: =$D$51 | AM22: =$D$51 | AN22: =$D$51 | AO22: =IFERROR(subQ!AO8/subQ!AO5,"")
A23: drv:영업이익 | B23: ratio | C23: 영업이익률(OPM) | E23: =IFERROR(subQ!E9/subQ!E5,"") | F23: =IFERROR(subQ!F9/subQ!F5,"") | G23: =IFERROR(subQ!G9/subQ!G5,"") | H23: =IFERROR(subQ!H9/subQ!H5,"") | I23: =IFERROR(subQ!I9/subQ!I5,"") | J23: =IFERROR(subQ!J9/subQ!J5,"") | K23: =IFERROR(subQ!K9/subQ!K5,"") | L23: =IFERROR(subQ!L9/subQ!L5,"") | ... AB23: =IFERROR(subQ!AB9/subQ!AB5,"") | AC23: 0.089255455 | AD23: 0.089262985 | AE23: =IFERROR(subQ!AE9/subQ!AE5,"") | AF23: 0.089255855 | AG23: 0.089259279 | AH23: 0.089261303 | AI23: 0.08926121 | AJ23: =IFERROR(subQ!AJ9/subQ!AJ5,"") | AK23: 0.089256213 | AL23: 0.089260512 | AM23: 0.089260965 | AN23: 0.089253439 | AO23: =IFERROR(subQ!AO9/subQ!AO5,"")
A24: drv:외환손익 | B24: abs | C24: 외환손익 (가정, 억원) | E24: =subQ!E13 | F24: =subQ!F13 | G24: =subQ!G13 | H24: =subQ!H13 | I24: =subQ!I13 | J24: =subQ!J13 | K24: =subQ!K13 | L24: =subQ!L13 | ... AB24: =subQ!AB13 | AC24: 0 | AD24: 0 | AE24: =subQ!AE13 | AF24: 0 | AG24: 0 | AH24: 0 | AI24: 0 | AJ24: =subQ!AJ13 | AK24: 0 | AL24: 0 | AM24: 0 | AN24: 0 | AO24: =subQ!AO13
A25: drv:파생상품손익 | B25: abs | C25: 파생상품손익 (가정, 억원) | E25: =subQ!E14 | F25: =subQ!F14 | G25: =subQ!G14 | H25: =subQ!H14 | I25: =subQ!I14 | J25: =subQ!J14 | K25: =subQ!K14 | L25: =subQ!L14 | ... AB25: =subQ!AB14 | AC25: 0 | AD25: 0 | AE25: =subQ!AE14 | AF25: 0 | AG25: 0 | AH25: 0 | AI25: 0 | AJ25: =subQ!AJ14 | AK25: 0 | AL25: 0 | AM25: 0 | AN25: 0 | AO25: =subQ!AO14
A26: drv:기타금융손익 | B26: abs | C26: 기타금융손익 (가정, 억원) | E26: =subQ!E15 | F26: =subQ!F15 | G26: =subQ!G15 | H26: =subQ!H15 | I26: =subQ!I15 | J26: =subQ!J15 | K26: =subQ!K15 | L26: =subQ!L15 | ... AB26: =subQ!AB15 | AC26: -4.7 | AD26: -4.7 | AE26: =subQ!AE15 | AF26: -4.7 | AG26: -4.7 | AH26: -4.7 | AI26: -4.7 | AJ26: =subQ!AJ15 | AK26: -4.7 | AL26: -4.7 | AM26: -4.7 | AN26: -4.7 | AO26: =subQ!AO15
A27: drv:기타영업외손익 | B27: abs | C27: 기타영업외손익 (가정, 억원) | E27: =subQ!E16 | F27: =subQ!F16 | G27: =subQ!G16 | H27: =subQ!H16 | I27: =subQ!I16 | J27: =subQ!J16 | K27: =subQ!K16 | L27: =subQ!L16 | ... AB27: =subQ!AB16 | AC27: 0 | AD27: 0 | AE27: =subQ!AE16 | AF27: 0 | AG27: 0 | AH27: 0 | AI27: 0 | AJ27: =subQ!AJ16 | AK27: 0 | AL27: 0 | AM27: 0 | AN27: 0 | AO27: =subQ!AO16
A28: drv:법인세비용 | B28: tax | C28: 법인세율(/세전) — 법인세 = MAX(세전,0) × 세율 | E28: =IFERROR(subQ!E18/subQ!E17,"") | F28: =IFERROR(subQ!F18/subQ!F17,"") | G28: =IFERROR(subQ!G18/subQ!G17,"") | H28: =IFERROR(subQ!H18/subQ!H17,"") | I28: =IFERROR(subQ!I18/subQ!I17,"") | J28: =IFERROR(subQ!J18/subQ!J17,"") | K28: =IFERROR(subQ!K18/subQ!K17,"") | L28: =IFERROR(subQ!L18/subQ!L17,"") | ... AB28: =IFERROR(subQ!AB18/subQ!AB17,"") | AC28: =$D$50 | AD28: =$D$50 | AE28: =IFERROR(subQ!AE18/subQ!AE17,"") | AF28: =$D$50 | AG28: =$D$50 | AH28: =$D$50 | AI28: =$D$50 | AJ28: =IFERROR(subQ!AJ18/subQ!AJ17,"") | AK28: =$D$50 | AL28: =$D$50 | AM28: =$D$50 | AN28: =$D$50 | AO28: =IFERROR(subQ!AO18/subQ!AO17,"")
A29: drv:지배주주순이익 | B29: ratio | C29: 지배주주 비중(/당기순이익) | E29: =IFERROR(subQ!E20/subQ!E19,"") | F29: =IFERROR(subQ!F20/subQ!F19,"") | G29: =IFERROR(subQ!G20/subQ!G19,"") | H29: =IFERROR(subQ!H20/subQ!H19,"") | I29: =IFERROR(subQ!I20/subQ!I19,"") | J29: =IFERROR(subQ!J20/subQ!J19,"") | K29: =IFERROR(subQ!K20/subQ!K19,"") | L29: =IFERROR(subQ!L20/subQ!L19,"") | ... AB29: =IFERROR(subQ!AB20/subQ!AB19,"") | AC29: =$D$52 | AD29: =$D$52 | AE29: =IFERROR(subQ!AE20/subQ!AE19,"") | AF29: =$D$52 | AG29: =$D$52 | AH29: =$D$52 | AI29: =$D$52 | AJ29: =IFERROR(subQ!AJ20/subQ!AJ19,"") | AK29: =$D$52 | AL29: =$D$52 | AM29: =$D$52 | AN29: =$D$52 | AO29: =IFERROR(subQ!AO20/subQ!AO19,"")
A30: drv:부채총계 | B30: qoq | C30: 부채총계 QoQ | G30: =IFERROR(subQ!G22/subQ!E22-1,"") | H30: =IFERROR(subQ!H22/subQ!G22-1,"") | I30: =IFERROR(subQ!I22/subQ!H22-1,"") | J30: =IFERROR(subQ!J22/subQ!I22-1,"") | L30: =IFERROR(subQ!L22/subQ!J22-1,"") | M30: =IFERROR(subQ!M22/subQ!L22-1,"") | N30: =IFERROR(subQ!N22/subQ!M22-1,"") | O30: =IFERROR(subQ!O22/subQ!N22-1,"") | Q30: =IFERROR(subQ!Q22/subQ!O22-1,"") | R30: =IFERROR(subQ!R22/subQ!Q22-1,"") | S30: =IFERROR(subQ!S22/subQ!R22-1,"") | T30: =IFERROR(subQ!T22/subQ!S22-1,"") | V30: =IFERROR(subQ!V22/subQ!T22-1,"") | W30: =IFERROR(subQ!W22/subQ!V22-1,"") | X30: =IFERROR(subQ!X22/subQ!W22-1,"") | Y30: =IFERROR(subQ!Y22/subQ!X22-1,"") | AA30: =IFERROR(subQ!AA22/subQ!Y22-1,"") | AB30: =IFERROR(subQ!AB22/subQ!AA22-1,"") | AC30: 2.14e-07 | AD30: 0 | AF30: 0 | AG30: 0 | AH30: 0 | AI30: 0 | AK30: 0 | AL30: 0 | AM30: 0 | AN30: 0
A31: drv:자본총계 | B31: roll | C31: 자본총계 기타변동(배당 등, 억원) | G31: =IFERROR(subQ!E23+subQ!G19-subQ!G23,"") | H31: =IFERROR(subQ!G23+subQ!H19-subQ!H23,"") | I31: =IFERROR(subQ!H23+subQ!I19-subQ!I23,"") | J31: =IFERROR(subQ!I23+subQ!J19-subQ!J23,"") | L31: =IFERROR(subQ!J23+subQ!L19-subQ!L23,"") | M31: =IFERROR(subQ!L23+subQ!M19-subQ!M23,"") | N31: =IFERROR(subQ!M23+subQ!N19-subQ!N23,"") | O31: =IFERROR(subQ!N23+subQ!O19-subQ!O23,"") | Q31: =IFERROR(subQ!O23+subQ!Q19-subQ!Q23,"") | R31: =IFERROR(subQ!Q23+subQ!R19-subQ!R23,"") | S31: =IFERROR(subQ!R23+subQ!S19-subQ!S23,"") | T31: =IFERROR(subQ!S23+subQ!T19-subQ!T23,"") | V31: =IFERROR(subQ!T23+subQ!V19-subQ!V23,"") | W31: =IFERROR(subQ!V23+subQ!W19-subQ!W23,"") | X31: =IFERROR(subQ!W23+subQ!X19-subQ!X23,"") | Y31: =IFERROR(subQ!X23+subQ!Y19-subQ!Y23,"") | AA31: =IFERROR(subQ!Y23+subQ!AA19-subQ!AA23,"") | AB31: =IFERROR(subQ!AA23+subQ!AB19-subQ!AB23,"") | AC31: -0.007330743 | AD31: 0.002684832 | AF31: 0.002550687 | AG31: 21.446243 | AH31: -0.001202619 | AI31: -0.004803738 | AK31: 0.003342605 | AL31: 21.44367 | AM31: 0.000849031 | AN31: -0.006215851
A32: drv:지배주주지분 | B32: roll | C32: 지배주주지분 기타변동(배당 등, 억원) | G32: =IFERROR(subQ!E24+subQ!G20-subQ!G24,"") | H32: =IFERROR(subQ!G24+subQ!H20-subQ!H24,"") | I32: =IFERROR(subQ!H24+subQ!I20-subQ!I24,"") | J32: =IFERROR(subQ!I24+subQ!J20-subQ!J24,"") | L32: =IFERROR(subQ!J24+subQ!L20-subQ!L24,"") | M32: =IFERROR(subQ!L24+subQ!M20-subQ!M24,"") | N32: =IFERROR(subQ!M24+subQ!N20-subQ!N24,"") | O32: =IFERROR(subQ!N24+subQ!O20-subQ!O24,"") | Q32: =IFERROR(subQ!O24+subQ!Q20-subQ!Q24,"") | R32: =IFERROR(subQ!Q24+subQ!R20-subQ!R24,"") | S32: =IFERROR(subQ!R24+subQ!S20-subQ!S24,"") | T32: =IFERROR(subQ!S24+subQ!T20-subQ!T24,"") | V32: =IFERROR(subQ!T24+subQ!V20-subQ!V24,"") | W32: =IFERROR(subQ!V24+subQ!W20-subQ!W24,"") | X32: =IFERROR(subQ!W24+subQ!X20-subQ!X24,"") | Y32: =IFERROR(subQ!X24+subQ!Y20-subQ!Y24,"") | AA32: =IFERROR(subQ!Y24+subQ!AA20-subQ!AA24,"") | AB32: =IFERROR(subQ!AA24+subQ!AB20-subQ!AB24,"") | AC32: -0.004046783 | AD32: -0.000106951 | AF32: -0.002995979 | AG32: 21.450091 | AH32: -0.003836866 | AI32: -0.000233978 | AK32: -0.006792382 | AL32: 21.452987 | AM32: -0.000677417 | AN32: -0.01129232
A33: drv:총차입금 | B33: qoq | C33: 총차입금 QoQ | G33: =IFERROR(subQ!G25/subQ!E25-1,"") | H33: =IFERROR(subQ!H25/subQ!G25-1,"") | I33: =IFERROR(subQ!I25/subQ!H25-1,"") | J33: =IFERROR(subQ!J25/subQ!I25-1,"") | L33: =IFERROR(subQ!L25/subQ!J25-1,"") | M33: =IFERROR(subQ!M25/subQ!L25-1,"") | N33: =IFERROR(subQ!N25/subQ!M25-1,"") | O33: =IFERROR(subQ!O25/subQ!N25-1,"") | Q33: =IFERROR(subQ!Q25/subQ!O25-1,"") | R33: =IFERROR(subQ!R25/subQ!Q25-1,"") | S33: =IFERROR(subQ!S25/subQ!R25-1,"") | T33: =IFERROR(subQ!T25/subQ!S25-1,"") | V33: =IFERROR(subQ!V25/subQ!T25-1,"") | W33: =IFERROR(subQ!W25/subQ!V25-1,"") | X33: =IFERROR(subQ!X25/subQ!W25-1,"") | Y33: =IFERROR(subQ!Y25/subQ!X25-1,"") | AA33: =IFERROR(subQ!AA25/subQ!Y25-1,"") | AB33: =IFERROR(subQ!AB25/subQ!AA25-1,"") | AC33: 2.422e-06 | AD33: 0 | AF33: 0 | AG33: 0 | AH33: 0 | AI33: 0 | AK33: 0 | AL33: 0 | AM33: 0 | AN33: 0
A34: drv:순차입금 | B34: qoq | C34: 순차입금 QoQ | G34: =IFERROR(subQ!G26/subQ!E26-1,"") | H34: =IFERROR(subQ!H26/subQ!G26-1,"") | I34: =IFERROR(subQ!I26/subQ!H26-1,"") | J34: =IFERROR(subQ!J26/subQ!I26-1,"") | L34: =IFERROR(subQ!L26/subQ!J26-1,"") | M34: =IFERROR(subQ!M26/subQ!L26-1,"") | N34: =IFERROR(subQ!N26/subQ!M26-1,"") | O34: =IFERROR(subQ!O26/subQ!N26-1,"") | Q34: =IFERROR(subQ!Q26/subQ!O26-1,"") | R34: =IFERROR(subQ!R26/subQ!Q26-1,"") | S34: =IFERROR(subQ!S26/subQ!R26-1,"") | T34: =IFERROR(subQ!T26/subQ!S26-1,"") | V34: =IFERROR(subQ!V26/subQ!T26-1,"") | W34: =IFERROR(subQ!W26/subQ!V26-1,"") | X34: =IFERROR(subQ!X26/subQ!W26-1,"") | Y34: =IFERROR(subQ!Y26/subQ!X26-1,"") | AA34: =IFERROR(subQ!AA26/subQ!Y26-1,"") | AB34: =IFERROR(subQ!AB26/subQ!AA26-1,"") | AC34: -0.040829623 | AD34: -0.045074493 | AF34: -0.048227337 | AG34: -0.033992095 | AH34: -0.058128451 | AI34: -0.066184193 | AK34: -0.076590393 | AL34: -0.065670154 | AM34: -0.1028394 | AN34: -0.12129818
A35: drv:이자발생자산 | B35: qoq | C35: 이자발생자산 QoQ | G35: =IFERROR(subQ!G27/subQ!E27-1,"") | H35: =IFERROR(subQ!H27/subQ!G27-1,"") | I35: =IFERROR(subQ!I27/subQ!H27-1,"") | J35: =IFERROR(subQ!J27/subQ!I27-1,"") | L35: =IFERROR(subQ!L27/subQ!J27-1,"") | M35: =IFERROR(subQ!M27/subQ!L27-1,"") | N35: =IFERROR(subQ!N27/subQ!M27-1,"") | O35: =IFERROR(subQ!O27/subQ!N27-1,"") | Q35: =IFERROR(subQ!Q27/subQ!O27-1,"") | R35: =IFERROR(subQ!R27/subQ!Q27-1,"") | S35: =IFERROR(subQ!S27/subQ!R27-1,"") | T35: =IFERROR(subQ!T27/subQ!S27-1,"") | V35: =IFERROR(subQ!V27/subQ!T27-1,"") | W35: =IFERROR(subQ!W27/subQ!V27-1,"") | X35: =IFERROR(subQ!X27/subQ!W27-1,"") | Y35: =IFERROR(subQ!Y27/subQ!X27-1,"") | AA35: =IFERROR(subQ!AA27/subQ!Y27-1,"") | AB35: =IFERROR(subQ!AB27/subQ!AA27-1,"") | AC35: 0.0681236 | AD35: 0.067535755 | AF35: 0.064637309 | AG35: 0.040728597 | AH35: 0.064647758 | AI35: 0.065118551 | AK35: 0.066067523 | AL35: 0.049067218 | AM35: 0.068435248 | AN35: 0.067779221
A36: drv:현금및현금성자산 | B36: qoq | C36: 현금및현금성자산 QoQ | G36: =IFERROR(subQ!G28/subQ!E28-1,"") | H36: =IFERROR(subQ!H28/subQ!G28-1,"") | I36: =IFERROR(subQ!I28/subQ!H28-1,"") | J36: =IFERROR(subQ!J28/subQ!I28-1,"") | L36: =IFERROR(subQ!L28/subQ!J28-1,"") | M36: =IFERROR(subQ!M28/subQ!L28-1,"") | N36: =IFERROR(subQ!N28/subQ!M28-1,"") | O36: =IFERROR(subQ!O28/subQ!N28-1,"") | Q36: =IFERROR(subQ!Q28/subQ!O28-1,"") | R36: =IFERROR(subQ!R28/subQ!Q28-1,"") | S36: =IFERROR(subQ!S28/subQ!R28-1,"") | T36: =IFERROR(subQ!T28/subQ!S28-1,"") | V36: =IFERROR(subQ!V28/subQ!T28-1,"") | W36: =IFERROR(subQ!W28/subQ!V28-1,"") | X36: =IFERROR(subQ!X28/subQ!W28-1,"") | Y36: =IFERROR(subQ!Y28/subQ!X28-1,"") | AA36: =IFERROR(subQ!AA28/subQ!Y28-1,"") | AB36: =IFERROR(subQ!AB28/subQ!AA28-1,"")
A37: drv:CAPEX | B37: yoy | C37: CAPEX YoY | J37: =IFERROR(subQ!J29/subQ!E29-1,"") | L37: =IFERROR(subQ!L29/subQ!G29-1,"") | M37: =IFERROR(subQ!M29/subQ!H29-1,"") | N37: =IFERROR(subQ!N29/subQ!I29-1,"") | O37: =IFERROR(subQ!O29/subQ!J29-1,"") | Q37: =IFERROR(subQ!Q29/subQ!L29-1,"") | R37: =IFERROR(subQ!R29/subQ!M29-1,"") | S37: =IFERROR(subQ!S29/subQ!N29-1,"") | T37: =IFERROR(subQ!T29/subQ!O29-1,"") | V37: =IFERROR(subQ!V29/subQ!Q29-1,"") | W37: =IFERROR(subQ!W29/subQ!R29-1,"") | X37: =IFERROR(subQ!X29/subQ!S29-1,"") | Y37: =IFERROR(subQ!Y29/subQ!T29-1,"") | AA37: =IFERROR(subQ!AA29/subQ!V29-1,"") | AB37: =IFERROR(subQ!AB29/subQ!W29-1,"") | AC37: 0.063829787 | AD37: 0 | AF37: 0 | AG37: 0 | AH37: 0 | AI37: 0 | AK37: 0 | AL37: 0 | AM37: 0 | AN37: 0
A38: drv:영업활동현금흐름 | B38: yoy | C38: 영업활동현금흐름 YoY | J38: =IFERROR(subQ!J30/subQ!E30-1,"") | L38: =IFERROR(subQ!L30/subQ!G30-1,"") | M38: =IFERROR(subQ!M30/subQ!H30-1,"") | N38: =IFERROR(subQ!N30/subQ!I30-1,"") | O38: =IFERROR(subQ!O30/subQ!J30-1,"") | Q38: =IFERROR(subQ!Q30/subQ!L30-1,"") | R38: =IFERROR(subQ!R30/subQ!M30-1,"") | S38: =IFERROR(subQ!S30/subQ!N30-1,"") | T38: =IFERROR(subQ!T30/subQ!O30-1,"") | V38: =IFERROR(subQ!V30/subQ!Q30-1,"") | W38: =IFERROR(subQ!W30/subQ!R30-1,"") | X38: =IFERROR(subQ!X30/subQ!S30-1,"") | Y38: =IFERROR(subQ!Y30/subQ!T30-1,"") | AA38: =IFERROR(subQ!AA30/subQ!V30-1,"") | AB38: =IFERROR(subQ!AB30/subQ!W30-1,"")
A39: drv:주식수 | B39: qoq | C39: 주식수 QoQ | G39: =IFERROR(subQ!G31/subQ!E31-1,"") | H39: =IFERROR(subQ!H31/subQ!G31-1,"") | I39: =IFERROR(subQ!I31/subQ!H31-1,"") | J39: =IFERROR(subQ!J31/subQ!I31-1,"") | L39: =IFERROR(subQ!L31/subQ!J31-1,"") | M39: =IFERROR(subQ!M31/subQ!L31-1,"") | N39: =IFERROR(subQ!N31/subQ!M31-1,"") | O39: =IFERROR(subQ!O31/subQ!N31-1,"") | Q39: =IFERROR(subQ!Q31/subQ!O31-1,"") | R39: =IFERROR(subQ!R31/subQ!Q31-1,"") | S39: =IFERROR(subQ!S31/subQ!R31-1,"") | T39: =IFERROR(subQ!T31/subQ!S31-1,"") | V39: =IFERROR(subQ!V31/subQ!T31-1,"") | W39: =IFERROR(subQ!W31/subQ!V31-1,"") | X39: =IFERROR(subQ!X31/subQ!W31-1,"") | Y39: =IFERROR(subQ!Y31/subQ!X31-1,"") | AA39: =IFERROR(subQ!AA31/subQ!Y31-1,"") | AB39: =IFERROR(subQ!AB31/subQ!AA31-1,"") | AC39: 0 | AD39: 0 | AF39: 0 | AG39: 0 | AH39: 0 | AI39: 0 | AK39: 0 | AL39: 0 | AM39: 0 | AN39: 0
A40: drv:DPS | B40: abs | C40: DPS (가정, 원) | E40: =subQ!E34 | F40: =subQ!F34 | G40: =subQ!G34 | H40: =subQ!H34 | I40: =subQ!I34 | J40: =subQ!J34 | K40: =subQ!K34 | L40: =subQ!L34 | ... AB40: =subQ!AB34 | AD40: 165 | AE40: =subQ!AE34 | AI40: 165 | AJ40: =subQ!AJ34 | AN40: 165 | AO40: =subQ!AO34
B42: 3. 밸류에이션·스칼라 | C42: 노란 셀 = 가정. '연결' 표시는 추정 전 분기 수식이 이 셀을 참조한다는 뜻
...

Sheet BS연결
B1: (백만원) | C1: 이름: BS연결H | E1: 4Q21 | F1: 2021 | G1: 1Q22 | H1: 2Q22 | I1: 3Q22 | J1: 4Q22 | K1: 2022 | L1: 1Q23 | M1: 2Q23 | N1: 3Q23 | O1: 4Q23 | P1: 2023 | Q1: 1Q24 | R1: 2Q24 | S1: 3Q24 | T1: 4Q24 | U1: 2024 | V1: 1Q25 | W1: 2Q25 | X1: 3Q25 | Y1: 4Q25 | Z1: 2025 | AA1: 1Q26 | AB1: 2Q26 | AC1: 3Q26 | AD1: 4Q26 | AE1: 2026 | AF1: 1Q27 | AG1: 2Q27 | AH1: 3Q27 | AI1: 4Q27 | AJ1: 2027 | AK1: 1Q28 | AL1: 2Q28 | AM1: 3Q28 | AN1: 4Q28 | AO1: 2028
B2: 연결 | D2: fin json(kship_fin.py)
B3: 삼영엠텍(연) | C3: UPDATE: 26-10-12 | E3: 1 | F3: 2 | G3: 3 | H3: 4 | I3: 5 | J3: 6 | K3: 7 | L3: 8 | M3: 9 | N3: 10 | O3: 11 | P3: 12 | Q3: 13 | R3: 14 | S3: 15 | T3: 16 | U3: 17 | V3: 18 | W3: 19 | X3: 20 | Y3: 21 | Z3: 22 | AA3: 23 | AB3: 24 | AC3: 25 | AD3: 26 | AE3: 27 | AF3: 28 | AG3: 29 | AH3: 30 | AI3: 31 | AJ3: 32 | AK3: 33 | AL3: 34 | AM3: 35 | AN3: 36 | AO3: 37
B4: Account Code | C4: AccountNAME | E4: 2021.12 | F4: 2021.12A | G4: 2022.03 | H4: 2022.06 | I4: 2022.09 | J4: 2022.12 | K4: 2022.12A | L4: 2023.03 | M4: 2023.06 | N4: 2023.09 | O4: 2023.12 | P4: 2023.12A | Q4: 2024.03 | R4: 2024.06 | S4: 2024.09 | T4: 2024.12 | U4: 2024.12A | V4: 2025.03 | W4: 2025.06 | X4: 2025.09 | Y4: 2025.12 | Z4: 2025.12A | AA4: 2026.03 | AB4: 2026.06 | AC4: 2026.09 | AD4: 2026.12 | AE4: 2026.12A | AF4: 2027.03 | AG4: 2027.06 | AH4: 2027.09 | AI4: 2027.12 | AJ4: 2027.12A | AK4: 2028.03 | AL4: 2028.06 | AM4: 2028.09 | AN4: 2028.12 | AO4: 2028.12A
A5: 1 | C5: 유동자산 | E5: 66115.28 | F5: 66115.28 | G5: 68321.55 | H5: 67763.99 | I5: 65204.7 | J5: 61900.88 | K5: 61900.88 | L5: 64135.79 | M5: 65842.46 | N5: 68500.11 | O5: 67455.23 | P5: 67455.23 | Q5: 69422.17 | R5: 61773.77 | S5: 69383.8 | T5: 70562.19 | U5: 70562.19 | V5: 79385.56 | W5: 72386.59 | X5: 100659.79 | Y5: 261304.09 | Z5: 261304.09 | AA5: 285093.91 | AB5: 297811.82
A6: 1 | C6: 현금및현금성자산 | E6: 8344.33 | F6: 8344.33 | G6: 9845.85 | H6: 11440.69 | I6: 6596.69 | J6: 8768.12 | K6: 8768.12 | L6: 7219.26 | M6: 5413.48 | N6: 6313.86 | O6: 4307.41 | P6: 4307.41 | Q6: 2369.61 | R6: 7857.36 | S6: 4656.4 | T6: 4712.28 | U6: 4712.28 | V6: 3231.07 | W6: 6781.86 | X6: 19986.86 | Y6: 46662.02 | Z6: 46662.02 | AA6: 40278.7 | AB6: 35038.03
A7: 1 | C7: 단기금융상품 | E7: 18627.05 | F7: 18627.05 | G7: 12270.36 | H7: 12520.98 | I7: 12988.94 | J7: 16124.88 | K7: 16124.88 | L7: 17090.87 | M7: 16612 | N7: 18498.02 | O7: 19477.53 | P7: 19477.53 | Q7: 16510.34 | R7: 5525.85 | S7: 19368.36 | T7: 15092.93 | U7: 15092.93 | V7: 19068.95 | W7: 13443.49 | X7: 26151.56 | Y7: 17127.88 | Z7: 17127.88 | AA7: 28697.66 | AB7: 30735.66
A8: 1 | C8: 단기금융자산 | E8: 18662.12 | F8: 18662.12 | G8: 12298.52 | H8: 12520.98 | I8: 12988.94 | J8: 16124.88 | K8: 16124.88 | L8: 17096.12 | M8: 16638.23 | N8: 18541.39 | O8: 19555.14 | P8: 19555.14 | Q8: 16510.34 | R8: 5525.85 | S8: 19401.5 | T8: 15105.11 | U8: 15105.11 | V8: 19068.95 | W8: 13582.44 | X8: 26155.63 | Y8: 18441.08 | Z8: 18441.08 | AA8: 29932.44 | AB8: 31108
A9: 1 | C9: 매출채권및기타채권 | E9: 13017.97 | F9: 13017.97 | G9: 18380.6 | H9: 15786.37 | I9: 19257.31 | J9: 12463.08 | K9: 12463.08 | L9: 13901.91 | M9: 15570.77 | N9: 15938.39 | O9: 14296.89 | P9: 14296.89 | Q9: 16314.26 | R9: 17675.63 | S9: 14943.47 | T9: 16618.93 | U9: 16618.93 | V9: 20101.02 | W9: 17560.17 | X9: 19106.4 | Y9: 103450.64 | Z9: 103450.64 | AA9: 114379.45 | AB9: 121879.38
A10: 1 | C10: 재고자산 | E10: 24819.29 | F10: 24819.29 | G10: 26178.57 | H10: 26353.15 | I10: 25323.12 | J10: 23378.41 | K10: 23378.41 | L10: 24612.95 | M10: 27232.05 | N10: 26019.01 | O10: 27007.79 | P10: 27007.79 | Q10: 32697.32 | R10: 29704.24 | S10: 28938.97 | T10: 32729.84 | U10: 32729.84 | V10: 35640.97 | W10: 33471.31 | X10: 34023.32 | Y10: 78602.59 | Z10: 78602.59 | AA10: 85173.08 | AB10: 92139.11
A11: 1 | C11: 유동파생상품자산 | E11: 35.07 | F11: 35.07 | G11: 28.16 | H11: 0 | I11: 0 | J11: 0 | K11: 0 | L11: 5.25 | M11: 26.23 | N11: 43.37 | O11: 77.61 | P11: 77.61 | Q11: 0 | R11: 0 | S11: 33.14 | T11: 12.18 | U11: 12.18 | V11: 0 | W11: 138.95 | X11: 4.07 | Y11: 1313.2 | Z11: 1313.2 | AA11: 1234.78 | AB11: 372.34
A12: 1 | C12: 당기법인세자산(선급법인세) | E12: 0 | F12: 0 | I12: 74.03 | J12: 74.16 | K12: 74.16 | L12: 74.16 | M12: 0 | N12: 0 | O12: 102.11 | P12: 102.11 | Q12: 102.11 | R12: 0 | S12: 0 | T12: 0 | U12: 0 | V12: 0 | Y12: 2010.88 | Z12: 2010.88 | AA12: 2150.93 | AB12: 1877.46
A13: 1 | C13: 기타유동자산 | E13: 1271.58 | F13: 1271.58 | G13: 1618 | H13: 1662.81 | I13: 964.61 | J13: 1092.22 | K13: 1092.22 | L13: 1231.37 | M13: 987.93 | N13: 1687.47 | O13: 2185.89 | P13: 2185.89 | Q13: 1428.53 | R13: 1010.69 | S13: 1443.45 | T13: 1396.03 | U13: 1396.03 | V13: 1343.56 | W13: 990.81 | X13: 1387.58 | Y13: 12136.88 | Z13: 12136.88 | AA13: 13179.31 | AB13: 15769.84
A14: 1 | C14: 비유동자산 | E14: 44266.75 | F14: 44266.75 | G14: 43745.76 | H14: 43061.26 | I14: 43465.6 | J14: 39400.74 | K14: 39400.74 | L14: 40688.77 | M14: 41087.81 | N14: 40629.04 | O14: 44126.11 | P14: 44126.11 | Q14: 44256.28 | R14: 45949.57 | S14: 45865.61 | T14: 45323.36 | U14: 45323.36 | V14: 49274.7 | W14: 47034.17 | X14: 45929.3 | Y14: 282810.78 | Z14: 282810.78 | AA14: 283205.27 | AB14: 282133.85
A15: 1 | C15: 장기금융자산 | E15: 12100.86 | F15: 12100.86 | G15: 11726.14 | H15: 9731.29 | I15: 7949.7 | J15: 8073.83 | K15: 8073.83 | L15: 9585.16 | M15: 10395.24 | N15: 9564.18 | O15: 9681.59 | P15: 9681.59 | Q15: 9987.92 | R15: 11078.65 | S15: 10582.52 | T15: 10390.73 | U15: 10390.73 | V15: 15706.26 | W15: 14607.8 | X15: 14667.95 | Y15: 13697.59 | Z15: 13697.59 | AA15: 12514.29 | AB15: 12995.56
A16: 1 | C16: 투자자산 | E16: 12100.86 | F16: 12100.86 | G16: 11726.14 | H16: 9731.29 | I16: 7949.7 | J16: 8073.83 | K16: 8073.83 | L16: 9585.16 | M16: 10395.24 | N16: 9564.18 | O16: 9681.59 | P16: 9681.59 | Q16: 9987.92 | R16: 11078.65 | S16: 10582.52 | T16: 10390.73 | U16: 10390.73 | V16: 15706.26 | W16: 14607.8 | X16: 14667.95 | Y16: 13697.59 | Z16: 13697.59 | AA16: 12514.29 | AB16: 12995.56
A17: 1 | C17: 장기매출채권및기타채권 | E17: 1003.28 | F17: 1003.28 | G17: 1021.64 | H17: 1018.04 | I17: 842.16 | J17: 883.93 | K17: 883.93 | L17: 922.33 | M17: 807.45 | N17: 772.83 | O17: 2797.97 | P17: 2797.97 | Q17: 2847.07 | R17: 2760.23 | Y17: 2589.04 | Z17: 2589.04 | AB17: 2056.84
A18: 1 | C18: 유형자산 | E18: 28248.53 | F18: 28248.53 | G18: 28090.26 | H18: 28663.24 | I18: 29544.03 | J18: 25419.86 | K18: 25419.86 | L18: 25586.14 | M18: 25477.46 | N18: 25647.57 | O18: 26143.03 | P18: 26143.03 | Q18: 26181.58 | R18: 26355.22 | S18: 26012.12 | T18: 26242.92 | U18: 26242.92 | V18: 26282.63 | W18: 26150.02 | X18: 25992.45 | Y18: 182318.33 | Z18: 182318.33 | AA18: 181886.15 | AB18: 183578.74
A19: 1 | C19: 사용권자산 | E19: 397.38 | F19: 397.38 | G19: 378.31 | H19: 357.37 | I19: 438.08 | J19: 93.94 | K19: 93.94 | L19: 77.56 | M19: 61.19 | N19: 44.81 | O19: 28.43 | P19: 28.43 | Q19: 173.85 | R19: 160.94 | S19: 143.09 | T19: 129.65 | U19: 129.65 | V19: 112.07 | W19: 91.56 | X19: 87.56 | Y19: 9859.68 | Z19: 9859.68 | AA19: 9888.55 | AB19: 9912.18
A20: 1 | C20: 기타비유동자산 | E20: 413.7 | F20: 413.7 | G20: 384.97 | H20: 357.37 | I20: 438.08 | J20: 93.94 | K20: 93.94 | L20: 77.56 | M20: 61.19 | N20: 44.81 | O20: 28.43 | P20: 28.43 | Q20: 173.85 | R20: 191 | S20: 170.33 | T20: 181.27 | U20: 181.27 | V20: 158.83 | W20: 130.76 | X20: 123.5 | Y20: 10800.82 | Z20: 10800.82 | AA20: 10715.49 | AB20: 10630.35
A21: 1 | C21: 무형자산 | E21: 317.53 | F21: 317.53 | G21: 317.53 | H21: 317.53 | I21: 558.89 | J21: 549.95 | K21: 549.95 | L21: 541.01 | M21: 532.07 | N21: 523.13 | O21: 512.19 | P21: 512.19 | Q21: 503.26 | R21: 417.55 | S21: 408.61 | T21: 1104.67 | U21: 1104.67 | V21: 1097.46 | W21: 1111.67 | X21: 1108.36 | Y21: 64210.13 | Z21: 64210.13 | AA21: 62059.76 | AB21: 60719.62
A22: 1 | C22: 투자부동산 | E22: 1951.11 | F22: 1951.11 | G22: 1942.48 | H22: 1933.85 | I22: 1925.22 | J22: 1916.6 | K22: 1916.6 | L22: 1907.97 | M22: 1899.34 | N22: 1890.71 | O22: 1882.08 | P22: 1882.08 | Q22: 1873.45 | R22: 1864.82 | S22: 1856.19 | T22: 1847.57 | U22: 1847.57 | V22: 1838.94 | W22: 1830.31 | X22: 1821.68 | Y22: 3305.39 | Z22: 3305.39 | AA22: 3324.91 | AB22: 3410.19
A23: 1 | C23: 이연법인세자산 | E23: 141.66 | F23: 141.66 | G23: 262.74 | H23: 1039.93 | I23: 2207.51 | J23: 2056.18 | K23: 2056.18 | L23: 1816.82 | M23: 1915.06 | N23: 2185.8 | O23: 2037.2 | P23: 2037.2 | Q23: 2037.2 | R23: 2617.71 | S23: 2894.42 | T23: 1678.2 | U23: 1678.2 | V23: 1308.5 | W23: 927.17 | X23: 666.49 | Y23: 5622.58 | Z23: 5622.58 | AA23: 8518.12 | AB23: 6243.89
A24: 1 | C24: 자산총계 | E24: 110382.02 | F24: 110382.02 | G24: 112067.31 | H24: 110825.25 | I24: 108670.3 | J24: 101301.62 | K24: 101301.62 | L24: 104824.56 | M24: 106930.27 | N24: 109129.15 | O24: 111581.33 | P24: 111581.33 | Q24: 113678.45 | R24: 107723.34 | S24: 115249.4 | T24: 115885.55 | U24: 115885.55 | V24: 128660.27 | W24: 119420.76 | X24: 146589.1 | Y24: 544114.87 | Z24: 544114.87 | AA24: 568299.17 | AB24: 579945.67
A25: 1 | C25: 유동부채 | E25: 35307.11 | F25: 35307.11 | G25: 37332.24 | H25: 38201.86 | I25: 38721.47 | J25: 36855.52 | K25: 36855.52 | L25: 38328.11 | M25: 39380.29 | N25: 40159.3 | O25: 42256.96 | P25: 42256.96 | Q25: 43746.19 | R25: 37521.81 | S25: 42228.3 | T25: 41132.79 | U25: 41132.79 | V25: 52034.44 | W25: 40415.49 | X25: 64388.4 | Y25: 226467.65 | Z25: 226467.65 | AA25: 241716.32 | AB25: 224351.87
A26: 1 | C26: 매입채무및기타채무 | E26: 7279.85 | F26: 7279.85 | G26: 7371.71 | H26: 6770.66 | I26: 7226.53 | J26: 7781.38 | K26: 7781.38 | L26: 7517.65 | M26: 7868.12 | N26: 7685.44 | O26: 8962.08 | P26: 8962.08 | Q26: 11316.23 | R26: 7989.79 | S26: 8710.36 | T26: 10931.03 | U26: 10931.03 | V26: 11416.28 | W26: 8325.52 | X26: 8653.52 | Y26: 64807.58 | Z26: 64807.58 | AA26: 65161.74 | AB26: 68137.94
A27: 1 | C27: 단기차입금 | E27: 24750.15 | F27: 24750.15 | G27: 24825.14 | H27: 25174.49 | I27: 25670.18 | J27: 23790.97 | K27: 23790.97 | L27: 25177.48 | M27: 25735.19 | N27: 27311.76 | O27: 27150.91 | P27: 27150.91 | Q27: 21311.19 | R27: 16927.92 | S27: 19298.83 | T27: 19859.48 | U27: 19859.48 | V27: 26868.3 | W27: 18399.76 | X27: 42341 | Y27: 140129.43 | Z27: 140129.43 | AA27: 148952.62 | AB27: 130647.56
A28: 1 | C28: 유동성장기부채 | E28: 513.52 | F28: 513.52 | G28: 13.52 | H28: 13.52 | I28: 1513.52 | J28: 1500 | K28: 1500 | L28: 1500 | M28: 1500 | N28: 0 | O28: 0 | P28: 0 | Q28: 0 | R28: 500 | S28: 500 | T28: 500 | U28: 500 | V28: 0 | W28: 0 | X28: 0 | Y28: 0 | Z28: 0 | AA28: 0 | AB28: 1083.35
A29: 1 | C29: 당기법인세부채(미지급법인세) | E29: 21.25 | F29: 21.25 | G29: 38.46 | H29: 27.55 | I29: 0 | J29: 0 | K29: 0 | L29: 119.59 | M29: 392.51 | N29: 777.75 | O29: 0 | P29: 0 | Q29: 199.25 | R29: 904.73 | S29: 1524.86 | T29: 82.62 | U29: 82.62 | V29: 145.57 | W29: 337.45 | X29: 561.34 | Y29: 2864.36 | Z29: 2864.36 | AA29: 3645.82
A30: 1 | C30: 단기충당부채 | E30: 221.46 | F30: 221.46 | G30: 199.47 | H30: 198.44 | I30: 1682.99 | J30: 1696.88 | K30: 1696.88 | L30: 1532.68 | M30: 1573.66 | N30: 1605.79 | O30: 1584 | P30: 1584 | Q30: 1492.11 | R30: 3659.61 | S30: 3712.34 | T30: 1610.17 | U30: 1610.17 | V30: 1433.01 | W30: 1501.87 | X30: 1525.84 | Y30: 1543.17 | Z30: 1543.17 | AA30: 1603.14 | AB30: 1487.59
A31: 1 | C31: 유동리스부채 | E31: 151.04 | F31: 151.04 | G31: 133.61 | H31: 114.95 | I31: 152.83 | J31: 212.03 | K31: 212.03 | L31: 135.2 | M31: 110.89 | N31: 82.24 | O31: 51.74 | P31: 51.74 | Q31: 66.32 | R31: 67.78 | S31: 68.33 | T31: 68.69 | U31: 68.69 | V31: 66.57 | W31: 62.45 | X31: 71.97 | Y31: 133.48 | Z31: 133.48 | AA31: 120.69 | AB31: 123.64
A32: 1 | C32: 리스부채 | E32: 254.4 | F32: 254.4 | G32: 212.29 | H32: 168.3 | I32: 228.85 | J32: 331.02 | K32: 331.02 | L32: 169.55 | M32: 126.17 | N32: 94.64 | O32: 61.24 | P32: 61.24 | Q32: 178.16 | R32: 163.65 | S32: 146.42 | T32: 133.5 | U32: 133.5 | V32: 116.17 | W32: 95.57 | X32: 90.86 | Y32: 507.18 | Z32: 507.18 | AA32: 460.92 | AB32: 472.28
A33: 1 | C33: 단기금융부채 | E33: 212.51 | F33: 212.51 | G33: 270.27 | H33: 397.76 | I33: 152.83 | J33: 212.03 | K33: 212.03 | L33: 354.07 | M33: 286.18 | N33: 265.03 | O33: 128.88 | P33: 128.88 | Q33: 462.56 | R33: 674.33 | S33: 285.68 | T33: 822.19 | U33: 822.19 | V33: 799.31 | W33: 424.56 | X33: 847.5 | Y33: 5885.84 | Z33: 5885.84 | AA33: 6179.9 | AB33: 2504.73
A34: 1 | C34: 단기파생상품부채 | E34: 61.47 | F34: 61.47 | G34: 136.66 | H34: 282.81 | I34: 0 | J34: 0 | K34: 0 | L34: 218.87 | M34: 175.29 | N34: 182.79 | O34: 77.14 | P34: 77.14 | Q34: 396.24 | R34: 606.55 | S34: 217.35 | T34: 753.5 | U34: 753.5 | V34: 732.74 | W34: 362.11 | X34: 775.53 | Y34: 5752.36 | Z34: 5752.36 | AA34: 6059.21 | AB34: 2381.09
A35: 1 | C35: 기타유동부채 | E35: 2308.37 | F35: 2308.37 | G35: 4613.69 | H35: 5619.43 | I35: 2475.42 | J35: 1874.27 | K35: 1874.27 | L35: 2126.63 | M35: 2024.62 | N35: 2513.53 | O35: 4431.09 | P35: 4431.09 | Q35: 8964.85 | R35: 6865.43 | S35: 8196.23 | T35: 7327.32 | U35: 7327.32 | V35: 11371.96 | W35: 11426.33 | X35: 10459.2 | Y35: 11237.28 | Z35: 11237.28 | AA35: 16173.1 | AB35: 19117.42
A36: 1 | C36: 비유동부채 | E36: 2041.45 | F36: 2041.45 | G36: 2068.24 | H36: 2697.87 | I36: 1416.27 | J36: 1017.66 | K36: 1017.66 | L36: 947.04 | M36: 1549.39 | N36: 1690.66 | O36: 960.22 | P36: 960.22 | Q36: 1086.59 | R36: 596.4 | S36: 592.18 | T36: 531.12 | U36: 531.12 | V36: 1522.87 | W36: 2507.25 | X36: 2519.23 | Y36: 74818.16 | Z36: 74818.16 | AA36: 78901.95 | AB36: 103265.06
A37: 1 | C37: 장기매입채무및기타채무 | E37: 216.46 | F37: 216.46 | G37: 221.96 | H37: 226.91 | I37: 233.76 | J37: 238.99 | K37: 238.99 | L37: 246.99 | M37: 250.85 | N37: 238.33 | O37: 270.29 | P37: 270.29 | Q37: 288.45 | R37: 288.07 | S37: 295.09 | T37: 254.28 | U37: 254.28 | V37: 242.75 | W37: 250.8 | X37: 258.24 | Y37: 792.06 | Z37: 792.06 | AA37: 845.29 | AB37: 865.69
A38: 1 | C38: 장기차입금 | E38: 1537.18 | F38: 1537.18 | G38: 1533.8 | H38: 2030.42 | I38: 527.04 | J38: 500 | K38: 500 | L38: 500 | M38: 500 | N38: 500 | O38: 500 | P38: 500 | Q38: 500 | R38: 0 | S38: 0 | T38: 0 | U38: 0 | V38: 1000 | W38: 2000 | X38: 2000 | Y38: 34007.91 | Z38: 34007.91 | AA38: 34826.94 | AB38: 58357.32
A39: 1 | C39: 비유동리스부채 | E39: 103.36 | F39: 103.36 | G39: 78.68 | H39: 53.35 | I39: 76.02 | J39: 118.99 | K39: 118.99 | L39: 34.35 | M39: 15.28 | N39: 12.4 | O39: 9.5 | P39: 9.5 | Q39: 111.84 | R39: 95.87 | S39: 78.09 | T39: 64.81 | U39: 64.81 | V39: 49.6 | W39: 33.12 | X39: 18.89 | Y39: 373.7 | Z39: 373.7 | AA39: 340.23 | AB39: 348.64
A40: 1 | C40: 장기금융부채 | E40: 103.36 | F40: 103.36 | G40: 78.68 | H40: 53.35 | I40: 76.02 | J40: 118.99 | K40: 118.99 | L40: 34.35 | M40: 15.28 | N40: 12.4 | O40: 9.5 | P40: 9.5 | Q40: 111.84 | R40: 95.87 | S40: 78.09 | T40: 64.81 | U40: 64.81 | V40: 49.6 | W40: 33.12 | X40: 18.89 | Y40: 3006.47 | Z40: 3006.47 | AA40: 2973 | AB40: 4024.06
...

Sheet BS별도
B1: (백만원) | C1: 이름: BS별도H | E1: 4Q21 | F1: 2021 | G1: 1Q22 | H1: 2Q22 | I1: 3Q22 | J1: 4Q22 | K1: 2022 | L1: 1Q23 | M1: 2Q23 | N1: 3Q23 | O1: 4Q23 | P1: 2023 | Q1: 1Q24 | R1: 2Q24 | S1: 3Q24 | T1: 4Q24 | U1: 2024 | V1: 1Q25 | W1: 2Q25 | X1: 3Q25 | Y1: 4Q25 | Z1: 2025 | AA1: 1Q26 | AB1: 2Q26 | AC1: 3Q26 | AD1: 4Q26 | AE1: 2026 | AF1: 1Q27 | AG1: 2Q27 | AH1: 3Q27 | AI1: 4Q27 | AJ1: 2027 | AK1: 1Q28 | AL1: 2Q28 | AM1: 3Q28 | AN1: 4Q28 | AO1: 2028
B2: 별도 | D2: fin json(kship_fin.py)
B3: 삼영엠텍(별) | C3: UPDATE: 26-10-12 | E3: 1 | F3: 2 | G3: 3 | H3: 4 | I3: 5 | J3: 6 | K3: 7 | L3: 8 | M3: 9 | N3: 10 | O3: 11 | P3: 12 | Q3: 13 | R3: 14 | S3: 15 | T3: 16 | U3: 17 | V3: 18 | W3: 19 | X3: 20 | Y3: 21 | Z3: 22 | AA3: 23 | AB3: 24 | AC3: 25 | AD3: 26 | AE3: 27 | AF3: 28 | AG3: 29 | AH3: 30 | AI3: 31 | AJ3: 32 | AK3: 33 | AL3: 34 | AM3: 35 | AN3: 36 | AO3: 37
B4: Account Code | C4: AccountNAME | E4: 2021.12 | F4: 2021.12A | G4: 2022.03 | H4: 2022.06 | I4: 2022.09 | J4: 2022.12 | K4: 2022.12A | L4: 2023.03 | M4: 2023.06 | N4: 2023.09 | O4: 2023.12 | P4: 2023.12A | Q4: 2024.03 | R4: 2024.06 | S4: 2024.09 | T4: 2024.12 | U4: 2024.12A | V4: 2025.03 | W4: 2025.06 | X4: 2025.09 | Y4: 2025.12 | Z4: 2025.12A | AA4: 2026.03 | AB4: 2026.06 | AC4: 2026.09 | AD4: 2026.12 | AE4: 2026.12A | AF4: 2027.03 | AG4: 2027.06 | AH4: 2027.09 | AI4: 2027.12 | AJ4: 2027.12A | AK4: 2028.03 | AL4: 2028.06 | AM4: 2028.09 | AN4: 2028.12 | AO4: 2028.12A
A5: 1 | C5: 유동자산 | E5: 50904.61 | F5: 50904.61 | G5: 53450.99 | H5: 49019.12 | I5: 45782.18 | J5: 44818.75 | K5: 44818.75 | L5: 47565.18 | M5: 49590.73 | N5: 51165.17 | O5: 50383.06 | P5: 50383.06 | Q5: 51894.13 | R5: 43087.14 | S5: 50521.04 | T5: 49762.02 | U5: 49762.02 | V5: 57099.58 | W5: 51734.43 | X5: 76185.06 | Y5: 41211.58 | Z5: 41211.58 | AA5: 51341.38 | AB5: 55353.75
A6: 1 | C6: 현금및현금성자산 | E6: 6028.82 | F6: 6028.82 | G6: 6718.53 | H6: 7148.99 | I6: 4588.54 | J6: 5223.45 | K6: 5223.45 | L6: 6270.1 | M6: 4292.09 | N6: 5736.93 | O6: 3690.9 | P6: 3690.9 | Q6: 2165.35 | R6: 5617.32 | S6: 2385.96 | T6: 4296.79 | U6: 4296.79 | V6: 2646.74 | W6: 5804.48 | X6: 19064.89 | Y6: 2465.88 | Z6: 2465.88 | AA6: 4469.18 | AB6: 2834.91
A7: 1 | C7: 단기금융상품 | E7: 15935.08 | F7: 15935.08 | G7: 11427.9 | H7: 11411.1 | I7: 10375.12 | J7: 15823.83 | K7: 15823.83 | L7: 16783.95 | M7: 16294.84 | N7: 18177.28 | O7: 19162.76 | P7: 19162.76 | Q7: 16183.86 | R7: 5186.73 | S7: 19032.25 | T7: 14724.98 | U7: 14724.98 | V7: 18700.77 | W7: 13443.49 | X7: 26151.56 | Y7: 1399.58 | Z7: 1399.58 | AA7: 2057.45 | AB7: 1072.99
A8: 1 | C8: 단기금융자산 | E8: 15970.15 | F8: 15970.15 | G8: 11456.06 | H8: 11411.1 | I8: 10375.12 | J8: 15823.83 | K8: 15823.83 | L8: 16789.2 | M8: 16321.07 | N8: 18220.65 | O8: 19240.37 | P8: 19240.37 | Q8: 16183.86 | R8: 5186.73 | S8: 19065.39 | T8: 14737.16 | U8: 14737.16 | V8: 18700.77 | W8: 13582.44 | X8: 26155.63 | Y8: 2712.78 | Z8: 2712.78 | AA8: 3292.23 | AB8: 1445.33
A9: 1 | C9: 매출채권및기타채권 | E9: 10986.4 | F9: 10986.4 | G9: 14863.67 | H9: 9957.76 | I9: 12669.76 | J9: 7500.63 | K9: 7500.63 | L9: 7949.77 | M9: 10860.06 | N9: 10998.93 | O9: 8184.82 | P9: 8184.82 | Q9: 9673.86 | R9: 11180.87 | S9: 8690.55 | T9: 7928.13 | U9: 7928.13 | V9: 10603.01 | W9: 9808.73 | X9: 9137.24 | Y9: 12403.59 | Z9: 12403.59 | AA9: 15130.83 | AB9: 16965.18
A10: 1 | C10: 재고자산 | E10: 16692.86 | F10: 16692.86 | G10: 18868.33 | H10: 19005.02 | I10: 17211.16 | J10: 15377.22 | K10: 15377.22 | L10: 15588.26 | M10: 17394.16 | N10: 14814.01 | O10: 17218.24 | P10: 17218.24 | Q10: 22604.94 | R10: 20369.85 | S10: 19303.78 | T10: 21691.84 | U10: 21691.84 | V10: 23951.84 | W10: 21697.98 | X10: 20595.42 | Y10: 22030.84 | Z10: 22030.84 | AA10: 26925.92 | AB10: 31585.37
A11: 1 | C11: 유동파생상품자산 | E11: 35.07 | F11: 35.07 | G11: 28.16 | H11: 0 | I11: 0 | J11: 0 | K11: 0 | L11: 5.25 | M11: 26.23 | N11: 43.37 | O11: 77.61 | P11: 77.61 | Q11: 0 | R11: 0 | S11: 33.14 | T11: 12.18 | U11: 12.18 | V11: 0 | W11: 138.95 | X11: 4.07 | Y11: 1313.2 | Z11: 1313.2 | AA11: 1234.78 | AB11: 372.34
A12: 1 | C12: 기타유동자산 | E12: 1226.39 | F12: 1226.39 | G12: 1544.39 | H12: 1496.24 | I12: 863.58 | J12: 819.47 | K12: 819.47 | L12: 893.68 | M12: 723.35 | N12: 1394.66 | O12: 1946.63 | P12: 1946.63 | Q12: 1164.01 | R12: 732.36 | S12: 1075.35 | T12: 1108.09 | U12: 1108.09 | V12: 1197.23 | W12: 840.81 | X12: 1231.88 | Y12: 1598.48 | Z12: 1598.48 | AA12: 1523.23 | AB12: 2522.96
A13: 1 | C13: 비유동자산 | E13: 55070.65 | F13: 55070.65 | G13: 54422.44 | H13: 56630.57 | I13: 56800.68 | J13: 49979.88 | K13: 49979.88 | L13: 48407.37 | M13: 48786.61 | N13: 48269.87 | O13: 51663.81 | P13: 51663.81 | Q13: 51624.67 | R13: 53110.29 | S13: 53179.06 | T13: 52306.59 | U13: 52306.59 | V13: 56271.08 | W13: 54044.9 | X13: 52858.08 | Y13: 140894.47 | Z13: 140894.47 | AA13: 139079.26 | AB13: 138007.69
A14: 1 | C14: 장기금융자산 | E14: 12100.86 | F14: 12100.86 | G14: 11726.14 | H14: 9731.29 | I14: 7949.7 | J14: 8073.83 | K14: 8073.83 | L14: 9585.16 | M14: 10395.24 | N14: 9564.18 | O14: 9681.59 | P14: 9681.59 | Q14: 9987.92 | R14: 11078.65 | S14: 10582.52 | T14: 10390.73 | U14: 10390.73 | V14: 15706.26 | W14: 14607.8 | X14: 14667.95 | Y14: 11265 | Z14: 11265 | AA14: 9836.28 | AB14: 10314.2
A15: 1 | C15: 투자자산 | E15: 27861.89 | F15: 27861.89 | G15: 27487.17 | H15: 25492.32 | I15: 23710.73 | J15: 16779.46 | K15: 16779.46 | L15: 18290.79 | M15: 19100.87 | N15: 18269.81 | O15: 18387.22 | P15: 18387.22 | Q15: 18693.55 | R15: 19784.28 | S15: 19288.15 | T15: 19096.36 | U15: 19096.36 | V15: 24411.89 | W15: 23313.43 | X15: 23373.58 | Y15: 109337.66 | Z15: 109337.66 | AA15: 107908.94 | AB15: 108386.86
A16: 1 | C16: 장기매출채권및기타채권 | E16: 965.65 | F16: 965.65 | G16: 983.25 | H16: 3870.35 | I16: 3796.73 | J16: 3568.88 | K16: 3568.88 | L16: 884.12 | M16: 770.88 | N16: 735.61 | O16: 2761.44 | P16: 2761.44 | Q16: 2786.7 | R16: 2698.34 | AB16: 825.6
A17: 1 | C17: 종속기업및관계기업투자 | E17: 15761.03 | F17: 15761.03 | G17: 15761.03 | H17: 15761.03 | I17: 15761.03 | J17: 8705.63 | K17: 8705.63 | L17: 8705.63 | M17: 8705.63 | N17: 8705.63 | O17: 8705.63 | P17: 8705.63 | Q17: 8705.63 | R17: 8705.63 | S17: 8705.63 | T17: 8705.63 | U17: 8705.63 | V17: 8705.63 | W17: 8705.63 | X17: 8705.63 | Y17: 98072.66 | Z17: 98072.66 | AA17: 98072.66 | AB17: 98072.66
A18: 1 | C18: 유형자산 | E18: 23625.95 | F18: 23625.95 | G18: 23326.02 | H18: 23886.87 | I18: 24525.42 | J18: 24608.42 | K18: 24608.42 | L18: 24637.31 | M18: 24507.21 | N18: 24620 | O18: 25011.63 | P18: 25011.63 | Q18: 24981.44 | R18: 24973.78 | S18: 24772.32 | T18: 24698.02 | U18: 24698.02 | V18: 24738.69 | W18: 24598.42 | X18: 24352.45 | Y18: 24028.44 | Z18: 24028.44 | AA18: 23415.6 | AB18: 23172.14
A19: 1 | C19: 사용권자산 | E19: 116.77 | F19: 116.77 | G19: 103.24 | H19: 89.71 | I19: 76.18 | J19: 93.94 | K19: 93.94 | L19: 77.56 | M19: 61.19 | N19: 44.81 | O19: 28.43 | P19: 28.43 | Q19: 97.12 | R19: 89.42 | S19: 79.3 | T19: 69.18 | U19: 69.18 | V19: 59.06 | W19: 48.93 | X19: 50.6 | Y19: 40.38 | Z19: 40.38 | AA19: 30.15 | AB19: 68.82
A20: 1 | C20: 기타비유동자산 | E20: 116.77 | F20: 116.77 | G20: 103.24 | H20: 89.71 | I20: 76.18 | J20: 93.94 | K20: 93.94 | L20: 77.56 | M20: 61.19 | N20: 44.81 | O20: 28.43 | P20: 28.43 | Q20: 97.12 | R20: 89.42 | S20: 79.3 | T20: 69.18 | U20: 69.18 | V20: 59.06 | W20: 48.93 | X20: 50.6 | Y20: 40.38 | Z20: 40.38 | AA20: 30.15 | AB20: 68.82
A21: 1 | C21: 무형자산 | E21: 317.53 | F21: 317.53 | G21: 317.53 | H21: 317.53 | I21: 558.89 | J21: 549.95 | K21: 549.95 | L21: 541.01 | M21: 532.07 | N21: 523.13 | O21: 512.19 | P21: 512.19 | Q21: 503.26 | R21: 417.55 | S21: 408.61 | T21: 1104.67 | U21: 1104.67 | V21: 1097.46 | W21: 1111.67 | X21: 1108.36 | Y21: 1203.77 | Z21: 1203.77 | AA21: 1201.48 | AB21: 1032.77
A22: 1 | C22: 투자부동산 | E22: 1951.11 | F22: 1951.11 | G22: 1942.48 | H22: 1933.85 | I22: 1925.22 | J22: 1916.6 | K22: 1916.6 | L22: 1907.97 | M22: 1899.34 | N22: 1890.71 | O22: 1882.08 | P22: 1882.08 | Q22: 1873.45 | R22: 1864.82 | S22: 1856.19 | T22: 1847.57 | U22: 1847.57 | V22: 1838.94 | W22: 1830.31 | X22: 1821.68 | Y22: 1813.05 | Z22: 1813.05 | AA22: 1804.42 | AB22: 1795.79
A23: 1 | C23: 이연법인세자산 | E23: 141.66 | F23: 141.66 | G23: 262.74 | H23: 1039.93 | I23: 2207.51 | J23: 2056.18 | K23: 2056.18 | L23: 1816.82 | M23: 1915.06 | N23: 2185.8 | O23: 2037.2 | P23: 2037.2 | Q23: 2037.2 | R23: 2617.71 | S23: 2894.42 | T23: 1678.2 | U23: 1678.2 | V23: 1308.5 | W23: 927.17 | X23: 666.49 | Y23: 1607.99 | Z23: 1607.99 | AA23: 1710.86 | AB23: 227.04
A24: 1 | C24: 자산총계 | E24: 105975.26 | F24: 105975.26 | G24: 107873.43 | H24: 105649.69 | I24: 102582.86 | J24: 94798.63 | K24: 94798.63 | L24: 95972.55 | M24: 98377.33 | N24: 99435.04 | O24: 102046.87 | P24: 102046.87 | Q24: 103518.8 | R24: 96197.43 | S24: 103700.1 | T24: 102068.61 | U24: 102068.61 | V24: 113370.66 | W24: 105779.33 | X24: 129043.14 | Y24: 182106.04 | Z24: 182106.04 | AA24: 190420.64 | AB24: 193361.44
A25: 1 | C25: 유동부채 | E25: 29656 | F25: 29656 | G25: 32651.42 | H25: 32383.2 | I25: 32640.41 | J25: 31727.71 | K25: 31727.71 | L25: 32067.51 | M25: 32933.9 | N25: 33299.71 | O25: 35626.43 | P25: 35626.43 | Q25: 37302.69 | R25: 29746.85 | S25: 34876.07 | T25: 32120.67 | U25: 32120.67 | V25: 42756.5 | W25: 31884.1 | X25: 53471.84 | Y25: 78968.45 | Z25: 78968.45 | AA25: 88291.91 | AB25: 89174.87
A26: 1 | C26: 매입채무및기타채무 | E26: 6515.92 | F26: 6515.92 | G26: 7636.24 | H26: 6356.84 | I26: 6960 | J26: 6843.81 | K26: 6843.81 | L26: 6613.77 | M26: 7268.89 | N26: 6736.02 | O26: 8126.95 | P26: 8126.95 | Q26: 10821.45 | R26: 7359.1 | S26: 8393.79 | T26: 9583.68 | U26: 9583.68 | V26: 9956.39 | W26: 6985.24 | X26: 7883 | Y26: 11541.67 | Z26: 11541.67 | AA26: 10342.09 | AB26: 11462.54
A27: 1 | C27: 단기차입금 | E27: 20000 | F27: 20000 | G27: 20000 | H27: 20000 | I27: 20000 | J27: 20000 | K27: 20000 | L27: 20000 | M27: 20000 | N27: 21500 | O27: 21500 | P27: 21500 | Q27: 15500 | R27: 10000 | S27: 12500 | T27: 12500 | U27: 12500 | V27: 19500 | W27: 11500 | X27: 32500 | Y27: 47640.06 | Z27: 47640.06 | AA27: 52506.33 | AB27: 54380.26
A28: 1 | C28: 유동성장기부채 | E28: 513.52 | F28: 513.52 | G28: 13.52 | H28: 13.52 | I28: 1513.52 | J28: 1500 | K28: 1500 | L28: 1500 | M28: 1500 | N28: 0 | Q28: 0 | R28: 500 | S28: 500 | T28: 500 | U28: 500 | V28: 0 | X28: 0 | AA28: 0 | AB28: 1000
A29: 1 | C29: 단기파생상품부채 | E29: 61.47 | F29: 61.47 | G29: 136.66 | H29: 282.81 | I29: 0 | J29: 0 | K29: 0 | L29: 218.87 | M29: 175.29 | N29: 182.79 | O29: 77.14 | P29: 77.14 | Q29: 396.24 | R29: 606.55 | S29: 217.35 | T29: 753.5 | U29: 753.5 | V29: 732.74 | W29: 362.11 | X29: 775.53 | Y29: 5752.36 | Z29: 5752.36 | AA29: 6059.21 | AB29: 2381.09
A30: 1 | C30: 단기금융부채 | E30: 114.81 | F30: 114.81 | G30: 190.17 | H30: 336.5 | I30: 53.87 | J30: 65.16 | K30: 65.16 | L30: 279.29 | M30: 222.31 | N30: 216.36 | O30: 97.23 | P30: 97.23 | Q30: 435.8 | R30: 646.52 | S30: 257.74 | T30: 791.98 | U30: 791.98 | V30: 768.63 | W30: 395.39 | X30: 816.73 | Y30: 5791.74 | Z30: 5791.74 | AA30: 6090.94 | AB30: 2421.76
A31: 1 | C31: 단기충당부채 | E31: 221.46 | F31: 221.46 | G31: 199.47 | H31: 198.44 | I31: 1682.99 | J31: 1696.88 | K31: 1696.88 | L31: 1532.68 | M31: 1573.66 | N31: 1605.79 | O31: 1584 | P31: 1584 | Q31: 1492.11 | R31: 3659.61 | S31: 3712.34 | T31: 1610.17 | U31: 1610.17 | V31: 1433.01 | W31: 1501.87 | X31: 1525.84 | Y31: 1543.17 | Z31: 1543.17 | AA31: 1603.14 | AB31: 1487.59
A32: 1 | C32: 유동리스부채 | E32: 53.34 | F32: 53.34 | G32: 53.51 | H32: 53.69 | I32: 53.87 | J32: 65.16 | K32: 65.16 | L32: 60.42 | M32: 47.02 | N32: 33.57 | O32: 20.09 | P32: 20.09 | Q32: 39.56 | R32: 39.97 | S32: 40.39 | T32: 38.48 | U32: 38.48 | V32: 35.89 | W32: 33.28 | X32: 41.2 | Y32: 39.38 | Z32: 39.38 | AA32: 31.73 | AB32: 40.67
A33: 1 | C33: 리스부채 | E33: 116 | F33: 116 | G33: 102.73 | H33: 89.42 | I33: 76.07 | J33: 94.75 | K33: 94.75 | L33: 78.56 | M33: 62.3 | N33: 45.97 | O33: 29.59 | P33: 29.59 | Q33: 100.92 | R33: 91.18 | S33: 81.34 | T33: 71.4 | U33: 71.4 | V33: 61.35 | W33: 51.21 | X33: 52.14 | Y33: 41.97 | Z33: 41.97 | AA33: 31.73 | AB33: 70.61
A34: 1 | C34: 당기법인세부채(미지급법인세) | E34: 21.25 | F34: 21.25 | G34: 38.46 | H34: 27.55 | I34: 0 | J34: 0 | K34: 0 | L34: 119.59 | M34: 392.51 | N34: 777.75 | O34: 0 | P34: 0 | Q34: 199.25 | R34: 904.73 | S34: 1524.7 | T34: 80.73 | U34: 80.73 | V34: 145.58 | W34: 337.46 | X34: 561.35 | Y34: 2475.37 | Z34: 2475.37 | AA34: 2841.42 | AB34: 558.86
A35: 1 | C35: 기타유동부채 | E35: 2269.04 | F35: 2269.04 | G35: 4573.57 | H35: 5450.34 | I35: 2430.03 | J35: 1621.85 | K35: 1621.85 | L35: 2022.18 | M35: 1976.53 | N35: 2463.79 | O35: 4318.26 | P35: 4318.26 | Q35: 8854.07 | R35: 6676.89 | S35: 7987.51 | T35: 7054.12 | U35: 7054.12 | V35: 10952.89 | W35: 11164.15 | X35: 10184.92 | Y35: 9976.45 | Z35: 9976.45 | AA35: 14907.99 | AB35: 17863.87
A36: 1 | C36: 비유동부채 | E36: 1903.13 | F36: 1903.13 | G36: 1939.19 | H36: 2598.06 | I36: 1272.26 | J36: 850.62 | K36: 850.62 | L36: 844.24 | M36: 1465.51 | N36: 1608.33 | O36: 873.98 | P36: 873.98 | Q36: 942.47 | R36: 449.07 | S36: 455.26 | T36: 393.33 | U36: 393.33 | V36: 1399.19 | W36: 2406.46 | X36: 2413.78 | Y36: 17614.19 | Z36: 17614.19 | AA36: 17844.37 | AB36: 18191.78
A37: 1 | C37: 장기매입채무및기타채무 | E37: 169.89 | F37: 169.89 | G37: 174.46 | H37: 178.72 | I37: 183.59 | J37: 193.63 | K37: 193.63 | L37: 199.71 | M37: 205.58 | N37: 192.26 | O37: 225.08 | P37: 225.08 | Q37: 232.72 | R37: 240.46 | S37: 247.91 | T37: 187.02 | U37: 187.02 | V37: 192.33 | W37: 198.14 | X37: 203.45 | Y37: 192.8 | Z37: 192.8 | AA37: 198.67 | AB37: 203.74
A38: 1 | C38: 장기차입금 | E38: 1537.18 | F38: 1537.18 | G38: 1533.8 | H38: 2030.42 | I38: 527.04 | J38: 500 | K38: 500 | L38: 500 | M38: 500 | N38: 500 | O38: 500 | P38: 500 | Q38: 500 | R38: 0 | S38: 0 | T38: 0 | U38: 0 | V38: 1000 | W38: 2000 | X38: 2000 | Y38: 7000 | Z38: 7000 | AA38: 7000 | AB38: 6000
A39: 1 | C39: 확정급여부채 | E39: 0 | F39: 0 | G39: 75.32 | H39: 240.79 | I39: 424.04 | J39: 0 | K39: 0 | M39: 609.25 | N39: 773.27 | O39: 0 | P39: 0
A40: 1 | C40: 비유동리스부채 | E40: 62.66 | F40: 62.66 | G40: 49.22 | H40: 35.73 | I40: 22.2 | J40: 29.59 | K40: 29.59 | L40: 18.14 | M40: 15.28 | N40: 12.4 | O40: 9.5 | P40: 9.5 | Q40: 61.36 | R40: 51.21 | S40: 40.95 | T40: 32.92 | U40: 32.92 | V40: 25.46 | W40: 17.93 | X40: 10.94 | Y40: 2.59 | Z40: 2.59 | AA40: 0 | AB40: 29.94
...

Sheet subQ
A1: YQ | C1: subQ 분기 서브모델(억원, U=100) | E1: 4Q21 | F1: 2021 | G1: 1Q22 | H1: 2Q22 | I1: 3Q22 | J1: 4Q22 | K1: 2022 | L1: 1Q23 | M1: 2Q23 | N1: 3Q23 | O1: 4Q23 | P1: 2023 | Q1: 1Q24 | R1: 2Q24 | S1: 3Q24 | T1: 4Q24 | U1: 2024 | V1: 1Q25 | W1: 2Q25 | X1: 3Q25 | Y1: 4Q25 | Z1: 2025 | AA1: 1Q26 | AB1: 2Q26 | AC1: 3Q26 | AD1: 4Q26 | AE1: 2026 | AF1: 1Q27 | AG1: 2Q27 | AH1: 3Q27 | AI1: 4Q27 | AJ1: 2027 | AK1: 1Q28 | AL1: 2Q28 | AM1: 3Q28 | AN1: 4Q28 | AO1: 2028
A2: A=이름(key) B=그룹 C=단위 D=FnGuide 계정명(VLOOKUP 키). 확정=VLOOKUP(BS), 추정=변수 가정 참조
E3: 1 | F3: 2 | G3: 3 | H3: 4 | I3: 5 | J3: 6 | K3: 7 | L3: 8 | M3: 9 | N3: 10 | O3: 11 | P3: 12 | Q3: 13 | R3: 14 | S3: 15 | T3: 16 | U3: 17 | V3: 18 | W3: 19 | X3: 20 | Y3: 21 | Z3: 22 | AA3: 23 | AB3: 24 | AC3: 25 | AD3: 26 | AE3: 27 | AF3: 28 | AG3: 29 | AH3: 30 | AI3: 31 | AJ3: 32 | AK3: 33 | AL3: 34 | AM3: 35 | AN3: 36 | AO3: 37
E4: 2021.12 | F4: 2021.12A | G4: 2022.03 | H4: 2022.06 | I4: 2022.09 | J4: 2022.12 | K4: 2022.12A | L4: 2023.03 | M4: 2023.06 | N4: 2023.09 | O4: 2023.12 | P4: 2023.12A | Q4: 2024.03 | R4: 2024.06 | S4: 2024.09 | T4: 2024.12 | U4: 2024.12A | V4: 2025.03 | W4: 2025.06 | X4: 2025.09 | Y4: 2025.12 | Z4: 2025.12A | AA4: 2026.03 | AB4: 2026.06 | AC4: 2026.09 | AD4: 2026.12 | AE4: 2026.12A | AF4: 2027.03 | AG4: 2027.06 | AH4: 2027.09 | AI4: 2027.12 | AJ4: 2027.12A | AK4: 2028.03 | AL4: 2028.06 | AM4: 2028.09 | AN4: 2028.12 | AO4: 2028.12A
A5: 매출액 | B5: 손익 | C5: 억원 | D5: 매출액(수익) | E5: =IFERROR(VLOOKUP($D5,BS연결,MATCH(E$1,BS연결H,0),0)/100,"") | G5: =IFERROR(VLOOKUP($D5,BS연결,MATCH(G$1,BS연결H,0),0)/100,"") | H5: =IFERROR(VLOOKUP($D5,BS연결,MATCH(H$1,BS연결H,0),0)/100,"") | I5: =IFERROR(VLOOKUP($D5,BS연결,MATCH(I$1,BS연결H,0),0)/100,"") | J5: =IFERROR(VLOOKUP($D5,BS연결,MATCH(J$1,BS연결H,0),0)/100,"") | K5: =IFERROR(VLOOKUP($D5,BS연결,MATCH(K$1,BS연결H,0),0)/100,"") | L5: =IFERROR(VLOOKUP($D5,BS연결,MATCH(L$1,BS연결H,0),0)/100,"") | M5: =IFERROR(VLOOKUP($D5,BS연결,MATCH(M$1,BS연결H,0),0)/100,"") | N5: =IFERROR(VLOOKUP($D5,BS연결,MATCH(N$1,BS연결H,0),0)/100,"") | ... AB5: =IFERROR(VLOOKUP($D5,BS연결,MATCH(AB$1,BS연결H,0),0)/100,"") | AC5: =IFERROR(X5*(1+변수!AC21),"") | AD5: =IFERROR(Y5*(1+변수!AD21),"") | AE5: =SUM(AA5:AD5) | AF5: =IFERROR(AA5*(1+변수!AF21),"") | AG5: =IFERROR(AB5*(1+변수!AG21),"") | AH5: =IFERROR(AC5*(1+변수!AH21),"") | AI5: =IFERROR(AD5*(1+변수!AI21),"") | AJ5: =SUM(AF5:AI5) | AK5: =IFERROR(AF5*(1+변수!AK21),"") | AL5: =IFERROR(AG5*(1+변수!AL21),"") | AM5: =IFERROR(AH5*(1+변수!AM21),"") | AN5: =IFERROR(AI5*(1+변수!AN21),"") | AO5: =SUM(AK5:AN5)
A6: 매출원가 | B6: 손익 | C6: 억원 | D6: 매출원가 | E6: =IFERROR(VLOOKUP($D6,BS연결,MATCH(E$1,BS연결H,0),0)/100,"") | G6: =IFERROR(VLOOKUP($D6,BS연결,MATCH(G$1,BS연결H,0),0)/100,"") | H6: =IFERROR(VLOOKUP($D6,BS연결,MATCH(H$1,BS연결H,0),0)/100,"") | I6: =IFERROR(VLOOKUP($D6,BS연결,MATCH(I$1,BS연결H,0),0)/100,"") | J6: =IFERROR(VLOOKUP($D6,BS연결,MATCH(J$1,BS연결H,0),0)/100,"") | K6: =IFERROR(VLOOKUP($D6,BS연결,MATCH(K$1,BS연결H,0),0)/100,"") | L6: =IFERROR(VLOOKUP($D6,BS연결,MATCH(L$1,BS연결H,0),0)/100,"") | M6: =IFERROR(VLOOKUP($D6,BS연결,MATCH(M$1,BS연결H,0),0)/100,"") | N6: =IFERROR(VLOOKUP($D6,BS연결,MATCH(N$1,BS연결H,0),0)/100,"") | ... AB6: =IFERROR(VLOOKUP($D6,BS연결,MATCH(AB$1,BS연결H,0),0)/100,"") | AC6: =IFERROR(AC5-AC7,"") | AD6: =IFERROR(AD5-AD7,"") | AE6: =SUM(AA6:AD6) | AF6: =IFERROR(AF5-AF7,"") | AG6: =IFERROR(AG5-AG7,"") | AH6: =IFERROR(AH5-AH7,"") | AI6: =IFERROR(AI5-AI7,"") | AJ6: =SUM(AF6:AI6) | AK6: =IFERROR(AK5-AK7,"") | AL6: =IFERROR(AL5-AL7,"") | AM6: =IFERROR(AM5-AM7,"") | AN6: =IFERROR(AN5-AN7,"") | AO6: =SUM(AK6:AN6)
A7: 매출총이익 | B7: 손익 | C7: 억원 | D7: 매출총이익 | E7: =IFERROR(VLOOKUP($D7,BS연결,MATCH(E$1,BS연결H,0),0)/100,"") | G7: =IFERROR(VLOOKUP($D7,BS연결,MATCH(G$1,BS연결H,0),0)/100,"") | H7: =IFERROR(VLOOKUP($D7,BS연결,MATCH(H$1,BS연결H,0),0)/100,"") | I7: =IFERROR(VLOOKUP($D7,BS연결,MATCH(I$1,BS연결H,0),0)/100,"") | J7: =IFERROR(VLOOKUP($D7,BS연결,MATCH(J$1,BS연결H,0),0)/100,"") | K7: =IFERROR(VLOOKUP($D7,BS연결,MATCH(K$1,BS연결H,0),0)/100,"") | L7: =IFERROR(VLOOKUP($D7,BS연결,MATCH(L$1,BS연결H,0),0)/100,"") | M7: =IFERROR(VLOOKUP($D7,BS연결,MATCH(M$1,BS연결H,0),0)/100,"") | N7: =IFERROR(VLOOKUP($D7,BS연결,MATCH(N$1,BS연결H,0),0)/100,"") | ... AB7: =IFERROR(VLOOKUP($D7,BS연결,MATCH(AB$1,BS연결H,0),0)/100,"") | AC7: =IFERROR(AC9+AC8,"") | AD7: =IFERROR(AD9+AD8,"") | AE7: =SUM(AA7:AD7) | AF7: =IFERROR(AF9+AF8,"") | AG7: =IFERROR(AG9+AG8,"") | AH7: =IFERROR(AH9+AH8,"") | AI7: =IFERROR(AI9+AI8,"") | AJ7: =SUM(AF7:AI7) | AK7: =IFERROR(AK9+AK8,"") | AL7: =IFERROR(AL9+AL8,"") | AM7: =IFERROR(AM9+AM8,"") | AN7: =IFERROR(AN9+AN8,"") | AO7: =SUM(AK7:AN7)
A8: 판관비 | B8: 손익 | C8: 억원 | D8: 판관비 | E8: =IFERROR(VLOOKUP($D8,BS연결,MATCH(E$1,BS연결H,0),0)/100,"") | G8: =IFERROR(VLOOKUP($D8,BS연결,MATCH(G$1,BS연결H,0),0)/100,"") | H8: =IFERROR(VLOOKUP($D8,BS연결,MATCH(H$1,BS연결H,0),0)/100,"") | I8: =IFERROR(VLOOKUP($D8,BS연결,MATCH(I$1,BS연결H,0),0)/100,"") | J8: =IFERROR(VLOOKUP($D8,BS연결,MATCH(J$1,BS연결H,0),0)/100,"") | K8: =IFERROR(VLOOKUP($D8,BS연결,MATCH(K$1,BS연결H,0),0)/100,"") | L8: =IFERROR(VLOOKUP($D8,BS연결,MATCH(L$1,BS연결H,0),0)/100,"") | M8: =IFERROR(VLOOKUP($D8,BS연결,MATCH(M$1,BS연결H,0),0)/100,"") | N8: =IFERROR(VLOOKUP($D8,BS연결,MATCH(N$1,BS연결H,0),0)/100,"") | ... AB8: =IFERROR(VLOOKUP($D8,BS연결,MATCH(AB$1,BS연결H,0),0)/100,"") | AC8: =IFERROR(AC5*변수!AC22,"") | AD8: =IFERROR(AD5*변수!AD22,"") | AE8: =SUM(AA8:AD8) | AF8: =IFERROR(AF5*변수!AF22,"") | AG8: =IFERROR(AG5*변수!AG22,"") | AH8: =IFERROR(AH5*변수!AH22,"") | AI8: =IFERROR(AI5*변수!AI22,"") | AJ8: =SUM(AF8:AI8) | AK8: =IFERROR(AK5*변수!AK22,"") | AL8: =IFERROR(AL5*변수!AL22,"") | AM8: =IFERROR(AM5*변수!AM22,"") | AN8: =IFERROR(AN5*변수!AN22,"") | AO8: =SUM(AK8:AN8)
A9: 영업이익 | B9: 손익 | C9: 억원 | D9: 영업이익 | E9: =IFERROR(VLOOKUP($D9,BS연결,MATCH(E$1,BS연결H,0),0)/100,"") | G9: =IFERROR(VLOOKUP($D9,BS연결,MATCH(G$1,BS연결H,0),0)/100,"") | H9: =IFERROR(VLOOKUP($D9,BS연결,MATCH(H$1,BS연결H,0),0)/100,"") | I9: =IFERROR(VLOOKUP($D9,BS연결,MATCH(I$1,BS연결H,0),0)/100,"") | J9: =IFERROR(VLOOKUP($D9,BS연결,MATCH(J$1,BS연결H,0),0)/100,"") | K9: =IFERROR(VLOOKUP($D9,BS연결,MATCH(K$1,BS연결H,0),0)/100,"") | L9: =IFERROR(VLOOKUP($D9,BS연결,MATCH(L$1,BS연결H,0),0)/100,"") | M9: =IFERROR(VLOOKUP($D9,BS연결,MATCH(M$1,BS연결H,0),0)/100,"") | N9: =IFERROR(VLOOKUP($D9,BS연결,MATCH(N$1,BS연결H,0),0)/100,"") | ... AB9: =IFERROR(VLOOKUP($D9,BS연결,MATCH(AB$1,BS연결H,0),0)/100,"") | AC9: =IFERROR(AC5*변수!AC23,"") | AD9: =IFERROR(AD5*변수!AD23,"") | AE9: =SUM(AA9:AD9) | AF9: =IFERROR(AF5*변수!AF23,"") | AG9: =IFERROR(AG5*변수!AG23,"") | AH9: =IFERROR(AH5*변수!AH23,"") | AI9: =IFERROR(AI5*변수!AI23,"") | AJ9: =SUM(AF9:AI9) | AK9: =IFERROR(AK5*변수!AK23,"") | AL9: =IFERROR(AL5*변수!AL23,"") | AM9: =IFERROR(AM5*변수!AM23,"") | AN9: =IFERROR(AN5*변수!AN23,"") | AO9: =SUM(AK9:AN9)
A10: OPM | B10: 손익 | C10: % | D10: 영업이익률 | E10: =IFERROR(E9/E5,"") | G10: =IFERROR(G9/G5,"") | H10: =IFERROR(H9/H5,"") | I10: =IFERROR(I9/I5,"") | J10: =IFERROR(J9/J5,"") | K10: =IFERROR(K9/K5,"") | L10: =IFERROR(L9/L5,"") | M10: =IFERROR(M9/M5,"") | N10: =IFERROR(N9/N5,"") | ... AO10: =IFERROR(AO9/AO5,"")
