Workbook
Name 변수H: 변수!$C$1:$AO$1
Name 환율: 변수!$C$6:$AO$13
Name BS연결H: BS연결!$C$1:$AO$1
Name BS연결: BS연결!$C$5:$AO$110
Name BS별도H: BS별도!$C$1:$AO$1
Name BS별도: BS별도!$C$5:$AO$95
Name SUBQH: subQ!$A$1:$AO$1
Name subQ: subQ!$A$5:$AO$46

Sheet README
A1: 세진중공업(075580) 실적 모델 — ARGUS 한국조선
A2: 기준 분기 2026Q2 · 마지막 실적 2026Q2 · 생성 2026-10-14
A3: 모든 수치는 모델 산출값(DART 공개 재무제표 + 우리 추정)이다 — 목표주가·투자 추천 아님. 참고용 · 투자조언 아님.
A5: 시트
A6: 변수 가정 시계열. 환율 8행(ECB via frankfurter — L2 fx.json; 추정 분기 = 노란 가정), 추정 드라이버(노란 셀 = 모델값에서 역산한 가정, 바꾸면 재계산; 연녹 셀 = 3절 스칼라 참조 수식), 3절 스칼라 가정(세율·판관비율·지배주주비중·이자율·종가·PER 밴드·COE·외화 순노출·헤지비율)
A7: BS연결/BS별도 FnGuide 계정명 × 기간 값 덤프(백만원). 행1 분기라벨, 행4 YYYY.MM / YYYY.12A. 이름정의 BS연결H·BS연결(계정명 C열부터)
A8: subQ 분기 서브모델(억원 = 백만원/100). 확정 행: =IFERROR(VLOOKUP($D행,BS연결,MATCH(E$1,BS연결H,0),0)/100,"") 추정 행: 변수 시트 가정 셀 참조 수식. 외환손익·파생상품손익은 BS 계정 합·차, 기타금융손익은 잔차, OPM·EPS·BPS·PER·PBR 은 파생 수식
A9: SLS 선표(조선사만, sls json 있을 때): 요약 행(sls 저장값) + 계약별 스케줄(백만$) × (헤지비율 × 헤지환율 + (1−헤지비율) × 건조시점 환율[변수 원/달러(평균)]) → 원화 수식 블록 → 합계 행이 subQ 매출조선에 연결
A10: 시나리오 신규수주 보수/기준/낙관(forecast_panel 패널, 모델에 scenarios 가 있을 때만): 매출액·영업이익 = subQ 기준값 ± (시나리오 신규 − base 신규) × OPM. base 만 subQ 행에 포함, 나머지는 합산 안 함
A11: 분기/연간예상 subQ 를 이름(A열 key)으로 VLOOKUP 한 보고서 표(억원)
A12: TP PER 밴드 × 12M fwd EPS, PBR = ROE/COE × BPS — 모델 산출값 구간, 목표주가·추천 아님
A13: 외화 환율 QoQ, 외화 순노출 × Δ기말환율 → 환관련손익 추정
... A34: 백테스트: {"freeze": "2025Q2", "horizon": 4, "revenue_wape_pct": 10.5, "op_wape_pct": 53.4, "n": 4, "note": "단일 회사 4분기 — 통계 아님", "driver_at_freeze": "trend_seasonal", "selection_oos_at_freeze": {"wape_link": null, "wape_trend": null, "adopted": false, "decision": "rejected", "note": "유의성 조건 미달 → OOS 비교 전 기각"}, "frozen_inputs": "fin(연결/별도)·고객 조선사 모델·지주 자회사 모델은 2025Q2 까지의 분기만; 선표는 체결일 ≤ 2025Q2 말일 계약(원장 최신 금액·코호트 등급, 환산 없음); 잔고는 yards_cache 2025Q2; 시세·환율 forward·prices·forecast_panel 신규수주 미사용. 고객 가중치(suppliers.json 언급 비중)와 합병 체인링크는 현재 지식; 고객 연동 채택은 동결 모델 안에서도 자기 la−4분기 OOS 규칙(selection_oos_at_freeze)", "detail": [{"q": "2025Q3", "rev_pred": 784.2, "rev_act": 903.68, "op_pred": 73.57, "op_act": 121.44}, {"q": "2025Q4", "rev_pred": 1146.12, "rev_act": 1156.51, "op_pred": 107.53, "op_act": 346.8}, {"q": "2026Q1", "rev_pred": 1045.89, "rev_act": 872.43, "op_pred": 98.13, "op_act": 136.39}, {"q": "2026Q2", "rev_pred": 1036.62, "rev_act": 934.98, "op_pred": 97.26, "op_act": 203.68}]}

Sheet 변수
C1: 이름: 변수H | E1: 4Q21 | F1: 2021 | G1: 1Q22 | H1: 2Q22 | I1: 3Q22 | J1: 4Q22 | K1: 2022 | L1: 1Q23 | M1: 2Q23 | N1: 3Q23 | O1: 4Q23 | P1: 2023 | Q1: 1Q24 | R1: 2Q24 | S1: 3Q24 | T1: 4Q24 | U1: 2024 | V1: 1Q25 | W1: 2Q25 | X1: 3Q25 | Y1: 4Q25 | Z1: 2025 | AA1: 1Q26 | AB1: 2Q26 | AC1: 3Q26 | AD1: 4Q26 | AE1: 2026 | AF1: 1Q27 | AG1: 2Q27 | AH1: 3Q27 | AI1: 4Q27 | AJ1: 2027 | AK1: 1Q28 | AL1: 2Q28 | AM1: 3Q28 | AN1: 4Q28 | AO1: 2028
A2: 가정 시계열 — 노란 셀은 추정 가정(모델값에서 역산), 연녹 셀은 3절 스칼라 참조 수식. 바꾸면 subQ·분기·연간예상·TP·시나리오가 재계산됩니다.
E3: 1 | F3: 2 | G3: 3 | H3: 4 | I3: 5 | J3: 6 | K3: 7 | L3: 8 | M3: 9 | N3: 10 | O3: 11 | P3: 12 | Q3: 13 | R3: 14 | S3: 15 | T3: 16 | U3: 17 | V3: 18 | W3: 19 | X3: 20 | Y3: 21 | Z3: 22 | AA3: 23 | AB3: 24 | AC3: 25 | AD3: 26 | AE3: 27 | AF3: 28 | AG3: 29 | AH3: 30 | AI3: 31 | AJ3: 32 | AK3: 33 | AL3: 34 | AM3: 35 | AN3: 36 | AO3: 37
E4: 2021.12 | F4: 2021.12A | G4: 2022.03 | H4: 2022.06 | I4: 2022.09 | J4: 2022.12 | K4: 2022.12A | L4: 2023.03 | M4: 2023.06 | N4: 2023.09 | O4: 2023.12 | P4: 2023.12A | Q4: 2024.03 | R4: 2024.06 | S4: 2024.09 | T4: 2024.12 | U4: 2024.12A | V4: 2025.03 | W4: 2025.06 | X4: 2025.09 | Y4: 2025.12 | Z4: 2025.12A | AA4: 2026.03 | AB4: 2026.06 | AC4: 2026.09 | AD4: 2026.12 | AE4: 2026.12A | AF4: 2027.03 | AG4: 2027.06 | AH4: 2027.09 | AI4: 2027.12 | AJ4: 2027.12A | AK4: 2028.03 | AL4: 2028.06 | AM4: 2028.09 | AN4: 2028.12 | AO4: 2028.12A
B5: 1. FX | C5: 이름: 환율
A6: USDKRW_avg | C6: 원/달러(평균) | E6: 1183.5 | F6: 1145.51 | G6: 1205.78 | H6: 1262.09 | I6: 1341.93 | J6: 1360.12 | K6: 1292.98 | L6: 1276.95 | M6: 1315.69 | N6: 1313.62 | O6: 1322.01 | P6: 1306.85 | Q6: 1330.14 | R6: 1371.28 | S6: 1356.22 | T6: 1396.3 | U6: 1363.53 | V6: 1452.28 | W6: 1398.52 | X6: 1386.95 | Y6: 1449.19 | Z6: 1421.52 | AA6: 1466.12 | AB6: 1501.75 | AC6: 1418.75 | AD6: 1343.39 | AE6: 1456.01 | AF6: 1341.45 | AG6: 1341.45 | AH6: 1341.45 | AI6: 1341.45 | AK6: 1341.45 | AL6: 1341.45 | AM6: 1341.45 | AN6: 1341.45
A7: USDKRW_end | C7: 원/달러(기말) | E7: 1188.75 | F7: 1188.75 | G7: 1213.74 | H7: 1301.24 | I7: 1436.9 | J7: 1260.16 | K7: 1260.16 | L7: 1305.99 | M7: 1321.44 | N7: 1345.35 | O7: 1297.43 | P7: 1297.43 | Q7: 1349.25 | R7: 1377.73 | S7: 1312.17 | T7: 1474.78 | U7: 1474.78 | V7: 1474.54 | W7: 1355.13 | X7: 1403.67 | Y7: 1444.2 | Z7: 1444.2 | AA7: 1524.8 | AB7: 1550.89 | AC7: 1355.4 | AD7: 1341.45 | AE7: 1341.45 | AF7: 1341.45 | AG7: 1341.45 | AH7: 1341.45 | AI7: 1341.45 | AK7: 1341.45 | AL7: 1341.45 | AM7: 1341.45 | AN7: 1341.45
A8: JPY100KRW_avg | C8: 원/100Y(평균) | E8: 1041.02 | F8: 1042.74 | G8: 1036.79 | H8: 972.23 | I8: 970.61 | J8: 961.03 | K8: 985.1 | L8: 964.89 | M8: 957.36 | N8: 909 | O8: 893.22 | P8: 931.11 | Q8: 896.29 | R8: 880.14 | S8: 909.35 | T8: 917.25 | U8: 900.92 | V8: 952.59 | W8: 967.92 | X8: 940.32 | Y8: 940.77 | Z8: 950.17 | AA8: 934.39 | AB8: 942.16 | AC8: 890.41 | AD8: 849.39 | AE8: 918.46 | AF8: 848.37 | AG8: 848.37 | AH8: 848.37 | AI8: 848.37 | AK8: 848.37 | AL8: 848.37 | AM8: 848.37 | AN8: 848.37
A9: JPY100KRW_end | C9: 원/100Y(기말) | E9: 1032.62 | F9: 1032.62 | G9: 996.83 | H9: 954.9 | I9: 993.29 | J9: 955.54 | K9: 955.54 | L9: 980.62 | M9: 913.67 | N9: 901.47 | O9: 917.04 | P9: 917.04 | Q9: 892.42 | R9: 857.76 | S9: 919.21 | T9: 939.65 | U9: 939.65 | V9: 986.84 | W9: 938.85 | X9: 948.49 | Y9: 921.81 | Z9: 921.81 | AA9: 955.99 | AB9: 954.75 | AC9: 863.31 | AD9: 848.37 | AE9: 848.37 | AF9: 848.37 | AG9: 848.37 | AH9: 848.37 | AI9: 848.37 | AK9: 848.37 | AL9: 848.37 | AM9: 848.37 | AN9: 848.37
A10: EURKRW_avg | C10: W/Euro(평균) | E10: 1353.32 | F10: 1354.06 | G10: 1352.29 | H10: 1343.31 | I10: 1350.63 | J10: 1386.07 | K10: 1358.07 | L10: 1369.93 | M10: 1432.41 | N10: 1429.41 | O10: 1420.91 | P10: 1412.88 | Q10: 1444.21 | R10: 1476.42 | S10: 1489.3 | T10: 1490.78 | U10: 1475.4 | V10: 1528.33 | W10: 1585.13 | X10: 1620.04 | Y10: 1686.02 | Z10: 1605.45 | AA10: 1715.47 | AB10: 1746.09 | AC10: 1631.97 | AD10: 1506.62 | AE10: 1688.01 | AF10: 1500.82 | AG10: 1500.82 | AH10: 1500.82 | AI10: 1500.82 | AK10: 1500.82 | AL10: 1500.82 | AM10: 1500.82 | AN10: 1500.82
A11: EURKRW_end | C11: W/Euro(기말) | E11: 1346.38 | F11: 1346.38 | G11: 1347.37 | H11: 1351.6 | I11: 1400.62 | J11: 1344.08 | K11: 1344.08 | L11: 1420.26 | M11: 1435.88 | N11: 1425.26 | O11: 1433.66 | P11: 1433.66 | Q11: 1458.68 | R11: 1474.86 | S11: 1469.1 | T11: 1532.14 | U11: 1532.14 | V11: 1594.72 | W11: 1588.22 | X11: 1648.04 | Y11: 1696.94 | Z11: 1696.94 | AA11: 1753.21 | AB11: 1767.09 | AC11: 1539.06 | AD11: 1500.82 | AE11: 1500.82 | AF11: 1500.82 | AG11: 1500.82 | AH11: 1500.82 | AI11: 1500.82 | AK11: 1500.82 | AL11: 1500.82 | AM11: 1500.82 | AN11: 1500.82
A12: CNYKRW_avg | C12: 원/중국원(평균) | E12: 185.14 | F12: 177.65 | G12: 189.93 | H12: 190.76 | I12: 195.79 | J12: 191.09 | K12: 191.93 | L12: 186.59 | M12: 187.45 | N12: 181.28 | O12: 182.86 | P12: 184.52 | Q12: 185.04 | R12: 189.35 | S12: 189.24 | T12: 194.24 | U12: 189.49 | V12: 199.63 | W12: 193.41 | X12: 193.79 | Y12: 204.38 | Z12: 197.8 | AA12: 211.75 | AB12: 220.8 | AC12: 210.43 | AD12: 200.49 | AE12: 213.61 | AF12: 200.4 | AG12: 200.4 | AH12: 200.4 | AI12: 200.4 | AK12: 200.4 | AL12: 200.4 | AM12: 200.4 | AN12: 200.4
A13: CNYKRW_end | C13: 원/중국원(기말) | E13: 187.13 | F13: 187.13 | G13: 191.38 | H13: 194.13 | I13: 201.92 | J13: 182.67 | K13: 182.67 | L13: 189.97 | M13: 181.8 | N13: 184.26 | O13: 182.61 | P13: 182.61 | Q13: 186.66 | R13: 189.7 | S13: 187.12 | T13: 202.04 | U13: 202.04 | V13: 203.3 | W13: 189.14 | X13: 197.16 | Y13: 206.28 | Z13: 206.28 | AA13: 220.97 | AB13: 228.56 | AC13: 202.16 | AD13: 200.4 | AE13: 200.4 | AF13: 200.4 | AG13: 200.4 | AH13: 200.4 | AI13: 200.4 | AK13: 200.4 | AL13: 200.4 | AM13: 200.4 | AN13: 200.4
B14: 1b. 종가
A15: price_close_end | C15: 종가(기말) | E15: 5900 | G15: 6840 | H15: 6500 | I15: 6210 | J15: 5150 | L15: 5810 | M15: 6510 | N15: 5160 | O15: 4755 | Q15: 6400 | R15: 10040 | S15: 7350 | T15: 8440 | V15: 6580 | W15: 11440 | X15: 21600 | Y15: 17400 | AA15: 15520 | AB15: 13210 | AC15: 9770 | AD15: 8710
A16: price_high | C16: 종가(최고) | E16: 6880 | G16: 7740 | H16: 7640 | I16: 8900 | J16: 6580 | L16: 6390 | M16: 7310 | N16: 7330 | O16: 5160 | Q16: 6700 | R16: 10680 | S16: 10920 | T16: 8880 | V16: 9600 | W16: 12950 | X16: 27400 | Y16: 25350 | AA16: 20900 | AB16: 22100 | AC16: 14570 | AD16: 10080
A17: price_low | C17: 종가(최저) | E17: 5230 | G17: 5850 | H17: 5560 | I17: 5030 | J17: 5030 | L17: 4945 | M17: 5810 | N17: 5010 | O17: 4195 | Q17: 4655 | R17: 6310 | S17: 6670 | T17: 6380 | V17: 6570 | W17: 6410 | X17: 10280 | Y17: 16750 | AA17: 14710 | AB17: 12600 | AC17: 8500 | AD17: 8120
A18: price_avg | C18: 종가(평균) | E18: 6025.2 | G18: 6785.4 | H18: 6666.8 | I18: 6841.6 | J18: 5779.7 | L18: 5762.3 | M18: 6450.5 | N18: 6145.2 | O18: 4592.2 | Q18: 5564.7 | R18: 7426.2 | S18: 8331.1 | T18: 7593 | V18: 8434 | W18: 9865.3 | X18: 15614.6 | Y18: 19573.9 | AA18: 18365.4 | AB18: 16779.2 | AC18: 10929 | AD18: 9386.2
B20: 2. 추정 드라이버 | C20: 실적 열 = subQ 실현값(수식), 추정 열 = 가정(노란 = 모델값 역산, 연녹 = 3절 스칼라 참조)
A21: drv:판관비 | B21: ratio | C21: 판관비율(/매출) | E21: =IFERROR(subQ!E8/subQ!E5,"") | F21: =IFERROR(subQ!F8/subQ!F5,"") | G21: =IFERROR(subQ!G8/subQ!G5,"") | H21: =IFERROR(subQ!H8/subQ!H5,"") | I21: =IFERROR(subQ!I8/subQ!I5,"") | J21: =IFERROR(subQ!J8/subQ!J5,"") | K21: =IFERROR(subQ!K8/subQ!K5,"") | L21: =IFERROR(subQ!L8/subQ!L5,"") | ... AB21: =IFERROR(subQ!AB8/subQ!AB5,"") | AC21: =$D$55 | AD21: =$D$55 | AE21: =IFERROR(subQ!AE8/subQ!AE5,"") | AF21: =$D$55 | AG21: =$D$55 | AH21: =$D$55 | AI21: =$D$55 | AJ21: =IFERROR(subQ!AJ8/subQ!AJ5,"") | AK21: =$D$55 | AL21: =$D$55 | AM21: =$D$55 | AN21: =$D$55 | AO21: =IFERROR(subQ!AO8/subQ!AO5,"")
A22: drv:외환손익 | B22: abs | C22: 외환손익 (가정, 억원) | E22: =subQ!E13 | F22: =subQ!F13 | G22: =subQ!G13 | H22: =subQ!H13 | I22: =subQ!I13 | J22: =subQ!J13 | K22: =subQ!K13 | L22: =subQ!L13 | ... AB22: =subQ!AB13 | AC22: 0 | AD22: 0 | AE22: =subQ!AE13 | AF22: 0 | AG22: 0 | AH22: 0 | AI22: 0 | AJ22: =subQ!AJ13 | AK22: 0 | AL22: 0 | AM22: 0 | AN22: 0 | AO22: =subQ!AO13
A23: drv:기타영업외손익 | B23: abs | C23: 기타영업외손익 (가정, 억원) | E23: =subQ!E14 | F23: =subQ!F14 | G23: =subQ!G14 | H23: =subQ!H14 | I23: =subQ!I14 | J23: =subQ!J14 | K23: =subQ!K14 | L23: =subQ!L14 | ... AB23: =subQ!AB14 | AC23: 0 | AD23: 0 | AE23: =subQ!AE14 | AF23: 0 | AG23: 0 | AH23: 0 | AI23: 0 | AJ23: =subQ!AJ14 | AK23: 0 | AL23: 0 | AM23: 0 | AN23: 0 | AO23: =subQ!AO14
A24: drv:지분법손익 | B24: abs | C24: 지분법손익 (가정, 억원) | E24: =subQ!E15 | F24: =subQ!F15 | G24: =subQ!G15 | H24: =subQ!H15 | I24: =subQ!I15 | J24: =subQ!J15 | K24: =subQ!K15 | L24: =subQ!L15 | ... AB24: =subQ!AB15 | AC24: -0.03 | AD24: -0.03 | AE24: =subQ!AE15 | AF24: -0.03 | AG24: -0.03 | AH24: -0.03 | AI24: -0.03 | AJ24: =subQ!AJ15 | AK24: -0.03 | AL24: -0.03 | AM24: -0.03 | AN24: -0.03 | AO24: =subQ!AO15
A25: drv:법인세비용 | B25: tax | C25: 법인세율(/세전) — 법인세 = MAX(세전,0) × 세율 | E25: =IFERROR(subQ!E17/subQ!E16,"") | F25: =IFERROR(subQ!F17/subQ!F16,"") | G25: =IFERROR(subQ!G17/subQ!G16,"") | H25: =IFERROR(subQ!H17/subQ!H16,"") | I25: =IFERROR(subQ!I17/subQ!I16,"") | J25: =IFERROR(subQ!J17/subQ!J16,"") | K25: =IFERROR(subQ!K17/subQ!K16,"") | L25: =IFERROR(subQ!L17/subQ!L16,"") | ... AB25: =IFERROR(subQ!AB17/subQ!AB16,"") | AC25: =$D$54 | AD25: =$D$54 | AE25: =IFERROR(subQ!AE17/subQ!AE16,"") | AF25: =$D$54 | AG25: =$D$54 | AH25: =$D$54 | AI25: =$D$54 | AJ25: =IFERROR(subQ!AJ17/subQ!AJ16,"") | AK25: =$D$54 | AL25: =$D$54 | AM25: =$D$54 | AN25: =$D$54 | AO25: =IFERROR(subQ!AO17/subQ!AO16,"")
A26: drv:지배주주순이익 | B26: ratio | C26: 지배주주 비중(/당기순이익) | E26: =IFERROR(subQ!E19/subQ!E18,"") | F26: =IFERROR(subQ!F19/subQ!F18,"") | G26: =IFERROR(subQ!G19/subQ!G18,"") | H26: =IFERROR(subQ!H19/subQ!H18,"") | I26: =IFERROR(subQ!I19/subQ!I18,"") | J26: =IFERROR(subQ!J19/subQ!J18,"") | K26: =IFERROR(subQ!K19/subQ!K18,"") | L26: =IFERROR(subQ!L19/subQ!L18,"") | ... AB26: =IFERROR(subQ!AB19/subQ!AB18,"") | AC26: =$D$56 | AD26: =$D$56 | AE26: =IFERROR(subQ!AE19/subQ!AE18,"") | AF26: =$D$56 | AG26: =$D$56 | AH26: =$D$56 | AI26: =$D$56 | AJ26: =IFERROR(subQ!AJ19/subQ!AJ18,"") | AK26: =$D$56 | AL26: =$D$56 | AM26: =$D$56 | AN26: =$D$56 | AO26: =IFERROR(subQ!AO19/subQ!AO18,"")
A27: drv:중단사업이익 | B27: abs | C27: 중단사업이익 (가정, 억원) | E27: =subQ!E20 | F27: =subQ!F20 | G27: =subQ!G20 | H27: =subQ!H20 | I27: =subQ!I20 | J27: =subQ!J20 | K27: =subQ!K20 | L27: =subQ!L20 | ... AB27: =subQ!AB20 | AE27: =subQ!AE20 | AJ27: =subQ!AJ20 | AO27: =subQ!AO20
A28: drv:부채총계 | B28: qoq | C28: 부채총계 QoQ | G28: =IFERROR(subQ!G22/subQ!E22-1,"") | H28: =IFERROR(subQ!H22/subQ!G22-1,"") | I28: =IFERROR(subQ!I22/subQ!H22-1,"") | J28: =IFERROR(subQ!J22/subQ!I22-1,"") | L28: =IFERROR(subQ!L22/subQ!J22-1,"") | M28: =IFERROR(subQ!M22/subQ!L22-1,"") | N28: =IFERROR(subQ!N22/subQ!M22-1,"") | O28: =IFERROR(subQ!O22/subQ!N22-1,"") | Q28: =IFERROR(subQ!Q22/subQ!O22-1,"") | R28: =IFERROR(subQ!R22/subQ!Q22-1,"") | S28: =IFERROR(subQ!S22/subQ!R22-1,"") | T28: =IFERROR(subQ!T22/subQ!S22-1,"") | V28: =IFERROR(subQ!V22/subQ!T22-1,"") | W28: =IFERROR(subQ!W22/subQ!V22-1,"") | X28: =IFERROR(subQ!X22/subQ!W22-1,"") | Y28: =IFERROR(subQ!Y22/subQ!X22-1,"") | AA28: =IFERROR(subQ!AA22/subQ!Y22-1,"") | AB28: =IFERROR(subQ!AB22/subQ!AA22-1,"") | AC28: 3.56e-07 | AD28: 0 | AF28: 0 | AG28: 0 | AH28: 0 | AI28: 0 | AK28: 0 | AL28: 0 | AM28: 0 | AN28: 0
A29: drv:자본총계 | B29: roll | C29: 자본총계 기타변동(배당 등, 억원) | G29: =IFERROR(subQ!E23+subQ!G18-subQ!G23,"") | H29: =IFERROR(subQ!G23+subQ!H18-subQ!H23,"") | I29: =IFERROR(subQ!H23+subQ!I18-subQ!I23,"") | J29: =IFERROR(subQ!I23+subQ!J18-subQ!J23,"") | L29: =IFERROR(subQ!J23+subQ!L18-subQ!L23,"") | M29: =IFERROR(subQ!L23+subQ!M18-subQ!M23,"") | N29: =IFERROR(subQ!M23+subQ!N18-subQ!N23,"") | O29: =IFERROR(subQ!N23+subQ!O18-subQ!O23,"") | Q29: =IFERROR(subQ!O23+subQ!Q18-subQ!Q23,"") | R29: =IFERROR(subQ!Q23+subQ!R18-subQ!R23,"") | S29: =IFERROR(subQ!R23+subQ!S18-subQ!S23,"") | T29: =IFERROR(subQ!S23+subQ!T18-subQ!T23,"") | V29: =IFERROR(subQ!T23+subQ!V18-subQ!V23,"") | W29: =IFERROR(subQ!V23+subQ!W18-subQ!W23,"") | X29: =IFERROR(subQ!W23+subQ!X18-subQ!X23,"") | Y29: =IFERROR(subQ!X23+subQ!Y18-subQ!Y23,"") | AA29: =IFERROR(subQ!Y23+subQ!AA18-subQ!AA23,"") | AB29: =IFERROR(subQ!AA23+subQ!AB18-subQ!AB23,"") | AC29: -0.004051246 | AD29: 0.004119066 | AF29: 0.001433243 | AG29: 127.91472 | AH29: 0.002618455 | AI29: 0.002143904 | AK29: -0.009662611 | AL29: 127.91791 | AM29: 0.007379189 | AN29: -0.008022117
A30: drv:지배주주지분 | B30: roll | C30: 지배주주지분 기타변동(배당 등, 억원) | G30: =IFERROR(subQ!E24+subQ!G19-subQ!G24,"") | H30: =IFERROR(subQ!G24+subQ!H19-subQ!H24,"") | I30: =IFERROR(subQ!H24+subQ!I19-subQ!I24,"") | J30: =IFERROR(subQ!I24+subQ!J19-subQ!J24,"") | L30: =IFERROR(subQ!J24+subQ!L19-subQ!L24,"") | M30: =IFERROR(subQ!L24+subQ!M19-subQ!M24,"") | N30: =IFERROR(subQ!M24+subQ!N19-subQ!N24,"") | O30: =IFERROR(subQ!N24+subQ!O19-subQ!O24,"") | Q30: =IFERROR(subQ!O24+subQ!Q19-subQ!Q24,"") | R30: =IFERROR(subQ!Q24+subQ!R19-subQ!R24,"") | S30: =IFERROR(subQ!R24+subQ!S19-subQ!S24,"") | T30: =IFERROR(subQ!S24+subQ!T19-subQ!T24,"") | V30: =IFERROR(subQ!T24+subQ!V19-subQ!V24,"") | W30: =IFERROR(subQ!V24+subQ!W19-subQ!W24,"") | X30: =IFERROR(subQ!W24+subQ!X19-subQ!X24,"") | Y30: =IFERROR(subQ!X24+subQ!Y19-subQ!Y24,"") | AA30: =IFERROR(subQ!Y24+subQ!AA19-subQ!AA24,"") | AB30: =IFERROR(subQ!AA24+subQ!AB19-subQ!AB24,"") | AC30: -0.004407822 | AD30: 0.010950517 | AF30: 0.000902872 | AG30: 127.91259 | AH30: 0.006426646 | AI30: -0.002653627 | AK30: -0.003054244 | AL30: 127.91709 | AM30: 0.007173953 | AN30: 0.002141468
A31: drv:총차입금 | B31: qoq | C31: 총차입금 QoQ | G31: =IFERROR(subQ!G25/subQ!E25-1,"") | H31: =IFERROR(subQ!H25/subQ!G25-1,"") | I31: =IFERROR(subQ!I25/subQ!H25-1,"") | J31: =IFERROR(subQ!J25/subQ!I25-1,"") | L31: =IFERROR(subQ!L25/subQ!J25-1,"") | M31: =IFERROR(subQ!M25/subQ!L25-1,"") | N31: =IFERROR(subQ!N25/subQ!M25-1,"") | O31: =IFERROR(subQ!O25/subQ!N25-1,"") | Q31: =IFERROR(subQ!Q25/subQ!O25-1,"") | R31: =IFERROR(subQ!R25/subQ!Q25-1,"") | S31: =IFERROR(subQ!S25/subQ!R25-1,"") | T31: =IFERROR(subQ!T25/subQ!S25-1,"") | V31: =IFERROR(subQ!V25/subQ!T25-1,"") | W31: =IFERROR(subQ!W25/subQ!V25-1,"") | X31: =IFERROR(subQ!X25/subQ!W25-1,"") | Y31: =IFERROR(subQ!Y25/subQ!X25-1,"") | AA31: =IFERROR(subQ!AA25/subQ!Y25-1,"") | AB31: =IFERROR(subQ!AB25/subQ!AA25-1,"") | AC31: 0 | AD31: 0 | AF31: 0 | AG31: 0 | AH31: 0 | AI31: 0 | AK31: 0 | AL31: 0 | AM31: 0 | AN31: 0
A32: drv:순차입금 | B32: qoq | C32: 순차입금 QoQ | G32: =IFERROR(subQ!G26/subQ!E26-1,"") | H32: =IFERROR(subQ!H26/subQ!G26-1,"") | I32: =IFERROR(subQ!I26/subQ!H26-1,"") | J32: =IFERROR(subQ!J26/subQ!I26-1,"") | L32: =IFERROR(subQ!L26/subQ!J26-1,"") | M32: =IFERROR(subQ!M26/subQ!L26-1,"") | N32: =IFERROR(subQ!N26/subQ!M26-1,"") | O32: =IFERROR(subQ!O26/subQ!N26-1,"") | Q32: =IFERROR(subQ!Q26/subQ!O26-1,"") | R32: =IFERROR(subQ!R26/subQ!Q26-1,"") | S32: =IFERROR(subQ!S26/subQ!R26-1,"") | T32: =IFERROR(subQ!T26/subQ!S26-1,"") | V32: =IFERROR(subQ!V26/subQ!T26-1,"") | W32: =IFERROR(subQ!W26/subQ!V26-1,"") | X32: =IFERROR(subQ!X26/subQ!W26-1,"") | Y32: =IFERROR(subQ!Y26/subQ!X26-1,"") | AA32: =IFERROR(subQ!AA26/subQ!Y26-1,"") | AB32: =IFERROR(subQ!AB26/subQ!AA26-1,"") | AC32: -0.078038257 | AD32: -0.11637173 | AF32: -0.094526295 | AG32: 0.003511428 | AH32: -0.11139993 | AI32: -0.17109543 | AK32: -0.14957676 | AL32: -0.00547011 | AM32: -0.18973491 | AN32: -0.31783644
A33: drv:이자발생자산 | B33: qoq | C33: 이자발생자산 QoQ | G33: =IFERROR(subQ!G27/subQ!E27-1,"") | H33: =IFERROR(subQ!H27/subQ!G27-1,"") | I33: =IFERROR(subQ!I27/subQ!H27-1,"") | J33: =IFERROR(subQ!J27/subQ!I27-1,"") | L33: =IFERROR(subQ!L27/subQ!J27-1,"") | M33: =IFERROR(subQ!M27/subQ!L27-1,"") | N33: =IFERROR(subQ!N27/subQ!M27-1,"") | O33: =IFERROR(subQ!O27/subQ!N27-1,"") | Q33: =IFERROR(subQ!Q27/subQ!O27-1,"") | R33: =IFERROR(subQ!R27/subQ!Q27-1,"") | S33: =IFERROR(subQ!S27/subQ!R27-1,"") | T33: =IFERROR(subQ!T27/subQ!S27-1,"") | V33: =IFERROR(subQ!V27/subQ!T27-1,"") | W33: =IFERROR(subQ!W27/subQ!V27-1,"") | X33: =IFERROR(subQ!X27/subQ!W27-1,"") | Y33: =IFERROR(subQ!Y27/subQ!X27-1,"") | AA33: =IFERROR(subQ!AA27/subQ!Y27-1,"") | AB33: =IFERROR(subQ!AB27/subQ!AA27-1,"") | AC33: 0.083679367 | AD33: 0.1061647 | AF33: 0.068886655 | AG33: -0.002167756 | AH33: 0.069163403 | AI33: 0.088291331 | AK33: 0.058781595 | AL33: 0.001731364 | AM33: 0.059464205 | AN33: 0.076177775
A34: drv:현금및현금성자산 | B34: qoq | C34: 현금및현금성자산 QoQ | G34: =IFERROR(subQ!G28/subQ!E28-1,"") | H34: =IFERROR(subQ!H28/subQ!G28-1,"") | I34: =IFERROR(subQ!I28/subQ!H28-1,"") | J34: =IFERROR(subQ!J28/subQ!I28-1,"") | L34: =IFERROR(subQ!L28/subQ!J28-1,"") | M34: =IFERROR(subQ!M28/subQ!L28-1,"") | N34: =IFERROR(subQ!N28/subQ!M28-1,"") | O34: =IFERROR(subQ!O28/subQ!N28-1,"") | Q34: =IFERROR(subQ!Q28/subQ!O28-1,"") | R34: =IFERROR(subQ!R28/subQ!Q28-1,"") | S34: =IFERROR(subQ!S28/subQ!R28-1,"") | T34: =IFERROR(subQ!T28/subQ!S28-1,"") | V34: =IFERROR(subQ!V28/subQ!T28-1,"") | W34: =IFERROR(subQ!W28/subQ!V28-1,"") | X34: =IFERROR(subQ!X28/subQ!W28-1,"") | Y34: =IFERROR(subQ!Y28/subQ!X28-1,"") | AA34: =IFERROR(subQ!AA28/subQ!Y28-1,"") | AB34: =IFERROR(subQ!AB28/subQ!AA28-1,"")
A35: drv:CAPEX | B35: yoy | C35: CAPEX YoY | J35: =IFERROR(subQ!J29/subQ!E29-1,"") | L35: =IFERROR(subQ!L29/subQ!G29-1,"") | M35: =IFERROR(subQ!M29/subQ!H29-1,"") | N35: =IFERROR(subQ!N29/subQ!I29-1,"") | O35: =IFERROR(subQ!O29/subQ!J29-1,"") | Q35: =IFERROR(subQ!Q29/subQ!L29-1,"") | R35: =IFERROR(subQ!R29/subQ!M29-1,"") | S35: =IFERROR(subQ!S29/subQ!N29-1,"") | T35: =IFERROR(subQ!T29/subQ!O29-1,"") | V35: =IFERROR(subQ!V29/subQ!Q29-1,"") | W35: =IFERROR(subQ!W29/subQ!R29-1,"") | X35: =IFERROR(subQ!X29/subQ!S29-1,"") | Y35: =IFERROR(subQ!Y29/subQ!T29-1,"") | AA35: =IFERROR(subQ!AA29/subQ!V29-1,"") | AB35: =IFERROR(subQ!AB29/subQ!W29-1,"") | AC35: 0.56216496 | AD35: -0.17731856 | AF35: 0.27488305 | AG35: -0.53450681 | AH35: 0 | AI35: 0 | AK35: 0 | AL35: 0 | AM35: 0 | AN35: 0
A36: drv:영업활동현금흐름 | B36: yoy | C36: 영업활동현금흐름 YoY | J36: =IFERROR(subQ!J30/subQ!E30-1,"") | L36: =IFERROR(subQ!L30/subQ!G30-1,"") | M36: =IFERROR(subQ!M30/subQ!H30-1,"") | N36: =IFERROR(subQ!N30/subQ!I30-1,"") | O36: =IFERROR(subQ!O30/subQ!J30-1,"") | Q36: =IFERROR(subQ!Q30/subQ!L30-1,"") | R36: =IFERROR(subQ!R30/subQ!M30-1,"") | S36: =IFERROR(subQ!S30/subQ!N30-1,"") | T36: =IFERROR(subQ!T30/subQ!O30-1,"") | V36: =IFERROR(subQ!V30/subQ!Q30-1,"") | W36: =IFERROR(subQ!W30/subQ!R30-1,"") | X36: =IFERROR(subQ!X30/subQ!S30-1,"") | Y36: =IFERROR(subQ!Y30/subQ!T30-1,"") | AA36: =IFERROR(subQ!AA30/subQ!V30-1,"") | AB36: =IFERROR(subQ!AB30/subQ!W30-1,"")
A37: drv:주식수 | B37: qoq | C37: 주식수 QoQ | G37: =IFERROR(subQ!G31/subQ!E31-1,"") | H37: =IFERROR(subQ!H31/subQ!G31-1,"") | I37: =IFERROR(subQ!I31/subQ!H31-1,"") | J37: =IFERROR(subQ!J31/subQ!I31-1,"") | L37: =IFERROR(subQ!L31/subQ!J31-1,"") | M37: =IFERROR(subQ!M31/subQ!L31-1,"") | N37: =IFERROR(subQ!N31/subQ!M31-1,"") | O37: =IFERROR(subQ!O31/subQ!N31-1,"") | Q37: =IFERROR(subQ!Q31/subQ!O31-1,"") | R37: =IFERROR(subQ!R31/subQ!Q31-1,"") | S37: =IFERROR(subQ!S31/subQ!R31-1,"") | T37: =IFERROR(subQ!T31/subQ!S31-1,"") | V37: =IFERROR(subQ!V31/subQ!T31-1,"") | W37: =IFERROR(subQ!W31/subQ!V31-1,"") | X37: =IFERROR(subQ!X31/subQ!W31-1,"") | Y37: =IFERROR(subQ!Y31/subQ!X31-1,"") | AA37: =IFERROR(subQ!AA31/subQ!Y31-1,"") | AB37: =IFERROR(subQ!AB31/subQ!AA31-1,"") | AC37: 0 | AD37: 0 | AF37: 0 | AG37: 0 | AH37: 0 | AI37: 0 | AK37: 0 | AL37: 0 | AM37: 0 | AN37: 0
A38: drv:DPS | B38: abs | C38: DPS (가정, 원) | E38: =subQ!E34 | F38: =subQ!F34 | G38: =subQ!G34 | H38: =subQ!H34 | I38: =subQ!I34 | J38: =subQ!J34 | K38: =subQ!K34 | L38: =subQ!L34 | ... AB38: =subQ!AB34 | AD38: 225 | AE38: =subQ!AE34 | AI38: 225 | AJ38: =subQ!AJ34 | AN38: 225 | AO38: =subQ!AO34
A39: drv:매출조선기자재 | B39: yoy | C39: 매출조선기자재 YoY | J39: =IFERROR(subQ!J37/subQ!E37-1,"") | L39: =IFERROR(subQ!L37/subQ!G37-1,"") | M39: =IFERROR(subQ!M37/subQ!H37-1,"") | N39: =IFERROR(subQ!N37/subQ!I37-1,"") | O39: =IFERROR(subQ!O37/subQ!J37-1,"") | Q39: =IFERROR(subQ!Q37/subQ!L37-1,"") | R39: =IFERROR(subQ!R37/subQ!M37-1,"") | S39: =IFERROR(subQ!S37/subQ!N37-1,"") | T39: =IFERROR(subQ!T37/subQ!O37-1,"") | V39: =IFERROR(subQ!V37/subQ!Q37-1,"") | W39: =IFERROR(subQ!W37/subQ!R37-1,"") | X39: =IFERROR(subQ!X37/subQ!S37-1,"") | Y39: =IFERROR(subQ!Y37/subQ!T37-1,"") | AA39: =IFERROR(subQ!AA37/subQ!V37-1,"") | AB39: =IFERROR(subQ!AB37/subQ!W37-1,"") | AC39: 0.026095373 | AD39: 0.026094896 | AF39: 0.026111765 | AG39: 0.026101455 | AH39: 0.013060514 | AI39: 0.01305611 | AK39: 0.013041581 | AL39: 0.01305776 | AM39: 0.006517691 | AN39: 0.006524584
A40: drv:OP조선기자재 | B40: ratio | C40: OP조선기자재 마진(/매출조선기자재) | E40: =IFERROR(subQ!E38/subQ!E37,"") | F40: =IFERROR(subQ!F38/subQ!F37,"") | G40: =IFERROR(subQ!G38/subQ!G37,"") | H40: =IFERROR(subQ!H38/subQ!H37,"") | I40: =IFERROR(subQ!I38/subQ!I37,"") | J40: =IFERROR(subQ!J38/subQ!J37,"") | K40: =IFERROR(subQ!K38/subQ!K37,"") | L40: =IFERROR(subQ!L38/subQ!L37,"") | ... AB40: =IFERROR(subQ!AB38/subQ!AB37,"") | AC40: 0.15727035 | AD40: 0.15727256 | AE40: =IFERROR(subQ!AE38/subQ!AE37,"") | AF40: 0.15727199 | AG40: 0.15726594 | AH40: 0.15727212 | AI40: 0.15727115 | AJ40: =IFERROR(subQ!AJ38/subQ!AJ37,"") | AK40: 0.15726576 | AL40: 0.15726979 | AM40: 0.15727365 | AN40: 0.15726675 | AO40: =IFERROR(subQ!AO38/subQ!AO37,"")
A41: drv:매출종속사 | B41: yoy | C41: 매출종속사 YoY | J41: =IFERROR(subQ!J39/subQ!E39-1,"") | L41: =IFERROR(subQ!L39/subQ!G39-1,"") | M41: =IFERROR(subQ!M39/subQ!H39-1,"") | N41: =IFERROR(subQ!N39/subQ!I39-1,"") | O41: =IFERROR(subQ!O39/subQ!J39-1,"") | Q41: =IFERROR(subQ!Q39/subQ!L39-1,"") | R41: =IFERROR(subQ!R39/subQ!M39-1,"") | S41: =IFERROR(subQ!S39/subQ!N39-1,"") | T41: =IFERROR(subQ!T39/subQ!O39-1,"") | V41: =IFERROR(subQ!V39/subQ!Q39-1,"") | W41: =IFERROR(subQ!W39/subQ!R39-1,"") | X41: =IFERROR(subQ!X39/subQ!S39-1,"") | Y41: =IFERROR(subQ!Y39/subQ!T39-1,"") | AA41: =IFERROR(subQ!AA39/subQ!V39-1,"") | AB41: =IFERROR(subQ!AB39/subQ!W39-1,"") | AC41: -0.010274649 | AD41: 0.24633327 | AF41: 0.16379959 | AG41: -0.00752985 | AH41: 0.1792773 | AI41: 0.16577343 | AK41: 0.18993579 | AL41: 0.22139528 | AM41: 0.24567462 | AN41: 0.24548175
...

Sheet BS연결
B1: (백만원) | C1: 이름: BS연결H | E1: 4Q21 | F1: 2021 | G1: 1Q22 | H1: 2Q22 | I1: 3Q22 | J1: 4Q22 | K1: 2022 | L1: 1Q23 | M1: 2Q23 | N1: 3Q23 | O1: 4Q23 | P1: 2023 | Q1: 1Q24 | R1: 2Q24 | S1: 3Q24 | T1: 4Q24 | U1: 2024 | V1: 1Q25 | W1: 2Q25 | X1: 3Q25 | Y1: 4Q25 | Z1: 2025 | AA1: 1Q26 | AB1: 2Q26 | AC1: 3Q26 | AD1: 4Q26 | AE1: 2026 | AF1: 1Q27 | AG1: 2Q27 | AH1: 3Q27 | AI1: 4Q27 | AJ1: 2027 | AK1: 1Q28 | AL1: 2Q28 | AM1: 3Q28 | AN1: 4Q28 | AO1: 2028
B2: 연결 | D2: fin json(kship_fin.py)
B3: 세진중공업(연) | C3: UPDATE: 26-10-14 | E3: 1 | F3: 2 | G3: 3 | H3: 4 | I3: 5 | J3: 6 | K3: 7 | L3: 8 | M3: 9 | N3: 10 | O3: 11 | P3: 12 | Q3: 13 | R3: 14 | S3: 15 | T3: 16 | U3: 17 | V3: 18 | W3: 19 | X3: 20 | Y3: 21 | Z3: 22 | AA3: 23 | AB3: 24 | AC3: 25 | AD3: 26 | AE3: 27 | AF3: 28 | AG3: 29 | AH3: 30 | AI3: 31 | AJ3: 32 | AK3: 33 | AL3: 34 | AM3: 35 | AN3: 36 | AO3: 37
B4: Account Code | C4: AccountNAME | E4: 2021.12 | F4: 2021.12A | G4: 2022.03 | H4: 2022.06 | I4: 2022.09 | J4: 2022.12 | K4: 2022.12A | L4: 2023.03 | M4: 2023.06 | N4: 2023.09 | O4: 2023.12 | P4: 2023.12A | Q4: 2024.03 | R4: 2024.06 | S4: 2024.09 | T4: 2024.12 | U4: 2024.12A | V4: 2025.03 | W4: 2025.06 | X4: 2025.09 | Y4: 2025.12 | Z4: 2025.12A | AA4: 2026.03 | AB4: 2026.06 | AC4: 2026.09 | AD4: 2026.12 | AE4: 2026.12A | AF4: 2027.03 | AG4: 2027.06 | AH4: 2027.09 | AI4: 2027.12 | AJ4: 2027.12A | AK4: 2028.03 | AL4: 2028.06 | AM4: 2028.09 | AN4: 2028.12 | AO4: 2028.12A
A5: 1 | C5: 유동자산 | E5: 199499.6 | F5: 199499.6 | G5: 178998.74 | H5: 145458.76 | I5: 159282.22 | J5: 154824.32 | K5: 154824.32 | L5: 150175.35 | M5: 131074.64 | N5: 126481.93 | O5: 125520.79 | P5: 125520.79 | Q5: 163955.01 | R5: 132666.8 | S5: 160199.03 | T5: 179641.93 | U5: 179641.93 | V5: 182158.07 | W5: 166651.69 | X5: 174398.44 | Y5: 164044.5 | Z5: 164044.5 | AA5: 177482.15 | AB5: 177209.19
A6: 1 | C6: 현금및현금성자산 | E6: 37668.74 | F6: 37668.74 | G6: 40389.7 | H6: 12766.44 | I6: 31143.77 | J6: 47137.19 | K6: 47137.19 | L6: 30087.12 | M6: 37120.17 | N6: 40568.36 | O6: 50751.66 | P6: 50751.66 | Q6: 69793.88 | R6: 46285.73 | S6: 79948.17 | T6: 79542.42 | U6: 79542.42 | V6: 74589.69 | W6: 89559.22 | X6: 97942.03 | Y6: 55053.8 | Z6: 55053.8 | AA6: 69548.18 | AB6: 43468.91
A7: 1 | C7: 단기투자자산(공정가치) | E7: 414.25 | F7: 414.25 | G7: 436.36 | H7: 386.91 | I7: 382.89 | J7: 394.77 | K7: 394.77 | L7: 406.03 | M7: 415.68 | N7: 450.65 | O7: 476.78 | P7: 476.78 | Q7: 0
A8: 1 | C8: 단기금융상품 | E8: 3975.43 | F8: 3975.43 | G8: 2010 | H8: 2010 | I8: 2015.2 | J8: 2013.54 | K8: 2013.54 | L8: 2019.17 | M8: 2011.56 | N8: 2010 | O8: 2011.53 | P8: 2011.53 | Q8: 2011.6 | R8: 2010 | S8: 2010 | T8: 11.75 | U8: 11.75 | V8: 10 | W8: 4996.7 | X8: 16217.23 | Y8: 26775.25 | Z8: 26775.25 | AA8: 35654.3 | AB8: 58677.94
A9: 1 | C9: 단기금융자산 | E9: 3975.43 | F9: 3975.43 | G9: 2010 | H9: 2010 | I9: 2015.2 | J9: 2013.54 | K9: 2013.54 | L9: 2019.17 | M9: 2011.56 | N9: 2010 | O9: 2011.53 | P9: 2011.53 | Q9: 2011.6 | R9: 2010 | S9: 2010 | T9: 11.75 | U9: 11.75 | V9: 10 | W9: 4996.7 | X9: 16217.23 | Y9: 26775.25 | Z9: 26775.25 | AA9: 35654.3 | AB9: 58677.94
A10: 1 | C10: 매출채권및기타채권 | E10: 32200.79 | F10: 32200.79 | G10: 56949.79 | H10: 43764.56 | I10: 30744.95 | J10: 29976.11 | K10: 29976.11 | L10: 39667.71 | M10: 39739.61 | N10: 28237.24 | O10: 29868.82 | P10: 29868.82 | Q10: 48163.6 | R10: 35810.35 | S10: 23892.82 | T10: 51576.69 | U10: 51576.69 | V10: 61521.1 | W10: 25806.6 | X10: 16031.6 | Y10: 38555.76 | Z10: 38555.76 | AA10: 24497.43 | AB10: 26230.92
A11: 1 | C11: 계약자산 | E11: 1962.36 | F11: 1962.36 | G11: 1165.39 | H11: 4726.92 | I11: 5004.79 | J11: 391.95 | K11: 391.95 | L11: 847.94 | M11: 406.02 | N11: 0 | O11: 190.13 | P11: 190.13 | Q11: 193.98 | R11: 192.44 | S11: 192.44 | T11: 5177.82 | U11: 5177.82 | V11: 192.44 | W11: 3878.74 | X11: 0
A12: 1 | C12: 기타유동자산 | E12: 10619.74 | F12: 10619.74 | G12: 7458.66 | H12: 5760.64 | I12: 6019.22 | J12: 5232.07 | K12: 5232.07 | L12: 5726.46 | M12: 3762.84 | N12: 6340.32 | O12: 6147.61 | P12: 6147.61 | Q12: 6158.9 | R12: 8248.57 | S12: 13467.6 | T12: 11970.72 | U12: 11970.72 | V12: 11509.09 | W12: 8875.87 | X12: 7883.43 | Y12: 12008.7 | Z12: 12008.7 | AA12: 11523.03 | AB12: 13635.84
A13: 1 | C13: 당기법인세자산(선급법인세) | E13: 20.99 | F13: 20.99 | G13: 8.31 | H13: 7.1 | I13: 8.26 | J13: 10.08 | K13: 10.08 | L13: 11.04 | M13: 1.95 | N13: 85.61 | O13: 3.98 | P13: 3.98 | Q13: 5.09 | R13: 2.2 | S13: 7.18 | T13: 68.65 | U13: 68.65 | V13: 69.58 | W13: 0.02 | X13: 0.03 | Y13: 0.05 | Z13: 0.05 | AA13: 0.06 | AB13: 0.02
A14: 1 | C14: 재고자산 | E14: 112637.3 | F14: 112637.3 | G14: 70580.53 | H14: 76036.19 | I14: 83963.14 | J14: 69668.6 | K14: 69668.6 | L14: 71409.88 | M14: 47616.81 | N14: 48789.74 | O14: 36070.27 | P14: 36070.27 | Q14: 37627.96 | R14: 40117.5 | S14: 40680.81 | T14: 31293.87 | U14: 31293.87 | V14: 34266.17 | W14: 33534.54 | X14: 36324.12 | Y14: 31650.95 | Z14: 31650.95 | AA14: 36259.16 | AB14: 34209.31
A15: 1 | C15: 매각예정비유동자산및처분자산 | E15: 0 | F15: 0 | J15: 0 | K15: 0 | AB15: 986.25
A16: 1 | C16: 비유동자산 | E16: 370904.7 | F16: 370904.7 | G16: 391461.51 | H16: 409624.06 | I16: 397881.39 | J16: 397024.86 | K16: 397024.86 | L16: 401360.12 | M16: 403480.08 | N16: 418077.89 | O16: 418498.12 | P16: 418498.12 | Q16: 419735.43 | R16: 427112.82 | S16: 430930.39 | T16: 441235.63 | U16: 441235.63 | V16: 447906.82 | W16: 460482.26 | X16: 467095.3 | Y16: 473719.16 | Z16: 473719.16 | AA16: 476315.05 | AB16: 482599.75
A17: 1 | C17: 장기매출채권및기타채권 | E17: 872.57 | F17: 872.57 | G17: 861.53 | H17: 542.56 | I17: 693.24 | J17: 838.04 | K17: 838.04 | L17: 1218.02 | M17: 775.8 | N17: 2377.67 | O17: 1700.85 | P17: 1700.85 | Q17: 1906.73 | R17: 1472.64 | S17: 1353.7 | T17: 1147.73 | U17: 1147.73 | V17: 1178.58 | W17: 14525.28 | X17: 15549.92 | Y17: 19687.52 | Z17: 19687.52 | AA17: 20801.3 | AB17: 21136.61
A18: 1 | C18: 장기금융자산 | E18: 8038.64 | F18: 8038.64 | G18: 8705.57 | H18: 27454.11 | I18: 10643.35 | J18: 9655.03 | K18: 9655.03 | L18: 14891.38 | M18: 16192.66 | N18: 15491 | O18: 15465.86 | P18: 15465.86 | Q18: 15318.81 | R18: 21576.81 | S18: 20500.33 | T18: 19887.19 | U18: 19887.19 | V18: 21519.9 | W18: 22558.18 | X18: 29794.03 | Y18: 30198.26 | Z18: 30198.26 | AA18: 31786.32 | AB18: 36464.26
A19: 1 | C19: 투자자산 | E19: 8038.64 | F19: 8038.64 | G19: 8705.57 | H19: 27454.11 | I19: 10643.35 | J19: 9655.03 | K19: 9655.03 | L19: 14891.38 | M19: 16192.66 | N19: 15491 | O19: 15465.86 | P19: 15465.86 | Q19: 15318.81 | R19: 21576.81 | S19: 20500.33 | T19: 19887.19 | U19: 19887.19 | V19: 21519.9 | W19: 22558.18 | X19: 29794.03 | Y19: 30198.26 | Z19: 30198.26 | AA19: 31786.32 | AB19: 36464.26
A20: 1 | C20: 종속기업및관계기업투자 | E20: 0 | F20: 0 | J20: 0 | K20: 0
A21: 1 | C21: 유형자산 | E21: 339118.58 | F21: 339118.58 | G21: 357299.42 | H21: 359959.38 | I21: 365692.01 | J21: 366038.15 | K21: 366038.15 | L21: 363344.23 | M21: 365127.41 | N21: 378722.38 | O21: 377377.93 | P21: 377377.93 | Q21: 378946.66 | R21: 379986.41 | S21: 383107.34 | T21: 393056.78 | U21: 393056.78 | V21: 392782.08 | W21: 391661.56 | X21: 391418.12 | Y21: 384127.19 | Z21: 384127.19 | AA21: 384477.73 | AB21: 387603.68
A22: 1 | C22: 사용권자산 | E22: 4220.09 | F22: 4220.09 | G22: 4041.95 | H22: 4569.46 | I22: 4239.45 | J22: 4060.19 | K22: 4060.19 | L22: 3904.97 | M22: 4054.65 | N22: 4197.24 | O22: 4046.92 | P22: 4046.92 | Q22: 3755.16 | R22: 3446.25 | S22: 3155.02 | T22: 2849.77 | U22: 2849.77 | V22: 9282.09 | W22: 8737.65 | X22: 8130.05 | Y22: 8009.74 | Z22: 8009.74 | AA22: 7357.28 | AB22: 6710.03
A23: 1 | C23: 기타비유동자산 | E23: 4220.09 | F23: 4220.09 | G23: 4041.95 | H23: 4569.46 | I23: 4239.45 | J23: 4060.19 | K23: 4060.19 | L23: 3904.97 | M23: 4054.65 | N23: 4197.24 | O23: 4046.92 | P23: 4046.92 | Q23: 3755.16 | R23: 3446.25 | S23: 3155.02 | T23: 2849.77 | U23: 2849.77 | V23: 9282.09 | W23: 8737.65 | X23: 8130.05 | Y23: 8009.74 | Z23: 8009.74 | AA23: 7357.28 | AB23: 6710.03
A24: 1 | C24: 무형자산 | E24: 12903.86 | F24: 12903.86 | G24: 12881.58 | H24: 12864.7 | I24: 13254.99 | J24: 13260.69 | K24: 13260.69 | L24: 13240.65 | M24: 13612.61 | N24: 13606.5 | O24: 13583.04 | P24: 13583.04 | Q24: 13565.09 | R24: 13647.45 | S24: 13636.69 | T24: 13619.33 | U24: 13619.33 | V24: 13606.87 | W24: 13594.64 | X24: 13582.88 | Y24: 13571.13 | Z24: 13571.13 | AA24: 13568.75 | AB24: 13565.79
A25: 1 | C25: 이연법인세자산 | E25: 5750.95 | F25: 5750.95 | G25: 7671.46 | H25: 4233.84 | I25: 3358.35 | J25: 3172.76 | K25: 3172.76 | L25: 4760.87 | M25: 3716.96 | N25: 3683.09 | O25: 6323.53 | P25: 6323.53 | Q25: 6242.98 | R25: 6983.25 | S25: 9177.31 | T25: 10674.83 | U25: 10674.83 | V25: 9537.3 | W25: 9404.96 | X25: 8620.29 | Y25: 9956.04 | Z25: 9956.04 | AA25: 10154.37 | AB25: 8950.08
A26: 1 | C26: 자산총계 | E26: 570404.3 | F26: 570404.3 | G26: 570460.24 | H26: 555082.82 | I26: 557163.61 | J26: 551849.17 | K26: 551849.17 | L26: 551535.47 | M26: 534554.72 | N26: 544559.82 | O26: 544018.92 | P26: 544018.92 | Q26: 583690.43 | R26: 559779.61 | S26: 591129.42 | T26: 620877.55 | U26: 620877.55 | V26: 630064.89 | W26: 627133.95 | X26: 641493.74 | Y26: 637763.65 | Z26: 637763.65 | AA26: 653797.2 | AB26: 659808.93
A27: 1 | C27: 유동부채 | E27: 241375.17 | F27: 241375.17 | G27: 218630.7 | H27: 227674.89 | I27: 266883.85 | J27: 245938.22 | K27: 245938.22 | L27: 304791.31 | M27: 283822.14 | N27: 265825.43 | O27: 247450.77 | P27: 247450.77 | Q27: 279334.83 | R27: 254465.61 | S27: 297598.92 | T27: 307570.48 | U27: 307570.48 | V27: 310609.46 | W27: 303540.87 | X27: 227355.89 | Y27: 200224.65 | Z27: 200224.65 | AA27: 220237.9 | AB27: 205546.29
A28: 1 | C28: 매입채무및기타채무 | E28: 56550.61 | F28: 56550.61 | G28: 59034.34 | H28: 44457.98 | I28: 37900.98 | J28: 29354.6 | K28: 29354.6 | L28: 48683.56 | M28: 43355.95 | N28: 51938.46 | O28: 41683.14 | P28: 41683.14 | Q28: 76014.84 | R28: 55300.82 | S28: 48495.62 | T28: 59526.84 | U28: 59526.84 | V28: 69662.71 | W28: 63036.54 | X28: 54729.31 | Y28: 52099.38 | Z28: 52099.38 | AA28: 71940.43 | AB28: 53203.34
A29: 1 | C29: 계약부채 | E29: 39485.15 | F29: 39485.15 | G29: 17379.57 | H29: 12905.83 | I29: 11004.26 | J29: 18123.98 | K29: 18123.98 | L29: 11773.52 | M29: 4814.15 | N29: 4759.15 | O29: 3172.67 | P29: 3172.67 | Q29: 12619.59 | R29: 13529.6 | S29: 15959.13 | T29: 13291.26 | U29: 13291.26 | V29: 5643.76 | W29: 5175 | X29: 17894.37 | Y29: 5175 | Z29: 5175 | AA29: 725.22 | AB29: 4286.67
A30: 1 | C30: 당기법인세부채(미지급법인세) | E30: 12208.71 | F30: 12208.71 | G30: 6629.09 | H30: 73.5 | I30: 602.61 | J30: 673.26 | K30: 673.26 | L30: 368.95 | M30: 3407.76 | N30: 3059.1 | O30: 9241.06 | P30: 9241.06 | Q30: 5777.9 | R30: 5913.41 | S30: 4043.35 | T30: 8325.35 | U30: 8325.35 | V30: 7653.73 | W30: 5743.46 | X30: 2642.92 | Y30: 8488.24 | Z30: 8488.24 | AA30: 9461.33 | AB30: 10603.22
A31: 1 | C31: 단기차입금 | E31: 36740.57 | F31: 36740.57 | G31: 54740.57 | H31: 53740.57 | I31: 57853.57 | J31: 54476.57 | K31: 54476.57 | L31: 56466.57 | M31: 77766.57 | N31: 83727.51 | O31: 88076 | P31: 88076 | Q31: 120076 | R31: 115076 | S31: 136476 | T31: 136476 | U31: 136476 | V31: 136476 | W31: 138461 | X31: 72261 | Y31: 47801 | Z31: 47801 | AA31: 132331 | AB31: 45801
A32: 1 | C32: 유동리스부채 | E32: 1419.51 | F32: 1419.51 | G32: 1212.16 | H32: 1044.11 | I32: 758.47 | J32: 751.68 | K32: 751.68 | L32: 765.63 | M32: 909.29 | N32: 1207.48 | O32: 1269.44 | P32: 1269.44 | Q32: 1561.82 | R32: 1306.15 | S32: 1039.39 | T32: 737.48 | U32: 737.48 | V32: 2861.5 | W32: 2770.68 | X32: 2613.53 | Y32: 2710.97 | Z32: 2710.97 | AA32: 2692.04 | AB32: 2674.43
... A56: 1 | C56: 이자발생자산 | E56: 49682.81 | F56: 49682.81 | G56: 51105.27 | H56: 42230.55 | I56: 43802.32 | J56: 58805.76 | K56: 58805.76 | L56: 46997.67 | M56: 55324.39 | N56: 58069.36 | O56: 68229.05 | P56: 68229.05 | Q56: 87124.29 | R56: 69872.54 | S56: 102458.5 | T56: 99441.36 | U56: 99441.36 | V56: 96119.59 | W56: 117114.1 | X56: 143953.29 | Y56: 112027.31 | Z56: 112027.31 | AA56: 136988.8 | AB56: 138611.11
A57: 1 | C57: 사채 | E57: 15000 | F57: 15000 | G57: 15000
A58: 1 | C58: 유동성장기부채 | E58: 91817.05 | F58: 91817.05 | G58: 76287.64 | H58: 110801.43 | I58: 151129.43 | J58: 138129.43 | K58: 138129.43 | L58: 181137.84 | M58: 147300.49 | N58: 114312.04 | O58: 100526.04 | P58: 100526.04 | Q58: 60880.12 | R58: 60879.96 | S58: 88046.64 | T58: 86330 | U58: 86330 | V58: 86030 | W58: 85730 | X58: 72630 | Y58: 79580 | Z58: 79580 | AB58: 85480
A59: 1 | C59: 투자부동산 | Y59: 8169.29 | Z59: 8169.29 | AA59: 8169.29 | AB59: 8169.29
A60: 1 | C60: 단기금융부채(face) | AA60: 132331
A61: 1 | C61: 장기금융부채(face) | AA61: 119500
A62: 1 | C62: 매출액(수익) | E62: 81901.42 | G62: 139922.87 | H62: 88872.43 | I62: 79905 | J62: 101190.53 | K62: 409890.83 | L62: 71702.28 | M62: 120491.49 | N62: 81986.97 | O62: 110615.72 | P62: 384796.46 | Q62: 86078.31 | R62: 80837.89 | S62: 74151.66 | T62: 111308.71 | U62: 352376.57 | V62: 98495.97 | W62: 98171.23 | X62: 90367.62 | Y62: 115651.44 | Z62: 402686.26 | AA62: 87243.09 | AB62: 93498.44
A63: 1 | C63: 매출원가 | E63: 86831.55 | G63: 141186.13 | H63: 70635.4 | I63: 69460.77 | J63: 81216.71 | K63: 362499.01 | L63: 72913.55 | M63: 93810.07 | N63: 82334.88 | O63: 79153.4 | P63: 328211.9 | Q63: 76060.99 | R63: 67462.41 | S63: 68006.93 | T63: 82318.69 | U63: 293849.02 | V63: 74721.46 | W63: 83099.11 | X63: 72766.24 | Y63: 74138.25 | Z63: 304725.06 | AA63: 67090.32 | AB63: 67311.53
...

Sheet BS별도
B1: (백만원) | C1: 이름: BS별도H | E1: 4Q21 | F1: 2021 | G1: 1Q22 | H1: 2Q22 | I1: 3Q22 | J1: 4Q22 | K1: 2022 | L1: 1Q23 | M1: 2Q23 | N1: 3Q23 | O1: 4Q23 | P1: 2023 | Q1: 1Q24 | R1: 2Q24 | S1: 3Q24 | T1: 4Q24 | U1: 2024 | V1: 1Q25 | W1: 2Q25 | X1: 3Q25 | Y1: 4Q25 | Z1: 2025 | AA1: 1Q26 | AB1: 2Q26 | AC1: 3Q26 | AD1: 4Q26 | AE1: 2026 | AF1: 1Q27 | AG1: 2Q27 | AH1: 3Q27 | AI1: 4Q27 | AJ1: 2027 | AK1: 1Q28 | AL1: 2Q28 | AM1: 3Q28 | AN1: 4Q28 | AO1: 2028
B2: 별도 | D2: fin json(kship_fin.py)
B3: 세진중공업(별) | C3: UPDATE: 26-10-14 | E3: 1 | F3: 2 | G3: 3 | H3: 4 | I3: 5 | J3: 6 | K3: 7 | L3: 8 | M3: 9 | N3: 10 | O3: 11 | P3: 12 | Q3: 13 | R3: 14 | S3: 15 | T3: 16 | U3: 17 | V3: 18 | W3: 19 | X3: 20 | Y3: 21 | Z3: 22 | AA3: 23 | AB3: 24 | AC3: 25 | AD3: 26 | AE3: 27 | AF3: 28 | AG3: 29 | AH3: 30 | AI3: 31 | AJ3: 32 | AK3: 33 | AL3: 34 | AM3: 35 | AN3: 36 | AO3: 37
B4: Account Code | C4: AccountNAME | E4: 2021.12 | F4: 2021.12A | G4: 2022.03 | H4: 2022.06 | I4: 2022.09 | J4: 2022.12 | K4: 2022.12A | L4: 2023.03 | M4: 2023.06 | N4: 2023.09 | O4: 2023.12 | P4: 2023.12A | Q4: 2024.03 | R4: 2024.06 | S4: 2024.09 | T4: 2024.12 | U4: 2024.12A | V4: 2025.03 | W4: 2025.06 | X4: 2025.09 | Y4: 2025.12 | Z4: 2025.12A | AA4: 2026.03 | AB4: 2026.06 | AC4: 2026.09 | AD4: 2026.12 | AE4: 2026.12A | AF4: 2027.03 | AG4: 2027.06 | AH4: 2027.09 | AI4: 2027.12 | AJ4: 2027.12A | AK4: 2028.03 | AL4: 2028.06 | AM4: 2028.09 | AN4: 2028.12 | AO4: 2028.12A
A5: 1 | C5: 유동자산 | E5: 165200.01 | F5: 165200.01 | G5: 143519.33 | H5: 114213.28 | I5: 127566.01 | J5: 123243.37 | K5: 123243.37 | L5: 119879.41 | M5: 101631.4 | N5: 97334.66 | O5: 97441.87 | P5: 97441.87 | Q5: 130312.84 | R5: 97267.01 | S5: 125377.62 | T5: 142029.44 | U5: 142029.44 | V5: 144931.6 | W5: 119425.03 | X5: 123221.59 | Y5: 108478.1 | Z5: 108478.1 | AA5: 113722.91 | AB5: 109350.3
A6: 1 | C6: 현금및현금성자산 | E6: 26602.1 | F6: 26602.1 | G6: 29348.29 | H6: 8217.24 | I6: 24468.91 | J6: 40107.62 | K6: 40107.62 | L6: 18265.36 | M6: 22638.06 | N6: 22665.16 | O6: 32509.25 | P6: 32509.25 | Q6: 46702.99 | R6: 21139.37 | S6: 52544.38 | T6: 44858.86 | U6: 44858.86 | V6: 43021.8 | W6: 57089.02 | X6: 67680.92 | Y6: 23475.75 | Z6: 23475.75 | AA6: 39558.69 | AB6: 16154.31
A7: 1 | C7: 단기금융상품 | E7: 10 | F7: 10 | G7: 10 | H7: 10 | I7: 10 | J7: 10 | K7: 10 | L7: 10 | M7: 10 | N7: 10 | O7: 10 | P7: 10 | Q7: 10 | R7: 10 | S7: 10 | T7: 10 | U7: 10 | V7: 10 | W7: 4067.84 | X7: 8947.75 | Y7: 14454.86 | Z7: 14454.86 | AA7: 17670.96 | AB7: 31566.23
A8: 1 | C8: 단기금융자산 | E8: 10 | F8: 10 | G8: 10 | H8: 10 | I8: 10 | J8: 10 | K8: 10 | L8: 10 | M8: 10 | N8: 10 | O8: 10 | P8: 10 | Q8: 10 | R8: 10 | S8: 10 | T8: 10 | U8: 10 | V8: 10 | W8: 4067.84 | X8: 8947.75 | Y8: 14454.86 | Z8: 14454.86 | AA8: 17670.96 | AB8: 31566.23
A9: 1 | C9: 매출채권및기타채권 | E9: 24150.25 | F9: 24150.25 | G9: 47455.32 | H9: 35159.73 | I9: 24935.83 | J9: 17706.17 | K9: 17706.17 | L9: 31711.15 | M9: 32123.94 | N9: 23950.16 | O9: 26540.42 | P9: 26540.42 | Q9: 45175.78 | R9: 34965.76 | S9: 24869.66 | T9: 52505.62 | U9: 52505.62 | V9: 62720.19 | W9: 17846.37 | X9: 8145.31 | Y9: 32049.42 | Z9: 32049.42 | AA9: 18662.66 | AB9: 20989.68
A10: 1 | C10: 기타유동자산 | E10: 9742.53 | F10: 9742.53 | G10: 6138.62 | H10: 3880.19 | I10: 5178.13 | J10: 4672.22 | K10: 4672.22 | L10: 5129.36 | M10: 2434.47 | N10: 4756.07 | O10: 5047.11 | P10: 5047.11 | Q10: 4613.39 | R10: 6412.04 | S10: 11651.69 | T10: 10885.88 | U10: 10885.88 | V10: 10215.86 | W10: 7806.12 | X10: 6725.38 | Y10: 10790.66 | Z10: 10790.66 | AA10: 10429 | AB10: 12746.58
A11: 1 | C11: 재고자산 | E11: 104695.13 | F11: 104695.13 | G11: 60567.09 | H11: 63206.48 | I11: 69233.49 | J11: 60747.36 | K11: 60747.36 | L11: 64318.85 | M11: 44424.92 | N11: 45953.28 | O11: 33335.09 | P11: 33335.09 | Q11: 33810.68 | R11: 34739.84 | S11: 36301.89 | T11: 28783.7 | U11: 28783.7 | V11: 28963.75 | W11: 28736.95 | X11: 31722.23 | Y11: 27707.41 | Z11: 27707.41 | AA11: 27401.61 | AB11: 27893.49
A12: 1 | C12: 매각예정비유동자산및처분자산 | E12: 0 | F12: 0
A13: 1 | C13: 비유동자산 | E13: 279197.55 | F13: 279197.55 | G13: 283040.06 | H13: 298506.75 | I13: 285727.23 | J13: 288633.38 | K13: 288633.38 | L13: 293088.27 | M13: 294520.11 | N13: 325926.65 | O13: 326818.92 | P13: 326818.92 | Q13: 328653.83 | R13: 336861.54 | S13: 341425.68 | T13: 347650.38 | U13: 347650.38 | V13: 354074.84 | W13: 375608.53 | X13: 383424.16 | Y13: 383298.96 | Z13: 383298.96 | AA13: 386049.89 | AB13: 391199.53
A14: 1 | C14: 장기매출채권및기타채권 | E14: 7797.71 | F14: 7797.71 | G14: 7858.32 | H14: 7981.53 | I14: 8293.88 | J14: 11678.56 | K14: 11678.56 | L14: 12271.04 | M14: 12190.47 | N14: 12598.64 | O14: 12335.07 | P14: 12335.07 | Q14: 12677.42 | R14: 12536.59 | S14: 12638.61 | T14: 10871.28 | U14: 10871.28 | V14: 10981.25 | W14: 33468.62 | X14: 36358.4 | Y14: 41376.38 | Z14: 41376.38 | AA14: 43021.13 | AB14: 44167.59
A15: 1 | C15: 장기금융자산 | E15: 49317.93 | F15: 49317.93 | G15: 1192.27 | H15: 18784.44 | I15: 1282.27 | J15: 1107.71 | K15: 1107.71 | L15: 6152.71 | M15: 6197.71 | N15: 6242.71 | O15: 6287.71 | P15: 6287.71 | Q15: 6332.71 | R15: 12922.74 | S15: 12506.83 | T15: 12699.37 | U15: 12699.37 | V15: 13933.59 | W15: 14635.64 | X15: 21571.9 | Y15: 22279.97 | Z15: 22279.97 | AA15: 23325.74 | AB15: 26217.39
A16: 1 | C16: 투자자산 | E16: 50465.2 | F16: 50465.2 | G16: 50550.2 | H16: 68142.37 | I16: 50640.2 | J16: 50465.64 | K16: 50465.64 | L16: 55510.64 | M16: 55555.64 | N16: 51874.14 | O16: 51919.14 | P16: 51919.14 | Q16: 51964.14 | R16: 58554.17 | S16: 58138.26 | T16: 58330.8 | U16: 58330.8 | V16: 59565.02 | W16: 60267.07 | X16: 67203.33 | Y16: 61979.47 | Z16: 61979.47 | AA16: 63025.24 | AB16: 64660.74
A17: 1 | C17: 종속기업및관계기업투자 | E17: 1147.27 | F17: 1147.27 | G17: 49357.93 | H17: 49357.93 | I17: 49357.93 | J17: 49357.93 | K17: 49357.93 | L17: 49357.93 | M17: 49357.93 | N17: 45631.43 | O17: 45631.43 | P17: 45631.43 | Q17: 45631.43 | R17: 45631.43 | S17: 45631.43 | T17: 45631.43 | U17: 45631.43 | V17: 45631.43 | W17: 45631.43 | X17: 45631.43 | Y17: 39699.5 | Z17: 39699.5 | AA17: 39699.5 | AB17: 38443.35
A18: 1 | C18: 유형자산 | E18: 203035.14 | F18: 203035.14 | G18: 205002.55 | H18: 205894.73 | I18: 210957.89 | J18: 211082.54 | K18: 211082.54 | L18: 211900.86 | M18: 213976.47 | N18: 248520.66 | O18: 247342.19 | P18: 247342.19 | Q18: 249085.24 | R18: 250318.7 | S18: 253422.93 | T18: 261508.52 | U18: 261508.52 | V18: 261083.92 | W18: 260216.65 | X18: 259634.69 | Y18: 260543.87 | Z18: 260543.87 | AA18: 260879.02 | AB18: 265078.54
A19: 1 | C19: 사용권자산 | E19: 4144.21 | F19: 4144.21 | G19: 3978.54 | H19: 4300.74 | I19: 4135.61 | J19: 3970.48 | K19: 3970.48 | L19: 3813.35 | M19: 3972.75 | N19: 4125.06 | O19: 3984.47 | P19: 3984.47 | Q19: 3696.54 | R19: 3397.48 | S19: 3101.02 | T19: 2804.56 | U19: 2804.56 | V19: 9341.51 | W19: 8705.27 | X19: 8103.13 | Y19: 7987.87 | Z19: 7987.87 | AA19: 7340.47 | AB19: 6697.25
A20: 1 | C20: 기타비유동자산 | E20: 4144.21 | F20: 4144.21 | G20: 3978.54 | H20: 4300.74 | I20: 4135.61 | J20: 3970.48 | K20: 3970.48 | L20: 3813.35 | M20: 3972.75 | N20: 4125.06 | O20: 3984.47 | P20: 3984.47 | Q20: 3696.54 | R20: 3397.48 | S20: 3101.02 | T20: 2804.56 | U20: 2804.56 | V20: 9341.51 | W20: 8705.27 | X20: 8103.13 | Y20: 7987.87 | Z20: 7987.87 | AA20: 7340.47 | AB20: 6697.25
A21: 1 | C21: 무형자산 | E21: 4418.66 | F21: 4418.66 | G21: 4418.66 | H21: 4418.66 | I21: 4831.51 | J21: 4831.51 | K21: 4831.51 | L21: 4831.51 | M21: 5225.51 | N21: 5234.17 | O21: 5234.17 | P21: 5234.17 | Q21: 5234.17 | R21: 5334.17 | S21: 5334.17 | T21: 5334.17 | U21: 5334.17 | V21: 5334.17 | W21: 5334.17 | X21: 5334.17 | Y21: 5334.17 | Z21: 5334.17 | AA21: 5334.17 | AB21: 5334.17
A22: 1 | C22: 투자부동산 | E22: 3585.67 | F22: 3585.67 | G22: 3560.34 | H22: 3534.88 | I22: 3509.78 | J22: 3484.69 | K22: 3484.69 | L22: 0 | N22: 0 | O22: 0 | P22: 0 | T22: 0 | U22: 0
A23: 1 | C23: 이연법인세자산 | E23: 5750.95 | F23: 5750.95 | G23: 7671.46 | H23: 4233.84 | I23: 3358.35 | J23: 3119.97 | K23: 3119.97 | L23: 4760.87 | M23: 3599.28 | N23: 3573.97 | O23: 6003.87 | P23: 6003.87 | Q23: 5996.32 | R23: 6720.43 | S23: 8790.68 | T23: 8801.04 | U23: 8801.04 | V23: 7768.97 | W23: 7616.74 | X23: 6790.43 | Y23: 6077.2 | Z23: 6077.2 | AA23: 6449.86 | AB23: 5261.24
A24: 1 | C24: 자산총계 | E24: 444397.56 | F24: 444397.56 | G24: 426559.39 | H24: 412720.03 | I24: 413293.23 | J24: 411876.75 | K24: 411876.75 | L24: 412967.68 | M24: 396151.51 | N24: 423261.31 | O24: 424260.79 | P24: 424260.79 | Q24: 458966.67 | R24: 434128.55 | S24: 466803.3 | T24: 489679.81 | U24: 489679.81 | V24: 499006.44 | W24: 495033.56 | X24: 506645.75 | Y24: 491777.06 | Z24: 491777.06 | AA24: 499772.8 | AB24: 500549.83
A25: 1 | C25: 유동부채 | E25: 171104.83 | F25: 171104.83 | G25: 138660.43 | H25: 149224.55 | I25: 186457.53 | J25: 168279.92 | K25: 168279.92 | L25: 227336.4 | M25: 207674.24 | N25: 205888.89 | O25: 191700.36 | P25: 191700.36 | Q25: 226620.81 | R25: 197790.18 | S25: 249548.4 | T25: 256664.27 | U25: 256664.27 | V25: 259998.17 | W25: 252224.9 | X25: 178473.16 | Y25: 145261 | Z25: 145261 | AA25: 155225.17 | AB25: 142309.05
A26: 1 | C26: 매입채무및기타채무 | E26: 48565.05 | F26: 48565.05 | G26: 49610.72 | H26: 37393.52 | I26: 32826.86 | J26: 25301.53 | K26: 25301.53 | L26: 44407.8 | M26: 40264.41 | N26: 48672.64 | O26: 42860.32 | P26: 42860.32 | Q26: 71650.34 | R26: 49498.56 | S26: 48511.29 | T26: 54393.99 | U26: 54393.99 | V26: 63079.63 | W26: 56293.11 | X26: 51400.72 | Y26: 50711.29 | Z26: 50711.29 | AA26: 66329.76 | AB26: 51702.87
A27: 1 | C27: 계약부채 | E27: 37018.85 | F27: 37018.85 | G27: 14719.34 | H27: 10109.8 | I27: 10745.11 | J27: 16037.88 | K27: 16037.88 | L27: 11514.37 | M27: 4555 | N27: 4500 | O27: 2702.96 | P27: 2702.96 | Q27: 12149.88 | R27: 13059.89 | S27: 15489.42 | T27: 13291.26 | U27: 13291.26 | V27: 5643.76 | W27: 5175 | X27: 17894.37 | Y27: 5175 | Z27: 5175 | AA27: 725.22 | AB27: 4286.67
A28: 1 | C28: 당기법인세부채(미지급법인세) | E28: 11763.79 | F28: 11763.79 | G28: 6380.03 | H28: 0 | I28: 0 | J28: 447.34 | K28: 447.34 | L28: 225.74 | M28: 3333.31 | N28: 3059.1 | O28: 9137.34 | P28: 9137.34 | Q28: 5640.93 | R28: 3441.3 | S28: 1291.13 | T28: 5325.3 | U28: 5325.3 | V28: 5853.3 | W28: 5458.02 | X28: 2154.45 | Y28: 7833.21 | Z28: 7833.21 | AA28: 8319.27 | AB28: 7682.01
A29: 1 | C29: 단기차입금 | E29: 69700 | F29: 69700 | G29: 64300 | H29: 96900 | I29: 138013 | J29: 121600 | K29: 121600 | L29: 166000 | M29: 153600 | N29: 143600 | O29: 133600 | P29: 133600 | Q29: 133600 | R29: 128600 | S29: 181600 | T29: 181300 | U29: 181300 | V29: 181000 | W29: 180700 | X29: 101400 | Y29: 76170 | Z29: 76170 | AA29: 75120 | AB29: 74070
A30: 1 | C30: 단기금융부채(face) | E30: 69700 | F30: 69700 | G30: 64300 | H30: 96900 | I30: 138013 | J30: 121600 | K30: 121600 | L30: 166000 | M30: 153600 | N30: 143600 | O30: 133600 | P30: 133600 | Q30: 133600 | R30: 128600 | S30: 181600 | T30: 181300 | U30: 181300 | V30: 181000 | W30: 180700 | X30: 101400 | Y30: 76170 | Z30: 76170 | AA30: 75120 | AB30: 74070
A31: 1 | C31: 유동리스부채 | E31: 1362.34 | F31: 1362.34 | G31: 987.6 | H31: 826.17 | I31: 724.01 | J31: 726.65 | K31: 726.65 | L31: 725.99 | M31: 871.39 | N31: 1174.68 | O31: 1242.64 | P31: 1242.64 | Q31: 1534.48 | R31: 1284.08 | S31: 1009.46 | T31: 711.87 | U31: 711.87 | V31: 2934.66 | W31: 2751.07 | X31: 2593.56 | Y31: 2691.68 | Z31: 2691.68 | AA31: 2674.43 | AB31: 2659.6
A32: 1 | C32: 리스부채 | E32: 4028.67 | F32: 4028.67 | G32: 3543.78 | H32: 3537.8 | I32: 3256.92 | J32: 3079.68 | K32: 3079.68 | L32: 2914.71 | M32: 3020.66 | N32: 3191.44 | O32: 3043.05 | P32: 3043.05 | Q32: 2750.35 | R32: 2439.74 | S32: 2129.59 | T32: 1816.76 | U32: 1816.76 | V32: 8381.99 | W32: 7771.79 | X32: 7187.38 | Y32: 7024.33 | Z32: 7024.33 | AA32: 6396.24 | AB32: 5767.33
A33: 1 | C33: 단기금융부채 | E33: 2006.74 | F33: 2006.74 | G33: 987.6 | H33: 826.17 | I33: 724.01 | J33: 726.65 | K33: 726.65 | L33: 725.99 | M33: 871.39 | N33: 1174.68 | O33: 1242.64 | P33: 1242.64 | Q33: 1534.48 | R33: 1284.08 | S33: 1009.46 | T33: 711.87 | U33: 711.87 | V33: 2934.66 | W33: 2751.07 | X33: 2593.56 | Y33: 2691.68 | Z33: 2691.68 | AA33: 2674.43 | AB33: 2659.6
A34: 1 | C34: 기타유동금융부채 | E34: 644.4 | F34: 644.4
A35: 1 | C35: 단기충당부채 | E35: 2050.39 | F35: 2050.39 | G35: 2256.2 | H35: 3073.46 | I35: 3081.32 | J35: 3079.97 | K35: 3079.97 | L35: 3250.86 | M35: 4033.88 | N35: 4206.11 | O35: 1759.64 | P35: 1759.64 | Q35: 1686.62 | R35: 1722.25 | S35: 1605.85 | T35: 1487.93 | U35: 1487.93 | V35: 1378.65 | W35: 1774.4 | X35: 1746.35 | Y35: 1679.11 | Z35: 1679.11 | AA35: 1422.41 | AB35: 1523.62
A36: 1 | C36: 비유동부채 | E36: 113033.85 | F36: 113033.85 | G36: 142541.09 | H36: 106995.49 | I36: 67442.92 | J36: 78086.1 | K36: 78086.1 | L36: 33933.63 | M36: 22873.12 | N36: 49205.17 | O36: 50498.85 | P36: 50498.85 | Q36: 49434.08 | R36: 49425.45 | S36: 33628.48 | T36: 35953.35 | U36: 35953.35 | V36: 40109.34 | W36: 38908.18 | X36: 116496 | Y36: 116031.72 | Z36: 116031.72 | AA36: 116018.9 | AB36: 115760.62
A37: 1 | C37: 장기차입금 | E37: 107300 | F37: 107300 | G37: 136700 | H37: 101100 | J37: 73700 | K37: 73700 | L37: 28700 | M37: 17500 | N37: 43900 | O37: 43300 | P37: 43300 | Q37: 42700 | R37: 42100 | S37: 25900 | T37: 30650 | U37: 30650 | V37: 29600 | W37: 28550 | X37: 106500 | Y37: 106200 | Z37: 106200 | AA37: 106200 | AB37: 106200
A38: 1 | C38: 장기금융부채(face) | E38: 107300 | F38: 107300 | G38: 136700 | H38: 101100 | J38: 73700 | K38: 73700 | L38: 28700 | M38: 17500 | N38: 43900 | O38: 43300 | P38: 43300 | Q38: 42700 | R38: 42100 | S38: 25900 | T38: 30650 | U38: 30650 | V38: 29600 | W38: 28550 | X38: 106500 | Y38: 106200 | Z38: 106200 | AA38: 106200 | AB38: 106200
A39: 1 | C39: 비유동리스부채 | E39: 2666.33 | F39: 2666.33 | G39: 2556.18 | H39: 2711.63 | I39: 2532.91 | J39: 2353.03 | K39: 2353.03 | L39: 2188.72 | M39: 2149.27 | N39: 2016.76 | O39: 1800.41 | P39: 1800.41 | Q39: 1215.87 | R39: 1155.66 | S39: 1120.13 | T39: 1104.89 | U39: 1104.89 | V39: 5447.33 | W39: 5020.72 | X39: 4593.82 | Y39: 4332.65 | Z39: 4332.65 | AA39: 3721.81 | AB39: 3107.73
A40: 1 | C40: 장기금융부채 | E40: 2666.33 | F40: 2666.33 | G40: 2556.18 | H40: 2711.63 | I40: 2532.91 | J40: 2353.03 | K40: 2353.03 | L40: 2188.72 | M40: 2149.27 | N40: 2016.76 | O40: 1800.41 | P40: 1800.41 | Q40: 1215.87 | R40: 1155.66 | S40: 1120.13 | T40: 1104.89 | U40: 1104.89 | V40: 5447.33 | W40: 5020.72 | X40: 4593.82 | Y40: 4332.65 | Z40: 4332.65 | AA40: 3721.81 | AB40: 3107.73
...

Sheet subQ
A1: YQ | C1: subQ 분기 서브모델(억원, U=100) | E1: 4Q21 | F1: 2021 | G1: 1Q22 | H1: 2Q22 | I1: 3Q22 | J1: 4Q22 | K1: 2022 | L1: 1Q23 | M1: 2Q23 | N1: 3Q23 | O1: 4Q23 | P1: 2023 | Q1: 1Q24 | R1: 2Q24 | S1: 3Q24 | T1: 4Q24 | U1: 2024 | V1: 1Q25 | W1: 2Q25 | X1: 3Q25 | Y1: 4Q25 | Z1: 2025 | AA1: 1Q26 | AB1: 2Q26 | AC1: 3Q26 | AD1: 4Q26 | AE1: 2026 | AF1: 1Q27 | AG1: 2Q27 | AH1: 3Q27 | AI1: 4Q27 | AJ1: 2027 | AK1: 1Q28 | AL1: 2Q28 | AM1: 3Q28 | AN1: 4Q28 | AO1: 2028
A2: A=이름(key) B=그룹 C=단위 D=FnGuide 계정명(VLOOKUP 키). 확정=VLOOKUP(BS), 추정=변수 가정 참조
E3: 1 | F3: 2 | G3: 3 | H3: 4 | I3: 5 | J3: 6 | K3: 7 | L3: 8 | M3: 9 | N3: 10 | O3: 11 | P3: 12 | Q3: 13 | R3: 14 | S3: 15 | T3: 16 | U3: 17 | V3: 18 | W3: 19 | X3: 20 | Y3: 21 | Z3: 22 | AA3: 23 | AB3: 24 | AC3: 25 | AD3: 26 | AE3: 27 | AF3: 28 | AG3: 29 | AH3: 30 | AI3: 31 | AJ3: 32 | AK3: 33 | AL3: 34 | AM3: 35 | AN3: 36 | AO3: 37
E4: 2021.12 | F4: 2021.12A | G4: 2022.03 | H4: 2022.06 | I4: 2022.09 | J4: 2022.12 | K4: 2022.12A | L4: 2023.03 | M4: 2023.06 | N4: 2023.09 | O4: 2023.12 | P4: 2023.12A | Q4: 2024.03 | R4: 2024.06 | S4: 2024.09 | T4: 2024.12 | U4: 2024.12A | V4: 2025.03 | W4: 2025.06 | X4: 2025.09 | Y4: 2025.12 | Z4: 2025.12A | AA4: 2026.03 | AB4: 2026.06 | AC4: 2026.09 | AD4: 2026.12 | AE4: 2026.12A | AF4: 2027.03 | AG4: 2027.06 | AH4: 2027.09 | AI4: 2027.12 | AJ4: 2027.12A | AK4: 2028.03 | AL4: 2028.06 | AM4: 2028.09 | AN4: 2028.12 | AO4: 2028.12A
A5: 매출액 | B5: 손익 | C5: 억원 | D5: 매출액(수익) | E5: =IFERROR(VLOOKUP($D5,BS연결,MATCH(E$1,BS연결H,0),0)/100,"") | G5: =IFERROR(VLOOKUP($D5,BS연결,MATCH(G$1,BS연결H,0),0)/100,"") | H5: =IFERROR(VLOOKUP($D5,BS연결,MATCH(H$1,BS연결H,0),0)/100,"") | I5: =IFERROR(VLOOKUP($D5,BS연결,MATCH(I$1,BS연결H,0),0)/100,"") | J5: =IFERROR(VLOOKUP($D5,BS연결,MATCH(J$1,BS연결H,0),0)/100,"") | K5: =IFERROR(VLOOKUP($D5,BS연결,MATCH(K$1,BS연결H,0),0)/100,"") | L5: =IFERROR(VLOOKUP($D5,BS연결,MATCH(L$1,BS연결H,0),0)/100,"") | M5: =IFERROR(VLOOKUP($D5,BS연결,MATCH(M$1,BS연결H,0),0)/100,"") | N5: =IFERROR(VLOOKUP($D5,BS연결,MATCH(N$1,BS연결H,0),0)/100,"") | ... AB5: =IFERROR(VLOOKUP($D5,BS연결,MATCH(AB$1,BS연결H,0),0)/100,"") | AC5: =IFERROR(AC37+AC39+AC41,"") | AD5: =IFERROR(AD37+AD39+AD41,"") | AE5: =SUM(AA5:AD5) | AF5: =IFERROR(AF37+AF39+AF41,"") | AG5: =IFERROR(AG37+AG39+AG41,"") | AH5: =IFERROR(AH37+AH39+AH41,"") | AI5: =IFERROR(AI37+AI39+AI41,"") | AJ5: =SUM(AF5:AI5) | AK5: =IFERROR(AK37+AK39+AK41,"") | AL5: =IFERROR(AL37+AL39+AL41,"") | AM5: =IFERROR(AM37+AM39+AM41,"") | AN5: =IFERROR(AN37+AN39+AN41,"") | AO5: =SUM(AK5:AN5)
A6: 매출원가 | B6: 손익 | C6: 억원 | D6: 매출원가 | E6: =IFERROR(VLOOKUP($D6,BS연결,MATCH(E$1,BS연결H,0),0)/100,"") | G6: =IFERROR(VLOOKUP($D6,BS연결,MATCH(G$1,BS연결H,0),0)/100,"") | H6: =IFERROR(VLOOKUP($D6,BS연결,MATCH(H$1,BS연결H,0),0)/100,"") | I6: =IFERROR(VLOOKUP($D6,BS연결,MATCH(I$1,BS연결H,0),0)/100,"") | J6: =IFERROR(VLOOKUP($D6,BS연결,MATCH(J$1,BS연결H,0),0)/100,"") | K6: =IFERROR(VLOOKUP($D6,BS연결,MATCH(K$1,BS연결H,0),0)/100,"") | L6: =IFERROR(VLOOKUP($D6,BS연결,MATCH(L$1,BS연결H,0),0)/100,"") | M6: =IFERROR(VLOOKUP($D6,BS연결,MATCH(M$1,BS연결H,0),0)/100,"") | N6: =IFERROR(VLOOKUP($D6,BS연결,MATCH(N$1,BS연결H,0),0)/100,"") | ... AB6: =IFERROR(VLOOKUP($D6,BS연결,MATCH(AB$1,BS연결H,0),0)/100,"") | AC6: =IFERROR(AC5-AC7,"") | AD6: =IFERROR(AD5-AD7,"") | AE6: =SUM(AA6:AD6) | AF6: =IFERROR(AF5-AF7,"") | AG6: =IFERROR(AG5-AG7,"") | AH6: =IFERROR(AH5-AH7,"") | AI6: =IFERROR(AI5-AI7,"") | AJ6: =SUM(AF6:AI6) | AK6: =IFERROR(AK5-AK7,"") | AL6: =IFERROR(AL5-AL7,"") | AM6: =IFERROR(AM5-AM7,"") | AN6: =IFERROR(AN5-AN7,"") | AO6: =SUM(AK6:AN6)
A7: 매출총이익 | B7: 손익 | C7: 억원 | D7: 매출총이익 | E7: =IFERROR(VLOOKUP($D7,BS연결,MATCH(E$1,BS연결H,0),0)/100,"") | G7: =IFERROR(VLOOKUP($D7,BS연결,MATCH(G$1,BS연결H,0),0)/100,"") | H7: =IFERROR(VLOOKUP($D7,BS연결,MATCH(H$1,BS연결H,0),0)/100,"") | I7: =IFERROR(VLOOKUP($D7,BS연결,MATCH(I$1,BS연결H,0),0)/100,"") | J7: =IFERROR(VLOOKUP($D7,BS연결,MATCH(J$1,BS연결H,0),0)/100,"") | K7: =IFERROR(VLOOKUP($D7,BS연결,MATCH(K$1,BS연결H,0),0)/100,"") | L7: =IFERROR(VLOOKUP($D7,BS연결,MATCH(L$1,BS연결H,0),0)/100,"") | M7: =IFERROR(VLOOKUP($D7,BS연결,MATCH(M$1,BS연결H,0),0)/100,"") | N7: =IFERROR(VLOOKUP($D7,BS연결,MATCH(N$1,BS연결H,0),0)/100,"") | ... AB7: =IFERROR(VLOOKUP($D7,BS연결,MATCH(AB$1,BS연결H,0),0)/100,"") | AC7: =IFERROR(AC9+AC8,"") | AD7: =IFERROR(AD9+AD8,"") | AE7: =SUM(AA7:AD7) | AF7: =IFERROR(AF9+AF8,"") | AG7: =IFERROR(AG9+AG8,"") | AH7: =IFERROR(AH9+AH8,"") | AI7: =IFERROR(AI9+AI8,"") | AJ7: =SUM(AF7:AI7) | AK7: =IFERROR(AK9+AK8,"") | AL7: =IFERROR(AL9+AL8,"") | AM7: =IFERROR(AM9+AM8,"") | AN7: =IFERROR(AN9+AN8,"") | AO7: =SUM(AK7:AN7)
A8: 판관비 | B8: 손익 | C8: 억원 | D8: 판관비 | E8: =IFERROR(VLOOKUP($D8,BS연결,MATCH(E$1,BS연결H,0),0)/100,"") | G8: =IFERROR(VLOOKUP($D8,BS연결,MATCH(G$1,BS연결H,0),0)/100,"") | H8: =IFERROR(VLOOKUP($D8,BS연결,MATCH(H$1,BS연결H,0),0)/100,"") | I8: =IFERROR(VLOOKUP($D8,BS연결,MATCH(I$1,BS연결H,0),0)/100,"") | J8: =IFERROR(VLOOKUP($D8,BS연결,MATCH(J$1,BS연결H,0),0)/100,"") | K8: =IFERROR(VLOOKUP($D8,BS연결,MATCH(K$1,BS연결H,0),0)/100,"") | L8: =IFERROR(VLOOKUP($D8,BS연결,MATCH(L$1,BS연결H,0),0)/100,"") | M8: =IFERROR(VLOOKUP($D8,BS연결,MATCH(M$1,BS연결H,0),0)/100,"") | N8: =IFERROR(VLOOKUP($D8,BS연결,MATCH(N$1,BS연결H,0),0)/100,"") | ... AB8: =IFERROR(VLOOKUP($D8,BS연결,MATCH(AB$1,BS연결H,0),0)/100,"") | AC8: =IFERROR(AC5*변수!AC21,"") | AD8: =IFERROR(AD5*변수!AD21,"") | AE8: =SUM(AA8:AD8) | AF8: =IFERROR(AF5*변수!AF21,"") | AG8: =IFERROR(AG5*변수!AG21,"") | AH8: =IFERROR(AH5*변수!AH21,"") | AI8: =IFERROR(AI5*변수!AI21,"") | AJ8: =SUM(AF8:AI8) | AK8: =IFERROR(AK5*변수!AK21,"") | AL8: =IFERROR(AL5*변수!AL21,"") | AM8: =IFERROR(AM5*변수!AM21,"") | AN8: =IFERROR(AN5*변수!AN21,"") | AO8: =SUM(AK8:AN8)
A9: 영업이익 | B9: 손익 | C9: 억원 | D9: 영업이익 | E9: =IFERROR(VLOOKUP($D9,BS연결,MATCH(E$1,BS연결H,0),0)/100,"") | G9: =IFERROR(VLOOKUP($D9,BS연결,MATCH(G$1,BS연결H,0),0)/100,"") | H9: =IFERROR(VLOOKUP($D9,BS연결,MATCH(H$1,BS연결H,0),0)/100,"") | I9: =IFERROR(VLOOKUP($D9,BS연결,MATCH(I$1,BS연결H,0),0)/100,"") | J9: =IFERROR(VLOOKUP($D9,BS연결,MATCH(J$1,BS연결H,0),0)/100,"") | K9: =IFERROR(VLOOKUP($D9,BS연결,MATCH(K$1,BS연결H,0),0)/100,"") | L9: =IFERROR(VLOOKUP($D9,BS연결,MATCH(L$1,BS연결H,0),0)/100,"") | M9: =IFERROR(VLOOKUP($D9,BS연결,MATCH(M$1,BS연결H,0),0)/100,"") | N9: =IFERROR(VLOOKUP($D9,BS연결,MATCH(N$1,BS연결H,0),0)/100,"") | ... T9: =IFERROR(VLOOKUP($D9,BS연결,MATCH(T$1,BS연결H,0),0)/100,"") | U9: =SUM(Q9:T9) | V9: =IFERROR(VLOOKUP($D9,BS연결,MATCH(V$1,BS연결H,0),0)/100,"") | W9: =IFERROR(VLOOKUP($D9,BS연결,MATCH(W$1,BS연결H,0),0)/100,"") | X9: =IFERROR(VLOOKUP($D9,BS연결,MATCH(X$1,BS연결H,0),0)/100,"") | Y9: =IFERROR(VLOOKUP($D9,BS연결,MATCH(Y$1,BS연결H,0),0)/100,"") | Z9: =IFERROR(VLOOKUP($D9,BS연결,MATCH(Z$1,BS연결H,0),0)/100,"") | AA9: =IFERROR(VLOOKUP($D9,BS연결,MATCH(AA$1,BS연결H,0),0)/100,"") | AB9: =IFERROR(VLOOKUP($D9,BS연결,MATCH(AB$1,BS연결H,0),0)/100,"") | AC9: =IFERROR(AC38+AC40+AC42,"") | AD9: =IFERROR(AD38+AD40+AD42,"") | AE9: =SUM(AA9:AD9) | AF9: =IFERROR(AF38+AF40+AF42,"") | AG9: =IFERROR(AG38+AG40+AG42,"") | AH9: =IFERROR(AH38+AH40+AH42,"") | AI9: =IFERROR(AI38+AI40+AI42,"") | AJ9: =SUM(AF9:AI9) | AK9: =IFERROR(AK38+AK40+AK42,"") | AL9: =IFERROR(AL38+AL40+AL42,"") | AM9: =IFERROR(AM38+AM40+AM42,"") | AN9: =IFERROR(AN38+AN40+AN42,"") | AO9: =SUM(AK9:AN9)
A10: OPM | B10: 손익 | C10: % | D10: 영업이익률 | E10: =IFERROR(E9/E5,"") | G10: =IFERROR(G9/G5,"") | H10: =IFERROR(H9/H5,"") | I10: =IFERROR(I9/I5,"") | J10: =IFERROR(J9/J5,"") | K10: =IFERROR(K9/K5,"") | L10: =IFERROR(L9/L5,"") | M10: =IFERROR(M9/M5,"") | N10: =IFERROR(N9/N5,"") | ... AO10: =IFERROR(AO9/AO5,"")
