Workbook
Name 변수H: 변수!$C$1:$AO$1
Name 환율: 변수!$C$6:$AO$13
Name BS연결H: BS연결!$C$1:$AO$1
Name BS연결: BS연결!$C$5:$AO$103
Name BS별도H: BS별도!$C$1:$AO$1
Name BS별도: BS별도!$C$5:$AO$92
Name SUBQH: subQ!$A$1:$AO$1
Name subQ: subQ!$A$5:$AO$42

Sheet README
A1: STX엔진(077970) 실적 모델 — ARGUS 한국조선
A2: 기준 분기 2026Q2 · 마지막 실적 2026Q2 · 생성 2026-10-26
A3: 모든 수치는 모델 산출값(DART 공개 재무제표 + 우리 추정)이다 — 목표주가·투자 추천 아님. 참고용 · 투자조언 아님.
A5: 시트
A6: 변수 가정 시계열. 환율 8행(ECB via frankfurter — L2 fx.json; 추정 분기 = 노란 가정), 추정 드라이버(노란 셀 = 모델값에서 역산한 가정, 바꾸면 재계산; 연녹 셀 = 3절 스칼라 참조 수식), 3절 스칼라 가정(세율·판관비율·지배주주비중·이자율·종가·PER 밴드·COE·외화 순노출·헤지비율)
A7: BS연결/BS별도 FnGuide 계정명 × 기간 값 덤프(백만원). 행1 분기라벨, 행4 YYYY.MM / YYYY.12A. 이름정의 BS연결H·BS연결(계정명 C열부터)
A8: subQ 분기 서브모델(억원 = 백만원/100). 확정 행: =IFERROR(VLOOKUP($D행,BS연결,MATCH(E$1,BS연결H,0),0)/100,"") 추정 행: 변수 시트 가정 셀 참조 수식. 외환손익·파생상품손익은 BS 계정 합·차, 기타금융손익은 잔차, OPM·EPS·BPS·PER·PBR 은 파생 수식
A9: SLS 선표(조선사만, sls json 있을 때): 요약 행(sls 저장값) + 계약별 스케줄(백만$) × (헤지비율 × 헤지환율 + (1−헤지비율) × 건조시점 환율[변수 원/달러(평균)]) → 원화 수식 블록 → 합계 행이 subQ 매출조선에 연결
A10: 시나리오 신규수주 보수/기준/낙관(forecast_panel 패널, 모델에 scenarios 가 있을 때만): 매출액·영업이익 = subQ 기준값 ± (시나리오 신규 − base 신규) × OPM. base 만 subQ 행에 포함, 나머지는 합산 안 함
A11: 분기/연간예상 subQ 를 이름(A열 key)으로 VLOOKUP 한 보고서 표(억원)
A12: TP PER 밴드 × 12M fwd EPS, PBR = ROE/COE × BPS — 모델 산출값 구간, 목표주가·추천 아님
A13: 외화 환율 QoQ, 외화 순노출 × Δ기말환율 → 환관련손익 추정
... A34: 백테스트: {"freeze": "2025Q2", "horizon": 4, "revenue_wape_pct": 20.9, "op_wape_pct": 48.8, "n": 4, "note": "단일 회사 4분기 — 통계 아님", "driver_at_freeze": "customer_yard_revenue_weighted", "selection_oos_at_freeze": {"freeze": "2024Q2", "n": 4, "wape_link": null, "wape_trend": 9.2, "adopted": "undetermined", "decision": "undetermined", "note": "현재 채택 조합(suppliers_mentions·시차 3·ma4·창 12)을 동결 데이터로 재적합할 수 없음(짝·고객 모델 부족) → 연동 WAPE 없음, undetermined(유의성 조건만으로 채택)"}, "frozen_inputs": "fin(연결/별도)·고객 조선사 모델·지주 자회사 모델은 2025Q2 까지의 분기만; 선표는 체결일 ≤ 2025Q2 말일 계약(원장 최신 금액·코호트 등급, 환산 없음); 잔고는 yards_cache 2025Q2; 시세·환율 forward·prices·forecast_panel 신규수주 미사용. 고객 가중치(suppliers.json 언급 비중)와 합병 체인링크는 현재 지식; 고객 연동 채택은 동결 모델 안에서도 자기 la−4분기 OOS 규칙(selection_oos_at_freeze)", "detail": [{"q": "2025Q3", "rev_pred": 2341.43, "rev_act": 1920.66, "op_pred": 140.4, "op_act": 154.26}, {"q": "2025Q4", "rev_pred": 3267.26, "rev_act": 2444.82, "op_pred": 195.91, "op_act": 53.68}, {"q": "2026Q1", "rev_pred": 1903.72, "rev_act": 1890.11, "op_pred": 114.15, "op_act": 175.04}, {"q": "2026Q2", "rev_pred": 2628.38, "rev_act": 2129.9, "op_pred": 157.6, "op_act": 249.61}]}

Sheet 변수
C1: 이름: 변수H | E1: 4Q21 | F1: 2021 | G1: 1Q22 | H1: 2Q22 | I1: 3Q22 | J1: 4Q22 | K1: 2022 | L1: 1Q23 | M1: 2Q23 | N1: 3Q23 | O1: 4Q23 | P1: 2023 | Q1: 1Q24 | R1: 2Q24 | S1: 3Q24 | T1: 4Q24 | U1: 2024 | V1: 1Q25 | W1: 2Q25 | X1: 3Q25 | Y1: 4Q25 | Z1: 2025 | AA1: 1Q26 | AB1: 2Q26 | AC1: 3Q26 | AD1: 4Q26 | AE1: 2026 | AF1: 1Q27 | AG1: 2Q27 | AH1: 3Q27 | AI1: 4Q27 | AJ1: 2027 | AK1: 1Q28 | AL1: 2Q28 | AM1: 3Q28 | AN1: 4Q28 | AO1: 2028
A2: 가정 시계열 — 노란 셀은 추정 가정(모델값에서 역산), 연녹 셀은 3절 스칼라 참조 수식. 바꾸면 subQ·분기·연간예상·TP·시나리오가 재계산됩니다.
E3: 1 | F3: 2 | G3: 3 | H3: 4 | I3: 5 | J3: 6 | K3: 7 | L3: 8 | M3: 9 | N3: 10 | O3: 11 | P3: 12 | Q3: 13 | R3: 14 | S3: 15 | T3: 16 | U3: 17 | V3: 18 | W3: 19 | X3: 20 | Y3: 21 | Z3: 22 | AA3: 23 | AB3: 24 | AC3: 25 | AD3: 26 | AE3: 27 | AF3: 28 | AG3: 29 | AH3: 30 | AI3: 31 | AJ3: 32 | AK3: 33 | AL3: 34 | AM3: 35 | AN3: 36 | AO3: 37
E4: 2021.12 | F4: 2021.12A | G4: 2022.03 | H4: 2022.06 | I4: 2022.09 | J4: 2022.12 | K4: 2022.12A | L4: 2023.03 | M4: 2023.06 | N4: 2023.09 | O4: 2023.12 | P4: 2023.12A | Q4: 2024.03 | R4: 2024.06 | S4: 2024.09 | T4: 2024.12 | U4: 2024.12A | V4: 2025.03 | W4: 2025.06 | X4: 2025.09 | Y4: 2025.12 | Z4: 2025.12A | AA4: 2026.03 | AB4: 2026.06 | AC4: 2026.09 | AD4: 2026.12 | AE4: 2026.12A | AF4: 2027.03 | AG4: 2027.06 | AH4: 2027.09 | AI4: 2027.12 | AJ4: 2027.12A | AK4: 2028.03 | AL4: 2028.06 | AM4: 2028.09 | AN4: 2028.12 | AO4: 2028.12A
B5: 1. FX | C5: 이름: 환율
A6: USDKRW_avg | C6: 원/달러(평균) | E6: 1183.5 | F6: 1145.51 | G6: 1205.78 | H6: 1262.09 | I6: 1341.93 | J6: 1360.12 | K6: 1292.98 | L6: 1276.95 | M6: 1315.69 | N6: 1313.62 | O6: 1322.01 | P6: 1306.85 | Q6: 1330.14 | R6: 1371.28 | S6: 1356.22 | T6: 1396.3 | U6: 1363.53 | V6: 1452.28 | W6: 1398.52 | X6: 1386.95 | Y6: 1449.19 | Z6: 1421.52 | AA6: 1466.12 | AB6: 1501.75 | AC6: 1418.75 | AD6: 1337.49 | AE6: 1451.19 | AF6: 1324.45 | AG6: 1324.45 | AH6: 1324.45 | AI6: 1324.45 | AK6: 1324.45 | AL6: 1324.45 | AM6: 1324.45 | AN6: 1324.45
A7: USDKRW_end | C7: 원/달러(기말) | E7: 1188.75 | F7: 1188.75 | G7: 1213.74 | H7: 1301.24 | I7: 1436.9 | J7: 1260.16 | K7: 1260.16 | L7: 1305.99 | M7: 1321.44 | N7: 1345.35 | O7: 1297.43 | P7: 1297.43 | Q7: 1349.25 | R7: 1377.73 | S7: 1312.17 | T7: 1474.78 | U7: 1474.78 | V7: 1474.54 | W7: 1355.13 | X7: 1403.67 | Y7: 1444.2 | Z7: 1444.2 | AA7: 1524.8 | AB7: 1550.89 | AC7: 1355.4 | AD7: 1324.45 | AE7: 1324.45 | AF7: 1324.45 | AG7: 1324.45 | AH7: 1324.45 | AI7: 1324.45 | AK7: 1324.45 | AL7: 1324.45 | AM7: 1324.45 | AN7: 1324.45
A8: JPY100KRW_avg | C8: 원/100Y(평균) | E8: 1041.02 | F8: 1042.74 | G8: 1036.79 | H8: 972.23 | I8: 970.61 | J8: 961.03 | K8: 985.1 | L8: 964.89 | M8: 957.36 | N8: 909 | O8: 893.22 | P8: 931.11 | Q8: 896.29 | R8: 880.14 | S8: 909.35 | T8: 917.25 | U8: 900.92 | V8: 952.59 | W8: 967.92 | X8: 940.32 | Y8: 940.77 | Z8: 950.17 | AA8: 934.39 | AB8: 942.16 | AC8: 890.41 | AD8: 846.51 | AE8: 915.57 | AF8: 844.67 | AG8: 844.67 | AH8: 844.67 | AI8: 844.67 | AK8: 844.67 | AL8: 844.67 | AM8: 844.67 | AN8: 844.67
A9: JPY100KRW_end | C9: 원/100Y(기말) | E9: 1032.62 | F9: 1032.62 | G9: 996.83 | H9: 954.9 | I9: 993.29 | J9: 955.54 | K9: 955.54 | L9: 980.62 | M9: 913.67 | N9: 901.47 | O9: 917.04 | P9: 917.04 | Q9: 892.42 | R9: 857.76 | S9: 919.21 | T9: 939.65 | U9: 939.65 | V9: 986.84 | W9: 938.85 | X9: 948.49 | Y9: 921.81 | Z9: 921.81 | AA9: 955.99 | AB9: 954.75 | AC9: 863.31 | AD9: 844.67 | AE9: 844.67 | AF9: 844.67 | AG9: 844.67 | AH9: 844.67 | AI9: 844.67 | AK9: 844.67 | AL9: 844.67 | AM9: 844.67 | AN9: 844.67
A10: EURKRW_avg | C10: W/Euro(평균) | E10: 1353.32 | F10: 1354.06 | G10: 1352.29 | H10: 1343.31 | I10: 1350.63 | J10: 1386.07 | K10: 1358.07 | L10: 1369.93 | M10: 1432.41 | N10: 1429.41 | O10: 1420.91 | P10: 1412.88 | Q10: 1444.21 | R10: 1476.42 | S10: 1489.3 | T10: 1490.78 | U10: 1475.4 | V10: 1528.33 | W10: 1585.13 | X10: 1620.04 | Y10: 1686.02 | Z10: 1605.45 | AA10: 1715.47 | AB10: 1746.09 | AC10: 1631.97 | AD10: 1500.06 | AE10: 1680.5 | AF10: 1482.45 | AG10: 1482.45 | AH10: 1482.45 | AI10: 1482.45 | AK10: 1482.45 | AL10: 1482.45 | AM10: 1482.45 | AN10: 1482.45
A11: EURKRW_end | C11: W/Euro(기말) | E11: 1346.38 | F11: 1346.38 | G11: 1347.37 | H11: 1351.6 | I11: 1400.62 | J11: 1344.08 | K11: 1344.08 | L11: 1420.26 | M11: 1435.88 | N11: 1425.26 | O11: 1433.66 | P11: 1433.66 | Q11: 1458.68 | R11: 1474.86 | S11: 1469.1 | T11: 1532.14 | U11: 1532.14 | V11: 1594.72 | W11: 1588.22 | X11: 1648.04 | Y11: 1696.94 | Z11: 1696.94 | AA11: 1753.21 | AB11: 1767.09 | AC11: 1539.06 | AD11: 1482.45 | AE11: 1482.45 | AF11: 1482.45 | AG11: 1482.45 | AH11: 1482.45 | AI11: 1482.45 | AK11: 1482.45 | AL11: 1482.45 | AM11: 1482.45 | AN11: 1482.45
A12: CNYKRW_avg | C12: 원/중국원(평균) | E12: 185.14 | F12: 177.65 | G12: 189.93 | H12: 190.76 | I12: 195.79 | J12: 191.09 | K12: 191.93 | L12: 186.59 | M12: 187.45 | N12: 181.28 | O12: 182.86 | P12: 184.52 | Q12: 185.04 | R12: 189.35 | S12: 189.24 | T12: 194.24 | U12: 189.49 | V12: 199.63 | W12: 193.41 | X12: 193.79 | Y12: 204.38 | Z12: 197.8 | AA12: 211.75 | AB12: 220.8 | AC12: 210.43 | AD12: 199.88 | AE12: 213.06 | AF12: 198.56 | AG12: 198.56 | AH12: 198.56 | AI12: 198.56 | AK12: 198.56 | AL12: 198.56 | AM12: 198.56 | AN12: 198.56
A13: CNYKRW_end | C13: 원/중국원(기말) | E13: 187.13 | F13: 187.13 | G13: 191.38 | H13: 194.13 | I13: 201.92 | J13: 182.67 | K13: 182.67 | L13: 189.97 | M13: 181.8 | N13: 184.26 | O13: 182.61 | P13: 182.61 | Q13: 186.66 | R13: 189.7 | S13: 187.12 | T13: 202.04 | U13: 202.04 | V13: 203.3 | W13: 189.14 | X13: 197.16 | Y13: 206.28 | Z13: 206.28 | AA13: 220.97 | AB13: 228.56 | AC13: 202.16 | AD13: 198.56 | AE13: 198.56 | AF13: 198.56 | AG13: 198.56 | AH13: 198.56 | AI13: 198.56 | AK13: 198.56 | AL13: 198.56 | AM13: 198.56 | AN13: 198.56
B14: 1b. 종가
A15: price_close_end | C15: 종가(기말) | E15: 9600 | G15: 12950 | H15: 14500 | I15: 12950 | J15: 13450 | L15: 12780 | M15: 14220 | N15: 13070 | O15: 11850 | Q15: 12970 | R15: 17100 | S15: 18120 | T15: 20100 | V15: 20800 | W15: 21500 | X15: 39550 | Y15: 34000 | AA15: 30650 | AB15: 29300 | AC15: 22200 | AD15: 15780
A16: price_high | C16: 종가(최고) | E16: 12900 | G16: 17500 | H16: 16550 | I16: 19500 | J16: 17350 | L16: 14840 | M16: 16080 | N16: 16180 | O16: 13510 | Q16: 13900 | R16: 18660 | S16: 24400 | T16: 22500 | V16: 31650 | W16: 27000 | X16: 49800 | Y16: 41850 | AA16: 40500 | AB16: 67700 | AC16: 31550 | AD16: 23800
A17: price_low | C17: 종가(최저) | E17: 8370 | G17: 8960 | H17: 11900 | I17: 12000 | J17: 11600 | L17: 12250 | M17: 12400 | N17: 12600 | O17: 11000 | Q17: 11450 | R17: 12310 | S17: 12880 | T17: 15150 | V17: 19150 | W17: 18310 | X17: 19910 | Y17: 28700 | AA17: 25100 | AB17: 26200 | AC17: 18830 | AD17: 15750
A18: price_avg | C18: 종가(평균) | E18: 10078.9 | G18: 11801.9 | H18: 13670.2 | I18: 14700 | J18: 13228.2 | L18: 13458.5 | M18: 13401.6 | N18: 14184.8 | O18: 11945.7 | Q18: 12403.1 | R18: 14312.3 | S18: 17817.6 | T18: 19656.2 | V18: 24307.6 | W18: 23137.2 | X18: 32170.8 | Y18: 35330.5 | AA18: 34270.3 | AB18: 41308.2 | AC18: 24844.4 | AD18: 19355.6
B20: 2. 추정 드라이버 | C20: 실적 열 = subQ 실현값(수식), 추정 열 = 가정(노란 = 모델값 역산, 연녹 = 3절 스칼라 참조)
A21: drv:매출액 | B21: yoy | C21: 매출액 YoY | J21: =IFERROR(subQ!J5/subQ!E5-1,"") | L21: =IFERROR(subQ!L5/subQ!G5-1,"") | M21: =IFERROR(subQ!M5/subQ!H5-1,"") | N21: =IFERROR(subQ!N5/subQ!I5-1,"") | O21: =IFERROR(subQ!O5/subQ!J5-1,"") | Q21: =IFERROR(subQ!Q5/subQ!L5-1,"") | R21: =IFERROR(subQ!R5/subQ!M5-1,"") | S21: =IFERROR(subQ!S5/subQ!N5-1,"") | T21: =IFERROR(subQ!T5/subQ!O5-1,"") | V21: =IFERROR(subQ!V5/subQ!Q5-1,"") | W21: =IFERROR(subQ!W5/subQ!R5-1,"") | X21: =IFERROR(subQ!X5/subQ!S5-1,"") | Y21: =IFERROR(subQ!Y5/subQ!T5-1,"") | AA21: =IFERROR(subQ!AA5/subQ!V5-1,"") | AB21: =IFERROR(subQ!AB5/subQ!W5-1,"") | AC21: 0.096806521 | AD21: 0.096802736 | AF21: 0.096806501 | AG21: 0.096803645 | AH21: 0.048400496 | AI21: 0.048402375 | AK21: 0.048401412 | AL21: 0.048401596 | AM21: 0.024201399 | AN21: 0.024202585
A22: drv:판관비 | B22: ratio | C22: 판관비율(/매출) | E22: =IFERROR(subQ!E8/subQ!E5,"") | F22: =IFERROR(subQ!F8/subQ!F5,"") | G22: =IFERROR(subQ!G8/subQ!G5,"") | H22: =IFERROR(subQ!H8/subQ!H5,"") | I22: =IFERROR(subQ!I8/subQ!I5,"") | J22: =IFERROR(subQ!J8/subQ!J5,"") | K22: =IFERROR(subQ!K8/subQ!K5,"") | L22: =IFERROR(subQ!L8/subQ!L5,"") | ... AB22: =IFERROR(subQ!AB8/subQ!AB5,"") | AC22: =$D$51 | AD22: =$D$51 | AE22: =IFERROR(subQ!AE8/subQ!AE5,"") | AF22: =$D$51 | AG22: =$D$51 | AH22: =$D$51 | AI22: =$D$51 | AJ22: =IFERROR(subQ!AJ8/subQ!AJ5,"") | AK22: =$D$51 | AL22: =$D$51 | AM22: =$D$51 | AN22: =$D$51 | AO22: =IFERROR(subQ!AO8/subQ!AO5,"")
A23: drv:영업이익 | B23: ratio | C23: 영업이익률(OPM) | E23: =IFERROR(subQ!E9/subQ!E5,"") | F23: =IFERROR(subQ!F9/subQ!F5,"") | G23: =IFERROR(subQ!G9/subQ!G5,"") | H23: =IFERROR(subQ!H9/subQ!H5,"") | I23: =IFERROR(subQ!I9/subQ!I5,"") | J23: =IFERROR(subQ!J9/subQ!J5,"") | K23: =IFERROR(subQ!K9/subQ!K5,"") | L23: =IFERROR(subQ!L9/subQ!L5,"") | ... AB23: =IFERROR(subQ!AB9/subQ!AB5,"") | AC23: 0.086462007 | AD23: 0.086459716 | AE23: =IFERROR(subQ!AE9/subQ!AE5,"") | AF23: 0.086460725 | AG23: 0.08646108 | AH23: 0.086459442 | AI23: 0.086462702 | AJ23: =IFERROR(subQ!AJ9/subQ!AJ5,"") | AK23: 0.08646281 | AL23: 0.08646265 | AM23: 0.086458886 | AN23: 0.086461687 | AO23: =IFERROR(subQ!AO9/subQ!AO5,"")
A24: drv:외환손익 | B24: abs | C24: 외환손익 (가정, 억원) | E24: =subQ!E13 | F24: =subQ!F13 | G24: =subQ!G13 | H24: =subQ!H13 | I24: =subQ!I13 | J24: =subQ!J13 | K24: =subQ!K13 | L24: =subQ!L13 | ... AB24: =subQ!AB13 | AC24: 0 | AD24: 0 | AE24: =subQ!AE13 | AF24: 0 | AG24: 0 | AH24: 0 | AI24: 0 | AJ24: =subQ!AJ13 | AK24: 0 | AL24: 0 | AM24: 0 | AN24: 0 | AO24: =subQ!AO13
A25: drv:파생상품손익 | B25: abs | C25: 파생상품손익 (가정, 억원) | E25: =subQ!E14 | F25: =subQ!F14 | G25: =subQ!G14 | H25: =subQ!H14 | I25: =subQ!I14 | J25: =subQ!J14 | K25: =subQ!K14 | L25: =subQ!L14 | ... AB25: =subQ!AB14 | AC25: 0 | AD25: 0 | AE25: =subQ!AE14 | AF25: 0 | AG25: 0 | AH25: 0 | AI25: 0 | AJ25: =subQ!AJ14 | AK25: 0 | AL25: 0 | AM25: 0 | AN25: 0 | AO25: =subQ!AO14
A26: drv:기타금융손익 | B26: abs | C26: 기타금융손익 (가정, 억원) | E26: =subQ!E15 | F26: =subQ!F15 | G26: =subQ!G15 | H26: =subQ!H15 | I26: =subQ!I15 | J26: =subQ!J15 | K26: =subQ!K15 | L26: =subQ!L15 | ... AB26: =subQ!AB15 | AC26: 0 | AD26: 0 | AE26: =subQ!AE15 | AF26: 0 | AG26: 0 | AH26: 0 | AI26: 0 | AJ26: =subQ!AJ15 | AK26: 0 | AL26: 0 | AM26: 0 | AN26: 0 | AO26: =subQ!AO15
A27: drv:기타영업외손익 | B27: abs | C27: 기타영업외손익 (가정, 억원) | E27: =subQ!E16 | F27: =subQ!F16 | G27: =subQ!G16 | H27: =subQ!H16 | I27: =subQ!I16 | J27: =subQ!J16 | K27: =subQ!K16 | L27: =subQ!L16 | ... AB27: =subQ!AB16 | AC27: 0 | AD27: 0 | AE27: =subQ!AE16 | AF27: 0 | AG27: 0 | AH27: 0 | AI27: 0 | AJ27: =subQ!AJ16 | AK27: 0 | AL27: 0 | AM27: 0 | AN27: 0 | AO27: =subQ!AO16
A28: drv:법인세비용 | B28: tax | C28: 법인세율(/세전) — 법인세 = MAX(세전,0) × 분기별 세율(이월결손 램프, assumptions.tax_schedule) | E28: =IFERROR(subQ!E18/subQ!E17,"") | F28: =IFERROR(subQ!F18/subQ!F17,"") | G28: =IFERROR(subQ!G18/subQ!G17,"") | H28: =IFERROR(subQ!H18/subQ!H17,"") | I28: =IFERROR(subQ!I18/subQ!I17,"") | J28: =IFERROR(subQ!J18/subQ!J17,"") | K28: =IFERROR(subQ!K18/subQ!K17,"") | L28: =IFERROR(subQ!L18/subQ!L17,"") | ... AB28: =IFERROR(subQ!AB18/subQ!AB17,"") | AC28: 0 | AD28: 0 | AE28: =IFERROR(subQ!AE18/subQ!AE17,"") | AF28: 0.027501426 | AG28: 0.055004409 | AH28: 0.08249227 | AI28: 0.11000713 | AJ28: =IFERROR(subQ!AJ18/subQ!AJ17,"") | AK28: 0.13751833 | AL28: 0.16500128 | AM28: 0.19247443 | AN28: 0.21999658 | AO28: =IFERROR(subQ!AO18/subQ!AO17,"")
A29: drv:지배주주순이익 | B29: ratio | C29: 지배주주 비중(/당기순이익) | E29: =IFERROR(subQ!E20/subQ!E19,"") | F29: =IFERROR(subQ!F20/subQ!F19,"") | G29: =IFERROR(subQ!G20/subQ!G19,"") | H29: =IFERROR(subQ!H20/subQ!H19,"") | I29: =IFERROR(subQ!I20/subQ!I19,"") | J29: =IFERROR(subQ!J20/subQ!J19,"") | K29: =IFERROR(subQ!K20/subQ!K19,"") | L29: =IFERROR(subQ!L20/subQ!L19,"") | ... AB29: =IFERROR(subQ!AB20/subQ!AB19,"") | AC29: =$D$52 | AD29: =$D$52 | AE29: =IFERROR(subQ!AE20/subQ!AE19,"") | AF29: =$D$52 | AG29: =$D$52 | AH29: =$D$52 | AI29: =$D$52 | AJ29: =IFERROR(subQ!AJ20/subQ!AJ19,"") | AK29: =$D$52 | AL29: =$D$52 | AM29: =$D$52 | AN29: =$D$52 | AO29: =IFERROR(subQ!AO20/subQ!AO19,"")
A30: drv:부채총계 | B30: qoq | C30: 부채총계 QoQ | G30: =IFERROR(subQ!G22/subQ!E22-1,"") | H30: =IFERROR(subQ!H22/subQ!G22-1,"") | I30: =IFERROR(subQ!I22/subQ!H22-1,"") | J30: =IFERROR(subQ!J22/subQ!I22-1,"") | L30: =IFERROR(subQ!L22/subQ!J22-1,"") | M30: =IFERROR(subQ!M22/subQ!L22-1,"") | N30: =IFERROR(subQ!N22/subQ!M22-1,"") | O30: =IFERROR(subQ!O22/subQ!N22-1,"") | Q30: =IFERROR(subQ!Q22/subQ!O22-1,"") | R30: =IFERROR(subQ!R22/subQ!Q22-1,"") | S30: =IFERROR(subQ!S22/subQ!R22-1,"") | T30: =IFERROR(subQ!T22/subQ!S22-1,"") | V30: =IFERROR(subQ!V22/subQ!T22-1,"") | W30: =IFERROR(subQ!W22/subQ!V22-1,"") | X30: =IFERROR(subQ!X22/subQ!W22-1,"") | Y30: =IFERROR(subQ!Y22/subQ!X22-1,"") | AA30: =IFERROR(subQ!AA22/subQ!Y22-1,"") | AB30: =IFERROR(subQ!AB22/subQ!AA22-1,"") | AC30: 5.41e-07 | AD30: 0 | AF30: 0 | AG30: 0 | AH30: 0 | AI30: 0 | AK30: 0 | AL30: 0 | AM30: 0 | AN30: 0
A31: drv:자본총계 | B31: roll | C31: 자본총계 기타변동(배당 등, 억원) | G31: =IFERROR(subQ!E23+subQ!G19-subQ!G23,"") | H31: =IFERROR(subQ!G23+subQ!H19-subQ!H23,"") | I31: =IFERROR(subQ!H23+subQ!I19-subQ!I23,"") | J31: =IFERROR(subQ!I23+subQ!J19-subQ!J23,"") | L31: =IFERROR(subQ!J23+subQ!L19-subQ!L23,"") | M31: =IFERROR(subQ!L23+subQ!M19-subQ!M23,"") | N31: =IFERROR(subQ!M23+subQ!N19-subQ!N23,"") | O31: =IFERROR(subQ!N23+subQ!O19-subQ!O23,"") | Q31: =IFERROR(subQ!O23+subQ!Q19-subQ!Q23,"") | R31: =IFERROR(subQ!Q23+subQ!R19-subQ!R23,"") | S31: =IFERROR(subQ!R23+subQ!S19-subQ!S23,"") | T31: =IFERROR(subQ!S23+subQ!T19-subQ!T23,"") | V31: =IFERROR(subQ!T23+subQ!V19-subQ!V23,"") | W31: =IFERROR(subQ!V23+subQ!W19-subQ!W23,"") | X31: =IFERROR(subQ!W23+subQ!X19-subQ!X23,"") | Y31: =IFERROR(subQ!X23+subQ!Y19-subQ!Y23,"") | AA31: =IFERROR(subQ!Y23+subQ!AA19-subQ!AA23,"") | AB31: =IFERROR(subQ!AA23+subQ!AB19-subQ!AB23,"") | AC31: 0.001220222 | AD31: 0.000867166 | AF31: -0.00160795 | AG31: 0.001357101 | AH31: -0.000606389 | AI31: 0.004095056 | AK31: -0.003889981 | AL31: 0.002249301 | AM31: 0.0027428 | AN31: -0.002731924
A32: drv:지배주주지분 | B32: roll | C32: 지배주주지분 기타변동(배당 등, 억원) | G32: =IFERROR(subQ!E24+subQ!G20-subQ!G24,"") | H32: =IFERROR(subQ!G24+subQ!H20-subQ!H24,"") | I32: =IFERROR(subQ!H24+subQ!I20-subQ!I24,"") | J32: =IFERROR(subQ!I24+subQ!J20-subQ!J24,"") | L32: =IFERROR(subQ!J24+subQ!L20-subQ!L24,"") | M32: =IFERROR(subQ!L24+subQ!M20-subQ!M24,"") | N32: =IFERROR(subQ!M24+subQ!N20-subQ!N24,"") | O32: =IFERROR(subQ!N24+subQ!O20-subQ!O24,"") | Q32: =IFERROR(subQ!O24+subQ!Q20-subQ!Q24,"") | R32: =IFERROR(subQ!Q24+subQ!R20-subQ!R24,"") | S32: =IFERROR(subQ!R24+subQ!S20-subQ!S24,"") | T32: =IFERROR(subQ!S24+subQ!T20-subQ!T24,"") | V32: =IFERROR(subQ!T24+subQ!V20-subQ!V24,"") | W32: =IFERROR(subQ!V24+subQ!W20-subQ!W24,"") | X32: =IFERROR(subQ!W24+subQ!X20-subQ!X24,"") | Y32: =IFERROR(subQ!X24+subQ!Y20-subQ!Y24,"") | AA32: =IFERROR(subQ!Y24+subQ!AA20-subQ!AA24,"") | AB32: =IFERROR(subQ!AA24+subQ!AB20-subQ!AB24,"") | AC32: 0.001220222 | AD32: 0.000867166 | AF32: -0.00160795 | AG32: 0.001357101 | AH32: -0.000606389 | AI32: 0.004095056 | AK32: -0.003889981 | AL32: 0.002249301 | AM32: 0.0027428 | AN32: -0.002731924
A33: drv:총차입금 | B33: qoq | C33: 총차입금 QoQ | G33: =IFERROR(subQ!G25/subQ!E25-1,"") | H33: =IFERROR(subQ!H25/subQ!G25-1,"") | I33: =IFERROR(subQ!I25/subQ!H25-1,"") | J33: =IFERROR(subQ!J25/subQ!I25-1,"") | L33: =IFERROR(subQ!L25/subQ!J25-1,"") | M33: =IFERROR(subQ!M25/subQ!L25-1,"") | N33: =IFERROR(subQ!N25/subQ!M25-1,"") | O33: =IFERROR(subQ!O25/subQ!N25-1,"") | Q33: =IFERROR(subQ!Q25/subQ!O25-1,"") | R33: =IFERROR(subQ!R25/subQ!Q25-1,"") | S33: =IFERROR(subQ!S25/subQ!R25-1,"") | T33: =IFERROR(subQ!T25/subQ!S25-1,"") | V33: =IFERROR(subQ!V25/subQ!T25-1,"") | W33: =IFERROR(subQ!W25/subQ!V25-1,"") | X33: =IFERROR(subQ!X25/subQ!W25-1,"") | Y33: =IFERROR(subQ!Y25/subQ!X25-1,"") | AA33: =IFERROR(subQ!AA25/subQ!Y25-1,"") | AB33: =IFERROR(subQ!AB25/subQ!AA25-1,"") | AC33: 7.58e-07 | AD33: 0 | AF33: 0 | AG33: 0 | AH33: 0 | AI33: 0 | AK33: 0 | AL33: 0 | AM33: 0 | AN33: 0
A34: drv:순차입금 | B34: qoq | C34: 순차입금 QoQ | G34: =IFERROR(subQ!G26/subQ!E26-1,"") | H34: =IFERROR(subQ!H26/subQ!G26-1,"") | I34: =IFERROR(subQ!I26/subQ!H26-1,"") | J34: =IFERROR(subQ!J26/subQ!I26-1,"") | L34: =IFERROR(subQ!L26/subQ!J26-1,"") | M34: =IFERROR(subQ!M26/subQ!L26-1,"") | N34: =IFERROR(subQ!N26/subQ!M26-1,"") | O34: =IFERROR(subQ!O26/subQ!N26-1,"") | Q34: =IFERROR(subQ!Q26/subQ!O26-1,"") | R34: =IFERROR(subQ!R26/subQ!Q26-1,"") | S34: =IFERROR(subQ!S26/subQ!R26-1,"") | T34: =IFERROR(subQ!T26/subQ!S26-1,"") | V34: =IFERROR(subQ!V26/subQ!T26-1,"") | W34: =IFERROR(subQ!W26/subQ!V26-1,"") | X34: =IFERROR(subQ!X26/subQ!W26-1,"") | Y34: =IFERROR(subQ!Y26/subQ!X26-1,"") | AA34: =IFERROR(subQ!AA26/subQ!Y26-1,"") | AB34: =IFERROR(subQ!AB26/subQ!AA26-1,"") | AC34: -0.07393204 | AD34: -0.10532172 | AF34: -0.086364174 | AG34: -0.10560873 | AH34: -0.10830671 | AI34: -0.15426974 | AK34: -0.13425748 | AL34: -0.17188093 | AM34: -0.18504885 | AN34: -0.28544412
A35: drv:이자발생자산 | B35: qoq | C35: 이자발생자산 QoQ | G35: =IFERROR(subQ!G27/subQ!E27-1,"") | H35: =IFERROR(subQ!H27/subQ!G27-1,"") | I35: =IFERROR(subQ!I27/subQ!H27-1,"") | J35: =IFERROR(subQ!J27/subQ!I27-1,"") | L35: =IFERROR(subQ!L27/subQ!J27-1,"") | M35: =IFERROR(subQ!M27/subQ!L27-1,"") | N35: =IFERROR(subQ!N27/subQ!M27-1,"") | O35: =IFERROR(subQ!O27/subQ!N27-1,"") | Q35: =IFERROR(subQ!Q27/subQ!O27-1,"") | R35: =IFERROR(subQ!R27/subQ!Q27-1,"") | S35: =IFERROR(subQ!S27/subQ!R27-1,"") | T35: =IFERROR(subQ!T27/subQ!S27-1,"") | V35: =IFERROR(subQ!V27/subQ!T27-1,"") | W35: =IFERROR(subQ!W27/subQ!V27-1,"") | X35: =IFERROR(subQ!X27/subQ!W27-1,"") | Y35: =IFERROR(subQ!Y27/subQ!X27-1,"") | AA35: =IFERROR(subQ!AA27/subQ!Y27-1,"") | AB35: =IFERROR(subQ!AB27/subQ!AA27-1,"") | AC35: 0.1118141 | AD35: 0.13268807 | AF35: 0.085932032 | AG35: 0.088418957 | AH35: 0.074508708 | AI35: 0.088072027 | AK35: 0.059575813 | AL35: 0.062318342 | AM35: 0.052301323 | AN35: 0.062476266
A36: drv:현금및현금성자산 | B36: qoq | C36: 현금및현금성자산 QoQ | G36: =IFERROR(subQ!G28/subQ!E28-1,"") | H36: =IFERROR(subQ!H28/subQ!G28-1,"") | I36: =IFERROR(subQ!I28/subQ!H28-1,"") | J36: =IFERROR(subQ!J28/subQ!I28-1,"") | L36: =IFERROR(subQ!L28/subQ!J28-1,"") | M36: =IFERROR(subQ!M28/subQ!L28-1,"") | N36: =IFERROR(subQ!N28/subQ!M28-1,"") | O36: =IFERROR(subQ!O28/subQ!N28-1,"") | Q36: =IFERROR(subQ!Q28/subQ!O28-1,"") | R36: =IFERROR(subQ!R28/subQ!Q28-1,"") | S36: =IFERROR(subQ!S28/subQ!R28-1,"") | T36: =IFERROR(subQ!T28/subQ!S28-1,"") | V36: =IFERROR(subQ!V28/subQ!T28-1,"") | W36: =IFERROR(subQ!W28/subQ!V28-1,"") | X36: =IFERROR(subQ!X28/subQ!W28-1,"") | Y36: =IFERROR(subQ!Y28/subQ!X28-1,"") | AA36: =IFERROR(subQ!AA28/subQ!Y28-1,"") | AB36: =IFERROR(subQ!AB28/subQ!AA28-1,"")
A37: drv:CAPEX | B37: yoy | C37: CAPEX YoY | J37: =IFERROR(subQ!J29/subQ!E29-1,"") | L37: =IFERROR(subQ!L29/subQ!G29-1,"") | M37: =IFERROR(subQ!M29/subQ!H29-1,"") | N37: =IFERROR(subQ!N29/subQ!I29-1,"") | O37: =IFERROR(subQ!O29/subQ!J29-1,"") | Q37: =IFERROR(subQ!Q29/subQ!L29-1,"") | R37: =IFERROR(subQ!R29/subQ!M29-1,"") | S37: =IFERROR(subQ!S29/subQ!N29-1,"") | T37: =IFERROR(subQ!T29/subQ!O29-1,"") | V37: =IFERROR(subQ!V29/subQ!Q29-1,"") | W37: =IFERROR(subQ!W29/subQ!R29-1,"") | X37: =IFERROR(subQ!X29/subQ!S29-1,"") | Y37: =IFERROR(subQ!Y29/subQ!T29-1,"") | AA37: =IFERROR(subQ!AA29/subQ!V29-1,"") | AB37: =IFERROR(subQ!AB29/subQ!W29-1,"") | AC37: -0.19513728 | AD37: -0.13989085 | AF37: 0.27028716 | AG37: 0.19434642 | AH37: 0 | AI37: 0 | AK37: 0 | AL37: 0 | AM37: 0 | AN37: 0
A38: drv:영업활동현금흐름 | B38: yoy | C38: 영업활동현금흐름 YoY | J38: =IFERROR(subQ!J30/subQ!E30-1,"") | L38: =IFERROR(subQ!L30/subQ!G30-1,"") | M38: =IFERROR(subQ!M30/subQ!H30-1,"") | N38: =IFERROR(subQ!N30/subQ!I30-1,"") | O38: =IFERROR(subQ!O30/subQ!J30-1,"") | Q38: =IFERROR(subQ!Q30/subQ!L30-1,"") | R38: =IFERROR(subQ!R30/subQ!M30-1,"") | S38: =IFERROR(subQ!S30/subQ!N30-1,"") | T38: =IFERROR(subQ!T30/subQ!O30-1,"") | V38: =IFERROR(subQ!V30/subQ!Q30-1,"") | W38: =IFERROR(subQ!W30/subQ!R30-1,"") | X38: =IFERROR(subQ!X30/subQ!S30-1,"") | Y38: =IFERROR(subQ!Y30/subQ!T30-1,"") | AA38: =IFERROR(subQ!AA30/subQ!V30-1,"") | AB38: =IFERROR(subQ!AB30/subQ!W30-1,"")
A39: drv:주식수 | B39: qoq | C39: 주식수 QoQ | G39: =IFERROR(subQ!G31/subQ!E31-1,"") | H39: =IFERROR(subQ!H31/subQ!G31-1,"") | I39: =IFERROR(subQ!I31/subQ!H31-1,"") | J39: =IFERROR(subQ!J31/subQ!I31-1,"") | L39: =IFERROR(subQ!L31/subQ!J31-1,"") | M39: =IFERROR(subQ!M31/subQ!L31-1,"") | N39: =IFERROR(subQ!N31/subQ!M31-1,"") | O39: =IFERROR(subQ!O31/subQ!N31-1,"") | Q39: =IFERROR(subQ!Q31/subQ!O31-1,"") | R39: =IFERROR(subQ!R31/subQ!Q31-1,"") | S39: =IFERROR(subQ!S31/subQ!R31-1,"") | T39: =IFERROR(subQ!T31/subQ!S31-1,"") | V39: =IFERROR(subQ!V31/subQ!T31-1,"") | W39: =IFERROR(subQ!W31/subQ!V31-1,"") | X39: =IFERROR(subQ!X31/subQ!W31-1,"") | Y39: =IFERROR(subQ!Y31/subQ!X31-1,"") | AA39: =IFERROR(subQ!AA31/subQ!Y31-1,"") | AB39: =IFERROR(subQ!AB31/subQ!AA31-1,"") | AC39: 0 | AD39: 0 | AF39: 0 | AG39: 0 | AH39: 0 | AI39: 0 | AK39: 0 | AL39: 0 | AM39: 0 | AN39: 0
A40: drv:DPS | B40: abs | C40: DPS (가정, 원) | E40: =subQ!E34 | F40: =subQ!F34 | G40: =subQ!G34 | H40: =subQ!H34 | I40: =subQ!I34 | J40: =subQ!J34 | K40: =subQ!K34 | L40: =subQ!L34 | ... AB40: =subQ!AB34 | AD40: 0 | AE40: =subQ!AE34 | AI40: 0 | AJ40: =subQ!AJ34 | AN40: 0 | AO40: =subQ!AO34
B42: 3. 밸류에이션·스칼라 | C42: 노란 셀 = 가정. '연결' 표시는 추정 전 분기 수식이 이 셀을 참조한다는 뜻
...

Sheet BS연결
B1: (백만원) | C1: 이름: BS연결H | E1: 4Q21 | F1: 2021 | G1: 1Q22 | H1: 2Q22 | I1: 3Q22 | J1: 4Q22 | K1: 2022 | L1: 1Q23 | M1: 2Q23 | N1: 3Q23 | O1: 4Q23 | P1: 2023 | Q1: 1Q24 | R1: 2Q24 | S1: 3Q24 | T1: 4Q24 | U1: 2024 | V1: 1Q25 | W1: 2Q25 | X1: 3Q25 | Y1: 4Q25 | Z1: 2025 | AA1: 1Q26 | AB1: 2Q26 | AC1: 3Q26 | AD1: 4Q26 | AE1: 2026 | AF1: 1Q27 | AG1: 2Q27 | AH1: 3Q27 | AI1: 4Q27 | AJ1: 2027 | AK1: 1Q28 | AL1: 2Q28 | AM1: 3Q28 | AN1: 4Q28 | AO1: 2028
B2: 연결 | D2: fin json(kship_fin.py)
B3: STX엔진(연) | C3: UPDATE: 26-10-26 | E3: 1 | F3: 2 | G3: 3 | H3: 4 | I3: 5 | J3: 6 | K3: 7 | L3: 8 | M3: 9 | N3: 10 | O3: 11 | P3: 12 | Q3: 13 | R3: 14 | S3: 15 | T3: 16 | U3: 17 | V3: 18 | W3: 19 | X3: 20 | Y3: 21 | Z3: 22 | AA3: 23 | AB3: 24 | AC3: 25 | AD3: 26 | AE3: 27 | AF3: 28 | AG3: 29 | AH3: 30 | AI3: 31 | AJ3: 32 | AK3: 33 | AL3: 34 | AM3: 35 | AN3: 36 | AO3: 37
B4: Account Code | C4: AccountNAME | E4: 2021.12 | F4: 2021.12A | G4: 2022.03 | H4: 2022.06 | I4: 2022.09 | J4: 2022.12 | K4: 2022.12A | L4: 2023.03 | M4: 2023.06 | N4: 2023.09 | O4: 2023.12 | P4: 2023.12A | Q4: 2024.03 | R4: 2024.06 | S4: 2024.09 | T4: 2024.12 | U4: 2024.12A | V4: 2025.03 | W4: 2025.06 | X4: 2025.09 | Y4: 2025.12 | Z4: 2025.12A | AA4: 2026.03 | AB4: 2026.06 | AC4: 2026.09 | AD4: 2026.12 | AE4: 2026.12A | AF4: 2027.03 | AG4: 2027.06 | AH4: 2027.09 | AI4: 2027.12 | AJ4: 2027.12A | AK4: 2028.03 | AL4: 2028.06 | AM4: 2028.09 | AN4: 2028.12 | AO4: 2028.12A
A5: 1 | C5: 유동자산 | E5: 427101 | F5: 427101 | G5: 419659 | H5: 418966 | I5: 429083 | J5: 468460 | K5: 468460 | L5: 483477 | M5: 448281 | N5: 446925 | O5: 490899 | P5: 490899 | Q5: 573665 | R5: 596885 | S5: 572986 | T5: 555213.66 | U5: 555213.66 | V5: 525196.82 | W5: 635843.1 | X5: 671710.7 | Y5: 727075.77 | Z5: 727075.77 | AA5: 774506.29 | AB5: 780031.12
A6: 1 | C6: 현금및현금성자산 | E6: 104687 | F6: 104687 | G6: 109517 | H6: 76889 | I6: 56648 | J6: 88277 | K6: 88277 | L6: 63412 | M6: 71516 | N6: 57911 | O6: 86616 | P6: 86616 | Q6: 105211 | R6: 101695 | S6: 98619 | T6: 131440.92 | U6: 131440.92 | V6: 44331.39 | W6: 109016.06 | X6: 167149.21 | Y6: 164134.33 | Z6: 164134.33 | AA6: 110270.44 | AB6: 114235.36
A7: 1 | C7: 기타유동금융자산 | E7: 1869 | F7: 1869 | G7: 1347 | H7: 1937 | I7: 1970 | L7: 9311 | M7: 369 | N7: 246
A8: 1 | C8: 매출채권및기타채권 | E8: 93506 | F8: 93506 | G8: 71354 | H8: 73359 | I8: 96141 | J8: 110235 | K8: 110235 | L8: 112722 | M8: 104788 | N8: 105637 | O8: 136635 | P8: 136635 | Q8: 101290 | R8: 124273 | S8: 124231 | T8: 91585.37 | U8: 91585.37 | V8: 101167.75 | W8: 141419.58 | X8: 99833.51 | Y8: 141748.29 | Z8: 141748.29 | AA8: 184178.49 | AB8: 137930.07
A9: 1 | C9: 계약자산 | E9: 16551 | F9: 16551 | G9: 16412 | H9: 17722 | I9: 17708 | J9: 12431 | K9: 12431 | L9: 18008 | M9: 15161 | N9: 14888 | O9: 6051 | P9: 6051 | Q9: 8170 | R9: 8362 | S9: 12439 | T9: 10372.02 | U9: 10372.02 | V9: 14089.45 | W9: 14583.59 | X9: 19223.46 | Y9: 24268.64 | Z9: 24268.64 | AA9: 32917.99 | AB9: 40432.66
A10: 1 | C10: 선급금 | E10: 22378 | F10: 22378 | G10: 37854 | H10: 39056 | I10: 35255 | J10: 47238 | K10: 47238 | L10: 55457 | M10: 59281 | N10: 54777 | O10: 53735 | P10: 53735 | Q10: 61152 | R10: 59737 | S10: 43214 | T10: 37270.7 | U10: 37270.7 | V10: 43594.87 | W10: 59011.95 | X10: 82649.35 | Y10: 45267.19 | Z10: 45267.19 | AA10: 67291.79 | AB10: 69367.13
A11: 1 | C11: 선급금등 | E11: 22378 | F11: 22378 | G11: 37854 | H11: 39056 | I11: 35255 | J11: 47238 | K11: 47238 | L11: 55457 | M11: 59281 | N11: 54777 | O11: 53735 | P11: 53735 | Q11: 61152 | R11: 59737 | S11: 43214 | T11: 37270.7 | U11: 37270.7 | V11: 43594.87 | W11: 59011.95 | X11: 82649.35 | Y11: 45267.19 | Z11: 45267.19 | AA11: 67291.79 | AB11: 69367.13
A12: 1 | C12: 기타유동자산 | E12: 28491 | F12: 28491 | G12: 43066 | H12: 45573 | I12: 40730 | J12: 47238 | K12: 47238 | L12: 60042 | M12: 63155 | N12: 59037 | O12: 53735 | P12: 53735 | Q12: 61152 | R12: 59737 | S12: 43214 | T12: 37270.7 | U12: 37270.7 | V12: 43594.87 | W12: 59011.95 | X12: 82649.35 | Y12: 45267.19 | Z12: 45267.19 | AA12: 67291.79 | AB12: 69367.13
A13: 1 | C13: 재고자산 | E13: 181566 | F13: 181566 | G13: 176620 | H13: 197952 | I13: 204463 | J13: 188620 | K13: 188620 | L13: 216215 | M13: 191044 | N13: 208383 | O13: 205831 | P13: 205831 | Q13: 292688 | R13: 299546 | S13: 289626 | T13: 276995.24 | U13: 276995.24 | V13: 316005.61 | W13: 303625.35 | X13: 295599.49 | Y13: 337393.7 | Z13: 337393.7 | AA13: 360422.92 | AB13: 396142.96
A14: 1 | C14: 당기법인세자산(선급법인세) | E14: 81 | F14: 81 | G14: 35 | H14: 58 | I14: 30 | J14: 161 | K14: 161 | L14: 576 | M14: 592 | N14: 662 | O14: 338 | P14: 338 | Q14: 449 | R14: 235 | S14: 113 | T14: 89.04 | U14: 89.04 | V14: 202.74 | Y14: 0 | Z14: 0
A15: 1 | C15: 유동확정계약자산 | E15: 350 | F15: 350 | G15: 1308 | H15: 5476 | I15: 11393 | J15: 3636 | K15: 3636 | L15: 3034 | M15: 1652 | N15: 161 | T15: 0 | U15: 0
A16: 1 | C16: 단기금융자산 | E16: 350 | F16: 350 | G16: 1308 | H16: 5476 | I16: 11393 | J16: 13435 | K16: 13435 | L16: 3191 | M16: 1656 | N16: 161 | O16: 246 | P16: 246 | Q16: 265 | R16: 631 | S16: 304 | T16: 2099.22 | U16: 2099.22 | V16: 2970.12 | W16: 2591.2 | X16: 2267.23 | Y16: 7272.27 | Z16: 7272.27 | AA16: 14347.17 | AB16: 14513.68
A17: 1 | C17: 비유동자산 | E17: 410379 | F17: 410379 | G17: 410733 | H17: 424700 | I17: 414494 | J17: 384928 | K17: 384928 | L17: 383836 | M17: 397592 | N17: 394369 | O17: 408235 | P17: 408235 | Q17: 400160 | R17: 397844 | S17: 407675 | T17: 413596.78 | U17: 413596.78 | V17: 421271 | W17: 418959.12 | X17: 426031.29 | Y17: 430459.27 | Z17: 430459.27 | AA17: 435031.3 | AB17: 435088.73
A18: 1 | C18: 유형자산 | E18: 294844 | F18: 294844 | G18: 295003 | H18: 294595 | I18: 293592 | J18: 277601 | K18: 277601 | L18: 276311 | M18: 276022 | N18: 276121 | O18: 276836 | P18: 276836 | Q18: 275194 | R18: 275524 | S18: 275750 | T18: 276213.39 | U18: 276213.39 | V18: 274955.99 | W18: 274865.01 | X18: 274481.36 | Y18: 279161.3 | Z18: 279161.3 | AA18: 278468.27 | AB18: 277656.07
A19: 1 | C19: 무형자산 | E19: 10813 | F19: 10813 | G19: 10622 | H19: 10628 | I19: 4927 | J19: 8804 | K19: 8804 | L19: 8740 | M19: 13881 | N19: 14115 | O19: 15207 | P19: 15207 | Q19: 15260 | R19: 16402 | S19: 19723 | T19: 22836.62 | U19: 22836.62 | V19: 24197.62 | W19: 24870.96 | X19: 27837.23 | Y19: 28831.72 | Z19: 28831.72 | AA19: 28307.74 | AB19: 28571.1
A20: 1 | C20: 투자부동산 | E20: 58779 | F20: 58779 | G20: 58343 | H20: 57907 | I20: 57471 | J20: 57035 | K20: 57035 | L20: 56599 | M20: 56164 | N20: 55728 | O20: 55292 | P20: 55292 | Q20: 54856 | R20: 54420 | S20: 53985 | T20: 53548.82 | U20: 53548.82 | V20: 53113.02 | W20: 52677.22 | X20: 52241.42 | Y20: 51805.62 | Z20: 51805.62 | AA20: 51369.82 | AB20: 50934.02
A21: 1 | C21: 장기매출채권및기타채권 | E21: 6806 | F21: 6806 | G21: 6977 | H21: 5599 | I21: 5417 | J21: 3884 | K21: 3884 | L21: 2004 | M21: 3480 | N21: 2243 | O21: 3617 | P21: 3617 | Q21: 1050 | R21: 3586 | S21: 2431 | T21: 582.2 | U21: 582.2 | V21: 484.9 | W21: 484.9 | X21: 484.9 | Y21: 222.04 | Z21: 222.04 | AA21: 222.04 | AB21: 222.04
A22: 1 | C22: 비유동확정계약자산 | E22: 116 | F22: 116 | G22: 137 | H22: 309
A23: 1 | C23: 투자자산 | E23: 116 | F23: 116 | G23: 137 | H23: 309 | J23: 7908 | K23: 7908 | O23: 8544 | P23: 8544 | Q23: 8493 | R23: 8865 | S23: 8865 | T23: 9170.53 | U23: 9170.53 | V23: 9194 | W23: 10943.74 | X23: 12875.88 | Y23: 12966.37 | Z23: 12966.37 | AA23: 13432.55 | AB23: 13057.94
A24: 1 | C24: 기타비유동자산 | E24: 27855 | F24: 27855 | G24: 28532 | H24: 45285 | I24: 45058 | J24: 27933 | K24: 27933 | L24: 30592 | M24: 37897 | N24: 36049 | O24: 46788 | P24: 46788 | Q24: 43327 | R24: 37118 | S24: 44856 | T24: 47670.29 | U24: 47670.29 | V24: 55623.46 | W24: 51532.58 | X24: 54032.38 | Y24: 54407.5 | Z24: 54407.5 | AA24: 60106.78 | AB24: 61512.53
A25: 1 | C25: 자산총계 | E25: 837480 | F25: 837480 | G25: 830392 | H25: 843666 | I25: 843577 | J25: 853388 | K25: 853388 | L25: 867313 | M25: 845873 | N25: 841294 | O25: 899134 | P25: 899134 | Q25: 973825 | R25: 994729 | S25: 980661 | T25: 968810.44 | U25: 968810.44 | V25: 946467.82 | W25: 1054802.2 | X25: 1097742 | Y25: 1157535 | Z25: 1157535 | AA25: 1209537.6 | AB25: 1215119.9
A26: 1 | C26: 유동부채 | E26: 490794 | F26: 490794 | G26: 485500 | H26: 499331 | I26: 508648 | J26: 539906 | K26: 539906 | L26: 555109 | M26: 531035 | N26: 525406 | O26: 577722 | P26: 577722 | Q26: 650598 | R26: 655142 | S26: 638608 | T26: 628413.77 | U26: 628413.77 | V26: 592952.6 | W26: 670122.46 | X26: 696259.97 | Y26: 744923.47 | Z26: 744923.47 | AA26: 779610.83 | AB26: 762086.76
A27: 1 | C27: 매입채무및기타채무 | E27: 73675 | F27: 73675 | G27: 74364 | H27: 75215 | I27: 69718 | J27: 117660 | K27: 117660 | L27: 103041 | M27: 98226 | N27: 104555 | O27: 132747 | P27: 132747 | Q27: 126425 | R27: 117556 | S27: 110425 | T27: 134985.47 | U27: 134985.47 | V27: 122331.51 | W27: 111544.62 | X27: 107069.3 | Y27: 162339.59 | Z27: 162339.59 | AA27: 121590.24 | AB27: 117415.48
A28: 1 | C28: 단기차입금 | E28: 258774 | F28: 258774 | G28: 245826 | H28: 234164 | I28: 239521 | J28: 237830 | K28: 237830 | L28: 251122 | M28: 244348 | N28: 245130 | O28: 259304 | P28: 259304 | Q28: 299177 | R28: 324065 | S28: 328481 | T28: 312315.66 | U28: 312315.66 | V28: 282732.55 | W28: 294527.04 | X28: 306662.23 | Y28: 311529.62 | Z28: 311529.62 | AA28: 351081.7 | AB28: 343225.74
A29: 1 | C29: 선수금 | E29: 115626 | F29: 115626 | G29: 127445 | H29: 143159 | I29: 149799 | J29: 148760 | K29: 148760 | L29: 172442 | M29: 154229 | N29: 145822 | O29: 165492 | P29: 165492 | Q29: 201790 | R29: 185409 | S29: 174218 | T29: 153797.27 | U29: 153797.27 | V29: 157194.14 | W29: 228975.9 | X29: 254095.51 | Y29: 246853.68 | Z29: 246853.68 | AA29: 284936.28 | AB29: 274435.18
A30: 1 | C30: 기타유동부채 | E30: 134856 | F30: 134856 | G30: 144778 | H30: 157926 | I30: 165101 | J30: 148760 | K30: 148760 | L30: 172442 | M30: 154346 | N30: 145922 | O30: 165492 | P30: 165492 | Q30: 201790 | R30: 185409 | S30: 174218 | T30: 153797.27 | U30: 153797.27 | V30: 157194.14 | W30: 228975.9 | X30: 254095.51 | Y30: 246853.68 | Z30: 246853.68 | AA30: 284936.28 | AB30: 274435.18
A31: 1 | C31: 계약부채 | E31: 19819 | F31: 19819 | G31: 15981 | H31: 23164 | I31: 21926 | J31: 22131 | K31: 22131 | L31: 17119 | M31: 25586 | N31: 22713 | O31: 13439 | P31: 13439 | Q31: 19077 | R31: 23427 | S31: 20654 | T31: 21720.44 | U31: 21720.44 | V31: 26179.81 | W31: 29457.74 | X31: 22200.95 | Y31: 16414.21 | Z31: 16414.21 | AA31: 14563.47 | AB31: 18282.17
A32: 1 | C32: 단기충당부채 | E32: 3350 | F32: 3350 | G32: 3248 | H32: 3556 | I32: 3582 | J32: 7638 | K32: 7638 | L32: 6994 | M32: 7057 | N32: 6817 | O32: 5455 | P32: 5455 | Q32: 3799 | R32: 3913 | S32: 4067 | T32: 4096.2 | U32: 4096.2 | V32: 3702.52 | W32: 4768.62 | X32: 5357.8 | Y32: 6030.41 | Z32: 6030.41 | AA32: 6053.63 | AB32: 6813.49
A33: 1 | C33: 단기파생상품부채 | E33: 320 | F33: 320 | G33: 1303 | H33: 5086 | I33: 8800 | J33: 5099 | K33: 5099 | L33: 3750 | M33: 1472 | N33: 269 | S33: 67 | T33: 0 | U33: 0 | W33: 136.47 | Y33: 365.37 | Z33: 365.37 | AA33: 340.01 | AB33: 113.4
A34: 1 | C34: 단기금융부채 | E34: 320 | F34: 320 | G34: 1303 | H34: 5086 | I34: 8800 | J34: 5099 | K34: 5099 | L34: 3750 | M34: 1472 | N34: 269 | S34: 67 | T34: 0 | U34: 0 | W34: 136.47 | Y34: 365.37 | Z34: 365.37 | AA34: 340.01 | AB34: 113.4
A35: 1 | C35: 비유동부채 | E35: 62711 | F35: 62711 | G35: 63980 | H35: 65384 | I35: 64134 | J35: 53237 | K35: 53237 | L35: 54695 | M35: 55653 | N35: 56884 | O35: 61778 | P35: 61778 | Q35: 63017 | R35: 64959 | S35: 68478 | T35: 63826.9 | U35: 63826.9 | V35: 68180.18 | W35: 69631.87 | X35: 70886.72 | Y35: 69640.48 | Z35: 69640.48 | AA35: 69514.3 | AB35: 70097.79
A36: 1 | C36: 확정급여부채 | E36: 37822 | F36: 37822 | G36: 38382 | H36: 39270 | I36: 39628 | J36: 31428 | K36: 31428 | L36: 32304 | M36: 33129 | N36: 33653 | O36: 35753 | P36: 35753 | Q36: 36629 | R36: 37141 | S36: 38123 | T36: 38703.49 | U36: 38703.49 | V36: 39698.49 | W36: 40688.94 | X36: 41679.69 | Y36: 41792.43 | Z36: 41792.43 | AA36: 42881.13 | AB36: 43871.59
A37: 1 | C37: 이연법인세부채 | E37: 19326 | F37: 19326 | G37: 19581 | H37: 19234 | I37: 17225 | J37: 15323 | K37: 15323 | L37: 15651 | M37: 15811 | N37: 16079 | O37: 18509 | P37: 18509 | Q37: 18509 | R37: 18360 | S37: 18444 | T37: 12296.12 | U37: 12296.12 | V37: 12078.9 | W37: 12011.73 | X37: 11986.17 | Y37: 3948.84 | Z37: 3948.84 | AA37: 2842 | AB37: 2711.72
A38: 1 | C38: 장기충당부채 | E38: 365 | F38: 365 | G38: 400
A39: 1 | C39: 장기파생상품부채 | E39: 152 | F39: 152 | G39: 133 | H39: 308
A40: 1 | C40: 장기금융부채 | E40: 152 | F40: 152 | G40: 133 | H40: 308
...

Sheet BS별도
B1: (백만원) | C1: 이름: BS별도H | E1: 4Q21 | F1: 2021 | G1: 1Q22 | H1: 2Q22 | I1: 3Q22 | J1: 4Q22 | K1: 2022 | L1: 1Q23 | M1: 2Q23 | N1: 3Q23 | O1: 4Q23 | P1: 2023 | Q1: 1Q24 | R1: 2Q24 | S1: 3Q24 | T1: 4Q24 | U1: 2024 | V1: 1Q25 | W1: 2Q25 | X1: 3Q25 | Y1: 4Q25 | Z1: 2025 | AA1: 1Q26 | AB1: 2Q26 | AC1: 3Q26 | AD1: 4Q26 | AE1: 2026 | AF1: 1Q27 | AG1: 2Q27 | AH1: 3Q27 | AI1: 4Q27 | AJ1: 2027 | AK1: 1Q28 | AL1: 2Q28 | AM1: 3Q28 | AN1: 4Q28 | AO1: 2028
B2: 별도 | D2: fin json(kship_fin.py)
B3: STX엔진(별) | C3: UPDATE: 26-10-26 | E3: 1 | F3: 2 | G3: 3 | H3: 4 | I3: 5 | J3: 6 | K3: 7 | L3: 8 | M3: 9 | N3: 10 | O3: 11 | P3: 12 | Q3: 13 | R3: 14 | S3: 15 | T3: 16 | U3: 17 | V3: 18 | W3: 19 | X3: 20 | Y3: 21 | Z3: 22 | AA3: 23 | AB3: 24 | AC3: 25 | AD3: 26 | AE3: 27 | AF3: 28 | AG3: 29 | AH3: 30 | AI3: 31 | AJ3: 32 | AK3: 33 | AL3: 34 | AM3: 35 | AN3: 36 | AO3: 37
B4: Account Code | C4: AccountNAME | E4: 2021.12 | F4: 2021.12A | G4: 2022.03 | H4: 2022.06 | I4: 2022.09 | J4: 2022.12 | K4: 2022.12A | L4: 2023.03 | M4: 2023.06 | N4: 2023.09 | O4: 2023.12 | P4: 2023.12A | Q4: 2024.03 | R4: 2024.06 | S4: 2024.09 | T4: 2024.12 | U4: 2024.12A | V4: 2025.03 | W4: 2025.06 | X4: 2025.09 | Y4: 2025.12 | Z4: 2025.12A | AA4: 2026.03 | AB4: 2026.06 | AC4: 2026.09 | AD4: 2026.12 | AE4: 2026.12A | AF4: 2027.03 | AG4: 2027.06 | AH4: 2027.09 | AI4: 2027.12 | AJ4: 2027.12A | AK4: 2028.03 | AL4: 2028.06 | AM4: 2028.09 | AN4: 2028.12 | AO4: 2028.12A
A5: 1 | C5: 유동자산 | E5: 405872 | F5: 405872 | G5: 400593 | H5: 400955 | I5: 411164 | J5: 452931 | K5: 452931 | L5: 467142 | M5: 430434 | N5: 426456 | O5: 473638 | P5: 473638 | Q5: 552266 | R5: 570673 | S5: 545197 | T5: 527154.66 | U5: 527154.66 | V5: 497251.45 | W5: 606147.76 | X5: 638990.13 | Y5: 698966.09 | Z5: 698966.09 | AA5: 743955.36 | AB5: 748842.33
A6: 1 | C6: 현금및현금성자산 | E6: 102715 | F6: 102715 | G6: 106855 | H6: 74388 | I6: 52061 | J6: 84255 | K6: 84255 | L6: 58442 | M6: 65990 | N6: 49445 | O6: 77545 | P6: 77545 | Q6: 98884 | R6: 96304 | S6: 88464 | T6: 122652.27 | U6: 122652.27 | V6: 36540.03 | W6: 101134.73 | X6: 156209.85 | Y6: 152795.42 | Z6: 152795.42 | AA6: 98302.8 | AB6: 100829.96
A7: 1 | C7: 기타유동금융자산 | E7: 1869 | F7: 1869 | G7: 1347 | H7: 1937 | I7: 1970 | L7: 9311 | M7: 369 | N7: 246
A8: 1 | C8: 매출채권및기타채권 | E8: 96356 | F8: 96356 | G8: 75272 | H8: 76904 | I8: 99940 | J8: 115691 | K8: 115691 | L8: 119120 | M8: 109020 | N8: 109440 | O8: 143338 | P8: 143338 | Q8: 101730 | R8: 121927 | S8: 124069 | T8: 91329.36 | U8: 91329.36 | V8: 99087.97 | W8: 137384.39 | X8: 97040.08 | Y8: 138447.21 | Z8: 138447.21 | AA8: 179257.1 | AB8: 134803.19
A9: 1 | C9: 계약자산 | E9: 3792 | F9: 3792 | G9: 5379 | H9: 8663 | I9: 10439 | J9: 7445 | K9: 7445 | L9: 14293 | M9: 13542 | N9: 13328 | O9: 6051 | P9: 6051 | Q9: 8170 | R9: 8362 | S9: 12439 | T9: 10372.02 | U9: 10372.02 | V9: 14089.45 | W9: 14583.59 | X9: 19223.46 | Y9: 24268.64 | Z9: 24268.64 | AA9: 32917.99 | AB9: 40291.51
A10: 1 | C10: 선급금 | E10: 21732 | F10: 21732 | G10: 36915 | H10: 38068 | I10: 34339 | J10: 45188 | K10: 45188 | L10: 53090 | M10: 55911 | N10: 52386 | O10: 50349 | P10: 50349 | Q10: 56958 | R10: 54450 | S10: 37909 | T10: 31880.82 | U10: 31880.82 | V10: 37975.62 | W10: 53600.66 | X10: 76966.04 | Y10: 45155.2 | Z10: 45155.2 | AA10: 66916.51 | AB10: 69202.67
A11: 1 | C11: 선급금등 | E11: 21732 | F11: 21732 | G11: 36915 | H11: 38068 | I11: 34339 | J11: 45188 | K11: 45188 | L11: 53090 | M11: 55911 | N11: 52386 | O11: 50349 | P11: 50349 | Q11: 56958 | R11: 54450 | S11: 37909 | T11: 31880.82 | U11: 31880.82 | V11: 37975.62 | W11: 53600.66 | X11: 76966.04 | Y11: 45155.2 | Z11: 45155.2 | AA11: 66916.51 | AB11: 69202.67
A12: 1 | C12: 기타유동자산 | E12: 27350 | F12: 27350 | G12: 41681 | H12: 44126 | I12: 39377 | J12: 45188 | K12: 45188 | L12: 57300 | M12: 59292 | N12: 56221 | O12: 50349 | P12: 50349 | Q12: 56958 | R12: 54450 | S12: 37909 | T12: 31880.82 | U12: 31880.82 | V12: 37975.62 | W12: 53600.66 | X12: 76966.04 | Y12: 45155.2 | Z12: 45155.2 | AA12: 66916.51 | AB12: 69202.67
A13: 1 | C13: 재고자산 | E13: 173359 | F13: 173359 | G13: 168716 | H13: 189403 | I13: 195954 | J13: 179148 | K13: 179148 | L13: 205238 | M13: 180378 | N13: 197356 | O13: 195192 | P13: 195192 | Q13: 282247 | R13: 287218 | S13: 278451 | T13: 265187.12 | U13: 265187.12 | V13: 304338.01 | W13: 292182.57 | X13: 283099.6 | Y13: 325059.44 | Z13: 325059.44 | AA13: 348560.66 | AB13: 383422.98
A14: 1 | C14: 당기법인세자산(선급법인세) | E14: 81 | F14: 81 | G14: 35 | H14: 58 | I14: 30 | J14: 161 | K14: 161 | L14: 247 | M14: 188 | N14: 259 | O14: 338 | P14: 338 | Q14: 449 | R14: 235 | S14: 113 | T14: 89.04 | U14: 89.04 | V14: 202.74 | W14: 0 | Y14: 0 | Z14: 0
A15: 1 | C15: 유동확정계약자산 | E15: 350 | F15: 350 | G15: 1308 | H15: 5476 | I15: 11393 | J15: 3636 | K15: 3636 | L15: 3034 | M15: 1652 | N15: 161 | T15: 0 | U15: 0
A16: 1 | C16: 단기금융자산 | E16: 350 | F16: 350 | G16: 1308 | H16: 5476 | I16: 11393 | J16: 13435 | K16: 13435 | L16: 3191 | M16: 1655 | N16: 161 | O16: 245 | P16: 245 | Q16: 265 | R16: 631 | S16: 304 | T16: 2099.22 | U16: 2099.22 | V16: 2970.12 | W16: 2591.2 | X16: 2267.23 | Y16: 7272.27 | Z16: 7272.27 | AA16: 14347.17 | AB16: 14513.68
A17: 1 | C17: 비유동자산 | E17: 417202 | F17: 417202 | G17: 415697 | H17: 428603 | I17: 416936 | J17: 384615 | K17: 384615 | L17: 382554 | M17: 395160 | N17: 392066 | O17: 406236 | P17: 406236 | Q17: 398393 | R17: 394807 | S17: 404991 | T17: 410535.95 | U17: 410535.95 | V17: 418370.24 | W17: 415470.15 | X17: 422774.1 | Y17: 426768.34 | Z17: 426768.34 | AA17: 431552.29 | AB17: 431810.94
A18: 1 | C18: 종속기업및관계기업투자 | E18: 480 | F18: 480 | G18: 480 | H18: 480 | I18: 480 | J18: 480 | K18: 480 | L18: 480 | M18: 480 | N18: 480 | O18: 480 | P18: 480 | Q18: 480 | R18: 480 | S18: 480 | T18: 480.39 | U18: 480.39 | V18: 480.39 | W18: 480.39 | X18: 480.39 | Y18: 480.39 | Z18: 480.39 | AA18: 480.39 | AB18: 480.39
A19: 1 | C19: 투자자산 | E19: 596 | F19: 596 | G19: 617 | H19: 790 | I19: 480 | J19: 8388 | K19: 8388 | L19: 480 | M19: 480 | N19: 480 | O19: 9024 | P19: 9024 | Q19: 8974 | R19: 9345 | S19: 9345 | T19: 9650.92 | U19: 9650.92 | V19: 9674.39 | W19: 11424.13 | X19: 13356.27 | Y19: 13446.76 | Z19: 13446.76 | AA19: 13912.94 | AB19: 13538.33
A20: 1 | C20: 유형자산 | E20: 293349 | F20: 293349 | G20: 292930 | H20: 292794 | I20: 291807 | J20: 275550 | K20: 275550 | L20: 274460 | M20: 274399 | N20: 274676 | O20: 275636 | P20: 275636 | Q20: 274203 | R20: 273470 | S20: 273899 | T20: 274013.18 | U20: 274013.18 | V20: 273009.95 | W20: 272162.08 | X20: 272041.99 | Y20: 276298.06 | Z20: 276298.06 | AA20: 275865.77 | AB20: 275361.54
A21: 1 | C21: 무형자산 | E21: 10813 | F21: 10813 | G21: 10622 | H21: 10628 | I21: 4927 | J21: 8804 | K21: 8804 | L21: 8741 | M21: 13881 | N21: 14115 | O21: 15207 | P21: 15207 | Q21: 15260 | R21: 16402 | S21: 19723 | T21: 22836.62 | U21: 22836.62 | V21: 24197.62 | W21: 24870.96 | X21: 27837.23 | Y21: 28831.72 | Z21: 28831.72 | AA21: 28307.74 | AB21: 28571.1
A22: 1 | C22: 투자부동산 | E22: 58778 | F22: 58778 | G22: 58343 | H22: 57907 | I22: 57471 | J22: 57035 | K22: 57035 | L22: 56599 | M22: 56164 | N22: 55728 | O22: 55292 | P22: 55292 | Q22: 54856 | R22: 54420 | S22: 53985 | T22: 53548.82 | U22: 53548.82 | V22: 53113.02 | W22: 52677.22 | X22: 52241.42 | Y22: 51805.62 | Z22: 51805.62 | AA22: 51369.82 | AB22: 50934.02
A23: 1 | C23: 장기매출채권및기타채권 | E23: 6806 | F23: 6806 | G23: 6976 | H23: 5599 | I23: 5417 | J23: 3884 | K23: 3884 | L23: 2004 | M23: 3480 | N23: 2243 | O23: 3618 | P23: 3618 | Q23: 1050 | R23: 3586 | S23: 2431 | T23: 582.2 | U23: 582.2 | V23: 484.9 | W23: 484.9 | X23: 484.9 | Y23: 222.04 | Z23: 222.04 | AA23: 222.04 | AB23: 222.04
A24: 1 | C24: 비유동확정계약자산 | E24: 116 | F24: 116 | G24: 137 | H24: 310
A25: 1 | C25: 기타비유동자산 | E25: 27720 | F25: 27720 | G25: 28401 | H25: 45162 | I25: 44950 | J25: 27933 | K25: 27933 | L25: 30583 | M25: 37889 | N25: 36041 | O25: 46788 | P25: 46788 | Q25: 43327 | R25: 37118 | S25: 44856 | T25: 47670.29 | U25: 47670.29 | V25: 55623.46 | W25: 51532.58 | X25: 54032.38 | Y25: 54407.5 | Z25: 54407.5 | AA25: 60106.78 | AB25: 61512.53
A26: 1 | C26: 자산총계 | E26: 823074 | F26: 823074 | G26: 816290 | H26: 829558 | I26: 828100 | J26: 837546 | K26: 837546 | L26: 849696 | M26: 825594 | N26: 818522 | O26: 879874 | P26: 879874 | Q26: 950659 | R26: 965480 | S26: 950188 | T26: 937690.62 | U26: 937690.62 | V26: 915621.69 | W26: 1021617.9 | X26: 1061764.2 | Y26: 1125734.4 | Z26: 1125734.4 | AA26: 1175507.6 | AB26: 1180653.3
A27: 1 | C27: 유동부채 | E27: 485167 | F27: 485167 | G27: 481597 | H27: 496193 | I27: 505630 | J27: 535074 | K27: 535074 | L27: 550972 | M27: 526597 | N27: 521090 | O27: 571394 | P27: 571394 | Q27: 642802 | R27: 645408 | S27: 628054 | T27: 617217.75 | U27: 617217.75 | V27: 582997.72 | W27: 660191.77 | X27: 685454.11 | Y27: 739416.83 | Z27: 739416.83 | AA27: 773946.48 | AB27: 757572.63
A28: 1 | C28: 매입채무및기타채무 | E28: 69062 | F28: 69062 | G28: 71709 | H28: 73414 | I28: 67827 | J28: 113827 | K28: 113827 | L28: 99870 | M28: 94831 | N28: 101280 | O28: 129153 | P28: 129153 | Q28: 122860 | R28: 113745 | S28: 106033 | T28: 130891.92 | U28: 130891.92 | V28: 119099.54 | W28: 108069.23 | X28: 103305.28 | Y28: 158154.38 | Z28: 158154.38 | AA28: 117403.29 | AB28: 114135.87
A29: 1 | C29: 단기차입금 | E29: 258774 | F29: 258774 | G29: 245826 | H29: 234164 | I29: 239521 | J29: 237830 | K29: 237830 | L29: 251122 | M29: 244348 | N29: 245130 | O29: 259304 | P29: 259304 | Q29: 299178 | R29: 324066 | S29: 328482 | T29: 312315.66 | U29: 312315.66 | V29: 282732.55 | W29: 294527.04 | X29: 306662.23 | Y29: 311529.62 | Z29: 311529.62 | AA29: 351081.7 | AB29: 343225.74
A30: 1 | C30: 선수금 | E30: 115116 | F30: 115116 | G30: 126961 | H30: 142740 | I30: 149380 | J30: 148334 | K30: 148334 | L30: 172073 | M30: 153302 | N30: 144849 | O30: 164569 | P30: 164569 | Q30: 201073 | R30: 184940 | S30: 173409 | T30: 152879.4 | U30: 152879.4 | V30: 156566.2 | W30: 228529.26 | X30: 253231.74 | Y30: 246226.99 | Z30: 246226.99 | AA30: 284238.47 | AB30: 273941.24
A31: 1 | C31: 기타유동부채 | E31: 133842 | F31: 133842 | G31: 143530 | H31: 156809 | I31: 163974 | J31: 148334 | K31: 148334 | L31: 172073 | M31: 153303 | N31: 144881 | O31: 164569 | P31: 164569 | Q31: 201073 | R31: 184940 | S31: 173409 | T31: 152879.4 | U31: 152879.4 | V31: 156566.2 | W31: 228529.26 | X31: 253231.74 | Y31: 246226.99 | Z31: 246226.99 | AA31: 284238.47 | AB31: 273941.24
A32: 1 | C32: 계약부채 | E32: 19819 | F32: 19819 | G32: 15981 | H32: 23164 | I32: 21926 | J32: 22131 | K32: 22131 | L32: 17119 | M32: 25586 | N32: 22713 | O32: 12408 | P32: 12408 | Q32: 15933 | R32: 18411 | S32: 15683 | T32: 16564.66 | U32: 16564.66 | V32: 20824.64 | W32: 24089.25 | X32: 16654.72 | Y32: 16414.21 | Z32: 16414.21 | AA32: 14540.06 | AB32: 18282.17
A33: 1 | C33: 단기충당부채 | E33: 3350 | F33: 3350 | G33: 3248 | H33: 3556 | I33: 3582 | J33: 7637 | K33: 7637 | L33: 6994 | M33: 7057 | N33: 6817 | O33: 5419 | P33: 5419 | Q33: 3758 | R33: 3868 | S33: 4025 | T33: 4057.78 | U33: 4057.78 | V33: 3652.06 | W33: 4718.02 | X33: 5313.64 | Y33: 5965.25 | Z33: 5965.25 | AA33: 5988.67 | AB33: 6742.73
A34: 1 | C34: 단기파생상품부채 | E34: 320 | F34: 320 | G34: 1303 | H34: 5086 | I34: 8800 | J34: 5099 | K34: 5099 | L34: 3750 | M34: 1472 | N34: 269 | S34: 67 | T34: 0 | U34: 0 | W34: 136.47 | Y34: 365.37 | Z34: 365.37 | AA34: 340.01 | AB34: 113.4
A35: 1 | C35: 단기금융부채 | E35: 320 | F35: 320 | G35: 1303 | H35: 5086 | I35: 8800 | J35: 5099 | K35: 5099 | L35: 3750 | M35: 1472 | N35: 269 | S35: 67 | T35: 0 | U35: 0 | W35: 136.47 | Y35: 365.37 | Z35: 365.37 | AA35: 340.01 | AB35: 113.4
A36: 1 | C36: 비유동부채 | E36: 62829 | F36: 62829 | G36: 63778 | H36: 65447 | I36: 64260 | J36: 52289 | K36: 52289 | L36: 53933 | M36: 55061 | N36: 56398 | O36: 61441 | P36: 61441 | Q36: 62779 | R36: 64063 | S36: 67717 | T36: 62949.37 | U36: 62949.37 | V36: 67459.88 | W36: 68297.7 | X36: 69769.71 | Y36: 68295.34 | Z36: 68295.34 | AA36: 68360.64 | AB36: 69118.28
A37: 1 | C37: 확정급여부채 | E37: 37822 | F37: 37822 | G37: 38382 | H37: 39270 | I37: 39628 | J37: 31428 | K37: 31428 | L37: 32304 | M37: 33129 | N37: 33653 | O37: 35753 | P37: 35753 | Q37: 36629 | R37: 37141 | S37: 38123 | T37: 38703.49 | U37: 38703.49 | V37: 39698.49 | W37: 40688.94 | X37: 41679.69 | Y37: 41792.43 | Z37: 41792.43 | AA37: 42881.13 | AB37: 43871.59
A38: 1 | C38: 이연법인세부채 | E38: 20151 | F38: 20151 | G38: 20439 | H38: 20124 | I38: 18129 | J38: 15323 | K38: 15323 | L38: 15650 | M38: 15811 | N38: 16080 | O38: 18509 | P38: 18509 | Q38: 18509 | R38: 18360 | S38: 18444 | T38: 12296.12 | U38: 12296.12 | V38: 12078.9 | W38: 12011.73 | X38: 11986.17 | Y38: 3948.84 | Z38: 3948.84 | AA38: 2842 | AB38: 2711.72
A39: 1 | C39: 장기충당부채 | E39: 364 | F39: 364 | G39: 400
A40: 1 | C40: 장기파생상품부채 | E40: 152 | F40: 152 | G40: 133 | H40: 308
...

Sheet subQ
A1: YQ | C1: subQ 분기 서브모델(억원, U=100) | E1: 4Q21 | F1: 2021 | G1: 1Q22 | H1: 2Q22 | I1: 3Q22 | J1: 4Q22 | K1: 2022 | L1: 1Q23 | M1: 2Q23 | N1: 3Q23 | O1: 4Q23 | P1: 2023 | Q1: 1Q24 | R1: 2Q24 | S1: 3Q24 | T1: 4Q24 | U1: 2024 | V1: 1Q25 | W1: 2Q25 | X1: 3Q25 | Y1: 4Q25 | Z1: 2025 | AA1: 1Q26 | AB1: 2Q26 | AC1: 3Q26 | AD1: 4Q26 | AE1: 2026 | AF1: 1Q27 | AG1: 2Q27 | AH1: 3Q27 | AI1: 4Q27 | AJ1: 2027 | AK1: 1Q28 | AL1: 2Q28 | AM1: 3Q28 | AN1: 4Q28 | AO1: 2028
A2: A=이름(key) B=그룹 C=단위 D=FnGuide 계정명(VLOOKUP 키). 확정=VLOOKUP(BS), 추정=변수 가정 참조
E3: 1 | F3: 2 | G3: 3 | H3: 4 | I3: 5 | J3: 6 | K3: 7 | L3: 8 | M3: 9 | N3: 10 | O3: 11 | P3: 12 | Q3: 13 | R3: 14 | S3: 15 | T3: 16 | U3: 17 | V3: 18 | W3: 19 | X3: 20 | Y3: 21 | Z3: 22 | AA3: 23 | AB3: 24 | AC3: 25 | AD3: 26 | AE3: 27 | AF3: 28 | AG3: 29 | AH3: 30 | AI3: 31 | AJ3: 32 | AK3: 33 | AL3: 34 | AM3: 35 | AN3: 36 | AO3: 37
E4: 2021.12 | F4: 2021.12A | G4: 2022.03 | H4: 2022.06 | I4: 2022.09 | J4: 2022.12 | K4: 2022.12A | L4: 2023.03 | M4: 2023.06 | N4: 2023.09 | O4: 2023.12 | P4: 2023.12A | Q4: 2024.03 | R4: 2024.06 | S4: 2024.09 | T4: 2024.12 | U4: 2024.12A | V4: 2025.03 | W4: 2025.06 | X4: 2025.09 | Y4: 2025.12 | Z4: 2025.12A | AA4: 2026.03 | AB4: 2026.06 | AC4: 2026.09 | AD4: 2026.12 | AE4: 2026.12A | AF4: 2027.03 | AG4: 2027.06 | AH4: 2027.09 | AI4: 2027.12 | AJ4: 2027.12A | AK4: 2028.03 | AL4: 2028.06 | AM4: 2028.09 | AN4: 2028.12 | AO4: 2028.12A
A5: 매출액 | B5: 손익 | C5: 억원 | D5: 매출액(수익) | E5: =IFERROR(VLOOKUP($D5,BS연결,MATCH(E$1,BS연결H,0),0)/100,"") | G5: =IFERROR(VLOOKUP($D5,BS연결,MATCH(G$1,BS연결H,0),0)/100,"") | H5: =IFERROR(VLOOKUP($D5,BS연결,MATCH(H$1,BS연결H,0),0)/100,"") | I5: =IFERROR(VLOOKUP($D5,BS연결,MATCH(I$1,BS연결H,0),0)/100,"") | J5: =IFERROR(VLOOKUP($D5,BS연결,MATCH(J$1,BS연결H,0),0)/100,"") | K5: =IFERROR(VLOOKUP($D5,BS연결,MATCH(K$1,BS연결H,0),0)/100,"") | L5: =IFERROR(VLOOKUP($D5,BS연결,MATCH(L$1,BS연결H,0),0)/100,"") | M5: =IFERROR(VLOOKUP($D5,BS연결,MATCH(M$1,BS연결H,0),0)/100,"") | N5: =IFERROR(VLOOKUP($D5,BS연결,MATCH(N$1,BS연결H,0),0)/100,"") | ... AB5: =IFERROR(VLOOKUP($D5,BS연결,MATCH(AB$1,BS연결H,0),0)/100,"") | AC5: =IFERROR(X5*(1+변수!AC21),"") | AD5: =IFERROR(Y5*(1+변수!AD21),"") | AE5: =SUM(AA5:AD5) | AF5: =IFERROR(AA5*(1+변수!AF21),"") | AG5: =IFERROR(AB5*(1+변수!AG21),"") | AH5: =IFERROR(AC5*(1+변수!AH21),"") | AI5: =IFERROR(AD5*(1+변수!AI21),"") | AJ5: =SUM(AF5:AI5) | AK5: =IFERROR(AF5*(1+변수!AK21),"") | AL5: =IFERROR(AG5*(1+변수!AL21),"") | AM5: =IFERROR(AH5*(1+변수!AM21),"") | AN5: =IFERROR(AI5*(1+변수!AN21),"") | AO5: =SUM(AK5:AN5)
A6: 매출원가 | B6: 손익 | C6: 억원 | D6: 매출원가 | E6: =IFERROR(VLOOKUP($D6,BS연결,MATCH(E$1,BS연결H,0),0)/100,"") | G6: =IFERROR(VLOOKUP($D6,BS연결,MATCH(G$1,BS연결H,0),0)/100,"") | H6: =IFERROR(VLOOKUP($D6,BS연결,MATCH(H$1,BS연결H,0),0)/100,"") | I6: =IFERROR(VLOOKUP($D6,BS연결,MATCH(I$1,BS연결H,0),0)/100,"") | J6: =IFERROR(VLOOKUP($D6,BS연결,MATCH(J$1,BS연결H,0),0)/100,"") | K6: =IFERROR(VLOOKUP($D6,BS연결,MATCH(K$1,BS연결H,0),0)/100,"") | L6: =IFERROR(VLOOKUP($D6,BS연결,MATCH(L$1,BS연결H,0),0)/100,"") | M6: =IFERROR(VLOOKUP($D6,BS연결,MATCH(M$1,BS연결H,0),0)/100,"") | N6: =IFERROR(VLOOKUP($D6,BS연결,MATCH(N$1,BS연결H,0),0)/100,"") | ... AB6: =IFERROR(VLOOKUP($D6,BS연결,MATCH(AB$1,BS연결H,0),0)/100,"") | AC6: =IFERROR(AC5-AC7,"") | AD6: =IFERROR(AD5-AD7,"") | AE6: =SUM(AA6:AD6) | AF6: =IFERROR(AF5-AF7,"") | AG6: =IFERROR(AG5-AG7,"") | AH6: =IFERROR(AH5-AH7,"") | AI6: =IFERROR(AI5-AI7,"") | AJ6: =SUM(AF6:AI6) | AK6: =IFERROR(AK5-AK7,"") | AL6: =IFERROR(AL5-AL7,"") | AM6: =IFERROR(AM5-AM7,"") | AN6: =IFERROR(AN5-AN7,"") | AO6: =SUM(AK6:AN6)
A7: 매출총이익 | B7: 손익 | C7: 억원 | D7: 매출총이익 | E7: =IFERROR(VLOOKUP($D7,BS연결,MATCH(E$1,BS연결H,0),0)/100,"") | G7: =IFERROR(VLOOKUP($D7,BS연결,MATCH(G$1,BS연결H,0),0)/100,"") | H7: =IFERROR(VLOOKUP($D7,BS연결,MATCH(H$1,BS연결H,0),0)/100,"") | I7: =IFERROR(VLOOKUP($D7,BS연결,MATCH(I$1,BS연결H,0),0)/100,"") | J7: =IFERROR(VLOOKUP($D7,BS연결,MATCH(J$1,BS연결H,0),0)/100,"") | K7: =IFERROR(VLOOKUP($D7,BS연결,MATCH(K$1,BS연결H,0),0)/100,"") | L7: =IFERROR(VLOOKUP($D7,BS연결,MATCH(L$1,BS연결H,0),0)/100,"") | M7: =IFERROR(VLOOKUP($D7,BS연결,MATCH(M$1,BS연결H,0),0)/100,"") | N7: =IFERROR(VLOOKUP($D7,BS연결,MATCH(N$1,BS연결H,0),0)/100,"") | ... AB7: =IFERROR(VLOOKUP($D7,BS연결,MATCH(AB$1,BS연결H,0),0)/100,"") | AC7: =IFERROR(AC9+AC8,"") | AD7: =IFERROR(AD9+AD8,"") | AE7: =SUM(AA7:AD7) | AF7: =IFERROR(AF9+AF8,"") | AG7: =IFERROR(AG9+AG8,"") | AH7: =IFERROR(AH9+AH8,"") | AI7: =IFERROR(AI9+AI8,"") | AJ7: =SUM(AF7:AI7) | AK7: =IFERROR(AK9+AK8,"") | AL7: =IFERROR(AL9+AL8,"") | AM7: =IFERROR(AM9+AM8,"") | AN7: =IFERROR(AN9+AN8,"") | AO7: =SUM(AK7:AN7)
A8: 판관비 | B8: 손익 | C8: 억원 | D8: 판관비 | E8: =IFERROR(VLOOKUP($D8,BS연결,MATCH(E$1,BS연결H,0),0)/100,"") | G8: =IFERROR(VLOOKUP($D8,BS연결,MATCH(G$1,BS연결H,0),0)/100,"") | H8: =IFERROR(VLOOKUP($D8,BS연결,MATCH(H$1,BS연결H,0),0)/100,"") | I8: =IFERROR(VLOOKUP($D8,BS연결,MATCH(I$1,BS연결H,0),0)/100,"") | J8: =IFERROR(VLOOKUP($D8,BS연결,MATCH(J$1,BS연결H,0),0)/100,"") | K8: =IFERROR(VLOOKUP($D8,BS연결,MATCH(K$1,BS연결H,0),0)/100,"") | L8: =IFERROR(VLOOKUP($D8,BS연결,MATCH(L$1,BS연결H,0),0)/100,"") | M8: =IFERROR(VLOOKUP($D8,BS연결,MATCH(M$1,BS연결H,0),0)/100,"") | N8: =IFERROR(VLOOKUP($D8,BS연결,MATCH(N$1,BS연결H,0),0)/100,"") | ... AB8: =IFERROR(VLOOKUP($D8,BS연결,MATCH(AB$1,BS연결H,0),0)/100,"") | AC8: =IFERROR(AC5*변수!AC22,"") | AD8: =IFERROR(AD5*변수!AD22,"") | AE8: =SUM(AA8:AD8) | AF8: =IFERROR(AF5*변수!AF22,"") | AG8: =IFERROR(AG5*변수!AG22,"") | AH8: =IFERROR(AH5*변수!AH22,"") | AI8: =IFERROR(AI5*변수!AI22,"") | AJ8: =SUM(AF8:AI8) | AK8: =IFERROR(AK5*변수!AK22,"") | AL8: =IFERROR(AL5*변수!AL22,"") | AM8: =IFERROR(AM5*변수!AM22,"") | AN8: =IFERROR(AN5*변수!AN22,"") | AO8: =SUM(AK8:AN8)
A9: 영업이익 | B9: 손익 | C9: 억원 | D9: 영업이익 | E9: =IFERROR(VLOOKUP($D9,BS연결,MATCH(E$1,BS연결H,0),0)/100,"") | G9: =IFERROR(VLOOKUP($D9,BS연결,MATCH(G$1,BS연결H,0),0)/100,"") | H9: =IFERROR(VLOOKUP($D9,BS연결,MATCH(H$1,BS연결H,0),0)/100,"") | I9: =IFERROR(VLOOKUP($D9,BS연결,MATCH(I$1,BS연결H,0),0)/100,"") | J9: =IFERROR(VLOOKUP($D9,BS연결,MATCH(J$1,BS연결H,0),0)/100,"") | K9: =IFERROR(VLOOKUP($D9,BS연결,MATCH(K$1,BS연결H,0),0)/100,"") | L9: =IFERROR(VLOOKUP($D9,BS연결,MATCH(L$1,BS연결H,0),0)/100,"") | M9: =IFERROR(VLOOKUP($D9,BS연결,MATCH(M$1,BS연결H,0),0)/100,"") | N9: =IFERROR(VLOOKUP($D9,BS연결,MATCH(N$1,BS연결H,0),0)/100,"") | ... AB9: =IFERROR(VLOOKUP($D9,BS연결,MATCH(AB$1,BS연결H,0),0)/100,"") | AC9: =IFERROR(AC5*변수!AC23,"") | AD9: =IFERROR(AD5*변수!AD23,"") | AE9: =SUM(AA9:AD9) | AF9: =IFERROR(AF5*변수!AF23,"") | AG9: =IFERROR(AG5*변수!AG23,"") | AH9: =IFERROR(AH5*변수!AH23,"") | AI9: =IFERROR(AI5*변수!AI23,"") | AJ9: =SUM(AF9:AI9) | AK9: =IFERROR(AK5*변수!AK23,"") | AL9: =IFERROR(AL5*변수!AL23,"") | AM9: =IFERROR(AM5*변수!AM23,"") | AN9: =IFERROR(AN5*변수!AN23,"") | AO9: =SUM(AK9:AN9)
A10: OPM | B10: 손익 | C10: % | D10: 영업이익률 | E10: =IFERROR(E9/E5,"") | G10: =IFERROR(G9/G5,"") | H10: =IFERROR(H9/H5,"") | I10: =IFERROR(I9/I5,"") | J10: =IFERROR(J9/J5,"") | K10: =IFERROR(K9/K5,"") | L10: =IFERROR(L9/L5,"") | M10: =IFERROR(M9/M5,"") | N10: =IFERROR(N9/N5,"") | ... AO10: =IFERROR(AO9/AO5,"")
A11: 금융손익 | B11: 손익 | C11: 억원 | D11: 금융손익 | E11: =IFERROR(VLOOKUP($D11,BS연결,MATCH(E$1,BS연결H,0),0)/100,"") | G11: =IFERROR(VLOOKUP($D11,BS연결,MATCH(G$1,BS연결H,0),0)/100,"") | H11: =IFERROR(VLOOKUP($D11,BS연결,MATCH(H$1,BS연결H,0),0)/100,"") | I11: =IFERROR(VLOOKUP($D11,BS연결,MATCH(I$1,BS연결H,0),0)/100,"") | J11: =IFERROR(VLOOKUP($D11,BS연결,MATCH(J$1,BS연결H,0),0)/100,"") | K11: =IFERROR(VLOOKUP($D11,BS연결,MATCH(K$1,BS연결H,0),0)/100,"") | L11: =IFERROR(VLOOKUP($D11,BS연결,MATCH(L$1,BS연결H,0),0)/100,"") | M11: =IFERROR(VLOOKUP($D11,BS연결,MATCH(M$1,BS연결H,0),0)/100,"") | N11: =IFERROR(VLOOKUP($D11,BS연결,MATCH(N$1,BS연결H,0),0)/100,"") | ... AB11: =IFERROR(VLOOKUP($D11,BS연결,MATCH(AB$1,BS연결H,0),0)/100,"") | AC11: =IFERROR(AC12+AC13+AC14+AC15,"") | AD11: =IFERROR(AD12+AD13+AD14+AD15,"") | AE11: =SUM(AA11:AD11) | AF11: =IFERROR(AF12+AF13+AF14+AF15,"") | AG11: =IFERROR(AG12+AG13+AG14+AG15,"") | AH11: =IFERROR(AH12+AH13+AH14+AH15,"") | AI11: =IFERROR(AI12+AI13+AI14+AI15,"") | AJ11: =SUM(AF11:AI11) | AK11: =IFERROR(AK12+AK13+AK14+AK15,"") | AL11: =IFERROR(AL12+AL13+AL14+AL15,"") | AM11: =IFERROR(AM12+AM13+AM14+AM15,"") | AN11: =IFERROR(AN12+AN13+AN14+AN15,"") | AO11: =SUM(AK11:AN11)
A12: 이자손익 | B12: 손익 | C12: 억원 | D12: 이자손익 | K12: =SUM(G12:J12) | P12: =SUM(L12:O12) | U12: =SUM(Q12:T12) | V12: =IFERROR(VLOOKUP($D12,BS연결,MATCH(V$1,BS연결H,0),0)/100,"") | W12: =IFERROR(VLOOKUP($D12,BS연결,MATCH(W$1,BS연결H,0),0)/100,"") | X12: =IFERROR(VLOOKUP($D12,BS연결,MATCH(X$1,BS연결H,0),0)/100,"") | Y12: =IFERROR(VLOOKUP($D12,BS연결,MATCH(Y$1,BS연결H,0),0)/100,"") | Z12: =IFERROR(VLOOKUP($D12,BS연결,MATCH(Z$1,BS연결H,0),0)/100,"") | AA12: =IFERROR(VLOOKUP($D12,BS연결,MATCH(AA$1,BS연결H,0),0)/100,"") | AB12: =IFERROR(VLOOKUP($D12,BS연결,MATCH(AB$1,BS연결H,0),0)/100,"") | AC12: =IFERROR((AB27*변수!$D$53-AB25*변수!$D$54)/4,"") | AD12: =IFERROR((AC27*변수!$D$53-AC25*변수!$D$54)/4,"") | AE12: =SUM(AA12:AD12) | AF12: =IFERROR((AD27*변수!$D$53-AD25*변수!$D$54)/4,"") | AG12: =IFERROR((AF27*변수!$D$53-AF25*변수!$D$54)/4,"") | AH12: =IFERROR((AG27*변수!$D$53-AG25*변수!$D$54)/4,"") | AI12: =IFERROR((AH27*변수!$D$53-AH25*변수!$D$54)/4,"") | AJ12: =SUM(AF12:AI12) | AK12: =IFERROR((AI27*변수!$D$53-AI25*변수!$D$54)/4,"") | AL12: =IFERROR((AK27*변수!$D$53-AK25*변수!$D$54)/4,"") | AM12: =IFERROR((AL27*변수!$D$53-AL25*변수!$D$54)/4,"") | AN12: =IFERROR((AM27*변수!$D$53-AM25*변수!$D$54)/4,"") | AO12: =SUM(AK12:AN12)
A13: 외환손익 | B13: 손익 | C13: 억원 | D13: 외환손익(실적만; 추정 환효과는 환관련손익) | K13: =SUM(G13:J13) | P13: =SUM(L13:O13) | U13: =SUM(Q13:T13) | V13: =IFERROR((VLOOKUP("외환차익",BS연결,MATCH(V$1,BS연결H,0),0)-VLOOKUP("외환차손",BS연결,MATCH(V$1,BS연결H,0),0)+VLOOKUP("외화환산이익",BS연결,MATCH(V$1,BS연결H,0),0)-VLOOKUP("외화환산손실",BS연결,MATCH(V$1,BS연결H,0),0))/100,"") | W13: =IFERROR((VLOOKUP("외환차익",BS연결,MATCH(W$1,BS연결H,0),0)-VLOOKUP("외환차손",BS연결,MATCH(W$1,BS연결H,0),0)+VLOOKUP("외화환산이익",BS연결,MATCH(W$1,BS연결H,0),0)-VLOOKUP("외화환산손실",BS연결,MATCH(W$1,BS연결H,0),0))/100,"") | X13: =IFERROR((VLOOKUP("외환차익",BS연결,MATCH(X$1,BS연결H,0),0)-VLOOKUP("외환차손",BS연결,MATCH(X$1,BS연결H,0),0)+VLOOKUP("외화환산이익",BS연결,MATCH(X$1,BS연결H,0),0)-VLOOKUP("외화환산손실",BS연결,MATCH(X$1,BS연결H,0),0))/100,"") | Y13: =IFERROR((VLOOKUP("외환차익",BS연결,MATCH(Y$1,BS연결H,0),0)-VLOOKUP("외환차손",BS연결,MATCH(Y$1,BS연결H,0),0)+VLOOKUP("외화환산이익",BS연결,MATCH(Y$1,BS연결H,0),0)-VLOOKUP("외화환산손실",BS연결,MATCH(Y$1,BS연결H,0),0))/100,"") | Z13: =SUM(V13:Y13) | AA13: =IFERROR((VLOOKUP("외환차익",BS연결,MATCH(AA$1,BS연결H,0),0)-VLOOKUP("외환차손",BS연결,MATCH(AA$1,BS연결H,0),0)+VLOOKUP("외화환산이익",BS연결,MATCH(AA$1,BS연결H,0),0)-VLOOKUP("외화환산손실",BS연결,MATCH(AA$1,BS연결H,0),0))/100,"") | AB13: =IFERROR((VLOOKUP("외환차익",BS연결,MATCH(AB$1,BS연결H,0),0)-VLOOKUP("외환차손",BS연결,MATCH(AB$1,BS연결H,0),0)+VLOOKUP("외화환산이익",BS연결,MATCH(AB$1,BS연결H,0),0)-VLOOKUP("외화환산손실",BS연결,MATCH(AB$1,BS연결H,0),0))/100,"") | AC13: =변수!AC24 | AD13: =변수!AD24 | AE13: =SUM(AA13:AD13) | AF13: =변수!AF24 | AG13: =변수!AG24 | AH13: =변수!AH24 | AI13: =변수!AI24 | AJ13: =SUM(AF13:AI13) | AK13: =변수!AK24 | AL13: =변수!AL24 | AM13: =변수!AM24 | AN13: =변수!AN24 | AO13: =SUM(AK13:AN13)
