Workbook
Name 변수H: 변수!$C$1:$AO$1
Name 환율: 변수!$C$6:$AO$13
Name BS연결H: BS연결!$C$1:$AO$1
Name BS연결: BS연결!$C$5:$AO$107
Name BS별도H: BS별도!$C$1:$AO$1
Name BS별도: BS별도!$C$5:$AO$94
Name SUBQH: subQ!$A$1:$AO$1
Name subQ: subQ!$A$5:$AO$42

Sheet README
A1: 현대리바트(079430) 실적 모델 — ARGUS 한국조선
A2: 기준 분기 2026Q2 · 마지막 실적 2026Q2 · 생성 2026-10-11
A3: 모든 수치는 모델 산출값(DART 공개 재무제표 + 우리 추정)이다 — 목표주가·투자 추천 아님. 참고용 · 투자조언 아님.
A5: 시트
A6: 변수 가정 시계열. 환율 8행(ECB via frankfurter — L2 fx.json; 추정 분기 = 노란 가정), 추정 드라이버(노란 셀 = 모델값에서 역산한 가정, 바꾸면 재계산; 연녹 셀 = 3절 스칼라 참조 수식), 3절 스칼라 가정(세율·판관비율·지배주주비중·이자율·종가·PER 밴드·COE·외화 순노출·헤지비율)
A7: BS연결/BS별도 FnGuide 계정명 × 기간 값 덤프(백만원). 행1 분기라벨, 행4 YYYY.MM / YYYY.12A. 이름정의 BS연결H·BS연결(계정명 C열부터)
A8: subQ 분기 서브모델(억원 = 백만원/100). 확정 행: =IFERROR(VLOOKUP($D행,BS연결,MATCH(E$1,BS연결H,0),0)/100,"") 추정 행: 변수 시트 가정 셀 참조 수식. 외환손익·파생상품손익은 BS 계정 합·차, 기타금융손익은 잔차, OPM·EPS·BPS·PER·PBR 은 파생 수식
A9: SLS 선표(조선사만, sls json 있을 때): 요약 행(sls 저장값) + 계약별 스케줄(백만$) × (헤지비율 × 헤지환율 + (1−헤지비율) × 건조시점 환율[변수 원/달러(평균)]) → 원화 수식 블록 → 합계 행이 subQ 매출조선에 연결
A10: 시나리오 신규수주 보수/기준/낙관(forecast_panel 패널, 모델에 scenarios 가 있을 때만): 매출액·영업이익 = subQ 기준값 ± (시나리오 신규 − base 신규) × OPM. base 만 subQ 행에 포함, 나머지는 합산 안 함
A11: 분기/연간예상 subQ 를 이름(A열 key)으로 VLOOKUP 한 보고서 표(억원)
A12: TP PER 밴드 × 12M fwd EPS, PBR = ROE/COE × BPS — 모델 산출값 구간, 목표주가·추천 아님
A13: 외화 환율 QoQ, 외화 순노출 × Δ기말환율 → 환관련손익 추정
... A34: 백테스트: {"freeze": "2025Q2", "horizon": 4, "revenue_wape_pct": 53.5, "op_wape_pct": 159.0, "n": 4, "note": "단일 회사 4분기 — 통계 아님", "driver_at_freeze": "customer_yard_revenue_weighted", "selection_oos_at_freeze": {"freeze": "2024Q2", "n": 4, "wape_link": 9.8, "wape_trend": 25.5, "adopted": true, "decision": "adopted"}, "frozen_inputs": "fin(연결/별도)·고객 조선사 모델·지주 자회사 모델은 2025Q2 까지의 분기만; 선표는 체결일 ≤ 2025Q2 말일 계약(원장 최신 금액·코호트 등급, 환산 없음); 잔고는 yards_cache 2025Q2; 시세·환율 forward·prices·forecast_panel 신규수주 미사용. 고객 가중치(suppliers.json 언급 비중)와 합병 체인링크는 현재 지식; 고객 연동 채택은 동결 모델 안에서도 자기 la−4분기 OOS 규칙(selection_oos_at_freeze)", "detail": [{"q": "2025Q3", "rev_pred": 5265.44, "rev_act": 3406.55, "op_pred": 68.09, "op_act": 37.37}, {"q": "2025Q4", "rev_pred": 5473.11, "rev_act": 3579.2, "op_pred": 70.77, "op_act": -26.11}, {"q": "2026Q1", "rev_pred": 5550.01, "rev_act": 3559.35, "op_pred": 71.77, "op_act": 10.53}, {"q": "2026Q2", "rev_pred": 5627.6, "rev_act": 3731.33, "op_pred": 72.77, "op_act": 55.59}]}

Sheet 변수
C1: 이름: 변수H | E1: 4Q21 | F1: 2021 | G1: 1Q22 | H1: 2Q22 | I1: 3Q22 | J1: 4Q22 | K1: 2022 | L1: 1Q23 | M1: 2Q23 | N1: 3Q23 | O1: 4Q23 | P1: 2023 | Q1: 1Q24 | R1: 2Q24 | S1: 3Q24 | T1: 4Q24 | U1: 2024 | V1: 1Q25 | W1: 2Q25 | X1: 3Q25 | Y1: 4Q25 | Z1: 2025 | AA1: 1Q26 | AB1: 2Q26 | AC1: 3Q26 | AD1: 4Q26 | AE1: 2026 | AF1: 1Q27 | AG1: 2Q27 | AH1: 3Q27 | AI1: 4Q27 | AJ1: 2027 | AK1: 1Q28 | AL1: 2Q28 | AM1: 3Q28 | AN1: 4Q28 | AO1: 2028
A2: 가정 시계열 — 노란 셀은 추정 가정(모델값에서 역산), 연녹 셀은 3절 스칼라 참조 수식. 바꾸면 subQ·분기·연간예상·TP·시나리오가 재계산됩니다.
E3: 1 | F3: 2 | G3: 3 | H3: 4 | I3: 5 | J3: 6 | K3: 7 | L3: 8 | M3: 9 | N3: 10 | O3: 11 | P3: 12 | Q3: 13 | R3: 14 | S3: 15 | T3: 16 | U3: 17 | V3: 18 | W3: 19 | X3: 20 | Y3: 21 | Z3: 22 | AA3: 23 | AB3: 24 | AC3: 25 | AD3: 26 | AE3: 27 | AF3: 28 | AG3: 29 | AH3: 30 | AI3: 31 | AJ3: 32 | AK3: 33 | AL3: 34 | AM3: 35 | AN3: 36 | AO3: 37
E4: 2021.12 | F4: 2021.12A | G4: 2022.03 | H4: 2022.06 | I4: 2022.09 | J4: 2022.12 | K4: 2022.12A | L4: 2023.03 | M4: 2023.06 | N4: 2023.09 | O4: 2023.12 | P4: 2023.12A | Q4: 2024.03 | R4: 2024.06 | S4: 2024.09 | T4: 2024.12 | U4: 2024.12A | V4: 2025.03 | W4: 2025.06 | X4: 2025.09 | Y4: 2025.12 | Z4: 2025.12A | AA4: 2026.03 | AB4: 2026.06 | AC4: 2026.09 | AD4: 2026.12 | AE4: 2026.12A | AF4: 2027.03 | AG4: 2027.06 | AH4: 2027.09 | AI4: 2027.12 | AJ4: 2027.12A | AK4: 2028.03 | AL4: 2028.06 | AM4: 2028.09 | AN4: 2028.12 | AO4: 2028.12A
B5: 1. FX | C5: 이름: 환율
A6: USDKRW_avg | C6: 원/달러(평균) | E6: 1183.5 | F6: 1145.51 | G6: 1205.78 | H6: 1262.09 | I6: 1341.93 | J6: 1360.12 | K6: 1292.98 | L6: 1276.95 | M6: 1315.69 | N6: 1313.62 | O6: 1322.01 | P6: 1306.85 | Q6: 1330.14 | R6: 1371.28 | S6: 1356.22 | T6: 1396.3 | U6: 1363.53 | V6: 1452.28 | W6: 1398.52 | X6: 1386.95 | Y6: 1449.19 | Z6: 1421.52 | AA6: 1466.12 | AB6: 1501.75 | AC6: 1418.75 | AD6: 1345.14 | AE6: 1457.21 | AF6: 1341.49 | AG6: 1341.49 | AH6: 1341.49 | AI6: 1341.49 | AK6: 1341.49 | AL6: 1341.49 | AM6: 1341.49 | AN6: 1341.49
A7: USDKRW_end | C7: 원/달러(기말) | E7: 1188.75 | F7: 1188.75 | G7: 1213.74 | H7: 1301.24 | I7: 1436.9 | J7: 1260.16 | K7: 1260.16 | L7: 1305.99 | M7: 1321.44 | N7: 1345.35 | O7: 1297.43 | P7: 1297.43 | Q7: 1349.25 | R7: 1377.73 | S7: 1312.17 | T7: 1474.78 | U7: 1474.78 | V7: 1474.54 | W7: 1355.13 | X7: 1403.67 | Y7: 1444.2 | Z7: 1444.2 | AA7: 1524.8 | AB7: 1550.89 | AC7: 1355.4 | AD7: 1341.49 | AE7: 1341.49 | AF7: 1341.49 | AG7: 1341.49 | AH7: 1341.49 | AI7: 1341.49 | AK7: 1341.49 | AL7: 1341.49 | AM7: 1341.49 | AN7: 1341.49
A8: JPY100KRW_avg | C8: 원/100Y(평균) | E8: 1041.02 | F8: 1042.74 | G8: 1036.79 | H8: 972.23 | I8: 970.61 | J8: 961.03 | K8: 985.1 | L8: 964.89 | M8: 957.36 | N8: 909 | O8: 893.22 | P8: 931.11 | Q8: 896.29 | R8: 880.14 | S8: 909.35 | T8: 917.25 | U8: 900.92 | V8: 952.59 | W8: 967.92 | X8: 940.32 | Y8: 940.77 | Z8: 950.17 | AA8: 934.39 | AB8: 942.16 | AC8: 890.41 | AD8: 850.79 | AE8: 919.21 | AF8: 847.7 | AG8: 847.7 | AH8: 847.7 | AI8: 847.7 | AK8: 847.7 | AL8: 847.7 | AM8: 847.7 | AN8: 847.7
A9: JPY100KRW_end | C9: 원/100Y(기말) | E9: 1032.62 | F9: 1032.62 | G9: 996.83 | H9: 954.9 | I9: 993.29 | J9: 955.54 | K9: 955.54 | L9: 980.62 | M9: 913.67 | N9: 901.47 | O9: 917.04 | P9: 917.04 | Q9: 892.42 | R9: 857.76 | S9: 919.21 | T9: 939.65 | U9: 939.65 | V9: 986.84 | W9: 938.85 | X9: 948.49 | Y9: 921.81 | Z9: 921.81 | AA9: 955.99 | AB9: 954.75 | AC9: 863.31 | AD9: 847.7 | AE9: 847.7 | AF9: 847.7 | AG9: 847.7 | AH9: 847.7 | AI9: 847.7 | AK9: 847.7 | AL9: 847.7 | AM9: 847.7 | AN9: 847.7
A10: EURKRW_avg | C10: W/Euro(평균) | E10: 1353.32 | F10: 1354.06 | G10: 1352.29 | H10: 1343.31 | I10: 1350.63 | J10: 1386.07 | K10: 1358.07 | L10: 1369.93 | M10: 1432.41 | N10: 1429.41 | O10: 1420.91 | P10: 1412.88 | Q10: 1444.21 | R10: 1476.42 | S10: 1489.3 | T10: 1490.78 | U10: 1475.4 | V10: 1528.33 | W10: 1585.13 | X10: 1620.04 | Y10: 1686.02 | Z10: 1605.45 | AA10: 1715.47 | AB10: 1746.09 | AC10: 1631.97 | AD10: 1509.74 | AE10: 1689.95 | AF10: 1503.27 | AG10: 1503.27 | AH10: 1503.27 | AI10: 1503.27 | AK10: 1503.27 | AL10: 1503.27 | AM10: 1503.27 | AN10: 1503.27
A11: EURKRW_end | C11: W/Euro(기말) | E11: 1346.38 | F11: 1346.38 | G11: 1347.37 | H11: 1351.6 | I11: 1400.62 | J11: 1344.08 | K11: 1344.08 | L11: 1420.26 | M11: 1435.88 | N11: 1425.26 | O11: 1433.66 | P11: 1433.66 | Q11: 1458.68 | R11: 1474.86 | S11: 1469.1 | T11: 1532.14 | U11: 1532.14 | V11: 1594.72 | W11: 1588.22 | X11: 1648.04 | Y11: 1696.94 | Z11: 1696.94 | AA11: 1753.21 | AB11: 1767.09 | AC11: 1539.06 | AD11: 1503.27 | AE11: 1503.27 | AF11: 1503.27 | AG11: 1503.27 | AH11: 1503.27 | AI11: 1503.27 | AK11: 1503.27 | AL11: 1503.27 | AM11: 1503.27 | AN11: 1503.27
A12: CNYKRW_avg | C12: 원/중국원(평균) | E12: 185.14 | F12: 177.65 | G12: 189.93 | H12: 190.76 | I12: 195.79 | J12: 191.09 | K12: 191.93 | L12: 186.59 | M12: 187.45 | N12: 181.28 | O12: 182.86 | P12: 184.52 | Q12: 185.04 | R12: 189.35 | S12: 189.24 | T12: 194.24 | U12: 189.49 | V12: 199.63 | W12: 193.41 | X12: 193.79 | Y12: 204.38 | Z12: 197.8 | AA12: 211.75 | AB12: 220.8 | AC12: 210.43 | AD12: 200.69 | AE12: 213.75 | AF12: 200.46 | AG12: 200.46 | AH12: 200.46 | AI12: 200.46 | AK12: 200.46 | AL12: 200.46 | AM12: 200.46 | AN12: 200.46
A13: CNYKRW_end | C13: 원/중국원(기말) | E13: 187.13 | F13: 187.13 | G13: 191.38 | H13: 194.13 | I13: 201.92 | J13: 182.67 | K13: 182.67 | L13: 189.97 | M13: 181.8 | N13: 184.26 | O13: 182.61 | P13: 182.61 | Q13: 186.66 | R13: 189.7 | S13: 187.12 | T13: 202.04 | U13: 202.04 | V13: 203.3 | W13: 189.14 | X13: 197.16 | Y13: 206.28 | Z13: 206.28 | AA13: 220.97 | AB13: 228.56 | AC13: 202.16 | AD13: 200.46 | AE13: 200.46 | AF13: 200.46 | AG13: 200.46 | AH13: 200.46 | AI13: 200.46 | AK13: 200.46 | AL13: 200.46 | AM13: 200.46 | AN13: 200.46
B14: 1b. 종가
A15: price_close_end | C15: 종가(기말) | E15: 15150 | G15: 15950 | H15: 10950 | I15: 9210 | J15: 8590 | L15: 7910 | M15: 8650 | N15: 8990 | O15: 7760 | Q15: 7670 | R15: 9220 | S15: 7990 | T15: 7630 | V15: 6910 | W15: 7880 | X15: 7070 | Y15: 6890 | AA15: 6810 | AB15: 5780 | AC15: 5730 | AD15: 5560
A16: price_high | C16: 종가(최고) | E16: 17500 | G16: 17800 | H16: 17000 | I16: 11950 | J16: 11750 | L16: 9730 | M16: 10010 | N16: 9200 | O16: 9650 | Q16: 9080 | R16: 11800 | S16: 10810 | T16: 9360 | V16: 7990 | W16: 8420 | X16: 8610 | Y16: 7170 | AA16: 8900 | AB16: 9300 | AC16: 6290 | AD16: 5800
A17: price_low | C17: 종가(최저) | E17: 13300 | G17: 12500 | H17: 10150 | I17: 9020 | J17: 8210 | L17: 7630 | M17: 7700 | N17: 6600 | O17: 7600 | Q17: 6840 | R17: 7160 | S17: 7690 | T17: 7060 | V17: 6900 | W17: 6590 | X17: 7040 | Y17: 5980 | AA17: 6330 | AB17: 5420 | AC17: 5100 | AD17: 5520
A18: price_avg | C18: 종가(평균) | E18: 15515.9 | G18: 14335.6 | H18: 13646.8 | I18: 10967.5 | J18: 9196.5 | L18: 8797.6 | M18: 8121.8 | N18: 8094.2 | O18: 8076.2 | Q18: 7589.3 | R18: 8743.8 | S18: 8906.6 | T18: 7951.6 | V18: 7493.1 | W18: 7575.8 | X18: 7612.3 | Y18: 6535.6 | AA18: 6910.8 | AB18: 6866.4 | AC18: 5830.8 | AD18: 5640
B20: 2. 추정 드라이버 | C20: 실적 열 = subQ 실현값(수식), 추정 열 = 가정(노란 = 모델값 역산, 연녹 = 3절 스칼라 참조)
A21: drv:매출액 | B21: yoy | C21: 매출액 YoY | J21: =IFERROR(subQ!J5/subQ!E5-1,"") | L21: =IFERROR(subQ!L5/subQ!G5-1,"") | M21: =IFERROR(subQ!M5/subQ!H5-1,"") | N21: =IFERROR(subQ!N5/subQ!I5-1,"") | O21: =IFERROR(subQ!O5/subQ!J5-1,"") | Q21: =IFERROR(subQ!Q5/subQ!L5-1,"") | R21: =IFERROR(subQ!R5/subQ!M5-1,"") | S21: =IFERROR(subQ!S5/subQ!N5-1,"") | T21: =IFERROR(subQ!T5/subQ!O5-1,"") | V21: =IFERROR(subQ!V5/subQ!Q5-1,"") | W21: =IFERROR(subQ!W5/subQ!R5-1,"") | X21: =IFERROR(subQ!X5/subQ!S5-1,"") | Y21: =IFERROR(subQ!Y5/subQ!T5-1,"") | AA21: =IFERROR(subQ!AA5/subQ!V5-1,"") | AB21: =IFERROR(subQ!AB5/subQ!W5-1,"") | AC21: -0.16830273 | AD21: -0.16830269 | AF21: -0.16830404 | AG21: -0.16830281 | AH21: -0.084151601 | AI21: -0.084150483 | AK21: -0.084150255 | AL21: -0.084151269 | AM21: -0.042076461 | AN21: -0.042078854
A22: drv:판관비 | B22: ratio | C22: 판관비율(/매출) | E22: =IFERROR(subQ!E8/subQ!E5,"") | F22: =IFERROR(subQ!F8/subQ!F5,"") | G22: =IFERROR(subQ!G8/subQ!G5,"") | H22: =IFERROR(subQ!H8/subQ!H5,"") | I22: =IFERROR(subQ!I8/subQ!I5,"") | J22: =IFERROR(subQ!J8/subQ!J5,"") | K22: =IFERROR(subQ!K8/subQ!K5,"") | L22: =IFERROR(subQ!L8/subQ!L5,"") | ... AB22: =IFERROR(subQ!AB8/subQ!AB5,"") | AC22: =$D$51 | AD22: =$D$51 | AE22: =IFERROR(subQ!AE8/subQ!AE5,"") | AF22: =$D$51 | AG22: =$D$51 | AH22: =$D$51 | AI22: =$D$51 | AJ22: =IFERROR(subQ!AJ8/subQ!AJ5,"") | AK22: =$D$51 | AL22: =$D$51 | AM22: =$D$51 | AN22: =$D$51 | AO22: =IFERROR(subQ!AO8/subQ!AO5,"")
A23: drv:영업이익 | B23: ratio | C23: 영업이익률(OPM) | E23: =IFERROR(subQ!E9/subQ!E5,"") | F23: =IFERROR(subQ!F9/subQ!F5,"") | G23: =IFERROR(subQ!G9/subQ!G5,"") | H23: =IFERROR(subQ!H9/subQ!H5,"") | I23: =IFERROR(subQ!I9/subQ!I5,"") | J23: =IFERROR(subQ!J9/subQ!J5,"") | K23: =IFERROR(subQ!K9/subQ!K5,"") | L23: =IFERROR(subQ!L9/subQ!L5,"") | ... AB23: =IFERROR(subQ!AB9/subQ!AB5,"") | AC23: 0.01168282 | AD23: 0.011683648 | AE23: =IFERROR(subQ!AE9/subQ!AE5,"") | AF23: 0.011681249 | AG23: 0.011680963 | AH23: 0.011681054 | AI23: 0.011682457 | AJ23: =IFERROR(subQ!AJ9/subQ!AJ5,"") | AK23: 0.011681217 | AL23: 0.011681133 | AM23: 0.011683202 | AN23: 0.011682538 | AO23: =IFERROR(subQ!AO9/subQ!AO5,"")
A24: drv:외환손익 | B24: abs | C24: 외환손익 (가정, 억원) | E24: =subQ!E13 | F24: =subQ!F13 | G24: =subQ!G13 | H24: =subQ!H13 | I24: =subQ!I13 | J24: =subQ!J13 | K24: =subQ!K13 | L24: =subQ!L13 | ... AB24: =subQ!AB13 | AC24: 0 | AD24: 0 | AE24: =subQ!AE13 | AF24: 0 | AG24: 0 | AH24: 0 | AI24: 0 | AJ24: =subQ!AJ13 | AK24: 0 | AL24: 0 | AM24: 0 | AN24: 0 | AO24: =subQ!AO13
A25: drv:파생상품손익 | B25: abs | C25: 파생상품손익 (가정, 억원) | E25: =subQ!E14 | F25: =subQ!F14 | G25: =subQ!G14 | H25: =subQ!H14 | I25: =subQ!I14 | J25: =subQ!J14 | K25: =subQ!K14 | L25: =subQ!L14 | ... AB25: =subQ!AB14 | AC25: 0 | AD25: 0 | AE25: =subQ!AE14 | AF25: 0 | AG25: 0 | AH25: 0 | AI25: 0 | AJ25: =subQ!AJ14 | AK25: 0 | AL25: 0 | AM25: 0 | AN25: 0 | AO25: =subQ!AO14
A26: drv:기타금융손익 | B26: abs | C26: 기타금융손익 (가정, 억원) | E26: =subQ!E15 | F26: =subQ!F15 | G26: =subQ!G15 | H26: =subQ!H15 | I26: =subQ!I15 | J26: =subQ!J15 | K26: =subQ!K15 | L26: =subQ!L15 | ... AB26: =subQ!AB15 | AC26: 0 | AD26: 0 | AE26: =subQ!AE15 | AF26: 0 | AG26: 0 | AH26: 0 | AI26: 0 | AJ26: =subQ!AJ15 | AK26: 0 | AL26: 0 | AM26: 0 | AN26: 0 | AO26: =subQ!AO15
A27: drv:기타영업외손익 | B27: abs | C27: 기타영업외손익 (가정, 억원) | E27: =subQ!E16 | F27: =subQ!F16 | G27: =subQ!G16 | H27: =subQ!H16 | I27: =subQ!I16 | J27: =subQ!J16 | K27: =subQ!K16 | L27: =subQ!L16 | ... AB27: =subQ!AB16 | AC27: 0 | AD27: 0 | AE27: =subQ!AE16 | AF27: 0 | AG27: 0 | AH27: 0 | AI27: 0 | AJ27: =subQ!AJ16 | AK27: 0 | AL27: 0 | AM27: 0 | AN27: 0 | AO27: =subQ!AO16
A28: drv:법인세비용 | B28: tax | C28: 법인세율(/세전) — 법인세 = MAX(세전,0) × 세율 | E28: =IFERROR(subQ!E18/subQ!E17,"") | F28: =IFERROR(subQ!F18/subQ!F17,"") | G28: =IFERROR(subQ!G18/subQ!G17,"") | H28: =IFERROR(subQ!H18/subQ!H17,"") | I28: =IFERROR(subQ!I18/subQ!I17,"") | J28: =IFERROR(subQ!J18/subQ!J17,"") | K28: =IFERROR(subQ!K18/subQ!K17,"") | L28: =IFERROR(subQ!L18/subQ!L17,"") | ... AB28: =IFERROR(subQ!AB18/subQ!AB17,"") | AC28: =$D$50 | AD28: =$D$50 | AE28: =IFERROR(subQ!AE18/subQ!AE17,"") | AF28: =$D$50 | AG28: =$D$50 | AH28: =$D$50 | AI28: =$D$50 | AJ28: =IFERROR(subQ!AJ18/subQ!AJ17,"") | AK28: =$D$50 | AL28: =$D$50 | AM28: =$D$50 | AN28: =$D$50 | AO28: =IFERROR(subQ!AO18/subQ!AO17,"")
A29: drv:지배주주순이익 | B29: ratio | C29: 지배주주 비중(/당기순이익) | E29: =IFERROR(subQ!E20/subQ!E19,"") | F29: =IFERROR(subQ!F20/subQ!F19,"") | G29: =IFERROR(subQ!G20/subQ!G19,"") | H29: =IFERROR(subQ!H20/subQ!H19,"") | I29: =IFERROR(subQ!I20/subQ!I19,"") | J29: =IFERROR(subQ!J20/subQ!J19,"") | K29: =IFERROR(subQ!K20/subQ!K19,"") | L29: =IFERROR(subQ!L20/subQ!L19,"") | ... AB29: =IFERROR(subQ!AB20/subQ!AB19,"") | AC29: =$D$52 | AD29: =$D$52 | AE29: =IFERROR(subQ!AE20/subQ!AE19,"") | AF29: =$D$52 | AG29: =$D$52 | AH29: =$D$52 | AI29: =$D$52 | AJ29: =IFERROR(subQ!AJ20/subQ!AJ19,"") | AK29: =$D$52 | AL29: =$D$52 | AM29: =$D$52 | AN29: =$D$52 | AO29: =IFERROR(subQ!AO20/subQ!AO19,"")
A30: drv:부채총계 | B30: qoq | C30: 부채총계 QoQ | G30: =IFERROR(subQ!G22/subQ!E22-1,"") | H30: =IFERROR(subQ!H22/subQ!G22-1,"") | I30: =IFERROR(subQ!I22/subQ!H22-1,"") | J30: =IFERROR(subQ!J22/subQ!I22-1,"") | L30: =IFERROR(subQ!L22/subQ!J22-1,"") | M30: =IFERROR(subQ!M22/subQ!L22-1,"") | N30: =IFERROR(subQ!N22/subQ!M22-1,"") | O30: =IFERROR(subQ!O22/subQ!N22-1,"") | Q30: =IFERROR(subQ!Q22/subQ!O22-1,"") | R30: =IFERROR(subQ!R22/subQ!Q22-1,"") | S30: =IFERROR(subQ!S22/subQ!R22-1,"") | T30: =IFERROR(subQ!T22/subQ!S22-1,"") | V30: =IFERROR(subQ!V22/subQ!T22-1,"") | W30: =IFERROR(subQ!W22/subQ!V22-1,"") | X30: =IFERROR(subQ!X22/subQ!W22-1,"") | Y30: =IFERROR(subQ!Y22/subQ!X22-1,"") | AA30: =IFERROR(subQ!AA22/subQ!Y22-1,"") | AB30: =IFERROR(subQ!AB22/subQ!AA22-1,"")
A31: drv:자본총계 | B31: roll | C31: 자본총계 기타변동(배당 등, 억원) | G31: =IFERROR(subQ!E23+subQ!G19-subQ!G23,"") | H31: =IFERROR(subQ!G23+subQ!H19-subQ!H23,"") | I31: =IFERROR(subQ!H23+subQ!I19-subQ!I23,"") | J31: =IFERROR(subQ!I23+subQ!J19-subQ!J23,"") | L31: =IFERROR(subQ!J23+subQ!L19-subQ!L23,"") | M31: =IFERROR(subQ!L23+subQ!M19-subQ!M23,"") | N31: =IFERROR(subQ!M23+subQ!N19-subQ!N23,"") | O31: =IFERROR(subQ!N23+subQ!O19-subQ!O23,"") | Q31: =IFERROR(subQ!O23+subQ!Q19-subQ!Q23,"") | R31: =IFERROR(subQ!Q23+subQ!R19-subQ!R23,"") | S31: =IFERROR(subQ!R23+subQ!S19-subQ!S23,"") | T31: =IFERROR(subQ!S23+subQ!T19-subQ!T23,"") | V31: =IFERROR(subQ!T23+subQ!V19-subQ!V23,"") | W31: =IFERROR(subQ!V23+subQ!W19-subQ!W23,"") | X31: =IFERROR(subQ!W23+subQ!X19-subQ!X23,"") | Y31: =IFERROR(subQ!X23+subQ!Y19-subQ!Y23,"") | AA31: =IFERROR(subQ!Y23+subQ!AA19-subQ!AA23,"") | AB31: =IFERROR(subQ!AA23+subQ!AB19-subQ!AB23,"") | AC31: 0.005754465 | AD31: -0.002606911 | AF31: -0.00403701 | AG31: 26.150263 | AH31: -0.003289889 | AI31: -0.000619259 | AK31: -0.004711348 | AL31: 26.145833 | AM31: 0.00172711 | AN31: -0.00113153
A32: drv:지배주주지분 | B32: roll | C32: 지배주주지분 기타변동(배당 등, 억원) | G32: =IFERROR(subQ!E24+subQ!G20-subQ!G24,"") | H32: =IFERROR(subQ!G24+subQ!H20-subQ!H24,"") | I32: =IFERROR(subQ!H24+subQ!I20-subQ!I24,"") | J32: =IFERROR(subQ!I24+subQ!J20-subQ!J24,"") | L32: =IFERROR(subQ!J24+subQ!L20-subQ!L24,"") | M32: =IFERROR(subQ!L24+subQ!M20-subQ!M24,"") | N32: =IFERROR(subQ!M24+subQ!N20-subQ!N24,"") | O32: =IFERROR(subQ!N24+subQ!O20-subQ!O24,"") | Q32: =IFERROR(subQ!O24+subQ!Q20-subQ!Q24,"") | R32: =IFERROR(subQ!Q24+subQ!R20-subQ!R24,"") | S32: =IFERROR(subQ!R24+subQ!S20-subQ!S24,"") | T32: =IFERROR(subQ!S24+subQ!T20-subQ!T24,"") | V32: =IFERROR(subQ!T24+subQ!V20-subQ!V24,"") | W32: =IFERROR(subQ!V24+subQ!W20-subQ!W24,"") | X32: =IFERROR(subQ!W24+subQ!X20-subQ!X24,"") | Y32: =IFERROR(subQ!X24+subQ!Y20-subQ!Y24,"") | AA32: =IFERROR(subQ!Y24+subQ!AA20-subQ!AA24,"") | AB32: =IFERROR(subQ!AA24+subQ!AB20-subQ!AB24,"") | AC32: 0.005754465 | AD32: -0.002606911 | AF32: -0.00403701 | AG32: 26.150263 | AH32: -0.003289889 | AI32: -0.000619259 | AK32: -0.004711348 | AL32: 26.145833 | AM32: 0.00172711 | AN32: -0.00113153
A33: drv:총차입금 | B33: qoq | C33: 총차입금 QoQ | G33: =IFERROR(subQ!G25/subQ!E25-1,"") | H33: =IFERROR(subQ!H25/subQ!G25-1,"") | I33: =IFERROR(subQ!I25/subQ!H25-1,"") | J33: =IFERROR(subQ!J25/subQ!I25-1,"") | L33: =IFERROR(subQ!L25/subQ!J25-1,"") | M33: =IFERROR(subQ!M25/subQ!L25-1,"") | N33: =IFERROR(subQ!N25/subQ!M25-1,"") | O33: =IFERROR(subQ!O25/subQ!N25-1,"") | Q33: =IFERROR(subQ!Q25/subQ!O25-1,"") | R33: =IFERROR(subQ!R25/subQ!Q25-1,"") | S33: =IFERROR(subQ!S25/subQ!R25-1,"") | T33: =IFERROR(subQ!T25/subQ!S25-1,"") | V33: =IFERROR(subQ!V25/subQ!T25-1,"") | W33: =IFERROR(subQ!W25/subQ!V25-1,"") | X33: =IFERROR(subQ!X25/subQ!W25-1,"") | Y33: =IFERROR(subQ!Y25/subQ!X25-1,"") | AA33: =IFERROR(subQ!AA25/subQ!Y25-1,"") | AB33: =IFERROR(subQ!AB25/subQ!AA25-1,"")
A34: drv:순차입금 | B34: qoq | C34: 순차입금 QoQ | G34: =IFERROR(subQ!G26/subQ!E26-1,"") | H34: =IFERROR(subQ!H26/subQ!G26-1,"") | I34: =IFERROR(subQ!I26/subQ!H26-1,"") | J34: =IFERROR(subQ!J26/subQ!I26-1,"") | L34: =IFERROR(subQ!L26/subQ!J26-1,"") | M34: =IFERROR(subQ!M26/subQ!L26-1,"") | N34: =IFERROR(subQ!N26/subQ!M26-1,"") | O34: =IFERROR(subQ!O26/subQ!N26-1,"") | Q34: =IFERROR(subQ!Q26/subQ!O26-1,"") | R34: =IFERROR(subQ!R26/subQ!Q26-1,"") | S34: =IFERROR(subQ!S26/subQ!R26-1,"") | T34: =IFERROR(subQ!T26/subQ!S26-1,"") | V34: =IFERROR(subQ!V26/subQ!T26-1,"") | W34: =IFERROR(subQ!W26/subQ!V26-1,"") | X34: =IFERROR(subQ!X26/subQ!W26-1,"") | Y34: =IFERROR(subQ!Y26/subQ!X26-1,"") | AA34: =IFERROR(subQ!AA26/subQ!Y26-1,"") | AB34: =IFERROR(subQ!AB26/subQ!AA26-1,"")
A35: drv:이자발생자산 | B35: qoq | C35: 이자발생자산 QoQ | G35: =IFERROR(subQ!G27/subQ!E27-1,"") | H35: =IFERROR(subQ!H27/subQ!G27-1,"") | I35: =IFERROR(subQ!I27/subQ!H27-1,"") | J35: =IFERROR(subQ!J27/subQ!I27-1,"") | L35: =IFERROR(subQ!L27/subQ!J27-1,"") | M35: =IFERROR(subQ!M27/subQ!L27-1,"") | N35: =IFERROR(subQ!N27/subQ!M27-1,"") | O35: =IFERROR(subQ!O27/subQ!N27-1,"") | Q35: =IFERROR(subQ!Q27/subQ!O27-1,"") | R35: =IFERROR(subQ!R27/subQ!Q27-1,"") | S35: =IFERROR(subQ!S27/subQ!R27-1,"") | T35: =IFERROR(subQ!T27/subQ!S27-1,"") | V35: =IFERROR(subQ!V27/subQ!T27-1,"") | W35: =IFERROR(subQ!W27/subQ!V27-1,"") | X35: =IFERROR(subQ!X27/subQ!W27-1,"") | Y35: =IFERROR(subQ!Y27/subQ!X27-1,"") | AA35: =IFERROR(subQ!AA27/subQ!Y27-1,"") | AB35: =IFERROR(subQ!AB27/subQ!AA27-1,"") | AC35: 0.032111391 | AD35: 0.032623198 | AF35: 0.031571708 | AG35: 0.005595847 | AH35: 0.027341396 | AI35: 0.02786523 | AK35: 0.027100297 | AL35: 0.003352566 | AM35: 0.024580253 | AN35: 0.025098647
A36: drv:현금및현금성자산 | B36: qoq | C36: 현금및현금성자산 QoQ | G36: =IFERROR(subQ!G28/subQ!E28-1,"") | H36: =IFERROR(subQ!H28/subQ!G28-1,"") | I36: =IFERROR(subQ!I28/subQ!H28-1,"") | J36: =IFERROR(subQ!J28/subQ!I28-1,"") | L36: =IFERROR(subQ!L28/subQ!J28-1,"") | M36: =IFERROR(subQ!M28/subQ!L28-1,"") | N36: =IFERROR(subQ!N28/subQ!M28-1,"") | O36: =IFERROR(subQ!O28/subQ!N28-1,"") | Q36: =IFERROR(subQ!Q28/subQ!O28-1,"") | R36: =IFERROR(subQ!R28/subQ!Q28-1,"") | S36: =IFERROR(subQ!S28/subQ!R28-1,"") | T36: =IFERROR(subQ!T28/subQ!S28-1,"") | V36: =IFERROR(subQ!V28/subQ!T28-1,"") | W36: =IFERROR(subQ!W28/subQ!V28-1,"") | X36: =IFERROR(subQ!X28/subQ!W28-1,"") | Y36: =IFERROR(subQ!Y28/subQ!X28-1,"") | AA36: =IFERROR(subQ!AA28/subQ!Y28-1,"") | AB36: =IFERROR(subQ!AB28/subQ!AA28-1,"")
A37: drv:CAPEX | B37: yoy | C37: CAPEX YoY | J37: =IFERROR(subQ!J29/subQ!E29-1,"") | L37: =IFERROR(subQ!L29/subQ!G29-1,"") | M37: =IFERROR(subQ!M29/subQ!H29-1,"") | N37: =IFERROR(subQ!N29/subQ!I29-1,"") | O37: =IFERROR(subQ!O29/subQ!J29-1,"") | Q37: =IFERROR(subQ!Q29/subQ!L29-1,"") | R37: =IFERROR(subQ!R29/subQ!M29-1,"") | S37: =IFERROR(subQ!S29/subQ!N29-1,"") | T37: =IFERROR(subQ!T29/subQ!O29-1,"") | V37: =IFERROR(subQ!V29/subQ!Q29-1,"") | W37: =IFERROR(subQ!W29/subQ!R29-1,"") | X37: =IFERROR(subQ!X29/subQ!S29-1,"") | Y37: =IFERROR(subQ!Y29/subQ!T29-1,"") | AA37: =IFERROR(subQ!AA29/subQ!V29-1,"") | AB37: =IFERROR(subQ!AB29/subQ!W29-1,"") | AC37: -0.47370001 | AD37: -0.21987213 | AF37: 0.39263125 | AG37: 0.81381603 | AH37: 0 | AI37: 0 | AK37: 0 | AL37: 0 | AM37: 0 | AN37: 0
A38: drv:영업활동현금흐름 | B38: yoy | C38: 영업활동현금흐름 YoY | J38: =IFERROR(subQ!J30/subQ!E30-1,"") | L38: =IFERROR(subQ!L30/subQ!G30-1,"") | M38: =IFERROR(subQ!M30/subQ!H30-1,"") | N38: =IFERROR(subQ!N30/subQ!I30-1,"") | O38: =IFERROR(subQ!O30/subQ!J30-1,"") | Q38: =IFERROR(subQ!Q30/subQ!L30-1,"") | R38: =IFERROR(subQ!R30/subQ!M30-1,"") | S38: =IFERROR(subQ!S30/subQ!N30-1,"") | T38: =IFERROR(subQ!T30/subQ!O30-1,"") | V38: =IFERROR(subQ!V30/subQ!Q30-1,"") | W38: =IFERROR(subQ!W30/subQ!R30-1,"") | X38: =IFERROR(subQ!X30/subQ!S30-1,"") | Y38: =IFERROR(subQ!Y30/subQ!T30-1,"") | AA38: =IFERROR(subQ!AA30/subQ!V30-1,"") | AB38: =IFERROR(subQ!AB30/subQ!W30-1,"")
A39: drv:주식수 | B39: qoq | C39: 주식수 QoQ | G39: =IFERROR(subQ!G31/subQ!E31-1,"") | H39: =IFERROR(subQ!H31/subQ!G31-1,"") | I39: =IFERROR(subQ!I31/subQ!H31-1,"") | J39: =IFERROR(subQ!J31/subQ!I31-1,"") | L39: =IFERROR(subQ!L31/subQ!J31-1,"") | M39: =IFERROR(subQ!M31/subQ!L31-1,"") | N39: =IFERROR(subQ!N31/subQ!M31-1,"") | O39: =IFERROR(subQ!O31/subQ!N31-1,"") | Q39: =IFERROR(subQ!Q31/subQ!O31-1,"") | R39: =IFERROR(subQ!R31/subQ!Q31-1,"") | S39: =IFERROR(subQ!S31/subQ!R31-1,"") | T39: =IFERROR(subQ!T31/subQ!S31-1,"") | V39: =IFERROR(subQ!V31/subQ!T31-1,"") | W39: =IFERROR(subQ!W31/subQ!V31-1,"") | X39: =IFERROR(subQ!X31/subQ!W31-1,"") | Y39: =IFERROR(subQ!Y31/subQ!X31-1,"") | AA39: =IFERROR(subQ!AA31/subQ!Y31-1,"") | AB39: =IFERROR(subQ!AB31/subQ!AA31-1,"") | AC39: 0 | AD39: 0 | AF39: 0 | AG39: 0 | AH39: 0 | AI39: 0 | AK39: 0 | AL39: 0 | AM39: 0 | AN39: 0
A40: drv:DPS | B40: abs | C40: DPS (가정, 원) | E40: =subQ!E34 | F40: =subQ!F34 | G40: =subQ!G34 | H40: =subQ!H34 | I40: =subQ!I34 | J40: =subQ!J34 | K40: =subQ!K34 | L40: =subQ!L34 | ... AB40: =subQ!AB34 | AD40: 130 | AE40: =subQ!AE34 | AI40: 130 | AJ40: =subQ!AJ34 | AN40: 130 | AO40: =subQ!AO34
B42: 3. 밸류에이션·스칼라 | C42: 노란 셀 = 가정. '연결' 표시는 추정 전 분기 수식이 이 셀을 참조한다는 뜻
...

Sheet BS연결
B1: (백만원) | C1: 이름: BS연결H | E1: 4Q21 | F1: 2021 | G1: 1Q22 | H1: 2Q22 | I1: 3Q22 | J1: 4Q22 | K1: 2022 | L1: 1Q23 | M1: 2Q23 | N1: 3Q23 | O1: 4Q23 | P1: 2023 | Q1: 1Q24 | R1: 2Q24 | S1: 3Q24 | T1: 4Q24 | U1: 2024 | V1: 1Q25 | W1: 2Q25 | X1: 3Q25 | Y1: 4Q25 | Z1: 2025 | AA1: 1Q26 | AB1: 2Q26 | AC1: 3Q26 | AD1: 4Q26 | AE1: 2026 | AF1: 1Q27 | AG1: 2Q27 | AH1: 3Q27 | AI1: 4Q27 | AJ1: 2027 | AK1: 1Q28 | AL1: 2Q28 | AM1: 3Q28 | AN1: 4Q28 | AO1: 2028
B2: 연결 | D2: fin json(kship_fin.py)
B3: 현대리바트(연) | C3: UPDATE: 26-10-11 | E3: 1 | F3: 2 | G3: 3 | H3: 4 | I3: 5 | J3: 6 | K3: 7 | L3: 8 | M3: 9 | N3: 10 | O3: 11 | P3: 12 | Q3: 13 | R3: 14 | S3: 15 | T3: 16 | U3: 17 | V3: 18 | W3: 19 | X3: 20 | Y3: 21 | Z3: 22 | AA3: 23 | AB3: 24 | AC3: 25 | AD3: 26 | AE3: 27 | AF3: 28 | AG3: 29 | AH3: 30 | AI3: 31 | AJ3: 32 | AK3: 33 | AL3: 34 | AM3: 35 | AN3: 36 | AO3: 37
B4: Account Code | C4: AccountNAME | E4: 2021.12 | F4: 2021.12A | G4: 2022.03 | H4: 2022.06 | I4: 2022.09 | J4: 2022.12 | K4: 2022.12A | L4: 2023.03 | M4: 2023.06 | N4: 2023.09 | O4: 2023.12 | P4: 2023.12A | Q4: 2024.03 | R4: 2024.06 | S4: 2024.09 | T4: 2024.12 | U4: 2024.12A | V4: 2025.03 | W4: 2025.06 | X4: 2025.09 | Y4: 2025.12 | Z4: 2025.12A | AA4: 2026.03 | AB4: 2026.06 | AC4: 2026.09 | AD4: 2026.12 | AE4: 2026.12A | AF4: 2027.03 | AG4: 2027.06 | AH4: 2027.09 | AI4: 2027.12 | AJ4: 2027.12A | AK4: 2028.03 | AL4: 2028.06 | AM4: 2028.09 | AN4: 2028.12 | AO4: 2028.12A
A5: 1 | C5: 유동자산 | E5: 430586.11 | F5: 430586.11 | G5: 385413.14 | H5: 407344.29 | I5: 440514.04 | J5: 452085.67 | K5: 452085.67 | L5: 436815.13 | M5: 469370.3 | N5: 530911.66 | O5: 511898.83 | P5: 511898.83 | Q5: 563551.18 | R5: 541852.46 | S5: 529131.27 | T5: 478301.94 | U5: 478301.94 | V5: 474362.69 | W5: 461003.21 | X5: 414269.07 | Y5: 405941.23 | Z5: 405941.23 | AA5: 455561.55 | AB5: 479386.76
A6: 1 | C6: 현금및현금성자산 | E6: 14279.25 | F6: 14279.25 | G6: 10698.94 | H6: 10653.03 | I6: 12545.3 | J6: 14896.6 | K6: 14896.6 | L6: 18605.43 | M6: 14313.62 | N6: 15942.53 | O6: 21158.75 | P6: 21158.75 | Q6: 9048.06 | R6: 10907 | S6: 58103.82 | T6: 19122.66 | U6: 19122.66 | V6: 20019.41 | W6: 32250.37 | X6: 17318.76 | Y6: 18308.94 | Z6: 18308.94 | AA6: 32198.25 | AB6: 62336.58
A7: 1 | C7: 매출채권및기타채권 | E7: 237036.37 | F7: 237036.37 | G7: 209882 | H7: 203970.25 | I7: 211829.17 | J7: 246854.8 | K7: 246854.8 | L7: 232002.24 | M7: 245614.88 | N7: 293236.36 | O7: 258609.36 | P7: 258609.36 | Q7: 332543.86 | R7: 315666.75 | S7: 253078.1 | T7: 223102.42 | U7: 223102.42 | V7: 241887.88 | W7: 236415.49 | X7: 213746.8 | Y7: 201881.38 | Z7: 201881.38 | AA7: 222690.27 | AB7: 222573.88
A8: 1 | C8: 단기금융상품 | E8: 8951.38 | F8: 8951.38 | G8: 8030.93 | H8: 7744.57 | I8: 7767.15 | J8: 7814.4 | K8: 7814.4 | L8: 5942.95 | M8: 5600.21 | N8: 5786.41 | O8: 5611.67 | P8: 5611.67 | Q8: 5536.68 | R8: 9005.57 | S8: 9295.65
A9: 1 | C9: 단기금융자산 | E9: 8951.38 | F9: 8951.38 | G9: 8030.93 | H9: 7744.57 | I9: 7767.15 | J9: 7814.4 | K9: 7814.4 | L9: 5942.95 | M9: 5600.21 | N9: 5786.41 | O9: 5611.67 | P9: 5611.67 | Q9: 5536.68 | R9: 9005.57 | S9: 9295.65
A10: 1 | C10: 재고자산 | E10: 142534.05 | F10: 142534.05 | G10: 132502.7 | H10: 153985.32 | I10: 164842.44 | J10: 162300.13 | K10: 162300.13 | L10: 166069.26 | M10: 189425.39 | N10: 203940.53 | O10: 213456.76 | P10: 213456.76 | Q10: 204099.94 | R10: 193026.95 | S10: 199808.92 | T10: 219376.94 | U10: 219376.94 | V10: 193972.96 | W10: 174032.45 | X10: 166883.51 | Y10: 165047.7 | Z10: 165047.7 | AA10: 153733.69 | AB10: 154965.33
A11: 1 | C11: 당기법인세자산(선급법인세) | E11: 62.9 | F11: 62.9 | G11: 33.31 | H11: 0.09 | I11: 45.29 | J11: 1844.5 | K11: 1844.5 | L11: 1854.79 | M11: 75.97 | N11: 61.12 | O11: 75.13 | P11: 75.13 | Q11: 203.19 | R11: 177.59 | S11: 47.63 | T11: 174.2 | U11: 174.2 | V11: 169.1 | W11: 37.52 | X11: 36.48 | Y11: 197.21 | Z11: 197.21 | AA11: 40.84 | AB11: 40.84
A12: 1 | C12: 계약자산 | E12: 60.09 | F12: 60.09 | G12: 61.37 | H12: 139.5 | I12: 19992.29 | J12: 6794.99 | K12: 6794.99 | L12: 5784.06 | M12: 5839.42 | N12: 6533.31 | O12: 6260.07 | P12: 6260.07 | Q12: 4268.77 | R12: 4369.59 | S12: 2145.51
A13: 1 | C13: 기타유동자산 | E13: 27662.06 | F13: 27662.06 | G13: 24203.9 | H13: 30851.52 | I13: 23492.4 | J13: 11580.25 | K13: 11580.25 | L13: 6556.4 | M13: 8500.8 | N13: 5411.4 | O13: 6727.08 | P13: 6727.08 | Q13: 7850.68 | R13: 8699.01 | S13: 6651.64 | T13: 6201.62 | U13: 6201.62 | V13: 7492.2 | W13: 6306.17 | X13: 5606.12 | Y13: 5956.56 | Z13: 5956.56 | AA13: 10597.22 | AB13: 10886.75
A14: 1 | C14: 비유동자산 | E14: 433062.39 | F14: 433062.39 | G14: 432150.86 | H14: 432157.5 | I14: 426520.87 | J14: 402073.66 | K14: 402073.66 | L14: 401198.54 | M14: 396144.87 | N14: 392192.79 | O14: 387562.5 | P14: 387562.5 | Q14: 374788.61 | R14: 367200.51 | S14: 361682.64 | T14: 380084.48 | U14: 380084.48 | V14: 369347.4 | W14: 364279.11 | X14: 362951.51 | Y14: 367314.96 | Z14: 367314.96 | AA14: 341816.4 | AB14: 343547.33
A15: 1 | C15: 장기금융자산 | E15: 35192.68 | F15: 35192.68 | G15: 35435.37 | H15: 35549.11 | I15: 34977.93 | J15: 33986.41 | K15: 33986.41 | L15: 37722.94 | M15: 38048.65 | N15: 36781.44 | O15: 36992.7 | P15: 36992.7 | Q15: 34034.56 | R15: 30238.61 | S15: 30007.66 | T15: 29972.42 | U15: 29972.42 | V15: 29803.19 | W15: 28198.72 | X15: 28653.21 | Y15: 23857.62 | Z15: 23857.62 | AA15: 21910.97 | AB15: 27711.84
A16: 1 | C16: 투자자산 | E16: 35192.68 | F16: 35192.68 | G16: 35435.37 | H16: 35549.11 | I16: 34977.93 | J16: 33986.41 | K16: 33986.41 | L16: 37722.94 | M16: 38048.65 | N16: 36781.44 | O16: 36992.7 | P16: 36992.7 | Q16: 34034.56 | R16: 30238.61 | S16: 30007.66 | T16: 29972.42 | U16: 29972.42 | V16: 29803.19 | W16: 28198.72 | X16: 28653.21 | Y16: 23857.62 | Z16: 23857.62 | AA16: 21910.97 | AB16: 27711.84
A17: 1 | C17: 유형자산 | E17: 365549.02 | F17: 365549.02 | G17: 366408.14 | H17: 366399.19 | I17: 361565.09 | J17: 322241.77 | K17: 322241.77 | L17: 319797.9 | M17: 315197.55 | N17: 313694.09 | O17: 302201.42 | P17: 302201.42 | Q17: 297181.71 | R17: 296479.32 | S17: 293717.9 | T17: 289575.46 | U17: 289575.46 | V17: 286014.41 | W17: 284320.95 | X17: 285179.85 | Y17: 279921.36 | Z17: 279921.36 | AA17: 276407.37 | AB17: 274244.31
A18: 1 | C18: 투자부동산 | E18: 1301.84 | F18: 1301.84 | G18: 1293.31 | H18: 910.47 | I18: 904.72 | J18: 898.97 | K18: 898.97 | L18: 893.21 | M18: 2008.17 | N18: 1994.65 | O18: 1981.13 | P18: 1981.13 | Q18: 1967.62 | R18: 1954.1 | S18: 1940.58 | T18: 1927.06 | U18: 1927.06 | V18: 1913.55 | W18: 1900.03 | X18: 1886.51 | Y18: 1873 | Z18: 1873 | AA18: 1859.48 | AB18: 1845.96
A19: 1 | C19: 무형자산 | E19: 27998.83 | F19: 27998.83 | G19: 27756.45 | H19: 27514.06 | I19: 27271.68 | J19: 27029.29 | K19: 27029.29 | L19: 26786.91 | M19: 26544.53 | N19: 26302.14 | O19: 27081.76 | P19: 27081.76 | Q19: 26839.38 | R19: 26596.99 | S19: 26354.61
A20: 1 | C20: 이연법인세자산 | E20: 119.66 | F20: 119.66 | G20: 139.56 | H20: 167.8 | I20: 202.69 | J20: 6873.3 | K20: 6873.3 | L20: 8439.76 | M20: 7889.3 | N20: 7729.01 | O20: 13866.9 | P20: 13866.9 | Q20: 12612.71 | R20: 10885.33 | S20: 9404.42 | T20: 11037.56 | U20: 11037.56 | V20: 9838.98 | W20: 9710.3 | X20: 8837.62 | Y20: 8997.84 | Z20: 8997.84 | AA20: 8831.94 | AB20: 8209.84
A21: 1 | C21: 기타비유동자산 | E21: 1808.5 | F21: 1808.5 | G21: 18.86 | H21: 18.1 | I21: 18.56 | J21: 9505.72 | K21: 9505.72 | L21: 7557.82 | M21: 6456.67 | N21: 5691.47 | O21: 5438.59 | P21: 5438.59 | Q21: 2152.63 | R21: 1046.17 | S21: 257.46 | T21: 2.09 | U21: 2.09
A22: 1 | C22: 자산총계 | E22: 863648.5 | F22: 863648.5 | G22: 817564 | H22: 839501.79 | I22: 867034.91 | J22: 854159.33 | K22: 854159.33 | L22: 838013.67 | M22: 865515.17 | N22: 923104.45 | O22: 899461.32 | P22: 899461.32 | Q22: 938339.78 | R22: 909052.97 | S22: 890813.9
A23: 1 | C23: 유동부채 | E23: 320525.54 | F23: 320525.54 | G23: 272846.15 | H23: 294374.53 | I23: 322671.77 | J23: 374995.67 | K23: 374995.67 | L23: 367884.75 | M23: 395847.62 | N23: 453378.85 | O23: 454030.88 | P23: 454030.88 | Q23: 498240.96 | R23: 443428.67 | S23: 417432.52 | T23: 386392.17 | U23: 386392.17 | V23: 369742.09 | W23: 372215.97 | X23: 330022.48 | Y23: 329975.03 | Z23: 329975.03 | AA23: 316255.87 | AB23: 319157.98
A24: 1 | C24: 매입채무및기타채무 | E24: 212254.17 | F24: 212254.17 | G24: 192043.44 | H24: 205094.65 | I24: 188587.42 | J24: 201387.12 | K24: 201387.12 | L24: 211795.1 | M24: 235150.9 | N24: 238064.63 | O24: 270930.14 | P24: 270930.14 | Q24: 278019.12 | R24: 265178.01 | S24: 257210.89 | T24: 244666.17 | U24: 244666.17 | V24: 219497.1 | W24: 228269.98 | X24: 184971.26 | Y24: 188794.21 | Z24: 188794.21 | AA24: 176848.17 | AB24: 204927.73
A25: 1 | C25: 단기차입금 | E25: 34471.7 | F25: 34471.7 | G25: 24161.19 | H25: 31728.61 | I25: 54195.75 | J25: 110019.58 | K25: 110019.58 | L25: 107559.93 | M25: 111575.32 | N25: 170590.04 | O25: 138808.86 | P25: 138808.86 | Q25: 153989.08 | R25: 112119.71 | S25: 111842.2
A26: 1 | C26: 단기금융부채(face) | E26: 34471.7 | F26: 34471.7 | G26: 24161.19 | H26: 31728.61 | I26: 54195.75 | J26: 110019.58 | K26: 110019.58 | L26: 107559.93 | M26: 111575.32 | N26: 170590.04 | O26: 138808.86 | P26: 138808.86 | Q26: 153989.08 | R26: 112119.71 | S26: 111842.2
A27: 1 | C27: 기타유동부채 | E27: 2818.96 | F27: 2818.96 | G27: 2104.93 | H27: 1114.5 | I27: 1167.92 | J27: 1809.07 | K27: 1809.07 | L27: 854.56 | M27: 872.52 | N27: 1258.77 | O27: 2288.57 | P27: 2288.57 | Q27: 2172.26 | R27: 4155.89 | S27: 1672.32 | T27: 2189.16 | U27: 2189.16 | V27: 4379.82 | W27: 3280.87 | X27: 3053.23 | Y27: 3352.75 | Z27: 3352.75 | AA27: 2922.05 | AB27: 1700.28
A28: 1 | C28: 계약부채 | E28: 53733.13 | F28: 53733.13 | G28: 35663.58 | H28: 37324.4 | I28: 60740.46 | J28: 39202.65 | K28: 39202.65 | L28: 28157.45 | M28: 30136.41 | N28: 26094.72 | O28: 24946.51 | P28: 24946.51 | Q28: 39856.15 | R28: 40819.64 | S28: 28235.66 | T28: 35628.21 | U28: 35628.21 | V28: 25298.9 | W28: 19976.68 | X28: 18582.45 | Y28: 21159.5 | Z28: 21159.5 | AA28: 26899.75 | AB28: 38711.05
A29: 1 | C29: 당기법인세부채(미지급법인세) | E29: 707.79 | F29: 707.79 | G29: 1445.75 | H29: 1377.23 | I29: 194.8 | J29: 0 | K29: 0 | L29: 3.18 | M29: 13.26 | N29: 2.53 | O29: 83.4 | P29: 83.4 | Q29: 358.64 | R29: 359.91 | S29: 297.11 | T29: 42.49 | U29: 42.49 | V29: 394.92 | W29: 446.03 | X29: 244.23 | Y29: 78.35 | Z29: 78.35 | AA29: 252.5 | AB29: 522.27
A30: 1 | C30: 단기충당부채 | E30: 2740.18 | F30: 2740.18 | G30: 3172.77 | H30: 3192.44 | I30: 3558.4 | J30: 9051.05 | K30: 9051.05 | L30: 6452.14 | M30: 5059.29 | N30: 4560.31 | O30: 4823.74 | P30: 4823.74 | Q30: 12132.79 | R30: 8355.23 | S30: 5157.5 | T30: 5921.23 | U30: 5921.23 | V30: 4937.72 | W30: 4856.03 | X30: 4679.6 | Y30: 3733.71 | Z30: 3733.71 | AA30: 3279.59 | AB30: 3127.38
A31: 1 | C31: 비유동부채 | E31: 54065.48 | F31: 54065.48 | G31: 55641.18 | H31: 56665.08 | I31: 55049.42 | J31: 40630.56 | K31: 40630.56 | L31: 38393.4 | M31: 36097.74 | N31: 36318.52 | O31: 43073.63 | P31: 43073.63 | Q31: 32988.15 | R31: 52856.45 | S31: 56331.03 | T31: 60250.5 | U31: 60250.5 | V31: 58386.12 | W31: 37522.79 | X31: 28517.56 | Y31: 25209.48 | Z31: 25209.48 | AA31: 64089.26 | AB31: 83113.67
A32: 1 | C32: 장기차입금 | E32: 628.01 | F32: 628.01 | G32: 276.18 | H32: 377.77 | I32: 323.23 | J32: 229.69 | K32: 229.69 | L32: 546.2 | M32: 528.01 | N32: 583.71 | O32: 591.98 | P32: 591.98 | Q32: 177.04 | R32: 20272.17 | S32: 24227.3
A33: 1 | C33: 장기금융부채(face) | E33: 628.01 | F33: 628.01 | G33: 276.18 | H33: 377.77 | I33: 323.23 | J33: 229.69 | K33: 229.69 | L33: 546.2 | M33: 528.01 | N33: 583.71 | O33: 591.98 | P33: 591.98 | Q33: 177.04 | R33: 20272.17 | S33: 24227.3
A34: 1 | C34: 장기충당부채 | E34: 2782.97 | F34: 2782.97 | G34: 2687.59 | H34: 2938.46 | I34: 2917.45 | J34: 2853.05 | K34: 2853.05 | L34: 2767.81 | M34: 2855.78 | N34: 2750.14 | O34: 10851.49 | P34: 10851.49 | Q34: 3014.42 | R34: 3074.15 | S34: 3071.4 | T34: 3155.88 | U34: 3155.88 | V34: 3109.87 | W34: 3321.85 | X34: 3396.67 | Y34: 3013.64 | Z34: 3013.64 | AA34: 2950.24 | AB34: 2735.44
A35: 1 | C35: 이연법인세부채 | E35: 7795.07 | F35: 7795.07 | G35: 7408.92 | H35: 6914.44 | I35: 6562.99 | J35: 0 | K35: 0 | L35: 0 | M35: 0 | N35: 0 | O35: 0 | P35: 0 | Q35: 0 | R35: 0 | S35: 0
A36: 1 | C36: 기타비유동부채 | E36: 1107.41 | F36: 1107.41 | G36: 1081.45 | H36: 1037.66 | I36: 1110.65 | J36: 1175.81 | K36: 1175.81 | L36: 1249.6 | M36: 1260.48 | N36: 1279.18 | O36: 1410.78 | P36: 1410.78 | Q36: 1413.37 | R36: 1423.17 | S36: 1432.7 | T36: 1750.34 | U36: 1750.34 | V36: 1811.24 | W36: 1746.52 | X36: 1871.23 | Y36: 2330.66 | Z36: 2330.66 | AA36: 2370.62 | AB36: 2395.89
A37: 1 | C37: 부채총계 | E37: 374591.02 | F37: 374591.02 | G37: 328487.33 | H37: 351039.6 | I37: 377721.19 | J37: 415626.22 | K37: 415626.22 | L37: 406278.15 | M37: 431945.35 | N37: 489697.37 | O37: 497104.51 | P37: 497104.51 | Q37: 531229.11 | R37: 496285.12 | S37: 473763.55
A38: 1 | C38: 지배주주지분 | E38: 489057.48 | F38: 489057.48 | G38: 489076.67 | H38: 488462.18 | I38: 489313.72 | J38: 438533.11 | K38: 438533.11 | L38: 431735.52 | M38: 433569.82 | N38: 433407.08 | O38: 402356.81 | P38: 402356.81 | Q38: 407110.67 | R38: 412767.85 | S38: 417050.36 | T38: 411743.74 | U38: 411743.74 | V38: 415581.89 | W38: 415543.55 | X38: 418680.54 | Y38: 418071.67 | Z38: 418071.67 | AA38: 417032.82 | AB38: 420662.43
A39: 1 | C39: 자본금 | E39: 20535.28 | F39: 20535.28 | G39: 20535.28 | H39: 20535.28 | I39: 20535.28 | J39: 20535.28 | K39: 20535.28 | L39: 20535.28 | M39: 20535.28 | N39: 20535.28 | O39: 20535.28 | P39: 20535.28 | Q39: 20535.28 | R39: 20535.28 | S39: 20535.28 | T39: 20535.28 | U39: 20535.28 | V39: 20535.28 | W39: 20535.28 | X39: 20535.28 | Y39: 20535.28 | Z39: 20535.28 | AA39: 20535.28 | AB39: 20535.28
A40: 1 | C40: 자본잉여금 | E40: 101695.16 | F40: 101695.16 | G40: 101695.16 | H40: 101695.16 | I40: 101695.16 | J40: 101695.16 | K40: 101695.16 | L40: 101695.16 | M40: 101695.16 | N40: 101695.16 | O40: 101695.16 | P40: 101695.16 | Q40: 101695.16 | R40: 101695.16 | S40: 101695.16 | T40: 101695.16 | U40: 101695.16 | V40: 101695.16 | W40: 101695.16 | X40: 101695.16 | Y40: 101695.16 | Z40: 101695.16 | AA40: 101695.16 | AB40: 101695.16
...

Sheet BS별도
B1: (백만원) | C1: 이름: BS별도H | E1: 4Q21 | F1: 2021 | G1: 1Q22 | H1: 2Q22 | I1: 3Q22 | J1: 4Q22 | K1: 2022 | L1: 1Q23 | M1: 2Q23 | N1: 3Q23 | O1: 4Q23 | P1: 2023 | Q1: 1Q24 | R1: 2Q24 | S1: 3Q24 | T1: 4Q24 | U1: 2024 | V1: 1Q25 | W1: 2Q25 | X1: 3Q25 | Y1: 4Q25 | Z1: 2025 | AA1: 1Q26 | AB1: 2Q26 | AC1: 3Q26 | AD1: 4Q26 | AE1: 2026 | AF1: 1Q27 | AG1: 2Q27 | AH1: 3Q27 | AI1: 4Q27 | AJ1: 2027 | AK1: 1Q28 | AL1: 2Q28 | AM1: 3Q28 | AN1: 4Q28 | AO1: 2028
B2: 별도 | D2: fin json(kship_fin.py)
B3: 현대리바트(별) | C3: UPDATE: 26-10-11 | E3: 1 | F3: 2 | G3: 3 | H3: 4 | I3: 5 | J3: 6 | K3: 7 | L3: 8 | M3: 9 | N3: 10 | O3: 11 | P3: 12 | Q3: 13 | R3: 14 | S3: 15 | T3: 16 | U3: 17 | V3: 18 | W3: 19 | X3: 20 | Y3: 21 | Z3: 22 | AA3: 23 | AB3: 24 | AC3: 25 | AD3: 26 | AE3: 27 | AF3: 28 | AG3: 29 | AH3: 30 | AI3: 31 | AJ3: 32 | AK3: 33 | AL3: 34 | AM3: 35 | AN3: 36 | AO3: 37
B4: Account Code | C4: AccountNAME | E4: 2021.12 | F4: 2021.12A | G4: 2022.03 | H4: 2022.06 | I4: 2022.09 | J4: 2022.12 | K4: 2022.12A | L4: 2023.03 | M4: 2023.06 | N4: 2023.09 | O4: 2023.12 | P4: 2023.12A | Q4: 2024.03 | R4: 2024.06 | S4: 2024.09 | T4: 2024.12 | U4: 2024.12A | V4: 2025.03 | W4: 2025.06 | X4: 2025.09 | Y4: 2025.12 | Z4: 2025.12A | AA4: 2026.03 | AB4: 2026.06 | AC4: 2026.09 | AD4: 2026.12 | AE4: 2026.12A | AF4: 2027.03 | AG4: 2027.06 | AH4: 2027.09 | AI4: 2027.12 | AJ4: 2027.12A | AK4: 2028.03 | AL4: 2028.06 | AM4: 2028.09 | AN4: 2028.12 | AO4: 2028.12A
A5: 1 | C5: 유동자산 | E5: 422929.92 | F5: 422929.92 | G5: 378492.77 | H5: 398793.92 | I5: 432112.23 | J5: 447441.04 | K5: 447441.04 | L5: 429806.46 | M5: 463656.89 | N5: 524621.11 | O5: 503826.87 | P5: 503826.87 | Q5: 554212.11 | R5: 533385.99 | S5: 520419.39 | T5: 469657 | U5: 469657 | V5: 463387.66 | W5: 449884.57 | X5: 403310.62 | Y5: 398061.05 | Z5: 398061.05 | AA5: 444422.27 | AB5: 469415.94
A6: 1 | C6: 현금및현금성자산 | E6: 8495.23 | F6: 8495.23 | G6: 6265.28 | H6: 5593.66 | I6: 7340.08 | J6: 11240.16 | K6: 11240.16 | L6: 15404.67 | M6: 10282.32 | N6: 12635.2 | O6: 18108.25 | P6: 18108.25 | Q6: 5709.74 | R6: 6891.07 | S6: 53508.92 | T6: 13963.04 | U6: 13963.04 | V6: 13764.41 | W6: 24215.67 | X6: 9389.26 | Y6: 12866.58 | Z6: 12866.58 | AA6: 23969.17 | AB6: 55729.05
A7: 1 | C7: 매출채권및기타채권 | E7: 240198.07 | F7: 240198.07 | G7: 213872.22 | H7: 206457.97 | I7: 215921.82 | J7: 251113.39 | K7: 251113.39 | L7: 234194.05 | M7: 248760.92 | N7: 295960.33 | O7: 265226.19 | P7: 265226.19 | Q7: 338580.41 | R7: 322116.44 | S7: 257619.45 | T7: 229730.44 | U7: 229730.44 | V7: 247789.02 | W7: 240997.15 | X7: 217793.85 | Y7: 206230.1 | Z7: 206230.1 | AA7: 226287.46 | AB7: 226498.83
A8: 1 | C8: 단기금융상품 | E8: 8801.38 | F8: 8801.38 | G8: 7880.93 | H8: 7594.57 | I8: 7617.15 | J8: 7664.4 | K8: 7664.4 | L8: 5792.95 | M8: 5450.21 | N8: 5636.41 | O8: 5461.67 | P8: 5461.67 | Q8: 5386.68 | R8: 8855.57 | S8: 9145.65
A9: 1 | C9: 단기금융자산 | E9: 8801.38 | F9: 8801.38 | G9: 7880.93 | H9: 7594.57 | I9: 7617.15 | J9: 7664.4 | K9: 7664.4 | L9: 5792.95 | M9: 5450.21 | N9: 5636.41 | O9: 5461.67 | P9: 5461.67 | Q9: 5386.68 | R9: 8855.57 | S9: 9145.65
A10: 1 | C10: 재고자산 | E10: 138877.55 | F10: 138877.55 | G10: 128542.95 | H10: 150214.53 | I10: 161652.06 | J10: 158197.77 | K10: 158197.77 | L10: 162465.09 | M10: 185658.37 | N10: 199273.29 | O10: 203274.54 | P10: 203274.54 | Q10: 193199.62 | R10: 184105.91 | S10: 192262 | T10: 210718.83 | U10: 210718.83 | V10: 185593.71 | W10: 168687.95 | X10: 161682.84 | Y10: 160221.43 | Z10: 160221.43 | AA10: 149420.19 | AB10: 149990.98
A11: 1 | C11: 당기법인세자산(선급법인세) | E11: 62.9 | F11: 62.9 | G11: 33.31 | I11: 27.11 | J11: 1821.24 | K11: 1821.24 | L11: 1838.78 | M11: 59.83 | N11: 45.22 | O11: 46.59 | P11: 46.59 | Q11: 178.8 | R11: 166.33 | S11: 36.58 | T11: 173.16 | U11: 173.16 | V11: 168.07 | W11: 36.48 | X11: 36.48 | Y11: 197.21 | Z11: 197.21 | AA11: 40.84 | AB11: 40.84
A12: 1 | C12: 계약자산 | E12: 60.09 | F12: 60.09 | G12: 61.37 | H12: 139.5 | I12: 19992.29 | J12: 6794.99 | K12: 6794.99 | L12: 5784.06 | M12: 5839.42 | N12: 6533.31 | O12: 6260.07 | P12: 6260.07 | Q12: 4268.77 | R12: 4369.59 | S12: 2145.51
A13: 1 | C13: 기타유동자산 | E13: 26434.7 | F13: 26434.7 | G13: 21836.71 | H13: 28793.69 | I13: 19561.72 | J13: 10609.1 | K13: 10609.1 | L13: 4326.86 | M13: 7605.81 | N13: 4537.35 | O13: 5449.56 | P13: 5449.56 | Q13: 6888.09 | R13: 6881.07 | S13: 5701.29 | T13: 4897.43 | U13: 4897.43 | V13: 5401.3 | W13: 4136.11 | X13: 3880.8 | Y13: 4146.29 | Z13: 4146.29 | AA13: 8553.34 | AB13: 8722.87
A14: 1 | C14: 비유동자산 | E14: 430902.98 | F14: 430902.98 | G14: 430036.6 | H14: 430768.18 | I14: 425066.13 | J14: 401153.05 | K14: 401153.05 | L14: 400518.99 | M14: 395867.17 | N14: 392099.58 | O14: 387788.51 | P14: 387788.51 | Q14: 375334.32 | R14: 368025.73 | S14: 361181.5 | T14: 379095 | U14: 379095 | V14: 368893.11 | W14: 362860.32 | X14: 361464.16 | Y14: 364951.71 | Z14: 364951.71 | AA14: 340611.06 | AB14: 342773.26
A15: 1 | C15: 장기금융자산 | E15: 34885.4 | F15: 34885.4 | G15: 35118.26 | H15: 35221.23 | I15: 34634.54 | J15: 33676.13 | K15: 33676.13 | L15: 37355.92 | M15: 37673.33 | N15: 36408.7 | O15: 36922.77 | P15: 36922.77 | Q15: 33964.3 | R15: 30170.22 | S15: 29938.84 | T15: 29803.18 | U15: 29803.18 | V15: 29637.43 | W15: 28033.74 | X15: 28488.09 | Y15: 23692.13 | Z15: 23692.13 | AA15: 21744.8 | AB15: 27508.51
A16: 1 | C16: 투자자산 | E16: 37686.26 | F16: 37686.26 | G16: 37919.12 | H16: 38669.34 | I16: 38082.65 | J16: 37124.24 | K16: 37124.24 | L16: 40804.03 | M16: 41121.44 | N16: 39856.81 | O16: 40370.88 | P16: 40370.88 | Q16: 37412.41 | R16: 33618.33 | S16: 33386.95 | T16: 33751.29 | U16: 33751.29 | V16: 33585.54 | W16: 31981.85 | X16: 32436.2 | Y16: 27640.24 | Z16: 27640.24 | AA16: 25692.91 | AB16: 27508.51
A17: 1 | C17: 종속기업및관계기업투자 | E17: 2800.86 | F17: 2800.86 | G17: 2800.86 | H17: 3448.11 | I17: 3448.11 | J17: 3448.11 | K17: 3448.11 | L17: 3448.11 | M17: 3448.11 | N17: 3448.11 | O17: 3448.11 | P17: 3448.11 | Q17: 3448.11 | R17: 3448.11 | S17: 3448.11 | T17: 3948.11 | U17: 3948.11 | V17: 3948.11 | W17: 3948.11 | X17: 3948.11 | Y17: 3948.11 | Z17: 3948.11 | AA17: 3948.11
A18: 1 | C18: 유형자산 | E18: 360983.13 | F18: 360983.13 | G18: 362000.39 | H18: 362108.14 | I18: 357259.01 | J18: 318632.28 | K18: 318632.28 | L18: 316355.39 | M18: 311983.37 | N18: 310615.92 | O18: 299438.69 | P18: 299438.69 | Q18: 294581.03 | R18: 294051.19 | S18: 289947.7 | T18: 285837.08 | U18: 285837.08 | V18: 282581.27 | W18: 279897.2 | X18: 280538.79 | Y18: 275525.93 | Z18: 275525.93 | AA18: 272163.14 | AB18: 270364.63
A19: 1 | C19: 투자부동산 | E19: 1301.84 | F19: 1301.84 | G19: 1293.31 | H19: 910.47 | I19: 904.72 | J19: 898.97 | K19: 898.97 | L19: 893.21 | M19: 2008.17 | N19: 1994.65 | O19: 1981.13 | P19: 1981.13 | Q19: 1967.62 | R19: 1954.1 | S19: 1940.58 | T19: 1927.06 | U19: 1927.06 | V19: 1913.55 | W19: 1900.03 | X19: 1886.51 | Y19: 1873 | Z19: 1873 | AA19: 1859.48 | AB19: 1845.96
A20: 1 | C20: 무형자산 | E20: 27998.83 | F20: 27998.83 | G20: 27756.45 | H20: 27514.06 | I20: 27271.68 | J20: 27029.29 | K20: 27029.29 | L20: 26786.91 | M20: 26544.53 | N20: 26302.14 | O20: 27081.76 | P20: 27081.76 | Q20: 26839.38 | R20: 26596.99 | S20: 26354.61
A21: 1 | C21: 기타비유동자산 | E21: 1891.75 | F21: 1891.75 | G21: 18.86 | H21: 18.1 | I21: 18.56 | J21: 9169.31 | K21: 9169.31 | L21: 7293.08 | M21: 6385.55 | N21: 5673.89 | O21: 5160.72 | P21: 5160.72 | Q21: 2020.29 | R21: 1022.32 | S21: 257.46 | T21: 2.09 | U21: 2.09
A22: 1 | C22: 자산총계 | E22: 853832.89 | F22: 853832.89 | G22: 808529.37 | H22: 829562.1 | I22: 857178.35 | J22: 848594.09 | K22: 848594.09 | L22: 830325.45 | M22: 859524.06 | N22: 916720.69 | O22: 891615.38 | P22: 891615.38 | Q22: 929546.43 | R22: 901411.72 | S22: 881600.89
A23: 1 | C23: 유동부채 | E23: 315248.63 | F23: 315248.63 | G23: 268209.52 | H23: 288971.68 | I23: 317200.39 | J23: 372180.01 | K23: 372180.01 | L23: 362201.15 | M23: 391665.83 | N23: 448200.86 | O23: 448544.76 | P23: 448544.76 | Q23: 491706.64 | R23: 438934.9 | S23: 412570.14 | T23: 381760.23 | U23: 381760.23 | V23: 363727.15 | W23: 364840.43 | X23: 322941.25 | Y23: 324690.44 | Z23: 324690.44 | AA23: 309340.79 | AB23: 314008.2
A24: 1 | C24: 매입채무및기타채무 | E24: 209858.21 | F24: 209858.21 | G24: 190842.08 | H24: 203165.26 | I24: 186523.1 | J24: 200149.63 | K24: 200149.63 | L24: 207551.01 | M24: 233164.81 | N24: 234580.31 | O24: 267920.97 | P24: 267920.97 | Q24: 273547.7 | R24: 261871.23 | S24: 254684.09 | T24: 241952.33 | U24: 241952.33 | V24: 216273.56 | W24: 224132.84 | X24: 181371.84 | Y24: 186857.19 | Z24: 186857.19 | AA24: 173358.49 | AB24: 202796.01
A25: 1 | C25: 단기차입금 | E25: 34191.16 | F25: 34191.16 | G25: 23419.58 | H25: 30916.47 | I25: 53610.96 | J25: 109452.45 | K25: 109452.45 | L25: 107081.85 | M25: 110805.05 | N25: 170308.05 | O25: 137722.8 | P25: 137722.8 | Q25: 153081.87 | R25: 111741.04 | S25: 111469.8
A26: 1 | C26: 단기금융부채(face) | E26: 34191.16 | F26: 34191.16 | G26: 23419.58 | H26: 30916.47 | I26: 53610.96 | J26: 109452.45 | K26: 109452.45 | L26: 107081.85 | M26: 110805.05 | N26: 170308.05 | O26: 137722.8 | P26: 137722.8 | Q26: 153081.87 | R26: 111741.04 | S26: 111469.8
A27: 1 | C27: 계약부채 | E27: 52427.35 | F27: 52427.35 | G27: 34340.17 | H27: 35974.35 | I27: 59315.2 | J27: 39199.05 | K27: 39199.05 | L27: 28169.83 | M27: 29704.59 | N27: 25726.51 | O27: 24530.36 | P27: 24530.36 | Q27: 39538.11 | R27: 40573.07 | S27: 27547.03 | T27: 35183.22 | U27: 35183.22 | V27: 24171.53 | W27: 19217.34 | X27: 17716.47 | Y27: 20488.6 | Z27: 20488.6 | AA27: 25906.56 | AB27: 37955.69
A28: 1 | C28: 기타유동부채 | E28: 2414.57 | F28: 2414.57 | G28: 1683.77 | H28: 750.64 | I28: 782.14 | J28: 1664.66 | K28: 1664.66 | L28: 741.51 | M28: 756.68 | N28: 874.76 | O28: 1894.85 | P28: 1894.85 | Q28: 1712.07 | R28: 3717.82 | S28: 1189.44 | T28: 1703.35 | U28: 1703.35 | V28: 3788.95 | W28: 2873.39 | X28: 2460.58 | Y28: 2833.11 | Z28: 2833.11 | AA28: 2529.18 | AB28: 1233.11
A29: 1 | C29: 당기법인세부채(미지급법인세) | E29: 667.32 | F29: 667.32 | G29: 1380.95 | H29: 1300.68 | I29: 98.82 | J29: 0 | K29: 0 | L29: 0 | M29: 0 | N29: 0 | O29: 0 | P29: 0 | Q29: 265.01 | R29: 322.15 | S29: 244.21 | V29: 267.85 | W29: 345.49 | X29: 199.94 | AA29: 11.02 | AB29: 181.93
A30: 1 | C30: 단기충당부채 | E30: 2740.18 | F30: 2740.18 | G30: 3172.77 | H30: 3192.44 | I30: 3558.4 | J30: 9051.05 | K30: 9051.05 | L30: 6452.14 | M30: 5059.29 | N30: 4560.31 | O30: 4823.74 | P30: 4823.74 | Q30: 12132.79 | R30: 8355.23 | S30: 5157.5 | T30: 5921.23 | U30: 5921.23 | V30: 4937.72 | W30: 4856.03 | X30: 4679.6 | Y30: 3733.71 | Z30: 3733.71 | AA30: 3279.59 | AB30: 3127.38
A31: 1 | C31: 비유동부채 | E31: 52814.92 | F31: 52814.92 | G31: 54351.65 | H31: 55341.61 | I31: 53744.42 | J31: 40173.51 | K31: 40173.51 | L31: 38103.19 | M31: 36045.97 | N31: 36287.24 | O31: 43053.05 | P31: 43053.05 | Q31: 32948.53 | R31: 52810.77 | S31: 55285.14 | T31: 59445.91 | U31: 59445.91 | V31: 57525.49 | W31: 36488.42 | X31: 27504.64 | Y31: 24887.3 | Z31: 24887.3 | AA31: 63748.47 | AB31: 82760.93
A32: 1 | C32: 장기차입금 | E32: 590.79 | F32: 590.79 | G32: 237.38 | H32: 337.65 | I32: 281.28 | J32: 192.27 | K32: 192.27 | L32: 507.63 | M32: 528.01 | N32: 583.71 | O32: 591.98 | P32: 591.98 | Q32: 177.04 | R32: 20272.17 | S32: 24227.3
A33: 1 | C33: 장기금융부채(face) | E33: 590.79 | F33: 590.79 | G33: 237.38 | H33: 337.65 | I33: 281.28 | J33: 192.27 | K33: 192.27 | L33: 507.63 | M33: 528.01 | N33: 583.71 | O33: 591.98 | P33: 591.98 | Q33: 177.04 | R33: 20272.17 | S33: 24227.3
A34: 1 | C34: 장기충당부채 | E34: 2782.97 | F34: 2782.97 | G34: 2687.59 | H34: 2938.46 | I34: 2917.45 | J34: 2853.05 | K34: 2853.05 | L34: 2767.81 | M34: 2855.78 | N34: 2750.14 | O34: 10851.49 | P34: 10851.49 | Q34: 3014.42 | R34: 3074.15 | S34: 3071.4 | T34: 3155.88 | U34: 3155.88 | V34: 3109.87 | W34: 3321.85 | X34: 3396.67 | Y34: 3013.64 | Z34: 3013.64 | AA34: 2950.24 | AB34: 2735.44
A35: 1 | C35: 확정급여부채 | E35: 0 | F35: 0 | G35: 1940.64 | H35: 3140.53 | I35: 4231.98 | J35: 0 | K35: 0 | L35: 0 | M35: 0 | N35: 0 | X35: 625.2
A36: 1 | C36: 이연법인세부채 | E36: 7795.07 | F36: 7795.07 | G36: 7408.92 | H36: 6914.44 | I36: 6562.99 | J36: 0 | K36: 0 | L36: 0 | M36: 0 | N36: 0 | O36: 0 | P36: 0 | Q36: 0 | R36: 0 | S36: 0
A37: 1 | C37: 기타비유동부채 | E37: 1107.41 | F37: 1107.41 | G37: 1081.45 | H37: 1037.66 | I37: 1110.65 | J37: 1175.81 | K37: 1175.81 | L37: 1249.6 | M37: 1260.48 | N37: 1279.18 | O37: 1410.78 | P37: 1410.78 | Q37: 1413.37 | R37: 1423.17 | S37: 1432.7 | T37: 1750.34 | U37: 1750.34 | V37: 1771.39 | W37: 1666.08 | X37: 1678.82 | Y37: 2068.32 | Z37: 2068.32 | AA37: 2109.19 | AB37: 2132.03
A38: 1 | C38: 부채총계 | E38: 368063.55 | F38: 368063.55 | G38: 322561.17 | H38: 344313.28 | I38: 370944.81 | J38: 412353.52 | K38: 412353.52 | L38: 400304.34 | M38: 427711.8 | N38: 484488.1 | O38: 491597.8 | P38: 491597.8 | Q38: 524655.17 | R38: 491745.67 | S38: 467855.27
A39: 1 | C39: 자본금 | E39: 20535.28 | F39: 20535.28 | G39: 20535.28 | H39: 20535.28 | I39: 20535.28 | J39: 20535.28 | K39: 20535.28 | L39: 20535.28 | M39: 20535.28 | N39: 20535.28 | O39: 20535.28 | P39: 20535.28 | Q39: 20535.28 | R39: 20535.28 | S39: 20535.28 | T39: 20535.28 | U39: 20535.28 | V39: 20535.28 | W39: 20535.28 | X39: 20535.28 | Y39: 20535.28 | Z39: 20535.28 | AA39: 20535.28 | AB39: 20535.28
A40: 1 | C40: 자본잉여금 | E40: 102586.87 | F40: 102586.87 | G40: 102586.87 | H40: 102586.87 | I40: 102586.87 | J40: 102586.87 | K40: 102586.87 | L40: 102586.87 | M40: 102586.87 | N40: 102586.87 | O40: 102586.87 | P40: 102586.87 | Q40: 102586.87 | R40: 102586.87 | S40: 102586.87 | T40: 102586.87 | U40: 102586.87 | V40: 102586.87 | W40: 102586.87 | X40: 102586.87 | Y40: 102586.87 | Z40: 102586.87 | AA40: 102586.87 | AB40: 102586.87
...

Sheet subQ
A1: YQ | C1: subQ 분기 서브모델(억원, U=100) | E1: 4Q21 | F1: 2021 | G1: 1Q22 | H1: 2Q22 | I1: 3Q22 | J1: 4Q22 | K1: 2022 | L1: 1Q23 | M1: 2Q23 | N1: 3Q23 | O1: 4Q23 | P1: 2023 | Q1: 1Q24 | R1: 2Q24 | S1: 3Q24 | T1: 4Q24 | U1: 2024 | V1: 1Q25 | W1: 2Q25 | X1: 3Q25 | Y1: 4Q25 | Z1: 2025 | AA1: 1Q26 | AB1: 2Q26 | AC1: 3Q26 | AD1: 4Q26 | AE1: 2026 | AF1: 1Q27 | AG1: 2Q27 | AH1: 3Q27 | AI1: 4Q27 | AJ1: 2027 | AK1: 1Q28 | AL1: 2Q28 | AM1: 3Q28 | AN1: 4Q28 | AO1: 2028
A2: A=이름(key) B=그룹 C=단위 D=FnGuide 계정명(VLOOKUP 키). 확정=VLOOKUP(BS), 추정=변수 가정 참조
E3: 1 | F3: 2 | G3: 3 | H3: 4 | I3: 5 | J3: 6 | K3: 7 | L3: 8 | M3: 9 | N3: 10 | O3: 11 | P3: 12 | Q3: 13 | R3: 14 | S3: 15 | T3: 16 | U3: 17 | V3: 18 | W3: 19 | X3: 20 | Y3: 21 | Z3: 22 | AA3: 23 | AB3: 24 | AC3: 25 | AD3: 26 | AE3: 27 | AF3: 28 | AG3: 29 | AH3: 30 | AI3: 31 | AJ3: 32 | AK3: 33 | AL3: 34 | AM3: 35 | AN3: 36 | AO3: 37
E4: 2021.12 | F4: 2021.12A | G4: 2022.03 | H4: 2022.06 | I4: 2022.09 | J4: 2022.12 | K4: 2022.12A | L4: 2023.03 | M4: 2023.06 | N4: 2023.09 | O4: 2023.12 | P4: 2023.12A | Q4: 2024.03 | R4: 2024.06 | S4: 2024.09 | T4: 2024.12 | U4: 2024.12A | V4: 2025.03 | W4: 2025.06 | X4: 2025.09 | Y4: 2025.12 | Z4: 2025.12A | AA4: 2026.03 | AB4: 2026.06 | AC4: 2026.09 | AD4: 2026.12 | AE4: 2026.12A | AF4: 2027.03 | AG4: 2027.06 | AH4: 2027.09 | AI4: 2027.12 | AJ4: 2027.12A | AK4: 2028.03 | AL4: 2028.06 | AM4: 2028.09 | AN4: 2028.12 | AO4: 2028.12A
A5: 매출액 | B5: 손익 | C5: 억원 | D5: 매출액(수익) | E5: =IFERROR(VLOOKUP($D5,BS연결,MATCH(E$1,BS연결H,0),0)/100,"") | G5: =IFERROR(VLOOKUP($D5,BS연결,MATCH(G$1,BS연결H,0),0)/100,"") | H5: =IFERROR(VLOOKUP($D5,BS연결,MATCH(H$1,BS연결H,0),0)/100,"") | I5: =IFERROR(VLOOKUP($D5,BS연결,MATCH(I$1,BS연결H,0),0)/100,"") | J5: =IFERROR(VLOOKUP($D5,BS연결,MATCH(J$1,BS연결H,0),0)/100,"") | K5: =IFERROR(VLOOKUP($D5,BS연결,MATCH(K$1,BS연결H,0),0)/100,"") | L5: =IFERROR(VLOOKUP($D5,BS연결,MATCH(L$1,BS연결H,0),0)/100,"") | M5: =IFERROR(VLOOKUP($D5,BS연결,MATCH(M$1,BS연결H,0),0)/100,"") | N5: =IFERROR(VLOOKUP($D5,BS연결,MATCH(N$1,BS연결H,0),0)/100,"") | ... AB5: =IFERROR(VLOOKUP($D5,BS연결,MATCH(AB$1,BS연결H,0),0)/100,"") | AC5: =IFERROR(X5*(1+변수!AC21),"") | AD5: =IFERROR(Y5*(1+변수!AD21),"") | AE5: =SUM(AA5:AD5) | AF5: =IFERROR(AA5*(1+변수!AF21),"") | AG5: =IFERROR(AB5*(1+변수!AG21),"") | AH5: =IFERROR(AC5*(1+변수!AH21),"") | AI5: =IFERROR(AD5*(1+변수!AI21),"") | AJ5: =SUM(AF5:AI5) | AK5: =IFERROR(AF5*(1+변수!AK21),"") | AL5: =IFERROR(AG5*(1+변수!AL21),"") | AM5: =IFERROR(AH5*(1+변수!AM21),"") | AN5: =IFERROR(AI5*(1+변수!AN21),"") | AO5: =SUM(AK5:AN5)
A6: 매출원가 | B6: 손익 | C6: 억원 | D6: 매출원가 | E6: =IFERROR(VLOOKUP($D6,BS연결,MATCH(E$1,BS연결H,0),0)/100,"") | G6: =IFERROR(VLOOKUP($D6,BS연결,MATCH(G$1,BS연결H,0),0)/100,"") | H6: =IFERROR(VLOOKUP($D6,BS연결,MATCH(H$1,BS연결H,0),0)/100,"") | I6: =IFERROR(VLOOKUP($D6,BS연결,MATCH(I$1,BS연결H,0),0)/100,"") | J6: =IFERROR(VLOOKUP($D6,BS연결,MATCH(J$1,BS연결H,0),0)/100,"") | K6: =IFERROR(VLOOKUP($D6,BS연결,MATCH(K$1,BS연결H,0),0)/100,"") | L6: =IFERROR(VLOOKUP($D6,BS연결,MATCH(L$1,BS연결H,0),0)/100,"") | M6: =IFERROR(VLOOKUP($D6,BS연결,MATCH(M$1,BS연결H,0),0)/100,"") | N6: =IFERROR(VLOOKUP($D6,BS연결,MATCH(N$1,BS연결H,0),0)/100,"") | ... AB6: =IFERROR(VLOOKUP($D6,BS연결,MATCH(AB$1,BS연결H,0),0)/100,"") | AC6: =IFERROR(AC5-AC7,"") | AD6: =IFERROR(AD5-AD7,"") | AE6: =SUM(AA6:AD6) | AF6: =IFERROR(AF5-AF7,"") | AG6: =IFERROR(AG5-AG7,"") | AH6: =IFERROR(AH5-AH7,"") | AI6: =IFERROR(AI5-AI7,"") | AJ6: =SUM(AF6:AI6) | AK6: =IFERROR(AK5-AK7,"") | AL6: =IFERROR(AL5-AL7,"") | AM6: =IFERROR(AM5-AM7,"") | AN6: =IFERROR(AN5-AN7,"") | AO6: =SUM(AK6:AN6)
A7: 매출총이익 | B7: 손익 | C7: 억원 | D7: 매출총이익 | E7: =IFERROR(VLOOKUP($D7,BS연결,MATCH(E$1,BS연결H,0),0)/100,"") | G7: =IFERROR(VLOOKUP($D7,BS연결,MATCH(G$1,BS연결H,0),0)/100,"") | H7: =IFERROR(VLOOKUP($D7,BS연결,MATCH(H$1,BS연결H,0),0)/100,"") | I7: =IFERROR(VLOOKUP($D7,BS연결,MATCH(I$1,BS연결H,0),0)/100,"") | J7: =IFERROR(VLOOKUP($D7,BS연결,MATCH(J$1,BS연결H,0),0)/100,"") | K7: =IFERROR(VLOOKUP($D7,BS연결,MATCH(K$1,BS연결H,0),0)/100,"") | L7: =IFERROR(VLOOKUP($D7,BS연결,MATCH(L$1,BS연결H,0),0)/100,"") | M7: =IFERROR(VLOOKUP($D7,BS연결,MATCH(M$1,BS연결H,0),0)/100,"") | N7: =IFERROR(VLOOKUP($D7,BS연결,MATCH(N$1,BS연결H,0),0)/100,"") | ... AB7: =IFERROR(VLOOKUP($D7,BS연결,MATCH(AB$1,BS연결H,0),0)/100,"") | AC7: =IFERROR(AC9+AC8,"") | AD7: =IFERROR(AD9+AD8,"") | AE7: =SUM(AA7:AD7) | AF7: =IFERROR(AF9+AF8,"") | AG7: =IFERROR(AG9+AG8,"") | AH7: =IFERROR(AH9+AH8,"") | AI7: =IFERROR(AI9+AI8,"") | AJ7: =SUM(AF7:AI7) | AK7: =IFERROR(AK9+AK8,"") | AL7: =IFERROR(AL9+AL8,"") | AM7: =IFERROR(AM9+AM8,"") | AN7: =IFERROR(AN9+AN8,"") | AO7: =SUM(AK7:AN7)
A8: 판관비 | B8: 손익 | C8: 억원 | D8: 판관비 | E8: =IFERROR(VLOOKUP($D8,BS연결,MATCH(E$1,BS연결H,0),0)/100,"") | G8: =IFERROR(VLOOKUP($D8,BS연결,MATCH(G$1,BS연결H,0),0)/100,"") | H8: =IFERROR(VLOOKUP($D8,BS연결,MATCH(H$1,BS연결H,0),0)/100,"") | I8: =IFERROR(VLOOKUP($D8,BS연결,MATCH(I$1,BS연결H,0),0)/100,"") | J8: =IFERROR(VLOOKUP($D8,BS연결,MATCH(J$1,BS연결H,0),0)/100,"") | K8: =IFERROR(VLOOKUP($D8,BS연결,MATCH(K$1,BS연결H,0),0)/100,"") | L8: =IFERROR(VLOOKUP($D8,BS연결,MATCH(L$1,BS연결H,0),0)/100,"") | M8: =IFERROR(VLOOKUP($D8,BS연결,MATCH(M$1,BS연결H,0),0)/100,"") | N8: =IFERROR(VLOOKUP($D8,BS연결,MATCH(N$1,BS연결H,0),0)/100,"") | ... AB8: =IFERROR(VLOOKUP($D8,BS연결,MATCH(AB$1,BS연결H,0),0)/100,"") | AC8: =IFERROR(AC5*변수!AC22,"") | AD8: =IFERROR(AD5*변수!AD22,"") | AE8: =SUM(AA8:AD8) | AF8: =IFERROR(AF5*변수!AF22,"") | AG8: =IFERROR(AG5*변수!AG22,"") | AH8: =IFERROR(AH5*변수!AH22,"") | AI8: =IFERROR(AI5*변수!AI22,"") | AJ8: =SUM(AF8:AI8) | AK8: =IFERROR(AK5*변수!AK22,"") | AL8: =IFERROR(AL5*변수!AL22,"") | AM8: =IFERROR(AM5*변수!AM22,"") | AN8: =IFERROR(AN5*변수!AN22,"") | AO8: =SUM(AK8:AN8)
A9: 영업이익 | B9: 손익 | C9: 억원 | D9: 영업이익 | E9: =IFERROR(VLOOKUP($D9,BS연결,MATCH(E$1,BS연결H,0),0)/100,"") | G9: =IFERROR(VLOOKUP($D9,BS연결,MATCH(G$1,BS연결H,0),0)/100,"") | H9: =IFERROR(VLOOKUP($D9,BS연결,MATCH(H$1,BS연결H,0),0)/100,"") | I9: =IFERROR(VLOOKUP($D9,BS연결,MATCH(I$1,BS연결H,0),0)/100,"") | J9: =IFERROR(VLOOKUP($D9,BS연결,MATCH(J$1,BS연결H,0),0)/100,"") | K9: =IFERROR(VLOOKUP($D9,BS연결,MATCH(K$1,BS연결H,0),0)/100,"") | L9: =IFERROR(VLOOKUP($D9,BS연결,MATCH(L$1,BS연결H,0),0)/100,"") | M9: =IFERROR(VLOOKUP($D9,BS연결,MATCH(M$1,BS연결H,0),0)/100,"") | N9: =IFERROR(VLOOKUP($D9,BS연결,MATCH(N$1,BS연결H,0),0)/100,"") | ... AB9: =IFERROR(VLOOKUP($D9,BS연결,MATCH(AB$1,BS연결H,0),0)/100,"") | AC9: =IFERROR(AC5*변수!AC23,"") | AD9: =IFERROR(AD5*변수!AD23,"") | AE9: =SUM(AA9:AD9) | AF9: =IFERROR(AF5*변수!AF23,"") | AG9: =IFERROR(AG5*변수!AG23,"") | AH9: =IFERROR(AH5*변수!AH23,"") | AI9: =IFERROR(AI5*변수!AI23,"") | AJ9: =SUM(AF9:AI9) | AK9: =IFERROR(AK5*변수!AK23,"") | AL9: =IFERROR(AL5*변수!AL23,"") | AM9: =IFERROR(AM5*변수!AM23,"") | AN9: =IFERROR(AN5*변수!AN23,"") | AO9: =SUM(AK9:AN9)
A10: OPM | B10: 손익 | C10: % | D10: 영업이익률 | E10: =IFERROR(E9/E5,"") | G10: =IFERROR(G9/G5,"") | H10: =IFERROR(H9/H5,"") | I10: =IFERROR(I9/I5,"") | J10: =IFERROR(J9/J5,"") | K10: =IFERROR(K9/K5,"") | L10: =IFERROR(L9/L5,"") | M10: =IFERROR(M9/M5,"") | N10: =IFERROR(N9/N5,"") | ... AO10: =IFERROR(AO9/AO5,"")
A11: 금융손익 | B11: 손익 | C11: 억원 | D11: 금융손익 | E11: =IFERROR(VLOOKUP($D11,BS연결,MATCH(E$1,BS연결H,0),0)/100,"") | G11: =IFERROR(VLOOKUP($D11,BS연결,MATCH(G$1,BS연결H,0),0)/100,"") | H11: =IFERROR(VLOOKUP($D11,BS연결,MATCH(H$1,BS연결H,0),0)/100,"") | I11: =IFERROR(VLOOKUP($D11,BS연결,MATCH(I$1,BS연결H,0),0)/100,"") | J11: =IFERROR(VLOOKUP($D11,BS연결,MATCH(J$1,BS연결H,0),0)/100,"") | K11: =IFERROR(VLOOKUP($D11,BS연결,MATCH(K$1,BS연결H,0),0)/100,"") | L11: =IFERROR(VLOOKUP($D11,BS연결,MATCH(L$1,BS연결H,0),0)/100,"") | M11: =IFERROR(VLOOKUP($D11,BS연결,MATCH(M$1,BS연결H,0),0)/100,"") | N11: =IFERROR(VLOOKUP($D11,BS연결,MATCH(N$1,BS연결H,0),0)/100,"") | ... AB11: =IFERROR(VLOOKUP($D11,BS연결,MATCH(AB$1,BS연결H,0),0)/100,"") | AC11: =IFERROR(AC12+AC13+AC14+AC15,"") | AD11: =IFERROR(AD12+AD13+AD14+AD15,"") | AE11: =SUM(AA11:AD11) | AF11: =IFERROR(AF12+AF13+AF14+AF15,"") | AG11: =IFERROR(AG12+AG13+AG14+AG15,"") | AH11: =IFERROR(AH12+AH13+AH14+AH15,"") | AI11: =IFERROR(AI12+AI13+AI14+AI15,"") | AJ11: =SUM(AF11:AI11) | AK11: =IFERROR(AK12+AK13+AK14+AK15,"") | AL11: =IFERROR(AL12+AL13+AL14+AL15,"") | AM11: =IFERROR(AM12+AM13+AM14+AM15,"") | AN11: =IFERROR(AN12+AN13+AN14+AN15,"") | AO11: =SUM(AK11:AN11)
