Workbook
Name 변수H: 변수!$C$1:$AO$1
Name 환율: 변수!$C$6:$AO$13
Name BS연결H: BS연결!$C$1:$AO$1
Name BS연결: BS연결!$C$5:$AO$122
Name BS별도H: BS별도!$C$1:$AO$1
Name BS별도: BS별도!$C$5:$AO$120
Name SUBQH: subQ!$A$1:$AO$1
Name subQ: subQ!$A$5:$AO$43

Sheet README
A1: 한화엔진(082740) 실적 모델 — ARGUS 한국조선
A2: 기준 분기 2026Q2 · 마지막 실적 2026Q2 · 생성 2026-10-13
A3: 모든 수치는 모델 산출값(DART 공개 재무제표 + 우리 추정)이다 — 목표주가·투자 추천 아님. 참고용 · 투자조언 아님.
A5: 시트
A6: 변수 가정 시계열. 환율 8행(ECB via frankfurter — L2 fx.json; 추정 분기 = 노란 가정), 추정 드라이버(노란 셀 = 모델값에서 역산한 가정, 바꾸면 재계산; 연녹 셀 = 3절 스칼라 참조 수식), 3절 스칼라 가정(세율·판관비율·지배주주비중·이자율·종가·PER 밴드·COE·외화 순노출·헤지비율)
A7: BS연결/BS별도 FnGuide 계정명 × 기간 값 덤프(백만원). 행1 분기라벨, 행4 YYYY.MM / YYYY.12A. 이름정의 BS연결H·BS연결(계정명 C열부터)
A8: subQ 분기 서브모델(억원 = 백만원/100). 확정 행: =IFERROR(VLOOKUP($D행,BS연결,MATCH(E$1,BS연결H,0),0)/100,"") 추정 행: 변수 시트 가정 셀 참조 수식. 외환손익·파생상품손익은 BS 계정 합·차, 기타금융손익은 잔차, OPM·EPS·BPS·PER·PBR 은 파생 수식
A9: SLS 선표(조선사만, sls json 있을 때): 요약 행(sls 저장값) + 계약별 스케줄(백만$) × (헤지비율 × 헤지환율 + (1−헤지비율) × 건조시점 환율[변수 원/달러(평균)]) → 원화 수식 블록 → 합계 행이 subQ 매출조선에 연결
A10: 시나리오 신규수주 보수/기준/낙관(forecast_panel 패널, 모델에 scenarios 가 있을 때만): 매출액·영업이익 = subQ 기준값 ± (시나리오 신규 − base 신규) × OPM. base 만 subQ 행에 포함, 나머지는 합산 안 함
A11: 분기/연간예상 subQ 를 이름(A열 key)으로 VLOOKUP 한 보고서 표(억원)
A12: TP PER 밴드 × 12M fwd EPS, PBR = ROE/COE × BPS — 모델 산출값 구간, 목표주가·추천 아님
A13: 외화 환율 QoQ, 외화 순노출 × Δ기말환율 → 환관련손익 추정
... A34: 백테스트: {"freeze": "2025Q2", "horizon": 4, "revenue_wape_pct": 9.7, "op_wape_pct": 44.3, "n": 4, "note": "단일 회사 4분기 — 통계 아님", "driver_at_freeze": "customer_yard_revenue_weighted", "selection_oos_at_freeze": {"freeze": "2024Q2", "n": 4, "wape_link": null, "wape_trend": 12.7, "adopted": "undetermined", "decision": "undetermined", "note": "현재 채택 조합(suppliers_mentions·시차 2·ma4·창 12)을 동결 데이터로 재적합할 수 없음(짝·고객 모델 부족) → 연동 WAPE 없음, undetermined(유의성 조건만으로 채택)"}, "frozen_inputs": "fin(연결/별도)·고객 조선사 모델·지주 자회사 모델은 2025Q2 까지의 분기만; 선표는 체결일 ≤ 2025Q2 말일 계약(원장 최신 금액·코호트 등급, 환산 없음); 잔고는 yards_cache 2025Q2; 시세·환율 forward·prices·forecast_panel 신규수주 미사용. 고객 가중치(suppliers.json 언급 비중)와 합병 체인링크는 현재 지식; 고객 연동 채택은 동결 모델 안에서도 자기 la−4분기 OOS 규칙(selection_oos_at_freeze)", "detail": [{"q": "2025Q3", "rev_pred": 3305.76, "rev_act": 2973.45, "op_pred": 199.62, "op_act": 266.31}, {"q": "2025Q4", "rev_pred": 4386.85, "rev_act": 3678.3, "op_pred": 264.9, "op_act": 473.48}, {"q": "2026Q1", "rev_pred": 3679.41, "rev_act": 3452.39, "op_pred": 222.19, "op_act": 513.79}, {"q": "2026Q2", "rev_pred": 3680.92, "rev_act": 3622.2, "op_pred": 222.28, "op_act": 379.11}]}

Sheet 변수
C1: 이름: 변수H | E1: 4Q21 | F1: 2021 | G1: 1Q22 | H1: 2Q22 | I1: 3Q22 | J1: 4Q22 | K1: 2022 | L1: 1Q23 | M1: 2Q23 | N1: 3Q23 | O1: 4Q23 | P1: 2023 | Q1: 1Q24 | R1: 2Q24 | S1: 3Q24 | T1: 4Q24 | U1: 2024 | V1: 1Q25 | W1: 2Q25 | X1: 3Q25 | Y1: 4Q25 | Z1: 2025 | AA1: 1Q26 | AB1: 2Q26 | AC1: 3Q26 | AD1: 4Q26 | AE1: 2026 | AF1: 1Q27 | AG1: 2Q27 | AH1: 3Q27 | AI1: 4Q27 | AJ1: 2027 | AK1: 1Q28 | AL1: 2Q28 | AM1: 3Q28 | AN1: 4Q28 | AO1: 2028
A2: 가정 시계열 — 노란 셀은 추정 가정(모델값에서 역산), 연녹 셀은 3절 스칼라 참조 수식. 바꾸면 subQ·분기·연간예상·TP·시나리오가 재계산됩니다.
E3: 1 | F3: 2 | G3: 3 | H3: 4 | I3: 5 | J3: 6 | K3: 7 | L3: 8 | M3: 9 | N3: 10 | O3: 11 | P3: 12 | Q3: 13 | R3: 14 | S3: 15 | T3: 16 | U3: 17 | V3: 18 | W3: 19 | X3: 20 | Y3: 21 | Z3: 22 | AA3: 23 | AB3: 24 | AC3: 25 | AD3: 26 | AE3: 27 | AF3: 28 | AG3: 29 | AH3: 30 | AI3: 31 | AJ3: 32 | AK3: 33 | AL3: 34 | AM3: 35 | AN3: 36 | AO3: 37
E4: 2021.12 | F4: 2021.12A | G4: 2022.03 | H4: 2022.06 | I4: 2022.09 | J4: 2022.12 | K4: 2022.12A | L4: 2023.03 | M4: 2023.06 | N4: 2023.09 | O4: 2023.12 | P4: 2023.12A | Q4: 2024.03 | R4: 2024.06 | S4: 2024.09 | T4: 2024.12 | U4: 2024.12A | V4: 2025.03 | W4: 2025.06 | X4: 2025.09 | Y4: 2025.12 | Z4: 2025.12A | AA4: 2026.03 | AB4: 2026.06 | AC4: 2026.09 | AD4: 2026.12 | AE4: 2026.12A | AF4: 2027.03 | AG4: 2027.06 | AH4: 2027.09 | AI4: 2027.12 | AJ4: 2027.12A | AK4: 2028.03 | AL4: 2028.06 | AM4: 2028.09 | AN4: 2028.12 | AO4: 2028.12A
B5: 1. FX | C5: 이름: 환율
A6: USDKRW_avg | C6: 원/달러(평균) | E6: 1183.5 | F6: 1145.51 | G6: 1205.78 | H6: 1262.09 | I6: 1341.93 | J6: 1360.12 | K6: 1292.98 | L6: 1276.95 | M6: 1315.69 | N6: 1313.62 | O6: 1322.01 | P6: 1306.85 | Q6: 1330.14 | R6: 1371.28 | S6: 1356.22 | T6: 1396.3 | U6: 1363.53 | V6: 1452.28 | W6: 1398.52 | X6: 1386.95 | Y6: 1449.19 | Z6: 1421.52 | AA6: 1466.12 | AB6: 1501.75 | AC6: 1418.75 | AD6: 1343.63 | AE6: 1456.58 | AF6: 1333.09 | AG6: 1333.09 | AH6: 1333.09 | AI6: 1333.09 | AK6: 1333.09 | AL6: 1333.09 | AM6: 1333.09 | AN6: 1333.09
A7: USDKRW_end | C7: 원/달러(기말) | E7: 1188.75 | F7: 1188.75 | G7: 1213.74 | H7: 1301.24 | I7: 1436.9 | J7: 1260.16 | K7: 1260.16 | L7: 1305.99 | M7: 1321.44 | N7: 1345.35 | O7: 1297.43 | P7: 1297.43 | Q7: 1349.25 | R7: 1377.73 | S7: 1312.17 | T7: 1474.78 | U7: 1474.78 | V7: 1474.54 | W7: 1355.13 | X7: 1403.67 | Y7: 1444.2 | Z7: 1444.2 | AA7: 1524.8 | AB7: 1550.89 | AC7: 1355.4 | AD7: 1333.09 | AE7: 1333.09 | AF7: 1333.09 | AG7: 1333.09 | AH7: 1333.09 | AI7: 1333.09 | AK7: 1333.09 | AL7: 1333.09 | AM7: 1333.09 | AN7: 1333.09
A8: JPY100KRW_avg | C8: 원/100Y(평균) | E8: 1041.02 | F8: 1042.74 | G8: 1036.79 | H8: 972.23 | I8: 970.61 | J8: 961.03 | K8: 985.1 | L8: 964.89 | M8: 957.36 | N8: 909 | O8: 893.22 | P8: 931.11 | Q8: 896.29 | R8: 880.14 | S8: 909.35 | T8: 917.25 | U8: 900.92 | V8: 952.59 | W8: 967.92 | X8: 940.32 | Y8: 940.77 | Z8: 950.17 | AA8: 934.39 | AB8: 942.16 | AC8: 890.41 | AD8: 849.51 | AE8: 918.81 | AF8: 840.54 | AG8: 840.54 | AH8: 840.54 | AI8: 840.54 | AK8: 840.54 | AL8: 840.54 | AM8: 840.54 | AN8: 840.54
A9: JPY100KRW_end | C9: 원/100Y(기말) | E9: 1032.62 | F9: 1032.62 | G9: 996.83 | H9: 954.9 | I9: 993.29 | J9: 955.54 | K9: 955.54 | L9: 980.62 | M9: 913.67 | N9: 901.47 | O9: 917.04 | P9: 917.04 | Q9: 892.42 | R9: 857.76 | S9: 919.21 | T9: 939.65 | U9: 939.65 | V9: 986.84 | W9: 938.85 | X9: 948.49 | Y9: 921.81 | Z9: 921.81 | AA9: 955.99 | AB9: 954.75 | AC9: 863.31 | AD9: 840.54 | AE9: 840.54 | AF9: 840.54 | AG9: 840.54 | AH9: 840.54 | AI9: 840.54 | AK9: 840.54 | AL9: 840.54 | AM9: 840.54 | AN9: 840.54
A10: EURKRW_avg | C10: W/Euro(평균) | E10: 1353.32 | F10: 1354.06 | G10: 1352.29 | H10: 1343.31 | I10: 1350.63 | J10: 1386.07 | K10: 1358.07 | L10: 1369.93 | M10: 1432.41 | N10: 1429.41 | O10: 1420.91 | P10: 1412.88 | Q10: 1444.21 | R10: 1476.42 | S10: 1489.3 | T10: 1490.78 | U10: 1475.4 | V10: 1528.33 | W10: 1585.13 | X10: 1620.04 | Y10: 1686.02 | Z10: 1605.45 | AA10: 1715.47 | AB10: 1746.09 | AC10: 1631.97 | AD10: 1507.34 | AE10: 1688.95 | AF10: 1490.54 | AG10: 1490.54 | AH10: 1490.54 | AI10: 1490.54 | AK10: 1490.54 | AL10: 1490.54 | AM10: 1490.54 | AN10: 1490.54
A11: EURKRW_end | C11: W/Euro(기말) | E11: 1346.38 | F11: 1346.38 | G11: 1347.37 | H11: 1351.6 | I11: 1400.62 | J11: 1344.08 | K11: 1344.08 | L11: 1420.26 | M11: 1435.88 | N11: 1425.26 | O11: 1433.66 | P11: 1433.66 | Q11: 1458.68 | R11: 1474.86 | S11: 1469.1 | T11: 1532.14 | U11: 1532.14 | V11: 1594.72 | W11: 1588.22 | X11: 1648.04 | Y11: 1696.94 | Z11: 1696.94 | AA11: 1753.21 | AB11: 1767.09 | AC11: 1539.06 | AD11: 1490.54 | AE11: 1490.54 | AF11: 1490.54 | AG11: 1490.54 | AH11: 1490.54 | AI11: 1490.54 | AK11: 1490.54 | AL11: 1490.54 | AM11: 1490.54 | AN11: 1490.54
A12: CNYKRW_avg | C12: 원/중국원(평균) | E12: 185.14 | F12: 177.65 | G12: 189.93 | H12: 190.76 | I12: 195.79 | J12: 191.09 | K12: 191.93 | L12: 186.59 | M12: 187.45 | N12: 181.28 | O12: 182.86 | P12: 184.52 | Q12: 185.04 | R12: 189.35 | S12: 189.24 | T12: 194.24 | U12: 189.49 | V12: 199.63 | W12: 193.41 | X12: 193.79 | Y12: 204.38 | Z12: 197.8 | AA12: 211.75 | AB12: 220.8 | AC12: 210.43 | AD12: 200.5 | AE12: 213.68 | AF12: 199.18 | AG12: 199.18 | AH12: 199.18 | AI12: 199.18 | AK12: 199.18 | AL12: 199.18 | AM12: 199.18 | AN12: 199.18
A13: CNYKRW_end | C13: 원/중국원(기말) | E13: 187.13 | F13: 187.13 | G13: 191.38 | H13: 194.13 | I13: 201.92 | J13: 182.67 | K13: 182.67 | L13: 189.97 | M13: 181.8 | N13: 184.26 | O13: 182.61 | P13: 182.61 | Q13: 186.66 | R13: 189.7 | S13: 187.12 | T13: 202.04 | U13: 202.04 | V13: 203.3 | W13: 189.14 | X13: 197.16 | Y13: 206.28 | Z13: 206.28 | AA13: 220.97 | AB13: 228.56 | AC13: 202.16 | AD13: 199.18 | AE13: 199.18 | AF13: 199.18 | AG13: 199.18 | AH13: 199.18 | AI13: 199.18 | AK13: 199.18 | AL13: 199.18 | AM13: 199.18 | AN13: 199.18
B14: 1b. 종가
A15: price_close_end | C15: 종가(기말) | E15: 6542 | G15: 7201 | H15: 8098 | I15: 7140 | J15: 7420 | L15: 7450 | M15: 10120 | N15: 8840 | O15: 9790 | Q15: 9820 | R15: 15630 | S15: 13460 | T15: 18440 | V15: 21250 | W15: 28450 | X15: 44900 | Y15: 42950 | AA15: 43550 | AB15: 51000 | AC15: 49350 | AD15: 37400
A16: price_high | C16: 종가(최고) | E16: 7428 | G16: 8196 | H16: 8785 | I16: 9470 | J16: 7970 | L16: 9100 | M16: 10850 | N16: 12750 | O16: 10220 | Q16: 10450 | R16: 16990 | S16: 17160 | T16: 19100 | V16: 28750 | W16: 32350 | X16: 48600 | Y16: 53900 | AA16: 59900 | AB16: 94400 | AC16: 58000 | AD16: 49500
A17: price_low | C17: 종가(최저) | E17: 5569 | G17: 6306 | H17: 6180 | I17: 6572 | J17: 6110 | L17: 6650 | M17: 7190 | N17: 8650 | O17: 7560 | Q17: 7990 | R17: 9270 | S17: 11000 | T17: 13110 | V17: 17820 | W17: 20000 | X17: 24650 | Y17: 39400 | AA17: 41300 | AB17: 42850 | AC17: 35800 | AD17: 34500
A18: price_avg | C18: 종가(평균) | E18: 6396.5 | G18: 7130.2 | H18: 7539.9 | I18: 7942.9 | J18: 7167.7 | L18: 7374 | M18: 8558.4 | N18: 10654.2 | O18: 8818.3 | Q18: 9172.8 | R18: 12623.3 | S18: 13837.9 | T18: 15717.2 | V18: 23237.1 | W18: 27122.5 | X18: 37497.7 | Y18: 44940.7 | AA18: 51281.4 | AB18: 62239.3 | AC18: 46760.5 | AD18: 43971.4
B20: 2. 추정 드라이버 | C20: 실적 열 = subQ 실현값(수식), 추정 열 = 가정(노란 = 모델값 역산, 연녹 = 3절 스칼라 참조)
A21: drv:매출액 | B21: yoy | C21: 매출액 YoY | J21: =IFERROR(subQ!J5/subQ!E5-1,"") | L21: =IFERROR(subQ!L5/subQ!G5-1,"") | M21: =IFERROR(subQ!M5/subQ!H5-1,"") | N21: =IFERROR(subQ!N5/subQ!I5-1,"") | O21: =IFERROR(subQ!O5/subQ!J5-1,"") | Q21: =IFERROR(subQ!Q5/subQ!L5-1,"") | R21: =IFERROR(subQ!R5/subQ!M5-1,"") | S21: =IFERROR(subQ!S5/subQ!N5-1,"") | T21: =IFERROR(subQ!T5/subQ!O5-1,"") | V21: =IFERROR(subQ!V5/subQ!Q5-1,"") | W21: =IFERROR(subQ!W5/subQ!R5-1,"") | X21: =IFERROR(subQ!X5/subQ!S5-1,"") | Y21: =IFERROR(subQ!Y5/subQ!T5-1,"") | AA21: =IFERROR(subQ!AA5/subQ!V5-1,"") | AB21: =IFERROR(subQ!AB5/subQ!W5-1,"") | AC21: 0.15722693 | AD21: 0.30545216 | AF21: 0.2183516 | AG21: 0.28408185 | AH21: 0.30867839 | AI21: 0.17476842 | AK21: 0.13292188 | AL21: 0.11538743 | AM21: 0.11270877 | AN21: 0.1512963
A22: drv:판관비 | B22: ratio | C22: 판관비율(/매출) | E22: =IFERROR(subQ!E8/subQ!E5,"") | F22: =IFERROR(subQ!F8/subQ!F5,"") | G22: =IFERROR(subQ!G8/subQ!G5,"") | H22: =IFERROR(subQ!H8/subQ!H5,"") | I22: =IFERROR(subQ!I8/subQ!I5,"") | J22: =IFERROR(subQ!J8/subQ!J5,"") | K22: =IFERROR(subQ!K8/subQ!K5,"") | L22: =IFERROR(subQ!L8/subQ!L5,"") | ... AB22: =IFERROR(subQ!AB8/subQ!AB5,"") | AC22: =$D$52 | AD22: =$D$52 | AE22: =IFERROR(subQ!AE8/subQ!AE5,"") | AF22: =$D$52 | AG22: =$D$52 | AH22: =$D$52 | AI22: =$D$52 | AJ22: =IFERROR(subQ!AJ8/subQ!AJ5,"") | AK22: =$D$52 | AL22: =$D$52 | AM22: =$D$52 | AN22: =$D$52 | AO22: =IFERROR(subQ!AO8/subQ!AO5,"")
A23: drv:영업이익 | B23: ratio | C23: 영업이익률(OPM) | E23: =IFERROR(subQ!E9/subQ!E5,"") | F23: =IFERROR(subQ!F9/subQ!F5,"") | G23: =IFERROR(subQ!G9/subQ!G5,"") | H23: =IFERROR(subQ!H9/subQ!H5,"") | I23: =IFERROR(subQ!I9/subQ!I5,"") | J23: =IFERROR(subQ!J9/subQ!J5,"") | K23: =IFERROR(subQ!K9/subQ!K5,"") | L23: =IFERROR(subQ!L9/subQ!L5,"") | ... AB23: =IFERROR(subQ!AB9/subQ!AB5,"") | AC23: 0.088341626 | AD23: 0.088339053 | AE23: =IFERROR(subQ!AE9/subQ!AE5,"") | AF23: 0.08834039 | AG23: 0.088340643 | AH23: 0.088338948 | AI23: 0.088339937 | AJ23: =IFERROR(subQ!AJ9/subQ!AJ5,"") | AK23: 0.088340157 | AL23: 0.088340346 | AM23: 0.088339836 | AN23: 0.088340632 | AO23: =IFERROR(subQ!AO9/subQ!AO5,"")
A24: drv:외환손익 | B24: abs | C24: 외환손익 (가정, 억원) | E24: =subQ!E13 | F24: =subQ!F13 | G24: =subQ!G13 | H24: =subQ!H13 | I24: =subQ!I13 | J24: =subQ!J13 | K24: =subQ!K13 | L24: =subQ!L13 | ... AB24: =subQ!AB13 | AC24: 0 | AD24: 0 | AE24: =subQ!AE13 | AF24: 0 | AG24: 0 | AH24: 0 | AI24: 0 | AJ24: =subQ!AJ13 | AK24: 0 | AL24: 0 | AM24: 0 | AN24: 0 | AO24: =subQ!AO13
A25: drv:파생상품손익 | B25: abs | C25: 파생상품손익 (가정, 억원) | E25: =subQ!E14 | F25: =subQ!F14 | G25: =subQ!G14 | H25: =subQ!H14 | I25: =subQ!I14 | J25: =subQ!J14 | K25: =subQ!K14 | L25: =subQ!L14 | ... AB25: =subQ!AB14 | AC25: 0 | AD25: 0 | AE25: =subQ!AE14 | AF25: 0 | AG25: 0 | AH25: 0 | AI25: 0 | AJ25: =subQ!AJ14 | AK25: 0 | AL25: 0 | AM25: 0 | AN25: 0 | AO25: =subQ!AO14
A26: drv:기타금융손익 | B26: abs | C26: 기타금융손익 (가정, 억원) | E26: =subQ!E15 | F26: =subQ!F15 | G26: =subQ!G15 | H26: =subQ!H15 | I26: =subQ!I15 | J26: =subQ!J15 | K26: =subQ!K15 | L26: =subQ!L15 | ... AB26: =subQ!AB15 | AC26: 0 | AD26: 0 | AE26: =subQ!AE15 | AF26: 0 | AG26: 0 | AH26: 0 | AI26: 0 | AJ26: =subQ!AJ15 | AK26: 0 | AL26: 0 | AM26: 0 | AN26: 0 | AO26: =subQ!AO15
A27: drv:기타영업외손익 | B27: abs | C27: 기타영업외손익 (가정, 억원) | E27: =subQ!E16 | F27: =subQ!F16 | G27: =subQ!G16 | H27: =subQ!H16 | I27: =subQ!I16 | J27: =subQ!J16 | K27: =subQ!K16 | L27: =subQ!L16 | ... AB27: =subQ!AB16 | AC27: 0 | AD27: 0 | AE27: =subQ!AE16 | AF27: 0 | AG27: 0 | AH27: 0 | AI27: 0 | AJ27: =subQ!AJ16 | AK27: 0 | AL27: 0 | AM27: 0 | AN27: 0 | AO27: =subQ!AO16
A28: drv:지분법손익 | B28: abs | C28: 지분법손익 (가정, 억원) | E28: =subQ!E17 | F28: =subQ!F17 | G28: =subQ!G17 | H28: =subQ!H17 | I28: =subQ!I17 | J28: =subQ!J17 | K28: =subQ!K17 | L28: =subQ!L17 | ... AB28: =subQ!AB17 | AC28: -0.04 | AD28: -0.04 | AE28: =subQ!AE17 | AF28: -0.04 | AG28: -0.04 | AH28: -0.04 | AI28: -0.04 | AJ28: =subQ!AJ17 | AK28: -0.04 | AL28: -0.04 | AM28: -0.04 | AN28: -0.04 | AO28: =subQ!AO17
A29: drv:법인세비용 | B29: tax | C29: 법인세율(/세전) — 법인세 = MAX(세전,0) × 세율 | E29: =IFERROR(subQ!E19/subQ!E18,"") | F29: =IFERROR(subQ!F19/subQ!F18,"") | G29: =IFERROR(subQ!G19/subQ!G18,"") | H29: =IFERROR(subQ!H19/subQ!H18,"") | I29: =IFERROR(subQ!I19/subQ!I18,"") | J29: =IFERROR(subQ!J19/subQ!J18,"") | K29: =IFERROR(subQ!K19/subQ!K18,"") | L29: =IFERROR(subQ!L19/subQ!L18,"") | ... AB29: =IFERROR(subQ!AB19/subQ!AB18,"") | AC29: =$D$51 | AD29: =$D$51 | AE29: =IFERROR(subQ!AE19/subQ!AE18,"") | AF29: =$D$51 | AG29: =$D$51 | AH29: =$D$51 | AI29: =$D$51 | AJ29: =IFERROR(subQ!AJ19/subQ!AJ18,"") | AK29: =$D$51 | AL29: =$D$51 | AM29: =$D$51 | AN29: =$D$51 | AO29: =IFERROR(subQ!AO19/subQ!AO18,"")
A30: drv:지배주주순이익 | B30: ratio | C30: 지배주주 비중(/당기순이익) | E30: =IFERROR(subQ!E21/subQ!E20,"") | F30: =IFERROR(subQ!F21/subQ!F20,"") | G30: =IFERROR(subQ!G21/subQ!G20,"") | H30: =IFERROR(subQ!H21/subQ!H20,"") | I30: =IFERROR(subQ!I21/subQ!I20,"") | J30: =IFERROR(subQ!J21/subQ!J20,"") | K30: =IFERROR(subQ!K21/subQ!K20,"") | L30: =IFERROR(subQ!L21/subQ!L20,"") | ... AB30: =IFERROR(subQ!AB21/subQ!AB20,"") | AC30: =$D$53 | AD30: =$D$53 | AE30: =IFERROR(subQ!AE21/subQ!AE20,"") | AF30: =$D$53 | AG30: =$D$53 | AH30: =$D$53 | AI30: =$D$53 | AJ30: =IFERROR(subQ!AJ21/subQ!AJ20,"") | AK30: =$D$53 | AL30: =$D$53 | AM30: =$D$53 | AN30: =$D$53 | AO30: =IFERROR(subQ!AO21/subQ!AO20,"")
A31: drv:부채총계 | B31: qoq | C31: 부채총계 QoQ | G31: =IFERROR(subQ!G23/subQ!E23-1,"") | H31: =IFERROR(subQ!H23/subQ!G23-1,"") | I31: =IFERROR(subQ!I23/subQ!H23-1,"") | J31: =IFERROR(subQ!J23/subQ!I23-1,"") | L31: =IFERROR(subQ!L23/subQ!J23-1,"") | M31: =IFERROR(subQ!M23/subQ!L23-1,"") | N31: =IFERROR(subQ!N23/subQ!M23-1,"") | O31: =IFERROR(subQ!O23/subQ!N23-1,"") | Q31: =IFERROR(subQ!Q23/subQ!O23-1,"") | R31: =IFERROR(subQ!R23/subQ!Q23-1,"") | S31: =IFERROR(subQ!S23/subQ!R23-1,"") | T31: =IFERROR(subQ!T23/subQ!S23-1,"") | V31: =IFERROR(subQ!V23/subQ!T23-1,"") | W31: =IFERROR(subQ!W23/subQ!V23-1,"") | X31: =IFERROR(subQ!X23/subQ!W23-1,"") | Y31: =IFERROR(subQ!Y23/subQ!X23-1,"") | AA31: =IFERROR(subQ!AA23/subQ!Y23-1,"") | AB31: =IFERROR(subQ!AB23/subQ!AA23-1,"") | AC31: 1.31e-07 | AD31: 0 | AF31: 0 | AG31: 0 | AH31: 0 | AI31: 0 | AK31: 0 | AL31: 0 | AM31: 0 | AN31: 0
A32: drv:자본총계 | B32: roll | C32: 자본총계 기타변동(배당 등, 억원) | G32: =IFERROR(subQ!E24+subQ!G20-subQ!G24,"") | H32: =IFERROR(subQ!G24+subQ!H20-subQ!H24,"") | I32: =IFERROR(subQ!H24+subQ!I20-subQ!I24,"") | J32: =IFERROR(subQ!I24+subQ!J20-subQ!J24,"") | L32: =IFERROR(subQ!J24+subQ!L20-subQ!L24,"") | M32: =IFERROR(subQ!L24+subQ!M20-subQ!M24,"") | N32: =IFERROR(subQ!M24+subQ!N20-subQ!N24,"") | O32: =IFERROR(subQ!N24+subQ!O20-subQ!O24,"") | Q32: =IFERROR(subQ!O24+subQ!Q20-subQ!Q24,"") | R32: =IFERROR(subQ!Q24+subQ!R20-subQ!R24,"") | S32: =IFERROR(subQ!R24+subQ!S20-subQ!S24,"") | T32: =IFERROR(subQ!S24+subQ!T20-subQ!T24,"") | V32: =IFERROR(subQ!T24+subQ!V20-subQ!V24,"") | W32: =IFERROR(subQ!V24+subQ!W20-subQ!W24,"") | X32: =IFERROR(subQ!W24+subQ!X20-subQ!X24,"") | Y32: =IFERROR(subQ!X24+subQ!Y20-subQ!Y24,"") | AA32: =IFERROR(subQ!Y24+subQ!AA20-subQ!AA24,"") | AB32: =IFERROR(subQ!AA24+subQ!AB20-subQ!AB24,"") | AC32: 0.00530175 | AD32: -0.013456659 | AF32: -9.101e-05 | AG32: -0.001622087 | AH32: -0.002867333 | AI32: -0.006608591 | AK32: -6.7464e-05 | AL32: 0.003934382 | AM32: -0.00065193 | AN32: 0.001525968
A33: drv:지배주주지분 | B33: roll | C33: 지배주주지분 기타변동(배당 등, 억원) | G33: =IFERROR(subQ!E25+subQ!G21-subQ!G25,"") | H33: =IFERROR(subQ!G25+subQ!H21-subQ!H25,"") | I33: =IFERROR(subQ!H25+subQ!I21-subQ!I25,"") | J33: =IFERROR(subQ!I25+subQ!J21-subQ!J25,"") | L33: =IFERROR(subQ!J25+subQ!L21-subQ!L25,"") | M33: =IFERROR(subQ!L25+subQ!M21-subQ!M25,"") | N33: =IFERROR(subQ!M25+subQ!N21-subQ!N25,"") | O33: =IFERROR(subQ!N25+subQ!O21-subQ!O25,"") | Q33: =IFERROR(subQ!O25+subQ!Q21-subQ!Q25,"") | R33: =IFERROR(subQ!Q25+subQ!R21-subQ!R25,"") | S33: =IFERROR(subQ!R25+subQ!S21-subQ!S25,"") | T33: =IFERROR(subQ!S25+subQ!T21-subQ!T25,"") | V33: =IFERROR(subQ!T25+subQ!V21-subQ!V25,"") | W33: =IFERROR(subQ!V25+subQ!W21-subQ!W25,"") | X33: =IFERROR(subQ!W25+subQ!X21-subQ!X25,"") | Y33: =IFERROR(subQ!X25+subQ!Y21-subQ!Y25,"") | AA33: =IFERROR(subQ!Y25+subQ!AA21-subQ!AA25,"") | AB33: =IFERROR(subQ!AA25+subQ!AB21-subQ!AB25,"") | AC33: 0.00530175 | AD33: -0.013456659 | AF33: -9.101e-05 | AG33: -0.001622087 | AH33: -0.002867333 | AI33: -0.006608591 | AK33: -6.7464e-05 | AL33: 0.003934382 | AM33: -0.00065193 | AN33: 0.001525968
A34: drv:총차입금 | B34: qoq | C34: 총차입금 QoQ | G34: =IFERROR(subQ!G26/subQ!E26-1,"") | H34: =IFERROR(subQ!H26/subQ!G26-1,"") | I34: =IFERROR(subQ!I26/subQ!H26-1,"") | J34: =IFERROR(subQ!J26/subQ!I26-1,"") | L34: =IFERROR(subQ!L26/subQ!J26-1,"") | M34: =IFERROR(subQ!M26/subQ!L26-1,"") | N34: =IFERROR(subQ!N26/subQ!M26-1,"") | O34: =IFERROR(subQ!O26/subQ!N26-1,"") | Q34: =IFERROR(subQ!Q26/subQ!O26-1,"") | R34: =IFERROR(subQ!R26/subQ!Q26-1,"") | S34: =IFERROR(subQ!S26/subQ!R26-1,"") | T34: =IFERROR(subQ!T26/subQ!S26-1,"") | V34: =IFERROR(subQ!V26/subQ!T26-1,"") | W34: =IFERROR(subQ!W26/subQ!V26-1,"") | X34: =IFERROR(subQ!X26/subQ!W26-1,"") | Y34: =IFERROR(subQ!Y26/subQ!X26-1,"") | AA34: =IFERROR(subQ!AA26/subQ!Y26-1,"") | AB34: =IFERROR(subQ!AB26/subQ!AA26-1,"") | AC34: 1.2984e-05 | AD34: 0 | AF34: 0 | AG34: 0 | AH34: 0 | AI34: 0 | AK34: 0 | AL34: 0 | AM34: 0 | AN34: 0
A35: drv:순차입금 | B35: qoq | C35: 순차입금 QoQ | G35: =IFERROR(subQ!G27/subQ!E27-1,"") | H35: =IFERROR(subQ!H27/subQ!G27-1,"") | I35: =IFERROR(subQ!I27/subQ!H27-1,"") | J35: =IFERROR(subQ!J27/subQ!I27-1,"") | L35: =IFERROR(subQ!L27/subQ!J27-1,"") | M35: =IFERROR(subQ!M27/subQ!L27-1,"") | N35: =IFERROR(subQ!N27/subQ!M27-1,"") | O35: =IFERROR(subQ!O27/subQ!N27-1,"") | Q35: =IFERROR(subQ!Q27/subQ!O27-1,"") | R35: =IFERROR(subQ!R27/subQ!Q27-1,"") | S35: =IFERROR(subQ!S27/subQ!R27-1,"") | T35: =IFERROR(subQ!T27/subQ!S27-1,"") | V35: =IFERROR(subQ!V27/subQ!T27-1,"") | W35: =IFERROR(subQ!W27/subQ!V27-1,"") | X35: =IFERROR(subQ!X27/subQ!W27-1,"") | Y35: =IFERROR(subQ!Y27/subQ!X27-1,"") | AA35: =IFERROR(subQ!AA27/subQ!Y27-1,"") | AB35: =IFERROR(subQ!AB27/subQ!AA27-1,"") | AC35: 0.093593109 | AD35: 0.11749772 | AF35: 0.093662308 | AG35: 0.094640444 | AH35: 0.084547923 | AI35: 0.096557401 | AK35: 0.076051152 | AL35: 0.076870616 | AM35: 0.069696915 | AN35: 0.082930741
A36: drv:이자발생자산 | B36: qoq | C36: 이자발생자산 QoQ | G36: =IFERROR(subQ!G28/subQ!E28-1,"") | H36: =IFERROR(subQ!H28/subQ!G28-1,"") | I36: =IFERROR(subQ!I28/subQ!H28-1,"") | J36: =IFERROR(subQ!J28/subQ!I28-1,"") | L36: =IFERROR(subQ!L28/subQ!J28-1,"") | M36: =IFERROR(subQ!M28/subQ!L28-1,"") | N36: =IFERROR(subQ!N28/subQ!M28-1,"") | O36: =IFERROR(subQ!O28/subQ!N28-1,"") | Q36: =IFERROR(subQ!Q28/subQ!O28-1,"") | R36: =IFERROR(subQ!R28/subQ!Q28-1,"") | S36: =IFERROR(subQ!S28/subQ!R28-1,"") | T36: =IFERROR(subQ!T28/subQ!S28-1,"") | V36: =IFERROR(subQ!V28/subQ!T28-1,"") | W36: =IFERROR(subQ!W28/subQ!V28-1,"") | X36: =IFERROR(subQ!X28/subQ!W28-1,"") | Y36: =IFERROR(subQ!Y28/subQ!X28-1,"") | AA36: =IFERROR(subQ!AA28/subQ!Y28-1,"") | AB36: =IFERROR(subQ!AB28/subQ!AA28-1,"") | AC36: 0.083527318 | AD36: 0.1058306 | AF36: 0.085254445 | AG36: 0.086812172 | AH36: 0.078113085 | AI36: 0.089743124 | AK36: 0.071124349 | AL36: 0.072221398 | AM36: 0.065765503 | AN36: 0.078541505
A37: drv:현금및현금성자산 | B37: qoq | C37: 현금및현금성자산 QoQ | G37: =IFERROR(subQ!G29/subQ!E29-1,"") | H37: =IFERROR(subQ!H29/subQ!G29-1,"") | I37: =IFERROR(subQ!I29/subQ!H29-1,"") | J37: =IFERROR(subQ!J29/subQ!I29-1,"") | L37: =IFERROR(subQ!L29/subQ!J29-1,"") | M37: =IFERROR(subQ!M29/subQ!L29-1,"") | N37: =IFERROR(subQ!N29/subQ!M29-1,"") | O37: =IFERROR(subQ!O29/subQ!N29-1,"") | Q37: =IFERROR(subQ!Q29/subQ!O29-1,"") | R37: =IFERROR(subQ!R29/subQ!Q29-1,"") | S37: =IFERROR(subQ!S29/subQ!R29-1,"") | T37: =IFERROR(subQ!T29/subQ!S29-1,"") | V37: =IFERROR(subQ!V29/subQ!T29-1,"") | W37: =IFERROR(subQ!W29/subQ!V29-1,"") | X37: =IFERROR(subQ!X29/subQ!W29-1,"") | Y37: =IFERROR(subQ!Y29/subQ!X29-1,"") | AA37: =IFERROR(subQ!AA29/subQ!Y29-1,"") | AB37: =IFERROR(subQ!AB29/subQ!AA29-1,"")
A38: drv:CAPEX | B38: yoy | C38: CAPEX YoY | J38: =IFERROR(subQ!J30/subQ!E30-1,"") | L38: =IFERROR(subQ!L30/subQ!G30-1,"") | M38: =IFERROR(subQ!M30/subQ!H30-1,"") | N38: =IFERROR(subQ!N30/subQ!I30-1,"") | O38: =IFERROR(subQ!O30/subQ!J30-1,"") | Q38: =IFERROR(subQ!Q30/subQ!L30-1,"") | R38: =IFERROR(subQ!R30/subQ!M30-1,"") | S38: =IFERROR(subQ!S30/subQ!N30-1,"") | T38: =IFERROR(subQ!T30/subQ!O30-1,"") | V38: =IFERROR(subQ!V30/subQ!Q30-1,"") | W38: =IFERROR(subQ!W30/subQ!R30-1,"") | X38: =IFERROR(subQ!X30/subQ!S30-1,"") | Y38: =IFERROR(subQ!Y30/subQ!T30-1,"") | AA38: =IFERROR(subQ!AA30/subQ!V30-1,"") | AB38: =IFERROR(subQ!AB30/subQ!W30-1,"") | AC38: 0.39933808 | AD38: -0.22199439 | AF38: -0.43968291 | AG38: 0 | AH38: 0 | AI38: 0 | AK38: 0 | AL38: 0 | AM38: 0 | AN38: 0
A39: drv:영업활동현금흐름 | B39: yoy | C39: 영업활동현금흐름 YoY | J39: =IFERROR(subQ!J31/subQ!E31-1,"") | L39: =IFERROR(subQ!L31/subQ!G31-1,"") | M39: =IFERROR(subQ!M31/subQ!H31-1,"") | N39: =IFERROR(subQ!N31/subQ!I31-1,"") | O39: =IFERROR(subQ!O31/subQ!J31-1,"") | Q39: =IFERROR(subQ!Q31/subQ!L31-1,"") | R39: =IFERROR(subQ!R31/subQ!M31-1,"") | S39: =IFERROR(subQ!S31/subQ!N31-1,"") | T39: =IFERROR(subQ!T31/subQ!O31-1,"") | V39: =IFERROR(subQ!V31/subQ!Q31-1,"") | W39: =IFERROR(subQ!W31/subQ!R31-1,"") | X39: =IFERROR(subQ!X31/subQ!S31-1,"") | Y39: =IFERROR(subQ!Y31/subQ!T31-1,"") | AA39: =IFERROR(subQ!AA31/subQ!V31-1,"") | AB39: =IFERROR(subQ!AB31/subQ!W31-1,"")
A40: drv:주식수 | B40: qoq | C40: 주식수 QoQ | G40: =IFERROR(subQ!G32/subQ!E32-1,"") | H40: =IFERROR(subQ!H32/subQ!G32-1,"") | I40: =IFERROR(subQ!I32/subQ!H32-1,"") | J40: =IFERROR(subQ!J32/subQ!I32-1,"") | L40: =IFERROR(subQ!L32/subQ!J32-1,"") | M40: =IFERROR(subQ!M32/subQ!L32-1,"") | N40: =IFERROR(subQ!N32/subQ!M32-1,"") | O40: =IFERROR(subQ!O32/subQ!N32-1,"") | Q40: =IFERROR(subQ!Q32/subQ!O32-1,"") | R40: =IFERROR(subQ!R32/subQ!Q32-1,"") | S40: =IFERROR(subQ!S32/subQ!R32-1,"") | T40: =IFERROR(subQ!T32/subQ!S32-1,"") | V40: =IFERROR(subQ!V32/subQ!T32-1,"") | W40: =IFERROR(subQ!W32/subQ!V32-1,"") | X40: =IFERROR(subQ!X32/subQ!W32-1,"") | Y40: =IFERROR(subQ!Y32/subQ!X32-1,"") | AA40: =IFERROR(subQ!AA32/subQ!Y32-1,"") | AB40: =IFERROR(subQ!AB32/subQ!AA32-1,"") | AC40: 0 | AD40: 0 | AF40: 0 | AG40: 0 | AH40: 0 | AI40: 0 | AK40: 0 | AL40: 0 | AM40: 0 | AN40: 0
A41: drv:DPS | B41: abs | C41: DPS (가정, 원) | E41: =subQ!E35 | F41: =subQ!F35 | G41: =subQ!G35 | H41: =subQ!H35 | I41: =subQ!I35 | J41: =subQ!J35 | K41: =subQ!K35 | L41: =subQ!L35 | ... AB41: =subQ!AB35 | AD41: 0 | AE41: =subQ!AE35 | AI41: 0 | AJ41: =subQ!AJ35 | AN41: 0 | AO41: =subQ!AO35
...

Sheet BS연결
B1: (백만원) | C1: 이름: BS연결H | E1: 4Q21 | F1: 2021 | G1: 1Q22 | H1: 2Q22 | I1: 3Q22 | J1: 4Q22 | K1: 2022 | L1: 1Q23 | M1: 2Q23 | N1: 3Q23 | O1: 4Q23 | P1: 2023 | Q1: 1Q24 | R1: 2Q24 | S1: 3Q24 | T1: 4Q24 | U1: 2024 | V1: 1Q25 | W1: 2Q25 | X1: 3Q25 | Y1: 4Q25 | Z1: 2025 | AA1: 1Q26 | AB1: 2Q26 | AC1: 3Q26 | AD1: 4Q26 | AE1: 2026 | AF1: 1Q27 | AG1: 2Q27 | AH1: 3Q27 | AI1: 4Q27 | AJ1: 2027 | AK1: 1Q28 | AL1: 2Q28 | AM1: 3Q28 | AN1: 4Q28 | AO1: 2028
B2: 연결 | D2: fin json(kship_fin.py)
B3: 한화엔진(연) | C3: UPDATE: 26-10-13 | E3: 1 | F3: 2 | G3: 3 | H3: 4 | I3: 5 | J3: 6 | K3: 7 | L3: 8 | M3: 9 | N3: 10 | O3: 11 | P3: 12 | Q3: 13 | R3: 14 | S3: 15 | T3: 16 | U3: 17 | V3: 18 | W3: 19 | X3: 20 | Y3: 21 | Z3: 22 | AA3: 23 | AB3: 24 | AC3: 25 | AD3: 26 | AE3: 27 | AF3: 28 | AG3: 29 | AH3: 30 | AI3: 31 | AJ3: 32 | AK3: 33 | AL3: 34 | AM3: 35 | AN3: 36 | AO3: 37
B4: Account Code | C4: AccountNAME | E4: 2021.12 | F4: 2021.12A | G4: 2022.03 | H4: 2022.06 | I4: 2022.09 | J4: 2022.12 | K4: 2022.12A | L4: 2023.03 | M4: 2023.06 | N4: 2023.09 | O4: 2023.12 | P4: 2023.12A | Q4: 2024.03 | R4: 2024.06 | S4: 2024.09 | T4: 2024.12 | U4: 2024.12A | V4: 2025.03 | W4: 2025.06 | X4: 2025.09 | Y4: 2025.12 | Z4: 2025.12A | AA4: 2026.03 | AB4: 2026.06 | AC4: 2026.09 | AD4: 2026.12 | AE4: 2026.12A | AF4: 2027.03 | AG4: 2027.06 | AH4: 2027.09 | AI4: 2027.12 | AJ4: 2027.12A | AK4: 2028.03 | AL4: 2028.06 | AM4: 2028.09 | AN4: 2028.12 | AO4: 2028.12A
A5: 1 | C5: 유동자산 | E5: 344869.46 | F5: 344869.46 | G5: 353848.61 | H5: 389318.95 | I5: 539497.07 | J5: 471073.55 | K5: 471073.55 | L5: 492546.99 | M5: 552402.07 | Y5: 1031851.2 | Z5: 1031851.2 | AA5: 856528.61 | AB5: 1040092.9
A6: 1 | C6: 현금및현금성자산 | E6: 54072.27 | F6: 54072.27 | G6: 63867.89 | H6: 54601.56 | I6: 91486.71 | J6: 54559.25 | K6: 54559.25 | L6: 66371.55 | M6: 33083.66 | Y6: 276708.03 | Z6: 276708.03 | AA6: 49997.56 | AB6: 163635.95
A7: 1 | C7: 단기금융상품 | E7: 12702.29 | F7: 12702.29 | G7: 8568 | H7: 8497.16 | I7: 42291.27 | J7: 15156.82 | K7: 15156.82 | L7: 13870.42 | M7: 13910.76 | Y7: 133988.65 | Z7: 133988.65 | AA7: 65265.9
A8: 1 | C8: 단기금융자산 | E8: 12825.24 | F8: 12825.24 | G8: 8689.65 | H8: 8610.46 | I8: 42395.52 | J8: 15257.32 | K8: 15257.32 | L8: 13974.42 | M8: 14015.66 | Y8: 134106 | Z8: 134106 | AA8: 70823.4 | AB8: 142045.33
A9: 1 | C9: 단기대여금 | E9: 122.95 | F9: 122.95 | G9: 121.65 | H9: 113.3 | I9: 104.25 | J9: 100.5 | K9: 100.5 | L9: 104 | M9: 104.9 | Y9: 117.35 | Z9: 117.35 | AA9: 176.2
A10: 1 | C10: 매출채권및기타채권 | E10: 59573.79 | F10: 59573.79 | G10: 56633.51 | H10: 50838.22 | I10: 49956.88 | J10: 71262.89 | K10: 71262.89 | L10: 69235.43 | M10: 72694.88 | Y10: 165742.58 | Z10: 165742.58 | AA10: 193202.37 | AB10: 152728.52
A11: 1 | C11: 계약자산 | E11: 12664.66 | F11: 12664.66 | AB11: 17130.13
A12: 1 | C12: 당기법인세자산(선급법인세) | E12: 146.29 | F12: 146.29 | G12: 152.66 | H12: 117.23 | I12: 139.42 | J12: 211.85 | K12: 211.85 | L12: 257.65 | M12: 312.85 | Y12: 18.3 | Z12: 18.3 | AB12: 334.38
A13: 1 | C13: 재고자산 | E13: 179427.93 | F13: 179427.93 | G13: 190338.02 | H13: 219008.4 | I13: 241946.35 | J13: 252292.72 | K13: 252292.72 | L13: 269549.22 | M13: 322351.85 | Y13: 356165.91 | Z13: 356165.91 | AA13: 391082.44 | AB13: 474237.38
A14: 1 | C14: 기타유동자산 | E14: 9051.3 | F14: 9051.3 | G14: 12040.68 | H14: 14130.14 | I14: 15952.97 | J14: 14647.14 | K14: 14647.14 | L14: 14546.24 | M14: 16315.88 | Y14: 15258.84 | Z14: 15258.84 | AA14: 29390.95 | AB14: 33442.32
A15: 1 | C15: 비유동자산 | E15: 450755.27 | F15: 450755.27 | G15: 449351.04 | H15: 482798.51 | I15: 541209.93 | J15: 485156.75 | K15: 485156.75 | L15: 502326.36 | M15: 477828.77 | Y15: 663839.01 | Z15: 663839.01 | AA15: 1054041 | AB15: 1130671.8
A16: 1 | C16: 장기금융자산 | E16: 518.77 | F16: 518.77 | G16: 1472 | H16: 3639.48 | I16: 5621.98 | J16: 8008.43 | K16: 8008.43 | L16: 7778.89 | M16: 8472.58 | Y16: 1158.77 | Z16: 1158.77 | AA16: 1158.77 | AB16: 1460.03
A17: 1 | C17: 투자자산 | E17: 3668.07 | F17: 3668.07 | G17: 3276.48 | H17: 5479.86 | I17: 7421.14 | J17: 44759.74 | K17: 44759.74 | L17: 44784.07 | M17: 9887.23 | Y17: 1517.76 | Z17: 1517.76 | AA17: 1866.96 | AB17: 128253.11
A18: 1 | C18: 종속기업및관계기업투자 | E18: 2839.41 | F18: 2839.41 | G18: 1514.03 | H18: 1532.32 | I18: 1532.32 | J18: 36484.57 | K18: 36484.57 | L18: 36624.78 | M18: 1076.27
A19: 1 | C19: 장기대여금 | E19: 309.89 | F19: 309.89 | G19: 290.45 | H19: 308.06 | I19: 266.84 | J19: 266.74 | K19: 266.74 | L19: 380.4 | M19: 338.38 | Y19: 358.99 | Z19: 358.99 | AA19: 463.3
A20: 1 | C20: 장기매출채권및기타채권 | E20: 579.58 | F20: 579.58 | G20: 591.47 | H20: 593.29 | I20: 596.43 | J20: 591.97 | K20: 591.97 | L20: 608.81 | M20: 596.33 | Y20: 2734.92 | Z20: 2734.92 | AA20: 2278.51 | AB20: 3173.69
A21: 1 | C21: 유형자산 | E21: 361262.63 | F21: 361262.63 | G21: 359286.02 | H21: 359531.92 | I21: 357967.24 | J21: 354241.66 | K21: 354241.66 | L21: 356421.66 | M21: 366070.83 | Y21: 433599.71 | Z21: 433599.71 | AA21: 460320.15 | AB21: 493553.84
A22: 1 | C22: 사용권자산 | E22: 11937.8 | F22: 11937.8 | G22: 11592.36 | H22: 11237.53 | I22: 10805 | J22: 10742.3 | K22: 10742.3 | L22: 10533.81 | M22: 11288.93 | Y22: 9028.79 | Z22: 9028.79 | AA22: 8890.83 | AB22: 19496.9
A23: 1 | C23: 기타비유동자산 | E23: 13689.75 | F23: 13689.75 | G23: 13217.1 | H23: 13172.23 | I23: 13028.98 | J23: 11779.6 | K23: 11779.6 | L23: 12044.73 | M23: 12723.46 | Y23: 16298.55 | Z23: 16298.55 | AA23: 323080.24 | AB23: 26664.74
A24: 1 | C24: 투자부동산 | E24: 47673.85 | F24: 47673.85 | G24: 47673.85 | H24: 47169.78 | I24: 47169.78 | J24: 47192.31 | K24: 47192.31 | L24: 47192.31 | M24: 47192.31 | Y24: 48965.82 | Z24: 48965.82 | AA24: 48965.82 | AB24: 48965.82
A25: 1 | C25: 무형자산 | E25: 3755.14 | F25: 3755.14 | G25: 3534.4 | H25: 3429.61 | I25: 3488.19 | J25: 3448.29 | K25: 3448.29 | L25: 3209.51 | M25: 2967.92 | Y25: 9617.77 | Z25: 9617.77 | AA25: 20383.14
A26: 1 | C26: 이연법인세자산 | E26: 13995.03 | F26: 13995.03 | G26: 14685.46 | H26: 14877.67 | I26: 13452.88 | J26: 13110.98 | K26: 13110.98 | L26: 11554.47 | M26: 11454.18 | Y26: 77750.89 | Z26: 77750.89 | AA26: 64689.18 | AB26: 65305.78
A27: 1 | C27: 자산총계 | E27: 795624.73 | F27: 795624.73 | G27: 803199.65 | H27: 872117.46 | I27: 1080707 | J27: 956230.29 | K27: 956230.29 | L27: 994873.36 | M27: 1030230.8 | Y27: 1695690.3 | Z27: 1695690.3 | AA27: 1910569.6 | AB27: 2170764.7
A28: 1 | C28: 유동부채 | E28: 431103.69 | F28: 431103.69 | G28: 475517.02 | H28: 549023.56 | I28: 606568.37 | J28: 498756.38 | K28: 498756.38 | L28: 533646.28 | M28: 518471.56 | Y28: 611221.29 | Z28: 611221.29 | AA28: 722234.12 | AB28: 818702.3
A29: 1 | C29: 매입채무및기타채무 | E29: 124028.52 | F29: 124028.52 | G29: 132551.37 | H29: 132319.06 | I29: 118165.31 | J29: 133169.77 | K29: 133169.77 | L29: 140100.22 | M29: 144542.5 | Y29: 179006.96 | Z29: 179006.96 | AA29: 229328.81 | AB29: 220566.4
A30: 1 | C30: 계약부채 | E30: 2381.61 | F30: 2381.61 | G30: 2232.58 | H30: 2337.48 | I30: 2295.76 | J30: 125312.31 | K30: 125312.31 | L30: 136489.79 | M30: 153159.35 | Y30: 250874.74 | Z30: 250874.74 | AA30: 269004.85 | AB30: 382815.21
A31: 1 | C31: 단기차입금 | E31: 127850.09 | F31: 127850.09 | G31: 137895.08 | H31: 148104.69 | I31: 128402.11 | J31: 125000 | K31: 125000 | L31: 125000 | M31: 143900 | AB31: 21576.59
A32: 1 | C32: 유동성장기부채 | E32: 8412 | F32: 8412 | G32: 12470.9 | H32: 62555.8 | I32: 60055.75 | J32: 57055.75 | K32: 57055.75 | L32: 54055.75 | M32: 4055.75 | Y32: 43008.75 | Z32: 43008.75 | AA32: 45391.85 | AB32: 0
A33: 1 | C33: 선수금 | E33: 128935.23 | F33: 128935.23 | G33: 130096.7 | H33: 119213.08 | I33: 125753.52
A34: 1 | C34: 기타유동부채 | E34: 143004.11 | F34: 143004.11 | G34: 147007.37 | H34: 138395.35 | I34: 144496.54 | J34: 16453.15 | K34: 16453.15 | L34: 19222.68 | M34: 20402.79 | Y34: 51443.19 | Z34: 51443.19 | AA34: 39711.02 | AB34: 49744.45
A35: 1 | C35: 단기충당부채 | E35: 7490.2 | F35: 7490.2 | G35: 20519.14 | H35: 16271.12 | I35: 12649.07 | J35: 9805.65 | K35: 9805.65 | L35: 10302.54 | M35: 7322.26 | Y35: 5951.68 | Z35: 5951.68 | AA35: 5357.49 | AB35: 6150.66
A36: 1 | C36: 비유동부채 | E36: 155419.72 | F36: 155419.72 | G36: 163610.83 | H36: 190146.91 | I36: 249697.55 | J36: 235848.09 | K36: 235848.09 | L36: 233601.97 | M36: 284381.98 | Y36: 528366.07 | Z36: 528366.07 | AA36: 578302.71 | AB36: 702314.5
A37: 1 | C37: 장기차입금 | E37: 75708 | F37: 75708 | G37: 72335.1 | H37: 21723.2 | I37: 20709.06 | J37: 19695.12 | K37: 19695.12 | L37: 18681.18 | M37: 17667.24 | Y37: 10000 | Z37: 10000 | AA37: 10000 | AB37: 10000
A38: 1 | C38: 장기매입채무및기타채무 | E38: 9704.52 | F38: 9704.52 | G38: 9530.38 | H38: 9235.66 | I38: 8963.7 | J38: 8747.39 | K38: 8747.39 | L38: 8670.86 | M38: 9188.19 | Y38: 20095.14 | Z38: 20095.14 | AA38: 11718.59
A39: 1 | C39: 확정급여부채 | E39: 9270.24 | F39: 9270.24 | G39: 11571.13 | H39: 12349.59 | I39: 13244.12 | J39: 4818.18 | K39: 4818.18 | L39: 7560.97 | M39: 8345.16 | Y39: 8347.75 | Z39: 8347.75 | AA39: 10306.64 | AB39: 9637.45
A40: 1 | C40: 장기충당부채 | E40: 5706.54 | F40: 5706.54 | G40: 19062.5 | H40: 37332.88 | I40: 21780.78 | J40: 15612.39 | K40: 15612.39 | L40: 7332.01 | M40: 5306.71 | Y40: 8035.87 | Z40: 8035.87 | AA40: 7031.03 | AB40: 8080.48
...

Sheet BS별도
B1: (백만원) | C1: 이름: BS별도H | E1: 4Q21 | F1: 2021 | G1: 1Q22 | H1: 2Q22 | I1: 3Q22 | J1: 4Q22 | K1: 2022 | L1: 1Q23 | M1: 2Q23 | N1: 3Q23 | O1: 4Q23 | P1: 2023 | Q1: 1Q24 | R1: 2Q24 | S1: 3Q24 | T1: 4Q24 | U1: 2024 | V1: 1Q25 | W1: 2Q25 | X1: 3Q25 | Y1: 4Q25 | Z1: 2025 | AA1: 1Q26 | AB1: 2Q26 | AC1: 3Q26 | AD1: 4Q26 | AE1: 2026 | AF1: 1Q27 | AG1: 2Q27 | AH1: 3Q27 | AI1: 4Q27 | AJ1: 2027 | AK1: 1Q28 | AL1: 2Q28 | AM1: 3Q28 | AN1: 4Q28 | AO1: 2028
B2: 별도 | D2: fin json(kship_fin.py)
B3: 한화엔진(별) | C3: UPDATE: 26-10-13 | E3: 1 | F3: 2 | G3: 3 | H3: 4 | I3: 5 | J3: 6 | K3: 7 | L3: 8 | M3: 9 | N3: 10 | O3: 11 | P3: 12 | Q3: 13 | R3: 14 | S3: 15 | T3: 16 | U3: 17 | V3: 18 | W3: 19 | X3: 20 | Y3: 21 | Z3: 22 | AA3: 23 | AB3: 24 | AC3: 25 | AD3: 26 | AE3: 27 | AF3: 28 | AG3: 29 | AH3: 30 | AI3: 31 | AJ3: 32 | AK3: 33 | AL3: 34 | AM3: 35 | AN3: 36 | AO3: 37
B4: Account Code | C4: AccountNAME | E4: 2021.12 | F4: 2021.12A | G4: 2022.03 | H4: 2022.06 | I4: 2022.09 | J4: 2022.12 | K4: 2022.12A | L4: 2023.03 | M4: 2023.06 | N4: 2023.09 | O4: 2023.12 | P4: 2023.12A | Q4: 2024.03 | R4: 2024.06 | S4: 2024.09 | T4: 2024.12 | U4: 2024.12A | V4: 2025.03 | W4: 2025.06 | X4: 2025.09 | Y4: 2025.12 | Z4: 2025.12A | AA4: 2026.03 | AB4: 2026.06 | AC4: 2026.09 | AD4: 2026.12 | AE4: 2026.12A | AF4: 2027.03 | AG4: 2027.06 | AH4: 2027.09 | AI4: 2027.12 | AJ4: 2027.12A | AK4: 2028.03 | AL4: 2028.06 | AM4: 2028.09 | AN4: 2028.12 | AO4: 2028.12A
A5: 1 | C5: 유동자산 | E5: 346614.99 | F5: 346614.99 | G5: 356365.88 | H5: 390253.03 | I5: 540764.2 | J5: 471073.55 | K5: 471073.55 | L5: 492253.39 | M5: 552402.07 | N5: 611065.18 | O5: 655667.27 | P5: 655667.27 | Q5: 750413.99 | R5: 699944.85 | S5: 612864.18 | T5: 785001.24 | U5: 785001.24 | V5: 851970.85 | W5: 853459.44 | X5: 917610.92 | Y5: 1031851.2 | Z5: 1031851.2 | AA5: 852962.37 | AB5: 976282.4
A6: 1 | C6: 현금및현금성자산 | E6: 53585.63 | F6: 53585.63 | G6: 63630.95 | H6: 54135.08 | I6: 91288.83 | J6: 54559.25 | K6: 54559.25 | L6: 66371.55 | M6: 33083.66 | N6: 47857.15 | O6: 102831.94 | P6: 102831.94 | Q6: 206784.17 | R6: 98484.97 | S6: 80109 | T6: 133001.19 | U6: 133001.19 | V6: 123194.8 | W6: 203510.89 | X6: 218647.84 | Y6: 276708.03 | Z6: 276708.03 | AA6: 46502.75 | AB6: 156711.61
A7: 1 | C7: 단기금융상품 | E7: 12702.29 | F7: 12702.29 | G7: 8568 | H7: 8497.16 | I7: 42291.27 | J7: 15156.82 | K7: 15156.82 | L7: 13870.42 | M7: 13910.76 | N7: 16846.02 | O7: 18612.47 | P7: 18612.47 | Q7: 16917.66 | R7: 24899.77 | S7: 12539.26 | T7: 6649.16 | U7: 6649.16 | V7: 65458.64 | W7: 133814.27 | X7: 150479.7 | Y7: 133988.65 | Z7: 133988.65 | AA7: 65265.9
A8: 1 | C8: 단기금융자산 | E8: 14059.78 | F8: 14059.78 | G8: 10082.11 | H8: 8610.46 | I8: 42395.52 | J8: 15257.32 | K8: 15257.32 | L8: 13974.42 | M8: 14015.66 | N8: 16953.42 | O8: 18726.37 | P8: 18726.37 | Q8: 17033.76 | R8: 25014.52 | S8: 12656.06 | T8: 6766.66 | U8: 6766.66 | V8: 65568.84 | W8: 133922.52 | X8: 150593.6 | Y8: 134106 | Z8: 134106 | AA8: 70823.4 | AB8: 142045.33
A9: 1 | C9: 단기대여금 | E9: 1357.49 | F9: 1357.49 | G9: 1514.11 | H9: 113.3 | I9: 104.25 | J9: 100.5 | K9: 100.5 | L9: 104 | M9: 104.9 | N9: 107.4 | O9: 113.9 | P9: 113.9 | Q9: 116.1 | R9: 114.75 | S9: 116.8 | T9: 117.5 | U9: 117.5 | V9: 110.2 | W9: 108.25 | X9: 113.9 | Y9: 117.35 | Z9: 117.35 | AA9: 176.2
A10: 1 | C10: 매출채권및기타채권 | E10: 61460.63 | F10: 61460.63 | G10: 58679.42 | H10: 52273.4 | I10: 51497.35 | J10: 71262.89 | K10: 71262.89 | L10: 69235.43 | M10: 72694.88 | N10: 68484.46 | O10: 86308.2 | P10: 86308.2 | Q10: 101001.9 | R10: 117001.28 | S10: 103633.04 | T10: 135080.97 | U10: 135080.97 | V10: 159251.38 | W10: 131598.76 | X10: 117452.15 | Y10: 165742.58 | Z10: 165742.58 | AA10: 193202 | AB10: 123760.64
A11: 1 | C11: 계약자산 | E11: 12664.66 | F11: 12664.66 | N11: 877.05 | O11: 700.7 | P11: 700.7 | R11: 530.23 | S11: 598.73 | T11: 4492.99 | U11: 4492.99 | V11: 0 | W11: 0 | X11: 0
A12: 1 | C12: 당기법인세자산(선급법인세) | E12: 146.29 | F12: 146.29 | G12: 152.66 | H12: 117.23 | I12: 139.42 | J12: 211.85 | K12: 211.85 | L12: 257.65 | M12: 312.85 | N12: 389.14 | O12: 385.46 | P12: 385.46 | Q12: 83.7 | R12: 44.69 | T12: 0 | U12: 0 | V12: 193.35 | W12: 127.35 | X12: 4.3 | Y12: 18.3 | Z12: 18.3 | AB12: 26.79
A13: 1 | C13: 재고자산 | E13: 179045.98 | F13: 179045.98 | G13: 190016.21 | H13: 218947.82 | I13: 241888.53 | J13: 252292.72 | K13: 252292.72 | L13: 269549.22 | M13: 322351.85 | N13: 374061.81 | O13: 366491.88 | P13: 366491.88 | Q13: 359722.18 | R13: 369663.85 | S13: 358367.95 | T13: 370325.63 | U13: 370325.63 | V13: 374170.9 | W13: 328435.94 | X13: 348771.35 | Y13: 356165.91 | Z13: 356165.91 | AA13: 391082.44 | AB13: 466105.59
A14: 1 | C14: 기타유동자산 | E14: 8544.04 | F14: 8544.04 | G14: 11678.34 | H14: 14156.09 | I14: 15935.33 | J14: 14647.14 | K14: 14647.14 | L14: 14546.24 | M14: 16315.88 | N14: 14592.13 | O14: 16741.12 | P14: 16741.12 | Q14: 14172.59 | R14: 14461.98 | S14: 15426.89 | T14: 16454.51 | U14: 16454.51 | V14: 16837.3 | W14: 15336.42 | X14: 17561.28 | Y14: 15258.84 | Z14: 15258.84 | AA14: 29319.9 | AB14: 31956.04
A15: 1 | C15: 비유동자산 | E15: 445773.77 | F15: 445773.77 | G15: 444183.58 | H15: 478591.64 | I15: 536908.77 | J15: 485156.75 | K15: 485156.75 | L15: 502186.15 | M15: 477828.77 | N15: 502787.6 | O15: 481190.9 | P15: 481190.9 | Q15: 499761.5 | R15: 520351.33 | S15: 508758.52 | T15: 628100.71 | U15: 628100.71 | V15: 633346.55 | W15: 576292.46 | X15: 576697.09 | Y15: 663843.29 | Z15: 663843.29 | AA15: 1057216.7 | AB15: 1085203.6
A16: 1 | C16: 장기금융자산 | E16: 518.77 | F16: 518.77 | G16: 1472 | H16: 3639.48 | I16: 5621.98 | J16: 8008.43 | K16: 8008.43 | L16: 7778.89 | M16: 8472.58 | N16: 5572.35 | O16: 3072.46 | P16: 3072.46 | Q16: 2702.18 | R16: 1158.77 | S16: 1158.77 | T16: 1158.77 | U16: 1158.77 | V16: 1158.77 | W16: 1158.77 | X16: 1158.77 | Y16: 1158.77 | Z16: 1158.77 | AA16: 1158.77 | AB16: 1220.54
A17: 1 | C17: 투자자산 | E17: 3668.07 | F17: 3668.07 | G17: 3276.48 | H17: 5461.57 | I17: 7402.85 | J17: 44759.74 | K17: 44759.74 | L17: 44643.86 | M17: 9887.23 | N17: 7064.51 | O17: 4611.29 | P17: 4611.29 | Q17: 4236.08 | R17: 2735.22 | S17: 2738.39 | T17: 2794.28 | U17: 2794.28 | V17: 2840.82 | W17: 2979.34 | X17: 1543.45 | Y17: 1522.04 | Z17: 1522.04 | AA17: 311931.24 | AB17: 128013.62
A18: 1 | C18: 종속기업및관계기업투자 | E18: 2839.41 | F18: 2839.41 | G18: 1514.03 | H18: 1514.03 | I18: 1514.03 | J18: 36484.57 | K18: 36484.57 | L18: 36484.57 | M18: 1076.27 | N18: 1153.64 | O18: 1154.81 | P18: 1154.81 | Q18: 1154.81 | R18: 1236.01 | S18: 1239.42 | T18: 1286.54 | U18: 1286.54 | V18: 1352.22 | W18: 1493.73 | X18: 0 | Y18: 4.28 | Z18: 4.28 | AA18: 310064.28
A19: 1 | C19: 장기대여금 | E19: 309.89 | F19: 309.89 | G19: 290.45 | H19: 308.06 | I19: 266.84 | J19: 266.74 | K19: 266.74 | L19: 380.4 | M19: 338.38 | N19: 338.52 | O19: 384.02 | P19: 384.02 | Q19: 379.09 | R19: 340.44 | S19: 340.2 | T19: 348.97 | U19: 348.97 | V19: 329.83 | W19: 326.84 | X19: 384.68 | Y19: 358.99 | Z19: 358.99 | AA19: 463.3
A20: 1 | C20: 장기매출채권및기타채권 | E20: 579.58 | F20: 579.58 | G20: 591.47 | H20: 593.29 | I20: 596.43 | J20: 591.97 | K20: 591.97 | L20: 608.81 | M20: 596.33 | N20: 603.52 | O20: 589.92 | P20: 589.92 | Q20: 1452.58 | R20: 1407.18 | S20: 1406.88 | T20: 1493.53 | U20: 1493.53 | V20: 1801.61 | W20: 1819.5 | X20: 2685.11 | Y20: 2734.92 | Z20: 2734.92 | AA20: 2278.51 | AB20: 3083.55
A21: 1 | C21: 유형자산 | E21: 358378.92 | F21: 358378.92 | G21: 356224.49 | H21: 356637.32 | I21: 355015.27 | J21: 354241.66 | K21: 354241.66 | L21: 356421.66 | M21: 366070.83 | N21: 370471.9 | O21: 379948.53 | P21: 379948.53 | Q21: 384268.82 | R21: 392748.36 | S21: 410808.32 | T21: 415497.11 | U21: 415497.11 | V21: 417018.14 | W21: 415696.73 | X21: 425828.43 | Y21: 433599.71 | Z21: 433599.71 | AA21: 460320.15 | AB21: 490282.47
A22: 1 | C22: 사용권자산 | E22: 11937.8 | F22: 11937.8 | G22: 11592.36 | H22: 11237.53 | I22: 10805 | J22: 10742.3 | K22: 10742.3 | L22: 10533.81 | M22: 11288.93 | N22: 10936.94 | O22: 10791.77 | P22: 10791.77 | Q22: 10790.39 | R22: 10609.86 | S22: 10459.36 | T22: 10091 | U22: 10091 | V22: 9976.15 | W22: 9545.87 | X22: 9098.02 | Y22: 9028.79 | Z22: 9028.79 | AA22: 8890.83 | AB22: 9319.68
A23: 1 | C23: 기타비유동자산 | E23: 12421.68 | F23: 12421.68 | G23: 11932.44 | H23: 11878.24 | I23: 11698.07 | J23: 11779.6 | K23: 11779.6 | L23: 12044.73 | M23: 12723.46 | N23: 12682.66 | O23: 12176.2 | P23: 12176.2 | Q23: 12036.46 | R23: 11812.68 | S23: 12792.21 | T23: 12714.65 | U23: 12714.65 | V23: 17327.25 | W23: 14331.01 | X23: 13403.04 | Y23: 16298.55 | Z23: 16298.55 | AA23: 16191.63 | AB23: 16078.69
A24: 1 | C24: 투자부동산 | E24: 47673.85 | F24: 47673.85 | G24: 47673.85 | H24: 47169.78 | I24: 47169.78 | J24: 47192.31 | K24: 47192.31 | L24: 47192.31 | M24: 47192.31 | N24: 47192.31 | O24: 48965.82 | P24: 48965.82 | Q24: 48965.82 | R24: 48965.82 | S24: 48965.82 | T24: 48965.82 | U24: 48965.82 | V24: 48965.82 | W24: 48965.82 | X24: 48965.82 | Y24: 48965.82 | Z24: 48965.82 | AA24: 48965.82 | AB24: 48965.82
A25: 1 | C25: 무형자산 | E25: 3755.14 | F25: 3755.14 | G25: 3534.4 | H25: 3429.61 | I25: 3488.19 | J25: 3448.29 | K25: 3448.29 | L25: 3209.51 | M25: 2967.92 | N25: 2730.67 | O25: 2861.61 | P25: 2861.61 | Q25: 2717.67 | R25: 2714.87 | S25: 3302.65 | T25: 5712.95 | U25: 5712.95 | V25: 7078.43 | W25: 6866.4 | X25: 7420.32 | Y25: 9617.77 | Z25: 9617.77 | AA25: 20383.14
A26: 1 | C26: 이연법인세자산 | E26: 13165.33 | F26: 13165.33 | G26: 13864.2 | H26: 14877.67 | I26: 13452.88 | J26: 13110.98 | K26: 13110.98 | L26: 11554.47 | M26: 11454.18 | N26: 12124.08 | O26: 13062.19 | P26: 13062.19 | Q26: 10030.96 | R26: 5909.52 | S26: 3353.98 | T26: 16906.84 | U26: 16906.84 | V26: 16373.32 | W26: 25717.08 | X26: 25545.1 | Y26: 77750.89 | Z26: 77750.89 | AA26: 64689.18 | AB26: 65260.11
A27: 1 | C27: 자산총계 | E27: 792388.77 | F27: 792388.77 | G27: 800549.46 | H27: 868844.67 | I27: 1077673 | J27: 956230.29 | K27: 956230.29 | L27: 994439.54 | M27: 1030230.8 | N27: 1113852.8 | O27: 1136858.2 | P27: 1136858.2 | Q27: 1250175.5 | R27: 1220296.2 | S27: 1121622.7 | T27: 1413101.9 | U27: 1413101.9 | V27: 1485317.4 | W27: 1429751.9 | X27: 1494308 | Y27: 1695694.5 | Z27: 1695694.5 | AA27: 1910179.1 | AB27: 2061486
A28: 1 | C28: 유동부채 | E28: 428139.57 | F28: 428139.57 | G28: 472573.32 | H28: 545879.3 | I28: 603253.72 | J28: 498797.88 | K28: 498797.88 | L28: 533688.97 | M28: 518514.55 | N28: 596934.07 | O28: 603567.82 | P28: 603567.82 | Q28: 613162.88 | R28: 535412.69 | S28: 443990.06 | T28: 586563.18 | U28: 586563.18 | V28: 606765.29 | W28: 528929.2 | X28: 561720.42 | Y28: 611225.57 | Z28: 611225.57 | AA28: 722238.4 | AB28: 740378.58
A29: 1 | C29: 매입채무및기타채무 | E29: 123914.49 | F29: 123914.49 | G29: 132502.75 | H29: 132279.49 | I29: 118306.45 | J29: 133211.27 | K29: 133211.27 | L29: 140142.91 | M29: 144585.49 | N29: 148992.39 | O29: 199823.97 | P29: 199823.97 | Q29: 176885.8 | R29: 174927.17 | S29: 136815.45 | T29: 160663.68 | U29: 160663.68 | V29: 178995.03 | W29: 149408.71 | X29: 150287.02 | Y29: 179011.24 | Z29: 179011.24 | AA29: 229333.1 | AB29: 196418.51
A30: 1 | C30: 계약부채 | E30: 2381.61 | F30: 2381.61 | G30: 2232.58 | H30: 2337.48 | I30: 2295.76 | J30: 125312.31 | K30: 125312.31 | L30: 136489.79 | M30: 153159.35 | N30: 173445.3 | O30: 180982.12 | P30: 180982.12 | Q30: 190770.4 | R30: 208366.09 | S30: 203483.4 | T30: 226940.11 | U30: 226940.11 | V30: 246984.13 | W30: 235275.65 | X30: 245235.76 | Y30: 250874.74 | Z30: 250874.74 | AA30: 269004.85 | AB30: 352317.06
A31: 1 | C31: 단기차입금 | E31: 125000 | F31: 125000 | G31: 135000 | H31: 145000 | I31: 125000 | J31: 125000 | K31: 125000 | L31: 125000 | M31: 143900 | N31: 169600 | O31: 153000 | P31: 153000 | Q31: 151800 | R31: 50000 | S31: 36000 | T31: 30000 | U31: 30000 | V31: 30000 | W31: 20000 | X31: 20000
A32: 1 | C32: 유동성장기부채 | E32: 8412 | F32: 8412 | G32: 12470.9 | H32: 62555.8 | I32: 60055.75 | J32: 57055.75 | K32: 57055.75 | L32: 54055.75 | M32: 4055.75 | N32: 17805.75 | O32: 17055.75 | P32: 17055.75 | Q32: 16305.75 | T32: 0 | U32: 0 | V32: 0 | W32: 40602.7 | X32: 42000.98 | Y32: 43008.75 | Z32: 43008.75 | AA32: 45391.85 | AB32: 0
A33: 1 | C33: 선수금 | E33: 128935.23 | F33: 128935.23 | G33: 130096.7 | H33: 119213.08 | I33: 125753.52
A34: 1 | C34: 기타유동부채 | E34: 143004.11 | F34: 143004.11 | G34: 147007.37 | H34: 138395.35 | I34: 144442.86 | J34: 16453.15 | K34: 16453.15 | L34: 19222.68 | M34: 20402.79 | N34: 21652.81 | O34: 19618.75 | P34: 19618.75 | Q34: 20576.7 | R34: 27229.97 | S34: 29142.58 | T34: 37789.59 | U34: 37789.59 | V34: 30157.53 | W34: 37085.04 | X34: 42740.59 | Y34: 51443.19 | Z34: 51443.19 | AA34: 39711.02 | AB34: 47480.87
A35: 1 | C35: 단기충당부채 | E35: 7490.2 | F35: 7490.2 | G35: 20519.14 | H35: 16271.12 | I35: 12649.07 | J35: 9805.65 | K35: 9805.65 | L35: 10302.54 | M35: 7322.26 | N35: 6003.42 | O35: 5418.09 | P35: 5418.09 | Q35: 5691.98 | R35: 4891.72 | S35: 4377.74 | T35: 4565.94 | U35: 4565.94 | V35: 4889.84 | W35: 5136.11 | X35: 6979.16 | Y35: 5951.68 | Z35: 5951.68 | AA35: 5357.49 | AB35: 5588.93
A36: 1 | C36: 비유동부채 | E36: 155419.72 | F36: 155419.72 | G36: 163610.83 | H36: 190146.91 | I36: 249697.55 | J36: 235848.09 | K36: 235848.09 | L36: 233601.97 | M36: 284381.98 | N36: 291310.33 | O36: 309142.06 | P36: 309142.06 | Q36: 308196.85 | R36: 343200.79 | S36: 325077.87 | T36: 433242.98 | U36: 433242.98 | V36: 465322.02 | W36: 470769.71 | X36: 471031 | Y36: 528366.07 | Z36: 528366.07 | AA36: 578302.71 | AB36: 668541.61
A37: 1 | C37: 장기차입금 | E37: 75708 | F37: 75708 | G37: 72335.1 | H37: 21723.2 | I37: 20709.06 | J37: 19695.12 | K37: 19695.12 | L37: 18681.18 | M37: 17667.24 | N37: 2903.31 | O37: 2639.37 | P37: 2639.37 | Q37: 2375.43 | S37: 10000 | T37: 0 | U37: 0 | V37: 10000 | W37: 10000 | X37: 10000 | Y37: 10000 | Z37: 10000 | AA37: 10000 | AB37: 10000
A38: 1 | C38: 장기매입채무및기타채무 | E38: 9704.52 | F38: 9704.52 | G38: 9530.38 | H38: 9235.66 | I38: 8963.7 | J38: 8747.39 | K38: 8747.39 | L38: 8670.86 | M38: 9188.19 | N38: 8949.29 | O38: 8708.96 | P38: 8708.96 | Q38: 8723.85 | R38: 8988.13 | S38: 9593.13 | T38: 10549.09 | U38: 10549.09 | V38: 11746.72 | W38: 14009.95 | X38: 19180.03 | Y38: 20095.14 | Z38: 20095.14 | AA38: 11718.59
A39: 1 | C39: 확정급여부채 | E39: 9270.24 | F39: 9270.24 | G39: 11571.13 | H39: 12349.59 | I39: 13244.12 | J39: 4818.18 | K39: 4818.18 | L39: 7560.97 | M39: 8345.16 | N39: 9237.29 | O39: 7110.7 | P39: 7110.7 | Q39: 9561.63 | R39: 10721.55 | S39: 11737.22 | T39: 5049.89 | U39: 5049.89 | V39: 0 | W39: 4151.62 | X39: 3526.66 | Y39: 8347.75 | Z39: 8347.75 | AA39: 10306.64 | AB39: 9637.45
A40: 1 | C40: 장기충당부채 | E40: 5706.54 | F40: 5706.54 | G40: 19062.5 | H40: 37332.88 | I40: 21780.78 | J40: 15612.39 | K40: 15612.39 | L40: 7332.01 | M40: 5306.71 | N40: 5048.55 | O40: 5957.99 | P40: 5957.99 | Q40: 5491.21 | R40: 5564.97 | S40: 5566.76 | T40: 5582.28 | U40: 5582.28 | V40: 5916.9 | W40: 6367.33 | X40: 9962.44 | Y40: 8035.87 | Z40: 8035.87 | AA40: 7031.03 | AB40: 8080.48
...

Sheet subQ
A1: YQ | C1: subQ 분기 서브모델(억원, U=100) | E1: 4Q21 | F1: 2021 | G1: 1Q22 | H1: 2Q22 | I1: 3Q22 | J1: 4Q22 | K1: 2022 | L1: 1Q23 | M1: 2Q23 | N1: 3Q23 | O1: 4Q23 | P1: 2023 | Q1: 1Q24 | R1: 2Q24 | S1: 3Q24 | T1: 4Q24 | U1: 2024 | V1: 1Q25 | W1: 2Q25 | X1: 3Q25 | Y1: 4Q25 | Z1: 2025 | AA1: 1Q26 | AB1: 2Q26 | AC1: 3Q26 | AD1: 4Q26 | AE1: 2026 | AF1: 1Q27 | AG1: 2Q27 | AH1: 3Q27 | AI1: 4Q27 | AJ1: 2027 | AK1: 1Q28 | AL1: 2Q28 | AM1: 3Q28 | AN1: 4Q28 | AO1: 2028
A2: A=이름(key) B=그룹 C=단위 D=FnGuide 계정명(VLOOKUP 키). 확정=VLOOKUP(BS), 추정=변수 가정 참조
E3: 1 | F3: 2 | G3: 3 | H3: 4 | I3: 5 | J3: 6 | K3: 7 | L3: 8 | M3: 9 | N3: 10 | O3: 11 | P3: 12 | Q3: 13 | R3: 14 | S3: 15 | T3: 16 | U3: 17 | V3: 18 | W3: 19 | X3: 20 | Y3: 21 | Z3: 22 | AA3: 23 | AB3: 24 | AC3: 25 | AD3: 26 | AE3: 27 | AF3: 28 | AG3: 29 | AH3: 30 | AI3: 31 | AJ3: 32 | AK3: 33 | AL3: 34 | AM3: 35 | AN3: 36 | AO3: 37
E4: 2021.12 | F4: 2021.12A | G4: 2022.03 | H4: 2022.06 | I4: 2022.09 | J4: 2022.12 | K4: 2022.12A | L4: 2023.03 | M4: 2023.06 | N4: 2023.09 | O4: 2023.12 | P4: 2023.12A | Q4: 2024.03 | R4: 2024.06 | S4: 2024.09 | T4: 2024.12 | U4: 2024.12A | V4: 2025.03 | W4: 2025.06 | X4: 2025.09 | Y4: 2025.12 | Z4: 2025.12A | AA4: 2026.03 | AB4: 2026.06 | AC4: 2026.09 | AD4: 2026.12 | AE4: 2026.12A | AF4: 2027.03 | AG4: 2027.06 | AH4: 2027.09 | AI4: 2027.12 | AJ4: 2027.12A | AK4: 2028.03 | AL4: 2028.06 | AM4: 2028.09 | AN4: 2028.12 | AO4: 2028.12A
A5: 매출액 | B5: 손익 | C5: 억원 | D5: 매출액(수익) | E5: =IFERROR(VLOOKUP($D5,BS연결,MATCH(E$1,BS연결H,0),0)/100,"") | G5: =IFERROR(VLOOKUP($D5,BS연결,MATCH(G$1,BS연결H,0),0)/100,"") | H5: =IFERROR(VLOOKUP($D5,BS연결,MATCH(H$1,BS연결H,0),0)/100,"") | I5: =IFERROR(VLOOKUP($D5,BS연결,MATCH(I$1,BS연결H,0),0)/100,"") | J5: =IFERROR(VLOOKUP($D5,BS연결,MATCH(J$1,BS연결H,0),0)/100,"") | K5: =IFERROR(VLOOKUP($D5,BS연결,MATCH(K$1,BS연결H,0),0)/100,"") | L5: =IFERROR(VLOOKUP($D5,BS연결,MATCH(L$1,BS연결H,0),0)/100,"") | M5: =IFERROR(VLOOKUP($D5,BS연결,MATCH(M$1,BS연결H,0),0)/100,"") | N5: =IFERROR(VLOOKUP($D5,BS별도,MATCH(N$1,BS별도H,0),0)/100,"") | O5: =IFERROR(VLOOKUP($D5,BS별도,MATCH(O$1,BS별도H,0),0)/100,"") | P5: =SUM(L5:O5) | Q5: =IFERROR(VLOOKUP($D5,BS별도,MATCH(Q$1,BS별도H,0),0)/100,"") | R5: =IFERROR(VLOOKUP($D5,BS별도,MATCH(R$1,BS별도H,0),0)/100,"") | S5: =IFERROR(VLOOKUP($D5,BS별도,MATCH(S$1,BS별도H,0),0)/100,"") | T5: =IFERROR(VLOOKUP($D5,BS별도,MATCH(T$1,BS별도H,0),0)/100,"") | U5: =SUM(Q5:T5) | V5: =IFERROR(VLOOKUP($D5,BS별도,MATCH(V$1,BS별도H,0),0)/100,"") | W5: =IFERROR(VLOOKUP($D5,BS별도,MATCH(W$1,BS별도H,0),0)/100,"") | X5: =IFERROR(VLOOKUP($D5,BS별도,MATCH(X$1,BS별도H,0),0)/100,"") | Y5: =IFERROR(VLOOKUP($D5,BS별도,MATCH(Y$1,BS별도H,0),0)/100,"") | Z5: =SUM(V5:Y5) | AA5: =IFERROR(VLOOKUP($D5,BS연결,MATCH(AA$1,BS연결H,0),0)/100,"") | AB5: =IFERROR(VLOOKUP($D5,BS연결,MATCH(AB$1,BS연결H,0),0)/100,"") | AC5: =IFERROR(X5*(1+변수!AC21),"") | AD5: =IFERROR(Y5*(1+변수!AD21),"") | AE5: =SUM(AA5:AD5) | AF5: =IFERROR(AA5*(1+변수!AF21),"") | AG5: =IFERROR(AB5*(1+변수!AG21),"") | AH5: =IFERROR(AC5*(1+변수!AH21),"") | AI5: =IFERROR(AD5*(1+변수!AI21),"") | AJ5: =SUM(AF5:AI5) | AK5: =IFERROR(AF5*(1+변수!AK21),"") | AL5: =IFERROR(AG5*(1+변수!AL21),"") | AM5: =IFERROR(AH5*(1+변수!AM21),"") | AN5: =IFERROR(AI5*(1+변수!AN21),"") | AO5: =SUM(AK5:AN5)
A6: 매출원가 | B6: 손익 | C6: 억원 | D6: 매출원가 | E6: =IFERROR(VLOOKUP($D6,BS연결,MATCH(E$1,BS연결H,0),0)/100,"") | G6: =IFERROR(VLOOKUP($D6,BS연결,MATCH(G$1,BS연결H,0),0)/100,"") | H6: =IFERROR(VLOOKUP($D6,BS연결,MATCH(H$1,BS연결H,0),0)/100,"") | I6: =IFERROR(VLOOKUP($D6,BS연결,MATCH(I$1,BS연결H,0),0)/100,"") | J6: =IFERROR(VLOOKUP($D6,BS연결,MATCH(J$1,BS연결H,0),0)/100,"") | K6: =IFERROR(VLOOKUP($D6,BS연결,MATCH(K$1,BS연결H,0),0)/100,"") | L6: =IFERROR(VLOOKUP($D6,BS연결,MATCH(L$1,BS연결H,0),0)/100,"") | M6: =IFERROR(VLOOKUP($D6,BS연결,MATCH(M$1,BS연결H,0),0)/100,"") | N6: =IFERROR(VLOOKUP($D6,BS별도,MATCH(N$1,BS별도H,0),0)/100,"") | O6: =IFERROR(VLOOKUP($D6,BS별도,MATCH(O$1,BS별도H,0),0)/100,"") | P6: =SUM(L6:O6) | Q6: =IFERROR(VLOOKUP($D6,BS별도,MATCH(Q$1,BS별도H,0),0)/100,"") | R6: =IFERROR(VLOOKUP($D6,BS별도,MATCH(R$1,BS별도H,0),0)/100,"") | S6: =IFERROR(VLOOKUP($D6,BS별도,MATCH(S$1,BS별도H,0),0)/100,"") | T6: =IFERROR(VLOOKUP($D6,BS별도,MATCH(T$1,BS별도H,0),0)/100,"") | U6: =SUM(Q6:T6) | V6: =IFERROR(VLOOKUP($D6,BS별도,MATCH(V$1,BS별도H,0),0)/100,"") | W6: =IFERROR(VLOOKUP($D6,BS별도,MATCH(W$1,BS별도H,0),0)/100,"") | X6: =IFERROR(VLOOKUP($D6,BS별도,MATCH(X$1,BS별도H,0),0)/100,"") | Y6: =IFERROR(VLOOKUP($D6,BS별도,MATCH(Y$1,BS별도H,0),0)/100,"") | Z6: =SUM(V6:Y6) | AA6: =IFERROR(VLOOKUP($D6,BS연결,MATCH(AA$1,BS연결H,0),0)/100,"") | AB6: =IFERROR(VLOOKUP($D6,BS연결,MATCH(AB$1,BS연결H,0),0)/100,"") | AC6: =IFERROR(AC5-AC7,"") | AD6: =IFERROR(AD5-AD7,"") | AE6: =SUM(AA6:AD6) | AF6: =IFERROR(AF5-AF7,"") | AG6: =IFERROR(AG5-AG7,"") | AH6: =IFERROR(AH5-AH7,"") | AI6: =IFERROR(AI5-AI7,"") | AJ6: =SUM(AF6:AI6) | AK6: =IFERROR(AK5-AK7,"") | AL6: =IFERROR(AL5-AL7,"") | AM6: =IFERROR(AM5-AM7,"") | AN6: =IFERROR(AN5-AN7,"") | AO6: =SUM(AK6:AN6)
A7: 매출총이익 | B7: 손익 | C7: 억원 | D7: 매출총이익 | E7: =IFERROR(VLOOKUP($D7,BS연결,MATCH(E$1,BS연결H,0),0)/100,"") | G7: =IFERROR(VLOOKUP($D7,BS연결,MATCH(G$1,BS연결H,0),0)/100,"") | H7: =IFERROR(VLOOKUP($D7,BS연결,MATCH(H$1,BS연결H,0),0)/100,"") | I7: =IFERROR(VLOOKUP($D7,BS연결,MATCH(I$1,BS연결H,0),0)/100,"") | J7: =IFERROR(VLOOKUP($D7,BS연결,MATCH(J$1,BS연결H,0),0)/100,"") | K7: =IFERROR(VLOOKUP($D7,BS연결,MATCH(K$1,BS연결H,0),0)/100,"") | L7: =IFERROR(VLOOKUP($D7,BS연결,MATCH(L$1,BS연결H,0),0)/100,"") | M7: =IFERROR(VLOOKUP($D7,BS연결,MATCH(M$1,BS연결H,0),0)/100,"") | N7: =IFERROR(VLOOKUP($D7,BS별도,MATCH(N$1,BS별도H,0),0)/100,"") | O7: =IFERROR(VLOOKUP($D7,BS별도,MATCH(O$1,BS별도H,0),0)/100,"") | P7: =SUM(L7:O7) | Q7: =IFERROR(VLOOKUP($D7,BS별도,MATCH(Q$1,BS별도H,0),0)/100,"") | R7: =IFERROR(VLOOKUP($D7,BS별도,MATCH(R$1,BS별도H,0),0)/100,"") | S7: =IFERROR(VLOOKUP($D7,BS별도,MATCH(S$1,BS별도H,0),0)/100,"") | T7: =IFERROR(VLOOKUP($D7,BS별도,MATCH(T$1,BS별도H,0),0)/100,"") | U7: =SUM(Q7:T7) | V7: =IFERROR(VLOOKUP($D7,BS별도,MATCH(V$1,BS별도H,0),0)/100,"") | W7: =IFERROR(VLOOKUP($D7,BS별도,MATCH(W$1,BS별도H,0),0)/100,"") | X7: =IFERROR(VLOOKUP($D7,BS별도,MATCH(X$1,BS별도H,0),0)/100,"") | Y7: =IFERROR(VLOOKUP($D7,BS별도,MATCH(Y$1,BS별도H,0),0)/100,"") | Z7: =SUM(V7:Y7) | AA7: =IFERROR(VLOOKUP($D7,BS연결,MATCH(AA$1,BS연결H,0),0)/100,"") | AB7: =IFERROR(VLOOKUP($D7,BS연결,MATCH(AB$1,BS연결H,0),0)/100,"") | AC7: =IFERROR(AC9+AC8,"") | AD7: =IFERROR(AD9+AD8,"") | AE7: =SUM(AA7:AD7) | AF7: =IFERROR(AF9+AF8,"") | AG7: =IFERROR(AG9+AG8,"") | AH7: =IFERROR(AH9+AH8,"") | AI7: =IFERROR(AI9+AI8,"") | AJ7: =SUM(AF7:AI7) | AK7: =IFERROR(AK9+AK8,"") | AL7: =IFERROR(AL9+AL8,"") | AM7: =IFERROR(AM9+AM8,"") | AN7: =IFERROR(AN9+AN8,"") | AO7: =SUM(AK7:AN7)
A8: 판관비 | B8: 손익 | C8: 억원 | D8: 판관비 | E8: =IFERROR(VLOOKUP($D8,BS연결,MATCH(E$1,BS연결H,0),0)/100,"") | G8: =IFERROR(VLOOKUP($D8,BS연결,MATCH(G$1,BS연결H,0),0)/100,"") | H8: =IFERROR(VLOOKUP($D8,BS연결,MATCH(H$1,BS연결H,0),0)/100,"") | I8: =IFERROR(VLOOKUP($D8,BS연결,MATCH(I$1,BS연결H,0),0)/100,"") | J8: =IFERROR(VLOOKUP($D8,BS연결,MATCH(J$1,BS연결H,0),0)/100,"") | K8: =SUM(G8:J8) | L8: =IFERROR(VLOOKUP($D8,BS연결,MATCH(L$1,BS연결H,0),0)/100,"") | M8: =IFERROR(VLOOKUP($D8,BS연결,MATCH(M$1,BS연결H,0),0)/100,"") | N8: =IFERROR(VLOOKUP($D8,BS별도,MATCH(N$1,BS별도H,0),0)/100,"") | O8: =IFERROR(VLOOKUP($D8,BS별도,MATCH(O$1,BS별도H,0),0)/100,"") | P8: =SUM(L8:O8) | Q8: =IFERROR(VLOOKUP($D8,BS별도,MATCH(Q$1,BS별도H,0),0)/100,"") | R8: =IFERROR(VLOOKUP($D8,BS별도,MATCH(R$1,BS별도H,0),0)/100,"") | S8: =IFERROR(VLOOKUP($D8,BS별도,MATCH(S$1,BS별도H,0),0)/100,"") | T8: =IFERROR(VLOOKUP($D8,BS별도,MATCH(T$1,BS별도H,0),0)/100,"") | U8: =SUM(Q8:T8) | V8: =IFERROR(VLOOKUP($D8,BS별도,MATCH(V$1,BS별도H,0),0)/100,"") | W8: =IFERROR(VLOOKUP($D8,BS별도,MATCH(W$1,BS별도H,0),0)/100,"") | X8: =IFERROR(VLOOKUP($D8,BS별도,MATCH(X$1,BS별도H,0),0)/100,"") | Y8: =IFERROR(VLOOKUP($D8,BS별도,MATCH(Y$1,BS별도H,0),0)/100,"") | Z8: =SUM(V8:Y8) | AA8: =IFERROR(VLOOKUP($D8,BS연결,MATCH(AA$1,BS연결H,0),0)/100,"") | AB8: =IFERROR(VLOOKUP($D8,BS연결,MATCH(AB$1,BS연결H,0),0)/100,"") | AC8: =IFERROR(AC5*변수!AC22,"") | AD8: =IFERROR(AD5*변수!AD22,"") | AE8: =SUM(AA8:AD8) | AF8: =IFERROR(AF5*변수!AF22,"") | AG8: =IFERROR(AG5*변수!AG22,"") | AH8: =IFERROR(AH5*변수!AH22,"") | AI8: =IFERROR(AI5*변수!AI22,"") | AJ8: =SUM(AF8:AI8) | AK8: =IFERROR(AK5*변수!AK22,"") | AL8: =IFERROR(AL5*변수!AL22,"") | AM8: =IFERROR(AM5*변수!AM22,"") | AN8: =IFERROR(AN5*변수!AN22,"") | AO8: =SUM(AK8:AN8)
A9: 영업이익 | B9: 손익 | C9: 억원 | D9: 영업이익 | E9: =IFERROR(VLOOKUP($D9,BS연결,MATCH(E$1,BS연결H,0),0)/100,"") | G9: =IFERROR(VLOOKUP($D9,BS연결,MATCH(G$1,BS연결H,0),0)/100,"") | H9: =IFERROR(VLOOKUP($D9,BS연결,MATCH(H$1,BS연결H,0),0)/100,"") | I9: =IFERROR(VLOOKUP($D9,BS연결,MATCH(I$1,BS연결H,0),0)/100,"") | J9: =IFERROR(VLOOKUP($D9,BS연결,MATCH(J$1,BS연결H,0),0)/100,"") | K9: =IFERROR(VLOOKUP($D9,BS연결,MATCH(K$1,BS연결H,0),0)/100,"") | L9: =IFERROR(VLOOKUP($D9,BS연결,MATCH(L$1,BS연결H,0),0)/100,"") | M9: =IFERROR(VLOOKUP($D9,BS연결,MATCH(M$1,BS연결H,0),0)/100,"") | N9: =IFERROR(VLOOKUP($D9,BS별도,MATCH(N$1,BS별도H,0),0)/100,"") | O9: =IFERROR(VLOOKUP($D9,BS별도,MATCH(O$1,BS별도H,0),0)/100,"") | P9: =SUM(L9:O9) | Q9: =IFERROR(VLOOKUP($D9,BS별도,MATCH(Q$1,BS별도H,0),0)/100,"") | R9: =IFERROR(VLOOKUP($D9,BS별도,MATCH(R$1,BS별도H,0),0)/100,"") | S9: =IFERROR(VLOOKUP($D9,BS별도,MATCH(S$1,BS별도H,0),0)/100,"") | T9: =IFERROR(VLOOKUP($D9,BS별도,MATCH(T$1,BS별도H,0),0)/100,"") | U9: =SUM(Q9:T9) | V9: =IFERROR(VLOOKUP($D9,BS별도,MATCH(V$1,BS별도H,0),0)/100,"") | W9: =IFERROR(VLOOKUP($D9,BS별도,MATCH(W$1,BS별도H,0),0)/100,"") | X9: =IFERROR(VLOOKUP($D9,BS별도,MATCH(X$1,BS별도H,0),0)/100,"") | Y9: =IFERROR(VLOOKUP($D9,BS별도,MATCH(Y$1,BS별도H,0),0)/100,"") | Z9: =SUM(V9:Y9) | AA9: =IFERROR(VLOOKUP($D9,BS연결,MATCH(AA$1,BS연결H,0),0)/100,"") | AB9: =IFERROR(VLOOKUP($D9,BS연결,MATCH(AB$1,BS연결H,0),0)/100,"") | AC9: =IFERROR(AC5*변수!AC23,"") | AD9: =IFERROR(AD5*변수!AD23,"") | AE9: =SUM(AA9:AD9) | AF9: =IFERROR(AF5*변수!AF23,"") | AG9: =IFERROR(AG5*변수!AG23,"") | AH9: =IFERROR(AH5*변수!AH23,"") | AI9: =IFERROR(AI5*변수!AI23,"") | AJ9: =SUM(AF9:AI9) | AK9: =IFERROR(AK5*변수!AK23,"") | AL9: =IFERROR(AL5*변수!AL23,"") | AM9: =IFERROR(AM5*변수!AM23,"") | AN9: =IFERROR(AN5*변수!AN23,"") | AO9: =SUM(AK9:AN9)
A10: OPM | B10: 손익 | C10: % | D10: 영업이익률 | E10: =IFERROR(E9/E5,"") | G10: =IFERROR(G9/G5,"") | H10: =IFERROR(H9/H5,"") | I10: =IFERROR(I9/I5,"") | J10: =IFERROR(J9/J5,"") | K10: =IFERROR(K9/K5,"") | L10: =IFERROR(L9/L5,"") | M10: =IFERROR(M9/M5,"") | N10: =IFERROR(N9/N5,"") | ... AO10: =IFERROR(AO9/AO5,"")
