Workbook
Name 변수H: 변수!$C$1:$AO$1
Name 환율: 변수!$C$6:$AO$13
Name BS연결H: BS연결!$C$1:$AO$1
Name BS연결: BS연결!$C$5:$AO$99
Name BS별도H: BS별도!$C$1:$AO$1
Name BS별도: BS별도!$C$5:$AO$95
Name SUBQH: subQ!$A$1:$AO$1
Name subQ: subQ!$A$5:$AO$41

Sheet README
A1: 엔케이(085310) 실적 모델 — ARGUS 한국조선
A2: 기준 분기 2026Q2 · 마지막 실적 2026Q2 · 생성 2026-10-11
A3: 모든 수치는 모델 산출값(DART 공개 재무제표 + 우리 추정)이다 — 목표주가·투자 추천 아님. 참고용 · 투자조언 아님.
A5: 시트
A6: 변수 가정 시계열. 환율 8행(ECB via frankfurter — L2 fx.json; 추정 분기 = 노란 가정), 추정 드라이버(노란 셀 = 모델값에서 역산한 가정, 바꾸면 재계산; 연녹 셀 = 3절 스칼라 참조 수식), 3절 스칼라 가정(세율·판관비율·지배주주비중·이자율·종가·PER 밴드·COE·외화 순노출·헤지비율)
A7: BS연결/BS별도 FnGuide 계정명 × 기간 값 덤프(백만원). 행1 분기라벨, 행4 YYYY.MM / YYYY.12A. 이름정의 BS연결H·BS연결(계정명 C열부터)
A8: subQ 분기 서브모델(억원 = 백만원/100). 확정 행: =IFERROR(VLOOKUP($D행,BS연결,MATCH(E$1,BS연결H,0),0)/100,"") 추정 행: 변수 시트 가정 셀 참조 수식. 외환손익·파생상품손익은 BS 계정 합·차, 기타금융손익은 잔차, OPM·EPS·BPS·PER·PBR 은 파생 수식
A9: SLS 선표(조선사만, sls json 있을 때): 요약 행(sls 저장값) + 계약별 스케줄(백만$) × (헤지비율 × 헤지환율 + (1−헤지비율) × 건조시점 환율[변수 원/달러(평균)]) → 원화 수식 블록 → 합계 행이 subQ 매출조선에 연결
A10: 시나리오 신규수주 보수/기준/낙관(forecast_panel 패널, 모델에 scenarios 가 있을 때만): 매출액·영업이익 = subQ 기준값 ± (시나리오 신규 − base 신규) × OPM. base 만 subQ 행에 포함, 나머지는 합산 안 함
A11: 분기/연간예상 subQ 를 이름(A열 key)으로 VLOOKUP 한 보고서 표(억원)
A12: TP PER 밴드 × 12M fwd EPS, PBR = ROE/COE × BPS — 모델 산출값 구간, 목표주가·추천 아님
A13: 외화 환율 QoQ, 외화 순노출 × Δ기말환율 → 환관련손익 추정
... A34: 백테스트: {"freeze": "2025Q2", "horizon": 4, "revenue_wape_pct": 8.3, "op_wape_pct": 129.2, "n": 4, "note": "단일 회사 4분기 — 통계 아님", "driver_at_freeze": "customer_yard_revenue_weighted", "selection_oos_at_freeze": {"freeze": "2024Q2", "n": 4, "wape_link": null, "wape_trend": 23.0, "adopted": "undetermined", "decision": "undetermined", "note": "현재 채택 조합(suppliers_mentions·시차 4·ma4·창 8)을 동결 데이터로 재적합할 수 없음(짝·고객 모델 부족) → 연동 WAPE 없음, undetermined(유의성 조건만으로 채택)"}, "frozen_inputs": "fin(연결/별도)·고객 조선사 모델·지주 자회사 모델은 2025Q2 까지의 분기만; 선표는 체결일 ≤ 2025Q2 말일 계약(원장 최신 금액·코호트 등급, 환산 없음); 잔고는 yards_cache 2025Q2; 시세·환율 forward·prices·forecast_panel 신규수주 미사용. 고객 가중치(suppliers.json 언급 비중)와 합병 체인링크는 현재 지식; 고객 연동 채택은 동결 모델 안에서도 자기 la−4분기 OOS 규칙(selection_oos_at_freeze)", "detail": [{"q": "2025Q3", "rev_pred": 277.78, "rev_act": 285.56, "op_pred": -13.37, "op_act": -50.22}, {"q": "2025Q4", "rev_pred": 411.63, "rev_act": 490.43, "op_pred": -19.81, "op_act": 49.97}, {"q": "2026Q1", "rev_pred": 341.66, "rev_act": 319.14, "op_pred": -16.44, "op_act": 5.34}, {"q": "2026Q2", "rev_pred": 355.91, "rev_act": 367.92, "op_pred": -17.13, "op_act": 31.44}]}

Sheet 변수
C1: 이름: 변수H | E1: 4Q21 | F1: 2021 | G1: 1Q22 | H1: 2Q22 | I1: 3Q22 | J1: 4Q22 | K1: 2022 | L1: 1Q23 | M1: 2Q23 | N1: 3Q23 | O1: 4Q23 | P1: 2023 | Q1: 1Q24 | R1: 2Q24 | S1: 3Q24 | T1: 4Q24 | U1: 2024 | V1: 1Q25 | W1: 2Q25 | X1: 3Q25 | Y1: 4Q25 | Z1: 2025 | AA1: 1Q26 | AB1: 2Q26 | AC1: 3Q26 | AD1: 4Q26 | AE1: 2026 | AF1: 1Q27 | AG1: 2Q27 | AH1: 3Q27 | AI1: 4Q27 | AJ1: 2027 | AK1: 1Q28 | AL1: 2Q28 | AM1: 3Q28 | AN1: 4Q28 | AO1: 2028
A2: 가정 시계열 — 노란 셀은 추정 가정(모델값에서 역산), 연녹 셀은 3절 스칼라 참조 수식. 바꾸면 subQ·분기·연간예상·TP·시나리오가 재계산됩니다.
E3: 1 | F3: 2 | G3: 3 | H3: 4 | I3: 5 | J3: 6 | K3: 7 | L3: 8 | M3: 9 | N3: 10 | O3: 11 | P3: 12 | Q3: 13 | R3: 14 | S3: 15 | T3: 16 | U3: 17 | V3: 18 | W3: 19 | X3: 20 | Y3: 21 | Z3: 22 | AA3: 23 | AB3: 24 | AC3: 25 | AD3: 26 | AE3: 27 | AF3: 28 | AG3: 29 | AH3: 30 | AI3: 31 | AJ3: 32 | AK3: 33 | AL3: 34 | AM3: 35 | AN3: 36 | AO3: 37
E4: 2021.12 | F4: 2021.12A | G4: 2022.03 | H4: 2022.06 | I4: 2022.09 | J4: 2022.12 | K4: 2022.12A | L4: 2023.03 | M4: 2023.06 | N4: 2023.09 | O4: 2023.12 | P4: 2023.12A | Q4: 2024.03 | R4: 2024.06 | S4: 2024.09 | T4: 2024.12 | U4: 2024.12A | V4: 2025.03 | W4: 2025.06 | X4: 2025.09 | Y4: 2025.12 | Z4: 2025.12A | AA4: 2026.03 | AB4: 2026.06 | AC4: 2026.09 | AD4: 2026.12 | AE4: 2026.12A | AF4: 2027.03 | AG4: 2027.06 | AH4: 2027.09 | AI4: 2027.12 | AJ4: 2027.12A | AK4: 2028.03 | AL4: 2028.06 | AM4: 2028.09 | AN4: 2028.12 | AO4: 2028.12A
B5: 1. FX | C5: 이름: 환율
A6: USDKRW_avg | C6: 원/달러(평균) | E6: 1183.5 | F6: 1145.51 | G6: 1205.78 | H6: 1262.09 | I6: 1341.93 | J6: 1360.12 | K6: 1292.98 | L6: 1276.95 | M6: 1315.69 | N6: 1313.62 | O6: 1322.01 | P6: 1306.85 | Q6: 1330.14 | R6: 1371.28 | S6: 1356.22 | T6: 1396.3 | U6: 1363.53 | V6: 1452.28 | W6: 1398.52 | X6: 1386.95 | Y6: 1449.19 | Z6: 1421.52 | AA6: 1466.12 | AB6: 1501.75 | AC6: 1418.75 | AD6: 1345.14 | AE6: 1457.21 | AF6: 1341.49 | AG6: 1341.49 | AH6: 1341.49 | AI6: 1341.49 | AK6: 1341.49 | AL6: 1341.49 | AM6: 1341.49 | AN6: 1341.49
A7: USDKRW_end | C7: 원/달러(기말) | E7: 1188.75 | F7: 1188.75 | G7: 1213.74 | H7: 1301.24 | I7: 1436.9 | J7: 1260.16 | K7: 1260.16 | L7: 1305.99 | M7: 1321.44 | N7: 1345.35 | O7: 1297.43 | P7: 1297.43 | Q7: 1349.25 | R7: 1377.73 | S7: 1312.17 | T7: 1474.78 | U7: 1474.78 | V7: 1474.54 | W7: 1355.13 | X7: 1403.67 | Y7: 1444.2 | Z7: 1444.2 | AA7: 1524.8 | AB7: 1550.89 | AC7: 1355.4 | AD7: 1341.49 | AE7: 1341.49 | AF7: 1341.49 | AG7: 1341.49 | AH7: 1341.49 | AI7: 1341.49 | AK7: 1341.49 | AL7: 1341.49 | AM7: 1341.49 | AN7: 1341.49
A8: JPY100KRW_avg | C8: 원/100Y(평균) | E8: 1041.02 | F8: 1042.74 | G8: 1036.79 | H8: 972.23 | I8: 970.61 | J8: 961.03 | K8: 985.1 | L8: 964.89 | M8: 957.36 | N8: 909 | O8: 893.22 | P8: 931.11 | Q8: 896.29 | R8: 880.14 | S8: 909.35 | T8: 917.25 | U8: 900.92 | V8: 952.59 | W8: 967.92 | X8: 940.32 | Y8: 940.77 | Z8: 950.17 | AA8: 934.39 | AB8: 942.16 | AC8: 890.41 | AD8: 850.79 | AE8: 919.21 | AF8: 847.7 | AG8: 847.7 | AH8: 847.7 | AI8: 847.7 | AK8: 847.7 | AL8: 847.7 | AM8: 847.7 | AN8: 847.7
A9: JPY100KRW_end | C9: 원/100Y(기말) | E9: 1032.62 | F9: 1032.62 | G9: 996.83 | H9: 954.9 | I9: 993.29 | J9: 955.54 | K9: 955.54 | L9: 980.62 | M9: 913.67 | N9: 901.47 | O9: 917.04 | P9: 917.04 | Q9: 892.42 | R9: 857.76 | S9: 919.21 | T9: 939.65 | U9: 939.65 | V9: 986.84 | W9: 938.85 | X9: 948.49 | Y9: 921.81 | Z9: 921.81 | AA9: 955.99 | AB9: 954.75 | AC9: 863.31 | AD9: 847.7 | AE9: 847.7 | AF9: 847.7 | AG9: 847.7 | AH9: 847.7 | AI9: 847.7 | AK9: 847.7 | AL9: 847.7 | AM9: 847.7 | AN9: 847.7
A10: EURKRW_avg | C10: W/Euro(평균) | E10: 1353.32 | F10: 1354.06 | G10: 1352.29 | H10: 1343.31 | I10: 1350.63 | J10: 1386.07 | K10: 1358.07 | L10: 1369.93 | M10: 1432.41 | N10: 1429.41 | O10: 1420.91 | P10: 1412.88 | Q10: 1444.21 | R10: 1476.42 | S10: 1489.3 | T10: 1490.78 | U10: 1475.4 | V10: 1528.33 | W10: 1585.13 | X10: 1620.04 | Y10: 1686.02 | Z10: 1605.45 | AA10: 1715.47 | AB10: 1746.09 | AC10: 1631.97 | AD10: 1509.74 | AE10: 1689.95 | AF10: 1503.27 | AG10: 1503.27 | AH10: 1503.27 | AI10: 1503.27 | AK10: 1503.27 | AL10: 1503.27 | AM10: 1503.27 | AN10: 1503.27
A11: EURKRW_end | C11: W/Euro(기말) | E11: 1346.38 | F11: 1346.38 | G11: 1347.37 | H11: 1351.6 | I11: 1400.62 | J11: 1344.08 | K11: 1344.08 | L11: 1420.26 | M11: 1435.88 | N11: 1425.26 | O11: 1433.66 | P11: 1433.66 | Q11: 1458.68 | R11: 1474.86 | S11: 1469.1 | T11: 1532.14 | U11: 1532.14 | V11: 1594.72 | W11: 1588.22 | X11: 1648.04 | Y11: 1696.94 | Z11: 1696.94 | AA11: 1753.21 | AB11: 1767.09 | AC11: 1539.06 | AD11: 1503.27 | AE11: 1503.27 | AF11: 1503.27 | AG11: 1503.27 | AH11: 1503.27 | AI11: 1503.27 | AK11: 1503.27 | AL11: 1503.27 | AM11: 1503.27 | AN11: 1503.27
A12: CNYKRW_avg | C12: 원/중국원(평균) | E12: 185.14 | F12: 177.65 | G12: 189.93 | H12: 190.76 | I12: 195.79 | J12: 191.09 | K12: 191.93 | L12: 186.59 | M12: 187.45 | N12: 181.28 | O12: 182.86 | P12: 184.52 | Q12: 185.04 | R12: 189.35 | S12: 189.24 | T12: 194.24 | U12: 189.49 | V12: 199.63 | W12: 193.41 | X12: 193.79 | Y12: 204.38 | Z12: 197.8 | AA12: 211.75 | AB12: 220.8 | AC12: 210.43 | AD12: 200.69 | AE12: 213.75 | AF12: 200.46 | AG12: 200.46 | AH12: 200.46 | AI12: 200.46 | AK12: 200.46 | AL12: 200.46 | AM12: 200.46 | AN12: 200.46
A13: CNYKRW_end | C13: 원/중국원(기말) | E13: 187.13 | F13: 187.13 | G13: 191.38 | H13: 194.13 | I13: 201.92 | J13: 182.67 | K13: 182.67 | L13: 189.97 | M13: 181.8 | N13: 184.26 | O13: 182.61 | P13: 182.61 | Q13: 186.66 | R13: 189.7 | S13: 187.12 | T13: 202.04 | U13: 202.04 | V13: 203.3 | W13: 189.14 | X13: 197.16 | Y13: 206.28 | Z13: 206.28 | AA13: 220.97 | AB13: 228.56 | AC13: 202.16 | AD13: 200.46 | AE13: 200.46 | AF13: 200.46 | AG13: 200.46 | AH13: 200.46 | AI13: 200.46 | AK13: 200.46 | AL13: 200.46 | AM13: 200.46 | AN13: 200.46
B14: 1b. 종가
A15: price_close_end | C15: 종가(기말) | E15: 10450 | G15: 10500 | H15: 9150 | I15: 8810 | J15: 8700 | L15: 9470 | M15: 10070 | N15: 9870 | O15: 10050 | Q15: 8920 | R15: 9480 | S15: 8000 | T15: 8620 | V15: 7990 | W15: 8440 | X15: 13070 | Y15: 11670 | AA15: 10780 | AB15: 9010 | AC15: 8930 | AD15: 8950
A16: price_high | C16: 종가(최고) | E16: 12500 | G16: 11000 | H16: 12000 | I16: 12400 | J16: 11300 | L16: 9810 | M16: 10500 | N16: 11480 | O16: 10990 | Q16: 10250 | R16: 11140 | S16: 9560 | T16: 8690 | V16: 10500 | W16: 9960 | X16: 17300 | Y16: 17610 | AA16: 13200 | AB16: 12630 | AC16: 11270 | AD16: 9990
A17: price_low | C17: 종가(최저) | E17: 9030 | G17: 9010 | H17: 8100 | I17: 8310 | J17: 8540 | L17: 8310 | M17: 9000 | N17: 9600 | O17: 9440 | Q17: 8850 | R17: 8450 | S17: 7640 | T17: 6100 | V17: 7900 | W17: 7420 | X17: 8020 | Y17: 11630 | AA17: 8750 | AB17: 8350 | AC17: 6950 | AD17: 8540
A18: price_avg | C18: 종가(평균) | E18: 10581.7 | G18: 9897.8 | H18: 10746.3 | I18: 9623.8 | J18: 9205.8 | L18: 9173.1 | M18: 9553.9 | N18: 10441.6 | O18: 9909.7 | Q18: 9451.5 | R18: 9359.7 | S18: 8521.1 | T18: 7566.9 | V18: 9200.7 | W18: 8436.2 | X18: 11064.2 | Y18: 13384.6 | AA18: 11161.2 | AB18: 10448.8 | AC18: 8774.7 | AD18: 8928
B20: 2. 추정 드라이버 | C20: 실적 열 = subQ 실현값(수식), 추정 열 = 가정(노란 = 모델값 역산, 연녹 = 3절 스칼라 참조)
A21: drv:매출액 | B21: yoy | C21: 매출액 YoY | J21: =IFERROR(subQ!J5/subQ!E5-1,"") | L21: =IFERROR(subQ!L5/subQ!G5-1,"") | M21: =IFERROR(subQ!M5/subQ!H5-1,"") | N21: =IFERROR(subQ!N5/subQ!I5-1,"") | O21: =IFERROR(subQ!O5/subQ!J5-1,"") | Q21: =IFERROR(subQ!Q5/subQ!L5-1,"") | R21: =IFERROR(subQ!R5/subQ!M5-1,"") | S21: =IFERROR(subQ!S5/subQ!N5-1,"") | T21: =IFERROR(subQ!T5/subQ!O5-1,"") | V21: =IFERROR(subQ!V5/subQ!Q5-1,"") | W21: =IFERROR(subQ!W5/subQ!R5-1,"") | X21: =IFERROR(subQ!X5/subQ!S5-1,"") | Y21: =IFERROR(subQ!Y5/subQ!T5-1,"") | AA21: =IFERROR(subQ!AA5/subQ!V5-1,"") | AB21: =IFERROR(subQ!AB5/subQ!W5-1,"") | AC21: 0.30229965 | AD21: 0.30229292 | AF21: 0.302299 | AG21: 0.30229008 | AH21: 0.15115091 | AI21: 0.15115551 | AK21: 0.15114768 | AL21: 0.1511458 | AM21: 0.075568222 | AN21: 0.075569217
A22: drv:판관비 | B22: ratio | C22: 판관비율(/매출) | E22: =IFERROR(subQ!E8/subQ!E5,"") | F22: =IFERROR(subQ!F8/subQ!F5,"") | G22: =IFERROR(subQ!G8/subQ!G5,"") | H22: =IFERROR(subQ!H8/subQ!H5,"") | I22: =IFERROR(subQ!I8/subQ!I5,"") | J22: =IFERROR(subQ!J8/subQ!J5,"") | K22: =IFERROR(subQ!K8/subQ!K5,"") | L22: =IFERROR(subQ!L8/subQ!L5,"") | ... AB22: =IFERROR(subQ!AB8/subQ!AB5,"") | AC22: =$D$50 | AD22: =$D$50 | AE22: =IFERROR(subQ!AE8/subQ!AE5,"") | AF22: =$D$50 | AG22: =$D$50 | AH22: =$D$50 | AI22: =$D$50 | AJ22: =IFERROR(subQ!AJ8/subQ!AJ5,"") | AK22: =$D$50 | AL22: =$D$50 | AM22: =$D$50 | AN22: =$D$50 | AO22: =IFERROR(subQ!AO8/subQ!AO5,"")
A23: drv:영업이익 | B23: ratio | C23: 영업이익률(OPM) | E23: =IFERROR(subQ!E9/subQ!E5,"") | F23: =IFERROR(subQ!F9/subQ!F5,"") | G23: =IFERROR(subQ!G9/subQ!G5,"") | H23: =IFERROR(subQ!H9/subQ!H5,"") | I23: =IFERROR(subQ!I9/subQ!I5,"") | J23: =IFERROR(subQ!J9/subQ!J5,"") | K23: =IFERROR(subQ!K9/subQ!K5,"") | L23: =IFERROR(subQ!L9/subQ!L5,"") | ... AB23: =IFERROR(subQ!AB9/subQ!AB5,"") | AC23: -0.014063676 | AD23: -0.014060249 | AE23: =IFERROR(subQ!AE9/subQ!AE5,"") | AF23: -0.014051297 | AG23: -0.01406687 | AH23: -0.014062464 | AI23: -0.014063818 | AJ23: =IFERROR(subQ!AJ9/subQ!AJ5,"") | AK23: -0.01406655 | AL23: -0.014069186 | AM23: -0.014051777 | AN23: -0.014062065 | AO23: =IFERROR(subQ!AO9/subQ!AO5,"")
A24: drv:기타영업외손익 | B24: abs | C24: 기타영업외손익 (가정, 억원) | E24: =subQ!E13 | F24: =subQ!F13 | G24: =subQ!G13 | H24: =subQ!H13 | I24: =subQ!I13 | J24: =subQ!J13 | K24: =subQ!K13 | L24: =subQ!L13 | ... AB24: =subQ!AB13 | AC24: 0 | AD24: 0 | AE24: =subQ!AE13 | AF24: 0 | AG24: 0 | AH24: 0 | AI24: 0 | AJ24: =subQ!AJ13 | AK24: 0 | AL24: 0 | AM24: 0 | AN24: 0 | AO24: =subQ!AO13
A25: drv:지분법손익 | B25: abs | C25: 지분법손익 (가정, 억원) | E25: =subQ!E14 | F25: =subQ!F14 | G25: =subQ!G14 | H25: =subQ!H14 | I25: =subQ!I14 | J25: =subQ!J14 | K25: =subQ!K14 | L25: =subQ!L14 | ... AB25: =subQ!AB14 | AC25: 0 | AD25: 0 | AE25: =subQ!AE14 | AF25: 0 | AG25: 0 | AH25: 0 | AI25: 0 | AJ25: =subQ!AJ14 | AK25: 0 | AL25: 0 | AM25: 0 | AN25: 0 | AO25: =subQ!AO14
A26: drv:법인세비용 | B26: tax | C26: 법인세율(/세전) — 법인세 = MAX(세전,0) × 세율 | E26: =IFERROR(subQ!E16/subQ!E15,"") | F26: =IFERROR(subQ!F16/subQ!F15,"") | G26: =IFERROR(subQ!G16/subQ!G15,"") | H26: =IFERROR(subQ!H16/subQ!H15,"") | I26: =IFERROR(subQ!I16/subQ!I15,"") | J26: =IFERROR(subQ!J16/subQ!J15,"") | K26: =IFERROR(subQ!K16/subQ!K15,"") | L26: =IFERROR(subQ!L16/subQ!L15,"") | ... AB26: =IFERROR(subQ!AB16/subQ!AB15,"") | AC26: =$D$49 | AD26: =$D$49 | AE26: =IFERROR(subQ!AE16/subQ!AE15,"") | AF26: =$D$49 | AG26: =$D$49 | AH26: =$D$49 | AI26: =$D$49 | AJ26: =IFERROR(subQ!AJ16/subQ!AJ15,"") | AK26: =$D$49 | AL26: =$D$49 | AM26: =$D$49 | AN26: =$D$49 | AO26: =IFERROR(subQ!AO16/subQ!AO15,"")
A27: drv:지배주주순이익 | B27: ratio | C27: 지배주주 비중(/당기순이익) | E27: =IFERROR(subQ!E18/subQ!E17,"") | F27: =IFERROR(subQ!F18/subQ!F17,"") | G27: =IFERROR(subQ!G18/subQ!G17,"") | H27: =IFERROR(subQ!H18/subQ!H17,"") | I27: =IFERROR(subQ!I18/subQ!I17,"") | J27: =IFERROR(subQ!J18/subQ!J17,"") | K27: =IFERROR(subQ!K18/subQ!K17,"") | L27: =IFERROR(subQ!L18/subQ!L17,"") | ... AB27: =IFERROR(subQ!AB18/subQ!AB17,"") | AC27: =$D$51 | AD27: =$D$51 | AE27: =IFERROR(subQ!AE18/subQ!AE17,"") | AF27: =$D$51 | AG27: =$D$51 | AH27: =$D$51 | AI27: =$D$51 | AJ27: =IFERROR(subQ!AJ18/subQ!AJ17,"") | AK27: =$D$51 | AL27: =$D$51 | AM27: =$D$51 | AN27: =$D$51 | AO27: =IFERROR(subQ!AO18/subQ!AO17,"")
A28: drv:중단사업이익 | B28: abs | C28: 중단사업이익 (가정, 억원) | E28: =subQ!E19 | F28: =subQ!F19 | G28: =subQ!G19 | H28: =subQ!H19 | I28: =subQ!I19 | J28: =subQ!J19 | K28: =subQ!K19 | L28: =subQ!L19 | ... AB28: =subQ!AB19 | AE28: =subQ!AE19 | AJ28: =subQ!AJ19 | AO28: =subQ!AO19
A29: drv:부채총계 | B29: qoq | C29: 부채총계 QoQ | G29: =IFERROR(subQ!G21/subQ!E21-1,"") | H29: =IFERROR(subQ!H21/subQ!G21-1,"") | I29: =IFERROR(subQ!I21/subQ!H21-1,"") | J29: =IFERROR(subQ!J21/subQ!I21-1,"") | L29: =IFERROR(subQ!L21/subQ!J21-1,"") | M29: =IFERROR(subQ!M21/subQ!L21-1,"") | N29: =IFERROR(subQ!N21/subQ!M21-1,"") | O29: =IFERROR(subQ!O21/subQ!N21-1,"") | Q29: =IFERROR(subQ!Q21/subQ!O21-1,"") | R29: =IFERROR(subQ!R21/subQ!Q21-1,"") | S29: =IFERROR(subQ!S21/subQ!R21-1,"") | T29: =IFERROR(subQ!T21/subQ!S21-1,"") | V29: =IFERROR(subQ!V21/subQ!T21-1,"") | W29: =IFERROR(subQ!W21/subQ!V21-1,"") | X29: =IFERROR(subQ!X21/subQ!W21-1,"") | Y29: =IFERROR(subQ!Y21/subQ!X21-1,"") | AA29: =IFERROR(subQ!AA21/subQ!Y21-1,"") | AB29: =IFERROR(subQ!AB21/subQ!AA21-1,"") | AC29: -5.849e-06 | AD29: 0 | AF29: 0 | AG29: 0 | AH29: 0 | AI29: 0 | AK29: 0 | AL29: 0 | AM29: 0 | AN29: 0
A30: drv:자본총계 | B30: roll | C30: 자본총계 기타변동(배당 등, 억원) | G30: =IFERROR(subQ!E22+subQ!G17-subQ!G22,"") | H30: =IFERROR(subQ!G22+subQ!H17-subQ!H22,"") | I30: =IFERROR(subQ!H22+subQ!I17-subQ!I22,"") | J30: =IFERROR(subQ!I22+subQ!J17-subQ!J22,"") | L30: =IFERROR(subQ!J22+subQ!L17-subQ!L22,"") | M30: =IFERROR(subQ!L22+subQ!M17-subQ!M22,"") | N30: =IFERROR(subQ!M22+subQ!N17-subQ!N22,"") | O30: =IFERROR(subQ!N22+subQ!O17-subQ!O22,"") | Q30: =IFERROR(subQ!O22+subQ!Q17-subQ!Q22,"") | R30: =IFERROR(subQ!Q22+subQ!R17-subQ!R22,"") | S30: =IFERROR(subQ!R22+subQ!S17-subQ!S22,"") | T30: =IFERROR(subQ!S22+subQ!T17-subQ!T22,"") | V30: =IFERROR(subQ!T22+subQ!V17-subQ!V22,"") | W30: =IFERROR(subQ!V22+subQ!W17-subQ!W22,"") | X30: =IFERROR(subQ!W22+subQ!X17-subQ!X22,"") | Y30: =IFERROR(subQ!X22+subQ!Y17-subQ!Y22,"") | AA30: =IFERROR(subQ!Y22+subQ!AA17-subQ!AA22,"") | AB30: =IFERROR(subQ!AA22+subQ!AB17-subQ!AB22,"") | AC30: 0.008637673 | AD30: -0.004379011 | AF30: 0.000791705 | AG30: 6.9424195 | AH30: 0.003009043 | AI30: -0.008588473 | AK30: -0.003047909 | AL30: 6.9397254 | AM30: 0.011795324 | AN30: -0.004061584
A31: drv:지배주주지분 | B31: roll | C31: 지배주주지분 기타변동(배당 등, 억원) | G31: =IFERROR(subQ!E23+subQ!G18-subQ!G23,"") | H31: =IFERROR(subQ!G23+subQ!H18-subQ!H23,"") | I31: =IFERROR(subQ!H23+subQ!I18-subQ!I23,"") | J31: =IFERROR(subQ!I23+subQ!J18-subQ!J23,"") | L31: =IFERROR(subQ!J23+subQ!L18-subQ!L23,"") | M31: =IFERROR(subQ!L23+subQ!M18-subQ!M23,"") | N31: =IFERROR(subQ!M23+subQ!N18-subQ!N23,"") | O31: =IFERROR(subQ!N23+subQ!O18-subQ!O23,"") | Q31: =IFERROR(subQ!O23+subQ!Q18-subQ!Q23,"") | R31: =IFERROR(subQ!Q23+subQ!R18-subQ!R23,"") | S31: =IFERROR(subQ!R23+subQ!S18-subQ!S23,"") | T31: =IFERROR(subQ!S23+subQ!T18-subQ!T23,"") | V31: =IFERROR(subQ!T23+subQ!V18-subQ!V23,"") | W31: =IFERROR(subQ!V23+subQ!W18-subQ!W23,"") | X31: =IFERROR(subQ!W23+subQ!X18-subQ!X23,"") | Y31: =IFERROR(subQ!X23+subQ!Y18-subQ!Y23,"") | AA31: =IFERROR(subQ!Y23+subQ!AA18-subQ!AA23,"") | AB31: =IFERROR(subQ!AA23+subQ!AB18-subQ!AB23,"") | AC31: 0.003137673 | AD31: 0.005620989 | AF31: 0.000791705 | AG31: 6.9424195 | AH31: -0.006990957 | AI31: 0.001411527 | AK31: -0.003047909 | AL31: 6.9397254 | AM31: 0.001795324 | AN31: 0.005938416
A32: drv:총차입금 | B32: qoq | C32: 총차입금 QoQ | G32: =IFERROR(subQ!G24/subQ!E24-1,"") | H32: =IFERROR(subQ!H24/subQ!G24-1,"") | I32: =IFERROR(subQ!I24/subQ!H24-1,"") | J32: =IFERROR(subQ!J24/subQ!I24-1,"") | L32: =IFERROR(subQ!L24/subQ!J24-1,"") | M32: =IFERROR(subQ!M24/subQ!L24-1,"") | N32: =IFERROR(subQ!N24/subQ!M24-1,"") | O32: =IFERROR(subQ!O24/subQ!N24-1,"") | Q32: =IFERROR(subQ!Q24/subQ!O24-1,"") | R32: =IFERROR(subQ!R24/subQ!Q24-1,"") | S32: =IFERROR(subQ!S24/subQ!R24-1,"") | T32: =IFERROR(subQ!T24/subQ!S24-1,"") | V32: =IFERROR(subQ!V24/subQ!T24-1,"") | W32: =IFERROR(subQ!W24/subQ!V24-1,"") | X32: =IFERROR(subQ!X24/subQ!W24-1,"") | Y32: =IFERROR(subQ!Y24/subQ!X24-1,"") | AA32: =IFERROR(subQ!AA24/subQ!Y24-1,"") | AB32: =IFERROR(subQ!AB24/subQ!AA24-1,"") | AC32: -7.576e-06 | AD32: 0 | AF32: 0 | AG32: 0 | AH32: 0 | AI32: 0 | AK32: 0 | AL32: 0 | AM32: 0 | AN32: 0
A33: drv:순차입금 | B33: qoq | C33: 순차입금 QoQ | G33: =IFERROR(subQ!G25/subQ!E25-1,"") | H33: =IFERROR(subQ!H25/subQ!G25-1,"") | I33: =IFERROR(subQ!I25/subQ!H25-1,"") | J33: =IFERROR(subQ!J25/subQ!I25-1,"") | L33: =IFERROR(subQ!L25/subQ!J25-1,"") | M33: =IFERROR(subQ!M25/subQ!L25-1,"") | N33: =IFERROR(subQ!N25/subQ!M25-1,"") | O33: =IFERROR(subQ!O25/subQ!N25-1,"") | Q33: =IFERROR(subQ!Q25/subQ!O25-1,"") | R33: =IFERROR(subQ!R25/subQ!Q25-1,"") | S33: =IFERROR(subQ!S25/subQ!R25-1,"") | T33: =IFERROR(subQ!T25/subQ!S25-1,"") | V33: =IFERROR(subQ!V25/subQ!T25-1,"") | W33: =IFERROR(subQ!W25/subQ!V25-1,"") | X33: =IFERROR(subQ!X25/subQ!W25-1,"") | Y33: =IFERROR(subQ!Y25/subQ!X25-1,"") | AA33: =IFERROR(subQ!AA25/subQ!Y25-1,"") | AB33: =IFERROR(subQ!AB25/subQ!AA25-1,"") | AC33: 0.001045741 | AD33: -0.005144738 | AF33: 3.358e-05 | AG33: -0.013095818 | AH33: -0.000357258 | AI33: -0.007709326 | AK33: -0.001629307 | AL33: -0.01534048 | AM33: -0.001343359 | AN33: -0.009468572
A34: drv:이자발생자산 | B34: qoq | C34: 이자발생자산 QoQ | G34: =IFERROR(subQ!G26/subQ!E26-1,"") | H34: =IFERROR(subQ!H26/subQ!G26-1,"") | I34: =IFERROR(subQ!I26/subQ!H26-1,"") | J34: =IFERROR(subQ!J26/subQ!I26-1,"") | L34: =IFERROR(subQ!L26/subQ!J26-1,"") | M34: =IFERROR(subQ!M26/subQ!L26-1,"") | N34: =IFERROR(subQ!N26/subQ!M26-1,"") | O34: =IFERROR(subQ!O26/subQ!N26-1,"") | Q34: =IFERROR(subQ!Q26/subQ!O26-1,"") | R34: =IFERROR(subQ!R26/subQ!Q26-1,"") | S34: =IFERROR(subQ!S26/subQ!R26-1,"") | T34: =IFERROR(subQ!T26/subQ!S26-1,"") | V34: =IFERROR(subQ!V26/subQ!T26-1,"") | W34: =IFERROR(subQ!W26/subQ!V26-1,"") | X34: =IFERROR(subQ!X26/subQ!W26-1,"") | Y34: =IFERROR(subQ!Y26/subQ!X26-1,"") | AA34: =IFERROR(subQ!AA26/subQ!Y26-1,"") | AB34: =IFERROR(subQ!AB26/subQ!AA26-1,"") | AC34: 0.000806296 | AD34: -0.00397404 | AF34: 3.8863e-05 | AG34: -0.010116842 | AH34: -0.000274808 | AI34: -0.00592963 | AK34: -0.001250938 | AL34: -0.011773547 | AM34: -0.001027283 | AN34: -0.007238441
A35: drv:현금및현금성자산 | B35: qoq | C35: 현금및현금성자산 QoQ | G35: =IFERROR(subQ!G27/subQ!E27-1,"") | H35: =IFERROR(subQ!H27/subQ!G27-1,"") | I35: =IFERROR(subQ!I27/subQ!H27-1,"") | J35: =IFERROR(subQ!J27/subQ!I27-1,"") | L35: =IFERROR(subQ!L27/subQ!J27-1,"") | M35: =IFERROR(subQ!M27/subQ!L27-1,"") | N35: =IFERROR(subQ!N27/subQ!M27-1,"") | O35: =IFERROR(subQ!O27/subQ!N27-1,"") | Q35: =IFERROR(subQ!Q27/subQ!O27-1,"") | R35: =IFERROR(subQ!R27/subQ!Q27-1,"") | S35: =IFERROR(subQ!S27/subQ!R27-1,"") | T35: =IFERROR(subQ!T27/subQ!S27-1,"") | V35: =IFERROR(subQ!V27/subQ!T27-1,"") | W35: =IFERROR(subQ!W27/subQ!V27-1,"") | X35: =IFERROR(subQ!X27/subQ!W27-1,"") | Y35: =IFERROR(subQ!Y27/subQ!X27-1,"") | AA35: =IFERROR(subQ!AA27/subQ!Y27-1,"") | AB35: =IFERROR(subQ!AB27/subQ!AA27-1,"")
A36: drv:CAPEX | B36: yoy | C36: CAPEX YoY | J36: =IFERROR(subQ!J28/subQ!E28-1,"") | L36: =IFERROR(subQ!L28/subQ!G28-1,"") | M36: =IFERROR(subQ!M28/subQ!H28-1,"") | N36: =IFERROR(subQ!N28/subQ!I28-1,"") | O36: =IFERROR(subQ!O28/subQ!J28-1,"") | Q36: =IFERROR(subQ!Q28/subQ!L28-1,"") | R36: =IFERROR(subQ!R28/subQ!M28-1,"") | S36: =IFERROR(subQ!S28/subQ!N28-1,"") | T36: =IFERROR(subQ!T28/subQ!O28-1,"") | V36: =IFERROR(subQ!V28/subQ!Q28-1,"") | W36: =IFERROR(subQ!W28/subQ!R28-1,"") | X36: =IFERROR(subQ!X28/subQ!S28-1,"") | Y36: =IFERROR(subQ!Y28/subQ!T28-1,"") | AA36: =IFERROR(subQ!AA28/subQ!V28-1,"") | AB36: =IFERROR(subQ!AB28/subQ!W28-1,"") | AC36: -0.39704984 | AD36: -0.44136601 | AF36: 1.9294432 | AG36: 2.4668816 | AH36: 0 | AI36: 0 | AK36: 0 | AL36: 0 | AM36: 0 | AN36: 0
A37: drv:영업활동현금흐름 | B37: yoy | C37: 영업활동현금흐름 YoY | J37: =IFERROR(subQ!J29/subQ!E29-1,"") | L37: =IFERROR(subQ!L29/subQ!G29-1,"") | M37: =IFERROR(subQ!M29/subQ!H29-1,"") | N37: =IFERROR(subQ!N29/subQ!I29-1,"") | O37: =IFERROR(subQ!O29/subQ!J29-1,"") | Q37: =IFERROR(subQ!Q29/subQ!L29-1,"") | R37: =IFERROR(subQ!R29/subQ!M29-1,"") | S37: =IFERROR(subQ!S29/subQ!N29-1,"") | T37: =IFERROR(subQ!T29/subQ!O29-1,"") | V37: =IFERROR(subQ!V29/subQ!Q29-1,"") | W37: =IFERROR(subQ!W29/subQ!R29-1,"") | X37: =IFERROR(subQ!X29/subQ!S29-1,"") | Y37: =IFERROR(subQ!Y29/subQ!T29-1,"") | AA37: =IFERROR(subQ!AA29/subQ!V29-1,"") | AB37: =IFERROR(subQ!AB29/subQ!W29-1,"")
A38: drv:주식수 | B38: qoq | C38: 주식수 QoQ | G38: =IFERROR(subQ!G30/subQ!E30-1,"") | H38: =IFERROR(subQ!H30/subQ!G30-1,"") | I38: =IFERROR(subQ!I30/subQ!H30-1,"") | J38: =IFERROR(subQ!J30/subQ!I30-1,"") | L38: =IFERROR(subQ!L30/subQ!J30-1,"") | M38: =IFERROR(subQ!M30/subQ!L30-1,"") | N38: =IFERROR(subQ!N30/subQ!M30-1,"") | O38: =IFERROR(subQ!O30/subQ!N30-1,"") | Q38: =IFERROR(subQ!Q30/subQ!O30-1,"") | R38: =IFERROR(subQ!R30/subQ!Q30-1,"") | S38: =IFERROR(subQ!S30/subQ!R30-1,"") | T38: =IFERROR(subQ!T30/subQ!S30-1,"") | V38: =IFERROR(subQ!V30/subQ!T30-1,"") | W38: =IFERROR(subQ!W30/subQ!V30-1,"") | X38: =IFERROR(subQ!X30/subQ!W30-1,"") | Y38: =IFERROR(subQ!Y30/subQ!X30-1,"") | AA38: =IFERROR(subQ!AA30/subQ!Y30-1,"") | AB38: =IFERROR(subQ!AB30/subQ!AA30-1,"") | AC38: 0 | AD38: 0 | AF38: 0 | AG38: 0 | AH38: 0 | AI38: 0 | AK38: 0 | AL38: 0 | AM38: 0 | AN38: 0
A39: drv:DPS | B39: abs | C39: DPS (가정, 원) | E39: =subQ!E33 | F39: =subQ!F33 | G39: =subQ!G33 | H39: =subQ!H33 | I39: =subQ!I33 | J39: =subQ!J33 | K39: =subQ!K33 | L39: =subQ!L33 | ... AB39: =subQ!AB33 | AD39: 100 | AE39: =subQ!AE33 | AI39: 100 | AJ39: =subQ!AJ33 | AN39: 100 | AO39: =subQ!AO33
B41: 3. 밸류에이션·스칼라 | C41: 노란 셀 = 가정. '연결' 표시는 추정 전 분기 수식이 이 셀을 참조한다는 뜻
A42: sc:종가 | C42: 종가 | D42: 8950 | E42: 원 — 네이버 정규장 종가(aik 확정종가 대조 · aik 8,810원)
...

Sheet BS연결
B1: (백만원) | C1: 이름: BS연결H | E1: 4Q21 | F1: 2021 | G1: 1Q22 | H1: 2Q22 | I1: 3Q22 | J1: 4Q22 | K1: 2022 | L1: 1Q23 | M1: 2Q23 | N1: 3Q23 | O1: 4Q23 | P1: 2023 | Q1: 1Q24 | R1: 2Q24 | S1: 3Q24 | T1: 4Q24 | U1: 2024 | V1: 1Q25 | W1: 2Q25 | X1: 3Q25 | Y1: 4Q25 | Z1: 2025 | AA1: 1Q26 | AB1: 2Q26 | AC1: 3Q26 | AD1: 4Q26 | AE1: 2026 | AF1: 1Q27 | AG1: 2Q27 | AH1: 3Q27 | AI1: 4Q27 | AJ1: 2027 | AK1: 1Q28 | AL1: 2Q28 | AM1: 3Q28 | AN1: 4Q28 | AO1: 2028
B2: 연결 | D2: fin json(kship_fin.py)
B3: 엔케이(연) | C3: UPDATE: 26-10-11 | E3: 1 | F3: 2 | G3: 3 | H3: 4 | I3: 5 | J3: 6 | K3: 7 | L3: 8 | M3: 9 | N3: 10 | O3: 11 | P3: 12 | Q3: 13 | R3: 14 | S3: 15 | T3: 16 | U3: 17 | V3: 18 | W3: 19 | X3: 20 | Y3: 21 | Z3: 22 | AA3: 23 | AB3: 24 | AC3: 25 | AD3: 26 | AE3: 27 | AF3: 28 | AG3: 29 | AH3: 30 | AI3: 31 | AJ3: 32 | AK3: 33 | AL3: 34 | AM3: 35 | AN3: 36 | AO3: 37
B4: Account Code | C4: AccountNAME | E4: 2021.12 | F4: 2021.12A | G4: 2022.03 | H4: 2022.06 | I4: 2022.09 | J4: 2022.12 | K4: 2022.12A | L4: 2023.03 | M4: 2023.06 | N4: 2023.09 | O4: 2023.12 | P4: 2023.12A | Q4: 2024.03 | R4: 2024.06 | S4: 2024.09 | T4: 2024.12 | U4: 2024.12A | V4: 2025.03 | W4: 2025.06 | X4: 2025.09 | Y4: 2025.12 | Z4: 2025.12A | AA4: 2026.03 | AB4: 2026.06 | AC4: 2026.09 | AD4: 2026.12 | AE4: 2026.12A | AF4: 2027.03 | AG4: 2027.06 | AH4: 2027.09 | AI4: 2027.12 | AJ4: 2027.12A | AK4: 2028.03 | AL4: 2028.06 | AM4: 2028.09 | AN4: 2028.12 | AO4: 2028.12A
A5: 1 | C5: 유동자산 | E5: 71679.87 | F5: 71679.87 | G5: 64304.02 | H5: 62744.95 | I5: 69036.31 | J5: 85643.41 | K5: 85643.41 | L5: 84154.74 | M5: 78641.35 | N5: 75977.76 | O5: 169799.53 | P5: 169799.53 | Q5: 173152.02 | R5: 170030.54 | S5: 162508 | T5: 166228.28 | U5: 166228.28 | V5: 157874.01 | W5: 135473.65 | X5: 131010.66 | Y5: 125704.72 | Z5: 125704.72 | AA5: 128279.78 | AB5: 126600.56
A6: 1 | C6: 현금및현금성자산 | E6: 51477.69 | F6: 51477.69 | G6: 30806.24 | H6: 30022.25 | I6: 21710.66 | J6: 29701.15 | K6: 29701.15 | L6: 28795.96 | M6: 27058.65 | N6: 27348.1 | O6: 24768.6 | P6: 24768.6 | Q6: 24771.32 | R6: 22065.86 | S6: 24250.94 | T6: 28765.02 | U6: 28765.02 | V6: 32241.33 | W6: 29451.54 | X6: 50369.61 | Y6: 48368.97 | Z6: 48368.97 | AA6: 54587.23 | AB6: 76964.59
A7: 1 | C7: 기타유동금융자산 | E7: 7887.37 | F7: 7887.37 | G7: 22709.38 | H7: 19709.38 | I7: 27659.39 | J7: 24847.25 | K7: 24847.25 | L7: 26241.16 | M7: 23277.21 | N7: 21392.85 | O7: 109172.01 | P7: 109172.01 | Q7: 108401.61 | R7: 108571.21 | S7: 103292.81 | T7: 98895.44 | U7: 98895.44 | V7: 79748.63 | W7: 60867.28 | X7: 20016.61 | Y7: 20000 | Z7: 20000 | AA7: 20000 | AB7: 0
A8: 1 | C8: 매출채권및기타채권 | E8: 10328.7 | F8: 10328.7 | G8: 8803.49 | H8: 11297.35 | I8: 16530.03 | J8: 20794.39 | K8: 20794.39 | L8: 19788.58 | M8: 18081.67 | N8: 13807.79 | O8: 17989.6 | P8: 17989.6 | Q8: 22131.19 | R8: 21567.47 | S8: 15528.65 | T8: 18230 | U8: 18230 | V8: 14915.44 | W8: 23182.68 | X8: 29530.14 | Y8: 28443.13 | Z8: 28443.13 | AA8: 22942.14 | AB8: 20643.78
A9: 1 | C9: 기타유동자산 | E9: 116.57 | F9: 116.57 | G9: 395.35 | H9: 261.86 | I9: 1240.54 | J9: 767.94 | K9: 767.94 | L9: 612.6 | M9: 1183.96 | N9: 2764.26 | O9: 3131.23 | P9: 3131.23 | Q9: 3652.91 | R9: 5233.87 | S9: 4679.88 | T9: 4581.33 | U9: 4581.33 | V9: 12618.49 | W9: 3791.02 | X9: 5209.86 | Y9: 8197.3 | Z9: 8197.3 | AA9: 10108.48 | AB9: 9363.95
A10: 1 | C10: 당기법인세자산(선급법인세) | E10: 36.46 | F10: 36.46 | G10: 55.6 | H10: 46.89 | I10: 85.12 | J10: 173.41 | K10: 173.41 | L10: 294.83 | M10: 219.81 | N10: 261.02 | O10: 46.79 | P10: 46.79 | Q10: 145.67 | R10: 153.65 | S10: 450.95 | T10: 488.86 | U10: 488.86 | V10: 789.21 | W10: 342.01 | X10: 527.11 | Y10: 554.94 | Z10: 554.94 | AA10: 619.99 | AB10: 18.01
A11: 1 | C11: 재고자산 | E11: 1833.08 | F11: 1833.08 | G11: 1533.96 | H11: 1407.23 | I11: 1810.57 | J11: 9359.28 | K11: 9359.28 | L11: 8421.62 | M11: 8820.05 | N11: 10403.75 | O11: 14691.29 | P11: 14691.29 | Q11: 14049.33 | R11: 12438.48 | S11: 14304.76 | T11: 13409.86 | U11: 13409.86 | V11: 15647.15 | W11: 16705.87 | X11: 23820.46 | Y11: 16999.58 | Z11: 16999.58 | AA11: 15686.4 | AB11: 14867.22
A12: 1 | C12: 유동파생상품자산 | E12: 0 | F12: 0 | G12: 0 | H12: 0 | I12: 0 | J12: 0 | K12: 0 | L12: 0 | M12: 0 | N12: 0 | O12: 0 | P12: 0 | Q12: 0 | R12: 0 | S12: 0 | T12: 0 | U12: 0 | V12: 0
A13: 1 | C13: 단기금융자산 | E13: 0 | F13: 0 | G13: 0 | H13: 0 | I13: 0 | J13: 0 | K13: 0 | L13: 0 | M13: 0 | N13: 0 | O13: 0 | P13: 0 | Q13: 0 | R13: 0 | S13: 0 | T13: 0 | U13: 0 | V13: 0
A14: 1 | C14: 매각예정비유동자산및처분자산 | E14: 0 | F14: 0 | G14: 0 | H14: 0 | I14: 0 | J14: 0 | K14: 0 | L14: 0 | M14: 0 | N14: 0 | O14: 10407.89 | P14: 10407.89 | Q14: 10407.89 | R14: 0 | S14: 0 | T14: 0 | U14: 0 | V14: 0
A15: 1 | C15: 비유동자산 | E15: 59046.65 | F15: 59046.65 | G15: 66383.16 | H15: 68472.8 | I15: 65383.72 | J15: 100102.52 | K15: 100102.52 | L15: 99547.66 | M15: 98262.42 | N15: 103965.19 | O15: 67458.66 | P15: 67458.66 | Q15: 61542.69 | R15: 61805.43 | S15: 63903 | T15: 60915.41 | U15: 60915.41 | V15: 60094.82 | W15: 70310.39 | X15: 100310.74 | Y15: 104842.51 | Z15: 104842.51 | AA15: 100513.06 | AB15: 100605.42
A16: 1 | C16: 장기금융자산 | E16: 12220.19 | F16: 12220.19 | G16: 15231.79 | H16: 14481.42 | I16: 14481.42 | J16: 2244.84 | K16: 2244.84 | L16: 1244.84 | M16: 645.84 | N16: 645.84 | O16: 644.93 | P16: 644.93 | Q16: 644.93 | R16: 644.93 | S16: 675.66 | T16: 644.93 | U16: 644.93 | V16: 644.93 | W16: 644.93 | X16: 729.43 | Y16: 475.47 | Z16: 475.47 | AA16: 475.47 | AB16: 475.97
A17: 1 | C17: 투자자산 | E17: 27935.17 | F17: 27935.17 | G17: 32097.53 | H17: 32210.21 | I17: 33203.19 | J17: 21317.01 | K17: 21317.01 | L17: 21103.88 | M17: 20049.73 | N17: 26055.25 | O17: 1891.78 | P17: 1891.78 | Q17: 1792.64 | R17: 1789.42 | S17: 1817.34 | T17: 1791.1 | U17: 1791.1 | V17: 1813.18 | W17: 1810.68 | X17: 1892.17 | Y17: 475.47 | Z17: 475.47 | AA17: 475.47 | AB17: 475.97
A18: 1 | C18: 종속기업및관계기업투자 | E18: 15714.98 | F18: 15714.98 | G18: 16865.74 | H18: 17728.79 | I18: 18721.77 | J18: 19072.17 | K18: 19072.17 | L18: 19859.04 | M18: 19403.89 | N18: 25409.41 | O18: 1246.85 | P18: 1246.85 | Q18: 1147.71 | R18: 1144.49 | S18: 1141.68 | T18: 1146.17 | U18: 1146.17 | V18: 1168.25 | W18: 1165.75 | X18: 1162.74 | Y18: 0 | Z18: 0 | AA18: 0
A19: 1 | C19: 장기매출채권및기타채권 | E19: 0 | F19: 0 | G19: 0 | H19: 0 | I19: 0 | J19: 0 | K19: 0 | L19: 0 | M19: 0 | N19: 0 | O19: 0 | P19: 0 | Q19: 0 | R19: 0 | Y19: 0 | Z19: 0 | AA19: 0 | AB19: 0
A20: 1 | C20: 유형자산 | E20: 21213.33 | F20: 21213.33 | G20: 23828.59 | H20: 25408.94 | I20: 21295.34 | J20: 51379.8 | K20: 51379.8 | L20: 50948.62 | M20: 50815.97 | N20: 50094.22 | O20: 40053.57 | P20: 40053.57 | Q20: 41454.66 | R20: 41495.46 | S20: 40136.05 | T20: 40617.62 | U20: 40617.62 | V20: 40104.11 | W20: 40974.14 | X20: 75752.46 | Y20: 80767.64 | Z20: 80767.64 | AA20: 80985.54 | AB20: 81301.79
A21: 1 | C21: 사용권자산 | E21: 96.25 | F21: 96.25 | G21: 92.5 | H21: 88.75 | I21: 85 | J21: 13341.87 | K21: 13341.87 | L21: 13256.6 | M21: 13171.33 | N21: 13086.06 | O21: 13367.43 | P21: 13367.43 | Q21: 6282.43 | R21: 6369.11 | S21: 6581.42 | T21: 6441.65 | U21: 6441.65 | V21: 6143.97 | W21: 6086.28 | X21: 6071.84 | Y21: 7643.6 | Z21: 7643.6 | AA21: 3051.47 | AB21: 2843.52
A22: 1 | C22: 기타비유동자산 | E22: 96.25 | F22: 96.25 | G22: 92.5 | H22: 88.75 | I22: 85 | J22: 13341.87 | K22: 13341.87 | L22: 13256.6 | M22: 13171.33 | N22: 13086.06 | O22: 13367.43 | P22: 13367.43 | Q22: 6282.43 | R22: 6369.11 | S22: 6581.42 | T22: 6441.65 | U22: 6441.65 | V22: 6143.97 | W22: 14886.28 | X22: 6071.84 | Y22: 7643.6 | Z22: 7643.6 | AA22: 3051.47 | AB22: 2843.52
A23: 1 | C23: 무형자산 | E23: 47.03 | F23: 47.03 | G23: 47.03 | H23: 47.03 | I23: 47.03 | J23: 103.87 | K23: 103.87 | L23: 96.76 | M23: 109.32 | N23: 175.78 | O23: 181.53 | P23: 181.53 | Q23: 175.21 | R23: 336.35 | S23: 271.54 | T23: 282.61 | U23: 282.61 | V23: 266.31 | W23: 250.34 | X23: 255.35 | Y23: 234.76 | Z23: 234.76 | AA23: 215.04 | AB23: 209.14
A24: 1 | C24: 투자부동산 | E24: 8962.2 | F24: 8962.2 | G24: 8949.12 | H24: 8936.04 | I24: 9977.22 | J24: 11476.04 | K24: 11476.04 | L24: 11527 | M24: 11501.27 | N24: 11889.08 | O24: 11388.38 | P24: 11388.38 | Q24: 11362.21 | R24: 11336.04 | S24: 11309.87 | T24: 11283.71 | U24: 11283.71 | V24: 11257.54 | W24: 11857.84 | X24: 14917.8 | Y24: 14254.69 | Z24: 14254.69 | AA24: 14228.52 | AB24: 14202.35
A25: 1 | C25: 이연법인세자산 | E25: 0 | F25: 0 | G25: 0 | H25: 0 | I25: 0 | J25: 0 | K25: 0 | L25: 0 | M25: 0 | N25: 0 | O25: 0 | P25: 0 | Q25: 0 | R25: 0 | S25: 0 | T25: 0 | U25: 0 | V25: 0 | Y25: 21.2 | Z25: 21.2 | AA25: 21.2 | AB25: 21.2
A26: 1 | C26: 자산총계 | E26: 130726.53 | F26: 130726.53 | G26: 130687.18 | H26: 131217.75 | I26: 134420.03 | J26: 185745.93 | K26: 185745.93 | L26: 183702.4 | M26: 176903.77 | N26: 179942.96 | O26: 247666.09 | P26: 247666.09 | Q26: 245102.6 | R26: 231835.97 | S26: 226411 | T26: 227143.69 | U26: 227143.69 | V26: 217968.84 | W26: 205784.04 | X26: 231321.4 | Y26: 230547.23 | Z26: 230547.23 | AA26: 228792.84 | AB26: 227205.97
A27: 1 | C27: 유동부채 | E27: 26677.28 | F27: 26677.28 | G27: 26786.67 | H27: 25952.57 | I27: 25624.92 | J27: 40936.88 | K27: 40936.88 | L27: 36507.5 | M27: 29216.18 | N27: 24954.35 | O27: 41882.69 | P27: 41882.69 | Q27: 43653.21 | R27: 35143.14 | S27: 32794.57 | T27: 37203.71 | U27: 37203.71 | V27: 31981.87 | W27: 27685.47 | X27: 57662.57 | Y27: 55256.86 | Z27: 55256.86 | AA27: 55697.7 | AB27: 50684.51
A28: 1 | C28: 기타유동부채 | E28: 0 | F28: 0 | G28: 0 | H28: 0 | I28: 0 | J28: 0 | K28: 0 | L28: 0 | M28: 0 | N28: 0 | O28: 0 | P28: 0 | Q28: 0 | R28: 0 | S28: 0 | T28: 0 | U28: 0 | V28: 0
A29: 1 | C29: 단기차입금 | E29: 0 | F29: 0 | G29: 0 | H29: 0 | I29: 0 | J29: 8248.15 | K29: 8248.15 | L29: 7271.23 | M29: 7498.54 | N29: 2265.85 | O29: 2525.93 | P29: 2525.93 | Q29: 2634.55 | R29: 3255.08 | S29: 3034.91 | T29: 5005.95 | U29: 5005.95 | V29: 3893.72 | W29: 122.04 | X29: 7070.13 | Y29: 6380 | Z29: 6380 | AA29: 15440 | AB29: 17160.13
A30: 1 | C30: 당기법인세부채(미지급법인세) | E30: 0 | F30: 0 | G30: 0 | H30: 0 | I30: 0 | J30: 0.21 | K30: 0.21 | L30: 0 | M30: 0 | N30: 0 | O30: 4159.27 | P30: 4159.27 | Q30: 4159.27 | R30: 0 | S30: 0 | T30: 0 | U30: 0 | V30: 0 | Y30: 201.83 | Z30: 201.83 | AA30: 25.63 | AB30: 684.38
A31: 1 | C31: 유동성장기부채 | E31: 10066.44 | F31: 10066.44 | G31: 10385.18 | H31: 10721.69 | I31: 10563.45 | J31: 10903.99 | K31: 10903.99 | L31: 7073.16 | M31: 0 | N31: 0 | O31: 0 | P31: 0 | Q31: 0 | R31: 0 | S31: 0 | T31: 0 | U31: 0 | V31: 0 | X31: 8760.5 | Y31: 9345.5 | Z31: 9345.5
A32: 1 | C32: 유동리스부채 | E32: 0 | F32: 0 | G32: 0 | H32: 0 | I32: 0 | J32: 27.09 | K32: 27.09 | L32: 27.34 | M32: 29.42 | N32: 23.24 | O32: 264.46 | P32: 264.46 | Q32: 162.32 | R32: 87.31 | S32: 358.4 | T32: 269.8 | U32: 269.8 | V32: 29.8 | W32: 29.8 | X32: 39.91 | Y32: 691.79 | Z32: 691.79 | AA32: 662.18 | AB32: 677.3
A33: 1 | C33: 리스부채 | E33: 0 | F33: 0 | G33: 0 | H33: 0 | I33: 0 | J33: 12951.62 | K33: 12951.62 | L33: 12945.21 | M33: 12936.92 | N33: 12930.74 | O33: 13171.96 | P33: 13171.96 | Q33: 6127.38 | R33: 6267.75 | S33: 6531.32 | T33: 6434.63 | U33: 6434.63 | V33: 6187.61 | W33: 6180.31 | X33: 6182.83 | Y33: 7785.57 | Z33: 7785.57 | AA33: 2964.76 | AB33: 2799.45
A34: 1 | C34: 단기금융부채 | E34: 3091.39 | F34: 3091.39 | G34: 3091.39 | H34: 1092.38 | I34: 1042.72 | J34: 511.36 | K34: 511.36 | L34: 331.74 | M34: 29.42 | N34: 23.24 | O34: 264.46 | P34: 264.46 | Q34: 162.32 | R34: 87.31 | S34: 358.4 | T34: 269.8 | U34: 269.8 | V34: 29.8 | W34: 29.8 | X34: 39.91 | Y34: 691.79 | Z34: 691.79 | AA34: 662.18 | AB34: 677.3
A35: 1 | C35: 단기충당부채 | E35: 1480.71 | F35: 1480.71 | G35: 1480.71 | H35: 2345 | I35: 2345 | J35: 2818.04 | K35: 2818.04 | L35: 2435.61 | M35: 2678.4 | N35: 2586.18 | O35: 1566.35 | P35: 1566.35 | Q35: 1305.06 | R35: 1349.31 | S35: 1389.2 | T35: 1769.37 | U35: 1769.37 | V35: 1336.98 | W35: 1334.68 | X35: 1338.94 | Y35: 1384.34 | Z35: 1384.34 | AA35: 1095.25 | AB35: 1121.27
A36: 1 | C36: 단기파생상품부채 | E36: 3091.39 | F36: 3091.39 | G36: 3091.39 | H36: 1092.38 | I36: 1042.72 | J36: 484.27 | K36: 484.27 | L36: 304.4 | M36: 0 | N36: 0 | O36: 0 | P36: 0 | Q36: 0 | R36: 0 | S36: 0 | T36: 0 | U36: 0 | V36: 0
A37: 1 | C37: 비유동부채 | E37: 1334.65 | F37: 1334.65 | G37: 1368 | H37: 1254.14 | I37: 1255.21 | J37: 16577.52 | K37: 16577.52 | L37: 16573.9 | M37: 16308.52 | N37: 21398.21 | O37: 21073.49 | P37: 21073.49 | Q37: 14365.46 | R37: 13531.49 | S37: 13494.35 | T37: 6883.4 | U37: 6883.4 | V37: 6866.88 | W37: 6869.43 | X37: 8751.85 | Y37: 9041.12 | Z37: 9041.12 | AA37: 4249.93 | AB37: 4027.81
A38: 1 | C38: 장기차입금 | E38: 0 | F38: 0 | G38: 0 | H38: 0 | I38: 0 | J38: 0 | K38: 0 | L38: 0 | M38: 0 | N38: 5000 | O38: 5000 | P38: 5000 | Q38: 5000 | R38: 5000 | S38: 5000 | T38: 0 | U38: 0 | V38: 0 | X38: 662 | Y38: 6 | Z38: 6 | AA38: 6 | AB38: 0
A39: 1 | C39: 비유동리스부채 | E39: 0 | F39: 0 | G39: 0 | H39: 0 | I39: 0 | J39: 12924.53 | K39: 12924.53 | L39: 12917.87 | M39: 12907.5 | N39: 12907.5 | O39: 12907.5 | P39: 12907.5 | Q39: 5965.06 | R39: 6180.44 | S39: 6172.92 | T39: 6164.83 | U39: 6164.83 | V39: 6157.81 | W39: 6150.51 | X39: 6142.92 | Y39: 7093.78 | Z39: 7093.78 | AA39: 2302.58 | AB39: 2122.15
A40: 1 | C40: 장기금융부채 | E40: 0 | F40: 0 | G40: 0 | H40: 0 | I40: 0 | J40: 12924.53 | K40: 12924.53 | L40: 12917.87 | M40: 12907.5 | N40: 12907.5 | O40: 12907.5 | P40: 12907.5 | Q40: 5965.06 | R40: 6180.44 | S40: 6172.92 | T40: 6164.83 | U40: 6164.83 | V40: 6157.81 | W40: 6150.51 | X40: 6142.92 | Y40: 7093.78 | Z40: 7093.78 | AA40: 2302.58 | AB40: 2122.15
...

Sheet BS별도
B1: (백만원) | C1: 이름: BS별도H | E1: 4Q21 | F1: 2021 | G1: 1Q22 | H1: 2Q22 | I1: 3Q22 | J1: 4Q22 | K1: 2022 | L1: 1Q23 | M1: 2Q23 | N1: 3Q23 | O1: 4Q23 | P1: 2023 | Q1: 1Q24 | R1: 2Q24 | S1: 3Q24 | T1: 4Q24 | U1: 2024 | V1: 1Q25 | W1: 2Q25 | X1: 3Q25 | Y1: 4Q25 | Z1: 2025 | AA1: 1Q26 | AB1: 2Q26 | AC1: 3Q26 | AD1: 4Q26 | AE1: 2026 | AF1: 1Q27 | AG1: 2Q27 | AH1: 3Q27 | AI1: 4Q27 | AJ1: 2027 | AK1: 1Q28 | AL1: 2Q28 | AM1: 3Q28 | AN1: 4Q28 | AO1: 2028
B2: 별도 | D2: fin json(kship_fin.py)
B3: 엔케이(별) | C3: UPDATE: 26-10-11 | E3: 1 | F3: 2 | G3: 3 | H3: 4 | I3: 5 | J3: 6 | K3: 7 | L3: 8 | M3: 9 | N3: 10 | O3: 11 | P3: 12 | Q3: 13 | R3: 14 | S3: 15 | T3: 16 | U3: 17 | V3: 18 | W3: 19 | X3: 20 | Y3: 21 | Z3: 22 | AA3: 23 | AB3: 24 | AC3: 25 | AD3: 26 | AE3: 27 | AF3: 28 | AG3: 29 | AH3: 30 | AI3: 31 | AJ3: 32 | AK3: 33 | AL3: 34 | AM3: 35 | AN3: 36 | AO3: 37
B4: Account Code | C4: AccountNAME | E4: 2021.12 | F4: 2021.12A | G4: 2022.03 | H4: 2022.06 | I4: 2022.09 | J4: 2022.12 | K4: 2022.12A | L4: 2023.03 | M4: 2023.06 | N4: 2023.09 | O4: 2023.12 | P4: 2023.12A | Q4: 2024.03 | R4: 2024.06 | S4: 2024.09 | T4: 2024.12 | U4: 2024.12A | V4: 2025.03 | W4: 2025.06 | X4: 2025.09 | Y4: 2025.12 | Z4: 2025.12A | AA4: 2026.03 | AB4: 2026.06 | AC4: 2026.09 | AD4: 2026.12 | AE4: 2026.12A | AF4: 2027.03 | AG4: 2027.06 | AH4: 2027.09 | AI4: 2027.12 | AJ4: 2027.12A | AK4: 2028.03 | AL4: 2028.06 | AM4: 2028.09 | AN4: 2028.12 | AO4: 2028.12A
A5: 1 | C5: 유동자산 | E5: 65566.7 | F5: 65566.7 | G5: 58061.8 | H5: 56092.85 | I5: 61653.85 | J5: 64525.92 | K5: 64525.92 | L5: 60619.77 | M5: 54225.72 | N5: 50780.97 | O5: 143601.76 | P5: 143601.76 | Q5: 140981.67 | R5: 139146.41 | S5: 136032.54 | T5: 136865.88 | U5: 136865.88 | V5: 130801.12 | W5: 100569.74 | X5: 79177.08 | Y5: 72833.22 | Z5: 72833.22 | AA5: 71039.31 | AB5: 75630.07
A6: 1 | C6: 현금및현금성자산 | E6: 45391.44 | F6: 45391.44 | G6: 24587.41 | H6: 23393.87 | I6: 14350.98 | J6: 19363.79 | K6: 19363.79 | L6: 17881.11 | M6: 14744.16 | N6: 11982.17 | O6: 10792.67 | P6: 10792.67 | Q6: 6039.45 | R6: 4140.99 | S6: 5998.83 | T6: 10292.83 | U6: 10292.83 | V6: 14756.4 | W6: 6412.75 | X6: 25044.62 | Y6: 25060.54 | Z6: 25060.54 | AA6: 26799.93 | AB6: 54894.2
A7: 1 | C7: 기타유동금융자산 | E7: 7887.37 | F7: 7887.37 | G7: 22709.38 | H7: 19709.38 | I7: 27659.39 | J7: 24833.6 | K7: 24833.6 | L7: 26226.8 | M7: 23262.8 | N7: 21379.2 | O7: 109157.6 | P7: 109157.6 | Q7: 108387.2 | R7: 108556.8 | S7: 103278.4 | T7: 98880 | U7: 98880 | V7: 79732 | W7: 60851.2 | X7: 20000 | Y7: 20000 | Z7: 20000 | AA7: 20000 | AB7: 0
A8: 1 | C8: 매출채권및기타채권 | E8: 10301.78 | F8: 10301.78 | G8: 8780.11 | H8: 11273.63 | I8: 16507.26 | J8: 14007.41 | K8: 14007.41 | L8: 14275.54 | M8: 13706.06 | N8: 13512.04 | O8: 12083.1 | P8: 12083.1 | Q8: 14827.28 | R8: 14369.05 | S8: 12758.09 | T8: 14752.08 | U8: 14752.08 | V8: 12942.06 | W8: 20081.87 | X8: 18544.05 | Y8: 19473.09 | Z8: 19473.09 | AA8: 14875.38 | AB8: 12513.45
A9: 1 | C9: 기타유동자산 | E9: 116.57 | F9: 116.57 | G9: 395.35 | H9: 261.86 | I9: 1240.54 | J9: 561.63 | K9: 561.63 | L9: 372.09 | M9: 819.55 | N9: 2251.58 | O9: 3045.64 | P9: 3045.64 | Q9: 3582.36 | R9: 5544.74 | S9: 5060.28 | T9: 4758.32 | U9: 4758.32 | V9: 13085.14 | W9: 3847.35 | X9: 4873.19 | Y9: 3192.83 | Z9: 3192.83 | AA9: 3777.35 | AB9: 3712.77
A10: 1 | C10: 당기법인세자산(선급법인세) | E10: 36.45 | F10: 36.45 | G10: 55.59 | H10: 46.89 | I10: 85.12 | J10: 129.57 | K10: 129.57 | L10: 250.44 | M10: 170.36 | N10: 210.73 | O10: 0 | P10: 0 | Q10: 49.4 | R10: 106.18 | S10: 401.01 | T10: 437.55 | U10: 437.55 | V10: 689.93 | W10: 291.49 | X10: 451.4 | Y10: 464.06 | Z10: 464.06 | AA10: 513.92 | AB10: 0
A11: 1 | C11: 재고자산 | E11: 1833.08 | F11: 1833.08 | G11: 1533.96 | H11: 1407.23 | I11: 1810.57 | J11: 2052.43 | K11: 2052.43 | L11: 1613.79 | M11: 1522.78 | N11: 1445.26 | O11: 8522.76 | P11: 8522.76 | Q11: 8095.98 | R11: 6428.65 | S11: 8535.92 | T11: 5887.29 | U11: 5887.29 | V11: 7681.84 | W11: 7951.82 | X11: 9130.56 | Y11: 3249.86 | Z11: 3249.86 | AA11: 3679.91 | AB11: 3116.82
A12: 1 | C12: 유동파생상품자산 | E12: 0 | F12: 0 | G12: 0 | H12: 0 | I12: 0 | J12: 0 | K12: 0 | L12: 0 | M12: 0 | N12: 0 | O12: 0 | P12: 0 | Q12: 0 | R12: 0 | S12: 0 | T12: 0 | U12: 0 | V12: 0
A13: 1 | C13: 단기금융자산 | E13: 0 | F13: 0 | G13: 0 | H13: 0 | I13: 0 | J13: 0 | K13: 0 | L13: 0 | M13: 0 | N13: 0 | O13: 0 | P13: 0 | Q13: 0 | R13: 0 | S13: 0 | T13: 0 | U13: 0 | V13: 0
A14: 1 | C14: 매각예정비유동자산및처분자산 | E14: 0 | F14: 0 | G14: 0 | H14: 0 | I14: 0 | J14: 3577.49 | K14: 3577.49 | L14: 0 | M14: 0 | N14: 0 | O14: 0 | P14: 0 | Q14: 0 | R14: 0 | S14: 0 | T14: 0 | U14: 0 | V14: 0
A15: 1 | C15: 비유동자산 | E15: 61435.85 | F15: 61435.85 | G15: 67617.44 | H15: 68826.76 | I15: 64698.62 | J15: 65851.86 | K15: 65851.86 | L15: 65182.82 | M15: 64756.09 | N15: 67818.82 | O15: 57484.07 | P15: 57484.07 | Q15: 57898.94 | R15: 58621.16 | S15: 58802.69 | T15: 60884.75 | U15: 60884.75 | V15: 60475.12 | W15: 81147.23 | X15: 103407.05 | Y15: 106726.67 | Z15: 106726.67 | AA15: 106931.04 | AB15: 101975.88
A16: 1 | C16: 장기금융자산 | E16: 12220.19 | F16: 12220.19 | G16: 15231.79 | H16: 14481.42 | I16: 14481.42 | J16: 12537.04 | K16: 12537.04 | L16: 11537.04 | M16: 10938.04 | N16: 10938.04 | O16: 12186.72 | P16: 12186.72 | Q16: 12186.72 | R16: 12186.72 | S16: 12186.72 | T16: 13991.7 | U16: 13991.7 | V16: 13991.7 | W16: 13991.7 | X16: 13991.7 | Y16: 13837.67 | Z16: 13837.67 | AA16: 13837.67 | AB16: 8697.39
A17: 1 | C17: 투자자산 | E17: 30330.09 | F17: 30330.09 | G17: 33337.17 | H17: 32569.16 | I17: 32522.71 | J17: 36534 | K17: 36534 | L17: 35722.67 | M17: 34924.47 | N17: 37699.74 | O17: 28127.07 | P17: 28127.07 | Q17: 28127.07 | R17: 28090.97 | S17: 28091.04 | T17: 29895.02 | U17: 29895.02 | V17: 29894.06 | W17: 42689.93 | X17: 69198.94 | Y17: 67997.48 | Z17: 67997.48 | AA17: 67997.48 | AB17: 8697.39
A18: 1 | C18: 종속기업및관계기업투자 | E18: 18109.9 | F18: 18109.9 | G18: 18105.38 | H18: 18087.74 | I18: 18041.29 | J18: 23996.96 | K18: 23996.96 | L18: 24185.63 | M18: 23986.43 | N18: 26761.7 | O18: 15940.35 | P18: 15940.35 | Q18: 15940.35 | R18: 15904.25 | S18: 15904.32 | T18: 15903.32 | U18: 15903.32 | V18: 15902.36 | W18: 28698.23 | X18: 55207.24 | Y18: 54159.81 | Z18: 54159.81 | AA18: 54159.81
A19: 1 | C19: 장기매출채권및기타채권 | E19: 0 | F19: 0 | G19: 0 | H19: 0 | I19: 0 | J19: 0 | K19: 0 | L19: 0 | M19: 0 | N19: 0 | O19: 0 | P19: 0 | Q19: 0 | R19: 0
A20: 1 | C20: 유형자산 | E20: 21207.61 | F20: 21207.61 | G20: 23823.24 | H20: 25403.95 | I20: 21290.72 | J20: 16195.17 | K20: 16195.17 | L20: 16159.38 | M20: 16560.33 | N20: 16413.72 | O20: 16925.15 | P20: 16925.15 | Q20: 17548.83 | R20: 18434.13 | S20: 18375.37 | T20: 18772.98 | U20: 18772.98 | V20: 18633.81 | W20: 17112.69 | X20: 21680.86 | Y20: 26386.49 | Z20: 26386.49 | AA20: 26709.65 | AB20: 27022.1
A21: 1 | C21: 사용권자산 | E21: 96.25 | F21: 96.25 | G21: 92.5 | H21: 88.75 | I21: 85 | J21: 81.25 | K21: 81.25 | L21: 77.5 | M21: 73.75 | N21: 70 | O21: 425.47 | P21: 425.47 | Q21: 340.26 | R21: 235.93 | S21: 491.61 | T21: 387.29 | U21: 387.29 | V21: 132.97 | W21: 118.64 | X21: 104.32 | Y21: 707.32 | Z21: 707.32 | AA21: 604.8 | AB21: 502.29
A22: 1 | C22: 기타비유동자산 | E22: 96.25 | F22: 96.25 | G22: 92.5 | H22: 88.75 | I22: 85 | J22: 81.25 | K22: 81.25 | L22: 77.5 | M22: 73.75 | N22: 70 | O22: 425.47 | P22: 425.47 | Q22: 340.26 | R22: 235.93 | S22: 491.61 | T22: 387.29 | U22: 387.29 | V22: 132.97 | W22: 8918.64 | X22: 104.32 | Y22: 707.32 | Z22: 707.32 | AA22: 604.8 | AB22: 502.29
A23: 1 | C23: 무형자산 | E23: 47.03 | F23: 47.03 | G23: 47.03 | H23: 47.03 | I23: 47.03 | J23: 47.03 | K23: 47.03 | L23: 47.03 | M23: 47.03 | N23: 47.03 | O23: 47.03 | P23: 47.03 | Q23: 47.03 | R23: 47.03 | S23: 47.03 | T23: 47.03 | U23: 47.03 | V23: 47.03 | W23: 47.03 | X23: 47.91 | Y23: 47.03 | Z23: 47.03 | AA23: 47.03 | AB23: 47.03
A24: 1 | C24: 투자부동산 | E24: 8962.2 | F24: 8962.2 | G24: 8949.12 | H24: 8936.04 | I24: 9977.22 | J24: 11476.04 | K24: 11476.04 | L24: 11527 | M24: 11501.27 | N24: 11889.08 | O24: 11388.38 | P24: 11388.38 | Q24: 11362.21 | R24: 11336.04 | S24: 11309.87 | T24: 11283.71 | U24: 11283.71 | V24: 11257.54 | W24: 11857.84 | X24: 11842.15 | Y24: 11179.03 | Z24: 11179.03 | AA24: 11152.86 | AB24: 11126.7
A25: 1 | C25: 이연법인세자산 | E25: 0 | F25: 0 | G25: 0 | H25: 0 | I25: 0 | J25: 0 | K25: 0 | L25: 0 | M25: 0 | N25: 0 | O25: 0 | P25: 0 | Q25: 0 | R25: 0 | S25: 0 | T25: 0 | U25: 0 | V25: 0
A26: 1 | C26: 자산총계 | E26: 127002.55 | F26: 127002.55 | G26: 125679.24 | H26: 124919.61 | I26: 126352.47 | J26: 130377.79 | K26: 130377.79 | L26: 125802.59 | M26: 118981.81 | N26: 118599.79 | O26: 201085.83 | P26: 201085.83 | Q26: 198880.61 | R26: 197767.58 | S26: 194835.24 | T26: 197750.63 | U26: 197750.63 | V26: 191276.24 | W26: 181716.97 | X26: 182584.13 | Y26: 179559.89 | Z26: 179559.89 | AA26: 177970.35 | AB26: 177605.94
A27: 1 | C27: 유동부채 | E27: 26434.17 | F27: 26434.17 | G27: 26527.84 | H27: 25684.43 | I27: 25301.97 | J27: 25675.45 | K27: 25675.45 | L27: 20779.9 | M27: 13418.56 | N27: 12704.99 | O27: 28139.98 | P27: 28139.98 | Q27: 24684.31 | R27: 23467.55 | S27: 21861.54 | T27: 23177.72 | U27: 23177.72 | V27: 19721.68 | W27: 19639.27 | X27: 21535.74 | Y27: 21263.41 | Z27: 21263.41 | AA27: 16180.38 | AB27: 13423.8
A28: 1 | C28: 기타유동부채 | E28: 0 | F28: 0 | G28: 0 | H28: 0 | I28: 0 | J28: 0 | K28: 0 | L28: 0 | M28: 0 | N28: 0 | O28: 0 | P28: 0 | Q28: 0 | R28: 0 | S28: 0 | T28: 0 | U28: 0 | V28: 0
A29: 1 | C29: 단기차입금 | E29: 0 | F29: 0 | G29: 0 | H29: 0 | I29: 0 | J29: 0 | K29: 0 | L29: 0 | M29: 0 | N29: 0 | O29: 0 | P29: 0 | Q29: 0 | R29: 0 | S29: 0 | T29: 0 | U29: 0 | V29: 0
A30: 1 | C30: 당기법인세부채(미지급법인세) | E30: 0 | F30: 0 | G30: 0 | H30: 0 | I30: 0 | J30: 0 | K30: 0 | L30: 0 | M30: 0 | N30: 0 | O30: 4159.27 | P30: 4159.27 | Q30: 4159.27 | R30: 0 | S30: 0 | T30: 0 | U30: 0 | V30: 0 | Y30: 0 | Z30: 0 | AA30: 0 | AB30: 684.38
A31: 1 | C31: 유동성장기부채 | E31: 10066.44 | F31: 10066.44 | G31: 10385.18 | H31: 10721.69 | I31: 10563.45 | J31: 10903.99 | K31: 10903.99 | L31: 7073.16 | M31: 0 | N31: 0 | O31: 0 | P31: 0 | Q31: 0 | R31: 0 | S31: 0 | T31: 0 | U31: 0 | V31: 0
A32: 1 | C32: 유동리스부채 | E32: 0 | F32: 0 | G32: 0 | H32: 0 | I32: 0 | J32: 0 | K32: 0 | L32: 0 | M32: 0 | N32: 0 | O32: 240 | P32: 240 | Q32: 150 | R32: 60 | S32: 330 | T32: 240 | U32: 240 | V32: 0 | W32: 0 | X32: 0 | Y32: 319.69 | Z32: 319.69 | AA32: 319.69 | AB32: 334.77
A33: 1 | C33: 리스부채 | E33: 0 | F33: 0 | G33: 0 | H33: 0 | I33: 0 | J33: 0 | K33: 0 | L33: 0 | M33: 0 | N33: 0 | O33: 240 | P33: 240 | Q33: 150 | R33: 60 | S33: 330 | T33: 240 | U33: 240 | V33: 0 | W33: 0 | X33: 0 | Y33: 579.56 | Z33: 579.56 | AA33: 502.38 | AB33: 423.4
A34: 1 | C34: 단기금융부채 | E34: 3091.39 | F34: 3091.39 | G34: 3091.39 | H34: 1092.38 | I34: 1042.72 | J34: 484.27 | K34: 484.27 | L34: 304.4 | M34: 0 | N34: 0 | O34: 240 | P34: 240 | Q34: 150 | R34: 60 | S34: 330 | T34: 240 | U34: 240 | V34: 0 | W34: 0 | X34: 0 | Y34: 319.69 | Z34: 319.69 | AA34: 319.69 | AB34: 334.77
A35: 1 | C35: 단기충당부채 | E35: 1480.71 | F35: 1480.71 | G35: 1480.71 | H35: 2345 | I35: 2345 | J35: 2818.04 | K35: 2818.04 | L35: 2435.61 | M35: 2678.4 | N35: 2586.18 | O35: 1566.35 | P35: 1566.35 | Q35: 1305.06 | R35: 1349.31 | S35: 1389.2 | T35: 1769.37 | U35: 1769.37 | V35: 1336.98 | W35: 1334.68 | X35: 1338.94 | Y35: 1384.34 | Z35: 1384.34 | AA35: 1095.25 | AB35: 1121.27
A36: 1 | C36: 기타유동금융부채 | E36: 0 | F36: 0 | G36: 0 | H36: 0 | I36: 0 | J36: 0 | K36: 0 | L36: 0 | M36: 0 | N36: 0 | O36: 0 | P36: 0 | Q36: 0 | R36: 0 | S36: 0 | T36: 0 | U36: 0 | V36: 0
A37: 1 | C37: 단기파생상품부채 | E37: 3091.39 | F37: 3091.39 | G37: 3091.39 | H37: 1092.38 | I37: 1042.72 | J37: 484.27 | K37: 484.27 | L37: 304.4 | M37: 0 | N37: 0 | O37: 0 | P37: 0 | Q37: 0 | R37: 0 | S37: 0 | T37: 0 | U37: 0 | V37: 0
A38: 1 | C38: 비유동부채 | E38: 1334.65 | F38: 1334.65 | G38: 1368 | H38: 1254.14 | I38: 1255.21 | J38: 898.46 | K38: 898.46 | L38: 901.5 | M38: 719.18 | N38: 651.38 | O38: 689 | P38: 689 | Q38: 689.03 | R38: 617.66 | S38: 618.63 | T38: 619.02 | U38: 619.02 | V38: 619.27 | W38: 619.37 | X38: 627.06 | Y38: 888.84 | Z38: 888.84 | AA38: 811.66 | AB38: 717.6
A39: 1 | C39: 장기차입금 | E39: 0 | F39: 0 | G39: 0 | H39: 0 | I39: 0 | J39: 0 | K39: 0 | L39: 0 | M39: 0 | N39: 0 | O39: 0 | P39: 0 | Q39: 0 | R39: 0 | S39: 0 | T39: 0 | U39: 0 | V39: 0
A40: 1 | C40: 비유동리스부채 | E40: 0 | F40: 0 | G40: 0 | H40: 0 | I40: 0 | J40: 0 | K40: 0 | L40: 0 | M40: 0 | N40: 0 | O40: 0 | P40: 0 | Q40: 0 | R40: 0 | S40: 0 | T40: 0 | U40: 0 | V40: 0 | Y40: 259.87 | Z40: 259.87 | AA40: 182.69 | AB40: 88.63
...

Sheet subQ
A1: YQ | C1: subQ 분기 서브모델(억원, U=100) | E1: 4Q21 | F1: 2021 | G1: 1Q22 | H1: 2Q22 | I1: 3Q22 | J1: 4Q22 | K1: 2022 | L1: 1Q23 | M1: 2Q23 | N1: 3Q23 | O1: 4Q23 | P1: 2023 | Q1: 1Q24 | R1: 2Q24 | S1: 3Q24 | T1: 4Q24 | U1: 2024 | V1: 1Q25 | W1: 2Q25 | X1: 3Q25 | Y1: 4Q25 | Z1: 2025 | AA1: 1Q26 | AB1: 2Q26 | AC1: 3Q26 | AD1: 4Q26 | AE1: 2026 | AF1: 1Q27 | AG1: 2Q27 | AH1: 3Q27 | AI1: 4Q27 | AJ1: 2027 | AK1: 1Q28 | AL1: 2Q28 | AM1: 3Q28 | AN1: 4Q28 | AO1: 2028
A2: A=이름(key) B=그룹 C=단위 D=FnGuide 계정명(VLOOKUP 키). 확정=VLOOKUP(BS), 추정=변수 가정 참조
E3: 1 | F3: 2 | G3: 3 | H3: 4 | I3: 5 | J3: 6 | K3: 7 | L3: 8 | M3: 9 | N3: 10 | O3: 11 | P3: 12 | Q3: 13 | R3: 14 | S3: 15 | T3: 16 | U3: 17 | V3: 18 | W3: 19 | X3: 20 | Y3: 21 | Z3: 22 | AA3: 23 | AB3: 24 | AC3: 25 | AD3: 26 | AE3: 27 | AF3: 28 | AG3: 29 | AH3: 30 | AI3: 31 | AJ3: 32 | AK3: 33 | AL3: 34 | AM3: 35 | AN3: 36 | AO3: 37
E4: 2021.12 | F4: 2021.12A | G4: 2022.03 | H4: 2022.06 | I4: 2022.09 | J4: 2022.12 | K4: 2022.12A | L4: 2023.03 | M4: 2023.06 | N4: 2023.09 | O4: 2023.12 | P4: 2023.12A | Q4: 2024.03 | R4: 2024.06 | S4: 2024.09 | T4: 2024.12 | U4: 2024.12A | V4: 2025.03 | W4: 2025.06 | X4: 2025.09 | Y4: 2025.12 | Z4: 2025.12A | AA4: 2026.03 | AB4: 2026.06 | AC4: 2026.09 | AD4: 2026.12 | AE4: 2026.12A | AF4: 2027.03 | AG4: 2027.06 | AH4: 2027.09 | AI4: 2027.12 | AJ4: 2027.12A | AK4: 2028.03 | AL4: 2028.06 | AM4: 2028.09 | AN4: 2028.12 | AO4: 2028.12A
A5: 매출액 | B5: 손익 | C5: 억원 | D5: 매출액(수익) | E5: =IFERROR(VLOOKUP($D5,BS연결,MATCH(E$1,BS연결H,0),0)/100,"") | G5: =IFERROR(VLOOKUP($D5,BS연결,MATCH(G$1,BS연결H,0),0)/100,"") | H5: =IFERROR(VLOOKUP($D5,BS연결,MATCH(H$1,BS연결H,0),0)/100,"") | I5: =IFERROR(VLOOKUP($D5,BS연결,MATCH(I$1,BS연결H,0),0)/100,"") | J5: =IFERROR(VLOOKUP($D5,BS연결,MATCH(J$1,BS연결H,0),0)/100,"") | K5: =IFERROR(VLOOKUP($D5,BS연결,MATCH(K$1,BS연결H,0),0)/100,"") | L5: =IFERROR(VLOOKUP($D5,BS연결,MATCH(L$1,BS연결H,0),0)/100,"") | M5: =IFERROR(VLOOKUP($D5,BS연결,MATCH(M$1,BS연결H,0),0)/100,"") | N5: =IFERROR(VLOOKUP($D5,BS연결,MATCH(N$1,BS연결H,0),0)/100,"") | ... AB5: =IFERROR(VLOOKUP($D5,BS연결,MATCH(AB$1,BS연결H,0),0)/100,"") | AC5: =IFERROR(X5*(1+변수!AC21),"") | AD5: =IFERROR(Y5*(1+변수!AD21),"") | AE5: =SUM(AA5:AD5) | AF5: =IFERROR(AA5*(1+변수!AF21),"") | AG5: =IFERROR(AB5*(1+변수!AG21),"") | AH5: =IFERROR(AC5*(1+변수!AH21),"") | AI5: =IFERROR(AD5*(1+변수!AI21),"") | AJ5: =SUM(AF5:AI5) | AK5: =IFERROR(AF5*(1+변수!AK21),"") | AL5: =IFERROR(AG5*(1+변수!AL21),"") | AM5: =IFERROR(AH5*(1+변수!AM21),"") | AN5: =IFERROR(AI5*(1+변수!AN21),"") | AO5: =SUM(AK5:AN5)
A6: 매출원가 | B6: 손익 | C6: 억원 | D6: 매출원가 | E6: =IFERROR(VLOOKUP($D6,BS연결,MATCH(E$1,BS연결H,0),0)/100,"") | G6: =IFERROR(VLOOKUP($D6,BS연결,MATCH(G$1,BS연결H,0),0)/100,"") | H6: =IFERROR(VLOOKUP($D6,BS연결,MATCH(H$1,BS연결H,0),0)/100,"") | I6: =IFERROR(VLOOKUP($D6,BS연결,MATCH(I$1,BS연결H,0),0)/100,"") | J6: =IFERROR(VLOOKUP($D6,BS연결,MATCH(J$1,BS연결H,0),0)/100,"") | K6: =IFERROR(VLOOKUP($D6,BS연결,MATCH(K$1,BS연결H,0),0)/100,"") | L6: =IFERROR(VLOOKUP($D6,BS연결,MATCH(L$1,BS연결H,0),0)/100,"") | M6: =IFERROR(VLOOKUP($D6,BS연결,MATCH(M$1,BS연결H,0),0)/100,"") | N6: =IFERROR(VLOOKUP($D6,BS연결,MATCH(N$1,BS연결H,0),0)/100,"") | ... AB6: =IFERROR(VLOOKUP($D6,BS연결,MATCH(AB$1,BS연결H,0),0)/100,"") | AC6: =IFERROR(AC5-AC7,"") | AD6: =IFERROR(AD5-AD7,"") | AE6: =SUM(AA6:AD6) | AF6: =IFERROR(AF5-AF7,"") | AG6: =IFERROR(AG5-AG7,"") | AH6: =IFERROR(AH5-AH7,"") | AI6: =IFERROR(AI5-AI7,"") | AJ6: =SUM(AF6:AI6) | AK6: =IFERROR(AK5-AK7,"") | AL6: =IFERROR(AL5-AL7,"") | AM6: =IFERROR(AM5-AM7,"") | AN6: =IFERROR(AN5-AN7,"") | AO6: =SUM(AK6:AN6)
A7: 매출총이익 | B7: 손익 | C7: 억원 | D7: 매출총이익 | E7: =IFERROR(VLOOKUP($D7,BS연결,MATCH(E$1,BS연결H,0),0)/100,"") | G7: =IFERROR(VLOOKUP($D7,BS연결,MATCH(G$1,BS연결H,0),0)/100,"") | H7: =IFERROR(VLOOKUP($D7,BS연결,MATCH(H$1,BS연결H,0),0)/100,"") | I7: =IFERROR(VLOOKUP($D7,BS연결,MATCH(I$1,BS연결H,0),0)/100,"") | J7: =IFERROR(VLOOKUP($D7,BS연결,MATCH(J$1,BS연결H,0),0)/100,"") | K7: =IFERROR(VLOOKUP($D7,BS연결,MATCH(K$1,BS연결H,0),0)/100,"") | L7: =IFERROR(VLOOKUP($D7,BS연결,MATCH(L$1,BS연결H,0),0)/100,"") | M7: =IFERROR(VLOOKUP($D7,BS연결,MATCH(M$1,BS연결H,0),0)/100,"") | N7: =IFERROR(VLOOKUP($D7,BS연결,MATCH(N$1,BS연결H,0),0)/100,"") | ... AB7: =IFERROR(VLOOKUP($D7,BS연결,MATCH(AB$1,BS연결H,0),0)/100,"") | AC7: =IFERROR(AC9+AC8,"") | AD7: =IFERROR(AD9+AD8,"") | AE7: =SUM(AA7:AD7) | AF7: =IFERROR(AF9+AF8,"") | AG7: =IFERROR(AG9+AG8,"") | AH7: =IFERROR(AH9+AH8,"") | AI7: =IFERROR(AI9+AI8,"") | AJ7: =SUM(AF7:AI7) | AK7: =IFERROR(AK9+AK8,"") | AL7: =IFERROR(AL9+AL8,"") | AM7: =IFERROR(AM9+AM8,"") | AN7: =IFERROR(AN9+AN8,"") | AO7: =SUM(AK7:AN7)
A8: 판관비 | B8: 손익 | C8: 억원 | D8: 판관비 | E8: =IFERROR(VLOOKUP($D8,BS연결,MATCH(E$1,BS연결H,0),0)/100,"") | G8: =IFERROR(VLOOKUP($D8,BS연결,MATCH(G$1,BS연결H,0),0)/100,"") | H8: =IFERROR(VLOOKUP($D8,BS연결,MATCH(H$1,BS연결H,0),0)/100,"") | I8: =IFERROR(VLOOKUP($D8,BS연결,MATCH(I$1,BS연결H,0),0)/100,"") | J8: =IFERROR(VLOOKUP($D8,BS연결,MATCH(J$1,BS연결H,0),0)/100,"") | K8: =IFERROR(VLOOKUP($D8,BS연결,MATCH(K$1,BS연결H,0),0)/100,"") | L8: =IFERROR(VLOOKUP($D8,BS연결,MATCH(L$1,BS연결H,0),0)/100,"") | M8: =IFERROR(VLOOKUP($D8,BS연결,MATCH(M$1,BS연결H,0),0)/100,"") | N8: =IFERROR(VLOOKUP($D8,BS연결,MATCH(N$1,BS연결H,0),0)/100,"") | ... AB8: =IFERROR(VLOOKUP($D8,BS연결,MATCH(AB$1,BS연결H,0),0)/100,"") | AC8: =IFERROR(AC5*변수!AC22,"") | AD8: =IFERROR(AD5*변수!AD22,"") | AE8: =SUM(AA8:AD8) | AF8: =IFERROR(AF5*변수!AF22,"") | AG8: =IFERROR(AG5*변수!AG22,"") | AH8: =IFERROR(AH5*변수!AH22,"") | AI8: =IFERROR(AI5*변수!AI22,"") | AJ8: =SUM(AF8:AI8) | AK8: =IFERROR(AK5*변수!AK22,"") | AL8: =IFERROR(AL5*변수!AL22,"") | AM8: =IFERROR(AM5*변수!AM22,"") | AN8: =IFERROR(AN5*변수!AN22,"") | AO8: =SUM(AK8:AN8)
A9: 영업이익 | B9: 손익 | C9: 억원 | D9: 영업이익 | E9: =IFERROR(VLOOKUP($D9,BS연결,MATCH(E$1,BS연결H,0),0)/100,"") | G9: =IFERROR(VLOOKUP($D9,BS연결,MATCH(G$1,BS연결H,0),0)/100,"") | H9: =IFERROR(VLOOKUP($D9,BS연결,MATCH(H$1,BS연결H,0),0)/100,"") | I9: =IFERROR(VLOOKUP($D9,BS연결,MATCH(I$1,BS연결H,0),0)/100,"") | J9: =IFERROR(VLOOKUP($D9,BS연결,MATCH(J$1,BS연결H,0),0)/100,"") | K9: =IFERROR(VLOOKUP($D9,BS연결,MATCH(K$1,BS연결H,0),0)/100,"") | L9: =IFERROR(VLOOKUP($D9,BS연결,MATCH(L$1,BS연결H,0),0)/100,"") | M9: =IFERROR(VLOOKUP($D9,BS연결,MATCH(M$1,BS연결H,0),0)/100,"") | N9: =IFERROR(VLOOKUP($D9,BS연결,MATCH(N$1,BS연결H,0),0)/100,"") | ... T9: =IFERROR(VLOOKUP($D9,BS연결,MATCH(T$1,BS연결H,0),0)/100,"") | U9: =SUM(Q9:T9) | V9: =IFERROR(VLOOKUP($D9,BS연결,MATCH(V$1,BS연결H,0),0)/100,"") | W9: =IFERROR(VLOOKUP($D9,BS연결,MATCH(W$1,BS연결H,0),0)/100,"") | X9: =IFERROR(VLOOKUP($D9,BS연결,MATCH(X$1,BS연결H,0),0)/100,"") | Y9: =IFERROR(VLOOKUP($D9,BS연결,MATCH(Y$1,BS연결H,0),0)/100,"") | Z9: =IFERROR(VLOOKUP($D9,BS연결,MATCH(Z$1,BS연결H,0),0)/100,"") | AA9: =IFERROR(VLOOKUP($D9,BS연결,MATCH(AA$1,BS연결H,0),0)/100,"") | AB9: =IFERROR(VLOOKUP($D9,BS연결,MATCH(AB$1,BS연결H,0),0)/100,"") | AC9: =IFERROR(AC5*변수!AC23,"") | AD9: =IFERROR(AD5*변수!AD23,"") | AE9: =SUM(AA9:AD9) | AF9: =IFERROR(AF5*변수!AF23,"") | AG9: =IFERROR(AG5*변수!AG23,"") | AH9: =IFERROR(AH5*변수!AH23,"") | AI9: =IFERROR(AI5*변수!AI23,"") | AJ9: =SUM(AF9:AI9) | AK9: =IFERROR(AK5*변수!AK23,"") | AL9: =IFERROR(AL5*변수!AL23,"") | AM9: =IFERROR(AM5*변수!AM23,"") | AN9: =IFERROR(AN5*변수!AN23,"") | AO9: =SUM(AK9:AN9)
A10: OPM | B10: 손익 | C10: % | D10: 영업이익률 | E10: =IFERROR(E9/E5,"") | G10: =IFERROR(G9/G5,"") | H10: =IFERROR(H9/H5,"") | I10: =IFERROR(I9/I5,"") | J10: =IFERROR(J9/J5,"") | K10: =IFERROR(K9/K5,"") | L10: =IFERROR(L9/L5,"") | M10: =IFERROR(M9/M5,"") | N10: =IFERROR(N9/N5,"") | ... AO10: =IFERROR(AO9/AO5,"")
A11: 금융손익 | B11: 손익 | C11: 억원 | D11: 금융손익 | E11: =IFERROR(VLOOKUP($D11,BS연결,MATCH(E$1,BS연결H,0),0)/100,"") | G11: =IFERROR(VLOOKUP($D11,BS연결,MATCH(G$1,BS연결H,0),0)/100,"") | H11: =IFERROR(VLOOKUP($D11,BS연결,MATCH(H$1,BS연결H,0),0)/100,"") | I11: =IFERROR(VLOOKUP($D11,BS연결,MATCH(I$1,BS연결H,0),0)/100,"") | J11: =IFERROR(VLOOKUP($D11,BS연결,MATCH(J$1,BS연결H,0),0)/100,"") | K11: =IFERROR(VLOOKUP($D11,BS연결,MATCH(K$1,BS연결H,0),0)/100,"") | L11: =IFERROR(VLOOKUP($D11,BS연결,MATCH(L$1,BS연결H,0),0)/100,"") | M11: =IFERROR(VLOOKUP($D11,BS연결,MATCH(M$1,BS연결H,0),0)/100,"") | N11: =IFERROR(VLOOKUP($D11,BS연결,MATCH(N$1,BS연결H,0),0)/100,"") | ... AB11: =IFERROR(VLOOKUP($D11,BS연결,MATCH(AB$1,BS연결H,0),0)/100,"") | AC11: =IFERROR(AC12,"") | AD11: =IFERROR(AD12,"") | AE11: =SUM(AA11:AD11) | AF11: =IFERROR(AF12,"") | AG11: =IFERROR(AG12,"") | AH11: =IFERROR(AH12,"") | AI11: =IFERROR(AI12,"") | AJ11: =SUM(AF11:AI11) | AK11: =IFERROR(AK12,"") | AL11: =IFERROR(AL12,"") | AM11: =IFERROR(AM12,"") | AN11: =IFERROR(AN12,"") | AO11: =SUM(AK11:AN11)
A12: 이자손익 | B12: 손익 | C12: 억원 | D12: 이자손익 | K12: =SUM(G12:J12) | P12: =SUM(L12:O12) | U12: =SUM(Q12:T12) | Z12: =SUM(V12:Y12) | AC12: =IFERROR((AB26*변수!$D$52-AB24*변수!$D$53)/4,"") | AD12: =IFERROR((AC26*변수!$D$52-AC24*변수!$D$53)/4,"") | AE12: =SUM(AA12:AD12) | AF12: =IFERROR((AD26*변수!$D$52-AD24*변수!$D$53)/4,"") | AG12: =IFERROR((AF26*변수!$D$52-AF24*변수!$D$53)/4,"") | AH12: =IFERROR((AG26*변수!$D$52-AG24*변수!$D$53)/4,"") | AI12: =IFERROR((AH26*변수!$D$52-AH24*변수!$D$53)/4,"") | AJ12: =SUM(AF12:AI12) | AK12: =IFERROR((AI26*변수!$D$52-AI24*변수!$D$53)/4,"") | AL12: =IFERROR((AK26*변수!$D$52-AK24*변수!$D$53)/4,"") | AM12: =IFERROR((AL26*변수!$D$52-AL24*변수!$D$53)/4,"") | AN12: =IFERROR((AM26*변수!$D$52-AM24*변수!$D$53)/4,"") | AO12: =SUM(AK12:AN12)
A13: 기타영업외손익 | B13: 손익 | C13: 억원 | D13: 기타영업외손익 | E13: =IFERROR(VLOOKUP($D13,BS연결,MATCH(E$1,BS연결H,0),0)/100,"") | G13: =IFERROR(VLOOKUP($D13,BS연결,MATCH(G$1,BS연결H,0),0)/100,"") | H13: =IFERROR(VLOOKUP($D13,BS연결,MATCH(H$1,BS연결H,0),0)/100,"") | I13: =IFERROR(VLOOKUP($D13,BS연결,MATCH(I$1,BS연결H,0),0)/100,"") | J13: =IFERROR(VLOOKUP($D13,BS연결,MATCH(J$1,BS연결H,0),0)/100,"") | K13: =IFERROR(VLOOKUP($D13,BS연결,MATCH(K$1,BS연결H,0),0)/100,"") | L13: =IFERROR(VLOOKUP($D13,BS연결,MATCH(L$1,BS연결H,0),0)/100,"") | M13: =IFERROR(VLOOKUP($D13,BS연결,MATCH(M$1,BS연결H,0),0)/100,"") | N13: =IFERROR(VLOOKUP($D13,BS연결,MATCH(N$1,BS연결H,0),0)/100,"") | ... AB13: =IFERROR(VLOOKUP($D13,BS연결,MATCH(AB$1,BS연결H,0),0)/100,"") | AC13: =변수!AC24 | AD13: =변수!AD24 | AE13: =SUM(AA13:AD13) | AF13: =변수!AF24 | AG13: =변수!AG24 | AH13: =변수!AH24 | AI13: =변수!AI24 | AJ13: =SUM(AF13:AI13) | AK13: =변수!AK24 | AL13: =변수!AL24 | AM13: =변수!AM24 | AN13: =변수!AN24 | AO13: =SUM(AK13:AN13)
