Workbook
Name 변수H: 변수!$C$1:$AO$1
Name 환율: 변수!$C$6:$AO$13
Name BS연결H: BS연결!$C$1:$AO$1
Name BS연결: BS연결!$C$5:$AO$106
Name BS별도H: BS별도!$C$1:$AO$1
Name BS별도: BS별도!$C$5:$AO$93
Name SUBQH: subQ!$A$1:$AO$1
Name subQ: subQ!$A$5:$AO$44

Sheet README
A1: 대창솔루션(096350) 실적 모델 — ARGUS 한국조선
A2: 기준 분기 2026Q2 · 마지막 실적 2026Q2 · 생성 2026-10-19
A3: 모든 수치는 모델 산출값(DART 공개 재무제표 + 우리 추정)이다 — 목표주가·투자 추천 아님. 참고용 · 투자조언 아님.
A5: 시트
A6: 변수 가정 시계열. 환율 8행(ECB via frankfurter — L2 fx.json; 추정 분기 = 노란 가정), 추정 드라이버(노란 셀 = 모델값에서 역산한 가정, 바꾸면 재계산; 연녹 셀 = 3절 스칼라 참조 수식), 3절 스칼라 가정(세율·판관비율·지배주주비중·이자율·종가·PER 밴드·COE·외화 순노출·헤지비율)
A7: BS연결/BS별도 FnGuide 계정명 × 기간 값 덤프(백만원). 행1 분기라벨, 행4 YYYY.MM / YYYY.12A. 이름정의 BS연결H·BS연결(계정명 C열부터)
A8: subQ 분기 서브모델(억원 = 백만원/100). 확정 행: =IFERROR(VLOOKUP($D행,BS연결,MATCH(E$1,BS연결H,0),0)/100,"") 추정 행: 변수 시트 가정 셀 참조 수식. 외환손익·파생상품손익은 BS 계정 합·차, 기타금융손익은 잔차, OPM·EPS·BPS·PER·PBR 은 파생 수식
A9: SLS 선표(조선사만, sls json 있을 때): 요약 행(sls 저장값) + 계약별 스케줄(백만$) × (헤지비율 × 헤지환율 + (1−헤지비율) × 건조시점 환율[변수 원/달러(평균)]) → 원화 수식 블록 → 합계 행이 subQ 매출조선에 연결
A10: 시나리오 신규수주 보수/기준/낙관(forecast_panel 패널, 모델에 scenarios 가 있을 때만): 매출액·영업이익 = subQ 기준값 ± (시나리오 신규 − base 신규) × OPM. base 만 subQ 행에 포함, 나머지는 합산 안 함
A11: 분기/연간예상 subQ 를 이름(A열 key)으로 VLOOKUP 한 보고서 표(억원)
A12: TP PER 밴드 × 12M fwd EPS, PBR = ROE/COE × BPS — 모델 산출값 구간, 목표주가·추천 아님
A13: 외화 환율 QoQ, 외화 순노출 × Δ기말환율 → 환관련손익 추정
... A34: 백테스트: {"freeze": "2025Q2", "horizon": 4, "revenue_wape_pct": 37.4, "op_wape_pct": 99.6, "n": 4, "note": "단일 회사 4분기 — 통계 아님", "driver_at_freeze": "trend_seasonal", "selection_oos_at_freeze": {"wape_link": null, "wape_trend": null, "adopted": false, "decision": "rejected", "note": "유의성 조건 미달 → OOS 비교 전 기각"}, "frozen_inputs": "fin(연결/별도)·고객 조선사 모델·지주 자회사 모델은 2025Q2 까지의 분기만; 선표는 체결일 ≤ 2025Q2 말일 계약(원장 최신 금액·코호트 등급, 환산 없음); 잔고는 yards_cache 2025Q2; 시세·환율 forward·prices·forecast_panel 신규수주 미사용. 고객 가중치(suppliers.json 언급 비중)와 합병 체인링크는 현재 지식; 고객 연동 채택은 동결 모델 안에서도 자기 la−4분기 OOS 규칙(selection_oos_at_freeze)", "detail": [{"q": "2025Q3", "rev_pred": 109.34, "rev_act": 171.56, "op_pred": 0.07, "op_act": 11.72}, {"q": "2025Q4", "rev_pred": 149.49, "rev_act": 177.73, "op_pred": 0.09, "op_act": 1.71}, {"q": "2026Q1", "rev_pred": 87.38, "rev_act": 212.48, "op_pred": 0.05, "op_act": 14.82}, {"q": "2026Q2", "rev_pred": 123.68, "rev_act": 188.86, "op_pred": 0.08, "op_act": -1.36}]}

Sheet 변수
C1: 이름: 변수H | E1: 4Q21 | F1: 2021 | G1: 1Q22 | H1: 2Q22 | I1: 3Q22 | J1: 4Q22 | K1: 2022 | L1: 1Q23 | M1: 2Q23 | N1: 3Q23 | O1: 4Q23 | P1: 2023 | Q1: 1Q24 | R1: 2Q24 | S1: 3Q24 | T1: 4Q24 | U1: 2024 | V1: 1Q25 | W1: 2Q25 | X1: 3Q25 | Y1: 4Q25 | Z1: 2025 | AA1: 1Q26 | AB1: 2Q26 | AC1: 3Q26 | AD1: 4Q26 | AE1: 2026 | AF1: 1Q27 | AG1: 2Q27 | AH1: 3Q27 | AI1: 4Q27 | AJ1: 2027 | AK1: 1Q28 | AL1: 2Q28 | AM1: 3Q28 | AN1: 4Q28 | AO1: 2028
A2: 가정 시계열 — 노란 셀은 추정 가정(모델값에서 역산), 연녹 셀은 3절 스칼라 참조 수식. 바꾸면 subQ·분기·연간예상·TP·시나리오가 재계산됩니다.
E3: 1 | F3: 2 | G3: 3 | H3: 4 | I3: 5 | J3: 6 | K3: 7 | L3: 8 | M3: 9 | N3: 10 | O3: 11 | P3: 12 | Q3: 13 | R3: 14 | S3: 15 | T3: 16 | U3: 17 | V3: 18 | W3: 19 | X3: 20 | Y3: 21 | Z3: 22 | AA3: 23 | AB3: 24 | AC3: 25 | AD3: 26 | AE3: 27 | AF3: 28 | AG3: 29 | AH3: 30 | AI3: 31 | AJ3: 32 | AK3: 33 | AL3: 34 | AM3: 35 | AN3: 36 | AO3: 37
E4: 2021.12 | F4: 2021.12A | G4: 2022.03 | H4: 2022.06 | I4: 2022.09 | J4: 2022.12 | K4: 2022.12A | L4: 2023.03 | M4: 2023.06 | N4: 2023.09 | O4: 2023.12 | P4: 2023.12A | Q4: 2024.03 | R4: 2024.06 | S4: 2024.09 | T4: 2024.12 | U4: 2024.12A | V4: 2025.03 | W4: 2025.06 | X4: 2025.09 | Y4: 2025.12 | Z4: 2025.12A | AA4: 2026.03 | AB4: 2026.06 | AC4: 2026.09 | AD4: 2026.12 | AE4: 2026.12A | AF4: 2027.03 | AG4: 2027.06 | AH4: 2027.09 | AI4: 2027.12 | AJ4: 2027.12A | AK4: 2028.03 | AL4: 2028.06 | AM4: 2028.09 | AN4: 2028.12 | AO4: 2028.12A
B5: 1. FX | C5: 이름: 환율
A6: USDKRW_avg | C6: 원/달러(평균) | E6: 1183.5 | F6: 1145.51 | G6: 1205.78 | H6: 1262.09 | I6: 1341.93 | J6: 1360.12 | K6: 1292.98 | L6: 1276.95 | M6: 1315.69 | N6: 1313.62 | O6: 1322.01 | P6: 1306.85 | Q6: 1330.14 | R6: 1371.28 | S6: 1356.22 | T6: 1396.3 | U6: 1363.53 | V6: 1452.28 | W6: 1398.52 | X6: 1386.95 | Y6: 1449.19 | Z6: 1421.52 | AA6: 1466.12 | AB6: 1501.75 | AC6: 1418.75 | AD6: 1342.11 | AE6: 1454.27 | AF6: 1332.1 | AG6: 1332.1 | AH6: 1332.1 | AI6: 1332.1 | AK6: 1332.1 | AL6: 1332.1 | AM6: 1332.1 | AN6: 1332.1
A7: USDKRW_end | C7: 원/달러(기말) | E7: 1188.75 | F7: 1188.75 | G7: 1213.74 | H7: 1301.24 | I7: 1436.9 | J7: 1260.16 | K7: 1260.16 | L7: 1305.99 | M7: 1321.44 | N7: 1345.35 | O7: 1297.43 | P7: 1297.43 | Q7: 1349.25 | R7: 1377.73 | S7: 1312.17 | T7: 1474.78 | U7: 1474.78 | V7: 1474.54 | W7: 1355.13 | X7: 1403.67 | Y7: 1444.2 | Z7: 1444.2 | AA7: 1524.8 | AB7: 1550.89 | AC7: 1355.4 | AD7: 1332.1 | AE7: 1332.1 | AF7: 1332.1 | AG7: 1332.1 | AH7: 1332.1 | AI7: 1332.1 | AK7: 1332.1 | AL7: 1332.1 | AM7: 1332.1 | AN7: 1332.1
A8: JPY100KRW_avg | C8: 원/100Y(평균) | E8: 1041.02 | F8: 1042.74 | G8: 1036.79 | H8: 972.23 | I8: 970.61 | J8: 961.03 | K8: 985.1 | L8: 964.89 | M8: 957.36 | N8: 909 | O8: 893.22 | P8: 931.11 | Q8: 896.29 | R8: 880.14 | S8: 909.35 | T8: 917.25 | U8: 900.92 | V8: 952.59 | W8: 967.92 | X8: 940.32 | Y8: 940.77 | Z8: 950.17 | AA8: 934.39 | AB8: 942.16 | AC8: 890.41 | AD8: 848.59 | AE8: 917.39 | AF8: 842.99 | AG8: 842.99 | AH8: 842.99 | AI8: 842.99 | AK8: 842.99 | AL8: 842.99 | AM8: 842.99 | AN8: 842.99
A9: JPY100KRW_end | C9: 원/100Y(기말) | E9: 1032.62 | F9: 1032.62 | G9: 996.83 | H9: 954.9 | I9: 993.29 | J9: 955.54 | K9: 955.54 | L9: 980.62 | M9: 913.67 | N9: 901.47 | O9: 917.04 | P9: 917.04 | Q9: 892.42 | R9: 857.76 | S9: 919.21 | T9: 939.65 | U9: 939.65 | V9: 986.84 | W9: 938.85 | X9: 948.49 | Y9: 921.81 | Z9: 921.81 | AA9: 955.99 | AB9: 954.75 | AC9: 863.31 | AD9: 842.99 | AE9: 842.99 | AF9: 842.99 | AG9: 842.99 | AH9: 842.99 | AI9: 842.99 | AK9: 842.99 | AL9: 842.99 | AM9: 842.99 | AN9: 842.99
A10: EURKRW_avg | C10: W/Euro(평균) | E10: 1353.32 | F10: 1354.06 | G10: 1352.29 | H10: 1343.31 | I10: 1350.63 | J10: 1386.07 | K10: 1358.07 | L10: 1369.93 | M10: 1432.41 | N10: 1429.41 | O10: 1420.91 | P10: 1412.88 | Q10: 1444.21 | R10: 1476.42 | S10: 1489.3 | T10: 1490.78 | U10: 1475.4 | V10: 1528.33 | W10: 1585.13 | X10: 1620.04 | Y10: 1686.02 | Z10: 1605.45 | AA10: 1715.47 | AB10: 1746.09 | AC10: 1631.97 | AD10: 1505.3 | AE10: 1685.25 | AF10: 1499.02 | AG10: 1499.02 | AH10: 1499.02 | AI10: 1499.02 | AK10: 1499.02 | AL10: 1499.02 | AM10: 1499.02 | AN10: 1499.02
A11: EURKRW_end | C11: W/Euro(기말) | E11: 1346.38 | F11: 1346.38 | G11: 1347.37 | H11: 1351.6 | I11: 1400.62 | J11: 1344.08 | K11: 1344.08 | L11: 1420.26 | M11: 1435.88 | N11: 1425.26 | O11: 1433.66 | P11: 1433.66 | Q11: 1458.68 | R11: 1474.86 | S11: 1469.1 | T11: 1532.14 | U11: 1532.14 | V11: 1594.72 | W11: 1588.22 | X11: 1648.04 | Y11: 1696.94 | Z11: 1696.94 | AA11: 1753.21 | AB11: 1767.09 | AC11: 1539.06 | AD11: 1499.02 | AE11: 1499.02 | AF11: 1499.02 | AG11: 1499.02 | AH11: 1499.02 | AI11: 1499.02 | AK11: 1499.02 | AL11: 1499.02 | AM11: 1499.02 | AN11: 1499.02
A12: CNYKRW_avg | C12: 원/중국원(평균) | E12: 185.14 | F12: 177.65 | G12: 189.93 | H12: 190.76 | I12: 195.79 | J12: 191.09 | K12: 191.93 | L12: 186.59 | M12: 187.45 | N12: 181.28 | O12: 182.86 | P12: 184.52 | Q12: 185.04 | R12: 189.35 | S12: 189.24 | T12: 194.24 | U12: 189.49 | V12: 199.63 | W12: 193.41 | X12: 193.79 | Y12: 204.38 | Z12: 197.8 | AA12: 211.75 | AB12: 220.8 | AC12: 210.43 | AD12: 200.38 | AE12: 213.41 | AF12: 199.23 | AG12: 199.23 | AH12: 199.23 | AI12: 199.23 | AK12: 199.23 | AL12: 199.23 | AM12: 199.23 | AN12: 199.23
A13: CNYKRW_end | C13: 원/중국원(기말) | E13: 187.13 | F13: 187.13 | G13: 191.38 | H13: 194.13 | I13: 201.92 | J13: 182.67 | K13: 182.67 | L13: 189.97 | M13: 181.8 | N13: 184.26 | O13: 182.61 | P13: 182.61 | Q13: 186.66 | R13: 189.7 | S13: 187.12 | T13: 202.04 | U13: 202.04 | V13: 203.3 | W13: 189.14 | X13: 197.16 | Y13: 206.28 | Z13: 206.28 | AA13: 220.97 | AB13: 228.56 | AC13: 202.16 | AD13: 199.23 | AE13: 199.23 | AF13: 199.23 | AG13: 199.23 | AH13: 199.23 | AI13: 199.23 | AK13: 199.23 | AL13: 199.23 | AM13: 199.23 | AN13: 199.23
B14: 1b. 종가
A15: price_close_end | C15: 종가(기말) | E15: 2490 | G15: 2460 | H15: 2050 | I15: 1465 | J15: 1520 | L15: 1470 | M15: 3390 | N15: 2830 | O15: 2180 | Q15: 2370 | R15: 2105 | S15: 1935 | T15: 1540 | V15: 1650 | W15: 2825 | X15: 2260 | Y15: 2335 | AA15: 3115 | AB15: 1658 | AC15: 1859 | AD15: 1772
A16: price_high | C16: 종가(최고) | E16: 3275 | G16: 2725 | H16: 2880 | I16: 2400 | J16: 2395 | L16: 1835 | M16: 4030 | N16: 4015 | O16: 2870 | Q16: 2700 | R16: 2600 | S16: 2190 | T16: 1985 | V16: 2185 | W16: 3355 | X16: 3020 | Y16: 3170 | AA16: 4180 | AB16: 3355 | AC16: 2345 | AD16: 1932
A17: price_low | C17: 종가(최저) | E17: 2255 | G17: 1995 | H17: 1940 | I17: 1365 | J17: 1045 | L17: 1305 | M17: 1425 | N17: 2690 | O17: 1990 | Q17: 2000 | R17: 2040 | S17: 1600 | T17: 1460 | V17: 1530 | W17: 1580 | X17: 2010 | Y17: 1976 | AA17: 1800 | AB17: 1554 | AC17: 1348 | AD17: 1562
A18: price_avg | C18: 종가(평균) | E18: 2643.4 | G18: 2334.7 | H18: 2440.5 | I18: 1978.6 | J18: 1571.3 | L18: 1520.3 | M18: 2171.1 | N18: 3187.4 | O18: 2338 | Q18: 2297.1 | R18: 2261.4 | S18: 1929.6 | T18: 1731.6 | V18: 1700.9 | W18: 1980.9 | X18: 2279 | Y18: 2250.2 | AA18: 2469.6 | AB18: 2517.8 | AC18: 1800.6 | AD18: 1808.2
B20: 2. 추정 드라이버 | C20: 실적 열 = subQ 실현값(수식), 추정 열 = 가정(노란 = 모델값 역산, 연녹 = 3절 스칼라 참조)
A21: drv:매출액 | B21: yoy | C21: 매출액 YoY | J21: =IFERROR(subQ!J5/subQ!E5-1,"") | L21: =IFERROR(subQ!L5/subQ!G5-1,"") | M21: =IFERROR(subQ!M5/subQ!H5-1,"") | N21: =IFERROR(subQ!N5/subQ!I5-1,"") | O21: =IFERROR(subQ!O5/subQ!J5-1,"") | Q21: =IFERROR(subQ!Q5/subQ!L5-1,"") | R21: =IFERROR(subQ!R5/subQ!M5-1,"") | S21: =IFERROR(subQ!S5/subQ!N5-1,"") | T21: =IFERROR(subQ!T5/subQ!O5-1,"") | V21: =IFERROR(subQ!V5/subQ!Q5-1,"") | W21: =IFERROR(subQ!W5/subQ!R5-1,"") | X21: =IFERROR(subQ!X5/subQ!S5-1,"") | Y21: =IFERROR(subQ!Y5/subQ!T5-1,"") | AA21: =IFERROR(subQ!AA5/subQ!V5-1,"") | AB21: =IFERROR(subQ!AB5/subQ!W5-1,"") | AC21: 0.20054163 | AD21: 0.38197536 | AF21: 0.047034422 | AG21: 0.20259093 | AH21: 0.1861041 | AI21: 0.16973373 | AK21: 0.18231672 | AL21: 0.20817189 | AM21: 0.23169184 | AN21: 0.23166614
A22: drv:판관비 | B22: ratio | C22: 판관비율(/매출) | E22: =IFERROR(subQ!E8/subQ!E5,"") | F22: =IFERROR(subQ!F8/subQ!F5,"") | G22: =IFERROR(subQ!G8/subQ!G5,"") | H22: =IFERROR(subQ!H8/subQ!H5,"") | I22: =IFERROR(subQ!I8/subQ!I5,"") | J22: =IFERROR(subQ!J8/subQ!J5,"") | K22: =IFERROR(subQ!K8/subQ!K5,"") | L22: =IFERROR(subQ!L8/subQ!L5,"") | ... AB22: =IFERROR(subQ!AB8/subQ!AB5,"") | AC22: =$D$52 | AD22: =$D$52 | AE22: =IFERROR(subQ!AE8/subQ!AE5,"") | AF22: =$D$52 | AG22: =$D$52 | AH22: =$D$52 | AI22: =$D$52 | AJ22: =IFERROR(subQ!AJ8/subQ!AJ5,"") | AK22: =$D$52 | AL22: =$D$52 | AM22: =$D$52 | AN22: =$D$52 | AO22: =IFERROR(subQ!AO8/subQ!AO5,"")
A23: drv:영업이익 | B23: ratio | C23: 영업이익률(OPM) | E23: =IFERROR(subQ!E9/subQ!E5,"") | F23: =IFERROR(subQ!F9/subQ!F5,"") | G23: =IFERROR(subQ!G9/subQ!G5,"") | H23: =IFERROR(subQ!H9/subQ!H5,"") | I23: =IFERROR(subQ!I9/subQ!I5,"") | J23: =IFERROR(subQ!J9/subQ!J5,"") | K23: =IFERROR(subQ!K9/subQ!K5,"") | L23: =IFERROR(subQ!L9/subQ!L5,"") | ... AB23: =IFERROR(subQ!AB9/subQ!AB5,"") | AC23: 0.001213828 | AD23: 0.001221399 | AE23: =IFERROR(subQ!AE9/subQ!AE5,"") | AF23: 0.001213647 | AG23: 0.001232828 | AH23: 0.001228049 | AI23: 0.001218196 | AJ23: =IFERROR(subQ!AJ9/subQ!AJ5,"") | AK23: 0.001216591 | AL23: 0.001239067 | AM23: 0.001229685 | AN23: 0.001215136 | AO23: =IFERROR(subQ!AO9/subQ!AO5,"")
A24: drv:외환손익 | B24: abs | C24: 외환손익 (가정, 억원) | E24: =subQ!E13 | F24: =subQ!F13 | G24: =subQ!G13 | H24: =subQ!H13 | I24: =subQ!I13 | J24: =subQ!J13 | K24: =subQ!K13 | L24: =subQ!L13 | ... AB24: =subQ!AB13 | AC24: 0 | AD24: 0 | AE24: =subQ!AE13 | AF24: 0 | AG24: 0 | AH24: 0 | AI24: 0 | AJ24: =subQ!AJ13 | AK24: 0 | AL24: 0 | AM24: 0 | AN24: 0 | AO24: =subQ!AO13
A25: drv:파생상품손익 | B25: abs | C25: 파생상품손익 (가정, 억원) | E25: =subQ!E14 | F25: =subQ!F14 | G25: =subQ!G14 | H25: =subQ!H14 | I25: =subQ!I14 | J25: =subQ!J14 | K25: =subQ!K14 | L25: =subQ!L14 | ... AB25: =subQ!AB14 | AC25: 0 | AD25: 0 | AE25: =subQ!AE14 | AF25: 0 | AG25: 0 | AH25: 0 | AI25: 0 | AJ25: =subQ!AJ14 | AK25: 0 | AL25: 0 | AM25: 0 | AN25: 0 | AO25: =subQ!AO14
A26: drv:기타금융손익 | B26: abs | C26: 기타금융손익 (가정, 억원) | E26: =subQ!E15 | F26: =subQ!F15 | G26: =subQ!G15 | H26: =subQ!H15 | I26: =subQ!I15 | J26: =subQ!J15 | K26: =subQ!K15 | L26: =subQ!L15 | ... AB26: =subQ!AB15 | AC26: 0 | AD26: 0 | AE26: =subQ!AE15 | AF26: 0 | AG26: 0 | AH26: 0 | AI26: 0 | AJ26: =subQ!AJ15 | AK26: 0 | AL26: 0 | AM26: 0 | AN26: 0 | AO26: =subQ!AO15
A27: drv:기타영업외손익 | B27: abs | C27: 기타영업외손익 (가정, 억원) | E27: =subQ!E16 | F27: =subQ!F16 | G27: =subQ!G16 | H27: =subQ!H16 | I27: =subQ!I16 | J27: =subQ!J16 | K27: =subQ!K16 | L27: =subQ!L16 | ... AB27: =subQ!AB16 | AC27: 0 | AD27: 0 | AE27: =subQ!AE16 | AF27: 0 | AG27: 0 | AH27: 0 | AI27: 0 | AJ27: =subQ!AJ16 | AK27: 0 | AL27: 0 | AM27: 0 | AN27: 0 | AO27: =subQ!AO16
A28: drv:법인세비용 | B28: ratio | C28: 법인세율(/세전) | E28: =IFERROR(subQ!E18/subQ!E17,"") | F28: =IFERROR(subQ!F18/subQ!F17,"") | G28: =IFERROR(subQ!G18/subQ!G17,"") | H28: =IFERROR(subQ!H18/subQ!H17,"") | I28: =IFERROR(subQ!I18/subQ!I17,"") | J28: =IFERROR(subQ!J18/subQ!J17,"") | K28: =IFERROR(subQ!K18/subQ!K17,"") | L28: =IFERROR(subQ!L18/subQ!L17,"") | ... AB28: =IFERROR(subQ!AB18/subQ!AB17,"") | AC28: 0 | AD28: 0 | AE28: =IFERROR(subQ!AE18/subQ!AE17,"") | AF28: 0 | AG28: 0 | AH28: 0 | AI28: 0 | AJ28: =IFERROR(subQ!AJ18/subQ!AJ17,"") | AK28: 0 | AL28: 0 | AM28: 0 | AN28: 0 | AO28: =IFERROR(subQ!AO18/subQ!AO17,"")
A29: drv:지배주주순이익 | B29: ratio | C29: 지배주주 비중(/당기순이익) | E29: =IFERROR(subQ!E20/subQ!E19,"") | F29: =IFERROR(subQ!F20/subQ!F19,"") | G29: =IFERROR(subQ!G20/subQ!G19,"") | H29: =IFERROR(subQ!H20/subQ!H19,"") | I29: =IFERROR(subQ!I20/subQ!I19,"") | J29: =IFERROR(subQ!J20/subQ!J19,"") | K29: =IFERROR(subQ!K20/subQ!K19,"") | L29: =IFERROR(subQ!L20/subQ!L19,"") | ... AB29: =IFERROR(subQ!AB20/subQ!AB19,"") | AC29: =$D$53 | AD29: =$D$53 | AE29: =IFERROR(subQ!AE20/subQ!AE19,"") | AF29: =$D$53 | AG29: =$D$53 | AH29: =$D$53 | AI29: =$D$53 | AJ29: =IFERROR(subQ!AJ20/subQ!AJ19,"") | AK29: =$D$53 | AL29: =$D$53 | AM29: =$D$53 | AN29: =$D$53 | AO29: =IFERROR(subQ!AO20/subQ!AO19,"")
A30: drv:감가상각비 | B30: abs | C30: 감가상각비 (가정, 억원) | E30: =subQ!E21 | F30: =subQ!F21 | G30: =subQ!G21 | H30: =subQ!H21 | I30: =subQ!I21 | J30: =subQ!J21 | K30: =subQ!K21 | L30: =subQ!L21 | ... AB30: =subQ!AB21 | AC30: 2.55 | AD30: 2.55 | AE30: =subQ!AE21 | AF30: 2.55 | AG30: 2.55 | AH30: 2.55 | AI30: 2.55 | AJ30: =subQ!AJ21 | AK30: 2.55 | AL30: 2.55 | AM30: 2.55 | AN30: 2.55 | AO30: =subQ!AO21
A31: drv:부채총계 | B31: qoq | C31: 부채총계 QoQ | G31: =IFERROR(subQ!G24/subQ!E24-1,"") | H31: =IFERROR(subQ!H24/subQ!G24-1,"") | I31: =IFERROR(subQ!I24/subQ!H24-1,"") | J31: =IFERROR(subQ!J24/subQ!I24-1,"") | L31: =IFERROR(subQ!L24/subQ!J24-1,"") | M31: =IFERROR(subQ!M24/subQ!L24-1,"") | N31: =IFERROR(subQ!N24/subQ!M24-1,"") | O31: =IFERROR(subQ!O24/subQ!N24-1,"") | Q31: =IFERROR(subQ!Q24/subQ!O24-1,"") | R31: =IFERROR(subQ!R24/subQ!Q24-1,"") | S31: =IFERROR(subQ!S24/subQ!R24-1,"") | T31: =IFERROR(subQ!T24/subQ!S24-1,"") | V31: =IFERROR(subQ!V24/subQ!T24-1,"") | W31: =IFERROR(subQ!W24/subQ!V24-1,"") | X31: =IFERROR(subQ!X24/subQ!W24-1,"") | Y31: =IFERROR(subQ!Y24/subQ!X24-1,"") | AA31: =IFERROR(subQ!AA24/subQ!Y24-1,"") | AB31: =IFERROR(subQ!AB24/subQ!AA24-1,"") | AC31: -5.27e-07 | AD31: 0 | AF31: 0 | AG31: 0 | AH31: 0 | AI31: 0 | AK31: 0 | AL31: 0 | AM31: 0 | AN31: 0
A32: drv:자본총계 | B32: roll | C32: 자본총계 기타변동(배당 등, 억원) | G32: =IFERROR(subQ!E25+subQ!G19-subQ!G25,"") | H32: =IFERROR(subQ!G25+subQ!H19-subQ!H25,"") | I32: =IFERROR(subQ!H25+subQ!I19-subQ!I25,"") | J32: =IFERROR(subQ!I25+subQ!J19-subQ!J25,"") | L32: =IFERROR(subQ!J25+subQ!L19-subQ!L25,"") | M32: =IFERROR(subQ!L25+subQ!M19-subQ!M25,"") | N32: =IFERROR(subQ!M25+subQ!N19-subQ!N25,"") | O32: =IFERROR(subQ!N25+subQ!O19-subQ!O25,"") | Q32: =IFERROR(subQ!O25+subQ!Q19-subQ!Q25,"") | R32: =IFERROR(subQ!Q25+subQ!R19-subQ!R25,"") | S32: =IFERROR(subQ!R25+subQ!S19-subQ!S25,"") | T32: =IFERROR(subQ!S25+subQ!T19-subQ!T25,"") | V32: =IFERROR(subQ!T25+subQ!V19-subQ!V25,"") | W32: =IFERROR(subQ!V25+subQ!W19-subQ!W25,"") | X32: =IFERROR(subQ!W25+subQ!X19-subQ!X25,"") | Y32: =IFERROR(subQ!X25+subQ!Y19-subQ!Y25,"") | AA32: =IFERROR(subQ!Y25+subQ!AA19-subQ!AA25,"") | AB32: =IFERROR(subQ!AA25+subQ!AB19-subQ!AB25,"") | AC32: 0.003104454 | AD32: -8.7193e-05 | AF32: -0.009884698 | AG32: 0.010116286 | AH32: 8.4064e-05 | AI32: 5.1448e-05 | AK32: 0.000119734 | AL32: 2.026e-05 | AM32: 0.009920667 | AN32: -0.000145049
A33: drv:지배주주지분 | B33: roll | C33: 지배주주지분 기타변동(배당 등, 억원) | G33: =IFERROR(subQ!E26+subQ!G20-subQ!G26,"") | H33: =IFERROR(subQ!G26+subQ!H20-subQ!H26,"") | I33: =IFERROR(subQ!H26+subQ!I20-subQ!I26,"") | J33: =IFERROR(subQ!I26+subQ!J20-subQ!J26,"") | L33: =IFERROR(subQ!J26+subQ!L20-subQ!L26,"") | M33: =IFERROR(subQ!L26+subQ!M20-subQ!M26,"") | N33: =IFERROR(subQ!M26+subQ!N20-subQ!N26,"") | O33: =IFERROR(subQ!N26+subQ!O20-subQ!O26,"") | Q33: =IFERROR(subQ!O26+subQ!Q20-subQ!Q26,"") | R33: =IFERROR(subQ!Q26+subQ!R20-subQ!R26,"") | S33: =IFERROR(subQ!R26+subQ!S20-subQ!S26,"") | T33: =IFERROR(subQ!S26+subQ!T20-subQ!T26,"") | V33: =IFERROR(subQ!T26+subQ!V20-subQ!V26,"") | W33: =IFERROR(subQ!V26+subQ!W20-subQ!W26,"") | X33: =IFERROR(subQ!W26+subQ!X20-subQ!X26,"") | Y33: =IFERROR(subQ!X26+subQ!Y20-subQ!Y26,"") | AA33: =IFERROR(subQ!Y26+subQ!AA20-subQ!AA26,"") | AB33: =IFERROR(subQ!AA26+subQ!AB20-subQ!AB26,"") | AC33: 0.000504454 | AD33: -8.7193e-05 | AF33: 0.000115302 | AG33: 0.000116286 | AH33: 8.4064e-05 | AI33: 5.1448e-05 | AK33: 0.000119734 | AL33: 0.01002026 | AM33: -7.9333e-05 | AN33: -0.000145049
A34: drv:총차입금 | B34: qoq | C34: 총차입금 QoQ | G34: =IFERROR(subQ!G27/subQ!E27-1,"") | H34: =IFERROR(subQ!H27/subQ!G27-1,"") | I34: =IFERROR(subQ!I27/subQ!H27-1,"") | J34: =IFERROR(subQ!J27/subQ!I27-1,"") | L34: =IFERROR(subQ!L27/subQ!J27-1,"") | M34: =IFERROR(subQ!M27/subQ!L27-1,"") | N34: =IFERROR(subQ!N27/subQ!M27-1,"") | O34: =IFERROR(subQ!O27/subQ!N27-1,"") | Q34: =IFERROR(subQ!Q27/subQ!O27-1,"") | R34: =IFERROR(subQ!R27/subQ!Q27-1,"") | S34: =IFERROR(subQ!S27/subQ!R27-1,"") | T34: =IFERROR(subQ!T27/subQ!S27-1,"") | V34: =IFERROR(subQ!V27/subQ!T27-1,"") | W34: =IFERROR(subQ!W27/subQ!V27-1,"") | X34: =IFERROR(subQ!X27/subQ!W27-1,"") | Y34: =IFERROR(subQ!Y27/subQ!X27-1,"") | AA34: =IFERROR(subQ!AA27/subQ!Y27-1,"") | AB34: =IFERROR(subQ!AB27/subQ!AA27-1,"") | AC34: -5.486e-06 | AD34: 0 | AF34: 0 | AG34: 0 | AH34: 0 | AI34: 0 | AK34: 0 | AL34: 0 | AM34: 0 | AN34: 0
A35: drv:순차입금 | B35: qoq | C35: 순차입금 QoQ | G35: =IFERROR(subQ!G28/subQ!E28-1,"") | H35: =IFERROR(subQ!H28/subQ!G28-1,"") | I35: =IFERROR(subQ!I28/subQ!H28-1,"") | J35: =IFERROR(subQ!J28/subQ!I28-1,"") | L35: =IFERROR(subQ!L28/subQ!J28-1,"") | M35: =IFERROR(subQ!M28/subQ!L28-1,"") | N35: =IFERROR(subQ!N28/subQ!M28-1,"") | O35: =IFERROR(subQ!O28/subQ!N28-1,"") | Q35: =IFERROR(subQ!Q28/subQ!O28-1,"") | R35: =IFERROR(subQ!R28/subQ!Q28-1,"") | S35: =IFERROR(subQ!S28/subQ!R28-1,"") | T35: =IFERROR(subQ!T28/subQ!S28-1,"") | V35: =IFERROR(subQ!V28/subQ!T28-1,"") | W35: =IFERROR(subQ!W28/subQ!V28-1,"") | X35: =IFERROR(subQ!X28/subQ!W28-1,"") | Y35: =IFERROR(subQ!Y28/subQ!X28-1,"") | AA35: =IFERROR(subQ!AA28/subQ!Y28-1,"") | AB35: =IFERROR(subQ!AB28/subQ!AA28-1,"") | AC35: 0.010491073 | AD35: 0.010336505 | AF35: 0.010299998 | AG35: 0.010246393 | AH35: 0.010125509 | AI35: 0.009956848 | AK35: 0.009958437 | AL35: 0.009860245 | AM35: 0.009763969 | AN35: 0.009572699
A36: drv:이자발생자산 | B36: qoq | C36: 이자발생자산 QoQ | G36: =IFERROR(subQ!G29/subQ!E29-1,"") | H36: =IFERROR(subQ!H29/subQ!G29-1,"") | I36: =IFERROR(subQ!I29/subQ!H29-1,"") | J36: =IFERROR(subQ!J29/subQ!I29-1,"") | L36: =IFERROR(subQ!L29/subQ!J29-1,"") | M36: =IFERROR(subQ!M29/subQ!L29-1,"") | N36: =IFERROR(subQ!N29/subQ!M29-1,"") | O36: =IFERROR(subQ!O29/subQ!N29-1,"") | Q36: =IFERROR(subQ!Q29/subQ!O29-1,"") | R36: =IFERROR(subQ!R29/subQ!Q29-1,"") | S36: =IFERROR(subQ!S29/subQ!R29-1,"") | T36: =IFERROR(subQ!T29/subQ!S29-1,"") | V36: =IFERROR(subQ!V29/subQ!T29-1,"") | W36: =IFERROR(subQ!W29/subQ!V29-1,"") | X36: =IFERROR(subQ!X29/subQ!W29-1,"") | Y36: =IFERROR(subQ!Y29/subQ!X29-1,"") | AA36: =IFERROR(subQ!AA29/subQ!Y29-1,"") | AB36: =IFERROR(subQ!AB29/subQ!AA29-1,"") | AC36: -0.035924541 | AD36: -0.037009158 | AF36: -0.038822303 | AG36: -0.040458119 | AH36: -0.042163995 | AI36: -0.04379885 | AK36: -0.046190623 | AL36: -0.04842752 | AM36: -0.050807137 | AN36: -0.053168636
A37: drv:현금및현금성자산 | B37: qoq | C37: 현금및현금성자산 QoQ | G37: =IFERROR(subQ!G30/subQ!E30-1,"") | H37: =IFERROR(subQ!H30/subQ!G30-1,"") | I37: =IFERROR(subQ!I30/subQ!H30-1,"") | J37: =IFERROR(subQ!J30/subQ!I30-1,"") | L37: =IFERROR(subQ!L30/subQ!J30-1,"") | M37: =IFERROR(subQ!M30/subQ!L30-1,"") | N37: =IFERROR(subQ!N30/subQ!M30-1,"") | O37: =IFERROR(subQ!O30/subQ!N30-1,"") | Q37: =IFERROR(subQ!Q30/subQ!O30-1,"") | R37: =IFERROR(subQ!R30/subQ!Q30-1,"") | S37: =IFERROR(subQ!S30/subQ!R30-1,"") | T37: =IFERROR(subQ!T30/subQ!S30-1,"") | V37: =IFERROR(subQ!V30/subQ!T30-1,"") | W37: =IFERROR(subQ!W30/subQ!V30-1,"") | X37: =IFERROR(subQ!X30/subQ!W30-1,"") | Y37: =IFERROR(subQ!Y30/subQ!X30-1,"") | AA37: =IFERROR(subQ!AA30/subQ!Y30-1,"") | AB37: =IFERROR(subQ!AB30/subQ!AA30-1,"")
A38: drv:CAPEX | B38: yoy | C38: CAPEX YoY | J38: =IFERROR(subQ!J31/subQ!E31-1,"") | L38: =IFERROR(subQ!L31/subQ!G31-1,"") | M38: =IFERROR(subQ!M31/subQ!H31-1,"") | N38: =IFERROR(subQ!N31/subQ!I31-1,"") | O38: =IFERROR(subQ!O31/subQ!J31-1,"") | Q38: =IFERROR(subQ!Q31/subQ!L31-1,"") | R38: =IFERROR(subQ!R31/subQ!M31-1,"") | S38: =IFERROR(subQ!S31/subQ!N31-1,"") | T38: =IFERROR(subQ!T31/subQ!O31-1,"") | V38: =IFERROR(subQ!V31/subQ!Q31-1,"") | W38: =IFERROR(subQ!W31/subQ!R31-1,"") | X38: =IFERROR(subQ!X31/subQ!S31-1,"") | Y38: =IFERROR(subQ!Y31/subQ!T31-1,"") | AA38: =IFERROR(subQ!AA31/subQ!V31-1,"") | AB38: =IFERROR(subQ!AB31/subQ!W31-1,"") | AC38: 0.93347911 | AD38: -0.66260318 | AF38: 0.088717517 | AG38: -0.074635087 | AH38: 0 | AI38: 0 | AK38: 0 | AL38: 0 | AM38: 0 | AN38: 0
A39: drv:영업활동현금흐름 | B39: yoy | C39: 영업활동현금흐름 YoY | J39: =IFERROR(subQ!J32/subQ!E32-1,"") | L39: =IFERROR(subQ!L32/subQ!G32-1,"") | M39: =IFERROR(subQ!M32/subQ!H32-1,"") | N39: =IFERROR(subQ!N32/subQ!I32-1,"") | O39: =IFERROR(subQ!O32/subQ!J32-1,"") | Q39: =IFERROR(subQ!Q32/subQ!L32-1,"") | R39: =IFERROR(subQ!R32/subQ!M32-1,"") | S39: =IFERROR(subQ!S32/subQ!N32-1,"") | T39: =IFERROR(subQ!T32/subQ!O32-1,"") | V39: =IFERROR(subQ!V32/subQ!Q32-1,"") | W39: =IFERROR(subQ!W32/subQ!R32-1,"") | X39: =IFERROR(subQ!X32/subQ!S32-1,"") | Y39: =IFERROR(subQ!Y32/subQ!T32-1,"") | AA39: =IFERROR(subQ!AA32/subQ!V32-1,"") | AB39: =IFERROR(subQ!AB32/subQ!W32-1,"")
A40: drv:주식수 | B40: qoq | C40: 주식수 QoQ | G40: =IFERROR(subQ!G33/subQ!E33-1,"") | H40: =IFERROR(subQ!H33/subQ!G33-1,"") | I40: =IFERROR(subQ!I33/subQ!H33-1,"") | J40: =IFERROR(subQ!J33/subQ!I33-1,"") | L40: =IFERROR(subQ!L33/subQ!J33-1,"") | M40: =IFERROR(subQ!M33/subQ!L33-1,"") | N40: =IFERROR(subQ!N33/subQ!M33-1,"") | O40: =IFERROR(subQ!O33/subQ!N33-1,"") | Q40: =IFERROR(subQ!Q33/subQ!O33-1,"") | R40: =IFERROR(subQ!R33/subQ!Q33-1,"") | S40: =IFERROR(subQ!S33/subQ!R33-1,"") | T40: =IFERROR(subQ!T33/subQ!S33-1,"") | V40: =IFERROR(subQ!V33/subQ!T33-1,"") | W40: =IFERROR(subQ!W33/subQ!V33-1,"") | X40: =IFERROR(subQ!X33/subQ!W33-1,"") | Y40: =IFERROR(subQ!Y33/subQ!X33-1,"") | AA40: =IFERROR(subQ!AA33/subQ!Y33-1,"") | AB40: =IFERROR(subQ!AB33/subQ!AA33-1,"") | AC40: 0 | AD40: 0 | AF40: 0 | AG40: 0 | AH40: 0 | AI40: 0 | AK40: 0 | AL40: 0 | AM40: 0 | AN40: 0
A41: drv:DPS | B41: abs | C41: DPS (가정, 원) | E41: =subQ!E36 | F41: =subQ!F36 | G41: =subQ!G36 | H41: =subQ!H36 | I41: =subQ!I36 | J41: =subQ!J36 | K41: =subQ!K36 | L41: =subQ!L36 | ... AB41: =subQ!AB36 | AD41: 0 | AE41: =subQ!AE36 | AI41: 0 | AJ41: =subQ!AJ36 | AN41: 0 | AO41: =subQ!AO36
...

Sheet BS연결
B1: (백만원) | C1: 이름: BS연결H | E1: 4Q21 | F1: 2021 | G1: 1Q22 | H1: 2Q22 | I1: 3Q22 | J1: 4Q22 | K1: 2022 | L1: 1Q23 | M1: 2Q23 | N1: 3Q23 | O1: 4Q23 | P1: 2023 | Q1: 1Q24 | R1: 2Q24 | S1: 3Q24 | T1: 4Q24 | U1: 2024 | V1: 1Q25 | W1: 2Q25 | X1: 3Q25 | Y1: 4Q25 | Z1: 2025 | AA1: 1Q26 | AB1: 2Q26 | AC1: 3Q26 | AD1: 4Q26 | AE1: 2026 | AF1: 1Q27 | AG1: 2Q27 | AH1: 3Q27 | AI1: 4Q27 | AJ1: 2027 | AK1: 1Q28 | AL1: 2Q28 | AM1: 3Q28 | AN1: 4Q28 | AO1: 2028
B2: 연결 | D2: fin json(kship_fin.py)
B3: 대창솔루션(연) | C3: UPDATE: 26-10-19 | E3: 1 | F3: 2 | G3: 3 | H3: 4 | I3: 5 | J3: 6 | K3: 7 | L3: 8 | M3: 9 | N3: 10 | O3: 11 | P3: 12 | Q3: 13 | R3: 14 | S3: 15 | T3: 16 | U3: 17 | V3: 18 | W3: 19 | X3: 20 | Y3: 21 | Z3: 22 | AA3: 23 | AB3: 24 | AC3: 25 | AD3: 26 | AE3: 27 | AF3: 28 | AG3: 29 | AH3: 30 | AI3: 31 | AJ3: 32 | AK3: 33 | AL3: 34 | AM3: 35 | AN3: 36 | AO3: 37
B4: Account Code | C4: AccountNAME | E4: 2021.12 | F4: 2021.12A | G4: 2022.03 | H4: 2022.06 | I4: 2022.09 | J4: 2022.12 | K4: 2022.12A | L4: 2023.03 | M4: 2023.06 | N4: 2023.09 | O4: 2023.12 | P4: 2023.12A | Q4: 2024.03 | R4: 2024.06 | S4: 2024.09 | T4: 2024.12 | U4: 2024.12A | V4: 2025.03 | W4: 2025.06 | X4: 2025.09 | Y4: 2025.12 | Z4: 2025.12A | AA4: 2026.03 | AB4: 2026.06 | AC4: 2026.09 | AD4: 2026.12 | AE4: 2026.12A | AF4: 2027.03 | AG4: 2027.06 | AH4: 2027.09 | AI4: 2027.12 | AJ4: 2027.12A | AK4: 2028.03 | AL4: 2028.06 | AM4: 2028.09 | AN4: 2028.12 | AO4: 2028.12A
A5: 1 | C5: 유동자산 | E5: 24556.46 | F5: 24556.46 | G5: 25107.33 | H5: 25596.04 | I5: 26728.68 | J5: 32748.23 | K5: 32748.23 | L5: 33105.99 | M5: 34157.52 | N5: 35131.96 | O5: 33319.96 | P5: 33319.96 | Q5: 39015.31 | R5: 40092.91 | S5: 37252.08 | T5: 40739.03 | U5: 40739.03 | V5: 41302.78 | W5: 43434.69 | X5: 47226.64 | Y5: 47475.46 | Z5: 47475.46 | AA5: 52752.53 | AB5: 55269.5
A6: 1 | C6: 현금및현금성자산 | E6: 5428.9 | F6: 5428.9 | G6: 726.75 | H6: 416.23 | I6: 1551.7 | J6: 1405.13 | K6: 1405.13 | L6: 2859.69 | M6: 2956.34 | N6: 2641.36 | O6: 6154.52 | P6: 6154.52 | Q6: 10783.2 | R6: 9059.81 | S6: 8414.06 | T6: 13311.7 | U6: 13311.7 | V6: 11889.63 | W6: 11018.06 | X6: 15450.44 | Y6: 9331.88 | Z6: 9331.88 | AA6: 11124.41 | AB6: 13491.59
A7: 1 | C7: 단기금융상품 | E7: 1072.61 | F7: 1072.61 | G7: 1120.61 | H7: 1120.61 | I7: 1045.15 | J7: 1600.25 | K7: 1600.25 | L7: 1591.69 | M7: 2650.21 | N7: 2033.27 | O7: 1907.66 | P7: 1907.66 | Q7: 2072.66 | R7: 1916.3 | S7: 1916.3 | T7: 2217.4 | U7: 2217.4 | V7: 1069.4 | W7: 744.82 | X7: 745.82 | Y7: 2832.42 | Z7: 2832.42 | AA7: 2835.42 | AB7: 2838.42
A8: 1 | C8: 단기금융자산 | E8: 1072.61 | F8: 1072.61 | G8: 1120.61 | H8: 1120.61 | I8: 1045.15 | J8: 1600.25 | K8: 1600.25 | L8: 1591.69 | M8: 2650.21 | N8: 2033.27 | O8: 2154.7 | P8: 2154.7 | Q8: 2985.95 | R8: 3115.78 | S8: 3115.78 | T8: 2278.13 | U8: 2278.13 | V8: 1130.13 | W8: 1473.54 | X8: 748.39 | Y8: 2988.9 | Z8: 2988.9 | AA8: 2835.42 | AB8: 2838.42
A9: 1 | C9: 매출채권및기타채권 | E9: 6911.78 | F9: 6911.78 | G9: 8909.25 | H9: 10023.11 | I9: 7712.26 | J9: 13901.61 | K9: 13901.61 | L9: 11008.88 | M9: 9582.27 | N9: 10768.44 | O9: 10251.21 | P9: 10251.21 | Q9: 9947.95 | R9: 13154.73 | S9: 10109.55 | T9: 10924.39 | U9: 10924.39 | V9: 9493.35 | W9: 11565.88 | X9: 9805.72 | Y9: 11937.03 | Z9: 11937.03 | AA9: 15256.88 | AB9: 15939.69
A10: 1 | C10: 계약자산 | E10: 1251.92 | F10: 1251.92 | G10: 3435.05 | H10: 2702.96 | I10: 2898.46 | J10: 2540.01 | K10: 2540.01 | L10: 3657.64 | M10: 3707.98 | N10: 2710.81 | O10: 1748.47 | P10: 1748.47 | Q10: 3592.18 | R10: 2036.5 | S10: 3175.35 | T10: 2410.3 | U10: 2410.3 | V10: 3224.68 | W10: 2636.35 | X10: 2207.72 | Y10: 3023.37 | Z10: 3023.37 | AA10: 3399.35 | AB10: 2265.57
A11: 1 | C11: 당기법인세자산(선급법인세) | E11: 68.21 | F11: 68.21 | G11: 68.73 | H11: 63.1 | I11: 1.38 | J11: 3.2 | K11: 3.2 | L11: 4.16 | M11: 2.3 | N11: 3.36 | O11: 10.69 | P11: 10.69 | Q11: 11.04 | R11: 3.85 | S11: 4.58 | T11: 15.26 | U11: 15.26 | V11: 17.11 | W11: 4.92 | X11: 64.08 | Y11: 64.73 | Z11: 64.73 | AA11: 65.61 | AB11: 6.03
A12: 1 | C12: 재고자산 | E12: 9250.28 | F12: 9250.28 | G12: 9707.44 | H12: 10073.92 | I12: 12175.74 | J12: 12497.23 | K12: 12497.23 | L12: 12566.15 | M12: 13858.95 | N12: 15521.72 | O12: 12362.97 | P12: 12362.97 | Q12: 11200.3 | R12: 12261.6 | S12: 11967.29 | T12: 10649.6 | U12: 10649.6 | V12: 14349.12 | W12: 15757.27 | X12: 16874.57 | Y12: 16671.53 | Z12: 16671.53 | AA12: 17831.5 | AB12: 19118.1
A13: 1 | C13: 기타유동자산 | E13: 572.77 | F13: 572.77 | G13: 1139.5 | H13: 1196.12 | I13: 1344.01 | J13: 800.79 | K13: 800.79 | L13: 1417.77 | M13: 1399.49 | N13: 1453 | O13: 637.4 | P13: 637.4 | Q13: 494.69 | R13: 460.63 | S13: 465.47 | T13: 1149.65 | U13: 1149.65 | V13: 1198.77 | W13: 978.66 | X13: 2075.72 | Y13: 3458.02 | Z13: 3458.02 | AA13: 2239.36 | AB13: 1610.1
A14: 1 | C14: 비유동자산 | E14: 95002.15 | F14: 95002.15 | G14: 94917.05 | H14: 92615.34 | I14: 92892.73 | J14: 91430.13 | K14: 91430.13 | L14: 91280.59 | M14: 91667.57 | N14: 91849.63 | O14: 95501.62 | P14: 95501.62 | Q14: 95312.52 | R14: 95416.67 | S14: 95313.98 | T14: 94689.52 | U14: 94689.52 | V14: 94687.14 | W14: 94336.73 | X14: 94130.47 | Y14: 94357.73 | Z14: 94357.73 | AA14: 94393.23 | AB14: 94157.89
A15: 1 | C15: 장기금융자산 | E15: 2845.82 | F15: 2845.82 | G15: 2988.61 | H15: 1241.54 | I15: 1539.12 | J15: 120.31 | K15: 120.31 | L15: 115.78 | M15: 123.14 | N15: 24.53 | O15: 80.04 | P15: 80.04 | Q15: 80.04 | R15: 24.04 | S15: 63.79 | T15: 377.46 | U15: 377.46 | V15: 407.46 | W15: 287.64 | X15: 297.64 | Y15: 204.04 | Z15: 204.04 | AA15: 204.04 | AB15: 206.04
A16: 1 | C16: 투자자산 | E16: 2845.82 | F16: 2845.82 | G16: 2988.61 | H16: 1241.54 | I16: 1539.12 | J16: 120.31 | K16: 120.31 | L16: 115.78 | M16: 123.14 | N16: 24.53 | O16: 80.04 | P16: 80.04 | Q16: 80.04 | R16: 24.04 | S16: 63.79 | T16: 377.46 | U16: 377.46 | V16: 407.46 | W16: 287.64 | X16: 297.64 | Y16: 204.04 | Z16: 204.04 | AA16: 204.04 | AB16: 206.04
... A24: 1 | C24: 단기차입금 | E24: 51332.92 | F24: 51332.92 | G24: 52448.56 | H24: 51972.01 | I24: 49745.6 | J24: 54192.86 | K24: 54192.86 | L24: 51504.29 | M24: 42180.76 | N24: 46438.65 | O24: 46265.1 | P24: 46265.1 | Q24: 40887.99 | R24: 42834.43 | S24: 41256.15 | T24: 40752.57 | U24: 40752.57 | V24: 39253.75 | W24: 43128.31 | X24: 42633.48 | Y24: 29850.99 | Z24: 29850.99 | AA24: 26648.23 | AB24: 22793.98
A25: 1 | C25: 단기금융부채(face) | E25: 51332.92 | F25: 51332.92 | G25: 52448.56 | H25: 51972.01 | I25: 49745.6 | J25: 54192.86 | K25: 54192.86 | L25: 51504.29 | N25: 46438.65 | O25: 46265.1 | P25: 46265.1 | Q25: 40887.99 | R25: 42834.43 | S25: 41256.15 | T25: 40752.57 | U25: 40752.57 | V25: 39253.75 | W25: 43128.31 | X25: 42633.48 | Y25: 29850.99 | Z25: 29850.99 | AA25: 26648.23 | AB25: 22793.98
A26: 1 | C26: 단기충당부채 | E26: 109.59 | F26: 109.59 | G26: 110.9 | H26: 112.31 | I26: 110.86 | J26: 114.19 | K26: 114.19 | L26: 129.35 | M26: 140.55 | N26: 139.76 | O26: 113.78 | P26: 113.78 | Q26: 94.64 | R26: 95.11 | S26: 92.99 | T26: 100.57 | U26: 100.57 | V26: 113.38 | W26: 140.35 | X26: 152.82 | Y26: 270.49 | Z26: 270.49 | AA26: 424.21 | AB26: 423.09
A27: 1 | C27: 기타유동금융부채 | E27: 3244.45 | F27: 3244.45 | G27: 4142.7 | H27: 2868.12 | I27: 2536.4 | J27: 4350.92 | K27: 4350.92 | L27: 3438.54 | M27: 3765.69 | N27: 5272 | O27: 3243.43 | P27: 3243.43 | Q27: 3458.77 | R27: 3320.74 | S27: 2426.72 | T27: 3399.62 | U27: 3399.62 | V27: 2871.38 | W27: 2949.69 | X27: 4209.74 | Y27: 3835.66 | Z27: 3835.66 | AA27: 3171.59 | AB27: 3870.1
A28: 1 | C28: 단기금융부채 | E28: 3303.28 | F28: 3303.28 | G28: 4201.53 | H28: 2888.73 | I28: 2557.01 | J28: 4413.71 | K28: 4413.71 | L28: 3501.33 | M28: 3826.35 | N28: 5332.66 | O28: 7335.62 | P28: 7335.62 | Q28: 14812.56 | R28: 12118.3 | S28: 11223.98 | T28: 8350.93 | U28: 8350.93 | V28: 7822.69 | W28: 6539.55 | X28: 6350.99 | Y28: 6640.13 | Z28: 6640.13 | AA28: 5362.9 | AB28: 6251.13
A29: 1 | C29: 기타유동부채 | E29: 1502.21 | F29: 1502.21 | G29: 1623.16 | H29: 2982.48 | I29: 6820.91 | J29: 11000.85 | K29: 11000.85 | L29: 11155.01 | M29: 8996.44 | N29: 7797.03 | O29: 1997.42 | P29: 1997.42 | Q29: 1769.84 | R29: 2097.24 | S29: 2412.67 | T29: 1215.93 | U29: 1215.93 | V29: 1957.73 | W29: 999.66 | X29: 743.96 | Y29: 542.61 | Z29: 542.61 | AA29: 707.22 | AB29: 2242.44
A30: 1 | C30: 유동리스부채 | E30: 58.83 | F30: 58.83 | G30: 58.83 | H30: 20.61 | I30: 20.61 | J30: 62.79 | K30: 62.79 | L30: 62.79 | M30: 60.66 | N30: 60.66 | O30: 66.63 | P30: 66.63 | Q30: 66.63 | R30: 62.7 | S30: 62.4 | T30: 59.64 | U30: 59.64 | V30: 59.64 | W30: 57.31 | X30: 57.31 | Y30: 66.2 | Z30: 66.2 | AA30: 58.38 | AB30: 37.07
A31: 1 | C31: 리스부채 | E31: 108.97 | F31: 108.97 | G31: 108.97 | H31: 48.19 | I31: 48.19 | J31: 205.37 | K31: 205.37 | L31: 205.37 | M31: 162.68 | N31: 162.68 | O31: 150.73 | P31: 150.73 | Q31: 150.73 | R31: 115.99 | S31: 120.09 | T31: 101.1 | U31: 101.1 | V31: 101.1 | W31: 70.08 | X31: 70.08 | Y31: 166.95 | Z31: 166.95 | AA31: 159.13 | AB31: 105.63
A32: 1 | C32: 비유동부채 | E32: 19232.54 | F32: 19232.54 | G32: 18521.63 | H32: 18257.56 | I32: 21361.99 | J32: 14406.7 | K32: 14406.7 | L32: 16448.86 | M32: 16529.91 | N32: 20206.43 | O32: 26199.09 | P32: 26199.09 | Q32: 32410.84 | R32: 32482.39 | S32: 33895.31 | T32: 29803.9 | U32: 29803.9 | V32: 31847.4 | W32: 28803.96 | X32: 29175.87 | Y32: 43370.69 | Z32: 43370.69 | AA32: 51469.09 | AB32: 53368.58
A33: 1 | C33: 장기차입금 | E33: 9378.89 | F33: 9378.89 | G33: 8701.68 | H33: 8350.04 | I33: 11341.84 | J33: 4815.38 | K33: 4815.38 | L33: 6828.81 | M33: 6879.59 | N33: 10437.41 | O33: 10090.68 | P33: 10090.68 | Q33: 11803.64 | R33: 11608.29 | S33: 13138.43 | T33: 18409.27 | U33: 18409.27 | V33: 20251.36 | W33: 17157.01 | X33: 16932.57 | Y33: 30870 | Z33: 30870 | AA33: 38870 | AB33: 41720
A34: 1 | C34: 확정급여부채 | E34: 2632.13 | F34: 2632.13 | G34: 2762.22 | H34: 2831.3 | I34: 2926.69 | J34: 2573.94 | K34: 2573.94 | L34: 2652.66 | M34: 2642.67 | N34: 2703.26 | O34: 3272.71 | P34: 3272.71 | Q34: 3309.65 | R34: 3400.14 | S34: 3300.73 | T34: 2729.14 | U34: 2729.14 | V34: 2901.24 | W34: 2955.03 | X34: 3091.18 | Y34: 2888.72 | Z34: 2888.72 | AA34: 2959.22 | AB34: 2010.52
A35: 1 | C35: 이연법인세부채 | E35: 6160.52 | F35: 6160.52 | G35: 6160.52 | H35: 6160.52 | I35: 6160.52 | J35: 5880.5 | K35: 5880.5 | L35: 5880.5 | M35: 5880.5 | N35: 5880.5 | O35: 6848.58 | P35: 6848.58 | Q35: 6848.58 | R35: 6848.58 | S35: 6848.58 | T35: 6848.58 | U35: 6848.58 | V35: 6848.58 | W35: 6848.58 | X35: 6848.58 | Y35: 7187.47 | Z35: 7187.47 | AA35: 7187.47 | AB35: 7187.47
A36: 1 | C36: 기타비유동금융부채 | E36: 640.54 | F36: 640.54 | G36: 476.75 | H36: 517.8 | I36: 535.03 | J36: 876.82 | K36: 876.82 | L36: 826.82 | M36: 907.64 | N36: 965.74 | O36: 1052.92 | P36: 1052.92 | Q36: 1083.06 | R36: 1141.5 | S36: 911.51 | T36: 975.46 | U36: 975.46 | V36: 1004.77 | W36: 1030.57 | X36: 1090.77 | Y36: 1123.74 | Z36: 1123.74 | AA36: 1151.65 | AB36: 1182.03
A37: 1 | C37: 장기금융부채 | E37: 943.52 | F37: 943.52 | G37: 779.73 | H37: 798.22 | I37: 815.45 | J37: 1019.4 | K37: 1019.4 | L37: 969.4 | M37: 1009.66 | N37: 1067.76 | O37: 1137.02 | P37: 1137.02 | Q37: 1167.16 | R37: 1194.79 | S37: 969.2 | T37: 1016.92 | U37: 1016.92 | V37: 1046.23 | W37: 1043.34 | X37: 1103.54 | Y37: 1224.49 | Z37: 1224.49 | AA37: 1252.4 | AB37: 1250.59
... A39: 1 | C39: 비유동리스부채 | E39: 50.14 | F39: 50.14 | G39: 50.14 | H39: 27.58 | I39: 27.58 | J39: 142.58 | K39: 142.58 | L39: 142.58 | M39: 102.02 | N39: 102.02 | O39: 84.1 | P39: 84.1 | Q39: 84.1 | R39: 53.29 | S39: 57.69 | T39: 41.46 | U39: 41.46 | V39: 41.46 | W39: 12.77 | X39: 12.77 | Y39: 100.75 | Z39: 100.75 | AA39: 100.75 | AB39: 68.56
A40: 1 | C40: 장기파생상품부채 | E40: 252.84 | F40: 252.84 | G40: 252.84 | H40: 252.84 | I40: 252.84 | J40: 0 | K40: 0 | L40: 0 | O40: 0 | P40: 0 | T40: 0 | U40: 0 | V40: 0
A41: 1 | C41: 부채총계 | E41: 82707.19 | F41: 82707.19 | G41: 85322.46 | H41: 85693.54 | I41: 88946.36 | J41: 95237.19 | K41: 95237.19 | L41: 93989.89 | M41: 94071.64 | N41: 94430.52 | O41: 93059.26 | P41: 93059.26 | Q41: 98110.65 | R41: 97877.93 | S41: 96449.3 | T41: 102592.31 | U41: 102592.31 | V41: 104939.66 | W41: 102926.03 | X41: 104238.37 | Y41: 105830.49 | Z41: 105830.49 | AA41: 110121.63 | AB41: 113884.06
A42: 1 | C42: 지배주주지분 | E42: 33482.84 | F42: 33482.84 | G42: 31628.7 | H42: 29813.69 | I42: 28119.57 | J42: 26364.39 | K42: 26364.39 | L42: 27653.41 | M42: 28952.89 | N42: 28731.43 | O42: 30125.66 | P42: 30125.66 | Q42: 30514.6 | R42: 31545.53 | S42: 30393.07 | T42: 26838.75 | U42: 26838.75 | V42: 25563.18 | W42: 30000.5 | X42: 31932.96 | Y42: 31339.35 | Z42: 31339.35 | AA42: 32128.31 | AB42: 31682.07
A43: 1 | C43: 자본금 | E43: 62161.14 | F43: 62161.14 | G43: 62161.14 | H43: 62161.14 | I43: 62161.14 | J43: 62161.14 | K43: 62161.14 | L43: 62161.14 | M43: 62161.14 | N43: 62161.14 | O43: 62161.14 | P43: 62161.14 | Q43: 62161.14 | R43: 62161.14 | S43: 62161.14 | T43: 62161.14 | U43: 62161.14 | V43: 62161.14 | W43: 71804.96 | X43: 73412.66 | Y43: 73412.66 | Z43: 73412.66 | AA43: 73412.66 | AB43: 73412.66
A44: 1 | C44: 보통주자본금 | E44: 16376.1 | F44: 16376.1 | G44: 16376.1 | H44: 16376.1 | I44: 16376.1 | J44: 16376.1 | K44: 16376.1 | L44: 16376.1 | M44: 16376.1 | N44: 16376.1 | O44: 16376.1 | P44: 16376.1 | Q44: 16376.1 | R44: 16376.1 | S44: 16376.1 | T44: 16376.1 | U44: 16376.1 | V44: 16376.1 | W44: 18017.13 | X44: 18427.38 | Y44: 18427.38 | Z44: 18427.38 | AA44: 18427.38 | AB44: 18427.38
A45: 1 | C45: 자본잉여금 | E45: 45785.04 | F45: 45785.04 | G45: 45785.04 | H45: 45785.04 | I45: 45785.04 | J45: 45785.04 | K45: 45785.04 | L45: 45785.04 | M45: 45785.04 | N45: 45785.04 | O45: 45785.04 | P45: 45785.04 | Q45: 45785.04 | R45: 45785.04 | S45: 45785.04 | T45: 45785.04 | U45: 45785.04 | V45: 45785.04 | W45: 53787.83 | X45: 54985.27 | Y45: 54985.27 | Z45: 54985.27 | AA45: 54985.27 | AB45: 54985.27
A46: 1 | C46: 이익잉여금 | E46: -39726.59 | F46: -39726.59 | G46: -41692.51 | H46: -42120.45 | I46: -43807.91 | J46: -45013.72 | K46: -45013.72 | L46: -43720.17 | M46: -42428.06 | N46: -42578.49 | O46: -43175.28 | P46: -43175.28 | Q46: -42788.67 | R46: -41786.77 | S46: -42914.49 | T46: -46469.31 | U46: -46469.31 | V46: -47745.01 | W46: -52976.75 | X46: -52676.73 | Y46: -52969.67 | Z46: -52969.67 | AA46: -52161.79 | AB46: -52594.9
A47: 1 | C47: 기타포괄이익누계액 | E47: 934.99 | F47: 934.99
A48: 1 | C48: 기타자본 | E48: 10113.3 | F48: 10113.3 | G48: 11160.07 | H48: 9773 | I48: 9766.34 | J48: 9216.97 | K48: 9216.97 | L48: 9212.44 | M48: 9219.81 | N48: 9148.78 | O48: 11139.8 | P48: 11139.8 | Q48: 11142.14 | R48: 11171.17 | S48: 11146.42 | T48: 11146.92 | U48: 11146.92 | V48: 11147.05 | W48: 11172.3 | X48: 11197.03 | Y48: 10896.37 | Z48: 10896.37 | AA48: 10877.45 | AB48: 10864.32
...

Sheet BS별도
B1: (백만원) | C1: 이름: BS별도H | E1: 4Q21 | F1: 2021 | G1: 1Q22 | H1: 2Q22 | I1: 3Q22 | J1: 4Q22 | K1: 2022 | L1: 1Q23 | M1: 2Q23 | N1: 3Q23 | O1: 4Q23 | P1: 2023 | Q1: 1Q24 | R1: 2Q24 | S1: 3Q24 | T1: 4Q24 | U1: 2024 | V1: 1Q25 | W1: 2Q25 | X1: 3Q25 | Y1: 4Q25 | Z1: 2025 | AA1: 1Q26 | AB1: 2Q26 | AC1: 3Q26 | AD1: 4Q26 | AE1: 2026 | AF1: 1Q27 | AG1: 2Q27 | AH1: 3Q27 | AI1: 4Q27 | AJ1: 2027 | AK1: 1Q28 | AL1: 2Q28 | AM1: 3Q28 | AN1: 4Q28 | AO1: 2028
B2: 별도 | D2: fin json(kship_fin.py)
B3: 대창솔루션(별) | C3: UPDATE: 26-10-19 | E3: 1 | F3: 2 | G3: 3 | H3: 4 | I3: 5 | J3: 6 | K3: 7 | L3: 8 | M3: 9 | N3: 10 | O3: 11 | P3: 12 | Q3: 13 | R3: 14 | S3: 15 | T3: 16 | U3: 17 | V3: 18 | W3: 19 | X3: 20 | Y3: 21 | Z3: 22 | AA3: 23 | AB3: 24 | AC3: 25 | AD3: 26 | AE3: 27 | AF3: 28 | AG3: 29 | AH3: 30 | AI3: 31 | AJ3: 32 | AK3: 33 | AL3: 34 | AM3: 35 | AN3: 36 | AO3: 37
B4: Account Code | C4: AccountNAME | E4: 2021.12 | F4: 2021.12A | G4: 2022.03 | H4: 2022.06 | I4: 2022.09 | J4: 2022.12 | K4: 2022.12A | L4: 2023.03 | M4: 2023.06 | N4: 2023.09 | O4: 2023.12 | P4: 2023.12A | Q4: 2024.03 | R4: 2024.06 | S4: 2024.09 | T4: 2024.12 | U4: 2024.12A | V4: 2025.03 | W4: 2025.06 | X4: 2025.09 | Y4: 2025.12 | Z4: 2025.12A | AA4: 2026.03 | AB4: 2026.06 | AC4: 2026.09 | AD4: 2026.12 | AE4: 2026.12A | AF4: 2027.03 | AG4: 2027.06 | AH4: 2027.09 | AI4: 2027.12 | AJ4: 2027.12A | AK4: 2028.03 | AL4: 2028.06 | AM4: 2028.09 | AN4: 2028.12 | AO4: 2028.12A
A5: 1 | C5: 유동자산 | E5: 18677.58 | F5: 18677.58 | G5: 18202.69 | H5: 18248.66 | I5: 18928.89 | J5: 19963.15 | K5: 19963.15 | L5: 20970.85 | M5: 20032.28 | N5: 21634.07 | O5: 24290.13 | P5: 24290.13 | Q5: 19836.79 | R5: 21608.09 | S5: 20945.45 | T5: 21373.36 | U5: 21373.36 | V5: 24151.67 | W5: 26697.05 | X5: 27654.31 | Y5: 29473.65 | Z5: 29473.65 | AA5: 32899.96 | AB5: 37546.4
A6: 1 | C6: 현금및현금성자산 | E6: 113.94 | F6: 113.94 | G6: 329.76 | H6: 261.9 | I6: 665.05 | J6: 1176.05 | K6: 1176.05 | L6: 123.5 | M6: 95.03 | N6: 955.15 | O6: 3398.27 | P6: 3398.27 | Q6: 226.09 | R6: 2446.43 | S6: 1485.81 | T6: 2970.44 | U6: 2970.44 | V6: 1748.68 | W6: 1859.65 | X6: 2788.58 | Y6: 45.69 | Z6: 45.69 | AA6: 1053.7 | AB6: 6655.07
A7: 1 | C7: 단기금융상품 | E7: 963.85 | F7: 963.85 | G7: 1011.85 | H7: 1011.85 | I7: 1011.85 | J7: 1081.85 | K7: 1081.85 | L7: 720.85 | M7: 726.36 | N7: 726.36 | O7: 726.36 | P7: 726.36 | Q7: 726.36 | R7: 570 | S7: 570 | T7: 570 | U7: 570 | V7: 570 | W7: 570 | X7: 571 | Y7: 574 | Z7: 574 | AA7: 577 | AB7: 580
A8: 1 | C8: 단기금융자산 | E8: 963.85 | F8: 963.85 | G8: 1011.85 | H8: 1011.85 | I8: 1011.85 | J8: 1081.85 | K8: 1081.85 | L8: 720.85 | M8: 726.36 | N8: 726.36 | O8: 973.4 | P8: 973.4 | Q8: 973.4 | R8: 1160.39 | S8: 1160.39 | T8: 627.44 | U8: 627.44 | V8: 627.44 | W8: 1296.15 | X8: 571 | Y8: 2408.84 | Z8: 2408.84 | AA8: 577 | AB8: 580
A9: 1 | C9: 매출채권및기타채권 | E9: 8074.28 | F9: 8074.28 | G9: 7342.91 | H9: 7950.46 | I9: 6722.98 | J9: 7205.56 | K9: 7205.56 | L9: 8671.49 | M9: 7259.96 | N9: 5561.68 | O9: 8503.21 | P9: 8503.21 | Q9: 8167.23 | R9: 6741.54 | S9: 7510.49 | T9: 7281.81 | U9: 7281.81 | V9: 6771.1 | W9: 7711.25 | X9: 7050.66 | Y9: 10590.19 | Z9: 10590.19 | AA9: 12739.95 | AB9: 11708.56
A10: 1 | C10: 단기투자자산(공정가치) | E10: 540 | F10: 540 | G10: 540 | H10: 0 | I10: 0 | J10: 0 | K10: 0 | L10: 0 | O10: 0 | P10: 0 | Q10: 0 | T10: 0 | U10: 0 | V10: 0
A11: 1 | C11: 당기법인세자산(선급법인세) | E11: 67.91 | F11: 67.91 | G11: 68.39 | H11: 62.5 | I11: 0.76 | J11: 2.43 | K11: 2.43 | L11: 2.43 | M11: 1 | N11: 1 | O11: 3.91 | P11: 3.91 | Q11: 3.91 | R11: 1.97 | S11: 1.97 | T11: 4.33 | U11: 4.33 | V11: 4.33 | W11: 1.34 | X11: 59.89 | Y11: 0 | Z11: 0 | AA11: 60.35 | AB11: 5.03
A12: 1 | C12: 재고자산 | E12: 8406.53 | F12: 8406.53 | G12: 7889.06 | H12: 7993.33 | I12: 9336.39 | J12: 9808.07 | K12: 9808.07 | L12: 10142.22 | M12: 10637.54 | N12: 13134.02 | O12: 10826.21 | P12: 10826.21 | Q12: 10034.62 | R12: 10898.72 | S12: 10389.95 | T12: 9696.68 | U12: 9696.68 | V12: 14019.08 | W12: 15226.78 | X12: 16687.53 | Y12: 59.89 | Z12: 59.89 | AA12: 17164.38 | AB12: 17301.55
A13: 1 | C13: 기타유동자산 | E13: 511.07 | F13: 511.07 | G13: 1020.71 | H13: 968.61 | I13: 1191.85 | J13: 689.2 | K13: 689.2 | L13: 1310.36 | M13: 1312.37 | N13: 1255.85 | O13: 585.13 | P13: 585.13 | Q13: 431.53 | R13: 359.04 | S13: 396.82 | T13: 792.66 | U13: 792.66 | V13: 981.05 | W13: 601.88 | X13: 496.66 | Y13: 16369.04 | Z13: 16369.04 | AA13: 1304.58 | AB13: 1296.19
A14: 1 | C14: 비유동자산 | E14: 76723.96 | F14: 76723.96 | G14: 76693.25 | H14: 73701.87 | I14: 73730.03 | J14: 72627.62 | K14: 72627.62 | L14: 72425.27 | M14: 72239.42 | N14: 72334.97 | O14: 71397.79 | P14: 71397.79 | Q14: 71215.76 | R14: 71027.22 | S14: 70967.96 | T14: 70627.26 | U14: 70627.26 | V14: 70527.99 | W14: 70415.42 | X14: 70248.67 | Y14: 70292.53 | Z14: 70292.53 | AA14: 70171.67 | AB14: 70151.15
A15: 1 | C15: 장기금융자산 | E15: 2178.8 | F15: 2178.8 | G15: 2321.59 | H15: 574.52 | I15: 597.86 | J15: 108.57 | K15: 108.57 | L15: 104.04 | M15: 111.4 | N15: 136.8 | O15: 135.79 | P15: 135.79 | Q15: 135.79 | R15: 135.79 | S15: 135.79 | T15: 335.79 | U15: 335.79 | V15: 335.79 | W15: 335.79 | X15: 345.79 | Y15: 354.52 | Z15: 354.52 | AA15: 413.2 | AB15: 444.04
A16: 1 | C16: 투자자산 | E16: 4531.32 | F16: 4531.32 | G16: 4674.11 | H16: 2226.24 | I16: 2249.58 | J16: 1314.25 | K16: 1314.25 | L16: 1309.72 | M16: 1317.08 | N16: 1342.48 | O16: 1341.47 | P16: 1341.47 | Q16: 1341.47 | R16: 1341.47 | S16: 1341.47 | T16: 1541.47 | U16: 1541.47 | V16: 1541.47 | W16: 1541.47 | X16: 1551.47 | Y16: 1560.2 | Z16: 1560.2 | AA16: 1618.88 | AB16: 1649.72
A17: 1 | C17: 종속기업및관계기업투자 | E17: 2352.52 | F17: 2352.52 | G17: 2352.52 | H17: 1651.72 | I17: 1651.72 | J17: 1205.68 | K17: 1205.68 | L17: 1205.68 | M17: 1205.68 | N17: 1205.68 | O17: 1205.68 | P17: 1205.68 | Q17: 1205.68 | R17: 1205.68 | S17: 1205.68 | T17: 1205.68 | U17: 1205.68 | V17: 1205.68 | W17: 1205.68 | X17: 1205.68 | Y17: 1205.68 | Z17: 1205.68 | AA17: 1205.68 | AB17: 1205.68
A18: 1 | C18: 유형자산 | E18: 69666.69 | F18: 69666.69 | G18: 69494.68 | H18: 69320.75 | I18: 69224.57 | J18: 69045.79 | K18: 69045.79 | L18: 68899.6 | M18: 68720.06 | N18: 68768.76 | O18: 68571.86 | P18: 68571.86 | Q18: 68416.85 | R18: 68229.25 | S18: 68228.4 | T18: 67844.67 | U18: 67844.67 | V18: 67749.77 | W18: 67596.16 | X18: 67401.06 | Y18: 67493.95 | Z18: 67493.95 | AA18: 67324.39 | AB18: 67248.14
A19: 1 | C19: 사용권자산 | E19: 162.78 | F19: 162.78 | G19: 162.78 | H19: 72.88 | I19: 72.88 | J19: 485.82 | K19: 485.82 | L19: 485.82 | M19: 412.86 | N19: 412.86 | O19: 352.71 | P19: 352.71 | Q19: 352.71 | R19: 293.09 | S19: 293.09 | T19: 264.16 | U19: 264.16 | V19: 264.16 | W19: 204.92 | X19: 204.92 | Y19: 147.49 | Z19: 147.49 | AA19: 147.49 | AB19: 148.04
A20: 1 | C20: 기타비유동자산 | E20: 248.61 | F20: 248.61 | G20: 259.1 | H20: 230.89 | I20: 331.9 | J20: 709.39 | K20: 709.39 | L20: 685.34 | M20: 672.5 | N20: 691.56 | O20: 655.68 | P20: 655.68 | Q20: 626.32 | R20: 594.55 | S20: 560.89 | T20: 493.87 | U20: 493.87 | V20: 489.38 | W20: 503.21 | X20: 506.82 | Y20: 441.56 | Z20: 441.56 | AA20: 450.49 | AB20: 443.84
A21: 1 | C21: 무형자산 | E21: 927.59 | F21: 927.59 | G21: 927.59 | H21: 588.03 | I21: 588.03 | J21: 588.03 | K21: 588.03 | L21: 588.03 | M21: 588.03 | N21: 588.03 | O21: 588.03 | P21: 588.03 | Q21: 588.03 | R21: 588.03 | S21: 588.03 | T21: 496.05 | U21: 496.05 | V21: 496.05 | W21: 496.05 | X21: 496.05 | Y21: 496.05 | Z21: 496.05 | AA21: 496.05 | AB21: 496.05
A22: 1 | C22: 자산총계 | E22: 95401.54 | F22: 95401.54 | G22: 94895.94 | H22: 91950.52 | I22: 92658.92 | J22: 92590.76 | K22: 92590.76 | L22: 93396.12 | M22: 92271.69 | N22: 93969.04 | O22: 95687.93 | P22: 95687.93 | Q22: 91052.55 | R22: 92635.3 | S22: 91913.41 | T22: 92000.63 | U22: 92000.63 | V22: 94679.66 | W22: 97112.47 | X22: 97902.98 | Y22: 99766.18 | Z22: 99766.18 | AA22: 103071.63 | AB22: 107697.56
... A25: 1 | C25: 단기차입금 | E25: 37957.05 | F25: 37957.05 | G25: 39126.71 | H25: 37978.65 | I25: 36879.24 | J25: 40443 | K25: 40443 | L25: 37802.33 | M25: 29525.9 | N25: 33707.73 | O25: 33463.14 | P25: 33463.14 | Q25: 28465.55 | R25: 30472.86 | S25: 29790.74 | T25: 29137.02 | U25: 29137.02 | V25: 29807.75 | W25: 34098.31 | X25: 34003.48 | Y25: 21220.99 | Z25: 21220.99 | AA25: 20318.23 | AB25: 16793.98
A26: 1 | C26: 단기금융부채(face) | E26: 37957.05 | F26: 37957.05 | G26: 39126.71 | H26: 37978.65 | I26: 36879.24 | J26: 40443 | K26: 40443 | L26: 37802.33 | N26: 33707.73 | O26: 33463.14 | P26: 33463.14 | Q26: 28465.55 | R26: 30472.86 | S26: 29790.74 | T26: 29137.02 | U26: 29137.02 | V26: 29807.75 | W26: 34098.31 | X26: 34003.48 | Y26: 21220.99 | Z26: 21220.99 | AA26: 20318.23 | AB26: 16793.98
A27: 1 | C27: 단기충당부채 | E27: 109.59 | F27: 109.59 | G27: 110.9 | H27: 112.31 | I27: 110.86 | J27: 114.19 | K27: 114.19 | L27: 129.35 | M27: 140.55 | N27: 139.76 | O27: 113.78 | P27: 113.78 | Q27: 94.64 | R27: 95.11 | S27: 92.99 | T27: 100.57 | U27: 100.57 | V27: 2104.99 | W27: 140.35 | X27: 152.82 | Y27: 2871.87 | Z27: 2871.87 | AA27: 424.21 | AB27: 423.09
A28: 1 | C28: 기타유동금융부채 | E28: 1572.83 | F28: 1572.83 | G28: 2504.43 | H28: 1635.19 | I28: 1624.62 | J28: 2806.7 | K28: 2806.7 | L28: 2135.69 | M28: 2077.03 | N28: 4315.38 | O28: 2394.22 | P28: 2394.22 | Q28: 1953.7 | R28: 1975.32 | S28: 1780.87 | T28: 2242.18 | U28: 2242.18 | V28: 2916.14 | W28: 2139.37 | X28: 2943.16 | Y28: 5214.62 | Z28: 5214.62 | AA28: 2315.25 | AB28: 3208.87
A29: 1 | C29: 단기금융부채 | E29: 1687.55 | F29: 1687.55 | G29: 2619.15 | H29: 1681.47 | I29: 1670.9 | J29: 2918.41 | K29: 2918.41 | L29: 2247.4 | M29: 2187.96 | N29: 4426.31 | O29: 6529.73 | P29: 6529.73 | Q29: 6089.21 | R29: 4752.54 | S29: 4558.09 | T29: 5024.8 | U29: 5024.8 | V29: 9755.06 | W29: 3701.37 | X29: 3056.55 | Y29: 5214.62 | Z29: 5214.62 | AA29: 2407.4 | AB29: 3307.91
A30: 1 | C30: 기타유동부채 | E30: 816.95 | F30: 816.95 | G30: 171.06 | H30: 1355.59 | I30: 4177.82 | J30: 6694.66 | K30: 6694.66 | L30: 7257.64 | M30: 4876.02 | N30: 4091.58 | O30: 834.69 | P30: 834.69 | Q30: 261.52 | R30: 174.07 | S30: 617.16 | T30: 985.51 | U30: 985.51 | V30: 114.21 | W30: 2907.4 | X30: 3803.11 | Y30: 92.15 | Z30: 92.15 | AA30: 4760.93 | AB30: 9675.9
A31: 1 | C31: 유동리스부채 | E31: 114.72 | F31: 114.72 | G31: 114.72 | H31: 46.28 | I31: 46.28 | J31: 111.71 | K31: 111.71 | L31: 111.71 | M31: 110.93 | N31: 110.93 | O31: 109.95 | P31: 109.95 | Q31: 109.95 | R31: 107.15 | S31: 107.15 | T31: 114.21 | U31: 114.21 | V31: 4170.51 | W31: 113.39 | X31: 113.39 | Y31: 0 | Z31: 0 | AA31: 92.15 | AB31: 99.04
A32: 1 | C32: 리스부채 | E32: 164.86 | F32: 164.86 | G32: 164.86 | H32: 73.86 | I32: 73.86 | J32: 473.83 | K32: 473.83 | L32: 473.83 | M32: 407 | N32: 407 | O32: 352.19 | P32: 352.19 | Q32: 352.19 | R32: 296.07 | S32: 296.07 | T32: 268.97 | U32: 268.97 | V32: 4325.27 | W32: 211.04 | X32: 211.04 | Y32: 62.72 | Z32: 62.72 | AA32: 154.87 | AB32: 154.11
A33: 1 | C33: 비유동부채 | E33: 15806.65 | F33: 15806.65 | G33: 15029.39 | H33: 14313.79 | I33: 14032.17 | J33: 8547.91 | K33: 8547.91 | L33: 10575.24 | M33: 10774.28 | N33: 14414.99 | O33: 19441.82 | P33: 19441.82 | Q33: 21217.18 | R33: 20914.62 | S33: 21558.47 | T33: 21032.05 | U33: 21032.05 | V33: 20943.53 | W33: 17874.09 | X33: 18265.98 | Y33: 32302.5 | Z33: 32302.5 | AA33: 34473.21 | AB33: 35975.53
A34: 1 | C34: 장기차입금 | E34: 8406.88 | F34: 8406.88 | G34: 7684.35 | H34: 6917.44 | I34: 6534.23 | J34: 882.76 | K34: 882.76 | L34: 2921.18 | M34: 2996.95 | N34: 6579.76 | O34: 6258.02 | P34: 6258.02 | Q34: 11447.32 | R34: 7792.29 | S34: 8850.6 | T34: 11600.33 | U34: 11600.33 | V34: 11311.36 | W34: 8217.01 | X34: 7992.57 | Y34: 21930 | Z34: 21930 | AA34: 23930 | AB34: 26780
A35: 1 | C35: 확정급여부채 | E35: 2085.99 | F35: 2085.99 | G35: 2195.05 | H35: 2227.88 | I35: 2312.22 | J35: 2007.92 | K35: 2007.92 | L35: 2046.82 | M35: 2155.31 | N35: 2155.1 | O35: 2737.71 | P35: 2737.71 | Q35: 2726.26 | R35: 2810.74 | S35: 2711.75 | T35: 3200.69 | U35: 3200.69 | V35: 3371.83 | W35: 3428.04 | X35: 3584.17 | Y35: 3480.42 | Z35: 3480.42 | AA35: 3623.23 | AB35: 2252.82
A36: 1 | C36: 이연법인세부채 | E36: 4505.62 | F36: 4505.62 | G36: 4505.62 | H36: 4505.62 | I36: 4505.62 | J36: 4300.82 | K36: 4300.82 | L36: 4300.82 | M36: 4300.82 | N36: 4300.82 | O36: 4300.82 | P36: 4300.82 | Q36: 4300.82 | R36: 4300.82 | S36: 4300.82 | T36: 4300.82 | U36: 4300.82 | V36: 4300.82 | W36: 4300.82 | X36: 4300.82 | Y36: 4505.62 | Z36: 4505.62 | AA36: 4505.62 | AB36: 4505.62
A37: 1 | C37: 기타비유동금융부채 | E37: 640.54 | F37: 640.54 | G37: 476.75 | H37: 517.8 | I37: 535.03 | J37: 876.82 | K37: 876.82 | L37: 826.82 | M37: 907.64 | N37: 965.74 | O37: 1052.92 | P37: 1052.92 | Q37: 1083.06 | R37: 1141.5 | S37: 911.51 | T37: 975.46 | U37: 975.46 | V37: 1004.77 | W37: 1030.57 | X37: 1090.77 | Y37: 1123.74 | Z37: 1123.74 | AA37: 1151.65 | AB37: 1182.03
A38: 1 | C38: 장기금융부채 | E38: 690.68 | F38: 690.68 | G38: 526.89 | H38: 545.38 | I38: 562.61 | J38: 1238.94 | K38: 1238.94 | L38: 1188.94 | M38: 1203.71 | N38: 1261.81 | O38: 1295.16 | P38: 1295.16 | Q38: 1325.3 | R38: 1330.42 | S38: 1100.43 | T38: 1130.22 | U38: 1130.22 | V38: 1159.53 | W38: 1128.22 | X38: 1188.42 | Y38: 1186.46 | Z38: 1186.46 | AA38: 1214.37 | AB38: 1237.1
... A45: 1 | C45: 이익잉여금 | E45: -38729.09 | F45: -38729.09 | G45: -40236.41 | H45: -40791.86 | I45: -42252.69 | J45: -44477.25 | K45: -44477.25 | L45: -43440.27 | M45: -42235.43 | N45: -42540.41 | O45: -43261.03 | P45: -43261.03 | Q45: -42950.01 | R45: -42395.53 | S45: -43101.97 | T45: -46976.29 | U45: -46976.29 | V45: 10295.27 | W45: -52143.71 | X45: -52239.74 | Y45: -52014.91 | Z45: -52014.91 | AA45: -51476.73 | AB45: -50705.7
A46: 1 | C46: 기타포괄이익누계액 | E46: 934.99 | F46: 934.99
A47: 1 | C47: 기타자본 | E47: 10636.98 | F47: 10636.98 | G47: 11683.75 | H47: 10296.68 | I47: 10290.02 | J47: 10284.06 | K47: 10284.06 | L47: 10279.53 | M47: 10286.89 | N47: 10285.68 | O47: 10288.03 | P47: 10288.03 | Q47: 10290.36 | R47: 10319.39 | S47: 10294.64 | T47: 10295.15 | U47: 10295.15 | V47: -47658.51 | W47: 10320.52 | X47: 10345.26 | Y47: 10134.17 | Z47: 10134.17 | AA47: 10115.25 | AB47: 10101.64
A48: 1 | C48: 자본총계 | E48: 35004.02 | F48: 35004.02 | G48: 33608.48 | H48: 31665.96 | I48: 30198.47 | J48: 27967.95 | K48: 27967.95 | L48: 29000.39 | M48: 30212.6 | N48: 29906.4 | O48: 29188.13 | P48: 29188.13 | Q48: 29501.49 | R48: 30084.99 | S48: 29353.81 | T48: 25479.99 | U48: 25479.99 | V48: 24797.9 | W48: 29981.77 | X48: 31518.17 | Y48: 31531.92 | Z48: 31531.92 | AA48: 32051.17 | AB48: 32808.59
...

Sheet subQ
A1: YQ | C1: subQ 분기 서브모델(억원, U=100) | E1: 4Q21 | F1: 2021 | G1: 1Q22 | H1: 2Q22 | I1: 3Q22 | J1: 4Q22 | K1: 2022 | L1: 1Q23 | M1: 2Q23 | N1: 3Q23 | O1: 4Q23 | P1: 2023 | Q1: 1Q24 | R1: 2Q24 | S1: 3Q24 | T1: 4Q24 | U1: 2024 | V1: 1Q25 | W1: 2Q25 | X1: 3Q25 | Y1: 4Q25 | Z1: 2025 | AA1: 1Q26 | AB1: 2Q26 | AC1: 3Q26 | AD1: 4Q26 | AE1: 2026 | AF1: 1Q27 | AG1: 2Q27 | AH1: 3Q27 | AI1: 4Q27 | AJ1: 2027 | AK1: 1Q28 | AL1: 2Q28 | AM1: 3Q28 | AN1: 4Q28 | AO1: 2028
A2: A=이름(key) B=그룹 C=단위 D=FnGuide 계정명(VLOOKUP 키). 확정=VLOOKUP(BS), 추정=변수 가정 참조
E3: 1 | F3: 2 | G3: 3 | H3: 4 | I3: 5 | J3: 6 | K3: 7 | L3: 8 | M3: 9 | N3: 10 | O3: 11 | P3: 12 | Q3: 13 | R3: 14 | S3: 15 | T3: 16 | U3: 17 | V3: 18 | W3: 19 | X3: 20 | Y3: 21 | Z3: 22 | AA3: 23 | AB3: 24 | AC3: 25 | AD3: 26 | AE3: 27 | AF3: 28 | AG3: 29 | AH3: 30 | AI3: 31 | AJ3: 32 | AK3: 33 | AL3: 34 | AM3: 35 | AN3: 36 | AO3: 37
E4: 2021.12 | F4: 2021.12A | G4: 2022.03 | H4: 2022.06 | I4: 2022.09 | J4: 2022.12 | K4: 2022.12A | L4: 2023.03 | M4: 2023.06 | N4: 2023.09 | O4: 2023.12 | P4: 2023.12A | Q4: 2024.03 | R4: 2024.06 | S4: 2024.09 | T4: 2024.12 | U4: 2024.12A | V4: 2025.03 | W4: 2025.06 | X4: 2025.09 | Y4: 2025.12 | Z4: 2025.12A | AA4: 2026.03 | AB4: 2026.06 | AC4: 2026.09 | AD4: 2026.12 | AE4: 2026.12A | AF4: 2027.03 | AG4: 2027.06 | AH4: 2027.09 | AI4: 2027.12 | AJ4: 2027.12A | AK4: 2028.03 | AL4: 2028.06 | AM4: 2028.09 | AN4: 2028.12 | AO4: 2028.12A
A5: 매출액 | B5: 손익 | C5: 억원 | D5: 매출액(수익) | E5: =IFERROR(VLOOKUP($D5,BS연결,MATCH(E$1,BS연결H,0),0)/100,"") | G5: =IFERROR(VLOOKUP($D5,BS연결,MATCH(G$1,BS연결H,0),0)/100,"") | H5: =IFERROR(VLOOKUP($D5,BS연결,MATCH(H$1,BS연결H,0),0)/100,"") | I5: =IFERROR(VLOOKUP($D5,BS연결,MATCH(I$1,BS연결H,0),0)/100,"") | J5: =IFERROR(VLOOKUP($D5,BS연결,MATCH(J$1,BS연결H,0),0)/100,"") | K5: =IFERROR(VLOOKUP($D5,BS연결,MATCH(K$1,BS연결H,0),0)/100,"") | L5: =IFERROR(VLOOKUP($D5,BS연결,MATCH(L$1,BS연결H,0),0)/100,"") | M5: =IFERROR(VLOOKUP($D5,BS연결,MATCH(M$1,BS연결H,0),0)/100,"") | N5: =IFERROR(VLOOKUP($D5,BS연결,MATCH(N$1,BS연결H,0),0)/100,"") | ... AB5: =IFERROR(VLOOKUP($D5,BS연결,MATCH(AB$1,BS연결H,0),0)/100,"") | AC5: =IFERROR(X5*(1+변수!AC21),"") | AD5: =IFERROR(Y5*(1+변수!AD21),"") | AE5: =SUM(AA5:AD5) | AF5: =IFERROR(AA5*(1+변수!AF21),"") | AG5: =IFERROR(AB5*(1+변수!AG21),"") | AH5: =IFERROR(AC5*(1+변수!AH21),"") | AI5: =IFERROR(AD5*(1+변수!AI21),"") | AJ5: =SUM(AF5:AI5) | AK5: =IFERROR(AF5*(1+변수!AK21),"") | AL5: =IFERROR(AG5*(1+변수!AL21),"") | AM5: =IFERROR(AH5*(1+변수!AM21),"") | AN5: =IFERROR(AI5*(1+변수!AN21),"") | AO5: =SUM(AK5:AN5)
A6: 매출원가 | B6: 손익 | C6: 억원 | D6: 매출원가 | E6: =IFERROR(VLOOKUP($D6,BS연결,MATCH(E$1,BS연결H,0),0)/100,"") | G6: =IFERROR(VLOOKUP($D6,BS연결,MATCH(G$1,BS연결H,0),0)/100,"") | H6: =IFERROR(VLOOKUP($D6,BS연결,MATCH(H$1,BS연결H,0),0)/100,"") | I6: =IFERROR(VLOOKUP($D6,BS연결,MATCH(I$1,BS연결H,0),0)/100,"") | J6: =IFERROR(VLOOKUP($D6,BS연결,MATCH(J$1,BS연결H,0),0)/100,"") | K6: =IFERROR(VLOOKUP($D6,BS연결,MATCH(K$1,BS연결H,0),0)/100,"") | L6: =IFERROR(VLOOKUP($D6,BS연결,MATCH(L$1,BS연결H,0),0)/100,"") | M6: =IFERROR(VLOOKUP($D6,BS연결,MATCH(M$1,BS연결H,0),0)/100,"") | N6: =IFERROR(VLOOKUP($D6,BS연결,MATCH(N$1,BS연결H,0),0)/100,"") | ... AB6: =IFERROR(VLOOKUP($D6,BS연결,MATCH(AB$1,BS연결H,0),0)/100,"") | AC6: =IFERROR(AC5-AC7,"") | AD6: =IFERROR(AD5-AD7,"") | AE6: =SUM(AA6:AD6) | AF6: =IFERROR(AF5-AF7,"") | AG6: =IFERROR(AG5-AG7,"") | AH6: =IFERROR(AH5-AH7,"") | AI6: =IFERROR(AI5-AI7,"") | AJ6: =SUM(AF6:AI6) | AK6: =IFERROR(AK5-AK7,"") | AL6: =IFERROR(AL5-AL7,"") | AM6: =IFERROR(AM5-AM7,"") | AN6: =IFERROR(AN5-AN7,"") | AO6: =SUM(AK6:AN6)
A7: 매출총이익 | B7: 손익 | C7: 억원 | D7: 매출총이익 | E7: =IFERROR(VLOOKUP($D7,BS연결,MATCH(E$1,BS연결H,0),0)/100,"") | G7: =IFERROR(VLOOKUP($D7,BS연결,MATCH(G$1,BS연결H,0),0)/100,"") | H7: =IFERROR(VLOOKUP($D7,BS연결,MATCH(H$1,BS연결H,0),0)/100,"") | I7: =IFERROR(VLOOKUP($D7,BS연결,MATCH(I$1,BS연결H,0),0)/100,"") | J7: =IFERROR(VLOOKUP($D7,BS연결,MATCH(J$1,BS연결H,0),0)/100,"") | K7: =IFERROR(VLOOKUP($D7,BS연결,MATCH(K$1,BS연결H,0),0)/100,"") | L7: =IFERROR(VLOOKUP($D7,BS연결,MATCH(L$1,BS연결H,0),0)/100,"") | M7: =IFERROR(VLOOKUP($D7,BS연결,MATCH(M$1,BS연결H,0),0)/100,"") | N7: =IFERROR(VLOOKUP($D7,BS연결,MATCH(N$1,BS연결H,0),0)/100,"") | O7: =IFERROR(VLOOKUP($D7,BS연결,MATCH(O$1,BS연결H,0),0)/100,"") | P7: =SUM(L7:O7) | Q7: =IFERROR(VLOOKUP($D7,BS연결,MATCH(Q$1,BS연결H,0),0)/100,"") | R7: =IFERROR(VLOOKUP($D7,BS연결,MATCH(R$1,BS연결H,0),0)/100,"") | S7: =IFERROR(VLOOKUP($D7,BS연결,MATCH(S$1,BS연결H,0),0)/100,"") | T7: =IFERROR(VLOOKUP($D7,BS연결,MATCH(T$1,BS연결H,0),0)/100,"") | U7: =IFERROR(VLOOKUP($D7,BS연결,MATCH(U$1,BS연결H,0),0)/100,"") | V7: =IFERROR(VLOOKUP($D7,BS연결,MATCH(V$1,BS연결H,0),0)/100,"") | W7: =IFERROR(VLOOKUP($D7,BS연결,MATCH(W$1,BS연결H,0),0)/100,"") | X7: =IFERROR(VLOOKUP($D7,BS연결,MATCH(X$1,BS연결H,0),0)/100,"") | Y7: =IFERROR(VLOOKUP($D7,BS연결,MATCH(Y$1,BS연결H,0),0)/100,"") | Z7: =SUM(V7:Y7) | AA7: =IFERROR(VLOOKUP($D7,BS연결,MATCH(AA$1,BS연결H,0),0)/100,"") | AB7: =IFERROR(VLOOKUP($D7,BS연결,MATCH(AB$1,BS연결H,0),0)/100,"") | AC7: =IFERROR(AC9+AC8,"") | AD7: =IFERROR(AD9+AD8,"") | AE7: =SUM(AA7:AD7) | AF7: =IFERROR(AF9+AF8,"") | AG7: =IFERROR(AG9+AG8,"") | AH7: =IFERROR(AH9+AH8,"") | AI7: =IFERROR(AI9+AI8,"") | AJ7: =SUM(AF7:AI7) | AK7: =IFERROR(AK9+AK8,"") | AL7: =IFERROR(AL9+AL8,"") | AM7: =IFERROR(AM9+AM8,"") | AN7: =IFERROR(AN9+AN8,"") | AO7: =SUM(AK7:AN7)
A8: 판관비 | B8: 손익 | C8: 억원 | D8: 판관비 | E8: =IFERROR(VLOOKUP($D8,BS연결,MATCH(E$1,BS연결H,0),0)/100,"") | G8: =IFERROR(VLOOKUP($D8,BS연결,MATCH(G$1,BS연결H,0),0)/100,"") | H8: =IFERROR(VLOOKUP($D8,BS연결,MATCH(H$1,BS연결H,0),0)/100,"") | I8: =IFERROR(VLOOKUP($D8,BS연결,MATCH(I$1,BS연결H,0),0)/100,"") | J8: =IFERROR(VLOOKUP($D8,BS연결,MATCH(J$1,BS연결H,0),0)/100,"") | K8: =IFERROR(VLOOKUP($D8,BS연결,MATCH(K$1,BS연결H,0),0)/100,"") | L8: =IFERROR(VLOOKUP($D8,BS연결,MATCH(L$1,BS연결H,0),0)/100,"") | M8: =IFERROR(VLOOKUP($D8,BS연결,MATCH(M$1,BS연결H,0),0)/100,"") | N8: =IFERROR(VLOOKUP($D8,BS연결,MATCH(N$1,BS연결H,0),0)/100,"") | ... AB8: =IFERROR(VLOOKUP($D8,BS연결,MATCH(AB$1,BS연결H,0),0)/100,"") | AC8: =IFERROR(AC5*변수!AC22,"") | AD8: =IFERROR(AD5*변수!AD22,"") | AE8: =SUM(AA8:AD8) | AF8: =IFERROR(AF5*변수!AF22,"") | AG8: =IFERROR(AG5*변수!AG22,"") | AH8: =IFERROR(AH5*변수!AH22,"") | AI8: =IFERROR(AI5*변수!AI22,"") | AJ8: =SUM(AF8:AI8) | AK8: =IFERROR(AK5*변수!AK22,"") | AL8: =IFERROR(AL5*변수!AL22,"") | AM8: =IFERROR(AM5*변수!AM22,"") | AN8: =IFERROR(AN5*변수!AN22,"") | AO8: =SUM(AK8:AN8)
