Workbook
Name 변수H: 변수!$C$1:$AO$1
Name 환율: 변수!$C$6:$AO$13
Name BS연결H: BS연결!$C$1:$AO$1
Name BS연결: BS연결!$C$5:$AO$102
Name BS별도H: BS별도!$C$1:$AO$1
Name BS별도: BS별도!$C$5:$AO$91
Name SUBQH: subQ!$A$1:$AO$1
Name subQ: subQ!$A$5:$AO$45
Name SLS_H: SLS!$A$1:$FE$1

Sheet README
A1: HJ중공업(097230) 실적 모델 — ARGUS 한국조선
A2: 기준 분기 2026Q2 · 마지막 실적 2026Q2 · 생성 2026-10-14
A3: 모든 수치는 모델 산출값(DART 공개 재무제표 + 우리 추정)이다 — 목표주가·투자 추천 아님. 참고용 · 투자조언 아님.
A5: 시트
A6: 변수 가정 시계열. 환율 8행(ECB via frankfurter — L2 fx.json; 추정 분기 = 노란 가정), 추정 드라이버(노란 셀 = 모델값에서 역산한 가정, 바꾸면 재계산; 연녹 셀 = 3절 스칼라 참조 수식), 3절 스칼라 가정(세율·판관비율·지배주주비중·이자율·종가·PER 밴드·COE·외화 순노출·헤지비율)
A7: BS연결/BS별도 FnGuide 계정명 × 기간 값 덤프(백만원). 행1 분기라벨, 행4 YYYY.MM / YYYY.12A. 이름정의 BS연결H·BS연결(계정명 C열부터)
A8: subQ 분기 서브모델(억원 = 백만원/100). 확정 행: =IFERROR(VLOOKUP($D행,BS연결,MATCH(E$1,BS연결H,0),0)/100,"") 추정 행: 변수 시트 가정 셀 참조 수식. 외환손익·파생상품손익은 BS 계정 합·차, 기타금융손익은 잔차, OPM·EPS·BPS·PER·PBR 은 파생 수식
A9: SLS 선표(조선사만, sls json 있을 때): 요약 행(sls 저장값) + 계약별 스케줄(백만$) × (헤지비율 × 헤지환율 + (1−헤지비율) × 건조시점 환율[변수 원/달러(평균)]) → 원화 수식 블록 → 합계 행이 subQ 매출조선에 연결
A10: 시나리오 신규수주 보수/기준/낙관(forecast_panel 패널, 모델에 scenarios 가 있을 때만): 매출액·영업이익 = subQ 기준값 ± (시나리오 신규 − base 신규) × OPM. base 만 subQ 행에 포함, 나머지는 합산 안 함
A11: 분기/연간예상 subQ 를 이름(A열 key)으로 VLOOKUP 한 보고서 표(억원)
A12: TP PER 밴드 × 12M fwd EPS, PBR = ROE/COE × BPS — 모델 산출값 구간, 목표주가·추천 아님
A13: 외화 환율 QoQ, 외화 순노출 × Δ기말환율 → 환관련손익 추정
... A36: 백테스트: {"freeze": "2025Q2", "horizon": 4, "revenue_wape_pct": 19.4, "op_wape_pct": 100.0, "n": 4, "note": "단일 회사 4분기 — 통계 아님", "driver_at_freeze": "sls_marine_plus_uncovered_backlog_runoff", "selection_oos_at_freeze": null, "frozen_inputs": "fin(연결/별도)·고객 조선사 모델·지주 자회사 모델은 2025Q2 까지의 분기만; 선표는 체결일 ≤ 2025Q2 말일 계약(원장 최신 금액·코호트 등급, 환산 없음); 잔고는 yards_cache 2025Q2; 시세·환율 forward·prices·forecast_panel 신규수주 미사용. 고객 가중치(suppliers.json 언급 비중)와 합병 체인링크는 현재 지식; 고객 연동 채택은 동결 모델 안에서도 자기 la−4분기 OOS 규칙(selection_oos_at_freeze)", "detail": [{"q": "2025Q3", "rev_pred": 4962.89, "rev_act": 4522.08, "op_pred": 0.0, "op_act": 57.94}, {"q": "2025Q4", "rev_pred": 4962.89, "rev_act": 6296.54, "op_pred": 0.0, "op_act": 504.87}, {"q": "2026Q1", "rev_pred": 4962.89, "rev_act": 5414.0, "op_pred": 0.0, "op_act": 245.81}, {"q": "2026Q2", "rev_pred": 4962.89, "rev_act": 7299.08, "op_pred": 0.0, "op_act": 648.53}]}

Sheet 변수
C1: 이름: 변수H | E1: 4Q21 | F1: 2021 | G1: 1Q22 | H1: 2Q22 | I1: 3Q22 | J1: 4Q22 | K1: 2022 | L1: 1Q23 | M1: 2Q23 | N1: 3Q23 | O1: 4Q23 | P1: 2023 | Q1: 1Q24 | R1: 2Q24 | S1: 3Q24 | T1: 4Q24 | U1: 2024 | V1: 1Q25 | W1: 2Q25 | X1: 3Q25 | Y1: 4Q25 | Z1: 2025 | AA1: 1Q26 | AB1: 2Q26 | AC1: 3Q26 | AD1: 4Q26 | AE1: 2026 | AF1: 1Q27 | AG1: 2Q27 | AH1: 3Q27 | AI1: 4Q27 | AJ1: 2027 | AK1: 1Q28 | AL1: 2Q28 | AM1: 3Q28 | AN1: 4Q28 | AO1: 2028
A2: 가정 시계열 — 노란 셀은 추정 가정(모델값에서 역산), 연녹 셀은 3절 스칼라 참조 수식. 바꾸면 subQ·분기·연간예상·TP·시나리오가 재계산됩니다.
E3: 1 | F3: 2 | G3: 3 | H3: 4 | I3: 5 | J3: 6 | K3: 7 | L3: 8 | M3: 9 | N3: 10 | O3: 11 | P3: 12 | Q3: 13 | R3: 14 | S3: 15 | T3: 16 | U3: 17 | V3: 18 | W3: 19 | X3: 20 | Y3: 21 | Z3: 22 | AA3: 23 | AB3: 24 | AC3: 25 | AD3: 26 | AE3: 27 | AF3: 28 | AG3: 29 | AH3: 30 | AI3: 31 | AJ3: 32 | AK3: 33 | AL3: 34 | AM3: 35 | AN3: 36 | AO3: 37
E4: 2021.12 | F4: 2021.12A | G4: 2022.03 | H4: 2022.06 | I4: 2022.09 | J4: 2022.12 | K4: 2022.12A | L4: 2023.03 | M4: 2023.06 | N4: 2023.09 | O4: 2023.12 | P4: 2023.12A | Q4: 2024.03 | R4: 2024.06 | S4: 2024.09 | T4: 2024.12 | U4: 2024.12A | V4: 2025.03 | W4: 2025.06 | X4: 2025.09 | Y4: 2025.12 | Z4: 2025.12A | AA4: 2026.03 | AB4: 2026.06 | AC4: 2026.09 | AD4: 2026.12 | AE4: 2026.12A | AF4: 2027.03 | AG4: 2027.06 | AH4: 2027.09 | AI4: 2027.12 | AJ4: 2027.12A | AK4: 2028.03 | AL4: 2028.06 | AM4: 2028.09 | AN4: 2028.12 | AO4: 2028.12A
B5: 1. FX | C5: 이름: 환율
A6: USDKRW_avg | C6: 원/달러(평균) | E6: 1183.5 | F6: 1145.51 | G6: 1205.78 | H6: 1262.09 | I6: 1341.93 | J6: 1360.12 | K6: 1292.98 | L6: 1276.95 | M6: 1315.69 | N6: 1313.62 | O6: 1322.01 | P6: 1306.85 | Q6: 1330.14 | R6: 1371.28 | S6: 1356.22 | T6: 1396.3 | U6: 1363.53 | V6: 1452.28 | W6: 1398.52 | X6: 1386.95 | Y6: 1449.19 | Z6: 1421.52 | AA6: 1466.12 | AB6: 1501.75 | AC6: 1418.75 | AD6: 1343.39 | AE6: 1456.01 | AF6: 1341.45 | AG6: 1341.45 | AH6: 1341.45 | AI6: 1341.45 | AK6: 1341.45 | AL6: 1341.45 | AM6: 1341.45 | AN6: 1341.45
A7: USDKRW_end | C7: 원/달러(기말) | E7: 1188.75 | F7: 1188.75 | G7: 1213.74 | H7: 1301.24 | I7: 1436.9 | J7: 1260.16 | K7: 1260.16 | L7: 1305.99 | M7: 1321.44 | N7: 1345.35 | O7: 1297.43 | P7: 1297.43 | Q7: 1349.25 | R7: 1377.73 | S7: 1312.17 | T7: 1474.78 | U7: 1474.78 | V7: 1474.54 | W7: 1355.13 | X7: 1403.67 | Y7: 1444.2 | Z7: 1444.2 | AA7: 1524.8 | AB7: 1550.89 | AC7: 1355.4 | AD7: 1341.45 | AE7: 1341.45 | AF7: 1341.45 | AG7: 1341.45 | AH7: 1341.45 | AI7: 1341.45 | AK7: 1341.45 | AL7: 1341.45 | AM7: 1341.45 | AN7: 1341.45
A8: JPY100KRW_avg | C8: 원/100Y(평균) | E8: 1041.02 | F8: 1042.74 | G8: 1036.79 | H8: 972.23 | I8: 970.61 | J8: 961.03 | K8: 985.1 | L8: 964.89 | M8: 957.36 | N8: 909 | O8: 893.22 | P8: 931.11 | Q8: 896.29 | R8: 880.14 | S8: 909.35 | T8: 917.25 | U8: 900.92 | V8: 952.59 | W8: 967.92 | X8: 940.32 | Y8: 940.77 | Z8: 950.17 | AA8: 934.39 | AB8: 942.16 | AC8: 890.41 | AD8: 849.39 | AE8: 918.46 | AF8: 848.37 | AG8: 848.37 | AH8: 848.37 | AI8: 848.37 | AK8: 848.37 | AL8: 848.37 | AM8: 848.37 | AN8: 848.37
A9: JPY100KRW_end | C9: 원/100Y(기말) | E9: 1032.62 | F9: 1032.62 | G9: 996.83 | H9: 954.9 | I9: 993.29 | J9: 955.54 | K9: 955.54 | L9: 980.62 | M9: 913.67 | N9: 901.47 | O9: 917.04 | P9: 917.04 | Q9: 892.42 | R9: 857.76 | S9: 919.21 | T9: 939.65 | U9: 939.65 | V9: 986.84 | W9: 938.85 | X9: 948.49 | Y9: 921.81 | Z9: 921.81 | AA9: 955.99 | AB9: 954.75 | AC9: 863.31 | AD9: 848.37 | AE9: 848.37 | AF9: 848.37 | AG9: 848.37 | AH9: 848.37 | AI9: 848.37 | AK9: 848.37 | AL9: 848.37 | AM9: 848.37 | AN9: 848.37
A10: EURKRW_avg | C10: W/Euro(평균) | E10: 1353.32 | F10: 1354.06 | G10: 1352.29 | H10: 1343.31 | I10: 1350.63 | J10: 1386.07 | K10: 1358.07 | L10: 1369.93 | M10: 1432.41 | N10: 1429.41 | O10: 1420.91 | P10: 1412.88 | Q10: 1444.21 | R10: 1476.42 | S10: 1489.3 | T10: 1490.78 | U10: 1475.4 | V10: 1528.33 | W10: 1585.13 | X10: 1620.04 | Y10: 1686.02 | Z10: 1605.45 | AA10: 1715.47 | AB10: 1746.09 | AC10: 1631.97 | AD10: 1506.62 | AE10: 1688.01 | AF10: 1500.82 | AG10: 1500.82 | AH10: 1500.82 | AI10: 1500.82 | AK10: 1500.82 | AL10: 1500.82 | AM10: 1500.82 | AN10: 1500.82
A11: EURKRW_end | C11: W/Euro(기말) | E11: 1346.38 | F11: 1346.38 | G11: 1347.37 | H11: 1351.6 | I11: 1400.62 | J11: 1344.08 | K11: 1344.08 | L11: 1420.26 | M11: 1435.88 | N11: 1425.26 | O11: 1433.66 | P11: 1433.66 | Q11: 1458.68 | R11: 1474.86 | S11: 1469.1 | T11: 1532.14 | U11: 1532.14 | V11: 1594.72 | W11: 1588.22 | X11: 1648.04 | Y11: 1696.94 | Z11: 1696.94 | AA11: 1753.21 | AB11: 1767.09 | AC11: 1539.06 | AD11: 1500.82 | AE11: 1500.82 | AF11: 1500.82 | AG11: 1500.82 | AH11: 1500.82 | AI11: 1500.82 | AK11: 1500.82 | AL11: 1500.82 | AM11: 1500.82 | AN11: 1500.82
A12: CNYKRW_avg | C12: 원/중국원(평균) | E12: 185.14 | F12: 177.65 | G12: 189.93 | H12: 190.76 | I12: 195.79 | J12: 191.09 | K12: 191.93 | L12: 186.59 | M12: 187.45 | N12: 181.28 | O12: 182.86 | P12: 184.52 | Q12: 185.04 | R12: 189.35 | S12: 189.24 | T12: 194.24 | U12: 189.49 | V12: 199.63 | W12: 193.41 | X12: 193.79 | Y12: 204.38 | Z12: 197.8 | AA12: 211.75 | AB12: 220.8 | AC12: 210.43 | AD12: 200.49 | AE12: 213.61 | AF12: 200.4 | AG12: 200.4 | AH12: 200.4 | AI12: 200.4 | AK12: 200.4 | AL12: 200.4 | AM12: 200.4 | AN12: 200.4
A13: CNYKRW_end | C13: 원/중국원(기말) | E13: 187.13 | F13: 187.13 | G13: 191.38 | H13: 194.13 | I13: 201.92 | J13: 182.67 | K13: 182.67 | L13: 189.97 | M13: 181.8 | N13: 184.26 | O13: 182.61 | P13: 182.61 | Q13: 186.66 | R13: 189.7 | S13: 187.12 | T13: 202.04 | U13: 202.04 | V13: 203.3 | W13: 189.14 | X13: 197.16 | Y13: 206.28 | Z13: 206.28 | AA13: 220.97 | AB13: 228.56 | AC13: 202.16 | AD13: 200.4 | AE13: 200.4 | AF13: 200.4 | AG13: 200.4 | AH13: 200.4 | AI13: 200.4 | AK13: 200.4 | AL13: 200.4 | AM13: 200.4 | AN13: 200.4
B14: 1b. 종가
A15: price_close_end | C15: 종가(기말) | E15: 8040 | G15: 7950 | H15: 7200 | I15: 4300 | J15: 3915 | L15: 3640 | M15: 4095 | N15: 3650 | O15: 4450 | Q15: 3295 | R15: 3585 | S15: 2655 | T15: 5930 | V15: 5900 | W15: 7950 | X15: 28000 | Y15: 21050 | AA15: 21750 | AB15: 20150 | AC15: 14710 | AD15: 13410
A16: price_high | C16: 종가(최고) | E16: 10500 | G16: 8300 | H16: 8450 | I16: 7260 | J16: 4850 | L16: 4225 | M16: 4285 | N16: 4975 | O16: 4500 | Q16: 4310 | R16: 3785 | S16: 3775 | T16: 7190 | V16: 9900 | W16: 8590 | X16: 34350 | Y16: 33100 | AA16: 29300 | AB16: 33800 | AC16: 20500 | AD16: 15630
A17: price_low | C17: 종가(최저) | E17: 7350 | G17: 6690 | H17: 6500 | I17: 4075 | J17: 3240 | L17: 3290 | M17: 3425 | N17: 3610 | O17: 3270 | Q17: 3250 | R17: 2875 | S17: 2585 | T17: 2180 | V17: 5540 | W17: 5630 | X17: 6950 | Y17: 19650 | AA17: 18800 | AB17: 18400 | AC17: 12910 | AD17: 12630
A18: price_avg | C18: 종가(평균) | E18: 8731.4 | G18: 7593.9 | H18: 7663.9 | I18: 6338.3 | J18: 4026.9 | L18: 3834.4 | M18: 3802.3 | N18: 4042.3 | O18: 3724.7 | Q18: 3575.7 | R18: 3208.9 | S18: 3080.5 | T18: 3454.6 | V18: 6934 | W18: 7398.3 | X18: 16561.2 | Y18: 23805.1 | AA18: 24852.4 | AB18: 24395.1 | AC18: 16326.3 | AD18: 14411.2
B20: 2. 추정 드라이버 | C20: 실적 열 = subQ 실현값(수식), 추정 열 = 가정(노란 = 모델값 역산, 연녹 = 3절 스칼라 참조)
A21: drv:판관비 | B21: ratio | C21: 판관비율(/매출) | E21: =IFERROR(subQ!E8/subQ!E5,"") | F21: =IFERROR(subQ!F8/subQ!F5,"") | G21: =IFERROR(subQ!G8/subQ!G5,"") | H21: =IFERROR(subQ!H8/subQ!H5,"") | I21: =IFERROR(subQ!I8/subQ!I5,"") | J21: =IFERROR(subQ!J8/subQ!J5,"") | K21: =IFERROR(subQ!K8/subQ!K5,"") | L21: =IFERROR(subQ!L8/subQ!L5,"") | ... AB21: =IFERROR(subQ!AB8/subQ!AB5,"") | AC21: =$D$53 | AD21: =$D$53 | AE21: =IFERROR(subQ!AE8/subQ!AE5,"") | AF21: =$D$53 | AG21: =$D$53 | AH21: =$D$53 | AI21: =$D$53 | AJ21: =IFERROR(subQ!AJ8/subQ!AJ5,"") | AK21: =$D$53 | AL21: =$D$53 | AM21: =$D$53 | AN21: =$D$53 | AO21: =IFERROR(subQ!AO8/subQ!AO5,"")
A22: drv:외환손익 | B22: abs | C22: 외환손익 (가정, 억원) | E22: =subQ!E13 | F22: =subQ!F13 | G22: =subQ!G13 | H22: =subQ!H13 | I22: =subQ!I13 | J22: =subQ!J13 | K22: =subQ!K13 | L22: =subQ!L13 | ... AB22: =subQ!AB13 | AC22: 0 | AD22: 0 | AE22: =subQ!AE13 | AF22: 0 | AG22: 0 | AH22: 0 | AI22: 0 | AJ22: =subQ!AJ13 | AK22: 0 | AL22: 0 | AM22: 0 | AN22: 0 | AO22: =subQ!AO13
A23: drv:기타영업외손익 | B23: abs | C23: 기타영업외손익 (가정, 억원) | E23: =subQ!E14 | F23: =subQ!F14 | G23: =subQ!G14 | H23: =subQ!H14 | I23: =subQ!I14 | J23: =subQ!J14 | K23: =subQ!K14 | L23: =subQ!L14 | ... AB23: =subQ!AB14 | AC23: 0 | AD23: 0 | AE23: =subQ!AE14 | AF23: 0 | AG23: 0 | AH23: 0 | AI23: 0 | AJ23: =subQ!AJ14 | AK23: 0 | AL23: 0 | AM23: 0 | AN23: 0 | AO23: =subQ!AO14
A24: drv:법인세비용 | B24: tax | C24: 법인세율(/세전) — 법인세 = MAX(세전,0) × 분기별 세율(이월결손 램프, assumptions.tax_schedule) | E24: =IFERROR(subQ!E16/subQ!E15,"") | F24: =IFERROR(subQ!F16/subQ!F15,"") | G24: =IFERROR(subQ!G16/subQ!G15,"") | H24: =IFERROR(subQ!H16/subQ!H15,"") | I24: =IFERROR(subQ!I16/subQ!I15,"") | J24: =IFERROR(subQ!J16/subQ!J15,"") | K24: =IFERROR(subQ!K16/subQ!K15,"") | L24: =IFERROR(subQ!L16/subQ!L15,"") | ... AB24: =IFERROR(subQ!AB16/subQ!AB15,"") | AC24: 0.004526838 | AD24: 0.004528014 | AE24: =IFERROR(subQ!AE16/subQ!AE15,"") | AF24: 0.031454969 | AG24: 0.058388922 | AH24: 0.085336388 | AI24: 0.1122543 | AJ24: =IFERROR(subQ!AJ16/subQ!AJ15,"") | AK24: 0.13920167 | AL24: 0.16613223 | AM24: 0.19307319 | AN24: 0.2199972 | AO24: =IFERROR(subQ!AO16/subQ!AO15,"")
A25: drv:지배주주순이익 | B25: ratio | C25: 지배주주 비중(/당기순이익) | E25: =IFERROR(subQ!E18/subQ!E17,"") | F25: =IFERROR(subQ!F18/subQ!F17,"") | G25: =IFERROR(subQ!G18/subQ!G17,"") | H25: =IFERROR(subQ!H18/subQ!H17,"") | I25: =IFERROR(subQ!I18/subQ!I17,"") | J25: =IFERROR(subQ!J18/subQ!J17,"") | K25: =IFERROR(subQ!K18/subQ!K17,"") | L25: =IFERROR(subQ!L18/subQ!L17,"") | ... AB25: =IFERROR(subQ!AB18/subQ!AB17,"") | AC25: =$D$54 | AD25: =$D$54 | AE25: =IFERROR(subQ!AE18/subQ!AE17,"") | AF25: =$D$54 | AG25: =$D$54 | AH25: =$D$54 | AI25: =$D$54 | AJ25: =IFERROR(subQ!AJ18/subQ!AJ17,"") | AK25: =$D$54 | AL25: =$D$54 | AM25: =$D$54 | AN25: =$D$54 | AO25: =IFERROR(subQ!AO18/subQ!AO17,"")
A26: drv:중단사업이익 | B26: abs | C26: 중단사업이익 (가정, 억원) | E26: =subQ!E19 | F26: =subQ!F19 | G26: =subQ!G19 | H26: =subQ!H19 | I26: =subQ!I19 | J26: =subQ!J19 | K26: =subQ!K19 | L26: =subQ!L19 | ... AB26: =subQ!AB19 | AE26: =subQ!AE19 | AJ26: =subQ!AJ19 | AO26: =subQ!AO19
A27: drv:부채총계 | B27: qoq | C27: 부채총계 QoQ | G27: =IFERROR(subQ!G21/subQ!E21-1,"") | H27: =IFERROR(subQ!H21/subQ!G21-1,"") | I27: =IFERROR(subQ!I21/subQ!H21-1,"") | J27: =IFERROR(subQ!J21/subQ!I21-1,"") | L27: =IFERROR(subQ!L21/subQ!J21-1,"") | M27: =IFERROR(subQ!M21/subQ!L21-1,"") | N27: =IFERROR(subQ!N21/subQ!M21-1,"") | O27: =IFERROR(subQ!O21/subQ!N21-1,"") | Q27: =IFERROR(subQ!Q21/subQ!O21-1,"") | R27: =IFERROR(subQ!R21/subQ!Q21-1,"") | S27: =IFERROR(subQ!S21/subQ!R21-1,"") | T27: =IFERROR(subQ!T21/subQ!S21-1,"") | V27: =IFERROR(subQ!V21/subQ!T21-1,"") | W27: =IFERROR(subQ!W21/subQ!V21-1,"") | X27: =IFERROR(subQ!X21/subQ!W21-1,"") | Y27: =IFERROR(subQ!Y21/subQ!X21-1,"") | AA27: =IFERROR(subQ!AA21/subQ!Y21-1,"") | AB27: =IFERROR(subQ!AB21/subQ!AA21-1,"") | AC27: 0 | AD27: 0 | AF27: 0 | AG27: 0 | AH27: 0 | AI27: 0 | AK27: 0 | AL27: 0 | AM27: 0 | AN27: 0
A28: drv:자본총계 | B28: roll | C28: 자본총계 기타변동(배당 등, 억원) | G28: =IFERROR(subQ!E22+subQ!G17-subQ!G22,"") | H28: =IFERROR(subQ!G22+subQ!H17-subQ!H22,"") | I28: =IFERROR(subQ!H22+subQ!I17-subQ!I22,"") | J28: =IFERROR(subQ!I22+subQ!J17-subQ!J22,"") | L28: =IFERROR(subQ!J22+subQ!L17-subQ!L22,"") | M28: =IFERROR(subQ!L22+subQ!M17-subQ!M22,"") | N28: =IFERROR(subQ!M22+subQ!N17-subQ!N22,"") | O28: =IFERROR(subQ!N22+subQ!O17-subQ!O22,"") | Q28: =IFERROR(subQ!O22+subQ!Q17-subQ!Q22,"") | R28: =IFERROR(subQ!Q22+subQ!R17-subQ!R22,"") | S28: =IFERROR(subQ!R22+subQ!S17-subQ!S22,"") | T28: =IFERROR(subQ!S22+subQ!T17-subQ!T22,"") | V28: =IFERROR(subQ!T22+subQ!V17-subQ!V22,"") | W28: =IFERROR(subQ!V22+subQ!W17-subQ!W22,"") | X28: =IFERROR(subQ!W22+subQ!X17-subQ!X22,"") | Y28: =IFERROR(subQ!X22+subQ!Y17-subQ!Y22,"") | AA28: =IFERROR(subQ!Y22+subQ!AA17-subQ!AA22,"") | AB28: =IFERROR(subQ!AA22+subQ!AB17-subQ!AB22,"") | AC28: -0.002075406 | AD28: -0.007476581 | AF28: 0.009488244 | AG28: 0.001637916 | AH28: 0.000552315 | AI28: 0.001637795 | AK28: -0.004154874 | AL28: 0.007380463 | AM28: -0.010869227 | AN28: 0.004536662
A29: drv:지배주주지분 | B29: roll | C29: 지배주주지분 기타변동(배당 등, 억원) | G29: =IFERROR(subQ!E23+subQ!G18-subQ!G23,"") | H29: =IFERROR(subQ!G23+subQ!H18-subQ!H23,"") | I29: =IFERROR(subQ!H23+subQ!I18-subQ!I23,"") | J29: =IFERROR(subQ!I23+subQ!J18-subQ!J23,"") | L29: =IFERROR(subQ!J23+subQ!L18-subQ!L23,"") | M29: =IFERROR(subQ!L23+subQ!M18-subQ!M23,"") | N29: =IFERROR(subQ!M23+subQ!N18-subQ!N23,"") | O29: =IFERROR(subQ!N23+subQ!O18-subQ!O23,"") | Q29: =IFERROR(subQ!O23+subQ!Q18-subQ!Q23,"") | R29: =IFERROR(subQ!Q23+subQ!R18-subQ!R23,"") | S29: =IFERROR(subQ!R23+subQ!S18-subQ!S23,"") | T29: =IFERROR(subQ!S23+subQ!T18-subQ!T23,"") | V29: =IFERROR(subQ!T23+subQ!V18-subQ!V23,"") | W29: =IFERROR(subQ!V23+subQ!W18-subQ!W23,"") | X29: =IFERROR(subQ!W23+subQ!X18-subQ!X23,"") | Y29: =IFERROR(subQ!X23+subQ!Y18-subQ!Y23,"") | AA29: =IFERROR(subQ!Y23+subQ!AA18-subQ!AA23,"") | AB29: =IFERROR(subQ!AA23+subQ!AB18-subQ!AB23,"") | AC29: -0.002075406 | AD29: -0.007476581 | AF29: 0.009488244 | AG29: 0.001637916 | AH29: 0.000552315 | AI29: 0.001637795 | AK29: -0.004154874 | AL29: 0.007380463 | AM29: -0.010869227 | AN29: 0.004536662
A30: drv:총차입금 | B30: qoq | C30: 총차입금 QoQ | G30: =IFERROR(subQ!G24/subQ!E24-1,"") | H30: =IFERROR(subQ!H24/subQ!G24-1,"") | I30: =IFERROR(subQ!I24/subQ!H24-1,"") | J30: =IFERROR(subQ!J24/subQ!I24-1,"") | L30: =IFERROR(subQ!L24/subQ!J24-1,"") | M30: =IFERROR(subQ!M24/subQ!L24-1,"") | N30: =IFERROR(subQ!N24/subQ!M24-1,"") | O30: =IFERROR(subQ!O24/subQ!N24-1,"") | Q30: =IFERROR(subQ!Q24/subQ!O24-1,"") | R30: =IFERROR(subQ!R24/subQ!Q24-1,"") | S30: =IFERROR(subQ!S24/subQ!R24-1,"") | T30: =IFERROR(subQ!T24/subQ!S24-1,"") | V30: =IFERROR(subQ!V24/subQ!T24-1,"") | W30: =IFERROR(subQ!W24/subQ!V24-1,"") | X30: =IFERROR(subQ!X24/subQ!W24-1,"") | Y30: =IFERROR(subQ!Y24/subQ!X24-1,"") | AA30: =IFERROR(subQ!AA24/subQ!Y24-1,"") | AB30: =IFERROR(subQ!AB24/subQ!AA24-1,"") | AC30: 0 | AD30: 0 | AF30: 0 | AG30: 0 | AH30: 0 | AI30: 0 | AK30: 0 | AL30: 0 | AM30: 0 | AN30: 0
A31: drv:순차입금 | B31: qoq | C31: 순차입금 QoQ | G31: =IFERROR(subQ!G25/subQ!E25-1,"") | H31: =IFERROR(subQ!H25/subQ!G25-1,"") | I31: =IFERROR(subQ!I25/subQ!H25-1,"") | J31: =IFERROR(subQ!J25/subQ!I25-1,"") | L31: =IFERROR(subQ!L25/subQ!J25-1,"") | M31: =IFERROR(subQ!M25/subQ!L25-1,"") | N31: =IFERROR(subQ!N25/subQ!M25-1,"") | O31: =IFERROR(subQ!O25/subQ!N25-1,"") | Q31: =IFERROR(subQ!Q25/subQ!O25-1,"") | R31: =IFERROR(subQ!R25/subQ!Q25-1,"") | S31: =IFERROR(subQ!S25/subQ!R25-1,"") | T31: =IFERROR(subQ!T25/subQ!S25-1,"") | V31: =IFERROR(subQ!V25/subQ!T25-1,"") | W31: =IFERROR(subQ!W25/subQ!V25-1,"") | X31: =IFERROR(subQ!X25/subQ!W25-1,"") | Y31: =IFERROR(subQ!Y25/subQ!X25-1,"") | AA31: =IFERROR(subQ!AA25/subQ!Y25-1,"") | AB31: =IFERROR(subQ!AB25/subQ!AA25-1,"") | AC31: -0.23126193 | AD31: -0.35660915 | AF31: -0.55617881 | AG31: -1.3170826 | AH31: 3.1594359 | AI31: 0.78355705 | AK31: 0.47894017 | AL31: 0.3478737 | AM31: 0.25051084 | AN31: 0.19533138
A32: drv:이자발생자산 | B32: qoq | C32: 이자발생자산 QoQ | G32: =IFERROR(subQ!G26/subQ!E26-1,"") | H32: =IFERROR(subQ!H26/subQ!G26-1,"") | I32: =IFERROR(subQ!I26/subQ!H26-1,"") | J32: =IFERROR(subQ!J26/subQ!I26-1,"") | L32: =IFERROR(subQ!L26/subQ!J26-1,"") | M32: =IFERROR(subQ!M26/subQ!L26-1,"") | N32: =IFERROR(subQ!N26/subQ!M26-1,"") | O32: =IFERROR(subQ!O26/subQ!N26-1,"") | Q32: =IFERROR(subQ!Q26/subQ!O26-1,"") | R32: =IFERROR(subQ!R26/subQ!Q26-1,"") | S32: =IFERROR(subQ!S26/subQ!R26-1,"") | T32: =IFERROR(subQ!T26/subQ!S26-1,"") | V32: =IFERROR(subQ!V26/subQ!T26-1,"") | W32: =IFERROR(subQ!W26/subQ!V26-1,"") | X32: =IFERROR(subQ!X26/subQ!W26-1,"") | Y32: =IFERROR(subQ!Y26/subQ!X26-1,"") | AA32: =IFERROR(subQ!AA26/subQ!Y26-1,"") | AB32: =IFERROR(subQ!AB26/subQ!AA26-1,"") | AC32: 0.16405789 | AD32: 0.16706646 | AF32: 0.14364501 | AG32: 0.13200972 | AH32: 0.088700229 | AI32: 0.084045011 | AK32: 0.084520541 | AL32: 0.083717341 | AM32: 0.074981397 | AN32: 0.068011997
A33: drv:현금및현금성자산 | B33: qoq | C33: 현금및현금성자산 QoQ | G33: =IFERROR(subQ!G27/subQ!E27-1,"") | H33: =IFERROR(subQ!H27/subQ!G27-1,"") | I33: =IFERROR(subQ!I27/subQ!H27-1,"") | J33: =IFERROR(subQ!J27/subQ!I27-1,"") | L33: =IFERROR(subQ!L27/subQ!J27-1,"") | M33: =IFERROR(subQ!M27/subQ!L27-1,"") | N33: =IFERROR(subQ!N27/subQ!M27-1,"") | O33: =IFERROR(subQ!O27/subQ!N27-1,"") | Q33: =IFERROR(subQ!Q27/subQ!O27-1,"") | R33: =IFERROR(subQ!R27/subQ!Q27-1,"") | S33: =IFERROR(subQ!S27/subQ!R27-1,"") | T33: =IFERROR(subQ!T27/subQ!S27-1,"") | V33: =IFERROR(subQ!V27/subQ!T27-1,"") | W33: =IFERROR(subQ!W27/subQ!V27-1,"") | X33: =IFERROR(subQ!X27/subQ!W27-1,"") | Y33: =IFERROR(subQ!Y27/subQ!X27-1,"") | AA33: =IFERROR(subQ!AA27/subQ!Y27-1,"") | AB33: =IFERROR(subQ!AB27/subQ!AA27-1,"")
A34: drv:CAPEX | B34: yoy | C34: CAPEX YoY | J34: =IFERROR(subQ!J28/subQ!E28-1,"") | L34: =IFERROR(subQ!L28/subQ!G28-1,"") | M34: =IFERROR(subQ!M28/subQ!H28-1,"") | N34: =IFERROR(subQ!N28/subQ!I28-1,"") | O34: =IFERROR(subQ!O28/subQ!J28-1,"") | Q34: =IFERROR(subQ!Q28/subQ!L28-1,"") | R34: =IFERROR(subQ!R28/subQ!M28-1,"") | S34: =IFERROR(subQ!S28/subQ!N28-1,"") | T34: =IFERROR(subQ!T28/subQ!O28-1,"") | V34: =IFERROR(subQ!V28/subQ!Q28-1,"") | W34: =IFERROR(subQ!W28/subQ!R28-1,"") | X34: =IFERROR(subQ!X28/subQ!S28-1,"") | Y34: =IFERROR(subQ!Y28/subQ!T28-1,"") | AA34: =IFERROR(subQ!AA28/subQ!V28-1,"") | AB34: =IFERROR(subQ!AB28/subQ!W28-1,"") | AC34: -0.33298712 | AD34: -0.012303906 | AF34: 0.012614317 | AG34: 0.15711712 | AH34: 0 | AI34: 0 | AK34: 0 | AL34: 0 | AM34: 0 | AN34: 0
A35: drv:영업활동현금흐름 | B35: yoy | C35: 영업활동현금흐름 YoY | J35: =IFERROR(subQ!J29/subQ!E29-1,"") | L35: =IFERROR(subQ!L29/subQ!G29-1,"") | M35: =IFERROR(subQ!M29/subQ!H29-1,"") | N35: =IFERROR(subQ!N29/subQ!I29-1,"") | O35: =IFERROR(subQ!O29/subQ!J29-1,"") | Q35: =IFERROR(subQ!Q29/subQ!L29-1,"") | R35: =IFERROR(subQ!R29/subQ!M29-1,"") | S35: =IFERROR(subQ!S29/subQ!N29-1,"") | T35: =IFERROR(subQ!T29/subQ!O29-1,"") | V35: =IFERROR(subQ!V29/subQ!Q29-1,"") | W35: =IFERROR(subQ!W29/subQ!R29-1,"") | X35: =IFERROR(subQ!X29/subQ!S29-1,"") | Y35: =IFERROR(subQ!Y29/subQ!T29-1,"") | AA35: =IFERROR(subQ!AA29/subQ!V29-1,"") | AB35: =IFERROR(subQ!AB29/subQ!W29-1,"")
A36: drv:주식수 | B36: qoq | C36: 주식수 QoQ | G36: =IFERROR(subQ!G30/subQ!E30-1,"") | H36: =IFERROR(subQ!H30/subQ!G30-1,"") | I36: =IFERROR(subQ!I30/subQ!H30-1,"") | J36: =IFERROR(subQ!J30/subQ!I30-1,"") | L36: =IFERROR(subQ!L30/subQ!J30-1,"") | M36: =IFERROR(subQ!M30/subQ!L30-1,"") | N36: =IFERROR(subQ!N30/subQ!M30-1,"") | O36: =IFERROR(subQ!O30/subQ!N30-1,"") | Q36: =IFERROR(subQ!Q30/subQ!O30-1,"") | R36: =IFERROR(subQ!R30/subQ!Q30-1,"") | S36: =IFERROR(subQ!S30/subQ!R30-1,"") | T36: =IFERROR(subQ!T30/subQ!S30-1,"") | V36: =IFERROR(subQ!V30/subQ!T30-1,"") | W36: =IFERROR(subQ!W30/subQ!V30-1,"") | X36: =IFERROR(subQ!X30/subQ!W30-1,"") | Y36: =IFERROR(subQ!Y30/subQ!X30-1,"") | AA36: =IFERROR(subQ!AA30/subQ!Y30-1,"") | AB36: =IFERROR(subQ!AB30/subQ!AA30-1,"") | AC36: 0 | AD36: 0 | AF36: 0 | AG36: 0 | AH36: 0 | AI36: 0 | AK36: 0 | AL36: 0 | AM36: 0 | AN36: 0
A37: drv:DPS | B37: abs | C37: DPS (가정, 원) | E37: =subQ!E33 | F37: =subQ!F33 | G37: =subQ!G33 | H37: =subQ!H33 | I37: =subQ!I33 | J37: =subQ!J33 | K37: =subQ!K33 | L37: =subQ!L33 | ... AB37: =subQ!AB33 | AD37: 0 | AE37: =subQ!AE33 | AI37: 0 | AJ37: =subQ!AJ33 | AN37: 0 | AO37: =subQ!AO33
A38: drv:매출조선 | B38: sls_link | C38: 원장 밖 잔고 소진(억원) — 매출조선 = SLS 원화/100 + 이 행 + 매출조선신규 | E38: =IFERROR(subQ!E36-SLS!S122/100,"") | G38: =IFERROR(subQ!G36-SLS!T122/100,"") | H38: =IFERROR(subQ!H36-SLS!U122/100,"") | I38: =IFERROR(subQ!I36-SLS!V122/100,"") | J38: =IFERROR(subQ!J36-SLS!W122/100,"") | L38: =IFERROR(subQ!L36-SLS!X122/100,"") | M38: =IFERROR(subQ!M36-SLS!Y122/100,"") | N38: =IFERROR(subQ!N36-SLS!Z122/100,"") | O38: =IFERROR(subQ!O36-SLS!AA122/100,"") | Q38: =IFERROR(subQ!Q36-SLS!AB122/100,"") | R38: =IFERROR(subQ!R36-SLS!AC122/100,"") | S38: =IFERROR(subQ!S36-SLS!AD122/100,"") | T38: =IFERROR(subQ!T36-SLS!AE122/100,"") | V38: =IFERROR(subQ!V36-SLS!AF122/100,"") | W38: =IFERROR(subQ!W36-SLS!AG122/100,"") | X38: =IFERROR(subQ!X36-SLS!AH122/100,"") | Y38: =IFERROR(subQ!Y36-SLS!AI122/100,"") | AA38: =IFERROR(subQ!AA36-SLS!AJ122/100,"") | AB38: =IFERROR(subQ!AB36-SLS!AK122/100,"") | AC38: 2224.2304 | AD38: 2797.9984 | AF38: 2783.7197 | AG38: 2790.7389 | AH38: 919.55968 | AI38: 644.71968 | AK38: 637.73891 | AL38: 637.73891 | AM38: 644.73862 | AN38: 644.76739
A39: drv:매출조선신규 | B39: abs | C39: 매출조선신규 (공시 계약 원장 체결 속도 폴백 신규수주 매출, 억원 — 가정) | E39: =subQ!E37 | F39: =subQ!F37 | G39: =subQ!G37 | H39: =subQ!H37 | I39: =subQ!I37 | J39: =subQ!J37 | K39: =subQ!K37 | L39: =subQ!L37 | ... AB39: =subQ!AB37 | AC39: 0 | AD39: 0 | AE39: =subQ!AE37 | AF39: 102.88 | AG39: 381.61 | AH39: 791.37 | AI39: 1287.31 | AJ39: =subQ!AJ37 | AK39: 1824.59 | AL39: 2358.38 | AM39: 2843.84 | AN39: 3236.14 | AO39: =subQ!AO37
A40: drv:OP조선 | B40: ratio | C40: OP조선 마진(/매출조선) | E40: =IFERROR(subQ!E38/subQ!E36,"") | F40: =IFERROR(subQ!F38/subQ!F36,"") | G40: =IFERROR(subQ!G38/subQ!G36,"") | H40: =IFERROR(subQ!H38/subQ!H36,"") | I40: =IFERROR(subQ!I38/subQ!I36,"") | J40: =IFERROR(subQ!J38/subQ!J36,"") | K40: =IFERROR(subQ!K38/subQ!K36,"") | L40: =IFERROR(subQ!L38/subQ!L36,"") | ... AB40: =IFERROR(subQ!AB38/subQ!AB36,"") | AC40: 0.09015805 | AD40: 0.095074961 | AE40: =IFERROR(subQ!AE38/subQ!AE36,"") | AF40: 0.096055981 | AG40: 0.097964892 | AH40: 0.098786984 | AI40: 0.099639189 | AJ40: =IFERROR(subQ!AJ38/subQ!AJ36,"") | AK40: 0.10093529 | AL40: 0.1016269 | AM40: 0.099193318 | AN40: 0.097282324 | AO40: =IFERROR(subQ!AO38/subQ!AO36,"")
A41: drv:매출기타 | B41: yoy | C41: 매출기타 YoY | J41: =IFERROR(subQ!J40/subQ!E40-1,"") | L41: =IFERROR(subQ!L40/subQ!G40-1,"") | M41: =IFERROR(subQ!M40/subQ!H40-1,"") | N41: =IFERROR(subQ!N40/subQ!I40-1,"") | O41: =IFERROR(subQ!O40/subQ!J40-1,"") | Q41: =IFERROR(subQ!Q40/subQ!L40-1,"") | R41: =IFERROR(subQ!R40/subQ!M40-1,"") | S41: =IFERROR(subQ!S40/subQ!N40-1,"") | T41: =IFERROR(subQ!T40/subQ!O40-1,"") | V41: =IFERROR(subQ!V40/subQ!Q40-1,"") | W41: =IFERROR(subQ!W40/subQ!R40-1,"") | X41: =IFERROR(subQ!X40/subQ!S40-1,"") | Y41: =IFERROR(subQ!Y40/subQ!T40-1,"") | AA41: =IFERROR(subQ!AA40/subQ!V40-1,"") | AB41: =IFERROR(subQ!AB40/subQ!W40-1,"") | AC41: 0.092004263 | AD41: 0 | AF41: 0 | AG41: -0.18588266 | AH41: 0 | AI41: 0 | AK41: 0 | AL41: 0 | AM41: 0 | AN41: 0
...

Sheet BS연결
B1: (백만원) | C1: 이름: BS연결H | E1: 4Q21 | F1: 2021 | G1: 1Q22 | H1: 2Q22 | I1: 3Q22 | J1: 4Q22 | K1: 2022 | L1: 1Q23 | M1: 2Q23 | N1: 3Q23 | O1: 4Q23 | P1: 2023 | Q1: 1Q24 | R1: 2Q24 | S1: 3Q24 | T1: 4Q24 | U1: 2024 | V1: 1Q25 | W1: 2Q25 | X1: 3Q25 | Y1: 4Q25 | Z1: 2025 | AA1: 1Q26 | AB1: 2Q26 | AC1: 3Q26 | AD1: 4Q26 | AE1: 2026 | AF1: 1Q27 | AG1: 2Q27 | AH1: 3Q27 | AI1: 4Q27 | AJ1: 2027 | AK1: 1Q28 | AL1: 2Q28 | AM1: 3Q28 | AN1: 4Q28 | AO1: 2028
B2: 연결 | D2: fin json(kship_fin.py)
B3: HJ중공업(연) | C3: UPDATE: 26-10-14 | E3: 1 | F3: 2 | G3: 3 | H3: 4 | I3: 5 | J3: 6 | K3: 7 | L3: 8 | M3: 9 | N3: 10 | O3: 11 | P3: 12 | Q3: 13 | R3: 14 | S3: 15 | T3: 16 | U3: 17 | V3: 18 | W3: 19 | X3: 20 | Y3: 21 | Z3: 22 | AA3: 23 | AB3: 24 | AC3: 25 | AD3: 26 | AE3: 27 | AF3: 28 | AG3: 29 | AH3: 30 | AI3: 31 | AJ3: 32 | AK3: 33 | AL3: 34 | AM3: 35 | AN3: 36 | AO3: 37
B4: Account Code | C4: AccountNAME | E4: 2021.12 | F4: 2021.12A | G4: 2022.03 | H4: 2022.06 | I4: 2022.09 | J4: 2022.12 | K4: 2022.12A | L4: 2023.03 | M4: 2023.06 | N4: 2023.09 | O4: 2023.12 | P4: 2023.12A | Q4: 2024.03 | R4: 2024.06 | S4: 2024.09 | T4: 2024.12 | U4: 2024.12A | V4: 2025.03 | W4: 2025.06 | X4: 2025.09 | Y4: 2025.12 | Z4: 2025.12A | AA4: 2026.03 | AB4: 2026.06 | AC4: 2026.09 | AD4: 2026.12 | AE4: 2026.12A | AF4: 2027.03 | AG4: 2027.06 | AH4: 2027.09 | AI4: 2027.12 | AJ4: 2027.12A | AK4: 2028.03 | AL4: 2028.06 | AM4: 2028.09 | AN4: 2028.12 | AO4: 2028.12A
A5: 1 | C5: 유동자산 | E5: 948999 | F5: 948999 | G5: 934919 | H5: 905536 | I5: 919574 | J5: 1430318 | K5: 1430318 | L5: 1527237 | M5: 1499074 | N5: 1721672 | O5: 1727429 | P5: 1727429 | Q5: 1684956 | R5: 1604577 | S5: 1043559 | T5: 1073183 | U5: 1073183 | V5: 1087315 | W5: 1150434 | X5: 1161936 | Y5: 1258882 | Z5: 1258882 | AA5: 1259495 | AB5: 1444391
A6: 1 | C6: 현금및현금성자산 | E6: 118309 | F6: 118309 | G6: 117115 | H6: 136160 | I6: 82734 | J6: 102233 | K6: 102233 | L6: 151777 | M6: 129563 | N6: 354177 | O6: 350257 | P6: 350257 | Q6: 286569 | R6: 257006 | S6: 195208 | T6: 207128 | U6: 207128 | V6: 80370 | W6: 170190 | X6: 202147 | Y6: 332206 | Z6: 332206 | AA6: 163666 | AB6: 249747
A7: 1 | C7: 단기금융상품 | E7: 45186 | F7: 45186 | G7: 39745 | H7: 27373 | I7: 22968 | J7: 53406 | K7: 53406 | L7: 16846 | M7: 12287 | N7: 12344 | O7: 12562 | P7: 12562 | Q7: 12582 | R7: 11366 | S7: 32232 | T7: 24244 | U7: 24244 | V7: 32937 | W7: 43023 | X7: 32489 | AA7: 22279 | AB7: 25642
A8: 1 | C8: 단기금융자산 | E8: 45186 | F8: 45186 | G8: 39745 | H8: 27373 | I8: 22968 | J8: 53406 | K8: 53406 | L8: 16846 | M8: 12287 | N8: 12344 | O8: 12562 | P8: 12562 | Q8: 12582 | R8: 11366 | S8: 32232 | T8: 24244 | U8: 24244 | V8: 32937 | W8: 43023 | X8: 32489 | AA8: 22279 | AB8: 25642
A9: 1 | C9: 매출채권및기타채권 | E9: 125946 | F9: 125946 | G9: 81033 | H9: 111314 | I9: 120201 | J9: 191243 | K9: 191243 | L9: 174100 | M9: 140661 | N9: 88754 | O9: 187650 | P9: 187650 | Q9: 202263 | R9: 206662 | S9: 134221 | T9: 140270 | U9: 140270 | V9: 152468 | W9: 165509 | X9: 152458 | Y9: 182938 | Z9: 182938 | AA9: 149796 | AB9: 186655
A10: 1 | C10: 계약자산 | E10: 267748 | F10: 267748 | G10: 244889 | H10: 158347 | I10: 217745 | J10: 233295 | K10: 233295 | L10: 220328 | M10: 268614 | N10: 330340 | O10: 387498 | P10: 387498 | Q10: 288610 | R10: 267775 | S10: 210411 | T10: 274766 | U10: 274766 | V10: 270254 | W10: 244218 | X10: 219922 | Y10: 225908 | Z10: 225908 | AA10: 371333 | AB10: 419831
A11: 1 | C11: 선급금 | E11: 149511 | F11: 149511 | G11: 197216 | H11: 195378 | I11: 186976 | J11: 166055 | K11: 166055 | L11: 213315 | M11: 213426 | N11: 194801 | O11: 204693 | P11: 204693 | Q11: 290391 | R11: 278756 | S11: 290243 | T11: 250695 | U11: 250695 | V11: 343448 | W11: 316910 | X11: 326142 | Y11: 272035 | Z11: 272035 | AA11: 313316 | AB11: 324473
A12: 1 | C12: 선급금등 | E12: 149511 | F12: 149511 | G12: 197216 | H12: 195378 | I12: 186976 | J12: 166055 | K12: 166055 | L12: 213315 | M12: 213426 | N12: 194801 | O12: 204693 | P12: 204693 | Q12: 290391 | R12: 278756 | S12: 290243 | T12: 250695 | U12: 250695 | V12: 343448 | W12: 316910 | X12: 326142 | Y12: 272035 | Z12: 272035 | AA12: 313316 | AB12: 324473
A13: 1 | C13: 기타유동자산 | E13: 211903 | F13: 211903 | G13: 265279 | H13: 260427 | I13: 249701 | J13: 226637 | K13: 226637 | L13: 281024 | M13: 273368 | N13: 251191 | O13: 261430 | P13: 261430 | Q13: 357675 | R13: 337450 | S13: 349685 | T13: 315072 | U13: 315072 | V13: 416850 | W13: 398286 | X13: 413773 | Y13: 357976 | Z13: 357976 | AA13: 415652 | AB13: 424375
A14: 1 | C14: 재고자산 | E14: 147110 | F14: 147110 | G14: 149202 | H14: 181122 | I14: 210942 | J14: 200698 | K14: 200698 | L14: 220097 | M14: 249327 | N14: 235852 | O14: 135297 | P14: 135297 | Q14: 146227 | R14: 134224 | S14: 115631 | T14: 105441 | U14: 105441 | V14: 125217 | W14: 120608 | X14: 122852 | Y14: 115769 | Z14: 115769 | AA14: 122106 | AB14: 125168
A15: 1 | C15: 기타유동금융자산 | E15: 32717 | F15: 32717 | G15: 27576 | H15: 20713 | I15: 15203 | J15: 33262 | K15: 33262 | L15: 33560 | M15: 15757 | N15: 6042 | O15: 8897 | P15: 8897 | Q15: 7199 | R15: 6269 | S15: 6091 | T15: 6262 | U15: 6262 | V15: 9219 | W15: 8600 | X15: 18295 | Y15: 17966 | Z15: 17966 | AA15: 14663 | AB15: 12973
A16: 1 | C16: 매각예정비유동자산및처분자산 | E16: 80 | F16: 80 | G16: 80 | H16: 80 | I16: 80 | J16: 379542 | K16: 379542 | L16: 379542 | M16: 379542 | N16: 379542 | O16: 379542 | P16: 379542 | Q16: 379542 | R16: 379542 | S16: 80 | T16: 0 | U16: 0 | Y16: 0 | Z16: 0
A17: 1 | C17: 비유동자산 | E17: 1436237 | F17: 1436237 | G17: 1437022 | H17: 1499898 | I17: 1508661 | J17: 1137379 | K17: 1137379 | L17: 1117654 | M17: 1124410 | N17: 1056109 | O17: 1163156 | P17: 1163156 | Q17: 1167916 | R17: 1159935 | S17: 1143077 | T17: 1131246 | U17: 1131246 | V17: 1132069 | W17: 1134733 | X17: 1126095 | Y17: 1194200 | Z17: 1194200 | AA17: 1192015 | AB17: 1199989
A18: 1 | C18: 종속기업및관계기업투자 | E18: 36250 | F18: 36250 | G18: 36057 | H18: 45863 | I18: 45985 | J18: 45985 | K18: 45985 | L18: 46138 | M18: 61401 | N18: 59818 | O18: 61737 | P18: 61737 | Q18: 59238 | R18: 60312 | S18: 57373 | T18: 52170 | U18: 52170 | V18: 58501 | W18: 60396 | X18: 39989 | Y18: 39086 | Z18: 39086 | AA18: 38893 | AB18: 40702
A19: 1 | C19: 투자자산 | E19: 88694 | F19: 88694 | G19: 90602 | H19: 109543 | I19: 130421 | J19: 130707 | K19: 130707 | L19: 142903 | M19: 150247 | N19: 151509 | O19: 156794 | P19: 156794 | Q19: 156218 | R19: 150884 | S19: 140633 | T19: 135418 | U19: 135418 | V19: 145936 | W19: 144027 | X19: 135210 | Y19: 115422 | Z19: 115422 | AA19: 119305 | AB19: 123529
A20: 1 | C20: 유형자산 | E20: 923488 | F20: 923488 | G20: 925918 | H20: 969278 | I20: 973379 | J20: 644984 | K20: 644984 | L20: 643554 | M20: 642554 | N20: 642000 | O20: 745840 | P20: 745840 | Q20: 745993 | R20: 743881 | S20: 742429 | T20: 740427 | U20: 740427 | V20: 738843 | W20: 738493 | X20: 740851 | Y20: 822328 | Z20: 822328 | AA20: 821228 | AB20: 823995
A21: 1 | C21: 투자부동산 | E21: 59891 | F21: 59891 | G21: 59798 | H21: 59704 | I21: 59611 | J21: 10643 | K21: 10643 | L21: 10643 | M21: 10643 | N21: 10643 | O21: 56345 | P21: 56345 | Q21: 55337 | R21: 52374 | S21: 50605 | T21: 48478 | U21: 48478 | V21: 46700 | W21: 44918 | X21: 43541 | Y21: 42005 | Z21: 42005 | AA21: 38820 | AB21: 38488
A22: 1 | C22: 무형자산 | E22: 6209 | F22: 6209 | G22: 6094 | H22: 5979 | I22: 5865 | J22: 5748 | K22: 5748 | L22: 5635 | M22: 6224 | N22: 5536 | O22: 5416 | P22: 5416 | Q22: 5301 | R22: 5168 | S22: 5053 | T22: 4940 | U22: 4940 | V22: 4825 | W22: 4708 | X22: 4593 | Y22: 4479 | Z22: 4479 | AA22: 4364 | AB22: 4249
A23: 1 | C23: 장기대여금 | E23: 44026 | F23: 44026 | G23: 47165 | H23: 60983 | I23: 79778 | J23: 80036 | K23: 80036 | L23: 85839 | M23: 80538 | N23: 83411 | O23: 87206 | P23: 87206 | Q23: 88692 | R23: 87067 | S23: 81840 | T23: 79469 | U23: 79469 | V23: 83954 | W23: 80064 | X23: 89654 | Y23: 71374 | Z23: 71374 | AA23: 75590 | AB23: 76730
A24: 1 | C24: 사용권자산 | E24: 185908 | F24: 185908 | G24: 184257 | H24: 183731 | I24: 183002 | J24: 181681 | K24: 181681 | L24: 180966 | M24: 180233 | N24: 93155 | O24: 46514 | P24: 46514 | Q24: 44015 | R24: 44146 | S24: 42273 | T24: 41620 | U24: 41620 | V24: 39488 | W24: 47924 | X24: 45908 | Y24: 43870 | Z24: 43870 | AA24: 43124 | AB24: 39979
A25: 1 | C25: 기타비유동자산 | E25: 224791 | F25: 224791 | G25: 222252 | H25: 223165 | I25: 206634 | J25: 210622 | K25: 210622 | L25: 210867 | M25: 211254 | N25: 134434 | O25: 89941 | P25: 89941 | Q25: 91352 | R25: 92884 | S25: 89490 | T25: 84698 | U25: 84698 | V25: 79002 | W25: 85538 | X25: 84270 | Y25: 92026 | Z25: 92026 | AA25: 90614 | AB25: 91902
A26: 1 | C26: 장기매출채권및기타채권 | E26: 339 | F26: 339 | G26: 346 | H26: 0 | I26: 0 | J26: 0 | K26: 0 | O26: 0 | P26: 0 | T26: 0 | U26: 0 | Y26: 0 | Z26: 0
A27: 1 | C27: 장기금융자산 | E27: 8418 | F27: 8418 | G27: 7380 | H27: 2697 | I27: 4658 | J27: 4686 | K27: 4686 | L27: 10926 | M27: 8308 | N27: 8280 | O27: 7851 | P27: 7851 | Q27: 8288 | R27: 3505 | S27: 1420 | T27: 3779 | U27: 3779 | V27: 3481 | W27: 3567 | X27: 5567 | Y27: 4962 | Z27: 4962 | AA27: 4822 | AB27: 6097
A28: 1 | C28: 자산총계 | E28: 2385236 | F28: 2385236 | G28: 2371941 | H28: 2405434 | I28: 2428235 | J28: 2567697 | K28: 2567697 | L28: 2644891 | M28: 2623484 | N28: 2777781 | O28: 2890585 | P28: 2890585 | Q28: 2852872 | R28: 2764512 | S28: 2186636 | T28: 2204429 | U28: 2204429 | V28: 2219384 | W28: 2285167 | X28: 2288031 | Y28: 2453082 | Z28: 2453082 | AA28: 2451510 | AB28: 2644380
A29: 1 | C29: 유동부채 | E29: 949994 | F29: 949994 | G29: 934823 | H29: 892571 | I29: 1034810 | J29: 1418222 | K29: 1418222 | L29: 1555760 | M29: 2141496 | N29: 2133838 | O29: 2125811 | P29: 2125811 | Q29: 2066092 | R29: 2017808 | S29: 1485051 | T29: 1555136 | U29: 1555136 | V29: 1560570 | W29: 1577354 | X29: 1585489 | Y29: 1491810 | Z29: 1491810 | AA29: 1458784 | AB29: 1391706
A30: 1 | C30: 매입채무및기타채무 | E30: 314782 | F30: 314782 | G30: 257206 | H30: 260808 | I30: 262620 | J30: 330500 | K30: 330500 | L30: 353136 | M30: 405750 | N30: 396293 | O30: 475323 | P30: 475323 | Q30: 436846 | R30: 511763 | S30: 381001 | T30: 386632 | U30: 386632 | V30: 393985 | W30: 409447 | X30: 439740 | Y30: 399070 | Z30: 399070 | AA30: 397446 | AB30: 401860
A31: 1 | C31: 유동성장기부채 | E31: 150785 | F31: 150785 | G31: 150785 | H31: 70785 | I31: 70785 | J31: 70785 | K31: 70785 | L31: 123685 | M31: 657143 | N31: 662313 | O31: 656520 | P31: 656520 | Q31: 662635 | R31: 623770 | S31: 452151 | T31: 70178 | U31: 70178 | V31: 68176 | W31: 65926 | X31: 62896 | Y31: 87896 | Z31: 87896 | AA31: 87896 | AB31: 42646
A32: 1 | C32: 계약부채 | E32: 298803 | F32: 298803 | G32: 356841 | H32: 401262 | I32: 372818 | J32: 472547 | K32: 472547 | L32: 554724 | M32: 546181 | N32: 711032 | O32: 616653 | P32: 616653 | Q32: 635090 | R32: 578712 | S32: 457810 | T32: 507566 | U32: 507566 | V32: 518746 | W32: 618176 | X32: 607326 | Y32: 542275 | Z32: 542275 | AA32: 519638 | AB32: 565272
A33: 1 | C33: 단기충당부채 | E33: 143937 | F33: 143937 | G33: 124560 | H33: 113702 | I33: 100629 | J33: 131793 | K33: 131793 | L33: 113111 | M33: 127901 | N33: 119811 | O33: 132953 | P33: 132953 | Q33: 86857 | R33: 65063 | S33: 55403 | T33: 71805 | U33: 71805 | V33: 66097 | W33: 59700 | X33: 59636 | Y33: 50616 | Z33: 50616 | AA33: 44973 | AB33: 47563
A34: 1 | C34: 기타유동금융부채 | E34: 28688 | F34: 28688 | G34: 28765 | H34: 29401 | I34: 194259 | J34: 193791 | K34: 193791 | L34: 193875 | M34: 194121 | N34: 33779 | O34: 35581 | P34: 35581 | Q34: 36656 | R34: 31943 | S34: 29211 | T34: 28368 | U34: 28368 | V34: 30245 | W34: 31776 | X34: 29285 | Y34: 29616 | Z34: 29616 | AA34: 31985 | AB34: 35734
A35: 1 | C35: 단기금융부채 | E35: 28688 | F35: 28688 | G35: 28765 | H35: 29401 | I35: 194259 | J35: 193791 | K35: 193791 | L35: 193875 | M35: 194121 | N35: 33779 | O35: 35581 | P35: 35581 | Q35: 36656 | R35: 31943 | S35: 29211 | T35: 28368 | U35: 28368 | V35: 30245 | W35: 31776 | X35: 29285 | Y35: 29616 | Z35: 29616 | AA35: 31985 | AB35: 35734
A36: 1 | C36: 기타유동부채 | E36: 12999 | F36: 12999 | G36: 16666 | H36: 16613 | I36: 33699 | J36: 218806 | K36: 218806 | L36: 217229 | M36: 210400 | N36: 210610 | O36: 208781 | P36: 208781 | Q36: 208008 | R36: 206557 | S36: 109475 | T36: 108840 | U36: 108840 | V36: 109148 | W36: 110152 | X36: 110513 | Y36: 111817 | Z36: 111817 | AA36: 109403 | AB36: 108598
A37: 1 | C37: 비유동부채 | E37: 1003237 | F37: 1003237 | G37: 1015066 | H37: 1105384 | I37: 1006201 | J37: 764485 | K37: 764485 | L37: 728779 | M37: 201420 | N37: 367906 | O37: 423862 | P37: 423862 | Q37: 432029 | R37: 433452 | S37: 335929 | T37: 305896 | U37: 305896 | V37: 310079 | W37: 364169 | X37: 355236 | Y37: 291684 | Z37: 291684 | AA37: 298775 | AB37: 499746
A38: 1 | C38: 사채 | E38: 28455 | F38: 28455 | G38: 28695 | H38: 28937 | I38: 29179 | J38: 29421 | K38: 29421 | L38: 29664 | M38: 0 | N38: 0 | O38: 0 | P38: 0 | T38: 0 | U38: 0 | Y38: 0 | Z38: 0
A39: 1 | C39: 장기차입금 | E39: 501064 | F39: 501064 | G39: 504714 | H39: 512205 | I39: 575853 | J39: 551007 | K39: 551007 | L39: 502539 | M39: 1571 | N39: 785 | O39: 25785 | P39: 25785 | Q39: 25785 | R39: 25785 | S39: 25000 | T39: 25000 | U39: 25000 | V39: 25000 | W39: 68428 | X39: 68610 | Y39: 43798 | Z39: 43798 | AA39: 43987 | AB39: 242397
A40: 1 | C40: 확정급여부채 | E40: 60832 | F40: 60832 | G40: 70087 | H40: 72630 | I40: 74669 | J40: 63747 | K40: 63747 | L40: 73192 | M40: 75422 | N40: 77765 | O40: 80222 | P40: 80222 | Q40: 88247 | R40: 90644 | S40: 94025 | T40: 92436 | U40: 92436 | V40: 101442 | W40: 104137 | X40: 107500 | Y40: 76072 | Z40: 76072 | AA40: 86530 | AB40: 89731
...

Sheet BS별도
B1: (백만원) | C1: 이름: BS별도H | E1: 4Q21 | F1: 2021 | G1: 1Q22 | H1: 2Q22 | I1: 3Q22 | J1: 4Q22 | K1: 2022 | L1: 1Q23 | M1: 2Q23 | N1: 3Q23 | O1: 4Q23 | P1: 2023 | Q1: 1Q24 | R1: 2Q24 | S1: 3Q24 | T1: 4Q24 | U1: 2024 | V1: 1Q25 | W1: 2Q25 | X1: 3Q25 | Y1: 4Q25 | Z1: 2025 | AA1: 1Q26 | AB1: 2Q26 | AC1: 3Q26 | AD1: 4Q26 | AE1: 2026 | AF1: 1Q27 | AG1: 2Q27 | AH1: 3Q27 | AI1: 4Q27 | AJ1: 2027 | AK1: 1Q28 | AL1: 2Q28 | AM1: 3Q28 | AN1: 4Q28 | AO1: 2028
B2: 별도 | D2: fin json(kship_fin.py)
B3: HJ중공업(별) | C3: UPDATE: 26-10-14 | E3: 1 | F3: 2 | G3: 3 | H3: 4 | I3: 5 | J3: 6 | K3: 7 | L3: 8 | M3: 9 | N3: 10 | O3: 11 | P3: 12 | Q3: 13 | R3: 14 | S3: 15 | T3: 16 | U3: 17 | V3: 18 | W3: 19 | X3: 20 | Y3: 21 | Z3: 22 | AA3: 23 | AB3: 24 | AC3: 25 | AD3: 26 | AE3: 27 | AF3: 28 | AG3: 29 | AH3: 30 | AI3: 31 | AJ3: 32 | AK3: 33 | AL3: 34 | AM3: 35 | AN3: 36 | AO3: 37
B4: Account Code | C4: AccountNAME | E4: 2021.12 | F4: 2021.12A | G4: 2022.03 | H4: 2022.06 | I4: 2022.09 | J4: 2022.12 | K4: 2022.12A | L4: 2023.03 | M4: 2023.06 | N4: 2023.09 | O4: 2023.12 | P4: 2023.12A | Q4: 2024.03 | R4: 2024.06 | S4: 2024.09 | T4: 2024.12 | U4: 2024.12A | V4: 2025.03 | W4: 2025.06 | X4: 2025.09 | Y4: 2025.12 | Z4: 2025.12A | AA4: 2026.03 | AB4: 2026.06 | AC4: 2026.09 | AD4: 2026.12 | AE4: 2026.12A | AF4: 2027.03 | AG4: 2027.06 | AH4: 2027.09 | AI4: 2027.12 | AJ4: 2027.12A | AK4: 2028.03 | AL4: 2028.06 | AM4: 2028.09 | AN4: 2028.12 | AO4: 2028.12A
A5: 1 | C5: 유동자산 | E5: 948911 | F5: 948911 | G5: 934811 | H5: 905456 | I5: 919500 | J5: 1430242 | K5: 1430242 | L5: 1527162 | M5: 1469744 | N5: 1717779 | O5: 1724579 | P5: 1724579 | Q5: 1682650 | R5: 1602652 | S5: 1041804 | T5: 1073132 | U5: 1073132 | V5: 1087266 | W5: 1150107 | X5: 1161613 | Y5: 1258557 | Z5: 1258557 | AA5: 1259136 | AB5: 1444063
A6: 1 | C6: 현금및현금성자산 | E6: 118298 | F6: 118298 | G6: 117104 | H6: 136138 | I6: 82718 | J6: 102217 | K6: 102217 | L6: 151763 | M6: 100845 | N6: 350400 | O6: 347519 | P6: 347519 | Q6: 284379 | R6: 255142 | S6: 193509 | T6: 207117 | U6: 207117 | V6: 80360 | W6: 169892 | X6: 201935 | Y6: 332116 | Z6: 332116 | AA6: 163576 | AB6: 249647
A7: 1 | C7: 단기금융상품 | E7: 45056 | F7: 45056 | G7: 39615 | H7: 27263 | I7: 22858 | J7: 53296 | K7: 53296 | L7: 16736 | M7: 12183 | N7: 12240 | O7: 12458 | P7: 12458 | Q7: 12478 | R7: 11276 | S7: 32142 | T7: 24154 | U7: 24154 | V7: 32847 | W7: 42942 | X7: 32408 | Y7: 26038 | Z7: 26038 | AA7: 22198 | AB7: 25560
A8: 1 | C8: 단기금융자산 | E8: 45056 | F8: 45056 | G8: 39615 | H8: 27263 | I8: 22858 | J8: 53296 | K8: 53296 | L8: 16736 | M8: 12183 | N8: 12240 | O8: 12458 | P8: 12458 | Q8: 12478 | R8: 11276 | S8: 32142 | T8: 24154 | U8: 24154 | V8: 32847 | W8: 42942 | X8: 32408 | Y8: 26038 | Z8: 26038 | AA8: 22198 | AB8: 25560
A9: 1 | C9: 매출채권및기타채권 | E9: 125998 | F9: 125998 | G9: 81066 | H9: 111366 | I9: 120253 | J9: 191295 | K9: 191295 | L9: 174153 | M9: 140611 | N9: 88751 | O9: 187649 | P9: 187649 | Q9: 202261 | R9: 206701 | S9: 134264 | T9: 140323 | U9: 140323 | V9: 152521 | W9: 165562 | X9: 152510 | Y9: 182991 | Z9: 182991 | AA9: 149848 | AB9: 186707
A10: 1 | C10: 계약자산 | E10: 267748 | F10: 267748 | G10: 244889 | H10: 158347 | I10: 217745 | J10: 233295 | K10: 233295 | L10: 220328 | M10: 268615 | N10: 330340 | O10: 387497 | P10: 387497 | Q10: 288610 | R10: 267775 | S10: 210411 | T10: 274766 | U10: 274766 | V10: 270254 | W10: 244218 | X10: 219922 | Y10: 225908 | Z10: 225908 | AA10: 371333 | AB10: 419831
A11: 1 | C11: 선급금 | E11: 149512 | F11: 149512 | G11: 197216 | H11: 195378 | I11: 186976 | J11: 166055 | K11: 166055 | L11: 213314 | M11: 213426 | N11: 194799 | O11: 204694 | P11: 204694 | Q11: 290387 | R11: 278752 | S11: 290239 | T11: 250694 | U11: 250694 | V11: 343447 | W11: 316909 | X11: 326142 | Y11: 272033 | Z11: 272033 | AA11: 313315 | AB11: 324474
A12: 1 | C12: 선급금등 | E12: 149512 | F12: 149512 | G12: 197216 | H12: 195378 | I12: 186976 | J12: 166055 | K12: 166055 | L12: 213314 | M12: 213426 | N12: 194799 | O12: 204694 | P12: 204694 | Q12: 290387 | R12: 278752 | S12: 290239 | T12: 250694 | U12: 250694 | V12: 343447 | W12: 316909 | X12: 326142 | Y12: 272033 | Z12: 272033 | AA12: 313315 | AB12: 324474
A13: 1 | C13: 기타유동자산 | E13: 211904 | F13: 211904 | G13: 265279 | H13: 260427 | I13: 249701 | J13: 226637 | K13: 226637 | L13: 281022 | M13: 272909 | N13: 251184 | O13: 261427 | P13: 261427 | Q13: 357668 | R13: 337442 | S13: 349678 | T13: 315070 | U13: 315070 | V13: 416849 | W13: 398285 | X13: 413691 | Y13: 357770 | Z13: 357770 | AA13: 415413 | AB13: 424177
A14: 1 | C14: 재고자산 | E14: 147110 | F14: 147110 | G14: 149202 | H14: 181122 | I14: 210942 | J14: 200698 | K14: 200698 | L14: 220097 | M14: 249327 | N14: 235852 | O14: 135297 | P14: 135297 | Q14: 146227 | R14: 134224 | S14: 115631 | T14: 105441 | U14: 105441 | V14: 125217 | W14: 120608 | X14: 122852 | Y14: 115769 | Z14: 115769 | AA14: 122106 | AB14: 125168
A15: 1 | C15: 기타유동금융자산 | E15: 32717 | F15: 32717 | G15: 27576 | H15: 20713 | I15: 15203 | J15: 33260 | K15: 33260 | L15: 33558 | M15: 15757 | N15: 6040 | O15: 8894 | P15: 8894 | Q15: 7196 | R15: 6267 | S15: 6089 | T15: 6261 | U15: 6261 | V15: 9218 | W15: 8600 | X15: 18295 | Y15: 17965 | Z15: 17965 | AA15: 14662 | AB15: 12973
A16: 1 | C16: 매각예정비유동자산및처분자산 | E16: 80 | F16: 80 | G16: 80 | H16: 80 | I16: 80 | J16: 379542 | K16: 379542 | L16: 379542 | M16: 379542 | N16: 379542 | O16: 379542 | P16: 379542 | Q16: 379542 | R16: 379542 | S16: 80 | T16: 0 | U16: 0 | Y16: 0 | Z16: 0
A17: 1 | C17: 비유동자산 | E17: 1432133 | F17: 1432133 | G17: 1433035 | H17: 1496027 | I17: 1504906 | J17: 1133741 | K17: 1133741 | L17: 1114133 | M17: 1122429 | N17: 1054376 | O17: 1161038 | P17: 1161038 | Q17: 1165440 | R17: 1157800 | S17: 1140982 | T17: 1129115 | U17: 1129115 | V17: 1130054 | W17: 1133118 | X17: 1124597 | Y17: 1192819 | Z17: 1192819 | AA17: 1190749 | AB17: 1198852
A18: 1 | C18: 종속기업및관계기업투자 | E18: 36250 | F18: 36250 | G18: 36057 | H18: 45863 | I18: 45985 | J18: 45985 | K18: 45985 | L18: 46138 | M18: 62896 | N18: 60869 | O18: 62275 | P18: 62275 | Q18: 59301 | R18: 60596 | S18: 57573 | T18: 52171 | U18: 52171 | V18: 58501 | W18: 60396 | X18: 39989 | Y18: 39087 | Z18: 39087 | AA18: 38893 | AB18: 40702
A19: 1 | C19: 투자자산 | E19: 88694 | F19: 88694 | G19: 90602 | H19: 109543 | I19: 130421 | J19: 130707 | K19: 130707 | L19: 142903 | M19: 151742 | N19: 152560 | O19: 157332 | P19: 157332 | Q19: 156281 | R19: 151168 | S19: 140833 | T19: 135419 | U19: 135419 | V19: 145937 | W19: 144310 | X19: 135493 | Y19: 115707 | Z19: 115707 | AA19: 119589 | AB19: 123812
A20: 1 | C20: 유형자산 | E20: 921567 | F20: 921567 | G20: 924011 | H20: 967385 | I20: 971500 | J20: 643121 | K20: 643121 | L20: 641704 | M20: 640650 | N20: 640112 | O20: 743975 | P20: 743975 | Q20: 744142 | R20: 742048 | S20: 740618 | T20: 738677 | U20: 738677 | V20: 737108 | W20: 736772 | X20: 739145 | Y20: 820636 | Z20: 820636 | AA20: 819550 | AB20: 822331
A21: 1 | C21: 투자부동산 | E21: 59891 | F21: 59891 | G21: 59798 | H21: 59705 | I21: 59611 | J21: 10643 | K21: 10643 | L21: 10643 | M21: 10643 | N21: 10643 | O21: 56345 | P21: 56345 | Q21: 55337 | R21: 52374 | S21: 50605 | T21: 48478 | U21: 48478 | V21: 46700 | W21: 44918 | X21: 43541 | Y21: 42005 | Z21: 42005 | AA21: 38820 | AB21: 38488
A22: 1 | C22: 무형자산 | E22: 2323 | F22: 2323 | G22: 2323 | H22: 2323 | I22: 2325 | J22: 2323 | K22: 2323 | L22: 2325 | M22: 3028 | N22: 3028 | O22: 3027 | P22: 3027 | Q22: 3028 | R22: 3010 | S22: 3010 | T22: 3012 | U22: 3012 | V22: 3012 | W22: 3011 | X22: 3011 | Y22: 3011 | Z22: 3011 | AA22: 3012 | AB22: 3012
A23: 1 | C23: 장기대여금 | E23: 44026 | F23: 44026 | G23: 47165 | H23: 60983 | I23: 79778 | J23: 80036 | K23: 80036 | L23: 85839 | M23: 80538 | N23: 83411 | O23: 87206 | P23: 87206 | Q23: 88692 | R23: 87067 | S23: 81840 | T23: 79469 | U23: 79469 | V23: 83955 | W23: 80347 | X23: 89937 | Y23: 71658 | Z23: 71658 | AA23: 75874 | AB23: 77013
A24: 1 | C24: 사용권자산 | E24: 185908 | F24: 185908 | G24: 184257 | H24: 183731 | I24: 183002 | J24: 181681 | K24: 181681 | L24: 180966 | M24: 180233 | N24: 93156 | O24: 46514 | P24: 46514 | Q24: 44015 | R24: 44146 | S24: 42273 | T24: 41620 | U24: 41620 | V24: 39488 | W24: 47924 | X24: 45908 | Y24: 43870 | Z24: 43870 | AA24: 43124 | AB24: 39979
A25: 1 | C25: 기타비유동자산 | E25: 224791 | F25: 224791 | G25: 222253 | H25: 223165 | I25: 206634 | J25: 210621 | K25: 210621 | L25: 210868 | M25: 211254 | N25: 134435 | O25: 89941 | P25: 89941 | Q25: 91352 | R25: 92884 | S25: 89490 | T25: 84698 | U25: 84698 | V25: 79001 | W25: 85538 | X25: 84270 | Y25: 92026 | Z25: 92026 | AA25: 90613 | AB25: 91902
A26: 1 | C26: 장기매출채권및기타채권 | E26: 2042 | F26: 2042 | G26: 2036 | H26: 1677 | I26: 1664 | J26: 1651 | K26: 1651 | L26: 1638 | M26: 1624 | N26: 1611 | O26: 1598 | P26: 1598 | Q26: 1585 | R26: 1572 | T26: 0 | U26: 0 | V26: 1533 | W26: 1520 | X26: 1507 | Y26: 0 | Z26: 0 | AA26: 1481 | AB26: 1481
A27: 1 | C27: 장기금융자산 | E27: 8418 | F27: 8418 | G27: 7380 | H27: 2697 | I27: 4658 | J27: 4686 | K27: 4686 | L27: 10926 | M27: 8308 | N27: 8280 | O27: 7851 | P27: 7851 | Q27: 8288 | R27: 3505 | S27: 1420 | T27: 3779 | U27: 3779 | V27: 3481 | W27: 3567 | X27: 5567 | Y27: 4962 | Z27: 4962 | AA27: 4822 | AB27: 6097
A28: 1 | C28: 자산총계 | E28: 2381044 | F28: 2381044 | G28: 2367846 | H28: 2401483 | I28: 2424406 | J28: 2563983 | K28: 2563983 | L28: 2641295 | M28: 2592173 | N28: 2772155 | O28: 2885617 | P28: 2885617 | Q28: 2848090 | R28: 2760452 | S28: 2182786 | T28: 2202247 | U28: 2202247 | V28: 2217320 | W28: 2283225 | X28: 2286210 | Y28: 2451376 | Z28: 2451376 | AA28: 2449885 | AB28: 2642915
A29: 1 | C29: 유동부채 | E29: 947510 | F29: 947510 | G29: 932325 | H29: 890113 | I29: 1032367 | J29: 1415824 | K29: 1415824 | L29: 1554976 | M29: 2113375 | N29: 2130565 | O29: 2122908 | P29: 2122908 | Q29: 2063119 | R29: 2015511 | S29: 1482820 | T29: 1554390 | U29: 1554390 | V29: 1559816 | W29: 1576602 | X29: 1584741 | Y29: 1491064 | Z29: 1491064 | AA29: 1457993 | AB29: 1390955
A30: 1 | C30: 매입채무및기타채무 | E30: 312298 | F30: 312298 | G30: 254708 | H30: 258352 | I30: 260178 | J30: 328103 | K30: 328103 | L30: 352352 | M30: 377630 | N30: 393842 | O30: 473208 | P30: 473208 | Q30: 434694 | R30: 510082 | S30: 379361 | T30: 385888 | U30: 385888 | V30: 393232 | W30: 408696 | X30: 438994 | Y30: 398325 | Z30: 398325 | AA30: 396656 | AB30: 401109
A31: 1 | C31: 유동성장기부채 | E31: 150785 | F31: 150785 | G31: 150785 | H31: 70785 | I31: 70785 | J31: 70785 | K31: 70785 | L31: 123685 | M31: 657143 | N31: 662313 | O31: 656520 | P31: 656520 | Q31: 662635 | R31: 623770 | S31: 452151 | T31: 70178 | U31: 70178 | V31: 68176 | W31: 65926 | X31: 62896 | Y31: 87896 | Z31: 87896 | AA31: 87896 | AB31: 42646
A32: 1 | C32: 계약부채 | E32: 298803 | F32: 298803 | G32: 356841 | H32: 401262 | I32: 372818 | J32: 472547 | K32: 472547 | L32: 554724 | M32: 546181 | N32: 711032 | O32: 616653 | P32: 616653 | Q32: 635090 | R32: 578712 | S32: 457810 | T32: 507566 | U32: 507566 | V32: 518746 | W32: 618176 | X32: 607326 | Y32: 542275 | Z32: 542275 | AA32: 519638 | AB32: 565272
A33: 1 | C33: 단기충당부채 | E33: 143937 | F33: 143937 | G33: 124560 | H33: 113702 | I33: 100629 | J33: 131793 | K33: 131793 | L33: 113111 | M33: 127901 | N33: 119811 | O33: 132953 | P33: 132953 | Q33: 86857 | R33: 65063 | S33: 55403 | T33: 71805 | U33: 71805 | V33: 66097 | W33: 59700 | X33: 59636 | Y33: 50616 | Z33: 50616 | AA33: 44973 | AB33: 47563
A34: 1 | C34: 기타유동금융부채 | E34: 28688 | F34: 28688 | G34: 28765 | H34: 29400 | I34: 194259 | J34: 193791 | K34: 193791 | L34: 193875 | M34: 194121 | N34: 33487 | O34: 35299 | P34: 35299 | Q34: 36363 | R34: 31864 | S34: 29133 | T34: 28368 | U34: 28368 | V34: 30245 | W34: 31776 | X34: 29285 | Y34: 29616 | Z34: 29616 | AA34: 31985 | AB34: 35735
A35: 1 | C35: 단기금융부채 | E35: 28688 | F35: 28688 | G35: 28765 | H35: 29400 | I35: 194259 | J35: 193791 | K35: 193791 | L35: 193875 | M35: 194121 | N35: 33487 | O35: 35299 | P35: 35299 | Q35: 36363 | R35: 31864 | S35: 29133 | T35: 28368 | U35: 28368 | V35: 30245 | W35: 31776 | X35: 29285 | Y35: 29616 | Z35: 29616 | AA35: 31985 | AB35: 35735
A36: 1 | C36: 기타유동부채 | E36: 12999 | F36: 12999 | G36: 16666 | H36: 16612 | I36: 33698 | J36: 218805 | K36: 218805 | L36: 217229 | M36: 210399 | N36: 210080 | O36: 208275 | P36: 208275 | Q36: 207480 | R36: 206020 | S36: 108962 | T36: 108838 | U36: 108838 | V36: 109147 | W36: 110151 | X36: 110511 | Y36: 111816 | Z36: 111816 | AA36: 109402 | AB36: 108597
A37: 1 | C37: 비유동부채 | E37: 1001336 | F37: 1001336 | G37: 1013278 | H37: 1103697 | I37: 1004639 | J37: 763003 | K37: 763003 | L37: 725807 | M37: 198581 | N37: 365201 | O37: 421300 | P37: 421300 | Q37: 429610 | R37: 431171 | S37: 333786 | T37: 303895 | U37: 303895 | V37: 308225 | W37: 362462 | X37: 353677 | Y37: 290276 | Z37: 290276 | AA37: 297522 | AB37: 498649
A38: 1 | C38: 사채 | E38: 28455 | F38: 28455 | G38: 28695 | H38: 28937 | I38: 29179 | J38: 29421 | K38: 29421 | L38: 29664 | M38: 0 | N38: 0 | O38: 0 | P38: 0 | T38: 0 | U38: 0 | Y38: 0 | Z38: 0
A39: 1 | C39: 장기차입금 | E39: 501064 | F39: 501064 | G39: 504714 | H39: 512205 | I39: 575853 | J39: 551007 | K39: 551007 | L39: 502539 | M39: 1571 | N39: 785 | O39: 25785 | P39: 25785 | Q39: 25785 | R39: 25785 | S39: 25000 | T39: 25000 | U39: 25000 | V39: 25000 | W39: 68428 | X39: 68610 | Y39: 43798 | Z39: 43798 | AA39: 43987 | AB39: 242397
A40: 1 | C40: 확정급여부채 | E40: 60832 | F40: 60832 | G40: 70087 | H40: 72630 | I40: 74669 | J40: 63747 | K40: 63747 | L40: 73192 | M40: 75422 | N40: 77765 | O40: 80222 | P40: 80222 | Q40: 88247 | R40: 90644 | S40: 94025 | T40: 92436 | U40: 92436 | V40: 101442 | W40: 104137 | X40: 107500 | Y40: 76072 | Z40: 76072 | AA40: 86530 | AB40: 89731
...

Sheet subQ
A1: YQ | C1: subQ 분기 서브모델(억원, U=100) | E1: 4Q21 | F1: 2021 | G1: 1Q22 | H1: 2Q22 | I1: 3Q22 | J1: 4Q22 | K1: 2022 | L1: 1Q23 | M1: 2Q23 | N1: 3Q23 | O1: 4Q23 | P1: 2023 | Q1: 1Q24 | R1: 2Q24 | S1: 3Q24 | T1: 4Q24 | U1: 2024 | V1: 1Q25 | W1: 2Q25 | X1: 3Q25 | Y1: 4Q25 | Z1: 2025 | AA1: 1Q26 | AB1: 2Q26 | AC1: 3Q26 | AD1: 4Q26 | AE1: 2026 | AF1: 1Q27 | AG1: 2Q27 | AH1: 3Q27 | AI1: 4Q27 | AJ1: 2027 | AK1: 1Q28 | AL1: 2Q28 | AM1: 3Q28 | AN1: 4Q28 | AO1: 2028
A2: A=이름(key) B=그룹 C=단위 D=FnGuide 계정명(VLOOKUP 키). 확정=VLOOKUP(BS), 추정=변수 가정 참조
E3: 1 | F3: 2 | G3: 3 | H3: 4 | I3: 5 | J3: 6 | K3: 7 | L3: 8 | M3: 9 | N3: 10 | O3: 11 | P3: 12 | Q3: 13 | R3: 14 | S3: 15 | T3: 16 | U3: 17 | V3: 18 | W3: 19 | X3: 20 | Y3: 21 | Z3: 22 | AA3: 23 | AB3: 24 | AC3: 25 | AD3: 26 | AE3: 27 | AF3: 28 | AG3: 29 | AH3: 30 | AI3: 31 | AJ3: 32 | AK3: 33 | AL3: 34 | AM3: 35 | AN3: 36 | AO3: 37
E4: 2021.12 | F4: 2021.12A | G4: 2022.03 | H4: 2022.06 | I4: 2022.09 | J4: 2022.12 | K4: 2022.12A | L4: 2023.03 | M4: 2023.06 | N4: 2023.09 | O4: 2023.12 | P4: 2023.12A | Q4: 2024.03 | R4: 2024.06 | S4: 2024.09 | T4: 2024.12 | U4: 2024.12A | V4: 2025.03 | W4: 2025.06 | X4: 2025.09 | Y4: 2025.12 | Z4: 2025.12A | AA4: 2026.03 | AB4: 2026.06 | AC4: 2026.09 | AD4: 2026.12 | AE4: 2026.12A | AF4: 2027.03 | AG4: 2027.06 | AH4: 2027.09 | AI4: 2027.12 | AJ4: 2027.12A | AK4: 2028.03 | AL4: 2028.06 | AM4: 2028.09 | AN4: 2028.12 | AO4: 2028.12A
A5: 매출액 | B5: 손익 | C5: 억원 | D5: 매출액(수익) | E5: =IFERROR(VLOOKUP($D5,BS연결,MATCH(E$1,BS연결H,0),0)/100,"") | G5: =IFERROR(VLOOKUP($D5,BS연결,MATCH(G$1,BS연결H,0),0)/100,"") | H5: =IFERROR(VLOOKUP($D5,BS연결,MATCH(H$1,BS연결H,0),0)/100,"") | I5: =IFERROR(VLOOKUP($D5,BS연결,MATCH(I$1,BS연결H,0),0)/100,"") | J5: =IFERROR(VLOOKUP($D5,BS연결,MATCH(J$1,BS연결H,0),0)/100,"") | K5: =IFERROR(VLOOKUP($D5,BS연결,MATCH(K$1,BS연결H,0),0)/100,"") | L5: =IFERROR(VLOOKUP($D5,BS연결,MATCH(L$1,BS연결H,0),0)/100,"") | M5: =IFERROR(VLOOKUP($D5,BS연결,MATCH(M$1,BS연결H,0),0)/100,"") | N5: =IFERROR(VLOOKUP($D5,BS연결,MATCH(N$1,BS연결H,0),0)/100,"") | ... AB5: =IFERROR(VLOOKUP($D5,BS연결,MATCH(AB$1,BS연결H,0),0)/100,"") | AC5: =IFERROR(AC36+AC40,"") | AD5: =IFERROR(AD36+AD40,"") | AE5: =SUM(AA5:AD5) | AF5: =IFERROR(AF36+AF40,"") | AG5: =IFERROR(AG36+AG40,"") | AH5: =IFERROR(AH36+AH40,"") | AI5: =IFERROR(AI36+AI40,"") | AJ5: =SUM(AF5:AI5) | AK5: =IFERROR(AK36+AK40,"") | AL5: =IFERROR(AL36+AL40,"") | AM5: =IFERROR(AM36+AM40,"") | AN5: =IFERROR(AN36+AN40,"") | AO5: =SUM(AK5:AN5)
A6: 매출원가 | B6: 손익 | C6: 억원 | D6: 매출원가 | E6: =IFERROR(VLOOKUP($D6,BS연결,MATCH(E$1,BS연결H,0),0)/100,"") | G6: =IFERROR(VLOOKUP($D6,BS연결,MATCH(G$1,BS연결H,0),0)/100,"") | H6: =IFERROR(VLOOKUP($D6,BS연결,MATCH(H$1,BS연결H,0),0)/100,"") | I6: =IFERROR(VLOOKUP($D6,BS연결,MATCH(I$1,BS연결H,0),0)/100,"") | J6: =IFERROR(VLOOKUP($D6,BS연결,MATCH(J$1,BS연결H,0),0)/100,"") | K6: =IFERROR(VLOOKUP($D6,BS연결,MATCH(K$1,BS연결H,0),0)/100,"") | L6: =IFERROR(VLOOKUP($D6,BS연결,MATCH(L$1,BS연결H,0),0)/100,"") | M6: =IFERROR(VLOOKUP($D6,BS연결,MATCH(M$1,BS연결H,0),0)/100,"") | N6: =IFERROR(VLOOKUP($D6,BS연결,MATCH(N$1,BS연결H,0),0)/100,"") | ... AB6: =IFERROR(VLOOKUP($D6,BS연결,MATCH(AB$1,BS연결H,0),0)/100,"") | AC6: =IFERROR(AC5-AC7,"") | AD6: =IFERROR(AD5-AD7,"") | AE6: =SUM(AA6:AD6) | AF6: =IFERROR(AF5-AF7,"") | AG6: =IFERROR(AG5-AG7,"") | AH6: =IFERROR(AH5-AH7,"") | AI6: =IFERROR(AI5-AI7,"") | AJ6: =SUM(AF6:AI6) | AK6: =IFERROR(AK5-AK7,"") | AL6: =IFERROR(AL5-AL7,"") | AM6: =IFERROR(AM5-AM7,"") | AN6: =IFERROR(AN5-AN7,"") | AO6: =SUM(AK6:AN6)
A7: 매출총이익 | B7: 손익 | C7: 억원 | D7: 매출총이익 | E7: =IFERROR(VLOOKUP($D7,BS연결,MATCH(E$1,BS연결H,0),0)/100,"") | G7: =IFERROR(VLOOKUP($D7,BS연결,MATCH(G$1,BS연결H,0),0)/100,"") | H7: =IFERROR(VLOOKUP($D7,BS연결,MATCH(H$1,BS연결H,0),0)/100,"") | I7: =IFERROR(VLOOKUP($D7,BS연결,MATCH(I$1,BS연결H,0),0)/100,"") | J7: =IFERROR(VLOOKUP($D7,BS연결,MATCH(J$1,BS연결H,0),0)/100,"") | K7: =IFERROR(VLOOKUP($D7,BS연결,MATCH(K$1,BS연결H,0),0)/100,"") | L7: =IFERROR(VLOOKUP($D7,BS연결,MATCH(L$1,BS연결H,0),0)/100,"") | M7: =IFERROR(VLOOKUP($D7,BS연결,MATCH(M$1,BS연결H,0),0)/100,"") | N7: =IFERROR(VLOOKUP($D7,BS연결,MATCH(N$1,BS연결H,0),0)/100,"") | ... AB7: =IFERROR(VLOOKUP($D7,BS연결,MATCH(AB$1,BS연결H,0),0)/100,"") | AC7: =IFERROR(AC9+AC8,"") | AD7: =IFERROR(AD9+AD8,"") | AE7: =SUM(AA7:AD7) | AF7: =IFERROR(AF9+AF8,"") | AG7: =IFERROR(AG9+AG8,"") | AH7: =IFERROR(AH9+AH8,"") | AI7: =IFERROR(AI9+AI8,"") | AJ7: =SUM(AF7:AI7) | AK7: =IFERROR(AK9+AK8,"") | AL7: =IFERROR(AL9+AL8,"") | AM7: =IFERROR(AM9+AM8,"") | AN7: =IFERROR(AN9+AN8,"") | AO7: =SUM(AK7:AN7)
A8: 판관비 | B8: 손익 | C8: 억원 | D8: 판관비 | E8: =IFERROR(VLOOKUP($D8,BS연결,MATCH(E$1,BS연결H,0),0)/100,"") | G8: =IFERROR(VLOOKUP($D8,BS연결,MATCH(G$1,BS연결H,0),0)/100,"") | H8: =IFERROR(VLOOKUP($D8,BS연결,MATCH(H$1,BS연결H,0),0)/100,"") | I8: =IFERROR(VLOOKUP($D8,BS연결,MATCH(I$1,BS연결H,0),0)/100,"") | J8: =IFERROR(VLOOKUP($D8,BS연결,MATCH(J$1,BS연결H,0),0)/100,"") | K8: =IFERROR(VLOOKUP($D8,BS연결,MATCH(K$1,BS연결H,0),0)/100,"") | L8: =IFERROR(VLOOKUP($D8,BS연결,MATCH(L$1,BS연결H,0),0)/100,"") | M8: =IFERROR(VLOOKUP($D8,BS연결,MATCH(M$1,BS연결H,0),0)/100,"") | N8: =IFERROR(VLOOKUP($D8,BS연결,MATCH(N$1,BS연결H,0),0)/100,"") | ... AB8: =IFERROR(VLOOKUP($D8,BS연결,MATCH(AB$1,BS연결H,0),0)/100,"") | AC8: =IFERROR(AC5*변수!AC21,"") | AD8: =IFERROR(AD5*변수!AD21,"") | AE8: =SUM(AA8:AD8) | AF8: =IFERROR(AF5*변수!AF21,"") | AG8: =IFERROR(AG5*변수!AG21,"") | AH8: =IFERROR(AH5*변수!AH21,"") | AI8: =IFERROR(AI5*변수!AI21,"") | AJ8: =SUM(AF8:AI8) | AK8: =IFERROR(AK5*변수!AK21,"") | AL8: =IFERROR(AL5*변수!AL21,"") | AM8: =IFERROR(AM5*변수!AM21,"") | AN8: =IFERROR(AN5*변수!AN21,"") | AO8: =SUM(AK8:AN8)
A9: 영업이익 | B9: 손익 | C9: 억원 | D9: 영업이익 | E9: =IFERROR(VLOOKUP($D9,BS연결,MATCH(E$1,BS연결H,0),0)/100,"") | G9: =IFERROR(VLOOKUP($D9,BS연결,MATCH(G$1,BS연결H,0),0)/100,"") | H9: =IFERROR(VLOOKUP($D9,BS연결,MATCH(H$1,BS연결H,0),0)/100,"") | I9: =IFERROR(VLOOKUP($D9,BS연결,MATCH(I$1,BS연결H,0),0)/100,"") | J9: =IFERROR(VLOOKUP($D9,BS연결,MATCH(J$1,BS연결H,0),0)/100,"") | K9: =IFERROR(VLOOKUP($D9,BS연결,MATCH(K$1,BS연결H,0),0)/100,"") | L9: =IFERROR(VLOOKUP($D9,BS연결,MATCH(L$1,BS연결H,0),0)/100,"") | M9: =IFERROR(VLOOKUP($D9,BS연결,MATCH(M$1,BS연결H,0),0)/100,"") | N9: =IFERROR(VLOOKUP($D9,BS연결,MATCH(N$1,BS연결H,0),0)/100,"") | ... AB9: =IFERROR(VLOOKUP($D9,BS연결,MATCH(AB$1,BS연결H,0),0)/100,"") | AC9: =IFERROR(AC38+AC41,"") | AD9: =IFERROR(AD38+AD41,"") | AE9: =SUM(AA9:AD9) | AF9: =IFERROR(AF38+AF41,"") | AG9: =IFERROR(AG38+AG41,"") | AH9: =IFERROR(AH38+AH41,"") | AI9: =IFERROR(AI38+AI41,"") | AJ9: =SUM(AF9:AI9) | AK9: =IFERROR(AK38+AK41,"") | AL9: =IFERROR(AL38+AL41,"") | AM9: =IFERROR(AM38+AM41,"") | AN9: =IFERROR(AN38+AN41,"") | AO9: =SUM(AK9:AN9)
A10: OPM | B10: 손익 | C10: % | D10: 영업이익률 | E10: =IFERROR(E9/E5,"") | G10: =IFERROR(G9/G5,"") | H10: =IFERROR(H9/H5,"") | I10: =IFERROR(I9/I5,"") | J10: =IFERROR(J9/J5,"") | K10: =IFERROR(K9/K5,"") | L10: =IFERROR(L9/L5,"") | M10: =IFERROR(M9/M5,"") | N10: =IFERROR(N9/N5,"") | ... AO10: =IFERROR(AO9/AO5,"")
A11: 금융손익 | B11: 손익 | C11: 억원 | D11: 금융손익 | E11: =IFERROR(VLOOKUP($D11,BS연결,MATCH(E$1,BS연결H,0),0)/100,"") | G11: =IFERROR(VLOOKUP($D11,BS연결,MATCH(G$1,BS연결H,0),0)/100,"") | H11: =IFERROR(VLOOKUP($D11,BS연결,MATCH(H$1,BS연결H,0),0)/100,"") | I11: =IFERROR(VLOOKUP($D11,BS연결,MATCH(I$1,BS연결H,0),0)/100,"") | J11: =IFERROR(VLOOKUP($D11,BS연결,MATCH(J$1,BS연결H,0),0)/100,"") | K11: =IFERROR(VLOOKUP($D11,BS연결,MATCH(K$1,BS연결H,0),0)/100,"") | L11: =IFERROR(VLOOKUP($D11,BS연결,MATCH(L$1,BS연결H,0),0)/100,"") | M11: =IFERROR(VLOOKUP($D11,BS연결,MATCH(M$1,BS연결H,0),0)/100,"") | N11: =IFERROR(VLOOKUP($D11,BS연결,MATCH(N$1,BS연결H,0),0)/100,"") | ... AB11: =IFERROR(VLOOKUP($D11,BS연결,MATCH(AB$1,BS연결H,0),0)/100,"") | AC11: =IFERROR(AC12+AC13,"") | AD11: =IFERROR(AD12+AD13,"") | AE11: =SUM(AA11:AD11) | AF11: =IFERROR(AF12+AF13,"") | AG11: =IFERROR(AG12+AG13,"") | AH11: =IFERROR(AH12+AH13,"") | AI11: =IFERROR(AI12+AI13,"") | AJ11: =SUM(AF11:AI11) | AK11: =IFERROR(AK12+AK13,"") | AL11: =IFERROR(AL12+AL13,"") | AM11: =IFERROR(AM12+AM13,"") | AN11: =IFERROR(AN12+AN13,"") | AO11: =SUM(AK11:AN11)
