Workbook
Name 변수H: 변수!$C$1:$AO$1
Name 환율: 변수!$C$6:$AO$13
Name BS연결H: BS연결!$C$1:$AO$1
Name BS연결: BS연결!$C$5:$AO$104
Name BS별도H: BS별도!$C$1:$AO$1
Name BS별도: BS별도!$C$5:$AO$91
Name SUBQH: subQ!$A$1:$AO$1
Name subQ: subQ!$A$5:$AO$45

Sheet README
A1: KS인더스트리(101000) 실적 모델 — ARGUS 한국조선
A2: 기준 분기 2026Q2 · 마지막 실적 2026Q2 · 생성 2026-10-11
A3: 모든 수치는 모델 산출값(DART 공개 재무제표 + 우리 추정)이다 — 목표주가·투자 추천 아님. 참고용 · 투자조언 아님.
A5: 시트
A6: 변수 가정 시계열. 환율 8행(ECB via frankfurter — L2 fx.json; 추정 분기 = 노란 가정), 추정 드라이버(노란 셀 = 모델값에서 역산한 가정, 바꾸면 재계산; 연녹 셀 = 3절 스칼라 참조 수식), 3절 스칼라 가정(세율·판관비율·지배주주비중·이자율·종가·PER 밴드·COE·외화 순노출·헤지비율)
A7: BS연결/BS별도 FnGuide 계정명 × 기간 값 덤프(백만원). 행1 분기라벨, 행4 YYYY.MM / YYYY.12A. 이름정의 BS연결H·BS연결(계정명 C열부터)
A8: subQ 분기 서브모델(억원 = 백만원/100). 확정 행: =IFERROR(VLOOKUP($D행,BS연결,MATCH(E$1,BS연결H,0),0)/100,"") 추정 행: 변수 시트 가정 셀 참조 수식. 외환손익·파생상품손익은 BS 계정 합·차, 기타금융손익은 잔차, OPM·EPS·BPS·PER·PBR 은 파생 수식, 조정EPS 는 EPS 참조(일회성 의심 분기만 산식 셀)
A9: SLS 선표(조선사만, sls json 있을 때): 요약 행(sls 저장값) + 계약별 스케줄(백만$) × (헤지비율 × 헤지환율 + (1−헤지비율) × 건조시점 환율[변수 원/달러(평균)]) → 원화 수식 블록 → 합계 행이 subQ 매출조선에 연결
A10: 시나리오 신규수주 보수/기준/낙관(forecast_panel 패널, 모델에 scenarios 가 있을 때만): 매출액·영업이익 = subQ 기준값 ± (시나리오 신규 − base 신규) × OPM. base 만 subQ 행에 포함, 나머지는 합산 안 함
A11: 분기/연간예상 subQ 를 이름(A열 key)으로 VLOOKUP 한 보고서 표(억원)
A12: TP PER 밴드 × 12M fwd EPS, PBR = ROE/COE × BPS — 모델 산출값 구간, 목표주가·추천 아님
A13: 외화 환율 QoQ, 외화 순노출 × Δ기말환율 → 환관련손익 추정
... A35: 백테스트: {"freeze": "2025Q2", "horizon": 4, "revenue_wape_pct": 38.4, "op_wape_pct": 77.8, "n": 4, "note": "단일 회사 4분기 — 통계 아님", "driver_at_freeze": "trend_seasonal", "selection_oos_at_freeze": {"wape_link": null, "wape_trend": null, "adopted": false, "decision": "rejected", "note": "유의성 조건 미달 → OOS 비교 전 기각"}, "frozen_inputs": "fin(연결/별도)·고객 조선사 모델·지주 자회사 모델은 2025Q2 까지의 분기만; 선표는 체결일 ≤ 2025Q2 말일 계약(원장 최신 금액·코호트 등급, 환산 없음); 잔고는 yards_cache 2025Q2; 시세·환율 forward·prices·forecast_panel 신규수주 미사용. 고객 가중치(suppliers.json 언급 비중)와 합병 체인링크는 현재 지식; 고객 연동 채택은 동결 모델 안에서도 자기 la−4분기 OOS 규칙(selection_oos_at_freeze)", "detail": [{"q": "2025Q3", "rev_pred": 42.42, "rev_act": 120.4, "op_pred": -1.17, "op_act": -10.12}, {"q": "2025Q4", "rev_pred": 56.65, "rev_act": 71.77, "op_pred": -1.56, "op_act": -3.76}, {"q": "2026Q1", "rev_pred": 63.15, "rev_act": 104.01, "op_pred": -1.74, "op_act": -7.94}, {"q": "2026Q2", "rev_pred": 78.46, "rev_act": 94.65, "op_pred": -2.16, "op_act": -8.06}]}

Sheet 변수
C1: 이름: 변수H | E1: 4Q21 | F1: 2021 | G1: 1Q22 | H1: 2Q22 | I1: 3Q22 | J1: 4Q22 | K1: 2022 | L1: 1Q23 | M1: 2Q23 | N1: 3Q23 | O1: 4Q23 | P1: 2023 | Q1: 1Q24 | R1: 2Q24 | S1: 3Q24 | T1: 4Q24 | U1: 2024 | V1: 1Q25 | W1: 2Q25 | X1: 3Q25 | Y1: 4Q25 | Z1: 2025 | AA1: 1Q26 | AB1: 2Q26 | AC1: 3Q26 | AD1: 4Q26 | AE1: 2026 | AF1: 1Q27 | AG1: 2Q27 | AH1: 3Q27 | AI1: 4Q27 | AJ1: 2027 | AK1: 1Q28 | AL1: 2Q28 | AM1: 3Q28 | AN1: 4Q28 | AO1: 2028
A2: 가정 시계열 — 노란 셀은 추정 가정(모델값에서 역산), 연녹 셀은 3절 스칼라 참조 수식. 바꾸면 subQ·분기·연간예상·TP·시나리오가 재계산됩니다.
E3: 1 | F3: 2 | G3: 3 | H3: 4 | I3: 5 | J3: 6 | K3: 7 | L3: 8 | M3: 9 | N3: 10 | O3: 11 | P3: 12 | Q3: 13 | R3: 14 | S3: 15 | T3: 16 | U3: 17 | V3: 18 | W3: 19 | X3: 20 | Y3: 21 | Z3: 22 | AA3: 23 | AB3: 24 | AC3: 25 | AD3: 26 | AE3: 27 | AF3: 28 | AG3: 29 | AH3: 30 | AI3: 31 | AJ3: 32 | AK3: 33 | AL3: 34 | AM3: 35 | AN3: 36 | AO3: 37
E4: 2021.12 | F4: 2021.12A | G4: 2022.03 | H4: 2022.06 | I4: 2022.09 | J4: 2022.12 | K4: 2022.12A | L4: 2023.03 | M4: 2023.06 | N4: 2023.09 | O4: 2023.12 | P4: 2023.12A | Q4: 2024.03 | R4: 2024.06 | S4: 2024.09 | T4: 2024.12 | U4: 2024.12A | V4: 2025.03 | W4: 2025.06 | X4: 2025.09 | Y4: 2025.12 | Z4: 2025.12A | AA4: 2026.03 | AB4: 2026.06 | AC4: 2026.09 | AD4: 2026.12 | AE4: 2026.12A | AF4: 2027.03 | AG4: 2027.06 | AH4: 2027.09 | AI4: 2027.12 | AJ4: 2027.12A | AK4: 2028.03 | AL4: 2028.06 | AM4: 2028.09 | AN4: 2028.12 | AO4: 2028.12A
B5: 1. FX | C5: 이름: 환율
A6: USDKRW_avg | C6: 원/달러(평균) | E6: 1183.5 | F6: 1145.51 | G6: 1205.78 | H6: 1262.09 | I6: 1341.93 | J6: 1360.12 | K6: 1292.98 | L6: 1276.95 | M6: 1315.69 | N6: 1313.62 | O6: 1322.01 | P6: 1306.85 | Q6: 1330.14 | R6: 1371.28 | S6: 1356.22 | T6: 1396.3 | U6: 1363.53 | V6: 1452.28 | W6: 1398.52 | X6: 1386.95 | Y6: 1449.19 | Z6: 1421.52 | AA6: 1466.12 | AB6: 1501.75 | AC6: 1418.75 | AD6: 1345.14 | AE6: 1457.21 | AF6: 1341.49 | AG6: 1341.49 | AH6: 1341.49 | AI6: 1341.49 | AK6: 1341.49 | AL6: 1341.49 | AM6: 1341.49 | AN6: 1341.49
A7: USDKRW_end | C7: 원/달러(기말) | E7: 1188.75 | F7: 1188.75 | G7: 1213.74 | H7: 1301.24 | I7: 1436.9 | J7: 1260.16 | K7: 1260.16 | L7: 1305.99 | M7: 1321.44 | N7: 1345.35 | O7: 1297.43 | P7: 1297.43 | Q7: 1349.25 | R7: 1377.73 | S7: 1312.17 | T7: 1474.78 | U7: 1474.78 | V7: 1474.54 | W7: 1355.13 | X7: 1403.67 | Y7: 1444.2 | Z7: 1444.2 | AA7: 1524.8 | AB7: 1550.89 | AC7: 1355.4 | AD7: 1341.49 | AE7: 1341.49 | AF7: 1341.49 | AG7: 1341.49 | AH7: 1341.49 | AI7: 1341.49 | AK7: 1341.49 | AL7: 1341.49 | AM7: 1341.49 | AN7: 1341.49
A8: JPY100KRW_avg | C8: 원/100Y(평균) | E8: 1041.02 | F8: 1042.74 | G8: 1036.79 | H8: 972.23 | I8: 970.61 | J8: 961.03 | K8: 985.1 | L8: 964.89 | M8: 957.36 | N8: 909 | O8: 893.22 | P8: 931.11 | Q8: 896.29 | R8: 880.14 | S8: 909.35 | T8: 917.25 | U8: 900.92 | V8: 952.59 | W8: 967.92 | X8: 940.32 | Y8: 940.77 | Z8: 950.17 | AA8: 934.39 | AB8: 942.16 | AC8: 890.41 | AD8: 850.79 | AE8: 919.21 | AF8: 847.7 | AG8: 847.7 | AH8: 847.7 | AI8: 847.7 | AK8: 847.7 | AL8: 847.7 | AM8: 847.7 | AN8: 847.7
A9: JPY100KRW_end | C9: 원/100Y(기말) | E9: 1032.62 | F9: 1032.62 | G9: 996.83 | H9: 954.9 | I9: 993.29 | J9: 955.54 | K9: 955.54 | L9: 980.62 | M9: 913.67 | N9: 901.47 | O9: 917.04 | P9: 917.04 | Q9: 892.42 | R9: 857.76 | S9: 919.21 | T9: 939.65 | U9: 939.65 | V9: 986.84 | W9: 938.85 | X9: 948.49 | Y9: 921.81 | Z9: 921.81 | AA9: 955.99 | AB9: 954.75 | AC9: 863.31 | AD9: 847.7 | AE9: 847.7 | AF9: 847.7 | AG9: 847.7 | AH9: 847.7 | AI9: 847.7 | AK9: 847.7 | AL9: 847.7 | AM9: 847.7 | AN9: 847.7
A10: EURKRW_avg | C10: W/Euro(평균) | E10: 1353.32 | F10: 1354.06 | G10: 1352.29 | H10: 1343.31 | I10: 1350.63 | J10: 1386.07 | K10: 1358.07 | L10: 1369.93 | M10: 1432.41 | N10: 1429.41 | O10: 1420.91 | P10: 1412.88 | Q10: 1444.21 | R10: 1476.42 | S10: 1489.3 | T10: 1490.78 | U10: 1475.4 | V10: 1528.33 | W10: 1585.13 | X10: 1620.04 | Y10: 1686.02 | Z10: 1605.45 | AA10: 1715.47 | AB10: 1746.09 | AC10: 1631.97 | AD10: 1509.74 | AE10: 1689.95 | AF10: 1503.27 | AG10: 1503.27 | AH10: 1503.27 | AI10: 1503.27 | AK10: 1503.27 | AL10: 1503.27 | AM10: 1503.27 | AN10: 1503.27
A11: EURKRW_end | C11: W/Euro(기말) | E11: 1346.38 | F11: 1346.38 | G11: 1347.37 | H11: 1351.6 | I11: 1400.62 | J11: 1344.08 | K11: 1344.08 | L11: 1420.26 | M11: 1435.88 | N11: 1425.26 | O11: 1433.66 | P11: 1433.66 | Q11: 1458.68 | R11: 1474.86 | S11: 1469.1 | T11: 1532.14 | U11: 1532.14 | V11: 1594.72 | W11: 1588.22 | X11: 1648.04 | Y11: 1696.94 | Z11: 1696.94 | AA11: 1753.21 | AB11: 1767.09 | AC11: 1539.06 | AD11: 1503.27 | AE11: 1503.27 | AF11: 1503.27 | AG11: 1503.27 | AH11: 1503.27 | AI11: 1503.27 | AK11: 1503.27 | AL11: 1503.27 | AM11: 1503.27 | AN11: 1503.27
A12: CNYKRW_avg | C12: 원/중국원(평균) | E12: 185.14 | F12: 177.65 | G12: 189.93 | H12: 190.76 | I12: 195.79 | J12: 191.09 | K12: 191.93 | L12: 186.59 | M12: 187.45 | N12: 181.28 | O12: 182.86 | P12: 184.52 | Q12: 185.04 | R12: 189.35 | S12: 189.24 | T12: 194.24 | U12: 189.49 | V12: 199.63 | W12: 193.41 | X12: 193.79 | Y12: 204.38 | Z12: 197.8 | AA12: 211.75 | AB12: 220.8 | AC12: 210.43 | AD12: 200.69 | AE12: 213.75 | AF12: 200.46 | AG12: 200.46 | AH12: 200.46 | AI12: 200.46 | AK12: 200.46 | AL12: 200.46 | AM12: 200.46 | AN12: 200.46
A13: CNYKRW_end | C13: 원/중국원(기말) | E13: 187.13 | F13: 187.13 | G13: 191.38 | H13: 194.13 | I13: 201.92 | J13: 182.67 | K13: 182.67 | L13: 189.97 | M13: 181.8 | N13: 184.26 | O13: 182.61 | P13: 182.61 | Q13: 186.66 | R13: 189.7 | S13: 187.12 | T13: 202.04 | U13: 202.04 | V13: 203.3 | W13: 189.14 | X13: 197.16 | Y13: 206.28 | Z13: 206.28 | AA13: 220.97 | AB13: 228.56 | AC13: 202.16 | AD13: 200.46 | AE13: 200.46 | AF13: 200.46 | AG13: 200.46 | AH13: 200.46 | AI13: 200.46 | AK13: 200.46 | AL13: 200.46 | AM13: 200.46 | AN13: 200.46
B14: 1b. 종가
A15: price_close_end | C15: 종가(기말) | E15: 11673 | G15: 12310 | H15: 9393 | I15: 7374 | J15: 6613 | L15: 3981 | M15: 5174 | N15: 5513 | O15: 5855 | Q15: 7689 | R15: 7223 | S15: 5554 | T15: 5924 | V15: 5568 | W15: 6033 | X15: 2681 | Y15: 1811 | AA15: 2758 | AB15: 1102 | AC15: 1443 | AD15: 1427
A16: price_high | C16: 종가(최고) | E16: 14576 | G16: 13903 | H16: 12494 | I16: 11574 | J16: 8219 | L16: 7349 | M16: 7689 | N16: 6225 | O16: 6074 | Q16: 11561 | R16: 8482 | S16: 8263 | T16: 6936 | V16: 7251 | W16: 8920 | X16: 6731 | Y16: 4224 | AA16: 3803 | AB16: 2897 | AC16: 2305 | AD16: 1646
A17: price_low | C17: 종가(최저) | E17: 10718 | G17: 11500 | H17: 8622 | I17: 7311 | J17: 6416 | L17: 3562 | M17: 3784 | N17: 4320 | O17: 5458 | Q17: 5442 | R17: 5188 | S17: 5308 | T17: 5097 | V17: 4255 | W17: 5335 | X17: 2060 | Y17: 1767 | AA17: 1699 | AB17: 985 | AC17: 680 | AD17: 1331
A18: price_avg | C18: 종가(평균) | E18: 11833.3 | G18: 12350.5 | H18: 10507.7 | I18: 8807 | J18: 6948.8 | L18: 5418.8 | M18: 5658.6 | N18: 5396.4 | O18: 5787.6 | Q18: 6886.9 | R18: 6790.7 | S18: 6735.7 | T18: 6019 | V18: 6062.9 | W18: 6244.6 | X18: 5001.5 | Y18: 2377.5 | AA18: 2765.9 | AB18: 2023.5 | AC18: 1132.7 | AD18: 1509.8
B20: 2. 추정 드라이버 | C20: 실적 열 = subQ 실현값(수식), 추정 열 = 가정(노란 = 모델값 역산, 연녹 = 3절 스칼라 참조)
A21: drv:매출액 | B21: yoy | C21: 매출액 YoY | J21: =IFERROR(subQ!J5/subQ!E5-1,"") | L21: =IFERROR(subQ!L5/subQ!G5-1,"") | M21: =IFERROR(subQ!M5/subQ!H5-1,"") | N21: =IFERROR(subQ!N5/subQ!I5-1,"") | O21: =IFERROR(subQ!O5/subQ!J5-1,"") | Q21: =IFERROR(subQ!Q5/subQ!L5-1,"") | R21: =IFERROR(subQ!R5/subQ!M5-1,"") | S21: =IFERROR(subQ!S5/subQ!N5-1,"") | T21: =IFERROR(subQ!T5/subQ!O5-1,"") | V21: =IFERROR(subQ!V5/subQ!Q5-1,"") | W21: =IFERROR(subQ!W5/subQ!R5-1,"") | X21: =IFERROR(subQ!X5/subQ!S5-1,"") | Y21: =IFERROR(subQ!Y5/subQ!T5-1,"") | AA21: =IFERROR(subQ!AA5/subQ!V5-1,"") | AB21: =IFERROR(subQ!AB5/subQ!W5-1,"") | AC21: 0.13668264 | AD21: 0.13668505 | AF21: 0.13669249 | AG21: 0.13673823 | AH21: 0.068391057 | AI21: 0.068399117 | AK21: 0.068341369 | AL21: 0.068314899 | AM21: 0.034195049 | AN21: 0.034189995
A22: drv:판관비 | B22: ratio | C22: 판관비율(/매출) | E22: =IFERROR(subQ!E8/subQ!E5,"") | F22: =IFERROR(subQ!F8/subQ!F5,"") | G22: =IFERROR(subQ!G8/subQ!G5,"") | H22: =IFERROR(subQ!H8/subQ!H5,"") | I22: =IFERROR(subQ!I8/subQ!I5,"") | J22: =IFERROR(subQ!J8/subQ!J5,"") | K22: =IFERROR(subQ!K8/subQ!K5,"") | L22: =IFERROR(subQ!L8/subQ!L5,"") | ... AB22: =IFERROR(subQ!AB8/subQ!AB5,"") | AC22: =$D$53 | AD22: =$D$53 | AE22: =IFERROR(subQ!AE8/subQ!AE5,"") | AF22: =$D$53 | AG22: =$D$53 | AH22: =$D$53 | AI22: =$D$53 | AJ22: =IFERROR(subQ!AJ8/subQ!AJ5,"") | AK22: =$D$53 | AL22: =$D$53 | AM22: =$D$53 | AN22: =$D$53 | AO22: =IFERROR(subQ!AO8/subQ!AO5,"")
A23: drv:영업이익 | B23: ratio | C23: 영업이익률(OPM) | E23: =IFERROR(subQ!E9/subQ!E5,"") | F23: =IFERROR(subQ!F9/subQ!F5,"") | G23: =IFERROR(subQ!G9/subQ!G5,"") | H23: =IFERROR(subQ!H9/subQ!H5,"") | I23: =IFERROR(subQ!I9/subQ!I5,"") | J23: =IFERROR(subQ!J9/subQ!J5,"") | K23: =IFERROR(subQ!K9/subQ!K5,"") | L23: =IFERROR(subQ!L9/subQ!L5,"") | ... AB23: =IFERROR(subQ!AB9/subQ!AB5,"") | AC23: -0.10565541 | AD23: -0.10566315 | AE23: =IFERROR(subQ!AE9/subQ!AE5,"") | AF23: -0.10564155 | AG23: -0.10567897 | AH23: -0.1056627 | AI23: -0.10566774 | AJ23: =IFERROR(subQ!AJ9/subQ!AJ5,"") | AK23: -0.10569234 | AL23: -0.10570733 | AM23: -0.10567385 | AN23: -0.10572443 | AO23: =IFERROR(subQ!AO9/subQ!AO5,"")
A24: drv:외환손익 | B24: abs | C24: 외환손익 (가정, 억원) | E24: =subQ!E13 | F24: =subQ!F13 | G24: =subQ!G13 | H24: =subQ!H13 | I24: =subQ!I13 | J24: =subQ!J13 | K24: =subQ!K13 | L24: =subQ!L13 | ... AB24: =subQ!AB13 | AC24: 0 | AD24: 0 | AE24: =subQ!AE13 | AF24: 0 | AG24: 0 | AH24: 0 | AI24: 0 | AJ24: =subQ!AJ13 | AK24: 0 | AL24: 0 | AM24: 0 | AN24: 0 | AO24: =subQ!AO13
A25: drv:파생상품손익 | B25: abs | C25: 파생상품손익 (가정, 억원) | E25: =subQ!E14 | F25: =subQ!F14 | G25: =subQ!G14 | H25: =subQ!H14 | I25: =subQ!I14 | J25: =subQ!J14 | K25: =subQ!K14 | L25: =subQ!L14 | ... AB25: =subQ!AB14 | AC25: 0 | AD25: 0 | AE25: =subQ!AE14 | AF25: 0 | AG25: 0 | AH25: 0 | AI25: 0 | AJ25: =subQ!AJ14 | AK25: 0 | AL25: 0 | AM25: 0 | AN25: 0 | AO25: =subQ!AO14
A26: drv:기타금융손익 | B26: abs | C26: 기타금융손익 (가정, 억원) | E26: =subQ!E15 | F26: =subQ!F15 | G26: =subQ!G15 | H26: =subQ!H15 | I26: =subQ!I15 | J26: =subQ!J15 | K26: =subQ!K15 | L26: =subQ!L15 | ... AB26: =subQ!AB15 | AC26: 0 | AD26: 0 | AE26: =subQ!AE15 | AF26: 0 | AG26: 0 | AH26: 0 | AI26: 0 | AJ26: =subQ!AJ15 | AK26: 0 | AL26: 0 | AM26: 0 | AN26: 0 | AO26: =subQ!AO15
A27: drv:기타영업외손익 | B27: abs | C27: 기타영업외손익 (가정, 억원) | E27: =subQ!E16 | F27: =subQ!F16 | G27: =subQ!G16 | H27: =subQ!H16 | I27: =subQ!I16 | J27: =subQ!J16 | K27: =subQ!K16 | L27: =subQ!L16 | ... AB27: =subQ!AB16 | AC27: 0 | AD27: 0 | AE27: =subQ!AE16 | AF27: 0 | AG27: 0 | AH27: 0 | AI27: 0 | AJ27: =subQ!AJ16 | AK27: 0 | AL27: 0 | AM27: 0 | AN27: 0 | AO27: =subQ!AO16
A28: drv:지분법손익 | B28: abs | C28: 지분법손익 (가정, 억원) | E28: =subQ!E17 | F28: =subQ!F17 | G28: =subQ!G17 | H28: =subQ!H17 | I28: =subQ!I17 | J28: =subQ!J17 | K28: =subQ!K17 | L28: =subQ!L17 | ... AB28: =subQ!AB17 | AC28: -7.62 | AD28: -7.62 | AE28: =subQ!AE17 | AF28: -7.62 | AG28: -7.62 | AH28: -7.62 | AI28: -7.62 | AJ28: =subQ!AJ17 | AK28: -7.62 | AL28: -7.62 | AM28: -7.62 | AN28: -7.62 | AO28: =subQ!AO17
A29: drv:법인세비용 | B29: ratio | C29: 법인세율(/세전) | E29: =IFERROR(subQ!E19/subQ!E18,"") | F29: =IFERROR(subQ!F19/subQ!F18,"") | G29: =IFERROR(subQ!G19/subQ!G18,"") | H29: =IFERROR(subQ!H19/subQ!H18,"") | I29: =IFERROR(subQ!I19/subQ!I18,"") | J29: =IFERROR(subQ!J19/subQ!J18,"") | K29: =IFERROR(subQ!K19/subQ!K18,"") | L29: =IFERROR(subQ!L19/subQ!L18,"") | ... AB29: =IFERROR(subQ!AB19/subQ!AB18,"") | AC29: 0 | AD29: 0 | AE29: =IFERROR(subQ!AE19/subQ!AE18,"") | AF29: 0 | AG29: 0 | AH29: 0 | AI29: 0 | AJ29: =IFERROR(subQ!AJ19/subQ!AJ18,"") | AK29: 0 | AL29: 0 | AM29: 0 | AN29: 0 | AO29: =IFERROR(subQ!AO19/subQ!AO18,"")
A30: drv:지배주주순이익 | B30: ratio | C30: 지배주주 비중(/당기순이익) | E30: =IFERROR(subQ!E21/subQ!E20,"") | F30: =IFERROR(subQ!F21/subQ!F20,"") | G30: =IFERROR(subQ!G21/subQ!G20,"") | H30: =IFERROR(subQ!H21/subQ!H20,"") | I30: =IFERROR(subQ!I21/subQ!I20,"") | J30: =IFERROR(subQ!J21/subQ!J20,"") | K30: =IFERROR(subQ!K21/subQ!K20,"") | L30: =IFERROR(subQ!L21/subQ!L20,"") | ... AB30: =IFERROR(subQ!AB21/subQ!AB20,"") | AC30: =$D$54 | AD30: =$D$54 | AE30: =IFERROR(subQ!AE21/subQ!AE20,"") | AF30: =$D$54 | AG30: =$D$54 | AH30: =$D$54 | AI30: =$D$54 | AJ30: =IFERROR(subQ!AJ21/subQ!AJ20,"") | AK30: =$D$54 | AL30: =$D$54 | AM30: =$D$54 | AN30: =$D$54 | AO30: =IFERROR(subQ!AO21/subQ!AO20,"")
A31: drv:중단사업이익 | B31: abs | C31: 중단사업이익 (가정, 억원) | E31: =subQ!E22 | F31: =subQ!F22 | G31: =subQ!G22 | H31: =subQ!H22 | I31: =subQ!I22 | J31: =subQ!J22 | K31: =subQ!K22 | L31: =subQ!L22 | ... AB31: =subQ!AB22 | AE31: =subQ!AE22 | AJ31: =subQ!AJ22 | AO31: =subQ!AO22
A32: drv:부채총계 | B32: qoq | C32: 부채총계 QoQ | G32: =IFERROR(subQ!G24/subQ!E24-1,"") | H32: =IFERROR(subQ!H24/subQ!G24-1,"") | I32: =IFERROR(subQ!I24/subQ!H24-1,"") | J32: =IFERROR(subQ!J24/subQ!I24-1,"") | L32: =IFERROR(subQ!L24/subQ!J24-1,"") | M32: =IFERROR(subQ!M24/subQ!L24-1,"") | N32: =IFERROR(subQ!N24/subQ!M24-1,"") | O32: =IFERROR(subQ!O24/subQ!N24-1,"") | Q32: =IFERROR(subQ!Q24/subQ!O24-1,"") | R32: =IFERROR(subQ!R24/subQ!Q24-1,"") | S32: =IFERROR(subQ!S24/subQ!R24-1,"") | T32: =IFERROR(subQ!T24/subQ!S24-1,"") | V32: =IFERROR(subQ!V24/subQ!T24-1,"") | W32: =IFERROR(subQ!W24/subQ!V24-1,"") | X32: =IFERROR(subQ!X24/subQ!W24-1,"") | Y32: =IFERROR(subQ!Y24/subQ!X24-1,"") | AA32: =IFERROR(subQ!AA24/subQ!Y24-1,"") | AB32: =IFERROR(subQ!AB24/subQ!AA24-1,"") | AC32: -1.3497e-05 | AD32: 0 | AF32: 0 | AG32: 0 | AH32: 0 | AI32: 0 | AK32: 0 | AL32: 0 | AM32: 0 | AN32: 0
A33: drv:자본총계 | B33: roll | C33: 자본총계 기타변동(배당 등, 억원) | G33: =IFERROR(subQ!E25+subQ!G20-subQ!G25,"") | H33: =IFERROR(subQ!G25+subQ!H20-subQ!H25,"") | I33: =IFERROR(subQ!H25+subQ!I20-subQ!I25,"") | J33: =IFERROR(subQ!I25+subQ!J20-subQ!J25,"") | L33: =IFERROR(subQ!J25+subQ!L20-subQ!L25,"") | M33: =IFERROR(subQ!L25+subQ!M20-subQ!M25,"") | N33: =IFERROR(subQ!M25+subQ!N20-subQ!N25,"") | O33: =IFERROR(subQ!N25+subQ!O20-subQ!O25,"") | Q33: =IFERROR(subQ!O25+subQ!Q20-subQ!Q25,"") | R33: =IFERROR(subQ!Q25+subQ!R20-subQ!R25,"") | S33: =IFERROR(subQ!R25+subQ!S20-subQ!S25,"") | T33: =IFERROR(subQ!S25+subQ!T20-subQ!T25,"") | V33: =IFERROR(subQ!T25+subQ!V20-subQ!V25,"") | W33: =IFERROR(subQ!V25+subQ!W20-subQ!W25,"") | X33: =IFERROR(subQ!W25+subQ!X20-subQ!X25,"") | Y33: =IFERROR(subQ!X25+subQ!Y20-subQ!Y25,"") | AA33: =IFERROR(subQ!Y25+subQ!AA20-subQ!AA25,"") | AB33: =IFERROR(subQ!AA25+subQ!AB20-subQ!AB25,"") | AC33: 0.006926205 | AD33: 0.002789916 | AF33: 0.012269244 | AG33: 0.003367536 | AH33: 0.006747604 | AI33: 0.001298913 | AK33: 0.009029466 | AL33: -0.002196851 | AM33: 0.009029348 | AN33: 0.001938567
A34: drv:지배주주지분 | B34: roll | C34: 지배주주지분 기타변동(배당 등, 억원) | G34: =IFERROR(subQ!E26+subQ!G21-subQ!G26,"") | H34: =IFERROR(subQ!G26+subQ!H21-subQ!H26,"") | I34: =IFERROR(subQ!H26+subQ!I21-subQ!I26,"") | J34: =IFERROR(subQ!I26+subQ!J21-subQ!J26,"") | L34: =IFERROR(subQ!J26+subQ!L21-subQ!L26,"") | M34: =IFERROR(subQ!L26+subQ!M21-subQ!M26,"") | N34: =IFERROR(subQ!M26+subQ!N21-subQ!N26,"") | O34: =IFERROR(subQ!N26+subQ!O21-subQ!O26,"") | Q34: =IFERROR(subQ!O26+subQ!Q21-subQ!Q26,"") | R34: =IFERROR(subQ!Q26+subQ!R21-subQ!R26,"") | S34: =IFERROR(subQ!R26+subQ!S21-subQ!S26,"") | T34: =IFERROR(subQ!S26+subQ!T21-subQ!T26,"") | V34: =IFERROR(subQ!T26+subQ!V21-subQ!V26,"") | W34: =IFERROR(subQ!V26+subQ!W21-subQ!W26,"") | X34: =IFERROR(subQ!W26+subQ!X21-subQ!X26,"") | Y34: =IFERROR(subQ!X26+subQ!Y21-subQ!Y26,"") | AA34: =IFERROR(subQ!Y26+subQ!AA21-subQ!AA26,"") | AB34: =IFERROR(subQ!AA26+subQ!AB21-subQ!AB26,"") | AC34: 0.006926205 | AD34: 0.002789916 | AF34: 0.012269244 | AG34: 0.003367536 | AH34: 0.006747604 | AI34: 0.001298913 | AK34: 0.009029466 | AL34: -0.002196851 | AM34: 0.009029348 | AN34: 0.001938567
A35: drv:총차입금 | B35: qoq | C35: 총차입금 QoQ | G35: =IFERROR(subQ!G27/subQ!E27-1,"") | H35: =IFERROR(subQ!H27/subQ!G27-1,"") | I35: =IFERROR(subQ!I27/subQ!H27-1,"") | J35: =IFERROR(subQ!J27/subQ!I27-1,"") | L35: =IFERROR(subQ!L27/subQ!J27-1,"") | M35: =IFERROR(subQ!M27/subQ!L27-1,"") | N35: =IFERROR(subQ!N27/subQ!M27-1,"") | O35: =IFERROR(subQ!O27/subQ!N27-1,"") | Q35: =IFERROR(subQ!Q27/subQ!O27-1,"") | R35: =IFERROR(subQ!R27/subQ!Q27-1,"") | S35: =IFERROR(subQ!S27/subQ!R27-1,"") | T35: =IFERROR(subQ!T27/subQ!S27-1,"") | V35: =IFERROR(subQ!V27/subQ!T27-1,"") | W35: =IFERROR(subQ!W27/subQ!V27-1,"") | X35: =IFERROR(subQ!X27/subQ!W27-1,"") | Y35: =IFERROR(subQ!Y27/subQ!X27-1,"") | AA35: =IFERROR(subQ!AA27/subQ!Y27-1,"") | AB35: =IFERROR(subQ!AB27/subQ!AA27-1,"") | AC35: 1.1784e-05 | AD35: 0 | AF35: 0 | AG35: 0 | AH35: 0 | AI35: 0 | AK35: 0 | AL35: 0 | AM35: 0 | AN35: 0
A36: drv:순차입금 | B36: qoq | C36: 순차입금 QoQ | G36: =IFERROR(subQ!G28/subQ!E28-1,"") | H36: =IFERROR(subQ!H28/subQ!G28-1,"") | I36: =IFERROR(subQ!I28/subQ!H28-1,"") | J36: =IFERROR(subQ!J28/subQ!I28-1,"") | L36: =IFERROR(subQ!L28/subQ!J28-1,"") | M36: =IFERROR(subQ!M28/subQ!L28-1,"") | N36: =IFERROR(subQ!N28/subQ!M28-1,"") | O36: =IFERROR(subQ!O28/subQ!N28-1,"") | Q36: =IFERROR(subQ!Q28/subQ!O28-1,"") | R36: =IFERROR(subQ!R28/subQ!Q28-1,"") | S36: =IFERROR(subQ!S28/subQ!R28-1,"") | T36: =IFERROR(subQ!T28/subQ!S28-1,"") | V36: =IFERROR(subQ!V28/subQ!T28-1,"") | W36: =IFERROR(subQ!W28/subQ!V28-1,"") | X36: =IFERROR(subQ!X28/subQ!W28-1,"") | Y36: =IFERROR(subQ!Y28/subQ!X28-1,"") | AA36: =IFERROR(subQ!AA28/subQ!Y28-1,"") | AB36: =IFERROR(subQ!AB28/subQ!AA28-1,"") | AC36: 0.16443948 | AD36: 0.11357646 | AF36: 0.11881912 | AG36: 0.10212324 | AH36: 0.1071092 | AI36: 0.077296513 | AK36: 0.083981975 | AL36: 0.074398013 | AM36: 0.079045226 | AN36: 0.058375635
A37: drv:이자발생자산 | B37: qoq | C37: 이자발생자산 QoQ | G37: =IFERROR(subQ!G29/subQ!E29-1,"") | H37: =IFERROR(subQ!H29/subQ!G29-1,"") | I37: =IFERROR(subQ!I29/subQ!H29-1,"") | J37: =IFERROR(subQ!J29/subQ!I29-1,"") | L37: =IFERROR(subQ!L29/subQ!J29-1,"") | M37: =IFERROR(subQ!M29/subQ!L29-1,"") | N37: =IFERROR(subQ!N29/subQ!M29-1,"") | O37: =IFERROR(subQ!O29/subQ!N29-1,"") | Q37: =IFERROR(subQ!Q29/subQ!O29-1,"") | R37: =IFERROR(subQ!R29/subQ!Q29-1,"") | S37: =IFERROR(subQ!S29/subQ!R29-1,"") | T37: =IFERROR(subQ!T29/subQ!S29-1,"") | V37: =IFERROR(subQ!V29/subQ!T29-1,"") | W37: =IFERROR(subQ!W29/subQ!V29-1,"") | X37: =IFERROR(subQ!X29/subQ!W29-1,"") | Y37: =IFERROR(subQ!Y29/subQ!X29-1,"") | AA37: =IFERROR(subQ!AA29/subQ!Y29-1,"") | AB37: =IFERROR(subQ!AB29/subQ!AA29-1,"") | AC37: -1.0268286 | AD37: 30.766234 | AF37: 1.1291905 | AG37: 0.50979263 | AH37: 0.39030904 | AI37: 0.22420417 | AK37: 0.21452589 | AL37: 0.16955826 | AM37: 0.16549185 | AN37: 0.11315219
A38: drv:현금및현금성자산 | B38: qoq | C38: 현금및현금성자산 QoQ | G38: =IFERROR(subQ!G30/subQ!E30-1,"") | H38: =IFERROR(subQ!H30/subQ!G30-1,"") | I38: =IFERROR(subQ!I30/subQ!H30-1,"") | J38: =IFERROR(subQ!J30/subQ!I30-1,"") | L38: =IFERROR(subQ!L30/subQ!J30-1,"") | M38: =IFERROR(subQ!M30/subQ!L30-1,"") | N38: =IFERROR(subQ!N30/subQ!M30-1,"") | O38: =IFERROR(subQ!O30/subQ!N30-1,"") | Q38: =IFERROR(subQ!Q30/subQ!O30-1,"") | R38: =IFERROR(subQ!R30/subQ!Q30-1,"") | S38: =IFERROR(subQ!S30/subQ!R30-1,"") | T38: =IFERROR(subQ!T30/subQ!S30-1,"") | V38: =IFERROR(subQ!V30/subQ!T30-1,"") | W38: =IFERROR(subQ!W30/subQ!V30-1,"") | X38: =IFERROR(subQ!X30/subQ!W30-1,"") | Y38: =IFERROR(subQ!Y30/subQ!X30-1,"") | AA38: =IFERROR(subQ!AA30/subQ!Y30-1,"") | AB38: =IFERROR(subQ!AB30/subQ!AA30-1,"")
A39: drv:CAPEX | B39: yoy | C39: CAPEX YoY | J39: =IFERROR(subQ!J31/subQ!E31-1,"") | L39: =IFERROR(subQ!L31/subQ!G31-1,"") | M39: =IFERROR(subQ!M31/subQ!H31-1,"") | N39: =IFERROR(subQ!N31/subQ!I31-1,"") | O39: =IFERROR(subQ!O31/subQ!J31-1,"") | Q39: =IFERROR(subQ!Q31/subQ!L31-1,"") | R39: =IFERROR(subQ!R31/subQ!M31-1,"") | S39: =IFERROR(subQ!S31/subQ!N31-1,"") | T39: =IFERROR(subQ!T31/subQ!O31-1,"") | V39: =IFERROR(subQ!V31/subQ!Q31-1,"") | W39: =IFERROR(subQ!W31/subQ!R31-1,"") | X39: =IFERROR(subQ!X31/subQ!S31-1,"") | Y39: =IFERROR(subQ!Y31/subQ!T31-1,"") | AA39: =IFERROR(subQ!AA31/subQ!V31-1,"") | AB39: =IFERROR(subQ!AB31/subQ!W31-1,"") | AC39: 1.3058664 | AD39: -0.23189879 | AF39: 0.42155326 | AG39: -0.40303749 | AH39: 0 | AI39: 0 | AK39: 0 | AL39: 0 | AM39: 0 | AN39: 0
A40: drv:영업활동현금흐름 | B40: yoy | C40: 영업활동현금흐름 YoY | J40: =IFERROR(subQ!J32/subQ!E32-1,"") | L40: =IFERROR(subQ!L32/subQ!G32-1,"") | M40: =IFERROR(subQ!M32/subQ!H32-1,"") | N40: =IFERROR(subQ!N32/subQ!I32-1,"") | O40: =IFERROR(subQ!O32/subQ!J32-1,"") | Q40: =IFERROR(subQ!Q32/subQ!L32-1,"") | R40: =IFERROR(subQ!R32/subQ!M32-1,"") | S40: =IFERROR(subQ!S32/subQ!N32-1,"") | T40: =IFERROR(subQ!T32/subQ!O32-1,"") | V40: =IFERROR(subQ!V32/subQ!Q32-1,"") | W40: =IFERROR(subQ!W32/subQ!R32-1,"") | X40: =IFERROR(subQ!X32/subQ!S32-1,"") | Y40: =IFERROR(subQ!Y32/subQ!T32-1,"") | AA40: =IFERROR(subQ!AA32/subQ!V32-1,"") | AB40: =IFERROR(subQ!AB32/subQ!W32-1,"")
A41: drv:주식수 | B41: qoq | C41: 주식수 QoQ | G41: =IFERROR(subQ!G33/subQ!E33-1,"") | H41: =IFERROR(subQ!H33/subQ!G33-1,"") | I41: =IFERROR(subQ!I33/subQ!H33-1,"") | J41: =IFERROR(subQ!J33/subQ!I33-1,"") | L41: =IFERROR(subQ!L33/subQ!J33-1,"") | M41: =IFERROR(subQ!M33/subQ!L33-1,"") | N41: =IFERROR(subQ!N33/subQ!M33-1,"") | O41: =IFERROR(subQ!O33/subQ!N33-1,"") | Q41: =IFERROR(subQ!Q33/subQ!O33-1,"") | R41: =IFERROR(subQ!R33/subQ!Q33-1,"") | S41: =IFERROR(subQ!S33/subQ!R33-1,"") | T41: =IFERROR(subQ!T33/subQ!S33-1,"") | V41: =IFERROR(subQ!V33/subQ!T33-1,"") | W41: =IFERROR(subQ!W33/subQ!V33-1,"") | X41: =IFERROR(subQ!X33/subQ!W33-1,"") | Y41: =IFERROR(subQ!Y33/subQ!X33-1,"") | AA41: =IFERROR(subQ!AA33/subQ!Y33-1,"") | AB41: =IFERROR(subQ!AB33/subQ!AA33-1,"") | AC41: -2.5e-08 | AD41: 0 | AF41: 0 | AG41: 0 | AH41: 0 | AI41: 0 | AK41: 0 | AL41: 0 | AM41: 0 | AN41: 0
...

Sheet BS연결
B1: (백만원) | C1: 이름: BS연결H | E1: 4Q21 | F1: 2021 | G1: 1Q22 | H1: 2Q22 | I1: 3Q22 | J1: 4Q22 | K1: 2022 | L1: 1Q23 | M1: 2Q23 | N1: 3Q23 | O1: 4Q23 | P1: 2023 | Q1: 1Q24 | R1: 2Q24 | S1: 3Q24 | T1: 4Q24 | U1: 2024 | V1: 1Q25 | W1: 2Q25 | X1: 3Q25 | Y1: 4Q25 | Z1: 2025 | AA1: 1Q26 | AB1: 2Q26 | AC1: 3Q26 | AD1: 4Q26 | AE1: 2026 | AF1: 1Q27 | AG1: 2Q27 | AH1: 3Q27 | AI1: 4Q27 | AJ1: 2027 | AK1: 1Q28 | AL1: 2Q28 | AM1: 3Q28 | AN1: 4Q28 | AO1: 2028
B2: 연결 | D2: fin json(kship_fin.py)
B3: KS인더스트리(연) | C3: UPDATE: 26-10-11 | E3: 1 | F3: 2 | G3: 3 | H3: 4 | I3: 5 | J3: 6 | K3: 7 | L3: 8 | M3: 9 | N3: 10 | O3: 11 | P3: 12 | Q3: 13 | R3: 14 | S3: 15 | T3: 16 | U3: 17 | V3: 18 | W3: 19 | X3: 20 | Y3: 21 | Z3: 22 | AA3: 23 | AB3: 24 | AC3: 25 | AD3: 26 | AE3: 27 | AF3: 28 | AG3: 29 | AH3: 30 | AI3: 31 | AJ3: 32 | AK3: 33 | AL3: 34 | AM3: 35 | AN3: 36 | AO3: 37
B4: Account Code | C4: AccountNAME | E4: 2021.12 | F4: 2021.12A | G4: 2022.03 | H4: 2022.06 | I4: 2022.09 | J4: 2022.12 | K4: 2022.12A | L4: 2023.03 | M4: 2023.06 | N4: 2023.09 | O4: 2023.12 | P4: 2023.12A | Q4: 2024.03 | R4: 2024.06 | S4: 2024.09 | T4: 2024.12 | U4: 2024.12A | V4: 2025.03 | W4: 2025.06 | X4: 2025.09 | Y4: 2025.12 | Z4: 2025.12A | AA4: 2026.03 | AB4: 2026.06 | AC4: 2026.09 | AD4: 2026.12 | AE4: 2026.12A | AF4: 2027.03 | AG4: 2027.06 | AH4: 2027.09 | AI4: 2027.12 | AJ4: 2027.12A | AK4: 2028.03 | AL4: 2028.06 | AM4: 2028.09 | AN4: 2028.12 | AO4: 2028.12A
A5: 1 | C5: 유동자산 | E5: 26377.33 | F5: 26377.33 | G5: 21070.51 | H5: 28814.52 | I5: 28181.07 | J5: 26887.14 | K5: 26887.14 | L5: 29627.19 | M5: 28900.32 | N5: 27575.94 | O5: 18136.22 | P5: 18136.22 | Q5: 35882.04 | R5: 35531.42 | S5: 26584.13 | T5: 25980.5 | U5: 25980.5 | V5: 22528.81 | W5: 22120.28 | X5: 21400.44 | Y5: 18664.24 | Z5: 18664.24 | AA5: 36218.6 | AB5: 26441.94
A6: 1 | C6: 현금및현금성자산 | E6: 1273.35 | F6: 1273.35 | G6: 1139.15 | H6: 853.64 | I6: 537.71 | J6: 717.83 | K6: 717.83 | L6: 421.39 | M6: 1502.1 | N6: 1390.21 | O6: 1206.27 | P6: 1206.27 | Q6: 12913.09 | R6: 16906.03 | S6: 9791.26 | T6: 11326.81 | U6: 11326.81 | V6: 8117.89 | W6: 6205.44 | X6: 2954.31 | Y6: 3381.75 | Z6: 3381.75 | AA6: 22604.41 | AB6: 743.57
A7: 1 | C7: 매출채권및기타채권 | E7: 2827.61 | F7: 2827.61 | G7: 3605.47 | H7: 6684.61 | I7: 8067.23 | J7: 8106.44 | K7: 8106.44 | L7: 7403.9 | M7: 6850.1 | N7: 5727.77 | O7: 4999.29 | P7: 4999.29 | Q7: 13006.2 | R7: 7705.54 | S7: 3010.89 | T7: 6297.56 | U7: 6297.56 | V7: 4518.12 | W7: 5299.15 | X7: 7010.62 | Y7: 7047.48 | Z7: 7047.48 | AA7: 4938.42 | AB7: 15957.42
A8: 1 | C8: 재고자산 | E8: 12149.58 | F8: 12149.58 | G8: 9706.18 | H8: 8440.08 | I8: 12617.06 | J8: 8553.1 | K8: 8553.1 | L8: 9161.58 | M8: 9465.48 | N8: 6995.26 | O8: 5571.81 | P8: 5571.81 | Q8: 5998.67 | R8: 6752.09 | S8: 6694.7 | T8: 6827.28 | U8: 6827.28 | V8: 7310.22 | W8: 6978.76 | X8: 7386.13 | Y8: 6888.22 | Z8: 6888.22 | AA8: 7277.42 | AB8: 8321.64
A9: 1 | C9: 당기법인세자산(선급법인세) | E9: 6.6 | F9: 6.6 | G9: 7.66 | H9: 4.56 | I9: 5.33 | J9: 5.57 | K9: 5.57 | L9: 5.58 | M9: 0.53 | N9: 0.03 | R9: 0.38 | S9: 14 | T9: 34.02 | U9: 34.02 | V9: 33.1 | W9: 9.99 | X9: 29.28 | Y9: 15.52 | Z9: 15.52 | AA9: 17.39 | AB9: 4.03
A10: 1 | C10: 비유동자산 | E10: 20521.6 | F10: 20521.6 | G10: 21939.39 | H10: 26283.73 | I10: 26642.11 | J10: 27288.78 | K10: 27288.78 | L10: 26986.12 | M10: 26163.31 | N10: 25687.56 | O10: 25420.68 | P10: 25420.68 | Q10: 16273.7 | R10: 7529.54 | S10: 29015.89 | T10: 39838.3 | U10: 39838.3 | V10: 46034.51 | W10: 45974.1 | X10: 44854.93 | Y10: 42529.37 | Z10: 42529.37 | AA10: 42145.44 | AB10: 49991.61
A11: 1 | C11: 장기금융자산 | E11: 28.76 | F11: 28.76 | G11: 34.76 | H11: 39.93 | J11: 158.58 | K11: 158.58 | L11: 93.13 | M11: 48.7 | O11: 237.48 | P11: 237.48 | Q11: 346.04 | S11: 4619.99 | T11: 2673.72 | U11: 2673.72 | V11: 5373.72 | W11: 5519.01 | X11: 4818.4 | Y11: 2889.71 | Z11: 2889.71 | AA11: 2876.2 | AB11: 2120.5
A12: 1 | C12: 투자자산 | E12: 28.76 | F12: 28.76 | G12: 34.76 | H12: 39.93 | J12: 158.58 | K12: 158.58 | L12: 93.13 | M12: 48.7 | O12: 237.48 | P12: 237.48 | Q12: 346.04 | S12: 4620.56 | T12: 2673.72 | U12: 2673.72 | V12: 5373.72 | W12: 5519.01 | X12: 4818.4 | Y12: 2889.71 | Z12: 2889.71 | AA12: 2876.2 | AB12: 11806.07
A13: 1 | C13: 유형자산 | E13: 16058.32 | F13: 16058.32 | G13: 17412.18 | H13: 18306.58 | I13: 18618.41 | J13: 18895.27 | K13: 18895.27 | L13: 18572.44 | M13: 17721.05 | N13: 17219.4 | O13: 16610.9 | P13: 16610.9 | Q13: 15239.23 | R13: 6160.38 | S13: 22787.77 | T13: 27023.09 | U13: 27023.09 | V13: 28205.55 | W13: 28350.4 | X13: 28107.07 | Y13: 27972.89 | Z13: 27972.89 | AA13: 27683.45 | AB13: 26599.21
A14: 1 | C14: 무형자산 | E14: 67.68 | F14: 67.68 | G14: 82.58 | H14: 76.6 | I14: 80.06 | J14: 196.89 | K14: 196.89 | L14: 186.69 | M14: 172.97 | N14: 161.69 | O14: 148.67 | P14: 148.67 | Q14: 135.66 | R14: 122.65 | S14: 109.64 | T14: 7969.09 | U14: 7969.09 | V14: 7950.59 | W14: 7838.34 | X14: 7726.08 | Y14: 7613.82 | Z14: 7613.82 | AA14: 7501.56 | AB14: 7644.36
A15: 1 | C15: 자산총계 | E15: 46898.93 | F15: 46898.93 | G15: 43009.9 | H15: 55098.25 | I15: 54823.18 | J15: 54175.92 | K15: 54175.92 | L15: 56613.31 | M15: 55063.64 | N15: 53263.51 | O15: 43556.9 | P15: 43556.9 | Q15: 52155.74 | R15: 43060.96 | S15: 55600.02 | T15: 65818.8 | U15: 65818.8 | V15: 68563.32 | W15: 68094.39 | X15: 66255.38 | Y15: 61193.61 | Z15: 61193.61 | AA15: 78364.04 | AB15: 76433.55
A16: 1 | C16: 유동부채 | E16: 20865.72 | F16: 20865.72 | G16: 18845.78 | H16: 32061.53 | I16: 35288.41 | J16: 42714.35 | K16: 42714.35 | L16: 46291.61 | M16: 41625.97 | N16: 39235.08 | O16: 27540.69 | P16: 27540.69 | Q16: 29807.34 | R16: 7073.1 | S16: 8657.76 | T16: 18613.96 | U16: 18613.96 | V16: 18255.73 | W16: 15322.09 | X16: 14709.23 | Y16: 13371.43 | Z16: 13371.43 | AA16: 23470.07 | AB16: 18890.11
A17: 1 | C17: 매입채무및기타채무 | E17: 8159.73 | F17: 8159.73 | G17: 7342.42 | H17: 9583.38 | I17: 10071.16 | J17: 10939.39 | K17: 10939.39 | L17: 23480.38 | M17: 8796.3 | N17: 7214.51 | O17: 5385.93 | P17: 5385.93 | Q17: 5032.72 | R17: 4145.25 | S17: 3309.31 | T17: 5771.63 | U17: 5771.63 | V17: 4271.11 | W17: 5085.52 | X17: 5446.89 | Y17: 4737.07 | Z17: 4737.07 | AA17: 4518.27 | AB17: 5015.07
A18: 1 | C18: 단기차입금 | E18: 4800 | F18: 4800 | G18: 4800 | H18: 6800 | I18: 7600 | J18: 6800 | K18: 6800 | L18: 6500 | M18: 6850 | N18: 5100 | O18: 5850 | P18: 5850 | Q18: 3500 | R18: 1720 | S18: 1720 | T18: 3823.6 | U18: 3823.6 | V18: 3823.6 | W18: 823.6 | X18: 303.59 | Y18: 303.59 | Z18: 303.59 | AA18: 303.59
A19: 1 | C19: 유동리스부채 | E19: 511.42 | F19: 511.42 | G19: 516.3 | H19: 260.97 | I19: 263.75 | J19: 266.57 | K19: 266.57 | L19: 269.42 | M19: 272.3 | N19: 251.84 | Q19: 833.96 | R19: 148.07 | S19: 252.14 | T19: 379.77 | U19: 379.77 | V19: 471.07 | W19: 391.47 | X19: 408.03 | Y19: 313.88 | Z19: 313.88 | AA19: 349.37 | AB19: 359.39
A20: 1 | C20: 리스부채 | E20: 1916.5 | F20: 1916.5 | G20: 1790.46 | H20: 851.99 | I20: 779.53 | J20: 714.64 | K20: 714.64 | L20: 649.06 | M20: 582.78 | N20: 540.69 | O20: 229.21 | P20: 229.21 | Q20: 1487.19 | R20: 276.75 | S20: 430.64 | T20: 673.3 | U20: 673.3 | V20: 786.98 | W20: 630.68 | X20: 617.01 | Y20: 534.86 | Z20: 534.86 | AA20: 667.52 | AB20: 706.52
A21: 1 | C21: 단기금융부채 | E21: 511.42 | F21: 511.42 | G21: 516.3 | H21: 3543.86 | I21: 2957.95 | J21: 266.57 | K21: 266.57 | L21: 269.42 | M21: 272.3 | N21: 251.84 | O21: 9540.93 | P21: 9540.93 | Q21: 833.96 | R21: 148.07 | S21: 2025.22 | T21: 3904.2 | U21: 3904.2 | V21: 4651.62 | W21: 3892.06 | X21: 3393.19 | Y21: 1523.71 | Z21: 1523.71 | AA21: 10957.5 | AB21: 5736.01
A22: 1 | C22: 유동성장기부채 | E22: 3111.11 | F22: 3111.11 | G22: 2777.78 | H22: 9079.13 | I22: 9091.06 | J22: 9344.25 | K22: 9344.25 | L22: 2000 | M22: 6349.16 | N22: 6704.54 | O22: 5220.13 | P22: 5220.13 | Q22: 5661.06 | R22: 245.31 | S22: 984.28 | T22: 4624.32 | U22: 4624.32 | V22: 5180.44 | W22: 5202.76 | X22: 4817.79 | Y22: 5304.72 | Z22: 5304.72 | AA22: 6280.79 | AB22: 6669.78
A23: 1 | C23: 비유동부채 | E23: 1461.79 | F23: 1461.79 | G23: 1379.56 | H23: 797.96 | I23: 568.71 | J23: 448.07 | K23: 448.07 | L23: 379.64 | M23: 310.48 | N23: 354.92 | O23: 386.28 | P23: 386.28 | Q23: 785.15 | R23: 234.68 | S23: 10005.28 | T23: 10373.46 | U23: 10373.46 | V23: 10429.28 | W23: 14323.65 | X23: 14307.64 | Y23: 12817.78 | Z23: 12817.78 | AA23: 12912.7 | AB23: 12968.32
A24: 1 | C24: 확정급여부채 | E24: 41.71 | F24: 41.71 | G24: 105.4 | H24: 206.94 | I24: 52.93 | N24: 66.07 | T24: 97.63 | U24: 97.63 | V24: 111.84 | W24: 126.05 | X24: 140.27 | Y24: 161.45 | Z24: 161.45 | AA24: 180.39 | AB24: 199.33
A25: 1 | C25: 비유동리스부채 | E25: 1405.08 | F25: 1405.08 | G25: 1274.16 | H25: 591.02 | I25: 515.78 | J25: 448.07 | K25: 448.07 | L25: 379.64 | M25: 310.48 | N25: 288.85 | O25: 229.21 | P25: 229.21 | Q25: 653.23 | R25: 128.68 | S25: 178.5 | T25: 293.53 | U25: 293.53 | V25: 315.91 | W25: 239.21 | X25: 208.98 | Y25: 220.98 | Z25: 220.98 | AA25: 318.15 | AB25: 347.13
A26: 1 | C26: 장기금융부채 | E26: 1405.08 | F26: 1405.08 | G26: 1274.16 | H26: 591.02 | I26: 515.78 | J26: 448.07 | K26: 448.07 | L26: 379.64 | M26: 310.48 | N26: 288.85 | O26: 229.21 | P26: 229.21 | Q26: 653.23 | R26: 128.68 | S26: 1843.37 | T26: 2217.09 | U26: 2217.09 | V26: 2258.07 | W26: 1625.33 | X26: -1177.14 | Y26: 220.98 | Z26: 220.98 | AA26: 318.15 | AB26: 347.13
A27: 1 | C27: 기타비유동부채 | E27: 15 | F27: 15 | T27: 58.74 | U27: 58.74 | V27: 59.38
A28: 1 | C28: 부채총계 | E28: 22327.51 | F28: 22327.51 | G28: 20225.34 | H28: 32859.49 | I28: 35857.12 | J28: 43162.43 | K28: 43162.43 | L28: 46671.25 | M28: 41936.45 | N28: 39590 | O28: 27926.98 | P28: 27926.98 | Q28: 30592.49 | R28: 7307.78 | S28: 18663.04 | T28: 28987.42 | U28: 28987.42 | V28: 28685.02 | W28: 29645.74 | X28: 29016.87 | Y28: 26189.21 | Z28: 26189.21 | AA28: 36382.77 | AB28: 31858.43
A29: 1 | C29: 지배주주지분 | E29: 24571.42 | F29: 24571.42 | G29: 22784.56 | H29: 22238.76 | I29: 18966.06 | J29: 11013.49 | K29: 11013.49 | L29: 9942.07 | M29: 13127.19 | N29: 13673.51 | O29: 15629.93 | P29: 15629.93 | Q29: 21563.25 | R29: 35753.19 | S29: 36936.97 | T29: 36831.38 | U29: 36831.38 | V29: 39878.3 | W29: 38448.65 | X29: 37238.51 | Y29: 35004.4 | Z29: 35004.4 | AA29: 41981.27 | AB29: 44575.12
A30: 1 | C30: 자본금 | E30: 35875.4 | F30: 35875.4 | G30: 35875.4 | H30: 35875.4 | I30: 35875.4 | J30: 35875.4 | K30: 35875.4 | L30: 8968.85 | M30: 9389.72 | N30: 9389.72 | O30: 9389.72 | P30: 9389.72 | Q30: 11421.21 | R30: 15074.81 | S30: 15074.81 | T30: 15323.57 | U30: 15323.57 | V30: 16635.9 | W30: 16723.4 | X30: 16723.4 | Y30: 16723.4 | Z30: 16723.4 | AA30: 19820.97 | AB30: 19820.97
A31: 1 | C31: 자본잉여금 | E31: 41176.71 | F31: 41176.71 | G31: 41176.71 | H31: 41176.71 | I31: 41176.71 | J31: 41176.71 | K31: 41176.71 | L31: 41176.71 | M31: 41753.57 | N31: 41753.57 | O31: 41749.49 | P31: 41749.49 | Q31: 47718 | R31: 61845.21 | S31: 61845.21 | T31: 62577 | U31: 62577 | V31: 66255.65 | W31: 66574.31 | X31: 66574.31 | Y31: 66574.31 | Z31: 66574.31 | AA31: 71480.34 | AB31: 71480.34
A32: 1 | C32: 이익잉여금 | E32: -52480.69 | F32: -52480.69 | G32: -54267.55 | H32: -54813.35 | I32: -58086.05 | J32: -66038.62 | K32: -66038.62 | L32: -40203.5 | M32: -38012.03 | N32: -37465.7 | O32: -35509.29 | P32: -35509.29 | Q32: -37575.96 | R32: -41130.31 | S32: -39945.79 | T32: -41034.61 | U32: -41034.61 | V32: -42980.69 | W32: -44818.53 | X32: -46030.73 | Y32: -48256.34 | Z32: -48256.34 | AA32: -49282.79 | AB32: -46764.5
A33: 1 | C33: 자본총계 | E33: 24571.42 | F33: 24571.42 | G33: 22784.56 | H33: 22238.76 | I33: 18966.06 | J33: 11013.49 | K33: 11013.49 | L33: 9942.07 | M33: 13127.19 | N33: 13673.51 | O33: 15629.93 | P33: 15629.93 | Q33: 21563.25 | R33: 35753.19 | S33: 36936.97 | T33: 36831.38 | U33: 36831.38 | V33: 39878.3 | W33: 38448.65 | X33: 37238.51 | Y33: 35004.4 | Z33: 35004.4 | AA33: 41981.27 | AB33: 44575.12
A34: 1 | C34: 부채와자본총계 | E34: 46898.93 | F34: 46898.93 | G34: 43009.9 | H34: 55098.25 | I34: 54823.18 | J34: 54175.92 | K34: 54175.92 | L34: 56613.31 | M34: 55063.64 | N34: 53263.51 | O34: 43556.9 | P34: 43556.9 | Q34: 52155.74 | R34: 43060.96 | S34: 55600.02 | T34: 65818.8 | U34: 65818.8 | V34: 68563.32 | W34: 68094.39 | X34: 66255.38 | Y34: 61193.61 | Z34: 61193.61 | AA34: 78364.04 | AB34: 76433.55
A35: 1 | C35: 총차입금 | E35: 9022.22 | F35: 9022.22 | G35: 8355.56 | H35: 16323.57 | I35: 16802.17 | J35: 18144.25 | K35: 18144.25 | L35: 10500 | M35: 15199.16 | N35: 12089.32 | O35: 11227.2 | P35: 11227.2 | Q35: 9292.98 | R35: 2071.31 | S35: 2885.99 | T35: 16447.92 | U35: 16447.92 | V35: 17004.04 | W35: 18026.36 | X35: 17121.38 | Y35: 17608.31 | Z35: 17608.31 | AA35: 18584.38 | AB35: 18669.78
A36: 1 | C36: 순차입금 | E36: 7748.87 | F36: 7748.87 | G36: 7216.41 | H36: 13469.93 | I36: 16264.46 | J36: 17426.42 | K36: 17426.42 | L36: 10078.61 | M36: 13697.06 | N36: 10699.11 | O36: 10020.93 | P36: 10020.93 | Q36: -3620.11 | R36: -14834.72 | S36: -6905.27 | T36: 5121.11 | U36: 5121.11 | V36: 8886.15 | W36: 11820.92 | X36: 14167.07 | Y36: 14226.56 | Z36: 14226.56 | AA36: -4020.03 | AB36: 17920.21
A37: 1 | C37: 이자발생자산 | E37: 1302.11 | F37: 1302.11 | G37: 1173.91 | H37: 2893.57 | I37: 537.71 | J37: 876.41 | K37: 876.41 | L37: 514.52 | M37: 1550.8 | N37: 1390.21 | O37: 1443.75 | P37: 1443.75 | Q37: 13259.13 | R37: 16906.03 | S37: 14411.25 | T37: 14000.53 | U37: 14000.53 | V37: 13491.61 | W37: 11724.45 | X37: 7772.71 | Y37: 6271.46 | Z37: 6271.46 | AA37: 25480.61 | AB37: 2870.07
A38: 1 | C38: 장기차입금 | E38: 1111.11 | F38: 1111.11 | G38: 777.78 | H38: 444.44 | I38: 111.11 | J38: 2000 | K38: 2000 | L38: 2000 | M38: 2000 | N38: 284.78 | O38: 157.07 | P38: 157.07 | Q38: 131.92 | R38: 106 | S38: 181.71 | T38: 8000 | U38: 8000 | V38: 8000 | W38: 12000 | X38: 12000 | Y38: 12000 | Z38: 12000 | AA38: 12000 | AB38: 12000
A39: 1 | C39: 단기금융상품 | H39: 2000 | AB39: 6
A40: 1 | C40: 단기금융자산 | H40: 2000 | AB40: 6
...

Sheet BS별도
B1: (백만원) | C1: 이름: BS별도H | E1: 4Q21 | F1: 2021 | G1: 1Q22 | H1: 2Q22 | I1: 3Q22 | J1: 4Q22 | K1: 2022 | L1: 1Q23 | M1: 2Q23 | N1: 3Q23 | O1: 4Q23 | P1: 2023 | Q1: 1Q24 | R1: 2Q24 | S1: 3Q24 | T1: 4Q24 | U1: 2024 | V1: 1Q25 | W1: 2Q25 | X1: 3Q25 | Y1: 4Q25 | Z1: 2025 | AA1: 1Q26 | AB1: 2Q26 | AC1: 3Q26 | AD1: 4Q26 | AE1: 2026 | AF1: 1Q27 | AG1: 2Q27 | AH1: 3Q27 | AI1: 4Q27 | AJ1: 2027 | AK1: 1Q28 | AL1: 2Q28 | AM1: 3Q28 | AN1: 4Q28 | AO1: 2028
B2: 별도 | D2: fin json(kship_fin.py)
B3: KS인더스트리(별) | C3: UPDATE: 26-10-11 | E3: 1 | F3: 2 | G3: 3 | H3: 4 | I3: 5 | J3: 6 | K3: 7 | L3: 8 | M3: 9 | N3: 10 | O3: 11 | P3: 12 | Q3: 13 | R3: 14 | S3: 15 | T3: 16 | U3: 17 | V3: 18 | W3: 19 | X3: 20 | Y3: 21 | Z3: 22 | AA3: 23 | AB3: 24 | AC3: 25 | AD3: 26 | AE3: 27 | AF3: 28 | AG3: 29 | AH3: 30 | AI3: 31 | AJ3: 32 | AK3: 33 | AL3: 34 | AM3: 35 | AN3: 36 | AO3: 37
B4: Account Code | C4: AccountNAME | E4: 2021.12 | F4: 2021.12A | G4: 2022.03 | H4: 2022.06 | I4: 2022.09 | J4: 2022.12 | K4: 2022.12A | L4: 2023.03 | M4: 2023.06 | N4: 2023.09 | O4: 2023.12 | P4: 2023.12A | Q4: 2024.03 | R4: 2024.06 | S4: 2024.09 | T4: 2024.12 | U4: 2024.12A | V4: 2025.03 | W4: 2025.06 | X4: 2025.09 | Y4: 2025.12 | Z4: 2025.12A | AA4: 2026.03 | AB4: 2026.06 | AC4: 2026.09 | AD4: 2026.12 | AE4: 2026.12A | AF4: 2027.03 | AG4: 2027.06 | AH4: 2027.09 | AI4: 2027.12 | AJ4: 2027.12A | AK4: 2028.03 | AL4: 2028.06 | AM4: 2028.09 | AN4: 2028.12 | AO4: 2028.12A
A5: 1 | C5: 유동자산 | E5: 26350.64 | F5: 26350.64 | G5: 21048.11 | H5: 28795.41 | I5: 28166.64 | J5: 26872.71 | K5: 26872.71 | L5: 29612.76 | M5: 28886.55 | N5: 27561.3 | O5: 18123.06 | P5: 18123.06 | Q5: 35868.79 | R5: 35419.29 | S5: 26472.57 | T5: 22896.7 | U5: 22896.7 | V5: 18857.18 | W5: 18489.99 | X5: 17218.14 | Y5: 14439.05 | Z5: 14439.05 | AA5: 32220.18 | AB5: 23080.42
A6: 1 | C6: 현금및현금성자산 | E6: 1252.26 | F6: 1252.26 | G6: 1122.42 | H6: 834.63 | I6: 523.27 | J6: 703.39 | K6: 703.39 | L6: 406.99 | M6: 1488.37 | N6: 1375.67 | O6: 1193.21 | P6: 1193.21 | Q6: 12899.94 | R6: 16794.03 | S6: 9679.77 | T6: 10650.47 | U6: 10650.47 | V6: 7222.99 | W6: 5472.07 | X6: 2298.13 | Y6: 2456.36 | Z6: 2456.36 | AA6: 21379.59 | AB6: 479.77
A7: 1 | C7: 매출채권및기타채권 | E7: 2827.58 | F7: 2827.58 | G7: 3605.37 | H7: 6684.51 | I7: 8067.23 | J7: 8106.44 | K7: 8106.44 | L7: 7403.87 | M7: 6850.05 | N7: 5727.67 | O7: 4999.19 | P7: 4999.19 | Q7: 13006.1 | R7: 7705.42 | S7: 3010.83 | T7: 4339.23 | U7: 4339.23 | V7: 2022.44 | W7: 3601.15 | X7: 4645.49 | Y7: 4600.86 | Z7: 4600.86 | AA7: 3096.41 | AB7: 13756.25
A8: 1 | C8: 재고자산 | E8: 12149.58 | F8: 12149.58 | G8: 9706.18 | H8: 8440.08 | I8: 12617.06 | J8: 8553.1 | K8: 8553.1 | L8: 9161.58 | M8: 9465.48 | N8: 6995.26 | O8: 5571.81 | P8: 5571.81 | Q8: 5998.67 | R8: 6752.09 | S8: 6694.7 | T8: 6537.24 | U8: 6537.24 | V8: 6841.31 | W8: 6215.69 | X8: 6616.43 | Y8: 6346.35 | Z8: 6346.35 | AA8: 6672.22 | AB8: 7766.79
A9: 1 | C9: 당기법인세자산(선급법인세) | E9: 1.03 | F9: 1.03 | G9: 2.09 | H9: 4.56 | I9: 5.33 | J9: 5.57 | K9: 5.57 | L9: 5.58 | M9: 0.53 | N9: 0.03 | R9: 0.37 | S9: 13.99 | T9: 27.41 | U9: 27.41 | V9: 33.09 | W9: 9.98 | X9: 13.63 | Y9: 15.5 | Z9: 15.5 | AA9: 17.37 | AB9: 4.02
A10: 1 | C10: 비유동자산 | E10: 20543.74 | F10: 20543.74 | G10: 21961.53 | H10: 26299.28 | I10: 26657.65 | J10: 27303.21 | K10: 27303.21 | L10: 27000.56 | M10: 26177.09 | N10: 25701.34 | O10: 25433.84 | P10: 25433.84 | Q10: 16286.86 | R10: 7641.67 | S10: 29127.44 | T10: 40756.97 | U10: 40756.97 | V10: 47842.35 | W10: 46995.92 | X10: 45986.97 | Y10: 43767.83 | Z10: 43767.83 | AA10: 43473.64 | AB10: 52017.73
A11: 1 | C11: 장기금융자산 | E11: 28.76 | F11: 28.76 | G11: 34.76 | H11: 39.93 | J11: 158.58 | K11: 158.58 | L11: 93.13 | M11: 48.7 | O11: 237.48 | P11: 237.48 | Q11: 346.04 | S11: 4619.99 | T11: 2673.72 | U11: 2673.72 | V11: 5373.72 | W11: 5519.01 | X11: 4819.01 | Y11: 2876.81 | Z11: 2876.81 | AA11: 2876.2 | AB11: 2120.5
A12: 1 | C12: 투자자산 | E12: 50.9 | F12: 50.9 | G12: 56.9 | H12: 55.48 | I12: 15.55 | J12: 173.01 | K12: 173.01 | L12: 107.56 | M12: 62.47 | N12: 13.77 | O12: 250.64 | P12: 250.64 | Q12: 359.2 | R12: 112.13 | S12: 4732.12 | T12: 11593.76 | U12: 11593.76 | V12: 14293.76 | W12: 14342.8 | X12: 13642.8 | Y12: 11696.85 | Z12: 11696.85 | AA12: 11696.24 | AB12: 21214.77
A13: 1 | C13: 종속기업및관계기업투자 | E13: 22.14 | F13: 22.14 | G13: 22.14 | H13: 15.55 | I13: 15.55 | J13: 14.43 | K13: 14.43 | L13: 14.43 | M13: 13.77 | N13: 13.77 | O13: 13.16 | P13: 13.16 | Q13: 13.16 | R13: 112.13 | S13: 112.13 | T13: 8920.04 | U13: 8920.04 | V13: 8920.04 | W13: 8823.79 | X13: 8823.79 | Y13: 8820.04 | Z13: 8820.04 | AA13: 8820.04 | AB13: 19094.27
A14: 1 | C14: 유형자산 | E14: 16058.32 | F14: 16058.32 | G14: 17412.18 | H14: 18306.58 | I14: 18618.41 | J14: 18895.27 | K14: 18895.27 | L14: 18572.44 | M14: 17721.05 | N14: 17219.4 | O14: 16610.9 | P14: 16610.9 | Q14: 15239.23 | R14: 6160.38 | S14: 22787.77 | T14: 26976.29 | U14: 26976.29 | V14: 28160.77 | W14: 28308.55 | X14: 28068.18 | Y14: 27936.96 | Z14: 27936.96 | AA14: 27650.41 | AB14: 26569.1
A15: 1 | C15: 무형자산 | E15: 67.68 | F15: 67.68 | G15: 82.58 | H15: 76.6 | I15: 80.06 | J15: 196.89 | K15: 196.89 | L15: 186.69 | M15: 172.97 | N15: 161.69 | O15: 148.67 | P15: 148.67 | Q15: 135.66 | R15: 122.65 | S15: 109.64 | T15: 157.09 | U15: 157.09 | V15: 234.98 | W15: 219.09 | X15: 203.19 | Y15: 187.3 | Z15: 187.3 | AA15: 171.41 | AB15: 410.57
A16: 1 | C16: 자산총계 | E16: 46894.38 | F16: 46894.38 | G16: 43009.64 | H16: 55094.69 | I16: 54824.29 | J16: 54175.92 | K16: 54175.92 | L16: 56613.31 | M16: 55063.64 | N16: 53262.64 | O16: 43556.9 | P16: 43556.9 | Q16: 52155.65 | R16: 43060.96 | S16: 55600.02 | T16: 63653.67 | U16: 63653.67 | V16: 66699.53 | W16: 65485.9 | X16: 63205.11 | Y16: 58206.88 | Z16: 58206.88 | AA16: 75693.82 | AB16: 75098.14
A17: 1 | C17: 유동부채 | E17: 20865.54 | F17: 20865.54 | G17: 18845.6 | H17: 32061.35 | I17: 35288.41 | J17: 42714.35 | K17: 42714.35 | L17: 46290.94 | M17: 41625.97 | N17: 39233.59 | O17: 27540.69 | P17: 27540.69 | Q17: 29806.24 | R17: 7073.1 | S17: 8657.76 | T17: 16928.97 | U17: 16928.97 | V17: 16806.95 | W17: 13210.27 | X17: 12597.99 | Y17: 11454.54 | Z17: 11454.54 | AA17: 22027.37 | AB17: 18121.01
A18: 1 | C18: 매입채무및기타채무 | E18: 8159.73 | F18: 8159.73 | G18: 7342.42 | H18: 9583.38 | I18: 10071.16 | J18: 10939.39 | K18: 10939.39 | L18: 23479.72 | M18: 8796.3 | N18: 7213.41 | O18: 5385.93 | P18: 5385.93 | Q18: 5031.62 | R18: 4145.25 | S18: 3309.31 | T18: 4965.52 | U18: 4965.52 | V18: 3707.41 | W18: 3862.23 | X18: 3824.53 | Y18: 3411.3 | Z18: 3411.3 | AA18: 3595.75 | AB18: 4440.36
A19: 1 | C19: 단기차입금 | E19: 4800 | F19: 4800 | G19: 4800 | H19: 6800 | I19: 7600 | J19: 6800 | K19: 6800 | L19: 6500 | M19: 6850 | N19: 5100 | O19: 5850 | P19: 5850 | Q19: 3500 | R19: 1720 | S19: 1720 | T19: 3000 | U19: 3000 | V19: 3000
A20: 1 | C20: 유동리스부채 | E20: 511.42 | F20: 511.42 | G20: 516.3 | H20: 260.97 | I20: 263.75 | J20: 266.57 | K20: 266.57 | L20: 269.42 | M20: 272.3 | N20: 251.84 | Q20: 833.96 | R20: 148.07 | S20: 252.14 | T20: 338.33 | U20: 338.33 | V20: 427.44 | W20: 352.81 | X20: 374.46 | Y20: 285.53 | Z20: 285.53 | AA20: 305.48 | AB20: 320.58
A21: 1 | C21: 리스부채 | E21: 1916.5 | F21: 1916.5 | G21: 1790.46 | H21: 851.99 | I21: 779.53 | J21: 714.64 | K21: 714.64 | L21: 649.06 | M21: 582.78 | N21: 540.69 | O21: 229.21 | P21: 229.21 | Q21: 1487.19 | R21: 276.75 | S21: 430.64 | T21: 586.84 | U21: 586.84 | V21: 693.54 | W21: 546.68 | X21: 542.72 | Y21: 470.53 | Z21: 470.53 | AA21: 592.54 | AB21: 641.64
A22: 1 | C22: 단기금융부채 | E22: 511.42 | F22: 511.42 | G22: 516.3 | H22: 3543.86 | I22: 2957.95 | J22: 266.57 | K22: 266.57 | L22: 269.42 | M22: 272.3 | N22: 251.84 | O22: 9540.93 | P22: 9540.93 | Q22: 833.96 | R22: 455.72 | S22: 2025.22 | T22: 3862.76 | U22: 3862.76 | V22: 4607.99 | W22: 3853.4 | X22: 3359.62 | Y22: 1495.36 | Z22: 1495.36 | AA22: 10913.61 | AB22: 5697.2
A23: 1 | C23: 유동성장기부채 | E23: 3111.11 | F23: 3111.11 | G23: 2777.78 | H23: 9079.13 | I23: 9091.06 | J23: 9344.25 | K23: 9344.25 | L23: 2000 | M23: 6349.16 | N23: 6704.54 | O23: 5220.13 | P23: 5220.13 | Q23: 5661.06 | R23: 245.31 | S23: 984.28 | T23: 4624.32 | U23: 4624.32 | V23: 5180.44 | W23: 5202.76 | X23: 4817.79 | Y23: 5304.72 | Z23: 5304.72 | AA23: 6280.79 | AB23: 6669.78
A24: 1 | C24: 비유동부채 | E24: 1457.42 | F24: 1457.42 | G24: 1376.43 | H24: 794.59 | I24: 568.71 | J24: 448.07 | K24: 448.07 | L24: 379.64 | M24: 310.48 | N24: 354.92 | O24: 386.28 | P24: 386.28 | Q24: 785.15 | R24: 234.68 | S24: 10005.28 | T24: 10221.95 | U24: 10221.95 | V24: 10258.58 | W24: 14152.26 | X24: 14126.65 | Y24: 12185 | Z24: 12185 | AA24: 12287.06 | AB24: 12321.06
A25: 1 | C25: 확정급여부채 | E25: 37.34 | F25: 37.34 | G25: 102.27 | H25: 203.56 | I25: 52.93 | N25: 66.07
A26: 1 | C26: 비유동리스부채 | E26: 1405.08 | F26: 1405.08 | G26: 1274.16 | H26: 591.02 | I26: 515.78 | J26: 448.07 | K26: 448.07 | L26: 379.64 | M26: 310.48 | N26: 288.85 | O26: 229.21 | P26: 229.21 | Q26: 653.23 | R26: 128.68 | S26: 178.5 | T26: 248.51 | U26: 248.51 | V26: 266.1 | W26: 193.87 | X26: 168.26 | Y26: 185 | Z26: 185 | AA26: 287.06 | AB26: 321.06
A27: 1 | C27: 장기금융부채 | E27: 1405.08 | F27: 1405.08 | G27: 1274.16 | H27: 591.02 | I27: 515.78 | J27: 448.07 | K27: 448.07 | L27: 379.64 | M27: 310.48 | N27: 288.85 | O27: 229.21 | P27: 229.21 | Q27: 653.23 | R27: 128.68 | S27: 1843.37 | T27: 2172.07 | U27: 2172.07 | V27: 2208.26 | W27: 1579.99 | X27: 1554.38 | Y27: 185 | Z27: 185 | AA27: 287.06 | AB27: 321.06
A28: 1 | C28: 기타비유동부채 | E28: 15 | F28: 15 | T28: 49.88 | U28: 49.88 | V28: 50.32
A29: 1 | C29: 부채총계 | E29: 22322.96 | F29: 22322.96 | G29: 20222.03 | H29: 32855.93 | I29: 35857.12 | J29: 43162.43 | K29: 43162.43 | L29: 46670.59 | M29: 41936.45 | N29: 39588.51 | O29: 27926.98 | P29: 27926.98 | Q29: 30591.39 | R29: 7307.78 | S29: 18663.04 | T29: 27150.92 | U29: 27150.92 | V29: 27065.53 | W29: 27362.53 | X29: 26724.64 | Y29: 23639.54 | Z29: 23639.54 | AA29: 34314.42 | AB29: 30442.08
A30: 1 | C30: 자본금 | E30: 35875.4 | F30: 35875.4 | G30: 35875.4 | H30: 35875.4 | I30: 35875.4 | J30: 35875.4 | K30: 35875.4 | L30: 8968.85 | M30: 9389.72 | N30: 9389.72 | O30: 9389.72 | P30: 9389.72 | Q30: 11421.21 | R30: 15074.81 | S30: 15074.81 | T30: 15323.57 | U30: 15323.57 | V30: 16635.9 | W30: 16723.4 | X30: 16723.4 | Y30: 16723.4 | Z30: 16723.4 | AA30: 19820.97 | AB30: 19820.97
A31: 1 | C31: 자본잉여금 | E31: 41176.71 | F31: 41176.71 | G31: 41176.71 | H31: 41176.71 | I31: 41176.71 | J31: 41176.71 | K31: 41176.71 | L31: 41176.71 | M31: 41753.57 | N31: 41753.57 | O31: 41749.49 | P31: 41749.49 | Q31: 47718 | R31: 61845.21 | S31: 61845.21 | T31: 62577 | U31: 62577 | V31: 66255.65 | W31: 66574.31 | X31: 66574.31 | Y31: 66574.31 | Z31: 66574.31 | AA31: 71480.34 | AB31: 71480.34
A32: 1 | C32: 이익잉여금 | E32: -52480.69 | F32: -52480.69 | G32: -54264.5 | H32: -54813.35 | I32: -58084.94 | J32: -66038.62 | K32: -66038.62 | L32: -40202.83 | M32: -38012.03 | N32: -37465.09 | O32: -35509.29 | P32: -35509.29 | Q32: -37574.95 | R32: -41130.31 | S32: -39945.79 | T32: -41363.24 | U32: -41363.24 | V32: -43224.98 | W32: -45143.81 | X32: -46788.77 | Y32: -48693.39 | Z32: -48693.39 | AA32: -49884.67 | AB32: -46607.99
A33: 1 | C33: 자본총계 | E33: 24571.42 | F33: 24571.42 | G33: 22787.61 | H33: 22238.76 | I33: 18967.17 | J33: 11013.49 | K33: 11013.49 | L33: 9942.73 | M33: 13127.19 | N33: 13674.13 | O33: 15629.93 | P33: 15629.93 | Q33: 21564.26 | R33: 35753.19 | S33: 36936.97 | T33: 36502.75 | U33: 36502.75 | V33: 39634 | W33: 38123.38 | X33: 36480.47 | Y33: 34567.35 | Z33: 34567.35 | AA33: 41379.4 | AB33: 44656.07
A34: 1 | C34: 부채와자본총계 | E34: 46894.38 | F34: 46894.38 | G34: 43009.64 | H34: 55094.69 | I34: 54824.29 | J34: 54175.92 | K34: 54175.92 | L34: 56613.31 | M34: 55063.64 | N34: 53262.64 | O34: 43556.9 | P34: 43556.9 | Q34: 52155.65 | R34: 43060.96 | S34: 55600.02 | T34: 63653.67 | U34: 63653.67 | V34: 66699.53 | W34: 65485.9 | X34: 63205.11 | Y34: 58206.88 | Z34: 58206.88 | AA34: 75693.82 | AB34: 75098.14
A35: 1 | C35: 지배주주지분 | E35: 24571.42 | F35: 24571.42 | G35: 22787.61 | H35: 22238.76 | I35: 18967.17 | J35: 11013.49 | K35: 11013.49 | L35: 9942.73 | M35: 13127.19 | N35: 13674.13 | O35: 15629.93 | P35: 15629.93 | Q35: 21564.26 | R35: 35753.19 | S35: 36936.97 | T35: 36502.75 | U35: 36502.75 | V35: 39634 | W35: 38123.38 | X35: 36480.47 | Y35: 34567.35 | Z35: 34567.35 | AA35: 41379.4 | AB35: 44656.07
A36: 1 | C36: 총차입금 | E36: 7911.11 | F36: 7911.11 | G36: 7577.78 | H36: 15879.13 | I36: 16691.06 | J36: 16144.25 | K36: 16144.25 | L36: 8500 | M36: 13199.16 | N36: 11804.54 | O36: 11227.2 | P36: 11227.2 | Q36: 9292.98 | R36: 2071.31 | S36: 2704.28 | T36: 15624.32 | U36: 15624.32 | V36: 16180.44 | W36: 17202.76 | X36: 16817.79 | Y36: 17304.72 | Z36: 17304.72 | AA36: 18280.79 | AB36: 18669.78
A37: 1 | C37: 순차입금 | E37: 6658.85 | F37: 6658.85 | G37: 6455.36 | H37: 13044.5 | I37: 16167.79 | J37: 15440.86 | K37: 15440.86 | L37: 8093.01 | M37: 11710.79 | N37: 10428.87 | O37: 10033.99 | P37: 10033.99 | Q37: -3606.96 | R37: -14722.72 | S37: -6975.49 | T37: 4973.85 | U37: 4973.85 | V37: 8957.45 | W37: 11730.69 | X37: 14519.66 | Y37: 14848.36 | Z37: 14848.36 | AA37: -3098.8 | AB37: 18190.01
A38: 1 | C38: 이자발생자산 | E38: 1281.02 | F38: 1281.02 | G38: 1157.18 | H38: 2874.56 | I38: 523.27 | J38: 861.97 | K38: 861.97 | L38: 500.12 | M38: 1537.07 | N38: 1375.67 | O38: 1430.69 | P38: 1430.69 | Q38: 13245.98 | R38: 16794.03 | S38: 14299.76 | T38: 13324.19 | U38: 13324.19 | V38: 12596.71 | W38: 10991.08 | X38: 7117.14 | Y38: 5333.17 | Z38: 5333.17 | AA38: 24255.79 | AB38: 2600.27
A39: 1 | C39: 단기금융상품 | H39: 2000
A40: 1 | C40: 단기금융자산 | H40: 2000
...

Sheet subQ
A1: YQ | C1: subQ 분기 서브모델(억원, U=100) | E1: 4Q21 | F1: 2021 | G1: 1Q22 | H1: 2Q22 | I1: 3Q22 | J1: 4Q22 | K1: 2022 | L1: 1Q23 | M1: 2Q23 | N1: 3Q23 | O1: 4Q23 | P1: 2023 | Q1: 1Q24 | R1: 2Q24 | S1: 3Q24 | T1: 4Q24 | U1: 2024 | V1: 1Q25 | W1: 2Q25 | X1: 3Q25 | Y1: 4Q25 | Z1: 2025 | AA1: 1Q26 | AB1: 2Q26 | AC1: 3Q26 | AD1: 4Q26 | AE1: 2026 | AF1: 1Q27 | AG1: 2Q27 | AH1: 3Q27 | AI1: 4Q27 | AJ1: 2027 | AK1: 1Q28 | AL1: 2Q28 | AM1: 3Q28 | AN1: 4Q28 | AO1: 2028
A2: A=이름(key) B=그룹 C=단위 D=FnGuide 계정명(VLOOKUP 키). 확정=VLOOKUP(BS), 추정=변수 가정 참조
E3: 1 | F3: 2 | G3: 3 | H3: 4 | I3: 5 | J3: 6 | K3: 7 | L3: 8 | M3: 9 | N3: 10 | O3: 11 | P3: 12 | Q3: 13 | R3: 14 | S3: 15 | T3: 16 | U3: 17 | V3: 18 | W3: 19 | X3: 20 | Y3: 21 | Z3: 22 | AA3: 23 | AB3: 24 | AC3: 25 | AD3: 26 | AE3: 27 | AF3: 28 | AG3: 29 | AH3: 30 | AI3: 31 | AJ3: 32 | AK3: 33 | AL3: 34 | AM3: 35 | AN3: 36 | AO3: 37
E4: 2021.12 | F4: 2021.12A | G4: 2022.03 | H4: 2022.06 | I4: 2022.09 | J4: 2022.12 | K4: 2022.12A | L4: 2023.03 | M4: 2023.06 | N4: 2023.09 | O4: 2023.12 | P4: 2023.12A | Q4: 2024.03 | R4: 2024.06 | S4: 2024.09 | T4: 2024.12 | U4: 2024.12A | V4: 2025.03 | W4: 2025.06 | X4: 2025.09 | Y4: 2025.12 | Z4: 2025.12A | AA4: 2026.03 | AB4: 2026.06 | AC4: 2026.09 | AD4: 2026.12 | AE4: 2026.12A | AF4: 2027.03 | AG4: 2027.06 | AH4: 2027.09 | AI4: 2027.12 | AJ4: 2027.12A | AK4: 2028.03 | AL4: 2028.06 | AM4: 2028.09 | AN4: 2028.12 | AO4: 2028.12A
A5: 매출액 | B5: 손익 | C5: 억원 | D5: 매출액(수익) | E5: =IFERROR(VLOOKUP($D5,BS연결,MATCH(E$1,BS연결H,0),0)/100,"") | G5: =IFERROR(VLOOKUP($D5,BS연결,MATCH(G$1,BS연결H,0),0)/100,"") | H5: =IFERROR(VLOOKUP($D5,BS연결,MATCH(H$1,BS연결H,0),0)/100,"") | I5: =IFERROR(VLOOKUP($D5,BS연결,MATCH(I$1,BS연결H,0),0)/100,"") | J5: =IFERROR(VLOOKUP($D5,BS연결,MATCH(J$1,BS연결H,0),0)/100,"") | K5: =IFERROR(VLOOKUP($D5,BS연결,MATCH(K$1,BS연결H,0),0)/100,"") | L5: =IFERROR(VLOOKUP($D5,BS연결,MATCH(L$1,BS연결H,0),0)/100,"") | M5: =IFERROR(VLOOKUP($D5,BS연결,MATCH(M$1,BS연결H,0),0)/100,"") | N5: =IFERROR(VLOOKUP($D5,BS연결,MATCH(N$1,BS연결H,0),0)/100,"") | ... AB5: =IFERROR(VLOOKUP($D5,BS연결,MATCH(AB$1,BS연결H,0),0)/100,"") | AC5: =IFERROR(X5*(1+변수!AC21),"") | AD5: =IFERROR(Y5*(1+변수!AD21),"") | AE5: =SUM(AA5:AD5) | AF5: =IFERROR(AA5*(1+변수!AF21),"") | AG5: =IFERROR(AB5*(1+변수!AG21),"") | AH5: =IFERROR(AC5*(1+변수!AH21),"") | AI5: =IFERROR(AD5*(1+변수!AI21),"") | AJ5: =SUM(AF5:AI5) | AK5: =IFERROR(AF5*(1+변수!AK21),"") | AL5: =IFERROR(AG5*(1+변수!AL21),"") | AM5: =IFERROR(AH5*(1+변수!AM21),"") | AN5: =IFERROR(AI5*(1+변수!AN21),"") | AO5: =SUM(AK5:AN5)
A6: 매출원가 | B6: 손익 | C6: 억원 | D6: 매출원가 | E6: =IFERROR(VLOOKUP($D6,BS연결,MATCH(E$1,BS연결H,0),0)/100,"") | G6: =IFERROR(VLOOKUP($D6,BS연결,MATCH(G$1,BS연결H,0),0)/100,"") | H6: =IFERROR(VLOOKUP($D6,BS연결,MATCH(H$1,BS연결H,0),0)/100,"") | I6: =IFERROR(VLOOKUP($D6,BS연결,MATCH(I$1,BS연결H,0),0)/100,"") | J6: =IFERROR(VLOOKUP($D6,BS연결,MATCH(J$1,BS연결H,0),0)/100,"") | K6: =IFERROR(VLOOKUP($D6,BS연결,MATCH(K$1,BS연결H,0),0)/100,"") | L6: =IFERROR(VLOOKUP($D6,BS연결,MATCH(L$1,BS연결H,0),0)/100,"") | M6: =IFERROR(VLOOKUP($D6,BS연결,MATCH(M$1,BS연결H,0),0)/100,"") | N6: =IFERROR(VLOOKUP($D6,BS연결,MATCH(N$1,BS연결H,0),0)/100,"") | ... AB6: =IFERROR(VLOOKUP($D6,BS연결,MATCH(AB$1,BS연결H,0),0)/100,"") | AC6: =IFERROR(AC5-AC7,"") | AD6: =IFERROR(AD5-AD7,"") | AE6: =SUM(AA6:AD6) | AF6: =IFERROR(AF5-AF7,"") | AG6: =IFERROR(AG5-AG7,"") | AH6: =IFERROR(AH5-AH7,"") | AI6: =IFERROR(AI5-AI7,"") | AJ6: =SUM(AF6:AI6) | AK6: =IFERROR(AK5-AK7,"") | AL6: =IFERROR(AL5-AL7,"") | AM6: =IFERROR(AM5-AM7,"") | AN6: =IFERROR(AN5-AN7,"") | AO6: =SUM(AK6:AN6)
A7: 매출총이익 | B7: 손익 | C7: 억원 | D7: 매출총이익 | E7: =IFERROR(VLOOKUP($D7,BS연결,MATCH(E$1,BS연결H,0),0)/100,"") | G7: =IFERROR(VLOOKUP($D7,BS연결,MATCH(G$1,BS연결H,0),0)/100,"") | H7: =IFERROR(VLOOKUP($D7,BS연결,MATCH(H$1,BS연결H,0),0)/100,"") | I7: =IFERROR(VLOOKUP($D7,BS연결,MATCH(I$1,BS연결H,0),0)/100,"") | J7: =IFERROR(VLOOKUP($D7,BS연결,MATCH(J$1,BS연결H,0),0)/100,"") | K7: =IFERROR(VLOOKUP($D7,BS연결,MATCH(K$1,BS연결H,0),0)/100,"") | L7: =IFERROR(VLOOKUP($D7,BS연결,MATCH(L$1,BS연결H,0),0)/100,"") | M7: =IFERROR(VLOOKUP($D7,BS연결,MATCH(M$1,BS연결H,0),0)/100,"") | N7: =IFERROR(VLOOKUP($D7,BS연결,MATCH(N$1,BS연결H,0),0)/100,"") | ... AB7: =IFERROR(VLOOKUP($D7,BS연결,MATCH(AB$1,BS연결H,0),0)/100,"") | AC7: =IFERROR(AC9+AC8,"") | AD7: =IFERROR(AD9+AD8,"") | AE7: =SUM(AA7:AD7) | AF7: =IFERROR(AF9+AF8,"") | AG7: =IFERROR(AG9+AG8,"") | AH7: =IFERROR(AH9+AH8,"") | AI7: =IFERROR(AI9+AI8,"") | AJ7: =SUM(AF7:AI7) | AK7: =IFERROR(AK9+AK8,"") | AL7: =IFERROR(AL9+AL8,"") | AM7: =IFERROR(AM9+AM8,"") | AN7: =IFERROR(AN9+AN8,"") | AO7: =SUM(AK7:AN7)
A8: 판관비 | B8: 손익 | C8: 억원 | D8: 판관비 | E8: =IFERROR(VLOOKUP($D8,BS연결,MATCH(E$1,BS연결H,0),0)/100,"") | G8: =IFERROR(VLOOKUP($D8,BS연결,MATCH(G$1,BS연결H,0),0)/100,"") | H8: =IFERROR(VLOOKUP($D8,BS연결,MATCH(H$1,BS연결H,0),0)/100,"") | I8: =IFERROR(VLOOKUP($D8,BS연결,MATCH(I$1,BS연결H,0),0)/100,"") | J8: =IFERROR(VLOOKUP($D8,BS연결,MATCH(J$1,BS연결H,0),0)/100,"") | K8: =IFERROR(VLOOKUP($D8,BS연결,MATCH(K$1,BS연결H,0),0)/100,"") | L8: =IFERROR(VLOOKUP($D8,BS연결,MATCH(L$1,BS연결H,0),0)/100,"") | M8: =IFERROR(VLOOKUP($D8,BS연결,MATCH(M$1,BS연결H,0),0)/100,"") | N8: =IFERROR(VLOOKUP($D8,BS연결,MATCH(N$1,BS연결H,0),0)/100,"") | ... AB8: =IFERROR(VLOOKUP($D8,BS연결,MATCH(AB$1,BS연결H,0),0)/100,"") | AC8: =IFERROR(AC5*변수!AC22,"") | AD8: =IFERROR(AD5*변수!AD22,"") | AE8: =SUM(AA8:AD8) | AF8: =IFERROR(AF5*변수!AF22,"") | AG8: =IFERROR(AG5*변수!AG22,"") | AH8: =IFERROR(AH5*변수!AH22,"") | AI8: =IFERROR(AI5*변수!AI22,"") | AJ8: =SUM(AF8:AI8) | AK8: =IFERROR(AK5*변수!AK22,"") | AL8: =IFERROR(AL5*변수!AL22,"") | AM8: =IFERROR(AM5*변수!AM22,"") | AN8: =IFERROR(AN5*변수!AN22,"") | AO8: =SUM(AK8:AN8)
A9: 영업이익 | B9: 손익 | C9: 억원 | D9: 영업이익 | E9: =IFERROR(VLOOKUP($D9,BS연결,MATCH(E$1,BS연결H,0),0)/100,"") | G9: =IFERROR(VLOOKUP($D9,BS연결,MATCH(G$1,BS연결H,0),0)/100,"") | H9: =IFERROR(VLOOKUP($D9,BS연결,MATCH(H$1,BS연결H,0),0)/100,"") | I9: =IFERROR(VLOOKUP($D9,BS연결,MATCH(I$1,BS연결H,0),0)/100,"") | J9: =IFERROR(VLOOKUP($D9,BS연결,MATCH(J$1,BS연결H,0),0)/100,"") | K9: =IFERROR(VLOOKUP($D9,BS연결,MATCH(K$1,BS연결H,0),0)/100,"") | L9: =IFERROR(VLOOKUP($D9,BS연결,MATCH(L$1,BS연결H,0),0)/100,"") | M9: =IFERROR(VLOOKUP($D9,BS연결,MATCH(M$1,BS연결H,0),0)/100,"") | N9: =IFERROR(VLOOKUP($D9,BS연결,MATCH(N$1,BS연결H,0),0)/100,"") | ... AB9: =IFERROR(VLOOKUP($D9,BS연결,MATCH(AB$1,BS연결H,0),0)/100,"") | AC9: =IFERROR(AC5*변수!AC23,"") | AD9: =IFERROR(AD5*변수!AD23,"") | AE9: =SUM(AA9:AD9) | AF9: =IFERROR(AF5*변수!AF23,"") | AG9: =IFERROR(AG5*변수!AG23,"") | AH9: =IFERROR(AH5*변수!AH23,"") | AI9: =IFERROR(AI5*변수!AI23,"") | AJ9: =SUM(AF9:AI9) | AK9: =IFERROR(AK5*변수!AK23,"") | AL9: =IFERROR(AL5*변수!AL23,"") | AM9: =IFERROR(AM5*변수!AM23,"") | AN9: =IFERROR(AN5*변수!AN23,"") | AO9: =SUM(AK9:AN9)
A10: OPM | B10: 손익 | C10: % | D10: 영업이익률 | E10: =IFERROR(E9/E5,"") | G10: =IFERROR(G9/G5,"") | H10: =IFERROR(H9/H5,"") | I10: =IFERROR(I9/I5,"") | J10: =IFERROR(J9/J5,"") | K10: =IFERROR(K9/K5,"") | L10: =IFERROR(L9/L5,"") | M10: =IFERROR(M9/M5,"") | N10: =IFERROR(N9/N5,"") | ... AO10: =IFERROR(AO9/AO5,"")
A11: 금융손익 | B11: 손익 | C11: 억원 | D11: 금융손익 | E11: =IFERROR(VLOOKUP($D11,BS연결,MATCH(E$1,BS연결H,0),0)/100,"") | G11: =IFERROR(VLOOKUP($D11,BS연결,MATCH(G$1,BS연결H,0),0)/100,"") | H11: =IFERROR(VLOOKUP($D11,BS연결,MATCH(H$1,BS연결H,0),0)/100,"") | I11: =IFERROR(VLOOKUP($D11,BS연결,MATCH(I$1,BS연결H,0),0)/100,"") | J11: =IFERROR(VLOOKUP($D11,BS연결,MATCH(J$1,BS연결H,0),0)/100,"") | K11: =IFERROR(VLOOKUP($D11,BS연결,MATCH(K$1,BS연결H,0),0)/100,"") | L11: =IFERROR(VLOOKUP($D11,BS연결,MATCH(L$1,BS연결H,0),0)/100,"") | M11: =IFERROR(VLOOKUP($D11,BS연결,MATCH(M$1,BS연결H,0),0)/100,"") | N11: =IFERROR(VLOOKUP($D11,BS연결,MATCH(N$1,BS연결H,0),0)/100,"") | ... AB11: =IFERROR(VLOOKUP($D11,BS연결,MATCH(AB$1,BS연결H,0),0)/100,"") | AC11: =IFERROR(AC12+AC13+AC14+AC15,"") | AD11: =IFERROR(AD12+AD13+AD14+AD15,"") | AE11: =SUM(AA11:AD11) | AF11: =IFERROR(AF12+AF13+AF14+AF15,"") | AG11: =IFERROR(AG12+AG13+AG14+AG15,"") | AH11: =IFERROR(AH12+AH13+AH14+AH15,"") | AI11: =IFERROR(AI12+AI13+AI14+AI15,"") | AJ11: =SUM(AF11:AI11) | AK11: =IFERROR(AK12+AK13+AK14+AK15,"") | AL11: =IFERROR(AL12+AL13+AL14+AL15,"") | AM11: =IFERROR(AM12+AM13+AM14+AM15,"") | AN11: =IFERROR(AN12+AN13+AN14+AN15,"") | AO11: =SUM(AK11:AN11)
