Workbook
Name 변수H: 변수!$C$1:$AO$1
Name 환율: 변수!$C$6:$AO$13
Name BS연결H: BS연결!$C$1:$AO$1
Name BS연결: BS연결!$C$5:$AO$108
Name BS별도H: BS별도!$C$1:$AO$1
Name BS별도: BS별도!$C$5:$AO$94
Name SUBQH: subQ!$A$1:$AO$1
Name subQ: subQ!$A$5:$AO$45

Sheet README
A1: 인화정공(101930) 실적 모델 — ARGUS 한국조선
A2: 기준 분기 2026Q2 · 마지막 실적 2026Q2 · 생성 2026-10-26
A3: 모든 수치는 모델 산출값(DART 공개 재무제표 + 우리 추정)이다 — 목표주가·투자 추천 아님. 참고용 · 투자조언 아님.
A5: 시트
A6: 변수 가정 시계열. 환율 8행(ECB via frankfurter — L2 fx.json; 추정 분기 = 노란 가정), 추정 드라이버(노란 셀 = 모델값에서 역산한 가정, 바꾸면 재계산; 연녹 셀 = 3절 스칼라 참조 수식), 3절 스칼라 가정(세율·판관비율·지배주주비중·이자율·종가·PER 밴드·COE·외화 순노출·헤지비율)
A7: BS연결/BS별도 FnGuide 계정명 × 기간 값 덤프(백만원). 행1 분기라벨, 행4 YYYY.MM / YYYY.12A. 이름정의 BS연결H·BS연결(계정명 C열부터)
A8: subQ 분기 서브모델(억원 = 백만원/100). 확정 행: =IFERROR(VLOOKUP($D행,BS연결,MATCH(E$1,BS연결H,0),0)/100,"") 추정 행: 변수 시트 가정 셀 참조 수식. 외환손익·파생상품손익은 BS 계정 합·차, 기타금융손익은 잔차, OPM·EPS·BPS·PER·PBR 은 파생 수식
A9: SLS 선표(조선사만, sls json 있을 때): 요약 행(sls 저장값) + 계약별 스케줄(백만$) × (헤지비율 × 헤지환율 + (1−헤지비율) × 건조시점 환율[변수 원/달러(평균)]) → 원화 수식 블록 → 합계 행이 subQ 매출조선에 연결
A10: 시나리오 신규수주 보수/기준/낙관(forecast_panel 패널, 모델에 scenarios 가 있을 때만): 매출액·영업이익 = subQ 기준값 ± (시나리오 신규 − base 신규) × OPM. base 만 subQ 행에 포함, 나머지는 합산 안 함
A11: 분기/연간예상 subQ 를 이름(A열 key)으로 VLOOKUP 한 보고서 표(억원)
A12: TP PER 밴드 × 12M fwd EPS, PBR = ROE/COE × BPS — 모델 산출값 구간, 목표주가·추천 아님
A13: 외화 환율 QoQ, 외화 순노출 × Δ기말환율 → 환관련손익 추정
... A34: 백테스트: {"freeze": "2025Q2", "horizon": 4, "revenue_wape_pct": 16.1, "op_wape_pct": 51.5, "n": 4, "note": "단일 회사 4분기 — 통계 아님", "driver_at_freeze": "trend_seasonal", "selection_oos_at_freeze": {"wape_link": null, "wape_trend": null, "adopted": false, "decision": "rejected", "note": "유의성 조건 미달 → OOS 비교 전 기각"}, "frozen_inputs": "fin(연결/별도)·고객 조선사 모델·지주 자회사 모델은 2025Q2 까지의 분기만; 선표는 체결일 ≤ 2025Q2 말일 계약(원장 최신 금액·코호트 등급, 환산 없음); 잔고는 yards_cache 2025Q2; 시세·환율 forward·prices·forecast_panel 신규수주 미사용. 고객 가중치(suppliers.json 언급 비중)와 합병 체인링크는 현재 지식; 고객 연동 채택은 동결 모델 안에서도 자기 la−4분기 OOS 규칙(selection_oos_at_freeze)", "detail": [{"q": "2025Q3", "rev_pred": 236.66, "rev_act": 287.95, "op_pred": 17.87, "op_act": 48.65}, {"q": "2025Q4", "rev_pred": 287.06, "rev_act": 254.8, "op_pred": 21.68, "op_act": 36.01}, {"q": "2026Q1", "rev_pred": 328.16, "rev_act": 259.87, "op_pred": 24.78, "op_act": 41.62}, {"q": "2026Q2", "rev_pred": 289.52, "rev_act": 318.3, "op_pred": 21.87, "op_act": 51.34}]}

Sheet 변수
C1: 이름: 변수H | E1: 4Q21 | F1: 2021 | G1: 1Q22 | H1: 2Q22 | I1: 3Q22 | J1: 4Q22 | K1: 2022 | L1: 1Q23 | M1: 2Q23 | N1: 3Q23 | O1: 4Q23 | P1: 2023 | Q1: 1Q24 | R1: 2Q24 | S1: 3Q24 | T1: 4Q24 | U1: 2024 | V1: 1Q25 | W1: 2Q25 | X1: 3Q25 | Y1: 4Q25 | Z1: 2025 | AA1: 1Q26 | AB1: 2Q26 | AC1: 3Q26 | AD1: 4Q26 | AE1: 2026 | AF1: 1Q27 | AG1: 2Q27 | AH1: 3Q27 | AI1: 4Q27 | AJ1: 2027 | AK1: 1Q28 | AL1: 2Q28 | AM1: 3Q28 | AN1: 4Q28 | AO1: 2028
A2: 가정 시계열 — 노란 셀은 추정 가정(모델값에서 역산), 연녹 셀은 3절 스칼라 참조 수식. 바꾸면 subQ·분기·연간예상·TP·시나리오가 재계산됩니다.
E3: 1 | F3: 2 | G3: 3 | H3: 4 | I3: 5 | J3: 6 | K3: 7 | L3: 8 | M3: 9 | N3: 10 | O3: 11 | P3: 12 | Q3: 13 | R3: 14 | S3: 15 | T3: 16 | U3: 17 | V3: 18 | W3: 19 | X3: 20 | Y3: 21 | Z3: 22 | AA3: 23 | AB3: 24 | AC3: 25 | AD3: 26 | AE3: 27 | AF3: 28 | AG3: 29 | AH3: 30 | AI3: 31 | AJ3: 32 | AK3: 33 | AL3: 34 | AM3: 35 | AN3: 36 | AO3: 37
E4: 2021.12 | F4: 2021.12A | G4: 2022.03 | H4: 2022.06 | I4: 2022.09 | J4: 2022.12 | K4: 2022.12A | L4: 2023.03 | M4: 2023.06 | N4: 2023.09 | O4: 2023.12 | P4: 2023.12A | Q4: 2024.03 | R4: 2024.06 | S4: 2024.09 | T4: 2024.12 | U4: 2024.12A | V4: 2025.03 | W4: 2025.06 | X4: 2025.09 | Y4: 2025.12 | Z4: 2025.12A | AA4: 2026.03 | AB4: 2026.06 | AC4: 2026.09 | AD4: 2026.12 | AE4: 2026.12A | AF4: 2027.03 | AG4: 2027.06 | AH4: 2027.09 | AI4: 2027.12 | AJ4: 2027.12A | AK4: 2028.03 | AL4: 2028.06 | AM4: 2028.09 | AN4: 2028.12 | AO4: 2028.12A
B5: 1. FX | C5: 이름: 환율
A6: USDKRW_avg | C6: 원/달러(평균) | E6: 1183.5 | F6: 1145.51 | G6: 1205.78 | H6: 1262.09 | I6: 1341.93 | J6: 1360.12 | K6: 1292.98 | L6: 1276.95 | M6: 1315.69 | N6: 1313.62 | O6: 1322.01 | P6: 1306.85 | Q6: 1330.14 | R6: 1371.28 | S6: 1356.22 | T6: 1396.3 | U6: 1363.53 | V6: 1452.28 | W6: 1398.52 | X6: 1386.95 | Y6: 1449.19 | Z6: 1421.52 | AA6: 1466.12 | AB6: 1501.75 | AC6: 1418.75 | AD6: 1337.49 | AE6: 1451.19 | AF6: 1324.45 | AG6: 1324.45 | AH6: 1324.45 | AI6: 1324.45 | AK6: 1324.45 | AL6: 1324.45 | AM6: 1324.45 | AN6: 1324.45
A7: USDKRW_end | C7: 원/달러(기말) | E7: 1188.75 | F7: 1188.75 | G7: 1213.74 | H7: 1301.24 | I7: 1436.9 | J7: 1260.16 | K7: 1260.16 | L7: 1305.99 | M7: 1321.44 | N7: 1345.35 | O7: 1297.43 | P7: 1297.43 | Q7: 1349.25 | R7: 1377.73 | S7: 1312.17 | T7: 1474.78 | U7: 1474.78 | V7: 1474.54 | W7: 1355.13 | X7: 1403.67 | Y7: 1444.2 | Z7: 1444.2 | AA7: 1524.8 | AB7: 1550.89 | AC7: 1355.4 | AD7: 1324.45 | AE7: 1324.45 | AF7: 1324.45 | AG7: 1324.45 | AH7: 1324.45 | AI7: 1324.45 | AK7: 1324.45 | AL7: 1324.45 | AM7: 1324.45 | AN7: 1324.45
A8: JPY100KRW_avg | C8: 원/100Y(평균) | E8: 1041.02 | F8: 1042.74 | G8: 1036.79 | H8: 972.23 | I8: 970.61 | J8: 961.03 | K8: 985.1 | L8: 964.89 | M8: 957.36 | N8: 909 | O8: 893.22 | P8: 931.11 | Q8: 896.29 | R8: 880.14 | S8: 909.35 | T8: 917.25 | U8: 900.92 | V8: 952.59 | W8: 967.92 | X8: 940.32 | Y8: 940.77 | Z8: 950.17 | AA8: 934.39 | AB8: 942.16 | AC8: 890.41 | AD8: 846.51 | AE8: 915.57 | AF8: 844.67 | AG8: 844.67 | AH8: 844.67 | AI8: 844.67 | AK8: 844.67 | AL8: 844.67 | AM8: 844.67 | AN8: 844.67
A9: JPY100KRW_end | C9: 원/100Y(기말) | E9: 1032.62 | F9: 1032.62 | G9: 996.83 | H9: 954.9 | I9: 993.29 | J9: 955.54 | K9: 955.54 | L9: 980.62 | M9: 913.67 | N9: 901.47 | O9: 917.04 | P9: 917.04 | Q9: 892.42 | R9: 857.76 | S9: 919.21 | T9: 939.65 | U9: 939.65 | V9: 986.84 | W9: 938.85 | X9: 948.49 | Y9: 921.81 | Z9: 921.81 | AA9: 955.99 | AB9: 954.75 | AC9: 863.31 | AD9: 844.67 | AE9: 844.67 | AF9: 844.67 | AG9: 844.67 | AH9: 844.67 | AI9: 844.67 | AK9: 844.67 | AL9: 844.67 | AM9: 844.67 | AN9: 844.67
A10: EURKRW_avg | C10: W/Euro(평균) | E10: 1353.32 | F10: 1354.06 | G10: 1352.29 | H10: 1343.31 | I10: 1350.63 | J10: 1386.07 | K10: 1358.07 | L10: 1369.93 | M10: 1432.41 | N10: 1429.41 | O10: 1420.91 | P10: 1412.88 | Q10: 1444.21 | R10: 1476.42 | S10: 1489.3 | T10: 1490.78 | U10: 1475.4 | V10: 1528.33 | W10: 1585.13 | X10: 1620.04 | Y10: 1686.02 | Z10: 1605.45 | AA10: 1715.47 | AB10: 1746.09 | AC10: 1631.97 | AD10: 1500.06 | AE10: 1680.5 | AF10: 1482.45 | AG10: 1482.45 | AH10: 1482.45 | AI10: 1482.45 | AK10: 1482.45 | AL10: 1482.45 | AM10: 1482.45 | AN10: 1482.45
A11: EURKRW_end | C11: W/Euro(기말) | E11: 1346.38 | F11: 1346.38 | G11: 1347.37 | H11: 1351.6 | I11: 1400.62 | J11: 1344.08 | K11: 1344.08 | L11: 1420.26 | M11: 1435.88 | N11: 1425.26 | O11: 1433.66 | P11: 1433.66 | Q11: 1458.68 | R11: 1474.86 | S11: 1469.1 | T11: 1532.14 | U11: 1532.14 | V11: 1594.72 | W11: 1588.22 | X11: 1648.04 | Y11: 1696.94 | Z11: 1696.94 | AA11: 1753.21 | AB11: 1767.09 | AC11: 1539.06 | AD11: 1482.45 | AE11: 1482.45 | AF11: 1482.45 | AG11: 1482.45 | AH11: 1482.45 | AI11: 1482.45 | AK11: 1482.45 | AL11: 1482.45 | AM11: 1482.45 | AN11: 1482.45
A12: CNYKRW_avg | C12: 원/중국원(평균) | E12: 185.14 | F12: 177.65 | G12: 189.93 | H12: 190.76 | I12: 195.79 | J12: 191.09 | K12: 191.93 | L12: 186.59 | M12: 187.45 | N12: 181.28 | O12: 182.86 | P12: 184.52 | Q12: 185.04 | R12: 189.35 | S12: 189.24 | T12: 194.24 | U12: 189.49 | V12: 199.63 | W12: 193.41 | X12: 193.79 | Y12: 204.38 | Z12: 197.8 | AA12: 211.75 | AB12: 220.8 | AC12: 210.43 | AD12: 199.88 | AE12: 213.06 | AF12: 198.56 | AG12: 198.56 | AH12: 198.56 | AI12: 198.56 | AK12: 198.56 | AL12: 198.56 | AM12: 198.56 | AN12: 198.56
A13: CNYKRW_end | C13: 원/중국원(기말) | E13: 187.13 | F13: 187.13 | G13: 191.38 | H13: 194.13 | I13: 201.92 | J13: 182.67 | K13: 182.67 | L13: 189.97 | M13: 181.8 | N13: 184.26 | O13: 182.61 | P13: 182.61 | Q13: 186.66 | R13: 189.7 | S13: 187.12 | T13: 202.04 | U13: 202.04 | V13: 203.3 | W13: 189.14 | X13: 197.16 | Y13: 206.28 | Z13: 206.28 | AA13: 220.97 | AB13: 228.56 | AC13: 202.16 | AD13: 198.56 | AE13: 198.56 | AF13: 198.56 | AG13: 198.56 | AH13: 198.56 | AI13: 198.56 | AK13: 198.56 | AL13: 198.56 | AM13: 198.56 | AN13: 198.56
B14: 1b. 종가
A15: price_close_end | C15: 종가(기말) | E15: 2760 | G15: 3190 | H15: 3010 | I15: 2660 | J15: 2520 | L15: 1996 | M15: 2328 | N15: 2140 | O15: 2328 | Q15: 2444 | R15: 4660 | S15: 4130 | T15: 6010 | V15: 6450 | W15: 7230 | X15: 11060 | Y15: 9240 | AA15: 9240 | AB15: 7440 | AC15: 6210 | AD15: 6340
A16: price_high | C16: 종가(최고) | E16: 2810 | G16: 3590 | H16: 3490 | I16: 3410 | J16: 2800 | L16: 3024 | M16: 2414 | N16: 2626 | O16: 2440 | Q16: 2548 | R16: 5600 | S16: 4990 | T16: 6730 | V16: 7780 | W16: 8700 | X16: 12360 | Y16: 12900 | AA16: 10980 | AB16: 17000 | AC16: 8740 | AD16: 7000
A17: price_low | C17: 종가(최저) | E17: 2000 | G17: 2370 | H17: 2730 | I17: 2470 | J17: 2400 | L17: 1846 | M17: 1918 | N17: 1520 | O17: 1956 | Q17: 2060 | R17: 2346 | S17: 3616 | T17: 4120 | V17: 5740 | W17: 6320 | X17: 6190 | Y17: 8680 | AA17: 7020 | AB17: 6790 | AC17: 5480 | AD17: 5290
A18: price_avg | C18: 종가(평균) | E18: 2359.8 | G18: 2870.3 | H18: 3096.9 | I18: 2927.9 | J18: 2574.5 | L18: 2361.4 | M18: 2156.4 | N18: 2291.6 | O18: 2158.7 | Q18: 2261.4 | R18: 2852.3 | S18: 4252.5 | T18: 5182.8 | V18: 6779 | W18: 7703.5 | X18: 8976.2 | Y18: 10363.2 | AA18: 9207.1 | AB18: 10322.6 | AC18: 6807.6 | AD18: 5925
B20: 2. 추정 드라이버 | C20: 실적 열 = subQ 실현값(수식), 추정 열 = 가정(노란 = 모델값 역산, 연녹 = 3절 스칼라 참조)
A21: drv:매출액 | B21: yoy | C21: 매출액 YoY | J21: =IFERROR(subQ!J5/subQ!E5-1,"") | L21: =IFERROR(subQ!L5/subQ!G5-1,"") | M21: =IFERROR(subQ!M5/subQ!H5-1,"") | N21: =IFERROR(subQ!N5/subQ!I5-1,"") | O21: =IFERROR(subQ!O5/subQ!J5-1,"") | Q21: =IFERROR(subQ!Q5/subQ!L5-1,"") | R21: =IFERROR(subQ!R5/subQ!M5-1,"") | S21: =IFERROR(subQ!S5/subQ!N5-1,"") | T21: =IFERROR(subQ!T5/subQ!O5-1,"") | V21: =IFERROR(subQ!V5/subQ!Q5-1,"") | W21: =IFERROR(subQ!W5/subQ!R5-1,"") | X21: =IFERROR(subQ!X5/subQ!S5-1,"") | Y21: =IFERROR(subQ!Y5/subQ!T5-1,"") | AA21: =IFERROR(subQ!AA5/subQ!V5-1,"") | AB21: =IFERROR(subQ!AB5/subQ!W5-1,"") | AC21: 0.23876232 | AD21: 0.065639266 | AF21: 0.68010248 | AG21: 0.46971965 | AH21: 0.35049061 | AI21: 0.25592016 | AK21: 0.18330279 | AL21: 0.16239499 | AM21: 0.18039525 | AN21: 0.20896135
A22: drv:판관비 | B22: ratio | C22: 판관비율(/매출) | E22: =IFERROR(subQ!E8/subQ!E5,"") | F22: =IFERROR(subQ!F8/subQ!F5,"") | G22: =IFERROR(subQ!G8/subQ!G5,"") | H22: =IFERROR(subQ!H8/subQ!H5,"") | I22: =IFERROR(subQ!I8/subQ!I5,"") | J22: =IFERROR(subQ!J8/subQ!J5,"") | K22: =IFERROR(subQ!K8/subQ!K5,"") | L22: =IFERROR(subQ!L8/subQ!L5,"") | ... AB22: =IFERROR(subQ!AB8/subQ!AB5,"") | AC22: =$D$53 | AD22: =$D$53 | AE22: =IFERROR(subQ!AE8/subQ!AE5,"") | AF22: =$D$53 | AG22: =$D$53 | AH22: =$D$53 | AI22: =$D$53 | AJ22: =IFERROR(subQ!AJ8/subQ!AJ5,"") | AK22: =$D$53 | AL22: =$D$53 | AM22: =$D$53 | AN22: =$D$53 | AO22: =IFERROR(subQ!AO8/subQ!AO5,"")
A23: drv:영업이익 | B23: ratio | C23: 영업이익률(OPM) | E23: =IFERROR(subQ!E9/subQ!E5,"") | F23: =IFERROR(subQ!F9/subQ!F5,"") | G23: =IFERROR(subQ!G9/subQ!G5,"") | H23: =IFERROR(subQ!H9/subQ!H5,"") | I23: =IFERROR(subQ!I9/subQ!I5,"") | J23: =IFERROR(subQ!J9/subQ!J5,"") | K23: =IFERROR(subQ!K9/subQ!K5,"") | L23: =IFERROR(subQ!L9/subQ!L5,"") | ... AB23: =IFERROR(subQ!AB9/subQ!AB5,"") | AC23: 0.15074292 | AD23: 0.15073841 | AE23: =IFERROR(subQ!AE9/subQ!AE5,"") | AF23: 0.15073294 | AG23: 0.15074496 | AH23: 0.15075147 | AI23: 0.15075362 | AJ23: =IFERROR(subQ!AJ9/subQ!AJ5,"") | AK23: 0.15074618 | AL23: 0.15074111 | AM23: 0.15075094 | AN23: 0.15074707 | AO23: =IFERROR(subQ!AO9/subQ!AO5,"")
A24: drv:파생상품손익 | B24: abs | C24: 파생상품손익 (가정, 억원) | E24: =subQ!E13 | F24: =subQ!F13 | G24: =subQ!G13 | H24: =subQ!H13 | I24: =subQ!I13 | J24: =subQ!J13 | K24: =subQ!K13 | L24: =subQ!L13 | ... AB24: =subQ!AB13 | AC24: 0 | AD24: 0 | AE24: =subQ!AE13 | AF24: 0 | AG24: 0 | AH24: 0 | AI24: 0 | AJ24: =subQ!AJ13 | AK24: 0 | AL24: 0 | AM24: 0 | AN24: 0 | AO24: =subQ!AO13
A25: drv:기타금융손익 | B25: abs | C25: 기타금융손익 (가정, 억원) | E25: =subQ!E14 | F25: =subQ!F14 | G25: =subQ!G14 | H25: =subQ!H14 | I25: =subQ!I14 | J25: =subQ!J14 | K25: =subQ!K14 | L25: =subQ!L14 | ... AB25: =subQ!AB14 | AC25: 0 | AD25: 0 | AE25: =subQ!AE14 | AF25: 0 | AG25: 0 | AH25: 0 | AI25: 0 | AJ25: =subQ!AJ14 | AK25: 0 | AL25: 0 | AM25: 0 | AN25: 0 | AO25: =subQ!AO14
A26: drv:기타영업외손익 | B26: abs | C26: 기타영업외손익 (가정, 억원) | E26: =subQ!E15 | F26: =subQ!F15 | G26: =subQ!G15 | H26: =subQ!H15 | I26: =subQ!I15 | J26: =subQ!J15 | K26: =subQ!K15 | L26: =subQ!L15 | ... AB26: =subQ!AB15 | AC26: 0 | AD26: 0 | AE26: =subQ!AE15 | AF26: 0 | AG26: 0 | AH26: 0 | AI26: 0 | AJ26: =subQ!AJ15 | AK26: 0 | AL26: 0 | AM26: 0 | AN26: 0 | AO26: =subQ!AO15
A27: drv:지분법손익 | B27: abs | C27: 지분법손익 (가정, 억원) | E27: =subQ!E16 | F27: =subQ!F16 | G27: =subQ!G16 | H27: =subQ!H16 | I27: =subQ!I16 | J27: =subQ!J16 | K27: =subQ!K16 | L27: =subQ!L16 | ... AB27: =subQ!AB16 | AC27: 36.67 | AD27: 36.67 | AE27: =subQ!AE16 | AF27: 36.67 | AG27: 36.67 | AH27: 36.67 | AI27: 36.67 | AJ27: =subQ!AJ16 | AK27: 36.67 | AL27: 36.67 | AM27: 36.67 | AN27: 36.67 | AO27: =subQ!AO16
A28: drv:법인세비용 | B28: tax | C28: 법인세율(/세전) — 법인세 = MAX(세전,0) × 세율 | E28: =IFERROR(subQ!E18/subQ!E17,"") | F28: =IFERROR(subQ!F18/subQ!F17,"") | G28: =IFERROR(subQ!G18/subQ!G17,"") | H28: =IFERROR(subQ!H18/subQ!H17,"") | I28: =IFERROR(subQ!I18/subQ!I17,"") | J28: =IFERROR(subQ!J18/subQ!J17,"") | K28: =IFERROR(subQ!K18/subQ!K17,"") | L28: =IFERROR(subQ!L18/subQ!L17,"") | ... AB28: =IFERROR(subQ!AB18/subQ!AB17,"") | AC28: =$D$52 | AD28: =$D$52 | AE28: =IFERROR(subQ!AE18/subQ!AE17,"") | AF28: =$D$52 | AG28: =$D$52 | AH28: =$D$52 | AI28: =$D$52 | AJ28: =IFERROR(subQ!AJ18/subQ!AJ17,"") | AK28: =$D$52 | AL28: =$D$52 | AM28: =$D$52 | AN28: =$D$52 | AO28: =IFERROR(subQ!AO18/subQ!AO17,"")
A29: drv:지배주주순이익 | B29: ratio | C29: 지배주주 비중(/당기순이익) | E29: =IFERROR(subQ!E20/subQ!E19,"") | F29: =IFERROR(subQ!F20/subQ!F19,"") | G29: =IFERROR(subQ!G20/subQ!G19,"") | H29: =IFERROR(subQ!H20/subQ!H19,"") | I29: =IFERROR(subQ!I20/subQ!I19,"") | J29: =IFERROR(subQ!J20/subQ!J19,"") | K29: =IFERROR(subQ!K20/subQ!K19,"") | L29: =IFERROR(subQ!L20/subQ!L19,"") | ... AB29: =IFERROR(subQ!AB20/subQ!AB19,"") | AC29: =$D$54 | AD29: =$D$54 | AE29: =IFERROR(subQ!AE20/subQ!AE19,"") | AF29: =$D$54 | AG29: =$D$54 | AH29: =$D$54 | AI29: =$D$54 | AJ29: =IFERROR(subQ!AJ20/subQ!AJ19,"") | AK29: =$D$54 | AL29: =$D$54 | AM29: =$D$54 | AN29: =$D$54 | AO29: =IFERROR(subQ!AO20/subQ!AO19,"")
A30: drv:중단사업이익 | B30: abs | C30: 중단사업이익 (가정, 억원) | E30: =subQ!E21 | F30: =subQ!F21 | G30: =subQ!G21 | H30: =subQ!H21 | I30: =subQ!I21 | J30: =subQ!J21 | K30: =subQ!K21 | L30: =subQ!L21 | ... AB30: =subQ!AB21 | AE30: =subQ!AE21 | AJ30: =subQ!AJ21 | AO30: =subQ!AO21
A31: drv:감가상각비 | B31: abs | C31: 감가상각비 (가정, 억원) | E31: =subQ!E22 | F31: =subQ!F22 | G31: =subQ!G22 | H31: =subQ!H22 | I31: =subQ!I22 | J31: =subQ!J22 | K31: =subQ!K22 | L31: =subQ!L22 | ... AB31: =subQ!AB22 | AC31: 16.36 | AD31: 16.36 | AE31: =subQ!AE22 | AF31: 16.36 | AG31: 16.36 | AH31: 16.36 | AI31: 16.36 | AJ31: =subQ!AJ22 | AK31: 16.36 | AL31: 16.36 | AM31: 16.36 | AN31: 16.36 | AO31: =subQ!AO22
A32: drv:부채총계 | B32: qoq | C32: 부채총계 QoQ | G32: =IFERROR(subQ!G25/subQ!E25-1,"") | H32: =IFERROR(subQ!H25/subQ!G25-1,"") | I32: =IFERROR(subQ!I25/subQ!H25-1,"") | J32: =IFERROR(subQ!J25/subQ!I25-1,"") | L32: =IFERROR(subQ!L25/subQ!J25-1,"") | M32: =IFERROR(subQ!M25/subQ!L25-1,"") | N32: =IFERROR(subQ!N25/subQ!M25-1,"") | O32: =IFERROR(subQ!O25/subQ!N25-1,"") | Q32: =IFERROR(subQ!Q25/subQ!O25-1,"") | R32: =IFERROR(subQ!R25/subQ!Q25-1,"") | S32: =IFERROR(subQ!S25/subQ!R25-1,"") | T32: =IFERROR(subQ!T25/subQ!S25-1,"") | V32: =IFERROR(subQ!V25/subQ!T25-1,"") | W32: =IFERROR(subQ!W25/subQ!V25-1,"") | X32: =IFERROR(subQ!X25/subQ!W25-1,"") | Y32: =IFERROR(subQ!Y25/subQ!X25-1,"") | AA32: =IFERROR(subQ!AA25/subQ!Y25-1,"") | AB32: =IFERROR(subQ!AB25/subQ!AA25-1,"") | AC32: -2.46e-06 | AD32: 0 | AF32: 0 | AG32: 0 | AH32: 0 | AI32: 0 | AK32: 0 | AL32: 0 | AM32: 0 | AN32: 0
A33: drv:자본총계 | B33: roll | C33: 자본총계 기타변동(배당 등, 억원) | G33: =IFERROR(subQ!E26+subQ!G19-subQ!G26,"") | H33: =IFERROR(subQ!G26+subQ!H19-subQ!H26,"") | I33: =IFERROR(subQ!H26+subQ!I19-subQ!I26,"") | J33: =IFERROR(subQ!I26+subQ!J19-subQ!J26,"") | L33: =IFERROR(subQ!J26+subQ!L19-subQ!L26,"") | M33: =IFERROR(subQ!L26+subQ!M19-subQ!M26,"") | N33: =IFERROR(subQ!M26+subQ!N19-subQ!N26,"") | O33: =IFERROR(subQ!N26+subQ!O19-subQ!O26,"") | Q33: =IFERROR(subQ!O26+subQ!Q19-subQ!Q26,"") | R33: =IFERROR(subQ!Q26+subQ!R19-subQ!R26,"") | S33: =IFERROR(subQ!R26+subQ!S19-subQ!S26,"") | T33: =IFERROR(subQ!S26+subQ!T19-subQ!T26,"") | V33: =IFERROR(subQ!T26+subQ!V19-subQ!V26,"") | W33: =IFERROR(subQ!V26+subQ!W19-subQ!W26,"") | X33: =IFERROR(subQ!W26+subQ!X19-subQ!X26,"") | Y33: =IFERROR(subQ!X26+subQ!Y19-subQ!Y26,"") | AA33: =IFERROR(subQ!Y26+subQ!AA19-subQ!AA26,"") | AB33: =IFERROR(subQ!AA26+subQ!AB19-subQ!AB26,"") | AC33: -0.000809684 | AD33: -0.007846888 | AF33: -0.004257786 | AG33: 68.541078 | AH33: -0.005516347 | AI33: 0.002605387 | AK33: -0.005427026 | AL33: 68.540767 | AM33: 0.004508613 | AN33: 0.000793615
A34: drv:지배주주지분 | B34: roll | C34: 지배주주지분 기타변동(배당 등, 억원) | G34: =IFERROR(subQ!E27+subQ!G20-subQ!G27,"") | H34: =IFERROR(subQ!G27+subQ!H20-subQ!H27,"") | I34: =IFERROR(subQ!H27+subQ!I20-subQ!I27,"") | J34: =IFERROR(subQ!I27+subQ!J20-subQ!J27,"") | L34: =IFERROR(subQ!J27+subQ!L20-subQ!L27,"") | M34: =IFERROR(subQ!L27+subQ!M20-subQ!M27,"") | N34: =IFERROR(subQ!M27+subQ!N20-subQ!N27,"") | O34: =IFERROR(subQ!N27+subQ!O20-subQ!O27,"") | Q34: =IFERROR(subQ!O27+subQ!Q20-subQ!Q27,"") | R34: =IFERROR(subQ!Q27+subQ!R20-subQ!R27,"") | S34: =IFERROR(subQ!R27+subQ!S20-subQ!S27,"") | T34: =IFERROR(subQ!S27+subQ!T20-subQ!T27,"") | V34: =IFERROR(subQ!T27+subQ!V20-subQ!V27,"") | W34: =IFERROR(subQ!V27+subQ!W20-subQ!W27,"") | X34: =IFERROR(subQ!W27+subQ!X20-subQ!X27,"") | Y34: =IFERROR(subQ!X27+subQ!Y20-subQ!Y27,"") | AA34: =IFERROR(subQ!Y27+subQ!AA20-subQ!AA27,"") | AB34: =IFERROR(subQ!AA27+subQ!AB20-subQ!AB27,"") | AC34: -0.000809684 | AD34: -0.007846888 | AF34: -0.004257786 | AG34: 68.541078 | AH34: -0.005516347 | AI34: 0.002605387 | AK34: -0.005427026 | AL34: 68.540767 | AM34: 0.004508613 | AN34: 0.000793615
A35: drv:총차입금 | B35: qoq | C35: 총차입금 QoQ | G35: =IFERROR(subQ!G28/subQ!E28-1,"") | H35: =IFERROR(subQ!H28/subQ!G28-1,"") | I35: =IFERROR(subQ!I28/subQ!H28-1,"") | J35: =IFERROR(subQ!J28/subQ!I28-1,"") | L35: =IFERROR(subQ!L28/subQ!J28-1,"") | M35: =IFERROR(subQ!M28/subQ!L28-1,"") | N35: =IFERROR(subQ!N28/subQ!M28-1,"") | O35: =IFERROR(subQ!O28/subQ!N28-1,"") | Q35: =IFERROR(subQ!Q28/subQ!O28-1,"") | R35: =IFERROR(subQ!R28/subQ!Q28-1,"") | S35: =IFERROR(subQ!S28/subQ!R28-1,"") | T35: =IFERROR(subQ!T28/subQ!S28-1,"") | V35: =IFERROR(subQ!V28/subQ!T28-1,"") | W35: =IFERROR(subQ!W28/subQ!V28-1,"") | X35: =IFERROR(subQ!X28/subQ!W28-1,"") | Y35: =IFERROR(subQ!Y28/subQ!X28-1,"") | AA35: =IFERROR(subQ!AA28/subQ!Y28-1,"") | AB35: =IFERROR(subQ!AB28/subQ!AA28-1,"") | AC35: 0 | AD35: 0 | AF35: 0 | AG35: 0 | AH35: 0 | AI35: 0 | AK35: 0 | AL35: 0 | AM35: 0 | AN35: 0
A36: drv:순차입금 | B36: qoq | C36: 순차입금 QoQ | G36: =IFERROR(subQ!G29/subQ!E29-1,"") | H36: =IFERROR(subQ!H29/subQ!G29-1,"") | I36: =IFERROR(subQ!I29/subQ!H29-1,"") | J36: =IFERROR(subQ!J29/subQ!I29-1,"") | L36: =IFERROR(subQ!L29/subQ!J29-1,"") | M36: =IFERROR(subQ!M29/subQ!L29-1,"") | N36: =IFERROR(subQ!N29/subQ!M29-1,"") | O36: =IFERROR(subQ!O29/subQ!N29-1,"") | Q36: =IFERROR(subQ!Q29/subQ!O29-1,"") | R36: =IFERROR(subQ!R29/subQ!Q29-1,"") | S36: =IFERROR(subQ!S29/subQ!R29-1,"") | T36: =IFERROR(subQ!T29/subQ!S29-1,"") | V36: =IFERROR(subQ!V29/subQ!T29-1,"") | W36: =IFERROR(subQ!W29/subQ!V29-1,"") | X36: =IFERROR(subQ!X29/subQ!W29-1,"") | Y36: =IFERROR(subQ!Y29/subQ!X29-1,"") | AA36: =IFERROR(subQ!AA29/subQ!Y29-1,"") | AB36: =IFERROR(subQ!AB29/subQ!AA29-1,"") | AC36: -0.27779818 | AD36: -0.3390478 | AF36: -0.65623871 | AG36: -0.55674653 | AH36: -4.5908013 | AI36: 1.0674766 | AK36: 0.65121032 | AL36: 0.14392914 | AM36: 0.36819504 | AN36: 0.22524281
A37: drv:이자발생자산 | B37: qoq | C37: 이자발생자산 QoQ | G37: =IFERROR(subQ!G30/subQ!E30-1,"") | H37: =IFERROR(subQ!H30/subQ!G30-1,"") | I37: =IFERROR(subQ!I30/subQ!H30-1,"") | J37: =IFERROR(subQ!J30/subQ!I30-1,"") | L37: =IFERROR(subQ!L30/subQ!J30-1,"") | M37: =IFERROR(subQ!M30/subQ!L30-1,"") | N37: =IFERROR(subQ!N30/subQ!M30-1,"") | O37: =IFERROR(subQ!O30/subQ!N30-1,"") | Q37: =IFERROR(subQ!Q30/subQ!O30-1,"") | R37: =IFERROR(subQ!R30/subQ!Q30-1,"") | S37: =IFERROR(subQ!S30/subQ!R30-1,"") | T37: =IFERROR(subQ!T30/subQ!S30-1,"") | V37: =IFERROR(subQ!V30/subQ!T30-1,"") | W37: =IFERROR(subQ!W30/subQ!V30-1,"") | X37: =IFERROR(subQ!X30/subQ!W30-1,"") | Y37: =IFERROR(subQ!Y30/subQ!X30-1,"") | AA37: =IFERROR(subQ!AA30/subQ!Y30-1,"") | AB37: =IFERROR(subQ!AB30/subQ!AA30-1,"") | AC37: 0.09772563 | AD37: 0.078457594 | AF37: 0.093091893 | AG37: 0.024834763 | AH37: 0.08857054 | AI37: 0.067926653 | AK37: 0.080241425 | AL37: 0.027105976 | AM37: 0.077228594 | AN37: 0.059998947
A38: drv:현금및현금성자산 | B38: qoq | C38: 현금및현금성자산 QoQ | G38: =IFERROR(subQ!G31/subQ!E31-1,"") | H38: =IFERROR(subQ!H31/subQ!G31-1,"") | I38: =IFERROR(subQ!I31/subQ!H31-1,"") | J38: =IFERROR(subQ!J31/subQ!I31-1,"") | L38: =IFERROR(subQ!L31/subQ!J31-1,"") | M38: =IFERROR(subQ!M31/subQ!L31-1,"") | N38: =IFERROR(subQ!N31/subQ!M31-1,"") | O38: =IFERROR(subQ!O31/subQ!N31-1,"") | Q38: =IFERROR(subQ!Q31/subQ!O31-1,"") | R38: =IFERROR(subQ!R31/subQ!Q31-1,"") | S38: =IFERROR(subQ!S31/subQ!R31-1,"") | T38: =IFERROR(subQ!T31/subQ!S31-1,"") | V38: =IFERROR(subQ!V31/subQ!T31-1,"") | W38: =IFERROR(subQ!W31/subQ!V31-1,"") | X38: =IFERROR(subQ!X31/subQ!W31-1,"") | Y38: =IFERROR(subQ!Y31/subQ!X31-1,"") | AA38: =IFERROR(subQ!AA31/subQ!Y31-1,"") | AB38: =IFERROR(subQ!AB31/subQ!AA31-1,"")
A39: drv:CAPEX | B39: yoy | C39: CAPEX YoY | J39: =IFERROR(subQ!J32/subQ!E32-1,"") | L39: =IFERROR(subQ!L32/subQ!G32-1,"") | M39: =IFERROR(subQ!M32/subQ!H32-1,"") | N39: =IFERROR(subQ!N32/subQ!I32-1,"") | O39: =IFERROR(subQ!O32/subQ!J32-1,"") | Q39: =IFERROR(subQ!Q32/subQ!L32-1,"") | R39: =IFERROR(subQ!R32/subQ!M32-1,"") | S39: =IFERROR(subQ!S32/subQ!N32-1,"") | T39: =IFERROR(subQ!T32/subQ!O32-1,"") | V39: =IFERROR(subQ!V32/subQ!Q32-1,"") | W39: =IFERROR(subQ!W32/subQ!R32-1,"") | X39: =IFERROR(subQ!X32/subQ!S32-1,"") | Y39: =IFERROR(subQ!Y32/subQ!T32-1,"") | AA39: =IFERROR(subQ!AA32/subQ!V32-1,"") | AB39: =IFERROR(subQ!AB32/subQ!W32-1,"") | AC39: -0.11545521 | AD39: -0.69555124 | AF39: 1.4277001 | AG39: 0.15141048 | AH39: 0 | AI39: 0 | AK39: 0 | AL39: 0 | AM39: 0 | AN39: 0
A40: drv:영업활동현금흐름 | B40: yoy | C40: 영업활동현금흐름 YoY | J40: =IFERROR(subQ!J33/subQ!E33-1,"") | L40: =IFERROR(subQ!L33/subQ!G33-1,"") | M40: =IFERROR(subQ!M33/subQ!H33-1,"") | N40: =IFERROR(subQ!N33/subQ!I33-1,"") | O40: =IFERROR(subQ!O33/subQ!J33-1,"") | Q40: =IFERROR(subQ!Q33/subQ!L33-1,"") | R40: =IFERROR(subQ!R33/subQ!M33-1,"") | S40: =IFERROR(subQ!S33/subQ!N33-1,"") | T40: =IFERROR(subQ!T33/subQ!O33-1,"") | V40: =IFERROR(subQ!V33/subQ!Q33-1,"") | W40: =IFERROR(subQ!W33/subQ!R33-1,"") | X40: =IFERROR(subQ!X33/subQ!S33-1,"") | Y40: =IFERROR(subQ!Y33/subQ!T33-1,"") | AA40: =IFERROR(subQ!AA33/subQ!V33-1,"") | AB40: =IFERROR(subQ!AB33/subQ!W33-1,"")
A41: drv:주식수 | B41: qoq | C41: 주식수 QoQ | G41: =IFERROR(subQ!G34/subQ!E34-1,"") | H41: =IFERROR(subQ!H34/subQ!G34-1,"") | I41: =IFERROR(subQ!I34/subQ!H34-1,"") | J41: =IFERROR(subQ!J34/subQ!I34-1,"") | L41: =IFERROR(subQ!L34/subQ!J34-1,"") | M41: =IFERROR(subQ!M34/subQ!L34-1,"") | N41: =IFERROR(subQ!N34/subQ!M34-1,"") | O41: =IFERROR(subQ!O34/subQ!N34-1,"") | Q41: =IFERROR(subQ!Q34/subQ!O34-1,"") | R41: =IFERROR(subQ!R34/subQ!Q34-1,"") | S41: =IFERROR(subQ!S34/subQ!R34-1,"") | T41: =IFERROR(subQ!T34/subQ!S34-1,"") | V41: =IFERROR(subQ!V34/subQ!T34-1,"") | W41: =IFERROR(subQ!W34/subQ!V34-1,"") | X41: =IFERROR(subQ!X34/subQ!W34-1,"") | Y41: =IFERROR(subQ!Y34/subQ!X34-1,"") | AA41: =IFERROR(subQ!AA34/subQ!Y34-1,"") | AB41: =IFERROR(subQ!AB34/subQ!AA34-1,"") | AC41: 0 | AD41: 0 | AF41: 0 | AG41: 0 | AH41: 0 | AI41: 0 | AK41: 0 | AL41: 0 | AM41: 0 | AN41: 0
...

Sheet BS연결
B1: (백만원) | C1: 이름: BS연결H | E1: 4Q21 | F1: 2021 | G1: 1Q22 | H1: 2Q22 | I1: 3Q22 | J1: 4Q22 | K1: 2022 | L1: 1Q23 | M1: 2Q23 | N1: 3Q23 | O1: 4Q23 | P1: 2023 | Q1: 1Q24 | R1: 2Q24 | S1: 3Q24 | T1: 4Q24 | U1: 2024 | V1: 1Q25 | W1: 2Q25 | X1: 3Q25 | Y1: 4Q25 | Z1: 2025 | AA1: 1Q26 | AB1: 2Q26 | AC1: 3Q26 | AD1: 4Q26 | AE1: 2026 | AF1: 1Q27 | AG1: 2Q27 | AH1: 3Q27 | AI1: 4Q27 | AJ1: 2027 | AK1: 1Q28 | AL1: 2Q28 | AM1: 3Q28 | AN1: 4Q28 | AO1: 2028
B2: 연결 | D2: fin json(kship_fin.py)
B3: 인화정공(연) | C3: UPDATE: 26-10-26 | E3: 1 | F3: 2 | G3: 3 | H3: 4 | I3: 5 | J3: 6 | K3: 7 | L3: 8 | M3: 9 | N3: 10 | O3: 11 | P3: 12 | Q3: 13 | R3: 14 | S3: 15 | T3: 16 | U3: 17 | V3: 18 | W3: 19 | X3: 20 | Y3: 21 | Z3: 22 | AA3: 23 | AB3: 24 | AC3: 25 | AD3: 26 | AE3: 27 | AF3: 28 | AG3: 29 | AH3: 30 | AI3: 31 | AJ3: 32 | AK3: 33 | AL3: 34 | AM3: 35 | AN3: 36 | AO3: 37
B4: Account Code | C4: AccountNAME | E4: 2021.12 | F4: 2021.12A | G4: 2022.03 | H4: 2022.06 | I4: 2022.09 | J4: 2022.12 | K4: 2022.12A | L4: 2023.03 | M4: 2023.06 | N4: 2023.09 | O4: 2023.12 | P4: 2023.12A | Q4: 2024.03 | R4: 2024.06 | S4: 2024.09 | T4: 2024.12 | U4: 2024.12A | V4: 2025.03 | W4: 2025.06 | X4: 2025.09 | Y4: 2025.12 | Z4: 2025.12A | AA4: 2026.03 | AB4: 2026.06 | AC4: 2026.09 | AD4: 2026.12 | AE4: 2026.12A | AF4: 2027.03 | AG4: 2027.06 | AH4: 2027.09 | AI4: 2027.12 | AJ4: 2027.12A | AK4: 2028.03 | AL4: 2028.06 | AM4: 2028.09 | AN4: 2028.12 | AO4: 2028.12A
A5: 1 | C5: 유동자산 | E5: 101723.74 | F5: 101723.74 | G5: 99806.1 | H5: 116046.67 | I5: 89406.79 | J5: 85858.05 | K5: 85858.05 | L5: 91617.72 | M5: 78320.56 | N5: 99152.72 | O5: 74798.44 | P5: 74798.44 | Q5: 90892.17 | R5: 105632.19 | S5: 104122.38 | T5: 104918.13 | U5: 104918.13 | V5: 211162.88 | W5: 177354.45 | X5: 221238.06 | Y5: 224602.52 | Z5: 224602.52 | AA5: 211813.39 | AB5: 179456.63
A6: 1 | C6: 현금및현금성자산 | E6: 28788.2 | F6: 28788.2 | G6: 27451.56 | H6: 45899.33 | I6: 19614.96 | J6: 12136.96 | K6: 12136.96 | L6: 10169.51 | M6: 7790.28 | N6: 23817.59 | O6: 29637.86 | P6: 29637.86 | Q6: 25376.1 | R6: 11142.13 | S6: 14042.55 | T6: 13305.55 | U6: 13305.55 | V6: 29599.31 | W6: 21715.88 | X6: 21060.28 | Y6: 18187.38 | Z6: 18187.38 | AA6: 17822.96 | AB6: 17643.95
A7: 1 | C7: 단기금융상품 | E7: 13649.67 | F7: 13649.67 | G7: 14262.76 | H7: 11898 | I7: 12198 | J7: 14298 | K7: 14298 | L7: 12306.67 | M7: 12150.67 | N7: 12477.42 | O7: 3594.41 | P7: 3594.41 | Q7: 33620.87 | R7: 24112.2 | S7: 51378.68 | T7: 46104.83 | U7: 46104.83 | V7: 136841.32 | W7: 111522.12 | X7: 168162.1
A8: 1 | C8: 단기금융자산 | E8: 19437.04 | F8: 19437.04 | G8: 18974.05 | H8: 18817.42 | I8: 16094.42 | J8: 17939.81 | K8: 17939.81 | L8: 15619.01 | M8: 15130.62 | N8: 17529.75 | O8: 5136.41 | P8: 5136.41 | Q8: 36148.47 | R8: 63936.54 | S8: 51378.68 | T8: 46104.83 | U8: 46104.83 | V8: 136841.32 | W8: 111556.35 | X8: 168162.1
A9: 1 | C9: 매출채권및기타채권 | E9: 43852.09 | F9: 43852.09 | G9: 49750.99 | H9: 35821.4 | I9: 41350.35 | J9: 55075.16 | K9: 55075.16 | L9: 64340.64 | M9: 42859.01 | N9: 44257.07 | O9: 54322.55 | P9: 54322.55 | Q9: 34498.02 | R9: 75628.44 | S9: 35520.47 | T9: 43956.1 | U9: 43956.1 | V9: 49471.95 | W9: 44276.78 | X9: 34225.3 | Y9: 15284.69 | Z9: 15284.69 | AA9: 17066.07 | AB9: 16777.91
A10: 1 | C10: 단기대여금 | E10: 1787.37 | F10: 1787.37 | G10: 1211.29 | H10: 1684.37 | I10: 1661.37 | J10: 1803.72 | K10: 1803.72 | L10: 1983.72 | M10: 2533.74 | N10: 4613.62 | O10: 1326.84 | P10: 1326.84 | Q10: 2325.59 | R10: 39824.34
A11: 1 | C11: 당기법인세자산(선급법인세) | E11: 25.28 | F11: 25.28 | G11: 13.07 | H11: 14.33 | I11: 170.16 | J11: 39.53 | K11: 39.53 | L11: 36.18 | M11: 33.48 | N11: 132.39 | O11: 326.29 | P11: 326.29 | Q11: 34.07 | R11: 19.34 | S11: 25.01 | T11: 34.55 | U11: 34.55 | V11: 31.81 | W11: 20.85 | X11: 25.41 | Y11: 29.9 | Z11: 29.9 | AA11: 32.42 | AB11: 23.19
A12: 1 | C12: 재고자산 | E12: 32539.81 | F12: 32539.81 | G12: 29153.76 | H12: 34145.5 | I12: 33589.33 | J12: 27926.1 | K12: 27926.1 | L12: 29933.31 | M12: 33779.36 | N12: 37646.26 | O12: 13443.51 | P12: 13443.51 | Q12: 13392.77 | R12: 12761.5 | S12: 14457.59 | T12: 16839.1 | U12: 16839.1 | V12: 13147.61 | W12: 14798.07 | X12: 13410.53 | Y12: 14789.23 | Z12: 14789.23 | AA12: 15617.58 | AB12: 16381.45
A13: 1 | C13: 기타유동금융자산 | E13: 4000 | F13: 4000 | G13: 3500 | H13: 5235.05 | I13: 2235.05 | J13: 1838.09 | K13: 1838.09 | L13: 1328.62 | M13: 446.21 | N13: 438.71 | O13: 215.16 | P13: 215.16 | Q13: 202.01 | R13: 0 | S13: 0 | T13: 0 | U13: 0 | W13: 34.23 | Y13: 172107.12 | Z13: 172107.12 | AA13: 158557.95 | AB13: 125341
A14: 1 | C14: 유동파생상품자산 | E14: 0 | F14: 0 | H14: 1735.05 | I14: 1735.05 | J14: 1338.09 | K14: 1338.09 | L14: 1328.62 | M14: 446.21 | N14: 438.71 | O14: 215.16 | P14: 215.16 | Q14: 202.01 | R14: 0 | S14: 0 | T14: 0 | U14: 0 | W14: 34.23
A15: 1 | C15: 비유동자산 | E15: 262975.94 | F15: 262975.94 | G15: 245866.22 | H15: 230958.45 | I15: 256459.19 | J15: 254863.66 | K15: 254863.66 | L15: 255594.17 | M15: 254568.07 | N15: 254180.01 | O15: 244392.17 | P15: 244392.17 | Q15: 265414.99 | R15: 304449.72 | S15: 289588.77 | T15: 325338.58 | U15: 325338.58 | V15: 232258.64 | W15: 268788.88 | X15: 241928.84 | Y15: 237467.73 | Z15: 237467.73 | AA15: 240715.96 | AB15: 253109.93
A16: 1 | C16: 장기금융자산 | E16: 3113.38 | F16: 3113.38 | G16: 2759.46 | H16: 2680.64 | I16: 2259.7 | J16: 2650.3 | K16: 2650.3 | L16: 2717.31 | M16: 2792.06 | N16: 2971.8 | O16: 1237.16 | P16: 1237.16 | Q16: 82706.26 | R16: 130886.66 | S16: 112929.07 | T16: 154214 | U16: 154214 | V16: 64914.86 | W16: 86030.52 | X16: 69675.14 | Y16: 54668.44 | Z16: 54668.44 | AA16: 55636.22 | AB16: 64782.84
A17: 1 | C17: 투자자산 | E17: 3613.38 | F17: 3613.38 | G17: 3159.46 | H17: 3080.64 | I17: 2659.7 | J17: 2950.3 | K17: 2950.3 | L17: 2817.31 | M17: 2892.06 | N17: 3571.8 | O17: 1822.16 | P17: 1822.16 | Q17: 83291.26 | R17: 130971.66 | S17: 112929.07 | T17: 154214 | U17: 154214 | V17: 64914.86 | W17: 86030.52 | X17: 69675.14 | Y17: 136527.32 | Z17: 136527.32 | AA17: 140054.9 | AB17: 153976.26
A18: 1 | C18: 장기매출채권및기타채권 | E18: 607.82 | F18: 607.82 | G18: 515.22 | H18: 463.73 | I18: 467.22 | J18: 377.74 | K18: 377.74 | L18: 163.12 | M18: 168.31 | N18: 667.69 | O18: 614.14 | P18: 614.14 | Q18: 614.37 | R18: 114.6 | Y18: 88.65 | Z18: 88.65 | AA18: 88.71 | AB18: 87.73
A19: 1 | C19: 장기대여금 | E19: 500 | F19: 500 | G19: 400 | H19: 400 | I19: 400 | J19: 300 | K19: 300 | L19: 100 | M19: 100 | N19: 600 | O19: 585 | P19: 585 | Q19: 585 | R19: 85
A20: 1 | C20: 유형자산 | E20: 95904.1 | F20: 95904.1 | G20: 94740.88 | H20: 93535.42 | I20: 92217.09 | J20: 91617.92 | K20: 91617.92 | L20: 90785.73 | M20: 89839.33 | N20: 88821.98 | O20: 71627.21 | P20: 71627.21 | Q20: 71242.99 | R20: 71288.51 | S20: 71347.01 | T20: 71009.16 | U20: 71009.16 | V20: 72084.03 | W20: 72164.57 | X20: 72111.12 | Y20: 73564.73 | Z20: 73564.73 | AA20: 73024.99 | AB20: 72387.9
A21: 1 | C21: 투자부동산 | E21: 38214.31 | F21: 38214.31 | G21: 38286.21 | H21: 35011.07 | I21: 32632.19 | J21: 32695.11 | K21: 32695.11 | L21: 32695.11 | M21: 32757.02 | N21: 33627.39 | O21: 28445.6 | P21: 28445.6 | Q21: 28445.6 | R21: 29252.81 | S21: 29268.81 | T21: 29268.81 | U21: 29268.81 | V21: 29205.88 | W21: 29205.88 | X21: 29205.88 | Y21: 27133.65 | Z21: 27133.65 | AA21: 26995.95 | AB21: 25607.38
A22: 1 | C22: 무형자산 | E22: 142 | F22: 142 | G22: 138.97 | H22: 128.94 | I22: 125.46 | J22: 123.85 | K22: 123.85 | L22: 122.94 | M22: 122.09 | N22: 121.5 | O22: 116.81 | P22: 116.81 | Q22: 116.67 | R22: 116.53 | S22: 116.39 | T22: 116.26 | U22: 116.26 | V22: 116.16 | W22: 116.06 | X22: 115.96 | Y22: 115.86 | Z22: 115.86 | AA22: 523.76 | AB22: 523.66
A23: 1 | C23: 이연법인세자산 | E23: 96.53 | F23: 96.53 | G23: 96.53 | J23: 0 | K23: 0 | O23: 2665.45 | P23: 2665.45 | Q23: 0 | R23: 0 | S23: 0 | T23: 0 | U23: 0 | V23: 0 | W23: 0 | Y23: 0 | Z23: 0
A24: 1 | C24: 기타비유동자산 | E24: 3.14 | F24: 3.14 | G24: 4.04 | H24: 11.43 | I24: 8.52 | J24: 7.39 | K24: 7.39 | L24: 11.81 | M24: 84463.45 | N24: 84462.51 | O24: 12.55 | P24: 12.55 | Q24: 11.56 | R24: 276.69 | S24: 103.07 | T24: 8.28 | U24: 8.28 | V24: 8.63 | W24: 6.98 | X24: 6.51 | Y24: 37.52 | Z24: 37.52 | AA24: 27.65 | AB24: 527.01
A25: 1 | C25: 자산총계 | E25: 364699.68 | F25: 364699.68 | G25: 345672.32 | H25: 347005.12 | I25: 345865.98 | J25: 340721.71 | K25: 340721.71 | L25: 347211.89 | M25: 332888.63 | N25: 353332.72 | O25: 319190.61 | P25: 319190.61 | Q25: 356307.15 | R25: 410081.9 | S25: 393711.15 | T25: 430256.71 | U25: 430256.71 | V25: 443421.53 | W25: 446143.32 | X25: 463166.9 | Y25: 462070.25 | Z25: 462070.25 | AA25: 452529.34 | AB25: 432566.56
A26: 1 | C26: 유동부채 | E26: 169586.87 | F26: 169586.87 | G26: 162047.67 | H26: 165948.12 | I26: 160920.17 | J26: 158686.2 | K26: 158686.2 | L26: 162871.2 | M26: 156116.89 | N26: 177484.85 | O26: 143470.04 | P26: 143470.04 | Q26: 133236.74 | R26: 130000.04 | S26: 131416.55 | T26: 133955.18 | U26: 133955.18 | V26: 144952.79 | W26: 122439.31 | X26: 117628 | Y26: 107007.16 | Z26: 107007.16 | AA26: 98168.73 | AB26: 62469.72
A27: 1 | C27: 매입채무및기타채무 | E27: 156919.62 | F27: 156919.62 | G27: 154814.86 | H27: 160944.21 | I27: 156115 | J27: 153694.1 | K27: 153694.1 | L27: 158386.33 | M27: 153948.19 | N27: 175558.47 | O27: 142343.96 | P27: 142343.96 | Q27: 122403.27 | R27: 121070.41 | S27: 120824.44 | T27: 123353.53 | U27: 123353.53 | V27: 118084.63 | W27: 100154.51 | X27: 83285.02 | Y27: 8383.42 | Z27: 8383.42 | AA27: 7526.44 | AB27: 8124.91
A28: 1 | C28: 단기차입금 | E28: 131396 | F28: 131396 | G28: 129456 | H28: 132156 | I28: 126576 | J28: 126576 | K28: 126576 | L28: 126726 | M28: 126576 | N28: 130836 | O28: 108680 | P28: 108680 | Q28: 103680 | R28: 109180 | S28: 109530 | T28: 109530 | U28: 109530 | V28: 99530 | W28: 74530 | X28: 58880 | Y28: 46880 | Z28: 46880 | AA28: 46880 | AB28: 45340
A29: 1 | C29: 유동성장기부채 | E29: 2579.4 | F29: 2579.4 | G29: 2079.4 | H29: 7602.9 | I29: 7763.82 | J29: 7924.78 | K29: 7924.78 | L29: 7082.23 | M29: 7248.98 | N29: 7410.69 | O29: 7574.85 | P29: 7574.85 | Q29: 7750.72 | R29: 1000 | S29: 1000 | T29: 1000 | U29: 1000 | V29: 1000 | W29: 14500 | X29: 14500 | Y29: 14500 | Z29: 14500 | AA29: 15000 | AB29: 1000
A30: 1 | C30: 유동리스부채 | E30: 46.2 | F30: 46.2 | G30: 44.07 | H30: 55.32 | I30: 56.87 | J30: 64.09 | K30: 64.09 | L30: 55.48 | M30: 73.89 | N30: 67.36 | O30: 41.71 | P30: 41.71 | Q30: 42.13 | R30: 45.09 | S30: 45.52 | T30: 45.96 | U30: 45.96 | V30: 30.6 | W30: 28.78 | X30: 25.75
A31: 1 | C31: 리스부채 | E31: 83.4 | F31: 83.4 | G31: 70.32 | H31: 105.38 | I31: 113.03 | J31: 157.98 | K31: 157.98 | L31: 139.47 | M31: 225.12 | N31: 203.91 | O31: 137.17 | P31: 137.17 | Q31: 126.26 | R31: 115.25 | S31: 104.13 | T31: 92.92 | U31: 92.92 | V31: 53.49 | W31: 45.89 | X31: 38.24 | Y31: 7.83 | Z31: 7.83 | AA31: 3.14 | AB31: 36.47
A32: 1 | C32: 단기금융부채 | E32: 46.2 | F32: 46.2 | G32: 46.45 | H32: 8711.56 | I32: 8721.93 | J32: 7678.61 | K32: 7678.61 | L32: 7670 | M32: 3676.51 | N32: 3679.68 | O32: 2236.51 | P32: 2236.51 | Q32: 2244.85 | R32: 45.09 | S32: 45.52 | T32: 97.36 | U32: 97.36 | V32: 32.04 | W32: 28.78 | X32: 25.75 | Y32: 0 | Z32: 0
A33: 1 | C33: 당기법인세부채(미지급법인세) | E33: 12667.25 | F33: 12667.25 | G33: 7231.62 | H33: 675.79 | I33: 472.63 | J33: 1184.84 | K33: 1184.84 | L33: 677.61 | M33: 367.4 | N33: 120.23 | O33: 28.68 | P33: 28.68 | Q33: 9732.1 | R33: 8929.64 | S33: 10592.11 | T33: 10575.94 | U33: 10575.94 | V33: 26867.44 | W33: 22284.79 | X33: 34342.98 | Y33: 34331.23 | Z33: 34331.23 | AA33: 19602.36 | AB33: 2268.65
A34: 1 | C34: 비유동부채 | E34: 5488.26 | F34: 5488.26 | G34: 5649.85 | H34: 10965.58 | I34: 13412.87 | J34: 11684.9 | K34: 11684.9 | L34: 11886.66 | M34: 12002.48 | N34: 12140.65 | O34: 7035.45 | P34: 7035.45 | Q34: 11092.59 | R34: 30054.15 | S34: 25324.75 | T34: 36376.77 | U34: 36376.77 | V34: 24319.48 | W34: 15069.58 | X34: 13613.61 | Y34: 13709.31 | Z34: 13709.31 | AA34: 13085.1 | AB34: 14755.47
A35: 1 | C35: 장기매입채무및기타채무 | E35: 1795.9 | F35: 1795.9 | G35: 1679.02 | H35: 7244.9 | I35: 9498.1 | J35: 9623.82 | K35: 9623.82 | L35: 9914.31 | M35: 9809.35 | N35: 9920.46 | O35: 7152.65 | P35: 7152.65 | Q35: 7293.56 | R35: 14505.22 | S35: 14341.85 | T35: 14168.91 | U35: 14168.91 | V35: 15124.54 | W35: 1098.47 | X35: 1423.55 | Y35: 127.53 | Z35: 127.53 | AA35: 120 | AB35: 50
A36: 1 | C36: 기타비유동부채 | E36: 711 | F36: 711 | G36: 661 | H36: 781 | I36: 441.15 | J36: 442.15 | K36: 442.15 | L36: 325.74 | M36: 442.4 | N36: 440.75 | O36: 190 | P36: 190 | Q36: 190 | R36: 190
A37: 1 | C37: 장기차입금 | E37: 116.2 | F37: 116.2 | G37: 96.35 | H37: 76.5 | I37: 2556.65 | J37: 2536.8 | K37: 2536.8 | L37: 2516.95 | M37: 2500 | N37: 2500 | O37: 0 | P37: 0 | Q37: 0 | R37: 14000 | S37: 14000 | T37: 14000 | U37: 14000 | V37: 15000 | W37: 1000 | X37: 1300 | Y37: 1300 | Z37: 1300 | AA37: 300 | AB37: 300
A38: 1 | C38: 비유동리스부채 | E38: 37.2 | F38: 37.2 | G38: 26.25 | H38: 50.06 | I38: 56.16 | J38: 93.89 | K38: 93.89 | L38: 83.99 | M38: 151.23 | N38: 136.55 | O38: 95.46 | P38: 95.46 | Q38: 84.13 | R38: 70.16 | S38: 58.61 | T38: 46.96 | U38: 46.96 | V38: 22.89 | W38: 17.11 | X38: 12.49 | Y38: 7.83 | Z38: 7.83 | AA38: 3.14 | AB38: 36.47
A39: 1 | C39: 장기금융부채 | E39: 37.2 | F39: 37.2 | G39: 26.25 | H39: 50.06 | I39: 56.16 | J39: 93.89 | K39: 93.89 | L39: 83.99 | M39: 151.23 | N39: 136.55 | O39: 95.46 | P39: 95.46 | Q39: 84.13 | R39: 70.16 | S39: 58.61 | T39: 46.96 | U39: 46.96 | V39: 22.89 | W39: 17.11 | X39: 12.49 | Y39: 7.83 | Z39: 7.83 | AA39: 3.14 | AB39: 36.47
A40: 1 | C40: 장기충당부채 | E40: 0 | F40: 0
...

Sheet BS별도
B1: (백만원) | C1: 이름: BS별도H | E1: 4Q21 | F1: 2021 | G1: 1Q22 | H1: 2Q22 | I1: 3Q22 | J1: 4Q22 | K1: 2022 | L1: 1Q23 | M1: 2Q23 | N1: 3Q23 | O1: 4Q23 | P1: 2023 | Q1: 1Q24 | R1: 2Q24 | S1: 3Q24 | T1: 4Q24 | U1: 2024 | V1: 1Q25 | W1: 2Q25 | X1: 3Q25 | Y1: 4Q25 | Z1: 2025 | AA1: 1Q26 | AB1: 2Q26 | AC1: 3Q26 | AD1: 4Q26 | AE1: 2026 | AF1: 1Q27 | AG1: 2Q27 | AH1: 3Q27 | AI1: 4Q27 | AJ1: 2027 | AK1: 1Q28 | AL1: 2Q28 | AM1: 3Q28 | AN1: 4Q28 | AO1: 2028
B2: 별도 | D2: fin json(kship_fin.py)
B3: 인화정공(별) | C3: UPDATE: 26-10-26 | E3: 1 | F3: 2 | G3: 3 | H3: 4 | I3: 5 | J3: 6 | K3: 7 | L3: 8 | M3: 9 | N3: 10 | O3: 11 | P3: 12 | Q3: 13 | R3: 14 | S3: 15 | T3: 16 | U3: 17 | V3: 18 | W3: 19 | X3: 20 | Y3: 21 | Z3: 22 | AA3: 23 | AB3: 24 | AC3: 25 | AD3: 26 | AE3: 27 | AF3: 28 | AG3: 29 | AH3: 30 | AI3: 31 | AJ3: 32 | AK3: 33 | AL3: 34 | AM3: 35 | AN3: 36 | AO3: 37
B4: Account Code | C4: AccountNAME | E4: 2021.12 | F4: 2021.12A | G4: 2022.03 | H4: 2022.06 | I4: 2022.09 | J4: 2022.12 | K4: 2022.12A | L4: 2023.03 | M4: 2023.06 | N4: 2023.09 | O4: 2023.12 | P4: 2023.12A | Q4: 2024.03 | R4: 2024.06 | S4: 2024.09 | T4: 2024.12 | U4: 2024.12A | V4: 2025.03 | W4: 2025.06 | X4: 2025.09 | Y4: 2025.12 | Z4: 2025.12A | AA4: 2026.03 | AB4: 2026.06 | AC4: 2026.09 | AD4: 2026.12 | AE4: 2026.12A | AF4: 2027.03 | AG4: 2027.06 | AH4: 2027.09 | AI4: 2027.12 | AJ4: 2027.12A | AK4: 2028.03 | AL4: 2028.06 | AM4: 2028.09 | AN4: 2028.12 | AO4: 2028.12A
A5: 1 | C5: 유동자산 | E5: 36188.84 | F5: 36188.84 | G5: 34043.97 | H5: 54813.13 | I5: 32299.22 | J5: 33484.86 | K5: 33484.86 | L5: 33451.61 | M5: 33572.3 | N5: 49575.79 | O5: 59137.79 | P5: 59137.79 | Q5: 76010.07 | R5: 91316.16 | S5: 91418.68 | T5: 90467.32 | U5: 90467.32 | V5: 196365.58 | W5: 163047.92 | X5: 207100.81 | Y5: 210447.27 | Z5: 210447.27 | AA5: 196904.1 | AB5: 163070.67
A6: 1 | C6: 현금및현금성자산 | E6: 14382.03 | F6: 14382.03 | G6: 11519.71 | H6: 30832.25 | I6: 6837.81 | J6: 4997.94 | K6: 4997.94 | L6: 3282.03 | M6: 3026.22 | N6: 17227.14 | O6: 25823 | P6: 25823 | Q6: 20315.68 | R6: 5007.86 | S6: 7788.4 | T6: 7078.57 | U6: 7078.57 | V6: 23544.42 | W6: 17190.85 | X6: 17533.8 | Y6: 13688.49 | Z6: 13688.49 | AA6: 12118.5 | AB6: 11995.39
A7: 1 | C7: 단기금융상품 | E7: 307.67 | F7: 307.67 | G7: 463.67 | H7: 256 | I7: 256 | J7: 156 | K7: 156 | L7: 164.67 | M7: 8.67 | N7: 935.42 | O7: 2094.41 | P7: 2094.41 | Q7: 32120.87 | R7: 22612.2 | S7: 49838.68 | T7: 45064.83 | U7: 45064.83 | V7: 134301.32 | W7: 108982.12 | X7: 165621.1
A8: 1 | C8: 단기금융자산 | E8: 1421.01 | F8: 1421.01 | G8: 1417.71 | H8: 2942.09 | I8: 2939.09 | J8: 2326.54 | K8: 2326.54 | L8: 4915.21 | M8: 7531.1 | N8: 11407.85 | O8: 9630.14 | P8: 9630.14 | Q8: 33156.6 | R8: 61445.92 | S8: 49838.68 | T8: 45064.83 | U8: 45064.83 | V8: 134301.32 | W8: 108982.12 | X8: 165621.1
A9: 1 | C9: 매출채권및기타채권 | E9: 23548.75 | F9: 23548.75 | G9: 25475.94 | H9: 22250.58 | I9: 24411.69 | J9: 29797.38 | K9: 29797.38 | L9: 33393.12 | M9: 31310.15 | N9: 32002.4 | O9: 35753.16 | P9: 35753.16 | Q9: 26943.04 | R9: 69621.13 | S9: 32759.25 | T9: 39334.28 | U9: 39334.28 | V9: 45027.59 | W9: 39417.83 | X9: 26733.08 | Y9: 12450.74 | Z9: 12450.74 | AA9: 15435.74 | AB9: 14287.92
A10: 1 | C10: 단기대여금 | E10: 1113.34 | F10: 1113.34 | G10: 954.04 | H10: 951.04 | I10: 948.04 | J10: 853.72 | K10: 853.72 | L10: 3433.72 | M10: 7083.72 | N10: 10033.72 | O10: 7333.72 | P10: 7333.72 | Q10: 833.72 | R10: 38833.72
A11: 1 | C11: 당기법인세자산(선급법인세) | E11: 0 | F11: 0 | I11: 170.05 | L11: 7.37 | O11: 283.05 | P11: 283.05 | Q11: 0 | R11: 0 | S11: 0 | T11: 0 | U11: 0 | V11: 0
A12: 1 | C12: 재고자산 | E12: 9452.32 | F12: 9452.32 | G12: 9139.66 | H12: 10657.67 | I12: 10913.64 | J12: 10962.94 | K12: 10962.94 | L12: 9491.65 | M12: 10152.45 | N12: 10180.94 | O12: 9428.34 | P12: 9428.34 | Q12: 9614.56 | R12: 9563.23 | S12: 11402.88 | T12: 12432.04 | U12: 12432.04 | V12: 9717.24 | W12: 10477.24 | X12: 9493.98 | Y12: 11355.36 | Z12: 11355.36 | AA12: 11428.02 | AB12: 11589
A13: 1 | C13: 비유동자산 | E13: 242563.59 | F13: 242563.59 | G13: 241815.96 | H13: 240990.23 | I13: 268999.97 | J13: 269022.1 | K13: 269022.1 | L13: 268297.36 | M13: 267732.27 | N13: 269175.26 | O13: 265478.3 | P13: 265478.3 | Q13: 271141.38 | R13: 319600.89 | S13: 301607.11 | T13: 342400.16 | U13: 342400.16 | V13: 254075.32 | W13: 275664.84 | X13: 258717.7 | Y13: 246832.24 | Z13: 246832.24 | AA13: 247641.11 | AB13: 256314.63
A14: 1 | C14: 장기금융자산 | E14: 450.02 | F14: 450.02 | G14: 457.08 | H14: 464.15 | I14: 471.21 | J14: 793.28 | K14: 793.28 | L14: 780.43 | M14: 802.5 | N14: 1124.56 | O14: 546.63 | P14: 546.63 | Q14: 163301.11 | R14: 259602.28 | S14: 223664.12 | T14: 153422.9 | U14: 153422.9 | V14: 64102.96 | W14: 85622.53 | X14: 68949.58 | Y14: 54150.44 | Z14: 54150.44 | AA14: 55107.54 | AB14: 64246.27
A15: 1 | C15: 투자자산 | E15: 158969.93 | F15: 158969.93 | G15: 158976.99 | H15: 158984.06 | I15: 32232.05 | J15: 32554.12 | K15: 32554.12 | L15: 32541.27 | M15: 32563.34 | N15: 32885.4 | O15: 17591.48 | P15: 17591.48 | Q15: 180290.32 | R15: 276591.49 | S15: 240653.33 | T15: 170412.11 | U15: 170412.11 | V15: 81092.17 | W15: 102611.74 | X15: 85938.79 | Y15: 165062.82 | Z15: 165062.82 | AA15: 166019.92 | AB15: 175158.65
A16: 1 | C16: 장기매출채권및기타채권 | E16: 42.79 | F16: 42.79 | G16: 51.04 | H16: 0.8 | I16: 0.8 | J16: 11.11 | K16: 11.11 | L16: 11.27 | M16: 11.33 | N16: 11.49 | O16: 21.09 | P16: 21.09 | Q16: 21.32 | R16: 21.55 | Y16: 10.59 | Z16: 10.59 | AA16: 10.65 | AB16: 10.71
A17: 1 | C17: 유형자산 | E17: 65888.7 | F17: 65888.7 | G17: 65126.78 | H17: 64345.23 | I17: 63426.83 | J17: 62640.07 | K17: 62640.07 | L17: 62023.64 | M17: 61380.51 | N17: 60948.53 | O17: 60612.98 | P17: 60612.98 | Q17: 60327.09 | R17: 60467.22 | S17: 60619.86 | T17: 60359.02 | U17: 60359.02 | V17: 61527.22 | W17: 61696 | X17: 61720.64 | Y17: 63109.97 | Z17: 63109.97 | AA17: 62652.57 | AB17: 62113.07
A18: 1 | C18: 투자부동산 | E18: 17549.03 | F18: 17549.03 | G18: 17549.03 | H18: 17549.03 | I18: 17549.03 | J18: 17549.03 | K18: 17549.03 | L18: 17611.95 | M18: 17549.03 | N18: 19629.99 | O18: 19629.99 | P18: 19629.99 | Q18: 19629.99 | R18: 19629.99 | S18: 19645.99 | T18: 19645.99 | U18: 19645.99 | V18: 19645.99 | W18: 19645.99 | X18: 19645.99 | Y18: 18507.85 | Z18: 18507.85 | AA18: 18413.52 | AB18: 18134.29
A19: 1 | C19: 무형자산 | E19: 115.18 | F19: 115.18 | G19: 115.18 | H19: 115.18 | I19: 115.18 | J19: 115.18 | K19: 115.18 | L19: 115.18 | M19: 115.18 | N19: 115.18 | O19: 115.18 | P19: 115.18 | Q19: 115.18 | R19: 115.18 | S19: 115.18 | T19: 115.18 | U19: 115.18 | V19: 115.18 | W19: 115.18 | X19: 115.18 | Y19: 115.18 | Z19: 115.18 | AA19: 523.18 | AB19: 523.18
A20: 1 | C20: 종속기업및관계기업투자 | E20: 158519.91 | F20: 158519.91 | G20: 158519.91 | H20: 158519.91 | I20: 31760.84 | J20: 31760.84 | K20: 31760.84 | L20: 31760.84 | M20: 31760.84 | N20: 31760.84 | O20: 17044.85 | P20: 17044.85 | Q20: 16989.21 | R20: 16989.21 | S20: 16989.21 | T20: 16989.21 | U20: 16989.21 | V20: 16989.21 | W20: 16989.21 | X20: 16989.21 | Y20: 110912.38 | Z20: 110912.38 | AA20: 110912.38 | AB20: 110912.38
A21: 1 | C21: 이연법인세자산 | E21: 0 | F21: 0 | J21: 0 | K21: 0
A22: 1 | C22: 자산총계 | E22: 278752.43 | F22: 278752.43 | G22: 275859.93 | H22: 295803.36 | I22: 301299.2 | J22: 302506.96 | K22: 302506.96 | L22: 301748.97 | M22: 301304.57 | N22: 318751.05 | O22: 324616.08 | P22: 324616.08 | Q22: 347151.45 | R22: 410917.05 | S22: 393025.8 | T22: 432867.47 | U22: 432867.47 | V22: 450440.91 | W22: 438712.76 | X22: 465818.51 | Y22: 457279.51 | Z22: 457279.51 | AA22: 444545.21 | AB22: 419385.31
A23: 1 | C23: 유동부채 | E23: 99937.8 | F23: 99937.8 | G23: 94272.52 | H23: 102922.79 | I23: 102103.62 | J23: 103446.12 | K23: 103446.12 | L23: 102659.76 | M23: 100774.77 | N23: 119756.78 | O23: 120145.99 | P23: 120145.99 | Q23: 110795.22 | R23: 107665.34 | S23: 110270.74 | T23: 110910.57 | U23: 110910.57 | V23: 122707.2 | W23: 100919.11 | X23: 96826.82 | Y23: 86337.68 | Z23: 86337.68 | AA23: 75604.14 | AB23: 39830.59
A24: 1 | C24: 매입채무및기타채무 | E24: 87297.24 | F24: 87297.24 | G24: 87194.34 | H24: 98194.9 | I24: 97789.88 | J24: 98744.72 | K24: 98744.72 | L24: 98345.54 | M24: 98606.07 | N24: 117835.25 | O24: 119048.59 | P24: 119048.59 | Q24: 99973.39 | R24: 98743.38 | S24: 99686.3 | T24: 100342.3 | U24: 100342.3 | V24: 95847.43 | W24: 78641.99 | X24: 62491.52 | Y24: 7041.08 | Z24: 7041.08 | AA24: 20004.76 | AB24: 6167.87
A25: 1 | C25: 단기차입금 | E25: 81400 | F25: 81400 | G25: 81000 | H25: 86000 | I25: 86000 | J25: 86000 | K25: 86000 | L25: 86000 | M25: 86000 | N25: 91800 | O25: 91800 | P25: 91800 | Q25: 86800 | R25: 92300 | S25: 92650 | T25: 92650 | U25: 92650 | V25: 82650 | W25: 57650 | X25: 42000 | Y25: 30000 | Z25: 30000 | AA25: 30000 | AB25: 30000
A26: 1 | C26: 유동성장기부채 | E26: 67.8 | F26: 67.8 | G26: 67.8 | H26: 5591.3 | I26: 5752.22 | J26: 5913.18 | K26: 5913.18 | L26: 6070.63 | M26: 6240.28 | N26: 6404.89 | O26: 6574.85 | P26: 6574.85 | Q26: 6750.72 | R26: 0 | S26: 0 | T26: 0 | U26: 0 | W26: 14000 | X26: 14000 | Y26: 14000 | Z26: 14000 | AB26: 0
A27: 1 | C27: 당기법인세부채(미지급법인세) | E27: 12640.56 | F27: 12640.56 | G27: 7078.18 | H27: 414.15 | J27: 894.13 | K27: 894.13 | L27: 506.96 | M27: 367.4 | N27: 120.23 | O27: 0 | P27: 0 | Q27: 9724.43 | R27: 8921.96 | S27: 10584.43 | T27: 10568.27 | U27: 10568.27 | V27: 26859.77 | W27: 22277.12 | X27: 34335.3 | Y27: 34323.56 | Z27: 34323.56 | AA27: 19594.69 | AB27: 2260.97
A28: 1 | C28: 비유동부채 | E28: 2443.4 | F28: 2443.4 | G28: 2494.31 | H28: 7819.94 | I28: 8054.85 | J28: 7515.21 | K28: 7515.21 | L28: 7646.58 | M28: 7787.73 | N28: 7958.88 | O28: 8531.07 | P28: 8531.07 | Q28: 11676.95 | R28: 30719.45 | S28: 26015.72 | T28: 37355.79 | U28: 37355.79 | V28: 24252.28 | W28: 15029.9 | X28: 13181.25 | Y28: 11001.07 | Z28: 11001.07 | AA28: 11311.78 | AB28: 12948.03
A29: 1 | C29: 장기매입채무및기타채무 | E29: 341.64 | F29: 341.64 | G29: 315.67 | H29: 5781.22 | I29: 5911.67 | J29: 6087.36 | K29: 6087.36 | L29: 6211.96 | M29: 6346.36 | N29: 6510.73 | O29: 6728.42 | P29: 6728.42 | Q29: 6899.47 | R29: 14141.3 | S29: 14085.29 | T29: 14070.03 | U29: 14070.03 | V29: 14042.38 | W29: 30.9 | X29: 19.51 | Y29: 7.02 | Z29: 7.02
A30: 1 | C30: 장기차입금 | E30: 101.7 | F30: 101.7 | G30: 84.75 | H30: 67.8 | I30: 50.85 | J30: 33.9 | K30: 33.9 | L30: 16.95 | O30: 0 | P30: 0 | Q30: 0 | R30: 14000 | S30: 14000 | T30: 14000 | U30: 14000 | V30: 14000
A31: 1 | C31: 확정급여부채 | E31: 342.19 | F31: 342.19 | G31: 456.38 | H31: 254.14 | I31: 351.84 | J31: 0 | K31: 0 | O31: 50.04 | P31: 50.04 | Q31: 162.47 | R31: 0 | S31: 0 | T31: 62.38 | U31: 62.38 | V31: 188.32 | W31: 12.36 | X31: 159.84 | Y31: 139.5 | Z31: 139.5 | AA31: 288.27
A32: 1 | C32: 이연법인세부채 | E32: 1879.54 | F32: 1879.54 | G32: 1837.73 | H32: 1879.54 | I32: 1879.54 | J32: 1509.28 | K32: 1509.28 | L32: 1509.28 | M32: 1509.28 | N32: 1509.28 | O32: 1806.99 | P32: 1806.99 | Q32: 4662.62 | R32: 16618.99 | S32: 11930.43 | T32: 23223.39 | U32: 23223.39 | V32: 10021.59 | W32: 14986.64 | X32: 13001.91 | Y32: 10846.72 | Z32: 10846.72 | AA32: 11020.37 | AB32: 12948.03
A33: 1 | C33: 부채총계 | E33: 102381.19 | F33: 102381.19 | G33: 96766.83 | H33: 110742.73 | I33: 110158.47 | J33: 110961.33 | K33: 110961.33 | L33: 110306.34 | M33: 108562.5 | N33: 127715.66 | O33: 128677.05 | P33: 128677.05 | Q33: 122472.18 | R33: 138384.79 | S33: 136286.45 | T33: 148266.36 | U33: 148266.36 | V33: 146959.48 | W33: 115949.01 | X33: 110008.07 | Y33: 97338.75 | Z33: 97338.75 | AA33: 86915.92 | AB33: 52778.62
A34: 1 | C34: 자본금 | E34: 4665.85 | F34: 4665.85 | G34: 4665.85 | H34: 4665.85 | I34: 4665.85 | J34: 4665.85 | K34: 4665.85 | L34: 4665.85 | M34: 4665.85 | N34: 4665.85 | O34: 4665.85 | P34: 4665.85 | Q34: 4665.85 | R34: 4940.08 | S34: 4940.08 | T34: 4940.08 | U34: 4940.08 | V34: 4940.08 | W34: 4940.08 | X34: 4940.08 | Y34: 4940.08 | Z34: 4940.08 | AA34: 4940.08 | AB34: 4940.08
A35: 1 | C35: 보통주자본금 | E35: 4665.85 | F35: 4665.85 | G35: 4665.85 | H35: 4665.85 | I35: 4665.85 | J35: 4665.85 | K35: 4665.85 | L35: 4665.85 | M35: 4665.85 | N35: 4665.85 | O35: 4665.85 | P35: 4665.85 | Q35: 4665.85 | R35: 4940.08 | S35: 4940.08 | T35: 4940.08 | U35: 4940.08 | V35: 4940.08 | W35: 4940.08 | X35: 4940.08
A36: 1 | C36: 자본잉여금 | E36: 94556.36 | F36: 94556.36 | G36: 94556.36 | H36: 94556.36 | I36: 94556.36 | J36: 94556.36 | K36: 94556.36 | L36: 94556.36 | M36: 94556.36 | N36: 94556.36 | O36: 13998.36 | P36: 13998.36 | Q36: 13998.36 | R36: 40596.48 | S36: 40596.48 | T36: 40596.48 | U36: 40596.48 | V36: 27976.48 | W36: 27976.48 | X36: 27976.48 | Y36: 13839.98 | Z36: 13839.98 | AA36: 11050.66 | AB36: 13839.98
A37: 1 | C37: 기타자본 | E37: -4378.76 | F37: -4378.76 | G37: -296.52 | H37: -296.52 | I37: -296.52 | J37: -296.52 | K37: -296.52 | L37: -296.52 | M37: -296.52 | N37: -4449.82 | O37: -6249.78 | P37: -6249.78 | Q37: 21331.82 | R37: 94770.04 | S37: 62531.91 | T37: 116358.28 | U37: 116358.28 | V37: 42684.96 | W37: 73200.86 | X37: 84439.6 | Y37: 32296.42 | Z37: 32296.42 | AA37: 32853.57 | AB37: 39771.58
A38: 1 | C38: 이익잉여금 | E38: 126616.58 | F38: 126616.58 | G38: 127297.33 | H38: 133264.86 | I38: 139344.95 | J38: 139749.86 | K38: 139749.86 | L38: 139646.85 | M38: 140946.29 | N38: 141316.27 | O38: 187398.89 | P38: 187398.89 | Q38: 202348.33 | R38: 199908.92 | S38: 200235.06 | T38: 201183.65 | U38: 201183.65 | V38: 263210.62 | W38: 267234.99 | X38: 294662.32 | Y38: 308864.28 | Z38: 308864.28 | AA38: 308784.97 | AB38: 308055.04
A39: 1 | C39: 자본총계 | E39: 176371.23 | F39: 176371.23 | G39: 179093.11 | H39: 185060.63 | I39: 191140.72 | J39: 191545.63 | K39: 191545.63 | L39: 191442.63 | M39: 192742.06 | N39: 191035.39 | O39: 195939.03 | P39: 195939.03 | Q39: 224679.27 | R39: 272532.26 | S39: 256739.34 | T39: 284601.11 | U39: 284601.11 | V39: 303481.43 | W39: 322763.75 | X39: 355810.44 | Y39: 359940.77 | Z39: 359940.77 | AA39: 357629.29 | AB39: 366606.69
A40: 1 | C40: 부채와자본총계 | E40: 278752.43 | F40: 278752.43 | G40: 275859.93 | H40: 295803.36 | I40: 301299.2 | J40: 302506.96 | K40: 302506.96 | L40: 301748.97 | M40: 301304.57 | N40: 318751.05 | O40: 324616.08 | P40: 324616.08 | Q40: 347151.45 | R40: 410917.05 | S40: 393025.8 | T40: 432867.47 | U40: 432867.47 | V40: 450440.91 | W40: 438712.76 | X40: 465818.51 | Y40: 457279.51 | Z40: 457279.51 | AA40: 444545.21 | AB40: 419385.31
...

Sheet subQ
A1: YQ | C1: subQ 분기 서브모델(억원, U=100) | E1: 4Q21 | F1: 2021 | G1: 1Q22 | H1: 2Q22 | I1: 3Q22 | J1: 4Q22 | K1: 2022 | L1: 1Q23 | M1: 2Q23 | N1: 3Q23 | O1: 4Q23 | P1: 2023 | Q1: 1Q24 | R1: 2Q24 | S1: 3Q24 | T1: 4Q24 | U1: 2024 | V1: 1Q25 | W1: 2Q25 | X1: 3Q25 | Y1: 4Q25 | Z1: 2025 | AA1: 1Q26 | AB1: 2Q26 | AC1: 3Q26 | AD1: 4Q26 | AE1: 2026 | AF1: 1Q27 | AG1: 2Q27 | AH1: 3Q27 | AI1: 4Q27 | AJ1: 2027 | AK1: 1Q28 | AL1: 2Q28 | AM1: 3Q28 | AN1: 4Q28 | AO1: 2028
A2: A=이름(key) B=그룹 C=단위 D=FnGuide 계정명(VLOOKUP 키). 확정=VLOOKUP(BS), 추정=변수 가정 참조
E3: 1 | F3: 2 | G3: 3 | H3: 4 | I3: 5 | J3: 6 | K3: 7 | L3: 8 | M3: 9 | N3: 10 | O3: 11 | P3: 12 | Q3: 13 | R3: 14 | S3: 15 | T3: 16 | U3: 17 | V3: 18 | W3: 19 | X3: 20 | Y3: 21 | Z3: 22 | AA3: 23 | AB3: 24 | AC3: 25 | AD3: 26 | AE3: 27 | AF3: 28 | AG3: 29 | AH3: 30 | AI3: 31 | AJ3: 32 | AK3: 33 | AL3: 34 | AM3: 35 | AN3: 36 | AO3: 37
E4: 2021.12 | F4: 2021.12A | G4: 2022.03 | H4: 2022.06 | I4: 2022.09 | J4: 2022.12 | K4: 2022.12A | L4: 2023.03 | M4: 2023.06 | N4: 2023.09 | O4: 2023.12 | P4: 2023.12A | Q4: 2024.03 | R4: 2024.06 | S4: 2024.09 | T4: 2024.12 | U4: 2024.12A | V4: 2025.03 | W4: 2025.06 | X4: 2025.09 | Y4: 2025.12 | Z4: 2025.12A | AA4: 2026.03 | AB4: 2026.06 | AC4: 2026.09 | AD4: 2026.12 | AE4: 2026.12A | AF4: 2027.03 | AG4: 2027.06 | AH4: 2027.09 | AI4: 2027.12 | AJ4: 2027.12A | AK4: 2028.03 | AL4: 2028.06 | AM4: 2028.09 | AN4: 2028.12 | AO4: 2028.12A
A5: 매출액 | B5: 손익 | C5: 억원 | D5: 매출액(수익) | E5: =IFERROR(VLOOKUP($D5,BS연결,MATCH(E$1,BS연결H,0),0)/100,"") | G5: =IFERROR(VLOOKUP($D5,BS연결,MATCH(G$1,BS연결H,0),0)/100,"") | H5: =IFERROR(VLOOKUP($D5,BS연결,MATCH(H$1,BS연결H,0),0)/100,"") | I5: =IFERROR(VLOOKUP($D5,BS연결,MATCH(I$1,BS연결H,0),0)/100,"") | J5: =IFERROR(VLOOKUP($D5,BS연결,MATCH(J$1,BS연결H,0),0)/100,"") | K5: =SUM(G5:J5) | L5: =IFERROR(VLOOKUP($D5,BS연결,MATCH(L$1,BS연결H,0),0)/100,"") | M5: =IFERROR(VLOOKUP($D5,BS연결,MATCH(M$1,BS연결H,0),0)/100,"") | N5: =IFERROR(VLOOKUP($D5,BS연결,MATCH(N$1,BS연결H,0),0)/100,"") | O5: =IFERROR(VLOOKUP($D5,BS연결,MATCH(O$1,BS연결H,0),0)/100,"") | P5: =IFERROR(VLOOKUP($D5,BS연결,MATCH(P$1,BS연결H,0),0)/100,"") | Q5: =IFERROR(VLOOKUP($D5,BS연결,MATCH(Q$1,BS연결H,0),0)/100,"") | R5: =IFERROR(VLOOKUP($D5,BS연결,MATCH(R$1,BS연결H,0),0)/100,"") | S5: =IFERROR(VLOOKUP($D5,BS연결,MATCH(S$1,BS연결H,0),0)/100,"") | ... AB5: =IFERROR(VLOOKUP($D5,BS연결,MATCH(AB$1,BS연결H,0),0)/100,"") | AC5: =IFERROR(X5*(1+변수!AC21),"") | AD5: =IFERROR(Y5*(1+변수!AD21),"") | AE5: =SUM(AA5:AD5) | AF5: =IFERROR(AA5*(1+변수!AF21),"") | AG5: =IFERROR(AB5*(1+변수!AG21),"") | AH5: =IFERROR(AC5*(1+변수!AH21),"") | AI5: =IFERROR(AD5*(1+변수!AI21),"") | AJ5: =SUM(AF5:AI5) | AK5: =IFERROR(AF5*(1+변수!AK21),"") | AL5: =IFERROR(AG5*(1+변수!AL21),"") | AM5: =IFERROR(AH5*(1+변수!AM21),"") | AN5: =IFERROR(AI5*(1+변수!AN21),"") | AO5: =SUM(AK5:AN5)
A6: 매출원가 | B6: 손익 | C6: 억원 | D6: 매출원가 | E6: =IFERROR(VLOOKUP($D6,BS연결,MATCH(E$1,BS연결H,0),0)/100,"") | G6: =IFERROR(VLOOKUP($D6,BS연결,MATCH(G$1,BS연결H,0),0)/100,"") | H6: =IFERROR(VLOOKUP($D6,BS연결,MATCH(H$1,BS연결H,0),0)/100,"") | I6: =IFERROR(VLOOKUP($D6,BS연결,MATCH(I$1,BS연결H,0),0)/100,"") | J6: =IFERROR(VLOOKUP($D6,BS연결,MATCH(J$1,BS연결H,0),0)/100,"") | K6: =IFERROR(VLOOKUP($D6,BS연결,MATCH(K$1,BS연결H,0),0)/100,"") | L6: =IFERROR(VLOOKUP($D6,BS연결,MATCH(L$1,BS연결H,0),0)/100,"") | M6: =IFERROR(VLOOKUP($D6,BS연결,MATCH(M$1,BS연결H,0),0)/100,"") | N6: =IFERROR(VLOOKUP($D6,BS연결,MATCH(N$1,BS연결H,0),0)/100,"") | ... AB6: =IFERROR(VLOOKUP($D6,BS연결,MATCH(AB$1,BS연결H,0),0)/100,"") | AC6: =IFERROR(AC5-AC7,"") | AD6: =IFERROR(AD5-AD7,"") | AE6: =SUM(AA6:AD6) | AF6: =IFERROR(AF5-AF7,"") | AG6: =IFERROR(AG5-AG7,"") | AH6: =IFERROR(AH5-AH7,"") | AI6: =IFERROR(AI5-AI7,"") | AJ6: =SUM(AF6:AI6) | AK6: =IFERROR(AK5-AK7,"") | AL6: =IFERROR(AL5-AL7,"") | AM6: =IFERROR(AM5-AM7,"") | AN6: =IFERROR(AN5-AN7,"") | AO6: =SUM(AK6:AN6)
A7: 매출총이익 | B7: 손익 | C7: 억원 | D7: 매출총이익 | E7: =IFERROR(VLOOKUP($D7,BS연결,MATCH(E$1,BS연결H,0),0)/100,"") | G7: =IFERROR(VLOOKUP($D7,BS연결,MATCH(G$1,BS연결H,0),0)/100,"") | H7: =IFERROR(VLOOKUP($D7,BS연결,MATCH(H$1,BS연결H,0),0)/100,"") | I7: =IFERROR(VLOOKUP($D7,BS연결,MATCH(I$1,BS연결H,0),0)/100,"") | J7: =IFERROR(VLOOKUP($D7,BS연결,MATCH(J$1,BS연결H,0),0)/100,"") | K7: =IFERROR(VLOOKUP($D7,BS연결,MATCH(K$1,BS연결H,0),0)/100,"") | L7: =IFERROR(VLOOKUP($D7,BS연결,MATCH(L$1,BS연결H,0),0)/100,"") | M7: =IFERROR(VLOOKUP($D7,BS연결,MATCH(M$1,BS연결H,0),0)/100,"") | N7: =IFERROR(VLOOKUP($D7,BS연결,MATCH(N$1,BS연결H,0),0)/100,"") | O7: =IFERROR(VLOOKUP($D7,BS연결,MATCH(O$1,BS연결H,0),0)/100,"") | P7: =SUM(L7:O7) | Q7: =IFERROR(VLOOKUP($D7,BS연결,MATCH(Q$1,BS연결H,0),0)/100,"") | R7: =IFERROR(VLOOKUP($D7,BS연결,MATCH(R$1,BS연결H,0),0)/100,"") | S7: =IFERROR(VLOOKUP($D7,BS연결,MATCH(S$1,BS연결H,0),0)/100,"") | T7: =IFERROR(VLOOKUP($D7,BS연결,MATCH(T$1,BS연결H,0),0)/100,"") | U7: =IFERROR(VLOOKUP($D7,BS연결,MATCH(U$1,BS연결H,0),0)/100,"") | V7: =IFERROR(VLOOKUP($D7,BS연결,MATCH(V$1,BS연결H,0),0)/100,"") | W7: =IFERROR(VLOOKUP($D7,BS연결,MATCH(W$1,BS연결H,0),0)/100,"") | X7: =IFERROR(VLOOKUP($D7,BS연결,MATCH(X$1,BS연결H,0),0)/100,"") | ... AB7: =IFERROR(VLOOKUP($D7,BS연결,MATCH(AB$1,BS연결H,0),0)/100,"") | AC7: =IFERROR(AC9+AC8,"") | AD7: =IFERROR(AD9+AD8,"") | AE7: =SUM(AA7:AD7) | AF7: =IFERROR(AF9+AF8,"") | AG7: =IFERROR(AG9+AG8,"") | AH7: =IFERROR(AH9+AH8,"") | AI7: =IFERROR(AI9+AI8,"") | AJ7: =SUM(AF7:AI7) | AK7: =IFERROR(AK9+AK8,"") | AL7: =IFERROR(AL9+AL8,"") | AM7: =IFERROR(AM9+AM8,"") | AN7: =IFERROR(AN9+AN8,"") | AO7: =SUM(AK7:AN7)
A8: 판관비 | B8: 손익 | C8: 억원 | D8: 판관비 | E8: =IFERROR(VLOOKUP($D8,BS연결,MATCH(E$1,BS연결H,0),0)/100,"") | G8: =IFERROR(VLOOKUP($D8,BS연결,MATCH(G$1,BS연결H,0),0)/100,"") | H8: =IFERROR(VLOOKUP($D8,BS연결,MATCH(H$1,BS연결H,0),0)/100,"") | I8: =IFERROR(VLOOKUP($D8,BS연결,MATCH(I$1,BS연결H,0),0)/100,"") | J8: =IFERROR(VLOOKUP($D8,BS연결,MATCH(J$1,BS연결H,0),0)/100,"") | K8: =IFERROR(VLOOKUP($D8,BS연결,MATCH(K$1,BS연결H,0),0)/100,"") | L8: =IFERROR(VLOOKUP($D8,BS연결,MATCH(L$1,BS연결H,0),0)/100,"") | M8: =IFERROR(VLOOKUP($D8,BS연결,MATCH(M$1,BS연결H,0),0)/100,"") | N8: =IFERROR(VLOOKUP($D8,BS연결,MATCH(N$1,BS연결H,0),0)/100,"") | ... AB8: =IFERROR(VLOOKUP($D8,BS연결,MATCH(AB$1,BS연결H,0),0)/100,"") | AC8: =IFERROR(AC5*변수!AC22,"") | AD8: =IFERROR(AD5*변수!AD22,"") | AE8: =SUM(AA8:AD8) | AF8: =IFERROR(AF5*변수!AF22,"") | AG8: =IFERROR(AG5*변수!AG22,"") | AH8: =IFERROR(AH5*변수!AH22,"") | AI8: =IFERROR(AI5*변수!AI22,"") | AJ8: =SUM(AF8:AI8) | AK8: =IFERROR(AK5*변수!AK22,"") | AL8: =IFERROR(AL5*변수!AL22,"") | AM8: =IFERROR(AM5*변수!AM22,"") | AN8: =IFERROR(AN5*변수!AN22,"") | AO8: =SUM(AK8:AN8)
A9: 영업이익 | B9: 손익 | C9: 억원 | D9: 영업이익 | E9: =IFERROR(VLOOKUP($D9,BS연결,MATCH(E$1,BS연결H,0),0)/100,"") | G9: =IFERROR(VLOOKUP($D9,BS연결,MATCH(G$1,BS연결H,0),0)/100,"") | H9: =IFERROR(VLOOKUP($D9,BS연결,MATCH(H$1,BS연결H,0),0)/100,"") | I9: =IFERROR(VLOOKUP($D9,BS연결,MATCH(I$1,BS연결H,0),0)/100,"") | J9: =IFERROR(VLOOKUP($D9,BS연결,MATCH(J$1,BS연결H,0),0)/100,"") | K9: =IFERROR(VLOOKUP($D9,BS연결,MATCH(K$1,BS연결H,0),0)/100,"") | L9: =IFERROR(VLOOKUP($D9,BS연결,MATCH(L$1,BS연결H,0),0)/100,"") | M9: =IFERROR(VLOOKUP($D9,BS연결,MATCH(M$1,BS연결H,0),0)/100,"") | N9: =IFERROR(VLOOKUP($D9,BS연결,MATCH(N$1,BS연결H,0),0)/100,"") | ... AB9: =IFERROR(VLOOKUP($D9,BS연결,MATCH(AB$1,BS연결H,0),0)/100,"") | AC9: =IFERROR(AC5*변수!AC23,"") | AD9: =IFERROR(AD5*변수!AD23,"") | AE9: =SUM(AA9:AD9) | AF9: =IFERROR(AF5*변수!AF23,"") | AG9: =IFERROR(AG5*변수!AG23,"") | AH9: =IFERROR(AH5*변수!AH23,"") | AI9: =IFERROR(AI5*변수!AI23,"") | AJ9: =SUM(AF9:AI9) | AK9: =IFERROR(AK5*변수!AK23,"") | AL9: =IFERROR(AL5*변수!AL23,"") | AM9: =IFERROR(AM5*변수!AM23,"") | AN9: =IFERROR(AN5*변수!AN23,"") | AO9: =SUM(AK9:AN9)
A10: OPM | B10: 손익 | C10: % | D10: 영업이익률 | E10: =IFERROR(E9/E5,"") | G10: =IFERROR(G9/G5,"") | H10: =IFERROR(H9/H5,"") | I10: =IFERROR(I9/I5,"") | J10: =IFERROR(J9/J5,"") | K10: =IFERROR(K9/K5,"") | L10: =IFERROR(L9/L5,"") | M10: =IFERROR(M9/M5,"") | N10: =IFERROR(N9/N5,"") | ... AO10: =IFERROR(AO9/AO5,"")
