Workbook
Name 변수H: 변수!$C$1:$AO$1
Name 환율: 변수!$C$6:$AO$13
Name BS연결H: BS연결!$C$1:$AO$1
Name BS연결: BS연결!$C$5:$AO$93
Name BS별도H: BS별도!$C$1:$AO$1
Name BS별도: BS별도!$C$5:$AO$94
Name SUBQH: subQ!$A$1:$AO$1
Name subQ: subQ!$A$5:$AO$42

Sheet README
A1: 화인베스틸(133820) 실적 모델 — ARGUS 한국조선
A2: 기준 분기 2026Q2 · 마지막 실적 2026Q2 · 생성 2026-10-13
A3: 모든 수치는 모델 산출값(DART 공개 재무제표 + 우리 추정)이다 — 목표주가·투자 추천 아님. 참고용 · 투자조언 아님.
A5: 시트
A6: 변수 가정 시계열. 환율 8행(ECB via frankfurter — L2 fx.json; 추정 분기 = 노란 가정), 추정 드라이버(노란 셀 = 모델값에서 역산한 가정, 바꾸면 재계산; 연녹 셀 = 3절 스칼라 참조 수식), 3절 스칼라 가정(세율·판관비율·지배주주비중·이자율·종가·PER 밴드·COE·외화 순노출·헤지비율)
A7: BS연결/BS별도 FnGuide 계정명 × 기간 값 덤프(백만원). 행1 분기라벨, 행4 YYYY.MM / YYYY.12A. 이름정의 BS연결H·BS연결(계정명 C열부터)
A8: subQ 분기 서브모델(억원 = 백만원/100). 확정 행: =IFERROR(VLOOKUP($D행,BS연결,MATCH(E$1,BS연결H,0),0)/100,"") 추정 행: 변수 시트 가정 셀 참조 수식. 외환손익·파생상품손익은 BS 계정 합·차, 기타금융손익은 잔차, OPM·EPS·BPS·PER·PBR 은 파생 수식
A9: SLS 선표(조선사만, sls json 있을 때): 요약 행(sls 저장값) + 계약별 스케줄(백만$) × (헤지비율 × 헤지환율 + (1−헤지비율) × 건조시점 환율[변수 원/달러(평균)]) → 원화 수식 블록 → 합계 행이 subQ 매출조선에 연결
A10: 시나리오 신규수주 보수/기준/낙관(forecast_panel 패널, 모델에 scenarios 가 있을 때만): 매출액·영업이익 = subQ 기준값 ± (시나리오 신규 − base 신규) × OPM. base 만 subQ 행에 포함, 나머지는 합산 안 함
A11: 분기/연간예상 subQ 를 이름(A열 key)으로 VLOOKUP 한 보고서 표(억원)
A12: TP PER 밴드 × 12M fwd EPS, PBR = ROE/COE × BPS — 모델 산출값 구간, 목표주가·추천 아님
A13: 외화 환율 QoQ, 외화 순노출 × Δ기말환율 → 환관련손익 추정
... A34: 백테스트: {"freeze": "2025Q2", "horizon": 4, "revenue_wape_pct": 17.2, "op_wape_pct": 622.3, "n": 4, "note": "단일 회사 4분기 — 통계 아님", "driver_at_freeze": "customer_yard_revenue_weighted", "selection_oos_at_freeze": {"freeze": "2024Q2", "n": 4, "wape_link": 17.3, "wape_trend": 39.8, "adopted": true, "decision": "adopted"}, "frozen_inputs": "fin(연결/별도)·고객 조선사 모델·지주 자회사 모델은 2025Q2 까지의 분기만; 선표는 체결일 ≤ 2025Q2 말일 계약(원장 최신 금액·코호트 등급, 환산 없음); 잔고는 yards_cache 2025Q2; 시세·환율 forward·prices·forecast_panel 신규수주 미사용. 고객 가중치(suppliers.json 언급 비중)와 합병 체인링크는 현재 지식; 고객 연동 채택은 동결 모델 안에서도 자기 la−4분기 OOS 규칙(selection_oos_at_freeze)", "detail": [{"q": "2025Q3", "rev_pred": 393.21, "rev_act": 485.14, "op_pred": -59.92, "op_act": 0.32}, {"q": "2025Q4", "rev_pred": 427.6, "rev_act": 533.85, "op_pred": -65.16, "op_act": 21.67}, {"q": "2026Q1", "rev_pred": 424.35, "rev_act": 506.2, "op_pred": -64.67, "op_act": 13.94}, {"q": "2026Q2", "rev_pred": 424.35, "rev_act": 491.36, "op_pred": -64.67, "op_act": 12.78}]}

Sheet 변수
C1: 이름: 변수H | E1: 4Q21 | F1: 2021 | G1: 1Q22 | H1: 2Q22 | I1: 3Q22 | J1: 4Q22 | K1: 2022 | L1: 1Q23 | M1: 2Q23 | N1: 3Q23 | O1: 4Q23 | P1: 2023 | Q1: 1Q24 | R1: 2Q24 | S1: 3Q24 | T1: 4Q24 | U1: 2024 | V1: 1Q25 | W1: 2Q25 | X1: 3Q25 | Y1: 4Q25 | Z1: 2025 | AA1: 1Q26 | AB1: 2Q26 | AC1: 3Q26 | AD1: 4Q26 | AE1: 2026 | AF1: 1Q27 | AG1: 2Q27 | AH1: 3Q27 | AI1: 4Q27 | AJ1: 2027 | AK1: 1Q28 | AL1: 2Q28 | AM1: 3Q28 | AN1: 4Q28 | AO1: 2028
A2: 가정 시계열 — 노란 셀은 추정 가정(모델값에서 역산), 연녹 셀은 3절 스칼라 참조 수식. 바꾸면 subQ·분기·연간예상·TP·시나리오가 재계산됩니다.
E3: 1 | F3: 2 | G3: 3 | H3: 4 | I3: 5 | J3: 6 | K3: 7 | L3: 8 | M3: 9 | N3: 10 | O3: 11 | P3: 12 | Q3: 13 | R3: 14 | S3: 15 | T3: 16 | U3: 17 | V3: 18 | W3: 19 | X3: 20 | Y3: 21 | Z3: 22 | AA3: 23 | AB3: 24 | AC3: 25 | AD3: 26 | AE3: 27 | AF3: 28 | AG3: 29 | AH3: 30 | AI3: 31 | AJ3: 32 | AK3: 33 | AL3: 34 | AM3: 35 | AN3: 36 | AO3: 37
E4: 2021.12 | F4: 2021.12A | G4: 2022.03 | H4: 2022.06 | I4: 2022.09 | J4: 2022.12 | K4: 2022.12A | L4: 2023.03 | M4: 2023.06 | N4: 2023.09 | O4: 2023.12 | P4: 2023.12A | Q4: 2024.03 | R4: 2024.06 | S4: 2024.09 | T4: 2024.12 | U4: 2024.12A | V4: 2025.03 | W4: 2025.06 | X4: 2025.09 | Y4: 2025.12 | Z4: 2025.12A | AA4: 2026.03 | AB4: 2026.06 | AC4: 2026.09 | AD4: 2026.12 | AE4: 2026.12A | AF4: 2027.03 | AG4: 2027.06 | AH4: 2027.09 | AI4: 2027.12 | AJ4: 2027.12A | AK4: 2028.03 | AL4: 2028.06 | AM4: 2028.09 | AN4: 2028.12 | AO4: 2028.12A
B5: 1. FX | C5: 이름: 환율
A6: USDKRW_avg | C6: 원/달러(평균) | E6: 1183.5 | F6: 1145.51 | G6: 1205.78 | H6: 1262.09 | I6: 1341.93 | J6: 1360.12 | K6: 1292.98 | L6: 1276.95 | M6: 1315.69 | N6: 1313.62 | O6: 1322.01 | P6: 1306.85 | Q6: 1330.14 | R6: 1371.28 | S6: 1356.22 | T6: 1396.3 | U6: 1363.53 | V6: 1452.28 | W6: 1398.52 | X6: 1386.95 | Y6: 1449.19 | Z6: 1421.52 | AA6: 1466.12 | AB6: 1501.75 | AC6: 1418.75 | AD6: 1343.63 | AE6: 1456.58 | AF6: 1333.09 | AG6: 1333.09 | AH6: 1333.09 | AI6: 1333.09 | AK6: 1333.09 | AL6: 1333.09 | AM6: 1333.09 | AN6: 1333.09
A7: USDKRW_end | C7: 원/달러(기말) | E7: 1188.75 | F7: 1188.75 | G7: 1213.74 | H7: 1301.24 | I7: 1436.9 | J7: 1260.16 | K7: 1260.16 | L7: 1305.99 | M7: 1321.44 | N7: 1345.35 | O7: 1297.43 | P7: 1297.43 | Q7: 1349.25 | R7: 1377.73 | S7: 1312.17 | T7: 1474.78 | U7: 1474.78 | V7: 1474.54 | W7: 1355.13 | X7: 1403.67 | Y7: 1444.2 | Z7: 1444.2 | AA7: 1524.8 | AB7: 1550.89 | AC7: 1355.4 | AD7: 1333.09 | AE7: 1333.09 | AF7: 1333.09 | AG7: 1333.09 | AH7: 1333.09 | AI7: 1333.09 | AK7: 1333.09 | AL7: 1333.09 | AM7: 1333.09 | AN7: 1333.09
A8: JPY100KRW_avg | C8: 원/100Y(평균) | E8: 1041.02 | F8: 1042.74 | G8: 1036.79 | H8: 972.23 | I8: 970.61 | J8: 961.03 | K8: 985.1 | L8: 964.89 | M8: 957.36 | N8: 909 | O8: 893.22 | P8: 931.11 | Q8: 896.29 | R8: 880.14 | S8: 909.35 | T8: 917.25 | U8: 900.92 | V8: 952.59 | W8: 967.92 | X8: 940.32 | Y8: 940.77 | Z8: 950.17 | AA8: 934.39 | AB8: 942.16 | AC8: 890.41 | AD8: 849.51 | AE8: 918.81 | AF8: 840.54 | AG8: 840.54 | AH8: 840.54 | AI8: 840.54 | AK8: 840.54 | AL8: 840.54 | AM8: 840.54 | AN8: 840.54
A9: JPY100KRW_end | C9: 원/100Y(기말) | E9: 1032.62 | F9: 1032.62 | G9: 996.83 | H9: 954.9 | I9: 993.29 | J9: 955.54 | K9: 955.54 | L9: 980.62 | M9: 913.67 | N9: 901.47 | O9: 917.04 | P9: 917.04 | Q9: 892.42 | R9: 857.76 | S9: 919.21 | T9: 939.65 | U9: 939.65 | V9: 986.84 | W9: 938.85 | X9: 948.49 | Y9: 921.81 | Z9: 921.81 | AA9: 955.99 | AB9: 954.75 | AC9: 863.31 | AD9: 840.54 | AE9: 840.54 | AF9: 840.54 | AG9: 840.54 | AH9: 840.54 | AI9: 840.54 | AK9: 840.54 | AL9: 840.54 | AM9: 840.54 | AN9: 840.54
A10: EURKRW_avg | C10: W/Euro(평균) | E10: 1353.32 | F10: 1354.06 | G10: 1352.29 | H10: 1343.31 | I10: 1350.63 | J10: 1386.07 | K10: 1358.07 | L10: 1369.93 | M10: 1432.41 | N10: 1429.41 | O10: 1420.91 | P10: 1412.88 | Q10: 1444.21 | R10: 1476.42 | S10: 1489.3 | T10: 1490.78 | U10: 1475.4 | V10: 1528.33 | W10: 1585.13 | X10: 1620.04 | Y10: 1686.02 | Z10: 1605.45 | AA10: 1715.47 | AB10: 1746.09 | AC10: 1631.97 | AD10: 1507.34 | AE10: 1688.95 | AF10: 1490.54 | AG10: 1490.54 | AH10: 1490.54 | AI10: 1490.54 | AK10: 1490.54 | AL10: 1490.54 | AM10: 1490.54 | AN10: 1490.54
A11: EURKRW_end | C11: W/Euro(기말) | E11: 1346.38 | F11: 1346.38 | G11: 1347.37 | H11: 1351.6 | I11: 1400.62 | J11: 1344.08 | K11: 1344.08 | L11: 1420.26 | M11: 1435.88 | N11: 1425.26 | O11: 1433.66 | P11: 1433.66 | Q11: 1458.68 | R11: 1474.86 | S11: 1469.1 | T11: 1532.14 | U11: 1532.14 | V11: 1594.72 | W11: 1588.22 | X11: 1648.04 | Y11: 1696.94 | Z11: 1696.94 | AA11: 1753.21 | AB11: 1767.09 | AC11: 1539.06 | AD11: 1490.54 | AE11: 1490.54 | AF11: 1490.54 | AG11: 1490.54 | AH11: 1490.54 | AI11: 1490.54 | AK11: 1490.54 | AL11: 1490.54 | AM11: 1490.54 | AN11: 1490.54
A12: CNYKRW_avg | C12: 원/중국원(평균) | E12: 185.14 | F12: 177.65 | G12: 189.93 | H12: 190.76 | I12: 195.79 | J12: 191.09 | K12: 191.93 | L12: 186.59 | M12: 187.45 | N12: 181.28 | O12: 182.86 | P12: 184.52 | Q12: 185.04 | R12: 189.35 | S12: 189.24 | T12: 194.24 | U12: 189.49 | V12: 199.63 | W12: 193.41 | X12: 193.79 | Y12: 204.38 | Z12: 197.8 | AA12: 211.75 | AB12: 220.8 | AC12: 210.43 | AD12: 200.5 | AE12: 213.68 | AF12: 199.18 | AG12: 199.18 | AH12: 199.18 | AI12: 199.18 | AK12: 199.18 | AL12: 199.18 | AM12: 199.18 | AN12: 199.18
A13: CNYKRW_end | C13: 원/중국원(기말) | E13: 187.13 | F13: 187.13 | G13: 191.38 | H13: 194.13 | I13: 201.92 | J13: 182.67 | K13: 182.67 | L13: 189.97 | M13: 181.8 | N13: 184.26 | O13: 182.61 | P13: 182.61 | Q13: 186.66 | R13: 189.7 | S13: 187.12 | T13: 202.04 | U13: 202.04 | V13: 203.3 | W13: 189.14 | X13: 197.16 | Y13: 206.28 | Z13: 206.28 | AA13: 220.97 | AB13: 228.56 | AC13: 202.16 | AD13: 199.18 | AE13: 199.18 | AF13: 199.18 | AG13: 199.18 | AH13: 199.18 | AI13: 199.18 | AK13: 199.18 | AL13: 199.18 | AM13: 199.18 | AN13: 199.18
B14: 1b. 종가
A15: price_close_end | C15: 종가(기말) | E15: 3045 | G15: 3355 | H15: 2805 | I15: 2280 | J15: 2090 | L15: 1819 | M15: 2490 | N15: 1431 | O15: 1263 | Q15: 1331 | R15: 1087 | S15: 900 | T15: 916 | V15: 810 | W15: 829 | X15: 1860 | Y15: 1643 | AA15: 1217 | AB15: 1002 | AC15: 1004 | AD15: 978
A16: price_high | C16: 종가(최고) | E16: 3670 | G16: 3960 | H16: 3755 | I16: 3055 | J16: 2390 | L16: 2245 | M16: 2985 | N16: 2765 | O16: 1460 | Q16: 1557 | R16: 1483 | S16: 1149 | T16: 1201 | V16: 1300 | W16: 1029 | X16: 2950 | Y16: 2620 | AA16: 1985 | AB16: 1838 | AC16: 1219 | AD16: 1149
A17: price_low | C17: 종가(최저) | E17: 2610 | G17: 2930 | H17: 2475 | I17: 2105 | J17: 2005 | L17: 1682 | M17: 1686 | N17: 1350 | O17: 1125 | Q17: 973 | R17: 1078 | S17: 801 | T17: 831 | V17: 810 | W17: 782 | X17: 821 | Y17: 1622 | AA17: 1151 | AB17: 921 | AC17: 875 | AD17: 940
A18: price_avg | C18: 종가(평균) | E18: 3083.4 | G18: 3366.2 | H18: 3127 | I18: 2624.3 | J18: 2222.2 | L18: 2017.2 | M18: 2246 | N18: 1953.1 | O18: 1297.3 | Q18: 1144.6 | R18: 1233.4 | S18: 958.7 | T18: 968.4 | V18: 1060.7 | W18: 861.7 | X18: 1506.7 | Y18: 1930 | AA18: 1541.3 | AB18: 1302.1 | AC18: 1003.3 | AD18: 990.6
B20: 2. 추정 드라이버 | C20: 실적 열 = subQ 실현값(수식), 추정 열 = 가정(노란 = 모델값 역산, 연녹 = 3절 스칼라 참조)
A21: drv:매출액 | B21: yoy | C21: 매출액 YoY | J21: =IFERROR(subQ!J5/subQ!E5-1,"") | L21: =IFERROR(subQ!L5/subQ!G5-1,"") | M21: =IFERROR(subQ!M5/subQ!H5-1,"") | N21: =IFERROR(subQ!N5/subQ!I5-1,"") | O21: =IFERROR(subQ!O5/subQ!J5-1,"") | Q21: =IFERROR(subQ!Q5/subQ!L5-1,"") | R21: =IFERROR(subQ!R5/subQ!M5-1,"") | S21: =IFERROR(subQ!S5/subQ!N5-1,"") | T21: =IFERROR(subQ!T5/subQ!O5-1,"") | V21: =IFERROR(subQ!V5/subQ!Q5-1,"") | W21: =IFERROR(subQ!W5/subQ!R5-1,"") | X21: =IFERROR(subQ!X5/subQ!S5-1,"") | Y21: =IFERROR(subQ!Y5/subQ!T5-1,"") | AA21: =IFERROR(subQ!AA5/subQ!V5-1,"") | AB21: =IFERROR(subQ!AB5/subQ!W5-1,"") | AC21: 0.013803759 | AD21: -0.006342281 | AF21: 0.017404791 | AG21: 0.12955303 | AH21: 0.23304327 | AI21: 0.24393922 | AK21: 0.23964583 | AL21: 0.17379554 | AM21: 0.14390067 | AN21: 0.14851635
A22: drv:판관비 | B22: ratio | C22: 판관비율(/매출) | E22: =IFERROR(subQ!E8/subQ!E5,"") | F22: =IFERROR(subQ!F8/subQ!F5,"") | G22: =IFERROR(subQ!G8/subQ!G5,"") | H22: =IFERROR(subQ!H8/subQ!H5,"") | I22: =IFERROR(subQ!I8/subQ!I5,"") | J22: =IFERROR(subQ!J8/subQ!J5,"") | K22: =IFERROR(subQ!K8/subQ!K5,"") | L22: =IFERROR(subQ!L8/subQ!L5,"") | ... AB22: =IFERROR(subQ!AB8/subQ!AB5,"") | AC22: =$D$50 | AD22: =$D$50 | AE22: =IFERROR(subQ!AE8/subQ!AE5,"") | AF22: =$D$50 | AG22: =$D$50 | AH22: =$D$50 | AI22: =$D$50 | AJ22: =IFERROR(subQ!AJ8/subQ!AJ5,"") | AK22: =$D$50 | AL22: =$D$50 | AM22: =$D$50 | AN22: =$D$50 | AO22: =IFERROR(subQ!AO8/subQ!AO5,"")
A23: drv:영업이익 | B23: ratio | C23: 영업이익률(OPM) | E23: =IFERROR(subQ!E9/subQ!E5,"") | F23: =IFERROR(subQ!F9/subQ!F5,"") | G23: =IFERROR(subQ!G9/subQ!G5,"") | H23: =IFERROR(subQ!H9/subQ!H5,"") | I23: =IFERROR(subQ!I9/subQ!I5,"") | J23: =IFERROR(subQ!J9/subQ!J5,"") | K23: =IFERROR(subQ!K9/subQ!K5,"") | L23: =IFERROR(subQ!L9/subQ!L5,"") | ... AB23: =IFERROR(subQ!AB9/subQ!AB5,"") | AC23: 0.013337671 | AD23: 0.013328055 | AE23: =IFERROR(subQ!AE9/subQ!AE5,"") | AF23: 0.013339547 | AG23: 0.013332853 | AH23: 0.013339709 | AI23: 0.013336162 | AJ23: =IFERROR(subQ!AJ9/subQ!AJ5,"") | AK23: 0.013329574 | AL23: 0.013338859 | AM23: 0.013333718 | AN23: 0.013340195 | AO23: =IFERROR(subQ!AO9/subQ!AO5,"")
A24: drv:파생상품손익 | B24: abs | C24: 파생상품손익 (가정, 억원) | E24: =subQ!E13 | F24: =subQ!F13 | G24: =subQ!G13 | H24: =subQ!H13 | I24: =subQ!I13 | J24: =subQ!J13 | K24: =subQ!K13 | L24: =subQ!L13 | ... AB24: =subQ!AB13 | AC24: 0 | AD24: 0 | AE24: =subQ!AE13 | AF24: 0 | AG24: 0 | AH24: 0 | AI24: 0 | AJ24: =subQ!AJ13 | AK24: 0 | AL24: 0 | AM24: 0 | AN24: 0 | AO24: =subQ!AO13
A25: drv:기타영업외손익 | B25: abs | C25: 기타영업외손익 (가정, 억원) | E25: =subQ!E14 | F25: =subQ!F14 | G25: =subQ!G14 | H25: =subQ!H14 | I25: =subQ!I14 | J25: =subQ!J14 | K25: =subQ!K14 | L25: =subQ!L14 | ... AB25: =subQ!AB14 | AC25: 0 | AD25: 0 | AE25: =subQ!AE14 | AF25: 0 | AG25: 0 | AH25: 0 | AI25: 0 | AJ25: =subQ!AJ14 | AK25: 0 | AL25: 0 | AM25: 0 | AN25: 0 | AO25: =subQ!AO14
A26: drv:법인세비용 | B26: tax | C26: 법인세율(/세전) — 법인세 = MAX(세전,0) × 세율 | E26: =IFERROR(subQ!E16/subQ!E15,"") | F26: =IFERROR(subQ!F16/subQ!F15,"") | G26: =IFERROR(subQ!G16/subQ!G15,"") | H26: =IFERROR(subQ!H16/subQ!H15,"") | I26: =IFERROR(subQ!I16/subQ!I15,"") | J26: =IFERROR(subQ!J16/subQ!J15,"") | K26: =IFERROR(subQ!K16/subQ!K15,"") | L26: =IFERROR(subQ!L16/subQ!L15,"") | ... AB26: =IFERROR(subQ!AB16/subQ!AB15,"") | AC26: =$D$49 | AD26: =$D$49 | AE26: =IFERROR(subQ!AE16/subQ!AE15,"") | AF26: =$D$49 | AG26: =$D$49 | AH26: =$D$49 | AI26: =$D$49 | AJ26: =IFERROR(subQ!AJ16/subQ!AJ15,"") | AK26: =$D$49 | AL26: =$D$49 | AM26: =$D$49 | AN26: =$D$49 | AO26: =IFERROR(subQ!AO16/subQ!AO15,"")
A27: drv:지배주주순이익 | B27: ratio | C27: 지배주주 비중(/당기순이익) | E27: =IFERROR(subQ!E18/subQ!E17,"") | F27: =IFERROR(subQ!F18/subQ!F17,"") | G27: =IFERROR(subQ!G18/subQ!G17,"") | H27: =IFERROR(subQ!H18/subQ!H17,"") | I27: =IFERROR(subQ!I18/subQ!I17,"") | J27: =IFERROR(subQ!J18/subQ!J17,"") | K27: =IFERROR(subQ!K18/subQ!K17,"") | L27: =IFERROR(subQ!L18/subQ!L17,"") | ... AB27: =IFERROR(subQ!AB18/subQ!AB17,"") | AC27: =$D$51 | AD27: =$D$51 | AE27: =IFERROR(subQ!AE18/subQ!AE17,"") | AF27: =$D$51 | AG27: =$D$51 | AH27: =$D$51 | AI27: =$D$51 | AJ27: =IFERROR(subQ!AJ18/subQ!AJ17,"") | AK27: =$D$51 | AL27: =$D$51 | AM27: =$D$51 | AN27: =$D$51 | AO27: =IFERROR(subQ!AO18/subQ!AO17,"")
A28: drv:감가상각비 | B28: abs | C28: 감가상각비 (가정, 억원) | E28: =subQ!E19 | F28: =subQ!F19 | G28: =subQ!G19 | H28: =subQ!H19 | I28: =subQ!I19 | J28: =subQ!J19 | K28: =subQ!K19 | L28: =subQ!L19 | ... AB28: =subQ!AB19 | AC28: 19.84 | AD28: 19.84 | AE28: =subQ!AE19 | AF28: 19.84 | AG28: 19.84 | AH28: 19.84 | AI28: 19.84 | AJ28: =subQ!AJ19 | AK28: 19.84 | AL28: 19.84 | AM28: 19.84 | AN28: 19.84 | AO28: =subQ!AO19
A29: drv:부채총계 | B29: qoq | C29: 부채총계 QoQ | G29: =IFERROR(subQ!G22/subQ!E22-1,"") | H29: =IFERROR(subQ!H22/subQ!G22-1,"") | I29: =IFERROR(subQ!I22/subQ!H22-1,"") | J29: =IFERROR(subQ!J22/subQ!I22-1,"") | L29: =IFERROR(subQ!L22/subQ!J22-1,"") | M29: =IFERROR(subQ!M22/subQ!L22-1,"") | N29: =IFERROR(subQ!N22/subQ!M22-1,"") | O29: =IFERROR(subQ!O22/subQ!N22-1,"") | Q29: =IFERROR(subQ!Q22/subQ!O22-1,"") | R29: =IFERROR(subQ!R22/subQ!Q22-1,"") | S29: =IFERROR(subQ!S22/subQ!R22-1,"") | T29: =IFERROR(subQ!T22/subQ!S22-1,"") | V29: =IFERROR(subQ!V22/subQ!T22-1,"") | W29: =IFERROR(subQ!W22/subQ!V22-1,"") | X29: =IFERROR(subQ!X22/subQ!W22-1,"") | Y29: =IFERROR(subQ!Y22/subQ!X22-1,"") | AA29: =IFERROR(subQ!AA22/subQ!Y22-1,"") | AB29: =IFERROR(subQ!AB22/subQ!AA22-1,"") | AC29: 2.695e-06 | AD29: 0 | AF29: 0 | AG29: 0 | AH29: 0 | AI29: 0 | AK29: 0 | AL29: 0 | AM29: 0 | AN29: 0
A30: drv:자본총계 | B30: roll | C30: 자본총계 기타변동(배당 등, 억원) | G30: =IFERROR(subQ!E23+subQ!G17-subQ!G23,"") | H30: =IFERROR(subQ!G23+subQ!H17-subQ!H23,"") | I30: =IFERROR(subQ!H23+subQ!I17-subQ!I23,"") | J30: =IFERROR(subQ!I23+subQ!J17-subQ!J23,"") | L30: =IFERROR(subQ!J23+subQ!L17-subQ!L23,"") | M30: =IFERROR(subQ!L23+subQ!M17-subQ!M23,"") | N30: =IFERROR(subQ!M23+subQ!N17-subQ!N23,"") | O30: =IFERROR(subQ!N23+subQ!O17-subQ!O23,"") | Q30: =IFERROR(subQ!O23+subQ!Q17-subQ!Q23,"") | R30: =IFERROR(subQ!Q23+subQ!R17-subQ!R23,"") | S30: =IFERROR(subQ!R23+subQ!S17-subQ!S23,"") | T30: =IFERROR(subQ!S23+subQ!T17-subQ!T23,"") | V30: =IFERROR(subQ!T23+subQ!V17-subQ!V23,"") | W30: =IFERROR(subQ!V23+subQ!W17-subQ!W23,"") | X30: =IFERROR(subQ!W23+subQ!X17-subQ!X23,"") | Y30: =IFERROR(subQ!X23+subQ!Y17-subQ!Y23,"") | AA30: =IFERROR(subQ!Y23+subQ!AA17-subQ!AA23,"") | AB30: =IFERROR(subQ!AA23+subQ!AB17-subQ!AB23,"") | AC30: 0.000410135 | AD30: -0.005496367 | AF30: 0.001310473 | AG30: -0.002655976 | AH30: -0.001780722 | AI30: -0.005210326 | AK30: 0.001659531 | AL30: -0.005004481 | AM30: -0.005319091 | AN30: 0.008387026
A31: drv:지배주주지분 | B31: roll | C31: 지배주주지분 기타변동(배당 등, 억원) | G31: =IFERROR(subQ!E24+subQ!G18-subQ!G24,"") | H31: =IFERROR(subQ!G24+subQ!H18-subQ!H24,"") | I31: =IFERROR(subQ!H24+subQ!I18-subQ!I24,"") | J31: =IFERROR(subQ!I24+subQ!J18-subQ!J24,"") | L31: =IFERROR(subQ!J24+subQ!L18-subQ!L24,"") | M31: =IFERROR(subQ!L24+subQ!M18-subQ!M24,"") | N31: =IFERROR(subQ!M24+subQ!N18-subQ!N24,"") | O31: =IFERROR(subQ!N24+subQ!O18-subQ!O24,"") | Q31: =IFERROR(subQ!O24+subQ!Q18-subQ!Q24,"") | R31: =IFERROR(subQ!Q24+subQ!R18-subQ!R24,"") | S31: =IFERROR(subQ!R24+subQ!S18-subQ!S24,"") | T31: =IFERROR(subQ!S24+subQ!T18-subQ!T24,"") | V31: =IFERROR(subQ!T24+subQ!V18-subQ!V24,"") | W31: =IFERROR(subQ!V24+subQ!W18-subQ!W24,"") | X31: =IFERROR(subQ!W24+subQ!X18-subQ!X24,"") | Y31: =IFERROR(subQ!X24+subQ!Y18-subQ!Y24,"") | AA31: =IFERROR(subQ!Y24+subQ!AA18-subQ!AA24,"") | AB31: =IFERROR(subQ!AA24+subQ!AB18-subQ!AB24,"") | AC31: 0.000910135 | AD31: -0.005496367 | AF31: 0.001310473 | AG31: -0.002655976 | AH31: -0.001780722 | AI31: -0.005210326 | AK31: 0.001659531 | AL31: -0.005004481 | AM31: -0.005319091 | AN31: 0.008387026
A32: drv:총차입금 | B32: qoq | C32: 총차입금 QoQ | G32: =IFERROR(subQ!G25/subQ!E25-1,"") | H32: =IFERROR(subQ!H25/subQ!G25-1,"") | I32: =IFERROR(subQ!I25/subQ!H25-1,"") | J32: =IFERROR(subQ!J25/subQ!I25-1,"") | L32: =IFERROR(subQ!L25/subQ!J25-1,"") | M32: =IFERROR(subQ!M25/subQ!L25-1,"") | N32: =IFERROR(subQ!N25/subQ!M25-1,"") | O32: =IFERROR(subQ!O25/subQ!N25-1,"") | Q32: =IFERROR(subQ!Q25/subQ!O25-1,"") | R32: =IFERROR(subQ!R25/subQ!Q25-1,"") | S32: =IFERROR(subQ!S25/subQ!R25-1,"") | T32: =IFERROR(subQ!T25/subQ!S25-1,"") | V32: =IFERROR(subQ!V25/subQ!T25-1,"") | W32: =IFERROR(subQ!W25/subQ!V25-1,"") | X32: =IFERROR(subQ!X25/subQ!W25-1,"") | Y32: =IFERROR(subQ!Y25/subQ!X25-1,"") | AA32: =IFERROR(subQ!AA25/subQ!Y25-1,"") | AB32: =IFERROR(subQ!AB25/subQ!AA25-1,"") | AC32: 1.774e-06 | AD32: 0 | AF32: 0 | AG32: 0 | AH32: 0 | AI32: 0 | AK32: 0 | AL32: 0 | AM32: 0 | AN32: 0
A33: drv:순차입금 | B33: qoq | C33: 순차입금 QoQ | G33: =IFERROR(subQ!G26/subQ!E26-1,"") | H33: =IFERROR(subQ!H26/subQ!G26-1,"") | I33: =IFERROR(subQ!I26/subQ!H26-1,"") | J33: =IFERROR(subQ!J26/subQ!I26-1,"") | L33: =IFERROR(subQ!L26/subQ!J26-1,"") | M33: =IFERROR(subQ!M26/subQ!L26-1,"") | N33: =IFERROR(subQ!N26/subQ!M26-1,"") | O33: =IFERROR(subQ!O26/subQ!N26-1,"") | Q33: =IFERROR(subQ!Q26/subQ!O26-1,"") | R33: =IFERROR(subQ!R26/subQ!Q26-1,"") | S33: =IFERROR(subQ!S26/subQ!R26-1,"") | T33: =IFERROR(subQ!T26/subQ!S26-1,"") | V33: =IFERROR(subQ!V26/subQ!T26-1,"") | W33: =IFERROR(subQ!W26/subQ!V26-1,"") | X33: =IFERROR(subQ!X26/subQ!W26-1,"") | Y33: =IFERROR(subQ!Y26/subQ!X26-1,"") | AA33: =IFERROR(subQ!AA26/subQ!Y26-1,"") | AB33: =IFERROR(subQ!AB26/subQ!AA26-1,"") | AC33: -0.017075663 | AD33: -0.017830609 | AF33: -0.017977023 | AG33: -0.018799572 | AH33: -0.019834407 | AI33: -0.020924063 | AK33: -0.021090035 | AL33: -0.021727209 | AM33: -0.022810389 | AN33: -0.024244328
A34: drv:이자발생자산 | B34: qoq | C34: 이자발생자산 QoQ | G34: =IFERROR(subQ!G27/subQ!E27-1,"") | H34: =IFERROR(subQ!H27/subQ!G27-1,"") | I34: =IFERROR(subQ!I27/subQ!H27-1,"") | J34: =IFERROR(subQ!J27/subQ!I27-1,"") | L34: =IFERROR(subQ!L27/subQ!J27-1,"") | M34: =IFERROR(subQ!M27/subQ!L27-1,"") | N34: =IFERROR(subQ!N27/subQ!M27-1,"") | O34: =IFERROR(subQ!O27/subQ!N27-1,"") | Q34: =IFERROR(subQ!Q27/subQ!O27-1,"") | R34: =IFERROR(subQ!R27/subQ!Q27-1,"") | S34: =IFERROR(subQ!S27/subQ!R27-1,"") | T34: =IFERROR(subQ!T27/subQ!S27-1,"") | V34: =IFERROR(subQ!V27/subQ!T27-1,"") | W34: =IFERROR(subQ!W27/subQ!V27-1,"") | X34: =IFERROR(subQ!X27/subQ!W27-1,"") | Y34: =IFERROR(subQ!Y27/subQ!X27-1,"") | AA34: =IFERROR(subQ!AA27/subQ!Y27-1,"") | AB34: =IFERROR(subQ!AB27/subQ!AA27-1,"") | AC34: 0.090500077 | AD34: 0.085177175 | AF34: 0.077724973 | AG34: 0.074063537 | AH34: 0.071384425 | AI34: 0.068894474 | AK34: 0.063605875 | AL34: 0.060309521 | AM34: 0.058417365 | AN34: 0.057324635
A35: drv:현금및현금성자산 | B35: qoq | C35: 현금및현금성자산 QoQ | G35: =IFERROR(subQ!G28/subQ!E28-1,"") | H35: =IFERROR(subQ!H28/subQ!G28-1,"") | I35: =IFERROR(subQ!I28/subQ!H28-1,"") | J35: =IFERROR(subQ!J28/subQ!I28-1,"") | L35: =IFERROR(subQ!L28/subQ!J28-1,"") | M35: =IFERROR(subQ!M28/subQ!L28-1,"") | N35: =IFERROR(subQ!N28/subQ!M28-1,"") | O35: =IFERROR(subQ!O28/subQ!N28-1,"") | Q35: =IFERROR(subQ!Q28/subQ!O28-1,"") | R35: =IFERROR(subQ!R28/subQ!Q28-1,"") | S35: =IFERROR(subQ!S28/subQ!R28-1,"") | T35: =IFERROR(subQ!T28/subQ!S28-1,"") | V35: =IFERROR(subQ!V28/subQ!T28-1,"") | W35: =IFERROR(subQ!W28/subQ!V28-1,"") | X35: =IFERROR(subQ!X28/subQ!W28-1,"") | Y35: =IFERROR(subQ!Y28/subQ!X28-1,"") | AA35: =IFERROR(subQ!AA28/subQ!Y28-1,"") | AB35: =IFERROR(subQ!AB28/subQ!AA28-1,"")
A36: drv:CAPEX | B36: yoy | C36: CAPEX YoY | J36: =IFERROR(subQ!J29/subQ!E29-1,"") | L36: =IFERROR(subQ!L29/subQ!G29-1,"") | M36: =IFERROR(subQ!M29/subQ!H29-1,"") | N36: =IFERROR(subQ!N29/subQ!I29-1,"") | O36: =IFERROR(subQ!O29/subQ!J29-1,"") | Q36: =IFERROR(subQ!Q29/subQ!L29-1,"") | R36: =IFERROR(subQ!R29/subQ!M29-1,"") | S36: =IFERROR(subQ!S29/subQ!N29-1,"") | T36: =IFERROR(subQ!T29/subQ!O29-1,"") | V36: =IFERROR(subQ!V29/subQ!Q29-1,"") | W36: =IFERROR(subQ!W29/subQ!R29-1,"") | X36: =IFERROR(subQ!X29/subQ!S29-1,"") | Y36: =IFERROR(subQ!Y29/subQ!T29-1,"") | AA36: =IFERROR(subQ!AA29/subQ!V29-1,"") | AB36: =IFERROR(subQ!AB29/subQ!W29-1,"") | AC36: 0.36139455 | AD36: -0.20983526 | AF36: 2.0630025 | AG36: -0.7805048 | AH36: 0 | AI36: 0 | AK36: 0 | AL36: 0 | AM36: 0 | AN36: 0
A37: drv:영업활동현금흐름 | B37: yoy | C37: 영업활동현금흐름 YoY | J37: =IFERROR(subQ!J30/subQ!E30-1,"") | L37: =IFERROR(subQ!L30/subQ!G30-1,"") | M37: =IFERROR(subQ!M30/subQ!H30-1,"") | N37: =IFERROR(subQ!N30/subQ!I30-1,"") | O37: =IFERROR(subQ!O30/subQ!J30-1,"") | Q37: =IFERROR(subQ!Q30/subQ!L30-1,"") | R37: =IFERROR(subQ!R30/subQ!M30-1,"") | S37: =IFERROR(subQ!S30/subQ!N30-1,"") | T37: =IFERROR(subQ!T30/subQ!O30-1,"") | V37: =IFERROR(subQ!V30/subQ!Q30-1,"") | W37: =IFERROR(subQ!W30/subQ!R30-1,"") | X37: =IFERROR(subQ!X30/subQ!S30-1,"") | Y37: =IFERROR(subQ!Y30/subQ!T30-1,"") | AA37: =IFERROR(subQ!AA30/subQ!V30-1,"") | AB37: =IFERROR(subQ!AB30/subQ!W30-1,"")
A38: drv:주식수 | B38: qoq | C38: 주식수 QoQ | G38: =IFERROR(subQ!G31/subQ!E31-1,"") | H38: =IFERROR(subQ!H31/subQ!G31-1,"") | I38: =IFERROR(subQ!I31/subQ!H31-1,"") | J38: =IFERROR(subQ!J31/subQ!I31-1,"") | L38: =IFERROR(subQ!L31/subQ!J31-1,"") | M38: =IFERROR(subQ!M31/subQ!L31-1,"") | N38: =IFERROR(subQ!N31/subQ!M31-1,"") | O38: =IFERROR(subQ!O31/subQ!N31-1,"") | Q38: =IFERROR(subQ!Q31/subQ!O31-1,"") | R38: =IFERROR(subQ!R31/subQ!Q31-1,"") | S38: =IFERROR(subQ!S31/subQ!R31-1,"") | T38: =IFERROR(subQ!T31/subQ!S31-1,"") | V38: =IFERROR(subQ!V31/subQ!T31-1,"") | W38: =IFERROR(subQ!W31/subQ!V31-1,"") | X38: =IFERROR(subQ!X31/subQ!W31-1,"") | Y38: =IFERROR(subQ!Y31/subQ!X31-1,"") | AA38: =IFERROR(subQ!AA31/subQ!Y31-1,"") | AB38: =IFERROR(subQ!AB31/subQ!AA31-1,"") | AC38: 0 | AD38: 0 | AF38: 0 | AG38: 0 | AH38: 0 | AI38: 0 | AK38: 0 | AL38: 0 | AM38: 0 | AN38: 0
A39: drv:DPS | B39: abs | C39: DPS (가정, 원) | E39: =subQ!E34 | F39: =subQ!F34 | G39: =subQ!G34 | H39: =subQ!H34 | I39: =subQ!I34 | J39: =subQ!J34 | K39: =subQ!K34 | L39: =subQ!L34 | ... AB39: =subQ!AB34 | AD39: 0 | AE39: =subQ!AE34 | AI39: 0 | AJ39: =subQ!AJ34 | AN39: 0 | AO39: =subQ!AO34
B41: 3. 밸류에이션·스칼라 | C41: 노란 셀 = 가정. '연결' 표시는 추정 전 분기 수식이 이 셀을 참조한다는 뜻
A42: sc:종가 | C42: 종가 | D42: 978 | E42: 원 — 네이버 정규장 종가(aik 확정종가 대조 · aik 1,000원)
...

Sheet BS연결
B1: (백만원) | C1: 이름: BS연결H | E1: 4Q21 | F1: 2021 | G1: 1Q22 | H1: 2Q22 | I1: 3Q22 | J1: 4Q22 | K1: 2022 | L1: 1Q23 | M1: 2Q23 | N1: 3Q23 | O1: 4Q23 | P1: 2023 | Q1: 1Q24 | R1: 2Q24 | S1: 3Q24 | T1: 4Q24 | U1: 2024 | V1: 1Q25 | W1: 2Q25 | X1: 3Q25 | Y1: 4Q25 | Z1: 2025 | AA1: 1Q26 | AB1: 2Q26 | AC1: 3Q26 | AD1: 4Q26 | AE1: 2026 | AF1: 1Q27 | AG1: 2Q27 | AH1: 3Q27 | AI1: 4Q27 | AJ1: 2027 | AK1: 1Q28 | AL1: 2Q28 | AM1: 3Q28 | AN1: 4Q28 | AO1: 2028
B2: 연결 | D2: fin json(kship_fin.py)
B3: 화인베스틸(연) | C3: UPDATE: 26-10-13 | E3: 1 | F3: 2 | G3: 3 | H3: 4 | I3: 5 | J3: 6 | K3: 7 | L3: 8 | M3: 9 | N3: 10 | O3: 11 | P3: 12 | Q3: 13 | R3: 14 | S3: 15 | T3: 16 | U3: 17 | V3: 18 | W3: 19 | X3: 20 | Y3: 21 | Z3: 22 | AA3: 23 | AB3: 24 | AC3: 25 | AD3: 26 | AE3: 27 | AF3: 28 | AG3: 29 | AH3: 30 | AI3: 31 | AJ3: 32 | AK3: 33 | AL3: 34 | AM3: 35 | AN3: 36 | AO3: 37
B4: Account Code | C4: AccountNAME | E4: 2021.12 | F4: 2021.12A | G4: 2022.03 | H4: 2022.06 | I4: 2022.09 | J4: 2022.12 | K4: 2022.12A | L4: 2023.03 | M4: 2023.06 | N4: 2023.09 | O4: 2023.12 | P4: 2023.12A | Q4: 2024.03 | R4: 2024.06 | S4: 2024.09 | T4: 2024.12 | U4: 2024.12A | V4: 2025.03 | W4: 2025.06 | X4: 2025.09 | Y4: 2025.12 | Z4: 2025.12A | AA4: 2026.03 | AB4: 2026.06 | AC4: 2026.09 | AD4: 2026.12 | AE4: 2026.12A | AF4: 2027.03 | AG4: 2027.06 | AH4: 2027.09 | AI4: 2027.12 | AJ4: 2027.12A | AK4: 2028.03 | AL4: 2028.06 | AM4: 2028.09 | AN4: 2028.12 | AO4: 2028.12A
A5: 1 | C5: 유동자산 | N5: 80500.2 | O5: 72783.2 | P5: 72783.2 | Q5: 65031.36 | R5: 64331.43 | S5: 49508.5 | T5: 43473.53 | U5: 43473.53 | V5: 49010.07 | W5: 47356.74 | X5: 69246.15 | Y5: 62163.93 | Z5: 62163.93 | AA5: 67737.44 | AB5: 90132.46
A6: 1 | C6: 현금및현금성자산 | N6: 8451.55 | O6: 3529.8 | P6: 3529.8 | Q6: 5395.63 | R6: 7659.37 | S6: 3611 | T6: 6099.74 | U6: 6099.74 | V6: 5079.65 | W6: 5452.05 | X6: 13091.42 | Y6: 7855.11 | Z6: 7855.11 | AA6: 2499.51 | AB6: 12097.22
A7: 1 | C7: 단기금융상품 | N7: 1481.14 | O7: 1882.03 | P7: 1882.03 | Q7: 2492.16 | R7: 2482.89 | S7: 2249.52 | T7: 1.9 | U7: 1.9 | V7: 1.9 | W7: 1.91 | X7: 1.91 | Y7: 194.15 | Z7: 194.15 | AA7: 277.82 | AB7: 1705.08
A8: 1 | C8: 단기금융자산 | N8: 1481.14 | O8: 1882.03 | P8: 1882.03 | Q8: 2492.16 | R8: 2482.89 | S8: 2249.52 | T8: 1.9 | U8: 1.9 | V8: 1.9 | W8: 1.91 | X8: 1.91 | Y8: 194.15 | Z8: 194.15 | AA8: 277.82 | AB8: 1705.08
A9: 1 | C9: 매출채권및기타채권 | N9: 32090 | O9: 32239.63 | P9: 32239.63 | Q9: 25706.86 | R9: 29650.85 | S9: 18103.16 | T9: 19614.94 | U9: 19614.94 | V9: 21841.42 | W9: 20397.82 | X9: 26696.39 | Y9: 20184.13 | Z9: 20184.13 | AA9: 21495.12 | AB9: 27862.2
A10: 1 | C10: 당기법인세자산(선급법인세) | N10: 0.91 | O10: 2.51 | P10: 2.51 | Q10: 17.17 | R10: 26.62 | S10: 34.05 | T10: 36.2 | U10: 36.2 | V10: 59.78 | W10: 26.93 | X10: 27.82 | Y10: 25.63 | Z10: 25.63 | AA10: 25.84 | AB10: 3.03
A11: 1 | C11: 재고자산 | N11: 34597.77 | O11: 32576.48 | P11: 32576.48 | Q11: 28935.28 | R11: 24303.7 | S11: 24988.01 | T11: 16715 | U11: 16715 | V11: 21863.63 | W11: 18734.09 | X11: 28953.2 | Y11: 32098.86 | Z11: 32098.86 | AA11: 34655.61 | AB11: 48349.61
A12: 1 | C12: 기타유동금융자산 | N12: 1496.28
A13: 1 | C13: 기타유동자산 | N13: 2382.56 | O13: 2215.96 | P13: 2215.96 | Q13: 2147.49 | R13: 85.07 | S13: 400.81 | T13: 976.3 | U13: 976.3 | V13: 134.22 | W13: 2743.95 | X13: 475.39 | Y13: 1806.06 | Z13: 1806.06 | AA13: 8783.54 | AB13: 115.32
A14: 1 | C14: 비유동자산 | N14: 110568.15 | O14: 117512.76 | P14: 117512.76 | Q14: 114140.93 | R14: 112704.4 | S14: 112124.81 | T14: 108899.31 | U14: 108899.31 | V14: 106872.1 | W14: 102447.53 | X14: 115492.63 | Y14: 109453.55 | Z14: 109453.55 | AA14: 106646.68 | AB14: 109737.78
A15: 1 | C15: 장기금융자산 | N15: 228.65 | O15: 5110.56 | P15: 5110.56 | Q15: 2923.03 | R15: 4844.58 | S15: 5585.4 | T15: 5030.98 | U15: 5030.98 | V15: 4899.68 | W15: 4825.79 | X15: 6495.54 | Y15: 3116.31 | Z15: 3116.31 | AA15: 2257.74 | AB15: 2734.15
A16: 1 | C16: 투자자산 | N16: 228.65 | O16: 5110.56 | P16: 5110.56 | Q16: 2923.03 | R16: 4844.58 | S16: 5585.4 | T16: 5030.98 | U16: 5030.98 | V16: 4899.68 | W16: 4825.79 | X16: 6495.54 | Y16: 3116.31 | Z16: 3116.31 | AA16: 2257.74 | AB16: 2734.15
A17: 1 | C17: 장기매출채권및기타채권 | N17: 1154.78 | O17: 1063.32 | P17: 1063.32 | Q17: 1272.29 | R17: 1297.12 | S17: 1070.17 | T17: 541.73 | U17: 541.73 | V17: 502.06 | W17: 393.12 | X17: 451.12 | Y17: 507.2 | Z17: 507.2 | AA17: 243.25 | AB17: 228.25
A18: 1 | C18: 유형자산 | N18: 84925.63 | O18: 83235.47 | P18: 83235.47 | Q18: 81890.95 | R18: 80146.78 | S18: 78976.96 | T18: 77558.31 | U18: 77558.31 | V18: 75717.07 | W18: 74111.35 | X18: 90267.04 | Y18: 89708.07 | Z18: 89708.07 | AA18: 88224.57 | AB18: 91055.1
A19: 1 | C19: 투자부동산 | N19: 9149.02 | O19: 11492.49 | P19: 11492.49 | Q19: 11465.98 | R19: 11439.47 | S19: 11412.96 | T19: 11386.44 | U19: 11386.44 | V19: 11359.93 | W19: 11333.42 | X19: 8645.94 | Y19: 8619.46 | Z19: 8619.46 | AA19: 8592.95 | AB19: 7153.85
A20: 1 | C20: 무형자산 | N20: 11825.4 | O20: 12572.58 | P20: 12572.58 | Q20: 12399.65 | R20: 12226.71 | S20: 12053.77 | T20: 10127.56 | U20: 10127.56 | V20: 9981.69 | W20: 9807.35 | X20: 9632.99 | Y20: 7502.53 | Z20: 7502.53 | AA20: 7328.19 | AB20: 8566.44
A21: 1 | C21: 이연법인세자산 | N21: 3284.67 | O21: 4038.33 | P21: 4038.33 | Q21: 4189.02 | R21: 2749.74 | S21: 3025.55 | T21: 4254.28 | U21: 4254.28 | V21: 4411.67 | W21: 1976.5
A22: 1 | C22: 자산총계 | N22: 191068.35 | O22: 190295.96 | P22: 190295.96 | Q22: 179172.29 | R22: 177035.83 | S22: 161633.31 | T22: 152372.84 | U22: 152372.84 | V22: 155882.17 | W22: 149804.27 | X22: 184738.77 | Y22: 171617.47 | Z22: 171617.47 | AA22: 174384.12 | AB22: 199870.23
A23: 1 | C23: 유동부채 | N23: 94862.88 | O23: 119570.95 | P23: 119570.95 | Q23: 115069.1 | R23: 115775.1 | S23: 107417.35 | T23: 111705.16 | U23: 111705.16 | V23: 122013.56 | W23: 111044.2 | X23: 123539.14 | Y23: 106919.48 | Z23: 106919.48 | AA23: 110973.12 | AB23: 113539.58
A24: 1 | C24: 매입채무및기타채무 | N24: 92871.75 | O24: 19440.14 | P24: 19440.14 | Q24: 12959.28 | R24: 23456.22 | S24: 14261.42 | T24: 16319.29 | U24: 16319.29 | V24: 25902.6 | W24: 22774.71 | X24: 36613.25 | Y24: 25077.03 | Z24: 25077.03 | AA24: 32337.41 | AB24: 38240.86
A25: 1 | C25: 기타유동금융부채 | N25: 993.85 | O25: 6926.4 | P25: 6926.4 | Q25: 6831.94 | R25: 5743.68 | S25: 5743.68 | T25: 8276.1 | U25: 8276.1 | V25: 8276.1 | W25: 303.18 | X25: 303.18 | AA25: 44 | AB25: 15
A26: 1 | C26: 단기금융부채 | N26: 993.85 | O26: 7329.07 | P26: 7329.07 | Q26: 7224.37 | R26: 6194.73 | S26: 6169.73 | T26: 8738.25 | U26: 8738.25 | V26: 8702 | W26: 614.74 | X26: 547.22 | Y26: 193.27 | Z26: 193.27 | AA26: 182.85 | AB26: 143.13
A27: 1 | C27: 단기충당부채 | N27: 30.9
A28: 1 | C28: 기타유동부채 | N28: 966.38 | O28: 929.05 | P28: 929.05 | Q28: 303.54 | R28: 471.14 | S28: 843.92 | T28: 277.21 | U28: 277.21 | V28: 312.18 | W28: 1136.59 | X28: 1545.82 | Y28: 1088.21 | Z28: 1088.21 | AA28: 1161.93 | AB28: 1065.09
A29: 1 | C29: 비유동부채 | N29: 25880.05 | O29: 5734.35 | P29: 5734.35 | Q29: 5998.2 | R29: 6234.23 | S29: 6623.41 | T29: 7074.63 | U29: 7074.63 | V29: 6927.41 | W29: 6784.78 | X29: 8924.84 | Y29: 12932.78 | Z29: 12932.78 | AA29: 12438.68 | AB29: 34903.02
A30: 1 | C30: 장기매입채무및기타채무 | N30: 9165.89 | O30: 371.44 | P30: 371.44 | Q30: 310 | R30: 310 | S30: 300 | T30: 300 | U30: 300 | V30: 310 | W30: 310 | X30: 310 | Y30: 310 | Z30: 310 | AA30: 310 | AB30: 310
A31: 1 | C31: 기타비유동금융부채 | N31: 13311.6
A32: 1 | C32: 장기금융부채 | N32: 13311.6 | O32: 307.76 | P32: 307.76 | Q32: 367.28 | R32: 401.41 | S32: 336.07 | T32: 287.98 | U32: 287.98 | V32: 205.16 | W32: 95.95 | X32: 80.58 | Y32: 105.23 | Z32: 105.23 | AA32: 97.64 | AB32: 83.27
A33: 1 | C33: 장기충당부채 | N33: 50.67 | O33: 55.38 | P33: 55.38 | Q33: 55.38 | R33: 28.4 | S33: 25.02 | T33: 160.37 | U33: 160.37 | V33: 160.37 | W33: 158.97 | X33: 149.9 | Y33: 170.7 | Z33: 170.7 | AA33: 170.7 | AB33: 177.63
A34: 1 | C34: 확정급여부채 | N34: 3351.89 | O34: 3483.76 | P34: 3483.76 | Q34: 3821.67 | R34: 3709.69 | S34: 4249.74 | T34: 4898.77 | U34: 4898.77 | V34: 5215.37 | W34: 5219.26 | X34: 5626.31 | Y34: 5382.88 | Z34: 5382.88 | AA34: 5449.73 | AB34: 4695.29
A35: 1 | C35: 부채총계 | N35: 120742.93 | O35: 125305.3 | P35: 125305.3 | Q35: 121067.3 | R35: 122009.33 | S35: 114040.76 | T35: 118779.79 | U35: 118779.79 | V35: 128940.98 | W35: 117828.98 | X35: 132463.99 | Y35: 119852.26 | Z35: 119852.26 | AA35: 123411.79 | AB35: 148442.6
A36: 1 | C36: 지배주주지분 | N36: 67428.99 | O36: 61109.44 | P36: 61109.44 | Q36: 56349.01 | R36: 53662.97 | S36: 46514.14 | T36: 33041.82 | U36: 33041.82 | V36: 26686.19 | W36: 31060.57 | X36: 50240.53 | Y36: 50334.12 | Z36: 50334.12 | AA36: 50002.77 | AB36: 50402.68
A37: 1 | C37: 자본금 | N37: 16234.06 | O37: 16234.06 | P37: 16234.06 | Q37: 16688.06 | R37: 16688.06 | S37: 16688.06 | T37: 16688.06 | U37: 16688.06 | V37: 16688.06 | W37: 16688.06 | X37: 18732.25 | Y37: 19832.25 | Z37: 19832.25 | AA37: 19832.25 | AB37: 19832.25
A38: 1 | C38: 자본잉여금 | N38: 61458.33 | O38: 61458.33 | P38: 61458.33 | Q38: 62004.04 | R38: 62223.59 | S38: 62285.66 | T38: 62302.9 | U38: 62302.9 | V38: 62302.9 | W38: 60879.15 | X38: 65331.39 | Y38: 68187.8 | Z38: 68187.8 | AA38: 68215.06 | AB38: 68215.06
A39: 1 | C39: 기타자본 | N39: -26.25 | O39: -73.04 | P39: -73.04 | Q39: -1233.55 | R39: -1099.88 | S39: -703.61 | T39: -1101.98 | U39: -1101.98 | V39: -1189.82 | W39: -1341.16 | X39: 14317.66 | Y39: 12120.4 | Z39: 12120.4 | AA39: 11550.76 | AB39: 11876.19
A40: 1 | C40: 이익잉여금 | N40: -10237.14 | O40: -16509.91 | P40: -16509.91 | Q40: -21109.53 | R40: -24148.8 | S40: -31755.97 | T40: -44847.16 | U40: -44847.16 | V40: -51114.94 | W40: -45165.47 | X40: -48140.78 | Y40: -49806.33 | Z40: -49806.33 | AA40: -49595.29 | AB40: -49520.82
...

Sheet BS별도
B1: (백만원) | C1: 이름: BS별도H | E1: 4Q21 | F1: 2021 | G1: 1Q22 | H1: 2Q22 | I1: 3Q22 | J1: 4Q22 | K1: 2022 | L1: 1Q23 | M1: 2Q23 | N1: 3Q23 | O1: 4Q23 | P1: 2023 | Q1: 1Q24 | R1: 2Q24 | S1: 3Q24 | T1: 4Q24 | U1: 2024 | V1: 1Q25 | W1: 2Q25 | X1: 3Q25 | Y1: 4Q25 | Z1: 2025 | AA1: 1Q26 | AB1: 2Q26 | AC1: 3Q26 | AD1: 4Q26 | AE1: 2026 | AF1: 1Q27 | AG1: 2Q27 | AH1: 3Q27 | AI1: 4Q27 | AJ1: 2027 | AK1: 1Q28 | AL1: 2Q28 | AM1: 3Q28 | AN1: 4Q28 | AO1: 2028
B2: 별도 | D2: fin json(kship_fin.py)
B3: 화인베스틸(별) | C3: UPDATE: 26-10-13 | E3: 1 | F3: 2 | G3: 3 | H3: 4 | I3: 5 | J3: 6 | K3: 7 | L3: 8 | M3: 9 | N3: 10 | O3: 11 | P3: 12 | Q3: 13 | R3: 14 | S3: 15 | T3: 16 | U3: 17 | V3: 18 | W3: 19 | X3: 20 | Y3: 21 | Z3: 22 | AA3: 23 | AB3: 24 | AC3: 25 | AD3: 26 | AE3: 27 | AF3: 28 | AG3: 29 | AH3: 30 | AI3: 31 | AJ3: 32 | AK3: 33 | AL3: 34 | AM3: 35 | AN3: 36 | AO3: 37
B4: Account Code | C4: AccountNAME | E4: 2021.12 | F4: 2021.12A | G4: 2022.03 | H4: 2022.06 | I4: 2022.09 | J4: 2022.12 | K4: 2022.12A | L4: 2023.03 | M4: 2023.06 | N4: 2023.09 | O4: 2023.12 | P4: 2023.12A | Q4: 2024.03 | R4: 2024.06 | S4: 2024.09 | T4: 2024.12 | U4: 2024.12A | V4: 2025.03 | W4: 2025.06 | X4: 2025.09 | Y4: 2025.12 | Z4: 2025.12A | AA4: 2026.03 | AB4: 2026.06 | AC4: 2026.09 | AD4: 2026.12 | AE4: 2026.12A | AF4: 2027.03 | AG4: 2027.06 | AH4: 2027.09 | AI4: 2027.12 | AJ4: 2027.12A | AK4: 2028.03 | AL4: 2028.06 | AM4: 2028.09 | AN4: 2028.12 | AO4: 2028.12A
A5: 1 | C5: 유동자산 | E5: 76618.87 | F5: 76618.87 | G5: 71249.68 | H5: 67165.39 | I5: 74556.08 | J5: 78946.83 | K5: 78946.83 | L5: 70165.68 | M5: 68759.5 | N5: 67419.54 | O5: 64638.05 | P5: 64638.05 | Q5: 59298.97 | R5: 59606.47 | S5: 45440.73 | T5: 40903.14 | U5: 40903.14 | V5: 47270.01 | W5: 45893.3 | X5: 66350.9 | Y5: 59676.67 | Z5: 59676.67 | AA5: 65331.3 | AB5: 87978.69
A6: 1 | C6: 현금및현금성자산 | E6: 1301.24 | F6: 1301.24 | G6: 406.48 | H6: 932.31 | I6: 1139.25 | J6: 4491.94 | K6: 4491.94 | L6: 3339.27 | M6: 421.68 | N6: 210.28 | O6: 339.06 | P6: 339.06 | Q6: 440.82 | R6: 3938.09 | S6: 531.53 | T6: 3740.24 | U6: 3740.24 | V6: 3778.3 | W6: 4084.19 | X6: 11567.18 | Y6: 6191.12 | Z6: 6191.12 | AA6: 1427.71 | AB6: 11820.84
A7: 1 | C7: 단기금융상품 | E7: 0.06 | F7: 0.06 | G7: 0.06 | H7: 0.06 | I7: 764.34 | J7: 305.92 | K7: 305.92 | L7: 802.11 | M7: 1163.79 | N7: 1481.12 | O7: 1882.02 | P7: 1882.02 | Q7: 2492.14 | R7: 2482.87 | S7: 2249.51 | T7: 1.88 | U7: 1.88 | V7: 1.89 | W7: 1.89 | X7: 1.9 | Y7: 194.13 | Z7: 194.13 | AA7: 277.8 | AB7: 1705.07
A8: 1 | C8: 단기금융자산 | E8: 0.06 | F8: 0.06 | G8: 0.06 | H8: 0.06 | I8: 764.34 | J8: 305.92 | K8: 305.92 | L8: 802.11 | M8: 1163.79 | N8: 1481.12 | O8: 1882.02 | P8: 1882.02 | Q8: 2492.14 | R8: 2482.87 | S8: 2249.51 | T8: 1.88 | U8: 1.88 | V8: 1.89 | W8: 1.89 | X8: 1.9 | Y8: 194.13 | Z8: 194.13 | AA8: 277.8 | AB8: 1705.07
A9: 1 | C9: 매출채권및기타채권 | E9: 34607 | F9: 34607 | G9: 27578.88 | H9: 24043.96 | I9: 26163.63 | J9: 25018.66 | K9: 25018.66 | L9: 28603.8 | M9: 28119.84 | N9: 27671.89 | O9: 27311.27 | P9: 27311.27 | Q9: 25295.68 | R9: 28697.81 | S9: 17228.58 | T9: 19475.52 | U9: 19475.52 | V9: 21488.43 | W9: 20391.43 | X9: 25395.91 | Y9: 19435.74 | Z9: 19435.74 | AA9: 20203.12 | AB9: 26034.91
A10: 1 | C10: 기타유동자산 | E10: 2703.72 | F10: 2703.72 | G10: 2722.15 | H10: 2647.12 | I10: 3168.19 | J10: 3291.39 | K10: 3291.39 | L10: 2230.49 | M10: 2903.39 | N10: 2321.89 | O10: 2190.46 | P10: 2190.46 | Q10: 1795.46 | R10: 52.11 | S10: 311.33 | T10: 931.05 | U10: 931.05 | V10: 75.48 | W10: 2657.95 | X10: 408.07 | Y10: 1740.07 | Z10: 1740.07 | AA10: 8742.16 | AB10: 65.38
A11: 1 | C11: 재고자산 | E11: 38006.86 | F11: 38006.86 | G11: 40541.19 | H11: 38775.86 | I11: 42554.55 | J11: 45440.89 | K11: 45440.89 | L11: 34775.11 | M11: 36145.19 | N11: 34597.77 | O11: 32576.48 | P11: 32576.48 | Q11: 28935.28 | R11: 24303.7 | S11: 24988.01 | T11: 16715 | U11: 16715 | V11: 21863.63 | W11: 18734.09 | X11: 28953.2 | Y11: 32090.94 | Z11: 32090.94 | AA11: 34655.61 | AB11: 48349.61
A12: 1 | C12: 비유동자산 | E12: 106620.06 | F12: 106620.06 | G12: 104709.19 | H12: 103085.9 | I12: 101764.84 | J12: 100676.08 | K12: 100676.08 | L12: 99006.78 | M12: 99663.09 | N12: 117572.86 | O12: 117998.24 | P12: 117998.24 | Q12: 116836.43 | R12: 114855.65 | S12: 114131.32 | T12: 107327.81 | U12: 107327.81 | V12: 105868.83 | W12: 101911.56 | X12: 113532.7 | Y12: 109010.15 | Z12: 109010.15 | AA12: 107625 | AB12: 110436.75
A13: 1 | C13: 장기금융자산 | E13: 674.3 | F13: 674.3 | G13: 129.26 | H13: 109.26 | I13: 98.22 | J13: 223.05 | K13: 223.05 | L13: 223.21 | M13: 229.93 | N13: 6007.83 | O13: 5115.75 | P13: 5115.75 | Q13: 5125.83 | R13: 6576.44 | S13: 6585.56 | T13: 5446.16 | U13: 5446.16 | V13: 1525.48 | W13: 1563.5 | X13: 1597.74 | Y13: 273.27 | Z13: 273.27 | AA13: 305.59 | AB13: 278.91
A14: 1 | C14: 투자자산 | E14: 674.3 | F14: 674.3 | G14: 129.26 | H14: 109.26 | I14: 98.22 | J14: 223.05 | K14: 223.05 | L14: 223.21 | M14: 1399.93 | N14: 20537.83 | O14: 19915.75 | P14: 19915.75 | Q14: 19925.83 | R14: 21376.44 | S14: 21385.56 | T14: 15123.06 | U14: 15123.06 | V14: 15316.82 | W14: 15354.84 | X14: 15389.08 | Y14: 11358.33 | Z14: 11358.33 | AA14: 11390.65 | AB14: 11363.97
A15: 1 | C15: 장기매출채권및기타채권 | E15: 95.29 | F15: 95.29 | G15: 113.41 | H15: 157.52 | I15: 632.52 | J15: 637.71 | K15: 637.71 | L15: 675.35 | M15: 675.02 | N15: 675 | O15: 678.02 | P15: 678.02 | Q15: 687.99 | R15: 719.82 | S15: 719.8 | T15: 221.36 | U15: 221.36 | V15: 183.69 | W15: 79.43 | X15: 79.43 | Y15: 135.7 | Z15: 135.7 | AA15: 146.75 | AB15: 146.75
A16: 1 | C16: 유형자산 | E16: 94583.32 | F16: 94583.32 | G16: 93104.91 | H16: 91415.75 | I16: 89660.41 | J16: 88540.98 | K16: 88540.98 | L16: 86740.76 | M16: 85615.12 | N16: 84188.56 | O16: 82426.7 | P16: 82426.7 | Q16: 81118.31 | R16: 79131.81 | S16: 78146.74 | T16: 76686 | U16: 76686 | V16: 74953.01 | W16: 73521.08 | X16: 89769.34 | Y16: 89245.19 | Z16: 89245.19 | AA16: 87840.59 | AB16: 90702.94
... A18: 1 | C18: 무형자산 | E18: 183.96 | F18: 183.96 | G18: 183.96 | H18: 183.96 | I18: 183.96 | J18: 183.96 | K18: 183.96 | L18: 183.96 | M18: 183.96 | N18: 183.96 | O18: 183.96 | P18: 183.96 | Q18: 183.96 | R18: 183.96 | S18: 183.96 | T18: 183.96 | U18: 183.96 | V18: 183.96 | W18: 183.96 | X18: 183.96 | Y18: 183.96 | Z18: 183.96 | AA18: 183.96 | AB18: 183.96
A19: 1 | C19: 이연법인세자산 | E19: 2400.29 | F19: 2400.29 | G19: 2507.55 | H19: 2562.12 | I19: 2545.26 | J19: 2458.71 | K19: 2458.71 | L19: 2564.64 | M19: 3183.01 | N19: 3284.67 | O19: 3854.5 | P19: 3854.5 | Q19: 4004.96 | R19: 2552.16 | S19: 2827.73 | T19: 4269.82 | U19: 4269.82 | V19: 4411.67 | W19: 1976.5
A20: 1 | C20: 자산총계 | E20: 183238.94 | F20: 183238.94 | G20: 175958.87 | H20: 170251.29 | I20: 176320.93 | J20: 179622.91 | K20: 179622.91 | L20: 169172.46 | M20: 168422.59 | N20: 184992.4 | O20: 182636.29 | P20: 182636.29 | Q20: 176135.4 | R20: 174462.12 | S20: 159572.05 | T20: 148230.95 | U20: 148230.95 | V20: 153138.84 | W20: 147804.86 | X20: 179883.6 | Y20: 168686.82 | Z20: 168686.82 | AA20: 172956.3 | AB20: 198415.43
A21: 1 | C21: 유동부채 | E21: 95245.46 | F21: 95245.46 | G21: 86135.4 | H21: 82372.42 | I21: 91532.42 | J21: 98773.91 | K21: 98773.91 | L21: 91023.52 | M21: 93923.81 | N21: 90246.94 | O21: 115884.38 | P21: 115884.38 | Q21: 112053.39 | R21: 112709.77 | S21: 104267.49 | T21: 108961.82 | U21: 108961.82 | V21: 118840.02 | W21: 106951.27 | X21: 119734.59 | Y21: 104319.91 | Z21: 104319.91 | AA21: 108329.95 | AB21: 110814.9
A22: 1 | C22: 매입채무및기타채무 | E22: 91715.21 | F22: 91715.21 | G22: 83107.57 | H22: 78205.12 | I22: 87980.43 | J22: 94820.74 | K22: 94820.74 | L22: 88797.26 | M22: 91434.39 | N22: 88586.07 | O22: 18691.38 | P22: 18691.38 | Q22: 12282.7 | R22: 22755.79 | S22: 13762.08 | T22: 15943.76 | U22: 15943.76 | V22: 25287.86 | W22: 21874.88 | X22: 35615.68 | Y22: 24734.44 | Z22: 24734.44 | AA22: 31875.22 | AB22: 37876.73
A23: 1 | C23: 단기차입금 | E23: 66952.56 | F23: 66952.56 | G23: 72954.56 | H23: 52105.3 | I23: 66987.73 | J23: 66237.79 | K23: 66237.79 | L23: 67470.47 | M23: 72127.57 | N23: 72672.68 | O23: 77926.33 | P23: 77926.33 | Q23: 81428.28 | R23: 74095.61 | S23: 74093.89 | T23: 73593.21 | U23: 73593.21 | V23: 73590.48 | W23: 72537.34 | X23: 81838.69 | Y23: 77499.64 | Z23: 77499.64 | AA23: 75201.91
A24: 1 | C24: 유동성장기부채 | E24: 2787.87 | F24: 2787.87 | G24: 3082.13 | H24: 7043.89 | I24: 7347.98 | J24: 7665.2 | K24: 7665.2 | L24: 7988.82 | M24: 3923.12 | N24: 3812.18 | O24: 11753.65 | P24: 11753.65 | Q24: 11099.32 | R24: 9732.44 | S24: 10223.43 | T24: 10739.31 | U24: 10739.31 | V24: 11269.57 | W24: 11832.32 | X24: 907.02 | Y24: 958.38 | Z24: 958.38 | AB24: 0
A25: 1 | C25: 유동리스부채 | E25: 64.96 | F25: 64.96 | G25: 73.68 | H25: 109.41 | I25: 109.41 | J25: 129.82 | K25: 129.82 | L25: 156.28 | M25: 163.72 | N25: 178.15 | O25: 176.21 | P25: 176.21 | Q25: 175.72 | R25: 175.72 | S25: 174.56 | T25: 196.72 | U25: 196.72 | V25: 184.41 | W25: 164.73 | X25: 132.32 | Y25: 115.43 | Z25: 115.43 | AA25: 87.22 | AB25: 71.68
A26: 1 | C26: 리스부채 | E26: 296.81 | F26: 296.81 | G26: 299.47 | H26: 425.71 | I26: 400.23 | J26: 430.63 | K26: 430.63 | L26: 480.05 | M26: 468.24 | N26: 436.62 | O26: 395.69 | P26: 395.69 | Q26: 355.6 | R26: 315.39 | S26: 278.24 | T26: 275.52 | U26: 275.52 | V26: 226.15 | W26: 175.9 | X26: 132.32 | Y26: 161.83 | Z26: 161.83 | AA26: 132.09 | AB26: 109.1
A27: 1 | C27: 단기금융부채 | E27: 5759.24 | F27: 5759.24 | G27: 5767.96 | H27: 2986.94 | I27: 2993.64 | J27: 2143.71 | K27: 2143.71 | L27: 2154.97 | M27: 1187.93 | N27: 1172 | O27: 7102.61 | P27: 7102.61 | Q27: 7007.66 | R27: 5919.4 | S27: 5918.24 | T27: 8472.82 | U27: 8472.82 | V27: 8460.51 | W27: 467.91 | X27: 435.5 | Y27: 115.43 | Z27: 115.43 | AA27: 131.22 | AB27: 86.68
A28: 1 | C28: 당기법인세부채(미지급법인세) | E28: 525.71 | F28: 525.71 | AB28: 29.64
A29: 1 | C29: 기타유동금융부채 | E29: 5694.28 | F29: 5694.28 | G29: 5694.28 | H29: 2877.53 | I29: 2884.23 | J29: 2013.89 | K29: 2013.89 | L29: 1998.69 | M29: 1024.21 | N29: 993.85 | O29: 6926.4 | P29: 6926.4 | Q29: 6831.94 | R29: 5743.68 | S29: 5743.68 | T29: 8276.1 | U29: 8276.1 | V29: 8276.1 | W29: 303.18 | X29: 303.18 | AA29: 44 | AB29: 15
A30: 1 | C30: 기타유동부채 | E30: 157.41 | F30: 157.41 | G30: 180.7 | H30: 1289.76 | I30: 667.76 | J30: 1939.27 | K30: 1939.27 | L30: 227.56 | M30: 1465.21 | N30: 667.02 | O30: 410.41 | P30: 410.41 | Q30: 235.43 | R30: 206.52 | S30: 269.84 | T30: 212.72 | U30: 212.72 | V30: 231.6 | W30: 238.82 | X30: 937.69 | Y30: 1012.02 | Z30: 1012.02 | AA30: 1121.6 | AB30: 1027.95
A31: 1 | C31: 비유동부채 | E31: 8495.61 | F31: 8495.61 | G31: 8236.65 | H31: 4211.76 | I31: 3142.49 | J31: 2586.01 | K31: 2586.01 | L31: 2887.08 | M31: 2852.66 | N31: 24334.38 | O31: 3284.33 | P31: 3284.33 | Q31: 3535.15 | R31: 3432.15 | S31: 3775.15 | T31: 4916.92 | U31: 4916.92 | V31: 5147.92 | W31: 5189.15 | X31: 7439.25 | Y31: 11761.59 | Z31: 11761.59 | AA31: 11463.21 | AB31: 34149.94
A32: 1 | C32: 장기매입채무및기타채무 | E32: 5626.69 | F32: 5626.69 | G32: 5351.76 | H32: 986.89 | I32: 684.56 | J32: 600.81 | K32: 600.81 | L32: 623.77 | M32: 604.52 | N32: 8207.34 | O32: 300 | P32: 300 | Q32: 300 | R32: 300 | S32: 300 | T32: 300 | U32: 300 | V32: 300 | W32: 300 | X32: 300 | Y32: 300 | Z32: 300 | AA32: 300 | AB32: 300
A33: 1 | C33: 기타비유동부채 | E33: 300 | F33: 300 | G33: 300 | H33: 300 | I33: 300 | J33: 300 | K33: 300 | L33: 300 | M33: 300 | N33: 3064.77
A34: 1 | C34: 장기차입금 | E34: 913.03 | F34: 913.03 | G34: 644.15 | H34: 370.59 | I34: 93.74 | M34: 373.45 | Y34: 4333.2 | Z34: 4333.2 | AA34: 3791.55 | AB34: 27249.9
A35: 1 | C35: 사채 | E35: 4181.81 | F35: 4181.81 | G35: 4181.81 | N35: 7648.87
A36: 1 | C36: 비유동리스부채 | E36: 231.85 | F36: 231.85 | G36: 225.79 | H36: 316.3 | I36: 290.82 | J36: 300.81 | K36: 300.81 | L36: 323.77 | M36: 304.52 | N36: 258.47 | O36: 219.48 | P36: 219.48 | Q36: 179.88 | R36: 139.67 | S36: 103.68 | T36: 78.8 | U36: 78.8 | V36: 41.74 | W36: 11.17 | Y36: 46.4 | Z36: 46.4 | AA36: 44.87 | AB36: 37.42
A37: 1 | C37: 장기금융부채 | E37: 231.85 | F37: 231.85 | G37: 225.79 | H37: 316.3 | I37: 290.82 | J37: 300.81 | K37: 300.81 | L37: 323.77 | M37: 304.52 | N37: 13570.07 | O37: 219.48 | P37: 219.48 | Q37: 179.88 | R37: 139.67 | S37: 103.68 | T37: 78.8 | U37: 78.8 | V37: 41.74 | W37: 11.17 | Y37: 46.4 | Z37: 46.4 | AA37: 44.87 | AB37: 37.42
A38: 1 | C38: 확정급여부채 | E38: 2868.92 | F38: 2868.92 | G38: 2884.9 | H38: 3224.87 | I38: 2457.93 | J38: 1934.53 | K38: 1934.53 | L38: 2212.64 | M38: 2193.92 | N38: 50.67 | O38: 2709.47 | P38: 2709.47 | Q38: 2999.89 | R38: 2964.08 | S38: 3346.45 | T38: 4377.75 | U38: 4377.75 | V38: 4645.82 | W38: 4719.01 | X38: 5145.87 | Y38: 5083.64 | Z38: 5083.64 | AA38: 5309.48 | AB38: 4564.72
A39: 1 | C39: 부채총계 | E39: 103741.07 | F39: 103741.07 | G39: 94372.05 | H39: 86584.18 | I39: 94674.91 | J39: 101359.93 | K39: 101359.93 | L39: 93910.6 | M39: 96776.48 | N39: 114581.33 | O39: 119168.71 | P39: 119168.71 | Q39: 115588.54 | R39: 116141.92 | S39: 108042.64 | T39: 113878.74 | U39: 113878.74 | V39: 123987.94 | W39: 112140.42 | X39: 127173.83 | Y39: 116081.5 | Z39: 116081.5 | AA39: 119793.16 | AB39: 144964.83
A40: 1 | C40: 자본금 | E40: 16050 | F40: 16050 | G40: 16050 | H40: 16165.97 | I40: 16165.97 | J40: 16165.97 | K40: 16165.97 | L40: 16165.97 | M40: 16234.06 | N40: 16234.06 | O40: 16234.06 | P40: 16234.06 | Q40: 16688.06 | R40: 16688.06 | S40: 16688.06 | T40: 16688.06 | U40: 16688.06 | V40: 16688.06 | W40: 16688.06 | X40: 18732.25 | Y40: 19832.25 | Z40: 19832.25 | AA40: 19832.25 | AB40: 19832.25
A41: 1 | C41: 자본잉여금 | E41: 60586.78 | F41: 60586.78 | G41: 60586.78 | H41: 61209 | I41: 61209 | J41: 61209 | K41: 61209 | L41: 61209 | M41: 61460.62 | N41: 61460.62 | O41: 61460.62 | P41: 61460.62 | Q41: 62006.32 | R41: 62006.32 | S41: 62006.32 | T41: 62006.32 | U41: 62006.32 | V41: 62006.32 | W41: 62006.32 | X41: 66458.57 | Y41: 69277.79 | Z41: 69277.79 | AA41: 69277.79 | AB41: 69277.79
...

Sheet subQ
A1: YQ | C1: subQ 분기 서브모델(억원, U=100) | E1: 4Q21 | F1: 2021 | G1: 1Q22 | H1: 2Q22 | I1: 3Q22 | J1: 4Q22 | K1: 2022 | L1: 1Q23 | M1: 2Q23 | N1: 3Q23 | O1: 4Q23 | P1: 2023 | Q1: 1Q24 | R1: 2Q24 | S1: 3Q24 | T1: 4Q24 | U1: 2024 | V1: 1Q25 | W1: 2Q25 | X1: 3Q25 | Y1: 4Q25 | Z1: 2025 | AA1: 1Q26 | AB1: 2Q26 | AC1: 3Q26 | AD1: 4Q26 | AE1: 2026 | AF1: 1Q27 | AG1: 2Q27 | AH1: 3Q27 | AI1: 4Q27 | AJ1: 2027 | AK1: 1Q28 | AL1: 2Q28 | AM1: 3Q28 | AN1: 4Q28 | AO1: 2028
A2: A=이름(key) B=그룹 C=단위 D=FnGuide 계정명(VLOOKUP 키). 확정=VLOOKUP(BS), 추정=변수 가정 참조
E3: 1 | F3: 2 | G3: 3 | H3: 4 | I3: 5 | J3: 6 | K3: 7 | L3: 8 | M3: 9 | N3: 10 | O3: 11 | P3: 12 | Q3: 13 | R3: 14 | S3: 15 | T3: 16 | U3: 17 | V3: 18 | W3: 19 | X3: 20 | Y3: 21 | Z3: 22 | AA3: 23 | AB3: 24 | AC3: 25 | AD3: 26 | AE3: 27 | AF3: 28 | AG3: 29 | AH3: 30 | AI3: 31 | AJ3: 32 | AK3: 33 | AL3: 34 | AM3: 35 | AN3: 36 | AO3: 37
E4: 2021.12 | F4: 2021.12A | G4: 2022.03 | H4: 2022.06 | I4: 2022.09 | J4: 2022.12 | K4: 2022.12A | L4: 2023.03 | M4: 2023.06 | N4: 2023.09 | O4: 2023.12 | P4: 2023.12A | Q4: 2024.03 | R4: 2024.06 | S4: 2024.09 | T4: 2024.12 | U4: 2024.12A | V4: 2025.03 | W4: 2025.06 | X4: 2025.09 | Y4: 2025.12 | Z4: 2025.12A | AA4: 2026.03 | AB4: 2026.06 | AC4: 2026.09 | AD4: 2026.12 | AE4: 2026.12A | AF4: 2027.03 | AG4: 2027.06 | AH4: 2027.09 | AI4: 2027.12 | AJ4: 2027.12A | AK4: 2028.03 | AL4: 2028.06 | AM4: 2028.09 | AN4: 2028.12 | AO4: 2028.12A
A5: 매출액 | B5: 손익 | C5: 억원 | D5: 매출액(수익) | E5: =IFERROR(VLOOKUP($D5,BS별도,MATCH(E$1,BS별도H,0),0)/100,"") | G5: =IFERROR(VLOOKUP($D5,BS별도,MATCH(G$1,BS별도H,0),0)/100,"") | H5: =IFERROR(VLOOKUP($D5,BS별도,MATCH(H$1,BS별도H,0),0)/100,"") | I5: =IFERROR(VLOOKUP($D5,BS별도,MATCH(I$1,BS별도H,0),0)/100,"") | J5: =IFERROR(VLOOKUP($D5,BS별도,MATCH(J$1,BS별도H,0),0)/100,"") | K5: =SUM(G5:J5) | L5: =IFERROR(VLOOKUP($D5,BS별도,MATCH(L$1,BS별도H,0),0)/100,"") | M5: =IFERROR(VLOOKUP($D5,BS별도,MATCH(M$1,BS별도H,0),0)/100,"") | N5: =IFERROR(VLOOKUP($D5,BS연결,MATCH(N$1,BS연결H,0),0)/100,"") | O5: =IFERROR(VLOOKUP($D5,BS연결,MATCH(O$1,BS연결H,0),0)/100,"") | P5: =SUM(L5:O5) | Q5: =IFERROR(VLOOKUP($D5,BS연결,MATCH(Q$1,BS연결H,0),0)/100,"") | R5: =IFERROR(VLOOKUP($D5,BS연결,MATCH(R$1,BS연결H,0),0)/100,"") | S5: =IFERROR(VLOOKUP($D5,BS연결,MATCH(S$1,BS연결H,0),0)/100,"") | T5: =IFERROR(VLOOKUP($D5,BS연결,MATCH(T$1,BS연결H,0),0)/100,"") | U5: =IFERROR(VLOOKUP($D5,BS연결,MATCH(U$1,BS연결H,0),0)/100,"") | V5: =IFERROR(VLOOKUP($D5,BS연결,MATCH(V$1,BS연결H,0),0)/100,"") | W5: =IFERROR(VLOOKUP($D5,BS연결,MATCH(W$1,BS연결H,0),0)/100,"") | X5: =IFERROR(VLOOKUP($D5,BS연결,MATCH(X$1,BS연결H,0),0)/100,"") | ... AB5: =IFERROR(VLOOKUP($D5,BS연결,MATCH(AB$1,BS연결H,0),0)/100,"") | AC5: =IFERROR(X5*(1+변수!AC21),"") | AD5: =IFERROR(Y5*(1+변수!AD21),"") | AE5: =SUM(AA5:AD5) | AF5: =IFERROR(AA5*(1+변수!AF21),"") | AG5: =IFERROR(AB5*(1+변수!AG21),"") | AH5: =IFERROR(AC5*(1+변수!AH21),"") | AI5: =IFERROR(AD5*(1+변수!AI21),"") | AJ5: =SUM(AF5:AI5) | AK5: =IFERROR(AF5*(1+변수!AK21),"") | AL5: =IFERROR(AG5*(1+변수!AL21),"") | AM5: =IFERROR(AH5*(1+변수!AM21),"") | AN5: =IFERROR(AI5*(1+변수!AN21),"") | AO5: =SUM(AK5:AN5)
A6: 매출원가 | B6: 손익 | C6: 억원 | D6: 매출원가 | E6: =IFERROR(VLOOKUP($D6,BS별도,MATCH(E$1,BS별도H,0),0)/100,"") | G6: =IFERROR(VLOOKUP($D6,BS별도,MATCH(G$1,BS별도H,0),0)/100,"") | H6: =IFERROR(VLOOKUP($D6,BS별도,MATCH(H$1,BS별도H,0),0)/100,"") | I6: =IFERROR(VLOOKUP($D6,BS별도,MATCH(I$1,BS별도H,0),0)/100,"") | J6: =IFERROR(VLOOKUP($D6,BS별도,MATCH(J$1,BS별도H,0),0)/100,"") | K6: =SUM(G6:J6) | L6: =IFERROR(VLOOKUP($D6,BS별도,MATCH(L$1,BS별도H,0),0)/100,"") | M6: =IFERROR(VLOOKUP($D6,BS별도,MATCH(M$1,BS별도H,0),0)/100,"") | N6: =IFERROR(VLOOKUP($D6,BS연결,MATCH(N$1,BS연결H,0),0)/100,"") | O6: =IFERROR(VLOOKUP($D6,BS연결,MATCH(O$1,BS연결H,0),0)/100,"") | P6: =SUM(L6:O6) | Q6: =IFERROR(VLOOKUP($D6,BS연결,MATCH(Q$1,BS연결H,0),0)/100,"") | R6: =IFERROR(VLOOKUP($D6,BS연결,MATCH(R$1,BS연결H,0),0)/100,"") | S6: =IFERROR(VLOOKUP($D6,BS연결,MATCH(S$1,BS연결H,0),0)/100,"") | T6: =IFERROR(VLOOKUP($D6,BS연결,MATCH(T$1,BS연결H,0),0)/100,"") | U6: =IFERROR(VLOOKUP($D6,BS연결,MATCH(U$1,BS연결H,0),0)/100,"") | V6: =IFERROR(VLOOKUP($D6,BS연결,MATCH(V$1,BS연결H,0),0)/100,"") | W6: =IFERROR(VLOOKUP($D6,BS연결,MATCH(W$1,BS연결H,0),0)/100,"") | X6: =IFERROR(VLOOKUP($D6,BS연결,MATCH(X$1,BS연결H,0),0)/100,"") | ... AB6: =IFERROR(VLOOKUP($D6,BS연결,MATCH(AB$1,BS연결H,0),0)/100,"") | AC6: =IFERROR(AC5-AC7,"") | AD6: =IFERROR(AD5-AD7,"") | AE6: =SUM(AA6:AD6) | AF6: =IFERROR(AF5-AF7,"") | AG6: =IFERROR(AG5-AG7,"") | AH6: =IFERROR(AH5-AH7,"") | AI6: =IFERROR(AI5-AI7,"") | AJ6: =SUM(AF6:AI6) | AK6: =IFERROR(AK5-AK7,"") | AL6: =IFERROR(AL5-AL7,"") | AM6: =IFERROR(AM5-AM7,"") | AN6: =IFERROR(AN5-AN7,"") | AO6: =SUM(AK6:AN6)
A7: 매출총이익 | B7: 손익 | C7: 억원 | D7: 매출총이익 | E7: =IFERROR(VLOOKUP($D7,BS별도,MATCH(E$1,BS별도H,0),0)/100,"") | G7: =IFERROR(VLOOKUP($D7,BS별도,MATCH(G$1,BS별도H,0),0)/100,"") | H7: =IFERROR(VLOOKUP($D7,BS별도,MATCH(H$1,BS별도H,0),0)/100,"") | I7: =IFERROR(VLOOKUP($D7,BS별도,MATCH(I$1,BS별도H,0),0)/100,"") | J7: =IFERROR(VLOOKUP($D7,BS별도,MATCH(J$1,BS별도H,0),0)/100,"") | K7: =SUM(G7:J7) | L7: =IFERROR(VLOOKUP($D7,BS별도,MATCH(L$1,BS별도H,0),0)/100,"") | M7: =IFERROR(VLOOKUP($D7,BS별도,MATCH(M$1,BS별도H,0),0)/100,"") | N7: =IFERROR(VLOOKUP($D7,BS연결,MATCH(N$1,BS연결H,0),0)/100,"") | O7: =IFERROR(VLOOKUP($D7,BS연결,MATCH(O$1,BS연결H,0),0)/100,"") | P7: =SUM(L7:O7) | Q7: =IFERROR(VLOOKUP($D7,BS연결,MATCH(Q$1,BS연결H,0),0)/100,"") | R7: =IFERROR(VLOOKUP($D7,BS연결,MATCH(R$1,BS연결H,0),0)/100,"") | S7: =IFERROR(VLOOKUP($D7,BS연결,MATCH(S$1,BS연결H,0),0)/100,"") | T7: =IFERROR(VLOOKUP($D7,BS연결,MATCH(T$1,BS연결H,0),0)/100,"") | U7: =IFERROR(VLOOKUP($D7,BS연결,MATCH(U$1,BS연결H,0),0)/100,"") | V7: =IFERROR(VLOOKUP($D7,BS연결,MATCH(V$1,BS연결H,0),0)/100,"") | W7: =IFERROR(VLOOKUP($D7,BS연결,MATCH(W$1,BS연결H,0),0)/100,"") | X7: =IFERROR(VLOOKUP($D7,BS연결,MATCH(X$1,BS연결H,0),0)/100,"") | ... AB7: =IFERROR(VLOOKUP($D7,BS연결,MATCH(AB$1,BS연결H,0),0)/100,"") | AC7: =IFERROR(AC9+AC8,"") | AD7: =IFERROR(AD9+AD8,"") | AE7: =SUM(AA7:AD7) | AF7: =IFERROR(AF9+AF8,"") | AG7: =IFERROR(AG9+AG8,"") | AH7: =IFERROR(AH9+AH8,"") | AI7: =IFERROR(AI9+AI8,"") | AJ7: =SUM(AF7:AI7) | AK7: =IFERROR(AK9+AK8,"") | AL7: =IFERROR(AL9+AL8,"") | AM7: =IFERROR(AM9+AM8,"") | AN7: =IFERROR(AN9+AN8,"") | AO7: =SUM(AK7:AN7)
A8: 판관비 | B8: 손익 | C8: 억원 | D8: 판관비 | E8: =IFERROR(VLOOKUP($D8,BS별도,MATCH(E$1,BS별도H,0),0)/100,"") | G8: =IFERROR(VLOOKUP($D8,BS별도,MATCH(G$1,BS별도H,0),0)/100,"") | H8: =IFERROR(VLOOKUP($D8,BS별도,MATCH(H$1,BS별도H,0),0)/100,"") | I8: =IFERROR(VLOOKUP($D8,BS별도,MATCH(I$1,BS별도H,0),0)/100,"") | J8: =IFERROR(VLOOKUP($D8,BS별도,MATCH(J$1,BS별도H,0),0)/100,"") | K8: =SUM(G8:J8) | L8: =IFERROR(VLOOKUP($D8,BS별도,MATCH(L$1,BS별도H,0),0)/100,"") | M8: =IFERROR(VLOOKUP($D8,BS별도,MATCH(M$1,BS별도H,0),0)/100,"") | N8: =IFERROR(VLOOKUP($D8,BS연결,MATCH(N$1,BS연결H,0),0)/100,"") | O8: =IFERROR(VLOOKUP($D8,BS연결,MATCH(O$1,BS연결H,0),0)/100,"") | P8: =SUM(L8:O8) | Q8: =IFERROR(VLOOKUP($D8,BS연결,MATCH(Q$1,BS연결H,0),0)/100,"") | R8: =IFERROR(VLOOKUP($D8,BS연결,MATCH(R$1,BS연결H,0),0)/100,"") | S8: =IFERROR(VLOOKUP($D8,BS연결,MATCH(S$1,BS연결H,0),0)/100,"") | T8: =IFERROR(VLOOKUP($D8,BS연결,MATCH(T$1,BS연결H,0),0)/100,"") | U8: =IFERROR(VLOOKUP($D8,BS연결,MATCH(U$1,BS연결H,0),0)/100,"") | V8: =IFERROR(VLOOKUP($D8,BS연결,MATCH(V$1,BS연결H,0),0)/100,"") | W8: =IFERROR(VLOOKUP($D8,BS연결,MATCH(W$1,BS연결H,0),0)/100,"") | X8: =IFERROR(VLOOKUP($D8,BS연결,MATCH(X$1,BS연결H,0),0)/100,"") | ... AB8: =IFERROR(VLOOKUP($D8,BS연결,MATCH(AB$1,BS연결H,0),0)/100,"") | AC8: =IFERROR(AC5*변수!AC22,"") | AD8: =IFERROR(AD5*변수!AD22,"") | AE8: =SUM(AA8:AD8) | AF8: =IFERROR(AF5*변수!AF22,"") | AG8: =IFERROR(AG5*변수!AG22,"") | AH8: =IFERROR(AH5*변수!AH22,"") | AI8: =IFERROR(AI5*변수!AI22,"") | AJ8: =SUM(AF8:AI8) | AK8: =IFERROR(AK5*변수!AK22,"") | AL8: =IFERROR(AL5*변수!AL22,"") | AM8: =IFERROR(AM5*변수!AM22,"") | AN8: =IFERROR(AN5*변수!AN22,"") | AO8: =SUM(AK8:AN8)
A9: 영업이익 | B9: 손익 | C9: 억원 | D9: 영업이익 | E9: =IFERROR(VLOOKUP($D9,BS별도,MATCH(E$1,BS별도H,0),0)/100,"") | G9: =IFERROR(VLOOKUP($D9,BS별도,MATCH(G$1,BS별도H,0),0)/100,"") | H9: =IFERROR(VLOOKUP($D9,BS별도,MATCH(H$1,BS별도H,0),0)/100,"") | I9: =IFERROR(VLOOKUP($D9,BS별도,MATCH(I$1,BS별도H,0),0)/100,"") | J9: =IFERROR(VLOOKUP($D9,BS별도,MATCH(J$1,BS별도H,0),0)/100,"") | K9: =SUM(G9:J9) | L9: =IFERROR(VLOOKUP($D9,BS별도,MATCH(L$1,BS별도H,0),0)/100,"") | M9: =IFERROR(VLOOKUP($D9,BS별도,MATCH(M$1,BS별도H,0),0)/100,"") | N9: =IFERROR(VLOOKUP($D9,BS연결,MATCH(N$1,BS연결H,0),0)/100,"") | O9: =IFERROR(VLOOKUP($D9,BS연결,MATCH(O$1,BS연결H,0),0)/100,"") | P9: =SUM(L9:O9) | Q9: =IFERROR(VLOOKUP($D9,BS연결,MATCH(Q$1,BS연결H,0),0)/100,"") | R9: =IFERROR(VLOOKUP($D9,BS연결,MATCH(R$1,BS연결H,0),0)/100,"") | S9: =IFERROR(VLOOKUP($D9,BS연결,MATCH(S$1,BS연결H,0),0)/100,"") | T9: =IFERROR(VLOOKUP($D9,BS연결,MATCH(T$1,BS연결H,0),0)/100,"") | U9: =IFERROR(VLOOKUP($D9,BS연결,MATCH(U$1,BS연결H,0),0)/100,"") | V9: =IFERROR(VLOOKUP($D9,BS연결,MATCH(V$1,BS연결H,0),0)/100,"") | W9: =IFERROR(VLOOKUP($D9,BS연결,MATCH(W$1,BS연결H,0),0)/100,"") | X9: =IFERROR(VLOOKUP($D9,BS연결,MATCH(X$1,BS연결H,0),0)/100,"") | ... AB9: =IFERROR(VLOOKUP($D9,BS연결,MATCH(AB$1,BS연결H,0),0)/100,"") | AC9: =IFERROR(AC5*변수!AC23,"") | AD9: =IFERROR(AD5*변수!AD23,"") | AE9: =SUM(AA9:AD9) | AF9: =IFERROR(AF5*변수!AF23,"") | AG9: =IFERROR(AG5*변수!AG23,"") | AH9: =IFERROR(AH5*변수!AH23,"") | AI9: =IFERROR(AI5*변수!AI23,"") | AJ9: =SUM(AF9:AI9) | AK9: =IFERROR(AK5*변수!AK23,"") | AL9: =IFERROR(AL5*변수!AL23,"") | AM9: =IFERROR(AM5*변수!AM23,"") | AN9: =IFERROR(AN5*변수!AN23,"") | AO9: =SUM(AK9:AN9)
A10: OPM | B10: 손익 | C10: % | D10: 영업이익률 | E10: =IFERROR(E9/E5,"") | G10: =IFERROR(G9/G5,"") | H10: =IFERROR(H9/H5,"") | I10: =IFERROR(I9/I5,"") | J10: =IFERROR(J9/J5,"") | K10: =IFERROR(K9/K5,"") | L10: =IFERROR(L9/L5,"") | M10: =IFERROR(M9/M5,"") | N10: =IFERROR(N9/N5,"") | ... AO10: =IFERROR(AO9/AO5,"")
A11: 금융손익 | B11: 손익 | C11: 억원 | D11: 금융손익 | E11: =IFERROR(VLOOKUP($D11,BS별도,MATCH(E$1,BS별도H,0),0)/100,"") | G11: =IFERROR(VLOOKUP($D11,BS별도,MATCH(G$1,BS별도H,0),0)/100,"") | H11: =IFERROR(VLOOKUP($D11,BS별도,MATCH(H$1,BS별도H,0),0)/100,"") | I11: =IFERROR(VLOOKUP($D11,BS별도,MATCH(I$1,BS별도H,0),0)/100,"") | J11: =IFERROR(VLOOKUP($D11,BS별도,MATCH(J$1,BS별도H,0),0)/100,"") | K11: =SUM(G11:J11) | L11: =IFERROR(VLOOKUP($D11,BS별도,MATCH(L$1,BS별도H,0),0)/100,"") | M11: =IFERROR(VLOOKUP($D11,BS별도,MATCH(M$1,BS별도H,0),0)/100,"") | N11: =IFERROR(VLOOKUP($D11,BS연결,MATCH(N$1,BS연결H,0),0)/100,"") | O11: =IFERROR(VLOOKUP($D11,BS연결,MATCH(O$1,BS연결H,0),0)/100,"") | P11: =SUM(L11:O11) | Q11: =IFERROR(VLOOKUP($D11,BS연결,MATCH(Q$1,BS연결H,0),0)/100,"") | R11: =IFERROR(VLOOKUP($D11,BS연결,MATCH(R$1,BS연결H,0),0)/100,"") | S11: =IFERROR(VLOOKUP($D11,BS연결,MATCH(S$1,BS연결H,0),0)/100,"") | T11: =IFERROR(VLOOKUP($D11,BS연결,MATCH(T$1,BS연결H,0),0)/100,"") | U11: =IFERROR(VLOOKUP($D11,BS연결,MATCH(U$1,BS연결H,0),0)/100,"") | V11: =IFERROR(VLOOKUP($D11,BS연결,MATCH(V$1,BS연결H,0),0)/100,"") | W11: =IFERROR(VLOOKUP($D11,BS연결,MATCH(W$1,BS연결H,0),0)/100,"") | X11: =IFERROR(VLOOKUP($D11,BS연결,MATCH(X$1,BS연결H,0),0)/100,"") | ... AB11: =IFERROR(VLOOKUP($D11,BS연결,MATCH(AB$1,BS연결H,0),0)/100,"") | AC11: =IFERROR(AC12+AC13,"") | AD11: =IFERROR(AD12+AD13,"") | AE11: =SUM(AA11:AD11) | AF11: =IFERROR(AF12+AF13,"") | AG11: =IFERROR(AG12+AG13,"") | AH11: =IFERROR(AH12+AH13,"") | AI11: =IFERROR(AI12+AI13,"") | AJ11: =SUM(AF11:AI11) | AK11: =IFERROR(AK12+AK13,"") | AL11: =IFERROR(AL12+AL13,"") | AM11: =IFERROR(AM12+AM13,"") | AN11: =IFERROR(AN12+AN13,"") | AO11: =SUM(AK11:AN11)
A12: 이자손익 | B12: 손익 | C12: 억원 | D12: 이자손익 | K12: =SUM(G12:J12) | L12: =IFERROR(VLOOKUP($D12,BS별도,MATCH(L$1,BS별도H,0),0)/100,"") | M12: =IFERROR(VLOOKUP($D12,BS별도,MATCH(M$1,BS별도H,0),0)/100,"") | P12: =SUM(L12:O12) | U12: =SUM(Q12:T12) | Z12: =SUM(V12:Y12) | AC12: =IFERROR((AB27*변수!$D$52-AB25*변수!$D$53)/4,"") | AD12: =IFERROR((AC27*변수!$D$52-AC25*변수!$D$53)/4,"") | AE12: =SUM(AA12:AD12) | AF12: =IFERROR((AD27*변수!$D$52-AD25*변수!$D$53)/4,"") | AG12: =IFERROR((AF27*변수!$D$52-AF25*변수!$D$53)/4,"") | AH12: =IFERROR((AG27*변수!$D$52-AG25*변수!$D$53)/4,"") | AI12: =IFERROR((AH27*변수!$D$52-AH25*변수!$D$53)/4,"") | AJ12: =SUM(AF12:AI12) | AK12: =IFERROR((AI27*변수!$D$52-AI25*변수!$D$53)/4,"") | AL12: =IFERROR((AK27*변수!$D$52-AK25*변수!$D$53)/4,"") | AM12: =IFERROR((AL27*변수!$D$52-AL25*변수!$D$53)/4,"") | AN12: =IFERROR((AM27*변수!$D$52-AM25*변수!$D$53)/4,"") | AO12: =SUM(AK12:AN12)
A13: 파생상품손익 | B13: 손익 | C13: 억원 | D13: 파생상품손익 | K13: =SUM(G13:J13) | P13: =SUM(L13:O13) | U13: =SUM(Q13:T13) | Z13: =SUM(V13:Y13) | AB13: =IFERROR((VLOOKUP("파생상품이익",BS연결,MATCH(AB$1,BS연결H,0),0)-VLOOKUP("파생상품손실",BS연결,MATCH(AB$1,BS연결H,0),0))/100,"") | AC13: =변수!AC24 | AD13: =변수!AD24 | AE13: =SUM(AA13:AD13) | AF13: =변수!AF24 | AG13: =변수!AG24 | AH13: =변수!AH24 | AI13: =변수!AI24 | AJ13: =SUM(AF13:AI13) | AK13: =변수!AK24 | AL13: =변수!AL24 | AM13: =변수!AM24 | AN13: =변수!AN24 | AO13: =SUM(AK13:AN13)
