Workbook
Name 변수H: 변수!$C$1:$W$1
Name 환율: 변수!$C$6:$W$13
Name BS연결H: BS연결!$C$1:$W$1
Name BS연결: BS연결!$C$5:$W$5
Name BS별도H: BS별도!$C$1:$W$1
Name BS별도: BS별도!$C$5:$W$76
Name SUBQH: subQ!$A$1:$W$1
Name subQ: subQ!$A$5:$W$39

Sheet README
A1: 원일티엔아이(136150) 실적 모델 — ARGUS 한국조선
A2: 기준 분기 2026Q2 · 마지막 실적 2026Q2 · 생성 2026-10-14
A3: 모든 수치는 모델 산출값(DART 공개 재무제표 + 우리 추정)이다 — 목표주가·투자 추천 아님. 참고용 · 투자조언 아님.
A5: 시트
A6: 변수 가정 시계열. 환율 8행(ECB via frankfurter — L2 fx.json; 추정 분기 = 노란 가정), 추정 드라이버(노란 셀 = 모델값에서 역산한 가정, 바꾸면 재계산; 연녹 셀 = 3절 스칼라 참조 수식), 3절 스칼라 가정(세율·판관비율·지배주주비중·이자율·종가·PER 밴드·COE·외화 순노출·헤지비율)
A7: BS연결/BS별도 FnGuide 계정명 × 기간 값 덤프(백만원). 행1 분기라벨, 행4 YYYY.MM / YYYY.12A. 이름정의 BS연결H·BS연결(계정명 C열부터)
A8: subQ 분기 서브모델(억원 = 백만원/100). 확정 행: =IFERROR(VLOOKUP($D행,BS연결,MATCH(E$1,BS연결H,0),0)/100,"") 추정 행: 변수 시트 가정 셀 참조 수식. 외환손익·파생상품손익은 BS 계정 합·차, 기타금융손익은 잔차, OPM·EPS·BPS·PER·PBR 은 파생 수식
A9: SLS 선표(조선사만, sls json 있을 때): 요약 행(sls 저장값) + 계약별 스케줄(백만$) × (헤지비율 × 헤지환율 + (1−헤지비율) × 건조시점 환율[변수 원/달러(평균)]) → 원화 수식 블록 → 합계 행이 subQ 매출조선에 연결
A10: 시나리오 신규수주 보수/기준/낙관(forecast_panel 패널, 모델에 scenarios 가 있을 때만): 매출액·영업이익 = subQ 기준값 ± (시나리오 신규 − base 신규) × OPM. base 만 subQ 행에 포함, 나머지는 합산 안 함
A11: 분기/연간예상 subQ 를 이름(A열 key)으로 VLOOKUP 한 보고서 표(억원)
A12: TP PER 밴드 × 12M fwd EPS, PBR = ROE/COE × BPS — 모델 산출값 구간, 목표주가·추천 아님
A13: 외화 환율 QoQ, 외화 순노출 × Δ기말환율 → 환관련손익 추정
... A34: 백테스트: {"freeze": "2025Q2", "horizon": 4, "revenue_wape_pct": 44.7, "op_wape_pct": 116.1, "n": 4, "note": "단일 회사 4분기 — 통계 아님", "driver_at_freeze": "trend_seasonal", "selection_oos_at_freeze": null, "frozen_inputs": "fin(연결/별도)·고객 조선사 모델·지주 자회사 모델은 2025Q2 까지의 분기만; 선표는 체결일 ≤ 2025Q2 말일 계약(원장 최신 금액·코호트 등급, 환산 없음); 잔고는 yards_cache 2025Q2; 시세·환율 forward·prices·forecast_panel 신규수주 미사용. 고객 가중치(suppliers.json 언급 비중)와 합병 체인링크는 현재 지식; 고객 연동 채택은 동결 모델 안에서도 자기 la−4분기 OOS 규칙(selection_oos_at_freeze)", "detail": [{"q": "2025Q3", "rev_pred": 68.89, "rev_act": 42.66, "op_pred": -13.78, "op_act": -10.14}, {"q": "2025Q4", "rev_pred": 68.89, "rev_act": 116.45, "op_pred": -13.78, "op_act": 9.48}, {"q": "2026Q1", "rev_pred": 68.89, "rev_act": 39.88, "op_pred": -13.78, "op_act": -20.14}, {"q": "2026Q2", "rev_pred": 68.89, "rev_act": 99.52, "op_pred": -13.78, "op_act": 5.43}]}

Sheet 변수
C1: 이름: 변수H | E1: 2Q25 | F1: 3Q25 | G1: 4Q25 | H1: 2025 | I1: 1Q26 | J1: 2Q26 | K1: 3Q26 | L1: 4Q26 | M1: 2026 | N1: 1Q27 | O1: 2Q27 | P1: 3Q27 | Q1: 4Q27 | R1: 2027 | S1: 1Q28 | T1: 2Q28 | U1: 3Q28 | V1: 4Q28 | W1: 2028
A2: 가정 시계열 — 노란 셀은 추정 가정(모델값에서 역산), 연녹 셀은 3절 스칼라 참조 수식. 바꾸면 subQ·분기·연간예상·TP·시나리오가 재계산됩니다.
E3: 1 | F3: 2 | G3: 3 | H3: 4 | I3: 5 | J3: 6 | K3: 7 | L3: 8 | M3: 9 | N3: 10 | O3: 11 | P3: 12 | Q3: 13 | R3: 14 | S3: 15 | T3: 16 | U3: 17 | V3: 18 | W3: 19
E4: 2025.06 | F4: 2025.09 | G4: 2025.12 | H4: 2025.12A | I4: 2026.03 | J4: 2026.06 | K4: 2026.09 | L4: 2026.12 | M4: 2026.12A | N4: 2027.03 | O4: 2027.06 | P4: 2027.09 | Q4: 2027.12 | R4: 2027.12A | S4: 2028.03 | T4: 2028.06 | U4: 2028.09 | V4: 2028.12 | W4: 2028.12A
B5: 1. FX | C5: 이름: 환율
A6: USDKRW_avg | C6: 원/달러(평균) | E6: 1398.52 | F6: 1386.95 | G6: 1449.19 | H6: 1421.52 | I6: 1466.12 | J6: 1501.75 | K6: 1418.75 | L6: 1343.39 | M6: 1456.01 | N6: 1341.45 | O6: 1341.45 | P6: 1341.45 | Q6: 1341.45 | S6: 1341.45 | T6: 1341.45 | U6: 1341.45 | V6: 1341.45
A7: USDKRW_end | C7: 원/달러(기말) | E7: 1355.13 | F7: 1403.67 | G7: 1444.2 | H7: 1444.2 | I7: 1524.8 | J7: 1550.89 | K7: 1355.4 | L7: 1341.45 | M7: 1341.45 | N7: 1341.45 | O7: 1341.45 | P7: 1341.45 | Q7: 1341.45 | S7: 1341.45 | T7: 1341.45 | U7: 1341.45 | V7: 1341.45
A8: JPY100KRW_avg | C8: 원/100Y(평균) | E8: 967.92 | F8: 940.32 | G8: 940.77 | H8: 950.17 | I8: 934.39 | J8: 942.16 | K8: 890.41 | L8: 849.39 | M8: 918.46 | N8: 848.37 | O8: 848.37 | P8: 848.37 | Q8: 848.37 | S8: 848.37 | T8: 848.37 | U8: 848.37 | V8: 848.37
A9: JPY100KRW_end | C9: 원/100Y(기말) | E9: 938.85 | F9: 948.49 | G9: 921.81 | H9: 921.81 | I9: 955.99 | J9: 954.75 | K9: 863.31 | L9: 848.37 | M9: 848.37 | N9: 848.37 | O9: 848.37 | P9: 848.37 | Q9: 848.37 | S9: 848.37 | T9: 848.37 | U9: 848.37 | V9: 848.37
A10: EURKRW_avg | C10: W/Euro(평균) | E10: 1585.13 | F10: 1620.04 | G10: 1686.02 | H10: 1605.45 | I10: 1715.47 | J10: 1746.09 | K10: 1631.97 | L10: 1506.62 | M10: 1688.01 | N10: 1500.82 | O10: 1500.82 | P10: 1500.82 | Q10: 1500.82 | S10: 1500.82 | T10: 1500.82 | U10: 1500.82 | V10: 1500.82
A11: EURKRW_end | C11: W/Euro(기말) | E11: 1588.22 | F11: 1648.04 | G11: 1696.94 | H11: 1696.94 | I11: 1753.21 | J11: 1767.09 | K11: 1539.06 | L11: 1500.82 | M11: 1500.82 | N11: 1500.82 | O11: 1500.82 | P11: 1500.82 | Q11: 1500.82 | S11: 1500.82 | T11: 1500.82 | U11: 1500.82 | V11: 1500.82
A12: CNYKRW_avg | C12: 원/중국원(평균) | E12: 193.41 | F12: 193.79 | G12: 204.38 | H12: 197.8 | I12: 211.75 | J12: 220.8 | K12: 210.43 | L12: 200.49 | M12: 213.61 | N12: 200.4 | O12: 200.4 | P12: 200.4 | Q12: 200.4 | S12: 200.4 | T12: 200.4 | U12: 200.4 | V12: 200.4
A13: CNYKRW_end | C13: 원/중국원(기말) | E13: 189.14 | F13: 197.16 | G13: 206.28 | H13: 206.28 | I13: 220.97 | J13: 228.56 | K13: 202.16 | L13: 200.4 | M13: 200.4 | N13: 200.4 | O13: 200.4 | P13: 200.4 | Q13: 200.4 | S13: 200.4 | T13: 200.4 | U13: 200.4 | V13: 200.4
B14: 1b. 종가
A15: price_close_end | C15: 종가(기말) | E15: 29650 | F15: 22050 | G15: 18390 | I15: 17190 | J15: 10820 | K15: 8580 | L15: 9860
A16: price_high | C16: 종가(최고) | E16: 41800 | F16: 29200 | G16: 29150 | I16: 21900 | J16: 19710 | K16: 12000 | L16: 15020
A17: price_low | C17: 종가(최저) | E17: 23600 | F17: 18900 | G17: 18170 | I17: 14000 | J17: 9030 | K17: 5400 | L17: 8350
A18: price_avg | C18: 종가(평균) | E18: 28574.3 | F18: 24211.2 | G18: 20802.2 | I18: 17932.9 | J18: 14728.7 | K18: 7830.5 | L18: 11665
B20: 2. 추정 드라이버 | C20: 실적 열 = subQ 실현값(수식), 추정 열 = 가정(노란 = 모델값 역산, 연녹 = 3절 스칼라 참조)
A21: drv:매출액 | B21: yoy | C21: 매출액 YoY | J21: =IFERROR(subQ!J5/subQ!E5-1,"") | K21: -5.3912e-05 | L21: -3.6924e-05 | N21: -0.000112826 | O21: 4.4214e-05 | P21: 0 | Q21: 0 | S21: 0 | T21: 0 | U21: 0 | V21: 0
A22: drv:판관비 | B22: ratio | C22: 판관비율(/매출) | E22: =IFERROR(subQ!E8/subQ!E5,"") | F22: =IFERROR(subQ!F8/subQ!F5,"") | G22: =IFERROR(subQ!G8/subQ!G5,"") | H22: =IFERROR(subQ!H8/subQ!H5,"") | I22: =IFERROR(subQ!I8/subQ!I5,"") | J22: =IFERROR(subQ!J8/subQ!J5,"") | K22: =$D$48 | L22: =$D$48 | M22: =IFERROR(subQ!M8/subQ!M5,"") | N22: =$D$48 | O22: =$D$48 | P22: =$D$48 | Q22: =$D$48 | R22: =IFERROR(subQ!R8/subQ!R5,"") | S22: =$D$48 | T22: =$D$48 | U22: =$D$48 | V22: =$D$48 | W22: =IFERROR(subQ!W8/subQ!W5,"")
A23: drv:영업이익 | B23: ratio | C23: 영업이익률(OPM) | E23: =IFERROR(subQ!E9/subQ!E5,"") | F23: =IFERROR(subQ!F9/subQ!F5,"") | G23: =IFERROR(subQ!G9/subQ!G5,"") | H23: =IFERROR(subQ!H9/subQ!H5,"") | I23: =IFERROR(subQ!I9/subQ!I5,"") | J23: =IFERROR(subQ!J9/subQ!J5,"") | K23: -0.19995312 | L23: -0.2 | M23: =IFERROR(subQ!M9/subQ!M5,"") | N23: -0.2001003 | O23: -0.19995981 | P23: -0.19995312 | Q23: -0.2 | R23: =IFERROR(subQ!R9/subQ!R5,"") | S23: -0.2001003 | T23: -0.19995981 | U23: -0.19995312 | V23: -0.2 | W23: =IFERROR(subQ!W9/subQ!W5,"")
A24: drv:기타영업외손익 | B24: abs | C24: 기타영업외손익 (가정, 억원) | E24: =subQ!E13 | F24: =subQ!F13 | G24: =subQ!G13 | H24: =subQ!H13 | I24: =subQ!I13 | J24: =subQ!J13 | K24: 0 | L24: 0 | M24: =subQ!M13 | N24: 0 | O24: 0 | P24: 0 | Q24: 0 | R24: =subQ!R13 | S24: 0 | T24: 0 | U24: 0 | V24: 0 | W24: =subQ!W13
A25: drv:법인세비용 | B25: ratio | C25: 법인세율(/세전) | E25: =IFERROR(subQ!E15/subQ!E14,"") | F25: =IFERROR(subQ!F15/subQ!F14,"") | G25: =IFERROR(subQ!G15/subQ!G14,"") | H25: =IFERROR(subQ!H15/subQ!H14,"") | I25: =IFERROR(subQ!I15/subQ!I14,"") | J25: =IFERROR(subQ!J15/subQ!J14,"") | K25: 0 | L25: 0 | M25: =IFERROR(subQ!M15/subQ!M14,"") | N25: 0 | O25: 0 | P25: 0 | Q25: 0 | R25: =IFERROR(subQ!R15/subQ!R14,"") | S25: 0 | T25: 0 | U25: 0 | V25: 0 | W25: =IFERROR(subQ!W15/subQ!W14,"")
A26: drv:지배주주순이익 | B26: ratio | C26: 지배주주 비중(/당기순이익) | E26: =IFERROR(subQ!E17/subQ!E16,"") | F26: =IFERROR(subQ!F17/subQ!F16,"") | G26: =IFERROR(subQ!G17/subQ!G16,"") | H26: =IFERROR(subQ!H17/subQ!H16,"") | I26: =IFERROR(subQ!I17/subQ!I16,"") | J26: =IFERROR(subQ!J17/subQ!J16,"") | K26: =$D$49 | L26: =$D$49 | M26: =IFERROR(subQ!M17/subQ!M16,"") | N26: =$D$49 | O26: =$D$49 | P26: =$D$49 | Q26: =$D$49 | R26: =IFERROR(subQ!R17/subQ!R16,"") | S26: =$D$49 | T26: =$D$49 | U26: =$D$49 | V26: =$D$49 | W26: =IFERROR(subQ!W17/subQ!W16,"")
A27: drv:부채총계 | B27: qoq | C27: 부채총계 QoQ | F27: =IFERROR(subQ!F19/subQ!E19-1,"") | G27: =IFERROR(subQ!G19/subQ!F19-1,"") | I27: =IFERROR(subQ!I19/subQ!G19-1,"") | J27: =IFERROR(subQ!J19/subQ!I19-1,"") | K27: -9.735e-06 | L27: 0 | N27: 0 | O27: 0 | P27: 0 | Q27: 0 | S27: 0 | T27: 0 | U27: 0 | V27: 0
A28: drv:자본총계 | B28: roll | C28: 자본총계 기타변동(배당 등, 억원) | F28: =IFERROR(subQ!E20+subQ!F16-subQ!F20,"") | G28: =IFERROR(subQ!F20+subQ!G16-subQ!G20,"") | I28: =IFERROR(subQ!G20+subQ!I16-subQ!I20,"") | J28: =IFERROR(subQ!I20+subQ!J16-subQ!J20,"") | K28: 0.002957824 | L28: 0.000885174 | N28: -0.006614541 | O28: 0.007439472 | P28: 0.001035279 | Q28: 0.002890469 | S28: -0.005285804 | T28: -0.001908349 | U28: 0.0010109 | V28: 0.002189532
A29: drv:지배주주지분 | B29: roll | C29: 지배주주지분 기타변동(배당 등, 억원) | F29: =IFERROR(subQ!E21+subQ!F17-subQ!F21,"") | G29: =IFERROR(subQ!F21+subQ!G17-subQ!G21,"") | I29: =IFERROR(subQ!G21+subQ!I17-subQ!I21,"") | J29: =IFERROR(subQ!I21+subQ!J17-subQ!J21,"") | K29: 0.002957824 | L29: 0.000885174 | N29: -0.006614541 | O29: 0.007439472 | P29: 0.001035279 | Q29: 0.002890469 | S29: -0.005285804 | T29: -0.001908349 | U29: 0.0010109 | V29: 0.002189532
A30: drv:총차입금 | B30: qoq | C30: 총차입금 QoQ | F30: =IFERROR(subQ!F22/subQ!E22-1,"") | G30: =IFERROR(subQ!G22/subQ!F22-1,"") | I30: =IFERROR(subQ!I22/subQ!G22-1,"") | J30: =IFERROR(subQ!J22/subQ!I22-1,"") | K30: 0 | L30: 0 | N30: 0 | O30: 0 | P30: 0 | Q30: 0 | S30: 0 | T30: 0 | U30: 0 | V30: 0
A31: drv:순차입금 | B31: qoq | C31: 순차입금 QoQ | F31: =IFERROR(subQ!F23/subQ!E23-1,"") | G31: =IFERROR(subQ!G23/subQ!F23-1,"") | I31: =IFERROR(subQ!I23/subQ!G23-1,"") | J31: =IFERROR(subQ!J23/subQ!I23-1,"") | K31: -0.85846765 | L31: -17.097015 | N31: 0.35558646 | O31: 0.67099863 | P31: 0.17028244 | Q31: 0.4041623 | S31: 0.098019679 | T31: 0.22493194 | U31: 0.078896194 | V31: 0.20006866
A32: drv:이자발생자산 | B32: qoq | C32: 이자발생자산 QoQ | F32: =IFERROR(subQ!F24/subQ!E24-1,"") | G32: =IFERROR(subQ!G24/subQ!F24-1,"") | I32: =IFERROR(subQ!I24/subQ!G24-1,"") | J32: =IFERROR(subQ!J24/subQ!I24-1,"") | K32: -0.06721189 | L32: -0.20326502 | N32: -0.085412027 | O32: -0.23901132 | P32: -0.13312 | Q32: -0.42654116 | S32: -0.253299 | T32: -0.85474138 | U32: -2.5281899 | V32: 4.5242718
A33: drv:현금및현금성자산 | B33: qoq | C33: 현금및현금성자산 QoQ | F33: =IFERROR(subQ!F25/subQ!E25-1,"") | G33: =IFERROR(subQ!G25/subQ!F25-1,"") | I33: =IFERROR(subQ!I25/subQ!G25-1,"") | J33: =IFERROR(subQ!J25/subQ!I25-1,"")
A34: drv:CAPEX | B34: yoy | C34: CAPEX YoY | J34: =IFERROR(subQ!J26/subQ!E26-1,"") | K34: 1.5761124 | L34: -0.77328937 | N34: 0.21078701 | O34: -0.13589945 | P34: 0 | Q34: 0 | S34: 0 | T34: 0 | U34: 0 | V34: 0
A35: drv:영업활동현금흐름 | B35: yoy | C35: 영업활동현금흐름 YoY | J35: =IFERROR(subQ!J27/subQ!E27-1,"")
A36: drv:주식수 | B36: qoq | C36: 주식수 QoQ | F36: =IFERROR(subQ!F28/subQ!E28-1,"") | G36: =IFERROR(subQ!G28/subQ!F28-1,"") | I36: =IFERROR(subQ!I28/subQ!G28-1,"") | J36: =IFERROR(subQ!J28/subQ!I28-1,"") | K36: 0 | L36: 0 | N36: 0 | O36: 0 | P36: 0 | Q36: 0 | S36: 0 | T36: 0 | U36: 0 | V36: 0
A37: drv:DPS | B37: abs | C37: DPS (가정, 원) | E37: =subQ!E31 | F37: =subQ!F31 | G37: =subQ!G31 | H37: =subQ!H31 | I37: =subQ!I31 | J37: =subQ!J31 | L37: 0 | M37: =subQ!M31 | Q37: 0 | R37: =subQ!R31 | V37: 0 | W37: =subQ!W31
B39: 3. 밸류에이션·스칼라 | C39: 노란 셀 = 가정. '연결' 표시는 추정 전 분기 수식이 이 셀을 참조한다는 뜻
A40: sc:종가 | C40: 종가 | D40: 9860 | E40: 원 — 네이버 정규장 종가(aik 확정종가 대조 · aik 10,650원)
A41: sc:기준일 | C41: 기준일 | D41: 20261014 | E41: 종가 기준일
A42: sc:COE | C42: COE | D42: 0.09 | E42: 자기자본비용(가정) — TP 적정 PBR = ROE/COE
...

Sheet BS연결
B1: (백만원) | C1: 이름: BS연결H | E1: 2Q25 | F1: 3Q25 | G1: 4Q25 | H1: 2025 | I1: 1Q26 | J1: 2Q26 | K1: 3Q26 | L1: 4Q26 | M1: 2026 | N1: 1Q27 | O1: 2Q27 | P1: 3Q27 | Q1: 4Q27 | R1: 2027 | S1: 1Q28 | T1: 2Q28 | U1: 3Q28 | V1: 4Q28 | W1: 2028
B2: 연결 | D2: fin json(kship_fin.py)
B3: 원일티엔아이(연) | C3: UPDATE: 26-10-14 | E3: 1 | F3: 2 | G3: 3 | H3: 4 | I3: 5 | J3: 6 | K3: 7 | L3: 8 | M3: 9 | N3: 10 | O3: 11 | P3: 12 | Q3: 13 | R3: 14 | S3: 15 | T3: 16 | U3: 17 | V3: 18 | W3: 19
B4: Account Code | C4: AccountNAME | E4: 2025.06 | F4: 2025.09 | G4: 2025.12 | H4: 2025.12A | I4: 2026.03 | J4: 2026.06 | K4: 2026.09 | L4: 2026.12 | M4: 2026.12A | N4: 2027.03 | O4: 2027.06 | P4: 2027.09 | Q4: 2027.12 | R4: 2027.12A | S4: 2028.03 | T4: 2028.06 | U4: 2028.09 | V4: 2028.12 | W4: 2028.12A

Sheet BS별도
B1: (백만원) | C1: 이름: BS별도H | E1: 2Q25 | F1: 3Q25 | G1: 4Q25 | H1: 2025 | I1: 1Q26 | J1: 2Q26 | K1: 3Q26 | L1: 4Q26 | M1: 2026 | N1: 1Q27 | O1: 2Q27 | P1: 3Q27 | Q1: 4Q27 | R1: 2027 | S1: 1Q28 | T1: 2Q28 | U1: 3Q28 | V1: 4Q28 | W1: 2028
B2: 별도 | D2: fin json(kship_fin.py)
B3: 원일티엔아이(별) | C3: UPDATE: 26-10-14 | E3: 1 | F3: 2 | G3: 3 | H3: 4 | I3: 5 | J3: 6 | K3: 7 | L3: 8 | M3: 9 | N3: 10 | O3: 11 | P3: 12 | Q3: 13 | R3: 14 | S3: 15 | T3: 16 | U3: 17 | V3: 18 | W3: 19
B4: Account Code | C4: AccountNAME | E4: 2025.06 | F4: 2025.09 | G4: 2025.12 | H4: 2025.12A | I4: 2026.03 | J4: 2026.06 | K4: 2026.09 | L4: 2026.12 | M4: 2026.12A | N4: 2027.03 | O4: 2027.06 | P4: 2027.09 | Q4: 2027.12 | R4: 2027.12A | S4: 2028.03 | T4: 2028.06 | U4: 2028.09 | V4: 2028.12 | W4: 2028.12A
A5: 1 | C5: 유동자산 | E5: 37933.84 | F5: 36420.19 | G5: 34371.29 | H5: 34371.29 | I5: 38045.57 | J5: 43632.35
A6: 1 | C6: 현금및현금성자산 | E6: 3043.13 | F6: 13383.7 | G6: 4428 | H6: 4428 | I6: 11312.96 | J6: 8905.03
A7: 1 | C7: 매출채권및기타채권 | E7: 18118.45 | F7: 7172.37 | G7: 8838.76 | H7: 8838.76 | I7: 6902.35 | J7: 9924.05
A8: 1 | C8: 계약자산 | E8: 7715.91 | F8: 5084.23 | G8: 8072.2 | H8: 8072.2 | I8: 9027.61 | J8: 14542.42
A9: 1 | C9: 단기금융상품 | E9: 2149.76 | F9: 2222.35 | G9: 5274.17 | H9: 5274.17 | J9: 41.75
A10: 1 | C10: 단기금융자산 | E10: 2149.76 | F10: 2222.35 | G10: 5274.17 | H10: 5274.17 | J10: 41.75
A11: 1 | C11: 재고자산 | E11: 5429.59 | F11: 5964.96 | G11: 6815.91 | H11: 6815.91 | I11: 7700.64 | J11: 6861.12
A12: 1 | C12: 기타유동자산 | E12: 1476.99 | F12: 2589.67 | G12: 930.6 | H12: 930.6 | I12: 3070.06 | J12: 3336.16
A13: 1 | C13: 비유동자산 | E13: 30031.38 | F13: 29926.19 | G13: 30429.99 | H13: 30429.99 | I13: 30103.1 | J13: 29988.35
A14: 1 | C14: 장기금융자산 | E14: 3033.77 | F14: 3103.46 | G14: 3172.14 | H14: 3172.14 | I14: 3110.12 | J14: 3136.35
A15: 1 | C15: 투자자산 | E15: 3033.77 | F15: 3103.46 | G15: 3172.14 | H15: 3172.14 | I15: 3110.12 | J15: 3136.35
A16: 1 | C16: 유형자산 | E16: 20095.9 | F16: 19993.58 | G16: 19889.64 | H16: 19889.64 | I16: 19799.87 | J16: 19715.96
A17: 1 | C17: 투자부동산 | E17: 539.82 | F17: 536.04 | G17: 532.25 | H17: 532.25 | I17: 528.47 | J17: 524.69
A18: 1 | C18: 사용권자산 | E18: 133.01 | F18: 189.26 | G18: 158.06 | H18: 158.06 | I18: 116.08 | J18: 84.63
A19: 1 | C19: 기타비유동자산 | E19: 133.01 | F19: 189.26 | G19: 158.06 | H19: 158.06 | I19: 116.08 | J19: 84.63
A20: 1 | C20: 무형자산 | E20: 5208.36 | F20: 5083.33 | G20: 5043.88 | H20: 5043.88 | I20: 4914.54 | J20: 4785.2
A21: 1 | C21: 장기매출채권및기타채권 | E21: 27.92 | F21: 27.92 | G21: 20.65 | H21: 20.65 | I21: 20.65 | J21: 56.99
A22: 1 | C22: 이연법인세자산 | E22: 992.6 | F22: 992.6 | G22: 1613.37 | H22: 1613.37 | I22: 1613.37 | J22: 1684.53
... A30: 1 | C30: 단기금융부채 | E30: 69.95 | F30: 140.03 | G30: 121.24 | H30: 121.24 | I30: 89.13 | J30: 66.16
A31: 1 | C31: 당기법인세부채(미지급법인세) | E31: 865.55 | F31: 327.39 | I31: 223.12 | J31: 238.82
A32: 1 | C32: 비유동부채 | E32: 1979.63 | F32: 2047.65 | G32: 1157.52 | H32: 1157.52 | I32: 1223.83 | J32: 1130.53
A33: 1 | C33: 비유동리스부채 | E33: 61.15 | F33: 45.01 | G33: 34.51 | H33: 34.51 | I33: 26.12 | J33: 18.9
A34: 1 | C34: 장기금융부채 | E34: 61.15 | F34: 45.01 | G34: 34.51 | H34: 34.51 | I34: 26.12 | J34: 18.9
A35: 1 | C35: 기타비유동부채 | E35: 21.2 | F35: 21.2 | G35: 21.2 | H35: 21.2 | I35: 21.2 | J35: 21.2
A36: 1 | C36: 부채총계 | E36: 21015.46 | F36: 20094.49 | G36: 16566.71 | H36: 16566.71 | I36: 21287.91 | J36: 25680.25
A37: 1 | C37: 자본금 | E37: 4190.51 | F37: 4190.51 | G37: 4190.51 | H37: 4190.51 | I37: 4190.51 | J37: 4190.51
A38: 1 | C38: 자본잉여금 | E38: 13591.96 | F38: 13591.96 | G38: 13591.96 | H38: 13591.96 | I38: 13591.96 | J38: 13591.96
A39: 1 | C39: 기타자본 | E39: 4296.12 | F39: 4296.12 | G39: 4296.12 | H39: 4296.12 | I39: 4296.12 | J39: 4296.12
A40: 1 | C40: 이익잉여금 | E40: 24871.16 | F40: 24173.3 | G40: 26155.98 | H40: 26155.98 | I40: 24782.17 | J40: 25861.87
A41: 1 | C41: 자본총계 | E41: 46949.76 | F41: 46251.9 | G41: 48234.57 | H41: 48234.57 | I41: 46860.76 | J41: 47940.46
A42: 1 | C42: 부채와자본총계 | E42: 67965.22 | F42: 66346.38 | G42: 64801.28 | H42: 64801.28 | I42: 68148.67 | J42: 73620.7
A43: 1 | C43: 지배주주지분 | E43: 46949.76 | F43: 46251.9 | G43: 48234.57 | H43: 48234.57 | I43: 46860.76 | J43: 47940.46
... A46: 1 | C46: 이자발생자산 | E46: 8226.66 | F46: 18709.51 | G46: 12874.31 | H46: 12874.31 | I46: 14423.08 | J46: 12083.13
A47: 1 | C47: 당기법인세자산(선급법인세) | F47: 2.92 | G47: 11.65 | H47: 11.65 | I47: 31.95 | J47: 21.83
A48: 1 | C48: 기타유동부채 | G48: 245.62 | H48: 245.62 | I48: 62.47 | J48: 64.82
A49: 1 | C49: 매출액(수익) | E49: 6888.5 | F49: 4266.23 | G49: 11645.43 | I49: 3988.45 | J49: 9951.56
...

Sheet subQ
A1: YQ | C1: subQ 분기 서브모델(억원, U=100) | E1: 2Q25 | F1: 3Q25 | G1: 4Q25 | H1: 2025 | I1: 1Q26 | J1: 2Q26 | K1: 3Q26 | L1: 4Q26 | M1: 2026 | N1: 1Q27 | O1: 2Q27 | P1: 3Q27 | Q1: 4Q27 | R1: 2027 | S1: 1Q28 | T1: 2Q28 | U1: 3Q28 | V1: 4Q28 | W1: 2028
A2: A=이름(key) B=그룹 C=단위 D=FnGuide 계정명(VLOOKUP 키). 확정=VLOOKUP(BS), 추정=변수 가정 참조
E3: 1 | F3: 2 | G3: 3 | H3: 4 | I3: 5 | J3: 6 | K3: 7 | L3: 8 | M3: 9 | N3: 10 | O3: 11 | P3: 12 | Q3: 13 | R3: 14 | S3: 15 | T3: 16 | U3: 17 | V3: 18 | W3: 19
E4: 2025.06 | F4: 2025.09 | G4: 2025.12 | H4: 2025.12A | I4: 2026.03 | J4: 2026.06 | K4: 2026.09 | L4: 2026.12 | M4: 2026.12A | N4: 2027.03 | O4: 2027.06 | P4: 2027.09 | Q4: 2027.12 | R4: 2027.12A | S4: 2028.03 | T4: 2028.06 | U4: 2028.09 | V4: 2028.12 | W4: 2028.12A
A5: 매출액 | B5: 손익 | C5: 억원 | D5: 매출액(수익) | E5: =IFERROR(VLOOKUP($D5,BS별도,MATCH(E$1,BS별도H,0),0)/100,"") | F5: =IFERROR(VLOOKUP($D5,BS별도,MATCH(F$1,BS별도H,0),0)/100,"") | G5: =IFERROR(VLOOKUP($D5,BS별도,MATCH(G$1,BS별도H,0),0)/100,"") | I5: =IFERROR(VLOOKUP($D5,BS별도,MATCH(I$1,BS별도H,0),0)/100,"") | J5: =IFERROR(VLOOKUP($D5,BS별도,MATCH(J$1,BS별도H,0),0)/100,"") | K5: =IFERROR(F5*(1+변수!K21),"") | L5: =IFERROR(G5*(1+변수!L21),"") | M5: =SUM(I5:L5) | N5: =IFERROR(I5*(1+변수!N21),"") | O5: =IFERROR(J5*(1+변수!O21),"") | P5: =IFERROR(K5*(1+변수!P21),"") | Q5: =IFERROR(L5*(1+변수!Q21),"") | R5: =SUM(N5:Q5) | S5: =IFERROR(N5*(1+변수!S21),"") | T5: =IFERROR(O5*(1+변수!T21),"") | U5: =IFERROR(P5*(1+변수!U21),"") | V5: =IFERROR(Q5*(1+변수!V21),"") | W5: =SUM(S5:V5)
A6: 매출원가 | B6: 손익 | C6: 억원 | D6: 매출원가 | E6: =IFERROR(VLOOKUP($D6,BS별도,MATCH(E$1,BS별도H,0),0)/100,"") | F6: =IFERROR(VLOOKUP($D6,BS별도,MATCH(F$1,BS별도H,0),0)/100,"") | G6: =IFERROR(VLOOKUP($D6,BS별도,MATCH(G$1,BS별도H,0),0)/100,"") | I6: =IFERROR(VLOOKUP($D6,BS별도,MATCH(I$1,BS별도H,0),0)/100,"") | J6: =IFERROR(VLOOKUP($D6,BS별도,MATCH(J$1,BS별도H,0),0)/100,"") | K6: =IFERROR(K5-K7,"") | L6: =IFERROR(L5-L7,"") | M6: =SUM(I6:L6) | N6: =IFERROR(N5-N7,"") | O6: =IFERROR(O5-O7,"") | P6: =IFERROR(P5-P7,"") | Q6: =IFERROR(Q5-Q7,"") | R6: =SUM(N6:Q6) | S6: =IFERROR(S5-S7,"") | T6: =IFERROR(T5-T7,"") | U6: =IFERROR(U5-U7,"") | V6: =IFERROR(V5-V7,"") | W6: =SUM(S6:V6)
A7: 매출총이익 | B7: 손익 | C7: 억원 | D7: 매출총이익 | E7: =IFERROR(VLOOKUP($D7,BS별도,MATCH(E$1,BS별도H,0),0)/100,"") | F7: =IFERROR(VLOOKUP($D7,BS별도,MATCH(F$1,BS별도H,0),0)/100,"") | G7: =IFERROR(VLOOKUP($D7,BS별도,MATCH(G$1,BS별도H,0),0)/100,"") | I7: =IFERROR(VLOOKUP($D7,BS별도,MATCH(I$1,BS별도H,0),0)/100,"") | J7: =IFERROR(VLOOKUP($D7,BS별도,MATCH(J$1,BS별도H,0),0)/100,"") | K7: =IFERROR(K9+K8,"") | L7: =IFERROR(L9+L8,"") | M7: =SUM(I7:L7) | N7: =IFERROR(N9+N8,"") | O7: =IFERROR(O9+O8,"") | P7: =IFERROR(P9+P8,"") | Q7: =IFERROR(Q9+Q8,"") | R7: =SUM(N7:Q7) | S7: =IFERROR(S9+S8,"") | T7: =IFERROR(T9+T8,"") | U7: =IFERROR(U9+U8,"") | V7: =IFERROR(V9+V8,"") | W7: =SUM(S7:V7)
A8: 판관비 | B8: 손익 | C8: 억원 | D8: 판관비 | E8: =IFERROR(VLOOKUP($D8,BS별도,MATCH(E$1,BS별도H,0),0)/100,"") | F8: =IFERROR(VLOOKUP($D8,BS별도,MATCH(F$1,BS별도H,0),0)/100,"") | G8: =IFERROR(VLOOKUP($D8,BS별도,MATCH(G$1,BS별도H,0),0)/100,"") | I8: =IFERROR(VLOOKUP($D8,BS별도,MATCH(I$1,BS별도H,0),0)/100,"") | J8: =IFERROR(VLOOKUP($D8,BS별도,MATCH(J$1,BS별도H,0),0)/100,"") | K8: =IFERROR(K5*변수!K22,"") | L8: =IFERROR(L5*변수!L22,"") | M8: =SUM(I8:L8) | N8: =IFERROR(N5*변수!N22,"") | O8: =IFERROR(O5*변수!O22,"") | P8: =IFERROR(P5*변수!P22,"") | Q8: =IFERROR(Q5*변수!Q22,"") | R8: =SUM(N8:Q8) | S8: =IFERROR(S5*변수!S22,"") | T8: =IFERROR(T5*변수!T22,"") | U8: =IFERROR(U5*변수!U22,"") | V8: =IFERROR(V5*변수!V22,"") | W8: =SUM(S8:V8)
A9: 영업이익 | B9: 손익 | C9: 억원 | D9: 영업이익 | E9: =IFERROR(VLOOKUP($D9,BS별도,MATCH(E$1,BS별도H,0),0)/100,"") | F9: =IFERROR(VLOOKUP($D9,BS별도,MATCH(F$1,BS별도H,0),0)/100,"") | G9: =IFERROR(VLOOKUP($D9,BS별도,MATCH(G$1,BS별도H,0),0)/100,"") | I9: =IFERROR(VLOOKUP($D9,BS별도,MATCH(I$1,BS별도H,0),0)/100,"") | J9: =IFERROR(VLOOKUP($D9,BS별도,MATCH(J$1,BS별도H,0),0)/100,"") | K9: =IFERROR(K5*변수!K23,"") | L9: =IFERROR(L5*변수!L23,"") | M9: =SUM(I9:L9) | N9: =IFERROR(N5*변수!N23,"") | O9: =IFERROR(O5*변수!O23,"") | P9: =IFERROR(P5*변수!P23,"") | Q9: =IFERROR(Q5*변수!Q23,"") | R9: =SUM(N9:Q9) | S9: =IFERROR(S5*변수!S23,"") | T9: =IFERROR(T5*변수!T23,"") | U9: =IFERROR(U5*변수!U23,"") | V9: =IFERROR(V5*변수!V23,"") | W9: =SUM(S9:V9)
A10: OPM | B10: 손익 | C10: % | D10: 영업이익률 | E10: =IFERROR(E9/E5,"") | F10: =IFERROR(F9/F5,"") | G10: =IFERROR(G9/G5,"") | I10: =IFERROR(I9/I5,"") | J10: =IFERROR(J9/J5,"") | K10: =IFERROR(K9/K5,"") | L10: =IFERROR(L9/L5,"") | M10: =IFERROR(M9/M5,"") | N10: =IFERROR(N9/N5,"") | O10: =IFERROR(O9/O5,"") | P10: =IFERROR(P9/P5,"") | ... W10: =IFERROR(W9/W5,"")
A11: 금융손익 | B11: 손익 | C11: 억원 | D11: 금융손익 | E11: =IFERROR(VLOOKUP($D11,BS별도,MATCH(E$1,BS별도H,0),0)/100,"") | F11: =IFERROR(VLOOKUP($D11,BS별도,MATCH(F$1,BS별도H,0),0)/100,"") | G11: =IFERROR(VLOOKUP($D11,BS별도,MATCH(G$1,BS별도H,0),0)/100,"") | I11: =IFERROR(VLOOKUP($D11,BS별도,MATCH(I$1,BS별도H,0),0)/100,"") | J11: =IFERROR(VLOOKUP($D11,BS별도,MATCH(J$1,BS별도H,0),0)/100,"") | K11: =IFERROR(K12,"") | L11: =IFERROR(L12,"") | M11: =SUM(I11:L11) | N11: =IFERROR(N12,"") | O11: =IFERROR(O12,"") | P11: =IFERROR(P12,"") | Q11: =IFERROR(Q12,"") | R11: =SUM(N11:Q11) | S11: =IFERROR(S12,"") | T11: =IFERROR(T12,"") | U11: =IFERROR(U12,"") | V11: =IFERROR(V12,"") | W11: =SUM(S11:V11)
A12: 이자손익 | B12: 손익 | C12: 억원 | D12: 이자손익 | K12: =IFERROR((J24*변수!$D$50-J22*변수!$D$51)/4,"") | L12: =IFERROR((K24*변수!$D$50-K22*변수!$D$51)/4,"") | M12: =SUM(I12:L12) | N12: =IFERROR((L24*변수!$D$50-L22*변수!$D$51)/4,"") | O12: =IFERROR((N24*변수!$D$50-N22*변수!$D$51)/4,"") | P12: =IFERROR((O24*변수!$D$50-O22*변수!$D$51)/4,"") | Q12: =IFERROR((P24*변수!$D$50-P22*변수!$D$51)/4,"") | R12: =SUM(N12:Q12) | S12: =IFERROR((Q24*변수!$D$50-Q22*변수!$D$51)/4,"") | T12: =IFERROR((S24*변수!$D$50-S22*변수!$D$51)/4,"") | U12: =IFERROR((T24*변수!$D$50-T22*변수!$D$51)/4,"") | V12: =IFERROR((U24*변수!$D$50-U22*변수!$D$51)/4,"") | W12: =SUM(S12:V12)
A13: 기타영업외손익 | B13: 손익 | C13: 억원 | D13: 기타영업외손익 | E13: =IFERROR(VLOOKUP($D13,BS별도,MATCH(E$1,BS별도H,0),0)/100,"") | F13: =IFERROR(VLOOKUP($D13,BS별도,MATCH(F$1,BS별도H,0),0)/100,"") | G13: =IFERROR(VLOOKUP($D13,BS별도,MATCH(G$1,BS별도H,0),0)/100,"") | I13: =IFERROR(VLOOKUP($D13,BS별도,MATCH(I$1,BS별도H,0),0)/100,"") | J13: =IFERROR(VLOOKUP($D13,BS별도,MATCH(J$1,BS별도H,0),0)/100,"") | K13: =변수!K24 | L13: =변수!L24 | M13: =SUM(I13:L13) | N13: =변수!N24 | O13: =변수!O24 | P13: =변수!P24 | Q13: =변수!Q24 | R13: =SUM(N13:Q13) | S13: =변수!S24 | T13: =변수!T24 | U13: =변수!U24 | V13: =변수!V24 | W13: =SUM(S13:V13)
A14: 세전이익 | B14: 손익 | C14: 억원 | D14: 법인세비용차감전계속사업이익 | E14: =IFERROR(VLOOKUP($D14,BS별도,MATCH(E$1,BS별도H,0),0)/100,"") | F14: =IFERROR(VLOOKUP($D14,BS별도,MATCH(F$1,BS별도H,0),0)/100,"") | G14: =IFERROR(VLOOKUP($D14,BS별도,MATCH(G$1,BS별도H,0),0)/100,"") | I14: =IFERROR(VLOOKUP($D14,BS별도,MATCH(I$1,BS별도H,0),0)/100,"") | J14: =IFERROR(VLOOKUP($D14,BS별도,MATCH(J$1,BS별도H,0),0)/100,"") | K14: =IFERROR(K9+K11+K13,"") | L14: =IFERROR(L9+L11+L13,"") | M14: =SUM(I14:L14) | N14: =IFERROR(N9+N11+N13,"") | O14: =IFERROR(O9+O11+O13,"") | P14: =IFERROR(P9+P11+P13,"") | Q14: =IFERROR(Q9+Q11+Q13,"") | R14: =SUM(N14:Q14) | S14: =IFERROR(S9+S11+S13,"") | T14: =IFERROR(T9+T11+T13,"") | U14: =IFERROR(U9+U11+U13,"") | V14: =IFERROR(V9+V11+V13,"") | W14: =SUM(S14:V14)
A15: 법인세비용 | B15: 손익 | C15: 억원 | D15: 법인세비용 | E15: =IFERROR(VLOOKUP($D15,BS별도,MATCH(E$1,BS별도H,0),0)/100,"") | G15: =IFERROR(VLOOKUP($D15,BS별도,MATCH(G$1,BS별도H,0),0)/100,"") | J15: =IFERROR(VLOOKUP($D15,BS별도,MATCH(J$1,BS별도H,0),0)/100,"") | K15: =IFERROR(K14*변수!K25,"") | L15: =IFERROR(L14*변수!L25,"") | M15: =SUM(I15:L15) | N15: =IFERROR(N14*변수!N25,"") | O15: =IFERROR(O14*변수!O25,"") | P15: =IFERROR(P14*변수!P25,"") | Q15: =IFERROR(Q14*변수!Q25,"") | R15: =SUM(N15:Q15) | S15: =IFERROR(S14*변수!S25,"") | T15: =IFERROR(T14*변수!T25,"") | U15: =IFERROR(U14*변수!U25,"") | V15: =IFERROR(V14*변수!V25,"") | W15: =SUM(S15:V15)
A16: 당기순이익 | B16: 손익 | C16: 억원 | D16: 당기순이익 | E16: =IFERROR(VLOOKUP($D16,BS별도,MATCH(E$1,BS별도H,0),0)/100,"") | F16: =IFERROR(VLOOKUP($D16,BS별도,MATCH(F$1,BS별도H,0),0)/100,"") | G16: =IFERROR(VLOOKUP($D16,BS별도,MATCH(G$1,BS별도H,0),0)/100,"") | I16: =IFERROR(VLOOKUP($D16,BS별도,MATCH(I$1,BS별도H,0),0)/100,"") | J16: =IFERROR(VLOOKUP($D16,BS별도,MATCH(J$1,BS별도H,0),0)/100,"") | K16: =IFERROR(K14-K15,"") | L16: =IFERROR(L14-L15,"") | M16: =SUM(I16:L16) | N16: =IFERROR(N14-N15,"") | O16: =IFERROR(O14-O15,"") | P16: =IFERROR(P14-P15,"") | Q16: =IFERROR(Q14-Q15,"") | R16: =SUM(N16:Q16) | S16: =IFERROR(S14-S15,"") | T16: =IFERROR(T14-T15,"") | U16: =IFERROR(U14-U15,"") | V16: =IFERROR(V14-V15,"") | W16: =SUM(S16:V16)
A17: 지배주주순이익 | B17: 손익 | C17: 억원 | D17: (지배주주지분)당기순이익 | E17: =IFERROR(VLOOKUP($D17,BS별도,MATCH(E$1,BS별도H,0),0)/100,"") | F17: =IFERROR(VLOOKUP($D17,BS별도,MATCH(F$1,BS별도H,0),0)/100,"") | G17: =IFERROR(VLOOKUP($D17,BS별도,MATCH(G$1,BS별도H,0),0)/100,"") | I17: =IFERROR(VLOOKUP($D17,BS별도,MATCH(I$1,BS별도H,0),0)/100,"") | J17: =IFERROR(VLOOKUP($D17,BS별도,MATCH(J$1,BS별도H,0),0)/100,"") | K17: =IFERROR(K16*변수!K26,"") | L17: =IFERROR(L16*변수!L26,"") | M17: =SUM(I17:L17) | N17: =IFERROR(N16*변수!N26,"") | O17: =IFERROR(O16*변수!O26,"") | P17: =IFERROR(P16*변수!P26,"") | Q17: =IFERROR(Q16*변수!Q26,"") | R17: =SUM(N17:Q17) | S17: =IFERROR(S16*변수!S26,"") | T17: =IFERROR(T16*변수!T26,"") | U17: =IFERROR(U16*변수!U26,"") | V17: =IFERROR(V16*변수!V26,"") | W17: =SUM(S17:V17)
A18: 자산총계 | B18: 재무상태 | C18: 억원 | D18: 자산총계 | E18: =IFERROR(VLOOKUP($D18,BS별도,MATCH(E$1,BS별도H,0),0)/100,"") | F18: =IFERROR(VLOOKUP($D18,BS별도,MATCH(F$1,BS별도H,0),0)/100,"") | G18: =IFERROR(VLOOKUP($D18,BS별도,MATCH(G$1,BS별도H,0),0)/100,"") | H18: 648.01 | I18: =IFERROR(VLOOKUP($D18,BS별도,MATCH(I$1,BS별도H,0),0)/100,"") | J18: =IFERROR(VLOOKUP($D18,BS별도,MATCH(J$1,BS별도H,0),0)/100,"") | K18: =IFERROR(K19+K20,"") | L18: =IFERROR(L19+L20,"") | M18: =L18 | N18: =IFERROR(N19+N20,"") | O18: =IFERROR(O19+O20,"") | P18: =IFERROR(P19+P20,"") | Q18: =IFERROR(Q19+Q20,"") | R18: =Q18 | S18: =IFERROR(S19+S20,"") | T18: =IFERROR(T19+T20,"") | U18: =IFERROR(U19+U20,"") | V18: =IFERROR(V19+V20,"") | W18: =V18
A19: 부채총계 | B19: 재무상태 | C19: 억원 | D19: 부채총계 | E19: =IFERROR(VLOOKUP($D19,BS별도,MATCH(E$1,BS별도H,0),0)/100,"") | F19: =IFERROR(VLOOKUP($D19,BS별도,MATCH(F$1,BS별도H,0),0)/100,"") | G19: =IFERROR(VLOOKUP($D19,BS별도,MATCH(G$1,BS별도H,0),0)/100,"") | H19: 165.67 | I19: =IFERROR(VLOOKUP($D19,BS별도,MATCH(I$1,BS별도H,0),0)/100,"") | J19: =IFERROR(VLOOKUP($D19,BS별도,MATCH(J$1,BS별도H,0),0)/100,"") | K19: =IFERROR(J19*(1+변수!K27),"") | L19: =IFERROR(K19*(1+변수!L27),"") | M19: =L19 | N19: =IFERROR(L19*(1+변수!N27),"") | O19: =IFERROR(N19*(1+변수!O27),"") | P19: =IFERROR(O19*(1+변수!P27),"") | Q19: =IFERROR(P19*(1+변수!Q27),"") | R19: =Q19 | S19: =IFERROR(Q19*(1+변수!S27),"") | T19: =IFERROR(S19*(1+변수!T27),"") | U19: =IFERROR(T19*(1+변수!U27),"") | V19: =IFERROR(U19*(1+변수!V27),"") | W19: =V19
A20: 자본총계 | B20: 재무상태 | C20: 억원 | D20: 자본총계 | E20: =IFERROR(VLOOKUP($D20,BS별도,MATCH(E$1,BS별도H,0),0)/100,"") | F20: =IFERROR(VLOOKUP($D20,BS별도,MATCH(F$1,BS별도H,0),0)/100,"") | G20: =IFERROR(VLOOKUP($D20,BS별도,MATCH(G$1,BS별도H,0),0)/100,"") | H20: 482.35 | I20: =IFERROR(VLOOKUP($D20,BS별도,MATCH(I$1,BS별도H,0),0)/100,"") | J20: =IFERROR(VLOOKUP($D20,BS별도,MATCH(J$1,BS별도H,0),0)/100,"") | K20: =IFERROR(J20+K16-변수!K28,"") | L20: =IFERROR(K20+L16-변수!L28,"") | M20: =L20 | N20: =IFERROR(L20+N16-변수!N28,"") | O20: =IFERROR(N20+O16-변수!O28,"") | P20: =IFERROR(O20+P16-변수!P28,"") | Q20: =IFERROR(P20+Q16-변수!Q28,"") | R20: =Q20 | S20: =IFERROR(Q20+S16-변수!S28,"") | T20: =IFERROR(S20+T16-변수!T28,"") | U20: =IFERROR(T20+U16-변수!U28,"") | V20: =IFERROR(U20+V16-변수!V28,"") | W20: =V20
A21: 지배주주지분 | B21: 재무상태 | C21: 억원 | D21: 지배주주지분 | E21: =IFERROR(VLOOKUP($D21,BS별도,MATCH(E$1,BS별도H,0),0)/100,"") | F21: =IFERROR(VLOOKUP($D21,BS별도,MATCH(F$1,BS별도H,0),0)/100,"") | G21: =IFERROR(VLOOKUP($D21,BS별도,MATCH(G$1,BS별도H,0),0)/100,"") | H21: 482.35 | I21: =IFERROR(VLOOKUP($D21,BS별도,MATCH(I$1,BS별도H,0),0)/100,"") | J21: =IFERROR(VLOOKUP($D21,BS별도,MATCH(J$1,BS별도H,0),0)/100,"") | K21: =IFERROR(J21+K17-변수!K29,"") | L21: =IFERROR(K21+L17-변수!L29,"") | M21: =L21 | N21: =IFERROR(L21+N17-변수!N29,"") | O21: =IFERROR(N21+O17-변수!O29,"") | P21: =IFERROR(O21+P17-변수!P29,"") | Q21: =IFERROR(P21+Q17-변수!Q29,"") | R21: =Q21 | S21: =IFERROR(Q21+S17-변수!S29,"") | T21: =IFERROR(S21+T17-변수!T29,"") | U21: =IFERROR(T21+U17-변수!U29,"") | V21: =IFERROR(U21+V17-변수!V29,"") | W21: =V21
A22: 총차입금 | B22: 재무상태 | C22: 억원 | D22: 총차입금 | E22: =IFERROR(VLOOKUP($D22,BS별도,MATCH(E$1,BS별도H,0),0)/100,"") | F22: =IFERROR(VLOOKUP($D22,BS별도,MATCH(F$1,BS별도H,0),0)/100,"") | G22: =IFERROR(VLOOKUP($D22,BS별도,MATCH(G$1,BS별도H,0),0)/100,"") | H22: 80 | I22: =IFERROR(VLOOKUP($D22,BS별도,MATCH(I$1,BS별도H,0),0)/100,"") | J22: =IFERROR(VLOOKUP($D22,BS별도,MATCH(J$1,BS별도H,0),0)/100,"") | K22: =IFERROR(J22*(1+변수!K30),"") | L22: =IFERROR(K22*(1+변수!L30),"") | M22: =L22 | N22: =IFERROR(L22*(1+변수!N30),"") | O22: =IFERROR(N22*(1+변수!O30),"") | P22: =IFERROR(O22*(1+변수!P30),"") | Q22: =IFERROR(P22*(1+변수!Q30),"") | R22: =Q22 | S22: =IFERROR(Q22*(1+변수!S30),"") | T22: =IFERROR(S22*(1+변수!T30),"") | U22: =IFERROR(T22*(1+변수!U30),"") | V22: =IFERROR(U22*(1+변수!V30),"") | W22: =V22
A23: 순차입금 | B23: 재무상태 | C23: 억원 | D23: 순차입금 | E23: =IFERROR(VLOOKUP($D23,BS별도,MATCH(E$1,BS별도H,0),0)/100,"") | F23: =IFERROR(VLOOKUP($D23,BS별도,MATCH(F$1,BS별도H,0),0)/100,"") | G23: =IFERROR(VLOOKUP($D23,BS별도,MATCH(G$1,BS별도H,0),0)/100,"") | H23: -17.02 | I23: =IFERROR(VLOOKUP($D23,BS별도,MATCH(I$1,BS별도H,0),0)/100,"") | J23: =IFERROR(VLOOKUP($D23,BS별도,MATCH(J$1,BS별도H,0),0)/100,"") | K23: =IFERROR(J23*(1+변수!K31),"") | L23: =IFERROR(K23*(1+변수!L31),"") | M23: =L23 | N23: =IFERROR(L23*(1+변수!N31),"") | O23: =IFERROR(N23*(1+변수!O31),"") | P23: =IFERROR(O23*(1+변수!P31),"") | Q23: =IFERROR(P23*(1+변수!Q31),"") | R23: =Q23 | S23: =IFERROR(Q23*(1+변수!S31),"") | T23: =IFERROR(S23*(1+변수!T31),"") | U23: =IFERROR(T23*(1+변수!U31),"") | V23: =IFERROR(U23*(1+변수!V31),"") | W23: =V23
A24: 이자발생자산 | B24: 재무상태 | C24: 억원 | D24: 이자발생자산 | E24: =IFERROR(VLOOKUP($D24,BS별도,MATCH(E$1,BS별도H,0),0)/100,"") | F24: =IFERROR(VLOOKUP($D24,BS별도,MATCH(F$1,BS별도H,0),0)/100,"") | G24: =IFERROR(VLOOKUP($D24,BS별도,MATCH(G$1,BS별도H,0),0)/100,"") | H24: 128.74 | I24: =IFERROR(VLOOKUP($D24,BS별도,MATCH(I$1,BS별도H,0),0)/100,"") | J24: =IFERROR(VLOOKUP($D24,BS별도,MATCH(J$1,BS별도H,0),0)/100,"") | K24: =IFERROR(J24*(1+변수!K32),"") | L24: =IFERROR(K24*(1+변수!L32),"") | M24: =L24 | N24: =IFERROR(L24*(1+변수!N32),"") | O24: =IFERROR(N24*(1+변수!O32),"") | P24: =IFERROR(O24*(1+변수!P32),"") | Q24: =IFERROR(P24*(1+변수!Q32),"") | R24: =Q24 | S24: =IFERROR(Q24*(1+변수!S32),"") | T24: =IFERROR(S24*(1+변수!T32),"") | U24: =IFERROR(T24*(1+변수!U32),"") | V24: =IFERROR(U24*(1+변수!V32),"") | W24: =V24
A25: 현금및현금성자산 | B25: 재무상태 | C25: 억원 | D25: 현금및현금성자산 | E25: =IFERROR(VLOOKUP($D25,BS별도,MATCH(E$1,BS별도H,0),0)/100,"") | F25: =IFERROR(VLOOKUP($D25,BS별도,MATCH(F$1,BS별도H,0),0)/100,"") | G25: =IFERROR(VLOOKUP($D25,BS별도,MATCH(G$1,BS별도H,0),0)/100,"") | H25: 44.28 | I25: =IFERROR(VLOOKUP($D25,BS별도,MATCH(I$1,BS별도H,0),0)/100,"") | J25: =IFERROR(VLOOKUP($D25,BS별도,MATCH(J$1,BS별도H,0),0)/100,"") | M25: =L25 | R25: =Q25 | W25: =V25
A26: CAPEX | B26: 현금흐름 | C26: 억원 | D26: CAPEX | E26: =IFERROR(VLOOKUP($D26,BS별도,MATCH(E$1,BS별도H,0),0)/100,"") | F26: =IFERROR(VLOOKUP($D26,BS별도,MATCH(F$1,BS별도H,0),0)/100,"") | G26: =IFERROR(VLOOKUP($D26,BS별도,MATCH(G$1,BS별도H,0),0)/100,"") | I26: =IFERROR(VLOOKUP($D26,BS별도,MATCH(I$1,BS별도H,0),0)/100,"") | J26: =IFERROR(VLOOKUP($D26,BS별도,MATCH(J$1,BS별도H,0),0)/100,"") | K26: =IFERROR(F26*(1+변수!K34),"") | L26: =IFERROR(G26*(1+변수!L34),"") | M26: =SUM(I26:L26) | N26: =IFERROR(I26*(1+변수!N34),"") | O26: =IFERROR(J26*(1+변수!O34),"") | P26: =IFERROR(K26*(1+변수!P34),"") | Q26: =IFERROR(L26*(1+변수!Q34),"") | R26: =SUM(N26:Q26) | S26: =IFERROR(N26*(1+변수!S34),"") | T26: =IFERROR(O26*(1+변수!T34),"") | U26: =IFERROR(P26*(1+변수!U34),"") | V26: =IFERROR(Q26*(1+변수!V34),"") | W26: =SUM(S26:V26)
A27: 영업활동현금흐름 | B27: 현금흐름 | C27: 억원 | D27: 영업활동으로인한현금흐름 | E27: =IFERROR(VLOOKUP($D27,BS별도,MATCH(E$1,BS별도H,0),0)/100,"") | F27: =IFERROR(VLOOKUP($D27,BS별도,MATCH(F$1,BS별도H,0),0)/100,"") | G27: =IFERROR(VLOOKUP($D27,BS별도,MATCH(G$1,BS별도H,0),0)/100,"") | I27: =IFERROR(VLOOKUP($D27,BS별도,MATCH(I$1,BS별도H,0),0)/100,"") | J27: =IFERROR(VLOOKUP($D27,BS별도,MATCH(J$1,BS별도H,0),0)/100,"") | M27: =SUM(I27:L27) | R27: =SUM(N27:Q27) | W27: =SUM(S27:V27)
A28: 주식수 | B28: 주당 | C28: 백만주 | D28: 유통주식수 | E28: 8.241 | F28: 8.241 | G28: 8.241 | H28: =G28 | I28: 8.241 | J28: 8.241 | K28: =IFERROR(J28*(1+변수!K36),"") | L28: =IFERROR(K28*(1+변수!L36),"") | M28: =L28 | N28: =IFERROR(L28*(1+변수!N36),"") | O28: =IFERROR(N28*(1+변수!O36),"") | P28: =IFERROR(O28*(1+변수!P36),"") | Q28: =IFERROR(P28*(1+변수!Q36),"") | R28: =Q28 | S28: =IFERROR(Q28*(1+변수!S36),"") | T28: =IFERROR(S28*(1+변수!T36),"") | U28: =IFERROR(T28*(1+변수!U36),"") | V28: =IFERROR(U28*(1+변수!V36),"") | W28: =V28
A29: EPS | B29: 주당 | C29: 원 | D29: EPS | E29: =IFERROR(E17*100/E28,"") | F29: =IFERROR(F17*100/F28,"") | G29: =IFERROR(G17*100/G28,"") | I29: =IFERROR(I17*100/I28,"") | J29: =IFERROR(J17*100/J28,"") | K29: =IFERROR(K17*100/K28,"") | L29: =IFERROR(L17*100/L28,"") | M29: =SUM(I29:L29) | N29: =IFERROR(N17*100/N28,"") | O29: =IFERROR(O17*100/O28,"") | P29: =IFERROR(P17*100/P28,"") | Q29: =IFERROR(Q17*100/Q28,"") | R29: =SUM(N29:Q29) | S29: =IFERROR(S17*100/S28,"") | T29: =IFERROR(T17*100/T28,"") | U29: =IFERROR(U17*100/U28,"") | V29: =IFERROR(V17*100/V28,"") | W29: =SUM(S29:V29)
A30: BPS | B30: 주당 | C30: 원 | D30: BPS | E30: =IFERROR(E21*100/E28,"") | F30: =IFERROR(F21*100/F28,"") | G30: =IFERROR(G21*100/G28,"") | H30: =G30 | I30: =IFERROR(I21*100/I28,"") | J30: =IFERROR(J21*100/J28,"") | K30: =IFERROR(K21*100/K28,"") | L30: =IFERROR(L21*100/L28,"") | M30: =L30 | N30: =IFERROR(N21*100/N28,"") | O30: =IFERROR(O21*100/O28,"") | P30: =IFERROR(P21*100/P28,"") | Q30: =IFERROR(Q21*100/Q28,"") | R30: =Q30 | S30: =IFERROR(S21*100/S28,"") | T30: =IFERROR(T21*100/T28,"") | U30: =IFERROR(U21*100/U28,"") | V30: =IFERROR(V21*100/V28,"") | W30: =V30
A31: DPS | B31: 주당 | C31: 원 | D31: DPS(보통주) | G31: 0 | H31: 0 | L31: =변수!L37 | M31: =SUM(I31:L31) | Q31: =변수!Q37 | R31: =SUM(N31:Q31) | V31: =변수!V37 | W31: =SUM(S31:V31)
A32: PER | B32: 주당 | C32: 배 | D32: PER | H32: =G32 | J32: =IFERROR(변수!J18/(F29+G29+I29+J29),"") | K32: =IFERROR(변수!$D$40/(G29+I29+J29+K29),"") | M32: =L32 | R32: =Q32 | W32: =V32
A33: PBR | B33: 주당 | C33: 배 | D33: PBR | E33: =IFERROR(변수!E18/E30,"") | F33: =IFERROR(변수!F18/F30,"") | G33: =IFERROR(변수!G18/G30,"") | H33: =G33 | I33: =IFERROR(변수!I18/I30,"") | J33: =IFERROR(변수!J18/J30,"") | K33: =IFERROR(변수!$D$40/K30,"") | L33: =IFERROR(변수!$D$40/L30,"") | M33: =L33 | N33: =IFERROR(변수!$D$40/N30,"") | O33: =IFERROR(변수!$D$40/O30,"") | P33: =IFERROR(변수!$D$40/P30,"") | Q33: =IFERROR(변수!$D$40/Q30,"") | R33: =Q33 | S33: =IFERROR(변수!$D$40/S30,"") | T33: =IFERROR(변수!$D$40/T30,"") | U33: =IFERROR(변수!$D$40/U30,"") | V33: =IFERROR(변수!$D$40/V30,"") | W33: =V33
A34: 매출전사 | B34: 사업부 | C34: 억원 | D34: 매출 전사(부문 미분리) | E34: 68.89 | F34: 42.66 | G34: 116.45 | I34: 39.88 | J34: 99.52 | K34: =IFERROR(K5,"") | L34: =IFERROR(L5,"") | M34: =SUM(I34:L34) | N34: =IFERROR(N5,"") | O34: =IFERROR(O5,"") | P34: =IFERROR(P5,"") | Q34: =IFERROR(Q5,"") | R34: =SUM(N34:Q34) | S34: =IFERROR(S5,"") | T34: =IFERROR(T5,"") | U34: =IFERROR(U5,"") | V34: =IFERROR(V5,"") | W34: =SUM(S34:V34)
A35: OP전사 | B35: 사업부 | C35: 억원 | D35: OP 전사(부문 미분리) | E35: -20.83 | F35: -10.14 | G35: 9.48 | I35: -20.14 | J35: 5.43 | K35: =IFERROR(K9,"") | L35: =IFERROR(L9,"") | M35: =SUM(I35:L35) | N35: =IFERROR(N9,"") | O35: =IFERROR(O9,"") | P35: =IFERROR(P9,"") | Q35: =IFERROR(Q9,"") | R35: =SUM(N35:Q35) | S35: =IFERROR(S9,"") | T35: =IFERROR(T9,"") | U35: =IFERROR(U9,"") | V35: =IFERROR(V9,"") | W35: =SUM(S35:V35)
B36: 비율(참고)
A37: NPM | C37: % | D37: 지배주주순이익 / 매출액 | E37: =IFERROR(E17/E5,"") | F37: =IFERROR(F17/F5,"") | G37: =IFERROR(G17/G5,"") | H37: =IFERROR(H17/H5,"") | I37: =IFERROR(I17/I5,"") | J37: =IFERROR(J17/J5,"") | K37: =IFERROR(K17/K5,"") | L37: =IFERROR(L17/L5,"") | ... W37: =IFERROR(W17/W5,"")
A38: 매출원가율 | C38: % | D38: 매출원가 / 매출액 | E38: =IFERROR(E6/E5,"") | F38: =IFERROR(F6/F5,"") | G38: =IFERROR(G6/G5,"") | H38: =IFERROR(H6/H5,"") | I38: =IFERROR(I6/I5,"") | J38: =IFERROR(J6/J5,"") | K38: =IFERROR(K6/K5,"") | L38: =IFERROR(L6/L5,"") | ... W38: =IFERROR(W6/W5,"")
A39: 판관비율 | C39: % | D39: 판관비 / 매출액 | E39: =IFERROR(E8/E5,"") | F39: =IFERROR(F8/F5,"") | G39: =IFERROR(G8/G5,"") | H39: =IFERROR(H8/H5,"") | I39: =IFERROR(I8/I5,"") | J39: =IFERROR(J8/J5,"") | K39: =IFERROR(K8/K5,"") | L39: =IFERROR(L8/L5,"") | ... W39: =IFERROR(W8/W5,"")

Sheet 분기
C1: 이름: 분기H — subQ 를 이름으로 VLOOKUP(억원) | E1: 2Q25 | F1: 3Q25 | G1: 4Q25 | H1: 1Q26 | I1: 2Q26 | J1: 3Q26 | K1: 4Q26 | L1: 1Q27 | M1: 2Q27 | N1: 3Q27 | O1: 4Q27 | P1: 1Q28 | Q1: 2Q28 | R1: 3Q28 | S1: 4Q28
C2: 종가: | D2: =변수!D40
C3: 기준일: | D3: 20261014 | E3: 1 | F3: 2 | G3: 3 | H3: 4 | I3: 5 | J3: 6 | K3: 7 | L3: 8 | M3: 9 | N3: 10 | O3: 11 | P3: 12 | Q3: 13 | R3: 14 | S3: 15
E4: 2025.06 | F4: 2025.09 | G4: 2025.12 | H4: 2026.03 | I4: 2026.06 | J4: 2026.09 | K4: 2026.12 | L4: 2027.03 | M4: 2027.06 | N4: 2027.09 | O4: 2027.12 | P4: 2028.03 | Q4: 2028.06 | R4: 2028.09 | S4: 2028.12
A5: 매출액 | D5: 매출액 | E5: =IFERROR(VLOOKUP($A5,subQ,MATCH(E$1,SUBQH,0),0),"") | F5: =IFERROR(VLOOKUP($A5,subQ,MATCH(F$1,SUBQH,0),0),"") | G5: =IFERROR(VLOOKUP($A5,subQ,MATCH(G$1,SUBQH,0),0),"") | H5: =IFERROR(VLOOKUP($A5,subQ,MATCH(H$1,SUBQH,0),0),"") | I5: =IFERROR(VLOOKUP($A5,subQ,MATCH(I$1,SUBQH,0),0),"") | J5: =IFERROR(VLOOKUP($A5,subQ,MATCH(J$1,SUBQH,0),0),"") | K5: =IFERROR(VLOOKUP($A5,subQ,MATCH(K$1,SUBQH,0),0),"") | L5: =IFERROR(VLOOKUP($A5,subQ,MATCH(L$1,SUBQH,0),0),"") | ... S5: =IFERROR(VLOOKUP($A5,subQ,MATCH(S$1,SUBQH,0),0),"")
A6: 매출원가 | D6: 매출원가 | E6: =IFERROR(VLOOKUP($A6,subQ,MATCH(E$1,SUBQH,0),0),"") | F6: =IFERROR(VLOOKUP($A6,subQ,MATCH(F$1,SUBQH,0),0),"") | G6: =IFERROR(VLOOKUP($A6,subQ,MATCH(G$1,SUBQH,0),0),"") | H6: =IFERROR(VLOOKUP($A6,subQ,MATCH(H$1,SUBQH,0),0),"") | I6: =IFERROR(VLOOKUP($A6,subQ,MATCH(I$1,SUBQH,0),0),"") | J6: =IFERROR(VLOOKUP($A6,subQ,MATCH(J$1,SUBQH,0),0),"") | K6: =IFERROR(VLOOKUP($A6,subQ,MATCH(K$1,SUBQH,0),0),"") | L6: =IFERROR(VLOOKUP($A6,subQ,MATCH(L$1,SUBQH,0),0),"") | ... S6: =IFERROR(VLOOKUP($A6,subQ,MATCH(S$1,SUBQH,0),0),"")
A7: 매출총이익 | D7: 매출총이익 | E7: =IFERROR(VLOOKUP($A7,subQ,MATCH(E$1,SUBQH,0),0),"") | F7: =IFERROR(VLOOKUP($A7,subQ,MATCH(F$1,SUBQH,0),0),"") | G7: =IFERROR(VLOOKUP($A7,subQ,MATCH(G$1,SUBQH,0),0),"") | H7: =IFERROR(VLOOKUP($A7,subQ,MATCH(H$1,SUBQH,0),0),"") | I7: =IFERROR(VLOOKUP($A7,subQ,MATCH(I$1,SUBQH,0),0),"") | J7: =IFERROR(VLOOKUP($A7,subQ,MATCH(J$1,SUBQH,0),0),"") | K7: =IFERROR(VLOOKUP($A7,subQ,MATCH(K$1,SUBQH,0),0),"") | L7: =IFERROR(VLOOKUP($A7,subQ,MATCH(L$1,SUBQH,0),0),"") | ... S7: =IFERROR(VLOOKUP($A7,subQ,MATCH(S$1,SUBQH,0),0),"")
A8: 판관비 | D8: 판매비와관리비 | E8: =IFERROR(VLOOKUP($A8,subQ,MATCH(E$1,SUBQH,0),0),"") | F8: =IFERROR(VLOOKUP($A8,subQ,MATCH(F$1,SUBQH,0),0),"") | G8: =IFERROR(VLOOKUP($A8,subQ,MATCH(G$1,SUBQH,0),0),"") | H8: =IFERROR(VLOOKUP($A8,subQ,MATCH(H$1,SUBQH,0),0),"") | I8: =IFERROR(VLOOKUP($A8,subQ,MATCH(I$1,SUBQH,0),0),"") | J8: =IFERROR(VLOOKUP($A8,subQ,MATCH(J$1,SUBQH,0),0),"") | K8: =IFERROR(VLOOKUP($A8,subQ,MATCH(K$1,SUBQH,0),0),"") | L8: =IFERROR(VLOOKUP($A8,subQ,MATCH(L$1,SUBQH,0),0),"") | ... S8: =IFERROR(VLOOKUP($A8,subQ,MATCH(S$1,SUBQH,0),0),"")
A9: 영업이익 | D9: 영업이익 | E9: =IFERROR(VLOOKUP($A9,subQ,MATCH(E$1,SUBQH,0),0),"") | F9: =IFERROR(VLOOKUP($A9,subQ,MATCH(F$1,SUBQH,0),0),"") | G9: =IFERROR(VLOOKUP($A9,subQ,MATCH(G$1,SUBQH,0),0),"") | H9: =IFERROR(VLOOKUP($A9,subQ,MATCH(H$1,SUBQH,0),0),"") | I9: =IFERROR(VLOOKUP($A9,subQ,MATCH(I$1,SUBQH,0),0),"") | J9: =IFERROR(VLOOKUP($A9,subQ,MATCH(J$1,SUBQH,0),0),"") | K9: =IFERROR(VLOOKUP($A9,subQ,MATCH(K$1,SUBQH,0),0),"") | L9: =IFERROR(VLOOKUP($A9,subQ,MATCH(L$1,SUBQH,0),0),"") | ... S9: =IFERROR(VLOOKUP($A9,subQ,MATCH(S$1,SUBQH,0),0),"")
A10: OPM | D10: 영업이익률 | E10: =IFERROR(VLOOKUP($A10,subQ,MATCH(E$1,SUBQH,0),0),"") | F10: =IFERROR(VLOOKUP($A10,subQ,MATCH(F$1,SUBQH,0),0),"") | G10: =IFERROR(VLOOKUP($A10,subQ,MATCH(G$1,SUBQH,0),0),"") | H10: =IFERROR(VLOOKUP($A10,subQ,MATCH(H$1,SUBQH,0),0),"") | I10: =IFERROR(VLOOKUP($A10,subQ,MATCH(I$1,SUBQH,0),0),"") | J10: =IFERROR(VLOOKUP($A10,subQ,MATCH(J$1,SUBQH,0),0),"") | K10: =IFERROR(VLOOKUP($A10,subQ,MATCH(K$1,SUBQH,0),0),"") | L10: =IFERROR(VLOOKUP($A10,subQ,MATCH(L$1,SUBQH,0),0),"") | ... S10: =IFERROR(VLOOKUP($A10,subQ,MATCH(S$1,SUBQH,0),0),"")
A11: 금융손익 | D11: 금융손익(이자·환 포함) | E11: =IFERROR(VLOOKUP($A11,subQ,MATCH(E$1,SUBQH,0),0),"") | F11: =IFERROR(VLOOKUP($A11,subQ,MATCH(F$1,SUBQH,0),0),"") | G11: =IFERROR(VLOOKUP($A11,subQ,MATCH(G$1,SUBQH,0),0),"") | H11: =IFERROR(VLOOKUP($A11,subQ,MATCH(H$1,SUBQH,0),0),"") | I11: =IFERROR(VLOOKUP($A11,subQ,MATCH(I$1,SUBQH,0),0),"") | J11: =IFERROR(VLOOKUP($A11,subQ,MATCH(J$1,SUBQH,0),0),"") | K11: =IFERROR(VLOOKUP($A11,subQ,MATCH(K$1,SUBQH,0),0),"") | L11: =IFERROR(VLOOKUP($A11,subQ,MATCH(L$1,SUBQH,0),0),"") | ... S11: =IFERROR(VLOOKUP($A11,subQ,MATCH(S$1,SUBQH,0),0),"")
A12: 이자손익 | D12: 이자손익(이자수익 − 이자비용) | E12: =IFERROR(VLOOKUP($A12,subQ,MATCH(E$1,SUBQH,0),0),"") | F12: =IFERROR(VLOOKUP($A12,subQ,MATCH(F$1,SUBQH,0),0),"") | G12: =IFERROR(VLOOKUP($A12,subQ,MATCH(G$1,SUBQH,0),0),"") | H12: =IFERROR(VLOOKUP($A12,subQ,MATCH(H$1,SUBQH,0),0),"") | I12: =IFERROR(VLOOKUP($A12,subQ,MATCH(I$1,SUBQH,0),0),"") | J12: =IFERROR(VLOOKUP($A12,subQ,MATCH(J$1,SUBQH,0),0),"") | K12: =IFERROR(VLOOKUP($A12,subQ,MATCH(K$1,SUBQH,0),0),"") | L12: =IFERROR(VLOOKUP($A12,subQ,MATCH(L$1,SUBQH,0),0),"") | ... S12: =IFERROR(VLOOKUP($A12,subQ,MATCH(S$1,SUBQH,0),0),"")
A13: 기타영업외손익 | D13: 기타영업외손익 | E13: =IFERROR(VLOOKUP($A13,subQ,MATCH(E$1,SUBQH,0),0),"") | F13: =IFERROR(VLOOKUP($A13,subQ,MATCH(F$1,SUBQH,0),0),"") | G13: =IFERROR(VLOOKUP($A13,subQ,MATCH(G$1,SUBQH,0),0),"") | H13: =IFERROR(VLOOKUP($A13,subQ,MATCH(H$1,SUBQH,0),0),"") | I13: =IFERROR(VLOOKUP($A13,subQ,MATCH(I$1,SUBQH,0),0),"") | J13: =IFERROR(VLOOKUP($A13,subQ,MATCH(J$1,SUBQH,0),0),"") | K13: =IFERROR(VLOOKUP($A13,subQ,MATCH(K$1,SUBQH,0),0),"") | L13: =IFERROR(VLOOKUP($A13,subQ,MATCH(L$1,SUBQH,0),0),"") | ... S13: =IFERROR(VLOOKUP($A13,subQ,MATCH(S$1,SUBQH,0),0),"")
A14: 세전이익 | D14: 법인세비용차감전이익 | E14: =IFERROR(VLOOKUP($A14,subQ,MATCH(E$1,SUBQH,0),0),"") | F14: =IFERROR(VLOOKUP($A14,subQ,MATCH(F$1,SUBQH,0),0),"") | G14: =IFERROR(VLOOKUP($A14,subQ,MATCH(G$1,SUBQH,0),0),"") | H14: =IFERROR(VLOOKUP($A14,subQ,MATCH(H$1,SUBQH,0),0),"") | I14: =IFERROR(VLOOKUP($A14,subQ,MATCH(I$1,SUBQH,0),0),"") | J14: =IFERROR(VLOOKUP($A14,subQ,MATCH(J$1,SUBQH,0),0),"") | K14: =IFERROR(VLOOKUP($A14,subQ,MATCH(K$1,SUBQH,0),0),"") | L14: =IFERROR(VLOOKUP($A14,subQ,MATCH(L$1,SUBQH,0),0),"") | ... S14: =IFERROR(VLOOKUP($A14,subQ,MATCH(S$1,SUBQH,0),0),"")
A15: 법인세비용 | D15: 법인세비용 | E15: =IFERROR(VLOOKUP($A15,subQ,MATCH(E$1,SUBQH,0),0),"") | F15: =IFERROR(VLOOKUP($A15,subQ,MATCH(F$1,SUBQH,0),0),"") | G15: =IFERROR(VLOOKUP($A15,subQ,MATCH(G$1,SUBQH,0),0),"") | H15: =IFERROR(VLOOKUP($A15,subQ,MATCH(H$1,SUBQH,0),0),"") | I15: =IFERROR(VLOOKUP($A15,subQ,MATCH(I$1,SUBQH,0),0),"") | J15: =IFERROR(VLOOKUP($A15,subQ,MATCH(J$1,SUBQH,0),0),"") | K15: =IFERROR(VLOOKUP($A15,subQ,MATCH(K$1,SUBQH,0),0),"") | L15: =IFERROR(VLOOKUP($A15,subQ,MATCH(L$1,SUBQH,0),0),"") | ... S15: =IFERROR(VLOOKUP($A15,subQ,MATCH(S$1,SUBQH,0),0),"")
A16: 당기순이익 | D16: 당기순이익 | E16: =IFERROR(VLOOKUP($A16,subQ,MATCH(E$1,SUBQH,0),0),"") | F16: =IFERROR(VLOOKUP($A16,subQ,MATCH(F$1,SUBQH,0),0),"") | G16: =IFERROR(VLOOKUP($A16,subQ,MATCH(G$1,SUBQH,0),0),"") | H16: =IFERROR(VLOOKUP($A16,subQ,MATCH(H$1,SUBQH,0),0),"") | I16: =IFERROR(VLOOKUP($A16,subQ,MATCH(I$1,SUBQH,0),0),"") | J16: =IFERROR(VLOOKUP($A16,subQ,MATCH(J$1,SUBQH,0),0),"") | K16: =IFERROR(VLOOKUP($A16,subQ,MATCH(K$1,SUBQH,0),0),"") | L16: =IFERROR(VLOOKUP($A16,subQ,MATCH(L$1,SUBQH,0),0),"") | ... S16: =IFERROR(VLOOKUP($A16,subQ,MATCH(S$1,SUBQH,0),0),"")
... A36: NPM | D36: NPM | E36: =IFERROR(VLOOKUP($A36,subQ,MATCH(E$1,SUBQH,0),0),"") | F36: =IFERROR(VLOOKUP($A36,subQ,MATCH(F$1,SUBQH,0),0),"") | G36: =IFERROR(VLOOKUP($A36,subQ,MATCH(G$1,SUBQH,0),0),"") | H36: =IFERROR(VLOOKUP($A36,subQ,MATCH(H$1,SUBQH,0),0),"") | I36: =IFERROR(VLOOKUP($A36,subQ,MATCH(I$1,SUBQH,0),0),"") | J36: =IFERROR(VLOOKUP($A36,subQ,MATCH(J$1,SUBQH,0),0),"") | K36: =IFERROR(VLOOKUP($A36,subQ,MATCH(K$1,SUBQH,0),0),"") | L36: =IFERROR(VLOOKUP($A36,subQ,MATCH(L$1,SUBQH,0),0),"") | ... S36: =IFERROR(VLOOKUP($A36,subQ,MATCH(S$1,SUBQH,0),0),"")
A37: 매출액 YoY | D37: 매출액 YoY | I37: =IFERROR(I5/E5-1,"") | J37: =IFERROR(J5/F5-1,"") | K37: =IFERROR(K5/G5-1,"") | L37: =IFERROR(L5/H5-1,"") | M37: =IFERROR(M5/I5-1,"") | N37: =IFERROR(N5/J5-1,"") | O37: =IFERROR(O5/K5-1,"") | P37: =IFERROR(P5/L5-1,"") | ... S37: =IFERROR(S5/O5-1,"")
A38: 영업이익 YoY | D38: 영업이익 YoY | I38: =IFERROR(I9/E9-1,"") | J38: =IFERROR(J9/F9-1,"") | K38: =IFERROR(K9/G9-1,"") | L38: =IFERROR(L9/H9-1,"") | M38: =IFERROR(M9/I9-1,"") | N38: =IFERROR(N9/J9-1,"") | O38: =IFERROR(O9/K9-1,"") | P38: =IFERROR(P9/L9-1,"") | ... S38: =IFERROR(S9/O9-1,"")
A39: 지배주주순이익 YoY | D39: 지배주주순이익 YoY | I39: =IFERROR(I17/E17-1,"") | J39: =IFERROR(J17/F17-1,"") | K39: =IFERROR(K17/G17-1,"") | L39: =IFERROR(L17/H17-1,"") | M39: =IFERROR(M17/I17-1,"") | N39: =IFERROR(N17/J17-1,"") | O39: =IFERROR(O17/K17-1,"") | P39: =IFERROR(P17/L17-1,"") | ... S39: =IFERROR(S17/O17-1,"")

Sheet 연간예상
C1: 이름: 연간예상H — subQ 를 이름으로 VLOOKUP(억원) | E1: 2025 | F1: 2026 | G1: 2027 | H1: 2028
C2: 종가: | D2: =변수!D40
C3: 기준일: | D3: 20261014 | E3: 1 | F3: 2 | G3: 3 | H3: 4
E4: 2025.12A | F4: 2026.12A | G4: 2027.12A | H4: 2028.12A
A5: 매출액 | D5: 매출액 | E5: =IFERROR(VLOOKUP($A5,subQ,MATCH(E$1,SUBQH,0),0),"") | F5: =IFERROR(VLOOKUP($A5,subQ,MATCH(F$1,SUBQH,0),0),"") | G5: =IFERROR(VLOOKUP($A5,subQ,MATCH(G$1,SUBQH,0),0),"") | H5: =IFERROR(VLOOKUP($A5,subQ,MATCH(H$1,SUBQH,0),0),"")
A6: 매출원가 | D6: 매출원가 | E6: =IFERROR(VLOOKUP($A6,subQ,MATCH(E$1,SUBQH,0),0),"") | F6: =IFERROR(VLOOKUP($A6,subQ,MATCH(F$1,SUBQH,0),0),"") | G6: =IFERROR(VLOOKUP($A6,subQ,MATCH(G$1,SUBQH,0),0),"") | H6: =IFERROR(VLOOKUP($A6,subQ,MATCH(H$1,SUBQH,0),0),"")
A7: 매출총이익 | D7: 매출총이익 | E7: =IFERROR(VLOOKUP($A7,subQ,MATCH(E$1,SUBQH,0),0),"") | F7: =IFERROR(VLOOKUP($A7,subQ,MATCH(F$1,SUBQH,0),0),"") | G7: =IFERROR(VLOOKUP($A7,subQ,MATCH(G$1,SUBQH,0),0),"") | H7: =IFERROR(VLOOKUP($A7,subQ,MATCH(H$1,SUBQH,0),0),"")
A8: 판관비 | D8: 판매비와관리비 | E8: =IFERROR(VLOOKUP($A8,subQ,MATCH(E$1,SUBQH,0),0),"") | F8: =IFERROR(VLOOKUP($A8,subQ,MATCH(F$1,SUBQH,0),0),"") | G8: =IFERROR(VLOOKUP($A8,subQ,MATCH(G$1,SUBQH,0),0),"") | H8: =IFERROR(VLOOKUP($A8,subQ,MATCH(H$1,SUBQH,0),0),"")
A9: 영업이익 | D9: 영업이익 | E9: =IFERROR(VLOOKUP($A9,subQ,MATCH(E$1,SUBQH,0),0),"") | F9: =IFERROR(VLOOKUP($A9,subQ,MATCH(F$1,SUBQH,0),0),"") | G9: =IFERROR(VLOOKUP($A9,subQ,MATCH(G$1,SUBQH,0),0),"") | H9: =IFERROR(VLOOKUP($A9,subQ,MATCH(H$1,SUBQH,0),0),"")
A10: OPM | D10: 영업이익률 | E10: =IFERROR(VLOOKUP($A10,subQ,MATCH(E$1,SUBQH,0),0),"") | F10: =IFERROR(VLOOKUP($A10,subQ,MATCH(F$1,SUBQH,0),0),"") | G10: =IFERROR(VLOOKUP($A10,subQ,MATCH(G$1,SUBQH,0),0),"") | H10: =IFERROR(VLOOKUP($A10,subQ,MATCH(H$1,SUBQH,0),0),"")
A11: 금융손익 | D11: 금융손익(이자·환 포함) | E11: =IFERROR(VLOOKUP($A11,subQ,MATCH(E$1,SUBQH,0),0),"") | F11: =IFERROR(VLOOKUP($A11,subQ,MATCH(F$1,SUBQH,0),0),"") | G11: =IFERROR(VLOOKUP($A11,subQ,MATCH(G$1,SUBQH,0),0),"") | H11: =IFERROR(VLOOKUP($A11,subQ,MATCH(H$1,SUBQH,0),0),"")
A12: 이자손익 | D12: 이자손익(이자수익 − 이자비용) | E12: =IFERROR(VLOOKUP($A12,subQ,MATCH(E$1,SUBQH,0),0),"") | F12: =IFERROR(VLOOKUP($A12,subQ,MATCH(F$1,SUBQH,0),0),"") | G12: =IFERROR(VLOOKUP($A12,subQ,MATCH(G$1,SUBQH,0),0),"") | H12: =IFERROR(VLOOKUP($A12,subQ,MATCH(H$1,SUBQH,0),0),"")
A13: 기타영업외손익 | D13: 기타영업외손익 | E13: =IFERROR(VLOOKUP($A13,subQ,MATCH(E$1,SUBQH,0),0),"") | F13: =IFERROR(VLOOKUP($A13,subQ,MATCH(F$1,SUBQH,0),0),"") | G13: =IFERROR(VLOOKUP($A13,subQ,MATCH(G$1,SUBQH,0),0),"") | H13: =IFERROR(VLOOKUP($A13,subQ,MATCH(H$1,SUBQH,0),0),"")
A14: 세전이익 | D14: 법인세비용차감전이익 | E14: =IFERROR(VLOOKUP($A14,subQ,MATCH(E$1,SUBQH,0),0),"") | F14: =IFERROR(VLOOKUP($A14,subQ,MATCH(F$1,SUBQH,0),0),"") | G14: =IFERROR(VLOOKUP($A14,subQ,MATCH(G$1,SUBQH,0),0),"") | H14: =IFERROR(VLOOKUP($A14,subQ,MATCH(H$1,SUBQH,0),0),"")
A15: 법인세비용 | D15: 법인세비용 | E15: =IFERROR(VLOOKUP($A15,subQ,MATCH(E$1,SUBQH,0),0),"") | F15: =IFERROR(VLOOKUP($A15,subQ,MATCH(F$1,SUBQH,0),0),"") | G15: =IFERROR(VLOOKUP($A15,subQ,MATCH(G$1,SUBQH,0),0),"") | H15: =IFERROR(VLOOKUP($A15,subQ,MATCH(H$1,SUBQH,0),0),"")
A16: 당기순이익 | D16: 당기순이익 | E16: =IFERROR(VLOOKUP($A16,subQ,MATCH(E$1,SUBQH,0),0),"") | F16: =IFERROR(VLOOKUP($A16,subQ,MATCH(F$1,SUBQH,0),0),"") | G16: =IFERROR(VLOOKUP($A16,subQ,MATCH(G$1,SUBQH,0),0),"") | H16: =IFERROR(VLOOKUP($A16,subQ,MATCH(H$1,SUBQH,0),0),"")
... A36: NPM | D36: NPM | E36: =IFERROR(VLOOKUP($A36,subQ,MATCH(E$1,SUBQH,0),0),"") | F36: =IFERROR(VLOOKUP($A36,subQ,MATCH(F$1,SUBQH,0),0),"") | G36: =IFERROR(VLOOKUP($A36,subQ,MATCH(G$1,SUBQH,0),0),"") | H36: =IFERROR(VLOOKUP($A36,subQ,MATCH(H$1,SUBQH,0),0),"")
A37: 매출액 YoY | D37: 매출액 YoY | F37: =IFERROR(F5/E5-1,"") | G37: =IFERROR(G5/F5-1,"") | H37: =IFERROR(H5/G5-1,"")
A38: 영업이익 YoY | D38: 영업이익 YoY | F38: =IFERROR(F9/E9-1,"") | G38: =IFERROR(G9/F9-1,"") | H38: =IFERROR(H9/G9-1,"")
A39: 지배주주순이익 YoY | D39: 지배주주순이익 YoY | F39: =IFERROR(F17/E17-1,"") | G39: =IFERROR(G17/F17-1,"") | H39: =IFERROR(H17/G17-1,"")

Sheet TP
B1: 종가 | C1: =변수!D40
B2: 기준일 | C2: =변수!D41
B3: 모델 산출값 — 목표주가·추천 아님. 밴드·COE 는 변수 시트 3절의 가정
C5: FY | D5: 2025 | E5: 2026 | F5: 2027 | G5: 2028
D6: A | E6: E | F6: E | G6: E
C7: EPS(원) | D7: =IFERROR(VLOOKUP("EPS",subQ,MATCH(D$5,SUBQH,0),0),"") | E7: =IFERROR(VLOOKUP("EPS",subQ,MATCH(E$5,SUBQH,0),0),"") | F7: =IFERROR(VLOOKUP("EPS",subQ,MATCH(F$5,SUBQH,0),0),"") | G7: =IFERROR(VLOOKUP("EPS",subQ,MATCH(G$5,SUBQH,0),0),"")
C8: BPS(원) | D8: =IFERROR(VLOOKUP("BPS",subQ,MATCH(D$5,SUBQH,0),0),"") | E8: =IFERROR(VLOOKUP("BPS",subQ,MATCH(E$5,SUBQH,0),0),"") | F8: =IFERROR(VLOOKUP("BPS",subQ,MATCH(F$5,SUBQH,0),0),"") | G8: =IFERROR(VLOOKUP("BPS",subQ,MATCH(G$5,SUBQH,0),0),"")
C9: 지배주주순이익(억원) | D9: =IFERROR(VLOOKUP("지배주주순이익",subQ,MATCH(D$5,SUBQH,0),0),"") | E9: =IFERROR(VLOOKUP("지배주주순이익",subQ,MATCH(E$5,SUBQH,0),0),"") | F9: =IFERROR(VLOOKUP("지배주주순이익",subQ,MATCH(F$5,SUBQH,0),0),"") | G9: =IFERROR(VLOOKUP("지배주주순이익",subQ,MATCH(G$5,SUBQH,0),0),"")
C10: 영업이익(억원) | D10: =IFERROR(VLOOKUP("영업이익",subQ,MATCH(D$5,SUBQH,0),0),"") | E10: =IFERROR(VLOOKUP("영업이익",subQ,MATCH(E$5,SUBQH,0),0),"") | F10: =IFERROR(VLOOKUP("영업이익",subQ,MATCH(F$5,SUBQH,0),0),"") | G10: =IFERROR(VLOOKUP("영업이익",subQ,MATCH(G$5,SUBQH,0),0),"")
C11: ROE(EPS/기초BPS) | E11: =IFERROR(E7/D8,"") | F11: =IFERROR(F7/E8,"") | G11: =IFERROR(G7/F8,"")
B13: PER
C14: 12M fwd EPS | D14: =IFERROR(E7*변수!D46+F7*(1-변수!D46),"")
C15: 적정가치 @PER_lo | D15: =변수!D43 | E15: =IFERROR(ROUND($D$14*D15,-2),"") | F15: =IFERROR(E15/$C$1-1,"") | G15: 배 · 원 · 종가 대비
C16: 적정가치 @PER_mid | D16: =변수!D44 | E16: =IFERROR(ROUND($D$14*D16,-2),"") | F16: =IFERROR(E16/$C$1-1,"") | G16: 배 · 원 · 종가 대비
C17: 적정가치 @PER_hi | D17: =변수!D45 | E17: =IFERROR(ROUND($D$14*D17,-2),"") | F17: =IFERROR(E17/$C$1-1,"") | G17: 배 · 원 · 종가 대비
C18: 현재 PER(종가/12M fwd EPS) | D18: =IFERROR($C$1/$D$14,"")
B20: PBR
C21: 최근 BPS(마지막 실적 분기) | D21: =IFERROR(VLOOKUP("BPS",subQ,MATCH("2Q26",SUBQH,0),0),"")
C22: ROE fwd(12M fwd EPS / BPS) | D22: =IFERROR($D$14/$D$21,"")
C23: COE | D23: =변수!D42
C24: 적정 PBR = ROE/COE | D24: =IFERROR(D22/D23,"")
C25: 적정가치(PBR) = BPS × 적정PBR | D25: =IFERROR(ROUND(D21*D24,-2),"") | E25: =IFERROR(D25/$C$1-1,"")
C26: 현재 PBR(종가/BPS) | D26: =IFERROR($C$1/D21,"")
B28: 모델 json valuation(참고)
C29: eps_fwd12m | D29: -707.8
C30: bps_latest | D30: 5817.1
C31: per_now
C32: pbr_now | D32: 1.7
C33: roe_fwd | D33: -0.1217
C34: fair_pbr
C35: fair_value_pbr
C36: ev_ebitda
C37: note | D37: 모델 산출값 — 목표주가·추천 아님

Sheet 외화
C1: 이름: 외화QH — 환율 QoQ · 외화 순노출 × Δ기말환율 | E1: 2Q25 | F1: 3Q25 | G1: 4Q25 | H1: 1Q26 | I1: 2Q26 | J1: 3Q26 | K1: 4Q26 | L1: 1Q27 | M1: 2Q27 | N1: 3Q27 | O1: 4Q27 | P1: 1Q28 | Q1: 2Q28 | R1: 3Q28 | S1: 4Q28
E3: 1 | F3: 2 | G3: 3 | H3: 4 | I3: 5 | J3: 6 | K3: 7 | L3: 8 | M3: 9 | N3: 10 | O3: 11 | P3: 12 | Q3: 13 | R3: 14 | S3: 15
E4: 2025.06 | F4: 2025.09 | G4: 2025.12 | H4: 2026.03 | I4: 2026.06 | J4: 2026.09 | K4: 2026.12 | L4: 2027.03 | M4: 2027.06 | N4: 2027.09 | O4: 2027.12 | P4: 2028.03 | Q4: 2028.06 | R4: 2028.09 | S4: 2028.12
D5: 원/달러(평균) | E5: =IFERROR(VLOOKUP($D5,환율,MATCH(E$1,변수H,0),0),"") | F5: =IFERROR(VLOOKUP($D5,환율,MATCH(F$1,변수H,0),0),"") | G5: =IFERROR(VLOOKUP($D5,환율,MATCH(G$1,변수H,0),0),"") | H5: =IFERROR(VLOOKUP($D5,환율,MATCH(H$1,변수H,0),0),"") | I5: =IFERROR(VLOOKUP($D5,환율,MATCH(I$1,변수H,0),0),"") | J5: =IFERROR(VLOOKUP($D5,환율,MATCH(J$1,변수H,0),0),"") | K5: =IFERROR(VLOOKUP($D5,환율,MATCH(K$1,변수H,0),0),"") | L5: =IFERROR(VLOOKUP($D5,환율,MATCH(L$1,변수H,0),0),"") | ... S5: =IFERROR(VLOOKUP($D5,환율,MATCH(S$1,변수H,0),0),"")
A6: 원/달러(평균) QoQ | F6: =IFERROR(F5/E5-1,"") | G6: =IFERROR(G5/F5-1,"") | H6: =IFERROR(H5/G5-1,"") | I6: =IFERROR(I5/H5-1,"") | J6: =IFERROR(J5/I5-1,"") | K6: =IFERROR(K5/J5-1,"") | L6: =IFERROR(L5/K5-1,"") | M6: =IFERROR(M5/L5-1,"") | ... S6: =IFERROR(S5/R5-1,"")
D7: 원/달러(기말) | E7: =IFERROR(VLOOKUP($D7,환율,MATCH(E$1,변수H,0),0),"") | F7: =IFERROR(VLOOKUP($D7,환율,MATCH(F$1,변수H,0),0),"") | G7: =IFERROR(VLOOKUP($D7,환율,MATCH(G$1,변수H,0),0),"") | H7: =IFERROR(VLOOKUP($D7,환율,MATCH(H$1,변수H,0),0),"") | I7: =IFERROR(VLOOKUP($D7,환율,MATCH(I$1,변수H,0),0),"") | J7: =IFERROR(VLOOKUP($D7,환율,MATCH(J$1,변수H,0),0),"") | K7: =IFERROR(VLOOKUP($D7,환율,MATCH(K$1,변수H,0),0),"") | L7: =IFERROR(VLOOKUP($D7,환율,MATCH(L$1,변수H,0),0),"") | ... S7: =IFERROR(VLOOKUP($D7,환율,MATCH(S$1,변수H,0),0),"")
A8: 원/달러(기말) QoQ | F8: =IFERROR(F7/E7-1,"") | G8: =IFERROR(G7/F7-1,"") | H8: =IFERROR(H7/G7-1,"") | I8: =IFERROR(I7/H7-1,"") | J8: =IFERROR(J7/I7-1,"") | K8: =IFERROR(K7/J7-1,"") | L8: =IFERROR(L7/K7-1,"") | M8: =IFERROR(M7/L7-1,"") | ... S8: =IFERROR(S7/R7-1,"")
D9: W/Euro(평균) | E9: =IFERROR(VLOOKUP($D9,환율,MATCH(E$1,변수H,0),0),"") | F9: =IFERROR(VLOOKUP($D9,환율,MATCH(F$1,변수H,0),0),"") | G9: =IFERROR(VLOOKUP($D9,환율,MATCH(G$1,변수H,0),0),"") | H9: =IFERROR(VLOOKUP($D9,환율,MATCH(H$1,변수H,0),0),"") | I9: =IFERROR(VLOOKUP($D9,환율,MATCH(I$1,변수H,0),0),"") | J9: =IFERROR(VLOOKUP($D9,환율,MATCH(J$1,변수H,0),0),"") | K9: =IFERROR(VLOOKUP($D9,환율,MATCH(K$1,변수H,0),0),"") | L9: =IFERROR(VLOOKUP($D9,환율,MATCH(L$1,변수H,0),0),"") | ... S9: =IFERROR(VLOOKUP($D9,환율,MATCH(S$1,변수H,0),0),"")
A10: W/Euro(평균) QoQ | F10: =IFERROR(F9/E9-1,"") | G10: =IFERROR(G9/F9-1,"") | H10: =IFERROR(H9/G9-1,"") | I10: =IFERROR(I9/H9-1,"") | J10: =IFERROR(J9/I9-1,"") | K10: =IFERROR(K9/J9-1,"") | L10: =IFERROR(L9/K9-1,"") | M10: =IFERROR(M9/L9-1,"") | ... S10: =IFERROR(S9/R9-1,"")
D11: W/Euro(기말) | E11: =IFERROR(VLOOKUP($D11,환율,MATCH(E$1,변수H,0),0),"") | F11: =IFERROR(VLOOKUP($D11,환율,MATCH(F$1,변수H,0),0),"") | G11: =IFERROR(VLOOKUP($D11,환율,MATCH(G$1,변수H,0),0),"") | H11: =IFERROR(VLOOKUP($D11,환율,MATCH(H$1,변수H,0),0),"") | I11: =IFERROR(VLOOKUP($D11,환율,MATCH(I$1,변수H,0),0),"") | J11: =IFERROR(VLOOKUP($D11,환율,MATCH(J$1,변수H,0),0),"") | K11: =IFERROR(VLOOKUP($D11,환율,MATCH(K$1,변수H,0),0),"") | L11: =IFERROR(VLOOKUP($D11,환율,MATCH(L$1,변수H,0),0),"") | ... S11: =IFERROR(VLOOKUP($D11,환율,MATCH(S$1,변수H,0),0),"")
A12: W/Euro(기말) QoQ | F12: =IFERROR(F11/E11-1,"") | G12: =IFERROR(G11/F11-1,"") | H12: =IFERROR(H11/G11-1,"") | I12: =IFERROR(I11/H11-1,"") | J12: =IFERROR(J11/I11-1,"") | K12: =IFERROR(K11/J11-1,"") | L12: =IFERROR(L11/K11-1,"") | M12: =IFERROR(M11/L11-1,"") | ... S12: =IFERROR(S11/R11-1,"")
D13: 원/100Y(기말) | E13: =IFERROR(VLOOKUP($D13,환율,MATCH(E$1,변수H,0),0),"") | F13: =IFERROR(VLOOKUP($D13,환율,MATCH(F$1,변수H,0),0),"") | G13: =IFERROR(VLOOKUP($D13,환율,MATCH(G$1,변수H,0),0),"") | H13: =IFERROR(VLOOKUP($D13,환율,MATCH(H$1,변수H,0),0),"") | I13: =IFERROR(VLOOKUP($D13,환율,MATCH(I$1,변수H,0),0),"") | J13: =IFERROR(VLOOKUP($D13,환율,MATCH(J$1,변수H,0),0),"") | K13: =IFERROR(VLOOKUP($D13,환율,MATCH(K$1,변수H,0),0),"") | L13: =IFERROR(VLOOKUP($D13,환율,MATCH(L$1,변수H,0),0),"") | ... S13: =IFERROR(VLOOKUP($D13,환율,MATCH(S$1,변수H,0),0),"")
A14: 원/100Y(기말) QoQ | F14: =IFERROR(F13/E13-1,"") | G14: =IFERROR(G13/F13-1,"") | H14: =IFERROR(H13/G13-1,"") | I14: =IFERROR(I13/H13-1,"") | J14: =IFERROR(J13/I13-1,"") | K14: =IFERROR(K13/J13-1,"") | L14: =IFERROR(L13/K13-1,"") | M14: =IFERROR(M13/L13-1,"") | ... S14: =IFERROR(S13/R13-1,"")
A16: 외화순노출 | C16: 외화 순노출(백만$) | D16: =변수!D53 | E16: 외화 순노출 × Δ기말환율 (외화 시트 방식)
A17: 환관련손익추정 | C17: 환관련손익 추정(억원) = 순노출 × Δ원/달러(기말) / 100 | F17: =IFERROR($D$16*(F7-E7)/100,"") | G17: =IFERROR($D$16*(G7-F7)/100,"") | H17: =IFERROR($D$16*(H7-G7)/100,"") | I17: =IFERROR($D$16*(I7-H7)/100,"") | J17: =IFERROR($D$16*(J7-I7)/100,"") | K17: =IFERROR($D$16*(K7-J7)/100,"") | L17: =IFERROR($D$16*(L7-K7)/100,"") | M17: =IFERROR($D$16*(M7-L7)/100,"") | ... S17: =IFERROR($D$16*(S7-R7)/100,"")
A18: fx_pnl.by_q | C18: 모델 fx_pnl.by_q(억원, 참고)
C19: 외화 순노출 미공시(face) → 0 + 표기
