Workbook
Name 변수H: 변수!$C$1:$AO$1
Name 환율: 변수!$C$6:$AO$13
Name BS연결H: BS연결!$C$1:$AO$1
Name BS연결: BS연결!$C$5:$AO$104
Name BS별도H: BS별도!$C$1:$AO$1
Name BS별도: BS별도!$C$5:$AO$90
Name SUBQH: subQ!$A$1:$AO$1
Name subQ: subQ!$A$5:$AO$44

Sheet README
A1: 나노(187790) 실적 모델 — ARGUS 한국조선
A2: 기준 분기 2026Q2 · 마지막 실적 2026Q2 · 생성 2026-10-14
A3: 모든 수치는 모델 산출값(DART 공개 재무제표 + 우리 추정)이다 — 목표주가·투자 추천 아님. 참고용 · 투자조언 아님.
A5: 시트
A6: 변수 가정 시계열. 환율 8행(ECB via frankfurter — L2 fx.json; 추정 분기 = 노란 가정), 추정 드라이버(노란 셀 = 모델값에서 역산한 가정, 바꾸면 재계산; 연녹 셀 = 3절 스칼라 참조 수식), 3절 스칼라 가정(세율·판관비율·지배주주비중·이자율·종가·PER 밴드·COE·외화 순노출·헤지비율)
A7: BS연결/BS별도 FnGuide 계정명 × 기간 값 덤프(백만원). 행1 분기라벨, 행4 YYYY.MM / YYYY.12A. 이름정의 BS연결H·BS연결(계정명 C열부터)
A8: subQ 분기 서브모델(억원 = 백만원/100). 확정 행: =IFERROR(VLOOKUP($D행,BS연결,MATCH(E$1,BS연결H,0),0)/100,"") 추정 행: 변수 시트 가정 셀 참조 수식. 외환손익·파생상품손익은 BS 계정 합·차, 기타금융손익은 잔차, OPM·EPS·BPS·PER·PBR 은 파생 수식, 조정EPS 는 EPS 참조(일회성 의심 분기만 산식 셀)
A9: SLS 선표(조선사만, sls json 있을 때): 요약 행(sls 저장값) + 계약별 스케줄(백만$) × (헤지비율 × 헤지환율 + (1−헤지비율) × 건조시점 환율[변수 원/달러(평균)]) → 원화 수식 블록 → 합계 행이 subQ 매출조선에 연결
A10: 시나리오 신규수주 보수/기준/낙관(forecast_panel 패널, 모델에 scenarios 가 있을 때만): 매출액·영업이익 = subQ 기준값 ± (시나리오 신규 − base 신규) × OPM. base 만 subQ 행에 포함, 나머지는 합산 안 함
A11: 분기/연간예상 subQ 를 이름(A열 key)으로 VLOOKUP 한 보고서 표(억원)
A12: TP PER 밴드 × 12M fwd EPS, PBR = ROE/COE × BPS — 모델 산출값 구간, 목표주가·추천 아님
A13: 외화 환율 QoQ, 외화 순노출 × Δ기말환율 → 환관련손익 추정
... A35: 백테스트: {"freeze": "2025Q2", "horizon": 4, "revenue_wape_pct": 29.5, "op_wape_pct": 91.0, "n": 4, "note": "단일 회사 4분기 — 통계 아님", "driver_at_freeze": "trend_seasonal", "selection_oos_at_freeze": null, "frozen_inputs": "fin(연결/별도)·고객 조선사 모델·지주 자회사 모델은 2025Q2 까지의 분기만; 선표는 체결일 ≤ 2025Q2 말일 계약(원장 최신 금액·코호트 등급, 환산 없음); 잔고는 yards_cache 2025Q2; 시세·환율 forward·prices·forecast_panel 신규수주 미사용. 고객 가중치(suppliers.json 언급 비중)와 합병 체인링크는 현재 지식; 고객 연동 채택은 동결 모델 안에서도 자기 la−4분기 OOS 규칙(selection_oos_at_freeze)", "detail": [{"q": "2025Q3", "rev_pred": 230.27, "rev_act": 344.65, "op_pred": 5.17, "op_act": 55.18}, {"q": "2025Q4", "rev_pred": 187.56, "rev_act": 217.83, "op_pred": 4.21, "op_act": 2.58}, {"q": "2026Q1", "rev_pred": 121.73, "rev_act": 110.35, "op_pred": 2.74, "op_act": -8.89}, {"q": "2026Q2", "rev_pred": 140.47, "rev_act": 259.5, "op_pred": 3.16, "op_act": 5.83}]}

Sheet 변수
C1: 이름: 변수H | E1: 4Q21 | F1: 2021 | G1: 1Q22 | H1: 2Q22 | I1: 3Q22 | J1: 4Q22 | K1: 2022 | L1: 1Q23 | M1: 2Q23 | N1: 3Q23 | O1: 4Q23 | P1: 2023 | Q1: 1Q24 | R1: 2Q24 | S1: 3Q24 | T1: 4Q24 | U1: 2024 | V1: 1Q25 | W1: 2Q25 | X1: 3Q25 | Y1: 4Q25 | Z1: 2025 | AA1: 1Q26 | AB1: 2Q26 | AC1: 3Q26 | AD1: 4Q26 | AE1: 2026 | AF1: 1Q27 | AG1: 2Q27 | AH1: 3Q27 | AI1: 4Q27 | AJ1: 2027 | AK1: 1Q28 | AL1: 2Q28 | AM1: 3Q28 | AN1: 4Q28 | AO1: 2028
A2: 가정 시계열 — 노란 셀은 추정 가정(모델값에서 역산), 연녹 셀은 3절 스칼라 참조 수식. 바꾸면 subQ·분기·연간예상·TP·시나리오가 재계산됩니다.
E3: 1 | F3: 2 | G3: 3 | H3: 4 | I3: 5 | J3: 6 | K3: 7 | L3: 8 | M3: 9 | N3: 10 | O3: 11 | P3: 12 | Q3: 13 | R3: 14 | S3: 15 | T3: 16 | U3: 17 | V3: 18 | W3: 19 | X3: 20 | Y3: 21 | Z3: 22 | AA3: 23 | AB3: 24 | AC3: 25 | AD3: 26 | AE3: 27 | AF3: 28 | AG3: 29 | AH3: 30 | AI3: 31 | AJ3: 32 | AK3: 33 | AL3: 34 | AM3: 35 | AN3: 36 | AO3: 37
E4: 2021.12 | F4: 2021.12A | G4: 2022.03 | H4: 2022.06 | I4: 2022.09 | J4: 2022.12 | K4: 2022.12A | L4: 2023.03 | M4: 2023.06 | N4: 2023.09 | O4: 2023.12 | P4: 2023.12A | Q4: 2024.03 | R4: 2024.06 | S4: 2024.09 | T4: 2024.12 | U4: 2024.12A | V4: 2025.03 | W4: 2025.06 | X4: 2025.09 | Y4: 2025.12 | Z4: 2025.12A | AA4: 2026.03 | AB4: 2026.06 | AC4: 2026.09 | AD4: 2026.12 | AE4: 2026.12A | AF4: 2027.03 | AG4: 2027.06 | AH4: 2027.09 | AI4: 2027.12 | AJ4: 2027.12A | AK4: 2028.03 | AL4: 2028.06 | AM4: 2028.09 | AN4: 2028.12 | AO4: 2028.12A
B5: 1. FX | C5: 이름: 환율
A6: USDKRW_avg | C6: 원/달러(평균) | E6: 1183.5 | F6: 1145.51 | G6: 1205.78 | H6: 1262.09 | I6: 1341.93 | J6: 1360.12 | K6: 1292.98 | L6: 1276.95 | M6: 1315.69 | N6: 1313.62 | O6: 1322.01 | P6: 1306.85 | Q6: 1330.14 | R6: 1371.28 | S6: 1356.22 | T6: 1396.3 | U6: 1363.53 | V6: 1452.28 | W6: 1398.52 | X6: 1386.95 | Y6: 1449.19 | Z6: 1421.52 | AA6: 1466.12 | AB6: 1501.75 | AC6: 1418.75 | AD6: 1343.39 | AE6: 1456.01 | AF6: 1341.45 | AG6: 1341.45 | AH6: 1341.45 | AI6: 1341.45 | AK6: 1341.45 | AL6: 1341.45 | AM6: 1341.45 | AN6: 1341.45
A7: USDKRW_end | C7: 원/달러(기말) | E7: 1188.75 | F7: 1188.75 | G7: 1213.74 | H7: 1301.24 | I7: 1436.9 | J7: 1260.16 | K7: 1260.16 | L7: 1305.99 | M7: 1321.44 | N7: 1345.35 | O7: 1297.43 | P7: 1297.43 | Q7: 1349.25 | R7: 1377.73 | S7: 1312.17 | T7: 1474.78 | U7: 1474.78 | V7: 1474.54 | W7: 1355.13 | X7: 1403.67 | Y7: 1444.2 | Z7: 1444.2 | AA7: 1524.8 | AB7: 1550.89 | AC7: 1355.4 | AD7: 1341.45 | AE7: 1341.45 | AF7: 1341.45 | AG7: 1341.45 | AH7: 1341.45 | AI7: 1341.45 | AK7: 1341.45 | AL7: 1341.45 | AM7: 1341.45 | AN7: 1341.45
A8: JPY100KRW_avg | C8: 원/100Y(평균) | E8: 1041.02 | F8: 1042.74 | G8: 1036.79 | H8: 972.23 | I8: 970.61 | J8: 961.03 | K8: 985.1 | L8: 964.89 | M8: 957.36 | N8: 909 | O8: 893.22 | P8: 931.11 | Q8: 896.29 | R8: 880.14 | S8: 909.35 | T8: 917.25 | U8: 900.92 | V8: 952.59 | W8: 967.92 | X8: 940.32 | Y8: 940.77 | Z8: 950.17 | AA8: 934.39 | AB8: 942.16 | AC8: 890.41 | AD8: 849.39 | AE8: 918.46 | AF8: 848.37 | AG8: 848.37 | AH8: 848.37 | AI8: 848.37 | AK8: 848.37 | AL8: 848.37 | AM8: 848.37 | AN8: 848.37
A9: JPY100KRW_end | C9: 원/100Y(기말) | E9: 1032.62 | F9: 1032.62 | G9: 996.83 | H9: 954.9 | I9: 993.29 | J9: 955.54 | K9: 955.54 | L9: 980.62 | M9: 913.67 | N9: 901.47 | O9: 917.04 | P9: 917.04 | Q9: 892.42 | R9: 857.76 | S9: 919.21 | T9: 939.65 | U9: 939.65 | V9: 986.84 | W9: 938.85 | X9: 948.49 | Y9: 921.81 | Z9: 921.81 | AA9: 955.99 | AB9: 954.75 | AC9: 863.31 | AD9: 848.37 | AE9: 848.37 | AF9: 848.37 | AG9: 848.37 | AH9: 848.37 | AI9: 848.37 | AK9: 848.37 | AL9: 848.37 | AM9: 848.37 | AN9: 848.37
A10: EURKRW_avg | C10: W/Euro(평균) | E10: 1353.32 | F10: 1354.06 | G10: 1352.29 | H10: 1343.31 | I10: 1350.63 | J10: 1386.07 | K10: 1358.07 | L10: 1369.93 | M10: 1432.41 | N10: 1429.41 | O10: 1420.91 | P10: 1412.88 | Q10: 1444.21 | R10: 1476.42 | S10: 1489.3 | T10: 1490.78 | U10: 1475.4 | V10: 1528.33 | W10: 1585.13 | X10: 1620.04 | Y10: 1686.02 | Z10: 1605.45 | AA10: 1715.47 | AB10: 1746.09 | AC10: 1631.97 | AD10: 1506.62 | AE10: 1688.01 | AF10: 1500.82 | AG10: 1500.82 | AH10: 1500.82 | AI10: 1500.82 | AK10: 1500.82 | AL10: 1500.82 | AM10: 1500.82 | AN10: 1500.82
A11: EURKRW_end | C11: W/Euro(기말) | E11: 1346.38 | F11: 1346.38 | G11: 1347.37 | H11: 1351.6 | I11: 1400.62 | J11: 1344.08 | K11: 1344.08 | L11: 1420.26 | M11: 1435.88 | N11: 1425.26 | O11: 1433.66 | P11: 1433.66 | Q11: 1458.68 | R11: 1474.86 | S11: 1469.1 | T11: 1532.14 | U11: 1532.14 | V11: 1594.72 | W11: 1588.22 | X11: 1648.04 | Y11: 1696.94 | Z11: 1696.94 | AA11: 1753.21 | AB11: 1767.09 | AC11: 1539.06 | AD11: 1500.82 | AE11: 1500.82 | AF11: 1500.82 | AG11: 1500.82 | AH11: 1500.82 | AI11: 1500.82 | AK11: 1500.82 | AL11: 1500.82 | AM11: 1500.82 | AN11: 1500.82
A12: CNYKRW_avg | C12: 원/중국원(평균) | E12: 185.14 | F12: 177.65 | G12: 189.93 | H12: 190.76 | I12: 195.79 | J12: 191.09 | K12: 191.93 | L12: 186.59 | M12: 187.45 | N12: 181.28 | O12: 182.86 | P12: 184.52 | Q12: 185.04 | R12: 189.35 | S12: 189.24 | T12: 194.24 | U12: 189.49 | V12: 199.63 | W12: 193.41 | X12: 193.79 | Y12: 204.38 | Z12: 197.8 | AA12: 211.75 | AB12: 220.8 | AC12: 210.43 | AD12: 200.49 | AE12: 213.61 | AF12: 200.4 | AG12: 200.4 | AH12: 200.4 | AI12: 200.4 | AK12: 200.4 | AL12: 200.4 | AM12: 200.4 | AN12: 200.4
A13: CNYKRW_end | C13: 원/중국원(기말) | E13: 187.13 | F13: 187.13 | G13: 191.38 | H13: 194.13 | I13: 201.92 | J13: 182.67 | K13: 182.67 | L13: 189.97 | M13: 181.8 | N13: 184.26 | O13: 182.61 | P13: 182.61 | Q13: 186.66 | R13: 189.7 | S13: 187.12 | T13: 202.04 | U13: 202.04 | V13: 203.3 | W13: 189.14 | X13: 197.16 | Y13: 206.28 | Z13: 206.28 | AA13: 220.97 | AB13: 228.56 | AC13: 202.16 | AD13: 200.4 | AE13: 200.4 | AF13: 200.4 | AG13: 200.4 | AH13: 200.4 | AI13: 200.4 | AK13: 200.4 | AL13: 200.4 | AM13: 200.4 | AN13: 200.4
B14: 1b. 종가
A15: price_close_end | C15: 종가(기말) | E15: 1860 | G15: 1772 | H15: 1212 | I15: 1119 | J15: 1130 | L15: 1297 | M15: 1487 | N15: 1443 | O15: 1492 | Q15: 1298 | R15: 1125 | W15: 1340 | X15: 1923 | Y15: 3480 | AA15: 3265 | AB15: 3640 | AC15: 3045 | AD15: 2680
A16: price_high | C16: 종가(최고) | E16: 2716 | G16: 2079 | H16: 1886 | I16: 1695 | J16: 1530 | L16: 1925 | M16: 1856 | N16: 2151 | O16: 1811 | Q16: 1518 | R16: 1320 | W16: 1370 | X16: 2190 | Y16: 4155 | AA16: 5000 | AB16: 7560 | AC16: 4005 | AD16: 3300
A17: price_low | C17: 종가(최저) | E17: 1662 | G17: 1579 | H17: 1075 | I17: 1075 | J17: 1033 | L17: 1118 | M17: 1245 | N17: 1294 | O17: 1241 | Q17: 1186 | R17: 1038 | W17: 936 | X17: 1261 | Y17: 1685 | AA17: 3075 | AB17: 3100 | AC17: 2160 | AD17: 2660
A18: price_avg | C18: 종가(평균) | E18: 2093.8 | G18: 1826.5 | H18: 1501 | I18: 1283.3 | J18: 1240.5 | L18: 1350.3 | M18: 1418.7 | N18: 1513.4 | O18: 1416.9 | Q18: 1431.9 | R18: 1236.6 | W18: 1080.4 | X18: 1781.7 | Y18: 2826.2 | AA18: 3846.3 | AB18: 5041.6 | AC18: 3053.3 | AD18: 3049.4
B20: 2. 추정 드라이버 | C20: 실적 열 = subQ 실현값(수식), 추정 열 = 가정(노란 = 모델값 역산, 연녹 = 3절 스칼라 참조)
A21: drv:매출액 | B21: yoy | C21: 매출액 YoY | J21: =IFERROR(subQ!J5/subQ!E5-1,"") | L21: =IFERROR(subQ!L5/subQ!G5-1,"") | M21: =IFERROR(subQ!M5/subQ!H5-1,"") | N21: =IFERROR(subQ!N5/subQ!I5-1,"") | O21: =IFERROR(subQ!O5/subQ!J5-1,"") | Q21: =IFERROR(subQ!Q5/subQ!L5-1,"") | R21: =IFERROR(subQ!R5/subQ!M5-1,"") | S21: =IFERROR(subQ!S5/subQ!N5-1,"") | T21: =IFERROR(subQ!T5/subQ!O5-1,"") | V21: =IFERROR(subQ!V5/subQ!Q5-1,"") | W21: =IFERROR(subQ!W5/subQ!R5-1,"") | X21: =IFERROR(subQ!X5/subQ!S5-1,"") | Y21: =IFERROR(subQ!Y5/subQ!T5-1,"") | AA21: =IFERROR(subQ!AA5/subQ!V5-1,"") | AB21: =IFERROR(subQ!AB5/subQ!W5-1,"") | AC21: 0.22160514 | AD21: 0.22158361 | AF21: 0.22160744 | AG21: 0.2215992 | AH21: 0.11077595 | AI21: 0.11078542 | AK21: 0.11074846 | AL21: 0.11078515 | AM21: 0.055402314 | AN21: 0.055416469
A22: drv:판관비 | B22: ratio | C22: 판관비율(/매출) | E22: =IFERROR(subQ!E8/subQ!E5,"") | F22: =IFERROR(subQ!F8/subQ!F5,"") | G22: =IFERROR(subQ!G8/subQ!G5,"") | H22: =IFERROR(subQ!H8/subQ!H5,"") | I22: =IFERROR(subQ!I8/subQ!I5,"") | J22: =IFERROR(subQ!J8/subQ!J5,"") | K22: =IFERROR(subQ!K8/subQ!K5,"") | L22: =IFERROR(subQ!L8/subQ!L5,"") | ... AB22: =IFERROR(subQ!AB8/subQ!AB5,"") | AC22: =$D$52 | AD22: =$D$52 | AE22: =IFERROR(subQ!AE8/subQ!AE5,"") | AF22: =$D$52 | AG22: =$D$52 | AH22: =$D$52 | AI22: =$D$52 | AJ22: =IFERROR(subQ!AJ8/subQ!AJ5,"") | AK22: =$D$52 | AL22: =$D$52 | AM22: =$D$52 | AN22: =$D$52 | AO22: =IFERROR(subQ!AO8/subQ!AO5,"")
A23: drv:영업이익 | B23: ratio | C23: 영업이익률(OPM) | E23: =IFERROR(subQ!E9/subQ!E5,"") | F23: =IFERROR(subQ!F9/subQ!F5,"") | G23: =IFERROR(subQ!G9/subQ!G5,"") | H23: =IFERROR(subQ!H9/subQ!H5,"") | I23: =IFERROR(subQ!I9/subQ!I5,"") | J23: =IFERROR(subQ!J9/subQ!J5,"") | K23: =IFERROR(subQ!K9/subQ!K5,"") | L23: =IFERROR(subQ!L9/subQ!L5,"") | ... AB23: =IFERROR(subQ!AB9/subQ!AB5,"") | AC23: 0.006365342 | AD23: 0.006388576 | AE23: =IFERROR(subQ!AE9/subQ!AE5,"") | AF23: 0.006379349 | AG23: 0.006372039 | AH23: 0.006372014 | AI23: 0.006360376 | AJ23: =IFERROR(subQ!AJ9/subQ!AJ5,"") | AK23: 0.00634433 | AL23: 0.006361287 | AM23: 0.006381944 | AN23: 0.006379023 | AO23: =IFERROR(subQ!AO9/subQ!AO5,"")
A24: drv:외환손익 | B24: abs | C24: 외환손익 (가정, 억원) | E24: =subQ!E13 | F24: =subQ!F13 | G24: =subQ!G13 | H24: =subQ!H13 | I24: =subQ!I13 | J24: =subQ!J13 | K24: =subQ!K13 | L24: =subQ!L13 | ... AB24: =subQ!AB13 | AC24: 0 | AD24: 0 | AE24: =subQ!AE13 | AF24: 0 | AG24: 0 | AH24: 0 | AI24: 0 | AJ24: =subQ!AJ13 | AK24: 0 | AL24: 0 | AM24: 0 | AN24: 0 | AO24: =subQ!AO13
A25: drv:파생상품손익 | B25: abs | C25: 파생상품손익 (가정, 억원) | E25: =subQ!E14 | F25: =subQ!F14 | G25: =subQ!G14 | H25: =subQ!H14 | I25: =subQ!I14 | J25: =subQ!J14 | K25: =subQ!K14 | L25: =subQ!L14 | ... AB25: =subQ!AB14 | AC25: 0 | AD25: 0 | AE25: =subQ!AE14 | AF25: 0 | AG25: 0 | AH25: 0 | AI25: 0 | AJ25: =subQ!AJ14 | AK25: 0 | AL25: 0 | AM25: 0 | AN25: 0 | AO25: =subQ!AO14
A26: drv:기타금융손익 | B26: abs | C26: 기타금융손익 (가정, 억원) | E26: =subQ!E15 | F26: =subQ!F15 | G26: =subQ!G15 | H26: =subQ!H15 | I26: =subQ!I15 | J26: =subQ!J15 | K26: =subQ!K15 | L26: =subQ!L15 | ... AB26: =subQ!AB15 | AC26: 0 | AD26: 0 | AE26: =subQ!AE15 | AF26: 0 | AG26: 0 | AH26: 0 | AI26: 0 | AJ26: =subQ!AJ15 | AK26: 0 | AL26: 0 | AM26: 0 | AN26: 0 | AO26: =subQ!AO15
A27: drv:기타영업외손익 | B27: abs | C27: 기타영업외손익 (가정, 억원) | E27: =subQ!E16 | F27: =subQ!F16 | G27: =subQ!G16 | H27: =subQ!H16 | I27: =subQ!I16 | J27: =subQ!J16 | K27: =subQ!K16 | L27: =subQ!L16 | ... AB27: =subQ!AB16 | AC27: 0 | AD27: 0 | AE27: =subQ!AE16 | AF27: 0 | AG27: 0 | AH27: 0 | AI27: 0 | AJ27: =subQ!AJ16 | AK27: 0 | AL27: 0 | AM27: 0 | AN27: 0 | AO27: =subQ!AO16
A28: drv:지분법손익 | B28: abs | C28: 지분법손익 (가정, 억원) | E28: =subQ!E17 | F28: =subQ!F17 | G28: =subQ!G17 | H28: =subQ!H17 | I28: =subQ!I17 | J28: =subQ!J17 | K28: =subQ!K17 | L28: =subQ!L17 | ... AB28: =subQ!AB17 | AC28: -3.98 | AD28: -3.98 | AE28: =subQ!AE17 | AF28: -3.98 | AG28: -3.98 | AH28: -3.98 | AI28: -3.98 | AJ28: =subQ!AJ17 | AK28: -3.98 | AL28: -3.98 | AM28: -3.98 | AN28: -3.98 | AO28: =subQ!AO17
A29: drv:법인세비용 | B29: ratio | C29: 법인세율(/세전) | E29: =IFERROR(subQ!E19/subQ!E18,"") | F29: =IFERROR(subQ!F19/subQ!F18,"") | G29: =IFERROR(subQ!G19/subQ!G18,"") | H29: =IFERROR(subQ!H19/subQ!H18,"") | I29: =IFERROR(subQ!I19/subQ!I18,"") | J29: =IFERROR(subQ!J19/subQ!J18,"") | K29: =IFERROR(subQ!K19/subQ!K18,"") | L29: =IFERROR(subQ!L19/subQ!L18,"") | ... AB29: =IFERROR(subQ!AB19/subQ!AB18,"") | AC29: 0 | AD29: 0 | AE29: =IFERROR(subQ!AE19/subQ!AE18,"") | AF29: 0 | AG29: 0 | AH29: 0 | AI29: 0 | AJ29: =IFERROR(subQ!AJ19/subQ!AJ18,"") | AK29: 0 | AL29: 0 | AM29: 0 | AN29: 0 | AO29: =IFERROR(subQ!AO19/subQ!AO18,"")
A30: drv:지배주주순이익 | B30: ratio | C30: 지배주주 비중(/당기순이익) | E30: =IFERROR(subQ!E21/subQ!E20,"") | F30: =IFERROR(subQ!F21/subQ!F20,"") | G30: =IFERROR(subQ!G21/subQ!G20,"") | H30: =IFERROR(subQ!H21/subQ!H20,"") | I30: =IFERROR(subQ!I21/subQ!I20,"") | J30: =IFERROR(subQ!J21/subQ!J20,"") | K30: =IFERROR(subQ!K21/subQ!K20,"") | L30: =IFERROR(subQ!L21/subQ!L20,"") | ... AB30: =IFERROR(subQ!AB21/subQ!AB20,"") | AC30: =$D$53 | AD30: =$D$53 | AE30: =IFERROR(subQ!AE21/subQ!AE20,"") | AF30: =$D$53 | AG30: =$D$53 | AH30: =$D$53 | AI30: =$D$53 | AJ30: =IFERROR(subQ!AJ21/subQ!AJ20,"") | AK30: =$D$53 | AL30: =$D$53 | AM30: =$D$53 | AN30: =$D$53 | AO30: =IFERROR(subQ!AO21/subQ!AO20,"")
A31: drv:부채총계 | B31: qoq | C31: 부채총계 QoQ | G31: =IFERROR(subQ!G23/subQ!E23-1,"") | H31: =IFERROR(subQ!H23/subQ!G23-1,"") | I31: =IFERROR(subQ!I23/subQ!H23-1,"") | J31: =IFERROR(subQ!J23/subQ!I23-1,"") | L31: =IFERROR(subQ!L23/subQ!J23-1,"") | M31: =IFERROR(subQ!M23/subQ!L23-1,"") | N31: =IFERROR(subQ!N23/subQ!M23-1,"") | O31: =IFERROR(subQ!O23/subQ!N23-1,"") | Q31: =IFERROR(subQ!Q23/subQ!O23-1,"") | R31: =IFERROR(subQ!R23/subQ!Q23-1,"") | S31: =IFERROR(subQ!S23/subQ!R23-1,"") | T31: =IFERROR(subQ!T23/subQ!S23-1,"") | V31: =IFERROR(subQ!V23/subQ!T23-1,"") | W31: =IFERROR(subQ!W23/subQ!V23-1,"") | X31: =IFERROR(subQ!X23/subQ!W23-1,"") | Y31: =IFERROR(subQ!Y23/subQ!X23-1,"") | AA31: =IFERROR(subQ!AA23/subQ!Y23-1,"") | AB31: =IFERROR(subQ!AB23/subQ!AA23-1,"") | AC31: 4.68e-07 | AD31: 0 | AF31: 0 | AG31: 0 | AH31: 0 | AI31: 0 | AK31: 0 | AL31: 0 | AM31: 0 | AN31: 0
A32: drv:자본총계 | B32: roll | C32: 자본총계 기타변동(배당 등, 억원) | G32: =IFERROR(subQ!E24+subQ!G20-subQ!G24,"") | H32: =IFERROR(subQ!G24+subQ!H20-subQ!H24,"") | I32: =IFERROR(subQ!H24+subQ!I20-subQ!I24,"") | J32: =IFERROR(subQ!I24+subQ!J20-subQ!J24,"") | L32: =IFERROR(subQ!J24+subQ!L20-subQ!L24,"") | M32: =IFERROR(subQ!L24+subQ!M20-subQ!M24,"") | N32: =IFERROR(subQ!M24+subQ!N20-subQ!N24,"") | O32: =IFERROR(subQ!N24+subQ!O20-subQ!O24,"") | Q32: =IFERROR(subQ!O24+subQ!Q20-subQ!Q24,"") | R32: =IFERROR(subQ!Q24+subQ!R20-subQ!R24,"") | S32: =IFERROR(subQ!R24+subQ!S20-subQ!S24,"") | T32: =IFERROR(subQ!S24+subQ!T20-subQ!T24,"") | V32: =IFERROR(subQ!T24+subQ!V20-subQ!V24,"") | W32: =IFERROR(subQ!V24+subQ!W20-subQ!W24,"") | X32: =IFERROR(subQ!W24+subQ!X20-subQ!X24,"") | Y32: =IFERROR(subQ!X24+subQ!Y20-subQ!Y24,"") | AA32: =IFERROR(subQ!Y24+subQ!AA20-subQ!AA24,"") | AB32: =IFERROR(subQ!AA24+subQ!AB20-subQ!AB24,"") | AC32: -0.001421295 | AD32: 0.005551683 | AF32: 0.003593538 | AG32: -0.002010082 | AH32: 0.007218436 | AI32: -0.00961031 | AK32: -0.001144482 | AL32: 0.00333665 | AM32: 0.003116466 | AN32: 0.006669175
A33: drv:지배주주지분 | B33: roll | C33: 지배주주지분 기타변동(배당 등, 억원) | G33: =IFERROR(subQ!E25+subQ!G21-subQ!G25,"") | H33: =IFERROR(subQ!G25+subQ!H21-subQ!H25,"") | I33: =IFERROR(subQ!H25+subQ!I21-subQ!I25,"") | J33: =IFERROR(subQ!I25+subQ!J21-subQ!J25,"") | L33: =IFERROR(subQ!J25+subQ!L21-subQ!L25,"") | M33: =IFERROR(subQ!L25+subQ!M21-subQ!M25,"") | N33: =IFERROR(subQ!M25+subQ!N21-subQ!N25,"") | O33: =IFERROR(subQ!N25+subQ!O21-subQ!O25,"") | Q33: =IFERROR(subQ!O25+subQ!Q21-subQ!Q25,"") | R33: =IFERROR(subQ!Q25+subQ!R21-subQ!R25,"") | S33: =IFERROR(subQ!R25+subQ!S21-subQ!S25,"") | T33: =IFERROR(subQ!S25+subQ!T21-subQ!T25,"") | V33: =IFERROR(subQ!T25+subQ!V21-subQ!V25,"") | W33: =IFERROR(subQ!V25+subQ!W21-subQ!W25,"") | X33: =IFERROR(subQ!W25+subQ!X21-subQ!X25,"") | Y33: =IFERROR(subQ!X25+subQ!Y21-subQ!Y25,"") | AA33: =IFERROR(subQ!Y25+subQ!AA21-subQ!AA25,"") | AB33: =IFERROR(subQ!AA25+subQ!AB21-subQ!AB25,"") | AC33: -0.005421295 | AD33: 0.005551683 | AF33: 0.003593538 | AG33: 0.007989918 | AH33: -0.002781564 | AI33: 0.00038969 | AK33: -0.001144482 | AL33: -0.00666335 | AM33: 0.013116466 | AN33: -0.003330825
A34: drv:총차입금 | B34: qoq | C34: 총차입금 QoQ | G34: =IFERROR(subQ!G26/subQ!E26-1,"") | H34: =IFERROR(subQ!H26/subQ!G26-1,"") | I34: =IFERROR(subQ!I26/subQ!H26-1,"") | J34: =IFERROR(subQ!J26/subQ!I26-1,"") | L34: =IFERROR(subQ!L26/subQ!J26-1,"") | M34: =IFERROR(subQ!M26/subQ!L26-1,"") | N34: =IFERROR(subQ!N26/subQ!M26-1,"") | O34: =IFERROR(subQ!O26/subQ!N26-1,"") | Q34: =IFERROR(subQ!Q26/subQ!O26-1,"") | R34: =IFERROR(subQ!R26/subQ!Q26-1,"") | S34: =IFERROR(subQ!S26/subQ!R26-1,"") | T34: =IFERROR(subQ!T26/subQ!S26-1,"") | V34: =IFERROR(subQ!V26/subQ!T26-1,"") | W34: =IFERROR(subQ!W26/subQ!V26-1,"") | X34: =IFERROR(subQ!X26/subQ!W26-1,"") | Y34: =IFERROR(subQ!Y26/subQ!X26-1,"") | AA34: =IFERROR(subQ!AA26/subQ!Y26-1,"") | AB34: =IFERROR(subQ!AB26/subQ!AA26-1,"") | AC34: 9.564e-06 | AD34: 0 | AF34: 0 | AG34: 0 | AH34: 0 | AI34: 0 | AK34: 0 | AL34: 0 | AM34: 0 | AN34: 0
A35: drv:순차입금 | B35: qoq | C35: 순차입금 QoQ | G35: =IFERROR(subQ!G27/subQ!E27-1,"") | H35: =IFERROR(subQ!H27/subQ!G27-1,"") | I35: =IFERROR(subQ!I27/subQ!H27-1,"") | J35: =IFERROR(subQ!J27/subQ!I27-1,"") | L35: =IFERROR(subQ!L27/subQ!J27-1,"") | M35: =IFERROR(subQ!M27/subQ!L27-1,"") | N35: =IFERROR(subQ!N27/subQ!M27-1,"") | O35: =IFERROR(subQ!O27/subQ!N27-1,"") | Q35: =IFERROR(subQ!Q27/subQ!O27-1,"") | R35: =IFERROR(subQ!R27/subQ!Q27-1,"") | S35: =IFERROR(subQ!S27/subQ!R27-1,"") | T35: =IFERROR(subQ!T27/subQ!S27-1,"") | V35: =IFERROR(subQ!V27/subQ!T27-1,"") | W35: =IFERROR(subQ!W27/subQ!V27-1,"") | X35: =IFERROR(subQ!X27/subQ!W27-1,"") | Y35: =IFERROR(subQ!Y27/subQ!X27-1,"") | AA35: =IFERROR(subQ!AA27/subQ!Y27-1,"") | AB35: =IFERROR(subQ!AB27/subQ!AA27-1,"") | AC35: 0.017396513 | AD35: 0.021236471 | AF35: 0.02424729 | AG35: 0.019244336 | AH35: 0.015227841 | AI35: 0.019241695 | AK35: 0.022408859 | AL35: 0.017301541 | AM35: 0.013898814 | AN35: 0.017796102
A36: drv:이자발생자산 | B36: qoq | C36: 이자발생자산 QoQ | G36: =IFERROR(subQ!G28/subQ!E28-1,"") | H36: =IFERROR(subQ!H28/subQ!G28-1,"") | I36: =IFERROR(subQ!I28/subQ!H28-1,"") | J36: =IFERROR(subQ!J28/subQ!I28-1,"") | L36: =IFERROR(subQ!L28/subQ!J28-1,"") | M36: =IFERROR(subQ!M28/subQ!L28-1,"") | N36: =IFERROR(subQ!N28/subQ!M28-1,"") | O36: =IFERROR(subQ!O28/subQ!N28-1,"") | Q36: =IFERROR(subQ!Q28/subQ!O28-1,"") | R36: =IFERROR(subQ!R28/subQ!Q28-1,"") | S36: =IFERROR(subQ!S28/subQ!R28-1,"") | T36: =IFERROR(subQ!T28/subQ!S28-1,"") | V36: =IFERROR(subQ!V28/subQ!T28-1,"") | W36: =IFERROR(subQ!W28/subQ!V28-1,"") | X36: =IFERROR(subQ!X28/subQ!W28-1,"") | Y36: =IFERROR(subQ!Y28/subQ!X28-1,"") | AA36: =IFERROR(subQ!AA28/subQ!Y28-1,"") | AB36: =IFERROR(subQ!AB28/subQ!AA28-1,"") | AC36: -0.024771238 | AD36: -0.031523856 | AF36: -0.037954003 | AG36: -0.032005225 | AH36: -0.026788124 | AI36: -0.035221521 | AK36: -0.043262666 | AL36: -0.03582964 | AM36: -0.030227485 | AN36: -0.0406491
A37: drv:현금및현금성자산 | B37: qoq | C37: 현금및현금성자산 QoQ | G37: =IFERROR(subQ!G29/subQ!E29-1,"") | H37: =IFERROR(subQ!H29/subQ!G29-1,"") | I37: =IFERROR(subQ!I29/subQ!H29-1,"") | J37: =IFERROR(subQ!J29/subQ!I29-1,"") | L37: =IFERROR(subQ!L29/subQ!J29-1,"") | M37: =IFERROR(subQ!M29/subQ!L29-1,"") | N37: =IFERROR(subQ!N29/subQ!M29-1,"") | O37: =IFERROR(subQ!O29/subQ!N29-1,"") | Q37: =IFERROR(subQ!Q29/subQ!O29-1,"") | R37: =IFERROR(subQ!R29/subQ!Q29-1,"") | S37: =IFERROR(subQ!S29/subQ!R29-1,"") | T37: =IFERROR(subQ!T29/subQ!S29-1,"") | V37: =IFERROR(subQ!V29/subQ!T29-1,"") | W37: =IFERROR(subQ!W29/subQ!V29-1,"") | X37: =IFERROR(subQ!X29/subQ!W29-1,"") | Y37: =IFERROR(subQ!Y29/subQ!X29-1,"") | AA37: =IFERROR(subQ!AA29/subQ!Y29-1,"") | AB37: =IFERROR(subQ!AB29/subQ!AA29-1,"")
A38: drv:CAPEX | B38: yoy | C38: CAPEX YoY | J38: =IFERROR(subQ!J30/subQ!E30-1,"") | L38: =IFERROR(subQ!L30/subQ!G30-1,"") | M38: =IFERROR(subQ!M30/subQ!H30-1,"") | N38: =IFERROR(subQ!N30/subQ!I30-1,"") | O38: =IFERROR(subQ!O30/subQ!J30-1,"") | Q38: =IFERROR(subQ!Q30/subQ!L30-1,"") | R38: =IFERROR(subQ!R30/subQ!M30-1,"") | S38: =IFERROR(subQ!S30/subQ!N30-1,"") | T38: =IFERROR(subQ!T30/subQ!O30-1,"") | V38: =IFERROR(subQ!V30/subQ!Q30-1,"") | W38: =IFERROR(subQ!W30/subQ!R30-1,"") | X38: =IFERROR(subQ!X30/subQ!S30-1,"") | Y38: =IFERROR(subQ!Y30/subQ!T30-1,"") | AA38: =IFERROR(subQ!AA30/subQ!V30-1,"") | AB38: =IFERROR(subQ!AB30/subQ!W30-1,"") | AC38: -0.64551414 | AD38: -0.39790881 | AF38: 1.9481858 | AG38: 5.5821725 | AH38: 0 | AI38: 0 | AK38: 0 | AL38: 0 | AM38: 0 | AN38: 0
A39: drv:영업활동현금흐름 | B39: yoy | C39: 영업활동현금흐름 YoY | J39: =IFERROR(subQ!J31/subQ!E31-1,"") | L39: =IFERROR(subQ!L31/subQ!G31-1,"") | M39: =IFERROR(subQ!M31/subQ!H31-1,"") | N39: =IFERROR(subQ!N31/subQ!I31-1,"") | O39: =IFERROR(subQ!O31/subQ!J31-1,"") | Q39: =IFERROR(subQ!Q31/subQ!L31-1,"") | R39: =IFERROR(subQ!R31/subQ!M31-1,"") | S39: =IFERROR(subQ!S31/subQ!N31-1,"") | T39: =IFERROR(subQ!T31/subQ!O31-1,"") | V39: =IFERROR(subQ!V31/subQ!Q31-1,"") | W39: =IFERROR(subQ!W31/subQ!R31-1,"") | X39: =IFERROR(subQ!X31/subQ!S31-1,"") | Y39: =IFERROR(subQ!Y31/subQ!T31-1,"") | AA39: =IFERROR(subQ!AA31/subQ!V31-1,"") | AB39: =IFERROR(subQ!AB31/subQ!W31-1,"")
A40: drv:주식수 | B40: qoq | C40: 주식수 QoQ | G40: =IFERROR(subQ!G32/subQ!E32-1,"") | H40: =IFERROR(subQ!H32/subQ!G32-1,"") | I40: =IFERROR(subQ!I32/subQ!H32-1,"") | J40: =IFERROR(subQ!J32/subQ!I32-1,"") | L40: =IFERROR(subQ!L32/subQ!J32-1,"") | M40: =IFERROR(subQ!M32/subQ!L32-1,"") | N40: =IFERROR(subQ!N32/subQ!M32-1,"") | O40: =IFERROR(subQ!O32/subQ!N32-1,"") | Q40: =IFERROR(subQ!Q32/subQ!O32-1,"") | R40: =IFERROR(subQ!R32/subQ!Q32-1,"") | S40: =IFERROR(subQ!S32/subQ!R32-1,"") | T40: =IFERROR(subQ!T32/subQ!S32-1,"") | V40: =IFERROR(subQ!V32/subQ!T32-1,"") | W40: =IFERROR(subQ!W32/subQ!V32-1,"") | X40: =IFERROR(subQ!X32/subQ!W32-1,"") | Y40: =IFERROR(subQ!Y32/subQ!X32-1,"") | AA40: =IFERROR(subQ!AA32/subQ!Y32-1,"") | AB40: =IFERROR(subQ!AB32/subQ!AA32-1,"") | AC40: 0 | AD40: 0 | AF40: 0 | AG40: 0 | AH40: 0 | AI40: 0 | AK40: 0 | AL40: 0 | AM40: 0 | AN40: 0
A41: drv:DPS | B41: abs | C41: DPS (가정, 원) | E41: =subQ!E36 | F41: =subQ!F36 | G41: =subQ!G36 | H41: =subQ!H36 | I41: =subQ!I36 | J41: =subQ!J36 | K41: =subQ!K36 | L41: =subQ!L36 | ... AB41: =subQ!AB36 | AD41: 0 | AE41: =subQ!AE36 | AI41: 0 | AJ41: =subQ!AJ36 | AN41: 0 | AO41: =subQ!AO36
...

Sheet BS연결
B1: (백만원) | C1: 이름: BS연결H | E1: 4Q21 | F1: 2021 | G1: 1Q22 | H1: 2Q22 | I1: 3Q22 | J1: 4Q22 | K1: 2022 | L1: 1Q23 | M1: 2Q23 | N1: 3Q23 | O1: 4Q23 | P1: 2023 | Q1: 1Q24 | R1: 2Q24 | S1: 3Q24 | T1: 4Q24 | U1: 2024 | V1: 1Q25 | W1: 2Q25 | X1: 3Q25 | Y1: 4Q25 | Z1: 2025 | AA1: 1Q26 | AB1: 2Q26 | AC1: 3Q26 | AD1: 4Q26 | AE1: 2026 | AF1: 1Q27 | AG1: 2Q27 | AH1: 3Q27 | AI1: 4Q27 | AJ1: 2027 | AK1: 1Q28 | AL1: 2Q28 | AM1: 3Q28 | AN1: 4Q28 | AO1: 2028
B2: 연결 | D2: fin json(kship_fin.py)
B3: 나노(연) | C3: UPDATE: 26-10-14 | E3: 1 | F3: 2 | G3: 3 | H3: 4 | I3: 5 | J3: 6 | K3: 7 | L3: 8 | M3: 9 | N3: 10 | O3: 11 | P3: 12 | Q3: 13 | R3: 14 | S3: 15 | T3: 16 | U3: 17 | V3: 18 | W3: 19 | X3: 20 | Y3: 21 | Z3: 22 | AA3: 23 | AB3: 24 | AC3: 25 | AD3: 26 | AE3: 27 | AF3: 28 | AG3: 29 | AH3: 30 | AI3: 31 | AJ3: 32 | AK3: 33 | AL3: 34 | AM3: 35 | AN3: 36 | AO3: 37
B4: Account Code | C4: AccountNAME | E4: 2021.12 | F4: 2021.12A | G4: 2022.03 | H4: 2022.06 | I4: 2022.09 | J4: 2022.12 | K4: 2022.12A | L4: 2023.03 | M4: 2023.06 | N4: 2023.09 | O4: 2023.12 | P4: 2023.12A | Q4: 2024.03 | R4: 2024.06 | S4: 2024.09 | T4: 2024.12 | U4: 2024.12A | V4: 2025.03 | W4: 2025.06 | X4: 2025.09 | Y4: 2025.12 | Z4: 2025.12A | AA4: 2026.03 | AB4: 2026.06 | AC4: 2026.09 | AD4: 2026.12 | AE4: 2026.12A | AF4: 2027.03 | AG4: 2027.06 | AH4: 2027.09 | AI4: 2027.12 | AJ4: 2027.12A | AK4: 2028.03 | AL4: 2028.06 | AM4: 2028.09 | AN4: 2028.12 | AO4: 2028.12A
A5: 1 | C5: 유동자산 | E5: 38107.93 | F5: 38107.93 | G5: 46979.15 | H5: 44990.71 | I5: 48326.25 | J5: 44789.52 | K5: 44789.52 | L5: 47782.65 | M5: 50014.48 | N5: 45592.34 | O5: 40389.85 | P5: 40389.85 | Q5: 47082.71 | R5: 51047.24 | S5: 50363.21 | T5: 57695.76 | U5: 57695.76 | V5: 54123.61 | W5: 57121.18 | X5: 46191.13 | Y5: 45833.72 | Z5: 45833.72 | AA5: 55112.26 | AB5: 54477.72
A6: 1 | C6: 현금및현금성자산 | E6: 4708.18 | F6: 4708.18 | G6: 8362.65 | H6: 5651.23 | I6: 8180.7 | J6: 11207.55 | K6: 11207.55 | L6: 6479.86 | M6: 9106.18 | N6: 4567.31 | O6: 8121.38 | P6: 8121.38 | Q6: 6239.84 | R6: 10080.39 | S6: 5269.31 | T6: 20758.41 | U6: 20758.41 | V6: 17012.76 | W6: 14376 | X6: 12655.87 | Y6: 13539.17 | Z6: 13539.17 | AA6: 4731.35 | AB6: 14184.69
A7: 1 | C7: 단기금융상품 | E7: 10010.19 | F7: 10010.19 | G7: 8514.68 | H7: 7029.23 | I7: 5800 | J7: 5800 | K7: 5800 | L7: 7800 | M7: 7800 | N7: 6300 | O7: 6300 | P7: 6300 | Q7: 5800 | R7: 5800 | S7: 9400 | T7: 2811.4 | U7: 2811.4 | V7: 2812.3 | W7: 2813.2 | X7: 2814.1 | Y7: 2815 | Z7: 2815 | AA7: 2620 | AB7: 2620
A8: 1 | C8: 단기금융자산 | E8: 10010.19 | F8: 10010.19 | G8: 8514.68 | H8: 7029.23 | I8: 6098.51 | J8: 5800 | K8: 5800 | L8: 7800 | M8: 7800 | N8: 6300 | O8: 6300 | P8: 6300 | Q8: 5800 | R8: 5800 | S8: 9400 | T8: 2811.4 | U8: 2811.4 | V8: 2812.3 | W8: 2813.2 | X8: 2814.1 | Y8: 2815 | Z8: 2815 | AA8: 2620 | AB8: 2620
A9: 1 | C9: 매출채권및기타채권 | E9: 7522.71 | F9: 7522.71 | G9: 4280.85 | H9: 10270.1 | I9: 14041.58 | J9: 8789.97 | K9: 8789.97 | L9: 6992.44 | M9: 10904.66 | N9: 9354.46 | O9: 5169.85 | P9: 5169.85 | Q9: 11727.15 | R9: 9019.52 | S9: 9958.97 | T9: 9591.55 | U9: 9591.55 | V9: 8513.4 | W9: 5783.09 | X9: 8802.26 | Y9: 8966.1 | Z9: 8966.1 | AA9: 18757.3 | AB9: 13495.95
A10: 1 | C10: 기타유동금융자산 | E10: 2680.06 | F10: 2680.06 | G10: 3622.82 | H10: 1690.91 | I10: 1018.01 | J10: 646.52 | K10: 646.52 | L10: 2435.33 | M10: 2154.23 | N10: 5603.06 | O10: 1122.9 | P10: 1122.9 | Q10: 1275.04 | R10: 1210.64 | S10: 1689.95 | T10: 4495.78 | U10: 4495.78 | V10: 1702.69 | W10: 2951.06 | X10: 1422.69 | Y10: 1741.92 | Z10: 1741.92 | AA10: 1487.43 | AB10: 1037.76
A11: 1 | C11: 기타유동자산 | E11: 2854.22 | F11: 2854.22 | G11: 4718.68 | H11: 4171.57 | I11: 4110.05 | J11: 2218.91 | K11: 2218.91 | L11: 2071.8 | M11: 2540.15 | N11: 3746.07 | O11: 1649.84 | P11: 1649.84 | Q11: 1515.74 | R11: 1749.61 | S11: 2295.51 | T11: 3600.4 | U11: 3600.4 | V11: 2240.39 | W11: 1502.87 | X11: 1796.94 | Y11: 4270.43 | Z11: 4270.43 | AA11: 3943.41 | AB11: 4361.01
A12: 1 | C12: 재고자산 | E12: 10312.98 | F12: 10312.98 | G12: 15859.15 | H12: 15856.23 | I12: 14737.94 | J12: 15771.71 | K12: 15771.71 | L12: 21606.47 | M12: 17141.99 | N12: 15110.46 | O12: 17114.2 | P12: 17114.2 | Q12: 19892.99 | R12: 22840.95 | S12: 21535.52 | T12: 16304.27 | U12: 16304.27 | V12: 21629.73 | W12: 29606.59 | X12: 18596.37 | Y12: 14389.76 | Z12: 14389.76 | AA12: 23451.17 | AB12: 18763.26
A13: 1 | C13: 당기법인세자산(선급법인세) | E13: 19.6 | F13: 19.6 | G13: 26.06 | H13: 11.67 | I13: 30.22 | J13: 41.8 | K13: 41.8 | L13: 52.96 | M13: 18.53 | N13: 43.21 | O13: 52.44 | P13: 52.44 | Q13: 122.71 | R13: 86.89 | S13: 104.71 | T13: 133.94 | U13: 133.94 | V13: 212.33 | W13: 88.37 | X13: 102.89 | Y13: 111.34 | Z13: 111.34 | AA13: 121.59 | AB13: 13.16
A14: 1 | C14: 비유동자산 | E14: 32955.73 | F14: 32955.73 | G14: 32935.3 | H14: 33848.38 | I14: 34736.97 | J14: 25135.22 | K14: 25135.22 | L14: 26271.06 | M14: 26863.92 | N14: 27127.01 | O14: 27395.17 | P14: 27395.17 | Q14: 27615.48 | R14: 29901.16 | S14: 28052.75 | T14: 28633.3 | U14: 28633.3 | V14: 32840.9 | W14: 38421.61 | X14: 47321.91 | Y14: 48410.52 | Z14: 48410.52 | AA14: 48116.73 | AB14: 48154.77
A15: 1 | C15: 장기금융자산 | E15: 0.6 | F15: 0.6 | G15: 1.5 | H15: 2.4 | I15: 3.3 | J15: 2402.94 | K15: 2402.94 | L15: 5.1 | M15: 6 | N15: 6.9 | O15: 2955.88 | P15: 2955.88 | Q15: 3185.15 | R15: 2822.91 | S15: 1430.86 | T15: 313.61 | U15: 313.61 | V15: 313.61 | W15: 313.61 | X15: 313.61 | Y15: 313.61 | Z15: 313.61 | AA15: 44.69 | AB15: 44.69
A16: 1 | C16: 투자자산 | E16: 103.75 | F16: 103.75 | G16: 22.94 | H16: 2.4 | I16: 3.3 | J16: 2402.94 | K16: 2402.94 | L16: 5.1 | M16: 6 | N16: 6.9 | O16: 2955.88 | P16: 2955.88 | Q16: 3185.15 | R16: 2822.91 | S16: 1430.86 | T16: 3466.05 | U16: 3466.05 | V16: 5301.48 | W16: 7814.08 | X16: 7773.2 | Y16: 8106.96 | Z16: 8106.96 | AA16: 7432.09 | AB16: 7175.86
A17: 1 | C17: 종속기업및관계기업투자 | E17: 103.15 | F17: 103.15 | G17: 21.44 | T17: 3152.44 | U17: 3152.44 | V17: 4987.87 | W17: 7500.47 | X17: 7459.59 | Y17: 7793.35 | Z17: 7793.35 | AA17: 7387.4 | AB17: 7131.17
A18: 1 | C18: 유형자산 | E18: 30042.22 | F18: 30042.22 | G18: 30194.03 | H18: 30117.83 | I18: 31196.11 | J18: 21717.25 | K18: 21717.25 | L18: 22637.85 | M18: 23368.82 | N18: 23521.34 | O18: 23373.09 | P18: 23373.09 | Q18: 23350.78 | R18: 23139.51 | S18: 22675.87 | T18: 22745.29 | U18: 22745.29 | V18: 25593.66 | W18: 28780.04 | X18: 37751.86 | Y18: 36775.1 | Z18: 36775.1 | AA18: 37066.83 | AB18: 37220.37
A19: 1 | C19: 사용권자산 | E19: 548.14 | F19: 548.14 | G19: 556.29 | H19: 500.43 | I19: 362.14 | J19: 337.3 | K19: 337.3 | L19: 357.64 | M19: 297.24 | N19: 429.08 | O19: 643.85 | P19: 643.85 | Q19: 659.69 | R19: 636.14 | S19: 644.89 | T19: 647.47 | U19: 647.47 | V19: 595.88 | W19: 596.59 | X19: 562.49 | Y19: 585.61 | Z19: 585.61 | AA19: 570.88 | AB19: 531.74
A20: 1 | C20: 기타비유동자산 | E20: 548.14 | F20: 548.14 | G20: 556.29 | H20: 500.43 | I20: 362.14 | J20: 337.3 | K20: 337.3 | L20: 357.64 | M20: 297.24 | N20: 429.08 | O20: 643.85 | P20: 643.85 | Q20: 659.69 | R20: 636.14 | S20: 644.89 | T20: 647.47 | U20: 647.47 | V20: 595.88 | W20: 596.59 | X20: 562.49 | Y20: 585.61 | Z20: 585.61 | AA20: 570.88 | AB20: 531.74
A21: 1 | C21: 무형자산 | E21: 284.66 | F21: 284.66 | G21: 260.38 | H21: 264.73 | I21: 239.04 | J21: 212.38 | K21: 212.38 | L21: 186.7 | M21: 160.55 | N21: 134.7 | O21: 108.74 | P21: 108.74 | Q21: 106.25 | R21: 103.7 | S21: 102.24 | T21: 100.78 | U21: 100.78 | V21: 99.32 | W21: 97.86 | X21: 96.4 | Y21: 94.94 | Z21: 94.94 | AA21: 146.1 | AB21: 145.25
A22: 1 | C22: 자산총계 | E22: 71063.65 | F22: 71063.65 | G22: 79914.45 | H22: 78839.09 | I22: 83063.22 | J22: 69924.74 | K22: 69924.74 | L22: 74053.71 | M22: 76878.4 | N22: 72719.35 | O22: 67785.02 | P22: 67785.02 | Q22: 74698.19 | R22: 80948.39 | S22: 78415.95 | T22: 86329.06 | U22: 86329.06 | V22: 86964.51 | W22: 95542.78 | X22: 93513.04 | Y22: 94244.24 | Z22: 94244.24 | AA22: 103228.99 | AB22: 102632.49
A23: 1 | C23: 유동부채 | E23: 34871.2 | F23: 34871.2 | G23: 43492.38 | H23: 42491.81 | I23: 46634.76 | J23: 67696.83 | K23: 67696.83 | L23: 47907.13 | M23: 45992.22 | N23: 40902.57 | O23: 64242.73 | P23: 64242.73 | Q23: 62541.13 | R23: 62609.49 | S23: 54749 | T23: 50959.95 | U23: 50959.95 | V23: 46851.51 | W23: 52966.3 | X23: 36566.45 | Y23: 39227.81 | Z23: 39227.81 | AA23: 50154.15 | AB23: 49130.91
A24: 1 | C24: 계약부채 | E24: 5024.35 | F24: 5024.35 | G24: 10094.44 | H24: 8816.62 | I24: 8183.98 | J24: 14787.93 | K24: 14787.93 | L24: 13532.69 | M24: 15325.87 | N24: 7886.78 | O24: 6128.25 | P24: 6128.25 | Q24: 7721.45 | R24: 14629.97 | S24: 6730.12 | T24: 14535.32 | U24: 14535.32 | V24: 14727.76 | W24: 20869.32 | X24: 5689.24 | Y24: 6472.55 | Z24: 6472.55 | AA24: 13965.44 | AB24: 5789.66
A25: 1 | C25: 단기파생상품부채 | E25: 2923.34 | F25: 2923.34 | G25: 2923.34 | H25: 2288.79 | I25: 2434.71 | J25: 15593.14 | K25: 15593.14 | L25: 749.21 | M25: 177.05 | O25: 15027.28 | P25: 15027.28 | Q25: 7288.71 | R25: 10001.96 | S25: 10001.96 | T25: 238.23 | U25: 238.23
A26: 1 | C26: 단기금융부채 | E26: 3090.73 | F26: 3090.73 | G26: 3092.85 | H26: 2450.19 | I26: 2556.97 | J26: 15730.14 | K26: 15730.14 | L26: 918.3 | M26: 296.67 | N26: 147.56 | O26: 15215.82 | P26: 15215.82 | Q26: 7481.08 | R26: 10190.33 | S26: 10187.4 | T26: 238.23 | U26: 238.23
A27: 1 | C27: 단기차입금 | E27: 13322.01 | F27: 13322.01 | G27: 13110.32 | H27: 12857.34 | I27: 12344.14 | J27: 12547.3 | K27: 12547.3 | L27: 13155.73 | M27: 13505.59 | N27: 16550.35 | O27: 16466.51 | P27: 16466.51 | Q27: 18109.59 | R27: 16597.89 | S27: 16574.74 | T27: 16645.76 | U27: 16645.76 | V27: 16651.18 | W27: 16848.08 | X27: 17547.66 | Y27: 17650.88 | Z27: 17650.88 | AA27: 18632.1 | AB27: 26539.61
A28: 1 | C28: 유동성장기부채 | E28: 4904.52 | F28: 4904.52 | G28: 4746.66 | H28: 4593.83 | I28: 4472.92 | J28: 2812.11 | K28: 2812.11 | L28: 1640.97 | M28: 532.18 | N28: 260 | O28: 260 | P28: 260 | Q28: 260 | R28: 260 | S28: 695 | T28: 630 | U28: 630 | V28: 565 | W28: 585 | X28: 670 | Y28: 840 | Z28: 840 | AA28: 840 | AB28: 840
A29: 1 | C29: 유동리스부채 | E29: 167.39 | F29: 167.39 | G29: 169.51 | H29: 161.4 | I29: 122.26 | J29: 137 | K29: 137 | L29: 169.09 | M29: 119.62 | N29: 147.56 | O29: 188.54 | P29: 188.54 | Q29: 192.37 | R29: 188.37 | S29: 185.44
A30: 1 | C30: 리스부채 | E30: 547.93 | F30: 547.93 | G30: 555.9 | H30: 503.38 | I30: 361.45 | J30: 337.69 | K30: 337.69 | L30: 353.87 | M30: 276.74 | N30: 432.35 | O30: 590.02 | P30: 590.02 | Q30: 604.33 | R30: 583.77 | S30: 578.06
A31: 1 | C31: 기타유동부채 | E31: 396.24 | F31: 396.24 | G31: 356.49 | H31: 383.91 | I31: 430.67 | J31: 455.48 | K31: 455.48 | L31: 651.91 | M31: 256.53 | N31: 290.07 | O31: 242.43 | P31: 242.43 | Q31: 276.96 | R31: 313.55 | S31: 378.6 | T31: 491.53 | U31: 491.53 | V31: 390.68 | W31: 291.32 | X31: 360.64 | Y31: 541.07 | Z31: 541.07 | AA31: 438.81 | AB31: 375.4
A32: 1 | C32: 비유동부채 | E32: 1359.68 | F32: 1359.68 | G32: 1301.66 | H32: 1211.08 | I32: 1048.04 | J32: 961.53 | K32: 961.53 | L32: 1780.61 | M32: 2487.95 | N32: 2602.92 | O32: 2943.1 | P32: 2943.1 | Q32: 2980.92 | R32: 2977.59 | S32: 4062.05 | T32: 4656.68 | U32: 4656.68 | V32: 4115.57 | W32: 4035.02 | X32: 12882.58 | Y32: 15131.96 | Z32: 15131.96 | AA32: 15085.2 | AB32: 14978.06
A33: 1 | C33: 장기차입금 | E33: 650 | F33: 650 | G33: 585 | H33: 520 | I33: 455 | J33: 390 | K33: 390 | L33: 1225 | M33: 1960 | N33: 1895 | O33: 1830 | P33: 1830 | Q33: 1765 | R33: 1700 | S33: 2700 | T33: 2575 | U33: 2575 | V33: 2450 | W33: 2240 | X33: 10990 | Y33: 13735 | Z33: 13735 | AA33: 13610 | AB33: 13400
A34: 1 | C34: 비유동리스부채 | E34: 380.54 | F34: 380.54 | G34: 386.39 | H34: 341.98 | I34: 239.19 | J34: 200.69 | K34: 200.69 | L34: 184.78 | M34: 157.12 | N34: 284.79 | O34: 401.48 | P34: 401.48 | Q34: 411.96 | R34: 395.4 | S34: 392.62
A35: 1 | C35: 장기금융부채 | E35: 709.68 | F35: 709.68 | G35: 716.67 | H35: 691.08 | I35: 593.03 | J35: 200.69 | K35: 200.69 | L35: 555.62 | M35: 527.96 | N35: 284.79 | O35: 401.48 | P35: 401.48 | Q35: 411.96 | R35: 395.4 | S35: 392.62
A36: 1 | C36: 기타비유동금융부채 | E36: 329.14 | F36: 329.14 | G36: 330.28 | H36: 349.1 | I36: 353.84 | L36: 370.84 | M36: 370.84
A37: 1 | C37: 부채총계 | E37: 36230.87 | F37: 36230.87 | G37: 44794.05 | H37: 43702.88 | I37: 47682.79 | J37: 68658.36 | K37: 68658.36 | L37: 49687.75 | M37: 48480.17 | N37: 43505.49 | O37: 67185.83 | P37: 67185.83 | Q37: 65522.05 | R37: 65587.08 | S37: 58811.05 | T37: 55616.63 | U37: 55616.63 | V37: 50967.08 | W37: 57001.32 | X37: 49449.03 | Y37: 54359.77 | Z37: 54359.77 | AA37: 65239.35 | AB37: 64108.97
A38: 1 | C38: 지배주주지분 | E38: 31490 | F38: 31490 | G38: 31796.8 | H38: 31870.39 | I38: 32188.04 | J38: 625.93 | K38: 625.93 | L38: 23960.02 | M38: 28203.33 | N38: 29102.58 | O38: 525.28 | P38: 525.28 | Q38: 9204.62 | R38: 15545.29 | S38: 19958.81 | T38: 31269.06 | U38: 31269.06 | V38: 36719.1 | W38: 39379.29 | X38: 45126.04 | Y38: 42706.28 | Z38: 42706.28 | AA38: 40370.85 | AB38: 41131.13
A39: 1 | C39: 자본금 | E39: 13533.85 | F39: 13533.85 | G39: 13533.85 | H39: 13533.85 | I39: 13709.29 | J39: 13709.29 | K39: 13709.29 | L39: 14551.05 | M39: 15259.42 | N39: 15420.41 | O39: 15420.41 | P39: 15420.41 | Q39: 15420.41 | R39: 15420.41 | S39: 15420.41 | T39: 15420.41 | U39: 15420.41 | V39: 15420.41 | W39: 15420.41 | X39: 15420.41 | Y39: 15420.41 | Z39: 15420.41 | AA39: 15420.41 | AB39: 15420.41
A40: 1 | C40: 자본잉여금 | E40: 24957.45 | F40: 24957.45 | G40: 24957.45 | H40: 24957.45 | I40: 25223.52 | J40: 25268.31 | K40: 25268.31 | L40: 26435.55 | M40: 27488.31 | N40: 27786.55 | O40: 28574.59 | P40: 28574.59 | Q40: 28574.59 | R40: 28574.59 | S40: 28574.59 | T40: 28574.59 | U40: 28574.59 | V40: 28574.59 | W40: 28574.59 | X40: 28574.59 | Y40: 28574.59 | Z40: 28574.59 | AA40: 23877.13 | AB40: 23877.13
...

Sheet BS별도
B1: (백만원) | C1: 이름: BS별도H | E1: 4Q21 | F1: 2021 | G1: 1Q22 | H1: 2Q22 | I1: 3Q22 | J1: 4Q22 | K1: 2022 | L1: 1Q23 | M1: 2Q23 | N1: 3Q23 | O1: 4Q23 | P1: 2023 | Q1: 1Q24 | R1: 2Q24 | S1: 3Q24 | T1: 4Q24 | U1: 2024 | V1: 1Q25 | W1: 2Q25 | X1: 3Q25 | Y1: 4Q25 | Z1: 2025 | AA1: 1Q26 | AB1: 2Q26 | AC1: 3Q26 | AD1: 4Q26 | AE1: 2026 | AF1: 1Q27 | AG1: 2Q27 | AH1: 3Q27 | AI1: 4Q27 | AJ1: 2027 | AK1: 1Q28 | AL1: 2Q28 | AM1: 3Q28 | AN1: 4Q28 | AO1: 2028
B2: 별도 | D2: fin json(kship_fin.py)
B3: 나노(별) | C3: UPDATE: 26-10-14 | E3: 1 | F3: 2 | G3: 3 | H3: 4 | I3: 5 | J3: 6 | K3: 7 | L3: 8 | M3: 9 | N3: 10 | O3: 11 | P3: 12 | Q3: 13 | R3: 14 | S3: 15 | T3: 16 | U3: 17 | V3: 18 | W3: 19 | X3: 20 | Y3: 21 | Z3: 22 | AA3: 23 | AB3: 24 | AC3: 25 | AD3: 26 | AE3: 27 | AF3: 28 | AG3: 29 | AH3: 30 | AI3: 31 | AJ3: 32 | AK3: 33 | AL3: 34 | AM3: 35 | AN3: 36 | AO3: 37
B4: Account Code | C4: AccountNAME | E4: 2021.12 | F4: 2021.12A | G4: 2022.03 | H4: 2022.06 | I4: 2022.09 | J4: 2022.12 | K4: 2022.12A | L4: 2023.03 | M4: 2023.06 | N4: 2023.09 | O4: 2023.12 | P4: 2023.12A | Q4: 2024.03 | R4: 2024.06 | S4: 2024.09 | T4: 2024.12 | U4: 2024.12A | V4: 2025.03 | W4: 2025.06 | X4: 2025.09 | Y4: 2025.12 | Z4: 2025.12A | AA4: 2026.03 | AB4: 2026.06 | AC4: 2026.09 | AD4: 2026.12 | AE4: 2026.12A | AF4: 2027.03 | AG4: 2027.06 | AH4: 2027.09 | AI4: 2027.12 | AJ4: 2027.12A | AK4: 2028.03 | AL4: 2028.06 | AM4: 2028.09 | AN4: 2028.12 | AO4: 2028.12A
A5: 1 | C5: 유동자산 | E5: 30900.66 | F5: 30900.66 | G5: 40515.02 | H5: 35695.16 | I5: 35126.14 | J5: 37431.81 | K5: 37431.81 | L5: 40900 | M5: 43160.42 | N5: 37337.57 | O5: 39829 | P5: 39829 | Q5: 44617.5 | R5: 48513.25 | S5: 43301.55 | T5: 51569.14 | U5: 51569.14 | V5: 48008.57 | W5: 50979.46 | X5: 41102.54 | Y5: 36530.2 | Z5: 36530.2 | AA5: 46299.88 | AB5: 44064.14
A6: 1 | C6: 현금및현금성자산 | E6: 4255.53 | F6: 4255.53 | G6: 8173.6 | H6: 5382.14 | I6: 7754.5 | J6: 10791.43 | K6: 10791.43 | L6: 5756.94 | M6: 7876.26 | N6: 3633.18 | O6: 7957.13 | P6: 7957.13 | Q6: 5831.42 | R6: 9730.15 | S6: 4837.41 | T6: 20256.12 | U6: 20256.12 | V6: 16618.2 | W6: 13999.18 | X6: 11646.56 | Y6: 13023.23 | Z6: 13023.23 | AA6: 4292.47 | AB6: 13403.77
A7: 1 | C7: 단기금융상품 | E7: 10010.19 | F7: 10010.19 | G7: 8514.68 | H7: 7029.23 | I7: 5800 | J7: 5800 | K7: 5800 | L7: 7800 | M7: 7800 | N7: 6300 | O7: 6300 | P7: 6300 | Q7: 5800 | R7: 5800 | S7: 9400 | T7: 2811.4 | U7: 2811.4 | V7: 2812.3 | W7: 2813.2 | X7: 2814.1 | Y7: 2815 | Z7: 2815 | AA7: 2620 | AB7: 2620
A8: 1 | C8: 단기금융자산 | E8: 10010.19 | F8: 10010.19 | G8: 8514.68 | H8: 7029.23 | I8: 6098.51 | J8: 5800 | K8: 5800 | L8: 7800 | M8: 7800 | N8: 6300 | O8: 6300 | P8: 6300 | Q8: 5800 | R8: 5800 | S8: 9400 | T8: 2811.4 | U8: 2811.4 | V8: 2812.3 | W8: 2813.2 | X8: 2814.1 | Y8: 2815 | Z8: 2815 | AA8: 2620 | AB8: 2620
A9: 1 | C9: 매출채권및기타채권 | E9: 3804.03 | F9: 3804.03 | G9: 2340.5 | H9: 5992.84 | I9: 5114.07 | J9: 4035.99 | K9: 4035.99 | L9: 3429.74 | M9: 6757.22 | N9: 5315.72 | O9: 3612.89 | P9: 3612.89 | Q9: 8003.3 | R9: 6797.24 | S9: 3556.65 | T9: 7363.24 | U9: 7363.24 | V9: 4715.69 | W9: 2795.19 | X9: 5517.99 | Y9: 5015.35 | Z9: 5015.35 | AA9: 11518.85 | AB9: 6508.74
A10: 1 | C10: 기타유동금융자산 | E10: 2129.58 | F10: 2129.58 | G10: 2867.49 | H10: 639.17 | I10: 481.33 | J10: 182.86 | K10: 182.86 | L10: 1294.86 | M10: 1552.34 | N10: 4964.46 | O10: 4524.61 | P10: 4524.61 | Q10: 4543.42 | R10: 3834.83 | S10: 4425.99 | T10: 3965.01 | U10: 3965.01 | V10: 840.65 | W10: 883.92 | X10: 1179.23 | Y10: 988.64 | Z10: 988.64 | AA10: 418.46 | AB10: 475.28
A11: 1 | C11: 기타유동자산 | E11: 2772.5 | F11: 2772.5 | G11: 3329.47 | H11: 2954.66 | I11: 3801.61 | J11: 2182.62 | K11: 2182.62 | L11: 2076.94 | M11: 2439.42 | N11: 2424.01 | O11: 1620.29 | P11: 1620.29 | Q11: 1428.24 | R11: 1668.7 | S11: 1643.71 | T11: 1564.66 | U11: 1564.66 | V11: 1784.87 | W11: 1311.57 | X11: 1877.02 | Y11: 1026.38 | Z11: 1026.38 | AA11: 5154.53 | AB11: 4130.14
A12: 1 | C12: 재고자산 | E12: 7910.91 | F12: 7910.91 | G12: 13670.64 | H12: 13375.69 | I12: 11736.74 | J12: 14087.97 | K12: 14087.97 | L12: 20148.69 | M12: 16367.91 | N12: 13789.22 | O12: 14902.41 | P12: 14902.41 | Q12: 18379.19 | R12: 20336.22 | S12: 19224.06 | T12: 15474.77 | U12: 15474.77 | V12: 21024.54 | W12: 29088.04 | X12: 17964.81 | Y12: 13550.27 | Z12: 13550.27 | AA12: 22174.05 | AB12: 16911.17
A13: 1 | C13: 당기법인세자산(선급법인세) | E13: 17.92 | F13: 17.92 | G13: 24.38 | H13: 11.66 | I13: 30.16 | J13: 37.88 | K13: 37.88 | L13: 49.04 | M13: 18.53 | N13: 43.21 | O13: 52.43 | P13: 52.43 | Q13: 122.7 | R13: 86.89 | S13: 104.5 | T13: 133.94 | U13: 133.94 | V13: 212.32 | W13: 88.37 | X13: 102.83 | Y13: 111.33 | Z13: 111.33 | AA13: 121.53 | AB13: 13.16
A14: 1 | C14: 비유동자산 | E14: 27330.58 | F14: 27330.58 | G14: 27068.17 | H14: 27627.46 | I14: 27986.3 | J14: 19527.66 | K14: 19527.66 | L14: 20581.94 | M14: 21759.43 | N14: 21969.23 | O14: 20218.18 | P14: 20218.18 | Q14: 20454.12 | R14: 23194.76 | S14: 22394.22 | T14: 19894.71 | U14: 19894.71 | V14: 24494.69 | W14: 28239.63 | X14: 36358.94 | Y14: 51553.56 | Z14: 51553.56 | AA14: 53603.38 | AB14: 49338.43
A15: 1 | C15: 장기금융자산 | E15: 0.6 | F15: 0.6 | G15: 1.5 | H15: 2.4 | I15: 3.3 | J15: 2353.49 | K15: 2353.49 | L15: 5.1 | M15: 6 | N15: 6.9 | O15: 2955.88 | P15: 2955.88 | Q15: 3185.15 | R15: 2822.91 | S15: 1430.86 | T15: 313.61 | U15: 313.61 | V15: 313.61 | W15: 313.61 | X15: 313.61 | Y15: 313.61 | Z15: 313.61 | AA15: 44.69 | AB15: 44.69
A16: 1 | C16: 투자자산 | E16: 10773.97 | F16: 10773.97 | G16: 10774.87 | H16: 10437.86 | I16: 10438.76 | J16: 4578.25 | K16: 4578.25 | L16: 2229.86 | M16: 2230.76 | N16: 2231.66 | O16: 3186.53 | P16: 3186.53 | Q16: 3415.8 | R16: 3443.56 | S16: 2809.37 | T16: 2392.12 | U16: 2392.12 | V16: 4392.12 | W16: 4392.12 | X16: 5670.92 | Y16: 14052.2 | Z16: 14052.2 | AA16: 15881.28 | AB16: 11515.97
... A23: 1 | C23: 유동부채 | E23: 28007.53 | F23: 28007.53 | G23: 37101.91 | H23: 32862.38 | I23: 32257.91 | J23: 57749.8 | K23: 57749.8 | L23: 36851.01 | M23: 35117.66 | N23: 28393.93 | O23: 55214.37 | P23: 55214.37 | Q23: 51294.27 | R23: 52286.02 | S23: 40491.94 | T23: 42132.97 | U23: 42132.97 | V23: 37207.09 | W23: 43292.75 | X23: 26884.07 | Y23: 24871.1 | Z23: 24871.1 | AA23: 37372.45 | AB23: 35595.4
A24: 1 | C24: 매입채무및기타채무 | E24: 3979.75 | F24: 3979.75 | G24: 8709.89 | H24: 6509.3 | I24: 8462.32 | J24: 9133.55 | K24: 9133.55 | L24: 13830.78 | M24: 10762.18 | N24: 8824.04 | O24: 10647.42 | P24: 10647.42 | Q24: 12006.45 | R24: 7041.46 | S24: 6157.08
A25: 1 | C25: 계약부채 | E25: 5015.57 | F25: 5015.57 | G25: 9879.49 | H25: 8725.85 | I25: 6802.91 | J25: 10331.9 | K25: 10331.9 | L25: 9590.71 | M25: 12260.37 | N25: 5007.16 | O25: 4916.03 | P25: 4916.03 | Q25: 7397.34 | R25: 14126.73 | S25: 6201.22 | T25: 14174.48 | U25: 14174.48 | V25: 14219.11 | W25: 20460.05 | X25: 5307.65 | Y25: 2406.41 | Z25: 2406.41 | AA25: 11200.17 | AB25: 3621.19
A26: 1 | C26: 단기파생상품부채 | E26: 2923.34 | F26: 2923.34 | G26: 2923.34 | H26: 2288.79 | I26: 2434.71 | J26: 15593.14 | K26: 15593.14 | L26: 749.21 | M26: 177.05 | O26: 15027.28 | P26: 15027.28 | Q26: 7288.71 | R26: 10001.96 | S26: 10001.96 | T26: 238.23 | U26: 238.23
A27: 1 | C27: 단기금융부채 | E27: 2985.45 | F27: 2985.45 | G27: 2985.45 | H27: 2349.03 | I27: 2493.5 | J27: 15649.18 | K27: 15649.18 | L27: 800.83 | M27: 224.25 | N27: 44.21 | O27: 15074.81 | P27: 15074.81 | Q27: 7336.24 | R27: 10052.31 | S27: 10047.21 | T27: 238.23 | U27: 238.23
A28: 1 | C28: 단기차입금 | E28: 10360.48 | F28: 10360.48 | G28: 10089 | H28: 10089 | I28: 9489 | J28: 9989 | K28: 9989 | L28: 10489 | M28: 10989 | N28: 13989 | O28: 13989 | P28: 13989 | Q28: 13989 | R28: 13989 | S28: 13989 | T28: 13989 | U28: 13989 | V28: 13989 | W28: 14389 | X28: 14989 | Y28: 14989 | Z28: 14989 | AA28: 15789 | AB28: 23589
A29: 1 | C29: 유동성장기부채 | E29: 4904.52 | F29: 4904.52 | G29: 4746.66 | H29: 4593.83 | I29: 4472.92 | J29: 2812.11 | K29: 2812.11 | L29: 1640.97 | M29: 532.18 | N29: 260 | O29: 260 | P29: 260 | Q29: 260 | R29: 260 | S29: 695 | T29: 630 | U29: 630 | V29: 565 | W29: 585 | X29: 670 | Y29: 840 | Z29: 840 | AA29: 840 | AB29: 840
A30: 1 | C30: 유동리스부채 | E30: 62.11 | F30: 62.11 | G30: 62.11 | H30: 60.24 | I30: 58.79 | J30: 56.04 | K30: 56.04 | L30: 51.62 | M30: 47.2 | N30: 44.21 | O30: 47.53 | P30: 47.53 | Q30: 47.53 | R30: 50.35 | S30: 45.25
A31: 1 | C31: 리스부채 | E31: 152.89 | F31: 152.89 | G31: 152.89 | H31: 140.65 | I31: 126.49 | J31: 112.21 | K31: 112.21 | L31: 97.76 | M31: 83.24 | N31: 70.06 | O31: 63.1 | P31: 63.1 | Q31: 63.1 | R31: 93.19 | S31: 100.18
A32: 1 | C32: 기타유동부채 | E32: 97.6 | F32: 97.6 | G32: 109.65 | H32: 79.48 | I32: 82.25 | J32: 46.1 | K32: 46.1 | L32: 134.84 | M32: 47.9 | N32: 48.93 | O32: 50.39 | P32: 50.39 | Q32: 56.19 | R32: 55.43 | S32: 120.91 | T32: 112.84 | U32: 112.84 | V32: 95.63 | W32: 69.31 | X32: 73.81 | Y32: 137.15 | Z32: 137.15 | AA32: 102.74 | AB32: 99.91
A33: 1 | C33: 비유동부채 | E33: 1069.92 | F33: 1069.92 | G33: 1006.06 | H33: 949.51 | I33: 876.54 | J33: 817 | K33: 817 | L33: 1641.98 | M33: 2366.87 | N33: 2343.98 | O33: 2557.19 | P33: 2557.19 | Q33: 2584.54 | R33: 2625.03 | S33: 3724.37 | T33: 4327.92 | U33: 4327.92 | V33: 3818.03 | W33: 3817.99 | X33: 12684.46 | Y33: 14902.48 | Z33: 14902.48 | AA33: 14895.39 | AB33: 14800.39
A34: 1 | C34: 장기차입금 | E34: 650 | F34: 650 | G34: 585 | H34: 520 | I34: 455 | J34: 390 | K34: 390 | L34: 1225 | M34: 1960 | N34: 1895 | O34: 1830 | P34: 1830 | Q34: 1765 | R34: 1700 | S34: 2700 | T34: 2575 | U34: 2575 | V34: 2450 | W34: 2240 | X34: 10990 | Y34: 13735 | Z34: 13735 | AA34: 13610 | AB34: 13400
A35: 1 | C35: 비유동리스부채 | E35: 90.78 | F35: 90.78 | G35: 90.78 | H35: 80.41 | I35: 67.7 | J35: 56.17 | K35: 56.17 | L35: 46.14 | M35: 36.04 | N35: 25.85 | O35: 15.57 | P35: 15.57 | Q35: 15.57 | R35: 42.84 | S35: 54.93
A36: 1 | C36: 장기금융부채 | E36: 419.92 | F36: 419.92 | G36: 421.06 | H36: 429.51 | I36: 421.54 | J36: 56.17 | K36: 56.17 | L36: 416.98 | M36: 406.88 | N36: 25.85 | O36: 15.57 | P36: 15.57 | Q36: 15.57 | R36: 42.84 | S36: 54.93
A37: 1 | C37: 기타비유동금융부채 | E37: 329.14 | F37: 329.14 | G37: 330.28 | H37: 349.1 | I37: 353.84 | L37: 370.84 | M37: 370.84
A38: 1 | C38: 부채총계 | E38: 29077.45 | F38: 29077.45 | G38: 38107.97 | H38: 33811.9 | I38: 33134.45 | J38: 58566.8 | K38: 58566.8 | L38: 38492.99 | M38: 37484.54 | N38: 30737.91 | O38: 57771.57 | P38: 57771.57 | Q38: 53878.81 | R38: 54911.05 | S38: 44216.31 | T38: 46460.89 | U38: 46460.89 | V38: 41025.12 | W38: 47110.74 | X38: 39568.54 | Y38: 39773.59 | Z38: 39773.59 | AA38: 52267.84 | AB38: 50395.79
A39: 1 | C39: 자본금 | E39: 13533.85 | F39: 13533.85 | G39: 13533.85 | H39: 13533.85 | I39: 13709.29 | J39: 13709.29 | K39: 13709.29 | L39: 14551.05 | M39: 15259.42 | N39: 15420.41 | O39: 15420.41 | P39: 15420.41 | Q39: 15420.41 | R39: 15420.41 | S39: 15420.41 | T39: 15420.41 | U39: 15420.41 | V39: 15420.41 | W39: 15420.41 | X39: 15420.41 | Y39: 15420.41 | Z39: 15420.41 | AA39: 15420.41 | AB39: 15420.41
A40: 1 | C40: 자본잉여금 | E40: 24957.45 | F40: 24957.45 | G40: 24957.45 | H40: 24957.45 | I40: 25223.52 | J40: 25268.31 | K40: 25268.31 | L40: 26435.55 | M40: 27488.31 | N40: 27786.55 | O40: 28574.59 | P40: 28574.59 | Q40: 28574.59 | R40: 28574.59 | S40: 28574.59 | T40: 28574.59 | U40: 28574.59 | V40: 28574.59 | W40: 28574.59 | X40: 28574.59 | Y40: 28574.59 | Z40: 28574.59 | AA40: 23877.13 | AB40: 23877.13
A41: 1 | C41: 기타자본 | E41: 877.35 | F41: 877.35 | G41: 877.35 | H41: 877.35 | I41: 877.35 | J41: 877.35 | K41: 877.35 | L41: 877.35 | M41: 877.35 | N41: 877.35 | O41: 877.35 | P41: 877.35 | Q41: 877.35 | R41: 877.35 | S41: 877.35 | T41: 877.35 | U41: 877.35 | V41: 877.35 | W41: 877.35 | X41: 877.35 | Y41: 877.35 | Z41: 877.35 | AA41: -425.19 | AB41: -425.19
A42: 1 | C42: 이익잉여금 | E42: -10214.86 | F42: -10214.86 | G42: -9893.44 | H42: -9857.93 | I42: -9832.17 | J42: -41462.28 | K42: -41462.28 | L42: -18874.99 | M42: -16189.76 | N42: -15515.42 | O42: -42596.74 | P42: -42596.74 | Q42: -33679.55 | R42: -28075.39 | S42: -23392.89 | T42: -19869.39 | U42: -19869.39 | V42: -15331.96 | W42: -14685.98 | X42: -8901.38 | Y42: 1546.2 | Z42: 1546.2 | AA42: 6871.45 | AB42: 2242.81
A43: 1 | C43: 자본총계 | E43: 29153.79 | F43: 29153.79 | G43: 29475.21 | H43: 29510.72 | I43: 29977.98 | J43: -1607.33 | K43: -1607.33 | L43: 22988.95 | M43: 27435.31 | N43: 28568.89 | O43: 2275.62 | P43: 2275.62 | Q43: 11192.81 | R43: 16796.97 | S43: 21479.46 | T43: 25002.96 | U43: 25002.96 | V43: 31478.15 | W43: 32108.34 | X43: 37892.94 | Y43: 48310.17 | Z43: 48310.17 | AA43: 47635.42 | AB43: 43006.78
A44: 1 | C44: 부채와자본총계 | E44: 58231.24 | F44: 58231.24 | G44: 67583.18 | H44: 63322.62 | I44: 63112.44 | J44: 56959.47 | K44: 56959.47 | L44: 61481.94 | M44: 64919.85 | N44: 59306.8 | O44: 60047.19 | P44: 60047.19 | Q44: 65071.62 | R44: 71708.01 | S44: 65695.77 | T44: 71463.85 | U44: 71463.85 | V44: 72503.27 | W44: 79219.08 | X44: 77461.48 | Y44: 88083.76 | Z44: 88083.76 | AA44: 99903.26 | AB44: 93402.57
A45: 1 | C45: 지배주주지분 | E45: 29153.79 | F45: 29153.79 | G45: 29475.21 | H45: 29510.72 | I45: 29977.98 | J45: -1607.33 | K45: -1607.33 | L45: 22988.95 | M45: 27435.31 | N45: 28568.89 | O45: 2275.62 | P45: 2275.62 | Q45: 11192.81 | R45: 16796.97 | S45: 21479.46 | T45: 25002.96 | U45: 25002.96 | V45: 31478.15 | W45: 32108.34 | X45: 37892.94 | Y45: 48310.17 | Z45: 48310.17 | AA45: 47635.42 | AB45: 43006.78
A46: 1 | C46: 총차입금 | E46: 15915 | F46: 15915 | G46: 15420.66 | H46: 15202.83 | I46: 14416.92 | J46: 13191.11 | K46: 13191.11 | L46: 13354.97 | M46: 13481.18 | N46: 16144 | O46: 16079 | P46: 16079 | Q46: 16014 | R46: 15949 | S46: 17384 | T46: 17194 | U46: 17194 | V46: 17004 | W46: 17214 | X46: 26649 | Y46: 29564 | Z46: 29564 | AA46: 30239 | AB46: 37829
...

Sheet subQ
A1: YQ | C1: subQ 분기 서브모델(억원, U=100) | E1: 4Q21 | F1: 2021 | G1: 1Q22 | H1: 2Q22 | I1: 3Q22 | J1: 4Q22 | K1: 2022 | L1: 1Q23 | M1: 2Q23 | N1: 3Q23 | O1: 4Q23 | P1: 2023 | Q1: 1Q24 | R1: 2Q24 | S1: 3Q24 | T1: 4Q24 | U1: 2024 | V1: 1Q25 | W1: 2Q25 | X1: 3Q25 | Y1: 4Q25 | Z1: 2025 | AA1: 1Q26 | AB1: 2Q26 | AC1: 3Q26 | AD1: 4Q26 | AE1: 2026 | AF1: 1Q27 | AG1: 2Q27 | AH1: 3Q27 | AI1: 4Q27 | AJ1: 2027 | AK1: 1Q28 | AL1: 2Q28 | AM1: 3Q28 | AN1: 4Q28 | AO1: 2028
A2: A=이름(key) B=그룹 C=단위 D=FnGuide 계정명(VLOOKUP 키). 확정=VLOOKUP(BS), 추정=변수 가정 참조
E3: 1 | F3: 2 | G3: 3 | H3: 4 | I3: 5 | J3: 6 | K3: 7 | L3: 8 | M3: 9 | N3: 10 | O3: 11 | P3: 12 | Q3: 13 | R3: 14 | S3: 15 | T3: 16 | U3: 17 | V3: 18 | W3: 19 | X3: 20 | Y3: 21 | Z3: 22 | AA3: 23 | AB3: 24 | AC3: 25 | AD3: 26 | AE3: 27 | AF3: 28 | AG3: 29 | AH3: 30 | AI3: 31 | AJ3: 32 | AK3: 33 | AL3: 34 | AM3: 35 | AN3: 36 | AO3: 37
E4: 2021.12 | F4: 2021.12A | G4: 2022.03 | H4: 2022.06 | I4: 2022.09 | J4: 2022.12 | K4: 2022.12A | L4: 2023.03 | M4: 2023.06 | N4: 2023.09 | O4: 2023.12 | P4: 2023.12A | Q4: 2024.03 | R4: 2024.06 | S4: 2024.09 | T4: 2024.12 | U4: 2024.12A | V4: 2025.03 | W4: 2025.06 | X4: 2025.09 | Y4: 2025.12 | Z4: 2025.12A | AA4: 2026.03 | AB4: 2026.06 | AC4: 2026.09 | AD4: 2026.12 | AE4: 2026.12A | AF4: 2027.03 | AG4: 2027.06 | AH4: 2027.09 | AI4: 2027.12 | AJ4: 2027.12A | AK4: 2028.03 | AL4: 2028.06 | AM4: 2028.09 | AN4: 2028.12 | AO4: 2028.12A
A5: 매출액 | B5: 손익 | C5: 억원 | D5: 매출액(수익) | E5: =IFERROR(VLOOKUP($D5,BS연결,MATCH(E$1,BS연결H,0),0)/100,"") | G5: =IFERROR(VLOOKUP($D5,BS연결,MATCH(G$1,BS연결H,0),0)/100,"") | H5: =IFERROR(VLOOKUP($D5,BS연결,MATCH(H$1,BS연결H,0),0)/100,"") | I5: =IFERROR(VLOOKUP($D5,BS연결,MATCH(I$1,BS연결H,0),0)/100,"") | J5: =IFERROR(VLOOKUP($D5,BS연결,MATCH(J$1,BS연결H,0),0)/100,"") | K5: =IFERROR(VLOOKUP($D5,BS연결,MATCH(K$1,BS연결H,0),0)/100,"") | L5: =IFERROR(VLOOKUP($D5,BS연결,MATCH(L$1,BS연결H,0),0)/100,"") | M5: =IFERROR(VLOOKUP($D5,BS연결,MATCH(M$1,BS연결H,0),0)/100,"") | N5: =IFERROR(VLOOKUP($D5,BS연결,MATCH(N$1,BS연결H,0),0)/100,"") | ... AB5: =IFERROR(VLOOKUP($D5,BS연결,MATCH(AB$1,BS연결H,0),0)/100,"") | AC5: =IFERROR(X5*(1+변수!AC21),"") | AD5: =IFERROR(Y5*(1+변수!AD21),"") | AE5: =SUM(AA5:AD5) | AF5: =IFERROR(AA5*(1+변수!AF21),"") | AG5: =IFERROR(AB5*(1+변수!AG21),"") | AH5: =IFERROR(AC5*(1+변수!AH21),"") | AI5: =IFERROR(AD5*(1+변수!AI21),"") | AJ5: =SUM(AF5:AI5) | AK5: =IFERROR(AF5*(1+변수!AK21),"") | AL5: =IFERROR(AG5*(1+변수!AL21),"") | AM5: =IFERROR(AH5*(1+변수!AM21),"") | AN5: =IFERROR(AI5*(1+변수!AN21),"") | AO5: =SUM(AK5:AN5)
A6: 매출원가 | B6: 손익 | C6: 억원 | D6: 매출원가 | E6: =IFERROR(VLOOKUP($D6,BS연결,MATCH(E$1,BS연결H,0),0)/100,"") | G6: =IFERROR(VLOOKUP($D6,BS연결,MATCH(G$1,BS연결H,0),0)/100,"") | H6: =IFERROR(VLOOKUP($D6,BS연결,MATCH(H$1,BS연결H,0),0)/100,"") | I6: =IFERROR(VLOOKUP($D6,BS연결,MATCH(I$1,BS연결H,0),0)/100,"") | J6: =IFERROR(VLOOKUP($D6,BS연결,MATCH(J$1,BS연결H,0),0)/100,"") | K6: =IFERROR(VLOOKUP($D6,BS연결,MATCH(K$1,BS연결H,0),0)/100,"") | L6: =IFERROR(VLOOKUP($D6,BS연결,MATCH(L$1,BS연결H,0),0)/100,"") | M6: =IFERROR(VLOOKUP($D6,BS연결,MATCH(M$1,BS연결H,0),0)/100,"") | N6: =IFERROR(VLOOKUP($D6,BS연결,MATCH(N$1,BS연결H,0),0)/100,"") | ... AB6: =IFERROR(VLOOKUP($D6,BS연결,MATCH(AB$1,BS연결H,0),0)/100,"") | AC6: =IFERROR(AC5-AC7,"") | AD6: =IFERROR(AD5-AD7,"") | AE6: =SUM(AA6:AD6) | AF6: =IFERROR(AF5-AF7,"") | AG6: =IFERROR(AG5-AG7,"") | AH6: =IFERROR(AH5-AH7,"") | AI6: =IFERROR(AI5-AI7,"") | AJ6: =SUM(AF6:AI6) | AK6: =IFERROR(AK5-AK7,"") | AL6: =IFERROR(AL5-AL7,"") | AM6: =IFERROR(AM5-AM7,"") | AN6: =IFERROR(AN5-AN7,"") | AO6: =SUM(AK6:AN6)
A7: 매출총이익 | B7: 손익 | C7: 억원 | D7: 매출총이익 | E7: =IFERROR(VLOOKUP($D7,BS연결,MATCH(E$1,BS연결H,0),0)/100,"") | G7: =IFERROR(VLOOKUP($D7,BS연결,MATCH(G$1,BS연결H,0),0)/100,"") | H7: =IFERROR(VLOOKUP($D7,BS연결,MATCH(H$1,BS연결H,0),0)/100,"") | I7: =IFERROR(VLOOKUP($D7,BS연결,MATCH(I$1,BS연결H,0),0)/100,"") | J7: =IFERROR(VLOOKUP($D7,BS연결,MATCH(J$1,BS연결H,0),0)/100,"") | K7: =IFERROR(VLOOKUP($D7,BS연결,MATCH(K$1,BS연결H,0),0)/100,"") | L7: =IFERROR(VLOOKUP($D7,BS연결,MATCH(L$1,BS연결H,0),0)/100,"") | M7: =IFERROR(VLOOKUP($D7,BS연결,MATCH(M$1,BS연결H,0),0)/100,"") | N7: =IFERROR(VLOOKUP($D7,BS연결,MATCH(N$1,BS연결H,0),0)/100,"") | ... T7: =IFERROR(VLOOKUP($D7,BS연결,MATCH(T$1,BS연결H,0),0)/100,"") | U7: =SUM(Q7:T7) | V7: =IFERROR(VLOOKUP($D7,BS연결,MATCH(V$1,BS연결H,0),0)/100,"") | W7: =IFERROR(VLOOKUP($D7,BS연결,MATCH(W$1,BS연결H,0),0)/100,"") | X7: =IFERROR(VLOOKUP($D7,BS연결,MATCH(X$1,BS연결H,0),0)/100,"") | Y7: =IFERROR(VLOOKUP($D7,BS연결,MATCH(Y$1,BS연결H,0),0)/100,"") | Z7: =IFERROR(VLOOKUP($D7,BS연결,MATCH(Z$1,BS연결H,0),0)/100,"") | AA7: =IFERROR(VLOOKUP($D7,BS연결,MATCH(AA$1,BS연결H,0),0)/100,"") | AB7: =IFERROR(VLOOKUP($D7,BS연결,MATCH(AB$1,BS연결H,0),0)/100,"") | AC7: =IFERROR(AC9+AC8,"") | AD7: =IFERROR(AD9+AD8,"") | AE7: =SUM(AA7:AD7) | AF7: =IFERROR(AF9+AF8,"") | AG7: =IFERROR(AG9+AG8,"") | AH7: =IFERROR(AH9+AH8,"") | AI7: =IFERROR(AI9+AI8,"") | AJ7: =SUM(AF7:AI7) | AK7: =IFERROR(AK9+AK8,"") | AL7: =IFERROR(AL9+AL8,"") | AM7: =IFERROR(AM9+AM8,"") | AN7: =IFERROR(AN9+AN8,"") | AO7: =SUM(AK7:AN7)
A8: 판관비 | B8: 손익 | C8: 억원 | D8: 판관비 | E8: =IFERROR(VLOOKUP($D8,BS연결,MATCH(E$1,BS연결H,0),0)/100,"") | G8: =IFERROR(VLOOKUP($D8,BS연결,MATCH(G$1,BS연결H,0),0)/100,"") | H8: =IFERROR(VLOOKUP($D8,BS연결,MATCH(H$1,BS연결H,0),0)/100,"") | I8: =IFERROR(VLOOKUP($D8,BS연결,MATCH(I$1,BS연결H,0),0)/100,"") | J8: =IFERROR(VLOOKUP($D8,BS연결,MATCH(J$1,BS연결H,0),0)/100,"") | K8: =IFERROR(VLOOKUP($D8,BS연결,MATCH(K$1,BS연결H,0),0)/100,"") | L8: =IFERROR(VLOOKUP($D8,BS연결,MATCH(L$1,BS연결H,0),0)/100,"") | M8: =IFERROR(VLOOKUP($D8,BS연결,MATCH(M$1,BS연결H,0),0)/100,"") | N8: =IFERROR(VLOOKUP($D8,BS연결,MATCH(N$1,BS연결H,0),0)/100,"") | ... AB8: =IFERROR(VLOOKUP($D8,BS연결,MATCH(AB$1,BS연결H,0),0)/100,"") | AC8: =IFERROR(AC5*변수!AC22,"") | AD8: =IFERROR(AD5*변수!AD22,"") | AE8: =SUM(AA8:AD8) | AF8: =IFERROR(AF5*변수!AF22,"") | AG8: =IFERROR(AG5*변수!AG22,"") | AH8: =IFERROR(AH5*변수!AH22,"") | AI8: =IFERROR(AI5*변수!AI22,"") | AJ8: =SUM(AF8:AI8) | AK8: =IFERROR(AK5*변수!AK22,"") | AL8: =IFERROR(AL5*변수!AL22,"") | AM8: =IFERROR(AM5*변수!AM22,"") | AN8: =IFERROR(AN5*변수!AN22,"") | AO8: =SUM(AK8:AN8)
A9: 영업이익 | B9: 손익 | C9: 억원 | D9: 영업이익 | E9: =IFERROR(VLOOKUP($D9,BS연결,MATCH(E$1,BS연결H,0),0)/100,"") | G9: =IFERROR(VLOOKUP($D9,BS연결,MATCH(G$1,BS연결H,0),0)/100,"") | H9: =IFERROR(VLOOKUP($D9,BS연결,MATCH(H$1,BS연결H,0),0)/100,"") | I9: =IFERROR(VLOOKUP($D9,BS연결,MATCH(I$1,BS연결H,0),0)/100,"") | J9: =IFERROR(VLOOKUP($D9,BS연결,MATCH(J$1,BS연결H,0),0)/100,"") | K9: =IFERROR(VLOOKUP($D9,BS연결,MATCH(K$1,BS연결H,0),0)/100,"") | L9: =IFERROR(VLOOKUP($D9,BS연결,MATCH(L$1,BS연결H,0),0)/100,"") | M9: =IFERROR(VLOOKUP($D9,BS연결,MATCH(M$1,BS연결H,0),0)/100,"") | N9: =IFERROR(VLOOKUP($D9,BS연결,MATCH(N$1,BS연결H,0),0)/100,"") | ... AB9: =IFERROR(VLOOKUP($D9,BS연결,MATCH(AB$1,BS연결H,0),0)/100,"") | AC9: =IFERROR(AC5*변수!AC23,"") | AD9: =IFERROR(AD5*변수!AD23,"") | AE9: =SUM(AA9:AD9) | AF9: =IFERROR(AF5*변수!AF23,"") | AG9: =IFERROR(AG5*변수!AG23,"") | AH9: =IFERROR(AH5*변수!AH23,"") | AI9: =IFERROR(AI5*변수!AI23,"") | AJ9: =SUM(AF9:AI9) | AK9: =IFERROR(AK5*변수!AK23,"") | AL9: =IFERROR(AL5*변수!AL23,"") | AM9: =IFERROR(AM5*변수!AM23,"") | AN9: =IFERROR(AN5*변수!AN23,"") | AO9: =SUM(AK9:AN9)
A10: OPM | B10: 손익 | C10: % | D10: 영업이익률 | E10: =IFERROR(E9/E5,"") | G10: =IFERROR(G9/G5,"") | H10: =IFERROR(H9/H5,"") | I10: =IFERROR(I9/I5,"") | J10: =IFERROR(J9/J5,"") | K10: =IFERROR(K9/K5,"") | L10: =IFERROR(L9/L5,"") | M10: =IFERROR(M9/M5,"") | N10: =IFERROR(N9/N5,"") | ... AO10: =IFERROR(AO9/AO5,"")
A11: 금융손익 | B11: 손익 | C11: 억원 | D11: 금융손익 | E11: =IFERROR(VLOOKUP($D11,BS연결,MATCH(E$1,BS연결H,0),0)/100,"") | G11: =IFERROR(VLOOKUP($D11,BS연결,MATCH(G$1,BS연결H,0),0)/100,"") | H11: =IFERROR(VLOOKUP($D11,BS연결,MATCH(H$1,BS연결H,0),0)/100,"") | I11: =IFERROR(VLOOKUP($D11,BS연결,MATCH(I$1,BS연결H,0),0)/100,"") | J11: =IFERROR(VLOOKUP($D11,BS연결,MATCH(J$1,BS연결H,0),0)/100,"") | K11: =IFERROR(VLOOKUP($D11,BS연결,MATCH(K$1,BS연결H,0),0)/100,"") | L11: =IFERROR(VLOOKUP($D11,BS연결,MATCH(L$1,BS연결H,0),0)/100,"") | M11: =IFERROR(VLOOKUP($D11,BS연결,MATCH(M$1,BS연결H,0),0)/100,"") | N11: =IFERROR(VLOOKUP($D11,BS연결,MATCH(N$1,BS연결H,0),0)/100,"") | ... AB11: =IFERROR(VLOOKUP($D11,BS연결,MATCH(AB$1,BS연결H,0),0)/100,"") | AC11: =IFERROR(AC12+AC13+AC14+AC15,"") | AD11: =IFERROR(AD12+AD13+AD14+AD15,"") | AE11: =SUM(AA11:AD11) | AF11: =IFERROR(AF12+AF13+AF14+AF15,"") | AG11: =IFERROR(AG12+AG13+AG14+AG15,"") | AH11: =IFERROR(AH12+AH13+AH14+AH15,"") | AI11: =IFERROR(AI12+AI13+AI14+AI15,"") | AJ11: =SUM(AF11:AI11) | AK11: =IFERROR(AK12+AK13+AK14+AK15,"") | AL11: =IFERROR(AL12+AL13+AL14+AL15,"") | AM11: =IFERROR(AM12+AM13+AM14+AM15,"") | AN11: =IFERROR(AN12+AN13+AN14+AN15,"") | AO11: =SUM(AK11:AN11)
