Workbook
Name 변수H: 변수!$C$1:$AO$1
Name 환율: 변수!$C$6:$AO$13
Name BS연결H: BS연결!$C$1:$AO$1
Name BS연결: BS연결!$C$5:$AO$100
Name BS별도H: BS별도!$C$1:$AO$1
Name BS별도: BS별도!$C$5:$AO$95
Name SUBQH: subQ!$A$1:$AO$1
Name subQ: subQ!$A$5:$AO$39

Sheet README
A1: 인텔리안테크(189300) 실적 모델 — ARGUS 한국조선
A2: 기준 분기 2026Q2 · 마지막 실적 2026Q2 · 생성 2026-10-11
A3: 모든 수치는 모델 산출값(DART 공개 재무제표 + 우리 추정)이다 — 목표주가·투자 추천 아님. 참고용 · 투자조언 아님.
A5: 시트
A6: 변수 가정 시계열. 환율 8행(ECB via frankfurter — L2 fx.json; 추정 분기 = 노란 가정), 추정 드라이버(노란 셀 = 모델값에서 역산한 가정, 바꾸면 재계산; 연녹 셀 = 3절 스칼라 참조 수식), 3절 스칼라 가정(세율·판관비율·지배주주비중·이자율·종가·PER 밴드·COE·외화 순노출·헤지비율)
A7: BS연결/BS별도 FnGuide 계정명 × 기간 값 덤프(백만원). 행1 분기라벨, 행4 YYYY.MM / YYYY.12A. 이름정의 BS연결H·BS연결(계정명 C열부터)
A8: subQ 분기 서브모델(억원 = 백만원/100). 확정 행: =IFERROR(VLOOKUP($D행,BS연결,MATCH(E$1,BS연결H,0),0)/100,"") 추정 행: 변수 시트 가정 셀 참조 수식. 외환손익·파생상품손익은 BS 계정 합·차, 기타금융손익은 잔차, OPM·EPS·BPS·PER·PBR 은 파생 수식
A9: SLS 선표(조선사만, sls json 있을 때): 요약 행(sls 저장값) + 계약별 스케줄(백만$) × (헤지비율 × 헤지환율 + (1−헤지비율) × 건조시점 환율[변수 원/달러(평균)]) → 원화 수식 블록 → 합계 행이 subQ 매출조선에 연결
A10: 시나리오 신규수주 보수/기준/낙관(forecast_panel 패널, 모델에 scenarios 가 있을 때만): 매출액·영업이익 = subQ 기준값 ± (시나리오 신규 − base 신규) × OPM. base 만 subQ 행에 포함, 나머지는 합산 안 함
A11: 분기/연간예상 subQ 를 이름(A열 key)으로 VLOOKUP 한 보고서 표(억원)
A12: TP PER 밴드 × 12M fwd EPS, PBR = ROE/COE × BPS — 모델 산출값 구간, 목표주가·추천 아님
A13: 외화 환율 QoQ, 외화 순노출 × Δ기말환율 → 환관련손익 추정
... A34: 백테스트: {"freeze": "2025Q2", "horizon": 4, "revenue_wape_pct": 32.8, "op_wape_pct": 137.5, "n": 4, "note": "단일 회사 4분기 — 통계 아님", "driver_at_freeze": "trend_seasonal", "selection_oos_at_freeze": null, "frozen_inputs": "fin(연결/별도)·고객 조선사 모델·지주 자회사 모델은 2025Q2 까지의 분기만; 선표는 체결일 ≤ 2025Q2 말일 계약(원장 최신 금액·코호트 등급, 환산 없음); 잔고는 yards_cache 2025Q2; 시세·환율 forward·prices·forecast_panel 신규수주 미사용. 고객 가중치(suppliers.json 언급 비중)와 합병 체인링크는 현재 지식; 고객 연동 채택은 동결 모델 안에서도 자기 la−4분기 OOS 규칙(selection_oos_at_freeze)", "detail": [{"q": "2025Q3", "rev_pred": 591.46, "rev_act": 772.26, "op_pred": -27.24, "op_act": 23.73}, {"q": "2025Q4", "rev_pred": 730.41, "rev_act": 1243.15, "op_pred": -33.64, "op_act": 198.56}, {"q": "2026Q1", "rev_pred": 411.16, "rev_act": 647.24, "op_pred": -18.93, "op_act": 5.93}, {"q": "2026Q2", "rev_pred": 708.83, "rev_act": 972.46, "op_pred": -32.64, "op_act": 71.36}]}

Sheet 변수
C1: 이름: 변수H | E1: 4Q21 | F1: 2021 | G1: 1Q22 | H1: 2Q22 | I1: 3Q22 | J1: 4Q22 | K1: 2022 | L1: 1Q23 | M1: 2Q23 | N1: 3Q23 | O1: 4Q23 | P1: 2023 | Q1: 1Q24 | R1: 2Q24 | S1: 3Q24 | T1: 4Q24 | U1: 2024 | V1: 1Q25 | W1: 2Q25 | X1: 3Q25 | Y1: 4Q25 | Z1: 2025 | AA1: 1Q26 | AB1: 2Q26 | AC1: 3Q26 | AD1: 4Q26 | AE1: 2026 | AF1: 1Q27 | AG1: 2Q27 | AH1: 3Q27 | AI1: 4Q27 | AJ1: 2027 | AK1: 1Q28 | AL1: 2Q28 | AM1: 3Q28 | AN1: 4Q28 | AO1: 2028
A2: 가정 시계열 — 노란 셀은 추정 가정(모델값에서 역산), 연녹 셀은 3절 스칼라 참조 수식. 바꾸면 subQ·분기·연간예상·TP·시나리오가 재계산됩니다.
E3: 1 | F3: 2 | G3: 3 | H3: 4 | I3: 5 | J3: 6 | K3: 7 | L3: 8 | M3: 9 | N3: 10 | O3: 11 | P3: 12 | Q3: 13 | R3: 14 | S3: 15 | T3: 16 | U3: 17 | V3: 18 | W3: 19 | X3: 20 | Y3: 21 | Z3: 22 | AA3: 23 | AB3: 24 | AC3: 25 | AD3: 26 | AE3: 27 | AF3: 28 | AG3: 29 | AH3: 30 | AI3: 31 | AJ3: 32 | AK3: 33 | AL3: 34 | AM3: 35 | AN3: 36 | AO3: 37
E4: 2021.12 | F4: 2021.12A | G4: 2022.03 | H4: 2022.06 | I4: 2022.09 | J4: 2022.12 | K4: 2022.12A | L4: 2023.03 | M4: 2023.06 | N4: 2023.09 | O4: 2023.12 | P4: 2023.12A | Q4: 2024.03 | R4: 2024.06 | S4: 2024.09 | T4: 2024.12 | U4: 2024.12A | V4: 2025.03 | W4: 2025.06 | X4: 2025.09 | Y4: 2025.12 | Z4: 2025.12A | AA4: 2026.03 | AB4: 2026.06 | AC4: 2026.09 | AD4: 2026.12 | AE4: 2026.12A | AF4: 2027.03 | AG4: 2027.06 | AH4: 2027.09 | AI4: 2027.12 | AJ4: 2027.12A | AK4: 2028.03 | AL4: 2028.06 | AM4: 2028.09 | AN4: 2028.12 | AO4: 2028.12A
B5: 1. FX | C5: 이름: 환율
A6: USDKRW_avg | C6: 원/달러(평균) | E6: 1183.5 | F6: 1145.51 | G6: 1205.78 | H6: 1262.09 | I6: 1341.93 | J6: 1360.12 | K6: 1292.98 | L6: 1276.95 | M6: 1315.69 | N6: 1313.62 | O6: 1322.01 | P6: 1306.85 | Q6: 1330.14 | R6: 1371.28 | S6: 1356.22 | T6: 1396.3 | U6: 1363.53 | V6: 1452.28 | W6: 1398.52 | X6: 1386.95 | Y6: 1449.19 | Z6: 1421.52 | AA6: 1466.12 | AB6: 1501.75 | AC6: 1418.75 | AD6: 1345.14 | AE6: 1457.21 | AF6: 1341.49 | AG6: 1341.49 | AH6: 1341.49 | AI6: 1341.49 | AK6: 1341.49 | AL6: 1341.49 | AM6: 1341.49 | AN6: 1341.49
A7: USDKRW_end | C7: 원/달러(기말) | E7: 1188.75 | F7: 1188.75 | G7: 1213.74 | H7: 1301.24 | I7: 1436.9 | J7: 1260.16 | K7: 1260.16 | L7: 1305.99 | M7: 1321.44 | N7: 1345.35 | O7: 1297.43 | P7: 1297.43 | Q7: 1349.25 | R7: 1377.73 | S7: 1312.17 | T7: 1474.78 | U7: 1474.78 | V7: 1474.54 | W7: 1355.13 | X7: 1403.67 | Y7: 1444.2 | Z7: 1444.2 | AA7: 1524.8 | AB7: 1550.89 | AC7: 1355.4 | AD7: 1341.49 | AE7: 1341.49 | AF7: 1341.49 | AG7: 1341.49 | AH7: 1341.49 | AI7: 1341.49 | AK7: 1341.49 | AL7: 1341.49 | AM7: 1341.49 | AN7: 1341.49
A8: JPY100KRW_avg | C8: 원/100Y(평균) | E8: 1041.02 | F8: 1042.74 | G8: 1036.79 | H8: 972.23 | I8: 970.61 | J8: 961.03 | K8: 985.1 | L8: 964.89 | M8: 957.36 | N8: 909 | O8: 893.22 | P8: 931.11 | Q8: 896.29 | R8: 880.14 | S8: 909.35 | T8: 917.25 | U8: 900.92 | V8: 952.59 | W8: 967.92 | X8: 940.32 | Y8: 940.77 | Z8: 950.17 | AA8: 934.39 | AB8: 942.16 | AC8: 890.41 | AD8: 850.79 | AE8: 919.21 | AF8: 847.7 | AG8: 847.7 | AH8: 847.7 | AI8: 847.7 | AK8: 847.7 | AL8: 847.7 | AM8: 847.7 | AN8: 847.7
A9: JPY100KRW_end | C9: 원/100Y(기말) | E9: 1032.62 | F9: 1032.62 | G9: 996.83 | H9: 954.9 | I9: 993.29 | J9: 955.54 | K9: 955.54 | L9: 980.62 | M9: 913.67 | N9: 901.47 | O9: 917.04 | P9: 917.04 | Q9: 892.42 | R9: 857.76 | S9: 919.21 | T9: 939.65 | U9: 939.65 | V9: 986.84 | W9: 938.85 | X9: 948.49 | Y9: 921.81 | Z9: 921.81 | AA9: 955.99 | AB9: 954.75 | AC9: 863.31 | AD9: 847.7 | AE9: 847.7 | AF9: 847.7 | AG9: 847.7 | AH9: 847.7 | AI9: 847.7 | AK9: 847.7 | AL9: 847.7 | AM9: 847.7 | AN9: 847.7
A10: EURKRW_avg | C10: W/Euro(평균) | E10: 1353.32 | F10: 1354.06 | G10: 1352.29 | H10: 1343.31 | I10: 1350.63 | J10: 1386.07 | K10: 1358.07 | L10: 1369.93 | M10: 1432.41 | N10: 1429.41 | O10: 1420.91 | P10: 1412.88 | Q10: 1444.21 | R10: 1476.42 | S10: 1489.3 | T10: 1490.78 | U10: 1475.4 | V10: 1528.33 | W10: 1585.13 | X10: 1620.04 | Y10: 1686.02 | Z10: 1605.45 | AA10: 1715.47 | AB10: 1746.09 | AC10: 1631.97 | AD10: 1509.74 | AE10: 1689.95 | AF10: 1503.27 | AG10: 1503.27 | AH10: 1503.27 | AI10: 1503.27 | AK10: 1503.27 | AL10: 1503.27 | AM10: 1503.27 | AN10: 1503.27
A11: EURKRW_end | C11: W/Euro(기말) | E11: 1346.38 | F11: 1346.38 | G11: 1347.37 | H11: 1351.6 | I11: 1400.62 | J11: 1344.08 | K11: 1344.08 | L11: 1420.26 | M11: 1435.88 | N11: 1425.26 | O11: 1433.66 | P11: 1433.66 | Q11: 1458.68 | R11: 1474.86 | S11: 1469.1 | T11: 1532.14 | U11: 1532.14 | V11: 1594.72 | W11: 1588.22 | X11: 1648.04 | Y11: 1696.94 | Z11: 1696.94 | AA11: 1753.21 | AB11: 1767.09 | AC11: 1539.06 | AD11: 1503.27 | AE11: 1503.27 | AF11: 1503.27 | AG11: 1503.27 | AH11: 1503.27 | AI11: 1503.27 | AK11: 1503.27 | AL11: 1503.27 | AM11: 1503.27 | AN11: 1503.27
A12: CNYKRW_avg | C12: 원/중국원(평균) | E12: 185.14 | F12: 177.65 | G12: 189.93 | H12: 190.76 | I12: 195.79 | J12: 191.09 | K12: 191.93 | L12: 186.59 | M12: 187.45 | N12: 181.28 | O12: 182.86 | P12: 184.52 | Q12: 185.04 | R12: 189.35 | S12: 189.24 | T12: 194.24 | U12: 189.49 | V12: 199.63 | W12: 193.41 | X12: 193.79 | Y12: 204.38 | Z12: 197.8 | AA12: 211.75 | AB12: 220.8 | AC12: 210.43 | AD12: 200.69 | AE12: 213.75 | AF12: 200.46 | AG12: 200.46 | AH12: 200.46 | AI12: 200.46 | AK12: 200.46 | AL12: 200.46 | AM12: 200.46 | AN12: 200.46
A13: CNYKRW_end | C13: 원/중국원(기말) | E13: 187.13 | F13: 187.13 | G13: 191.38 | H13: 194.13 | I13: 201.92 | J13: 182.67 | K13: 182.67 | L13: 189.97 | M13: 181.8 | N13: 184.26 | O13: 182.61 | P13: 182.61 | Q13: 186.66 | R13: 189.7 | S13: 187.12 | T13: 202.04 | U13: 202.04 | V13: 203.3 | W13: 189.14 | X13: 197.16 | Y13: 206.28 | Z13: 206.28 | AA13: 220.97 | AB13: 228.56 | AC13: 202.16 | AD13: 200.46 | AE13: 200.46 | AF13: 200.46 | AG13: 200.46 | AH13: 200.46 | AI13: 200.46 | AK13: 200.46 | AL13: 200.46 | AM13: 200.46 | AN13: 200.46
B14: 1b. 종가
A15: price_close_end | C15: 종가(기말) | E15: 89064 | G15: 85772 | H15: 57988 | I15: 53051 | J15: 65830 | L15: 90613 | M15: 73400 | N15: 82100 | O15: 72500 | Q15: 59000 | R15: 58900 | S15: 55000 | T15: 37500 | V15: 34850 | W15: 50100 | X15: 47150 | Y15: 59500 | AA15: 110900 | AB15: 77700 | AC15: 66500 | AD15: 63800
A16: price_high | C16: 종가(최고) | E16: 90031 | G16: 92742 | H16: 87902 | I16: 72993 | J16: 74639 | L16: 96324 | M16: 92742 | N16: 92000 | O16: 86700 | Q16: 82400 | R16: 69500 | S16: 60500 | T16: 57400 | V16: 46400 | W16: 54000 | X16: 54900 | Y16: 64600 | AA16: 149400 | AB16: 180200 | AC16: 81400 | AD16: 77300
A17: price_low | C17: 종가(최저) | E17: 64280 | G17: 69992 | H17: 53244 | I17: 51308 | J17: 53728 | L17: 59634 | M17: 63409 | N17: 67400 | O17: 66400 | Q17: 52300 | R17: 53600 | S17: 43000 | T17: 33500 | V17: 33350 | W17: 30800 | X17: 43400 | Y17: 39000 | AA17: 59400 | AB17: 67700 | AC17: 48100 | AD17: 62900
A18: price_avg | C18: 종가(평균) | E18: 74710.1 | G18: 79783.4 | H18: 76683.3 | I18: 64300.9 | J18: 64056 | L18: 74957.9 | M18: 73942.8 | N18: 78641.9 | O18: 74175 | Q18: 61383.6 | R18: 60596.7 | S18: 53920.2 | T18: 45203.3 | V18: 38918.1 | W18: 42007.5 | X18: 48463.1 | Y18: 46804.2 | AA18: 105422 | AB18: 124445.9 | AC18: 66313.7 | AD18: 69920
B20: 2. 추정 드라이버 | C20: 실적 열 = subQ 실현값(수식), 추정 열 = 가정(노란 = 모델값 역산, 연녹 = 3절 스칼라 참조)
A21: drv:매출액 | B21: yoy | C21: 매출액 YoY | J21: =IFERROR(subQ!J5/subQ!E5-1,"") | L21: =IFERROR(subQ!L5/subQ!G5-1,"") | M21: =IFERROR(subQ!M5/subQ!H5-1,"") | N21: =IFERROR(subQ!N5/subQ!I5-1,"") | O21: =IFERROR(subQ!O5/subQ!J5-1,"") | Q21: =IFERROR(subQ!Q5/subQ!L5-1,"") | R21: =IFERROR(subQ!R5/subQ!M5-1,"") | S21: =IFERROR(subQ!S5/subQ!N5-1,"") | T21: =IFERROR(subQ!T5/subQ!O5-1,"") | V21: =IFERROR(subQ!V5/subQ!Q5-1,"") | W21: =IFERROR(subQ!W5/subQ!R5-1,"") | X21: =IFERROR(subQ!X5/subQ!S5-1,"") | Y21: =IFERROR(subQ!Y5/subQ!T5-1,"") | AA21: =IFERROR(subQ!AA5/subQ!V5-1,"") | AB21: =IFERROR(subQ!AB5/subQ!W5-1,"") | AC21: 0.41192503 | AD21: 0.4119246 | AF21: 0.41192768 | AG21: 0.41192178 | AH21: 0.20595572 | AI21: 0.20596044 | AK21: 0.20595284 | AL21: 0.20595904 | AM21: 0.1029849 | AN21: 0.10297862
A22: drv:판관비 | B22: ratio | C22: 판관비율(/매출) | E22: =IFERROR(subQ!E8/subQ!E5,"") | F22: =IFERROR(subQ!F8/subQ!F5,"") | G22: =IFERROR(subQ!G8/subQ!G5,"") | H22: =IFERROR(subQ!H8/subQ!H5,"") | I22: =IFERROR(subQ!I8/subQ!I5,"") | J22: =IFERROR(subQ!J8/subQ!J5,"") | K22: =IFERROR(subQ!K8/subQ!K5,"") | L22: =IFERROR(subQ!L8/subQ!L5,"") | ... AB22: =IFERROR(subQ!AB8/subQ!AB5,"") | AC22: =$D$48 | AD22: =$D$48 | AE22: =IFERROR(subQ!AE8/subQ!AE5,"") | AF22: =$D$48 | AG22: =$D$48 | AH22: =$D$48 | AI22: =$D$48 | AJ22: =IFERROR(subQ!AJ8/subQ!AJ5,"") | AK22: =$D$48 | AL22: =$D$48 | AM22: =$D$48 | AN22: =$D$48 | AO22: =IFERROR(subQ!AO8/subQ!AO5,"")
A23: drv:영업이익 | B23: ratio | C23: 영업이익률(OPM) | E23: =IFERROR(subQ!E9/subQ!E5,"") | F23: =IFERROR(subQ!F9/subQ!F5,"") | G23: =IFERROR(subQ!G9/subQ!G5,"") | H23: =IFERROR(subQ!H9/subQ!H5,"") | I23: =IFERROR(subQ!I9/subQ!I5,"") | J23: =IFERROR(subQ!J9/subQ!J5,"") | K23: =IFERROR(subQ!K9/subQ!K5,"") | L23: =IFERROR(subQ!L9/subQ!L5,"") | ... AB23: =IFERROR(subQ!AB9/subQ!AB5,"") | AC23: 0.016379611 | AD23: 0.016379526 | AE23: =IFERROR(subQ!AE9/subQ!AE5,"") | AF23: 0.016381244 | AG23: 0.016379712 | AH23: 0.016380851 | AI23: 0.016378883 | AJ23: =IFERROR(subQ!AJ9/subQ!AJ5,"") | AK23: 0.016378419 | AL23: 0.016378493 | AM23: 0.016382027 | AN23: 0.016378768 | AO23: =IFERROR(subQ!AO9/subQ!AO5,"")
A24: drv:기타영업외손익 | B24: abs | C24: 기타영업외손익 (가정, 억원) | E24: =subQ!E13 | F24: =subQ!F13 | G24: =subQ!G13 | H24: =subQ!H13 | I24: =subQ!I13 | J24: =subQ!J13 | K24: =subQ!K13 | L24: =subQ!L13 | ... AB24: =subQ!AB13 | AC24: 0 | AD24: 0 | AE24: =subQ!AE13 | AF24: 0 | AG24: 0 | AH24: 0 | AI24: 0 | AJ24: =subQ!AJ13 | AK24: 0 | AL24: 0 | AM24: 0 | AN24: 0 | AO24: =subQ!AO13
A25: drv:법인세비용 | B25: tax | C25: 법인세율(/세전) — 법인세 = MAX(세전,0) × 세율 | E25: =IFERROR(subQ!E15/subQ!E14,"") | F25: =IFERROR(subQ!F15/subQ!F14,"") | G25: =IFERROR(subQ!G15/subQ!G14,"") | H25: =IFERROR(subQ!H15/subQ!H14,"") | I25: =IFERROR(subQ!I15/subQ!I14,"") | J25: =IFERROR(subQ!J15/subQ!J14,"") | K25: =IFERROR(subQ!K15/subQ!K14,"") | L25: =IFERROR(subQ!L15/subQ!L14,"") | ... AB25: =IFERROR(subQ!AB15/subQ!AB14,"") | AC25: =$D$47 | AD25: =$D$47 | AE25: =IFERROR(subQ!AE15/subQ!AE14,"") | AF25: =$D$47 | AG25: =$D$47 | AH25: =$D$47 | AI25: =$D$47 | AJ25: =IFERROR(subQ!AJ15/subQ!AJ14,"") | AK25: =$D$47 | AL25: =$D$47 | AM25: =$D$47 | AN25: =$D$47 | AO25: =IFERROR(subQ!AO15/subQ!AO14,"")
A26: drv:지배주주순이익 | B26: ratio | C26: 지배주주 비중(/당기순이익) | E26: =IFERROR(subQ!E17/subQ!E16,"") | F26: =IFERROR(subQ!F17/subQ!F16,"") | G26: =IFERROR(subQ!G17/subQ!G16,"") | H26: =IFERROR(subQ!H17/subQ!H16,"") | I26: =IFERROR(subQ!I17/subQ!I16,"") | J26: =IFERROR(subQ!J17/subQ!J16,"") | K26: =IFERROR(subQ!K17/subQ!K16,"") | L26: =IFERROR(subQ!L17/subQ!L16,"") | ... AB26: =IFERROR(subQ!AB17/subQ!AB16,"") | AC26: =$D$49 | AD26: =$D$49 | AE26: =IFERROR(subQ!AE17/subQ!AE16,"") | AF26: =$D$49 | AG26: =$D$49 | AH26: =$D$49 | AI26: =$D$49 | AJ26: =IFERROR(subQ!AJ17/subQ!AJ16,"") | AK26: =$D$49 | AL26: =$D$49 | AM26: =$D$49 | AN26: =$D$49 | AO26: =IFERROR(subQ!AO17/subQ!AO16,"")
A27: drv:부채총계 | B27: qoq | C27: 부채총계 QoQ | G27: =IFERROR(subQ!G19/subQ!E19-1,"") | H27: =IFERROR(subQ!H19/subQ!G19-1,"") | I27: =IFERROR(subQ!I19/subQ!H19-1,"") | J27: =IFERROR(subQ!J19/subQ!I19-1,"") | L27: =IFERROR(subQ!L19/subQ!J19-1,"") | M27: =IFERROR(subQ!M19/subQ!L19-1,"") | N27: =IFERROR(subQ!N19/subQ!M19-1,"") | O27: =IFERROR(subQ!O19/subQ!N19-1,"") | Q27: =IFERROR(subQ!Q19/subQ!O19-1,"") | R27: =IFERROR(subQ!R19/subQ!Q19-1,"") | S27: =IFERROR(subQ!S19/subQ!R19-1,"") | T27: =IFERROR(subQ!T19/subQ!S19-1,"") | V27: =IFERROR(subQ!V19/subQ!T19-1,"") | W27: =IFERROR(subQ!W19/subQ!V19-1,"") | X27: =IFERROR(subQ!X19/subQ!W19-1,"") | Y27: =IFERROR(subQ!Y19/subQ!X19-1,"") | AA27: =IFERROR(subQ!AA19/subQ!Y19-1,"") | AB27: =IFERROR(subQ!AB19/subQ!AA19-1,"") | AC27: -8.58e-07 | AD27: 0 | AF27: 0 | AG27: 0 | AH27: 0 | AI27: 0 | AK27: 0 | AL27: 0 | AM27: 0 | AN27: 0
A28: drv:자본총계 | B28: roll | C28: 자본총계 기타변동(배당 등, 억원) | G28: =IFERROR(subQ!E20+subQ!G16-subQ!G20,"") | H28: =IFERROR(subQ!G20+subQ!H16-subQ!H20,"") | I28: =IFERROR(subQ!H20+subQ!I16-subQ!I20,"") | J28: =IFERROR(subQ!I20+subQ!J16-subQ!J20,"") | L28: =IFERROR(subQ!J20+subQ!L16-subQ!L20,"") | M28: =IFERROR(subQ!L20+subQ!M16-subQ!M20,"") | N28: =IFERROR(subQ!M20+subQ!N16-subQ!N20,"") | O28: =IFERROR(subQ!N20+subQ!O16-subQ!O20,"") | Q28: =IFERROR(subQ!O20+subQ!Q16-subQ!Q20,"") | R28: =IFERROR(subQ!Q20+subQ!R16-subQ!R20,"") | S28: =IFERROR(subQ!R20+subQ!S16-subQ!S20,"") | T28: =IFERROR(subQ!S20+subQ!T16-subQ!T20,"") | V28: =IFERROR(subQ!T20+subQ!V16-subQ!V20,"") | W28: =IFERROR(subQ!V20+subQ!W16-subQ!W20,"") | X28: =IFERROR(subQ!W20+subQ!X16-subQ!X20,"") | Y28: =IFERROR(subQ!X20+subQ!Y16-subQ!Y20,"") | AA28: =IFERROR(subQ!Y20+subQ!AA16-subQ!AA20,"") | AB28: =IFERROR(subQ!AA20+subQ!AB16-subQ!AB20,"")
A29: drv:지배주주지분 | B29: roll | C29: 지배주주지분 기타변동(배당 등, 억원) | G29: =IFERROR(subQ!E21+subQ!G17-subQ!G21,"") | H29: =IFERROR(subQ!G21+subQ!H17-subQ!H21,"") | I29: =IFERROR(subQ!H21+subQ!I17-subQ!I21,"") | J29: =IFERROR(subQ!I21+subQ!J17-subQ!J21,"") | L29: =IFERROR(subQ!J21+subQ!L17-subQ!L21,"") | M29: =IFERROR(subQ!L21+subQ!M17-subQ!M21,"") | N29: =IFERROR(subQ!M21+subQ!N17-subQ!N21,"") | O29: =IFERROR(subQ!N21+subQ!O17-subQ!O21,"") | Q29: =IFERROR(subQ!O21+subQ!Q17-subQ!Q21,"") | R29: =IFERROR(subQ!Q21+subQ!R17-subQ!R21,"") | S29: =IFERROR(subQ!R21+subQ!S17-subQ!S21,"") | T29: =IFERROR(subQ!S21+subQ!T17-subQ!T21,"") | V29: =IFERROR(subQ!T21+subQ!V17-subQ!V21,"") | W29: =IFERROR(subQ!V21+subQ!W17-subQ!W21,"") | X29: =IFERROR(subQ!W21+subQ!X17-subQ!X21,"") | Y29: =IFERROR(subQ!X21+subQ!Y17-subQ!Y21,"") | AA29: =IFERROR(subQ!Y21+subQ!AA17-subQ!AA21,"") | AB29: =IFERROR(subQ!AA21+subQ!AB17-subQ!AB21,"") | AC29: -0.000200803 | AD29: -0.001997346 | AF29: 5.8479e-05 | AG29: 20.441998 | AH29: 0.00506408 | AI29: -0.002850513 | AK29: -0.003170288 | AL29: 20.444163 | AM29: 0.001883336 | AN29: -0.004446441
A30: drv:총차입금 | B30: qoq | C30: 총차입금 QoQ | G30: =IFERROR(subQ!G22/subQ!E22-1,"") | H30: =IFERROR(subQ!H22/subQ!G22-1,"") | I30: =IFERROR(subQ!I22/subQ!H22-1,"") | J30: =IFERROR(subQ!J22/subQ!I22-1,"") | L30: =IFERROR(subQ!L22/subQ!J22-1,"") | M30: =IFERROR(subQ!M22/subQ!L22-1,"") | N30: =IFERROR(subQ!N22/subQ!M22-1,"") | O30: =IFERROR(subQ!O22/subQ!N22-1,"") | Q30: =IFERROR(subQ!Q22/subQ!O22-1,"") | R30: =IFERROR(subQ!R22/subQ!Q22-1,"") | S30: =IFERROR(subQ!S22/subQ!R22-1,"") | T30: =IFERROR(subQ!T22/subQ!S22-1,"") | V30: =IFERROR(subQ!V22/subQ!T22-1,"") | W30: =IFERROR(subQ!W22/subQ!V22-1,"") | X30: =IFERROR(subQ!X22/subQ!W22-1,"") | Y30: =IFERROR(subQ!Y22/subQ!X22-1,"") | AA30: =IFERROR(subQ!AA22/subQ!Y22-1,"") | AB30: =IFERROR(subQ!AB22/subQ!AA22-1,"") | AC30: 3.136e-06 | AD30: 0 | AF30: 0 | AG30: 0 | AH30: 0 | AI30: 0 | AK30: 0 | AL30: 0 | AM30: 0 | AN30: 0
A31: drv:순차입금 | B31: qoq | C31: 순차입금 QoQ | G31: =IFERROR(subQ!G23/subQ!E23-1,"") | H31: =IFERROR(subQ!H23/subQ!G23-1,"") | I31: =IFERROR(subQ!I23/subQ!H23-1,"") | J31: =IFERROR(subQ!J23/subQ!I23-1,"") | L31: =IFERROR(subQ!L23/subQ!J23-1,"") | M31: =IFERROR(subQ!M23/subQ!L23-1,"") | N31: =IFERROR(subQ!N23/subQ!M23-1,"") | O31: =IFERROR(subQ!O23/subQ!N23-1,"") | Q31: =IFERROR(subQ!Q23/subQ!O23-1,"") | R31: =IFERROR(subQ!R23/subQ!Q23-1,"") | S31: =IFERROR(subQ!S23/subQ!R23-1,"") | T31: =IFERROR(subQ!T23/subQ!S23-1,"") | V31: =IFERROR(subQ!V23/subQ!T23-1,"") | W31: =IFERROR(subQ!W23/subQ!V23-1,"") | X31: =IFERROR(subQ!X23/subQ!W23-1,"") | Y31: =IFERROR(subQ!Y23/subQ!X23-1,"") | AA31: =IFERROR(subQ!AA23/subQ!Y23-1,"") | AB31: =IFERROR(subQ!AB23/subQ!AA23-1,"") | AC31: -0.003702945 | AD31: -0.012149612 | AF31: -0.001543849 | AG31: 0.01021034 | AH31: -0.006601281 | AI31: -0.016931354 | AK31: -0.004062763 | AL31: 0.006646504 | AM31: -0.008567686 | AN31: -0.020252116
A32: drv:이자발생자산 | B32: qoq | C32: 이자발생자산 QoQ | G32: =IFERROR(subQ!G24/subQ!E24-1,"") | H32: =IFERROR(subQ!H24/subQ!G24-1,"") | I32: =IFERROR(subQ!I24/subQ!H24-1,"") | J32: =IFERROR(subQ!J24/subQ!I24-1,"") | L32: =IFERROR(subQ!L24/subQ!J24-1,"") | M32: =IFERROR(subQ!M24/subQ!L24-1,"") | N32: =IFERROR(subQ!N24/subQ!M24-1,"") | O32: =IFERROR(subQ!O24/subQ!N24-1,"") | Q32: =IFERROR(subQ!Q24/subQ!O24-1,"") | R32: =IFERROR(subQ!R24/subQ!Q24-1,"") | S32: =IFERROR(subQ!S24/subQ!R24-1,"") | T32: =IFERROR(subQ!T24/subQ!S24-1,"") | V32: =IFERROR(subQ!V24/subQ!T24-1,"") | W32: =IFERROR(subQ!W24/subQ!V24-1,"") | X32: =IFERROR(subQ!X24/subQ!W24-1,"") | Y32: =IFERROR(subQ!Y24/subQ!X24-1,"") | AA32: =IFERROR(subQ!AA24/subQ!Y24-1,"") | AB32: =IFERROR(subQ!AB24/subQ!AA24-1,"") | AC32: 0.005555568 | AD32: 0.01807901 | AF32: 0.002229085 | AG32: -0.014686696 | AH32: 0.009747916 | AI32: 0.024565391 | AK32: 0.005643657 | AL32: -0.009151293 | AM32: 0.011988208 | AN32: 0.027790202
A33: drv:현금및현금성자산 | B33: qoq | C33: 현금및현금성자산 QoQ | G33: =IFERROR(subQ!G25/subQ!E25-1,"") | H33: =IFERROR(subQ!H25/subQ!G25-1,"") | I33: =IFERROR(subQ!I25/subQ!H25-1,"") | J33: =IFERROR(subQ!J25/subQ!I25-1,"") | L33: =IFERROR(subQ!L25/subQ!J25-1,"") | M33: =IFERROR(subQ!M25/subQ!L25-1,"") | N33: =IFERROR(subQ!N25/subQ!M25-1,"") | O33: =IFERROR(subQ!O25/subQ!N25-1,"") | Q33: =IFERROR(subQ!Q25/subQ!O25-1,"") | R33: =IFERROR(subQ!R25/subQ!Q25-1,"") | S33: =IFERROR(subQ!S25/subQ!R25-1,"") | T33: =IFERROR(subQ!T25/subQ!S25-1,"") | V33: =IFERROR(subQ!V25/subQ!T25-1,"") | W33: =IFERROR(subQ!W25/subQ!V25-1,"") | X33: =IFERROR(subQ!X25/subQ!W25-1,"") | Y33: =IFERROR(subQ!Y25/subQ!X25-1,"") | AA33: =IFERROR(subQ!AA25/subQ!Y25-1,"") | AB33: =IFERROR(subQ!AB25/subQ!AA25-1,"")
A34: drv:CAPEX | B34: yoy | C34: CAPEX YoY | J34: =IFERROR(subQ!J26/subQ!E26-1,"") | L34: =IFERROR(subQ!L26/subQ!G26-1,"") | M34: =IFERROR(subQ!M26/subQ!H26-1,"") | N34: =IFERROR(subQ!N26/subQ!I26-1,"") | O34: =IFERROR(subQ!O26/subQ!J26-1,"") | Q34: =IFERROR(subQ!Q26/subQ!L26-1,"") | R34: =IFERROR(subQ!R26/subQ!M26-1,"") | S34: =IFERROR(subQ!S26/subQ!N26-1,"") | T34: =IFERROR(subQ!T26/subQ!O26-1,"") | V34: =IFERROR(subQ!V26/subQ!Q26-1,"") | W34: =IFERROR(subQ!W26/subQ!R26-1,"") | X34: =IFERROR(subQ!X26/subQ!S26-1,"") | Y34: =IFERROR(subQ!Y26/subQ!T26-1,"") | AA34: =IFERROR(subQ!AA26/subQ!V26-1,"") | AB34: =IFERROR(subQ!AB26/subQ!W26-1,"") | AC34: -0.19762378 | AD34: 0.37421763 | AF34: -0.10901338 | AG34: 0.13946764 | AH34: 0 | AI34: 0 | AK34: 0 | AL34: 0 | AM34: 0 | AN34: 0
A35: drv:영업활동현금흐름 | B35: yoy | C35: 영업활동현금흐름 YoY | J35: =IFERROR(subQ!J27/subQ!E27-1,"") | L35: =IFERROR(subQ!L27/subQ!G27-1,"") | M35: =IFERROR(subQ!M27/subQ!H27-1,"") | N35: =IFERROR(subQ!N27/subQ!I27-1,"") | O35: =IFERROR(subQ!O27/subQ!J27-1,"") | Q35: =IFERROR(subQ!Q27/subQ!L27-1,"") | R35: =IFERROR(subQ!R27/subQ!M27-1,"") | S35: =IFERROR(subQ!S27/subQ!N27-1,"") | T35: =IFERROR(subQ!T27/subQ!O27-1,"") | V35: =IFERROR(subQ!V27/subQ!Q27-1,"") | W35: =IFERROR(subQ!W27/subQ!R27-1,"") | X35: =IFERROR(subQ!X27/subQ!S27-1,"") | Y35: =IFERROR(subQ!Y27/subQ!T27-1,"") | AA35: =IFERROR(subQ!AA27/subQ!V27-1,"") | AB35: =IFERROR(subQ!AB27/subQ!W27-1,"")
A36: drv:주식수 | B36: qoq | C36: 주식수 QoQ | G36: =IFERROR(subQ!G28/subQ!E28-1,"") | H36: =IFERROR(subQ!H28/subQ!G28-1,"") | I36: =IFERROR(subQ!I28/subQ!H28-1,"") | J36: =IFERROR(subQ!J28/subQ!I28-1,"") | L36: =IFERROR(subQ!L28/subQ!J28-1,"") | M36: =IFERROR(subQ!M28/subQ!L28-1,"") | N36: =IFERROR(subQ!N28/subQ!M28-1,"") | O36: =IFERROR(subQ!O28/subQ!N28-1,"") | Q36: =IFERROR(subQ!Q28/subQ!O28-1,"") | R36: =IFERROR(subQ!R28/subQ!Q28-1,"") | S36: =IFERROR(subQ!S28/subQ!R28-1,"") | T36: =IFERROR(subQ!T28/subQ!S28-1,"") | V36: =IFERROR(subQ!V28/subQ!T28-1,"") | W36: =IFERROR(subQ!W28/subQ!V28-1,"") | X36: =IFERROR(subQ!X28/subQ!W28-1,"") | Y36: =IFERROR(subQ!Y28/subQ!X28-1,"") | AA36: =IFERROR(subQ!AA28/subQ!Y28-1,"") | AB36: =IFERROR(subQ!AB28/subQ!AA28-1,"") | AC36: 0 | AD36: 0 | AF36: 0 | AG36: 0 | AH36: 0 | AI36: 0 | AK36: 0 | AL36: 0 | AM36: 0 | AN36: 0
A37: drv:DPS | B37: abs | C37: DPS (가정, 원) | E37: =subQ!E31 | F37: =subQ!F31 | G37: =subQ!G31 | H37: =subQ!H31 | I37: =subQ!I31 | J37: =subQ!J31 | K37: =subQ!K31 | L37: =subQ!L31 | ... AB37: =subQ!AB31 | AD37: 200 | AE37: =subQ!AE31 | AI37: 200 | AJ37: =subQ!AJ31 | AN37: 200 | AO37: =subQ!AO31
B39: 3. 밸류에이션·스칼라 | C39: 노란 셀 = 가정. '연결' 표시는 추정 전 분기 수식이 이 셀을 참조한다는 뜻
A40: sc:종가 | C40: 종가 | D40: 63800 | E40: 원 — 네이버 정규장 종가(aik 확정종가 대조 · aik 68,500원)
A41: sc:기준일 | C41: 기준일 | D41: 20261008 | E41: 종가 기준일
A42: sc:COE | C42: COE | D42: 0.09 | E42: 자기자본비용(가정) — TP 적정 PBR = ROE/COE
...

Sheet BS연결
B1: (백만원) | C1: 이름: BS연결H | E1: 4Q21 | F1: 2021 | G1: 1Q22 | H1: 2Q22 | I1: 3Q22 | J1: 4Q22 | K1: 2022 | L1: 1Q23 | M1: 2Q23 | N1: 3Q23 | O1: 4Q23 | P1: 2023 | Q1: 1Q24 | R1: 2Q24 | S1: 3Q24 | T1: 4Q24 | U1: 2024 | V1: 1Q25 | W1: 2Q25 | X1: 3Q25 | Y1: 4Q25 | Z1: 2025 | AA1: 1Q26 | AB1: 2Q26 | AC1: 3Q26 | AD1: 4Q26 | AE1: 2026 | AF1: 1Q27 | AG1: 2Q27 | AH1: 3Q27 | AI1: 4Q27 | AJ1: 2027 | AK1: 1Q28 | AL1: 2Q28 | AM1: 3Q28 | AN1: 4Q28 | AO1: 2028
B2: 연결 | D2: fin json(kship_fin.py)
B3: 인텔리안테크(연) | C3: UPDATE: 26-10-11 | E3: 1 | F3: 2 | G3: 3 | H3: 4 | I3: 5 | J3: 6 | K3: 7 | L3: 8 | M3: 9 | N3: 10 | O3: 11 | P3: 12 | Q3: 13 | R3: 14 | S3: 15 | T3: 16 | U3: 17 | V3: 18 | W3: 19 | X3: 20 | Y3: 21 | Z3: 22 | AA3: 23 | AB3: 24 | AC3: 25 | AD3: 26 | AE3: 27 | AF3: 28 | AG3: 29 | AH3: 30 | AI3: 31 | AJ3: 32 | AK3: 33 | AL3: 34 | AM3: 35 | AN3: 36 | AO3: 37
B4: Account Code | C4: AccountNAME | E4: 2021.12 | F4: 2021.12A | G4: 2022.03 | H4: 2022.06 | I4: 2022.09 | J4: 2022.12 | K4: 2022.12A | L4: 2023.03 | M4: 2023.06 | N4: 2023.09 | O4: 2023.12 | P4: 2023.12A | Q4: 2024.03 | R4: 2024.06 | S4: 2024.09 | T4: 2024.12 | U4: 2024.12A | V4: 2025.03 | W4: 2025.06 | X4: 2025.09 | Y4: 2025.12 | Z4: 2025.12A | AA4: 2026.03 | AB4: 2026.06 | AC4: 2026.09 | AD4: 2026.12 | AE4: 2026.12A | AF4: 2027.03 | AG4: 2027.06 | AH4: 2027.09 | AI4: 2027.12 | AJ4: 2027.12A | AK4: 2028.03 | AL4: 2028.06 | AM4: 2028.09 | AN4: 2028.12 | AO4: 2028.12A
A5: 1 | C5: 유동자산 | E5: 155257 | F5: 155257 | G5: 168420.72 | H5: 175170.56 | I5: 202264.03 | J5: 214268.22 | K5: 214268.22 | L5: 213169.3 | M5: 221710.78 | N5: 291151.19 | O5: 283330.11 | P5: 283330.11 | Q5: 254872.26 | R5: 280715.87 | S5: 249812.87 | T5: 225272.82 | U5: 225272.82 | V5: 217246.58 | W5: 237396.12 | X5: 260203.49 | Y5: 276818.59 | Z5: 276818.59 | AA5: 271015.01 | AB5: 291867.65
A6: 1 | C6: 현금및현금성자산 | E6: 22538.5 | F6: 22538.5 | G6: 20133.03 | H6: 19262 | I6: 26906.15 | J6: 24414.57 | K6: 24414.57 | L6: 17940.93 | M6: 26838.97 | N6: 47860.78 | O6: 55948.74 | P6: 55948.74 | Q6: 39907.26 | R6: 30670.91 | S6: 26478.87 | T6: 21486.67 | U6: 21486.67 | V6: 24147.18 | W6: 17215.97 | X6: 23519.4 | Y6: 32845.85 | Z6: 32845.85 | AA6: 31798.82 | AB6: 25099.37
A7: 1 | C7: 단기금융상품 | E7: 35344.38 | F7: 35344.38 | G7: 31965.52 | H7: 19001.27 | I7: 18704.43 | J7: 5896.06 | K7: 5896.06 | M7: 10834.26 | N7: 65030.04 | O7: 66353.66 | P7: 66353.66 | Q7: 78172.43 | R7: 75138.84 | S7: 42642.71 | T7: 37682.92 | U7: 37682.92 | V7: 42166.67 | W7: 15049.2 | X7: 7558.8 | Y7: 500 | Z7: 500 | AA7: 0 | AB7: 598.95
A8: 1 | C8: 단기금융자산 | E8: 35346.69 | F8: 35346.69 | G8: 31965.52 | H8: 19001.27 | I8: 18704.43 | J8: 5896.06 | K8: 5896.06 | M8: 10834.26 | N8: 65030.04 | O8: 66353.66 | P8: 66353.66 | Q8: 78172.43 | R8: 75138.84 | S8: 42642.71 | T8: 37682.92 | U8: 37682.92 | V8: 42166.67 | W8: 15049.2 | X8: 7558.8 | Y8: 500 | Z8: 500 | AA8: 0 | AB8: 598.95
A9: 1 | C9: 매출채권및기타채권 | E9: 43622.87 | F9: 43622.87 | G9: 49846.19 | H9: 52682.95 | I9: 55441.44 | J9: 63639.26 | K9: 63639.26 | L9: 62842.46 | M9: 69482.24 | N9: 66971.91 | O9: 68761.04 | P9: 68761.04 | Q9: 41545.82 | R9: 67405.78 | S9: 61597.96 | T9: 70798.5 | U9: 70798.5 | V9: 49518.75 | W9: 87994.45 | X9: 96730.02 | Y9: 130468.5 | Z9: 130468.5 | AA9: 107536.57 | AB9: 121805.82
A10: 1 | C10: 계약자산 | E10: 77.05 | F10: 77.05 | G10: 116 | H10: 255.99 | I10: 63.42 | J10: 53.4 | K10: 53.4 | L10: 53.4 | Q10: 852.66 | R10: 512.5 | S10: 1274.68
A11: 1 | C11: 유동파생상품자산 | E11: 2.31 | F11: 2.31
A12: 1 | C12: 기타유동자산 | E12: 6434.53 | F12: 6434.53 | G12: 8680.7 | H12: 11014.57 | I12: 11698.09 | J12: 12851.93 | K12: 12851.93 | L12: 13219.99 | M12: 8941.03 | N12: 9241.59 | O12: 9213.85 | P12: 9213.85 | Q12: 8942.13 | R12: 10378.18 | S12: 11577.38 | T12: 6249.1 | U12: 6249.1 | V12: 5304.76 | W12: 6912.37 | X12: 8380.74 | Y12: 11228.48 | Z12: 11228.48 | AA12: 8180.87 | AB12: 9070.62
A13: 1 | C13: 재고자산 | E13: 47140.58 | F13: 47140.58 | G13: 57587.93 | H13: 72870.71 | I13: 88621.32 | J13: 107271.58 | K13: 107271.58 | L13: 118939.89 | M13: 105222.95 | N13: 101641.63 | O13: 82665.42 | P13: 82665.42 | Q13: 84393.99 | R13: 95594.85 | S13: 105177.88 | T13: 87223.09 | U13: 87223.09 | V13: 94913.21 | W13: 108221.33 | X13: 122010.21 | Y13: 100736.64 | Z13: 100736.64 | AA13: 122444.42 | AB13: 134194.48
A14: 1 | C14: 비유동자산 | E14: 106217.93 | F14: 106217.93 | G14: 115824.85 | H14: 127212.67 | I14: 137975.68 | J14: 156108.92 | K14: 156108.92 | L14: 166958.29 | M14: 168902.49 | N14: 168903.97 | O14: 170359.06 | P14: 170359.06 | Q14: 188206.15 | R14: 200516.13 | S14: 204974.79 | T14: 215420.25 | U14: 215420.25 | V14: 212230.22 | W14: 222176.49 | X14: 223884.44 | Y14: 219639.58 | Z14: 219639.58 | AA14: 247014.59 | AB14: 250469.61
A15: 1 | C15: 장기금융자산 | E15: 9092.16 | F15: 9092.16 | G15: 10625.57 | H15: 14862.05 | I15: 14283.48 | J15: 18454.42 | K15: 18454.42 | L15: 17258.75 | M15: 17431.76 | N15: 16953.26 | O15: 15114.96 | P15: 15114.96 | Q15: 22661.82 | R15: 29292.55 | S15: 36585.35 | T15: 48740.17 | U15: 48740.17 | V15: 48628.62 | W15: 60145.56 | X15: 51312.22 | Y15: 47752.82 | Z15: 47752.82 | AA15: 56186.96 | AB15: 52741.9
A16: 1 | C16: 투자자산 | E16: 9092.16 | F16: 9092.16 | G16: 10625.57 | H16: 14862.05 | I16: 14283.48 | J16: 18454.42 | K16: 18454.42 | L16: 17258.75 | M16: 17431.76 | N16: 16953.26 | O16: 15114.96 | P16: 15114.96 | Q16: 22661.82 | R16: 29292.55 | S16: 36585.35 | T16: 48740.17 | U16: 48740.17 | V16: 48628.62 | W16: 60145.56 | X16: 51312.22 | Y16: 47752.82 | Z16: 47752.82 | AA16: 56186.96 | AB16: 52741.9
A17: 1 | C17: 장기매출채권및기타채권 | E17: 3487.81 | F17: 3487.81 | G17: 3160.29 | H17: 2854.93 | I17: 1042.34 | J17: 879.63 | K17: 879.63 | L17: 292.79 | M17: 410.51 | N17: 462.23 | O17: 472.78 | P17: 472.78 | Q17: 712.46 | R17: 832.48 | S17: 910.33 | T17: 722.84 | U17: 722.84 | V17: 786.11 | W17: 804.03 | X17: 1125.12 | Y17: 1001.79 | Z17: 1001.79 | AA17: 989.17 | AB17: 1002.48
A18: 1 | C18: 유형자산 | E18: 64589.43 | F18: 64589.43 | G18: 72341.91 | H18: 78786.34 | I18: 89604.02 | J18: 101649.21 | K18: 101649.21 | L18: 112261.6 | M18: 114673.48 | N18: 114069.75 | O18: 113528.17 | P18: 113528.17 | Q18: 119540.01 | R18: 118510.17 | S18: 114522.89 | T18: 114876.85 | U18: 114876.85 | V18: 111788.47 | W18: 106983.11 | X18: 113538.66 | Y18: 109056.67 | Z18: 109056.67 | AA18: 127286.17 | AB18: 124727.98
A19: 1 | C19: 무형자산 | E19: 17017.54 | F19: 17017.54 | G19: 16960.74 | H19: 17614.25 | I19: 18593.49 | J19: 19660.05 | K19: 19660.05 | L19: 20139.7 | M19: 19288.39 | N19: 22390.12 | O19: 26961.02 | P19: 26961.02 | Q19: 32499.63 | R19: 38655.66 | S19: 39795.79 | T19: 38179.61 | U19: 38179.61 | V19: 37999.2 | W19: 41117.41 | X19: 44024.37 | Y19: 44437.64 | Z19: 44437.64 | AA19: 45627.89 | AB19: 44145.02
A20: 1 | C20: 기타비유동자산 | E20: 1139.5 | F20: 1139.5 | G20: 1355.83 | H20: 1675.43 | I20: 1331.97 | J20: 2426.34 | K20: 2426.34 | L20: 2451.26 | M20: 2510.77 | N20: 2506.14 | O20: 2528.6 | P20: 2528.6 | Q20: 1938.73 | R20: 2052.39 | S20: 1993.62 | T20: 1329.62 | U20: 1329.62 | V20: 1454 | W20: 1328.17 | X20: 1653.24 | Y20: 2922.12 | Z20: 2922.12 | AA20: 2681.92 | AB20: 5790.29
A21: 1 | C21: 이연법인세자산 | E21: 10480.94 | F21: 10480.94 | G21: 10448.36 | H21: 11265.24 | I21: 12187.93 | J21: 11562.58 | K21: 11562.58 | L21: 11099.64 | M21: 10855.35 | N21: 11461.42 | O21: 10952.81 | P21: 10952.81 | Q21: 10853.51 | R21: 11172.87 | S21: 11166.82 | T21: 11571.16 | U21: 11571.16 | V21: 11573.83 | W21: 11798.21 | X21: 12230.82 | Y21: 14468.54 | Z21: 14468.54 | AA21: 14242.48 | AB21: 14284.12
A22: 1 | C22: 자산총계 | E22: 261474.93 | F22: 261474.93 | G22: 284245.57 | H22: 302383.23 | I22: 340239.7 | J22: 370377.14 | K22: 370377.14 | L22: 380127.59 | M22: 390613.27 | N22: 460055.16 | O22: 453689.17 | P22: 453689.17 | Q22: 443078.41 | R22: 481232 | S22: 454787.67 | T22: 440693.07 | U22: 440693.07 | V22: 429476.8 | W22: 459572.61 | X22: 484087.93 | Y22: 496458.17 | Z22: 496458.17 | AA22: 518029.61 | AB22: 542337.27
A23: 1 | C23: 유동부채 | E23: 67404.79 | F23: 67404.79 | G23: 81496.98 | H23: 87762.13 | I23: 109097.67 | J23: 134703.61 | K23: 134703.61 | L23: 128826.8 | M23: 126075.02 | N23: 106247.36 | O23: 101749.21 | P23: 101749.21 | Q23: 93190.43 | R23: 125653.1 | S23: 114721.34 | T23: 91670.41 | U23: 91670.41 | V23: 107974.97 | W23: 145073.28 | X23: 140794.63 | Y23: 147623.21 | Z23: 147623.21 | AA23: 150049.12 | AB23: 169769.49
... A41: 1 | C41: 이익잉여금 | E41: 41398.63 | F41: 41398.63 | G41: 43405.14 | H41: 50191.95 | I41: 56856.67 | J41: 56692.74 | K41: 56692.74 | L41: 56803.97 | M41: 62689.89 | N41: 63209.83 | O41: 61271.07 | P41: 61271.07 | Q41: 55348.37 | R41: 56221.94 | S41: 44103.47 | T41: 55195.96 | U41: 55195.96 | V41: 40025.76 | W41: 35957.94 | X41: 39316.75 | Y41: 62997.43 | Z41: 62997.43 | AA41: 74429 | AB41: 79174.48
A42: 1 | C42: 자본총계 | E42: 161998.34 | F42: 161998.34 | G42: 164374.03 | H42: 172083.95 | I42: 179878.56 | J42: 178704.3 | K42: 178704.3 | L42: 179291.98 | M42: 185897.16 | N42: 276656.86 | O42: 275032.31 | P42: 275032.31 | Q42: 267136.64 | R42: 267360.8 | S42: 254069.81 | T42: 264642.29 | U42: 264642.29 | V42: 248538.99 | W42: 243443.25 | X42: 247072.29 | Y42: 266272.02 | Z42: 266272.02 | AA42: 279643.6
A43: 1 | C43: 부채와자본총계 | E43: 261474.93 | F43: 261474.93 | G43: 284245.57 | H43: 302383.23 | I43: 340239.7 | J43: 370377.14 | K43: 370377.14 | L43: 380127.59 | M43: 390613.27 | N43: 460055.16 | O43: 453689.17 | P43: 453689.17 | Q43: 443078.41 | R43: 481232 | S43: 454787.67 | T43: 440693.07 | U43: 440693.07 | V43: 429476.8 | W43: 459572.61 | X43: 484087.93 | Y43: 496458.17 | Z43: 496458.17 | AA43: 518029.61 | AB43: 542337.27
A44: 1 | C44: 총차입금 | E44: 46941.27 | F44: 46941.27 | G44: 62110.6 | H44: 63084.33 | I44: 84436.03 | J44: 105897.02 | K44: 105897.02 | L44: 118339.99 | M44: 139019.94 | N44: 113107.43 | O44: 109602.76 | P44: 109602.76 | Q44: 108765.16 | R44: 117473.78 | S44: 114225.23 | T44: 108055.68 | U44: 108055.68 | V44: 107397.5 | W44: 125874.97 | X44: 141235.44 | Y44: 136340.8 | Z44: 136340.8 | AA44: 132735.99 | AB44: 143504.55
A45: 1 | C45: 순차입금 | E45: -10943.92 | F45: -10943.92 | G45: 10012.05 | H45: 24821.06 | I45: 38825.45 | J45: 75586.39 | K45: 75586.39 | L45: 100399.06 | M45: 101346.71 | N45: 216.61 | O45: -12699.64 | P45: -12699.64 | Q45: -9314.53 | R45: 11664.03 | S45: 45103.65 | T45: 48886.09 | U45: 48886.09 | V45: 41083.65 | W45: 93609.8 | X45: 110157.24 | Y45: 102994.95 | Z45: 102994.95 | AA45: 100937.17 | AB45: 117806.23
A46: 1 | C46: 이자발생자산 | E46: 66977.35 | F46: 66977.35 | G46: 62724.12 | H46: 53125.32 | I46: 59894.06 | J46: 48765.05 | K46: 48765.05 | L46: 35199.68 | M46: 55104.99 | N46: 129844.08 | O46: 137417.36 | P46: 137417.36 | Q46: 140741.51 | R46: 135102.3 | S46: 105706.93 | T46: 107909.76 | U46: 107909.76 | V46: 114942.47 | W46: 92410.73 | X46: 82390.42 | Y46: 81098.67 | Z46: 81098.67 | AA46: 87985.78 | AB46: 78440.22
A47: 1 | C47: 단기파생상품부채 | G47: 199.85 | H47: 2126.26 | I47: 4487.19 | J47: 746.68 | K47: 746.68
A48: 1 | C48: 단기금융부채 | G48: 199.85 | H48: 2126.26 | I48: 4487.19 | J48: 746.68 | K48: 746.68
A49: 1 | C49: 비지배주주지분 | L49: 0 | X49: 0 | Y49: 0 | Z49: 0 | AA49: 0 | AB49: 0
A50: 1 | C50: 기타비유동부채 | O50: 299.6 | P50: 299.6
A51: 1 | C51: 이연법인세부채 | Q51: 312.94 | R51: 322.79 | S51: 306.62 | T51: 383.94 | U51: 383.94 | V51: 383.03 | W51: 354.27 | X51: 366.24 | Y51: 202.19 | Z51: 202.19 | AA51: 211.51 | AB51: 215.97
A52: 1 | C52: 장기금융부채(face) | S52: 52991.19 | T52: 54051.68 | U52: 54051.68 | V52: 43122.7 | X52: 67212.37
A53: 1 | C53: 당기법인세자산(선급법인세) | W53: 808.68 | X53: 868.48 | Y53: 706.61 | Z53: 706.61 | AA53: 802.34 | AB53: 791.18
A54: 1 | C54: 당기법인세부채(미지급법인세) | W54: 62.59 | X54: 64.07 | Y54: 2419.15 | Z54: 2419.15 | AA54: 1510.68 | AB54: 1198.35
A55: 1 | C55: 사채 | Y55: 20000 | Z55: 20000 | AA55: 20000 | AB55: 20000
A56: 1 | C56: 투자부동산 | AB56: 7777.84
A57: 1 | C57: 매출액(수익) | E57: 48293.36 | G57: 43025.3 | H57: 56984.24 | I57: 57036.79 | J57: 82419.02 | K57: 239465.35 | L57: 64393.46 | M57: 87594.79 | N57: 66774.94 | O57: 86279.65 | P57: 305042.84 | Q57: 46697.93 | R57: 71699.4 | S57: 62360.86 | T57: 77011.25 | U57: 257769.44 | V57: 43350.44 | W57: 74736 | X57: 77226.48 | Y57: 124315.42 | Z57: 319628.34 | AA57: 64723.57 | AB57: 97246.18
...

Sheet BS별도
B1: (백만원) | C1: 이름: BS별도H | E1: 4Q21 | F1: 2021 | G1: 1Q22 | H1: 2Q22 | I1: 3Q22 | J1: 4Q22 | K1: 2022 | L1: 1Q23 | M1: 2Q23 | N1: 3Q23 | O1: 4Q23 | P1: 2023 | Q1: 1Q24 | R1: 2Q24 | S1: 3Q24 | T1: 4Q24 | U1: 2024 | V1: 1Q25 | W1: 2Q25 | X1: 3Q25 | Y1: 4Q25 | Z1: 2025 | AA1: 1Q26 | AB1: 2Q26 | AC1: 3Q26 | AD1: 4Q26 | AE1: 2026 | AF1: 1Q27 | AG1: 2Q27 | AH1: 3Q27 | AI1: 4Q27 | AJ1: 2027 | AK1: 1Q28 | AL1: 2Q28 | AM1: 3Q28 | AN1: 4Q28 | AO1: 2028
B2: 별도 | D2: fin json(kship_fin.py)
B3: 인텔리안테크(별) | C3: UPDATE: 26-10-11 | E3: 1 | F3: 2 | G3: 3 | H3: 4 | I3: 5 | J3: 6 | K3: 7 | L3: 8 | M3: 9 | N3: 10 | O3: 11 | P3: 12 | Q3: 13 | R3: 14 | S3: 15 | T3: 16 | U3: 17 | V3: 18 | W3: 19 | X3: 20 | Y3: 21 | Z3: 22 | AA3: 23 | AB3: 24 | AC3: 25 | AD3: 26 | AE3: 27 | AF3: 28 | AG3: 29 | AH3: 30 | AI3: 31 | AJ3: 32 | AK3: 33 | AL3: 34 | AM3: 35 | AN3: 36 | AO3: 37
B4: Account Code | C4: AccountNAME | E4: 2021.12 | F4: 2021.12A | G4: 2022.03 | H4: 2022.06 | I4: 2022.09 | J4: 2022.12 | K4: 2022.12A | L4: 2023.03 | M4: 2023.06 | N4: 2023.09 | O4: 2023.12 | P4: 2023.12A | Q4: 2024.03 | R4: 2024.06 | S4: 2024.09 | T4: 2024.12 | U4: 2024.12A | V4: 2025.03 | W4: 2025.06 | X4: 2025.09 | Y4: 2025.12 | Z4: 2025.12A | AA4: 2026.03 | AB4: 2026.06 | AC4: 2026.09 | AD4: 2026.12 | AE4: 2026.12A | AF4: 2027.03 | AG4: 2027.06 | AH4: 2027.09 | AI4: 2027.12 | AJ4: 2027.12A | AK4: 2028.03 | AL4: 2028.06 | AM4: 2028.09 | AN4: 2028.12 | AO4: 2028.12A
A5: 1 | C5: 유동자산 | E5: 150245.59 | F5: 150245.59 | G5: 161544.35 | H5: 166391.98 | I5: 189426.26 | J5: 213759.26 | K5: 213759.26 | L5: 209663.09 | M5: 212953.11 | N5: 284836.15 | O5: 282081.26 | P5: 282081.26 | Q5: 260391.19 | R5: 285531.4 | S5: 254468.96 | T5: 221626.85 | U5: 221626.85 | V5: 221161.82 | W5: 239697.61 | X5: 268514.69 | Y5: 280363.82 | Z5: 280363.82 | AA5: 265961.92 | AB5: 299508.88
A6: 1 | C6: 현금및현금성자산 | E6: 15272.86 | F6: 15272.86 | G6: 10716.67 | H6: 11220.52 | I6: 18082.28 | J6: 14470.34 | K6: 14470.34 | L6: 7943.73 | M6: 14470.35 | N6: 30099.79 | O6: 44532.01 | P6: 44532.01 | Q6: 21302.45 | R6: 17584.38 | S6: 12596.01 | T6: 9814.01 | U6: 9814.01 | V6: 9959.15 | W6: 5333.45 | X6: 9780.07 | Y6: 20151.37 | Z6: 20151.37 | AA6: 10562.46 | AB6: 14978.31
A7: 1 | C7: 단기금융상품 | E7: 35344.38 | F7: 35344.38 | G7: 31965.52 | H7: 19001.27 | I7: 18704.43 | J7: 5896.06 | K7: 5896.06 | M7: 10834.26 | N7: 65030.04 | O7: 66353.66 | P7: 66353.66 | Q7: 78172.43 | R7: 75138.84 | S7: 42642.71 | T7: 37682.92 | U7: 37682.92 | V7: 42166.67 | W7: 15049.2 | X7: 7558.8 | Y7: 500 | Z7: 500 | AA7: 0 | AB7: 0
A8: 1 | C8: 단기금융자산 | E8: 35346.69 | F8: 35346.69 | G8: 31965.52 | H8: 19001.27 | I8: 18704.43 | J8: 5896.06 | K8: 5896.06 | M8: 10834.26 | N8: 65030.04 | O8: 66353.66 | P8: 66353.66 | Q8: 78172.43 | R8: 75138.84 | S8: 42642.71 | T8: 37682.92 | U8: 37682.92 | V8: 42166.67 | W8: 15049.2 | X8: 7558.8 | Y8: 500 | Z8: 500 | AA8: 0 | AB8: 0
A9: 1 | C9: 매출채권및기타채권 | E9: 58629.42 | F9: 58629.42 | G9: 67543.39 | H9: 67396.85 | I9: 72297.52 | J9: 96690.69 | K9: 96690.69 | L9: 94392.19 | M9: 92223.7 | N9: 102397.4 | O9: 99788.66 | P9: 99788.66 | Q9: 83787.33 | R9: 103559.32 | S9: 99077.8 | T9: 95504.7 | U9: 95504.7 | V9: 82785.76 | W9: 121787.93 | X9: 147368.75 | Y9: 174031.03 | Z9: 174031.03 | AA9: 148460.54 | AB9: 163858.65
A10: 1 | C10: 계약자산 | E10: 77.05 | F10: 77.05 | G10: 116 | H10: 255.99 | I10: 63.42 | J10: 53.4 | K10: 53.4 | L10: 53.4 | Q10: 852.66 | R10: 512.5 | S10: 1274.68
A11: 1 | C11: 유동파생상품자산 | E11: 2.31 | F11: 2.31
A12: 1 | C12: 기타유동자산 | E12: 5359.41 | F12: 5359.41 | G12: 6282.55 | H12: 9133.24 | I12: 9118.48 | J12: 9646.44 | K12: 9646.44 | L12: 8872.05 | M12: 9023.4 | N12: 6006.97 | O12: 5991.66 | P12: 5991.66 | Q12: 7143.94 | R12: 8704.4 | S12: 9430.28 | T12: 4155.7 | U12: 4155.7 | V12: 4441.33 | W12: 6691.89 | X12: 4350.94 | Y12: 5081.45 | Z12: 5081.45 | AA12: 5040.88 | AB12: 6782.69
A13: 1 | C13: 재고자산 | E13: 35477.19 | F13: 35477.19 | G13: 44839.1 | H13: 59313.54 | I13: 70342.94 | J13: 86864.33 | K13: 86864.33 | L13: 98229.64 | M13: 86010.53 | N13: 80897.29 | O13: 65039.12 | P13: 65039.12 | Q13: 68092.39 | R13: 79029.13 | S13: 88391.27 | T13: 72645.21 | U13: 72645.21 | V13: 80629.35 | W13: 89556.98 | X13: 98201.03 | Y13: 80279.35 | Z13: 80279.35 | AA13: 101633.07 | AB13: 113594.78
A14: 1 | C14: 비유동자산 | E14: 90035.22 | F14: 90035.22 | G14: 101409.96 | H14: 110966.4 | I14: 122547.94 | J14: 136519.24 | K14: 136519.24 | L14: 143995.92 | M14: 143785.4 | N14: 141514.41 | O14: 141281.09 | P14: 141281.09 | Q14: 152728.02 | R14: 164781.78 | S14: 171632.46 | T14: 187019.75 | U14: 187019.75 | V14: 181252.8 | W14: 196044.62 | X14: 194297.69 | Y14: 195975.13 | Z14: 195975.13 | AA14: 206407.32 | AB14: 208009.67
A15: 1 | C15: 종속기업및관계기업투자 | E15: 644.96 | F15: 644.96 | G15: 4071.89 | H15: 3691.01 | I15: 7213.38 | J15: 1750.75 | K15: 1750.75 | L15: 7898.08 | M15: 8034.04 | N15: 7371.56 | O15: 4607.85 | P15: 4607.85 | Q15: 3576.9 | R15: 2954.02 | S15: 2483.63 | T15: 9635.4 | U15: 9635.4 | V15: 5396.83 | W15: 6438.41 | X15: 3506.26 | Y15: 9383.83 | Z15: 9383.83 | AA15: 9678.59 | AB15: 14138.94
A16: 1 | C16: 투자자산 | E16: 9737.12 | F16: 9737.12 | G16: 14697.46 | H16: 18553.06 | I16: 21496.86 | J16: 20205.17 | K16: 20205.17 | L16: 25156.83 | M16: 25465.8 | N16: 24324.82 | O16: 19722.81 | P16: 19722.81 | Q16: 26238.72 | R16: 32246.57 | S16: 39068.98 | T16: 58375.57 | U16: 58375.57 | V16: 54025.45 | W16: 66583.97 | X16: 54818.48 | Y16: 57136.65 | Z16: 57136.65 | AA16: 65865.55 | AB16: 66880.84
A17: 1 | C17: 장기금융자산 | E17: 9092.16 | F17: 9092.16 | G17: 10625.57 | H17: 14862.05 | I17: 14283.48 | J17: 18454.42 | K17: 18454.42 | L17: 17258.75 | M17: 17431.76 | N17: 16953.26 | O17: 15114.96 | P17: 15114.96 | Q17: 22661.82 | R17: 29292.55 | S17: 36585.35 | T17: 48740.17 | U17: 48740.17 | V17: 48628.62 | W17: 60145.56 | X17: 51312.22 | Y17: 47752.82 | Z17: 47752.82 | AA17: 56186.96 | AB17: 52741.9
A18: 1 | C18: 장기매출채권및기타채권 | E18: 2813.44 | F18: 2813.44 | G18: 2589.47 | H18: 2406.76 | I18: 757.67 | J18: 697.89 | K18: 697.89 | L18: 338.27 | M18: 453.92 | N18: 503.23 | O18: 513.93 | P18: 513.93 | Q18: 746.04 | R18: 862.96 | S18: 938.56 | T18: 745.25 | U18: 745.25 | V18: 809.92 | W18: 824.28 | X18: 1142.59 | Y18: 1016.48 | Z18: 1016.48 | AA18: 999.86 | AB18: 1010.97
A19: 1 | C19: 유형자산 | E19: 50821.23 | F19: 50821.23 | G19: 57055.71 | H19: 62750.31 | I19: 72327.9 | J19: 84490.36 | K19: 84490.36 | L19: 84950.66 | M19: 85083.37 | N19: 83468.46 | O19: 83086.51 | P19: 83086.51 | Q19: 83654.86 | R19: 82816.54 | S19: 81590.77 | T19: 80123.4 | U19: 80123.4 | V19: 78672.11 | W19: 77672.06 | X19: 84669.34 | Y19: 80859.6 | Z19: 80859.6 | AA19: 81601.12 | AB19: 72784.95
A20: 1 | C20: 무형자산 | E20: 16999.84 | F20: 16999.84 | G20: 16820.25 | H20: 17377.53 | I20: 18018.77 | J20: 19140.5 | K20: 19140.5 | L20: 19530.63 | M20: 18567.78 | N20: 21660.58 | O20: 26302.72 | P20: 26302.72 | Q20: 31859.11 | R20: 38042.85 | S20: 39256.03 | T20: 37603.34 | U20: 37603.34 | V20: 37445.23 | W20: 40650.73 | X20: 43286.79 | Y20: 43752.24 | Z20: 43752.24 | AA20: 44979.52 | AB20: 43558.83
A21: 1 | C21: 기타비유동자산 | E21: 782.99 | F21: 782.99 | G21: 844.85 | H21: 925.95 | I21: 215.91 | J21: 1322.55 | K21: 1322.55 | L21: 1378.89 | M21: 1376.53 | N21: 1390.5 | O21: 1434.53 | P21: 1434.53 | Q21: 809.41 | R21: 870.65 | S21: 835.91 | T21: 77.17 | U21: 77.17 | V21: 205.05 | W21: 210.11 | X21: 277.02 | Y21: 1410.4 | Z21: 1410.4 | AA21: 1161.53 | AB21: 4196.51
A22: 1 | C22: 이연법인세자산 | E22: 8470.06 | F22: 8470.06 | G22: 8470.06 | H22: 8798.37 | I22: 8798.37 | J22: 9186.08 | K22: 9186.08 | L22: 9186.08 | M22: 9105.77 | N22: 9105.77 | O22: 9419.88 | P22: 9419.88 | Q22: 9419.88 | R22: 9942.21 | S22: 9942.21 | T22: 10095.04 | U22: 10095.04 | V22: 10095.04 | W22: 10103.47 | X22: 10103.47 | Y22: 11799.74 | Z22: 11799.74 | AA22: 11799.74 | AB22: 11799.74
A23: 1 | C23: 자산총계 | E23: 240280.81 | F23: 240280.81 | G23: 262954.31 | H23: 277358.39 | I23: 311974.2 | J23: 350278.5 | K23: 350278.5 | L23: 353659.01 | M23: 356738.51 | N23: 426350.56 | O23: 423362.35 | P23: 423362.35 | Q23: 413119.2 | R23: 450313.18 | S23: 426101.42 | T23: 408646.6 | U23: 408646.6 | V23: 402414.62 | W23: 435742.23 | X23: 462812.38 | Y23: 476338.95 | Z23: 476338.95 | AA23: 472369.24 | AB23: 507518.55
... A41: 1 | C41: 이익잉여금 | E41: 39151.77 | F41: 39151.77 | G41: 39307.42 | H41: 45687.72 | I41: 49995.47 | J41: 51728.33 | K41: 51728.33 | L41: 50275.17 | M41: 55670.62 | N41: 53722.53 | O41: 54651.74 | P41: 54651.74 | Q41: 52479.02 | R41: 50075.91 | S41: 41122.44 | T41: 48714.55 | U41: 48714.55 | V41: 36657.83 | W41: 29022.13 | X41: 35890.85 | Y41: 57069.34 | Z41: 57069.34 | AA41: 68859.16 | AB41: 70973.15
A42: 1 | C42: 자본총계 | E42: 160801.77 | F42: 160801.77 | G42: 161884.44 | H42: 169290.85 | I42: 175442.39 | J42: 174774.87 | K42: 174774.87 | L42: 174858.81 | M42: 180860.57 | N42: 269276.22 | O42: 270184.59 | P42: 270184.59 | Q42: 266173.42 | R42: 263260.34 | S42: 252839.06 | T42: 260456.55 | U42: 260456.55 | V42: 246944.26 | W42: 237568.37 | X42: 245996.6 | Y42: 262061.29 | Z42: 262061.29 | AA42: 276018.61
A43: 1 | C43: 부채와자본총계 | E43: 240280.81 | F43: 240280.81 | G43: 262954.31 | H43: 277358.39 | I43: 311974.2 | J43: 350278.5 | K43: 350278.5 | L43: 353659.01 | M43: 356738.51 | N43: 426350.56 | O43: 423362.35 | P43: 423362.35 | Q43: 413119.2 | R43: 450313.18 | S43: 426101.42 | T43: 408646.6 | U43: 408646.6 | V43: 402414.62 | W43: 435742.23 | X43: 462812.38 | Y43: 476338.95 | Z43: 476338.95 | AA43: 472369.24 | AB43: 507518.55
A44: 1 | C44: 지배주주지분 | E44: 160801.77 | F44: 160801.77 | G44: 161884.44 | H44: 169290.85 | I44: 175442.39 | J44: 174774.87 | K44: 174774.87 | L44: 174858.81 | M44: 180860.57 | N44: 269276.22 | O44: 270184.59 | P44: 270184.59 | Q44: 266173.42 | R44: 263260.34 | S44: 252839.06 | T44: 260456.55 | U44: 260456.55 | V44: 246944.26 | W44: 237568.37 | X44: 245996.6 | Y44: 262061.29 | Z44: 262061.29 | AA44: 276018.61
A45: 1 | C45: 총차입금 | E45: 34720 | F45: 34720 | G45: 50625 | H45: 52760 | I45: 72435 | J45: 95763.05 | K45: 95763.05 | L45: 107678.49 | M45: 128321.28 | N45: 100640.57 | O45: 99331.29 | P45: 99331.29 | Q45: 98522.01 | R45: 107212.53 | S45: 104274.88 | T45: 97965.6 | U45: 97965.6 | V45: 97156.32 | W45: 115847.04 | X45: 131121.76 | Y45: 126226.48 | Z45: 126226.48 | AA45: 122596.2 | AB45: 133465.92
A46: 1 | C46: 순차입금 | E46: -15899.55 | F46: -15899.55 | G46: 7942.81 | H46: 22538.21 | I46: 35648.29 | J46: 75396.65 | K46: 75396.65 | L46: 99734.76 | M46: 103016.67 | N46: 5510.74 | O46: -11554.38 | P46: -11554.38 | Q46: -952.87 | R46: 14489.31 | S46: 49036.16 | T46: 50468.67 | U46: 50468.67 | V46: 45030.5 | W46: 95464.39 | X46: 113782.89 | Y46: 105575.11 | Z46: 105575.11 | AA46: 112033.74 | AB46: 118487.61
A47: 1 | C47: 이자발생자산 | E47: 59711.71 | F47: 59711.71 | G47: 53307.76 | H47: 45083.84 | I47: 51070.19 | J47: 38820.82 | K47: 38820.82 | L47: 25202.48 | M47: 42736.37 | N47: 112083.09 | O47: 126000.63 | P47: 126000.63 | Q47: 122136.7 | R47: 122015.77 | S47: 91824.07 | T47: 96237.1 | U47: 96237.1 | V47: 100754.44 | W47: 80528.21 | X47: 68651.09 | Y47: 68404.19 | Z47: 68404.19 | AA47: 66749.42 | AB47: 67720.21
A48: 1 | C48: 단기파생상품부채 | G48: 199.85 | H48: 2126.26 | I48: 4487.19 | J48: 746.68 | K48: 746.68
A49: 1 | C49: 단기금융부채 | G49: 199.85 | H49: 2126.26 | I49: 4487.19 | J49: 746.68 | K49: 746.68
A50: 1 | C50: 단기금융부채(face) | N50: 45200 | O50: 44200 | P50: 44200 | Q50: 43700 | R50: 52699.8 | S50: 50700 | T50: 43000 | U50: 43000 | V50: 43000
A51: 1 | C51: 장기금융부채(face) | S51: 50337.76 | T51: 51758.48 | U51: 51758.48 | V51: 40979.2
A52: 1 | C52: 당기법인세자산(선급법인세) | W52: 95.23 | X52: 130.91 | Y52: 0 | Z52: 0 | AA52: 25.58
A53: 1 | C53: 당기법인세부채(미지급법인세) | Y53: 1524.42 | Z53: 1524.42 | AA53: 1071.81 | AB53: 1578.9
A54: 1 | C54: 사채 | Y54: 20000 | Z54: 20000 | AA54: 20000 | AB54: 20000
A55: 1 | C55: 투자부동산 | AB55: 7777.84
A56: 1 | C56: 매출액(수익) | E56: 37973.82 | G56: 33141.38 | H56: 49450.78 | I56: 49183.97 | J56: 83818.2 | K56: 215594.33 | L56: 46976.74 | M56: 74811.04 | N56: 61103.01 | O56: 81708.21 | P56: 264599 | Q56: 38646.54 | R56: 57830.18 | S56: 58652.2 | T56: 57547.24 | U56: 212676.16 | V56: 37869.34 | W56: 65481.74 | X56: 78414.36 | Y56: 106044.48 | Z56: 287809.92 | AA56: 55718.72 | AB56: 80065.64
A57: 1 | C57: 매출원가 | E57: 25088.94 | G57: 24820.05 | H57: 32964.67 | I57: 36290.44 | J57: 47170.35 | K57: 141245.51 | L57: 39148.08 | M57: 47449.35 | N57: 43169.84 | O57: 50830.93 | P57: 180598.2 | Q57: 27498.2 | R57: 41377.63 | S57: 39931.54 | T57: 45288.86 | U57: 154096.23 | V57: 25957.65 | W57: 52657.16 | X57: 50662.63 | Y57: 71582.92 | Z57: 200860.36 | AA57: 33714 | AB57: 57762.25
...

Sheet subQ
A1: YQ | C1: subQ 분기 서브모델(억원, U=100) | E1: 4Q21 | F1: 2021 | G1: 1Q22 | H1: 2Q22 | I1: 3Q22 | J1: 4Q22 | K1: 2022 | L1: 1Q23 | M1: 2Q23 | N1: 3Q23 | O1: 4Q23 | P1: 2023 | Q1: 1Q24 | R1: 2Q24 | S1: 3Q24 | T1: 4Q24 | U1: 2024 | V1: 1Q25 | W1: 2Q25 | X1: 3Q25 | Y1: 4Q25 | Z1: 2025 | AA1: 1Q26 | AB1: 2Q26 | AC1: 3Q26 | AD1: 4Q26 | AE1: 2026 | AF1: 1Q27 | AG1: 2Q27 | AH1: 3Q27 | AI1: 4Q27 | AJ1: 2027 | AK1: 1Q28 | AL1: 2Q28 | AM1: 3Q28 | AN1: 4Q28 | AO1: 2028
A2: A=이름(key) B=그룹 C=단위 D=FnGuide 계정명(VLOOKUP 키). 확정=VLOOKUP(BS), 추정=변수 가정 참조
E3: 1 | F3: 2 | G3: 3 | H3: 4 | I3: 5 | J3: 6 | K3: 7 | L3: 8 | M3: 9 | N3: 10 | O3: 11 | P3: 12 | Q3: 13 | R3: 14 | S3: 15 | T3: 16 | U3: 17 | V3: 18 | W3: 19 | X3: 20 | Y3: 21 | Z3: 22 | AA3: 23 | AB3: 24 | AC3: 25 | AD3: 26 | AE3: 27 | AF3: 28 | AG3: 29 | AH3: 30 | AI3: 31 | AJ3: 32 | AK3: 33 | AL3: 34 | AM3: 35 | AN3: 36 | AO3: 37
E4: 2021.12 | F4: 2021.12A | G4: 2022.03 | H4: 2022.06 | I4: 2022.09 | J4: 2022.12 | K4: 2022.12A | L4: 2023.03 | M4: 2023.06 | N4: 2023.09 | O4: 2023.12 | P4: 2023.12A | Q4: 2024.03 | R4: 2024.06 | S4: 2024.09 | T4: 2024.12 | U4: 2024.12A | V4: 2025.03 | W4: 2025.06 | X4: 2025.09 | Y4: 2025.12 | Z4: 2025.12A | AA4: 2026.03 | AB4: 2026.06 | AC4: 2026.09 | AD4: 2026.12 | AE4: 2026.12A | AF4: 2027.03 | AG4: 2027.06 | AH4: 2027.09 | AI4: 2027.12 | AJ4: 2027.12A | AK4: 2028.03 | AL4: 2028.06 | AM4: 2028.09 | AN4: 2028.12 | AO4: 2028.12A
A5: 매출액 | B5: 손익 | C5: 억원 | D5: 매출액(수익) | E5: =IFERROR(VLOOKUP($D5,BS연결,MATCH(E$1,BS연결H,0),0)/100,"") | G5: =IFERROR(VLOOKUP($D5,BS연결,MATCH(G$1,BS연결H,0),0)/100,"") | H5: =IFERROR(VLOOKUP($D5,BS연결,MATCH(H$1,BS연결H,0),0)/100,"") | I5: =IFERROR(VLOOKUP($D5,BS연결,MATCH(I$1,BS연결H,0),0)/100,"") | J5: =IFERROR(VLOOKUP($D5,BS연결,MATCH(J$1,BS연결H,0),0)/100,"") | K5: =IFERROR(VLOOKUP($D5,BS연결,MATCH(K$1,BS연결H,0),0)/100,"") | L5: =IFERROR(VLOOKUP($D5,BS연결,MATCH(L$1,BS연결H,0),0)/100,"") | M5: =IFERROR(VLOOKUP($D5,BS연결,MATCH(M$1,BS연결H,0),0)/100,"") | N5: =IFERROR(VLOOKUP($D5,BS연결,MATCH(N$1,BS연결H,0),0)/100,"") | ... AB5: =IFERROR(VLOOKUP($D5,BS연결,MATCH(AB$1,BS연결H,0),0)/100,"") | AC5: =IFERROR(X5*(1+변수!AC21),"") | AD5: =IFERROR(Y5*(1+변수!AD21),"") | AE5: =SUM(AA5:AD5) | AF5: =IFERROR(AA5*(1+변수!AF21),"") | AG5: =IFERROR(AB5*(1+변수!AG21),"") | AH5: =IFERROR(AC5*(1+변수!AH21),"") | AI5: =IFERROR(AD5*(1+변수!AI21),"") | AJ5: =SUM(AF5:AI5) | AK5: =IFERROR(AF5*(1+변수!AK21),"") | AL5: =IFERROR(AG5*(1+변수!AL21),"") | AM5: =IFERROR(AH5*(1+변수!AM21),"") | AN5: =IFERROR(AI5*(1+변수!AN21),"") | AO5: =SUM(AK5:AN5)
A6: 매출원가 | B6: 손익 | C6: 억원 | D6: 매출원가 | E6: =IFERROR(VLOOKUP($D6,BS연결,MATCH(E$1,BS연결H,0),0)/100,"") | G6: =IFERROR(VLOOKUP($D6,BS연결,MATCH(G$1,BS연결H,0),0)/100,"") | H6: =IFERROR(VLOOKUP($D6,BS연결,MATCH(H$1,BS연결H,0),0)/100,"") | I6: =IFERROR(VLOOKUP($D6,BS연결,MATCH(I$1,BS연결H,0),0)/100,"") | J6: =IFERROR(VLOOKUP($D6,BS연결,MATCH(J$1,BS연결H,0),0)/100,"") | K6: =IFERROR(VLOOKUP($D6,BS연결,MATCH(K$1,BS연결H,0),0)/100,"") | L6: =IFERROR(VLOOKUP($D6,BS연결,MATCH(L$1,BS연결H,0),0)/100,"") | M6: =IFERROR(VLOOKUP($D6,BS연결,MATCH(M$1,BS연결H,0),0)/100,"") | N6: =IFERROR(VLOOKUP($D6,BS연결,MATCH(N$1,BS연결H,0),0)/100,"") | ... AB6: =IFERROR(VLOOKUP($D6,BS연결,MATCH(AB$1,BS연결H,0),0)/100,"") | AC6: =IFERROR(AC5-AC7,"") | AD6: =IFERROR(AD5-AD7,"") | AE6: =SUM(AA6:AD6) | AF6: =IFERROR(AF5-AF7,"") | AG6: =IFERROR(AG5-AG7,"") | AH6: =IFERROR(AH5-AH7,"") | AI6: =IFERROR(AI5-AI7,"") | AJ6: =SUM(AF6:AI6) | AK6: =IFERROR(AK5-AK7,"") | AL6: =IFERROR(AL5-AL7,"") | AM6: =IFERROR(AM5-AM7,"") | AN6: =IFERROR(AN5-AN7,"") | AO6: =SUM(AK6:AN6)
A7: 매출총이익 | B7: 손익 | C7: 억원 | D7: 매출총이익 | E7: =IFERROR(VLOOKUP($D7,BS연결,MATCH(E$1,BS연결H,0),0)/100,"") | G7: =IFERROR(VLOOKUP($D7,BS연결,MATCH(G$1,BS연결H,0),0)/100,"") | H7: =IFERROR(VLOOKUP($D7,BS연결,MATCH(H$1,BS연결H,0),0)/100,"") | I7: =IFERROR(VLOOKUP($D7,BS연결,MATCH(I$1,BS연결H,0),0)/100,"") | J7: =IFERROR(VLOOKUP($D7,BS연결,MATCH(J$1,BS연결H,0),0)/100,"") | K7: =IFERROR(VLOOKUP($D7,BS연결,MATCH(K$1,BS연결H,0),0)/100,"") | L7: =IFERROR(VLOOKUP($D7,BS연결,MATCH(L$1,BS연결H,0),0)/100,"") | M7: =IFERROR(VLOOKUP($D7,BS연결,MATCH(M$1,BS연결H,0),0)/100,"") | N7: =IFERROR(VLOOKUP($D7,BS연결,MATCH(N$1,BS연결H,0),0)/100,"") | ... AB7: =IFERROR(VLOOKUP($D7,BS연결,MATCH(AB$1,BS연결H,0),0)/100,"") | AC7: =IFERROR(AC9+AC8,"") | AD7: =IFERROR(AD9+AD8,"") | AE7: =SUM(AA7:AD7) | AF7: =IFERROR(AF9+AF8,"") | AG7: =IFERROR(AG9+AG8,"") | AH7: =IFERROR(AH9+AH8,"") | AI7: =IFERROR(AI9+AI8,"") | AJ7: =SUM(AF7:AI7) | AK7: =IFERROR(AK9+AK8,"") | AL7: =IFERROR(AL9+AL8,"") | AM7: =IFERROR(AM9+AM8,"") | AN7: =IFERROR(AN9+AN8,"") | AO7: =SUM(AK7:AN7)
A8: 판관비 | B8: 손익 | C8: 억원 | D8: 판관비 | E8: =IFERROR(VLOOKUP($D8,BS연결,MATCH(E$1,BS연결H,0),0)/100,"") | G8: =IFERROR(VLOOKUP($D8,BS연결,MATCH(G$1,BS연결H,0),0)/100,"") | H8: =IFERROR(VLOOKUP($D8,BS연결,MATCH(H$1,BS연결H,0),0)/100,"") | I8: =IFERROR(VLOOKUP($D8,BS연결,MATCH(I$1,BS연결H,0),0)/100,"") | J8: =IFERROR(VLOOKUP($D8,BS연결,MATCH(J$1,BS연결H,0),0)/100,"") | K8: =IFERROR(VLOOKUP($D8,BS연결,MATCH(K$1,BS연결H,0),0)/100,"") | L8: =IFERROR(VLOOKUP($D8,BS연결,MATCH(L$1,BS연결H,0),0)/100,"") | M8: =IFERROR(VLOOKUP($D8,BS연결,MATCH(M$1,BS연결H,0),0)/100,"") | N8: =IFERROR(VLOOKUP($D8,BS연결,MATCH(N$1,BS연결H,0),0)/100,"") | ... AB8: =IFERROR(VLOOKUP($D8,BS연결,MATCH(AB$1,BS연결H,0),0)/100,"") | AC8: =IFERROR(AC5*변수!AC22,"") | AD8: =IFERROR(AD5*변수!AD22,"") | AE8: =SUM(AA8:AD8) | AF8: =IFERROR(AF5*변수!AF22,"") | AG8: =IFERROR(AG5*변수!AG22,"") | AH8: =IFERROR(AH5*변수!AH22,"") | AI8: =IFERROR(AI5*변수!AI22,"") | AJ8: =SUM(AF8:AI8) | AK8: =IFERROR(AK5*변수!AK22,"") | AL8: =IFERROR(AL5*변수!AL22,"") | AM8: =IFERROR(AM5*변수!AM22,"") | AN8: =IFERROR(AN5*변수!AN22,"") | AO8: =SUM(AK8:AN8)
A9: 영업이익 | B9: 손익 | C9: 억원 | D9: 영업이익 | E9: =IFERROR(VLOOKUP($D9,BS연결,MATCH(E$1,BS연결H,0),0)/100,"") | G9: =IFERROR(VLOOKUP($D9,BS연결,MATCH(G$1,BS연결H,0),0)/100,"") | H9: =IFERROR(VLOOKUP($D9,BS연결,MATCH(H$1,BS연결H,0),0)/100,"") | I9: =IFERROR(VLOOKUP($D9,BS연결,MATCH(I$1,BS연결H,0),0)/100,"") | J9: =IFERROR(VLOOKUP($D9,BS연결,MATCH(J$1,BS연결H,0),0)/100,"") | K9: =IFERROR(VLOOKUP($D9,BS연결,MATCH(K$1,BS연결H,0),0)/100,"") | L9: =IFERROR(VLOOKUP($D9,BS연결,MATCH(L$1,BS연결H,0),0)/100,"") | M9: =IFERROR(VLOOKUP($D9,BS연결,MATCH(M$1,BS연결H,0),0)/100,"") | N9: =IFERROR(VLOOKUP($D9,BS연결,MATCH(N$1,BS연결H,0),0)/100,"") | ... AB9: =IFERROR(VLOOKUP($D9,BS연결,MATCH(AB$1,BS연결H,0),0)/100,"") | AC9: =IFERROR(AC5*변수!AC23,"") | AD9: =IFERROR(AD5*변수!AD23,"") | AE9: =SUM(AA9:AD9) | AF9: =IFERROR(AF5*변수!AF23,"") | AG9: =IFERROR(AG5*변수!AG23,"") | AH9: =IFERROR(AH5*변수!AH23,"") | AI9: =IFERROR(AI5*변수!AI23,"") | AJ9: =SUM(AF9:AI9) | AK9: =IFERROR(AK5*변수!AK23,"") | AL9: =IFERROR(AL5*변수!AL23,"") | AM9: =IFERROR(AM5*변수!AM23,"") | AN9: =IFERROR(AN5*변수!AN23,"") | AO9: =SUM(AK9:AN9)
A10: OPM | B10: 손익 | C10: % | D10: 영업이익률 | E10: =IFERROR(E9/E5,"") | G10: =IFERROR(G9/G5,"") | H10: =IFERROR(H9/H5,"") | I10: =IFERROR(I9/I5,"") | J10: =IFERROR(J9/J5,"") | K10: =IFERROR(K9/K5,"") | L10: =IFERROR(L9/L5,"") | M10: =IFERROR(M9/M5,"") | N10: =IFERROR(N9/N5,"") | ... AO10: =IFERROR(AO9/AO5,"")
A11: 금융손익 | B11: 손익 | C11: 억원 | D11: 금융손익 | E11: =IFERROR(VLOOKUP($D11,BS연결,MATCH(E$1,BS연결H,0),0)/100,"") | G11: =IFERROR(VLOOKUP($D11,BS연결,MATCH(G$1,BS연결H,0),0)/100,"") | H11: =IFERROR(VLOOKUP($D11,BS연결,MATCH(H$1,BS연결H,0),0)/100,"") | I11: =IFERROR(VLOOKUP($D11,BS연결,MATCH(I$1,BS연결H,0),0)/100,"") | J11: =IFERROR(VLOOKUP($D11,BS연결,MATCH(J$1,BS연결H,0),0)/100,"") | K11: =SUM(G11:J11) | L11: =IFERROR(VLOOKUP($D11,BS연결,MATCH(L$1,BS연결H,0),0)/100,"") | M11: =IFERROR(VLOOKUP($D11,BS연결,MATCH(M$1,BS연결H,0),0)/100,"") | N11: =IFERROR(VLOOKUP($D11,BS연결,MATCH(N$1,BS연결H,0),0)/100,"") | O11: =IFERROR(VLOOKUP($D11,BS연결,MATCH(O$1,BS연결H,0),0)/100,"") | P11: =IFERROR(VLOOKUP($D11,BS연결,MATCH(P$1,BS연결H,0),0)/100,"") | Q11: =IFERROR(VLOOKUP($D11,BS연결,MATCH(Q$1,BS연결H,0),0)/100,"") | R11: =IFERROR(VLOOKUP($D11,BS연결,MATCH(R$1,BS연결H,0),0)/100,"") | S11: =IFERROR(VLOOKUP($D11,BS연결,MATCH(S$1,BS연결H,0),0)/100,"") | ... AB11: =IFERROR(VLOOKUP($D11,BS연결,MATCH(AB$1,BS연결H,0),0)/100,"") | AC11: =IFERROR(AC12,"") | AD11: =IFERROR(AD12,"") | AE11: =SUM(AA11:AD11) | AF11: =IFERROR(AF12,"") | AG11: =IFERROR(AG12,"") | AH11: =IFERROR(AH12,"") | AI11: =IFERROR(AI12,"") | AJ11: =SUM(AF11:AI11) | AK11: =IFERROR(AK12,"") | AL11: =IFERROR(AL12,"") | AM11: =IFERROR(AM12,"") | AN11: =IFERROR(AN12,"") | AO11: =SUM(AK11:AN11)
A12: 이자손익 | B12: 손익 | C12: 억원 | D12: 이자손익 | G12: =IFERROR(VLOOKUP($D12,BS연결,MATCH(G$1,BS연결H,0),0)/100,"") | H12: =IFERROR(VLOOKUP($D12,BS연결,MATCH(H$1,BS연결H,0),0)/100,"") | I12: =IFERROR(VLOOKUP($D12,BS연결,MATCH(I$1,BS연결H,0),0)/100,"") | J12: =IFERROR(VLOOKUP($D12,BS연결,MATCH(J$1,BS연결H,0),0)/100,"") | K12: =IFERROR(VLOOKUP($D12,BS연결,MATCH(K$1,BS연결H,0),0)/100,"") | L12: =IFERROR(VLOOKUP($D12,BS연결,MATCH(L$1,BS연결H,0),0)/100,"") | M12: =IFERROR(VLOOKUP($D12,BS연결,MATCH(M$1,BS연결H,0),0)/100,"") | N12: =IFERROR(VLOOKUP($D12,BS연결,MATCH(N$1,BS연결H,0),0)/100,"") | ... Z12: =IFERROR(VLOOKUP($D12,BS연결,MATCH(Z$1,BS연결H,0),0)/100,"") | AB12: =IFERROR(VLOOKUP($D12,BS연결,MATCH(AB$1,BS연결H,0),0)/100,"") | AC12: =IFERROR((AB24*변수!$D$50-AB22*변수!$D$51)/4,"") | AD12: =IFERROR((AC24*변수!$D$50-AC22*변수!$D$51)/4,"") | AE12: =SUM(AA12:AD12) | AF12: =IFERROR((AD24*변수!$D$50-AD22*변수!$D$51)/4,"") | AG12: =IFERROR((AF24*변수!$D$50-AF22*변수!$D$51)/4,"") | AH12: =IFERROR((AG24*변수!$D$50-AG22*변수!$D$51)/4,"") | AI12: =IFERROR((AH24*변수!$D$50-AH22*변수!$D$51)/4,"") | AJ12: =SUM(AF12:AI12) | AK12: =IFERROR((AI24*변수!$D$50-AI22*변수!$D$51)/4,"") | AL12: =IFERROR((AK24*변수!$D$50-AK22*변수!$D$51)/4,"") | AM12: =IFERROR((AL24*변수!$D$50-AL22*변수!$D$51)/4,"") | AN12: =IFERROR((AM24*변수!$D$50-AM22*변수!$D$51)/4,"") | AO12: =SUM(AK12:AN12)
A13: 기타영업외손익 | B13: 손익 | C13: 억원 | D13: 기타영업외손익 | E13: =IFERROR(VLOOKUP($D13,BS연결,MATCH(E$1,BS연결H,0),0)/100,"") | G13: =IFERROR(VLOOKUP($D13,BS연결,MATCH(G$1,BS연결H,0),0)/100,"") | H13: =IFERROR(VLOOKUP($D13,BS연결,MATCH(H$1,BS연결H,0),0)/100,"") | I13: =IFERROR(VLOOKUP($D13,BS연결,MATCH(I$1,BS연결H,0),0)/100,"") | J13: =IFERROR(VLOOKUP($D13,BS연결,MATCH(J$1,BS연결H,0),0)/100,"") | K13: =IFERROR(VLOOKUP($D13,BS연결,MATCH(K$1,BS연결H,0),0)/100,"") | L13: =IFERROR(VLOOKUP($D13,BS연결,MATCH(L$1,BS연결H,0),0)/100,"") | M13: =IFERROR(VLOOKUP($D13,BS연결,MATCH(M$1,BS연결H,0),0)/100,"") | N13: =IFERROR(VLOOKUP($D13,BS연결,MATCH(N$1,BS연결H,0),0)/100,"") | ... AB13: =IFERROR(VLOOKUP($D13,BS연결,MATCH(AB$1,BS연결H,0),0)/100,"") | AC13: =변수!AC24 | AD13: =변수!AD24 | AE13: =SUM(AA13:AD13) | AF13: =변수!AF24 | AG13: =변수!AG24 | AH13: =변수!AH24 | AI13: =변수!AI24 | AJ13: =SUM(AF13:AI13) | AK13: =변수!AK24 | AL13: =변수!AL24 | AM13: =변수!AM24 | AN13: =변수!AN24 | AO13: =SUM(AK13:AN13)
A14: 세전이익 | B14: 손익 | C14: 억원 | D14: 법인세비용차감전계속사업이익 | E14: =IFERROR(VLOOKUP($D14,BS연결,MATCH(E$1,BS연결H,0),0)/100,"") | G14: =IFERROR(VLOOKUP($D14,BS연결,MATCH(G$1,BS연결H,0),0)/100,"") | H14: =IFERROR(VLOOKUP($D14,BS연결,MATCH(H$1,BS연결H,0),0)/100,"") | I14: =IFERROR(VLOOKUP($D14,BS연결,MATCH(I$1,BS연결H,0),0)/100,"") | J14: =IFERROR(VLOOKUP($D14,BS연결,MATCH(J$1,BS연결H,0),0)/100,"") | K14: =IFERROR(VLOOKUP($D14,BS연결,MATCH(K$1,BS연결H,0),0)/100,"") | L14: =IFERROR(VLOOKUP($D14,BS연결,MATCH(L$1,BS연결H,0),0)/100,"") | M14: =IFERROR(VLOOKUP($D14,BS연결,MATCH(M$1,BS연결H,0),0)/100,"") | N14: =IFERROR(VLOOKUP($D14,BS연결,MATCH(N$1,BS연결H,0),0)/100,"") | ... AB14: =IFERROR(VLOOKUP($D14,BS연결,MATCH(AB$1,BS연결H,0),0)/100,"") | AC14: =IFERROR(AC9+AC11+AC13,"") | AD14: =IFERROR(AD9+AD11+AD13,"") | AE14: =SUM(AA14:AD14) | AF14: =IFERROR(AF9+AF11+AF13,"") | AG14: =IFERROR(AG9+AG11+AG13,"") | AH14: =IFERROR(AH9+AH11+AH13,"") | AI14: =IFERROR(AI9+AI11+AI13,"") | AJ14: =SUM(AF14:AI14) | AK14: =IFERROR(AK9+AK11+AK13,"") | AL14: =IFERROR(AL9+AL11+AL13,"") | AM14: =IFERROR(AM9+AM11+AM13,"") | AN14: =IFERROR(AN9+AN11+AN13,"") | AO14: =SUM(AK14:AN14)
