Workbook
Name 변수H: 변수!$C$1:$V$1
Name 환율: 변수!$C$6:$V$13
Name BS연결H: BS연결!$C$1:$V$1
Name BS연결: BS연결!$C$5:$V$101
Name BS별도H: BS별도!$C$1:$V$1
Name BS별도: BS별도!$C$5:$V$92
Name SUBQH: subQ!$A$1:$V$1
Name subQ: subQ!$A$5:$V$43

Sheet README
A1: 티엠씨(217590) 실적 모델 — ARGUS 한국조선
A2: 기준 분기 2026Q2 · 마지막 실적 2026Q2 · 생성 2026-10-11
A3: 모든 수치는 모델 산출값(DART 공개 재무제표 + 우리 추정)이다 — 목표주가·투자 추천 아님. 참고용 · 투자조언 아님.
A5: 시트
A6: 변수 가정 시계열. 환율 8행(ECB via frankfurter — L2 fx.json; 추정 분기 = 노란 가정), 추정 드라이버(노란 셀 = 모델값에서 역산한 가정, 바꾸면 재계산; 연녹 셀 = 3절 스칼라 참조 수식), 3절 스칼라 가정(세율·판관비율·지배주주비중·이자율·종가·PER 밴드·COE·외화 순노출·헤지비율)
A7: BS연결/BS별도 FnGuide 계정명 × 기간 값 덤프(백만원). 행1 분기라벨, 행4 YYYY.MM / YYYY.12A. 이름정의 BS연결H·BS연결(계정명 C열부터)
A8: subQ 분기 서브모델(억원 = 백만원/100). 확정 행: =IFERROR(VLOOKUP($D행,BS연결,MATCH(E$1,BS연결H,0),0)/100,"") 추정 행: 변수 시트 가정 셀 참조 수식. 외환손익·파생상품손익은 BS 계정 합·차, 기타금융손익은 잔차, OPM·EPS·BPS·PER·PBR 은 파생 수식
A9: SLS 선표(조선사만, sls json 있을 때): 요약 행(sls 저장값) + 계약별 스케줄(백만$) × (헤지비율 × 헤지환율 + (1−헤지비율) × 건조시점 환율[변수 원/달러(평균)]) → 원화 수식 블록 → 합계 행이 subQ 매출조선에 연결
A10: 시나리오 신규수주 보수/기준/낙관(forecast_panel 패널, 모델에 scenarios 가 있을 때만): 매출액·영업이익 = subQ 기준값 ± (시나리오 신규 − base 신규) × OPM. base 만 subQ 행에 포함, 나머지는 합산 안 함
A11: 분기/연간예상 subQ 를 이름(A열 key)으로 VLOOKUP 한 보고서 표(억원)
A12: TP PER 밴드 × 12M fwd EPS, PBR = ROE/COE × BPS — 모델 산출값 구간, 목표주가·추천 아님
A13: 외화 환율 QoQ, 외화 순노출 × Δ기말환율 → 환관련손익 추정
... A34: 백테스트: {"freeze": "2025Q2", "horizon": 4, "revenue_wape_pct": null, "op_wape_pct": null, "n": 0, "note": "freeze 2025Q2 이후 실적 분기 없음 → 백테스트 없음"}

Sheet 변수
C1: 이름: 변수H | E1: 3Q25 | F1: 4Q25 | G1: 2025 | H1: 1Q26 | I1: 2Q26 | J1: 3Q26 | K1: 4Q26 | L1: 2026 | M1: 1Q27 | N1: 2Q27 | O1: 3Q27 | P1: 4Q27 | Q1: 2027 | R1: 1Q28 | S1: 2Q28 | T1: 3Q28 | U1: 4Q28 | V1: 2028
A2: 가정 시계열 — 노란 셀은 추정 가정(모델값에서 역산), 연녹 셀은 3절 스칼라 참조 수식. 바꾸면 subQ·분기·연간예상·TP·시나리오가 재계산됩니다.
E3: 1 | F3: 2 | G3: 3 | H3: 4 | I3: 5 | J3: 6 | K3: 7 | L3: 8 | M3: 9 | N3: 10 | O3: 11 | P3: 12 | Q3: 13 | R3: 14 | S3: 15 | T3: 16 | U3: 17 | V3: 18
E4: 2025.09 | F4: 2025.12 | G4: 2025.12A | H4: 2026.03 | I4: 2026.06 | J4: 2026.09 | K4: 2026.12 | L4: 2026.12A | M4: 2027.03 | N4: 2027.06 | O4: 2027.09 | P4: 2027.12 | Q4: 2027.12A | R4: 2028.03 | S4: 2028.06 | T4: 2028.09 | U4: 2028.12 | V4: 2028.12A
B5: 1. FX | C5: 이름: 환율
A6: USDKRW_avg | C6: 원/달러(평균) | E6: 1386.95 | F6: 1449.19 | G6: 1421.52 | H6: 1466.12 | I6: 1501.75 | J6: 1418.75 | K6: 1345.14 | L6: 1457.21 | M6: 1341.49 | N6: 1341.49 | O6: 1341.49 | P6: 1341.49 | R6: 1341.49 | S6: 1341.49 | T6: 1341.49 | U6: 1341.49
A7: USDKRW_end | C7: 원/달러(기말) | E7: 1403.67 | F7: 1444.2 | G7: 1444.2 | H7: 1524.8 | I7: 1550.89 | J7: 1355.4 | K7: 1341.49 | L7: 1341.49 | M7: 1341.49 | N7: 1341.49 | O7: 1341.49 | P7: 1341.49 | R7: 1341.49 | S7: 1341.49 | T7: 1341.49 | U7: 1341.49
A8: JPY100KRW_avg | C8: 원/100Y(평균) | E8: 940.32 | F8: 940.77 | G8: 950.17 | H8: 934.39 | I8: 942.16 | J8: 890.41 | K8: 850.79 | L8: 919.21 | M8: 847.7 | N8: 847.7 | O8: 847.7 | P8: 847.7 | R8: 847.7 | S8: 847.7 | T8: 847.7 | U8: 847.7
A9: JPY100KRW_end | C9: 원/100Y(기말) | E9: 948.49 | F9: 921.81 | G9: 921.81 | H9: 955.99 | I9: 954.75 | J9: 863.31 | K9: 847.7 | L9: 847.7 | M9: 847.7 | N9: 847.7 | O9: 847.7 | P9: 847.7 | R9: 847.7 | S9: 847.7 | T9: 847.7 | U9: 847.7
A10: EURKRW_avg | C10: W/Euro(평균) | E10: 1620.04 | F10: 1686.02 | G10: 1605.45 | H10: 1715.47 | I10: 1746.09 | J10: 1631.97 | K10: 1509.74 | L10: 1689.95 | M10: 1503.27 | N10: 1503.27 | O10: 1503.27 | P10: 1503.27 | R10: 1503.27 | S10: 1503.27 | T10: 1503.27 | U10: 1503.27
A11: EURKRW_end | C11: W/Euro(기말) | E11: 1648.04 | F11: 1696.94 | G11: 1696.94 | H11: 1753.21 | I11: 1767.09 | J11: 1539.06 | K11: 1503.27 | L11: 1503.27 | M11: 1503.27 | N11: 1503.27 | O11: 1503.27 | P11: 1503.27 | R11: 1503.27 | S11: 1503.27 | T11: 1503.27 | U11: 1503.27
A12: CNYKRW_avg | C12: 원/중국원(평균) | E12: 193.79 | F12: 204.38 | G12: 197.8 | H12: 211.75 | I12: 220.8 | J12: 210.43 | K12: 200.69 | L12: 213.75 | M12: 200.46 | N12: 200.46 | O12: 200.46 | P12: 200.46 | R12: 200.46 | S12: 200.46 | T12: 200.46 | U12: 200.46
A13: CNYKRW_end | C13: 원/중국원(기말) | E13: 197.16 | F13: 206.28 | G13: 206.28 | H13: 220.97 | I13: 228.56 | J13: 202.16 | K13: 200.46 | L13: 200.46 | M13: 200.46 | N13: 200.46 | O13: 200.46 | P13: 200.46 | R13: 200.46 | S13: 200.46 | T13: 200.46 | U13: 200.46
B14: 1b. 종가
A15: price_close_end | C15: 종가(기말) | F15: 15130 | H15: 18740 | I15: 13020 | J15: 13570 | K15: 18240
A16: price_high | C16: 종가(최고) | F16: 25850 | H16: 28950 | I16: 38700 | J16: 16170 | K16: 20300
A17: price_low | C17: 종가(최저) | F17: 15050 | H17: 11600 | I17: 11500 | J17: 8820 | K17: 13410
A18: price_avg | C18: 종가(평균) | F18: 19043.6 | H18: 16048.1 | I18: 23966.7 | J18: 12227.4 | K18: 17760
B20: 2. 추정 드라이버 | C20: 실적 열 = subQ 실현값(수식), 추정 열 = 가정(노란 = 모델값 역산, 연녹 = 3절 스칼라 참조)
A21: drv:매출액 | B21: yoy | C21: 매출액 YoY | J21: 2.884e-06 | K21: 2.108e-06 | M21: 3.193e-06 | N21: 3.855e-06 | O21: 0 | P21: 0 | R21: 0 | S21: 0 | T21: 0 | U21: 0
A22: drv:판관비 | B22: ratio | C22: 판관비율(/매출) | E22: =IFERROR(subQ!E8/subQ!E5,"") | F22: =IFERROR(subQ!F8/subQ!F5,"") | G22: =IFERROR(subQ!G8/subQ!G5,"") | H22: =IFERROR(subQ!H8/subQ!H5,"") | I22: =IFERROR(subQ!I8/subQ!I5,"") | J22: =$D$52 | K22: =$D$52 | L22: =IFERROR(subQ!L8/subQ!L5,"") | M22: =$D$52 | N22: =$D$52 | O22: =$D$52 | P22: =$D$52 | Q22: =IFERROR(subQ!Q8/subQ!Q5,"") | R22: =$D$52 | S22: =$D$52 | T22: =$D$52 | U22: =$D$52 | V22: =IFERROR(subQ!V8/subQ!V5,"")
A23: drv:영업이익 | B23: ratio | C23: 영업이익률(OPM) | E23: =IFERROR(subQ!E9/subQ!E5,"") | F23: =IFERROR(subQ!F9/subQ!F5,"") | G23: =IFERROR(subQ!G9/subQ!G5,"") | H23: =IFERROR(subQ!H9/subQ!H5,"") | I23: =IFERROR(subQ!I9/subQ!I5,"") | J23: 0.011497856 | K23: 0.011503492 | L23: =IFERROR(subQ!L9/subQ!L5,"") | M23: 0.011495599 | N23: 0.011499549 | O23: 0.011497856 | P23: 0.011503492 | Q23: =IFERROR(subQ!Q9/subQ!Q5,"") | R23: 0.011495599 | S23: 0.011499549 | T23: 0.011497856 | U23: 0.011503492 | V23: =IFERROR(subQ!V9/subQ!V5,"")
A24: drv:외환손익 | B24: abs | C24: 외환손익 (가정, 억원) | E24: =subQ!E13 | F24: =subQ!F13 | G24: =subQ!G13 | H24: =subQ!H13 | I24: =subQ!I13 | J24: 0 | K24: 0 | L24: =subQ!L13 | M24: 0 | N24: 0 | O24: 0 | P24: 0 | Q24: =subQ!Q13 | R24: 0 | S24: 0 | T24: 0 | U24: 0 | V24: =subQ!V13
A25: drv:파생상품손익 | B25: abs | C25: 파생상품손익 (가정, 억원) | E25: =subQ!E14 | F25: =subQ!F14 | G25: =subQ!G14 | H25: =subQ!H14 | I25: =subQ!I14 | J25: 0 | K25: 0 | L25: =subQ!L14 | M25: 0 | N25: 0 | O25: 0 | P25: 0 | Q25: =subQ!Q14 | R25: 0 | S25: 0 | T25: 0 | U25: 0 | V25: =subQ!V14
A26: drv:기타금융손익 | B26: abs | C26: 기타금융손익 (가정, 억원) | E26: =subQ!E15 | F26: =subQ!F15 | G26: =subQ!G15 | H26: =subQ!H15 | I26: =subQ!I15 | J26: 0 | K26: 0 | L26: =subQ!L15 | M26: 0 | N26: 0 | O26: 0 | P26: 0 | Q26: =subQ!Q15 | R26: 0 | S26: 0 | T26: 0 | U26: 0 | V26: =subQ!V15
A27: drv:기타영업외손익 | B27: abs | C27: 기타영업외손익 (가정, 억원) | E27: =subQ!E16 | F27: =subQ!F16 | G27: =subQ!G16 | H27: =subQ!H16 | I27: =subQ!I16 | J27: 0 | K27: 0 | L27: =subQ!L16 | M27: 0 | N27: 0 | O27: 0 | P27: 0 | Q27: =subQ!Q16 | R27: 0 | S27: 0 | T27: 0 | U27: 0 | V27: =subQ!V16
A28: drv:법인세비용 | B28: tax | C28: 법인세율(/세전) — 법인세 = MAX(세전,0) × 세율 | E28: =IFERROR(subQ!E18/subQ!E17,"") | F28: =IFERROR(subQ!F18/subQ!F17,"") | G28: =IFERROR(subQ!G18/subQ!G17,"") | H28: =IFERROR(subQ!H18/subQ!H17,"") | I28: =IFERROR(subQ!I18/subQ!I17,"") | J28: =$D$51 | K28: =$D$51 | L28: =IFERROR(subQ!L18/subQ!L17,"") | M28: =$D$51 | N28: =$D$51 | O28: =$D$51 | P28: =$D$51 | Q28: =IFERROR(subQ!Q18/subQ!Q17,"") | R28: =$D$51 | S28: =$D$51 | T28: =$D$51 | U28: =$D$51 | V28: =IFERROR(subQ!V18/subQ!V17,"")
A29: drv:지배주주순이익 | B29: ratio | C29: 지배주주 비중(/당기순이익) | E29: =IFERROR(subQ!E20/subQ!E19,"") | F29: =IFERROR(subQ!F20/subQ!F19,"") | G29: =IFERROR(subQ!G20/subQ!G19,"") | H29: =IFERROR(subQ!H20/subQ!H19,"") | I29: =IFERROR(subQ!I20/subQ!I19,"") | J29: =$D$53 | K29: =$D$53 | L29: =IFERROR(subQ!L20/subQ!L19,"") | M29: =$D$53 | N29: =$D$53 | O29: =$D$53 | P29: =$D$53 | Q29: =IFERROR(subQ!Q20/subQ!Q19,"") | R29: =$D$53 | S29: =$D$53 | T29: =$D$53 | U29: =$D$53 | V29: =IFERROR(subQ!V20/subQ!V19,"")
A30: drv:중단사업이익 | B30: abs | C30: 중단사업이익 (가정, 억원) | E30: =subQ!E21 | F30: =subQ!F21 | G30: =subQ!G21 | H30: =subQ!H21 | I30: =subQ!I21 | L30: =subQ!L21 | Q30: =subQ!Q21 | V30: =subQ!V21
A31: drv:부채총계 | B31: qoq | C31: 부채총계 QoQ | F31: =IFERROR(subQ!F23/subQ!E23-1,"") | H31: =IFERROR(subQ!H23/subQ!F23-1,"") | I31: =IFERROR(subQ!I23/subQ!H23-1,"") | J31: -4.27e-07 | K31: 0 | M31: 0 | N31: 0 | O31: 0 | P31: 0 | R31: 0 | S31: 0 | T31: 0 | U31: 0
A32: drv:자본총계 | B32: roll | C32: 자본총계 기타변동(배당 등, 억원) | F32: =IFERROR(subQ!E24+subQ!F19-subQ!F24,"") | H32: =IFERROR(subQ!F24+subQ!H19-subQ!H24,"") | I32: =IFERROR(subQ!H24+subQ!I19-subQ!I24,"") | J32: -0.003677405 | K32: 0.00526301 | M32: 0.002339075 | N32: 11.915829 | O32: 0.001168411 | P32: -0.003883395 | R32: -0.001970572 | S32: 11.917722 | T32: 0.000289181 | U32: 0.0034895
A33: drv:지배주주지분 | B33: roll | C33: 지배주주지분 기타변동(배당 등, 억원) | F33: =IFERROR(subQ!E25+subQ!F20-subQ!F25,"") | H33: =IFERROR(subQ!F25+subQ!H20-subQ!H25,"") | I33: =IFERROR(subQ!H25+subQ!I20-subQ!I25,"") | J33: -0.001677405 | K33: 0.00526301 | M33: -0.007660925 | N33: 11.925829 | O33: -0.008831589 | P33: 0.006116605 | R33: -0.001970572 | S33: 11.917722 | T33: 0.000289181 | U33: 0.0034895
A34: drv:총차입금 | B34: qoq | C34: 총차입금 QoQ | F34: =IFERROR(subQ!F26/subQ!E26-1,"") | H34: =IFERROR(subQ!H26/subQ!F26-1,"") | I34: =IFERROR(subQ!I26/subQ!H26-1,"") | J34: -3.97e-07 | K34: 0 | M34: 0 | N34: 0 | O34: 0 | P34: 0 | R34: 0 | S34: 0 | T34: 0 | U34: 0
A35: drv:순차입금 | B35: qoq | C35: 순차입금 QoQ | F35: =IFERROR(subQ!F27/subQ!E27-1,"") | H35: =IFERROR(subQ!H27/subQ!F27-1,"") | I35: =IFERROR(subQ!I27/subQ!H27-1,"") | J35: -0.019668263 | K35: -0.019963498 | M35: -0.024807449 | N35: -0.00082516 | O35: -0.023335929 | P35: -0.023869347 | R35: -0.029304029 | S35: -0.003671596 | T35: -0.028201454 | U35: -0.029098857
A36: drv:이자발생자산 | B36: qoq | C36: 이자발생자산 QoQ | F36: =IFERROR(subQ!F28/subQ!E28-1,"") | H36: =IFERROR(subQ!H28/subQ!F28-1,"") | I36: =IFERROR(subQ!I28/subQ!H28-1,"") | J36: 0.17362015 | K36: 0.14715164 | M36: 0.15607355 | N36: 0.004383219 | O36: 0.1234414 | P36: 0.10965594 | R36: 0.11842369 | S36: 0.012877839 | T36: 0.097298252 | U36: 0.088912134
A37: drv:현금및현금성자산 | B37: qoq | C37: 현금및현금성자산 QoQ | F37: =IFERROR(subQ!F29/subQ!E29-1,"") | H37: =IFERROR(subQ!H29/subQ!F29-1,"") | I37: =IFERROR(subQ!I29/subQ!H29-1,"")
A38: drv:CAPEX | B38: yoy | C38: CAPEX YoY | J38: -0.63991413 | K38: 2.7135279 | M38: 0.19164539 | N38: -0.13752251 | O38: 0 | P38: 0 | R38: 0 | S38: 0 | T38: 0 | U38: 0
A39: drv:영업활동현금흐름 | B39: yoy | C39: 영업활동현금흐름 YoY
A40: drv:주식수 | B40: qoq | C40: 주식수 QoQ | F40: =IFERROR(subQ!F32/subQ!E32-1,"") | H40: =IFERROR(subQ!H32/subQ!F32-1,"") | I40: =IFERROR(subQ!I32/subQ!H32-1,"") | J40: 0 | K40: 0 | M40: 0 | N40: 0 | O40: 0 | P40: 0 | R40: 0 | S40: 0 | T40: 0 | U40: 0
A41: drv:DPS | B41: abs | C41: DPS (가정, 원) | E41: =subQ!E35 | F41: =subQ!F35 | G41: =subQ!G35 | H41: =subQ!H35 | I41: =subQ!I35 | K41: 50 | L41: =subQ!L35 | P41: 50 | Q41: =subQ!Q35 | U41: 50 | V41: =subQ!V35
...

Sheet BS연결
B1: (백만원) | C1: 이름: BS연결H | E1: 3Q25 | F1: 4Q25 | G1: 2025 | H1: 1Q26 | I1: 2Q26 | J1: 3Q26 | K1: 4Q26 | L1: 2026 | M1: 1Q27 | N1: 2Q27 | O1: 3Q27 | P1: 4Q27 | Q1: 2027 | R1: 1Q28 | S1: 2Q28 | T1: 3Q28 | U1: 4Q28 | V1: 2028
B2: 연결 | D2: fin json(kship_fin.py)
B3: 티엠씨(연) | C3: UPDATE: 26-10-11 | E3: 1 | F3: 2 | G3: 3 | H3: 4 | I3: 5 | J3: 6 | K3: 7 | L3: 8 | M3: 9 | N3: 10 | O3: 11 | P3: 12 | Q3: 13 | R3: 14 | S3: 15 | T3: 16 | U3: 17 | V3: 18
B4: Account Code | C4: AccountNAME | E4: 2025.09 | F4: 2025.12 | G4: 2025.12A | H4: 2026.03 | I4: 2026.06 | J4: 2026.09 | K4: 2026.12 | L4: 2026.12A | M4: 2027.03 | N4: 2027.06 | O4: 2027.09 | P4: 2027.12 | Q4: 2027.12A | R4: 2028.03 | S4: 2028.06 | T4: 2028.09 | U4: 2028.12 | V4: 2028.12A
A5: 1 | C5: 유동자산 | E5: 107016.02 | F5: 147327.62 | G5: 147327.62 | H5: 144625.12 | I5: 140873.07
A6: 1 | C6: 현금및현금성자산 | E6: 5582.15 | F6: 10547.79 | G6: 10547.79 | H6: 1934.29 | I6: 3604.77
A7: 1 | C7: 매출채권및기타채권 | E7: 42672.33 | F7: 42096.92 | G7: 42096.92 | H7: 47382.1 | I7: 46817.2
A8: 1 | C8: 유동파생상품자산 | E8: 0 | F8: 226.15 | G8: 226.15 | H8: 614.16 | I8: 1488.84
A9: 1 | C9: 단기금융자산 | E9: 0 | F9: 226.15 | G9: 226.15 | H9: 614.16 | I9: 1488.84
A10: 1 | C10: 기타유동금융자산 | E10: 7576.18 | F10: 31642.99 | G10: 31642.99 | H10: 28265.11 | I10: 20202.01
A11: 1 | C11: 기타유동자산 | E11: 1892.46 | F11: 1140.74 | G11: 1140.74 | H11: 1769.52 | I11: 1584.73
A12: 1 | C12: 재고자산 | E12: 39340.55 | F12: 53943.82 | G12: 53943.82 | H12: 61950.49 | I12: 65474.21
A13: 1 | C13: 매각예정비유동자산및처분자산 | E13: 9905.35 | F13: 2654.65 | G13: 2654.65 | H13: 2654.65 | I13: 1656.51
A14: 1 | C14: 비유동자산 | E14: 90206.75 | F14: 89785.68 | G14: 89785.68 | H14: 89416.46 | I14: 89692.18
A15: 1 | C15: 장기금융자산 | E15: 36.67 | F15: 36.67 | G15: 36.67 | H15: 36.67 | I15: 36.67
A16: 1 | C16: 투자자산 | E16: 36.67 | F16: 36.67 | G16: 36.67 | H16: 36.67 | I16: 36.67
A17: 1 | C17: 유형자산 | E17: 70976.89 | F17: 76843.84 | G17: 76843.84 | H17: 76220.81
A18: 1 | C18: 투자부동산 | E18: 7406.51 | F18: 929.62 | G18: 929.62 | H18: 923.45 | I18: 2147.24
A19: 1 | C19: 무형자산 | E19: 7060.2
A20: 1 | C20: 장기매출채권및기타채권 | E20: 1138.34 | F20: 1098.75 | G20: 1098.75 | H20: 1093.96 | I20: 1085.67
A21: 1 | C21: 기타비유동자산 | E21: 2859.41 | F21: 2892.44 | G21: 2892.44 | H21: 3623.29 | I21: 2761.56
A22: 1 | C22: 이연법인세자산 | E22: 728.72 | F22: 1107.57 | G22: 1107.57 | H22: 859.09 | I22: 1052.82
A23: 1 | C23: 자산총계 | E23: 197222.78 | F23: 237113.29 | G23: 237113.29 | H23: 234041.58 | I23: 230565.25
A24: 1 | C24: 유동부채 | E24: 102965.81 | F24: 109666 | G24: 109666 | H24: 105461.27 | I24: 111387.94
A25: 1 | C25: 매입채무및기타채무 | E25: 42056.06 | F25: 56967.69 | G25: 56967.69 | H25: 55440.6 | I25: 53892.31
A26: 1 | C26: 단기차입금 | E26: 51365.03 | I26: 37321.54
A27: 1 | C27: 유동성장기부채 | E27: 2347.83 | F27: 0 | G27: 0 | I27: 13043.48
A28: 1 | C28: 당기법인세부채(미지급법인세) | E28: 969.84 | F28: 540.87 | G28: 540.87 | H28: 1273.2 | I28: 2359.86
A29: 1 | C29: 단기파생상품부채 | E29: 27.39 | F29: 91.76 | G29: 91.76 | H29: 477.27 | I29: 1081.83
A30: 1 | C30: 단기금융부채 | E30: 221.41 | F30: 349.52 | G30: 349.52 | H30: 980.07 | I30: 1468.78
A31: 1 | C31: 기타유동금융부채 | E31: 194.02 | F31: 257.76 | G31: 257.76 | H31: 502.8 | I31: 386.95
A32: 1 | C32: 기타유동부채 | E32: 1318.25 | F32: 2161.18 | G32: 2161.18 | H32: 2814.77 | I32: 2185.72
A33: 1 | C33: 단기충당부채 | E33: 26.22 | F33: 146.65 | G33: 146.65 | H33: 121.1 | I33: 154.13
A34: 1 | C34: 비유동부채 | E34: 19147.12 | F34: 16612.81 | G34: 16612.81 | H34: 16939.71 | I34: 5663.1
A35: 1 | C35: 장기차입금 | E35: 12456.52 | F35: 11869.57 | G35: 11869.57 | H35: 11282.61 | I35: 0
A36: 1 | C36: 사채 | E36: 0 | F36: 0 | G36: 0
A37: 1 | C37: 비유동리스부채 | E37: 2651.78 | F37: 2211.71 | G37: 2211.71 | H37: 2646.72 | I37: 2830.49
A38: 1 | C38: 리스부채 | E38: 2651.78 | F38: 2211.71 | G38: 2211.71 | H38: 2646.72 | I38: 2830.49
A39: 1 | C39: 장기금융부채 | E39: 2659.32 | F39: 2219.29 | G39: 2219.29 | H39: 2654.38 | I39: 2838.19
A40: 1 | C40: 기타비유동금융부채 | E40: 7.54 | F40: 7.58 | G40: 7.58 | H40: 7.66 | I40: 7.7
...

Sheet BS별도
B1: (백만원) | C1: 이름: BS별도H | E1: 3Q25 | F1: 4Q25 | G1: 2025 | H1: 1Q26 | I1: 2Q26 | J1: 3Q26 | K1: 4Q26 | L1: 2026 | M1: 1Q27 | N1: 2Q27 | O1: 3Q27 | P1: 4Q27 | Q1: 2027 | R1: 1Q28 | S1: 2Q28 | T1: 3Q28 | U1: 4Q28 | V1: 2028
B2: 별도 | D2: fin json(kship_fin.py)
B3: 티엠씨(별) | C3: UPDATE: 26-10-11 | E3: 1 | F3: 2 | G3: 3 | H3: 4 | I3: 5 | J3: 6 | K3: 7 | L3: 8 | M3: 9 | N3: 10 | O3: 11 | P3: 12 | Q3: 13 | R3: 14 | S3: 15 | T3: 16 | U3: 17 | V3: 18
B4: Account Code | C4: AccountNAME | E4: 2025.09 | F4: 2025.12 | G4: 2025.12A | H4: 2026.03 | I4: 2026.06 | J4: 2026.09 | K4: 2026.12 | L4: 2026.12A | M4: 2027.03 | N4: 2027.06 | O4: 2027.09 | P4: 2027.12 | Q4: 2027.12A | R4: 2028.03 | S4: 2028.06 | T4: 2028.09 | U4: 2028.12 | V4: 2028.12A
A5: 1 | C5: 유동자산 | E5: 96734.52 | F5: 137690.4 | G5: 137690.4 | H5: 133448.83 | I5: 132615.2
A6: 1 | C6: 현금및현금성자산 | E6: 4627.4 | F6: 8963.8 | G6: 8963.8 | H6: 1667.91 | I6: 1693.41
A7: 1 | C7: 매출채권및기타채권 | E7: 39388.6 | F7: 39278.03 | G7: 39278.03 | H7: 41945.32 | I7: 45080.19
A8: 1 | C8: 유동파생상품자산 | E8: 0 | F8: 226.15 | G8: 226.15 | H8: 614.16 | I8: 1488.84
A9: 1 | C9: 단기금융자산 | E9: 0 | F9: 226.15 | G9: 226.15 | H9: 614.16 | I9: 1488.84
A10: 1 | C10: 기타유동금융자산 | E10: 7576.18 | F10: 31642.99 | G10: 31642.99 | H10: 28265.11 | I10: 20202.01
A11: 1 | C11: 기타유동자산 | E11: 1768.54 | F11: 969.86 | G11: 969.86 | H11: 1696.06 | I11: 1477.29
A12: 1 | C12: 재고자산 | E12: 36331.33 | F12: 49943.29 | G12: 49943.29 | H12: 57603.76 | I12: 61016.94
A13: 1 | C13: 매각예정비유동자산및처분자산 | E13: 7042.47 | F13: 1656.51 | G13: 1656.51 | H13: 1656.51 | I13: 1656.51
A14: 1 | C14: 비유동자산 | E14: 90557.19 | F14: 91170.64 | G14: 91170.64 | H14: 91081.2 | I14: 93433.67
A15: 1 | C15: 장기금융자산 | E15: 36.67 | F15: 36.67 | G15: 36.67 | H15: 36.67 | I15: 36.67
A16: 1 | C16: 투자자산 | E16: 10279.86 | F16: 10328.63 | G16: 10328.63 | H16: 10328.63 | I16: 10328.63
A17: 1 | C17: 유형자산 | E17: 61823.13 | F17: 67701.58 | G17: 67701.58 | H17: 67255.22
A18: 1 | C18: 투자부동산 | E18: 7406.51 | F18: 929.62 | G18: 929.62 | H18: 923.45 | I18: 2147.24
A19: 1 | C19: 무형자산 | E19: 6649.94 | F19: 6583.41 | G19: 6583.41 | H19: 6447.68 | I19: 6241.99
A20: 1 | C20: 종속기업및관계기업투자 | E20: 10243.19 | F20: 10291.96 | G20: 10291.96 | H20: 10291.96 | I20: 10291.96
A21: 1 | C21: 장기매출채권및기타채권 | E21: 1138.34 | F21: 1953.69 | G21: 1953.69 | H21: 1996.75 | I21: 4631.12
A22: 1 | C22: 기타비유동자산 | E22: 2530.69 | F22: 2566.15 | G22: 2566.15 | H22: 3270.37 | I22: 2420.5
A23: 1 | C23: 이연법인세자산 | E23: 728.72 | F23: 1107.57 | G23: 1107.57 | H23: 859.09 | I23: 1052.82
A24: 1 | C24: 자산총계 | E24: 187291.71 | F24: 228861.05 | G24: 228861.05 | H24: 224530.02 | I24: 226048.87
A25: 1 | C25: 유동부채 | E25: 90974.79 | F25: 98429.5 | G25: 98429.5 | H25: 91931.57 | I25: 99895.25
A26: 1 | C26: 매입채무및기타채무 | E26: 35637.3 | F26: 50437.99 | G26: 50437.99 | H26: 48419.58 | I26: 47573.57
A27: 1 | C27: 단기차입금 | E27: 48115.03 | F27: 44830.98 | G27: 44830.98 | H27: 38273.29
A28: 1 | C28: 유동성장기부채 | E28: 2347.83
A29: 1 | C29: 유동리스부채 | E29: 448.08 | F29: 388.84 | G29: 388.84 | H29: 339.75 | I29: 507.37
A30: 1 | C30: 리스부채 | E30: 676.63 | F30: 623.43 | G30: 623.43 | H30: 659.8 | I30: 1251.02
A31: 1 | C31: 단기금융부채 | E31: 669.49 | F31: 738.36 | G31: 738.36 | H31: 1476.01 | I31: 1995.96
A32: 1 | C32: 당기법인세부채(미지급법인세) | E32: 969.84 | F32: 540.87 | G32: 540.87 | H32: 1273.2 | I32: 2359.86
A33: 1 | C33: 단기파생상품부채 | E33: 27.39 | F33: 91.76 | G33: 91.76 | H33: 477.27 | I33: 1081.83
A34: 1 | C34: 기타유동금융부채 | E34: 194.02 | F34: 257.76 | G34: 257.76 | H34: 658.99 | I34: 406.76
A35: 1 | C35: 기타유동부채 | E35: 1191.88 | F35: 1748.3 | G35: 1748.3 | H35: 2396.34 | I35: 1680.73
A36: 1 | C36: 단기충당부채 | E36: 10.34 | F36: 133.01 | G36: 133.01 | H36: 93.14 | I36: 100.1
A37: 1 | C37: 비유동부채 | E37: 16088.11 | F37: 12895.61 | G37: 12895.61 | H37: 12700.91 | I37: 2186.29
A38: 1 | C38: 장기차입금 | E38: 12456.52 | F38: 11869.57 | G38: 11869.57 | H38: 11282.61 | I38: 0
A39: 1 | C39: 사채 | E39: 0
A40: 1 | C40: 비유동리스부채 | E40: 228.55 | F40: 234.59 | G40: 234.59 | H40: 320.05 | I40: 743.65
...

Sheet subQ
A1: YQ | C1: subQ 분기 서브모델(억원, U=100) | E1: 3Q25 | F1: 4Q25 | G1: 2025 | H1: 1Q26 | I1: 2Q26 | J1: 3Q26 | K1: 4Q26 | L1: 2026 | M1: 1Q27 | N1: 2Q27 | O1: 3Q27 | P1: 4Q27 | Q1: 2027 | R1: 1Q28 | S1: 2Q28 | T1: 3Q28 | U1: 4Q28 | V1: 2028
A2: A=이름(key) B=그룹 C=단위 D=FnGuide 계정명(VLOOKUP 키). 확정=VLOOKUP(BS), 추정=변수 가정 참조
E3: 1 | F3: 2 | G3: 3 | H3: 4 | I3: 5 | J3: 6 | K3: 7 | L3: 8 | M3: 9 | N3: 10 | O3: 11 | P3: 12 | Q3: 13 | R3: 14 | S3: 15 | T3: 16 | U3: 17 | V3: 18
E4: 2025.09 | F4: 2025.12 | G4: 2025.12A | H4: 2026.03 | I4: 2026.06 | J4: 2026.09 | K4: 2026.12 | L4: 2026.12A | M4: 2027.03 | N4: 2027.06 | O4: 2027.09 | P4: 2027.12 | Q4: 2027.12A | R4: 2028.03 | S4: 2028.06 | T4: 2028.09 | U4: 2028.12 | V4: 2028.12A
A5: 매출액 | B5: 손익 | C5: 억원 | D5: 매출액(수익) | E5: =IFERROR(VLOOKUP($D5,BS연결,MATCH(E$1,BS연결H,0),0)/100,"") | F5: =IFERROR(VLOOKUP($D5,BS연결,MATCH(F$1,BS연결H,0),0)/100,"") | H5: =IFERROR(VLOOKUP($D5,BS연결,MATCH(H$1,BS연결H,0),0)/100,"") | I5: =IFERROR(VLOOKUP($D5,BS연결,MATCH(I$1,BS연결H,0),0)/100,"") | J5: =IFERROR(E5*(1+변수!J21),"") | K5: =IFERROR(F5*(1+변수!K21),"") | L5: =SUM(H5:K5) | M5: =IFERROR(H5*(1+변수!M21),"") | N5: =IFERROR(I5*(1+변수!N21),"") | O5: =IFERROR(J5*(1+변수!O21),"") | P5: =IFERROR(K5*(1+변수!P21),"") | Q5: =SUM(M5:P5) | R5: =IFERROR(M5*(1+변수!R21),"") | S5: =IFERROR(N5*(1+변수!S21),"") | T5: =IFERROR(O5*(1+변수!T21),"") | U5: =IFERROR(P5*(1+변수!U21),"") | V5: =SUM(R5:U5)
A6: 매출원가 | B6: 손익 | C6: 억원 | D6: 매출원가 | E6: =IFERROR(VLOOKUP($D6,BS연결,MATCH(E$1,BS연결H,0),0)/100,"") | F6: =IFERROR(VLOOKUP($D6,BS연결,MATCH(F$1,BS연결H,0),0)/100,"") | H6: =IFERROR(VLOOKUP($D6,BS연결,MATCH(H$1,BS연결H,0),0)/100,"") | I6: =IFERROR(VLOOKUP($D6,BS연결,MATCH(I$1,BS연결H,0),0)/100,"") | J6: =IFERROR(J5-J7,"") | K6: =IFERROR(K5-K7,"") | L6: =SUM(H6:K6) | M6: =IFERROR(M5-M7,"") | N6: =IFERROR(N5-N7,"") | O6: =IFERROR(O5-O7,"") | P6: =IFERROR(P5-P7,"") | Q6: =SUM(M6:P6) | R6: =IFERROR(R5-R7,"") | S6: =IFERROR(S5-S7,"") | T6: =IFERROR(T5-T7,"") | U6: =IFERROR(U5-U7,"") | V6: =SUM(R6:U6)
A7: 매출총이익 | B7: 손익 | C7: 억원 | D7: 매출총이익 | E7: =IFERROR(VLOOKUP($D7,BS연결,MATCH(E$1,BS연결H,0),0)/100,"") | F7: =IFERROR(VLOOKUP($D7,BS연결,MATCH(F$1,BS연결H,0),0)/100,"") | H7: =IFERROR(VLOOKUP($D7,BS연결,MATCH(H$1,BS연결H,0),0)/100,"") | I7: =IFERROR(VLOOKUP($D7,BS연결,MATCH(I$1,BS연결H,0),0)/100,"") | J7: =IFERROR(J9+J8,"") | K7: =IFERROR(K9+K8,"") | L7: =SUM(H7:K7) | M7: =IFERROR(M9+M8,"") | N7: =IFERROR(N9+N8,"") | O7: =IFERROR(O9+O8,"") | P7: =IFERROR(P9+P8,"") | Q7: =SUM(M7:P7) | R7: =IFERROR(R9+R8,"") | S7: =IFERROR(S9+S8,"") | T7: =IFERROR(T9+T8,"") | U7: =IFERROR(U9+U8,"") | V7: =SUM(R7:U7)
A8: 판관비 | B8: 손익 | C8: 억원 | D8: 판관비 | E8: =IFERROR(VLOOKUP($D8,BS연결,MATCH(E$1,BS연결H,0),0)/100,"") | F8: =IFERROR(VLOOKUP($D8,BS연결,MATCH(F$1,BS연결H,0),0)/100,"") | H8: =IFERROR(VLOOKUP($D8,BS연결,MATCH(H$1,BS연결H,0),0)/100,"") | I8: =IFERROR(VLOOKUP($D8,BS연결,MATCH(I$1,BS연결H,0),0)/100,"") | J8: =IFERROR(J5*변수!J22,"") | K8: =IFERROR(K5*변수!K22,"") | L8: =SUM(H8:K8) | M8: =IFERROR(M5*변수!M22,"") | N8: =IFERROR(N5*변수!N22,"") | O8: =IFERROR(O5*변수!O22,"") | P8: =IFERROR(P5*변수!P22,"") | Q8: =SUM(M8:P8) | R8: =IFERROR(R5*변수!R22,"") | S8: =IFERROR(S5*변수!S22,"") | T8: =IFERROR(T5*변수!T22,"") | U8: =IFERROR(U5*변수!U22,"") | V8: =SUM(R8:U8)
A9: 영업이익 | B9: 손익 | C9: 억원 | D9: 영업이익 | E9: =IFERROR(VLOOKUP($D9,BS연결,MATCH(E$1,BS연결H,0),0)/100,"") | F9: =IFERROR(VLOOKUP($D9,BS연결,MATCH(F$1,BS연결H,0),0)/100,"") | H9: =IFERROR(VLOOKUP($D9,BS연결,MATCH(H$1,BS연결H,0),0)/100,"") | I9: =IFERROR(VLOOKUP($D9,BS연결,MATCH(I$1,BS연결H,0),0)/100,"") | J9: =IFERROR(J5*변수!J23,"") | K9: =IFERROR(K5*변수!K23,"") | L9: =SUM(H9:K9) | M9: =IFERROR(M5*변수!M23,"") | N9: =IFERROR(N5*변수!N23,"") | O9: =IFERROR(O5*변수!O23,"") | P9: =IFERROR(P5*변수!P23,"") | Q9: =SUM(M9:P9) | R9: =IFERROR(R5*변수!R23,"") | S9: =IFERROR(S5*변수!S23,"") | T9: =IFERROR(T5*변수!T23,"") | U9: =IFERROR(U5*변수!U23,"") | V9: =SUM(R9:U9)
A10: OPM | B10: 손익 | C10: % | D10: 영업이익률 | E10: =IFERROR(E9/E5,"") | F10: =IFERROR(F9/F5,"") | H10: =IFERROR(H9/H5,"") | I10: =IFERROR(I9/I5,"") | J10: =IFERROR(J9/J5,"") | K10: =IFERROR(K9/K5,"") | L10: =IFERROR(L9/L5,"") | M10: =IFERROR(M9/M5,"") | N10: =IFERROR(N9/N5,"") | O10: =IFERROR(O9/O5,"") | ... V10: =IFERROR(V9/V5,"")
A11: 금융손익 | B11: 손익 | C11: 억원 | D11: 금융손익 | E11: =IFERROR(VLOOKUP($D11,BS연결,MATCH(E$1,BS연결H,0),0)/100,"") | F11: =IFERROR(VLOOKUP($D11,BS연결,MATCH(F$1,BS연결H,0),0)/100,"") | H11: =IFERROR(VLOOKUP($D11,BS연결,MATCH(H$1,BS연결H,0),0)/100,"") | I11: =IFERROR(VLOOKUP($D11,BS연결,MATCH(I$1,BS연결H,0),0)/100,"") | J11: =IFERROR(J12+J13+J14+J15,"") | K11: =IFERROR(K12+K13+K14+K15,"") | L11: =SUM(H11:K11) | M11: =IFERROR(M12+M13+M14+M15,"") | N11: =IFERROR(N12+N13+N14+N15,"") | O11: =IFERROR(O12+O13+O14+O15,"") | P11: =IFERROR(P12+P13+P14+P15,"") | Q11: =SUM(M11:P11) | R11: =IFERROR(R12+R13+R14+R15,"") | S11: =IFERROR(S12+S13+S14+S15,"") | T11: =IFERROR(T12+T13+T14+T15,"") | U11: =IFERROR(U12+U13+U14+U15,"") | V11: =SUM(R11:U11)
A12: 이자손익 | B12: 손익 | C12: 억원 | D12: 이자손익 | E12: =IFERROR(VLOOKUP($D12,BS연결,MATCH(E$1,BS연결H,0),0)/100,"") | F12: =IFERROR(VLOOKUP($D12,BS연결,MATCH(F$1,BS연결H,0),0)/100,"") | I12: =IFERROR(VLOOKUP($D12,BS연결,MATCH(I$1,BS연결H,0),0)/100,"") | J12: =IFERROR((I28*변수!$D$54-I26*변수!$D$55)/4,"") | K12: =IFERROR((J28*변수!$D$54-J26*변수!$D$55)/4,"") | L12: =SUM(H12:K12) | M12: =IFERROR((K28*변수!$D$54-K26*변수!$D$55)/4,"") | N12: =IFERROR((M28*변수!$D$54-M26*변수!$D$55)/4,"") | O12: =IFERROR((N28*변수!$D$54-N26*변수!$D$55)/4,"") | P12: =IFERROR((O28*변수!$D$54-O26*변수!$D$55)/4,"") | Q12: =SUM(M12:P12) | R12: =IFERROR((P28*변수!$D$54-P26*변수!$D$55)/4,"") | S12: =IFERROR((R28*변수!$D$54-R26*변수!$D$55)/4,"") | T12: =IFERROR((S28*변수!$D$54-S26*변수!$D$55)/4,"") | U12: =IFERROR((T28*변수!$D$54-T26*변수!$D$55)/4,"") | V12: =SUM(R12:U12)
A13: 외환손익 | B13: 손익 | C13: 억원 | D13: 외환손익(실적만; 추정 환효과는 환관련손익) | E13: =IFERROR((VLOOKUP("외환차익",BS연결,MATCH(E$1,BS연결H,0),0)-VLOOKUP("외환차손",BS연결,MATCH(E$1,BS연결H,0),0)+VLOOKUP("외화환산이익",BS연결,MATCH(E$1,BS연결H,0),0)-VLOOKUP("외화환산손실",BS연결,MATCH(E$1,BS연결H,0),0))/100,"") | F13: =IFERROR((VLOOKUP("외환차익",BS연결,MATCH(F$1,BS연결H,0),0)-VLOOKUP("외환차손",BS연결,MATCH(F$1,BS연결H,0),0)+VLOOKUP("외화환산이익",BS연결,MATCH(F$1,BS연결H,0),0)-VLOOKUP("외화환산손실",BS연결,MATCH(F$1,BS연결H,0),0))/100,"") | I13: =IFERROR((VLOOKUP("외환차익",BS연결,MATCH(I$1,BS연결H,0),0)-VLOOKUP("외환차손",BS연결,MATCH(I$1,BS연결H,0),0)+VLOOKUP("외화환산이익",BS연결,MATCH(I$1,BS연결H,0),0)-VLOOKUP("외화환산손실",BS연결,MATCH(I$1,BS연결H,0),0))/100,"") | J13: =변수!J24 | K13: =변수!K24 | L13: =SUM(H13:K13) | M13: =변수!M24 | N13: =변수!N24 | O13: =변수!O24 | P13: =변수!P24 | Q13: =SUM(M13:P13) | R13: =변수!R24 | S13: =변수!S24 | T13: =변수!T24 | U13: =변수!U24 | V13: =SUM(R13:U13)
A14: 파생상품손익 | B14: 손익 | C14: 억원 | D14: 파생상품손익 | E14: =IFERROR((VLOOKUP("파생상품이익",BS연결,MATCH(E$1,BS연결H,0),0)-VLOOKUP("파생상품손실",BS연결,MATCH(E$1,BS연결H,0),0))/100,"") | F14: =IFERROR((VLOOKUP("파생상품이익",BS연결,MATCH(F$1,BS연결H,0),0)-VLOOKUP("파생상품손실",BS연결,MATCH(F$1,BS연결H,0),0))/100,"") | I14: =IFERROR((VLOOKUP("파생상품이익",BS연결,MATCH(I$1,BS연결H,0),0)-VLOOKUP("파생상품손실",BS연결,MATCH(I$1,BS연결H,0),0))/100,"") | J14: =변수!J25 | K14: =변수!K25 | L14: =SUM(H14:K14) | M14: =변수!M25 | N14: =변수!N25 | O14: =변수!O25 | P14: =변수!P25 | Q14: =SUM(M14:P14) | R14: =변수!R25 | S14: =변수!S25 | T14: =변수!T25 | U14: =변수!U25 | V14: =SUM(R14:U14)
A15: 기타금융손익 | B15: 손익 | C15: 억원 | D15: 기타금융손익(금융손익 잔차) | E15: =IFERROR(E11-E12-E13-E14,"") | F15: =IFERROR(F11-F12-F13-F14,"") | I15: =IFERROR(I11-I12-I13-I14,"") | J15: =변수!J26 | K15: =변수!K26 | L15: =SUM(H15:K15) | M15: =변수!M26 | N15: =변수!N26 | O15: =변수!O26 | P15: =변수!P26 | Q15: =SUM(M15:P15) | R15: =변수!R26 | S15: =변수!S26 | T15: =변수!T26 | U15: =변수!U26 | V15: =SUM(R15:U15)
A16: 기타영업외손익 | B16: 손익 | C16: 억원 | D16: 기타영업외손익 | E16: =IFERROR(VLOOKUP($D16,BS연결,MATCH(E$1,BS연결H,0),0)/100,"") | F16: =IFERROR(VLOOKUP($D16,BS연결,MATCH(F$1,BS연결H,0),0)/100,"") | H16: =IFERROR(VLOOKUP($D16,BS연결,MATCH(H$1,BS연결H,0),0)/100,"") | I16: =IFERROR(VLOOKUP($D16,BS연결,MATCH(I$1,BS연결H,0),0)/100,"") | J16: =변수!J27 | K16: =변수!K27 | L16: =SUM(H16:K16) | M16: =변수!M27 | N16: =변수!N27 | O16: =변수!O27 | P16: =변수!P27 | Q16: =SUM(M16:P16) | R16: =변수!R27 | S16: =변수!S27 | T16: =변수!T27 | U16: =변수!U27 | V16: =SUM(R16:U16)
A17: 세전이익 | B17: 손익 | C17: 억원 | D17: 법인세비용차감전계속사업이익 | E17: =IFERROR(VLOOKUP($D17,BS연결,MATCH(E$1,BS연결H,0),0)/100,"") | F17: =IFERROR(VLOOKUP($D17,BS연결,MATCH(F$1,BS연결H,0),0)/100,"") | H17: =IFERROR(VLOOKUP($D17,BS연결,MATCH(H$1,BS연결H,0),0)/100,"") | I17: =IFERROR(VLOOKUP($D17,BS연결,MATCH(I$1,BS연결H,0),0)/100,"") | J17: =IFERROR(J9+J11+J16,"") | K17: =IFERROR(K9+K11+K16,"") | L17: =SUM(H17:K17) | M17: =IFERROR(M9+M11+M16,"") | N17: =IFERROR(N9+N11+N16,"") | O17: =IFERROR(O9+O11+O16,"") | P17: =IFERROR(P9+P11+P16,"") | Q17: =SUM(M17:P17) | R17: =IFERROR(R9+R11+R16,"") | S17: =IFERROR(S9+S11+S16,"") | T17: =IFERROR(T9+T11+T16,"") | U17: =IFERROR(U9+U11+U16,"") | V17: =SUM(R17:U17)
A18: 법인세비용 | B18: 손익 | C18: 억원 | D18: 법인세비용 | E18: =IFERROR(VLOOKUP($D18,BS연결,MATCH(E$1,BS연결H,0),0)/100,"") | F18: =IFERROR(VLOOKUP($D18,BS연결,MATCH(F$1,BS연결H,0),0)/100,"") | H18: =IFERROR(VLOOKUP($D18,BS연결,MATCH(H$1,BS연결H,0),0)/100,"") | I18: =IFERROR(VLOOKUP($D18,BS연결,MATCH(I$1,BS연결H,0),0)/100,"") | J18: =IFERROR(MAX(J17,0)*변수!J28,"") | K18: =IFERROR(MAX(K17,0)*변수!K28,"") | L18: =SUM(H18:K18) | M18: =IFERROR(MAX(M17,0)*변수!M28,"") | N18: =IFERROR(MAX(N17,0)*변수!N28,"") | O18: =IFERROR(MAX(O17,0)*변수!O28,"") | P18: =IFERROR(MAX(P17,0)*변수!P28,"") | Q18: =SUM(M18:P18) | R18: =IFERROR(MAX(R17,0)*변수!R28,"") | S18: =IFERROR(MAX(S17,0)*변수!S28,"") | T18: =IFERROR(MAX(T17,0)*변수!T28,"") | U18: =IFERROR(MAX(U17,0)*변수!U28,"") | V18: =SUM(R18:U18)
A19: 당기순이익 | B19: 손익 | C19: 억원 | D19: 당기순이익 | E19: =IFERROR(VLOOKUP($D19,BS연결,MATCH(E$1,BS연결H,0),0)/100,"") | F19: =IFERROR(VLOOKUP($D19,BS연결,MATCH(F$1,BS연결H,0),0)/100,"") | H19: =IFERROR(VLOOKUP($D19,BS연결,MATCH(H$1,BS연결H,0),0)/100,"") | I19: =IFERROR(VLOOKUP($D19,BS연결,MATCH(I$1,BS연결H,0),0)/100,"") | J19: =IFERROR(J17-J18,"") | K19: =IFERROR(K17-K18,"") | L19: =SUM(H19:K19) | M19: =IFERROR(M17-M18,"") | N19: =IFERROR(N17-N18,"") | O19: =IFERROR(O17-O18,"") | P19: =IFERROR(P17-P18,"") | Q19: =SUM(M19:P19) | R19: =IFERROR(R17-R18,"") | S19: =IFERROR(S17-S18,"") | T19: =IFERROR(T17-T18,"") | U19: =IFERROR(U17-U18,"") | V19: =SUM(R19:U19)
A20: 지배주주순이익 | B20: 손익 | C20: 억원 | D20: (지배주주지분)당기순이익 | E20: =IFERROR(VLOOKUP($D20,BS연결,MATCH(E$1,BS연결H,0),0)/100,"") | F20: =IFERROR(VLOOKUP($D20,BS연결,MATCH(F$1,BS연결H,0),0)/100,"") | H20: =IFERROR(VLOOKUP($D20,BS연결,MATCH(H$1,BS연결H,0),0)/100,"") | I20: =IFERROR(VLOOKUP($D20,BS연결,MATCH(I$1,BS연결H,0),0)/100,"") | J20: =IFERROR(J19*변수!J29,"") | K20: =IFERROR(K19*변수!K29,"") | L20: =SUM(H20:K20) | M20: =IFERROR(M19*변수!M29,"") | N20: =IFERROR(N19*변수!N29,"") | O20: =IFERROR(O19*변수!O29,"") | P20: =IFERROR(P19*변수!P29,"") | Q20: =SUM(M20:P20) | R20: =IFERROR(R19*변수!R29,"") | S20: =IFERROR(S19*변수!S29,"") | T20: =IFERROR(T19*변수!T29,"") | U20: =IFERROR(U19*변수!U29,"") | V20: =SUM(R20:U20)
A21: 중단사업이익 | B21: 손익 | C21: 억원 | D21: 중단사업이익 | E21: =IFERROR(VLOOKUP($D21,BS연결,MATCH(E$1,BS연결H,0),0)/100,"") | F21: =IFERROR(VLOOKUP($D21,BS연결,MATCH(F$1,BS연결H,0),0)/100,"") | H21: =IFERROR(VLOOKUP($D21,BS연결,MATCH(H$1,BS연결H,0),0)/100,"") | L21: =SUM(H21:K21) | Q21: =SUM(M21:P21) | V21: =SUM(R21:U21)
A22: 자산총계 | B22: 재무상태 | C22: 억원 | D22: 자산총계 | E22: =IFERROR(VLOOKUP($D22,BS연결,MATCH(E$1,BS연결H,0),0)/100,"") | F22: =IFERROR(VLOOKUP($D22,BS연결,MATCH(F$1,BS연결H,0),0)/100,"") | G22: =IFERROR(VLOOKUP($D22,BS연결,MATCH(G$1,BS연결H,0),0)/100,"") | H22: =IFERROR(VLOOKUP($D22,BS연결,MATCH(H$1,BS연결H,0),0)/100,"") | I22: =IFERROR(VLOOKUP($D22,BS연결,MATCH(I$1,BS연결H,0),0)/100,"") | J22: =IFERROR(J23+J24,"") | K22: =IFERROR(K23+K24,"") | L22: =K22 | M22: =IFERROR(M23+M24,"") | N22: =IFERROR(N23+N24,"") | O22: =IFERROR(O23+O24,"") | P22: =IFERROR(P23+P24,"") | Q22: =P22 | R22: =IFERROR(R23+R24,"") | S22: =IFERROR(S23+S24,"") | T22: =IFERROR(T23+T24,"") | U22: =IFERROR(U23+U24,"") | V22: =U22
A23: 부채총계 | B23: 재무상태 | C23: 억원 | D23: 부채총계 | E23: =IFERROR(VLOOKUP($D23,BS연결,MATCH(E$1,BS연결H,0),0)/100,"") | F23: =IFERROR(VLOOKUP($D23,BS연결,MATCH(F$1,BS연결H,0),0)/100,"") | G23: =IFERROR(VLOOKUP($D23,BS연결,MATCH(G$1,BS연결H,0),0)/100,"") | H23: =IFERROR(VLOOKUP($D23,BS연결,MATCH(H$1,BS연결H,0),0)/100,"") | I23: =IFERROR(VLOOKUP($D23,BS연결,MATCH(I$1,BS연결H,0),0)/100,"") | J23: =IFERROR(I23*(1+변수!J31),"") | K23: =IFERROR(J23*(1+변수!K31),"") | L23: =K23 | M23: =IFERROR(K23*(1+변수!M31),"") | N23: =IFERROR(M23*(1+변수!N31),"") | O23: =IFERROR(N23*(1+변수!O31),"") | P23: =IFERROR(O23*(1+변수!P31),"") | Q23: =P23 | R23: =IFERROR(P23*(1+변수!R31),"") | S23: =IFERROR(R23*(1+변수!S31),"") | T23: =IFERROR(S23*(1+변수!T31),"") | U23: =IFERROR(T23*(1+변수!U31),"") | V23: =U23
A24: 자본총계 | B24: 재무상태 | C24: 억원 | D24: 자본총계 | E24: =IFERROR(VLOOKUP($D24,BS연결,MATCH(E$1,BS연결H,0),0)/100,"") | F24: =IFERROR(VLOOKUP($D24,BS연결,MATCH(F$1,BS연결H,0),0)/100,"") | G24: =IFERROR(VLOOKUP($D24,BS연결,MATCH(G$1,BS연결H,0),0)/100,"") | H24: =IFERROR(VLOOKUP($D24,BS연결,MATCH(H$1,BS연결H,0),0)/100,"") | I24: =IFERROR(VLOOKUP($D24,BS연결,MATCH(I$1,BS연결H,0),0)/100,"") | J24: =IFERROR(I24+J19-변수!J32,"") | K24: =IFERROR(J24+K19-변수!K32,"") | L24: =K24 | M24: =IFERROR(K24+M19-변수!M32,"") | N24: =IFERROR(M24+N19-변수!N32,"") | O24: =IFERROR(N24+O19-변수!O32,"") | P24: =IFERROR(O24+P19-변수!P32,"") | Q24: =P24 | R24: =IFERROR(P24+R19-변수!R32,"") | S24: =IFERROR(R24+S19-변수!S32,"") | T24: =IFERROR(S24+T19-변수!T32,"") | U24: =IFERROR(T24+U19-변수!U32,"") | V24: =U24
A25: 지배주주지분 | B25: 재무상태 | C25: 억원 | D25: 지배주주지분 | E25: =IFERROR(VLOOKUP($D25,BS연결,MATCH(E$1,BS연결H,0),0)/100,"") | F25: =IFERROR(VLOOKUP($D25,BS연결,MATCH(F$1,BS연결H,0),0)/100,"") | G25: =IFERROR(VLOOKUP($D25,BS연결,MATCH(G$1,BS연결H,0),0)/100,"") | H25: =IFERROR(VLOOKUP($D25,BS연결,MATCH(H$1,BS연결H,0),0)/100,"") | I25: =IFERROR(VLOOKUP($D25,BS연결,MATCH(I$1,BS연결H,0),0)/100,"") | J25: =IFERROR(I25+J20-변수!J33,"") | K25: =IFERROR(J25+K20-변수!K33,"") | L25: =K25 | M25: =IFERROR(K25+M20-변수!M33,"") | N25: =IFERROR(M25+N20-변수!N33,"") | O25: =IFERROR(N25+O20-변수!O33,"") | P25: =IFERROR(O25+P20-변수!P33,"") | Q25: =P25 | R25: =IFERROR(P25+R20-변수!R33,"") | S25: =IFERROR(R25+S20-변수!S33,"") | T25: =IFERROR(S25+T20-변수!T33,"") | U25: =IFERROR(T25+U20-변수!U33,"") | V25: =U25
A26: 총차입금 | B26: 재무상태 | C26: 억원 | D26: 총차입금 | E26: =IFERROR(VLOOKUP($D26,BS연결,MATCH(E$1,BS연결H,0),0)/100,"") | F26: =IFERROR(VLOOKUP($D26,BS연결,MATCH(F$1,BS연결H,0),0)/100,"") | G26: =IFERROR(VLOOKUP($D26,BS연결,MATCH(G$1,BS연결H,0),0)/100,"") | H26: =IFERROR(VLOOKUP($D26,BS연결,MATCH(H$1,BS연결H,0),0)/100,"") | I26: =IFERROR(VLOOKUP($D26,BS연결,MATCH(I$1,BS연결H,0),0)/100,"") | J26: =IFERROR(I26*(1+변수!J34),"") | K26: =IFERROR(J26*(1+변수!K34),"") | L26: =K26 | M26: =IFERROR(K26*(1+변수!M34),"") | N26: =IFERROR(M26*(1+변수!N34),"") | O26: =IFERROR(N26*(1+변수!O34),"") | P26: =IFERROR(O26*(1+변수!P34),"") | Q26: =P26 | R26: =IFERROR(P26*(1+변수!R34),"") | S26: =IFERROR(R26*(1+변수!S34),"") | T26: =IFERROR(S26*(1+변수!T34),"") | U26: =IFERROR(T26*(1+변수!U34),"") | V26: =U26
A27: 순차입금 | B27: 재무상태 | C27: 억원 | D27: 순차입금 | E27: =IFERROR(VLOOKUP($D27,BS연결,MATCH(E$1,BS연결H,0),0)/100,"") | F27: =IFERROR(VLOOKUP($D27,BS연결,MATCH(F$1,BS연결H,0),0)/100,"") | G27: =IFERROR(VLOOKUP($D27,BS연결,MATCH(G$1,BS연결H,0),0)/100,"") | H27: =IFERROR(VLOOKUP($D27,BS연결,MATCH(H$1,BS연결H,0),0)/100,"") | I27: =IFERROR(VLOOKUP($D27,BS연결,MATCH(I$1,BS연결H,0),0)/100,"") | J27: =IFERROR(I27*(1+변수!J35),"") | K27: =IFERROR(J27*(1+변수!K35),"") | L27: =K27 | M27: =IFERROR(K27*(1+변수!M35),"") | N27: =IFERROR(M27*(1+변수!N35),"") | O27: =IFERROR(N27*(1+변수!O35),"") | P27: =IFERROR(O27*(1+변수!P35),"") | Q27: =P27 | R27: =IFERROR(P27*(1+변수!R35),"") | S27: =IFERROR(R27*(1+변수!S35),"") | T27: =IFERROR(S27*(1+변수!T35),"") | U27: =IFERROR(T27*(1+변수!U35),"") | V27: =U27
A28: 이자발생자산 | B28: 재무상태 | C28: 억원 | D28: 이자발생자산 | E28: =IFERROR(VLOOKUP($D28,BS연결,MATCH(E$1,BS연결H,0),0)/100,"") | F28: =IFERROR(VLOOKUP($D28,BS연결,MATCH(F$1,BS연결H,0),0)/100,"") | G28: =IFERROR(VLOOKUP($D28,BS연결,MATCH(G$1,BS연결H,0),0)/100,"") | H28: =IFERROR(VLOOKUP($D28,BS연결,MATCH(H$1,BS연결H,0),0)/100,"") | I28: =IFERROR(VLOOKUP($D28,BS연결,MATCH(I$1,BS연결H,0),0)/100,"") | J28: =IFERROR(I28*(1+변수!J36),"") | K28: =IFERROR(J28*(1+변수!K36),"") | L28: =K28 | M28: =IFERROR(K28*(1+변수!M36),"") | N28: =IFERROR(M28*(1+변수!N36),"") | O28: =IFERROR(N28*(1+변수!O36),"") | P28: =IFERROR(O28*(1+변수!P36),"") | Q28: =P28 | R28: =IFERROR(P28*(1+변수!R36),"") | S28: =IFERROR(R28*(1+변수!S36),"") | T28: =IFERROR(S28*(1+변수!T36),"") | U28: =IFERROR(T28*(1+변수!U36),"") | V28: =U28
A29: 현금및현금성자산 | B29: 재무상태 | C29: 억원 | D29: 현금및현금성자산 | E29: =IFERROR(VLOOKUP($D29,BS연결,MATCH(E$1,BS연결H,0),0)/100,"") | F29: =IFERROR(VLOOKUP($D29,BS연결,MATCH(F$1,BS연결H,0),0)/100,"") | G29: =IFERROR(VLOOKUP($D29,BS연결,MATCH(G$1,BS연결H,0),0)/100,"") | H29: =IFERROR(VLOOKUP($D29,BS연결,MATCH(H$1,BS연결H,0),0)/100,"") | I29: =IFERROR(VLOOKUP($D29,BS연결,MATCH(I$1,BS연결H,0),0)/100,"") | L29: =K29 | Q29: =P29 | V29: =U29
A30: CAPEX | B30: 현금흐름 | C30: 억원 | D30: CAPEX | E30: =IFERROR(VLOOKUP($D30,BS연결,MATCH(E$1,BS연결H,0),0)/100,"") | F30: =IFERROR(VLOOKUP($D30,BS연결,MATCH(F$1,BS연결H,0),0)/100,"") | H30: =IFERROR(VLOOKUP($D30,BS연결,MATCH(H$1,BS연결H,0),0)/100,"") | I30: =IFERROR(VLOOKUP($D30,BS연결,MATCH(I$1,BS연결H,0),0)/100,"") | J30: =IFERROR(E30*(1+변수!J38),"") | K30: =IFERROR(F30*(1+변수!K38),"") | L30: =SUM(H30:K30) | M30: =IFERROR(H30*(1+변수!M38),"") | N30: =IFERROR(I30*(1+변수!N38),"") | O30: =IFERROR(J30*(1+변수!O38),"") | P30: =IFERROR(K30*(1+변수!P38),"") | Q30: =SUM(M30:P30) | R30: =IFERROR(M30*(1+변수!R38),"") | S30: =IFERROR(N30*(1+변수!S38),"") | T30: =IFERROR(O30*(1+변수!T38),"") | U30: =IFERROR(P30*(1+변수!U38),"") | V30: =SUM(R30:U30)
A31: 영업활동현금흐름 | B31: 현금흐름 | C31: 억원 | D31: 영업활동으로인한현금흐름 | E31: =IFERROR(VLOOKUP($D31,BS연결,MATCH(E$1,BS연결H,0),0)/100,"") | F31: =IFERROR(VLOOKUP($D31,BS연결,MATCH(F$1,BS연결H,0),0)/100,"") | H31: =IFERROR(VLOOKUP($D31,BS연결,MATCH(H$1,BS연결H,0),0)/100,"") | I31: =IFERROR(VLOOKUP($D31,BS연결,MATCH(I$1,BS연결H,0),0)/100,"") | L31: =SUM(H31:K31) | Q31: =SUM(M31:P31) | V31: =SUM(R31:U31)
A32: 주식수 | B32: 주당 | C32: 백만주 | D32: 유통주식수 | E32: 19.482 | F32: 23.832 | G32: =F32 | H32: 23.832 | I32: 23.832 | J32: =IFERROR(I32*(1+변수!J40),"") | K32: =IFERROR(J32*(1+변수!K40),"") | L32: =K32 | M32: =IFERROR(K32*(1+변수!M40),"") | N32: =IFERROR(M32*(1+변수!N40),"") | O32: =IFERROR(N32*(1+변수!O40),"") | P32: =IFERROR(O32*(1+변수!P40),"") | Q32: =P32 | R32: =IFERROR(P32*(1+변수!R40),"") | S32: =IFERROR(R32*(1+변수!S40),"") | T32: =IFERROR(S32*(1+변수!T40),"") | U32: =IFERROR(T32*(1+변수!U40),"") | V32: =U32
A33: EPS | B33: 주당 | C33: 원 | D33: EPS | E33: =IFERROR(E20*100/E32,"") | F33: =IFERROR(F20*100/F32,"") | H33: =IFERROR(H20*100/H32,"") | I33: =IFERROR(I20*100/I32,"") | J33: =IFERROR(J20*100/J32,"") | K33: =IFERROR(K20*100/K32,"") | L33: =SUM(H33:K33) | M33: =IFERROR(M20*100/M32,"") | N33: =IFERROR(N20*100/N32,"") | O33: =IFERROR(O20*100/O32,"") | P33: =IFERROR(P20*100/P32,"") | Q33: =SUM(M33:P33) | R33: =IFERROR(R20*100/R32,"") | S33: =IFERROR(S20*100/S32,"") | T33: =IFERROR(T20*100/T32,"") | U33: =IFERROR(U20*100/U32,"") | V33: =SUM(R33:U33)
A34: BPS | B34: 주당 | C34: 원 | D34: BPS | E34: =IFERROR(E25*100/E32,"") | F34: =IFERROR(F25*100/F32,"") | G34: =F34 | H34: =IFERROR(H25*100/H32,"") | I34: =IFERROR(I25*100/I32,"") | J34: =IFERROR(J25*100/J32,"") | K34: =IFERROR(K25*100/K32,"") | L34: =K34 | M34: =IFERROR(M25*100/M32,"") | N34: =IFERROR(N25*100/N32,"") | O34: =IFERROR(O25*100/O32,"") | P34: =IFERROR(P25*100/P32,"") | Q34: =P34 | R34: =IFERROR(R25*100/R32,"") | S34: =IFERROR(S25*100/S32,"") | T34: =IFERROR(T25*100/T32,"") | U34: =IFERROR(U25*100/U32,"") | V34: =U34
A35: DPS | B35: 주당 | C35: 원 | D35: DPS(보통주) | F35: 50 | G35: 50 | K35: =변수!K41 | L35: =SUM(H35:K35) | P35: =변수!P41 | Q35: =SUM(M35:P35) | U35: =변수!U41 | V35: =SUM(R35:U35)
A36: PER | B36: 주당 | C36: 배 | D36: PER | G36: =F36 | I36: =IFERROR(변수!I18/(E33+F33+H33+I33),"") | J36: =IFERROR(변수!$D$44/(F33+H33+I33+J33),"") | K36: =IFERROR(변수!$D$44/(H33+I33+J33+K33),"") | L36: =K36 | M36: =IFERROR(변수!$D$44/(I33+J33+K33+M33),"") | N36: =IFERROR(변수!$D$44/(J33+K33+M33+N33),"") | O36: =IFERROR(변수!$D$44/(K33+M33+N33+O33),"") | P36: =IFERROR(변수!$D$44/(M33+N33+O33+P33),"") | Q36: =P36 | R36: =IFERROR(변수!$D$44/(N33+O33+P33+R33),"") | S36: =IFERROR(변수!$D$44/(O33+P33+R33+S33),"") | T36: =IFERROR(변수!$D$44/(P33+R33+S33+T33),"") | U36: =IFERROR(변수!$D$44/(R33+S33+T33+U33),"") | V36: =U36
A37: PBR | B37: 주당 | C37: 배 | D37: PBR | F37: =IFERROR(변수!F18/F34,"") | G37: =F37 | H37: =IFERROR(변수!H18/H34,"") | I37: =IFERROR(변수!I18/I34,"") | J37: =IFERROR(변수!$D$44/J34,"") | K37: =IFERROR(변수!$D$44/K34,"") | L37: =K37 | M37: =IFERROR(변수!$D$44/M34,"") | N37: =IFERROR(변수!$D$44/N34,"") | O37: =IFERROR(변수!$D$44/O34,"") | P37: =IFERROR(변수!$D$44/P34,"") | Q37: =P37 | R37: =IFERROR(변수!$D$44/R34,"") | S37: =IFERROR(변수!$D$44/S34,"") | T37: =IFERROR(변수!$D$44/T34,"") | U37: =IFERROR(변수!$D$44/U34,"") | V37: =U37
A38: 매출전사 | B38: 사업부 | C38: 억원 | D38: 매출 전사(부문 미분리) | E38: 797.54 | F38: 758.9 | H38: 939.49 | I38: 1063.52 | J38: =IFERROR(J5,"") | K38: =IFERROR(K5,"") | L38: =SUM(H38:K38) | M38: =IFERROR(M5,"") | N38: =IFERROR(N5,"") | O38: =IFERROR(O5,"") | P38: =IFERROR(P5,"") | Q38: =SUM(M38:P38) | R38: =IFERROR(R5,"") | S38: =IFERROR(S5,"") | T38: =IFERROR(T5,"") | U38: =IFERROR(U5,"") | V38: =SUM(R38:U38)
A39: OP전사 | B39: 사업부 | C39: 억원 | D39: OP 전사(부문 미분리) | E39: 14.13 | F39: -21.04 | H39: 9.75 | I39: 13.42 | J39: =IFERROR(J9,"") | K39: =IFERROR(K9,"") | L39: =SUM(H39:K39) | M39: =IFERROR(M9,"") | N39: =IFERROR(N9,"") | O39: =IFERROR(O9,"") | P39: =IFERROR(P9,"") | Q39: =SUM(M39:P39) | R39: =IFERROR(R9,"") | S39: =IFERROR(S9,"") | T39: =IFERROR(T9,"") | U39: =IFERROR(U9,"") | V39: =SUM(R39:U39)
B40: 비율(참고)
...

Sheet 분기
C1: 이름: 분기H — subQ 를 이름으로 VLOOKUP(억원) | E1: 3Q25 | F1: 4Q25 | G1: 1Q26 | H1: 2Q26 | I1: 3Q26 | J1: 4Q26 | K1: 1Q27 | L1: 2Q27 | M1: 3Q27 | N1: 4Q27 | O1: 1Q28 | P1: 2Q28 | Q1: 3Q28 | R1: 4Q28
C2: 종가: | D2: =변수!D44
C3: 기준일: | D3: 20261008 | E3: 1 | F3: 2 | G3: 3 | H3: 4 | I3: 5 | J3: 6 | K3: 7 | L3: 8 | M3: 9 | N3: 10 | O3: 11 | P3: 12 | Q3: 13 | R3: 14
E4: 2025.09 | F4: 2025.12 | G4: 2026.03 | H4: 2026.06 | I4: 2026.09 | J4: 2026.12 | K4: 2027.03 | L4: 2027.06 | M4: 2027.09 | N4: 2027.12 | O4: 2028.03 | P4: 2028.06 | Q4: 2028.09 | R4: 2028.12
A5: 매출액 | D5: 매출액 | E5: =IFERROR(VLOOKUP($A5,subQ,MATCH(E$1,SUBQH,0),0),"") | F5: =IFERROR(VLOOKUP($A5,subQ,MATCH(F$1,SUBQH,0),0),"") | G5: =IFERROR(VLOOKUP($A5,subQ,MATCH(G$1,SUBQH,0),0),"") | H5: =IFERROR(VLOOKUP($A5,subQ,MATCH(H$1,SUBQH,0),0),"") | I5: =IFERROR(VLOOKUP($A5,subQ,MATCH(I$1,SUBQH,0),0),"") | J5: =IFERROR(VLOOKUP($A5,subQ,MATCH(J$1,SUBQH,0),0),"") | K5: =IFERROR(VLOOKUP($A5,subQ,MATCH(K$1,SUBQH,0),0),"") | L5: =IFERROR(VLOOKUP($A5,subQ,MATCH(L$1,SUBQH,0),0),"") | ... R5: =IFERROR(VLOOKUP($A5,subQ,MATCH(R$1,SUBQH,0),0),"")
A6: 매출원가 | D6: 매출원가 | E6: =IFERROR(VLOOKUP($A6,subQ,MATCH(E$1,SUBQH,0),0),"") | F6: =IFERROR(VLOOKUP($A6,subQ,MATCH(F$1,SUBQH,0),0),"") | G6: =IFERROR(VLOOKUP($A6,subQ,MATCH(G$1,SUBQH,0),0),"") | H6: =IFERROR(VLOOKUP($A6,subQ,MATCH(H$1,SUBQH,0),0),"") | I6: =IFERROR(VLOOKUP($A6,subQ,MATCH(I$1,SUBQH,0),0),"") | J6: =IFERROR(VLOOKUP($A6,subQ,MATCH(J$1,SUBQH,0),0),"") | K6: =IFERROR(VLOOKUP($A6,subQ,MATCH(K$1,SUBQH,0),0),"") | L6: =IFERROR(VLOOKUP($A6,subQ,MATCH(L$1,SUBQH,0),0),"") | ... R6: =IFERROR(VLOOKUP($A6,subQ,MATCH(R$1,SUBQH,0),0),"")
A7: 매출총이익 | D7: 매출총이익 | E7: =IFERROR(VLOOKUP($A7,subQ,MATCH(E$1,SUBQH,0),0),"") | F7: =IFERROR(VLOOKUP($A7,subQ,MATCH(F$1,SUBQH,0),0),"") | G7: =IFERROR(VLOOKUP($A7,subQ,MATCH(G$1,SUBQH,0),0),"") | H7: =IFERROR(VLOOKUP($A7,subQ,MATCH(H$1,SUBQH,0),0),"") | I7: =IFERROR(VLOOKUP($A7,subQ,MATCH(I$1,SUBQH,0),0),"") | J7: =IFERROR(VLOOKUP($A7,subQ,MATCH(J$1,SUBQH,0),0),"") | K7: =IFERROR(VLOOKUP($A7,subQ,MATCH(K$1,SUBQH,0),0),"") | L7: =IFERROR(VLOOKUP($A7,subQ,MATCH(L$1,SUBQH,0),0),"") | ... R7: =IFERROR(VLOOKUP($A7,subQ,MATCH(R$1,SUBQH,0),0),"")
A8: 판관비 | D8: 판매비와관리비 | E8: =IFERROR(VLOOKUP($A8,subQ,MATCH(E$1,SUBQH,0),0),"") | F8: =IFERROR(VLOOKUP($A8,subQ,MATCH(F$1,SUBQH,0),0),"") | G8: =IFERROR(VLOOKUP($A8,subQ,MATCH(G$1,SUBQH,0),0),"") | H8: =IFERROR(VLOOKUP($A8,subQ,MATCH(H$1,SUBQH,0),0),"") | I8: =IFERROR(VLOOKUP($A8,subQ,MATCH(I$1,SUBQH,0),0),"") | J8: =IFERROR(VLOOKUP($A8,subQ,MATCH(J$1,SUBQH,0),0),"") | K8: =IFERROR(VLOOKUP($A8,subQ,MATCH(K$1,SUBQH,0),0),"") | L8: =IFERROR(VLOOKUP($A8,subQ,MATCH(L$1,SUBQH,0),0),"") | ... R8: =IFERROR(VLOOKUP($A8,subQ,MATCH(R$1,SUBQH,0),0),"")
A9: 영업이익 | D9: 영업이익 | E9: =IFERROR(VLOOKUP($A9,subQ,MATCH(E$1,SUBQH,0),0),"") | F9: =IFERROR(VLOOKUP($A9,subQ,MATCH(F$1,SUBQH,0),0),"") | G9: =IFERROR(VLOOKUP($A9,subQ,MATCH(G$1,SUBQH,0),0),"") | H9: =IFERROR(VLOOKUP($A9,subQ,MATCH(H$1,SUBQH,0),0),"") | I9: =IFERROR(VLOOKUP($A9,subQ,MATCH(I$1,SUBQH,0),0),"") | J9: =IFERROR(VLOOKUP($A9,subQ,MATCH(J$1,SUBQH,0),0),"") | K9: =IFERROR(VLOOKUP($A9,subQ,MATCH(K$1,SUBQH,0),0),"") | L9: =IFERROR(VLOOKUP($A9,subQ,MATCH(L$1,SUBQH,0),0),"") | ... R9: =IFERROR(VLOOKUP($A9,subQ,MATCH(R$1,SUBQH,0),0),"")
A10: OPM | D10: 영업이익률 | E10: =IFERROR(VLOOKUP($A10,subQ,MATCH(E$1,SUBQH,0),0),"") | F10: =IFERROR(VLOOKUP($A10,subQ,MATCH(F$1,SUBQH,0),0),"") | G10: =IFERROR(VLOOKUP($A10,subQ,MATCH(G$1,SUBQH,0),0),"") | H10: =IFERROR(VLOOKUP($A10,subQ,MATCH(H$1,SUBQH,0),0),"") | I10: =IFERROR(VLOOKUP($A10,subQ,MATCH(I$1,SUBQH,0),0),"") | J10: =IFERROR(VLOOKUP($A10,subQ,MATCH(J$1,SUBQH,0),0),"") | K10: =IFERROR(VLOOKUP($A10,subQ,MATCH(K$1,SUBQH,0),0),"") | L10: =IFERROR(VLOOKUP($A10,subQ,MATCH(L$1,SUBQH,0),0),"") | ... R10: =IFERROR(VLOOKUP($A10,subQ,MATCH(R$1,SUBQH,0),0),"")
A11: 금융손익 | D11: 금융손익(이자·환 포함) | E11: =IFERROR(VLOOKUP($A11,subQ,MATCH(E$1,SUBQH,0),0),"") | F11: =IFERROR(VLOOKUP($A11,subQ,MATCH(F$1,SUBQH,0),0),"") | G11: =IFERROR(VLOOKUP($A11,subQ,MATCH(G$1,SUBQH,0),0),"") | H11: =IFERROR(VLOOKUP($A11,subQ,MATCH(H$1,SUBQH,0),0),"") | I11: =IFERROR(VLOOKUP($A11,subQ,MATCH(I$1,SUBQH,0),0),"") | J11: =IFERROR(VLOOKUP($A11,subQ,MATCH(J$1,SUBQH,0),0),"") | K11: =IFERROR(VLOOKUP($A11,subQ,MATCH(K$1,SUBQH,0),0),"") | L11: =IFERROR(VLOOKUP($A11,subQ,MATCH(L$1,SUBQH,0),0),"") | ... R11: =IFERROR(VLOOKUP($A11,subQ,MATCH(R$1,SUBQH,0),0),"")
A12: 이자손익 | D12: 이자손익(이자수익 − 이자비용) | E12: =IFERROR(VLOOKUP($A12,subQ,MATCH(E$1,SUBQH,0),0),"") | F12: =IFERROR(VLOOKUP($A12,subQ,MATCH(F$1,SUBQH,0),0),"") | G12: =IFERROR(VLOOKUP($A12,subQ,MATCH(G$1,SUBQH,0),0),"") | H12: =IFERROR(VLOOKUP($A12,subQ,MATCH(H$1,SUBQH,0),0),"") | I12: =IFERROR(VLOOKUP($A12,subQ,MATCH(I$1,SUBQH,0),0),"") | J12: =IFERROR(VLOOKUP($A12,subQ,MATCH(J$1,SUBQH,0),0),"") | K12: =IFERROR(VLOOKUP($A12,subQ,MATCH(K$1,SUBQH,0),0),"") | L12: =IFERROR(VLOOKUP($A12,subQ,MATCH(L$1,SUBQH,0),0),"") | ... R12: =IFERROR(VLOOKUP($A12,subQ,MATCH(R$1,SUBQH,0),0),"")
A13: 외환손익 | D13: 외환손익(실적만; 추정 환효과는 환관련손익) | E13: =IFERROR(VLOOKUP($A13,subQ,MATCH(E$1,SUBQH,0),0),"") | F13: =IFERROR(VLOOKUP($A13,subQ,MATCH(F$1,SUBQH,0),0),"") | G13: =IFERROR(VLOOKUP($A13,subQ,MATCH(G$1,SUBQH,0),0),"") | H13: =IFERROR(VLOOKUP($A13,subQ,MATCH(H$1,SUBQH,0),0),"") | I13: =IFERROR(VLOOKUP($A13,subQ,MATCH(I$1,SUBQH,0),0),"") | J13: =IFERROR(VLOOKUP($A13,subQ,MATCH(J$1,SUBQH,0),0),"") | K13: =IFERROR(VLOOKUP($A13,subQ,MATCH(K$1,SUBQH,0),0),"") | L13: =IFERROR(VLOOKUP($A13,subQ,MATCH(L$1,SUBQH,0),0),"") | ... R13: =IFERROR(VLOOKUP($A13,subQ,MATCH(R$1,SUBQH,0),0),"")
A14: 파생상품손익 | D14: 파생상품손익 | E14: =IFERROR(VLOOKUP($A14,subQ,MATCH(E$1,SUBQH,0),0),"") | F14: =IFERROR(VLOOKUP($A14,subQ,MATCH(F$1,SUBQH,0),0),"") | G14: =IFERROR(VLOOKUP($A14,subQ,MATCH(G$1,SUBQH,0),0),"") | H14: =IFERROR(VLOOKUP($A14,subQ,MATCH(H$1,SUBQH,0),0),"") | I14: =IFERROR(VLOOKUP($A14,subQ,MATCH(I$1,SUBQH,0),0),"") | J14: =IFERROR(VLOOKUP($A14,subQ,MATCH(J$1,SUBQH,0),0),"") | K14: =IFERROR(VLOOKUP($A14,subQ,MATCH(K$1,SUBQH,0),0),"") | L14: =IFERROR(VLOOKUP($A14,subQ,MATCH(L$1,SUBQH,0),0),"") | ... R14: =IFERROR(VLOOKUP($A14,subQ,MATCH(R$1,SUBQH,0),0),"")
A15: 기타금융손익 | D15: 기타금융손익(금융손익 잔차) | E15: =IFERROR(VLOOKUP($A15,subQ,MATCH(E$1,SUBQH,0),0),"") | F15: =IFERROR(VLOOKUP($A15,subQ,MATCH(F$1,SUBQH,0),0),"") | G15: =IFERROR(VLOOKUP($A15,subQ,MATCH(G$1,SUBQH,0),0),"") | H15: =IFERROR(VLOOKUP($A15,subQ,MATCH(H$1,SUBQH,0),0),"") | I15: =IFERROR(VLOOKUP($A15,subQ,MATCH(I$1,SUBQH,0),0),"") | J15: =IFERROR(VLOOKUP($A15,subQ,MATCH(J$1,SUBQH,0),0),"") | K15: =IFERROR(VLOOKUP($A15,subQ,MATCH(K$1,SUBQH,0),0),"") | L15: =IFERROR(VLOOKUP($A15,subQ,MATCH(L$1,SUBQH,0),0),"") | ... R15: =IFERROR(VLOOKUP($A15,subQ,MATCH(R$1,SUBQH,0),0),"")
A16: 기타영업외손익 | D16: 기타영업외손익 | E16: =IFERROR(VLOOKUP($A16,subQ,MATCH(E$1,SUBQH,0),0),"") | F16: =IFERROR(VLOOKUP($A16,subQ,MATCH(F$1,SUBQH,0),0),"") | G16: =IFERROR(VLOOKUP($A16,subQ,MATCH(G$1,SUBQH,0),0),"") | H16: =IFERROR(VLOOKUP($A16,subQ,MATCH(H$1,SUBQH,0),0),"") | I16: =IFERROR(VLOOKUP($A16,subQ,MATCH(I$1,SUBQH,0),0),"") | J16: =IFERROR(VLOOKUP($A16,subQ,MATCH(J$1,SUBQH,0),0),"") | K16: =IFERROR(VLOOKUP($A16,subQ,MATCH(K$1,SUBQH,0),0),"") | L16: =IFERROR(VLOOKUP($A16,subQ,MATCH(L$1,SUBQH,0),0),"") | ... R16: =IFERROR(VLOOKUP($A16,subQ,MATCH(R$1,SUBQH,0),0),"")
... A40: NPM | D40: NPM | E40: =IFERROR(VLOOKUP($A40,subQ,MATCH(E$1,SUBQH,0),0),"") | F40: =IFERROR(VLOOKUP($A40,subQ,MATCH(F$1,SUBQH,0),0),"") | G40: =IFERROR(VLOOKUP($A40,subQ,MATCH(G$1,SUBQH,0),0),"") | H40: =IFERROR(VLOOKUP($A40,subQ,MATCH(H$1,SUBQH,0),0),"") | I40: =IFERROR(VLOOKUP($A40,subQ,MATCH(I$1,SUBQH,0),0),"") | J40: =IFERROR(VLOOKUP($A40,subQ,MATCH(J$1,SUBQH,0),0),"") | K40: =IFERROR(VLOOKUP($A40,subQ,MATCH(K$1,SUBQH,0),0),"") | L40: =IFERROR(VLOOKUP($A40,subQ,MATCH(L$1,SUBQH,0),0),"") | ... R40: =IFERROR(VLOOKUP($A40,subQ,MATCH(R$1,SUBQH,0),0),"")
A41: 매출액 YoY | D41: 매출액 YoY | I41: =IFERROR(I5/E5-1,"") | J41: =IFERROR(J5/F5-1,"") | K41: =IFERROR(K5/G5-1,"") | L41: =IFERROR(L5/H5-1,"") | M41: =IFERROR(M5/I5-1,"") | N41: =IFERROR(N5/J5-1,"") | O41: =IFERROR(O5/K5-1,"") | P41: =IFERROR(P5/L5-1,"") | ... R41: =IFERROR(R5/N5-1,"")
A42: 영업이익 YoY | D42: 영업이익 YoY | I42: =IFERROR(I9/E9-1,"") | J42: =IFERROR(J9/F9-1,"") | K42: =IFERROR(K9/G9-1,"") | L42: =IFERROR(L9/H9-1,"") | M42: =IFERROR(M9/I9-1,"") | N42: =IFERROR(N9/J9-1,"") | O42: =IFERROR(O9/K9-1,"") | P42: =IFERROR(P9/L9-1,"") | ... R42: =IFERROR(R9/N9-1,"")
A43: 지배주주순이익 YoY | D43: 지배주주순이익 YoY | I43: =IFERROR(I20/E20-1,"") | J43: =IFERROR(J20/F20-1,"") | K43: =IFERROR(K20/G20-1,"") | L43: =IFERROR(L20/H20-1,"") | M43: =IFERROR(M20/I20-1,"") | N43: =IFERROR(N20/J20-1,"") | O43: =IFERROR(O20/K20-1,"") | P43: =IFERROR(P20/L20-1,"") | ... R43: =IFERROR(R20/N20-1,"")

Sheet 연간예상
C1: 이름: 연간예상H — subQ 를 이름으로 VLOOKUP(억원) | E1: 2025 | F1: 2026 | G1: 2027 | H1: 2028
C2: 종가: | D2: =변수!D44
C3: 기준일: | D3: 20261008 | E3: 1 | F3: 2 | G3: 3 | H3: 4
E4: 2025.12A | F4: 2026.12A | G4: 2027.12A | H4: 2028.12A
A5: 매출액 | D5: 매출액 | E5: =IFERROR(VLOOKUP($A5,subQ,MATCH(E$1,SUBQH,0),0),"") | F5: =IFERROR(VLOOKUP($A5,subQ,MATCH(F$1,SUBQH,0),0),"") | G5: =IFERROR(VLOOKUP($A5,subQ,MATCH(G$1,SUBQH,0),0),"") | H5: =IFERROR(VLOOKUP($A5,subQ,MATCH(H$1,SUBQH,0),0),"")
A6: 매출원가 | D6: 매출원가 | E6: =IFERROR(VLOOKUP($A6,subQ,MATCH(E$1,SUBQH,0),0),"") | F6: =IFERROR(VLOOKUP($A6,subQ,MATCH(F$1,SUBQH,0),0),"") | G6: =IFERROR(VLOOKUP($A6,subQ,MATCH(G$1,SUBQH,0),0),"") | H6: =IFERROR(VLOOKUP($A6,subQ,MATCH(H$1,SUBQH,0),0),"")
A7: 매출총이익 | D7: 매출총이익 | E7: =IFERROR(VLOOKUP($A7,subQ,MATCH(E$1,SUBQH,0),0),"") | F7: =IFERROR(VLOOKUP($A7,subQ,MATCH(F$1,SUBQH,0),0),"") | G7: =IFERROR(VLOOKUP($A7,subQ,MATCH(G$1,SUBQH,0),0),"") | H7: =IFERROR(VLOOKUP($A7,subQ,MATCH(H$1,SUBQH,0),0),"")
A8: 판관비 | D8: 판매비와관리비 | E8: =IFERROR(VLOOKUP($A8,subQ,MATCH(E$1,SUBQH,0),0),"") | F8: =IFERROR(VLOOKUP($A8,subQ,MATCH(F$1,SUBQH,0),0),"") | G8: =IFERROR(VLOOKUP($A8,subQ,MATCH(G$1,SUBQH,0),0),"") | H8: =IFERROR(VLOOKUP($A8,subQ,MATCH(H$1,SUBQH,0),0),"")
A9: 영업이익 | D9: 영업이익 | E9: =IFERROR(VLOOKUP($A9,subQ,MATCH(E$1,SUBQH,0),0),"") | F9: =IFERROR(VLOOKUP($A9,subQ,MATCH(F$1,SUBQH,0),0),"") | G9: =IFERROR(VLOOKUP($A9,subQ,MATCH(G$1,SUBQH,0),0),"") | H9: =IFERROR(VLOOKUP($A9,subQ,MATCH(H$1,SUBQH,0),0),"")
A10: OPM | D10: 영업이익률 | E10: =IFERROR(VLOOKUP($A10,subQ,MATCH(E$1,SUBQH,0),0),"") | F10: =IFERROR(VLOOKUP($A10,subQ,MATCH(F$1,SUBQH,0),0),"") | G10: =IFERROR(VLOOKUP($A10,subQ,MATCH(G$1,SUBQH,0),0),"") | H10: =IFERROR(VLOOKUP($A10,subQ,MATCH(H$1,SUBQH,0),0),"")
A11: 금융손익 | D11: 금융손익(이자·환 포함) | E11: =IFERROR(VLOOKUP($A11,subQ,MATCH(E$1,SUBQH,0),0),"") | F11: =IFERROR(VLOOKUP($A11,subQ,MATCH(F$1,SUBQH,0),0),"") | G11: =IFERROR(VLOOKUP($A11,subQ,MATCH(G$1,SUBQH,0),0),"") | H11: =IFERROR(VLOOKUP($A11,subQ,MATCH(H$1,SUBQH,0),0),"")
A12: 이자손익 | D12: 이자손익(이자수익 − 이자비용) | E12: =IFERROR(VLOOKUP($A12,subQ,MATCH(E$1,SUBQH,0),0),"") | F12: =IFERROR(VLOOKUP($A12,subQ,MATCH(F$1,SUBQH,0),0),"") | G12: =IFERROR(VLOOKUP($A12,subQ,MATCH(G$1,SUBQH,0),0),"") | H12: =IFERROR(VLOOKUP($A12,subQ,MATCH(H$1,SUBQH,0),0),"")
A13: 외환손익 | D13: 외환손익(실적만; 추정 환효과는 환관련손익) | E13: =IFERROR(VLOOKUP($A13,subQ,MATCH(E$1,SUBQH,0),0),"") | F13: =IFERROR(VLOOKUP($A13,subQ,MATCH(F$1,SUBQH,0),0),"") | G13: =IFERROR(VLOOKUP($A13,subQ,MATCH(G$1,SUBQH,0),0),"") | H13: =IFERROR(VLOOKUP($A13,subQ,MATCH(H$1,SUBQH,0),0),"")
A14: 파생상품손익 | D14: 파생상품손익 | E14: =IFERROR(VLOOKUP($A14,subQ,MATCH(E$1,SUBQH,0),0),"") | F14: =IFERROR(VLOOKUP($A14,subQ,MATCH(F$1,SUBQH,0),0),"") | G14: =IFERROR(VLOOKUP($A14,subQ,MATCH(G$1,SUBQH,0),0),"") | H14: =IFERROR(VLOOKUP($A14,subQ,MATCH(H$1,SUBQH,0),0),"")
A15: 기타금융손익 | D15: 기타금융손익(금융손익 잔차) | E15: =IFERROR(VLOOKUP($A15,subQ,MATCH(E$1,SUBQH,0),0),"") | F15: =IFERROR(VLOOKUP($A15,subQ,MATCH(F$1,SUBQH,0),0),"") | G15: =IFERROR(VLOOKUP($A15,subQ,MATCH(G$1,SUBQH,0),0),"") | H15: =IFERROR(VLOOKUP($A15,subQ,MATCH(H$1,SUBQH,0),0),"")
A16: 기타영업외손익 | D16: 기타영업외손익 | E16: =IFERROR(VLOOKUP($A16,subQ,MATCH(E$1,SUBQH,0),0),"") | F16: =IFERROR(VLOOKUP($A16,subQ,MATCH(F$1,SUBQH,0),0),"") | G16: =IFERROR(VLOOKUP($A16,subQ,MATCH(G$1,SUBQH,0),0),"") | H16: =IFERROR(VLOOKUP($A16,subQ,MATCH(H$1,SUBQH,0),0),"")
... A40: NPM | D40: NPM | E40: =IFERROR(VLOOKUP($A40,subQ,MATCH(E$1,SUBQH,0),0),"") | F40: =IFERROR(VLOOKUP($A40,subQ,MATCH(F$1,SUBQH,0),0),"") | G40: =IFERROR(VLOOKUP($A40,subQ,MATCH(G$1,SUBQH,0),0),"") | H40: =IFERROR(VLOOKUP($A40,subQ,MATCH(H$1,SUBQH,0),0),"")
A41: 매출액 YoY | D41: 매출액 YoY | F41: =IFERROR(F5/E5-1,"") | G41: =IFERROR(G5/F5-1,"") | H41: =IFERROR(H5/G5-1,"")
A42: 영업이익 YoY | D42: 영업이익 YoY | F42: =IFERROR(F9/E9-1,"") | G42: =IFERROR(G9/F9-1,"") | H42: =IFERROR(H9/G9-1,"")
A43: 지배주주순이익 YoY | D43: 지배주주순이익 YoY | F43: =IFERROR(F20/E20-1,"") | G43: =IFERROR(G20/F20-1,"") | H43: =IFERROR(H20/G20-1,"")

Sheet TP
B1: 종가 | C1: =변수!D44
B2: 기준일 | C2: =변수!D45
B3: 모델 산출값 — 목표주가·추천 아님. 밴드·COE 는 변수 시트 3절의 가정
C5: FY | D5: 2025 | E5: 2026 | F5: 2027 | G5: 2028
D6: A | E6: E | F6: E | G6: E
C7: EPS(원) | D7: =IFERROR(VLOOKUP("EPS",subQ,MATCH(D$5,SUBQH,0),0),"") | E7: =IFERROR(VLOOKUP("EPS",subQ,MATCH(E$5,SUBQH,0),0),"") | F7: =IFERROR(VLOOKUP("EPS",subQ,MATCH(F$5,SUBQH,0),0),"") | G7: =IFERROR(VLOOKUP("EPS",subQ,MATCH(G$5,SUBQH,0),0),"")
C8: BPS(원) | D8: =IFERROR(VLOOKUP("BPS",subQ,MATCH(D$5,SUBQH,0),0),"") | E8: =IFERROR(VLOOKUP("BPS",subQ,MATCH(E$5,SUBQH,0),0),"") | F8: =IFERROR(VLOOKUP("BPS",subQ,MATCH(F$5,SUBQH,0),0),"") | G8: =IFERROR(VLOOKUP("BPS",subQ,MATCH(G$5,SUBQH,0),0),"")
C9: 지배주주순이익(억원) | D9: =IFERROR(VLOOKUP("지배주주순이익",subQ,MATCH(D$5,SUBQH,0),0),"") | E9: =IFERROR(VLOOKUP("지배주주순이익",subQ,MATCH(E$5,SUBQH,0),0),"") | F9: =IFERROR(VLOOKUP("지배주주순이익",subQ,MATCH(F$5,SUBQH,0),0),"") | G9: =IFERROR(VLOOKUP("지배주주순이익",subQ,MATCH(G$5,SUBQH,0),0),"")
C10: 영업이익(억원) | D10: =IFERROR(VLOOKUP("영업이익",subQ,MATCH(D$5,SUBQH,0),0),"") | E10: =IFERROR(VLOOKUP("영업이익",subQ,MATCH(E$5,SUBQH,0),0),"") | F10: =IFERROR(VLOOKUP("영업이익",subQ,MATCH(F$5,SUBQH,0),0),"") | G10: =IFERROR(VLOOKUP("영업이익",subQ,MATCH(G$5,SUBQH,0),0),"")
C11: ROE(EPS/기초BPS) | E11: =IFERROR(E7/D8,"") | F11: =IFERROR(F7/E8,"") | G11: =IFERROR(G7/F8,"")
B13: PER
C14: 12M fwd EPS | D14: =IFERROR(E7*변수!D50+F7*(1-변수!D50),"")
C15: 적정가치 @PER_lo | D15: =변수!D47 | E15: =IFERROR(ROUND($D$14*D15,-2),"") | F15: =IFERROR(E15/$C$1-1,"") | G15: 배 · 원 · 종가 대비
C16: 적정가치 @PER_mid | D16: =변수!D48 | E16: =IFERROR(ROUND($D$14*D16,-2),"") | F16: =IFERROR(E16/$C$1-1,"") | G16: 배 · 원 · 종가 대비
C17: 적정가치 @PER_hi | D17: =변수!D49 | E17: =IFERROR(ROUND($D$14*D17,-2),"") | F17: =IFERROR(E17/$C$1-1,"") | G17: 배 · 원 · 종가 대비
C18: 현재 PER(종가/12M fwd EPS) | D18: =IFERROR($C$1/$D$14,"")
B20: PBR
C21: 최근 BPS(마지막 실적 분기) | D21: =IFERROR(VLOOKUP("BPS",subQ,MATCH("2Q26",SUBQH,0),0),"")
C22: ROE fwd(12M fwd EPS / BPS) | D22: =IFERROR($D$14/$D$21,"")
C23: COE | D23: =변수!D46
C24: 적정 PBR = ROE/COE | D24: =IFERROR(D22/D23,"")
C25: 적정가치(PBR) = BPS × 적정PBR | D25: =IFERROR(ROUND(D21*D24,-2),"") | E25: =IFERROR(D25/$C$1-1,"")
C26: 현재 PBR(종가/BPS) | D26: =IFERROR($C$1/D21,"")
B28: 모델 json valuation(참고)
C29: eps_fwd12m | D29: 171.4
C30: bps_latest | D30: 4762.2
C31: per_now | D31: 106.42
C32: pbr_now | D32: 3.83
C33: roe_fwd | D33: 0.036
C34: fair_pbr | D34: 0.4
C35: fair_value_pbr | D35: 1900
C36: ev_ebitda
C37: note | D37: 모델 산출값 — 목표주가·추천 아님

Sheet 외화
C1: 이름: 외화QH — 환율 QoQ · 외화 순노출 × Δ기말환율 | E1: 3Q25 | F1: 4Q25 | G1: 1Q26 | H1: 2Q26 | I1: 3Q26 | J1: 4Q26 | K1: 1Q27 | L1: 2Q27 | M1: 3Q27 | N1: 4Q27 | O1: 1Q28 | P1: 2Q28 | Q1: 3Q28 | R1: 4Q28
E3: 1 | F3: 2 | G3: 3 | H3: 4 | I3: 5 | J3: 6 | K3: 7 | L3: 8 | M3: 9 | N3: 10 | O3: 11 | P3: 12 | Q3: 13 | R3: 14
E4: 2025.09 | F4: 2025.12 | G4: 2026.03 | H4: 2026.06 | I4: 2026.09 | J4: 2026.12 | K4: 2027.03 | L4: 2027.06 | M4: 2027.09 | N4: 2027.12 | O4: 2028.03 | P4: 2028.06 | Q4: 2028.09 | R4: 2028.12
D5: 원/달러(평균) | E5: =IFERROR(VLOOKUP($D5,환율,MATCH(E$1,변수H,0),0),"") | F5: =IFERROR(VLOOKUP($D5,환율,MATCH(F$1,변수H,0),0),"") | G5: =IFERROR(VLOOKUP($D5,환율,MATCH(G$1,변수H,0),0),"") | H5: =IFERROR(VLOOKUP($D5,환율,MATCH(H$1,변수H,0),0),"") | I5: =IFERROR(VLOOKUP($D5,환율,MATCH(I$1,변수H,0),0),"") | J5: =IFERROR(VLOOKUP($D5,환율,MATCH(J$1,변수H,0),0),"") | K5: =IFERROR(VLOOKUP($D5,환율,MATCH(K$1,변수H,0),0),"") | L5: =IFERROR(VLOOKUP($D5,환율,MATCH(L$1,변수H,0),0),"") | ... R5: =IFERROR(VLOOKUP($D5,환율,MATCH(R$1,변수H,0),0),"")
A6: 원/달러(평균) QoQ | F6: =IFERROR(F5/E5-1,"") | G6: =IFERROR(G5/F5-1,"") | H6: =IFERROR(H5/G5-1,"") | I6: =IFERROR(I5/H5-1,"") | J6: =IFERROR(J5/I5-1,"") | K6: =IFERROR(K5/J5-1,"") | L6: =IFERROR(L5/K5-1,"") | M6: =IFERROR(M5/L5-1,"") | ... R6: =IFERROR(R5/Q5-1,"")
D7: 원/달러(기말) | E7: =IFERROR(VLOOKUP($D7,환율,MATCH(E$1,변수H,0),0),"") | F7: =IFERROR(VLOOKUP($D7,환율,MATCH(F$1,변수H,0),0),"") | G7: =IFERROR(VLOOKUP($D7,환율,MATCH(G$1,변수H,0),0),"") | H7: =IFERROR(VLOOKUP($D7,환율,MATCH(H$1,변수H,0),0),"") | I7: =IFERROR(VLOOKUP($D7,환율,MATCH(I$1,변수H,0),0),"") | J7: =IFERROR(VLOOKUP($D7,환율,MATCH(J$1,변수H,0),0),"") | K7: =IFERROR(VLOOKUP($D7,환율,MATCH(K$1,변수H,0),0),"") | L7: =IFERROR(VLOOKUP($D7,환율,MATCH(L$1,변수H,0),0),"") | ... R7: =IFERROR(VLOOKUP($D7,환율,MATCH(R$1,변수H,0),0),"")
A8: 원/달러(기말) QoQ | F8: =IFERROR(F7/E7-1,"") | G8: =IFERROR(G7/F7-1,"") | H8: =IFERROR(H7/G7-1,"") | I8: =IFERROR(I7/H7-1,"") | J8: =IFERROR(J7/I7-1,"") | K8: =IFERROR(K7/J7-1,"") | L8: =IFERROR(L7/K7-1,"") | M8: =IFERROR(M7/L7-1,"") | ... R8: =IFERROR(R7/Q7-1,"")
D9: W/Euro(평균) | E9: =IFERROR(VLOOKUP($D9,환율,MATCH(E$1,변수H,0),0),"") | F9: =IFERROR(VLOOKUP($D9,환율,MATCH(F$1,변수H,0),0),"") | G9: =IFERROR(VLOOKUP($D9,환율,MATCH(G$1,변수H,0),0),"") | H9: =IFERROR(VLOOKUP($D9,환율,MATCH(H$1,변수H,0),0),"") | I9: =IFERROR(VLOOKUP($D9,환율,MATCH(I$1,변수H,0),0),"") | J9: =IFERROR(VLOOKUP($D9,환율,MATCH(J$1,변수H,0),0),"") | K9: =IFERROR(VLOOKUP($D9,환율,MATCH(K$1,변수H,0),0),"") | L9: =IFERROR(VLOOKUP($D9,환율,MATCH(L$1,변수H,0),0),"") | ... R9: =IFERROR(VLOOKUP($D9,환율,MATCH(R$1,변수H,0),0),"")
A10: W/Euro(평균) QoQ | F10: =IFERROR(F9/E9-1,"") | G10: =IFERROR(G9/F9-1,"") | H10: =IFERROR(H9/G9-1,"") | I10: =IFERROR(I9/H9-1,"") | J10: =IFERROR(J9/I9-1,"") | K10: =IFERROR(K9/J9-1,"") | L10: =IFERROR(L9/K9-1,"") | M10: =IFERROR(M9/L9-1,"") | ... R10: =IFERROR(R9/Q9-1,"")
D11: W/Euro(기말) | E11: =IFERROR(VLOOKUP($D11,환율,MATCH(E$1,변수H,0),0),"") | F11: =IFERROR(VLOOKUP($D11,환율,MATCH(F$1,변수H,0),0),"") | G11: =IFERROR(VLOOKUP($D11,환율,MATCH(G$1,변수H,0),0),"") | H11: =IFERROR(VLOOKUP($D11,환율,MATCH(H$1,변수H,0),0),"") | I11: =IFERROR(VLOOKUP($D11,환율,MATCH(I$1,변수H,0),0),"") | J11: =IFERROR(VLOOKUP($D11,환율,MATCH(J$1,변수H,0),0),"") | K11: =IFERROR(VLOOKUP($D11,환율,MATCH(K$1,변수H,0),0),"") | L11: =IFERROR(VLOOKUP($D11,환율,MATCH(L$1,변수H,0),0),"") | ... R11: =IFERROR(VLOOKUP($D11,환율,MATCH(R$1,변수H,0),0),"")
A12: W/Euro(기말) QoQ | F12: =IFERROR(F11/E11-1,"") | G12: =IFERROR(G11/F11-1,"") | H12: =IFERROR(H11/G11-1,"") | I12: =IFERROR(I11/H11-1,"") | J12: =IFERROR(J11/I11-1,"") | K12: =IFERROR(K11/J11-1,"") | L12: =IFERROR(L11/K11-1,"") | M12: =IFERROR(M11/L11-1,"") | ... R12: =IFERROR(R11/Q11-1,"")
D13: 원/100Y(기말) | E13: =IFERROR(VLOOKUP($D13,환율,MATCH(E$1,변수H,0),0),"") | F13: =IFERROR(VLOOKUP($D13,환율,MATCH(F$1,변수H,0),0),"") | G13: =IFERROR(VLOOKUP($D13,환율,MATCH(G$1,변수H,0),0),"") | H13: =IFERROR(VLOOKUP($D13,환율,MATCH(H$1,변수H,0),0),"") | I13: =IFERROR(VLOOKUP($D13,환율,MATCH(I$1,변수H,0),0),"") | J13: =IFERROR(VLOOKUP($D13,환율,MATCH(J$1,변수H,0),0),"") | K13: =IFERROR(VLOOKUP($D13,환율,MATCH(K$1,변수H,0),0),"") | L13: =IFERROR(VLOOKUP($D13,환율,MATCH(L$1,변수H,0),0),"") | ... R13: =IFERROR(VLOOKUP($D13,환율,MATCH(R$1,변수H,0),0),"")
