Workbook
Name 변수H: 변수!$C$1:$AO$1
Name 환율: 변수!$C$6:$AO$13
Name BS연결H: BS연결!$C$1:$AO$1
Name BS연결: BS연결!$C$5:$AO$108
Name BS별도H: BS별도!$C$1:$AO$1
Name BS별도: BS별도!$C$5:$AO$91
Name SUBQH: subQ!$A$1:$AO$1
Name subQ: subQ!$A$5:$AO$43

Sheet README
A1: 한화시스템(272210) 실적 모델 — ARGUS 한국조선
A2: 기준 분기 2026Q2 · 마지막 실적 2026Q2 · 생성 2026-10-11
A3: 모든 수치는 모델 산출값(DART 공개 재무제표 + 우리 추정)이다 — 목표주가·투자 추천 아님. 참고용 · 투자조언 아님.
A5: 시트
A6: 변수 가정 시계열. 환율 8행(ECB via frankfurter — L2 fx.json; 추정 분기 = 노란 가정), 추정 드라이버(노란 셀 = 모델값에서 역산한 가정, 바꾸면 재계산; 연녹 셀 = 3절 스칼라 참조 수식), 3절 스칼라 가정(세율·판관비율·지배주주비중·이자율·종가·PER 밴드·COE·외화 순노출·헤지비율)
A7: BS연결/BS별도 FnGuide 계정명 × 기간 값 덤프(백만원). 행1 분기라벨, 행4 YYYY.MM / YYYY.12A. 이름정의 BS연결H·BS연결(계정명 C열부터)
A8: subQ 분기 서브모델(억원 = 백만원/100). 확정 행: =IFERROR(VLOOKUP($D행,BS연결,MATCH(E$1,BS연결H,0),0)/100,"") 추정 행: 변수 시트 가정 셀 참조 수식. 외환손익·파생상품손익은 BS 계정 합·차, 기타금융손익은 잔차, OPM·EPS·BPS·PER·PBR 은 파생 수식
A9: SLS 선표(조선사만, sls json 있을 때): 요약 행(sls 저장값) + 계약별 스케줄(백만$) × (헤지비율 × 헤지환율 + (1−헤지비율) × 건조시점 환율[변수 원/달러(평균)]) → 원화 수식 블록 → 합계 행이 subQ 매출조선에 연결
A10: 시나리오 신규수주 보수/기준/낙관(forecast_panel 패널, 모델에 scenarios 가 있을 때만): 매출액·영업이익 = subQ 기준값 ± (시나리오 신규 − base 신규) × OPM. base 만 subQ 행에 포함, 나머지는 합산 안 함
A11: 분기/연간예상 subQ 를 이름(A열 key)으로 VLOOKUP 한 보고서 표(억원)
A12: TP PER 밴드 × 12M fwd EPS, PBR = ROE/COE × BPS — 모델 산출값 구간, 목표주가·추천 아님
A13: 외화 환율 QoQ, 외화 순노출 × Δ기말환율 → 환관련손익 추정
... A34: 백테스트: {"freeze": "2025Q2", "horizon": 4, "revenue_wape_pct": 15.6, "op_wape_pct": 93.1, "n": 4, "note": "단일 회사 4분기 — 통계 아님", "driver_at_freeze": "trend_seasonal", "selection_oos_at_freeze": {"wape_link": null, "wape_trend": null, "adopted": false, "decision": "rejected", "note": "자격 미달 → 격자·OOS 전 기각"}, "frozen_inputs": "fin(연결/별도)·고객 조선사 모델·지주 자회사 모델은 2025Q2 까지의 분기만; 선표는 체결일 ≤ 2025Q2 말일 계약(원장 최신 금액·코호트 등급, 환산 없음); 잔고는 yards_cache 2025Q2; 시세·환율 forward·prices·forecast_panel 신규수주 미사용. 고객 가중치(suppliers.json 언급 비중)와 합병 체인링크는 현재 지식; 고객 연동 채택은 동결 모델 안에서도 자기 la−4분기 OOS 규칙(selection_oos_at_freeze)", "detail": [{"q": "2025Q3", "rev_pred": 7351.79, "rev_act": 8077.37, "op_pred": 486.18, "op_act": 225.21}, {"q": "2025Q4", "rev_pred": 10729.48, "rev_act": 13981.23, "op_pred": 709.56, "op_act": 57.62}, {"q": "2026Q1", "rev_pred": 7937.57, "rev_act": 8070.99, "op_pred": 524.92, "op_act": 342.84}, {"q": "2026Q2", "rev_pred": 8835.77, "rev_act": 11175.52, "op_pred": 584.32, "op_act": 1036.52}]}

Sheet 변수
C1: 이름: 변수H | E1: 4Q21 | F1: 2021 | G1: 1Q22 | H1: 2Q22 | I1: 3Q22 | J1: 4Q22 | K1: 2022 | L1: 1Q23 | M1: 2Q23 | N1: 3Q23 | O1: 4Q23 | P1: 2023 | Q1: 1Q24 | R1: 2Q24 | S1: 3Q24 | T1: 4Q24 | U1: 2024 | V1: 1Q25 | W1: 2Q25 | X1: 3Q25 | Y1: 4Q25 | Z1: 2025 | AA1: 1Q26 | AB1: 2Q26 | AC1: 3Q26 | AD1: 4Q26 | AE1: 2026 | AF1: 1Q27 | AG1: 2Q27 | AH1: 3Q27 | AI1: 4Q27 | AJ1: 2027 | AK1: 1Q28 | AL1: 2Q28 | AM1: 3Q28 | AN1: 4Q28 | AO1: 2028
A2: 가정 시계열 — 노란 셀은 추정 가정(모델값에서 역산), 연녹 셀은 3절 스칼라 참조 수식. 바꾸면 subQ·분기·연간예상·TP·시나리오가 재계산됩니다.
E3: 1 | F3: 2 | G3: 3 | H3: 4 | I3: 5 | J3: 6 | K3: 7 | L3: 8 | M3: 9 | N3: 10 | O3: 11 | P3: 12 | Q3: 13 | R3: 14 | S3: 15 | T3: 16 | U3: 17 | V3: 18 | W3: 19 | X3: 20 | Y3: 21 | Z3: 22 | AA3: 23 | AB3: 24 | AC3: 25 | AD3: 26 | AE3: 27 | AF3: 28 | AG3: 29 | AH3: 30 | AI3: 31 | AJ3: 32 | AK3: 33 | AL3: 34 | AM3: 35 | AN3: 36 | AO3: 37
E4: 2021.12 | F4: 2021.12A | G4: 2022.03 | H4: 2022.06 | I4: 2022.09 | J4: 2022.12 | K4: 2022.12A | L4: 2023.03 | M4: 2023.06 | N4: 2023.09 | O4: 2023.12 | P4: 2023.12A | Q4: 2024.03 | R4: 2024.06 | S4: 2024.09 | T4: 2024.12 | U4: 2024.12A | V4: 2025.03 | W4: 2025.06 | X4: 2025.09 | Y4: 2025.12 | Z4: 2025.12A | AA4: 2026.03 | AB4: 2026.06 | AC4: 2026.09 | AD4: 2026.12 | AE4: 2026.12A | AF4: 2027.03 | AG4: 2027.06 | AH4: 2027.09 | AI4: 2027.12 | AJ4: 2027.12A | AK4: 2028.03 | AL4: 2028.06 | AM4: 2028.09 | AN4: 2028.12 | AO4: 2028.12A
B5: 1. FX | C5: 이름: 환율
A6: USDKRW_avg | C6: 원/달러(평균) | E6: 1183.5 | F6: 1145.51 | G6: 1205.78 | H6: 1262.09 | I6: 1341.93 | J6: 1360.12 | K6: 1292.98 | L6: 1276.95 | M6: 1315.69 | N6: 1313.62 | O6: 1322.01 | P6: 1306.85 | Q6: 1330.14 | R6: 1371.28 | S6: 1356.22 | T6: 1396.3 | U6: 1363.53 | V6: 1452.28 | W6: 1398.52 | X6: 1386.95 | Y6: 1449.19 | Z6: 1421.52 | AA6: 1466.12 | AB6: 1501.75 | AC6: 1418.75 | AD6: 1345.14 | AE6: 1457.21 | AF6: 1341.49 | AG6: 1341.49 | AH6: 1341.49 | AI6: 1341.49 | AK6: 1341.49 | AL6: 1341.49 | AM6: 1341.49 | AN6: 1341.49
A7: USDKRW_end | C7: 원/달러(기말) | E7: 1188.75 | F7: 1188.75 | G7: 1213.74 | H7: 1301.24 | I7: 1436.9 | J7: 1260.16 | K7: 1260.16 | L7: 1305.99 | M7: 1321.44 | N7: 1345.35 | O7: 1297.43 | P7: 1297.43 | Q7: 1349.25 | R7: 1377.73 | S7: 1312.17 | T7: 1474.78 | U7: 1474.78 | V7: 1474.54 | W7: 1355.13 | X7: 1403.67 | Y7: 1444.2 | Z7: 1444.2 | AA7: 1524.8 | AB7: 1550.89 | AC7: 1355.4 | AD7: 1341.49 | AE7: 1341.49 | AF7: 1341.49 | AG7: 1341.49 | AH7: 1341.49 | AI7: 1341.49 | AK7: 1341.49 | AL7: 1341.49 | AM7: 1341.49 | AN7: 1341.49
A8: JPY100KRW_avg | C8: 원/100Y(평균) | E8: 1041.02 | F8: 1042.74 | G8: 1036.79 | H8: 972.23 | I8: 970.61 | J8: 961.03 | K8: 985.1 | L8: 964.89 | M8: 957.36 | N8: 909 | O8: 893.22 | P8: 931.11 | Q8: 896.29 | R8: 880.14 | S8: 909.35 | T8: 917.25 | U8: 900.92 | V8: 952.59 | W8: 967.92 | X8: 940.32 | Y8: 940.77 | Z8: 950.17 | AA8: 934.39 | AB8: 942.16 | AC8: 890.41 | AD8: 850.79 | AE8: 919.21 | AF8: 847.7 | AG8: 847.7 | AH8: 847.7 | AI8: 847.7 | AK8: 847.7 | AL8: 847.7 | AM8: 847.7 | AN8: 847.7
A9: JPY100KRW_end | C9: 원/100Y(기말) | E9: 1032.62 | F9: 1032.62 | G9: 996.83 | H9: 954.9 | I9: 993.29 | J9: 955.54 | K9: 955.54 | L9: 980.62 | M9: 913.67 | N9: 901.47 | O9: 917.04 | P9: 917.04 | Q9: 892.42 | R9: 857.76 | S9: 919.21 | T9: 939.65 | U9: 939.65 | V9: 986.84 | W9: 938.85 | X9: 948.49 | Y9: 921.81 | Z9: 921.81 | AA9: 955.99 | AB9: 954.75 | AC9: 863.31 | AD9: 847.7 | AE9: 847.7 | AF9: 847.7 | AG9: 847.7 | AH9: 847.7 | AI9: 847.7 | AK9: 847.7 | AL9: 847.7 | AM9: 847.7 | AN9: 847.7
A10: EURKRW_avg | C10: W/Euro(평균) | E10: 1353.32 | F10: 1354.06 | G10: 1352.29 | H10: 1343.31 | I10: 1350.63 | J10: 1386.07 | K10: 1358.07 | L10: 1369.93 | M10: 1432.41 | N10: 1429.41 | O10: 1420.91 | P10: 1412.88 | Q10: 1444.21 | R10: 1476.42 | S10: 1489.3 | T10: 1490.78 | U10: 1475.4 | V10: 1528.33 | W10: 1585.13 | X10: 1620.04 | Y10: 1686.02 | Z10: 1605.45 | AA10: 1715.47 | AB10: 1746.09 | AC10: 1631.97 | AD10: 1509.74 | AE10: 1689.95 | AF10: 1503.27 | AG10: 1503.27 | AH10: 1503.27 | AI10: 1503.27 | AK10: 1503.27 | AL10: 1503.27 | AM10: 1503.27 | AN10: 1503.27
A11: EURKRW_end | C11: W/Euro(기말) | E11: 1346.38 | F11: 1346.38 | G11: 1347.37 | H11: 1351.6 | I11: 1400.62 | J11: 1344.08 | K11: 1344.08 | L11: 1420.26 | M11: 1435.88 | N11: 1425.26 | O11: 1433.66 | P11: 1433.66 | Q11: 1458.68 | R11: 1474.86 | S11: 1469.1 | T11: 1532.14 | U11: 1532.14 | V11: 1594.72 | W11: 1588.22 | X11: 1648.04 | Y11: 1696.94 | Z11: 1696.94 | AA11: 1753.21 | AB11: 1767.09 | AC11: 1539.06 | AD11: 1503.27 | AE11: 1503.27 | AF11: 1503.27 | AG11: 1503.27 | AH11: 1503.27 | AI11: 1503.27 | AK11: 1503.27 | AL11: 1503.27 | AM11: 1503.27 | AN11: 1503.27
A12: CNYKRW_avg | C12: 원/중국원(평균) | E12: 185.14 | F12: 177.65 | G12: 189.93 | H12: 190.76 | I12: 195.79 | J12: 191.09 | K12: 191.93 | L12: 186.59 | M12: 187.45 | N12: 181.28 | O12: 182.86 | P12: 184.52 | Q12: 185.04 | R12: 189.35 | S12: 189.24 | T12: 194.24 | U12: 189.49 | V12: 199.63 | W12: 193.41 | X12: 193.79 | Y12: 204.38 | Z12: 197.8 | AA12: 211.75 | AB12: 220.8 | AC12: 210.43 | AD12: 200.69 | AE12: 213.75 | AF12: 200.46 | AG12: 200.46 | AH12: 200.46 | AI12: 200.46 | AK12: 200.46 | AL12: 200.46 | AM12: 200.46 | AN12: 200.46
A13: CNYKRW_end | C13: 원/중국원(기말) | E13: 187.13 | F13: 187.13 | G13: 191.38 | H13: 194.13 | I13: 201.92 | J13: 182.67 | K13: 182.67 | L13: 189.97 | M13: 181.8 | N13: 184.26 | O13: 182.61 | P13: 182.61 | Q13: 186.66 | R13: 189.7 | S13: 187.12 | T13: 202.04 | U13: 202.04 | V13: 203.3 | W13: 189.14 | X13: 197.16 | Y13: 206.28 | Z13: 206.28 | AA13: 220.97 | AB13: 228.56 | AC13: 202.16 | AD13: 200.46 | AE13: 200.46 | AF13: 200.46 | AG13: 200.46 | AH13: 200.46 | AI13: 200.46 | AK13: 200.46 | AL13: 200.46 | AM13: 200.46 | AN13: 200.46
B14: 1b. 종가
A15: price_close_end | C15: 종가(기말) | E15: 16000 | G15: 16400 | H15: 13950 | I15: 11050 | J15: 10550 | L15: 13860 | M15: 14600 | N15: 12270 | O15: 17360 | Q15: 17170 | R15: 18860 | S15: 17880 | T15: 22600 | V15: 32100 | W15: 58000 | X15: 59500 | Y15: 54400 | AA15: 114100 | AB15: 73000 | AC15: 75200 | AD15: 76700
A16: price_high | C16: 종가(최고) | E16: 18100 | G16: 18400 | H16: 17100 | I16: 16200 | J16: 12600 | L16: 14240 | M16: 15700 | N16: 17720 | O16: 17500 | Q16: 19910 | R16: 22450 | S16: 23400 | T16: 30200 | V16: 43400 | W16: 70200 | X16: 62000 | Y16: 65900 | AA16: 184000 | AB16: 138900 | AC16: 87900 | AD16: 89600
A17: price_low | C17: 종가(최저) | E17: 13850 | G17: 14000 | H17: 12750 | I17: 10650 | J17: 10150 | L17: 10200 | M17: 13610 | N17: 12050 | O17: 11530 | Q17: 14950 | R17: 16170 | S17: 16530 | T17: 17460 | V17: 22550 | W17: 30100 | X17: 47550 | Y17: 44750 | AA17: 54400 | AB17: 70700 | AC17: 50700 | AD17: 72500
A18: price_avg | C18: 종가(평균) | E18: 15928.6 | G18: 15916.1 | H18: 15483.9 | I18: 14063.5 | J18: 11266.1 | L18: 12469.4 | M18: 14381.1 | N18: 14105.6 | O18: 14439.7 | Q18: 17156.6 | R18: 18262.5 | S18: 18915 | T18: 21548.7 | V18: 30619 | W18: 45727.5 | X18: 55034.6 | Y18: 52632.2 | AA18: 109610.2 | AB18: 110444.3 | AC18: 70688.7 | AD18: 79380
B20: 2. 추정 드라이버 | C20: 실적 열 = subQ 실현값(수식), 추정 열 = 가정(노란 = 모델값 역산, 연녹 = 3절 스칼라 참조)
A21: drv:매출액 | B21: yoy | C21: 매출액 YoY | J21: =IFERROR(subQ!J5/subQ!E5-1,"") | L21: =IFERROR(subQ!L5/subQ!G5-1,"") | M21: =IFERROR(subQ!M5/subQ!H5-1,"") | N21: =IFERROR(subQ!N5/subQ!I5-1,"") | O21: =IFERROR(subQ!O5/subQ!J5-1,"") | Q21: =IFERROR(subQ!Q5/subQ!L5-1,"") | R21: =IFERROR(subQ!R5/subQ!M5-1,"") | S21: =IFERROR(subQ!S5/subQ!N5-1,"") | T21: =IFERROR(subQ!T5/subQ!O5-1,"") | V21: =IFERROR(subQ!V5/subQ!Q5-1,"") | W21: =IFERROR(subQ!W5/subQ!R5-1,"") | X21: =IFERROR(subQ!X5/subQ!S5-1,"") | Y21: =IFERROR(subQ!Y5/subQ!T5-1,"") | AA21: =IFERROR(subQ!AA5/subQ!V5-1,"") | AB21: =IFERROR(subQ!AB5/subQ!W5-1,"") | AC21: 0.36307186 | AD21: 0.36307204 | AF21: 0.36307162 | AG21: 0.36307166 | AH21: 0.18153629 | AI21: 0.18153612 | AK21: 0.18153607 | AL21: 0.18153644 | AM21: 0.090768137 | AN21: 0.090767743
A22: drv:판관비 | B22: ratio | C22: 판관비율(/매출) | E22: =IFERROR(subQ!E8/subQ!E5,"") | F22: =IFERROR(subQ!F8/subQ!F5,"") | G22: =IFERROR(subQ!G8/subQ!G5,"") | H22: =IFERROR(subQ!H8/subQ!H5,"") | I22: =IFERROR(subQ!I8/subQ!I5,"") | J22: =IFERROR(subQ!J8/subQ!J5,"") | K22: =IFERROR(subQ!K8/subQ!K5,"") | L22: =IFERROR(subQ!L8/subQ!L5,"") | ... AB22: =IFERROR(subQ!AB8/subQ!AB5,"") | AC22: =$D$52 | AD22: =$D$52 | AE22: =IFERROR(subQ!AE8/subQ!AE5,"") | AF22: =$D$52 | AG22: =$D$52 | AH22: =$D$52 | AI22: =$D$52 | AJ22: =IFERROR(subQ!AJ8/subQ!AJ5,"") | AK22: =$D$52 | AL22: =$D$52 | AM22: =$D$52 | AN22: =$D$52 | AO22: =IFERROR(subQ!AO8/subQ!AO5,"")
A23: drv:영업이익 | B23: ratio | C23: 영업이익률(OPM) | E23: =IFERROR(subQ!E9/subQ!E5,"") | F23: =IFERROR(subQ!F9/subQ!F5,"") | G23: =IFERROR(subQ!G9/subQ!G5,"") | H23: =IFERROR(subQ!H9/subQ!H5,"") | I23: =IFERROR(subQ!I9/subQ!I5,"") | J23: =IFERROR(subQ!J9/subQ!J5,"") | K23: =IFERROR(subQ!K9/subQ!K5,"") | L23: =IFERROR(subQ!L9/subQ!L5,"") | ... AB23: =IFERROR(subQ!AB9/subQ!AB5,"") | AC23: 0.044952648 | AD23: 0.044952045 | AE23: =IFERROR(subQ!AE9/subQ!AE5,"") | AF23: 0.044952706 | AG23: 0.044952317 | AH23: 0.044952052 | AI23: 0.044952198 | AJ23: =IFERROR(subQ!AJ9/subQ!AJ5,"") | AK23: 0.044952179 | AL23: 0.044952379 | AM23: 0.044952158 | AN23: 0.044952434 | AO23: =IFERROR(subQ!AO9/subQ!AO5,"")
A24: drv:외환손익 | B24: abs | C24: 외환손익 (가정, 억원) | E24: =subQ!E13 | F24: =subQ!F13 | G24: =subQ!G13 | H24: =subQ!H13 | I24: =subQ!I13 | J24: =subQ!J13 | K24: =subQ!K13 | L24: =subQ!L13 | ... AB24: =subQ!AB13 | AC24: 0 | AD24: 0 | AE24: =subQ!AE13 | AF24: 0 | AG24: 0 | AH24: 0 | AI24: 0 | AJ24: =subQ!AJ13 | AK24: 0 | AL24: 0 | AM24: 0 | AN24: 0 | AO24: =subQ!AO13
A25: drv:기타금융손익 | B25: abs | C25: 기타금융손익 (가정, 억원) | E25: =subQ!E14 | F25: =subQ!F14 | G25: =subQ!G14 | H25: =subQ!H14 | I25: =subQ!I14 | J25: =subQ!J14 | K25: =subQ!K14 | L25: =subQ!L14 | ... AB25: =subQ!AB14 | AC25: 44.45 | AD25: 44.45 | AE25: =subQ!AE14 | AF25: 44.45 | AG25: 44.45 | AH25: 44.45 | AI25: 44.45 | AJ25: =subQ!AJ14 | AK25: 44.45 | AL25: 44.45 | AM25: 44.45 | AN25: 44.45 | AO25: =subQ!AO14
A26: drv:기타영업외손익 | B26: abs | C26: 기타영업외손익 (가정, 억원) | E26: =subQ!E15 | F26: =subQ!F15 | G26: =subQ!G15 | H26: =subQ!H15 | I26: =subQ!I15 | J26: =subQ!J15 | K26: =subQ!K15 | L26: =subQ!L15 | ... AB26: =subQ!AB15 | AC26: 0 | AD26: 0 | AE26: =subQ!AE15 | AF26: 0 | AG26: 0 | AH26: 0 | AI26: 0 | AJ26: =subQ!AJ15 | AK26: 0 | AL26: 0 | AM26: 0 | AN26: 0 | AO26: =subQ!AO15
A27: drv:지분법손익 | B27: abs | C27: 지분법손익 (가정, 억원) | E27: =subQ!E16 | F27: =subQ!F16 | G27: =subQ!G16 | H27: =subQ!H16 | I27: =subQ!I16 | J27: =subQ!J16 | K27: =subQ!K16 | L27: =subQ!L16 | ... AB27: =subQ!AB16 | AC27: -12.11 | AD27: -12.11 | AE27: =subQ!AE16 | AF27: -12.11 | AG27: -12.11 | AH27: -12.11 | AI27: -12.11 | AJ27: =subQ!AJ16 | AK27: -12.11 | AL27: -12.11 | AM27: -12.11 | AN27: -12.11 | AO27: =subQ!AO16
A28: drv:법인세비용 | B28: tax | C28: 법인세율(/세전) — 법인세 = MAX(세전,0) × 세율 | E28: =IFERROR(subQ!E18/subQ!E17,"") | F28: =IFERROR(subQ!F18/subQ!F17,"") | G28: =IFERROR(subQ!G18/subQ!G17,"") | H28: =IFERROR(subQ!H18/subQ!H17,"") | I28: =IFERROR(subQ!I18/subQ!I17,"") | J28: =IFERROR(subQ!J18/subQ!J17,"") | K28: =IFERROR(subQ!K18/subQ!K17,"") | L28: =IFERROR(subQ!L18/subQ!L17,"") | ... AB28: =IFERROR(subQ!AB18/subQ!AB17,"") | AC28: =$D$51 | AD28: =$D$51 | AE28: =IFERROR(subQ!AE18/subQ!AE17,"") | AF28: =$D$51 | AG28: =$D$51 | AH28: =$D$51 | AI28: =$D$51 | AJ28: =IFERROR(subQ!AJ18/subQ!AJ17,"") | AK28: =$D$51 | AL28: =$D$51 | AM28: =$D$51 | AN28: =$D$51 | AO28: =IFERROR(subQ!AO18/subQ!AO17,"")
A29: drv:지배주주순이익 | B29: ratio | C29: 지배주주 비중(/당기순이익) | E29: =IFERROR(subQ!E20/subQ!E19,"") | F29: =IFERROR(subQ!F20/subQ!F19,"") | G29: =IFERROR(subQ!G20/subQ!G19,"") | H29: =IFERROR(subQ!H20/subQ!H19,"") | I29: =IFERROR(subQ!I20/subQ!I19,"") | J29: =IFERROR(subQ!J20/subQ!J19,"") | K29: =IFERROR(subQ!K20/subQ!K19,"") | L29: =IFERROR(subQ!L20/subQ!L19,"") | ... AB29: =IFERROR(subQ!AB20/subQ!AB19,"") | AC29: =$D$53 | AD29: =$D$53 | AE29: =IFERROR(subQ!AE20/subQ!AE19,"") | AF29: =$D$53 | AG29: =$D$53 | AH29: =$D$53 | AI29: =$D$53 | AJ29: =IFERROR(subQ!AJ20/subQ!AJ19,"") | AK29: =$D$53 | AL29: =$D$53 | AM29: =$D$53 | AN29: =$D$53 | AO29: =IFERROR(subQ!AO20/subQ!AO19,"")
A30: drv:중단사업이익 | B30: abs | C30: 중단사업이익 (가정, 억원) | E30: =subQ!E21 | F30: =subQ!F21 | G30: =subQ!G21 | H30: =subQ!H21 | I30: =subQ!I21 | J30: =subQ!J21 | K30: =subQ!K21 | L30: =subQ!L21 | ... AB30: =subQ!AB21 | AE30: =subQ!AE21 | AJ30: =subQ!AJ21 | AO30: =subQ!AO21
A31: drv:부채총계 | B31: qoq | C31: 부채총계 QoQ | G31: =IFERROR(subQ!G23/subQ!E23-1,"") | H31: =IFERROR(subQ!H23/subQ!G23-1,"") | I31: =IFERROR(subQ!I23/subQ!H23-1,"") | J31: =IFERROR(subQ!J23/subQ!I23-1,"") | L31: =IFERROR(subQ!L23/subQ!J23-1,"") | M31: =IFERROR(subQ!M23/subQ!L23-1,"") | N31: =IFERROR(subQ!N23/subQ!M23-1,"") | O31: =IFERROR(subQ!O23/subQ!N23-1,"") | Q31: =IFERROR(subQ!Q23/subQ!O23-1,"") | R31: =IFERROR(subQ!R23/subQ!Q23-1,"") | S31: =IFERROR(subQ!S23/subQ!R23-1,"") | T31: =IFERROR(subQ!T23/subQ!S23-1,"") | V31: =IFERROR(subQ!V23/subQ!T23-1,"") | W31: =IFERROR(subQ!W23/subQ!V23-1,"") | X31: =IFERROR(subQ!X23/subQ!W23-1,"") | Y31: =IFERROR(subQ!Y23/subQ!X23-1,"") | AA31: =IFERROR(subQ!AA23/subQ!Y23-1,"") | AB31: =IFERROR(subQ!AB23/subQ!AA23-1,"") | AC31: -2.3e-08 | AD31: 0 | AF31: 0 | AG31: 0 | AH31: 0 | AI31: 0 | AK31: 0 | AL31: 0 | AM31: 0 | AN31: 0
A32: drv:자본총계 | B32: roll | C32: 자본총계 기타변동(배당 등, 억원) | G32: =IFERROR(subQ!E24+subQ!G19-subQ!G24,"") | H32: =IFERROR(subQ!G24+subQ!H19-subQ!H24,"") | I32: =IFERROR(subQ!H24+subQ!I19-subQ!I24,"") | J32: =IFERROR(subQ!I24+subQ!J19-subQ!J24,"") | L32: =IFERROR(subQ!J24+subQ!L19-subQ!L24,"") | M32: =IFERROR(subQ!L24+subQ!M19-subQ!M24,"") | N32: =IFERROR(subQ!M24+subQ!N19-subQ!N24,"") | O32: =IFERROR(subQ!N24+subQ!O19-subQ!O24,"") | Q32: =IFERROR(subQ!O24+subQ!Q19-subQ!Q24,"") | R32: =IFERROR(subQ!Q24+subQ!R19-subQ!R24,"") | S32: =IFERROR(subQ!R24+subQ!S19-subQ!S24,"") | T32: =IFERROR(subQ!S24+subQ!T19-subQ!T24,"") | V32: =IFERROR(subQ!T24+subQ!V19-subQ!V24,"") | W32: =IFERROR(subQ!V24+subQ!W19-subQ!W24,"") | X32: =IFERROR(subQ!W24+subQ!X19-subQ!X24,"") | Y32: =IFERROR(subQ!X24+subQ!Y19-subQ!Y24,"") | AA32: =IFERROR(subQ!Y24+subQ!AA19-subQ!AA24,"") | AB32: =IFERROR(subQ!AA24+subQ!AB19-subQ!AB24,"") | AC32: 0.006716294 | AD32: -0.005551901 | AF32: 0.005733464 | AG32: 934.96971 | AH32: -0.006163254 | AI32: 0.002632521 | AK32: -0.00466542 | AL32: 934.97461 | AM32: -0.005038271 | AN32: 0.003419515
A33: drv:지배주주지분 | B33: roll | C33: 지배주주지분 기타변동(배당 등, 억원) | G33: =IFERROR(subQ!E25+subQ!G20-subQ!G25,"") | H33: =IFERROR(subQ!G25+subQ!H20-subQ!H25,"") | I33: =IFERROR(subQ!H25+subQ!I20-subQ!I25,"") | J33: =IFERROR(subQ!I25+subQ!J20-subQ!J25,"") | L33: =IFERROR(subQ!J25+subQ!L20-subQ!L25,"") | M33: =IFERROR(subQ!L25+subQ!M20-subQ!M25,"") | N33: =IFERROR(subQ!M25+subQ!N20-subQ!N25,"") | O33: =IFERROR(subQ!N25+subQ!O20-subQ!O25,"") | Q33: =IFERROR(subQ!O25+subQ!Q20-subQ!Q25,"") | R33: =IFERROR(subQ!Q25+subQ!R20-subQ!R25,"") | S33: =IFERROR(subQ!R25+subQ!S20-subQ!S25,"") | T33: =IFERROR(subQ!S25+subQ!T20-subQ!T25,"") | V33: =IFERROR(subQ!T25+subQ!V20-subQ!V25,"") | W33: =IFERROR(subQ!V25+subQ!W20-subQ!W25,"") | X33: =IFERROR(subQ!W25+subQ!X20-subQ!X25,"") | Y33: =IFERROR(subQ!X25+subQ!Y20-subQ!Y25,"") | AA33: =IFERROR(subQ!Y25+subQ!AA20-subQ!AA25,"") | AB33: =IFERROR(subQ!AA25+subQ!AB20-subQ!AB25,"") | AC33: 0.006816294 | AD33: -0.005551901 | AF33: 0.005733464 | AG33: 934.96971 | AH33: -0.006163254 | AI33: 0.002632521 | AK33: -0.00466542 | AL33: 934.97461 | AM33: -0.005038271 | AN33: 0.003419515
A34: drv:총차입금 | B34: qoq | C34: 총차입금 QoQ | G34: =IFERROR(subQ!G26/subQ!E26-1,"") | H34: =IFERROR(subQ!H26/subQ!G26-1,"") | I34: =IFERROR(subQ!I26/subQ!H26-1,"") | J34: =IFERROR(subQ!J26/subQ!I26-1,"") | L34: =IFERROR(subQ!L26/subQ!J26-1,"") | M34: =IFERROR(subQ!M26/subQ!L26-1,"") | N34: =IFERROR(subQ!N26/subQ!M26-1,"") | O34: =IFERROR(subQ!O26/subQ!N26-1,"") | Q34: =IFERROR(subQ!Q26/subQ!O26-1,"") | R34: =IFERROR(subQ!R26/subQ!Q26-1,"") | S34: =IFERROR(subQ!S26/subQ!R26-1,"") | T34: =IFERROR(subQ!T26/subQ!S26-1,"") | V34: =IFERROR(subQ!V26/subQ!T26-1,"") | W34: =IFERROR(subQ!W26/subQ!V26-1,"") | X34: =IFERROR(subQ!X26/subQ!W26-1,"") | Y34: =IFERROR(subQ!Y26/subQ!X26-1,"") | AA34: =IFERROR(subQ!AA26/subQ!Y26-1,"") | AB34: =IFERROR(subQ!AB26/subQ!AA26-1,"") | AC34: 1.07e-07 | AD34: 0 | AF34: 0 | AG34: 0 | AH34: 0 | AI34: 0 | AK34: 0 | AL34: 0 | AM34: 0 | AN34: 0
A35: drv:순차입금 | B35: qoq | C35: 순차입금 QoQ | G35: =IFERROR(subQ!G27/subQ!E27-1,"") | H35: =IFERROR(subQ!H27/subQ!G27-1,"") | I35: =IFERROR(subQ!I27/subQ!H27-1,"") | J35: =IFERROR(subQ!J27/subQ!I27-1,"") | L35: =IFERROR(subQ!L27/subQ!J27-1,"") | M35: =IFERROR(subQ!M27/subQ!L27-1,"") | N35: =IFERROR(subQ!N27/subQ!M27-1,"") | O35: =IFERROR(subQ!O27/subQ!N27-1,"") | Q35: =IFERROR(subQ!Q27/subQ!O27-1,"") | R35: =IFERROR(subQ!R27/subQ!Q27-1,"") | S35: =IFERROR(subQ!S27/subQ!R27-1,"") | T35: =IFERROR(subQ!T27/subQ!S27-1,"") | V35: =IFERROR(subQ!V27/subQ!T27-1,"") | W35: =IFERROR(subQ!W27/subQ!V27-1,"") | X35: =IFERROR(subQ!X27/subQ!W27-1,"") | Y35: =IFERROR(subQ!Y27/subQ!X27-1,"") | AA35: =IFERROR(subQ!AA27/subQ!Y27-1,"") | AB35: =IFERROR(subQ!AB27/subQ!AA27-1,"") | AC35: -0.014903231 | AD35: -0.033179638 | AF35: -0.015863892 | AG35: 0.033617672 | AH35: -0.020075961 | AI35: -0.042626327 | AK35: -0.021686121 | AL35: 0.028336713 | AM35: -0.024394462 | AN35: -0.050709194
A36: drv:이자발생자산 | B36: qoq | C36: 이자발생자산 QoQ | G36: =IFERROR(subQ!G28/subQ!E28-1,"") | H36: =IFERROR(subQ!H28/subQ!G28-1,"") | I36: =IFERROR(subQ!I28/subQ!H28-1,"") | J36: =IFERROR(subQ!J28/subQ!I28-1,"") | L36: =IFERROR(subQ!L28/subQ!J28-1,"") | M36: =IFERROR(subQ!M28/subQ!L28-1,"") | N36: =IFERROR(subQ!N28/subQ!M28-1,"") | O36: =IFERROR(subQ!O28/subQ!N28-1,"") | Q36: =IFERROR(subQ!Q28/subQ!O28-1,"") | R36: =IFERROR(subQ!R28/subQ!Q28-1,"") | S36: =IFERROR(subQ!S28/subQ!R28-1,"") | T36: =IFERROR(subQ!T28/subQ!S28-1,"") | V36: =IFERROR(subQ!V28/subQ!T28-1,"") | W36: =IFERROR(subQ!W28/subQ!V28-1,"") | X36: =IFERROR(subQ!X28/subQ!W28-1,"") | Y36: =IFERROR(subQ!Y28/subQ!X28-1,"") | AA36: =IFERROR(subQ!AA28/subQ!Y28-1,"") | AB36: =IFERROR(subQ!AB28/subQ!AA28-1,"") | AC36: 0.011489923 | AD36: 0.024912798 | AF36: 0.0112362 | AG36: -0.023172876 | AH36: 0.014642576 | AI36: 0.030027431 | AK36: 0.014198263 | AL36: -0.017896208 | AM36: 0.016131673 | AN36: 0.032197086
A37: drv:현금및현금성자산 | B37: qoq | C37: 현금및현금성자산 QoQ | G37: =IFERROR(subQ!G29/subQ!E29-1,"") | H37: =IFERROR(subQ!H29/subQ!G29-1,"") | I37: =IFERROR(subQ!I29/subQ!H29-1,"") | J37: =IFERROR(subQ!J29/subQ!I29-1,"") | L37: =IFERROR(subQ!L29/subQ!J29-1,"") | M37: =IFERROR(subQ!M29/subQ!L29-1,"") | N37: =IFERROR(subQ!N29/subQ!M29-1,"") | O37: =IFERROR(subQ!O29/subQ!N29-1,"") | Q37: =IFERROR(subQ!Q29/subQ!O29-1,"") | R37: =IFERROR(subQ!R29/subQ!Q29-1,"") | S37: =IFERROR(subQ!S29/subQ!R29-1,"") | T37: =IFERROR(subQ!T29/subQ!S29-1,"") | V37: =IFERROR(subQ!V29/subQ!T29-1,"") | W37: =IFERROR(subQ!W29/subQ!V29-1,"") | X37: =IFERROR(subQ!X29/subQ!W29-1,"") | Y37: =IFERROR(subQ!Y29/subQ!X29-1,"") | AA37: =IFERROR(subQ!AA29/subQ!Y29-1,"") | AB37: =IFERROR(subQ!AB29/subQ!AA29-1,"")
A38: drv:CAPEX | B38: yoy | C38: CAPEX YoY | J38: =IFERROR(subQ!J30/subQ!E30-1,"") | L38: =IFERROR(subQ!L30/subQ!G30-1,"") | M38: =IFERROR(subQ!M30/subQ!H30-1,"") | N38: =IFERROR(subQ!N30/subQ!I30-1,"") | O38: =IFERROR(subQ!O30/subQ!J30-1,"") | Q38: =IFERROR(subQ!Q30/subQ!L30-1,"") | R38: =IFERROR(subQ!R30/subQ!M30-1,"") | S38: =IFERROR(subQ!S30/subQ!N30-1,"") | T38: =IFERROR(subQ!T30/subQ!O30-1,"") | V38: =IFERROR(subQ!V30/subQ!Q30-1,"") | W38: =IFERROR(subQ!W30/subQ!R30-1,"") | X38: =IFERROR(subQ!X30/subQ!S30-1,"") | Y38: =IFERROR(subQ!Y30/subQ!T30-1,"") | AA38: =IFERROR(subQ!AA30/subQ!V30-1,"") | AB38: =IFERROR(subQ!AB30/subQ!W30-1,"") | AC38: 0.053712178 | AD38: -0.20586516 | AF38: -0.03220323 | AG38: 0 | AH38: 0 | AI38: 0 | AK38: 0 | AL38: 0 | AM38: 0 | AN38: 0
A39: drv:영업활동현금흐름 | B39: yoy | C39: 영업활동현금흐름 YoY | J39: =IFERROR(subQ!J31/subQ!E31-1,"") | L39: =IFERROR(subQ!L31/subQ!G31-1,"") | M39: =IFERROR(subQ!M31/subQ!H31-1,"") | N39: =IFERROR(subQ!N31/subQ!I31-1,"") | O39: =IFERROR(subQ!O31/subQ!J31-1,"") | Q39: =IFERROR(subQ!Q31/subQ!L31-1,"") | R39: =IFERROR(subQ!R31/subQ!M31-1,"") | S39: =IFERROR(subQ!S31/subQ!N31-1,"") | T39: =IFERROR(subQ!T31/subQ!O31-1,"") | V39: =IFERROR(subQ!V31/subQ!Q31-1,"") | W39: =IFERROR(subQ!W31/subQ!R31-1,"") | X39: =IFERROR(subQ!X31/subQ!S31-1,"") | Y39: =IFERROR(subQ!Y31/subQ!T31-1,"") | AA39: =IFERROR(subQ!AA31/subQ!V31-1,"") | AB39: =IFERROR(subQ!AB31/subQ!W31-1,"")
A40: drv:주식수 | B40: qoq | C40: 주식수 QoQ | G40: =IFERROR(subQ!G32/subQ!E32-1,"") | H40: =IFERROR(subQ!H32/subQ!G32-1,"") | I40: =IFERROR(subQ!I32/subQ!H32-1,"") | J40: =IFERROR(subQ!J32/subQ!I32-1,"") | L40: =IFERROR(subQ!L32/subQ!J32-1,"") | M40: =IFERROR(subQ!M32/subQ!L32-1,"") | N40: =IFERROR(subQ!N32/subQ!M32-1,"") | O40: =IFERROR(subQ!O32/subQ!N32-1,"") | Q40: =IFERROR(subQ!Q32/subQ!O32-1,"") | R40: =IFERROR(subQ!R32/subQ!Q32-1,"") | S40: =IFERROR(subQ!S32/subQ!R32-1,"") | T40: =IFERROR(subQ!T32/subQ!S32-1,"") | V40: =IFERROR(subQ!V32/subQ!T32-1,"") | W40: =IFERROR(subQ!W32/subQ!V32-1,"") | X40: =IFERROR(subQ!X32/subQ!W32-1,"") | Y40: =IFERROR(subQ!Y32/subQ!X32-1,"") | AA40: =IFERROR(subQ!AA32/subQ!Y32-1,"") | AB40: =IFERROR(subQ!AB32/subQ!AA32-1,"") | AC40: 0 | AD40: 0 | AF40: 0 | AG40: 0 | AH40: 0 | AI40: 0 | AK40: 0 | AL40: 0 | AM40: 0 | AN40: 0
A41: drv:DPS | B41: abs | C41: DPS (가정, 원) | E41: =subQ!E35 | F41: =subQ!F35 | G41: =subQ!G35 | H41: =subQ!H35 | I41: =subQ!I35 | J41: =subQ!J35 | K41: =subQ!K35 | L41: =subQ!L35 | ... AB41: =subQ!AB35 | AD41: 500 | AE41: =subQ!AE35 | AI41: 500 | AJ41: =subQ!AJ35 | AN41: 500 | AO41: =subQ!AO35
...

Sheet BS연결
B1: (백만원) | C1: 이름: BS연결H | E1: 4Q21 | F1: 2021 | G1: 1Q22 | H1: 2Q22 | I1: 3Q22 | J1: 4Q22 | K1: 2022 | L1: 1Q23 | M1: 2Q23 | N1: 3Q23 | O1: 4Q23 | P1: 2023 | Q1: 1Q24 | R1: 2Q24 | S1: 3Q24 | T1: 4Q24 | U1: 2024 | V1: 1Q25 | W1: 2Q25 | X1: 3Q25 | Y1: 4Q25 | Z1: 2025 | AA1: 1Q26 | AB1: 2Q26 | AC1: 3Q26 | AD1: 4Q26 | AE1: 2026 | AF1: 1Q27 | AG1: 2Q27 | AH1: 3Q27 | AI1: 4Q27 | AJ1: 2027 | AK1: 1Q28 | AL1: 2Q28 | AM1: 3Q28 | AN1: 4Q28 | AO1: 2028
B2: 연결 | D2: fin json(kship_fin.py)
B3: 한화시스템(연) | C3: UPDATE: 26-10-11 | E3: 1 | F3: 2 | G3: 3 | H3: 4 | I3: 5 | J3: 6 | K3: 7 | L3: 8 | M3: 9 | N3: 10 | O3: 11 | P3: 12 | Q3: 13 | R3: 14 | S3: 15 | T3: 16 | U3: 17 | V3: 18 | W3: 19 | X3: 20 | Y3: 21 | Z3: 22 | AA3: 23 | AB3: 24 | AC3: 25 | AD3: 26 | AE3: 27 | AF3: 28 | AG3: 29 | AH3: 30 | AI3: 31 | AJ3: 32 | AK3: 33 | AL3: 34 | AM3: 35 | AN3: 36 | AO3: 37
B4: Account Code | C4: AccountNAME | E4: 2021.12 | F4: 2021.12A | G4: 2022.03 | H4: 2022.06 | I4: 2022.09 | J4: 2022.12 | K4: 2022.12A | L4: 2023.03 | M4: 2023.06 | N4: 2023.09 | O4: 2023.12 | P4: 2023.12A | Q4: 2024.03 | R4: 2024.06 | S4: 2024.09 | T4: 2024.12 | U4: 2024.12A | V4: 2025.03 | W4: 2025.06 | X4: 2025.09 | Y4: 2025.12 | Z4: 2025.12A | AA4: 2026.03 | AB4: 2026.06 | AC4: 2026.09 | AD4: 2026.12 | AE4: 2026.12A | AF4: 2027.03 | AG4: 2027.06 | AH4: 2027.09 | AI4: 2027.12 | AJ4: 2027.12A | AK4: 2028.03 | AL4: 2028.06 | AM4: 2028.09 | AN4: 2028.12 | AO4: 2028.12A
A5: 1 | C5: 유동자산 | E5: 2676109.4 | F5: 2676109.4 | G5: 2071230.8 | H5: 2213495.5 | I5: 2182018.3 | J5: 2326839.8 | K5: 2326839.8 | L5: 2369967.6 | M5: 1786841.5 | N5: 1934736.2 | O5: 1890139.7 | P5: 1890139.7 | Q5: 2063469.5 | R5: 2325690.9 | S5: 2337727.3 | T5: 2286147.3 | U5: 2286147.3 | V5: 2418286.9 | W5: 2699940.2 | X5: 2855518.9 | Y5: 2928529.6 | Z5: 2928529.6 | AA5: 3157609.5 | AB5: 4666192.3
A6: 1 | C6: 현금및현금성자산 | E6: 1636831.2 | F6: 1636831.2 | G6: 958490.4 | H6: 1186796.2 | I6: 1008736 | J6: 1228217.7 | K6: 1228217.7 | L6: 991661.98 | M6: 514881.17 | N6: 541058.32 | O6: 476088.82 | P6: 476088.82 | Q6: 454384.22 | R6: 413662.48 | S6: 246643.66 | T6: 199842.74 | U6: 199842.74 | V6: 240375.74 | W6: 360013.44 | X6: 243848.2 | Y6: 325483.66 | Z6: 325483.66 | AA6: 492567.83 | AB6: 1591309.1
A7: 1 | C7: 매출채권및기타채권 | E7: 181114.56 | F7: 181114.56 | G7: 140859.54 | H7: 111942.26 | I7: 128296.83 | J7: 208560.92 | K7: 208560.92 | L7: 161337.5 | M7: 147970.28 | N7: 169227.01 | O7: 202103.1 | P7: 202103.1 | Q7: 251777.12 | R7: 290811.4 | S7: 264814.67 | T7: 309758.81 | U7: 309758.81 | V7: 251595.8 | W7: 238594.18 | X7: 313499.68 | Y7: 450887.46 | Z7: 450887.46 | AA7: 358037.84 | AB7: 449803.66
A8: 1 | C8: 기타유동금융자산 | E8: 27567.45 | F8: 27567.45 | G8: 25167.73 | H8: 19884.51 | I8: 26502.26 | J8: 25669.19 | K8: 25669.19 | L8: 161613.27 | M8: 19521.76 | N8: 37196.87 | O8: 34748.2 | P8: 34748.2 | Q8: 24160.51 | R8: 137314.71 | S8: 117048.93 | T8: 124138.31 | U8: 124138.31 | V8: 107170.97 | W8: 41973.47 | X8: 40074.41 | Y8: 164123.08 | Z8: 164123.08 | AA8: 162606.91 | AB8: 275220.18
A9: 1 | C9: 기타유동자산 | E9: 424551.09 | F9: 424551.09 | G9: 501934.23 | H9: 497584.55 | I9: 561594.48 | J9: 469952.75 | K9: 469952.75 | L9: 559831.21 | M9: 631304.16 | N9: 698945.67 | O9: 676114.3 | P9: 676114.3 | Q9: 763842.2 | R9: 851096.58 | S9: 1036019.9 | T9: 1025685.1 | U9: 1025685.1 | V9: 1113491.2 | W9: 1226913.5 | X9: 1314803.5 | Y9: 1177292.4 | Z9: 1177292.4 | AA9: 1222536.8 | AB9: 1358830.3
A10: 1 | C10: 재고자산 | E10: 406045.06 | F10: 406045.06 | G10: 444778.89 | H10: 397288.01 | I10: 456888.7 | J10: 372962.72 | K10: 372962.72 | L10: 495523.67 | M10: 473164.17 | N10: 488308.33 | O10: 501085.25 | P10: 501085.25 | Q10: 569305.42 | R10: 632788.84 | S10: 673183.26 | T10: 610096.27 | U10: 610096.27 | V10: 705653.19 | W10: 832445.59 | X10: 943293.2 | Y10: 810743.03 | Z10: 810743.03 | AA10: 921860.15 | AB10: 953529.03
A11: 1 | C11: 비유동자산 | E11: 1218193.3 | F11: 1218193.3 | G11: 1663560.8 | H11: 1713150.2 | I11: 1777753.1 | J11: 1618787.9 | K11: 1618787.9 | L11: 1674767.6 | M11: 2380954.9 | N11: 2460087.8 | O11: 2593071.2 | P11: 2593071.2 | Q11: 2667756.3 | R11: 2685541.7 | S11: 2722679.6 | T11: 3437862.8 | U11: 3437862.8 | V11: 4794326 | W11: 5342920.4 | X11: 6716552 | Y11: 7398735.9 | Z11: 7398735.9 | AA11: 7663054.1 | AB11: 7181132.6
A12: 1 | C12: 장기금융자산 | E12: 167383.88 | F12: 167383.88 | G12: 633442.66 | H12: 665642.73 | I12: 721417.59 | J12: 553749.04 | K12: 553749.04 | L12: 549872.02 | M12: 559925.06 | N12: 548021.68 | O12: 313244.37 | P12: 313244.37 | Q12: 370111.27 | R12: 324802.47 | S12: 324788.49 | T12: 440588.06 | U12: 440588.06 | V12: 470194.7 | W12: 632598.3 | X12: 719196.83 | Y12: 659129.16 | Z12: 659129.16 | AA12: 602052.88 | AB12: 574130.17
A13: 1 | C13: 투자자산 | E13: 195934.2 | F13: 195934.2 | G13: 657228.77 | H13: 682547.1 | I13: 739718.05 | J13: 570182.24 | K13: 570182.24 | L13: 639147.18 | M13: 1369478.4 | N13: 1398313.7 | O13: 1305753.2 | P13: 1305753.2 | Q13: 1363596.4 | R13: 1316986.5 | S13: 1289467.7 | T13: 465139.59 | U13: 465139.59 | V13: 489496.04 | W13: 650260.85 | X13: 829324.17 | Y13: 1207613.2 | Z13: 1207613.2 | AA13: 1220336.3 | AB13: 574130.17
A14: 1 | C14: 종속기업및관계기업투자 | E14: 28550.32 | F14: 28550.32 | G14: 23786.11 | H14: 16904.37 | I14: 18300.46 | J14: 16433.2 | K14: 16433.2 | L14: 89275.16 | M14: 809553.32 | N14: 850292.05 | O14: 992508.82 | P14: 992508.82 | Q14: 993485.13 | R14: 992184.02 | S14: 964679.23 | T14: 24551.53 | U14: 24551.53 | V14: 19301.34 | W14: 17662.55 | X14: 110127.34 | Y14: 548484.06 | Z14: 548484.06 | AA14: 618283.41
A15: 1 | C15: 유형자산 | E15: 256905.96 | F15: 256905.96 | G15: 252637.54 | H15: 274600.35 | I15: 273265.61 | J15: 274368.03 | K15: 274368.03 | L15: 302997.24 | M15: 307580.98 | N15: 335100.92 | O15: 347646.33 | P15: 347646.33 | Q15: 372628.71 | R15: 410190.35 | S15: 434393.19 | T15: 569952.77 | U15: 569952.77 | V15: 607018.91 | W15: 673066.16 | X15: 715329.96 | Y15: 822739.44 | Z15: 822739.44 | AA15: 869841.2 | AB15: 923316.25
A16: 1 | C16: 사용권자산 | E16: 101068.99 | F16: 101068.99 | G16: 95800.75 | H16: 93039.6 | I16: 97212.17 | J16: 100640.33 | K16: 100640.33 | L16: 94602.64 | M16: 88817.05 | N16: 109253.11 | O16: 117782.08 | P16: 117782.08 | Q16: 117358.17 | R16: 110732.6 | S16: 142958.81 | T16: 154215.14 | U16: 154215.14 | V16: 146705.81 | W16: 139745.56 | X16: 132572.46 | Y16: 191329.22 | Z16: 191329.22 | AA16: 189788.54 | AB16: 188868.87
A17: 1 | C17: 기타비유동자산 | E17: 103654.8 | F17: 103654.8 | G17: 99249.37 | H17: 96700.21 | I17: 100855.85 | J17: 105049.47 | K17: 105049.47 | L17: 98539.18 | M17: 92971.72 | N17: 112842.2 | O17: 122398.3 | P17: 122398.3 | Q17: 121612.03 | R17: 114708.65 | S17: 147714.95 | T17: 160954.83 | U17: 160954.83 | V17: 153914.07 | W17: 146606.4 | X17: 152432.73 | Y17: 210721.84 | Z17: 210721.84 | AA17: 211037.73 | AB17: 209466.19
A18: 1 | C18: 무형자산 | E18: 562162.92 | F18: 562162.92 | G18: 559190.23 | H18: 560853.63 | I18: 562774.46 | J18: 557833.98 | K18: 557833.98 | L18: 556422.16 | M18: 555153.48 | N18: 555337.34 | O18: 558922.41 | P18: 558922.41 | Q18: 553061.67 | R18: 562261.41 | S18: 565382.81 | T18: 762189.51 | U18: 762189.51 | V18: 759170.73 | W18: 756130.12 | X18: 750473.69 | Y18: 709755.42 | Z18: 709755.42 | AA18: 709358.13
A19: 1 | C19: 이연법인세자산 | E19: 81719.78 | F19: 81719.78 | G19: 77212.85 | H19: 76372.27 | I19: 77904.25 | J19: 87386.88 | K19: 87386.88 | L19: 54281.9 | M19: 30913.03 | N19: 30695.95 | O19: 77888.32 | P19: 77888.32 | Q19: 80676.72 | R19: 112159.34 | S19: 109599.88 | T19: 41589.41 | U19: 41589.41 | V19: 14077.56 | W19: 8681.79 | X19: 8328.51 | Y19: 16578.71 | Z19: 16578.71 | AA19: 20513.61 | AB19: 27063.24
A20: 1 | C20: 자산총계 | E20: 3894302.6 | F20: 3894302.6 | G20: 3734791.6 | H20: 3926645.7 | I20: 3959771.4 | J20: 3945627.7 | K20: 3945627.7 | L20: 4044735.2 | M20: 4167796.4 | N20: 4394824 | O20: 4483210.8 | P20: 4483210.8 | Q20: 4731225.8 | R20: 5011232.6 | S20: 5060406.9 | T20: 5724010.1 | U20: 5724010.1 | V20: 7212612.8 | W20: 8042860.7 | X20: 9572071 | Y20: 10327266 | Z20: 10327266 | AA20: 10820664 | AB20: 11847325
A21: 1 | C21: 유동부채 | E21: 1363163.3 | F21: 1363163.3 | G21: 1225479.3 | H21: 1452996.4 | I21: 1436892.7 | J21: 1618535.6 | K21: 1618535.6 | L21: 1587063.3 | M21: 1640871.9 | N21: 1781226.5 | O21: 1951414.8 | P21: 1951414.8 | Q21: 2170441.1 | R21: 2167709.4 | S21: 2271473.5 | T21: 2677051.5 | U21: 2677051.5 | V21: 2897194.7 | W21: 2992558.8 | X21: 3192807.5 | Y21: 3334859.8 | Z21: 3334859.8 | AA21: 3514271.4 | AB21: 5354369.3
A22: 1 | C22: 매입채무및기타채무 | E22: 125173.01 | F22: 125173.01 | G22: 125284.93 | H22: 112848.63 | I22: 107061.22 | J22: 160863.44 | K22: 160863.44 | L22: 210002.7 | M22: 116868.83 | N22: 107073.7 | O22: 213095.62 | P22: 213095.62 | Q22: 234773.41 | R22: 215163.82 | S22: 166186.57 | T22: 250001.34 | U22: 250001.34 | V22: 345784.37 | W22: 267463.73 | X22: 365541.88 | Y22: 480878.76 | Z22: 480878.76 | AA22: 536933.02 | AB22: 379114.46
A23: 1 | C23: 단기차입금 | E23: 29986.12 | F23: 29986.12 | G23: 29992.82 | H23: 0 | I23: 50000 | J23: 80000 | K23: 80000 | L23: 80000 | M23: 80000 | N23: 289988.04 | O23: 162334.77 | P23: 162334.77 | Q23: 319996.02 | R23: 209999.79 | S23: 130056.02 | T23: 79955.19 | U23: 79955.19 | V23: 244634.77 | W23: 203864.65 | X23: 389958.29 | Y23: 401210.4 | Z23: 401210.4 | AA23: 546707.92 | AB23: 2163871.5
A24: 1 | C24: 단기금융부채(face) | E24: 29986.12 | F24: 29986.12 | G24: 29992.82 | H24: 0 | I24: 50000 | L24: 80000 | M24: 80000 | N24: 289988.04 | O24: 162334.77 | P24: 162334.77 | Q24: 319996.02 | R24: 209999.79 | S24: 130056.02 | T24: 79955.19 | U24: 79955.19 | V24: 244634.77 | W24: 203864.65 | X24: 389958.29 | Y24: 401210.4 | Z24: 401210.4 | AA24: 546707.92 | AB24: 2163871.5
A25: 1 | C25: 기타유동금융부채 | E25: 70856.03 | F25: 70856.03 | G25: 50838.48 | H25: 51656.58 | I25: 58168.37 | J25: 79617.42 | K25: 79617.42 | L25: 60084.97 | M25: 69779.68 | N25: 69432.29 | O25: 93424.94 | P25: 93424.94 | Q25: 67996.06 | R25: 71334.47 | S25: 83849.04 | T25: 195531.57 | U25: 195531.57 | V25: 124861.04 | W25: 149038.6 | X25: 174229.82 | Y25: 247603.2 | Z25: 247603.2 | AA25: 215824.56 | AB25: 233308.71
A26: 1 | C26: 단기금융부채 | E26: 70856.03 | F26: 70856.03 | G26: 50838.48 | H26: 51656.58 | I26: 58168.37 | J26: 79617.42 | K26: 79617.42 | L26: 60084.97 | M26: 69779.68 | N26: 69432.29 | O26: 93424.94 | P26: 93424.94 | Q26: 67996.06 | R26: 71334.47 | S26: 83849.04 | T26: 195531.57 | U26: 195531.57 | V26: 124861.04 | W26: 149038.6 | X26: 174229.82 | Y26: 247603.2 | Z26: 247603.2 | AA26: 215824.56 | AB26: 233308.71
A27: 1 | C27: 기타유동부채 | E27: 1111361.1 | F27: 1111361.1 | G27: 997671.88 | H27: 1270618.7 | I27: 1197271.1 | J27: 1252876.2 | K27: 1252876.2 | L27: 1203201.1 | M27: 1334719.1 | N27: 1271834.4 | O27: 1432347.3 | P27: 1432347.3 | Q27: 1494639.6 | R27: 1628194.4 | S27: 1849992.3 | T27: 2027772.1 | U27: 2027772.1 | V27: 2090673.8 | W27: 2300085.8 | X27: 2184475.8 | Y27: 2106457.9 | Z27: 2106457.9 | AA27: 2138505.9 | AB27: 2508841.6
A28: 1 | C28: 단기충당부채 | E28: 10475.01 | F28: 10475.01 | G28: 10782.41 | H28: 9174.43 | I28: 15589.43 | J28: 22953.73 | K28: 22953.73 | L28: 19267.13 | M28: 24497.65 | N28: 22914.93 | O28: 31754.6 | P28: 31754.6 | Q28: 28816.23 | R28: 22772.1 | S28: 26263.65 | T28: 83709.54 | U28: 83709.54 | V28: 69394.05 | W28: 61258.61 | X28: 58915.2 | Y28: 63950.21 | Z28: 63950.21 | AA28: 52769.85 | AB28: 39973.75
A29: 1 | C29: 당기법인세부채(미지급법인세) | E29: 15312.02 | F29: 15312.02 | G29: 10908.78 | H29: 8698.08 | I29: 8802.61 | J29: 14839.62 | K29: 14839.62 | L29: 14507.47 | M29: 15006.68 | N29: 19983.24 | O29: 18457.56 | P29: 18457.56 | Q29: 24219.79 | R29: 20244.8 | S29: 15125.9 | T29: 37318.84 | U29: 37318.84 | V29: 21846.7 | W29: 10847.38 | X29: 19686.55 | Y29: 34759.3 | Z29: 34759.3 | AA29: 23530.12 | AB29: 29259.2
A30: 1 | C30: 비유동부채 | E30: 291377.86 | F30: 291377.86 | G30: 290775.72 | H30: 293510.47 | I30: 303533.63 | J30: 308140.1 | K30: 308140.1 | L30: 309593.68 | M30: 310469.31 | N30: 353578.76 | O30: 377669.9 | P30: 377669.9 | Q30: 392965.39 | R30: 645297.99 | S30: 593090.16 | T30: 630541.75 | U30: 630541.75 | V30: 902350.01 | W30: 1244532 | X30: 1519496.8 | Y30: 1991406.7 | Z30: 1991406.7 | AA30: 2263602.3 | AB30: 1921296.9
A31: 1 | C31: 장기차입금 | E31: 0 | F31: 0 | G31: 0 | H31: 0 | I31: 0 | J31: 0 | K31: 0 | L31: 0 | M31: 0 | N31: 0 | O31: 49899.32 | P31: 49899.32 | Q31: 140 | R31: 140 | S31: 249185.35 | T31: 249276.74 | U31: 249276.74 | V31: 290667.02 | W31: 489861.28 | X31: 558310.01 | Y31: 1073225.9 | Z31: 1073225.9 | AA31: 1306257.3 | AB31: 1096911.1
A32: 1 | C32: 기타비유동금융부채 | E32: 80085.85 | F32: 80085.85 | G32: 75456.36 | H32: 72227.29 | I32: 75484.13 | J32: 77868.38 | K32: 77868.38 | L32: 75418.64 | M32: 72037.07 | N32: 89211.63 | O32: 99017.34 | P32: 99017.34 | Q32: 100830.43 | R32: 97406.52 | S32: 131057.96 | T32: 132646.05 | U32: 132646.05 | V32: 136787.94 | W32: 131031.93 | X32: 129607.65 | Y32: 140849.54 | Z32: 140849.54 | AA32: 155383.58 | AB32: 140138.64
A33: 1 | C33: 장기금융부채 | E33: 80085.85 | F33: 80085.85 | G33: 75456.36 | H33: 72227.29 | I33: 75484.13 | J33: 77868.38 | K33: 77868.38 | L33: 75418.64 | M33: 72037.07 | N33: 89211.63 | O33: 99017.34 | P33: 99017.34 | Q33: 100830.43 | R33: 97406.52 | S33: 131057.96 | T33: 132646.05 | U33: 132646.05 | V33: 136787.94 | W33: 131031.93 | X33: 129607.65 | Y33: 140849.54 | Z33: 140849.54 | AA33: 155383.58 | AB33: 140138.64
A34: 1 | C34: 확정급여부채 | E34: 160419.16 | F34: 160419.16 | G34: 164325.31 | H34: 169696.52 | I34: 174978.65 | J34: 180295.29 | K34: 180295.29 | L34: 183662.8 | M34: 187353.93 | N34: 192526.89 | O34: 206769.51 | P34: 206769.51 | Q34: 215215.89 | R34: 222771.94 | S34: 185986.69 | T34: 207330.08 | U34: 207330.08 | V34: 214432 | W34: 226999.46 | X34: 232970.91 | Y34: 151006.05 | Z34: 151006.05 | AA34: 150019.27 | AB34: 156314.24
A35: 1 | C35: 장기충당부채 | E35: 20444.74 | F35: 20444.74 | G35: 21030.68 | H35: 21619.24 | I35: 23099.33 | J35: 19866.57 | K35: 19866.57 | L35: 20398.65 | M35: 20967.31 | N35: 21828.9 | O35: 21983.73 | P35: 21983.73 | Q35: 22365.43 | R35: 23047.55 | S35: 23765.49 | T35: 30505.07 | U35: 30505.07 | V35: 31211.51 | W35: 32308.55 | X35: 33195.88 | Y35: 47254.28 | Z35: 47254.28 | AA35: 48528.7 | AB35: 49835.25
A36: 1 | C36: 이연법인세부채 | E36: 0 | F36: 0 | J36: 7.04 | K36: 7.04 | L36: 6.71 | M36: 0 | N36: 0 | O36: 0 | P36: 0 | Q36: 4500.3 | R36: 2910.09 | S36: 3094.67 | T36: 10783.8 | U36: 10783.8 | V36: 229251.55 | W36: 364330.76 | X36: 565412.35 | Y36: 579070.95 | Z36: 579070.95 | AA36: 603413.39 | AB36: 478097.63
A37: 1 | C37: 부채총계 | E37: 1654541.2 | F37: 1654541.2 | G37: 1516255 | H37: 1746506.9 | I37: 1740426.4 | J37: 1926675.7 | K37: 1926675.7 | L37: 1896657 | M37: 1951341.3 | N37: 2134805.3 | O37: 2329084.7 | P37: 2329084.7 | Q37: 2563406.5 | R37: 2813007.4 | S37: 2864563.6 | T37: 3307593.2 | U37: 3307593.2 | V37: 3799544.7 | W37: 4237090.7 | X37: 4712304.3 | Y37: 5326266.5 | Z37: 5326266.5 | AA37: 5777873.6 | AB37: 7275666.2
A38: 1 | C38: 지배주주지분 | E38: 2222498.1 | F38: 2222498.1 | G38: 2202290.4 | H38: 2164764.1 | I38: 2200040.2 | J38: 2000339 | K38: 2000339 | L38: 2130862.4 | M38: 2200004.1 | N38: 2243378 | O38: 2139817.9 | P38: 2139817.9 | Q38: 2151948.2 | R38: 2183606.2 | S38: 2182511.9 | T38: 2490055 | U38: 2490055 | V38: 3357851.8 | W38: 3721430.3 | X38: 4755342.2 | Y38: 4849228.7 | Z38: 4849228.7 | AA38: 4943895.6 | AB38: 4492709.7
A39: 1 | C39: 자본금 | E39: 944596.94 | F39: 944596.94 | G39: 944596.94 | H39: 944596.94 | I39: 944596.94 | J39: 944596.94 | K39: 944596.94 | L39: 944596.94 | M39: 944596.94 | N39: 944596.94 | O39: 944596.94 | P39: 944596.94 | Q39: 944596.94 | R39: 944596.94 | S39: 944596.94 | T39: 944596.94 | U39: 944596.94 | V39: 944596.94 | W39: 944596.94 | X39: 944596.94 | Y39: 944596.94 | Z39: 944596.94 | AA39: 944596.94 | AB39: 944596.94
A40: 1 | C40: 자본잉여금 | E40: 1084938.9 | F40: 1084938.9 | G40: 1085079.9 | H40: 1085529.2 | I40: 1086220 | J40: 1085520.5 | K40: 1085520.5 | L40: 1086702.8 | M40: 1088049.5 | N40: 1100125.9 | O40: 1100087.1 | P40: 1100087.1 | Q40: 844765.57 | R40: 845562.96 | S40: 846253.93 | T40: 1092001.1 | U40: 1092001.1 | V40: 1092202.3 | W40: 1114239 | X40: 1116579.9 | Y40: 1122977.3 | Z40: 1122977.3 | AA40: 1124166.7 | AB40: 1126777.3
...

Sheet BS별도
B1: (백만원) | C1: 이름: BS별도H | E1: 4Q21 | F1: 2021 | G1: 1Q22 | H1: 2Q22 | I1: 3Q22 | J1: 4Q22 | K1: 2022 | L1: 1Q23 | M1: 2Q23 | N1: 3Q23 | O1: 4Q23 | P1: 2023 | Q1: 1Q24 | R1: 2Q24 | S1: 3Q24 | T1: 4Q24 | U1: 2024 | V1: 1Q25 | W1: 2Q25 | X1: 3Q25 | Y1: 4Q25 | Z1: 2025 | AA1: 1Q26 | AB1: 2Q26 | AC1: 3Q26 | AD1: 4Q26 | AE1: 2026 | AF1: 1Q27 | AG1: 2Q27 | AH1: 3Q27 | AI1: 4Q27 | AJ1: 2027 | AK1: 1Q28 | AL1: 2Q28 | AM1: 3Q28 | AN1: 4Q28 | AO1: 2028
B2: 별도 | D2: fin json(kship_fin.py)
B3: 한화시스템(별) | C3: UPDATE: 26-10-11 | E3: 1 | F3: 2 | G3: 3 | H3: 4 | I3: 5 | J3: 6 | K3: 7 | L3: 8 | M3: 9 | N3: 10 | O3: 11 | P3: 12 | Q3: 13 | R3: 14 | S3: 15 | T3: 16 | U3: 17 | V3: 18 | W3: 19 | X3: 20 | Y3: 21 | Z3: 22 | AA3: 23 | AB3: 24 | AC3: 25 | AD3: 26 | AE3: 27 | AF3: 28 | AG3: 29 | AH3: 30 | AI3: 31 | AJ3: 32 | AK3: 33 | AL3: 34 | AM3: 35 | AN3: 36 | AO3: 37
B4: Account Code | C4: AccountNAME | E4: 2021.12 | F4: 2021.12A | G4: 2022.03 | H4: 2022.06 | I4: 2022.09 | J4: 2022.12 | K4: 2022.12A | L4: 2023.03 | M4: 2023.06 | N4: 2023.09 | O4: 2023.12 | P4: 2023.12A | Q4: 2024.03 | R4: 2024.06 | S4: 2024.09 | T4: 2024.12 | U4: 2024.12A | V4: 2025.03 | W4: 2025.06 | X4: 2025.09 | Y4: 2025.12 | Z4: 2025.12A | AA4: 2026.03 | AB4: 2026.06 | AC4: 2026.09 | AD4: 2026.12 | AE4: 2026.12A | AF4: 2027.03 | AG4: 2027.06 | AH4: 2027.09 | AI4: 2027.12 | AJ4: 2027.12A | AK4: 2028.03 | AL4: 2028.06 | AM4: 2028.09 | AN4: 2028.12 | AO4: 2028.12A
A5: 1 | C5: 유동자산 | E5: 2652387 | F5: 2652387 | G5: 1929577.4 | H5: 2089907.3 | I5: 2054762.1 | J5: 2208441.8 | K5: 2208441.8 | L5: 2277193.2 | M5: 1715570.3 | N5: 1883371.2 | O5: 1843097 | P5: 1843097 | Q5: 2040114 | R5: 2291067.9 | S5: 2320000.7 | T5: 2069939.6 | U5: 2069939.6 | V5: 2095025.9 | W5: 2367643.5 | X5: 2500441.7 | Y5: 2371127.2 | Z5: 2371127.2 | AA5: 2658703.2 | AB5: 3975405.6
A6: 1 | C6: 현금및현금성자산 | E6: 1621392.8 | F6: 1621392.8 | G6: 822403.09 | H6: 1068259.6 | I6: 892697.8 | J6: 1143568.8 | K6: 1143568.8 | L6: 909441.85 | M6: 449184.23 | N6: 508467.31 | O6: 446939.27 | P6: 446939.27 | Q6: 428557.79 | R6: 387062.02 | S6: 229879.69 | T6: 132154.37 | U6: 132154.37 | V6: 74638.05 | W6: 174659.83 | X6: 36100.21 | Y6: 44175.33 | Z6: 44175.33 | AA6: 287220.28 | AB6: 1333982.7
A7: 1 | C7: 매출채권및기타채권 | E7: 176954.56 | F7: 176954.56 | G7: 138572.02 | H7: 110734.35 | I7: 126965.38 | J7: 207189.74 | K7: 207189.74 | L7: 161082.91 | M7: 146928.7 | N7: 168130.04 | O7: 199620.74 | P7: 199620.74 | Q7: 250610.62 | R7: 287233.18 | S7: 263379.58 | T7: 295774.11 | U7: 295774.11 | V7: 237182.76 | W7: 225171.76 | X7: 298959.56 | Y7: 436993.47 | Z7: 436993.47 | AA7: 346980.34 | AB7: 418524.17
A8: 1 | C8: 기타유동금융자산 | E8: 27413.21 | F8: 27413.21 | G8: 25012.98 | H8: 19575.18 | I8: 20173.55 | J8: 21502.88 | K8: 21502.88 | L8: 160255.79 | M8: 19410.2 | N8: 23111.95 | O8: 21331.2 | P8: 21331.2 | Q8: 21596.06 | R8: 134710.86 | S8: 105620.73 | T8: 104199.69 | U8: 104199.69 | V8: 76980.61 | W8: 22300.75 | X8: 19382.16 | Y8: 27123.43 | Z8: 27123.43 | AA8: 25282.3 | AB8: 27171.8
A9: 1 | C9: 기타유동자산 | E9: 420581.33 | F9: 420581.33 | G9: 498810.43 | H9: 494050.1 | I9: 558251.15 | J9: 463586.64 | K9: 463586.64 | L9: 551258.06 | M9: 627177.26 | N9: 695612.75 | O9: 674308.26 | P9: 674308.26 | Q9: 770159.59 | R9: 849350.27 | S9: 1048014.7 | T9: 930145.01 | U9: 930145.01 | V9: 1002780.4 | W9: 1115694.6 | X9: 1205717.9 | Y9: 1069476.2 | Z9: 1069476.2 | AA9: 1082151.8 | AB9: 1211067.1
A10: 1 | C10: 재고자산 | E10: 406045.06 | F10: 406045.06 | G10: 444778.89 | H10: 397288.01 | I10: 456674.18 | J10: 372593.68 | K10: 372593.68 | L10: 495154.64 | M10: 472869.93 | N10: 488049.14 | O10: 500897.54 | P10: 500897.54 | Q10: 569189.95 | R10: 632711.58 | S10: 673106 | T10: 607666.38 | U10: 607666.38 | V10: 703444.03 | W10: 829816.48 | X10: 940281.92 | Y10: 793358.72 | Z10: 793358.72 | AA10: 917068.5 | AB10: 947159.79
A11: 1 | C11: 비유동자산 | E11: 1262225.9 | F11: 1262225.9 | G11: 1841545.5 | H11: 1939437.2 | I11: 1992426.6 | J11: 1943658.3 | K11: 1943658.3 | L11: 1941812.8 | M11: 2682025.1 | N11: 2737965 | O11: 2712337.4 | P11: 2712337.4 | Q11: 2746738 | R11: 2702637.6 | S11: 2761772.8 | T11: 3149549.9 | U11: 3149549.9 | V11: 4423319.8 | W11: 4917521.1 | X11: 6125241 | Y11: 6972295.6 | Z11: 6972295.6 | AA11: 7297722.8 | AB11: 6792759.8
A12: 1 | C12: 장기금융자산 | E12: 144144.83 | F12: 144144.83 | G12: 158178.4 | H12: 225288.02 | I12: 236641 | J12: 205483.91 | K12: 205483.91 | L12: 208510.12 | M12: 216569.6 | N12: 220522.85 | O12: 194228.39 | P12: 194228.39 | Q12: 203715.87 | R12: 85205.38 | S12: 86486.4 | T12: 76492.07 | U12: 76492.07 | V12: 76971.15 | W12: 81371.11 | X12: 83457.28 | Y12: 86993.09 | Z12: 86993.09 | AA12: 98416.45 | AB12: 101605.4
A13: 1 | C13: 투자자산 | E13: 144144.83 | F13: 144144.83 | G13: 158178.4 | H13: 225288.02 | I13: 236641 | J13: 205483.91 | K13: 205483.91 | L13: 208510.12 | M13: 216569.6 | N13: 220522.85 | O13: 1627449.3 | P13: 1627449.3 | Q13: 1640136.8 | R13: 1524528.1 | S13: 1527407.4 | T13: 580535.58 | U13: 580535.58 | V13: 766368.87 | W13: 770768.83 | X13: 863386.5 | Y13: 1470917.3 | Z13: 1470917.3 | AA13: 1527747.8 | AB13: 101605.4
A14: 1 | C14: 유형자산 | E14: 237584.76 | F14: 237584.76 | G14: 231283.49 | H14: 253532.96 | I14: 252392.3 | J14: 256265.2 | K14: 256265.2 | L14: 285139.81 | M14: 289912.3 | N14: 316982.87 | O14: 329710.04 | P14: 329710.04 | Q14: 355809.56 | R14: 394447.15 | S14: 420470.99 | T14: 508914.03 | U14: 508914.03 | V14: 553254.63 | W14: 621229.48 | X14: 650360.35 | Y14: 710199.09 | Z14: 710199.09 | AA14: 728578.74 | AB14: 769401.94
A15: 1 | C15: 사용권자산 | E15: 96093.13 | F15: 96093.13 | G15: 91105.05 | H15: 86142.84 | I15: 90456.2 | J15: 91379.37 | K15: 91379.37 | L15: 85809.5 | M15: 81788.12 | N15: 102891.4 | O15: 110224.89 | P15: 110224.89 | Q15: 116182.55 | R15: 109863.54 | S15: 142128.05 | T15: 130701.11 | U15: 130701.11 | V15: 123926.27 | W15: 118982.22 | X15: 111334.98 | Y15: 123318.87 | Z15: 123318.87 | AA15: 118914.75 | AB15: 112477.58
A16: 1 | C16: 기타비유동자산 | E16: 98456.28 | F16: 98456.28 | G16: 94323.69 | H16: 89397.7 | I16: 93518.21 | J16: 95489.43 | K16: 95489.43 | L16: 89453.79 | M16: 85683.18 | N16: 106250 | O16: 114650.39 | P16: 114650.39 | Q16: 120311.5 | R16: 113745.64 | S16: 146836.64 | T16: 137319.36 | U16: 137319.36 | V16: 131013.53 | W16: 125731.3 | X16: 131079.87 | Y16: 142593.56 | Z16: 142593.56 | AA16: 140038.89 | AB16: 132947.69
A17: 1 | C17: 무형자산 | E17: 538727.83 | F17: 538727.83 | G17: 536074.61 | H17: 539148.2 | I17: 541358.56 | J17: 544089.39 | K17: 544089.39 | L17: 542690.91 | M17: 541483.88 | N17: 541660.34 | O17: 547331.37 | P17: 547331.37 | Q17: 541950.44 | R17: 551312.09 | S17: 554848.15 | T17: 553167.61 | U17: 553167.61 | V17: 550148.83 | W17: 547108.22 | X17: 541451.79 | Y17: 538159.37 | Z17: 538159.37 | AA17: 530984.52
A18: 1 | C18: 이연법인세자산 | E18: 81719.2 | F18: 81719.2 | G18: 77207.53 | H18: 76362 | I18: 77885.59 | J18: 87386.88 | K18: 87386.88 | L18: 54281.9 | M18: 30891.55 | N18: 30671.17 | O18: 77866.84 | P18: 77866.84 | Q18: 73200.28 | R18: 103275.32 | S18: 96880.25 | T18: 29856.95 | U18: 29856.95 | V18: 0 | W18: 0 | X18: 0 | Y18: 0 | Z18: 0
A19: 1 | C19: 자산총계 | E19: 3914612.9 | F19: 3914612.9 | G19: 3771122.9 | H19: 4029344.5 | I19: 4047188.7 | J19: 4152100.1 | K19: 4152100.1 | L19: 4219006.1 | M19: 4397595.4 | N19: 4621336.2 | O19: 4555434.4 | P19: 4555434.4 | Q19: 4786852 | R19: 4993705.5 | S19: 5081773.5 | T19: 5219489.5 | U19: 5219489.5 | V19: 6518345.7 | W19: 7285164.6 | X19: 8625682.8 | Y19: 9343422.8 | Z19: 9343422.8 | AA19: 9956425.9 | AB19: 10768165
A20: 1 | C20: 유동부채 | E20: 1358175.2 | F20: 1358175.2 | G20: 1219943.9 | H20: 1448190.6 | I20: 1431444.4 | J20: 1605605 | K20: 1605605 | L20: 1581264.5 | M20: 1635652.8 | N20: 1777251.5 | O20: 1941385.8 | P20: 1941385.8 | Q20: 2164973.6 | R20: 2160315 | S20: 2267270.3 | T20: 2176932.2 | U20: 2176932.2 | V20: 2402202.9 | W20: 2493731.6 | X20: 2631721.1 | Y20: 2639692 | Z20: 2639692 | AA20: 2784824.5 | AB20: 4438112
A21: 1 | C21: 매입채무및기타채무 | E21: 124422.77 | F21: 124422.77 | G21: 124106.12 | H21: 111331.13 | I21: 104013.97 | J21: 159257.46 | K21: 159257.46 | L21: 208830.23 | M21: 115098.57 | N21: 105886.55 | O21: 210278.32 | P21: 210278.32 | Q21: 231992.32 | R21: 209988.9 | S21: 164271.76 | T21: 211650.83 | U21: 211650.83 | V21: 311589.43 | W21: 223456.93 | X21: 278142.02 | Y21: 424062.6 | Z21: 424062.6 | AA21: 480886.77 | AB21: 330379.56
A22: 1 | C22: 단기차입금 | E22: 29986.12 | F22: 29986.12 | G22: 29992.82 | H22: 0 | I22: 50000 | J22: 80000 | K22: 80000 | L22: 80000 | M22: 80000 | N22: 289988.04 | O22: 159992.26 | P22: 159992.26 | Q22: 319996.02 | R22: 209999.79 | S22: 129941.02 | T22: 79955.19 | U22: 79955.19 | V22: 229969.77 | W22: 149808.42 | X22: 333870.29 | Y22: 286418.4 | Z22: 286418.4 | AA22: 455903.92 | AB22: 2009721.5
A23: 1 | C23: 단기금융부채(face) | E23: 29986.12 | F23: 29986.12 | G23: 29992.82 | H23: 0 | I23: 50000 | J23: 80000 | K23: 80000 | L23: 80000 | M23: 80000 | N23: 289988.04 | O23: 159992.26 | P23: 159992.26 | Q23: 319996.02 | R23: 209999.79 | S23: 129941.02 | T23: 79955.19 | U23: 79955.19 | V23: 229969.77 | W23: 149808.42 | X23: 333870.29 | Y23: 286418.4 | Z23: 286418.4 | AA23: 455903.92 | AB23: 2009721.5
A24: 1 | C24: 기타유동금융부채 | E24: 67197.46 | F24: 67197.46 | G24: 47633.97 | H24: 49042.48 | I24: 56484.1 | J24: 76906.88 | K24: 76906.88 | L24: 56724.56 | M24: 66855.3 | N24: 67283.39 | O24: 89683.52 | P24: 89683.52 | Q24: 66971.52 | R24: 70600.76 | S24: 83507.1 | T24: 137422.36 | U24: 137422.36 | V24: 75349.2 | W24: 93409.19 | X24: 109650.46 | Y24: 168029.99 | Z24: 168029.99 | AA24: 120411.53 | AB24: 141558.12
A25: 1 | C25: 단기금융부채 | E25: 67197.46 | F25: 67197.46 | G25: 47633.97 | H25: 49042.48 | I25: 56484.1 | J25: 76906.88 | K25: 76906.88 | L25: 56724.56 | M25: 66855.3 | N25: 67283.39 | O25: 89683.52 | P25: 89683.52 | Q25: 66971.52 | R25: 70600.76 | S25: 83507.1 | T25: 137422.36 | U25: 137422.36 | V25: 75349.2 | W25: 93409.19 | X25: 109650.46 | Y25: 168029.99 | Z25: 168029.99 | AA25: 120411.53 | AB25: 141558.12
A26: 1 | C26: 기타유동부채 | E26: 1110781.8 | F26: 1110781.8 | G26: 996519.81 | H26: 1269944.5 | I26: 1196554.3 | J26: 1252282.2 | K26: 1252282.2 | L26: 1202733.3 | M26: 1334313.4 | N26: 1271319.4 | O26: 1431341.5 | P26: 1431341.5 | Q26: 1493112.1 | R26: 1626924.2 | S26: 1848372.9 | T26: 1675436.7 | U26: 1675436.7 | V26: 1733985.2 | W26: 1988516.9 | X26: 1865028.2 | Y26: 1695969.3 | Z26: 1695969.3 | AA26: 1677887.7 | AB26: 1905412.4
A27: 1 | C27: 단기충당부채 | E27: 10475.01 | F27: 10475.01 | G27: 10782.41 | H27: 9174.43 | I27: 15589.43 | J27: 22888.11 | K27: 22888.11 | L27: 19182.69 | M27: 24378.83 | N27: 22790.81 | O27: 31632.6 | P27: 31632.6 | Q27: 28690.2 | R27: 22645.38 | S27: 26139.25 | T27: 35162.4 | U27: 35162.4 | V27: 29518.94 | W27: 27692.82 | X27: 25343.56 | Y27: 30452.43 | Z27: 30452.43 | AA27: 26204.4 | AB27: 23662.57
A28: 1 | C28: 당기법인세부채(미지급법인세) | E28: 15312.02 | F28: 15312.02 | G28: 10908.78 | H28: 8698.08 | I28: 8802.61 | J28: 14270.38 | K28: 14270.38 | L28: 13793.72 | M28: 15006.68 | N28: 19983.24 | O28: 18457.56 | P28: 18457.56 | Q28: 24211.41 | R28: 20155.91 | S28: 15038.21 | T28: 37304.77 | U28: 37304.77 | V28: 21790.37 | W28: 10847.38 | X28: 19686.55 | Y28: 34759.3 | Z28: 34759.3 | AA28: 23530.12 | AB28: 27377.82
A29: 1 | C29: 비유동부채 | E29: 286977.4 | F29: 286977.4 | G29: 286650.41 | H29: 287609.65 | I29: 297747.91 | J29: 299465.71 | K29: 299465.71 | L29: 301136.66 | M29: 303408.4 | N29: 346989.72 | O29: 370401.32 | P29: 370401.32 | Q29: 386344.11 | R29: 640242.57 | S29: 589067.7 | T29: 611522.94 | U29: 611522.94 | V29: 889748.36 | W29: 1188891.4 | X29: 1421260.2 | Y29: 1887466.2 | Z29: 1887466.2 | AA29: 2203873.8 | AB29: 1874425.5
A30: 1 | C30: 장기차입금 | E30: 29959.4 | F30: 29959.4 | G30: 29963.37 | H30: 29967.41 | I30: 29971.52 | J30: 29975.65 | K30: 29975.65 | L30: 29979.71 | M30: 29983.84 | N30: 49884.18 | O30: 49899.32 | P30: 49899.32 | Q30: 49913.35 | R30: 299021.88 | S30: 249185.35 | T30: 249276.74 | U30: 249276.74 | V30: 290667.02 | W30: 489861.28 | X30: 558310.01 | Y30: 1073225.9 | Z30: 1073225.9 | AA30: 1306257.3 | AB30: 1096911.1
... A47: 1 | C47: 이자발생자산 | E47: 1765537.7 | F47: 1765537.7 | G47: 980581.49 | H47: 1293547.6 | I47: 1129338.8 | J47: 1349052.7 | K47: 1349052.7 | L47: 1117952 | M47: 665753.83 | N47: 728990.16 | O47: 641167.66 | P47: 641167.66 | Q47: 632273.66 | R47: 472267.4 | S47: 316366.09 | T47: 208646.44 | U47: 208646.44 | V47: 151609.2 | W47: 256030.94 | X47: 119557.49 | Y47: 131168.42 | Z47: 131168.42 | AA47: 385636.73 | AB47: 1435588.1
A48: 1 | C48: 장기매출채권및기타채권 | O48: 0 | P48: 0
A49: 1 | C49: 종속기업및관계기업투자 | O49: 1433220.9 | P49: 1433220.9 | Q49: 1436420.9 | R49: 1439322.7 | S49: 1440920.9 | T49: 504043.51 | U49: 504043.51 | V49: 689397.72 | W49: 689397.72 | X49: 779929.22 | Y49: 1383924.2 | Z49: 1383924.2 | AA49: 1429331.3
A50: 1 | C50: 장기매입채무및기타채무 | O50: 0 | P50: 0
A51: 1 | C51: 이연법인세부채 | V51: 224521.68 | W51: 315486 | X51: 474993.16 | Y51: 482825.52 | Z51: 482825.52 | AA51: 551472 | AB51: 442888.43
A52: 1 | C52: 단기투자자산(공정가치) | AB52: 37500
A53: 1 | C53: 매출액(수익) | E53: 679521.79 | G53: 429467.46 | H53: 510321.04 | I53: 459131.01 | J53: 788486.16 | K53: 2187405.7 | L53: 439361.13 | M53: 610524.6 | N53: 620671.62 | O53: 780028.04 | P53: 2450585.4 | Q53: 542147.8 | R53: 683326.11 | S53: 637373.3 | T53: 930785.78 | U53: 2793633 | V53: 571805.15 | W53: 617249.03 | X53: 637073.94 | Y53: 1265357.2 | Z53: 3091485.4 | AA53: 643555.8 | AB53: 887824.91
A54: 1 | C54: 매출원가 | E54: 614496.32 | G54: 365999.66 | H54: 438744.36 | I54: 401383.87 | J54: 725983.49 | K54: 1932111.4 | L54: 373861.56 | M54: 525640.22 | N54: 532473.79 | O54: 714661.97 | P54: 2146637.5 | Q54: 456412.06 | R54: 556956.49 | S54: 531967.43 | T54: 834899.54 | U54: 2380235.5 | V54: 462881.37 | W54: 501951.6 | X54: 519999.67 | Y54: 1108883.8 | Z54: 2593716.5 | AA54: 506334.15 | AB54: 708008.58
A55: 1 | C55: 매출총이익 | E55: 65025.47 | G55: 63467.8 | H55: 71576.68 | I55: 57747.14 | J55: 62502.67 | K55: 255294.29 | L55: 65499.57 | M55: 84884.38 | N55: 88197.83 | O55: 65366.08 | P55: 303947.86 | Q55: 85735.74 | R55: 126369.62 | S55: 105405.87 | T55: 95886.24 | U55: 413397.47 | V55: 108923.78 | W55: 115297.43 | X55: 117074.27 | Y55: 156473.42 | Z55: 497768.9 | AA55: 137221.65 | AB55: 179816.32
A56: 1 | C56: 판관비 | E56: 47834.63 | G56: 35599.47 | H56: 39630.22 | I56: 40652.66 | J56: 45732.05 | K56: 161614.4 | L56: 44613.04 | M56: 45630.44 | N56: 42193.89 | O56: 45945.31 | P56: 178382.68 | Q56: 39776.59 | R56: 42227.38 | S56: 44425.58 | T56: 61828.29 | U56: 188257.84 | V56: 47823.95 | W56: 52022.96 | X56: 55207.77 | Y56: 62736.69 | Z56: 217791.37 | AA56: 54870.31 | AB56: 55320.9
...

Sheet subQ
A1: YQ | C1: subQ 분기 서브모델(억원, U=100) | E1: 4Q21 | F1: 2021 | G1: 1Q22 | H1: 2Q22 | I1: 3Q22 | J1: 4Q22 | K1: 2022 | L1: 1Q23 | M1: 2Q23 | N1: 3Q23 | O1: 4Q23 | P1: 2023 | Q1: 1Q24 | R1: 2Q24 | S1: 3Q24 | T1: 4Q24 | U1: 2024 | V1: 1Q25 | W1: 2Q25 | X1: 3Q25 | Y1: 4Q25 | Z1: 2025 | AA1: 1Q26 | AB1: 2Q26 | AC1: 3Q26 | AD1: 4Q26 | AE1: 2026 | AF1: 1Q27 | AG1: 2Q27 | AH1: 3Q27 | AI1: 4Q27 | AJ1: 2027 | AK1: 1Q28 | AL1: 2Q28 | AM1: 3Q28 | AN1: 4Q28 | AO1: 2028
A2: A=이름(key) B=그룹 C=단위 D=FnGuide 계정명(VLOOKUP 키). 확정=VLOOKUP(BS), 추정=변수 가정 참조
E3: 1 | F3: 2 | G3: 3 | H3: 4 | I3: 5 | J3: 6 | K3: 7 | L3: 8 | M3: 9 | N3: 10 | O3: 11 | P3: 12 | Q3: 13 | R3: 14 | S3: 15 | T3: 16 | U3: 17 | V3: 18 | W3: 19 | X3: 20 | Y3: 21 | Z3: 22 | AA3: 23 | AB3: 24 | AC3: 25 | AD3: 26 | AE3: 27 | AF3: 28 | AG3: 29 | AH3: 30 | AI3: 31 | AJ3: 32 | AK3: 33 | AL3: 34 | AM3: 35 | AN3: 36 | AO3: 37
E4: 2021.12 | F4: 2021.12A | G4: 2022.03 | H4: 2022.06 | I4: 2022.09 | J4: 2022.12 | K4: 2022.12A | L4: 2023.03 | M4: 2023.06 | N4: 2023.09 | O4: 2023.12 | P4: 2023.12A | Q4: 2024.03 | R4: 2024.06 | S4: 2024.09 | T4: 2024.12 | U4: 2024.12A | V4: 2025.03 | W4: 2025.06 | X4: 2025.09 | Y4: 2025.12 | Z4: 2025.12A | AA4: 2026.03 | AB4: 2026.06 | AC4: 2026.09 | AD4: 2026.12 | AE4: 2026.12A | AF4: 2027.03 | AG4: 2027.06 | AH4: 2027.09 | AI4: 2027.12 | AJ4: 2027.12A | AK4: 2028.03 | AL4: 2028.06 | AM4: 2028.09 | AN4: 2028.12 | AO4: 2028.12A
A5: 매출액 | B5: 손익 | C5: 억원 | D5: 매출액(수익) | E5: =IFERROR(VLOOKUP($D5,BS연결,MATCH(E$1,BS연결H,0),0)/100,"") | G5: =IFERROR(VLOOKUP($D5,BS연결,MATCH(G$1,BS연결H,0),0)/100,"") | H5: =IFERROR(VLOOKUP($D5,BS연결,MATCH(H$1,BS연결H,0),0)/100,"") | I5: =IFERROR(VLOOKUP($D5,BS연결,MATCH(I$1,BS연결H,0),0)/100,"") | J5: =IFERROR(VLOOKUP($D5,BS연결,MATCH(J$1,BS연결H,0),0)/100,"") | K5: =IFERROR(VLOOKUP($D5,BS연결,MATCH(K$1,BS연결H,0),0)/100,"") | L5: =IFERROR(VLOOKUP($D5,BS연결,MATCH(L$1,BS연결H,0),0)/100,"") | M5: =IFERROR(VLOOKUP($D5,BS연결,MATCH(M$1,BS연결H,0),0)/100,"") | N5: =IFERROR(VLOOKUP($D5,BS연결,MATCH(N$1,BS연결H,0),0)/100,"") | ... AB5: =IFERROR(VLOOKUP($D5,BS연결,MATCH(AB$1,BS연결H,0),0)/100,"") | AC5: =IFERROR(X5*(1+변수!AC21),"") | AD5: =IFERROR(Y5*(1+변수!AD21),"") | AE5: =SUM(AA5:AD5) | AF5: =IFERROR(AA5*(1+변수!AF21),"") | AG5: =IFERROR(AB5*(1+변수!AG21),"") | AH5: =IFERROR(AC5*(1+변수!AH21),"") | AI5: =IFERROR(AD5*(1+변수!AI21),"") | AJ5: =SUM(AF5:AI5) | AK5: =IFERROR(AF5*(1+변수!AK21),"") | AL5: =IFERROR(AG5*(1+변수!AL21),"") | AM5: =IFERROR(AH5*(1+변수!AM21),"") | AN5: =IFERROR(AI5*(1+변수!AN21),"") | AO5: =SUM(AK5:AN5)
A6: 매출원가 | B6: 손익 | C6: 억원 | D6: 매출원가 | E6: =IFERROR(VLOOKUP($D6,BS연결,MATCH(E$1,BS연결H,0),0)/100,"") | G6: =IFERROR(VLOOKUP($D6,BS연결,MATCH(G$1,BS연결H,0),0)/100,"") | H6: =IFERROR(VLOOKUP($D6,BS연결,MATCH(H$1,BS연결H,0),0)/100,"") | I6: =IFERROR(VLOOKUP($D6,BS연결,MATCH(I$1,BS연결H,0),0)/100,"") | J6: =IFERROR(VLOOKUP($D6,BS연결,MATCH(J$1,BS연결H,0),0)/100,"") | K6: =IFERROR(VLOOKUP($D6,BS연결,MATCH(K$1,BS연결H,0),0)/100,"") | L6: =IFERROR(VLOOKUP($D6,BS연결,MATCH(L$1,BS연결H,0),0)/100,"") | M6: =IFERROR(VLOOKUP($D6,BS연결,MATCH(M$1,BS연결H,0),0)/100,"") | N6: =IFERROR(VLOOKUP($D6,BS연결,MATCH(N$1,BS연결H,0),0)/100,"") | ... AB6: =IFERROR(VLOOKUP($D6,BS연결,MATCH(AB$1,BS연결H,0),0)/100,"") | AC6: =IFERROR(AC5-AC7,"") | AD6: =IFERROR(AD5-AD7,"") | AE6: =SUM(AA6:AD6) | AF6: =IFERROR(AF5-AF7,"") | AG6: =IFERROR(AG5-AG7,"") | AH6: =IFERROR(AH5-AH7,"") | AI6: =IFERROR(AI5-AI7,"") | AJ6: =SUM(AF6:AI6) | AK6: =IFERROR(AK5-AK7,"") | AL6: =IFERROR(AL5-AL7,"") | AM6: =IFERROR(AM5-AM7,"") | AN6: =IFERROR(AN5-AN7,"") | AO6: =SUM(AK6:AN6)
A7: 매출총이익 | B7: 손익 | C7: 억원 | D7: 매출총이익 | E7: =IFERROR(VLOOKUP($D7,BS연결,MATCH(E$1,BS연결H,0),0)/100,"") | G7: =IFERROR(VLOOKUP($D7,BS연결,MATCH(G$1,BS연결H,0),0)/100,"") | H7: =IFERROR(VLOOKUP($D7,BS연결,MATCH(H$1,BS연결H,0),0)/100,"") | I7: =IFERROR(VLOOKUP($D7,BS연결,MATCH(I$1,BS연결H,0),0)/100,"") | J7: =IFERROR(VLOOKUP($D7,BS연결,MATCH(J$1,BS연결H,0),0)/100,"") | K7: =IFERROR(VLOOKUP($D7,BS연결,MATCH(K$1,BS연결H,0),0)/100,"") | L7: =IFERROR(VLOOKUP($D7,BS연결,MATCH(L$1,BS연결H,0),0)/100,"") | M7: =IFERROR(VLOOKUP($D7,BS연결,MATCH(M$1,BS연결H,0),0)/100,"") | N7: =IFERROR(VLOOKUP($D7,BS연결,MATCH(N$1,BS연결H,0),0)/100,"") | ... AB7: =IFERROR(VLOOKUP($D7,BS연결,MATCH(AB$1,BS연결H,0),0)/100,"") | AC7: =IFERROR(AC9+AC8,"") | AD7: =IFERROR(AD9+AD8,"") | AE7: =SUM(AA7:AD7) | AF7: =IFERROR(AF9+AF8,"") | AG7: =IFERROR(AG9+AG8,"") | AH7: =IFERROR(AH9+AH8,"") | AI7: =IFERROR(AI9+AI8,"") | AJ7: =SUM(AF7:AI7) | AK7: =IFERROR(AK9+AK8,"") | AL7: =IFERROR(AL9+AL8,"") | AM7: =IFERROR(AM9+AM8,"") | AN7: =IFERROR(AN9+AN8,"") | AO7: =SUM(AK7:AN7)
