Workbook
Name 변수H: 변수!$C$1:$AO$1
Name 환율: 변수!$C$6:$AO$13
Name BS연결H: BS연결!$C$1:$AO$1
Name BS연결: BS연결!$C$5:$AO$112
Name BS별도H: BS별도!$C$1:$AO$1
Name BS별도: BS별도!$C$5:$AO$95
Name SUBQH: subQ!$A$1:$AO$1
Name subQ: subQ!$A$5:$AO$48
Name SLS_H: SLS!$A$1:$BE$1

Sheet README
A1: HD현대중공업(329180) 실적 모델 — ARGUS 한국조선
A2: 기준 분기 2026Q2 · 마지막 실적 2026Q2 · 생성 2026-10-14
A3: 모든 수치는 모델 산출값(DART 공개 재무제표 + 우리 추정)이다 — 목표주가·투자 추천 아님. 참고용 · 투자조언 아님.
A5: 시트
A6: 변수 가정 시계열. 환율 8행(ECB via frankfurter — L2 fx.json; 추정 분기 = 노란 가정), 추정 드라이버(노란 셀 = 모델값에서 역산한 가정, 바꾸면 재계산; 연녹 셀 = 3절 스칼라 참조 수식), 3절 스칼라 가정(세율·판관비율·지배주주비중·이자율·종가·PER 밴드·COE·외화 순노출·헤지비율)
A7: BS연결/BS별도 FnGuide 계정명 × 기간 값 덤프(백만원). 행1 분기라벨, 행4 YYYY.MM / YYYY.12A. 이름정의 BS연결H·BS연결(계정명 C열부터)
A8: subQ 분기 서브모델(억원 = 백만원/100). 확정 행: =IFERROR(VLOOKUP($D행,BS연결,MATCH(E$1,BS연결H,0),0)/100,"") 추정 행: 변수 시트 가정 셀 참조 수식. 외환손익·파생상품손익은 BS 계정 합·차, 기타금융손익은 잔차, OPM·EPS·BPS·PER·PBR 은 파생 수식
A9: SLS 선표(조선사만, sls json 있을 때): 요약 행(sls 저장값) + 계약별 스케줄(백만$) × (헤지비율 × 헤지환율 + (1−헤지비율) × 건조시점 환율[변수 원/달러(평균)]) → 원화 수식 블록 → 합계 행이 subQ 매출조선에 연결
A10: 시나리오 신규수주 보수/기준/낙관(forecast_panel 패널, 모델에 scenarios 가 있을 때만): 매출액·영업이익 = subQ 기준값 ± (시나리오 신규 − base 신규) × OPM. base 만 subQ 행에 포함, 나머지는 합산 안 함
A11: 분기/연간예상 subQ 를 이름(A열 key)으로 VLOOKUP 한 보고서 표(억원)
A12: TP PER 밴드 × 12M fwd EPS, PBR = ROE/COE × BPS — 모델 산출값 구간, 목표주가·추천 아님
A13: 외화 환율 QoQ, 외화 순노출 × Δ기말환율 → 환관련손익 추정
... A36: 백테스트: {"freeze": "2025Q2", "horizon": 4, "revenue_wape_pct": 24.0, "op_wape_pct": 50.3, "n": 4, "note": "단일 회사 4분기 — 통계 아님", "driver_at_freeze": "sls_marine_plus_uncovered_backlog_runoff", "selection_oos_at_freeze": null, "frozen_inputs": "fin(연결/별도)·고객 조선사 모델·지주 자회사 모델은 2025Q2 까지의 분기만; 선표는 체결일 ≤ 2025Q2 말일 계약(원장 최신 금액·코호트 등급, 환산 없음); 잔고는 yards_cache 2025Q2; 시세·환율 forward·prices·forecast_panel 신규수주 미사용. 고객 가중치(suppliers.json 언급 비중)와 합병 체인링크는 현재 지식; 고객 연동 채택은 동결 모델 안에서도 자기 la−4분기 OOS 규칙(selection_oos_at_freeze)", "detail": [{"q": "2025Q3", "rev_pred": 41613.18, "rev_act": 44178.98, "op_pred": 3826.68, "op_act": 5572.85}, {"q": "2025Q4", "rev_pred": 41613.18, "rev_act": 51930.94, "op_pred": 3826.68, "op_act": 5750.35}, {"q": "2026Q1", "rev_pred": 41460.55, "rev_act": 59163.32, "op_pred": 3812.64, "op_act": 9053.86}, {"q": "2026Q2", "rev_pred": 41536.85, "rev_act": 63321.55, "op_pred": 3819.66, "op_act": 10399.38}]}

Sheet 변수
C1: 이름: 변수H | E1: 4Q21 | F1: 2021 | G1: 1Q22 | H1: 2Q22 | I1: 3Q22 | J1: 4Q22 | K1: 2022 | L1: 1Q23 | M1: 2Q23 | N1: 3Q23 | O1: 4Q23 | P1: 2023 | Q1: 1Q24 | R1: 2Q24 | S1: 3Q24 | T1: 4Q24 | U1: 2024 | V1: 1Q25 | W1: 2Q25 | X1: 3Q25 | Y1: 4Q25 | Z1: 2025 | AA1: 1Q26 | AB1: 2Q26 | AC1: 3Q26 | AD1: 4Q26 | AE1: 2026 | AF1: 1Q27 | AG1: 2Q27 | AH1: 3Q27 | AI1: 4Q27 | AJ1: 2027 | AK1: 1Q28 | AL1: 2Q28 | AM1: 3Q28 | AN1: 4Q28 | AO1: 2028
A2: 가정 시계열 — 노란 셀은 추정 가정(모델값에서 역산), 연녹 셀은 3절 스칼라 참조 수식. 바꾸면 subQ·분기·연간예상·TP·시나리오가 재계산됩니다.
E3: 1 | F3: 2 | G3: 3 | H3: 4 | I3: 5 | J3: 6 | K3: 7 | L3: 8 | M3: 9 | N3: 10 | O3: 11 | P3: 12 | Q3: 13 | R3: 14 | S3: 15 | T3: 16 | U3: 17 | V3: 18 | W3: 19 | X3: 20 | Y3: 21 | Z3: 22 | AA3: 23 | AB3: 24 | AC3: 25 | AD3: 26 | AE3: 27 | AF3: 28 | AG3: 29 | AH3: 30 | AI3: 31 | AJ3: 32 | AK3: 33 | AL3: 34 | AM3: 35 | AN3: 36 | AO3: 37
E4: 2021.12 | F4: 2021.12A | G4: 2022.03 | H4: 2022.06 | I4: 2022.09 | J4: 2022.12 | K4: 2022.12A | L4: 2023.03 | M4: 2023.06 | N4: 2023.09 | O4: 2023.12 | P4: 2023.12A | Q4: 2024.03 | R4: 2024.06 | S4: 2024.09 | T4: 2024.12 | U4: 2024.12A | V4: 2025.03 | W4: 2025.06 | X4: 2025.09 | Y4: 2025.12 | Z4: 2025.12A | AA4: 2026.03 | AB4: 2026.06 | AC4: 2026.09 | AD4: 2026.12 | AE4: 2026.12A | AF4: 2027.03 | AG4: 2027.06 | AH4: 2027.09 | AI4: 2027.12 | AJ4: 2027.12A | AK4: 2028.03 | AL4: 2028.06 | AM4: 2028.09 | AN4: 2028.12 | AO4: 2028.12A
B5: 1. FX | C5: 이름: 환율
A6: USDKRW_avg | C6: 원/달러(평균) | E6: 1183.5 | F6: 1145.51 | G6: 1205.78 | H6: 1262.09 | I6: 1341.93 | J6: 1360.12 | K6: 1292.98 | L6: 1276.95 | M6: 1315.69 | N6: 1313.62 | O6: 1322.01 | P6: 1306.85 | Q6: 1330.14 | R6: 1371.28 | S6: 1356.22 | T6: 1396.3 | U6: 1363.53 | V6: 1452.28 | W6: 1398.52 | X6: 1386.95 | Y6: 1449.19 | Z6: 1421.52 | AA6: 1466.12 | AB6: 1501.75 | AC6: 1418.75 | AD6: 1343.39 | AE6: 1456.01 | AF6: 1341.45 | AG6: 1341.45 | AH6: 1341.45 | AI6: 1341.45 | AK6: 1341.45 | AL6: 1341.45 | AM6: 1341.45 | AN6: 1341.45
A7: USDKRW_end | C7: 원/달러(기말) | E7: 1188.75 | F7: 1188.75 | G7: 1213.74 | H7: 1301.24 | I7: 1436.9 | J7: 1260.16 | K7: 1260.16 | L7: 1305.99 | M7: 1321.44 | N7: 1345.35 | O7: 1297.43 | P7: 1297.43 | Q7: 1349.25 | R7: 1377.73 | S7: 1312.17 | T7: 1474.78 | U7: 1474.78 | V7: 1474.54 | W7: 1355.13 | X7: 1403.67 | Y7: 1444.2 | Z7: 1444.2 | AA7: 1524.8 | AB7: 1550.89 | AC7: 1355.4 | AD7: 1341.45 | AE7: 1341.45 | AF7: 1341.45 | AG7: 1341.45 | AH7: 1341.45 | AI7: 1341.45 | AK7: 1341.45 | AL7: 1341.45 | AM7: 1341.45 | AN7: 1341.45
A8: JPY100KRW_avg | C8: 원/100Y(평균) | E8: 1041.02 | F8: 1042.74 | G8: 1036.79 | H8: 972.23 | I8: 970.61 | J8: 961.03 | K8: 985.1 | L8: 964.89 | M8: 957.36 | N8: 909 | O8: 893.22 | P8: 931.11 | Q8: 896.29 | R8: 880.14 | S8: 909.35 | T8: 917.25 | U8: 900.92 | V8: 952.59 | W8: 967.92 | X8: 940.32 | Y8: 940.77 | Z8: 950.17 | AA8: 934.39 | AB8: 942.16 | AC8: 890.41 | AD8: 849.39 | AE8: 918.46 | AF8: 848.37 | AG8: 848.37 | AH8: 848.37 | AI8: 848.37 | AK8: 848.37 | AL8: 848.37 | AM8: 848.37 | AN8: 848.37
A9: JPY100KRW_end | C9: 원/100Y(기말) | E9: 1032.62 | F9: 1032.62 | G9: 996.83 | H9: 954.9 | I9: 993.29 | J9: 955.54 | K9: 955.54 | L9: 980.62 | M9: 913.67 | N9: 901.47 | O9: 917.04 | P9: 917.04 | Q9: 892.42 | R9: 857.76 | S9: 919.21 | T9: 939.65 | U9: 939.65 | V9: 986.84 | W9: 938.85 | X9: 948.49 | Y9: 921.81 | Z9: 921.81 | AA9: 955.99 | AB9: 954.75 | AC9: 863.31 | AD9: 848.37 | AE9: 848.37 | AF9: 848.37 | AG9: 848.37 | AH9: 848.37 | AI9: 848.37 | AK9: 848.37 | AL9: 848.37 | AM9: 848.37 | AN9: 848.37
A10: EURKRW_avg | C10: W/Euro(평균) | E10: 1353.32 | F10: 1354.06 | G10: 1352.29 | H10: 1343.31 | I10: 1350.63 | J10: 1386.07 | K10: 1358.07 | L10: 1369.93 | M10: 1432.41 | N10: 1429.41 | O10: 1420.91 | P10: 1412.88 | Q10: 1444.21 | R10: 1476.42 | S10: 1489.3 | T10: 1490.78 | U10: 1475.4 | V10: 1528.33 | W10: 1585.13 | X10: 1620.04 | Y10: 1686.02 | Z10: 1605.45 | AA10: 1715.47 | AB10: 1746.09 | AC10: 1631.97 | AD10: 1506.62 | AE10: 1688.01 | AF10: 1500.82 | AG10: 1500.82 | AH10: 1500.82 | AI10: 1500.82 | AK10: 1500.82 | AL10: 1500.82 | AM10: 1500.82 | AN10: 1500.82
A11: EURKRW_end | C11: W/Euro(기말) | E11: 1346.38 | F11: 1346.38 | G11: 1347.37 | H11: 1351.6 | I11: 1400.62 | J11: 1344.08 | K11: 1344.08 | L11: 1420.26 | M11: 1435.88 | N11: 1425.26 | O11: 1433.66 | P11: 1433.66 | Q11: 1458.68 | R11: 1474.86 | S11: 1469.1 | T11: 1532.14 | U11: 1532.14 | V11: 1594.72 | W11: 1588.22 | X11: 1648.04 | Y11: 1696.94 | Z11: 1696.94 | AA11: 1753.21 | AB11: 1767.09 | AC11: 1539.06 | AD11: 1500.82 | AE11: 1500.82 | AF11: 1500.82 | AG11: 1500.82 | AH11: 1500.82 | AI11: 1500.82 | AK11: 1500.82 | AL11: 1500.82 | AM11: 1500.82 | AN11: 1500.82
A12: CNYKRW_avg | C12: 원/중국원(평균) | E12: 185.14 | F12: 177.65 | G12: 189.93 | H12: 190.76 | I12: 195.79 | J12: 191.09 | K12: 191.93 | L12: 186.59 | M12: 187.45 | N12: 181.28 | O12: 182.86 | P12: 184.52 | Q12: 185.04 | R12: 189.35 | S12: 189.24 | T12: 194.24 | U12: 189.49 | V12: 199.63 | W12: 193.41 | X12: 193.79 | Y12: 204.38 | Z12: 197.8 | AA12: 211.75 | AB12: 220.8 | AC12: 210.43 | AD12: 200.49 | AE12: 213.61 | AF12: 200.4 | AG12: 200.4 | AH12: 200.4 | AI12: 200.4 | AK12: 200.4 | AL12: 200.4 | AM12: 200.4 | AN12: 200.4
A13: CNYKRW_end | C13: 원/중국원(기말) | E13: 187.13 | F13: 187.13 | G13: 191.38 | H13: 194.13 | I13: 201.92 | J13: 182.67 | K13: 182.67 | L13: 189.97 | M13: 181.8 | N13: 184.26 | O13: 182.61 | P13: 182.61 | Q13: 186.66 | R13: 189.7 | S13: 187.12 | T13: 202.04 | U13: 202.04 | V13: 203.3 | W13: 189.14 | X13: 197.16 | Y13: 206.28 | Z13: 206.28 | AA13: 220.97 | AB13: 228.56 | AC13: 202.16 | AD13: 200.4 | AE13: 200.4 | AF13: 200.4 | AG13: 200.4 | AH13: 200.4 | AI13: 200.4 | AK13: 200.4 | AL13: 200.4 | AM13: 200.4 | AN13: 200.4
B14: 1b. 종가
A15: price_close_end | C15: 종가(기말) | E15: 95200 | G15: 119500 | H15: 143000 | I15: 115000 | J15: 116000 | L15: 100000 | M15: 131700 | N15: 121200 | O15: 129000 | Q15: 118000 | R15: 155700 | S15: 184600 | T15: 287500 | V15: 279000 | W15: 428500 | X15: 515000 | Y15: 509000 | AA15: 465000 | AB15: 592000 | AC15: 434500 | AD15: 369000
A16: price_high | C16: 종가(최고) | E16: 119500 | G16: 124000 | H16: 161500 | I16: 151000 | J16: 125500 | L16: 119500 | M16: 131900 | N16: 149700 | O16: 135900 | Q16: 128500 | R16: 158500 | S16: 222500 | T16: 299000 | V16: 371500 | W16: 476000 | X16: 535000 | Y16: 640000 | AA16: 652000 | AB16: 765000 | AC16: 622000 | AD16: 435500
A17: price_low | C17: 종가(최저) | E17: 89700 | G17: 92700 | H17: 111000 | I17: 112500 | J17: 101500 | L17: 91500 | M17: 96900 | N17: 118400 | O17: 101500 | Q17: 107900 | R17: 110800 | S17: 147400 | T17: 168900 | V17: 271500 | W17: 275500 | X17: 370000 | Y17: 489500 | AA17: 460500 | AB17: 428000 | AC17: 411500 | AD17: 347000
A18: price_avg | C18: 종가(평균) | E18: 105952.4 | G18: 106772.9 | H18: 131112.9 | I18: 129166.7 | J18: 115338.7 | L18: 105532.3 | M18: 115295.1 | N18: 131943.5 | O18: 117131.7 | Q18: 116886.9 | R18: 131906.7 | S18: 185524.2 | T18: 214772.1 | V18: 307482.8 | W18: 391666.7 | X18: 463830.8 | Y18: 547372.9 | AA18: 571906.8 | AB18: 616245.9 | AC18: 478298.4 | AD18: 395062.5
B20: 2. 추정 드라이버 | C20: 실적 열 = subQ 실현값(수식), 추정 열 = 가정(노란 = 모델값 역산, 연녹 = 3절 스칼라 참조)
A21: drv:판관비 | B21: ratio | C21: 판관비율(/매출) | E21: =IFERROR(subQ!E8/subQ!E5,"") | F21: =IFERROR(subQ!F8/subQ!F5,"") | G21: =IFERROR(subQ!G8/subQ!G5,"") | H21: =IFERROR(subQ!H8/subQ!H5,"") | I21: =IFERROR(subQ!I8/subQ!I5,"") | J21: =IFERROR(subQ!J8/subQ!J5,"") | K21: =IFERROR(subQ!K8/subQ!K5,"") | L21: =IFERROR(subQ!L8/subQ!L5,"") | ... AB21: =IFERROR(subQ!AB8/subQ!AB5,"") | AC21: =$D$55 | AD21: =$D$55 | AE21: =IFERROR(subQ!AE8/subQ!AE5,"") | AF21: =$D$55 | AG21: =$D$55 | AH21: =$D$55 | AI21: =$D$55 | AJ21: =IFERROR(subQ!AJ8/subQ!AJ5,"") | AK21: =$D$55 | AL21: =$D$55 | AM21: =$D$55 | AN21: =$D$55 | AO21: =IFERROR(subQ!AO8/subQ!AO5,"")
A22: drv:외환손익 | B22: abs | C22: 외환손익 (가정, 억원) | E22: =subQ!E13 | F22: =subQ!F13 | G22: =subQ!G13 | H22: =subQ!H13 | I22: =subQ!I13 | J22: =subQ!J13 | K22: =subQ!K13 | L22: =subQ!L13 | ... AB22: =subQ!AB13 | AC22: 0 | AD22: 0 | AE22: =subQ!AE13 | AF22: 0 | AG22: 0 | AH22: 0 | AI22: 0 | AJ22: =subQ!AJ13 | AK22: 0 | AL22: 0 | AM22: 0 | AN22: 0 | AO22: =subQ!AO13
A23: drv:파생상품손익 | B23: abs | C23: 파생상품손익 (가정, 억원) | E23: =subQ!E14 | F23: =subQ!F14 | G23: =subQ!G14 | H23: =subQ!H14 | I23: =subQ!I14 | J23: =subQ!J14 | K23: =subQ!K14 | L23: =subQ!L14 | ... AB23: =subQ!AB14 | AC23: 0 | AD23: 0 | AE23: =subQ!AE14 | AF23: 0 | AG23: 0 | AH23: 0 | AI23: 0 | AJ23: =subQ!AJ14 | AK23: 0 | AL23: 0 | AM23: 0 | AN23: 0 | AO23: =subQ!AO14
A24: drv:기타금융손익 | B24: abs | C24: 기타금융손익 (가정, 억원) | E24: =subQ!E15 | F24: =subQ!F15 | G24: =subQ!G15 | H24: =subQ!H15 | I24: =subQ!I15 | J24: =subQ!J15 | K24: =subQ!K15 | L24: =subQ!L15 | ... AB24: =subQ!AB15 | AC24: 0 | AD24: 0 | AE24: =subQ!AE15 | AF24: 0 | AG24: 0 | AH24: 0 | AI24: 0 | AJ24: =subQ!AJ15 | AK24: 0 | AL24: 0 | AM24: 0 | AN24: 0 | AO24: =subQ!AO15
A25: drv:기타영업외손익 | B25: abs | C25: 기타영업외손익 (가정, 억원) | E25: =subQ!E16 | F25: =subQ!F16 | G25: =subQ!G16 | H25: =subQ!H16 | I25: =subQ!I16 | J25: =subQ!J16 | K25: =subQ!K16 | L25: =subQ!L16 | ... AB25: =subQ!AB16 | AC25: 0 | AD25: 0 | AE25: =subQ!AE16 | AF25: 0 | AG25: 0 | AH25: 0 | AI25: 0 | AJ25: =subQ!AJ16 | AK25: 0 | AL25: 0 | AM25: 0 | AN25: 0 | AO25: =subQ!AO16
A26: drv:지분법손익 | B26: abs | C26: 지분법손익 (가정, 억원) | E26: =subQ!E17 | F26: =subQ!F17 | G26: =subQ!G17 | H26: =subQ!H17 | I26: =subQ!I17 | J26: =subQ!J17 | K26: =subQ!K17 | L26: =subQ!L17 | ... AB26: =subQ!AB17 | AC26: -0.07 | AD26: -0.07 | AE26: =subQ!AE17 | AF26: -0.07 | AG26: -0.07 | AH26: -0.07 | AI26: -0.07 | AJ26: =subQ!AJ17 | AK26: -0.07 | AL26: -0.07 | AM26: -0.07 | AN26: -0.07 | AO26: =subQ!AO17
A27: drv:법인세비용 | B27: tax | C27: 법인세율(/세전) — 법인세 = MAX(세전,0) × 세율 | E27: =IFERROR(subQ!E20/subQ!E19,"") | F27: =IFERROR(subQ!F20/subQ!F19,"") | G27: =IFERROR(subQ!G20/subQ!G19,"") | H27: =IFERROR(subQ!H20/subQ!H19,"") | I27: =IFERROR(subQ!I20/subQ!I19,"") | J27: =IFERROR(subQ!J20/subQ!J19,"") | K27: =IFERROR(subQ!K20/subQ!K19,"") | L27: =IFERROR(subQ!L20/subQ!L19,"") | ... AB27: =IFERROR(subQ!AB20/subQ!AB19,"") | AC27: =$D$54 | AD27: =$D$54 | AE27: =IFERROR(subQ!AE20/subQ!AE19,"") | AF27: =$D$54 | AG27: =$D$54 | AH27: =$D$54 | AI27: =$D$54 | AJ27: =IFERROR(subQ!AJ20/subQ!AJ19,"") | AK27: =$D$54 | AL27: =$D$54 | AM27: =$D$54 | AN27: =$D$54 | AO27: =IFERROR(subQ!AO20/subQ!AO19,"")
A28: drv:지배주주순이익 | B28: ratio | C28: 지배주주 비중(/당기순이익) | E28: =IFERROR(subQ!E22/subQ!E21,"") | F28: =IFERROR(subQ!F22/subQ!F21,"") | G28: =IFERROR(subQ!G22/subQ!G21,"") | H28: =IFERROR(subQ!H22/subQ!H21,"") | I28: =IFERROR(subQ!I22/subQ!I21,"") | J28: =IFERROR(subQ!J22/subQ!J21,"") | K28: =IFERROR(subQ!K22/subQ!K21,"") | L28: =IFERROR(subQ!L22/subQ!L21,"") | ... AB28: =IFERROR(subQ!AB22/subQ!AB21,"") | AC28: =$D$56 | AD28: =$D$56 | AE28: =IFERROR(subQ!AE22/subQ!AE21,"") | AF28: =$D$56 | AG28: =$D$56 | AH28: =$D$56 | AI28: =$D$56 | AJ28: =IFERROR(subQ!AJ22/subQ!AJ21,"") | AK28: =$D$56 | AL28: =$D$56 | AM28: =$D$56 | AN28: =$D$56 | AO28: =IFERROR(subQ!AO22/subQ!AO21,"")
A29: drv:부채총계 | B29: qoq | C29: 부채총계 QoQ | G29: =IFERROR(subQ!G24/subQ!E24-1,"") | H29: =IFERROR(subQ!H24/subQ!G24-1,"") | I29: =IFERROR(subQ!I24/subQ!H24-1,"") | J29: =IFERROR(subQ!J24/subQ!I24-1,"") | L29: =IFERROR(subQ!L24/subQ!J24-1,"") | M29: =IFERROR(subQ!M24/subQ!L24-1,"") | N29: =IFERROR(subQ!N24/subQ!M24-1,"") | O29: =IFERROR(subQ!O24/subQ!N24-1,"") | Q29: =IFERROR(subQ!Q24/subQ!O24-1,"") | R29: =IFERROR(subQ!R24/subQ!Q24-1,"") | S29: =IFERROR(subQ!S24/subQ!R24-1,"") | T29: =IFERROR(subQ!T24/subQ!S24-1,"") | V29: =IFERROR(subQ!V24/subQ!T24-1,"") | W29: =IFERROR(subQ!W24/subQ!V24-1,"") | X29: =IFERROR(subQ!X24/subQ!W24-1,"") | Y29: =IFERROR(subQ!Y24/subQ!X24-1,"") | AA29: =IFERROR(subQ!AA24/subQ!Y24-1,"") | AB29: =IFERROR(subQ!AB24/subQ!AA24-1,"") | AC29: -2e-09 | AD29: 0 | AF29: 0 | AG29: 0 | AH29: 0 | AI29: 0 | AK29: 0 | AL29: 0 | AM29: 0 | AN29: 0
A30: drv:자본총계 | B30: roll | C30: 자본총계 기타변동(배당 등, 억원) | G30: =IFERROR(subQ!E25+subQ!G21-subQ!G25,"") | H30: =IFERROR(subQ!G25+subQ!H21-subQ!H25,"") | I30: =IFERROR(subQ!H25+subQ!I21-subQ!I25,"") | J30: =IFERROR(subQ!I25+subQ!J21-subQ!J25,"") | L30: =IFERROR(subQ!J25+subQ!L21-subQ!L25,"") | M30: =IFERROR(subQ!L25+subQ!M21-subQ!M25,"") | N30: =IFERROR(subQ!M25+subQ!N21-subQ!N25,"") | O30: =IFERROR(subQ!N25+subQ!O21-subQ!O25,"") | Q30: =IFERROR(subQ!O25+subQ!Q21-subQ!Q25,"") | R30: =IFERROR(subQ!Q25+subQ!R21-subQ!R25,"") | S30: =IFERROR(subQ!R25+subQ!S21-subQ!S25,"") | T30: =IFERROR(subQ!S25+subQ!T21-subQ!T25,"") | V30: =IFERROR(subQ!T25+subQ!V21-subQ!V25,"") | W30: =IFERROR(subQ!V25+subQ!W21-subQ!W25,"") | X30: =IFERROR(subQ!W25+subQ!X21-subQ!X25,"") | Y30: =IFERROR(subQ!X25+subQ!Y21-subQ!Y25,"") | AA30: =IFERROR(subQ!Y25+subQ!AA21-subQ!AA25,"") | AB30: =IFERROR(subQ!AA25+subQ!AB21-subQ!AB25,"") | AC30: 0.001846638 | AD30: -0.003953463 | AF30: 0.000615447 | AG30: 5940.2406 | AH30: 0.009846201 | AI30: -0.003687078 | AK30: 0.00723402 | AL30: 5940.251 | AM30: 0.004250544 | AN30: -0.003765865
A31: drv:지배주주지분 | B31: roll | C31: 지배주주지분 기타변동(배당 등, 억원) | G31: =IFERROR(subQ!E26+subQ!G22-subQ!G26,"") | H31: =IFERROR(subQ!G26+subQ!H22-subQ!H26,"") | I31: =IFERROR(subQ!H26+subQ!I22-subQ!I26,"") | J31: =IFERROR(subQ!I26+subQ!J22-subQ!J26,"") | L31: =IFERROR(subQ!J26+subQ!L22-subQ!L26,"") | M31: =IFERROR(subQ!L26+subQ!M22-subQ!M26,"") | N31: =IFERROR(subQ!M26+subQ!N22-subQ!N26,"") | O31: =IFERROR(subQ!N26+subQ!O22-subQ!O26,"") | Q31: =IFERROR(subQ!O26+subQ!Q22-subQ!Q26,"") | R31: =IFERROR(subQ!Q26+subQ!R22-subQ!R26,"") | S31: =IFERROR(subQ!R26+subQ!S22-subQ!S26,"") | T31: =IFERROR(subQ!S26+subQ!T22-subQ!T26,"") | V31: =IFERROR(subQ!T26+subQ!V22-subQ!V26,"") | W31: =IFERROR(subQ!V26+subQ!W22-subQ!W26,"") | X31: =IFERROR(subQ!W26+subQ!X22-subQ!X26,"") | Y31: =IFERROR(subQ!X26+subQ!Y22-subQ!Y26,"") | AA31: =IFERROR(subQ!Y26+subQ!AA22-subQ!AA26,"") | AB31: =IFERROR(subQ!AA26+subQ!AB22-subQ!AB26,"") | AC31: -0.0015741 | AD31: -0.004779296 | AF31: -0.000234528 | AG31: 5940.2497 | AH31: -0.001099846 | AI31: 0.005304503 | AK31: 0.006160329 | AL31: 5940.2499 | AM31: 0.003054234 | AN31: -0.005005766
A32: drv:총차입금 | B32: qoq | C32: 총차입금 QoQ | G32: =IFERROR(subQ!G27/subQ!E27-1,"") | H32: =IFERROR(subQ!H27/subQ!G27-1,"") | I32: =IFERROR(subQ!I27/subQ!H27-1,"") | J32: =IFERROR(subQ!J27/subQ!I27-1,"") | L32: =IFERROR(subQ!L27/subQ!J27-1,"") | M32: =IFERROR(subQ!M27/subQ!L27-1,"") | N32: =IFERROR(subQ!N27/subQ!M27-1,"") | O32: =IFERROR(subQ!O27/subQ!N27-1,"") | Q32: =IFERROR(subQ!Q27/subQ!O27-1,"") | R32: =IFERROR(subQ!R27/subQ!Q27-1,"") | S32: =IFERROR(subQ!S27/subQ!R27-1,"") | T32: =IFERROR(subQ!T27/subQ!S27-1,"") | V32: =IFERROR(subQ!V27/subQ!T27-1,"") | W32: =IFERROR(subQ!W27/subQ!V27-1,"") | X32: =IFERROR(subQ!X27/subQ!W27-1,"") | Y32: =IFERROR(subQ!Y27/subQ!X27-1,"") | AA32: =IFERROR(subQ!AA27/subQ!Y27-1,"") | AB32: =IFERROR(subQ!AB27/subQ!AA27-1,"") | AC32: 8.22e-07 | AD32: 0 | AF32: 0 | AG32: 0 | AH32: 0 | AI32: 0 | AK32: 0 | AL32: 0 | AM32: 0 | AN32: 0
A33: drv:순차입금 | B33: qoq | C33: 순차입금 QoQ | G33: =IFERROR(subQ!G28/subQ!E28-1,"") | H33: =IFERROR(subQ!H28/subQ!G28-1,"") | I33: =IFERROR(subQ!I28/subQ!H28-1,"") | J33: =IFERROR(subQ!J28/subQ!I28-1,"") | L33: =IFERROR(subQ!L28/subQ!J28-1,"") | M33: =IFERROR(subQ!M28/subQ!L28-1,"") | N33: =IFERROR(subQ!N28/subQ!M28-1,"") | O33: =IFERROR(subQ!O28/subQ!N28-1,"") | Q33: =IFERROR(subQ!Q28/subQ!O28-1,"") | R33: =IFERROR(subQ!R28/subQ!Q28-1,"") | S33: =IFERROR(subQ!S28/subQ!R28-1,"") | T33: =IFERROR(subQ!T28/subQ!S28-1,"") | V33: =IFERROR(subQ!V28/subQ!T28-1,"") | W33: =IFERROR(subQ!W28/subQ!V28-1,"") | X33: =IFERROR(subQ!X28/subQ!W28-1,"") | Y33: =IFERROR(subQ!Y28/subQ!X28-1,"") | AA33: =IFERROR(subQ!AA28/subQ!Y28-1,"") | AB33: =IFERROR(subQ!AB28/subQ!AA28-1,"") | AC33: 0.12000928 | AD33: 0.10781562 | AF33: 0.10016767 | AG33: 0.024233599 | AH33: 0.098940854 | AI33: 0.095968948 | AK33: 0.093233113 | AL33: 0.037486219 | AM33: 0.091588291 | AN33: 0.086960903
A34: drv:이자발생자산 | B34: qoq | C34: 이자발생자산 QoQ | G34: =IFERROR(subQ!G29/subQ!E29-1,"") | H34: =IFERROR(subQ!H29/subQ!G29-1,"") | I34: =IFERROR(subQ!I29/subQ!H29-1,"") | J34: =IFERROR(subQ!J29/subQ!I29-1,"") | L34: =IFERROR(subQ!L29/subQ!J29-1,"") | M34: =IFERROR(subQ!M29/subQ!L29-1,"") | N34: =IFERROR(subQ!N29/subQ!M29-1,"") | O34: =IFERROR(subQ!O29/subQ!N29-1,"") | Q34: =IFERROR(subQ!Q29/subQ!O29-1,"") | R34: =IFERROR(subQ!R29/subQ!Q29-1,"") | S34: =IFERROR(subQ!S29/subQ!R29-1,"") | T34: =IFERROR(subQ!T29/subQ!S29-1,"") | V34: =IFERROR(subQ!V29/subQ!T29-1,"") | W34: =IFERROR(subQ!W29/subQ!V29-1,"") | X34: =IFERROR(subQ!X29/subQ!W29-1,"") | Y34: =IFERROR(subQ!Y29/subQ!X29-1,"") | AA34: =IFERROR(subQ!AA29/subQ!Y29-1,"") | AB34: =IFERROR(subQ!AB29/subQ!AA29-1,"") | AC34: 0.11004074 | AD34: 0.099747731 | AF34: 0.093351937 | AG34: 0.022725454 | AH34: 0.092920226 | AI34: 0.090625663 | AK34: 0.088473495 | AL34: 0.03572807 | AM34: 0.087440869 | AN34: 0.083339668
A35: drv:현금및현금성자산 | B35: qoq | C35: 현금및현금성자산 QoQ | G35: =IFERROR(subQ!G30/subQ!E30-1,"") | H35: =IFERROR(subQ!H30/subQ!G30-1,"") | I35: =IFERROR(subQ!I30/subQ!H30-1,"") | J35: =IFERROR(subQ!J30/subQ!I30-1,"") | L35: =IFERROR(subQ!L30/subQ!J30-1,"") | M35: =IFERROR(subQ!M30/subQ!L30-1,"") | N35: =IFERROR(subQ!N30/subQ!M30-1,"") | O35: =IFERROR(subQ!O30/subQ!N30-1,"") | Q35: =IFERROR(subQ!Q30/subQ!O30-1,"") | R35: =IFERROR(subQ!R30/subQ!Q30-1,"") | S35: =IFERROR(subQ!S30/subQ!R30-1,"") | T35: =IFERROR(subQ!T30/subQ!S30-1,"") | V35: =IFERROR(subQ!V30/subQ!T30-1,"") | W35: =IFERROR(subQ!W30/subQ!V30-1,"") | X35: =IFERROR(subQ!X30/subQ!W30-1,"") | Y35: =IFERROR(subQ!Y30/subQ!X30-1,"") | AA35: =IFERROR(subQ!AA30/subQ!Y30-1,"") | AB35: =IFERROR(subQ!AB30/subQ!AA30-1,"")
A36: drv:CAPEX | B36: yoy | C36: CAPEX YoY | J36: =IFERROR(subQ!J31/subQ!E31-1,"") | L36: =IFERROR(subQ!L31/subQ!G31-1,"") | M36: =IFERROR(subQ!M31/subQ!H31-1,"") | N36: =IFERROR(subQ!N31/subQ!I31-1,"") | O36: =IFERROR(subQ!O31/subQ!J31-1,"") | Q36: =IFERROR(subQ!Q31/subQ!L31-1,"") | R36: =IFERROR(subQ!R31/subQ!M31-1,"") | S36: =IFERROR(subQ!S31/subQ!N31-1,"") | T36: =IFERROR(subQ!T31/subQ!O31-1,"") | V36: =IFERROR(subQ!V31/subQ!Q31-1,"") | W36: =IFERROR(subQ!W31/subQ!R31-1,"") | X36: =IFERROR(subQ!X31/subQ!S31-1,"") | Y36: =IFERROR(subQ!Y31/subQ!T31-1,"") | AA36: =IFERROR(subQ!AA31/subQ!V31-1,"") | AB36: =IFERROR(subQ!AB31/subQ!W31-1,"") | AC36: -0.060772002 | AD36: 0.022962206 | AF36: -0.021958407 | AG36: 0.027331156 | AH36: 0 | AI36: 0 | AK36: 0 | AL36: 0 | AM36: 0 | AN36: 0
A37: drv:영업활동현금흐름 | B37: yoy | C37: 영업활동현금흐름 YoY | J37: =IFERROR(subQ!J32/subQ!E32-1,"") | L37: =IFERROR(subQ!L32/subQ!G32-1,"") | M37: =IFERROR(subQ!M32/subQ!H32-1,"") | N37: =IFERROR(subQ!N32/subQ!I32-1,"") | O37: =IFERROR(subQ!O32/subQ!J32-1,"") | Q37: =IFERROR(subQ!Q32/subQ!L32-1,"") | R37: =IFERROR(subQ!R32/subQ!M32-1,"") | S37: =IFERROR(subQ!S32/subQ!N32-1,"") | T37: =IFERROR(subQ!T32/subQ!O32-1,"") | V37: =IFERROR(subQ!V32/subQ!Q32-1,"") | W37: =IFERROR(subQ!W32/subQ!R32-1,"") | X37: =IFERROR(subQ!X32/subQ!S32-1,"") | Y37: =IFERROR(subQ!Y32/subQ!T32-1,"") | AA37: =IFERROR(subQ!AA32/subQ!V32-1,"") | AB37: =IFERROR(subQ!AB32/subQ!W32-1,"")
A38: drv:주식수 | B38: qoq | C38: 주식수 QoQ | G38: =IFERROR(subQ!G33/subQ!E33-1,"") | H38: =IFERROR(subQ!H33/subQ!G33-1,"") | I38: =IFERROR(subQ!I33/subQ!H33-1,"") | J38: =IFERROR(subQ!J33/subQ!I33-1,"") | L38: =IFERROR(subQ!L33/subQ!J33-1,"") | M38: =IFERROR(subQ!M33/subQ!L33-1,"") | N38: =IFERROR(subQ!N33/subQ!M33-1,"") | O38: =IFERROR(subQ!O33/subQ!N33-1,"") | Q38: =IFERROR(subQ!Q33/subQ!O33-1,"") | R38: =IFERROR(subQ!R33/subQ!Q33-1,"") | S38: =IFERROR(subQ!S33/subQ!R33-1,"") | T38: =IFERROR(subQ!T33/subQ!S33-1,"") | V38: =IFERROR(subQ!V33/subQ!T33-1,"") | W38: =IFERROR(subQ!W33/subQ!V33-1,"") | X38: =IFERROR(subQ!X33/subQ!W33-1,"") | Y38: =IFERROR(subQ!Y33/subQ!X33-1,"") | AA38: =IFERROR(subQ!AA33/subQ!Y33-1,"") | AB38: =IFERROR(subQ!AB33/subQ!AA33-1,"") | AC38: 0 | AD38: 0 | AF38: 0 | AG38: 0 | AH38: 0 | AI38: 0 | AK38: 0 | AL38: 0 | AM38: 0 | AN38: 0
A39: drv:DPS | B39: abs | C39: DPS (가정, 원) | E39: =subQ!E36 | F39: =subQ!F36 | G39: =subQ!G36 | H39: =subQ!H36 | I39: =subQ!I36 | J39: =subQ!J36 | K39: =subQ!K36 | L39: =subQ!L36 | ... AB39: =subQ!AB36 | AD39: 5661 | AE39: =subQ!AE36 | AI39: 5661 | AJ39: =subQ!AJ36 | AN39: 5661 | AO39: =subQ!AO36
A40: drv:매출조선 | B40: sls_link | C40: 원장 밖 잔고 소진(억원) — 매출조선 = SLS 원화/100 + 이 행 + 매출조선신규 | N40: =IFERROR(subQ!N39-SLS!E124/100,"") | O40: =IFERROR(subQ!O39-SLS!F124/100,"") | Q40: =IFERROR(subQ!Q39-SLS!G124/100,"") | R40: =IFERROR(subQ!R39-SLS!H124/100,"") | S40: =IFERROR(subQ!S39-SLS!I124/100,"") | T40: =IFERROR(subQ!T39-SLS!J124/100,"") | V40: =IFERROR(subQ!V39-SLS!K124/100,"") | W40: =IFERROR(subQ!W39-SLS!L124/100,"") | X40: =IFERROR(subQ!X39-SLS!M124/100,"") | Y40: =IFERROR(subQ!Y39-SLS!N124/100,"") | AA40: =IFERROR(subQ!AA39-SLS!O124/100,"") | AB40: =IFERROR(subQ!AB39-SLS!P124/100,"") | AC40: 35378.05 | AD40: 35827.501 | AF40: 35805.243 | AG40: 35816.094 | AH40: 35827.016 | AI40: 35827.091 | AK40: 35816.105 | AL40: 35816.106 | AM40: 35827.09 | AN40: 35827.15
A41: drv:매출조선신규 | B41: abs | C41: 매출조선신규 (forecast_panel base · 공시 상계 신규수주 매출, 억원 — 가정) | E41: =subQ!E40 | F41: =subQ!F40 | G41: =subQ!G40 | H41: =subQ!H40 | I41: =subQ!I40 | J41: =subQ!J40 | K41: =subQ!K40 | L41: =subQ!L40 | ... AB41: =subQ!AB40 | AC41: 0 | AD41: 713.92 | AE41: =subQ!AE40 | AF41: 2954 | AG41: 6661.68 | AH41: 11468.92 | AI41: 17007.63 | AJ41: =subQ!AJ40 | AK41: 22909.76 | AL41: 28807.24 | AM41: 34331.99 | AN41: 39115.96 | AO41: =subQ!AO40
...

Sheet BS연결
B1: (백만원) | C1: 이름: BS연결H | E1: 4Q21 | F1: 2021 | G1: 1Q22 | H1: 2Q22 | I1: 3Q22 | J1: 4Q22 | K1: 2022 | L1: 1Q23 | M1: 2Q23 | N1: 3Q23 | O1: 4Q23 | P1: 2023 | Q1: 1Q24 | R1: 2Q24 | S1: 3Q24 | T1: 4Q24 | U1: 2024 | V1: 1Q25 | W1: 2Q25 | X1: 3Q25 | Y1: 4Q25 | Z1: 2025 | AA1: 1Q26 | AB1: 2Q26 | AC1: 3Q26 | AD1: 4Q26 | AE1: 2026 | AF1: 1Q27 | AG1: 2Q27 | AH1: 3Q27 | AI1: 4Q27 | AJ1: 2027 | AK1: 1Q28 | AL1: 2Q28 | AM1: 3Q28 | AN1: 4Q28 | AO1: 2028
B2: 연결 | D2: fin json(kship_fin.py)
B3: HD현대중공업(연) | C3: UPDATE: 26-10-14 | E3: 1 | F3: 2 | G3: 3 | H3: 4 | I3: 5 | J3: 6 | K3: 7 | L3: 8 | M3: 9 | N3: 10 | O3: 11 | P3: 12 | Q3: 13 | R3: 14 | S3: 15 | T3: 16 | U3: 17 | V3: 18 | W3: 19 | X3: 20 | Y3: 21 | Z3: 22 | AA3: 23 | AB3: 24 | AC3: 25 | AD3: 26 | AE3: 27 | AF3: 28 | AG3: 29 | AH3: 30 | AI3: 31 | AJ3: 32 | AK3: 33 | AL3: 34 | AM3: 35 | AN3: 36 | AO3: 37
B4: Account Code | C4: AccountNAME | E4: 2021.12 | F4: 2021.12A | G4: 2022.03 | H4: 2022.06 | I4: 2022.09 | J4: 2022.12 | K4: 2022.12A | L4: 2023.03 | M4: 2023.06 | N4: 2023.09 | O4: 2023.12 | P4: 2023.12A | Q4: 2024.03 | R4: 2024.06 | S4: 2024.09 | T4: 2024.12 | U4: 2024.12A | V4: 2025.03 | W4: 2025.06 | X4: 2025.09 | Y4: 2025.12 | Z4: 2025.12A | AA4: 2026.03 | AB4: 2026.06 | AC4: 2026.09 | AD4: 2026.12 | AE4: 2026.12A | AF4: 2027.03 | AG4: 2027.06 | AH4: 2027.09 | AI4: 2027.12 | AJ4: 2027.12A | AK4: 2028.03 | AL4: 2028.06 | AM4: 2028.09 | AN4: 2028.12 | AO4: 2028.12A
A5: 1 | C5: 유동자산 | E5: 7886064.9 | F5: 7886064.9 | G5: 7731369.7 | H5: 8371718.1 | I5: 9009512.3 | J5: 8000865.9 | K5: 8000865.9 | L5: 8644922.8 | M5: 8900996.9 | N5: 9459114.2 | O5: 8799684.1 | P5: 8799684.1 | Q5: 8984373.7 | R5: 9085824.7 | S5: 8505588.6 | T5: 10403122 | U5: 10403122 | V5: 11956276 | W5: 11299361 | X5: 12293516 | Y5: 14980009 | Z5: 14980009 | AA5: 16185175 | AB5: 17952609
A6: 1 | C6: 현금및현금성자산 | E6: 2137391.4 | F6: 2137391.4 | G6: 1778545.2 | H6: 1647639.9 | I6: 1514079.8 | J6: 744148.12 | K6: 744148.12 | L6: 844743.65 | M6: 763327.15 | N6: 1014008.4 | O6: 928043.11 | P6: 928043.11 | Q6: 728591.78 | R6: 770024.38 | S6: 268526.5 | T6: 1257867.1 | U6: 1257867.1 | V6: 2736801.9 | W6: 2354964.6 | X6: 2355097.9 | Y6: 1869917.7 | Z6: 1869917.7 | AA6: 2975455.8 | AB6: 4550913.2
A7: 1 | C7: 단기금융상품 | E7: 151000 | F7: 151000 | G7: 151000 | H7: 181017.42 | I7: 151026.42 | J7: 161000 | K7: 161000 | L7: 161000 | M7: 131000 | N7: 131000 | O7: 131000 | P7: 131000 | Q7: 131000.01 | R7: 131000 | S7: 131000 | T7: 131000 | U7: 131000 | V7: 131000 | W7: 481000 | X7: 1671000 | Y7: 1702500 | Z7: 1702500 | AA7: 1284000 | AB7: 922000
A8: 1 | C8: 단기금융자산 | E8: 259137.32 | F8: 259137.32 | G8: 314512.06 | H8: 548823.98 | I8: 974210.98 | J8: 485992.28 | K8: 485992.28 | L8: 547844.55 | M8: 526571.39 | N8: 608327.41 | O8: 432686.75 | P8: 432686.75 | Q8: 559683.45 | R8: 673414.52 | S8: 462191.31 | T8: 954876.65 | U8: 954876.65 | V8: 804978.33 | W8: 771947.75 | X8: 2012261.4 | Y8: 2211181.1 | Z8: 2211181.1 | AA8: 2212931.5 | AB8: 2031825.8
A9: 1 | C9: 매출채권및기타채권 | E9: 1032431.2 | F9: 1032431.2 | G9: 873375.34 | H9: 1534385.6 | I9: 1091182.4 | J9: 1135986.6 | K9: 1135986.6 | L9: 1416503.2 | M9: 1391656.7 | N9: 1409062.3 | O9: 1386425.1 | P9: 1386425.1 | Q9: 1380041 | R9: 1552926.9 | S9: 1583631.6 | T9: 1659563 | U9: 1659563 | V9: 1872571.4 | W9: 1713157.5 | X9: 1702043.8 | Y9: 1713176.6 | Z9: 1713176.6 | AA9: 1629663.1 | AB9: 1773669.7
A10: 1 | C10: 계약자산 | E10: 2836711.4 | F10: 2836711.4 | G10: 3073532.6 | H10: 2863561.3 | I10: 3254217.4 | J10: 3180079.7 | K10: 3180079.7 | L10: 3232105.7 | M10: 3494267.8 | N10: 3647358.6 | O10: 3458668.9 | P10: 3458668.9 | Q10: 3515123.4 | R10: 3396531 | S10: 3397567.1 | T10: 3573015.7 | U10: 3573015.7 | V10: 3273711.1 | W10: 3118247.5 | X10: 2988952.8 | Y10: 5131962.9 | Z10: 5131962.9 | AA10: 5344888 | AB10: 5656017.1
A11: 1 | C11: 재고자산 | E11: 898666.74 | F11: 898666.74 | G11: 955114.32 | H11: 1011856.2 | I11: 1289281.2 | J11: 1377137.5 | K11: 1377137.5 | L11: 1453476.1 | M11: 1433760.2 | N11: 1433016.4 | O11: 1309807.3 | P11: 1309807.3 | Q11: 1517713.4 | R11: 1447893.5 | S11: 1544622.2 | T11: 1510905.6 | U11: 1510905.6 | V11: 1662745.5 | W11: 1711077.7 | X11: 1764922.8 | Y11: 2016750.9 | Z11: 2016750.9 | AA11: 1981798.2 | AB11: 2020764.5
A12: 1 | C12: 유동파생상품자산 | E12: 11368.27 | F12: 11368.27 | G12: 39634.66 | H12: 69702.84 | I12: 131045.43 | J12: 106450.66 | K12: 106450.66 | L12: 102084.18 | M12: 104796.3 | N12: 99587.15 | O12: 104488.45 | P12: 104488.45 | Q12: 24628.9 | R12: 3770.28 | S12: 72075.84 | T12: 927.29 | U12: 927.29 | V12: 2644.75 | W12: 66289.1 | X12: 11211.79 | Y12: 8611.82 | Z12: 8611.82 | AA12: 88344.33 | AB12: 99217.49
A13: 1 | C13: 유동확정계약자산 | E13: 96769.05 | F13: 96769.05 | G13: 123877.4 | H13: 298103.72 | I13: 692139.13 | J13: 218541.62 | K13: 218541.62 | L13: 284760.37 | M13: 290775.09 | N13: 377740.26 | O13: 197198.3 | P13: 197198.3 | Q13: 404054.54 | R13: 538644.24 | S13: 259115.47 | T13: 822949.36 | U13: 822949.36 | V13: 671333.58 | W13: 224658.65 | X13: 330049.56 | Y13: 500069.33 | Z13: 500069.33 | AA13: 840587.19 | AB13: 1010608.3
A14: 1 | C14: 당기법인세자산(선급법인세) | E14: 2447.05 | F14: 2447.05 | G14: 3543.2 | H14: 2225.52 | I14: 3567.84 | J14: 5192.93 | K14: 5192.93 | L14: 6561.62 | M14: 2724.72 | N14: 3872.75 | O14: 5481.78 | P14: 5481.78 | Q14: 7337.46 | R14: 140.7 | S14: 66.71 | T14: 45.45 | U14: 45.45 | V14: 71.56 | W14: 0 | X14: 0 | Y14: 0 | Z14: 0
A15: 1 | C15: 매각예정비유동자산및처분자산 | E15: 4719.32 | F15: 4719.32 | O15: 0 | P15: 0
A16: 1 | C16: 기타유동자산 | E16: 714560.46 | F16: 714560.46 | G16: 732746.95 | H16: 763225.7 | I16: 882972.75 | J16: 1072328.8 | K16: 1072328.8 | L16: 1143688 | M16: 1288689.1 | N16: 1343468.3 | O16: 1278571.2 | P16: 1278571.2 | Q16: 1275883.1 | R16: 1244893.7 | S16: 1248983.2 | T16: 1446848.4 | U16: 1446848.4 | V16: 1605395.9 | W16: 1629966.3 | X16: 1470237.5 | Y16: 2037020.3 | Z16: 2037020.3 | AA16: 2040438 | AB16: 1919419.1
A17: 1 | C17: 비유동자산 | E17: 7192606.6 | F17: 7192606.6 | G17: 7326280.2 | H17: 7853155.6 | I17: 8860497.6 | J17: 8288532.1 | K17: 8288532.1 | L17: 8338649.2 | M17: 8340330.3 | N17: 8493865.6 | O17: 8333934 | P17: 8333934 | Q17: 8442535.2 | R17: 8612612.7 | S17: 8350275.5 | T17: 8987824.9 | U17: 8987824.9 | V17: 8948270.4 | W17: 8442078.2 | X17: 8500096.6 | Y17: 11183035 | Z17: 11183035 | AA17: 11392013 | AB17: 11419496
A18: 1 | C18: 종속기업및관계기업투자 | E18: 2789.84 | F18: 2789.84 | G18: 2691.61 | H18: 2502.7 | I18: 2374.96 | J18: 1345.76 | K18: 1345.76 | L18: 1245.92 | M18: 1144.92 | N18: 1057.93 | O18: 1331.63 | P18: 1331.63 | Q18: 1191.87 | R18: 1061.4 | S18: 933.23 | T18: 1132.87 | U18: 1132.87 | V18: 1030.49 | W18: 936.91 | X18: 0 | Y18: 305260.99 | Z18: 305260.99 | AA18: 322053.8 | AB18: 328762.4
A19: 1 | C19: 투자자산 | E19: 201161.17 | F19: 201161.17 | G19: 199975.28 | H19: 604415.13 | I19: 1474644.8 | J19: 494994.5 | K19: 494994.5 | L19: 469291.6 | M19: 399784.34 | N19: 483788.98 | O19: 308240.49 | P19: 308240.49 | Q19: 392144.48 | R19: 556170.77 | S19: 274295.41 | T19: 1070170.8 | U19: 1070170.8 | V19: 1070020.3 | W19: 438371.68 | X19: 590583 | Y19: 1214175.2 | Z19: 1214175.2 | AA19: 1691578.7 | AB19: 1722652.1
A20: 1 | C20: 장기금융자산 | E20: 9560.27 | F20: 9560.27 | G20: 9560.27 | H20: 9554.27 | I20: 9554.27 | J20: 9554.27 | K20: 9554.27 | L20: 9554.27 | M20: 10554.27 | N20: 10554.27 | O20: 10562.23 | P20: 10562.23 | Q20: 10562.23 | R20: 10562.23 | S20: 10562.23 | T20: 10562.23 | U20: 10562.23 | V20: 10562.23 | W20: 10562.23 | X20: 10562.23 | Y20: 25480.06 | Z20: 25480.06 | AA20: 25494.18 | AB20: 25509.37
A21: 1 | C21: 장기매출채권및기타채권 | E21: 38942.19 | F21: 38942.19 | G21: 47787.87 | H21: 97432.15 | I21: 168877.73 | J21: 176766.79 | K21: 176766.79 | L21: 205534.06 | M21: 199004.31 | N21: 216154.11 | O21: 168216.13 | P21: 168216.13 | Q21: 176985.59 | R21: 161036.32 | S21: 137038.47 | T21: 125839.47 | U21: 125839.47 | V21: 100074.38 | W21: 89806.83 | X21: 83283.23 | Y21: 92825.89 | Z21: 92825.89 | AA21: 91716.34 | AB21: 94035.67
A22: 1 | C22: 투자부동산 | E22: 4108.68 | F22: 4108.68 | G22: 1486.97 | H22: 1477.15 | I22: 1467.33 | J22: 1457.52 | K22: 1457.52 | L22: 1447.7 | M22: 1437.88 | N22: 1428.07 | O22: 1418.25 | P22: 1418.25 | Q22: 1408.43 | R22: 1398.61 | S22: 1388.8 | T22: 1378.98 | U22: 1378.98 | V22: 1369.16 | W22: 1359.35 | X22: 1349.53 | Y22: 1339.71 | Z22: 1339.71 | AA22: 1329.89 | AB22: 1320.08
A23: 1 | C23: 유형자산 | E23: 5986254.8 | F23: 5986254.8 | G23: 6034621.2 | H23: 6063618.4 | I23: 6155308.9 | J23: 6237402.6 | K23: 6237402.6 | L23: 6285258.8 | M23: 6345666.1 | N23: 6402169.2 | O23: 6452067.7 | P23: 6452067.7 | Q23: 6476802.9 | R23: 6519937.6 | S23: 6566633.3 | T23: 6609789 | U23: 6609789 | V23: 6709772.4 | W23: 6969670.6 | X23: 7020680.7 | Y23: 8780697.1 | Z23: 8780697.1 | AA23: 8778998.4 | AB23: 8853605.5
A24: 1 | C24: 무형자산 | E24: 79457.82 | F24: 79457.82 | G24: 80867.62 | H24: 82648.44 | I24: 89452.56 | J24: 100465.28 | K24: 100465.28 | L24: 104102.2 | M24: 107161.67 | N24: 111859.43 | O24: 108419.95 | P24: 108419.95 | Q24: 111949.57 | R24: 115445.26 | S24: 118152.46 | T24: 128126.18 | U24: 128126.18 | V24: 127920.59 | W24: 133293.01 | X24: 127612.81 | Y24: 161134.67 | Z24: 161134.67 | AA24: 160918.55 | AB24: 161245.31
A25: 1 | C25: 사용권자산 | E25: 17906.01 | F25: 17906.01 | G25: 21299.24 | H25: 22944.07 | I25: 22153.53 | J25: 43390.37 | K25: 43390.37 | L25: 41511.66 | M25: 41047.61 | N25: 38281.29 | O25: 37417.51 | P25: 37417.51 | Q25: 37699.22 | R25: 35477.32 | S25: 33064.2 | T25: 31509.95 | U25: 31509.95 | V25: 28723.11 | W25: 25667.03 | X25: 25221.9 | Y25: 34922.12 | Z25: 34922.12 | AA25: 36259.92 | AB25: 32815.06
A26: 1 | C26: 기타비유동자산 | E26: 45026.2 | F26: 45026.2 | G26: 73425.54 | H26: 89183.99 | I26: 76374 | J26: 383826.18 | K26: 383826.18 | L26: 371677.17 | M26: 392593.78 | N26: 380910.02 | O26: 372204.41 | P26: 372204.41 | Q26: 360369.53 | R26: 378525.06 | S26: 377579.69 | T26: 243632.3 | U26: 243632.3 | V26: 206745.12 | W26: 185502.49 | X26: 166110.41 | Y26: 461064.31 | Z26: 461064.31 | AA26: 441039.99 | AB26: 414643.67
A27: 1 | C27: 비유동파생상품자산 | E27: 43123.04 | F27: 43123.04 | G27: 59450.95 | H27: 89605.37 | I27: 168106.53 | J27: 293924.05 | K27: 293924.05 | L27: 138341.71 | M27: 158160.86 | N27: 100114.82 | O27: 191895.22 | P27: 191895.22 | Q27: 74200.08 | R27: 52575.75 | S27: 103871.68 | T27: 64055.7 | U27: 64055.7 | V27: 66259.55 | W27: 216190.71 | X27: 90721.64 | Y27: 81469.69 | Z27: 81469.69 | AA27: 2366.41 | AB27: 7453.98
... A59: 1 | C59: 이자발생자산 | E59: 2406089 | F59: 2406089 | G59: 2102617.6 | H59: 2206018.1 | I59: 2497845 | J59: 1239694.7 | K59: 1239694.7 | L59: 1402142.5 | M59: 1300452.8 | N59: 1632890.1 | O59: 1371292.1 | P59: 1371292.1 | Q59: 1298837.5 | R59: 1454001.1 | S59: 741280.04 | T59: 2223306 | U59: 2223306 | V59: 3552342.5 | W59: 3137474.6 | X59: 4377921.5 | Y59: 4106578.9 | Z59: 4106578.9 | AA59: 5213881.5 | AB59: 6608248.4
A60: 1 | C60: 사채 | E60: 536292.31 | F60: 536292.31 | G60: 844823 | H60: 885946 | I60: 956970 | J60: 873294 | K60: 873294 | L60: 391140 | M60: 643175 | N60: 652871
A61: 1 | C61: 유동성장기부채 | E61: 845229.83 | F61: 845229.83 | G61: 1048626.7 | H61: 1514784 | I61: 1577253.8 | J61: 1226167.2 | K61: 1226167.2 | L61: 1143453.2 | M61: 666452.81 | N61: 845029.23 | T61: 371613.31 | U61: 371613.31 | V61: 386666.87 | W61: 332765.09 | X61: 255898.54 | AA61: 599939.45 | AB61: 520403.57
A62: 1 | C62: 비지배주주지분 | L62: 43.5 | M62: 38.62 | N62: 0.63 | O62: 0.23 | P62: 0.23 | Q62: -0.03 | R62: 0.24 | S62: 0.55 | T62: 0.55 | U62: 0.55 | V62: 0.38 | W62: 0.34 | X62: 0.18 | Y62: 0.14 | Z62: 0.14 | AA62: 0.18 | AB62: 0.25
A63: 1 | C63: 당기법인세부채(미지급법인세) | M63: 14.5 | N63: 21.75 | Q63: 4.95 | R63: 307.18 | S63: 9831.55 | T63: 13795.56 | U63: 13795.56 | V63: 24577.83 | W63: 29960.97 | X63: 29065.36 | Y63: 39130.11 | Z63: 39130.11 | AA63: 58633.97 | AB63: 314038.78
A64: 1 | C64: 단기금융부채(face) | O64: 1560030.7 | P64: 1560030.7 | Q64: 1444122.4 | R64: 687243.41 | S64: 655904.62 | Y64: 156966.8 | Z64: 156966.8
A65: 1 | C65: 장기금융부채(face) | O65: 1568942.8 | P65: 1568942.8 | Q65: 1335593.8 | R65: 1215680.3 | S65: 809134.19 | T65: 751605.74 | U65: 751605.74 | V65: 685730.58 | W65: 464790.16 | X65: 478555.37 | Y65: 488384.39 | Z65: 488384.39 | AA65: 0 | AB65: 0
A66: 1 | C66: 이연법인세부채 | Y66: 755.27 | Z66: 755.27 | AA66: 755.27 | AB66: 755.27
A67: 1 | C67: 매출액(수익) | E67: 2475866.7 | G67: 2001636.5 | H67: 2166032.4 | I67: 2203563.7 | J67: 2674247.9 | K67: 9045480.5 | L67: 2632890.3 | M67: 3064397.8 | N67: 2853526.4 | O67: 3413111.5 | P67: 11963926 | Q67: 2987745 | R67: 3883982.5 | S67: 3609175.7 | T67: 4005550.3 | U67: 14486454 | V67: 3822515.7 | W67: 4147124.8 | X67: 4417898.2 | Y67: 5193094.5 | Z67: 17580633 | AA67: 5916331.8 | AB67: 6332155
A68: 1 | C68: 매출원가 | E68: 2727132.9 | G68: 2089477.6 | H68: 2151534.4 | I68: 2067127.5 | J68: 2574480 | K68: 8882619.4 | L68: 2506895.1 | M68: 2866040.5 | N68: 2692363.8 | O68: 3243763.2 | P68: 11309062 | Q68: 2837657.5 | R68: 3443086.3 | S68: 3202405.4 | T68: 3509373.5 | U68: 12992523 | V68: 3193437.9 | W68: 3453431 | X68: 3650707.1 | Y68: 4318841 | Z68: 14616417 | AA68: 4743761.1 | AB68: 4975570.5
A69: 1 | C69: 매출총이익 | E69: -251266.21 | G69: -87841.17 | H69: 14498.03 | I69: 136436.24 | J69: 99767.95 | K69: 162861.05 | L69: 125995.18 | M69: 198357.33 | N69: 161162.62 | O69: 169348.38 | P69: 654863.51 | Q69: 150087.48 | R69: 440896.26 | S69: 406770.28 | T69: 496176.86 | U69: 1493930.9 | V69: 629077.83 | W69: 693693.87 | X69: 767191.13 | Y69: 874253.49 | Z69: 2964216.3 | AA69: 1172570.7 | AB69: 1356584.5
A70: 1 | C70: 판관비 | E70: 229430.52 | G70: 129577.42 | H70: 122749.78 | I70: 122096.1 | J70: 77588.9 | K70: 452012.2 | L70: 167463.91 | M70: 129823.11 | N70: 148254.87 | O70: 30681.66 | P70: 476223.55 | Q70: 128823.57 | R70: 245266.13 | S70: 200625.27 | T70: 213992.42 | U70: 788707.39 | V70: 195343.66 | W70: 222237.89 | X70: 209905.74 | Y70: 299218.92 | Z70: 926706.21 | AA70: 267184.78 | AB70: 316646.91
A71: 1 | C71: 영업이익 | E71: -480696.74 | G71: -217418.59 | H71: -108251.75 | I71: 14340.14 | J71: 22179.05 | K71: -289151.15 | L71: -41468.73 | M71: 68534.23 | N71: 12907.76 | O71: 138666.71 | P71: 178639.97 | Q71: 21263.91 | R71: 195630.12 | S71: 206145 | T71: 282184.44 | U71: 705223.47 | V71: 433734.17 | W71: 471455.98 | X71: 557285.39 | Y71: 575034.55 | Z71: 2037510.1 | AA71: 905385.91 | AB71: 1039937.6
...

Sheet BS별도
B1: (백만원) | C1: 이름: BS별도H | E1: 4Q21 | F1: 2021 | G1: 1Q22 | H1: 2Q22 | I1: 3Q22 | J1: 4Q22 | K1: 2022 | L1: 1Q23 | M1: 2Q23 | N1: 3Q23 | O1: 4Q23 | P1: 2023 | Q1: 1Q24 | R1: 2Q24 | S1: 3Q24 | T1: 4Q24 | U1: 2024 | V1: 1Q25 | W1: 2Q25 | X1: 3Q25 | Y1: 4Q25 | Z1: 2025 | AA1: 1Q26 | AB1: 2Q26 | AC1: 3Q26 | AD1: 4Q26 | AE1: 2026 | AF1: 1Q27 | AG1: 2Q27 | AH1: 3Q27 | AI1: 4Q27 | AJ1: 2027 | AK1: 1Q28 | AL1: 2Q28 | AM1: 3Q28 | AN1: 4Q28 | AO1: 2028
B2: 별도 | D2: fin json(kship_fin.py)
B3: HD현대중공업(별) | C3: UPDATE: 26-10-14 | E3: 1 | F3: 2 | G3: 3 | H3: 4 | I3: 5 | J3: 6 | K3: 7 | L3: 8 | M3: 9 | N3: 10 | O3: 11 | P3: 12 | Q3: 13 | R3: 14 | S3: 15 | T3: 16 | U3: 17 | V3: 18 | W3: 19 | X3: 20 | Y3: 21 | Z3: 22 | AA3: 23 | AB3: 24 | AC3: 25 | AD3: 26 | AE3: 27 | AF3: 28 | AG3: 29 | AH3: 30 | AI3: 31 | AJ3: 32 | AK3: 33 | AL3: 34 | AM3: 35 | AN3: 36 | AO3: 37
B4: Account Code | C4: AccountNAME | E4: 2021.12 | F4: 2021.12A | G4: 2022.03 | H4: 2022.06 | I4: 2022.09 | J4: 2022.12 | K4: 2022.12A | L4: 2023.03 | M4: 2023.06 | N4: 2023.09 | O4: 2023.12 | P4: 2023.12A | Q4: 2024.03 | R4: 2024.06 | S4: 2024.09 | T4: 2024.12 | U4: 2024.12A | V4: 2025.03 | W4: 2025.06 | X4: 2025.09 | Y4: 2025.12 | Z4: 2025.12A | AA4: 2026.03 | AB4: 2026.06 | AC4: 2026.09 | AD4: 2026.12 | AE4: 2026.12A | AF4: 2027.03 | AG4: 2027.06 | AH4: 2027.09 | AI4: 2027.12 | AJ4: 2027.12A | AK4: 2028.03 | AL4: 2028.06 | AM4: 2028.09 | AN4: 2028.12 | AO4: 2028.12A
A5: 1 | C5: 유동자산 | E5: 7885398.9 | F5: 7885398.9 | G5: 7716074.5 | H5: 8357606 | I5: 8992402.1 | J5: 7988297 | K5: 7988297 | L5: 8634179.6 | M5: 8896685.2 | N5: 9425959.3 | O5: 8768341.2 | P5: 8768341.2 | Q5: 8966573.2 | R5: 9065484.4 | S5: 8493977.8 | T5: 10398748 | U5: 10398748 | V5: 11918956 | W5: 11283601 | X5: 12277537 | Y5: 14937275 | Z5: 14937275 | AA5: 16145796 | AB5: 17912015
A6: 1 | C6: 현금및현금성자산 | E6: 2137125.6 | F6: 2137125.6 | G6: 1763733.1 | H6: 1634136.9 | I6: 1498890.3 | J6: 723249.2 | K6: 723249.2 | L6: 836315.64 | M6: 760729.54 | N6: 981370.99 | O6: 900193.71 | P6: 900193.71 | Q6: 708556.74 | R6: 748727.8 | S6: 254298.5 | T6: 1242675.6 | U6: 1242675.6 | V6: 2708098.3 | W6: 2338193.9 | X6: 2334257.5 | Y6: 1842183.3 | Z6: 1842183.3 | AA6: 2945633 | AB6: 4513006.2
A7: 1 | C7: 단기금융상품 | E7: 151000 | F7: 151000 | G7: 151000 | H7: 181000 | I7: 151000 | J7: 161000 | K7: 161000 | L7: 161000 | M7: 131000 | N7: 131000 | O7: 131000 | P7: 131000 | Q7: 131000.01 | R7: 131000 | S7: 131000 | T7: 131000 | U7: 131000 | V7: 131000 | W7: 481000 | X7: 1671000 | Y7: 1689000 | Z7: 1689000 | AA7: 1279000 | AB7: 917000
A8: 1 | C8: 단기금융자산 | E8: 259137.32 | F8: 259137.32 | G8: 314512.06 | H8: 548806.56 | I8: 974184.56 | J8: 485992.28 | K8: 485992.28 | L8: 547844.55 | M8: 526571.39 | N8: 608327.41 | O8: 432686.75 | P8: 432686.75 | Q8: 559683.45 | R8: 673414.52 | S8: 462191.31 | T8: 954876.65 | U8: 954876.65 | V8: 804978.33 | W8: 771947.75 | X8: 2012261.4 | Y8: 2197681.1 | Z8: 2197681.1 | AA8: 2207931.5 | AB8: 2026825.8
A9: 1 | C9: 매출채권및기타채권 | E9: 1032383.4 | F9: 1032383.4 | G9: 873302.75 | H9: 1534205.9 | I9: 1101477.2 | J9: 1156122.3 | K9: 1156122.3 | L9: 1420480.3 | M9: 1391097.2 | N9: 1408045.2 | O9: 1383651.2 | P9: 1383651.2 | Q9: 1378783.7 | R9: 1551626.1 | S9: 1581293.3 | T9: 1666695.7 | U9: 1666695.7 | V9: 1865479.1 | W9: 1709653.7 | X9: 1697101.6 | Y9: 1700100.2 | Z9: 1700100.2 | AA9: 1617171.2 | AB9: 1761399.8
A10: 1 | C10: 계약자산 | E10: 2836359.4 | F10: 2836359.4 | G10: 3073176.9 | H10: 2863181.2 | I10: 3253811.6 | J10: 3180079.7 | K10: 3180079.7 | L10: 3232105.7 | M10: 3494267.8 | N10: 3647358.6 | O10: 3458668.9 | P10: 3458668.9 | Q10: 3515123.4 | R10: 3396531 | S10: 3397567.1 | T10: 3573015.7 | U10: 3573015.7 | V10: 3273711.1 | W10: 3118247.5 | X10: 2988952.8 | Y10: 5131962.9 | Z10: 5131962.9 | AA10: 5344888 | AB10: 5656017.1
A11: 1 | C11: 재고자산 | E11: 898666.74 | F11: 898666.74 | G11: 955114.32 | H11: 1011856.2 | I11: 1277538.8 | J11: 1360377.4 | K11: 1360377.4 | L11: 1445702.6 | M11: 1432643.1 | N11: 1432420.2 | O11: 1308520.4 | P11: 1308520.4 | Q11: 1515234.9 | R11: 1445122.4 | S11: 1537922.3 | T11: 1495877.3 | U11: 1495877.3 | V11: 1631668.6 | W11: 1681490.4 | X11: 1730507.7 | Y11: 1979474 | Z11: 1979474 | AA11: 1945915.4 | AB11: 1982548.7
A12: 1 | C12: 유동파생상품자산 | E12: 11368.27 | F12: 11368.27 | G12: 39634.66 | H12: 69702.84 | I12: 131045.43 | J12: 106450.66 | K12: 106450.66 | L12: 102084.18 | M12: 104796.3 | N12: 99587.15 | O12: 104488.45 | P12: 104488.45 | Q12: 24628.9 | R12: 3770.28 | S12: 72075.84 | T12: 927.29 | U12: 927.29 | V12: 2644.75 | W12: 66289.1 | X12: 11211.79 | Y12: 8611.82 | Z12: 8611.82 | AA12: 88344.33 | AB12: 99217.49
A13: 1 | C13: 유동확정계약자산 | E13: 96769.05 | F13: 96769.05 | G13: 123877.4 | H13: 298103.72 | I13: 692139.13 | J13: 218541.62 | K13: 218541.62 | L13: 284760.37 | M13: 290775.09 | N13: 377740.26 | O13: 197198.3 | P13: 197198.3 | Q13: 404054.54 | R13: 538644.24 | S13: 259115.47 | T13: 822949.36 | U13: 822949.36 | V13: 671333.58 | W13: 224658.65 | X13: 330049.56 | Y13: 500069.33 | Z13: 500069.33 | AA13: 840587.19 | AB13: 1010608.3
A14: 1 | C14: 당기법인세자산(선급법인세) | E14: 2447.05 | F14: 2447.05 | G14: 3510.83 | H14: 2208.75 | I14: 3534.69 | J14: 5146.87 | K14: 5146.87 | L14: 6504.98 | M14: 2707.69 | N14: 3779.05 | O14: 5401.22 | P14: 5401.22 | Q14: 7227.15 | R14: 92.27 | S14: 0 | T14: 0 | U14: 0 | Y14: 0 | Z14: 0
A15: 1 | C15: 매각예정비유동자산및처분자산 | E15: 4719.32 | F15: 4719.32 | O15: 0 | P15: 0
A16: 1 | C16: 기타유동자산 | E16: 714559.98 | F16: 714559.98 | G16: 732724.52 | H16: 763210.54 | I16: 882965 | J16: 1077329.3 | K16: 1077329.3 | L16: 1145225.9 | M16: 1288668.6 | N16: 1344657.8 | O16: 1279219.1 | P16: 1279219.1 | Q16: 1281963.8 | R16: 1249970.4 | S16: 1260705.3 | T16: 1465607.2 | U16: 1465607.2 | V16: 1635020.9 | W16: 1664068.2 | X16: 1514456 | Y16: 2085873 | Z16: 2085873 | AA16: 2084257 | AB16: 1972217.4
A17: 1 | C17: 비유동자산 | E17: 7193370.1 | F17: 7193370.1 | G17: 7341258.7 | H17: 7867597.1 | I17: 8870069.1 | J17: 8294797.9 | K17: 8294797.9 | L17: 8344621.5 | M17: 8345253.3 | N17: 8520002.8 | O17: 8355832.9 | P17: 8355832.9 | Q17: 8456151.3 | R17: 8626537.7 | S17: 8364703.7 | T17: 9002546.1 | U17: 9002546.1 | V17: 8987176.1 | W17: 8481259.9 | X17: 8539167.7 | Y17: 11261787 | Z17: 11261787 | AA17: 11455773 | AB17: 11477994
A18: 1 | C18: 종속기업및관계기업투자 | E18: 3556.2 | F18: 3556.2 | G18: 32556.2 | H18: 32556.2 | I18: 32556.2 | J18: 30345.76 | K18: 30345.76 | L18: 30346.4 | M18: 30346.4 | N18: 56498.92 | O18: 68946.32 | P18: 68946.32 | Q18: 57151.27 | R18: 57151.27 | S18: 57151.27 | T18: 56938.38 | U18: 56938.38 | V18: 154385.95 | W18: 154385.95 | X18: 153253.08 | Y18: 513708.18 | Z18: 513708.18 | AA18: 513708.18 | AB18: 513708.18
A19: 1 | C19: 투자자산 | E19: 201927.53 | F19: 201927.53 | G19: 229839.87 | H19: 634468.63 | I19: 1504826.1 | J19: 523994.5 | K19: 523994.5 | L19: 498392.08 | M19: 428985.82 | N19: 539229.97 | O19: 375855.18 | P19: 375855.18 | Q19: 448103.88 | R19: 612260.64 | S19: 330513.45 | T19: 1125976.3 | U19: 1125976.3 | V19: 1223375.8 | W19: 591820.72 | X19: 743836.08 | Y19: 1422423.8 | Z19: 1422423.8 | AA19: 1883020.3 | AB19: 1907370
A20: 1 | C20: 장기금융자산 | E20: 9560.27 | F20: 9560.27 | G20: 9560.27 | H20: 9554.27 | I20: 9554.27 | J20: 9554.27 | K20: 9554.27 | L20: 9554.27 | M20: 10554.27 | N20: 10554.27 | O20: 10562.23 | P20: 10562.23 | Q20: 10562.23 | R20: 10562.23 | S20: 10562.23 | T20: 10562.23 | U20: 10562.23 | V20: 10562.23 | W20: 10562.23 | X20: 10562.23 | Y20: 25281.42 | Z20: 25281.42 | AA20: 25281.42 | AB20: 25281.42
A21: 1 | C21: 장기매출채권및기타채권 | E21: 38942.19 | F21: 38942.19 | G21: 47759.87 | H21: 97404.15 | I21: 168849.73 | J21: 176738.79 | K21: 176738.79 | L21: 205506.06 | M21: 198976.31 | N21: 216126.11 | O21: 168168.13 | P21: 168168.13 | Q21: 176937.59 | R21: 160888.32 | S21: 136890.47 | T21: 125711.47 | U21: 125711.47 | V21: 99946.38 | W21: 89678.83 | X21: 83155.23 | Y21: 91230.79 | Z21: 91230.79 | AA21: 90261.32 | AB21: 92563.73
A22: 1 | C22: 투자부동산 | E22: 4108.68 | F22: 4108.68 | G22: 1486.97 | H22: 1477.15 | I22: 1467.33 | J22: 1457.52 | K22: 1457.52 | L22: 1447.7 | M22: 1437.88 | N22: 1428.07 | O22: 1418.25 | P22: 1418.25 | Q22: 1408.43 | R22: 1398.61 | S22: 1388.8 | T22: 1378.98 | U22: 1378.98 | V22: 1369.16 | W22: 1359.35 | X22: 1349.53 | Y22: 1339.71 | Z22: 1339.71 | AA22: 1329.89 | AB22: 1320.08
A23: 1 | C23: 유형자산 | E23: 5986251.9 | F23: 5986251.9 | G23: 6020784.9 | H23: 6049050.5 | I23: 6135792.8 | J23: 6216100.2 | K23: 6216100.2 | L23: 6264242.7 | M23: 6323567.2 | N23: 6375744 | O23: 6414554.2 | P23: 6414554.2 | Q23: 6437196.5 | R23: 6480780.4 | S23: 6527707.5 | T23: 6571431.6 | U23: 6571431.6 | V23: 6598042.9 | W23: 6858019.6 | X23: 6909098.2 | Y23: 8665345.3 | Z23: 8665345.3 | AA23: 8664445.9 | AB23: 8738314.8
A24: 1 | C24: 무형자산 | E24: 79457.82 | F24: 79457.82 | G24: 80867.62 | H24: 82644.42 | I24: 89389.13 | J24: 100046.84 | K24: 100046.84 | L24: 102981.85 | M24: 105997.21 | N24: 109984.01 | O24: 106633.43 | P24: 106633.43 | Q24: 110283.7 | R24: 113590.25 | S24: 116423.02 | T24: 126522.3 | U24: 126522.3 | V24: 126436.2 | W24: 131928.11 | X24: 126367.39 | Y24: 159207.64 | Z24: 159207.64 | AA24: 159179.91 | AB24: 159638.96
A25: 1 | C25: 사용권자산 | E25: 17906.01 | F25: 17906.01 | G25: 20295.85 | H25: 21950.59 | I25: 21169.95 | J25: 42416.69 | K25: 42416.69 | L25: 40547.88 | M25: 40060.44 | N25: 37306.15 | O25: 36432.63 | P25: 36432.63 | Q25: 36676.19 | R25: 34472.54 | S25: 32077.68 | T25: 30541.67 | U25: 30541.67 | V25: 27630.03 | W25: 24556.85 | X25: 24082.86 | Y25: 33716.29 | Z25: 33716.29 | AA25: 34119.66 | AB25: 30995.03
A26: 1 | C26: 기타비유동자산 | E26: 45026.2 | F26: 45026.2 | G26: 72403.75 | H26: 88171.96 | I26: 75371.77 | J26: 382840.74 | K26: 382840.74 | L26: 370713.39 | M26: 391606.61 | N26: 379934.88 | O26: 366871.99 | P26: 366871.99 | Q26: 359346.5 | R26: 377520.28 | S26: 376593.17 | T26: 242637.37 | U26: 242637.37 | V26: 205652.04 | W26: 184392.31 | X26: 164971.37 | Y26: 450919.57 | Z26: 450919.57 | AA26: 431567.94 | AB26: 407103.37
A27: 1 | C27: 비유동파생상품자산 | E27: 43123.04 | F27: 43123.04 | G27: 59450.95 | H27: 89605.37 | I27: 168106.53 | J27: 293924.05 | K27: 293924.05 | L27: 138341.71 | M27: 158160.86 | N27: 100114.82 | O27: 191895.22 | P27: 191895.22 | Q27: 74200.08 | R27: 52575.75 | S27: 103871.68 | T27: 64055.7 | U27: 64055.7 | V27: 66259.55 | W27: 216190.71 | X27: 90721.64 | Y27: 81469.69 | Z27: 81469.69 | AA27: 2366.41 | AB27: 7453.98
... A41: 1 | C41: 비유동부채 | E41: 2436039.1 | F41: 2436039.1 | G41: 2118819.1 | H41: 2063705.2 | I41: 2926939.7 | J41: 1919430 | K41: 1919430 | L41: 1991644.8 | M41: 2495330.3 | N41: 2389906.6 | O41: 1969554.4 | P41: 1969554.4 | Q41: 1809162.8 | R41: 1845785.2 | S41: 1187834.9 | T41: 1888114.8 | U41: 1888114.8 | V41: 1826089.5 | W41: 996978.52 | X41: 1156625.1 | Y41: 1484222.2 | Z41: 1484222.2 | AA41: 1523370.9 | AB41: 1546209.3
A42: 1 | C42: 장기차입금 | E42: 1958992.3 | F42: 1958992.3 | G42: 1626173.2 | H42: 1197558.8 | I42: 1250450.2 | J42: 1150024.2 | K42: 1150024.2 | L42: 1236710 | M42: 1790094.7 | N42: 1602871 | O42: 1559942.8 | P42: 1559942.8 | Q42: 1326593.8 | R42: 1206680.3 | S42: 809134.19 | V42: 685730.58 | W42: 464790.16 | X42: 478555.37 | Y42: 488384.39 | Z42: 488384.39 | AA42: 0 | AB42: 0
A43: 1 | C43: 장기금융부채(face) | E43: 1958992.3 | F43: 1958992.3 | G43: 1626173.2 | H43: 1197558.8 | I43: 1250450.2 | J43: 1150024.2 | K43: 1150024.2 | L43: 1236710 | M43: 1790094.7 | N43: 1602871 | O43: 1559942.8 | P43: 1559942.8 | Q43: 1326593.8 | R43: 1206680.3 | S43: 809134.19 | V43: 685730.58 | W43: 464790.16 | X43: 478555.37 | Y43: 488384.39 | Z43: 488384.39 | AA43: 0 | AB43: 0
A44: 1 | C44: 비유동리스부채 | E44: 12746.17 | F44: 12746.17 | G44: 13306.69 | H44: 14749.51 | I44: 15167.06 | J44: 30331.12 | K44: 30331.12 | L44: 28628.18 | M44: 27644.11 | N44: 25642.43 | O44: 26059.3 | P44: 26059.3 | Q44: 25218.75 | R44: 22407.1 | S44: 20160.72 | T44: 19194.81 | U44: 19194.81 | V44: 16027.79 | W44: 12612.19 | X44: 11620.04 | Y44: 19495.02 | Z44: 19495.02 | AA44: 19098.16 | AB44: 17703.06
A45: 1 | C45: 장기금융부채 | E45: 163221.98 | F45: 163221.98 | G45: 168609.19 | H45: 525081 | I45: 1309776.1 | J45: 450460.66 | K45: 450460.66 | L45: 469913.87 | M45: 399506.92 | N45: 472943.71 | O45: 314089.53 | P45: 314089.53 | Q45: 381685.29 | R45: 528525.66 | S45: 258153.31 | T45: 1013701.8 | U45: 1013701.8 | V45: 1011282 | W45: 406468.73 | X45: 549200.68 | Y45: 851545.58 | Z45: 851545.58 | AA45: 1373195.6 | AB45: 1393144.6
A46: 1 | C46: 장기매입채무및기타채무 | E46: 248.8 | F46: 248.8 | G46: 249.68 | H46: 253.81 | I46: 329.61 | J46: 381 | K46: 381 | L46: 388.77 | M46: 583.75 | N46: 673.66 | O46: 3790.81 | P46: 3790.81 | Q46: 2967.37 | R46: 4133.22 | S46: 4911.86 | T46: 8835.74 | U46: 8835.74 | V46: 10196.03 | W46: 11351.53 | X46: 12591.07 | Y46: 15699.25 | Z46: 15699.25 | AA46: 18240.03 | AB46: 19448.75
A47: 1 | C47: 확정급여부채 | E47: 33198.09 | F47: 33198.09 | G47: 33198.09 | H47: 33198.09 | I47: 33198.09 | J47: 28462.25 | K47: 28462.25 | L47: 28462.25 | M47: 28462.25 | N47: 28462.25 | O47: 30857.21 | P47: 30857.21 | Q47: 31477.91 | R47: 31477.91 | S47: 31477.91 | T47: 33647.53 | U47: 33647.53 | V47: 25659.51 | W47: 25659.51 | X47: 25659.51 | Y47: 31153.15 | Z47: 31153.15 | AA47: 31153.15 | AB47: 31153.15
A48: 1 | C48: 장기충당부채 | E48: 269562.66 | F48: 269562.66 | G48: 279839.61 | H48: 296930.2 | I48: 322568.42 | J48: 279550.66 | K48: 279550.66 | L48: 245686.94 | M48: 266267.96 | N48: 274609.47 | O48: 50595.84 | P48: 50595.84 | Q48: 56230.86 | R48: 64831.17 | S48: 74091.3 | T48: 70328.19 | U48: 70328.19 | V48: 83298.64 | W48: 78858.93 | X48: 80841.82 | Y48: 87736.3 | Z48: 87736.3 | AA48: 91154.08 | AB48: 92910.3
A49: 1 | C49: 장기파생상품부채 | E49: 150475.81 | F49: 150475.81 | G49: 155302.5 | H49: 510331.49 | I49: 1294609.1 | J49: 420129.54 | K49: 420129.54 | L49: 441285.69 | M49: 371862.81 | N49: 447301.28 | O49: 288030.23 | P49: 288030.23 | Q49: 356466.54 | R49: 506118.56 | S49: 237992.59 | T49: 994507.02 | U49: 994507.02 | V49: 995254.24 | W49: 393856.54 | X49: 537580.64 | Y49: 832050.56 | Z49: 832050.56 | AA49: 1354097.4 | AB49: 1375441.6
A50: 1 | C50: 부채총계 | E50: 9484635.7 | F50: 9484635.7 | G50: 9605667.2 | H50: 10837498 | I50: 12421428 | J50: 10992977 | K50: 10992977 | L50: 11714430 | M50: 11952887 | N50: 12669589 | O50: 11915188 | P50: 11915188 | Q50: 12190594 | R50: 12308927 | S50: 11399303 | T50: 13698694 | U50: 13698694 | V50: 15100871 | W50: 13583891 | X50: 14351971 | Y50: 16816487 | Z50: 16816487 | AA50: 17869552 | AB50: 18838537
A51: 1 | C51: 자본금 | E51: 443865.58 | F51: 443865.58 | G51: 443865.58 | H51: 443865.58 | I51: 443865.58 | J51: 443865.58 | K51: 443865.58 | L51: 443865.58 | M51: 443865.58 | N51: 443865.58 | O51: 443865.58 | P51: 443865.58 | Q51: 443865.58 | R51: 443865.58 | S51: 443865.58 | T51: 443865.58 | U51: 443865.58 | V51: 443865.58 | W51: 443865.58 | X51: 443865.58 | Y51: 524806.12 | Z51: 524806.12 | AA51: 524806.12 | AB51: 524806.12
A52: 1 | C52: 자본잉여금 | E52: 3118365 | F52: 3118365 | G52: 3118365 | H52: 3118365 | I52: 3118365 | J52: 3118365 | K52: 3118365 | L52: 3118365 | M52: 3123097.1 | N52: 3122767.3 | O52: 3120677.5 | P52: 3120677.5 | Q52: 3119482.8 | R52: 3119482.8 | S52: 3119482.8 | T52: 3119482.8 | U52: 3119482.8 | V52: 3119482.8 | W52: 3119482.8 | X52: 3119482.8 | Y52: 5124626.2 | Z52: 5124626.2 | AA52: 5124626.2 | AB52: 5124626.2
A53: 1 | C53: 기타자본 | E53: -1411 | F53: -1411 | G53: -1411 | H53: -1411 | I53: -1411 | J53: -1411 | K53: -1411 | L53: -1411 | M53: -1411 | N53: -1411 | O53: -1411 | P53: -1411 | Q53: -1411 | R53: -1411 | S53: -1411 | T53: -1411 | U53: -1411 | V53: -1411 | W53: -1411 | X53: -1411 | Y53: -16907.95 | Z53: -16907.95 | AA53: -16907.95 | AB53: -16907.95
...

Sheet subQ
A1: YQ | C1: subQ 분기 서브모델(억원, U=100) | E1: 4Q21 | F1: 2021 | G1: 1Q22 | H1: 2Q22 | I1: 3Q22 | J1: 4Q22 | K1: 2022 | L1: 1Q23 | M1: 2Q23 | N1: 3Q23 | O1: 4Q23 | P1: 2023 | Q1: 1Q24 | R1: 2Q24 | S1: 3Q24 | T1: 4Q24 | U1: 2024 | V1: 1Q25 | W1: 2Q25 | X1: 3Q25 | Y1: 4Q25 | Z1: 2025 | AA1: 1Q26 | AB1: 2Q26 | AC1: 3Q26 | AD1: 4Q26 | AE1: 2026 | AF1: 1Q27 | AG1: 2Q27 | AH1: 3Q27 | AI1: 4Q27 | AJ1: 2027 | AK1: 1Q28 | AL1: 2Q28 | AM1: 3Q28 | AN1: 4Q28 | AO1: 2028
A2: A=이름(key) B=그룹 C=단위 D=FnGuide 계정명(VLOOKUP 키). 확정=VLOOKUP(BS), 추정=변수 가정 참조
E3: 1 | F3: 2 | G3: 3 | H3: 4 | I3: 5 | J3: 6 | K3: 7 | L3: 8 | M3: 9 | N3: 10 | O3: 11 | P3: 12 | Q3: 13 | R3: 14 | S3: 15 | T3: 16 | U3: 17 | V3: 18 | W3: 19 | X3: 20 | Y3: 21 | Z3: 22 | AA3: 23 | AB3: 24 | AC3: 25 | AD3: 26 | AE3: 27 | AF3: 28 | AG3: 29 | AH3: 30 | AI3: 31 | AJ3: 32 | AK3: 33 | AL3: 34 | AM3: 35 | AN3: 36 | AO3: 37
E4: 2021.12 | F4: 2021.12A | G4: 2022.03 | H4: 2022.06 | I4: 2022.09 | J4: 2022.12 | K4: 2022.12A | L4: 2023.03 | M4: 2023.06 | N4: 2023.09 | O4: 2023.12 | P4: 2023.12A | Q4: 2024.03 | R4: 2024.06 | S4: 2024.09 | T4: 2024.12 | U4: 2024.12A | V4: 2025.03 | W4: 2025.06 | X4: 2025.09 | Y4: 2025.12 | Z4: 2025.12A | AA4: 2026.03 | AB4: 2026.06 | AC4: 2026.09 | AD4: 2026.12 | AE4: 2026.12A | AF4: 2027.03 | AG4: 2027.06 | AH4: 2027.09 | AI4: 2027.12 | AJ4: 2027.12A | AK4: 2028.03 | AL4: 2028.06 | AM4: 2028.09 | AN4: 2028.12 | AO4: 2028.12A
A5: 매출액 | B5: 손익 | C5: 억원 | D5: 매출액(수익) | E5: =IFERROR(VLOOKUP($D5,BS연결,MATCH(E$1,BS연결H,0),0)/100,"") | G5: =IFERROR(VLOOKUP($D5,BS연결,MATCH(G$1,BS연결H,0),0)/100,"") | H5: =IFERROR(VLOOKUP($D5,BS연결,MATCH(H$1,BS연결H,0),0)/100,"") | I5: =IFERROR(VLOOKUP($D5,BS연결,MATCH(I$1,BS연결H,0),0)/100,"") | J5: =IFERROR(VLOOKUP($D5,BS연결,MATCH(J$1,BS연결H,0),0)/100,"") | K5: =IFERROR(VLOOKUP($D5,BS연결,MATCH(K$1,BS연결H,0),0)/100,"") | L5: =IFERROR(VLOOKUP($D5,BS연결,MATCH(L$1,BS연결H,0),0)/100,"") | M5: =IFERROR(VLOOKUP($D5,BS연결,MATCH(M$1,BS연결H,0),0)/100,"") | N5: =IFERROR(VLOOKUP($D5,BS연결,MATCH(N$1,BS연결H,0),0)/100,"") | ... AB5: =IFERROR(VLOOKUP($D5,BS연결,MATCH(AB$1,BS연결H,0),0)/100,"") | AC5: =IFERROR(AC39+AC43,"") | AD5: =IFERROR(AD39+AD43,"") | AE5: =SUM(AA5:AD5) | AF5: =IFERROR(AF39+AF43,"") | AG5: =IFERROR(AG39+AG43,"") | AH5: =IFERROR(AH39+AH43,"") | AI5: =IFERROR(AI39+AI43,"") | AJ5: =SUM(AF5:AI5) | AK5: =IFERROR(AK39+AK43,"") | AL5: =IFERROR(AL39+AL43,"") | AM5: =IFERROR(AM39+AM43,"") | AN5: =IFERROR(AN39+AN43,"") | AO5: =SUM(AK5:AN5)
A6: 매출원가 | B6: 손익 | C6: 억원 | D6: 매출원가 | E6: =IFERROR(VLOOKUP($D6,BS연결,MATCH(E$1,BS연결H,0),0)/100,"") | G6: =IFERROR(VLOOKUP($D6,BS연결,MATCH(G$1,BS연결H,0),0)/100,"") | H6: =IFERROR(VLOOKUP($D6,BS연결,MATCH(H$1,BS연결H,0),0)/100,"") | I6: =IFERROR(VLOOKUP($D6,BS연결,MATCH(I$1,BS연결H,0),0)/100,"") | J6: =IFERROR(VLOOKUP($D6,BS연결,MATCH(J$1,BS연결H,0),0)/100,"") | K6: =IFERROR(VLOOKUP($D6,BS연결,MATCH(K$1,BS연결H,0),0)/100,"") | L6: =IFERROR(VLOOKUP($D6,BS연결,MATCH(L$1,BS연결H,0),0)/100,"") | M6: =IFERROR(VLOOKUP($D6,BS연결,MATCH(M$1,BS연결H,0),0)/100,"") | N6: =IFERROR(VLOOKUP($D6,BS연결,MATCH(N$1,BS연결H,0),0)/100,"") | ... AB6: =IFERROR(VLOOKUP($D6,BS연결,MATCH(AB$1,BS연결H,0),0)/100,"") | AC6: =IFERROR(AC5-AC7,"") | AD6: =IFERROR(AD5-AD7,"") | AE6: =SUM(AA6:AD6) | AF6: =IFERROR(AF5-AF7,"") | AG6: =IFERROR(AG5-AG7,"") | AH6: =IFERROR(AH5-AH7,"") | AI6: =IFERROR(AI5-AI7,"") | AJ6: =SUM(AF6:AI6) | AK6: =IFERROR(AK5-AK7,"") | AL6: =IFERROR(AL5-AL7,"") | AM6: =IFERROR(AM5-AM7,"") | AN6: =IFERROR(AN5-AN7,"") | AO6: =SUM(AK6:AN6)
A7: 매출총이익 | B7: 손익 | C7: 억원 | D7: 매출총이익 | E7: =IFERROR(VLOOKUP($D7,BS연결,MATCH(E$1,BS연결H,0),0)/100,"") | G7: =IFERROR(VLOOKUP($D7,BS연결,MATCH(G$1,BS연결H,0),0)/100,"") | H7: =IFERROR(VLOOKUP($D7,BS연결,MATCH(H$1,BS연결H,0),0)/100,"") | I7: =IFERROR(VLOOKUP($D7,BS연결,MATCH(I$1,BS연결H,0),0)/100,"") | J7: =IFERROR(VLOOKUP($D7,BS연결,MATCH(J$1,BS연결H,0),0)/100,"") | K7: =IFERROR(VLOOKUP($D7,BS연결,MATCH(K$1,BS연결H,0),0)/100,"") | L7: =IFERROR(VLOOKUP($D7,BS연결,MATCH(L$1,BS연결H,0),0)/100,"") | M7: =IFERROR(VLOOKUP($D7,BS연결,MATCH(M$1,BS연결H,0),0)/100,"") | N7: =IFERROR(VLOOKUP($D7,BS연결,MATCH(N$1,BS연결H,0),0)/100,"") | ... AB7: =IFERROR(VLOOKUP($D7,BS연결,MATCH(AB$1,BS연결H,0),0)/100,"") | AC7: =IFERROR(AC9+AC8,"") | AD7: =IFERROR(AD9+AD8,"") | AE7: =SUM(AA7:AD7) | AF7: =IFERROR(AF9+AF8,"") | AG7: =IFERROR(AG9+AG8,"") | AH7: =IFERROR(AH9+AH8,"") | AI7: =IFERROR(AI9+AI8,"") | AJ7: =SUM(AF7:AI7) | AK7: =IFERROR(AK9+AK8,"") | AL7: =IFERROR(AL9+AL8,"") | AM7: =IFERROR(AM9+AM8,"") | AN7: =IFERROR(AN9+AN8,"") | AO7: =SUM(AK7:AN7)
A8: 판관비 | B8: 손익 | C8: 억원 | D8: 판관비 | E8: =IFERROR(VLOOKUP($D8,BS연결,MATCH(E$1,BS연결H,0),0)/100,"") | G8: =IFERROR(VLOOKUP($D8,BS연결,MATCH(G$1,BS연결H,0),0)/100,"") | H8: =IFERROR(VLOOKUP($D8,BS연결,MATCH(H$1,BS연결H,0),0)/100,"") | I8: =IFERROR(VLOOKUP($D8,BS연결,MATCH(I$1,BS연결H,0),0)/100,"") | J8: =IFERROR(VLOOKUP($D8,BS연결,MATCH(J$1,BS연결H,0),0)/100,"") | K8: =IFERROR(VLOOKUP($D8,BS연결,MATCH(K$1,BS연결H,0),0)/100,"") | L8: =IFERROR(VLOOKUP($D8,BS연결,MATCH(L$1,BS연결H,0),0)/100,"") | M8: =IFERROR(VLOOKUP($D8,BS연결,MATCH(M$1,BS연결H,0),0)/100,"") | N8: =IFERROR(VLOOKUP($D8,BS연결,MATCH(N$1,BS연결H,0),0)/100,"") | ... AB8: =IFERROR(VLOOKUP($D8,BS연결,MATCH(AB$1,BS연결H,0),0)/100,"") | AC8: =IFERROR(AC5*변수!AC21,"") | AD8: =IFERROR(AD5*변수!AD21,"") | AE8: =SUM(AA8:AD8) | AF8: =IFERROR(AF5*변수!AF21,"") | AG8: =IFERROR(AG5*변수!AG21,"") | AH8: =IFERROR(AH5*변수!AH21,"") | AI8: =IFERROR(AI5*변수!AI21,"") | AJ8: =SUM(AF8:AI8) | AK8: =IFERROR(AK5*변수!AK21,"") | AL8: =IFERROR(AL5*변수!AL21,"") | AM8: =IFERROR(AM5*변수!AM21,"") | AN8: =IFERROR(AN5*변수!AN21,"") | AO8: =SUM(AK8:AN8)
