Workbook
Name 변수H: 변수!$C$1:$AL$1
Name 환율: 변수!$C$6:$AL$13
Name BS연결H: BS연결!$C$1:$AL$1
Name BS연결: BS연결!$C$5:$AL$95
Name BS별도H: BS별도!$C$1:$AL$1
Name BS별도: BS별도!$C$5:$AL$95
Name SUBQH: subQ!$A$1:$AL$1
Name subQ: subQ!$A$5:$AL$40

Sheet README
A1: 범한퓨얼셀(382900) 실적 모델 — ARGUS 한국조선
A2: 기준 분기 2026Q2 · 마지막 실적 2026Q2 · 생성 2026-10-11
A3: 모든 수치는 모델 산출값(DART 공개 재무제표 + 우리 추정)이다 — 목표주가·투자 추천 아님. 참고용 · 투자조언 아님.
A5: 시트
A6: 변수 가정 시계열. 환율 8행(ECB via frankfurter — L2 fx.json; 추정 분기 = 노란 가정), 추정 드라이버(노란 셀 = 모델값에서 역산한 가정, 바꾸면 재계산; 연녹 셀 = 3절 스칼라 참조 수식), 3절 스칼라 가정(세율·판관비율·지배주주비중·이자율·종가·PER 밴드·COE·외화 순노출·헤지비율)
A7: BS연결/BS별도 FnGuide 계정명 × 기간 값 덤프(백만원). 행1 분기라벨, 행4 YYYY.MM / YYYY.12A. 이름정의 BS연결H·BS연결(계정명 C열부터)
A8: subQ 분기 서브모델(억원 = 백만원/100). 확정 행: =IFERROR(VLOOKUP($D행,BS연결,MATCH(E$1,BS연결H,0),0)/100,"") 추정 행: 변수 시트 가정 셀 참조 수식. 외환손익·파생상품손익은 BS 계정 합·차, 기타금융손익은 잔차, OPM·EPS·BPS·PER·PBR 은 파생 수식
A9: SLS 선표(조선사만, sls json 있을 때): 요약 행(sls 저장값) + 계약별 스케줄(백만$) × (헤지비율 × 헤지환율 + (1−헤지비율) × 건조시점 환율[변수 원/달러(평균)]) → 원화 수식 블록 → 합계 행이 subQ 매출조선에 연결
A10: 시나리오 신규수주 보수/기준/낙관(forecast_panel 패널, 모델에 scenarios 가 있을 때만): 매출액·영업이익 = subQ 기준값 ± (시나리오 신규 − base 신규) × OPM. base 만 subQ 행에 포함, 나머지는 합산 안 함
A11: 분기/연간예상 subQ 를 이름(A열 key)으로 VLOOKUP 한 보고서 표(억원)
A12: TP PER 밴드 × 12M fwd EPS, PBR = ROE/COE × BPS — 모델 산출값 구간, 목표주가·추천 아님
A13: 외화 환율 QoQ, 외화 순노출 × Δ기말환율 → 환관련손익 추정
... A34: 백테스트: {"freeze": "2025Q2", "horizon": 4, "revenue_wape_pct": 51.1, "op_wape_pct": 104.4, "n": 4, "note": "단일 회사 4분기 — 통계 아님", "driver_at_freeze": "trend_seasonal", "selection_oos_at_freeze": null, "frozen_inputs": "fin(연결/별도)·고객 조선사 모델·지주 자회사 모델은 2025Q2 까지의 분기만; 선표는 체결일 ≤ 2025Q2 말일 계약(원장 최신 금액·코호트 등급, 환산 없음); 잔고는 yards_cache 2025Q2; 시세·환율 forward·prices·forecast_panel 신규수주 미사용. 고객 가중치(suppliers.json 언급 비중)와 합병 체인링크는 현재 지식; 고객 연동 채택은 동결 모델 안에서도 자기 la−4분기 OOS 규칙(selection_oos_at_freeze)", "detail": [{"q": "2025Q3", "rev_pred": 152.12, "rev_act": 103.99, "op_pred": 2.16, "op_act": 8.42}, {"q": "2025Q4", "rev_pred": 128.35, "rev_act": 154.55, "op_pred": 1.82, "op_act": -8.21}, {"q": "2026Q1", "rev_pred": 144.47, "rev_act": 50.54, "op_pred": 2.05, "op_act": -21.45}, {"q": "2026Q2", "rev_pred": 97.65, "rev_act": 178.25, "op_pred": 1.39, "op_act": -32.33}]}

Sheet 변수
C1: 이름: 변수H | E1: 2Q22 | F1: 3Q22 | G1: 4Q22 | H1: 2022 | I1: 1Q23 | J1: 2Q23 | K1: 3Q23 | L1: 4Q23 | M1: 2023 | N1: 1Q24 | O1: 2Q24 | P1: 3Q24 | Q1: 4Q24 | R1: 2024 | S1: 1Q25 | T1: 2Q25 | U1: 3Q25 | V1: 4Q25 | W1: 2025 | X1: 1Q26 | Y1: 2Q26 | Z1: 3Q26 | AA1: 4Q26 | AB1: 2026 | AC1: 1Q27 | AD1: 2Q27 | AE1: 3Q27 | AF1: 4Q27 | AG1: 2027 | AH1: 1Q28 | AI1: 2Q28 | AJ1: 3Q28 | AK1: 4Q28 | AL1: 2028
A2: 가정 시계열 — 노란 셀은 추정 가정(모델값에서 역산), 연녹 셀은 3절 스칼라 참조 수식. 바꾸면 subQ·분기·연간예상·TP·시나리오가 재계산됩니다.
E3: 1 | F3: 2 | G3: 3 | H3: 4 | I3: 5 | J3: 6 | K3: 7 | L3: 8 | M3: 9 | N3: 10 | O3: 11 | P3: 12 | Q3: 13 | R3: 14 | S3: 15 | T3: 16 | U3: 17 | V3: 18 | W3: 19 | X3: 20 | Y3: 21 | Z3: 22 | AA3: 23 | AB3: 24 | AC3: 25 | AD3: 26 | AE3: 27 | AF3: 28 | AG3: 29 | AH3: 30 | AI3: 31 | AJ3: 32 | AK3: 33 | AL3: 34
E4: 2022.06 | F4: 2022.09 | G4: 2022.12 | H4: 2022.12A | I4: 2023.03 | J4: 2023.06 | K4: 2023.09 | L4: 2023.12 | M4: 2023.12A | N4: 2024.03 | O4: 2024.06 | P4: 2024.09 | Q4: 2024.12 | R4: 2024.12A | S4: 2025.03 | T4: 2025.06 | U4: 2025.09 | V4: 2025.12 | W4: 2025.12A | X4: 2026.03 | Y4: 2026.06 | Z4: 2026.09 | AA4: 2026.12 | AB4: 2026.12A | AC4: 2027.03 | AD4: 2027.06 | AE4: 2027.09 | AF4: 2027.12 | AG4: 2027.12A | AH4: 2028.03 | AI4: 2028.06 | AJ4: 2028.09 | AK4: 2028.12 | AL4: 2028.12A
B5: 1. FX | C5: 이름: 환율
A6: USDKRW_avg | C6: 원/달러(평균) | E6: 1262.09 | F6: 1341.93 | G6: 1360.12 | H6: 1292.98 | I6: 1276.95 | J6: 1315.69 | K6: 1313.62 | L6: 1322.01 | M6: 1306.85 | N6: 1330.14 | O6: 1371.28 | P6: 1356.22 | Q6: 1396.3 | R6: 1363.53 | S6: 1452.28 | T6: 1398.52 | U6: 1386.95 | V6: 1449.19 | W6: 1421.52 | X6: 1466.12 | Y6: 1501.75 | Z6: 1418.75 | AA6: 1345.14 | AB6: 1457.21 | AC6: 1341.49 | AD6: 1341.49 | AE6: 1341.49 | AF6: 1341.49 | AH6: 1341.49 | AI6: 1341.49 | AJ6: 1341.49 | AK6: 1341.49
A7: USDKRW_end | C7: 원/달러(기말) | E7: 1301.24 | F7: 1436.9 | G7: 1260.16 | H7: 1260.16 | I7: 1305.99 | J7: 1321.44 | K7: 1345.35 | L7: 1297.43 | M7: 1297.43 | N7: 1349.25 | O7: 1377.73 | P7: 1312.17 | Q7: 1474.78 | R7: 1474.78 | S7: 1474.54 | T7: 1355.13 | U7: 1403.67 | V7: 1444.2 | W7: 1444.2 | X7: 1524.8 | Y7: 1550.89 | Z7: 1355.4 | AA7: 1341.49 | AB7: 1341.49 | AC7: 1341.49 | AD7: 1341.49 | AE7: 1341.49 | AF7: 1341.49 | AH7: 1341.49 | AI7: 1341.49 | AJ7: 1341.49 | AK7: 1341.49
A8: JPY100KRW_avg | C8: 원/100Y(평균) | E8: 972.23 | F8: 970.61 | G8: 961.03 | H8: 985.1 | I8: 964.89 | J8: 957.36 | K8: 909 | L8: 893.22 | M8: 931.11 | N8: 896.29 | O8: 880.14 | P8: 909.35 | Q8: 917.25 | R8: 900.92 | S8: 952.59 | T8: 967.92 | U8: 940.32 | V8: 940.77 | W8: 950.17 | X8: 934.39 | Y8: 942.16 | Z8: 890.41 | AA8: 850.79 | AB8: 919.21 | AC8: 847.7 | AD8: 847.7 | AE8: 847.7 | AF8: 847.7 | AH8: 847.7 | AI8: 847.7 | AJ8: 847.7 | AK8: 847.7
A9: JPY100KRW_end | C9: 원/100Y(기말) | E9: 954.9 | F9: 993.29 | G9: 955.54 | H9: 955.54 | I9: 980.62 | J9: 913.67 | K9: 901.47 | L9: 917.04 | M9: 917.04 | N9: 892.42 | O9: 857.76 | P9: 919.21 | Q9: 939.65 | R9: 939.65 | S9: 986.84 | T9: 938.85 | U9: 948.49 | V9: 921.81 | W9: 921.81 | X9: 955.99 | Y9: 954.75 | Z9: 863.31 | AA9: 847.7 | AB9: 847.7 | AC9: 847.7 | AD9: 847.7 | AE9: 847.7 | AF9: 847.7 | AH9: 847.7 | AI9: 847.7 | AJ9: 847.7 | AK9: 847.7
A10: EURKRW_avg | C10: W/Euro(평균) | E10: 1343.31 | F10: 1350.63 | G10: 1386.07 | H10: 1358.07 | I10: 1369.93 | J10: 1432.41 | K10: 1429.41 | L10: 1420.91 | M10: 1412.88 | N10: 1444.21 | O10: 1476.42 | P10: 1489.3 | Q10: 1490.78 | R10: 1475.4 | S10: 1528.33 | T10: 1585.13 | U10: 1620.04 | V10: 1686.02 | W10: 1605.45 | X10: 1715.47 | Y10: 1746.09 | Z10: 1631.97 | AA10: 1509.74 | AB10: 1689.95 | AC10: 1503.27 | AD10: 1503.27 | AE10: 1503.27 | AF10: 1503.27 | AH10: 1503.27 | AI10: 1503.27 | AJ10: 1503.27 | AK10: 1503.27
A11: EURKRW_end | C11: W/Euro(기말) | E11: 1351.6 | F11: 1400.62 | G11: 1344.08 | H11: 1344.08 | I11: 1420.26 | J11: 1435.88 | K11: 1425.26 | L11: 1433.66 | M11: 1433.66 | N11: 1458.68 | O11: 1474.86 | P11: 1469.1 | Q11: 1532.14 | R11: 1532.14 | S11: 1594.72 | T11: 1588.22 | U11: 1648.04 | V11: 1696.94 | W11: 1696.94 | X11: 1753.21 | Y11: 1767.09 | Z11: 1539.06 | AA11: 1503.27 | AB11: 1503.27 | AC11: 1503.27 | AD11: 1503.27 | AE11: 1503.27 | AF11: 1503.27 | AH11: 1503.27 | AI11: 1503.27 | AJ11: 1503.27 | AK11: 1503.27
A12: CNYKRW_avg | C12: 원/중국원(평균) | E12: 190.76 | F12: 195.79 | G12: 191.09 | H12: 191.93 | I12: 186.59 | J12: 187.45 | K12: 181.28 | L12: 182.86 | M12: 184.52 | N12: 185.04 | O12: 189.35 | P12: 189.24 | Q12: 194.24 | R12: 189.49 | S12: 199.63 | T12: 193.41 | U12: 193.79 | V12: 204.38 | W12: 197.8 | X12: 211.75 | Y12: 220.8 | Z12: 210.43 | AA12: 200.69 | AB12: 213.75 | AC12: 200.46 | AD12: 200.46 | AE12: 200.46 | AF12: 200.46 | AH12: 200.46 | AI12: 200.46 | AJ12: 200.46 | AK12: 200.46
A13: CNYKRW_end | C13: 원/중국원(기말) | E13: 194.13 | F13: 201.92 | G13: 182.67 | H13: 182.67 | I13: 189.97 | J13: 181.8 | K13: 184.26 | L13: 182.61 | M13: 182.61 | N13: 186.66 | O13: 189.7 | P13: 187.12 | Q13: 202.04 | R13: 202.04 | S13: 203.3 | T13: 189.14 | U13: 197.16 | V13: 206.28 | W13: 206.28 | X13: 220.97 | Y13: 228.56 | Z13: 202.16 | AA13: 200.46 | AB13: 200.46 | AC13: 200.46 | AD13: 200.46 | AE13: 200.46 | AF13: 200.46 | AH13: 200.46 | AI13: 200.46 | AJ13: 200.46 | AK13: 200.46
B14: 1b. 종가
A15: price_close_end | C15: 종가(기말) | E15: 35250 | F15: 25600 | G15: 26100 | I15: 27600 | J15: 28450 | K15: 19740 | L15: 20250 | N15: 18530 | O15: 22200 | P15: 15810 | Q15: 12830 | S15: 14170 | T15: 18130 | U15: 28550 | V15: 26200 | X15: 25750 | Y15: 24150 | Z15: 25050 | AA15: 24400
A16: price_high | C16: 종가(최고) | E16: 52400 | F16: 45250 | G16: 33500 | I16: 31450 | J16: 32300 | K16: 28850 | L16: 23100 | N16: 21700 | O16: 29500 | P16: 21950 | Q16: 16090 | S16: 16780 | T16: 21250 | U16: 35950 | V16: 44200 | X16: 36300 | Y16: 43700 | Z16: 28200 | AA16: 26450
A17: price_low | C17: 종가(최저) | E17: 30300 | F17: 25000 | G17: 23600 | I17: 24050 | J17: 25950 | K17: 19400 | L17: 16630 | N17: 17210 | O17: 17300 | P17: 14500 | Q17: 11300 | S17: 12900 | T17: 12590 | U17: 17000 | V17: 26000 | X17: 24350 | Y17: 21100 | Z17: 11810 | AA17: 24050
A18: price_avg | C18: 종가(평균) | E18: 37470 | F18: 32902.4 | G18: 27931.5 | I18: 28058.1 | J18: 28250.8 | K18: 23875 | L18: 18674.3 | N18: 18942.6 | O18: 20921.3 | P18: 17361.5 | Q18: 13716.7 | S18: 14663.8 | T18: 16378.5 | U18: 21695.5 | V18: 30210.2 | X18: 30416.9 | Y18: 29614.8 | Z18: 18741.1 | AA18: 25150
B20: 2. 추정 드라이버 | C20: 실적 열 = subQ 실현값(수식), 추정 열 = 가정(노란 = 모델값 역산, 연녹 = 3절 스칼라 참조)
A21: drv:매출액 | B21: yoy | C21: 매출액 YoY | J21: =IFERROR(subQ!J5/subQ!E5-1,"") | K21: =IFERROR(subQ!K5/subQ!F5-1,"") | L21: =IFERROR(subQ!L5/subQ!G5-1,"") | N21: =IFERROR(subQ!N5/subQ!I5-1,"") | O21: =IFERROR(subQ!O5/subQ!J5-1,"") | P21: =IFERROR(subQ!P5/subQ!K5-1,"") | Q21: =IFERROR(subQ!Q5/subQ!L5-1,"") | S21: =IFERROR(subQ!S5/subQ!N5-1,"") | T21: =IFERROR(subQ!T5/subQ!O5-1,"") | U21: =IFERROR(subQ!U5/subQ!P5-1,"") | V21: =IFERROR(subQ!V5/subQ!Q5-1,"") | X21: =IFERROR(subQ!X5/subQ!S5-1,"") | Y21: =IFERROR(subQ!Y5/subQ!T5-1,"") | Z21: 0.28965316 | AA21: 0.28958786 | AC21: 0.28970217 | AD21: 0.28959399 | AE21: 0.14473194 | AF21: 0.14480682 | AH21: 0.14467628 | AI21: 0.14482099 | AJ21: 0.072433559 | AK21: 0.07240533
A22: drv:판관비 | B22: ratio | C22: 판관비율(/매출) | E22: =IFERROR(subQ!E8/subQ!E5,"") | F22: =IFERROR(subQ!F8/subQ!F5,"") | G22: =IFERROR(subQ!G8/subQ!G5,"") | H22: =IFERROR(subQ!H8/subQ!H5,"") | I22: =IFERROR(subQ!I8/subQ!I5,"") | J22: =IFERROR(subQ!J8/subQ!J5,"") | K22: =IFERROR(subQ!K8/subQ!K5,"") | L22: =IFERROR(subQ!L8/subQ!L5,"") | ... Y22: =IFERROR(subQ!Y8/subQ!Y5,"") | Z22: =$D$48 | AA22: =$D$48 | AB22: =IFERROR(subQ!AB8/subQ!AB5,"") | AC22: =$D$48 | AD22: =$D$48 | AE22: =$D$48 | AF22: =$D$48 | AG22: =IFERROR(subQ!AG8/subQ!AG5,"") | AH22: =$D$48 | AI22: =$D$48 | AJ22: =$D$48 | AK22: =$D$48 | AL22: =IFERROR(subQ!AL8/subQ!AL5,"")
A23: drv:영업이익 | B23: ratio | C23: 영업이익률(OPM) | E23: =IFERROR(subQ!E9/subQ!E5,"") | F23: =IFERROR(subQ!F9/subQ!F5,"") | G23: =IFERROR(subQ!G9/subQ!G5,"") | H23: =IFERROR(subQ!H9/subQ!H5,"") | I23: =IFERROR(subQ!I9/subQ!I5,"") | J23: =IFERROR(subQ!J9/subQ!J5,"") | K23: =IFERROR(subQ!K9/subQ!K5,"") | L23: =IFERROR(subQ!L9/subQ!L5,"") | ... Y23: =IFERROR(subQ!Y9/subQ!Y5,"") | Z23: 0.014167474 | AA23: 0.014199699 | AB23: =IFERROR(subQ!AB9/subQ!AB5,"") | AC23: 0.01426818 | AD23: 0.014181929 | AE23: 0.014200104 | AF23: 0.014200561 | AG23: =IFERROR(subQ!AG9/subQ!AG5,"") | AH23: 0.014207211 | AI23: 0.014211886 | AJ23: 0.014212828 | AK23: 0.014222658 | AL23: =IFERROR(subQ!AL9/subQ!AL5,"")
A24: drv:기타영업외손익 | B24: abs | C24: 기타영업외손익 (가정, 억원) | E24: =subQ!E13 | F24: =subQ!F13 | G24: =subQ!G13 | H24: =subQ!H13 | I24: =subQ!I13 | J24: =subQ!J13 | K24: =subQ!K13 | L24: =subQ!L13 | ... Y24: =subQ!Y13 | Z24: 0 | AA24: 0 | AB24: =subQ!AB13 | AC24: 0 | AD24: 0 | AE24: 0 | AF24: 0 | AG24: =subQ!AG13 | AH24: 0 | AI24: 0 | AJ24: 0 | AK24: 0 | AL24: =subQ!AL13
A25: drv:법인세비용 | B25: ratio | C25: 법인세율(/세전) | E25: =IFERROR(subQ!E15/subQ!E14,"") | F25: =IFERROR(subQ!F15/subQ!F14,"") | G25: =IFERROR(subQ!G15/subQ!G14,"") | H25: =IFERROR(subQ!H15/subQ!H14,"") | I25: =IFERROR(subQ!I15/subQ!I14,"") | J25: =IFERROR(subQ!J15/subQ!J14,"") | K25: =IFERROR(subQ!K15/subQ!K14,"") | L25: =IFERROR(subQ!L15/subQ!L14,"") | ... Y25: =IFERROR(subQ!Y15/subQ!Y14,"") | Z25: 0 | AA25: 0 | AB25: =IFERROR(subQ!AB15/subQ!AB14,"") | AC25: 0 | AD25: 0 | AE25: 0 | AF25: 0 | AG25: =IFERROR(subQ!AG15/subQ!AG14,"") | AH25: 0 | AI25: 0 | AJ25: 0 | AK25: 0 | AL25: =IFERROR(subQ!AL15/subQ!AL14,"")
A26: drv:지배주주순이익 | B26: ratio | C26: 지배주주 비중(/당기순이익) | E26: =IFERROR(subQ!E17/subQ!E16,"") | F26: =IFERROR(subQ!F17/subQ!F16,"") | G26: =IFERROR(subQ!G17/subQ!G16,"") | H26: =IFERROR(subQ!H17/subQ!H16,"") | I26: =IFERROR(subQ!I17/subQ!I16,"") | J26: =IFERROR(subQ!J17/subQ!J16,"") | K26: =IFERROR(subQ!K17/subQ!K16,"") | L26: =IFERROR(subQ!L17/subQ!L16,"") | ... Y26: =IFERROR(subQ!Y17/subQ!Y16,"") | Z26: =$D$49 | AA26: =$D$49 | AB26: =IFERROR(subQ!AB17/subQ!AB16,"") | AC26: =$D$49 | AD26: =$D$49 | AE26: =$D$49 | AF26: =$D$49 | AG26: =IFERROR(subQ!AG17/subQ!AG16,"") | AH26: =$D$49 | AI26: =$D$49 | AJ26: =$D$49 | AK26: =$D$49 | AL26: =IFERROR(subQ!AL17/subQ!AL16,"")
A27: drv:감가상각비 | B27: abs | C27: 감가상각비 (가정, 억원) | E27: =subQ!E18 | F27: =subQ!F18 | G27: =subQ!G18 | H27: =subQ!H18 | I27: =subQ!I18 | J27: =subQ!J18 | K27: =subQ!K18 | L27: =subQ!L18 | ... Y27: =subQ!Y18 | Z27: 5.16 | AA27: 5.16 | AB27: =subQ!AB18 | AC27: 5.16 | AD27: 5.16 | AE27: 5.16 | AF27: 5.16 | AG27: =subQ!AG18 | AH27: 5.16 | AI27: 5.16 | AJ27: 5.16 | AK27: 5.16 | AL27: =subQ!AL18
A28: drv:부채총계 | B28: qoq | C28: 부채총계 QoQ | F28: =IFERROR(subQ!F21/subQ!E21-1,"") | G28: =IFERROR(subQ!G21/subQ!F21-1,"") | I28: =IFERROR(subQ!I21/subQ!G21-1,"") | J28: =IFERROR(subQ!J21/subQ!I21-1,"") | K28: =IFERROR(subQ!K21/subQ!J21-1,"") | L28: =IFERROR(subQ!L21/subQ!K21-1,"") | N28: =IFERROR(subQ!N21/subQ!L21-1,"") | O28: =IFERROR(subQ!O21/subQ!N21-1,"") | P28: =IFERROR(subQ!P21/subQ!O21-1,"") | Q28: =IFERROR(subQ!Q21/subQ!P21-1,"") | S28: =IFERROR(subQ!S21/subQ!Q21-1,"") | T28: =IFERROR(subQ!T21/subQ!S21-1,"") | U28: =IFERROR(subQ!U21/subQ!T21-1,"") | V28: =IFERROR(subQ!V21/subQ!U21-1,"") | X28: =IFERROR(subQ!X21/subQ!V21-1,"") | Y28: =IFERROR(subQ!Y21/subQ!X21-1,"") | Z28: 2.395e-06 | AA28: 0 | AC28: 0 | AD28: 0 | AE28: 0 | AF28: 0 | AH28: 0 | AI28: 0 | AJ28: 0 | AK28: 0
A29: drv:자본총계 | B29: roll | C29: 자본총계 기타변동(배당 등, 억원) | F29: =IFERROR(subQ!E22+subQ!F16-subQ!F22,"") | G29: =IFERROR(subQ!F22+subQ!G16-subQ!G22,"") | I29: =IFERROR(subQ!G22+subQ!I16-subQ!I22,"") | J29: =IFERROR(subQ!I22+subQ!J16-subQ!J22,"") | K29: =IFERROR(subQ!J22+subQ!K16-subQ!K22,"") | L29: =IFERROR(subQ!K22+subQ!L16-subQ!L22,"") | N29: =IFERROR(subQ!L22+subQ!N16-subQ!N22,"") | O29: =IFERROR(subQ!N22+subQ!O16-subQ!O22,"") | P29: =IFERROR(subQ!O22+subQ!P16-subQ!P22,"") | Q29: =IFERROR(subQ!P22+subQ!Q16-subQ!Q22,"") | S29: =IFERROR(subQ!Q22+subQ!S16-subQ!S22,"") | T29: =IFERROR(subQ!S22+subQ!T16-subQ!T22,"") | U29: =IFERROR(subQ!T22+subQ!U16-subQ!U22,"") | V29: =IFERROR(subQ!U22+subQ!V16-subQ!V22,"") | X29: =IFERROR(subQ!V22+subQ!X16-subQ!X22,"") | Y29: =IFERROR(subQ!X22+subQ!Y16-subQ!Y22,"") | Z29: -0.007541919 | AA29: 0.000416409 | AC29: 0.000543429 | AD29: -0.013436241 | AE29: -5.263e-06 | AF29: -0.000646678 | AH29: 0.00070409 | AI29: 0.004521633 | AJ29: -8.934e-05 | AK29: 0.00743363
A30: drv:지배주주지분 | B30: roll | C30: 지배주주지분 기타변동(배당 등, 억원) | F30: =IFERROR(subQ!E23+subQ!F17-subQ!F23,"") | G30: =IFERROR(subQ!F23+subQ!G17-subQ!G23,"") | I30: =IFERROR(subQ!G23+subQ!I17-subQ!I23,"") | J30: =IFERROR(subQ!I23+subQ!J17-subQ!J23,"") | K30: =IFERROR(subQ!J23+subQ!K17-subQ!K23,"") | L30: =IFERROR(subQ!K23+subQ!L17-subQ!L23,"") | N30: =IFERROR(subQ!L23+subQ!N17-subQ!N23,"") | O30: =IFERROR(subQ!N23+subQ!O17-subQ!O23,"") | P30: =IFERROR(subQ!O23+subQ!P17-subQ!P23,"") | Q30: =IFERROR(subQ!P23+subQ!Q17-subQ!Q23,"") | S30: =IFERROR(subQ!Q23+subQ!S17-subQ!S23,"") | T30: =IFERROR(subQ!S23+subQ!T17-subQ!T23,"") | U30: =IFERROR(subQ!T23+subQ!U17-subQ!U23,"") | V30: =IFERROR(subQ!U23+subQ!V17-subQ!V23,"") | X30: =IFERROR(subQ!V23+subQ!X17-subQ!X23,"") | Y30: =IFERROR(subQ!X23+subQ!Y17-subQ!Y23,"") | Z30: -0.009441919 | AA30: 0.000416409 | AC30: 0.000543429 | AD30: -0.003436241 | AE30: -5.263e-06 | AF30: -0.010646678 | AH30: 0.00070409 | AI30: 0.004521633 | AJ30: 0.00991066 | AK30: -0.00256637
A31: drv:총차입금 | B31: qoq | C31: 총차입금 QoQ | F31: =IFERROR(subQ!F24/subQ!E24-1,"") | G31: =IFERROR(subQ!G24/subQ!F24-1,"") | I31: =IFERROR(subQ!I24/subQ!G24-1,"") | J31: =IFERROR(subQ!J24/subQ!I24-1,"") | K31: =IFERROR(subQ!K24/subQ!J24-1,"") | L31: =IFERROR(subQ!L24/subQ!K24-1,"") | N31: =IFERROR(subQ!N24/subQ!L24-1,"") | O31: =IFERROR(subQ!O24/subQ!N24-1,"") | P31: =IFERROR(subQ!P24/subQ!O24-1,"") | Q31: =IFERROR(subQ!Q24/subQ!P24-1,"") | S31: =IFERROR(subQ!S24/subQ!Q24-1,"") | T31: =IFERROR(subQ!T24/subQ!S24-1,"") | U31: =IFERROR(subQ!U24/subQ!T24-1,"") | V31: =IFERROR(subQ!V24/subQ!U24-1,"") | X31: =IFERROR(subQ!X24/subQ!V24-1,"") | Y31: =IFERROR(subQ!Y24/subQ!X24-1,"") | Z31: 1.38e-06 | AA31: 0 | AC31: 0 | AD31: 0 | AE31: 0 | AF31: 0 | AH31: 0 | AI31: 0 | AJ31: 0 | AK31: 0
A32: drv:순차입금 | B32: qoq | C32: 순차입금 QoQ | F32: =IFERROR(subQ!F25/subQ!E25-1,"") | G32: =IFERROR(subQ!G25/subQ!F25-1,"") | I32: =IFERROR(subQ!I25/subQ!G25-1,"") | J32: =IFERROR(subQ!J25/subQ!I25-1,"") | K32: =IFERROR(subQ!K25/subQ!J25-1,"") | L32: =IFERROR(subQ!L25/subQ!K25-1,"") | N32: =IFERROR(subQ!N25/subQ!L25-1,"") | O32: =IFERROR(subQ!O25/subQ!N25-1,"") | P32: =IFERROR(subQ!P25/subQ!O25-1,"") | Q32: =IFERROR(subQ!Q25/subQ!P25-1,"") | S32: =IFERROR(subQ!S25/subQ!Q25-1,"") | T32: =IFERROR(subQ!T25/subQ!S25-1,"") | U32: =IFERROR(subQ!U25/subQ!T25-1,"") | V32: =IFERROR(subQ!V25/subQ!U25-1,"") | X32: =IFERROR(subQ!X25/subQ!V25-1,"") | Y32: =IFERROR(subQ!Y25/subQ!X25-1,"") | Z32: 0.006490235 | AA32: 0.005606263 | AC32: 0.00751159 | AD32: 0.005281041 | AE32: 0.006363829 | AF32: 0.005383206 | AH32: 0.007501861 | AI32: 0.005001895 | AJ32: 0.006353216 | AK32: 0.005329612
A33: drv:이자발생자산 | B33: qoq | C33: 이자발생자산 QoQ | F33: =IFERROR(subQ!F26/subQ!E26-1,"") | G33: =IFERROR(subQ!G26/subQ!F26-1,"") | I33: =IFERROR(subQ!I26/subQ!G26-1,"") | J33: =IFERROR(subQ!J26/subQ!I26-1,"") | K33: =IFERROR(subQ!K26/subQ!J26-1,"") | L33: =IFERROR(subQ!L26/subQ!K26-1,"") | N33: =IFERROR(subQ!N26/subQ!L26-1,"") | O33: =IFERROR(subQ!O26/subQ!N26-1,"") | P33: =IFERROR(subQ!P26/subQ!O26-1,"") | Q33: =IFERROR(subQ!Q26/subQ!P26-1,"") | S33: =IFERROR(subQ!S26/subQ!Q26-1,"") | T33: =IFERROR(subQ!T26/subQ!S26-1,"") | U33: =IFERROR(subQ!U26/subQ!T26-1,"") | V33: =IFERROR(subQ!V26/subQ!U26-1,"") | X33: =IFERROR(subQ!X26/subQ!V26-1,"") | Y33: =IFERROR(subQ!Y26/subQ!X26-1,"") | Z33: -0.02202364 | AA33: -0.01963819 | AC33: -0.026942642 | AD33: -0.019612792 | AE33: -0.024234178 | AF33: -0.021142685 | AH33: -0.030262195 | AI33: -0.020963195 | AJ33: -0.02733282 | AK33: -0.02372316
A34: drv:현금및현금성자산 | B34: qoq | C34: 현금및현금성자산 QoQ | F34: =IFERROR(subQ!F27/subQ!E27-1,"") | G34: =IFERROR(subQ!G27/subQ!F27-1,"") | I34: =IFERROR(subQ!I27/subQ!G27-1,"") | J34: =IFERROR(subQ!J27/subQ!I27-1,"") | K34: =IFERROR(subQ!K27/subQ!J27-1,"") | L34: =IFERROR(subQ!L27/subQ!K27-1,"") | N34: =IFERROR(subQ!N27/subQ!L27-1,"") | O34: =IFERROR(subQ!O27/subQ!N27-1,"") | P34: =IFERROR(subQ!P27/subQ!O27-1,"") | Q34: =IFERROR(subQ!Q27/subQ!P27-1,"") | S34: =IFERROR(subQ!S27/subQ!Q27-1,"") | T34: =IFERROR(subQ!T27/subQ!S27-1,"") | U34: =IFERROR(subQ!U27/subQ!T27-1,"") | V34: =IFERROR(subQ!V27/subQ!U27-1,"") | X34: =IFERROR(subQ!X27/subQ!V27-1,"") | Y34: =IFERROR(subQ!Y27/subQ!X27-1,"")
A35: drv:영업활동현금흐름 | B35: yoy | C35: 영업활동현금흐름 YoY | J35: =IFERROR(subQ!J28/subQ!E28-1,"") | K35: =IFERROR(subQ!K28/subQ!F28-1,"") | L35: =IFERROR(subQ!L28/subQ!G28-1,"") | N35: =IFERROR(subQ!N28/subQ!I28-1,"") | O35: =IFERROR(subQ!O28/subQ!J28-1,"") | P35: =IFERROR(subQ!P28/subQ!K28-1,"") | Q35: =IFERROR(subQ!Q28/subQ!L28-1,"") | S35: =IFERROR(subQ!S28/subQ!N28-1,"") | T35: =IFERROR(subQ!T28/subQ!O28-1,"") | U35: =IFERROR(subQ!U28/subQ!P28-1,"") | V35: =IFERROR(subQ!V28/subQ!Q28-1,"") | X35: =IFERROR(subQ!X28/subQ!S28-1,"") | Y35: =IFERROR(subQ!Y28/subQ!T28-1,"")
A36: drv:주식수 | B36: qoq | C36: 주식수 QoQ | F36: =IFERROR(subQ!F29/subQ!E29-1,"") | G36: =IFERROR(subQ!G29/subQ!F29-1,"") | I36: =IFERROR(subQ!I29/subQ!G29-1,"") | J36: =IFERROR(subQ!J29/subQ!I29-1,"") | K36: =IFERROR(subQ!K29/subQ!J29-1,"") | L36: =IFERROR(subQ!L29/subQ!K29-1,"") | N36: =IFERROR(subQ!N29/subQ!L29-1,"") | O36: =IFERROR(subQ!O29/subQ!N29-1,"") | P36: =IFERROR(subQ!P29/subQ!O29-1,"") | Q36: =IFERROR(subQ!Q29/subQ!P29-1,"") | S36: =IFERROR(subQ!S29/subQ!Q29-1,"") | T36: =IFERROR(subQ!T29/subQ!S29-1,"") | U36: =IFERROR(subQ!U29/subQ!T29-1,"") | V36: =IFERROR(subQ!V29/subQ!U29-1,"") | X36: =IFERROR(subQ!X29/subQ!V29-1,"") | Y36: =IFERROR(subQ!Y29/subQ!X29-1,"") | Z36: 0 | AA36: 0 | AC36: 0 | AD36: 0 | AE36: 0 | AF36: 0 | AH36: 0 | AI36: 0 | AJ36: 0 | AK36: 0
A37: drv:DPS | B37: abs | C37: DPS (가정, 원) | E37: =subQ!E32 | F37: =subQ!F32 | G37: =subQ!G32 | H37: =subQ!H32 | I37: =subQ!I32 | J37: =subQ!J32 | K37: =subQ!K32 | L37: =subQ!L32 | ... Y37: =subQ!Y32 | AA37: 0 | AB37: =subQ!AB32 | AF37: 0 | AG37: =subQ!AG32 | AK37: 0 | AL37: =subQ!AL32
B39: 3. 밸류에이션·스칼라 | C39: 노란 셀 = 가정. '연결' 표시는 추정 전 분기 수식이 이 셀을 참조한다는 뜻
A40: sc:종가 | C40: 종가 | D40: 24400 | E40: 원 — 네이버 정규장 종가(aik 확정종가 대조 · aik 25,150원)
A41: sc:기준일 | C41: 기준일 | D41: 20261008 | E41: 종가 기준일
A42: sc:COE | C42: COE | D42: 0.09 | E42: 자기자본비용(가정) — TP 적정 PBR = ROE/COE
...

Sheet BS연결
B1: (백만원) | C1: 이름: BS연결H | E1: 2Q22 | F1: 3Q22 | G1: 4Q22 | H1: 2022 | I1: 1Q23 | J1: 2Q23 | K1: 3Q23 | L1: 4Q23 | M1: 2023 | N1: 1Q24 | O1: 2Q24 | P1: 3Q24 | Q1: 4Q24 | R1: 2024 | S1: 1Q25 | T1: 2Q25 | U1: 3Q25 | V1: 4Q25 | W1: 2025 | X1: 1Q26 | Y1: 2Q26 | Z1: 3Q26 | AA1: 4Q26 | AB1: 2026 | AC1: 1Q27 | AD1: 2Q27 | AE1: 3Q27 | AF1: 4Q27 | AG1: 2027 | AH1: 1Q28 | AI1: 2Q28 | AJ1: 3Q28 | AK1: 4Q28 | AL1: 2028
B2: 연결 | D2: fin json(kship_fin.py)
B3: 범한퓨얼셀(연) | C3: UPDATE: 26-10-11 | E3: 1 | F3: 2 | G3: 3 | H3: 4 | I3: 5 | J3: 6 | K3: 7 | L3: 8 | M3: 9 | N3: 10 | O3: 11 | P3: 12 | Q3: 13 | R3: 14 | S3: 15 | T3: 16 | U3: 17 | V3: 18 | W3: 19 | X3: 20 | Y3: 21 | Z3: 22 | AA3: 23 | AB3: 24 | AC3: 25 | AD3: 26 | AE3: 27 | AF3: 28 | AG3: 29 | AH3: 30 | AI3: 31 | AJ3: 32 | AK3: 33 | AL3: 34
B4: Account Code | C4: AccountNAME | E4: 2022.06 | F4: 2022.09 | G4: 2022.12 | H4: 2022.12A | I4: 2023.03 | J4: 2023.06 | K4: 2023.09 | L4: 2023.12 | M4: 2023.12A | N4: 2024.03 | O4: 2024.06 | P4: 2024.09 | Q4: 2024.12 | R4: 2024.12A | S4: 2025.03 | T4: 2025.06 | U4: 2025.09 | V4: 2025.12 | W4: 2025.12A | X4: 2026.03 | Y4: 2026.06 | Z4: 2026.09 | AA4: 2026.12 | AB4: 2026.12A | AC4: 2027.03 | AD4: 2027.06 | AE4: 2027.09 | AF4: 2027.12 | AG4: 2027.12A | AH4: 2028.03 | AI4: 2028.06 | AJ4: 2028.09 | AK4: 2028.12 | AL4: 2028.12A
A5: 1 | C5: 유동자산 | L5: 89028.47 | M5: 89028.47 | N5: 78664.34 | O5: 76383.22 | P5: 72699.49 | Q5: 87944.01 | R5: 87944.01 | S5: 88788.95 | T5: 92384.06 | U5: 86456.73 | V5: 129650.83 | W5: 129650.83 | X5: 125052.52 | Y5: 110872.56
A6: 1 | C6: 현금및현금성자산 | L6: 26732.9 | M6: 26732.9 | N6: 2817.92 | O6: 26929.3 | P6: 17192.62 | Q6: 19597.33 | R6: 19597.33 | S6: 25886.48 | T6: 13731.92 | U6: 7986.22 | V6: 45853.97 | W6: 45853.97 | X6: 21114.54 | Y6: 19840.45
A7: 1 | C7: 단기금융상품 | L7: 15540 | M7: 15540 | N7: 5630 | O7: 5360 | P7: 4450 | Q7: 3540 | R7: 3540 | S7: 600 | T7: 2651.36 | U7: 2651.36 | V7: 2651.36 | W7: 2651.36 | X7: 7651.36 | Y7: 2351
A8: 1 | C8: 단기금융자산 | L8: 15540 | M8: 15540 | N8: 5630 | O8: 5360 | P8: 4450 | Q8: 3540 | R8: 3540 | S8: 600 | T8: 2651.36 | U8: 2651.36 | V8: 2651.36 | W8: 2651.36 | X8: 7651.36 | Y8: 2351
A9: 1 | C9: 단기투자자산(공정가치) | L9: 52.09 | M9: 52.09 | N9: 12.35 | O9: 12.45 | P9: 12.55 | Q9: 2699.87 | R9: 2699.87 | S9: 2687.53 | T9: 2687.53 | U9: 2687.53 | V9: 2887.42 | W9: 2887.42 | X9: 2887.42 | Y9: 2887.42
A10: 1 | C10: 매출채권및기타채권 | L10: 19237.51 | M10: 19237.51 | N10: 41826.51 | O10: 14479.48 | P10: 21479.18 | Q10: 39804.81 | R10: 39804.81 | S10: 42172.66 | T10: 48435.93 | U10: 47634.36 | V10: 48702.23 | W10: 48702.23 | X10: 52310.41 | Y10: 52137.88
A11: 1 | C11: 계약자산 | L11: 9255.73 | M11: 9255.73 | N11: 9095.55 | O11: 9620.15 | P11: 10310.92 | Q11: 5907.38 | R11: 5907.38 | S11: 3323.67 | T11: 10175.87 | U11: 9141.36 | V11: 10343.67 | W11: 10343.67 | X11: 9128.41 | Y11: 439.94
A12: 1 | C12: 재고자산 | L12: 16502.04 | M12: 16502.04 | N12: 18140.08 | O12: 19297.2 | P12: 17761.96 | Q12: 15681.99 | R12: 15681.99 | S12: 12869.69 | T12: 12963.13 | U12: 13808.6 | V12: 14059.45 | W12: 14059.45 | X12: 17938.99 | Y12: 21115.81
A13: 1 | C13: 기타유동자산 | L13: 1241.19 | M13: 1241.19 | N13: 633.31 | O13: 558.69 | P13: 1309.71 | Q13: 508.77 | R13: 508.77 | S13: 1016.64 | T13: 1598.68 | U13: 2333.33 | V13: 4840.5 | W13: 4840.5 | X13: 13698.7 | Y13: 11887.62
A14: 1 | C14: 당기법인세자산(선급법인세) | L14: 467.01 | M14: 467.01 | N14: 508.6 | O14: 125.95 | P14: 182.56 | Q14: 203.85 | R14: 203.85 | S14: 232.28 | T14: 139.64 | U14: 213.95 | V14: 312.22 | W14: 312.22 | X14: 322.68 | Y14: 212.44
A15: 1 | C15: 비유동자산 | L15: 34607.2 | M15: 34607.2 | N15: 152692.81 | O15: 151776.8 | P15: 150386.2 | Q15: 224474.91 | R15: 224474.91 | S15: 225062.59 | T15: 217577.27 | U15: 222901.31 | V15: 222709.94 | W15: 222709.94 | X15: 225990.09 | Y15: 225697.2
A16: 1 | C16: 장기금융자산 | L16: 8106.68 | M16: 8106.68 | N16: 8131.12 | O16: 8131.12 | P16: 8131.12 | Q16: 4631.12 | R16: 4631.12 | S16: 4949.61 | T16: 4949.61 | U16: 8959.61 | V16: 7084.61 | W16: 7084.61 | X16: 7539.33 | Y16: 7539.33
... A21: 1 | C21: 무형자산 | L21: 2717.95 | M21: 2717.95 | N21: 2720.25 | O21: 2682.51 | P21: 5458.7 | Q21: 5237.08 | R21: 5237.08 | S21: 5050.91 | T21: 5052.5 | U21: 4843.19 | V21: 4685.33 | W21: 4685.33 | X21: 4521.93 | Y21: 4541
A22: 1 | C22: 이연법인세자산 | L22: 1237.2 | M22: 1237.2 | N22: 1237.2 | O22: 1102.86 | P22: 1102.86 | Q22: 0 | R22: 0 | V22: 0 | W22: 0
A23: 1 | C23: 자산총계 | L23: 123635.67 | M23: 123635.67 | N23: 231357.15 | O23: 228160.02 | P23: 223085.69 | Q23: 312418.93 | R23: 312418.93 | S23: 313851.54 | T23: 309961.34 | U23: 309358.04 | V23: 352360.77 | W23: 352360.77 | X23: 351042.61 | Y23: 336569.76
A24: 1 | C24: 유동부채 | L24: 10647.87 | M24: 10647.87 | N24: 30796.56 | O24: 28173.41 | P24: 23066.24 | Q24: 41752.13 | R24: 41752.13 | S24: 43001.66 | T24: 40009.22 | U24: 40620.34 | V24: 84803.18 | W24: 84803.18 | X24: 165915.11 | Y24: 163667.48
A25: 1 | C25: 매입채무및기타채무 | L25: 4928.09 | M25: 4928.09 | N25: 5266.91 | O25: 5628.93 | P25: 5560.2 | Q25: 5077.61 | R25: 5077.61 | S25: 5026.43 | T25: 5840.4 | U25: 5867.05 | V25: 12248.55 | W25: 12248.55 | X25: 8297.44 | Y25: 10735.1
A26: 1 | C26: 계약부채 | L26: 0 | M26: 0 | N26: 20064.66 | O26: 16090.44 | P26: 10975.58 | Q26: 9347.55 | R26: 9347.55 | S26: 7708.47 | T26: 4316.21 | U26: 3212.12 | V26: 27046.57 | W26: 27046.57 | X26: 26562.04 | Y26: 14957.59
A27: 1 | C27: 단기차입금 | L27: 5000 | M27: 5000 | N27: 5000 | O27: 6000 | P27: 6000 | Q27: 22785.01 | R27: 22785.01 | S27: 25008.92 | T27: 24737.08 | U27: 26809.57 | V27: 35410.7 | W27: 35410.7 | X27: 120338.23 | Y27: 123207.83
A28: 1 | C28: 유동리스부채 | L28: 167.76 | M28: 167.76 | N28: 153.64 | O28: 134.37 | P28: 120.25 | Q28: 120.62 | R28: 120.62 | S28: 119.08 | T28: 116.23 | U28: 168.46 | V28: 163.92 | W28: 163.92 | X28: 154.52 | Y28: 146.75
A29: 1 | C29: 리스부채 | L29: 1217.15 | M29: 1217.15 | N29: 1186.97 | O29: 1136.75 | P29: 1103.64 | Q29: 1080.55 | R29: 1080.55 | S29: 1010.5 | T29: 987.56 | U29: 1448.35 | V29: 1140.94 | W29: 1140.94 | X29: 1108.1 | Y29: 1076.37
A30: 1 | C30: 단기금융부채 | L30: 167.76 | M30: 167.76 | N30: 153.64 | O30: 134.37 | P30: 120.25 | Q30: 4201.66 | R30: 4201.66 | S30: 4200.12 | T30: 4197.27 | U30: 4249.5 | V30: 9718.49 | W30: 9718.49 | X30: 9709.09 | Y30: 13520.55
A31: 1 | C31: 당기법인세부채(미지급법인세) | L31: 0 | M31: 0
A32: 1 | C32: 단기충당부채 | L32: 103.86 | M32: 103.86 | N32: 126.2 | O32: 122.91 | P32: 163.36 | Q32: 106.93 | R32: 106.93 | S32: 841.34 | T32: 712.65 | U32: 291.24 | V32: 246.66 | W32: 246.66 | X32: 835.29 | Y32: 1005.26
A33: 1 | C33: 기타유동부채 | L33: 448.16 | M33: 448.16 | N33: 185.15 | O33: 196.75 | P33: 246.84 | Q33: 233.37 | R33: 233.37 | S33: 216.39 | T33: 205.62 | U33: 190.87 | V33: 132.21 | W33: 132.21 | X33: 173.03 | Y33: 241.16
A34: 1 | C34: 비유동부채 | L34: 7091.18 | M34: 7091.18 | N34: 95286.74 | O34: 93806.17 | P34: 93134.17 | Q34: 104814.39 | R34: 104814.39 | S34: 105070.2 | T34: 104639.26 | U34: 103195.48 | V34: 104864.33 | W34: 104864.33 | X34: 24091.29 | Y34: 15842.09
A35: 1 | C35: 장기차입금 | L35: 3090 | M35: 3090 | N35: 91090 | O35: 90090 | P35: 90090 | Q35: 90090 | R35: 90090 | S35: 90090 | T35: 90090 | U35: 88000 | V35: 88000 | W35: 88000 | X35: 7025.28 | Y35: 0
A36: 1 | C36: 비유동리스부채 | L36: 1049.39 | M36: 1049.39 | N36: 1033.33 | O36: 1002.38 | P36: 983.39 | Q36: 959.93 | R36: 959.93 | S36: 891.42 | T36: 871.33 | U36: 1279.89 | V36: 977.02 | W36: 977.02 | X36: 953.58 | Y36: 929.62
A37: 1 | C37: 장기금융부채 | L37: 1049.39 | M37: 1049.39 | N37: 1033.33 | O37: 1002.38 | P37: 983.39 | Q37: 959.93 | R37: 959.93 | S37: 891.42 | T37: 871.33 | U37: 1279.89 | V37: 977.02 | W37: 977.02 | X37: 953.58 | Y37: 929.62
A38: 1 | C38: 확정급여부채 | L38: 338.53 | M38: 338.53 | N38: 488.6 | O38: 625.52 | P38: 759.51 | Q38: 913.67 | R38: 913.67 | S38: 1093.17 | T38: 1277.01 | U38: 1451.31 | V38: 760 | W38: 760 | X38: 957.75 | Y38: 990.04
A39: 1 | C39: 기타비유동부채 | L39: 30.43 | M39: 30.43 | N39: 31.98 | O39: 33.54 | P39: 35.1 | Q39: 34.93 | R39: 34.93 | S39: 36.59 | T39: 38.39 | U39: 40.12 | V39: 43.77 | W39: 43.77 | X39: 45.65 | Y39: 47.54
A40: 1 | C40: 부채총계 | L40: 17739.06 | M40: 17739.06 | N40: 126083.3 | O40: 121979.57 | P40: 116200.41 | Q40: 146566.52 | R40: 146566.52 | S40: 148071.87 | T40: 144648.48 | U40: 143815.82 | V40: 189667.51 | W40: 189667.51 | X40: 190006.4 | Y40: 179509.57
A41: 1 | C41: 지배주주지분 | L41: 103901.83 | M41: 103901.83 | N41: 103319.43 | O41: 104241.26 | P41: 105016.48 | Q41: 164067.07 | R41: 164067.07 | S41: 164071.91 | T41: 163694.17 | U41: 164030.72 | V41: 161305.57 | W41: 161305.57 | X41: 159659.58 | Y41: 155873
A42: 1 | C42: 자본금 | L42: 4380.5 | M42: 4380.5 | N42: 4380.5 | O42: 4380.5 | P42: 4380.5 | Q42: 4380.5 | R42: 4380.5 | S42: 4380.5 | T42: 4380.5 | U42: 4380.5 | V42: 4380.5 | W42: 4380.5 | X42: 4380.5 | Y42: 4380.5
A43: 1 | C43: 자본잉여금 | L43: 92513.42 | M43: 92513.42 | N43: 92527.79 | O43: 92538.2 | P43: 92538.2 | Q43: 92538.2 | R43: 92538.2 | S43: 92538.2 | T43: 92538.2 | U43: 92538.2 | V43: 92538.2 | W43: 92538.2 | X43: 92538.2 | Y43: 92538.2
... A50: 1 | C50: 이자발생자산 | L50: 50379.58 | M50: 50379.58 | N50: 16579.04 | O50: 40420.42 | P50: 29773.74 | Q50: 27768.45 | R50: 27768.45 | S50: 31436.09 | T50: 21332.89 | U50: 19597.19 | V50: 55589.94 | W50: 55589.94 | X50: 36305.23 | Y50: 29730.78
...

Sheet BS별도
B1: (백만원) | C1: 이름: BS별도H | E1: 2Q22 | F1: 3Q22 | G1: 4Q22 | H1: 2022 | I1: 1Q23 | J1: 2Q23 | K1: 3Q23 | L1: 4Q23 | M1: 2023 | N1: 1Q24 | O1: 2Q24 | P1: 3Q24 | Q1: 4Q24 | R1: 2024 | S1: 1Q25 | T1: 2Q25 | U1: 3Q25 | V1: 4Q25 | W1: 2025 | X1: 1Q26 | Y1: 2Q26 | Z1: 3Q26 | AA1: 4Q26 | AB1: 2026 | AC1: 1Q27 | AD1: 2Q27 | AE1: 3Q27 | AF1: 4Q27 | AG1: 2027 | AH1: 1Q28 | AI1: 2Q28 | AJ1: 3Q28 | AK1: 4Q28 | AL1: 2028
B2: 별도 | D2: fin json(kship_fin.py)
B3: 범한퓨얼셀(별) | C3: UPDATE: 26-10-11 | E3: 1 | F3: 2 | G3: 3 | H3: 4 | I3: 5 | J3: 6 | K3: 7 | L3: 8 | M3: 9 | N3: 10 | O3: 11 | P3: 12 | Q3: 13 | R3: 14 | S3: 15 | T3: 16 | U3: 17 | V3: 18 | W3: 19 | X3: 20 | Y3: 21 | Z3: 22 | AA3: 23 | AB3: 24 | AC3: 25 | AD3: 26 | AE3: 27 | AF3: 28 | AG3: 29 | AH3: 30 | AI3: 31 | AJ3: 32 | AK3: 33 | AL3: 34
B4: Account Code | C4: AccountNAME | E4: 2022.06 | F4: 2022.09 | G4: 2022.12 | H4: 2022.12A | I4: 2023.03 | J4: 2023.06 | K4: 2023.09 | L4: 2023.12 | M4: 2023.12A | N4: 2024.03 | O4: 2024.06 | P4: 2024.09 | Q4: 2024.12 | R4: 2024.12A | S4: 2025.03 | T4: 2025.06 | U4: 2025.09 | V4: 2025.12 | W4: 2025.12A | X4: 2026.03 | Y4: 2026.06 | Z4: 2026.09 | AA4: 2026.12 | AB4: 2026.12A | AC4: 2027.03 | AD4: 2027.06 | AE4: 2027.09 | AF4: 2027.12 | AG4: 2027.12A | AH4: 2028.03 | AI4: 2028.06 | AJ4: 2028.09 | AK4: 2028.12 | AL4: 2028.12A
A5: 1 | C5: 유동자산 | E5: 114458.15 | F5: 114290.53 | G5: 103753.55 | H5: 103753.55 | I5: 97022.25 | J5: 102450.84 | K5: 96405.19 | L5: 85052.2 | M5: 85052.2 | N5: 75072.06 | O5: 72705.69 | P5: 69211.78 | Q5: 85624.4 | R5: 85624.4 | S5: 86757.79 | T5: 91089.64 | U5: 85674.93 | V5: 129005.09 | W5: 129005.09 | X5: 124017.58 | Y5: 110998.72
A6: 1 | C6: 현금및현금성자산 | E6: 89978.9 | F6: 16279.67 | G6: 22958.12 | H6: 22958.12 | I6: 30031.84 | J6: 15829.3 | K6: 35637.08 | L6: 26629.85 | M6: 26629.85 | N6: 2750.94 | O6: 26775.18 | P6: 16801.7 | Q6: 19009.47 | R6: 19009.47 | S6: 25416.47 | T6: 13321.65 | U6: 7462.37 | V6: 45601.24 | W6: 45601.24 | X6: 18696.87 | Y6: 19327.03
A7: 1 | C7: 단기금융상품 | E7: 2530 | F7: 73510 | G7: 53600 | H7: 53600 | I7: 33690 | J7: 46622.59 | K7: 19000.14 | L7: 15540 | M7: 15540 | N7: 5630 | O7: 5360 | P7: 4450 | Q7: 3540 | R7: 3540 | S7: 600 | T7: 2651.36 | U7: 2651.36 | V7: 2651.36 | W7: 2651.36 | X7: 7651.36 | Y7: 2351
A8: 1 | C8: 단기금융자산 | E8: 2530 | F8: 73510 | G8: 53600 | H8: 53600 | I8: 33690 | J8: 46622.59 | K8: 19000.14 | L8: 15540 | M8: 15540 | N8: 5630 | O8: 5360 | P8: 4450 | Q8: 3540 | R8: 3540 | S8: 600 | T8: 2651.36 | U8: 2651.36 | V8: 2651.36 | W8: 2651.36 | X8: 7651.36 | Y8: 2351
A9: 1 | C9: 매출채권및기타채권 | E9: 7963.55 | F9: 6898.83 | G9: 4668.59 | H9: 4668.59 | I9: 7346.63 | J9: 6846.83 | K9: 4963.28 | L9: 15418.49 | M9: 15418.49 | N9: 38314.44 | O9: 10969.78 | P9: 19211.56 | Q9: 38107.03 | R9: 38107.03 | S9: 40737.17 | T9: 47588.34 | U9: 47413.09 | V9: 48381.85 | W9: 48381.85 | X9: 51864.52 | Y9: 51330.02
A10: 1 | C10: 재고자산 | E10: 6019.45 | F10: 8289.05 | G10: 10925.5 | H10: 10925.5 | I10: 10319.53 | J10: 14316.07 | K10: 15449.61 | L10: 16502.04 | M10: 16502.04 | N10: 18140.08 | O10: 19297.2 | P10: 17761.96 | Q10: 15681.99 | R10: 15681.99 | S10: 12869.69 | T10: 12963.07 | U10: 13794.35 | V10: 14045.17 | W10: 14045.17 | X10: 17701.26 | Y10: 19485.29
A11: 1 | C11: 계약자산 | E11: 2668.9 | F11: 5073.44 | G11: 8787.73 | H11: 8787.73 | I11: 12948.93 | J11: 17052.45 | K11: 18487.52 | L11: 9255.73 | M11: 9255.73 | N11: 9095.55 | O11: 9620.15 | P11: 10310.92 | Q11: 5907.38 | R11: 5907.38 | S11: 3323.67 | T11: 10175.87 | U11: 9141.36 | V11: 10343.67 | W11: 10343.67 | X11: 9128.41 | Y11: 439.94
A12: 1 | C12: 기타유동자산 | E12: 5297.35 | F12: 4239.54 | G12: 2390.27 | H12: 2390.27 | I12: 2314.49 | J12: 1662.01 | K12: 2462.46 | L12: 1239.64 | M12: 1239.64 | N12: 633.31 | O12: 558.69 | P12: 505.25 | Q12: 507.44 | R12: 507.44 | S12: 918.95 | T12: 1582.36 | U12: 2333.17 | V12: 4804.46 | W12: 4804.46 | X12: 15787.53 | Y12: 14965.98
A13: 1 | C13: 비유동자산 | E13: 23459.25 | F13: 23243.08 | G13: 25948.5 | H13: 25948.5 | I13: 27217.28 | J13: 26935.06 | K13: 26563.91 | L13: 36181.61 | M13: 36181.61 | N13: 154246.03 | O13: 153449.71 | P13: 152018.73 | Q13: 225055.74 | R13: 225055.74 | S13: 225571.54 | T13: 217694.25 | U13: 222594.89 | V13: 222823.24 | W13: 222823.24 | X13: 226254.05 | Y13: 225869.29
A14: 1 | C14: 장기금융자산 | E14: 7635.8 | F14: 7635.8 | G14: 7587.15 | H14: 7587.15 | I14: 7606.68 | J14: 7606.68 | K14: 7606.68 | L14: 8106.68 | M14: 8106.68 | N14: 8131.12 | O14: 8131.12 | P14: 8131.12 | Q14: 4631.12 | R14: 4631.12 | S14: 4949.61 | T14: 4949.61 | U14: 8959.61 | V14: 7084.61 | W14: 7084.61 | X14: 7539.33 | Y14: 7539.33
A15: 1 | C15: 투자자산 | E15: 7635.8 | F15: 7635.8 | G15: 7587.15 | H15: 7587.15 | I15: 7606.68 | J15: 7606.68 | K15: 7606.68 | L15: 13056.68 | M15: 13056.68 | N15: 13081.12 | O15: 13081.12 | P15: 13081.12 | Q15: 9581.12 | R15: 9581.12 | S15: 9899.61 | T15: 9899.61 | U15: 13909.61 | V15: 12034.61 | W15: 12034.61 | X15: 12489.33 | Y15: 12489.33
A16: 1 | C16: 유형자산 | E16: 7538.41 | F16: 7406.52 | G16: 9287.48 | H16: 9287.48 | I16: 10768.03 | J16: 10986.07 | K16: 10783.11 | L16: 10708.3 | M16: 10708.3 | N16: 126989.18 | O16: 10367.06 | P16: 10178.14 | Q16: 203706.51 | R16: 203706.51 | S16: 203384.5 | T16: 202956.06 | U16: 202602.93 | V16: 202895.33 | W16: 202895.33 | X16: 205138.14 | Y16: 205027.75
... A19: 1 | C19: 무형자산 | E19: 2844.95 | F19: 2905.22 | G19: 2835.41 | H19: 2835.41 | I19: 2918.46 | J19: 2855.7 | K19: 2766.29 | L19: 2717.95 | M19: 2717.95 | N19: 2720.25 | O19: 2682.51 | P19: 2628.35 | Q19: 2477.23 | R19: 2477.23 | S19: 2360.85 | T19: 2434.58 | U19: 2297.43 | V19: 2211.72 | W19: 2211.72 | X19: 2120.47 | Y19: 2210.6
A20: 1 | C20: 이연법인세자산 | E20: 417.92 | F20: 417.92 | G20: 305.47 | H20: 305.47 | I20: 305.47 | J20: 695.71 | K20: 695.71 | L20: 1237.2 | M20: 1237.2 | N20: 1237.2 | O20: 1102.86 | P20: 1102.86 | Q20: 0 | R20: 0 | V20: 0 | W20: 0
A21: 1 | C21: 자산총계 | E21: 137917.4 | F21: 137533.61 | G21: 129702.05 | H21: 129702.05 | I21: 124239.54 | J21: 129385.9 | K21: 122969.1 | L21: 121233.81 | M21: 121233.81 | N21: 229318.1 | O21: 226155.41 | P21: 221230.51 | Q21: 310680.14 | R21: 310680.14 | S21: 312329.33 | T21: 308783.88 | U21: 308269.82 | V21: 351828.33 | W21: 351828.33 | X21: 350271.63 | Y21: 336868
A22: 1 | C22: 유동부채 | E22: 20626.58 | F22: 21638.65 | G22: 17042.64 | H22: 17042.64 | I22: 11720.44 | J22: 16205.76 | K22: 10773.4 | L22: 10330.35 | M22: 10330.35 | N22: 30701.84 | O22: 28058.91 | P22: 22858.62 | Q22: 41406.76 | R22: 41406.76 | S22: 42611.35 | T22: 39685.18 | U22: 40446.51 | V22: 84463.64 | W22: 84463.64 | X22: 165250.85 | Y22: 163380.03
A23: 1 | C23: 매입채무및기타채무 | E23: 5004.85 | F23: 8751.2 | G23: 9278.99 | H23: 9278.99 | I23: 6904.36 | J23: 8128.91 | K23: 3602.51 | L23: 4907.27 | M23: 4907.27 | N23: 5218.18 | O23: 5561 | P23: 5461.16 | Q23: 4774.05 | R23: 4774.05 | S23: 4682.6 | T23: 5566.66 | U23: 5797.14 | V23: 12012.39 | W23: 12012.39 | X23: 7737.04 | Y23: 10579.25
A24: 1 | C24: 계약부채 | E24: 11509.15 | F24: 8437.59 | G24: 2943.19 | H24: 2943.19 | I24: 756 | J24: 2034.58 | K24: 1541 | L24: 0 | M24: 0 | N24: 20064.66 | O24: 16090.44 | P24: 10975.58 | Q24: 9347.55 | R24: 9347.55 | S24: 7708.47 | T24: 4316.21 | U24: 3212.12 | V24: 27046.57 | W24: 27046.57 | X24: 26562.04 | Y24: 14957.59
A25: 1 | C25: 단기차입금 | E25: 3110 | F25: 3220 | G25: 3330 | H25: 3330 | I25: 3440 | J25: 5440 | K25: 5000 | L25: 5000 | M25: 5000 | N25: 5000 | O25: 6000 | P25: 6000 | Q25: 22785.01 | R25: 22785.01 | S25: 25008.92 | T25: 24737.08 | U25: 26809.57 | V25: 35410.7 | W25: 35410.7 | X25: 120338.23 | Y25: 123207.83
A26: 1 | C26: 유동리스부채 | E26: 113.54 | F26: 102.03 | G26: 128.34 | H26: 128.34 | I26: 162.31 | J26: 149.71 | K26: 147.05 | L26: 131.65 | M26: 131.65 | N26: 117.53 | O26: 98.25 | P26: 84.13 | Q26: 84.51 | R26: 84.51 | S26: 82.09 | T26: 78.78 | U26: 75.02 | V26: 69.85 | W26: 69.85 | X26: 60.33 | Y26: 52.45
A27: 1 | C27: 리스부채 | E27: 846.67 | F27: 813.06 | G27: 904.86 | H27: 904.86 | I27: 1058.99 | J27: 1019.37 | K27: 992.45 | L27: 957.18 | M27: 957.18 | N27: 929.15 | O27: 881.14 | P27: 850.31 | Q27: 829.57 | R27: 829.57 | S27: 761.94 | T27: 741.49 | U27: 720.82 | V27: 699.93 | W27: 699.93 | X27: 690.53 | Y27: 682.26
A28: 1 | C28: 단기금융부채 | E28: 113.54 | F28: 102.03 | G28: 128.34 | H28: 128.34 | I28: 162.31 | J28: 149.71 | K28: 147.05 | L28: 131.65 | M28: 131.65 | N28: 117.53 | O28: 98.25 | P28: 84.13 | Q28: 4165.55 | R28: 4165.55 | S28: 4163.13 | T28: 4159.82 | U28: 4156.06 | V28: 9624.42 | W28: 9624.42 | X28: 9614.9 | Y28: 13426.25
A29: 1 | C29: 당기법인세부채(미지급법인세) | E29: 320.6 | F29: 634.52 | G29: 0 | H29: 0 | L29: 0 | M29: 0
A30: 1 | C30: 단기충당부채 | E30: 419.89 | F30: 345.39 | G30: 296.95 | H30: 296.95 | I30: 280.74 | J30: 274.26 | K30: 278.63 | L30: 103.86 | M30: 103.86 | N30: 126.2 | O30: 122.91 | P30: 163.36 | Q30: 106.93 | R30: 106.93 | S30: 841.34 | T30: 712.65 | U30: 291.24 | V30: 246.66 | W30: 246.66 | X30: 835.29 | Y30: 1005.26
A31: 1 | C31: 기타유동부채 | E31: 148.55 | F31: 147.92 | G31: 1065.17 | H31: 1065.17 | I31: 177.04 | J31: 178.3 | K31: 204.21 | L31: 187.57 | M31: 187.57 | N31: 175.29 | O31: 186.3 | P31: 174.37 | Q31: 227.68 | R31: 227.68 | S31: 206.9 | T31: 192.77 | U31: 180.4 | V31: 122.89 | W31: 122.89 | X31: 163.35 | Y31: 203.86
A32: 1 | C32: 비유동부채 | E32: 6301.81 | F32: 6553.1 | G32: 6250.5 | H32: 6250.5 | I32: 5545.6 | J32: 6602.5 | K32: 7088.53 | L32: 6867.32 | M32: 6867.32 | N32: 95065.03 | O32: 93586.67 | P32: 92916.96 | Q32: 104566.35 | R32: 104566.35 | S32: 104818.84 | T32: 104362.25 | U32: 102491.53 | V32: 104422.71 | W32: 104422.71 | X32: 23668.37 | Y32: 15435.63
A33: 1 | C33: 장기차입금 | E33: 2090 | F33: 1980 | G33: 1870 | H33: 1870 | I33: 1760 | J33: 2650 | K33: 3090 | L33: 3090 | M33: 3090 | N33: 91090 | O33: 90090 | P33: 90090 | Q33: 90090 | R33: 90090 | S33: 90090 | T33: 90090 | U33: 88000 | V33: 88000 | W33: 88000 | X33: 7025.28 | Y33: 0
A34: 1 | C34: 비유동리스부채 | E34: 733.13 | F34: 711.03 | G34: 776.52 | H34: 776.52 | I34: 896.68 | J34: 869.66 | K34: 845.4 | L34: 825.53 | M34: 825.53 | N34: 811.62 | O34: 782.89 | P34: 766.18 | Q34: 745.06 | R34: 745.06 | S34: 679.85 | T34: 662.71 | U34: 645.8 | V34: 630.08 | W34: 630.08 | X34: 630.2 | Y34: 629.81
A35: 1 | C35: 장기금융부채 | E35: 733.13 | F35: 711.03 | G35: 776.52 | H35: 776.52 | I35: 896.68 | J35: 869.66 | K35: 845.4 | L35: 825.53 | M35: 825.53 | N35: 811.62 | O35: 782.89 | P35: 766.18 | Q35: 745.06 | R35: 745.06 | S35: 679.85 | T35: 662.71 | U35: 645.8 | V35: 630.08 | W35: 630.08 | X35: 630.2 | Y35: 629.81
A36: 1 | C36: 확정급여부채 | E36: 1424.81 | F36: 1562.5 | G36: 1183.55 | H36: 1183.55 | I36: 398.48 | J36: 530.91 | K36: 560.34 | L36: 338.53 | M36: 338.53 | N36: 488.6 | O36: 625.52 | P36: 759.51 | Q36: 880.67 | R36: 880.67 | S36: 1053.55 | T36: 1226.43 | U36: 1399.32 | V36: 683.26 | W36: 683.26 | X36: 876.25 | Y36: 901.5
A37: 1 | C37: 기타비유동부채 | E37: 28.46 | F37: 29.76 | G37: 28.17 | H37: 28.17 | I37: 29.51 | J37: 30.84 | K37: 32.18 | L37: 30.43 | M37: 30.43 | N37: 31.98 | O37: 33.54 | P37: 35.1 | Q37: 34.75 | R37: 34.75 | S37: 36.41 | T37: 38.08 | U37: 39.74 | V37: 43.32 | W37: 43.32 | X37: 45.12 | Y37: 46.92
A38: 1 | C38: 부채총계 | E38: 26928.39 | F38: 28191.75 | G38: 23293.14 | H38: 23293.14 | I38: 17266.04 | J38: 22808.26 | K38: 17861.93 | L38: 17197.67 | M38: 17197.67 | N38: 125766.88 | O38: 121645.59 | P38: 115775.57 | Q38: 145973.11 | R38: 145973.11 | S38: 147430.19 | T38: 144047.44 | U38: 142938.04 | V38: 188886.35 | W38: 188886.35 | X38: 188919.21 | Y38: 178815.67
A39: 1 | C39: 자본금 | E39: 4380.5 | F39: 4380.5 | G39: 4380.5 | H39: 4380.5 | I39: 4380.5 | J39: 4380.5 | K39: 4380.5 | L39: 4380.5 | M39: 4380.5 | N39: 4380.5 | O39: 4380.5 | P39: 4380.5 | Q39: 4380.5 | R39: 4380.5 | S39: 4380.5 | T39: 4380.5 | U39: 4380.5 | V39: 4380.5 | W39: 4380.5 | X39: 4380.5 | Y39: 4380.5
A40: 1 | C40: 자본잉여금 | E40: 98129.17 | F40: 95077.91 | G40: 92602.21 | H40: 92602.21 | I40: 92577.66 | J40: 92581.5 | K40: 92585.34 | L40: 92513.42 | M40: 92513.42 | N40: 92527.79 | O40: 92538.2 | P40: 92538.2 | Q40: 92538.2 | R40: 92538.2 | S40: 92538.2 | T40: 92538.2 | U40: 92538.2 | V40: 92538.2 | W40: 92538.2 | X40: 92538.2 | Y40: 92538.2
A41: 1 | C41: 이익잉여금 | E41: 8479.34 | F41: 9883.45 | G41: 9426.2 | H41: 9426.2 | I41: 10015.34 | J41: 9615.65 | K41: 8141.32 | L41: 7142.22 | M41: 7142.22 | N41: 6642.93 | O41: 7591.12 | P41: 8536.24 | Q41: 8092.02 | R41: 8092.02 | S41: 8284.13 | T41: 8121.44 | U41: 8716.77 | V41: 10571.84 | W41: 10571.84 | X41: 8982.27 | Y41: 5682.2
... A47: 1 | C47: 이자발생자산 | E47: 100144.7 | F47: 97425.47 | G47: 84145.27 | H47: 84145.27 | I47: 71328.52 | J47: 70058.57 | K47: 62243.9 | L47: 50276.53 | M47: 50276.53 | N47: 16512.06 | O47: 40266.3 | P47: 29382.82 | Q47: 27180.59 | R47: 27180.59 | S47: 30966.08 | T47: 20922.62 | U47: 19073.34 | V47: 55337.21 | W47: 55337.21 | X47: 33887.56 | Y47: 29217.36
...

Sheet subQ
A1: YQ | C1: subQ 분기 서브모델(억원, U=100) | E1: 2Q22 | F1: 3Q22 | G1: 4Q22 | H1: 2022 | I1: 1Q23 | J1: 2Q23 | K1: 3Q23 | L1: 4Q23 | M1: 2023 | N1: 1Q24 | O1: 2Q24 | P1: 3Q24 | Q1: 4Q24 | R1: 2024 | S1: 1Q25 | T1: 2Q25 | U1: 3Q25 | V1: 4Q25 | W1: 2025 | X1: 1Q26 | Y1: 2Q26 | Z1: 3Q26 | AA1: 4Q26 | AB1: 2026 | AC1: 1Q27 | AD1: 2Q27 | AE1: 3Q27 | AF1: 4Q27 | AG1: 2027 | AH1: 1Q28 | AI1: 2Q28 | AJ1: 3Q28 | AK1: 4Q28 | AL1: 2028
A2: A=이름(key) B=그룹 C=단위 D=FnGuide 계정명(VLOOKUP 키). 확정=VLOOKUP(BS), 추정=변수 가정 참조
E3: 1 | F3: 2 | G3: 3 | H3: 4 | I3: 5 | J3: 6 | K3: 7 | L3: 8 | M3: 9 | N3: 10 | O3: 11 | P3: 12 | Q3: 13 | R3: 14 | S3: 15 | T3: 16 | U3: 17 | V3: 18 | W3: 19 | X3: 20 | Y3: 21 | Z3: 22 | AA3: 23 | AB3: 24 | AC3: 25 | AD3: 26 | AE3: 27 | AF3: 28 | AG3: 29 | AH3: 30 | AI3: 31 | AJ3: 32 | AK3: 33 | AL3: 34
E4: 2022.06 | F4: 2022.09 | G4: 2022.12 | H4: 2022.12A | I4: 2023.03 | J4: 2023.06 | K4: 2023.09 | L4: 2023.12 | M4: 2023.12A | N4: 2024.03 | O4: 2024.06 | P4: 2024.09 | Q4: 2024.12 | R4: 2024.12A | S4: 2025.03 | T4: 2025.06 | U4: 2025.09 | V4: 2025.12 | W4: 2025.12A | X4: 2026.03 | Y4: 2026.06 | Z4: 2026.09 | AA4: 2026.12 | AB4: 2026.12A | AC4: 2027.03 | AD4: 2027.06 | AE4: 2027.09 | AF4: 2027.12 | AG4: 2027.12A | AH4: 2028.03 | AI4: 2028.06 | AJ4: 2028.09 | AK4: 2028.12 | AL4: 2028.12A
A5: 매출액 | B5: 손익 | C5: 억원 | D5: 매출액(수익) | E5: =IFERROR(VLOOKUP($D5,BS별도,MATCH(E$1,BS별도H,0),0)/100,"") | F5: =IFERROR(VLOOKUP($D5,BS별도,MATCH(F$1,BS별도H,0),0)/100,"") | G5: =IFERROR(VLOOKUP($D5,BS별도,MATCH(G$1,BS별도H,0),0)/100,"") | I5: =IFERROR(VLOOKUP($D5,BS별도,MATCH(I$1,BS별도H,0),0)/100,"") | J5: =IFERROR(VLOOKUP($D5,BS별도,MATCH(J$1,BS별도H,0),0)/100,"") | K5: =IFERROR(VLOOKUP($D5,BS별도,MATCH(K$1,BS별도H,0),0)/100,"") | L5: =IFERROR(VLOOKUP($D5,BS연결,MATCH(L$1,BS연결H,0),0)/100,"") | M5: =SUM(I5:L5) | N5: =IFERROR(VLOOKUP($D5,BS연결,MATCH(N$1,BS연결H,0),0)/100,"") | O5: =IFERROR(VLOOKUP($D5,BS연결,MATCH(O$1,BS연결H,0),0)/100,"") | P5: =IFERROR(VLOOKUP($D5,BS연결,MATCH(P$1,BS연결H,0),0)/100,"") | Q5: =IFERROR(VLOOKUP($D5,BS연결,MATCH(Q$1,BS연결H,0),0)/100,"") | R5: =IFERROR(VLOOKUP($D5,BS연결,MATCH(R$1,BS연결H,0),0)/100,"") | S5: =IFERROR(VLOOKUP($D5,BS연결,MATCH(S$1,BS연결H,0),0)/100,"") | T5: =IFERROR(VLOOKUP($D5,BS연결,MATCH(T$1,BS연결H,0),0)/100,"") | U5: =IFERROR(VLOOKUP($D5,BS연결,MATCH(U$1,BS연결H,0),0)/100,"") | ... Y5: =IFERROR(VLOOKUP($D5,BS연결,MATCH(Y$1,BS연결H,0),0)/100,"") | Z5: =IFERROR(U5*(1+변수!Z21),"") | AA5: =IFERROR(V5*(1+변수!AA21),"") | AB5: =SUM(X5:AA5) | AC5: =IFERROR(X5*(1+변수!AC21),"") | AD5: =IFERROR(Y5*(1+변수!AD21),"") | AE5: =IFERROR(Z5*(1+변수!AE21),"") | AF5: =IFERROR(AA5*(1+변수!AF21),"") | AG5: =SUM(AC5:AF5) | AH5: =IFERROR(AC5*(1+변수!AH21),"") | AI5: =IFERROR(AD5*(1+변수!AI21),"") | AJ5: =IFERROR(AE5*(1+변수!AJ21),"") | AK5: =IFERROR(AF5*(1+변수!AK21),"") | AL5: =SUM(AH5:AK5)
A6: 매출원가 | B6: 손익 | C6: 억원 | D6: 매출원가 | E6: =IFERROR(VLOOKUP($D6,BS별도,MATCH(E$1,BS별도H,0),0)/100,"") | F6: =IFERROR(VLOOKUP($D6,BS별도,MATCH(F$1,BS별도H,0),0)/100,"") | G6: =IFERROR(VLOOKUP($D6,BS별도,MATCH(G$1,BS별도H,0),0)/100,"") | I6: =IFERROR(VLOOKUP($D6,BS별도,MATCH(I$1,BS별도H,0),0)/100,"") | J6: =IFERROR(VLOOKUP($D6,BS별도,MATCH(J$1,BS별도H,0),0)/100,"") | K6: =IFERROR(VLOOKUP($D6,BS별도,MATCH(K$1,BS별도H,0),0)/100,"") | L6: =IFERROR(VLOOKUP($D6,BS연결,MATCH(L$1,BS연결H,0),0)/100,"") | M6: =SUM(I6:L6) | N6: =IFERROR(VLOOKUP($D6,BS연결,MATCH(N$1,BS연결H,0),0)/100,"") | O6: =IFERROR(VLOOKUP($D6,BS연결,MATCH(O$1,BS연결H,0),0)/100,"") | P6: =IFERROR(VLOOKUP($D6,BS연결,MATCH(P$1,BS연결H,0),0)/100,"") | Q6: =IFERROR(VLOOKUP($D6,BS연결,MATCH(Q$1,BS연결H,0),0)/100,"") | R6: =IFERROR(VLOOKUP($D6,BS연결,MATCH(R$1,BS연결H,0),0)/100,"") | S6: =IFERROR(VLOOKUP($D6,BS연결,MATCH(S$1,BS연결H,0),0)/100,"") | T6: =IFERROR(VLOOKUP($D6,BS연결,MATCH(T$1,BS연결H,0),0)/100,"") | U6: =IFERROR(VLOOKUP($D6,BS연결,MATCH(U$1,BS연결H,0),0)/100,"") | ... Y6: =IFERROR(VLOOKUP($D6,BS연결,MATCH(Y$1,BS연결H,0),0)/100,"") | Z6: =IFERROR(Z5-Z7,"") | AA6: =IFERROR(AA5-AA7,"") | AB6: =SUM(X6:AA6) | AC6: =IFERROR(AC5-AC7,"") | AD6: =IFERROR(AD5-AD7,"") | AE6: =IFERROR(AE5-AE7,"") | AF6: =IFERROR(AF5-AF7,"") | AG6: =SUM(AC6:AF6) | AH6: =IFERROR(AH5-AH7,"") | AI6: =IFERROR(AI5-AI7,"") | AJ6: =IFERROR(AJ5-AJ7,"") | AK6: =IFERROR(AK5-AK7,"") | AL6: =SUM(AH6:AK6)
A7: 매출총이익 | B7: 손익 | C7: 억원 | D7: 매출총이익 | E7: =IFERROR(VLOOKUP($D7,BS별도,MATCH(E$1,BS별도H,0),0)/100,"") | F7: =IFERROR(VLOOKUP($D7,BS별도,MATCH(F$1,BS별도H,0),0)/100,"") | G7: =IFERROR(VLOOKUP($D7,BS별도,MATCH(G$1,BS별도H,0),0)/100,"") | I7: =IFERROR(VLOOKUP($D7,BS별도,MATCH(I$1,BS별도H,0),0)/100,"") | J7: =IFERROR(VLOOKUP($D7,BS별도,MATCH(J$1,BS별도H,0),0)/100,"") | K7: =IFERROR(VLOOKUP($D7,BS별도,MATCH(K$1,BS별도H,0),0)/100,"") | L7: =IFERROR(VLOOKUP($D7,BS연결,MATCH(L$1,BS연결H,0),0)/100,"") | M7: =SUM(I7:L7) | N7: =IFERROR(VLOOKUP($D7,BS연결,MATCH(N$1,BS연결H,0),0)/100,"") | O7: =IFERROR(VLOOKUP($D7,BS연결,MATCH(O$1,BS연결H,0),0)/100,"") | P7: =IFERROR(VLOOKUP($D7,BS연결,MATCH(P$1,BS연결H,0),0)/100,"") | Q7: =IFERROR(VLOOKUP($D7,BS연결,MATCH(Q$1,BS연결H,0),0)/100,"") | R7: =IFERROR(VLOOKUP($D7,BS연결,MATCH(R$1,BS연결H,0),0)/100,"") | S7: =IFERROR(VLOOKUP($D7,BS연결,MATCH(S$1,BS연결H,0),0)/100,"") | T7: =IFERROR(VLOOKUP($D7,BS연결,MATCH(T$1,BS연결H,0),0)/100,"") | U7: =IFERROR(VLOOKUP($D7,BS연결,MATCH(U$1,BS연결H,0),0)/100,"") | ... Y7: =IFERROR(VLOOKUP($D7,BS연결,MATCH(Y$1,BS연결H,0),0)/100,"") | Z7: =IFERROR(Z9+Z8,"") | AA7: =IFERROR(AA9+AA8,"") | AB7: =SUM(X7:AA7) | AC7: =IFERROR(AC9+AC8,"") | AD7: =IFERROR(AD9+AD8,"") | AE7: =IFERROR(AE9+AE8,"") | AF7: =IFERROR(AF9+AF8,"") | AG7: =SUM(AC7:AF7) | AH7: =IFERROR(AH9+AH8,"") | AI7: =IFERROR(AI9+AI8,"") | AJ7: =IFERROR(AJ9+AJ8,"") | AK7: =IFERROR(AK9+AK8,"") | AL7: =SUM(AH7:AK7)
A8: 판관비 | B8: 손익 | C8: 억원 | D8: 판관비 | E8: =IFERROR(VLOOKUP($D8,BS별도,MATCH(E$1,BS별도H,0),0)/100,"") | F8: =IFERROR(VLOOKUP($D8,BS별도,MATCH(F$1,BS별도H,0),0)/100,"") | G8: =IFERROR(VLOOKUP($D8,BS별도,MATCH(G$1,BS별도H,0),0)/100,"") | I8: =IFERROR(VLOOKUP($D8,BS별도,MATCH(I$1,BS별도H,0),0)/100,"") | J8: =IFERROR(VLOOKUP($D8,BS별도,MATCH(J$1,BS별도H,0),0)/100,"") | K8: =IFERROR(VLOOKUP($D8,BS별도,MATCH(K$1,BS별도H,0),0)/100,"") | L8: =IFERROR(VLOOKUP($D8,BS연결,MATCH(L$1,BS연결H,0),0)/100,"") | M8: =SUM(I8:L8) | N8: =IFERROR(VLOOKUP($D8,BS연결,MATCH(N$1,BS연결H,0),0)/100,"") | O8: =IFERROR(VLOOKUP($D8,BS연결,MATCH(O$1,BS연결H,0),0)/100,"") | P8: =IFERROR(VLOOKUP($D8,BS연결,MATCH(P$1,BS연결H,0),0)/100,"") | Q8: =IFERROR(VLOOKUP($D8,BS연결,MATCH(Q$1,BS연결H,0),0)/100,"") | R8: =IFERROR(VLOOKUP($D8,BS연결,MATCH(R$1,BS연결H,0),0)/100,"") | S8: =IFERROR(VLOOKUP($D8,BS연결,MATCH(S$1,BS연결H,0),0)/100,"") | T8: =IFERROR(VLOOKUP($D8,BS연결,MATCH(T$1,BS연결H,0),0)/100,"") | U8: =IFERROR(VLOOKUP($D8,BS연결,MATCH(U$1,BS연결H,0),0)/100,"") | ... Y8: =IFERROR(VLOOKUP($D8,BS연결,MATCH(Y$1,BS연결H,0),0)/100,"") | Z8: =IFERROR(Z5*변수!Z22,"") | AA8: =IFERROR(AA5*변수!AA22,"") | AB8: =SUM(X8:AA8) | AC8: =IFERROR(AC5*변수!AC22,"") | AD8: =IFERROR(AD5*변수!AD22,"") | AE8: =IFERROR(AE5*변수!AE22,"") | AF8: =IFERROR(AF5*변수!AF22,"") | AG8: =SUM(AC8:AF8) | AH8: =IFERROR(AH5*변수!AH22,"") | AI8: =IFERROR(AI5*변수!AI22,"") | AJ8: =IFERROR(AJ5*변수!AJ22,"") | AK8: =IFERROR(AK5*변수!AK22,"") | AL8: =SUM(AH8:AK8)
A9: 영업이익 | B9: 손익 | C9: 억원 | D9: 영업이익 | E9: =IFERROR(VLOOKUP($D9,BS별도,MATCH(E$1,BS별도H,0),0)/100,"") | F9: =IFERROR(VLOOKUP($D9,BS별도,MATCH(F$1,BS별도H,0),0)/100,"") | G9: =IFERROR(VLOOKUP($D9,BS별도,MATCH(G$1,BS별도H,0),0)/100,"") | I9: =IFERROR(VLOOKUP($D9,BS별도,MATCH(I$1,BS별도H,0),0)/100,"") | J9: =IFERROR(VLOOKUP($D9,BS별도,MATCH(J$1,BS별도H,0),0)/100,"") | K9: =IFERROR(VLOOKUP($D9,BS별도,MATCH(K$1,BS별도H,0),0)/100,"") | L9: =IFERROR(VLOOKUP($D9,BS연결,MATCH(L$1,BS연결H,0),0)/100,"") | M9: =SUM(I9:L9) | N9: =IFERROR(VLOOKUP($D9,BS연결,MATCH(N$1,BS연결H,0),0)/100,"") | O9: =IFERROR(VLOOKUP($D9,BS연결,MATCH(O$1,BS연결H,0),0)/100,"") | P9: =IFERROR(VLOOKUP($D9,BS연결,MATCH(P$1,BS연결H,0),0)/100,"") | Q9: =IFERROR(VLOOKUP($D9,BS연결,MATCH(Q$1,BS연결H,0),0)/100,"") | R9: =IFERROR(VLOOKUP($D9,BS연결,MATCH(R$1,BS연결H,0),0)/100,"") | S9: =IFERROR(VLOOKUP($D9,BS연결,MATCH(S$1,BS연결H,0),0)/100,"") | T9: =IFERROR(VLOOKUP($D9,BS연결,MATCH(T$1,BS연결H,0),0)/100,"") | U9: =IFERROR(VLOOKUP($D9,BS연결,MATCH(U$1,BS연결H,0),0)/100,"") | ... Y9: =IFERROR(VLOOKUP($D9,BS연결,MATCH(Y$1,BS연결H,0),0)/100,"") | Z9: =IFERROR(Z5*변수!Z23,"") | AA9: =IFERROR(AA5*변수!AA23,"") | AB9: =SUM(X9:AA9) | AC9: =IFERROR(AC5*변수!AC23,"") | AD9: =IFERROR(AD5*변수!AD23,"") | AE9: =IFERROR(AE5*변수!AE23,"") | AF9: =IFERROR(AF5*변수!AF23,"") | AG9: =SUM(AC9:AF9) | AH9: =IFERROR(AH5*변수!AH23,"") | AI9: =IFERROR(AI5*변수!AI23,"") | AJ9: =IFERROR(AJ5*변수!AJ23,"") | AK9: =IFERROR(AK5*변수!AK23,"") | AL9: =SUM(AH9:AK9)
A10: OPM | B10: 손익 | C10: % | D10: 영업이익률 | E10: =IFERROR(E9/E5,"") | F10: =IFERROR(F9/F5,"") | G10: =IFERROR(G9/G5,"") | I10: =IFERROR(I9/I5,"") | J10: =IFERROR(J9/J5,"") | K10: =IFERROR(K9/K5,"") | L10: =IFERROR(L9/L5,"") | M10: =IFERROR(M9/M5,"") | N10: =IFERROR(N9/N5,"") | O10: =IFERROR(O9/O5,"") | P10: =IFERROR(P9/P5,"") | ... AL10: =IFERROR(AL9/AL5,"")
A11: 금융손익 | B11: 손익 | C11: 억원 | D11: 금융손익 | E11: =IFERROR(VLOOKUP($D11,BS별도,MATCH(E$1,BS별도H,0),0)/100,"") | F11: =IFERROR(VLOOKUP($D11,BS별도,MATCH(F$1,BS별도H,0),0)/100,"") | G11: =IFERROR(VLOOKUP($D11,BS별도,MATCH(G$1,BS별도H,0),0)/100,"") | I11: =IFERROR(VLOOKUP($D11,BS별도,MATCH(I$1,BS별도H,0),0)/100,"") | J11: =IFERROR(VLOOKUP($D11,BS별도,MATCH(J$1,BS별도H,0),0)/100,"") | K11: =IFERROR(VLOOKUP($D11,BS별도,MATCH(K$1,BS별도H,0),0)/100,"") | L11: =IFERROR(VLOOKUP($D11,BS연결,MATCH(L$1,BS연결H,0),0)/100,"") | M11: =SUM(I11:L11) | N11: =IFERROR(VLOOKUP($D11,BS연결,MATCH(N$1,BS연결H,0),0)/100,"") | O11: =IFERROR(VLOOKUP($D11,BS연결,MATCH(O$1,BS연결H,0),0)/100,"") | P11: =IFERROR(VLOOKUP($D11,BS연결,MATCH(P$1,BS연결H,0),0)/100,"") | Q11: =IFERROR(VLOOKUP($D11,BS연결,MATCH(Q$1,BS연결H,0),0)/100,"") | R11: =IFERROR(VLOOKUP($D11,BS연결,MATCH(R$1,BS연결H,0),0)/100,"") | S11: =IFERROR(VLOOKUP($D11,BS연결,MATCH(S$1,BS연결H,0),0)/100,"") | T11: =IFERROR(VLOOKUP($D11,BS연결,MATCH(T$1,BS연결H,0),0)/100,"") | U11: =IFERROR(VLOOKUP($D11,BS연결,MATCH(U$1,BS연결H,0),0)/100,"") | ... Y11: =IFERROR(VLOOKUP($D11,BS연결,MATCH(Y$1,BS연결H,0),0)/100,"") | Z11: =IFERROR(Z12,"") | AA11: =IFERROR(AA12,"") | AB11: =SUM(X11:AA11) | AC11: =IFERROR(AC12,"") | AD11: =IFERROR(AD12,"") | AE11: =IFERROR(AE12,"") | AF11: =IFERROR(AF12,"") | AG11: =SUM(AC11:AF11) | AH11: =IFERROR(AH12,"") | AI11: =IFERROR(AI12,"") | AJ11: =IFERROR(AJ12,"") | AK11: =IFERROR(AK12,"") | AL11: =SUM(AH11:AK11)
A12: 이자손익 | B12: 손익 | C12: 억원 | D12: 이자손익 | E12: =IFERROR(VLOOKUP($D12,BS별도,MATCH(E$1,BS별도H,0),0)/100,"") | F12: =IFERROR(VLOOKUP($D12,BS별도,MATCH(F$1,BS별도H,0),0)/100,"") | G12: =IFERROR(VLOOKUP($D12,BS별도,MATCH(G$1,BS별도H,0),0)/100,"") | I12: =IFERROR(VLOOKUP($D12,BS별도,MATCH(I$1,BS별도H,0),0)/100,"") | J12: =IFERROR(VLOOKUP($D12,BS별도,MATCH(J$1,BS별도H,0),0)/100,"") | K12: =IFERROR(VLOOKUP($D12,BS별도,MATCH(K$1,BS별도H,0),0)/100,"") | L12: =IFERROR(VLOOKUP($D12,BS연결,MATCH(L$1,BS연결H,0),0)/100,"") | M12: =SUM(I12:L12) | N12: =IFERROR(VLOOKUP($D12,BS연결,MATCH(N$1,BS연결H,0),0)/100,"") | O12: =IFERROR(VLOOKUP($D12,BS연결,MATCH(O$1,BS연결H,0),0)/100,"") | P12: =IFERROR(VLOOKUP($D12,BS연결,MATCH(P$1,BS연결H,0),0)/100,"") | Q12: =IFERROR(VLOOKUP($D12,BS연결,MATCH(Q$1,BS연결H,0),0)/100,"") | R12: =IFERROR(VLOOKUP($D12,BS연결,MATCH(R$1,BS연결H,0),0)/100,"") | S12: =IFERROR(VLOOKUP($D12,BS연결,MATCH(S$1,BS연결H,0),0)/100,"") | W12: =SUM(S12:V12) | Z12: =IFERROR((Y26*변수!$D$50-Y24*변수!$D$51)/4,"") | AA12: =IFERROR((Z26*변수!$D$50-Z24*변수!$D$51)/4,"") | AB12: =SUM(X12:AA12) | AC12: =IFERROR((AA26*변수!$D$50-AA24*변수!$D$51)/4,"") | AD12: =IFERROR((AC26*변수!$D$50-AC24*변수!$D$51)/4,"") | AE12: =IFERROR((AD26*변수!$D$50-AD24*변수!$D$51)/4,"") | AF12: =IFERROR((AE26*변수!$D$50-AE24*변수!$D$51)/4,"") | AG12: =SUM(AC12:AF12) | AH12: =IFERROR((AF26*변수!$D$50-AF24*변수!$D$51)/4,"") | AI12: =IFERROR((AH26*변수!$D$50-AH24*변수!$D$51)/4,"") | AJ12: =IFERROR((AI26*변수!$D$50-AI24*변수!$D$51)/4,"") | AK12: =IFERROR((AJ26*변수!$D$50-AJ24*변수!$D$51)/4,"") | AL12: =SUM(AH12:AK12)
A13: 기타영업외손익 | B13: 손익 | C13: 억원 | D13: 기타영업외손익 | E13: =IFERROR(VLOOKUP($D13,BS별도,MATCH(E$1,BS별도H,0),0)/100,"") | F13: =IFERROR(VLOOKUP($D13,BS별도,MATCH(F$1,BS별도H,0),0)/100,"") | G13: =IFERROR(VLOOKUP($D13,BS별도,MATCH(G$1,BS별도H,0),0)/100,"") | I13: =IFERROR(VLOOKUP($D13,BS별도,MATCH(I$1,BS별도H,0),0)/100,"") | J13: =IFERROR(VLOOKUP($D13,BS별도,MATCH(J$1,BS별도H,0),0)/100,"") | K13: =IFERROR(VLOOKUP($D13,BS별도,MATCH(K$1,BS별도H,0),0)/100,"") | L13: =IFERROR(VLOOKUP($D13,BS연결,MATCH(L$1,BS연결H,0),0)/100,"") | M13: =SUM(I13:L13) | N13: =IFERROR(VLOOKUP($D13,BS연결,MATCH(N$1,BS연결H,0),0)/100,"") | O13: =IFERROR(VLOOKUP($D13,BS연결,MATCH(O$1,BS연결H,0),0)/100,"") | P13: =IFERROR(VLOOKUP($D13,BS연결,MATCH(P$1,BS연결H,0),0)/100,"") | Q13: =IFERROR(VLOOKUP($D13,BS연결,MATCH(Q$1,BS연결H,0),0)/100,"") | R13: =IFERROR(VLOOKUP($D13,BS연결,MATCH(R$1,BS연결H,0),0)/100,"") | S13: =IFERROR(VLOOKUP($D13,BS연결,MATCH(S$1,BS연결H,0),0)/100,"") | T13: =IFERROR(VLOOKUP($D13,BS연결,MATCH(T$1,BS연결H,0),0)/100,"") | U13: =IFERROR(VLOOKUP($D13,BS연결,MATCH(U$1,BS연결H,0),0)/100,"") | V13: =IFERROR(VLOOKUP($D13,BS연결,MATCH(V$1,BS연결H,0),0)/100,"") | W13: =SUM(S13:V13) | X13: =IFERROR(VLOOKUP($D13,BS연결,MATCH(X$1,BS연결H,0),0)/100,"") | Y13: =IFERROR(VLOOKUP($D13,BS연결,MATCH(Y$1,BS연결H,0),0)/100,"") | Z13: =변수!Z24 | AA13: =변수!AA24 | AB13: =SUM(X13:AA13) | AC13: =변수!AC24 | AD13: =변수!AD24 | AE13: =변수!AE24 | AF13: =변수!AF24 | AG13: =SUM(AC13:AF13) | AH13: =변수!AH24 | AI13: =변수!AI24 | AJ13: =변수!AJ24 | AK13: =변수!AK24 | AL13: =SUM(AH13:AK13)
A14: 세전이익 | B14: 손익 | C14: 억원 | D14: 법인세비용차감전계속사업이익 | E14: =IFERROR(VLOOKUP($D14,BS별도,MATCH(E$1,BS별도H,0),0)/100,"") | F14: =IFERROR(VLOOKUP($D14,BS별도,MATCH(F$1,BS별도H,0),0)/100,"") | G14: =IFERROR(VLOOKUP($D14,BS별도,MATCH(G$1,BS별도H,0),0)/100,"") | I14: =IFERROR(VLOOKUP($D14,BS별도,MATCH(I$1,BS별도H,0),0)/100,"") | J14: =IFERROR(VLOOKUP($D14,BS별도,MATCH(J$1,BS별도H,0),0)/100,"") | K14: =IFERROR(VLOOKUP($D14,BS별도,MATCH(K$1,BS별도H,0),0)/100,"") | L14: =IFERROR(VLOOKUP($D14,BS연결,MATCH(L$1,BS연결H,0),0)/100,"") | M14: =SUM(I14:L14) | N14: =IFERROR(VLOOKUP($D14,BS연결,MATCH(N$1,BS연결H,0),0)/100,"") | O14: =IFERROR(VLOOKUP($D14,BS연결,MATCH(O$1,BS연결H,0),0)/100,"") | P14: =IFERROR(VLOOKUP($D14,BS연결,MATCH(P$1,BS연결H,0),0)/100,"") | Q14: =IFERROR(VLOOKUP($D14,BS연결,MATCH(Q$1,BS연결H,0),0)/100,"") | R14: =IFERROR(VLOOKUP($D14,BS연결,MATCH(R$1,BS연결H,0),0)/100,"") | S14: =IFERROR(VLOOKUP($D14,BS연결,MATCH(S$1,BS연결H,0),0)/100,"") | T14: =IFERROR(VLOOKUP($D14,BS연결,MATCH(T$1,BS연결H,0),0)/100,"") | U14: =IFERROR(VLOOKUP($D14,BS연결,MATCH(U$1,BS연결H,0),0)/100,"") | ... Y14: =IFERROR(VLOOKUP($D14,BS연결,MATCH(Y$1,BS연결H,0),0)/100,"") | Z14: =IFERROR(Z9+Z11+Z13,"") | AA14: =IFERROR(AA9+AA11+AA13,"") | AB14: =SUM(X14:AA14) | AC14: =IFERROR(AC9+AC11+AC13,"") | AD14: =IFERROR(AD9+AD11+AD13,"") | AE14: =IFERROR(AE9+AE11+AE13,"") | AF14: =IFERROR(AF9+AF11+AF13,"") | AG14: =SUM(AC14:AF14) | AH14: =IFERROR(AH9+AH11+AH13,"") | AI14: =IFERROR(AI9+AI11+AI13,"") | AJ14: =IFERROR(AJ9+AJ11+AJ13,"") | AK14: =IFERROR(AK9+AK11+AK13,"") | AL14: =SUM(AH14:AK14)
A15: 법인세비용 | B15: 손익 | C15: 억원 | D15: 법인세비용 | E15: =IFERROR(VLOOKUP($D15,BS별도,MATCH(E$1,BS별도H,0),0)/100,"") | F15: =IFERROR(VLOOKUP($D15,BS별도,MATCH(F$1,BS별도H,0),0)/100,"") | G15: =IFERROR(VLOOKUP($D15,BS별도,MATCH(G$1,BS별도H,0),0)/100,"") | I15: =IFERROR(VLOOKUP($D15,BS별도,MATCH(I$1,BS별도H,0),0)/100,"") | J15: =IFERROR(VLOOKUP($D15,BS별도,MATCH(J$1,BS별도H,0),0)/100,"") | K15: =IFERROR(VLOOKUP($D15,BS별도,MATCH(K$1,BS별도H,0),0)/100,"") | L15: =IFERROR(VLOOKUP($D15,BS연결,MATCH(L$1,BS연결H,0),0)/100,"") | M15: =SUM(I15:L15) | N15: =IFERROR(VLOOKUP($D15,BS연결,MATCH(N$1,BS연결H,0),0)/100,"") | O15: =IFERROR(VLOOKUP($D15,BS연결,MATCH(O$1,BS연결H,0),0)/100,"") | P15: =IFERROR(VLOOKUP($D15,BS연결,MATCH(P$1,BS연결H,0),0)/100,"") | Q15: =IFERROR(VLOOKUP($D15,BS연결,MATCH(Q$1,BS연결H,0),0)/100,"") | R15: =IFERROR(VLOOKUP($D15,BS연결,MATCH(R$1,BS연결H,0),0)/100,"") | S15: =IFERROR(VLOOKUP($D15,BS연결,MATCH(S$1,BS연결H,0),0)/100,"") | T15: =IFERROR(VLOOKUP($D15,BS연결,MATCH(T$1,BS연결H,0),0)/100,"") | U15: =IFERROR(VLOOKUP($D15,BS연결,MATCH(U$1,BS연결H,0),0)/100,"") | ... Y15: =IFERROR(VLOOKUP($D15,BS연결,MATCH(Y$1,BS연결H,0),0)/100,"") | Z15: =IFERROR(Z14*변수!Z25,"") | AA15: =IFERROR(AA14*변수!AA25,"") | AB15: =SUM(X15:AA15) | AC15: =IFERROR(AC14*변수!AC25,"") | AD15: =IFERROR(AD14*변수!AD25,"") | AE15: =IFERROR(AE14*변수!AE25,"") | AF15: =IFERROR(AF14*변수!AF25,"") | AG15: =SUM(AC15:AF15) | AH15: =IFERROR(AH14*변수!AH25,"") | AI15: =IFERROR(AI14*변수!AI25,"") | AJ15: =IFERROR(AJ14*변수!AJ25,"") | AK15: =IFERROR(AK14*변수!AK25,"") | AL15: =SUM(AH15:AK15)
