Workbook
Name 변수H: 변수!$C$1:$W$1
Name 환율: 변수!$C$6:$W$13
Name BS연결H: BS연결!$C$1:$W$1
Name BS연결: BS연결!$C$5:$W$96
Name BS별도H: BS별도!$C$1:$W$1
Name BS별도: BS별도!$C$5:$W$84
Name SUBQH: subQ!$A$1:$W$1
Name subQ: subQ!$A$5:$W$47
Name SLS_H: SLS!$A$1:$AA$1

Sheet README
A1: 대한조선(439260) 실적 모델 — ARGUS 한국조선
A2: 기준 분기 2026Q2 · 마지막 실적 2026Q2 · 생성 2026-10-14
A3: 모든 수치는 모델 산출값(DART 공개 재무제표 + 우리 추정)이다 — 목표주가·투자 추천 아님. 참고용 · 투자조언 아님.
A5: 시트
A6: 변수 가정 시계열. 환율 8행(ECB via frankfurter — L2 fx.json; 추정 분기 = 노란 가정), 추정 드라이버(노란 셀 = 모델값에서 역산한 가정, 바꾸면 재계산; 연녹 셀 = 3절 스칼라 참조 수식), 3절 스칼라 가정(세율·판관비율·지배주주비중·이자율·종가·PER 밴드·COE·외화 순노출·헤지비율)
A7: BS연결/BS별도 FnGuide 계정명 × 기간 값 덤프(백만원). 행1 분기라벨, 행4 YYYY.MM / YYYY.12A. 이름정의 BS연결H·BS연결(계정명 C열부터)
A8: subQ 분기 서브모델(억원 = 백만원/100). 확정 행: =IFERROR(VLOOKUP($D행,BS연결,MATCH(E$1,BS연결H,0),0)/100,"") 추정 행: 변수 시트 가정 셀 참조 수식. 외환손익·파생상품손익은 BS 계정 합·차, 기타금융손익은 잔차, OPM·EPS·BPS·PER·PBR 은 파생 수식
A9: SLS 선표(조선사만, sls json 있을 때): 요약 행(sls 저장값) + 계약별 스케줄(백만$) × (헤지비율 × 헤지환율 + (1−헤지비율) × 건조시점 환율[변수 원/달러(평균)]) → 원화 수식 블록 → 합계 행이 subQ 매출조선에 연결
A10: 시나리오 신규수주 보수/기준/낙관(forecast_panel 패널, 모델에 scenarios 가 있을 때만): 매출액·영업이익 = subQ 기준값 ± (시나리오 신규 − base 신규) × OPM. base 만 subQ 행에 포함, 나머지는 합산 안 함
A11: 분기/연간예상 subQ 를 이름(A열 key)으로 VLOOKUP 한 보고서 표(억원)
A12: TP PER 밴드 × 12M fwd EPS, PBR = ROE/COE × BPS — 모델 산출값 구간, 목표주가·추천 아님
A13: 외화 환율 QoQ, 외화 순노출 × Δ기말환율 → 환관련손익 추정
... A36: 백테스트: {"freeze": "2025Q2", "horizon": 4, "revenue_wape_pct": 11.4, "op_wape_pct": 26.4, "n": 4, "note": "단일 회사 4분기 — 통계 아님", "driver_at_freeze": "trend_seasonal", "selection_oos_at_freeze": null, "frozen_inputs": "fin(연결/별도)·고객 조선사 모델·지주 자회사 모델은 2025Q2 까지의 분기만; 선표는 체결일 ≤ 2025Q2 말일 계약(원장 최신 금액·코호트 등급, 환산 없음); 잔고는 yards_cache 2025Q2; 시세·환율 forward·prices·forecast_panel 신규수주 미사용. 고객 가중치(suppliers.json 언급 비중)와 합병 체인링크는 현재 지식; 고객 연동 채택은 동결 모델 안에서도 자기 la−4분기 OOS 규칙(selection_oos_at_freeze)", "detail": [{"q": "2025Q3", "rev_pred": 2960.48, "rev_act": 2739.73, "op_pred": 624.67, "op_act": 664.89}, {"q": "2025Q4", "rev_pred": 2960.48, "rev_act": 3504.05, "op_pred": 624.67, "op_act": 953.29}, {"q": "2026Q1", "rev_pred": 2960.48, "rev_act": 3082.71, "op_pred": 624.67, "op_act": 826.39}, {"q": "2026Q2", "rev_pred": 2960.48, "rev_act": 3544.35, "op_pred": 624.67, "op_act": 952.49}]}

Sheet 변수
C1: 이름: 변수H | E1: 2Q25 | F1: 3Q25 | G1: 4Q25 | H1: 2025 | I1: 1Q26 | J1: 2Q26 | K1: 3Q26 | L1: 4Q26 | M1: 2026 | N1: 1Q27 | O1: 2Q27 | P1: 3Q27 | Q1: 4Q27 | R1: 2027 | S1: 1Q28 | T1: 2Q28 | U1: 3Q28 | V1: 4Q28 | W1: 2028
A2: 가정 시계열 — 노란 셀은 추정 가정(모델값에서 역산), 연녹 셀은 3절 스칼라 참조 수식. 바꾸면 subQ·분기·연간예상·TP·시나리오가 재계산됩니다.
E3: 1 | F3: 2 | G3: 3 | H3: 4 | I3: 5 | J3: 6 | K3: 7 | L3: 8 | M3: 9 | N3: 10 | O3: 11 | P3: 12 | Q3: 13 | R3: 14 | S3: 15 | T3: 16 | U3: 17 | V3: 18 | W3: 19
E4: 2025.06 | F4: 2025.09 | G4: 2025.12 | H4: 2025.12A | I4: 2026.03 | J4: 2026.06 | K4: 2026.09 | L4: 2026.12 | M4: 2026.12A | N4: 2027.03 | O4: 2027.06 | P4: 2027.09 | Q4: 2027.12 | R4: 2027.12A | S4: 2028.03 | T4: 2028.06 | U4: 2028.09 | V4: 2028.12 | W4: 2028.12A
B5: 1. FX | C5: 이름: 환율
A6: USDKRW_avg | C6: 원/달러(평균) | E6: 1398.52 | F6: 1386.95 | G6: 1449.19 | H6: 1421.52 | I6: 1466.12 | J6: 1501.75 | K6: 1418.75 | L6: 1343.39 | M6: 1456.01 | N6: 1341.45 | O6: 1341.45 | P6: 1341.45 | Q6: 1341.45 | S6: 1341.45 | T6: 1341.45 | U6: 1341.45 | V6: 1341.45
A7: USDKRW_end | C7: 원/달러(기말) | E7: 1355.13 | F7: 1403.67 | G7: 1444.2 | H7: 1444.2 | I7: 1524.8 | J7: 1550.89 | K7: 1355.4 | L7: 1341.45 | M7: 1341.45 | N7: 1341.45 | O7: 1341.45 | P7: 1341.45 | Q7: 1341.45 | S7: 1341.45 | T7: 1341.45 | U7: 1341.45 | V7: 1341.45
A8: JPY100KRW_avg | C8: 원/100Y(평균) | E8: 967.92 | F8: 940.32 | G8: 940.77 | H8: 950.17 | I8: 934.39 | J8: 942.16 | K8: 890.41 | L8: 849.39 | M8: 918.46 | N8: 848.37 | O8: 848.37 | P8: 848.37 | Q8: 848.37 | S8: 848.37 | T8: 848.37 | U8: 848.37 | V8: 848.37
A9: JPY100KRW_end | C9: 원/100Y(기말) | E9: 938.85 | F9: 948.49 | G9: 921.81 | H9: 921.81 | I9: 955.99 | J9: 954.75 | K9: 863.31 | L9: 848.37 | M9: 848.37 | N9: 848.37 | O9: 848.37 | P9: 848.37 | Q9: 848.37 | S9: 848.37 | T9: 848.37 | U9: 848.37 | V9: 848.37
A10: EURKRW_avg | C10: W/Euro(평균) | E10: 1585.13 | F10: 1620.04 | G10: 1686.02 | H10: 1605.45 | I10: 1715.47 | J10: 1746.09 | K10: 1631.97 | L10: 1506.62 | M10: 1688.01 | N10: 1500.82 | O10: 1500.82 | P10: 1500.82 | Q10: 1500.82 | S10: 1500.82 | T10: 1500.82 | U10: 1500.82 | V10: 1500.82
A11: EURKRW_end | C11: W/Euro(기말) | E11: 1588.22 | F11: 1648.04 | G11: 1696.94 | H11: 1696.94 | I11: 1753.21 | J11: 1767.09 | K11: 1539.06 | L11: 1500.82 | M11: 1500.82 | N11: 1500.82 | O11: 1500.82 | P11: 1500.82 | Q11: 1500.82 | S11: 1500.82 | T11: 1500.82 | U11: 1500.82 | V11: 1500.82
A12: CNYKRW_avg | C12: 원/중국원(평균) | E12: 193.41 | F12: 193.79 | G12: 204.38 | H12: 197.8 | I12: 211.75 | J12: 220.8 | K12: 210.43 | L12: 200.49 | M12: 213.61 | N12: 200.4 | O12: 200.4 | P12: 200.4 | Q12: 200.4 | S12: 200.4 | T12: 200.4 | U12: 200.4 | V12: 200.4
A13: CNYKRW_end | C13: 원/중국원(기말) | E13: 189.14 | F13: 197.16 | G13: 206.28 | H13: 206.28 | I13: 220.97 | J13: 228.56 | K13: 202.16 | L13: 200.4 | M13: 200.4 | N13: 200.4 | O13: 200.4 | P13: 200.4 | Q13: 200.4 | S13: 200.4 | T13: 200.4 | U13: 200.4 | V13: 200.4
B14: 1b. 종가
A15: price_close_end | C15: 종가(기말) | F15: 80900 | G15: 67000 | I15: 85700 | J15: 52000 | K15: 45700 | L15: 41900
A16: price_high | C16: 종가(최고) | F16: 116000 | G16: 82500 | I16: 109700 | J16: 97600 | K16: 57500 | L16: 48350
A17: price_low | C17: 종가(최저) | F17: 77500 | G17: 57300 | I17: 64400 | J17: 48800 | K17: 42100 | L17: 39950
A18: price_avg | C18: 종가(평균) | F18: 86250 | G18: 71403.4 | I18: 81345.8 | J18: 74616.4 | K18: 48174.2 | L18: 44643.8
B20: 2. 추정 드라이버 | C20: 실적 열 = subQ 실현값(수식), 추정 열 = 가정(노란 = 모델값 역산, 연녹 = 3절 스칼라 참조)
A21: drv:판관비 | B21: ratio | C21: 판관비율(/매출) | E21: =IFERROR(subQ!E8/subQ!E5,"") | F21: =IFERROR(subQ!F8/subQ!F5,"") | G21: =IFERROR(subQ!G8/subQ!G5,"") | H21: =IFERROR(subQ!H8/subQ!H5,"") | I21: =IFERROR(subQ!I8/subQ!I5,"") | J21: =IFERROR(subQ!J8/subQ!J5,"") | K21: =$D$54 | L21: =$D$54 | M21: =IFERROR(subQ!M8/subQ!M5,"") | N21: =$D$54 | O21: =$D$54 | P21: =$D$54 | Q21: =$D$54 | R21: =IFERROR(subQ!R8/subQ!R5,"") | S21: =$D$54 | T21: =$D$54 | U21: =$D$54 | V21: =$D$54 | W21: =IFERROR(subQ!W8/subQ!W5,"")
A22: drv:외환손익 | B22: abs | C22: 외환손익 (가정, 억원) | E22: =subQ!E13 | F22: =subQ!F13 | G22: =subQ!G13 | H22: =subQ!H13 | I22: =subQ!I13 | J22: =subQ!J13 | K22: 0 | L22: 0 | M22: =subQ!M13 | N22: 0 | O22: 0 | P22: 0 | Q22: 0 | R22: =subQ!R13 | S22: 0 | T22: 0 | U22: 0 | V22: 0 | W22: =subQ!W13
A23: drv:파생상품손익 | B23: abs | C23: 파생상품손익 (가정, 억원) | E23: =subQ!E14 | F23: =subQ!F14 | G23: =subQ!G14 | H23: =subQ!H14 | I23: =subQ!I14 | J23: =subQ!J14 | K23: 0 | L23: 0 | M23: =subQ!M14 | N23: 0 | O23: 0 | P23: 0 | Q23: 0 | R23: =subQ!R14 | S23: 0 | T23: 0 | U23: 0 | V23: 0 | W23: =subQ!W14
A24: drv:기타금융손익 | B24: abs | C24: 기타금융손익 (가정, 억원) | E24: =subQ!E15 | F24: =subQ!F15 | G24: =subQ!G15 | H24: =subQ!H15 | I24: =subQ!I15 | J24: =subQ!J15 | K24: 0 | L24: 0 | M24: =subQ!M15 | N24: 0 | O24: 0 | P24: 0 | Q24: 0 | R24: =subQ!R15 | S24: 0 | T24: 0 | U24: 0 | V24: 0 | W24: =subQ!W15
A25: drv:기타영업외손익 | B25: abs | C25: 기타영업외손익 (가정, 억원) | E25: =subQ!E16 | F25: =subQ!F16 | G25: =subQ!G16 | H25: =subQ!H16 | I25: =subQ!I16 | J25: =subQ!J16 | K25: 0 | L25: 0 | M25: =subQ!M16 | N25: 0 | O25: 0 | P25: 0 | Q25: 0 | R25: =subQ!R16 | S25: 0 | T25: 0 | U25: 0 | V25: 0 | W25: =subQ!W16
A26: drv:법인세비용 | B26: tax | C26: 법인세율(/세전) — 법인세 = MAX(세전,0) × 세율 | E26: =IFERROR(subQ!E19/subQ!E18,"") | F26: =IFERROR(subQ!F19/subQ!F18,"") | G26: =IFERROR(subQ!G19/subQ!G18,"") | H26: =IFERROR(subQ!H19/subQ!H18,"") | I26: =IFERROR(subQ!I19/subQ!I18,"") | J26: =IFERROR(subQ!J19/subQ!J18,"") | K26: =$D$53 | L26: =$D$53 | M26: =IFERROR(subQ!M19/subQ!M18,"") | N26: =$D$53 | O26: =$D$53 | P26: =$D$53 | Q26: =$D$53 | R26: =IFERROR(subQ!R19/subQ!R18,"") | S26: =$D$53 | T26: =$D$53 | U26: =$D$53 | V26: =$D$53 | W26: =IFERROR(subQ!W19/subQ!W18,"")
A27: drv:지배주주순이익 | B27: ratio | C27: 지배주주 비중(/당기순이익) | E27: =IFERROR(subQ!E21/subQ!E20,"") | F27: =IFERROR(subQ!F21/subQ!F20,"") | G27: =IFERROR(subQ!G21/subQ!G20,"") | H27: =IFERROR(subQ!H21/subQ!H20,"") | I27: =IFERROR(subQ!I21/subQ!I20,"") | J27: =IFERROR(subQ!J21/subQ!J20,"") | K27: =$D$55 | L27: =$D$55 | M27: =IFERROR(subQ!M21/subQ!M20,"") | N27: =$D$55 | O27: =$D$55 | P27: =$D$55 | Q27: =$D$55 | R27: =IFERROR(subQ!R21/subQ!R20,"") | S27: =$D$55 | T27: =$D$55 | U27: =$D$55 | V27: =$D$55 | W27: =IFERROR(subQ!W21/subQ!W20,"")
A28: drv:부채총계 | B28: qoq | C28: 부채총계 QoQ | F28: =IFERROR(subQ!F23/subQ!E23-1,"") | G28: =IFERROR(subQ!G23/subQ!F23-1,"") | I28: =IFERROR(subQ!I23/subQ!G23-1,"") | J28: =IFERROR(subQ!J23/subQ!I23-1,"") | K28: 7.8e-07 | L28: 0 | N28: 0 | O28: 0 | P28: 0 | Q28: 0 | S28: 0 | T28: 0 | U28: 0 | V28: 0
A29: drv:자본총계 | B29: roll | C29: 자본총계 기타변동(배당 등, 억원) | F29: =IFERROR(subQ!E24+subQ!F20-subQ!F24,"") | G29: =IFERROR(subQ!F24+subQ!G20-subQ!G24,"") | I29: =IFERROR(subQ!G24+subQ!I20-subQ!I24,"") | J29: =IFERROR(subQ!I24+subQ!J20-subQ!J24,"") | K29: -0.005789965 | L29: 0.001223934 | N29: -0.002919616 | O29: 95.22518 | P29: 0.000648981 | Q29: -0.005272189 | S29: 0.000109623 | T29: 95.227296 | U29: 0.000554141 | V29: -0.002287123
A30: drv:지배주주지분 | B30: roll | C30: 지배주주지분 기타변동(배당 등, 억원) | F30: =IFERROR(subQ!E25+subQ!F21-subQ!F25,"") | G30: =IFERROR(subQ!F25+subQ!G21-subQ!G25,"") | I30: =IFERROR(subQ!G25+subQ!I21-subQ!I25,"") | J30: =IFERROR(subQ!I25+subQ!J21-subQ!J25,"") | K30: -0.005789965 | L30: 0.001223934 | N30: -0.002919616 | O30: 95.22518 | P30: 0.000648981 | Q30: -0.005272189 | S30: 0.000109623 | T30: 95.227296 | U30: 0.000554141 | V30: -0.002287123
A31: drv:총차입금 | B31: qoq | C31: 총차입금 QoQ | F31: =IFERROR(subQ!F26/subQ!E26-1,"") | G31: =IFERROR(subQ!G26/subQ!F26-1,"") | I31: =IFERROR(subQ!I26/subQ!G26-1,"") | J31: =IFERROR(subQ!J26/subQ!I26-1,"")
A32: drv:순차입금 | B32: qoq | C32: 순차입금 QoQ | F32: =IFERROR(subQ!F27/subQ!E27-1,"") | G32: =IFERROR(subQ!G27/subQ!F27-1,"") | I32: =IFERROR(subQ!I27/subQ!G27-1,"") | J32: =IFERROR(subQ!J27/subQ!I27-1,"")
A33: drv:이자발생자산 | B33: qoq | C33: 이자발생자산 QoQ | F33: =IFERROR(subQ!F28/subQ!E28-1,"") | G33: =IFERROR(subQ!G28/subQ!F28-1,"") | I33: =IFERROR(subQ!I28/subQ!G28-1,"") | J33: =IFERROR(subQ!J28/subQ!I28-1,"") | K33: 0.10480713 | L33: 0.095726125 | N33: 0.089567306 | O33: 0.077948214 | P33: 0.090301064 | Q33: 0.08557965 | S33: 0.085357585 | T33: 0.079730858 | U33: 0.086985744 | V33: 0.081033033
A34: drv:현금및현금성자산 | B34: qoq | C34: 현금및현금성자산 QoQ | F34: =IFERROR(subQ!F29/subQ!E29-1,"") | G34: =IFERROR(subQ!G29/subQ!F29-1,"") | I34: =IFERROR(subQ!I29/subQ!G29-1,"") | J34: =IFERROR(subQ!J29/subQ!I29-1,"")
A35: drv:CAPEX | B35: yoy | C35: CAPEX YoY | J35: =IFERROR(subQ!J30/subQ!E30-1,"") | K35: -0.20220675 | L35: 0.35951662 | N35: 0.34013311 | O35: -0.61045911 | P35: 0 | Q35: 0 | S35: 0 | T35: 0 | U35: 0 | V35: 0
A36: drv:영업활동현금흐름 | B36: yoy | C36: 영업활동현금흐름 YoY | J36: =IFERROR(subQ!J31/subQ!E31-1,"")
A37: drv:주식수 | B37: qoq | C37: 주식수 QoQ | F37: =IFERROR(subQ!F32/subQ!E32-1,"") | G37: =IFERROR(subQ!G32/subQ!F32-1,"") | I37: =IFERROR(subQ!I32/subQ!G32-1,"") | J37: =IFERROR(subQ!J32/subQ!I32-1,"") | K37: 0 | L37: 0 | N37: 0 | O37: 0 | P37: 0 | Q37: 0 | S37: 0 | T37: 0 | U37: 0 | V37: 0
A38: drv:DPS | B38: abs | C38: DPS (가정, 원) | E38: =subQ!E35 | F38: =subQ!F35 | G38: =subQ!G35 | H38: =subQ!H35 | I38: =subQ!I35 | J38: =subQ!J35 | L38: 250 | M38: =subQ!M35 | Q38: 250 | R38: =subQ!R35 | V38: 250 | W38: =subQ!W35
A39: drv:매출조선 | B39: sls_link | C39: 원장 밖 잔고 소진(억원) — 매출조선 = SLS 원화/100 + 이 행 + 매출조선신규 | F39: =IFERROR(subQ!F38-SLS!E62/100,"") | G39: =IFERROR(subQ!G38-SLS!F62/100,"") | I39: =IFERROR(subQ!I38-SLS!G62/100,"") | J39: =IFERROR(subQ!J38-SLS!H62/100,"") | K39: 148.90116 | L39: 195.37663 | N39: 191.06623 | O39: 193.2195 | P39: 195.31848 | Q39: 195.29925 | S39: 193.20929 | T39: 193.19711 | U39: 195.287 | V39: 195.28866
A40: drv:매출조선신규 | B40: abs | C40: 매출조선신규 (forecast_panel base · 공시 상계 신규수주 매출, 억원 — 가정) | E40: =subQ!E39 | F40: =subQ!F39 | G40: =subQ!G39 | H40: =subQ!H39 | I40: =subQ!I39 | J40: =subQ!J39 | K40: 0 | L40: 24.58 | M40: =subQ!M39 | N40: 149.36 | O40: 408.45 | P40: 772.01 | Q40: 1210.15 | R40: =subQ!R39 | S40: 1693.02 | T40: 2190.75 | U40: 2673.48 | V40: 3111.34 | W40: =subQ!W39
A41: drv:OP조선 | B41: ratio | C41: OP조선 마진(/매출조선) | E41: =IFERROR(subQ!E40/subQ!E38,"") | F41: =IFERROR(subQ!F40/subQ!F38,"") | G41: =IFERROR(subQ!G40/subQ!G38,"") | H41: =IFERROR(subQ!H40/subQ!H38,"") | I41: =IFERROR(subQ!I40/subQ!I38,"") | J41: =IFERROR(subQ!J40/subQ!J38,"") | K41: 0.26840165 | L41: 0.26840233 | M41: =IFERROR(subQ!M40/subQ!M38,"") | N41: 0.26840382 | O41: 0.26840322 | P41: 0.2684036 | Q41: 0.26840155 | R41: =IFERROR(subQ!R40/subQ!R38,"") | S41: 0.26840412 | T41: 0.26840347 | U41: 0.26840277 | V41: 0.26840304 | W41: =IFERROR(subQ!W40/subQ!W38,"")
...

Sheet BS연결
B1: (백만원) | C1: 이름: BS연결H | E1: 2Q25 | F1: 3Q25 | G1: 4Q25 | H1: 2025 | I1: 1Q26 | J1: 2Q26 | K1: 3Q26 | L1: 4Q26 | M1: 2026 | N1: 1Q27 | O1: 2Q27 | P1: 3Q27 | Q1: 4Q27 | R1: 2027 | S1: 1Q28 | T1: 2Q28 | U1: 3Q28 | V1: 4Q28 | W1: 2028
B2: 연결 | D2: fin json(kship_fin.py)
B3: 대한조선(연) | C3: UPDATE: 26-10-14 | E3: 1 | F3: 2 | G3: 3 | H3: 4 | I3: 5 | J3: 6 | K3: 7 | L3: 8 | M3: 9 | N3: 10 | O3: 11 | P3: 12 | Q3: 13 | R3: 14 | S3: 15 | T3: 16 | U3: 17 | V3: 18 | W3: 19
B4: Account Code | C4: AccountNAME | E4: 2025.06 | F4: 2025.09 | G4: 2025.12 | H4: 2025.12A | I4: 2026.03 | J4: 2026.06 | K4: 2026.09 | L4: 2026.12 | M4: 2026.12A | N4: 2027.03 | O4: 2027.06 | P4: 2027.09 | Q4: 2027.12 | R4: 2027.12A | S4: 2028.03 | T4: 2028.06 | U4: 2028.09 | V4: 2028.12 | W4: 2028.12A
A5: 1 | C5: 유동자산 | E5: 827551.81 | F5: 1049562.5 | G5: 1123261.9 | H5: 1123261.9 | I5: 1218967.1 | J5: 1197597.3
A6: 1 | C6: 현금및현금성자산 | E6: 376409.64 | F6: 296925.16 | G6: 215303.78 | H6: 215303.78 | I6: 290133.13 | J6: 325886.41
A7: 1 | C7: 단기금융상품 | E7: 1488.5 | G7: 12899.49 | H7: 12899.49 | I7: 72277.51 | J7: 108767.29
A8: 1 | C8: 단기금융자산 | E8: 1488.5 | G8: 12899.49 | H8: 12899.49 | I8: 72277.51 | J8: 108767.29
A9: 1 | C9: 매출채권및기타채권 | E9: 77272.88 | F9: 85223.92 | G9: 102458.4 | H9: 102458.4 | I9: 93121.98 | J9: 101413.78
A10: 1 | C10: 계약자산 | E10: 265910.36 | F10: 265726.2 | G10: 376052.97 | H10: 376052.97 | I10: 355960.68 | J10: 311813.71
A11: 1 | C11: 재고자산 | E11: 23812.21 | F11: 34357.59 | G11: 35906.45 | H11: 35906.45 | I11: 54649.14 | J11: 36216.55
A12: 1 | C12: 기타유동자산 | E12: 73659.28 | F12: 73463.28 | G12: 72357.36 | H12: 72357.36 | I12: 70491.15 | J12: 74134.28
A13: 1 | C13: 당기법인세자산(선급법인세) | E13: 634.69 | F13: 2923.65 | G13: 0.02 | H13: 0.02 | I13: 0
A14: 1 | C14: 비유동자산 | E14: 385560.42 | F14: 379621.13 | G14: 414791.45 | H14: 414791.45 | I14: 424772.01 | J14: 565065.39
A15: 1 | C15: 투자부동산 | E15: 913.14 | F15: 901.38 | G15: 889.62 | H15: 889.62 | I15: 877.86 | J15: 866.11
A16: 1 | C16: 유형자산 | E16: 353138.77 | F16: 353958.01 | G16: 353759.76 | H16: 353759.76 | I16: 349024.77 | J16: 354783.81
A17: 1 | C17: 무형자산 | E17: 1361.16 | F17: 1332.41 | G17: 1462.83 | H17: 1462.83 | I17: 5710.78 | J17: 5468.79
A18: 1 | C18: 사용권자산 | E18: 457.83 | F18: 400.84 | G18: 333.21 | H18: 333.21 | I18: 279.77 | J18: 246.64
A19: 1 | C19: 기타비유동자산 | E19: 457.83 | F19: 400.84 | G19: 13017.91 | H19: 13017.91 | I19: 13516.28 | J19: 26437.34
A20: 1 | C20: 장기매출채권및기타채권 | E20: 7702.32 | F20: 7672.17 | G20: 7376.09 | H20: 7376.09 | I20: 7377.29 | J20: 8006.54
A21: 1 | C21: 이연법인세자산 | E21: 13160.88
A22: 1 | C22: 자산총계 | E22: 1213112.2 | F22: 1429183.6 | G22: 1538053.4 | H22: 1538053.4 | I22: 1643739.1 | J22: 1762662.7
A23: 1 | C23: 유동부채 | E23: 630345.17 | F23: 376126.54 | G23: 410566.45 | H23: 410566.45 | I23: 462209.34 | J23: 512495.74
A24: 1 | C24: 매입채무및기타채무 | E24: 103892.27 | F24: 94836.7 | G24: 127630.93 | H24: 127630.93 | I24: 132017.33 | J24: 130803.16
A25: 1 | C25: 단기차입금 | E25: 187365.85 | F25: 23739.99
A26: 1 | C26: 단기사채 | E26: 20989.41
A27: 1 | C27: 유동성장기부채 | E27: 20000
A28: 1 | C28: 계약부채 | E28: 280517.02 | F28: 230107.11 | G28: 215414.72 | H28: 215414.72 | I28: 210986.68 | J28: 261230.99
A29: 1 | C29: 단기충당부채 | E29: 2975.68 | F29: 2272.59 | G29: 2168.34 | H29: 2168.34 | I29: 2318.93 | J29: 2385.39
A30: 1 | C30: 당기법인세부채(미지급법인세) | E30: 0 | G30: 21598.7 | H30: 21598.7 | I30: 32589.33 | J30: 41733.34
A31: 1 | C31: 기타유동부채 | E31: 817.06 | F31: 647.97 | G31: 608.78 | H31: 608.78 | I31: 10300.6 | J31: 595.06
A32: 1 | C32: 비유동부채 | E32: 25089.73 | F32: 34667.36 | G32: 35102.86 | H32: 35102.86 | I32: 47243.89 | J32: 51304.83
A33: 1 | C33: 장기매입채무및기타채무 | E33: 3743.58 | F33: 4096.32 | G33: 4579.13 | H33: 4579.13 | I33: 4935.5 | J33: 5045.69
A34: 1 | C34: 확정급여부채 | E34: 12052.14 | F34: 12869.68 | G34: 8501.95 | H34: 8501.95 | I34: 9480.97 | J34: 7937.2
A35: 1 | C35: 장기충당부채 | E35: 271.02 | F35: 301.78 | G35: 363.1 | H35: 363.1 | I35: 355.88 | J35: 351.76
A36: 1 | C36: 부채총계 | E36: 655434.9 | F36: 410793.91 | G36: 445669.31 | H36: 445669.31 | I36: 509453.23 | J36: 563800.56
A37: 1 | C37: 지배주주지분 | E37: 557677.33 | F37: 1018389.7 | G37: 1092384.1 | H37: 1092384.1 | I37: 1134285.9 | J37: 1198862.2
A38: 1 | C38: 자본금 | E38: 152631.56 | F38: 192631.56 | G38: 192631.56 | H38: 192631.56 | I38: 192631.56 | J38: 192631.56
A39: 1 | C39: 자본잉여금 | E39: 47947.23 | F39: 402861.42 | G39: 398917.63 | H39: 398917.63 | I39: 398917.63 | J39: 398917.63
A40: 1 | C40: 기타포괄이익누계액 | E40: 40823.25 | F40: 40804.12 | G40: 40029.25 | H40: 40029.25 | I40: 40051.07 | J40: 40020.6
...

Sheet BS별도
B1: (백만원) | C1: 이름: BS별도H | E1: 2Q25 | F1: 3Q25 | G1: 4Q25 | H1: 2025 | I1: 1Q26 | J1: 2Q26 | K1: 3Q26 | L1: 4Q26 | M1: 2026 | N1: 1Q27 | O1: 2Q27 | P1: 3Q27 | Q1: 4Q27 | R1: 2027 | S1: 1Q28 | T1: 2Q28 | U1: 3Q28 | V1: 4Q28 | W1: 2028
B2: 별도 | D2: fin json(kship_fin.py)
B3: 대한조선(별) | C3: UPDATE: 26-10-14 | E3: 1 | F3: 2 | G3: 3 | H3: 4 | I3: 5 | J3: 6 | K3: 7 | L3: 8 | M3: 9 | N3: 10 | O3: 11 | P3: 12 | Q3: 13 | R3: 14 | S3: 15 | T3: 16 | U3: 17 | V3: 18 | W3: 19
B4: Account Code | C4: AccountNAME | E4: 2025.06 | F4: 2025.09 | G4: 2025.12 | H4: 2025.12A | I4: 2026.03 | J4: 2026.06 | K4: 2026.09 | L4: 2026.12 | M4: 2026.12A | N4: 2027.03 | O4: 2027.06 | P4: 2027.09 | Q4: 2027.12 | R4: 2027.12A | S4: 2028.03 | T4: 2028.06 | U4: 2028.09 | V4: 2028.12 | W4: 2028.12A
A5: 1 | C5: 유동자산 | E5: 829391.23 | F5: 1051424.7 | G5: 1125162.7 | H5: 1125162.7 | I5: 1221806.2 | J5: 1200778.7
A6: 1 | C6: 현금및현금성자산 | E6: 376281.41 | F6: 296802.23 | G6: 215179.11 | H6: 215179.11 | I6: 289943.57 | J6: 323277.24
A7: 1 | C7: 단기금융상품 | E7: 1488.5 | G7: 12899.49 | H7: 12899.49 | I7: 72277.51 | J7: 108767.29
A8: 1 | C8: 단기금융자산 | E8: 1488.5 | G8: 12899.49 | H8: 12899.49 | I8: 72277.51 | J8: 108767.29
A9: 1 | C9: 매출채권및기타채권 | E9: 79278.81 | F9: 87232.83 | G9: 104502.3 | H9: 104502.3 | I9: 96172.6 | J9: 107196.98
A10: 1 | C10: 계약자산 | E10: 265910.36 | F10: 265726.2 | G10: 376052.97 | H10: 376052.97 | I10: 355960.68 | J10: 311813.71
A11: 1 | C11: 재고자산 | E11: 23773.93 | F11: 34326.11 | G11: 35874.49 | H11: 35874.49 | I11: 54617.84 | J11: 36183.86
A12: 1 | C12: 기타유동자산 | E12: 73659.28 | F12: 73471 | G12: 72370.88 | H12: 72370.88 | I12: 70500.48 | J12: 74174.34
A13: 1 | C13: 당기법인세자산(선급법인세) | E13: 634.68 | F13: 2923.64
A14: 1 | C14: 비유동자산 | E14: 383370.26 | F14: 377438 | G14: 412126.84 | H14: 412126.84 | I14: 421592.05 | J14: 558306.11
A15: 1 | C15: 종속기업및관계기업투자 | E15: 50 | F15: 50 | G15: 50 | H15: 50 | I15: 50 | J15: 50
A16: 1 | C16: 투자자산 | E16: 50 | F16: 50 | G16: 24675.75 | H16: 24675.75 | I16: 29635.62 | J16: 145555.48
A17: 1 | C17: 투자부동산 | E17: 913.14 | F17: 901.38 | G17: 889.62 | H17: 889.62 | I17: 877.86 | J17: 866.11
A18: 1 | C18: 유형자산 | E18: 350898.62 | F18: 351724.88 | G18: 351045.15 | H18: 351045.15 | I18: 345794.8 | J18: 347974.52
A19: 1 | C19: 무형자산 | E19: 1361.16 | F19: 1332.41 | G19: 1462.83 | H19: 1462.83 | I19: 5710.78 | J19: 5468.79
A20: 1 | C20: 사용권자산 | E20: 457.83 | F20: 400.84 | G20: 333.21 | H20: 333.21 | I20: 279.77 | J20: 246.64
A21: 1 | C21: 기타비유동자산 | E21: 457.83 | F21: 400.84 | G21: 13017.91 | H21: 13017.91 | I21: 13516.28 | J21: 26437.34
A22: 1 | C22: 장기매출채권및기타채권 | E22: 7702.32 | F22: 7672.17 | G22: 7376.09 | H22: 7376.09 | I22: 7377.29 | J22: 8006.54
A23: 1 | C23: 이연법인세자산 | E23: 13160.88
A24: 1 | C24: 자산총계 | E24: 1212761.5 | F24: 1428862.7 | G24: 1537289.5 | H24: 1537289.5 | I24: 1643398.2 | J24: 1759084.8
A25: 1 | C25: 유동부채 | E25: 630274.7 | F25: 376058.99 | G25: 410081.13 | H25: 410081.13 | I25: 462138.03 | J25: 509427
A26: 1 | C26: 매입채무및기타채무 | E26: 103834.76 | F26: 94770.91 | G26: 127151.18 | H26: 127151.18 | I26: 131954.79 | J26: 127776.35
A27: 1 | C27: 단기차입금 | E27: 187365.85 | F27: 23739.99
A28: 1 | C28: 단기사채 | E28: 20989.41
A29: 1 | C29: 유동성장기부채 | E29: 20000
A30: 1 | C30: 계약부채 | E30: 280517.02 | F30: 230107.11 | G30: 215414.72 | H30: 215414.72 | I30: 210986.68 | J30: 261230.99
A31: 1 | C31: 단기충당부채 | E31: 2975.68 | F31: 2272.59 | G31: 2168.34 | H31: 2168.34 | I31: 2318.93 | J31: 2385.39
A32: 1 | C32: 기타유동부채 | E32: 804.11 | F32: 646.2 | G32: 603.21 | H32: 603.21 | I32: 10291.85 | J32: 592.96
A33: 1 | C33: 비유동부채 | E33: 25057.08 | F33: 34627.97 | G33: 35054.45 | H33: 35054.45 | I33: 47187.81 | J33: 51241.08
A34: 1 | C34: 장기매입채무및기타채무 | E34: 3743.58 | F34: 4096.32 | G34: 4579.13 | H34: 4579.13 | I34: 4935.5 | J34: 5045.69
A35: 1 | C35: 확정급여부채 | E35: 12019.49 | F35: 12830.28 | G35: 8453.54 | H35: 8453.54 | I35: 9424.89 | J35: 7873.45
A36: 1 | C36: 장기충당부채 | E36: 271.02 | F36: 301.78 | G36: 363.1 | H36: 363.1 | I36: 355.88 | J36: 351.76
A37: 1 | C37: 부채총계 | E37: 655331.78 | F37: 410686.96 | G37: 445135.58 | H37: 445135.58 | I37: 509325.84 | J37: 560668.08
A38: 1 | C38: 자본금 | E38: 152631.56 | F38: 192631.56 | G38: 192631.56 | H38: 192631.56 | I38: 192631.56 | J38: 192631.56
A39: 1 | C39: 자본잉여금 | E39: 47947.23 | F39: 402861.42 | G39: 398917.63 | H39: 398917.63 | I39: 398917.63 | J39: 398917.63
A40: 1 | C40: 기타포괄이익누계액 | E40: 40832.26 | F40: 40813.13 | G40: 40037.22 | H40: 40037.22 | I40: 40059.04 | J40: 40028.56
...

Sheet subQ
A1: YQ | C1: subQ 분기 서브모델(억원, U=100) | E1: 2Q25 | F1: 3Q25 | G1: 4Q25 | H1: 2025 | I1: 1Q26 | J1: 2Q26 | K1: 3Q26 | L1: 4Q26 | M1: 2026 | N1: 1Q27 | O1: 2Q27 | P1: 3Q27 | Q1: 4Q27 | R1: 2027 | S1: 1Q28 | T1: 2Q28 | U1: 3Q28 | V1: 4Q28 | W1: 2028
A2: A=이름(key) B=그룹 C=단위 D=FnGuide 계정명(VLOOKUP 키). 확정=VLOOKUP(BS), 추정=변수 가정 참조
E3: 1 | F3: 2 | G3: 3 | H3: 4 | I3: 5 | J3: 6 | K3: 7 | L3: 8 | M3: 9 | N3: 10 | O3: 11 | P3: 12 | Q3: 13 | R3: 14 | S3: 15 | T3: 16 | U3: 17 | V3: 18 | W3: 19
E4: 2025.06 | F4: 2025.09 | G4: 2025.12 | H4: 2025.12A | I4: 2026.03 | J4: 2026.06 | K4: 2026.09 | L4: 2026.12 | M4: 2026.12A | N4: 2027.03 | O4: 2027.06 | P4: 2027.09 | Q4: 2027.12 | R4: 2027.12A | S4: 2028.03 | T4: 2028.06 | U4: 2028.09 | V4: 2028.12 | W4: 2028.12A
A5: 매출액 | B5: 손익 | C5: 억원 | D5: 매출액(수익) | E5: =IFERROR(VLOOKUP($D5,BS연결,MATCH(E$1,BS연결H,0),0)/100,"") | F5: =IFERROR(VLOOKUP($D5,BS연결,MATCH(F$1,BS연결H,0),0)/100,"") | G5: =IFERROR(VLOOKUP($D5,BS연결,MATCH(G$1,BS연결H,0),0)/100,"") | I5: =IFERROR(VLOOKUP($D5,BS연결,MATCH(I$1,BS연결H,0),0)/100,"") | J5: =IFERROR(VLOOKUP($D5,BS연결,MATCH(J$1,BS연결H,0),0)/100,"") | K5: =IFERROR(K38+K42,"") | L5: =IFERROR(L38+L42,"") | M5: =SUM(I5:L5) | N5: =IFERROR(N38+N42,"") | O5: =IFERROR(O38+O42,"") | P5: =IFERROR(P38+P42,"") | Q5: =IFERROR(Q38+Q42,"") | R5: =SUM(N5:Q5) | S5: =IFERROR(S38+S42,"") | T5: =IFERROR(T38+T42,"") | U5: =IFERROR(U38+U42,"") | V5: =IFERROR(V38+V42,"") | W5: =SUM(S5:V5)
A6: 매출원가 | B6: 손익 | C6: 억원 | D6: 매출원가 | E6: =IFERROR(VLOOKUP($D6,BS연결,MATCH(E$1,BS연결H,0),0)/100,"") | F6: =IFERROR(VLOOKUP($D6,BS연결,MATCH(F$1,BS연결H,0),0)/100,"") | G6: =IFERROR(VLOOKUP($D6,BS연결,MATCH(G$1,BS연결H,0),0)/100,"") | I6: =IFERROR(VLOOKUP($D6,BS연결,MATCH(I$1,BS연결H,0),0)/100,"") | J6: =IFERROR(VLOOKUP($D6,BS연결,MATCH(J$1,BS연결H,0),0)/100,"") | K6: =IFERROR(K5-K7,"") | L6: =IFERROR(L5-L7,"") | M6: =SUM(I6:L6) | N6: =IFERROR(N5-N7,"") | O6: =IFERROR(O5-O7,"") | P6: =IFERROR(P5-P7,"") | Q6: =IFERROR(Q5-Q7,"") | R6: =SUM(N6:Q6) | S6: =IFERROR(S5-S7,"") | T6: =IFERROR(T5-T7,"") | U6: =IFERROR(U5-U7,"") | V6: =IFERROR(V5-V7,"") | W6: =SUM(S6:V6)
A7: 매출총이익 | B7: 손익 | C7: 억원 | D7: 매출총이익 | E7: =IFERROR(VLOOKUP($D7,BS연결,MATCH(E$1,BS연결H,0),0)/100,"") | F7: =IFERROR(VLOOKUP($D7,BS연결,MATCH(F$1,BS연결H,0),0)/100,"") | G7: =IFERROR(VLOOKUP($D7,BS연결,MATCH(G$1,BS연결H,0),0)/100,"") | I7: =IFERROR(VLOOKUP($D7,BS연결,MATCH(I$1,BS연결H,0),0)/100,"") | J7: =IFERROR(VLOOKUP($D7,BS연결,MATCH(J$1,BS연결H,0),0)/100,"") | K7: =IFERROR(K9+K8,"") | L7: =IFERROR(L9+L8,"") | M7: =SUM(I7:L7) | N7: =IFERROR(N9+N8,"") | O7: =IFERROR(O9+O8,"") | P7: =IFERROR(P9+P8,"") | Q7: =IFERROR(Q9+Q8,"") | R7: =SUM(N7:Q7) | S7: =IFERROR(S9+S8,"") | T7: =IFERROR(T9+T8,"") | U7: =IFERROR(U9+U8,"") | V7: =IFERROR(V9+V8,"") | W7: =SUM(S7:V7)
A8: 판관비 | B8: 손익 | C8: 억원 | D8: 판관비 | E8: =IFERROR(VLOOKUP($D8,BS연결,MATCH(E$1,BS연결H,0),0)/100,"") | F8: =IFERROR(VLOOKUP($D8,BS연결,MATCH(F$1,BS연결H,0),0)/100,"") | G8: =IFERROR(VLOOKUP($D8,BS연결,MATCH(G$1,BS연결H,0),0)/100,"") | I8: =IFERROR(VLOOKUP($D8,BS연결,MATCH(I$1,BS연결H,0),0)/100,"") | J8: =IFERROR(VLOOKUP($D8,BS연결,MATCH(J$1,BS연결H,0),0)/100,"") | K8: =IFERROR(K5*변수!K21,"") | L8: =IFERROR(L5*변수!L21,"") | M8: =SUM(I8:L8) | N8: =IFERROR(N5*변수!N21,"") | O8: =IFERROR(O5*변수!O21,"") | P8: =IFERROR(P5*변수!P21,"") | Q8: =IFERROR(Q5*변수!Q21,"") | R8: =SUM(N8:Q8) | S8: =IFERROR(S5*변수!S21,"") | T8: =IFERROR(T5*변수!T21,"") | U8: =IFERROR(U5*변수!U21,"") | V8: =IFERROR(V5*변수!V21,"") | W8: =SUM(S8:V8)
A9: 영업이익 | B9: 손익 | C9: 억원 | D9: 영업이익 | E9: =IFERROR(VLOOKUP($D9,BS연결,MATCH(E$1,BS연결H,0),0)/100,"") | F9: =IFERROR(VLOOKUP($D9,BS연결,MATCH(F$1,BS연결H,0),0)/100,"") | G9: =IFERROR(VLOOKUP($D9,BS연결,MATCH(G$1,BS연결H,0),0)/100,"") | I9: =IFERROR(VLOOKUP($D9,BS연결,MATCH(I$1,BS연결H,0),0)/100,"") | J9: =IFERROR(VLOOKUP($D9,BS연결,MATCH(J$1,BS연결H,0),0)/100,"") | K9: =IFERROR(K40+K43,"") | L9: =IFERROR(L40+L43,"") | M9: =SUM(I9:L9) | N9: =IFERROR(N40+N43,"") | O9: =IFERROR(O40+O43,"") | P9: =IFERROR(P40+P43,"") | Q9: =IFERROR(Q40+Q43,"") | R9: =SUM(N9:Q9) | S9: =IFERROR(S40+S43,"") | T9: =IFERROR(T40+T43,"") | U9: =IFERROR(U40+U43,"") | V9: =IFERROR(V40+V43,"") | W9: =SUM(S9:V9)
A10: OPM | B10: 손익 | C10: % | D10: 영업이익률 | E10: =IFERROR(E9/E5,"") | F10: =IFERROR(F9/F5,"") | G10: =IFERROR(G9/G5,"") | I10: =IFERROR(I9/I5,"") | J10: =IFERROR(J9/J5,"") | K10: =IFERROR(K9/K5,"") | L10: =IFERROR(L9/L5,"") | M10: =IFERROR(M9/M5,"") | N10: =IFERROR(N9/N5,"") | O10: =IFERROR(O9/O5,"") | P10: =IFERROR(P9/P5,"") | ... W10: =IFERROR(W9/W5,"")
A11: 금융손익 | B11: 손익 | C11: 억원 | D11: 금융손익 | E11: =IFERROR(VLOOKUP($D11,BS연결,MATCH(E$1,BS연결H,0),0)/100,"") | F11: =IFERROR(VLOOKUP($D11,BS연결,MATCH(F$1,BS연결H,0),0)/100,"") | G11: =IFERROR(VLOOKUP($D11,BS연결,MATCH(G$1,BS연결H,0),0)/100,"") | I11: =IFERROR(VLOOKUP($D11,BS연결,MATCH(I$1,BS연결H,0),0)/100,"") | J11: =IFERROR(VLOOKUP($D11,BS연결,MATCH(J$1,BS연결H,0),0)/100,"") | K11: =IFERROR(K12+K13+K14+K15,"") | L11: =IFERROR(L12+L13+L14+L15,"") | M11: =SUM(I11:L11) | N11: =IFERROR(N12+N13+N14+N15,"") | O11: =IFERROR(O12+O13+O14+O15,"") | P11: =IFERROR(P12+P13+P14+P15,"") | Q11: =IFERROR(Q12+Q13+Q14+Q15,"") | R11: =SUM(N11:Q11) | S11: =IFERROR(S12+S13+S14+S15,"") | T11: =IFERROR(T12+T13+T14+T15,"") | U11: =IFERROR(U12+U13+U14+U15,"") | V11: =IFERROR(V12+V13+V14+V15,"") | W11: =SUM(S11:V11)
A12: 이자손익 | B12: 손익 | C12: 억원 | D12: 이자손익 | E12: =IFERROR(VLOOKUP($D12,BS연결,MATCH(E$1,BS연결H,0),0)/100,"") | F12: =IFERROR(VLOOKUP($D12,BS연결,MATCH(F$1,BS연결H,0),0)/100,"") | G12: =IFERROR(VLOOKUP($D12,BS연결,MATCH(G$1,BS연결H,0),0)/100,"") | I12: =IFERROR(VLOOKUP($D12,BS연결,MATCH(I$1,BS연결H,0),0)/100,"") | J12: =IFERROR(VLOOKUP($D12,BS연결,MATCH(J$1,BS연결H,0),0)/100,"") | K12: =IFERROR((J28*변수!$D$56-J26*변수!$D$57)/4,"") | L12: =IFERROR((K28*변수!$D$56-K26*변수!$D$57)/4,"") | M12: =SUM(I12:L12) | N12: =IFERROR((L28*변수!$D$56-L26*변수!$D$57)/4,"") | O12: =IFERROR((N28*변수!$D$56-N26*변수!$D$57)/4,"") | P12: =IFERROR((O28*변수!$D$56-O26*변수!$D$57)/4,"") | Q12: =IFERROR((P28*변수!$D$56-P26*변수!$D$57)/4,"") | R12: =SUM(N12:Q12) | S12: =IFERROR((Q28*변수!$D$56-Q26*변수!$D$57)/4,"") | T12: =IFERROR((S28*변수!$D$56-S26*변수!$D$57)/4,"") | U12: =IFERROR((T28*변수!$D$56-T26*변수!$D$57)/4,"") | V12: =IFERROR((U28*변수!$D$56-U26*변수!$D$57)/4,"") | W12: =SUM(S12:V12)
A13: 외환손익 | B13: 손익 | C13: 억원 | D13: 외환손익(실적만; 추정 환효과는 환관련손익) | E13: =IFERROR((VLOOKUP("외환차익",BS연결,MATCH(E$1,BS연결H,0),0)-VLOOKUP("외환차손",BS연결,MATCH(E$1,BS연결H,0),0)+VLOOKUP("외화환산이익",BS연결,MATCH(E$1,BS연결H,0),0)-VLOOKUP("외화환산손실",BS연결,MATCH(E$1,BS연결H,0),0))/100,"") | F13: =IFERROR((VLOOKUP("외환차익",BS연결,MATCH(F$1,BS연결H,0),0)-VLOOKUP("외환차손",BS연결,MATCH(F$1,BS연결H,0),0)+VLOOKUP("외화환산이익",BS연결,MATCH(F$1,BS연결H,0),0)-VLOOKUP("외화환산손실",BS연결,MATCH(F$1,BS연결H,0),0))/100,"") | G13: =IFERROR((VLOOKUP("외환차익",BS연결,MATCH(G$1,BS연결H,0),0)-VLOOKUP("외환차손",BS연결,MATCH(G$1,BS연결H,0),0)+VLOOKUP("외화환산이익",BS연결,MATCH(G$1,BS연결H,0),0)-VLOOKUP("외화환산손실",BS연결,MATCH(G$1,BS연결H,0),0))/100,"") | K13: =변수!K22 | L13: =변수!L22 | M13: =SUM(I13:L13) | N13: =변수!N22 | O13: =변수!O22 | P13: =변수!P22 | Q13: =변수!Q22 | R13: =SUM(N13:Q13) | S13: =변수!S22 | T13: =변수!T22 | U13: =변수!U22 | V13: =변수!V22 | W13: =SUM(S13:V13)
A14: 파생상품손익 | B14: 손익 | C14: 억원 | D14: 파생상품손익 | E14: =IFERROR((VLOOKUP("파생상품이익",BS연결,MATCH(E$1,BS연결H,0),0)-VLOOKUP("파생상품손실",BS연결,MATCH(E$1,BS연결H,0),0))/100,"") | F14: =IFERROR((VLOOKUP("파생상품이익",BS연결,MATCH(F$1,BS연결H,0),0)-VLOOKUP("파생상품손실",BS연결,MATCH(F$1,BS연결H,0),0))/100,"") | G14: =IFERROR((VLOOKUP("파생상품이익",BS연결,MATCH(G$1,BS연결H,0),0)-VLOOKUP("파생상품손실",BS연결,MATCH(G$1,BS연결H,0),0))/100,"") | I14: =IFERROR((VLOOKUP("파생상품이익",BS연결,MATCH(I$1,BS연결H,0),0)-VLOOKUP("파생상품손실",BS연결,MATCH(I$1,BS연결H,0),0))/100,"") | J14: =IFERROR((VLOOKUP("파생상품이익",BS연결,MATCH(J$1,BS연결H,0),0)-VLOOKUP("파생상품손실",BS연결,MATCH(J$1,BS연결H,0),0))/100,"") | K14: =변수!K23 | L14: =변수!L23 | M14: =SUM(I14:L14) | N14: =변수!N23 | O14: =변수!O23 | P14: =변수!P23 | Q14: =변수!Q23 | R14: =SUM(N14:Q14) | S14: =변수!S23 | T14: =변수!T23 | U14: =변수!U23 | V14: =변수!V23 | W14: =SUM(S14:V14)
A15: 기타금융손익 | B15: 손익 | C15: 억원 | D15: 기타금융손익(금융손익 잔차) | E15: =IFERROR(E11-E12-E13-E14,"") | F15: =IFERROR(F11-F12-F13-F14,"") | G15: =IFERROR(G11-G12-G13-G14,"") | K15: =변수!K24 | L15: =변수!L24 | M15: =SUM(I15:L15) | N15: =변수!N24 | O15: =변수!O24 | P15: =변수!P24 | Q15: =변수!Q24 | R15: =SUM(N15:Q15) | S15: =변수!S24 | T15: =변수!T24 | U15: =변수!U24 | V15: =변수!V24 | W15: =SUM(S15:V15)
A16: 기타영업외손익 | B16: 손익 | C16: 억원 | D16: 기타영업외손익 | E16: =IFERROR(VLOOKUP($D16,BS연결,MATCH(E$1,BS연결H,0),0)/100,"") | F16: =IFERROR(VLOOKUP($D16,BS연결,MATCH(F$1,BS연결H,0),0)/100,"") | G16: =IFERROR(VLOOKUP($D16,BS연결,MATCH(G$1,BS연결H,0),0)/100,"") | I16: =IFERROR(VLOOKUP($D16,BS연결,MATCH(I$1,BS연결H,0),0)/100,"") | J16: =IFERROR(VLOOKUP($D16,BS연결,MATCH(J$1,BS연결H,0),0)/100,"") | K16: =변수!K25 | L16: =변수!L25 | M16: =SUM(I16:L16) | N16: =변수!N25 | O16: =변수!O25 | P16: =변수!P25 | Q16: =변수!Q25 | R16: =SUM(N16:Q16) | S16: =변수!S25 | T16: =변수!T25 | U16: =변수!U25 | V16: =변수!V25 | W16: =SUM(S16:V16)
A17: 환관련손익 | B17: 손익 | C17: 억원 | D17: 환관련손익(모델 추정분) | K17: =IFERROR(변수!$D$59*(변수!K7-변수!J7)/100,"") | L17: =IFERROR(변수!$D$59*(변수!L7-변수!K7)/100,"") | M17: =SUM(I17:L17) | N17: =IFERROR(변수!$D$59*(변수!N7-변수!L7)/100,"") | O17: =IFERROR(변수!$D$59*(변수!O7-변수!N7)/100,"") | P17: =IFERROR(변수!$D$59*(변수!P7-변수!O7)/100,"") | Q17: =IFERROR(변수!$D$59*(변수!Q7-변수!P7)/100,"") | R17: =SUM(N17:Q17) | S17: =IFERROR(변수!$D$59*(변수!S7-변수!Q7)/100,"") | T17: =IFERROR(변수!$D$59*(변수!T7-변수!S7)/100,"") | U17: =IFERROR(변수!$D$59*(변수!U7-변수!T7)/100,"") | V17: =IFERROR(변수!$D$59*(변수!V7-변수!U7)/100,"") | W17: =SUM(S17:V17)
A18: 세전이익 | B18: 손익 | C18: 억원 | D18: 법인세비용차감전계속사업이익 | E18: =IFERROR(VLOOKUP($D18,BS연결,MATCH(E$1,BS연결H,0),0)/100,"") | F18: =IFERROR(VLOOKUP($D18,BS연결,MATCH(F$1,BS연결H,0),0)/100,"") | G18: =IFERROR(VLOOKUP($D18,BS연결,MATCH(G$1,BS연결H,0),0)/100,"") | I18: =IFERROR(VLOOKUP($D18,BS연결,MATCH(I$1,BS연결H,0),0)/100,"") | J18: =IFERROR(VLOOKUP($D18,BS연결,MATCH(J$1,BS연결H,0),0)/100,"") | K18: =IFERROR(K9+K11+K16+K17,"") | L18: =IFERROR(L9+L11+L16+L17,"") | M18: =SUM(I18:L18) | N18: =IFERROR(N9+N11+N16+N17,"") | O18: =IFERROR(O9+O11+O16+O17,"") | P18: =IFERROR(P9+P11+P16+P17,"") | Q18: =IFERROR(Q9+Q11+Q16+Q17,"") | R18: =SUM(N18:Q18) | S18: =IFERROR(S9+S11+S16+S17,"") | T18: =IFERROR(T9+T11+T16+T17,"") | U18: =IFERROR(U9+U11+U16+U17,"") | V18: =IFERROR(V9+V11+V16+V17,"") | W18: =SUM(S18:V18)
A19: 법인세비용 | B19: 손익 | C19: 억원 | D19: 법인세비용 | E19: =IFERROR(VLOOKUP($D19,BS연결,MATCH(E$1,BS연결H,0),0)/100,"") | F19: =IFERROR(VLOOKUP($D19,BS연결,MATCH(F$1,BS연결H,0),0)/100,"") | G19: =IFERROR(VLOOKUP($D19,BS연결,MATCH(G$1,BS연결H,0),0)/100,"") | I19: =IFERROR(VLOOKUP($D19,BS연결,MATCH(I$1,BS연결H,0),0)/100,"") | J19: =IFERROR(VLOOKUP($D19,BS연결,MATCH(J$1,BS연결H,0),0)/100,"") | K19: =IFERROR(MAX(K18,0)*변수!K26,"") | L19: =IFERROR(MAX(L18,0)*변수!L26,"") | M19: =SUM(I19:L19) | N19: =IFERROR(MAX(N18,0)*변수!N26,"") | O19: =IFERROR(MAX(O18,0)*변수!O26,"") | P19: =IFERROR(MAX(P18,0)*변수!P26,"") | Q19: =IFERROR(MAX(Q18,0)*변수!Q26,"") | R19: =SUM(N19:Q19) | S19: =IFERROR(MAX(S18,0)*변수!S26,"") | T19: =IFERROR(MAX(T18,0)*변수!T26,"") | U19: =IFERROR(MAX(U18,0)*변수!U26,"") | V19: =IFERROR(MAX(V18,0)*변수!V26,"") | W19: =SUM(S19:V19)
A20: 당기순이익 | B20: 손익 | C20: 억원 | D20: 당기순이익 | E20: =IFERROR(VLOOKUP($D20,BS연결,MATCH(E$1,BS연결H,0),0)/100,"") | F20: =IFERROR(VLOOKUP($D20,BS연결,MATCH(F$1,BS연결H,0),0)/100,"") | G20: =IFERROR(VLOOKUP($D20,BS연결,MATCH(G$1,BS연결H,0),0)/100,"") | I20: =IFERROR(VLOOKUP($D20,BS연결,MATCH(I$1,BS연결H,0),0)/100,"") | J20: =IFERROR(VLOOKUP($D20,BS연결,MATCH(J$1,BS연결H,0),0)/100,"") | K20: =IFERROR(K18-K19,"") | L20: =IFERROR(L18-L19,"") | M20: =SUM(I20:L20) | N20: =IFERROR(N18-N19,"") | O20: =IFERROR(O18-O19,"") | P20: =IFERROR(P18-P19,"") | Q20: =IFERROR(Q18-Q19,"") | R20: =SUM(N20:Q20) | S20: =IFERROR(S18-S19,"") | T20: =IFERROR(T18-T19,"") | U20: =IFERROR(U18-U19,"") | V20: =IFERROR(V18-V19,"") | W20: =SUM(S20:V20)
A21: 지배주주순이익 | B21: 손익 | C21: 억원 | D21: (지배주주지분)당기순이익 | E21: =IFERROR(VLOOKUP($D21,BS연결,MATCH(E$1,BS연결H,0),0)/100,"") | F21: =IFERROR(VLOOKUP($D21,BS연결,MATCH(F$1,BS연결H,0),0)/100,"") | G21: =IFERROR(VLOOKUP($D21,BS연결,MATCH(G$1,BS연결H,0),0)/100,"") | I21: =IFERROR(VLOOKUP($D21,BS연결,MATCH(I$1,BS연결H,0),0)/100,"") | J21: =IFERROR(VLOOKUP($D21,BS연결,MATCH(J$1,BS연결H,0),0)/100,"") | K21: =IFERROR(K20*변수!K27,"") | L21: =IFERROR(L20*변수!L27,"") | M21: =SUM(I21:L21) | N21: =IFERROR(N20*변수!N27,"") | O21: =IFERROR(O20*변수!O27,"") | P21: =IFERROR(P20*변수!P27,"") | Q21: =IFERROR(Q20*변수!Q27,"") | R21: =SUM(N21:Q21) | S21: =IFERROR(S20*변수!S27,"") | T21: =IFERROR(T20*변수!T27,"") | U21: =IFERROR(U20*변수!U27,"") | V21: =IFERROR(V20*변수!V27,"") | W21: =SUM(S21:V21)
A22: 자산총계 | B22: 재무상태 | C22: 억원 | D22: 자산총계 | E22: =IFERROR(VLOOKUP($D22,BS연결,MATCH(E$1,BS연결H,0),0)/100,"") | F22: =IFERROR(VLOOKUP($D22,BS연결,MATCH(F$1,BS연결H,0),0)/100,"") | G22: =IFERROR(VLOOKUP($D22,BS연결,MATCH(G$1,BS연결H,0),0)/100,"") | H22: =IFERROR(VLOOKUP($D22,BS연결,MATCH(H$1,BS연결H,0),0)/100,"") | I22: =IFERROR(VLOOKUP($D22,BS연결,MATCH(I$1,BS연결H,0),0)/100,"") | J22: =IFERROR(VLOOKUP($D22,BS연결,MATCH(J$1,BS연결H,0),0)/100,"") | K22: =IFERROR(K23+K24,"") | L22: =IFERROR(L23+L24,"") | M22: =L22 | N22: =IFERROR(N23+N24,"") | O22: =IFERROR(O23+O24,"") | P22: =IFERROR(P23+P24,"") | Q22: =IFERROR(Q23+Q24,"") | R22: =Q22 | S22: =IFERROR(S23+S24,"") | T22: =IFERROR(T23+T24,"") | U22: =IFERROR(U23+U24,"") | V22: =IFERROR(V23+V24,"") | W22: =V22
A23: 부채총계 | B23: 재무상태 | C23: 억원 | D23: 부채총계 | E23: =IFERROR(VLOOKUP($D23,BS연결,MATCH(E$1,BS연결H,0),0)/100,"") | F23: =IFERROR(VLOOKUP($D23,BS연결,MATCH(F$1,BS연결H,0),0)/100,"") | G23: =IFERROR(VLOOKUP($D23,BS연결,MATCH(G$1,BS연결H,0),0)/100,"") | H23: =IFERROR(VLOOKUP($D23,BS연결,MATCH(H$1,BS연결H,0),0)/100,"") | I23: =IFERROR(VLOOKUP($D23,BS연결,MATCH(I$1,BS연결H,0),0)/100,"") | J23: =IFERROR(VLOOKUP($D23,BS연결,MATCH(J$1,BS연결H,0),0)/100,"") | K23: =IFERROR(J23*(1+변수!K28),"") | L23: =IFERROR(K23*(1+변수!L28),"") | M23: =L23 | N23: =IFERROR(L23*(1+변수!N28),"") | O23: =IFERROR(N23*(1+변수!O28),"") | P23: =IFERROR(O23*(1+변수!P28),"") | Q23: =IFERROR(P23*(1+변수!Q28),"") | R23: =Q23 | S23: =IFERROR(Q23*(1+변수!S28),"") | T23: =IFERROR(S23*(1+변수!T28),"") | U23: =IFERROR(T23*(1+변수!U28),"") | V23: =IFERROR(U23*(1+변수!V28),"") | W23: =V23
A24: 자본총계 | B24: 재무상태 | C24: 억원 | D24: 자본총계 | E24: =IFERROR(VLOOKUP($D24,BS연결,MATCH(E$1,BS연결H,0),0)/100,"") | F24: =IFERROR(VLOOKUP($D24,BS연결,MATCH(F$1,BS연결H,0),0)/100,"") | G24: =IFERROR(VLOOKUP($D24,BS연결,MATCH(G$1,BS연결H,0),0)/100,"") | H24: =IFERROR(VLOOKUP($D24,BS연결,MATCH(H$1,BS연결H,0),0)/100,"") | I24: =IFERROR(VLOOKUP($D24,BS연결,MATCH(I$1,BS연결H,0),0)/100,"") | J24: =IFERROR(VLOOKUP($D24,BS연결,MATCH(J$1,BS연결H,0),0)/100,"") | K24: =IFERROR(J24+K20-변수!K29,"") | L24: =IFERROR(K24+L20-변수!L29,"") | M24: =L24 | N24: =IFERROR(L24+N20-변수!N29,"") | O24: =IFERROR(N24+O20-변수!O29,"") | P24: =IFERROR(O24+P20-변수!P29,"") | Q24: =IFERROR(P24+Q20-변수!Q29,"") | R24: =Q24 | S24: =IFERROR(Q24+S20-변수!S29,"") | T24: =IFERROR(S24+T20-변수!T29,"") | U24: =IFERROR(T24+U20-변수!U29,"") | V24: =IFERROR(U24+V20-변수!V29,"") | W24: =V24
A25: 지배주주지분 | B25: 재무상태 | C25: 억원 | D25: 지배주주지분 | E25: =IFERROR(VLOOKUP($D25,BS연결,MATCH(E$1,BS연결H,0),0)/100,"") | F25: =IFERROR(VLOOKUP($D25,BS연결,MATCH(F$1,BS연결H,0),0)/100,"") | G25: =IFERROR(VLOOKUP($D25,BS연결,MATCH(G$1,BS연결H,0),0)/100,"") | H25: =IFERROR(VLOOKUP($D25,BS연결,MATCH(H$1,BS연결H,0),0)/100,"") | I25: =IFERROR(VLOOKUP($D25,BS연결,MATCH(I$1,BS연결H,0),0)/100,"") | J25: =IFERROR(VLOOKUP($D25,BS연결,MATCH(J$1,BS연결H,0),0)/100,"") | K25: =IFERROR(J25+K21-변수!K30,"") | L25: =IFERROR(K25+L21-변수!L30,"") | M25: =L25 | N25: =IFERROR(L25+N21-변수!N30,"") | O25: =IFERROR(N25+O21-변수!O30,"") | P25: =IFERROR(O25+P21-변수!P30,"") | Q25: =IFERROR(P25+Q21-변수!Q30,"") | R25: =Q25 | S25: =IFERROR(Q25+S21-변수!S30,"") | T25: =IFERROR(S25+T21-변수!T30,"") | U25: =IFERROR(T25+U21-변수!U30,"") | V25: =IFERROR(U25+V21-변수!V30,"") | W25: =V25
A26: 총차입금 | B26: 재무상태 | C26: 억원 | D26: 총차입금 | E26: =IFERROR(VLOOKUP($D26,BS연결,MATCH(E$1,BS연결H,0),0)/100,"") | F26: =IFERROR(VLOOKUP($D26,BS연결,MATCH(F$1,BS연결H,0),0)/100,"") | H26: =G26 | M26: =L26 | R26: =Q26 | W26: =V26
A27: 순차입금 | B27: 재무상태 | C27: 억원 | D27: 순차입금 | E27: =IFERROR(VLOOKUP($D27,BS연결,MATCH(E$1,BS연결H,0),0)/100,"") | F27: =IFERROR(VLOOKUP($D27,BS연결,MATCH(F$1,BS연결H,0),0)/100,"") | H27: =G27 | M27: =L27 | R27: =Q27 | W27: =V27
A28: 이자발생자산 | B28: 재무상태 | C28: 억원 | D28: 이자발생자산 | E28: =IFERROR(VLOOKUP($D28,BS연결,MATCH(E$1,BS연결H,0),0)/100,"") | F28: =IFERROR(VLOOKUP($D28,BS연결,MATCH(F$1,BS연결H,0),0)/100,"") | G28: =IFERROR(VLOOKUP($D28,BS연결,MATCH(G$1,BS연결H,0),0)/100,"") | H28: =IFERROR(VLOOKUP($D28,BS연결,MATCH(H$1,BS연결H,0),0)/100,"") | I28: =IFERROR(VLOOKUP($D28,BS연결,MATCH(I$1,BS연결H,0),0)/100,"") | J28: =IFERROR(VLOOKUP($D28,BS연결,MATCH(J$1,BS연결H,0),0)/100,"") | K28: =IFERROR(J28*(1+변수!K33),"") | L28: =IFERROR(K28*(1+변수!L33),"") | M28: =L28 | N28: =IFERROR(L28*(1+변수!N33),"") | O28: =IFERROR(N28*(1+변수!O33),"") | P28: =IFERROR(O28*(1+변수!P33),"") | Q28: =IFERROR(P28*(1+변수!Q33),"") | R28: =Q28 | S28: =IFERROR(Q28*(1+변수!S33),"") | T28: =IFERROR(S28*(1+변수!T33),"") | U28: =IFERROR(T28*(1+변수!U33),"") | V28: =IFERROR(U28*(1+변수!V33),"") | W28: =V28
A29: 현금및현금성자산 | B29: 재무상태 | C29: 억원 | D29: 현금및현금성자산 | E29: =IFERROR(VLOOKUP($D29,BS연결,MATCH(E$1,BS연결H,0),0)/100,"") | F29: =IFERROR(VLOOKUP($D29,BS연결,MATCH(F$1,BS연결H,0),0)/100,"") | G29: =IFERROR(VLOOKUP($D29,BS연결,MATCH(G$1,BS연결H,0),0)/100,"") | H29: =IFERROR(VLOOKUP($D29,BS연결,MATCH(H$1,BS연결H,0),0)/100,"") | I29: =IFERROR(VLOOKUP($D29,BS연결,MATCH(I$1,BS연결H,0),0)/100,"") | J29: =IFERROR(VLOOKUP($D29,BS연결,MATCH(J$1,BS연결H,0),0)/100,"") | M29: =L29 | R29: =Q29 | W29: =V29
A30: CAPEX | B30: 현금흐름 | C30: 억원 | D30: CAPEX | E30: =IFERROR(VLOOKUP($D30,BS연결,MATCH(E$1,BS연결H,0),0)/100,"") | F30: =IFERROR(VLOOKUP($D30,BS연결,MATCH(F$1,BS연결H,0),0)/100,"") | G30: =IFERROR(VLOOKUP($D30,BS연결,MATCH(G$1,BS연결H,0),0)/100,"") | I30: =IFERROR(VLOOKUP($D30,BS연결,MATCH(I$1,BS연결H,0),0)/100,"") | J30: =IFERROR(VLOOKUP($D30,BS연결,MATCH(J$1,BS연결H,0),0)/100,"") | K30: =IFERROR(F30*(1+변수!K35),"") | L30: =IFERROR(G30*(1+변수!L35),"") | M30: =SUM(I30:L30) | N30: =IFERROR(I30*(1+변수!N35),"") | O30: =IFERROR(J30*(1+변수!O35),"") | P30: =IFERROR(K30*(1+변수!P35),"") | Q30: =IFERROR(L30*(1+변수!Q35),"") | R30: =SUM(N30:Q30) | S30: =IFERROR(N30*(1+변수!S35),"") | T30: =IFERROR(O30*(1+변수!T35),"") | U30: =IFERROR(P30*(1+변수!U35),"") | V30: =IFERROR(Q30*(1+변수!V35),"") | W30: =SUM(S30:V30)
A31: 영업활동현금흐름 | B31: 현금흐름 | C31: 억원 | D31: 영업활동으로인한현금흐름 | E31: =IFERROR(VLOOKUP($D31,BS연결,MATCH(E$1,BS연결H,0),0)/100,"") | F31: =IFERROR(VLOOKUP($D31,BS연결,MATCH(F$1,BS연결H,0),0)/100,"") | G31: =IFERROR(VLOOKUP($D31,BS연결,MATCH(G$1,BS연결H,0),0)/100,"") | I31: =IFERROR(VLOOKUP($D31,BS연결,MATCH(I$1,BS연결H,0),0)/100,"") | J31: =IFERROR(VLOOKUP($D31,BS연결,MATCH(J$1,BS연결H,0),0)/100,"") | M31: =SUM(I31:L31) | R31: =SUM(N31:Q31) | W31: =SUM(S31:V31)
A32: 주식수 | B32: 주당 | C32: 백만주 | D32: 유통주식수 | E32: 30.526 | F32: 38.526 | G32: 38.526 | H32: =G32 | I32: 38.526 | J32: 38.089 | K32: =IFERROR(J32*(1+변수!K37),"") | L32: =IFERROR(K32*(1+변수!L37),"") | M32: =L32 | N32: =IFERROR(L32*(1+변수!N37),"") | O32: =IFERROR(N32*(1+변수!O37),"") | P32: =IFERROR(O32*(1+변수!P37),"") | Q32: =IFERROR(P32*(1+변수!Q37),"") | R32: =Q32 | S32: =IFERROR(Q32*(1+변수!S37),"") | T32: =IFERROR(S32*(1+변수!T37),"") | U32: =IFERROR(T32*(1+변수!U37),"") | V32: =IFERROR(U32*(1+변수!V37),"") | W32: =V32
A33: EPS | B33: 주당 | C33: 원 | D33: EPS | E33: =IFERROR(E21*100/E32,"") | F33: =IFERROR(F21*100/F32,"") | G33: =IFERROR(G21*100/G32,"") | I33: =IFERROR(I21*100/I32,"") | J33: =IFERROR(J21*100/J32,"") | K33: =IFERROR(K21*100/K32,"") | L33: =IFERROR(L21*100/L32,"") | M33: =SUM(I33:L33) | N33: =IFERROR(N21*100/N32,"") | O33: =IFERROR(O21*100/O32,"") | P33: =IFERROR(P21*100/P32,"") | Q33: =IFERROR(Q21*100/Q32,"") | R33: =SUM(N33:Q33) | S33: =IFERROR(S21*100/S32,"") | T33: =IFERROR(T21*100/T32,"") | U33: =IFERROR(U21*100/U32,"") | V33: =IFERROR(V21*100/V32,"") | W33: =SUM(S33:V33)
A34: BPS | B34: 주당 | C34: 원 | D34: BPS | E34: =IFERROR(E25*100/E32,"") | F34: =IFERROR(F25*100/F32,"") | G34: =IFERROR(G25*100/G32,"") | H34: =G34 | I34: =IFERROR(I25*100/I32,"") | J34: =IFERROR(J25*100/J32,"") | K34: =IFERROR(K25*100/K32,"") | L34: =IFERROR(L25*100/L32,"") | M34: =L34 | N34: =IFERROR(N25*100/N32,"") | O34: =IFERROR(O25*100/O32,"") | P34: =IFERROR(P25*100/P32,"") | Q34: =IFERROR(Q25*100/Q32,"") | R34: =Q34 | S34: =IFERROR(S25*100/S32,"") | T34: =IFERROR(T25*100/T32,"") | U34: =IFERROR(U25*100/U32,"") | V34: =IFERROR(V25*100/V32,"") | W34: =V34
A35: DPS | B35: 주당 | C35: 원 | D35: DPS(보통주) | G35: 250 | H35: 250 | L35: =변수!L38 | M35: =SUM(I35:L35) | Q35: =변수!Q38 | R35: =SUM(N35:Q35) | V35: =변수!V38 | W35: =SUM(S35:V35)
A36: PER | B36: 주당 | C36: 배 | D36: PER | H36: =G36 | I36: =IFERROR(변수!I18/(E33+F33+G33+I33),"") | J36: =IFERROR(변수!J18/(F33+G33+I33+J33),"") | K36: =IFERROR(변수!$D$46/(G33+I33+J33+K33),"") | L36: =IFERROR(변수!$D$46/(I33+J33+K33+L33),"") | M36: =L36 | N36: =IFERROR(변수!$D$46/(J33+K33+L33+N33),"") | O36: =IFERROR(변수!$D$46/(K33+L33+N33+O33),"") | P36: =IFERROR(변수!$D$46/(L33+N33+O33+P33),"") | Q36: =IFERROR(변수!$D$46/(N33+O33+P33+Q33),"") | R36: =Q36 | S36: =IFERROR(변수!$D$46/(O33+P33+Q33+S33),"") | T36: =IFERROR(변수!$D$46/(P33+Q33+S33+T33),"") | U36: =IFERROR(변수!$D$46/(Q33+S33+T33+U33),"") | V36: =IFERROR(변수!$D$46/(S33+T33+U33+V33),"") | W36: =V36
A37: PBR | B37: 주당 | C37: 배 | D37: PBR | F37: =IFERROR(변수!F18/F34,"") | G37: =IFERROR(변수!G18/G34,"") | H37: =G37 | I37: =IFERROR(변수!I18/I34,"") | J37: =IFERROR(변수!J18/J34,"") | K37: =IFERROR(변수!$D$46/K34,"") | L37: =IFERROR(변수!$D$46/L34,"") | M37: =L37 | N37: =IFERROR(변수!$D$46/N34,"") | O37: =IFERROR(변수!$D$46/O34,"") | P37: =IFERROR(변수!$D$46/P34,"") | Q37: =IFERROR(변수!$D$46/Q34,"") | R37: =Q37 | S37: =IFERROR(변수!$D$46/S34,"") | T37: =IFERROR(변수!$D$46/T34,"") | U37: =IFERROR(변수!$D$46/U34,"") | V37: =IFERROR(변수!$D$46/V34,"") | W37: =V37
A38: 매출조선 | B38: 사업부 | C38: 억원 | D38: 매출 조선·해양(선박) | F38: 2720.35 | G38: 3481.49 | I38: 3062.16 | J38: 3514.02 | K38: =IFERROR(SLS!I62/100+변수!K39+K39,"") | L38: =IFERROR(SLS!J62/100+변수!L39+L39,"") | M38: =SUM(I38:L38) | N38: =IFERROR(SLS!K62/100+변수!N39+N39,"") | O38: =IFERROR(SLS!L62/100+변수!O39+O39,"") | P38: =IFERROR(SLS!M62/100+변수!P39+P39,"") | Q38: =IFERROR(SLS!N62/100+변수!Q39+Q39,"") | R38: =SUM(N38:Q38) | S38: =IFERROR(SLS!O62/100+변수!S39+S39,"") | T38: =IFERROR(SLS!P62/100+변수!T39+T39,"") | U38: =IFERROR(SLS!Q62/100+변수!U39+U39,"") | V38: =IFERROR(SLS!R62/100+변수!V39+V39,"") | W38: =SUM(S38:V38)
A39: 매출조선신규 | B39: 사업부 | C39: 억원 | D39: 매출 조선·해양(선박) 신규수주(forecast_panel base(공시 상계) — 매출조선에 포함) | I39: 0 | J39: 0 | K39: =변수!K40 | L39: =변수!L40 | M39: =SUM(I39:L39) | N39: =변수!N40 | O39: =변수!O40 | P39: =변수!P40 | Q39: =변수!Q40 | R39: =SUM(N39:Q39) | S39: =변수!S40 | T39: =변수!T40 | U39: =변수!U40 | V39: =변수!V40 | W39: =SUM(S39:V39)
A40: OP조선 | B40: 사업부 | C40: 억원 | D40: OP 조선·해양(선박) | K40: =IFERROR(K38*변수!K41,"") | L40: =IFERROR(L38*변수!L41,"") | M40: =SUM(I40:L40) | N40: =IFERROR(N38*변수!N41,"") | O40: =IFERROR(O38*변수!O41,"") | P40: =IFERROR(P38*변수!P41,"") | Q40: =IFERROR(Q38*변수!Q41,"") | R40: =SUM(N40:Q40) | S40: =IFERROR(S38*변수!S41,"") | T40: =IFERROR(T38*변수!T41,"") | U40: =IFERROR(U38*변수!U41,"") | V40: =IFERROR(V38*변수!V41,"") | W40: =SUM(S40:V40)
...

Sheet SLS
C1: 이름: SLS_H · 선표 매출인식(백만$) — sls json origin 2026Q2 | E1: 3Q25 | F1: 4Q25 | G1: 1Q26 | H1: 2Q26 | I1: 3Q26 | J1: 4Q26 | K1: 1Q27 | L1: 2Q27 | M1: 3Q27 | N1: 4Q27 | O1: 1Q28 | P1: 2Q28 | Q1: 3Q28 | R1: 4Q28 | S1: 1Q29 | T1: 2Q29 | U1: 3Q29 | V1: 4Q29 | W1: 2025 | X1: 2026 | Y1: 2027 | Z1: 2028 | AA1: 2029
A2: 코호트 표(레퍼런스 실측 캘리브레이션): ①적자 −1.1% ②BEP 1% ③중마진 4.3% ④호황 5.4% ⑤초호황 10.8% — 회사별 캘리브레이션은 target_opm.basis 참조 · 코호트 모드 reference_anchor(대안 ledger_relative) · 잔고 캡 적용 × 0.8593
E3: 1 | F3: 2 | G3: 3 | H3: 4 | I3: 5 | J3: 6 | K3: 7 | L3: 8 | M3: 9 | N3: 10 | O3: 11 | P3: 12 | Q3: 13 | R3: 14 | S3: 15 | T3: 16 | U3: 17 | V3: 18 | W3: 19 | X3: 20 | Y3: 21 | Z3: 22 | AA3: 23
E4: 2025.09 | F4: 2025.12 | G4: 2026.03 | H4: 2026.06 | I4: 2026.09 | J4: 2026.12 | K4: 2027.03 | L4: 2027.06 | M4: 2027.09 | N4: 2027.12 | O4: 2028.03 | P4: 2028.06 | Q4: 2028.09 | R4: 2028.12 | S4: 2029.03 | T4: 2029.06 | U4: 2029.09 | V4: 2029.12 | W4: 2025.12A | X4: 2026.12A | Y4: 2027.12A | Z4: 2028.12A | AA4: 2029.12A
A5: usd_m | D5: 매출인식 합계(백만$) | E5: 6.893 | F5: 96.164 | G5: 146.311 | H5: 198.344 | I5: 193.641 | J5: 197.139 | K5: 192.854 | L5: 194.997 | M5: 186.248 | N5: 161.938 | O5: 148.336 | P5: 148.336 | Q5: 131.812 | R5: 103.017 | S5: 64.129 | T5: 53.634 | U5: 33.077 | V5: 14.594 | W5: 103.057 | X5: 735.435 | Y5: 736.037 | Z5: 531.501 | AA5: 165.434
A6: marine_usd_m | D6: 해양(type≠OTHER) 합계(백만$) | E6: 6.893 | F6: 96.164 | G6: 146.311 | H6: 198.344 | I6: 193.641 | J6: 197.139 | K6: 192.854 | L6: 194.997 | M6: 186.248 | N6: 161.938 | O6: 148.336 | P6: 148.336 | Q6: 131.812 | R6: 103.017 | S6: 64.129 | T6: 53.634 | U6: 33.077 | V6: 14.594 | W6: 103.057 | X6: 735.435 | Y6: 736.037 | Z6: 531.501 | AA6: 165.434
A7: type:VLCC | D7: 선종 VLCC | E7: 6.893 | F7: 78.022 | G7: 125.644 | H7: 177.447 | I7: 175.487 | J7: 178.986 | K7: 175.095 | L7: 177.04 | M7: 168.094 | N7: 143.784 | O7: 130.38 | P7: 130.38 | Q7: 131.812 | R7: 103.017 | S7: 64.129 | T7: 53.634 | U7: 33.077 | V7: 14.594 | W7: 84.915 | X7: 657.564 | Y7: 664.013 | Z7: 495.589 | AA7: 165.434
A8: type:CONT | D8: 선종 CONT | F8: 18.142 | G8: 20.668 | H8: 20.897 | I8: 18.154 | J8: 18.154 | K8: 17.759 | L8: 17.957 | M8: 18.154 | N8: 18.154 | O8: 17.957 | P8: 17.957 | W8: 18.142 | X8: 77.873 | Y8: 72.024 | Z8: 35.914
A9: cohort:⑤초호황 | D9: 코호트 ⑤초호황 | E9: 6.893 | F9: 96.164 | G9: 146.311 | H9: 198.344 | I9: 193.641 | J9: 197.139 | K9: 192.854 | L9: 194.997 | M9: 186.248 | N9: 161.938 | O9: 148.336 | P9: 148.336 | Q9: 131.812 | R9: 103.017 | S9: 64.129 | T9: 53.634 | U9: 33.077 | V9: 14.594 | W9: 103.057 | X9: 735.435 | Y9: 736.037 | Z9: 531.501 | AA9: 165.434
A10: hedge_ratio | D10: 헤지비율 | E10: 0.7 | F10: 0.7 | G10: 0.7 | H10: 0.7 | I10: 0.7 | J10: 0.7 | K10: 0.7 | L10: 0.7 | M10: 0.7 | N10: 0.7 | O10: 0.7 | P10: 0.7 | Q10: 0.7 | R10: 0.7 | S10: 0.7 | T10: 0.7 | U10: 0.7 | V10: 0.7
A11: hedge_rate | D11: 헤지환율(가중) | E11: 1386.95 | F11: 1402 | G11: 1423.95 | H11: 1436.87 | I11: 1439.52 | J11: 1439.15 | K11: 1439.15 | L11: 1439.15 | M11: 1442.21 | N11: 1450.5 | O11: 1451.85 | P11: 1451.85 | Q11: 1452.22 | R11: 1467.12 | S11: 1459.16 | T11: 1457.71 | U11: 1448.18 | V11: 1420.69
A12: spot_assumed | D12: 건조시점 환율(sls 가정) | E12: 1386.95 | F12: 1449.19 | G12: 1466.12 | H12: 1501.75 | I12: 1418.75 | J12: 1343.39 | K12: 1341.45 | L12: 1341.45 | M12: 1341.45 | N12: 1341.45 | O12: 1341.45 | P12: 1341.45 | Q12: 1341.45 | R12: 1341.45 | S12: 1341.45 | T12: 1341.45 | U12: 1341.45 | V12: 1341.45
A13: applied_rate | D13: 적용환율 | E13: 1386.95 | F13: 1416.15 | G13: 1436.6 | H13: 1456.34 | I13: 1433.29 | J13: 1410.42 | K13: 1409.84 | L13: 1409.84 | M13: 1411.98 | N13: 1417.79 | O13: 1418.73 | P13: 1418.73 | Q13: 1418.99 | R13: 1429.42 | S13: 1423.85 | T13: 1422.83 | U13: 1416.16 | V13: 1396.92
A14: hedged_krw_m | D14: 헤지적용 원화매출(백만원) | E14: 9559.6 | F14: 136182.6 | G14: 210190.8 | H14: 288856.2 | I14: 277543 | J14: 278050.2 | K14: 271893.4 | L14: 274914.5 | M14: 262977.6 | N14: 229593.4 | O14: 210449.4 | P14: 210449.4 | Q14: 187040.3 | R14: 147255.2 | S14: 91310.4 | T14: 76312.4 | U14: 46842.8 | V14: 20387.3 | W14: 145742.2 | X14: 1054640.2 | Y14: 1039378.9 | Z14: 755194.3 | AA14: 234852.9
A15: marine_hedged_krw_m | D15: 해양 원화(백만원) | E15: 9559.6 | F15: 136182.6 | G15: 210190.8 | H15: 288856.2 | I15: 277543 | J15: 278050.2 | K15: 271893.4 | L15: 274914.5 | M15: 262977.6 | N15: 229593.4 | O15: 210449.4 | P15: 210449.4 | Q15: 187040.3 | R15: 147255.2 | S15: 91310.4 | T15: 76312.4 | U15: 46842.8 | V15: 20387.3 | W15: 145742.2 | X15: 1054640.2 | Y15: 1039378.9 | Z15: 755194.3 | AA15: 234852.9
A16: marine_hedged_krw_m_signed_by_origin | D16: 해양 원화 — origin 분기말까지 체결분(백만원) | E16: 9559.6 | F16: 136182.6 | G16: 210190.8 | H16: 288856.2 | I16: 262650.7 | J16: 258510.1 | K16: 252786.1 | L16: 255594.8 | M16: 243445.6 | N16: 210061.5 | O16: 191129.8 | P16: 191129.8 | Q16: 167508.3 | R16: 127723.3 | S16: 72203 | T16: 56992.8 | U16: 27310.8 | V16: 855.3
A17: marine_hedged_krw_m_post_origin | D17: 해양 원화 — origin 이후 체결분(백만원) | E17: 0 | F17: 0 | G17: 0 | H17: 0 | I17: 14892.4 | J17: 19540.1 | K17: 19107.3 | L17: 19319.7 | M17: 19532 | N17: 19532 | O17: 19319.7 | P17: 19319.7 | Q17: 19532 | R17: 19532 | S17: 19107.3 | T17: 19319.7 | U17: 19532 | V17: 19532
A18: target_opm | D18: 타겟 OPM(코호트) | E18: 0.108 | F18: 0.108 | G18: 0.108 | H18: 0.108 | I18: 0.108 | J18: 0.108 | K18: 0.108 | L18: 0.108 | M18: 0.108 | N18: 0.108 | O18: 0.108 | P18: 0.108 | Q18: 0.108 | R18: 0.108 | S18: 0.108 | T18: 0.108 | U18: 0.108 | V18: 0.108
A20: 선표 연결(수식) — 원화(백만원) = 스케줄(백만$) × 포함 × (1 + (캡배율 − 1) × origin 이후) × (헤지비율 × 헤지환율 + (1 − 헤지비율) × 건조시점 환율) | J20: subQ 매출조선 = 합계/100 + 변수 잔고 소진 + 매출조선신규
A21: 헤지비율 | D21: =변수!$D$60 | E21: 변수 3절 '헤지비율' 참조 — 통화선도 공시 없음 → HEDGE 70% 가정(레퍼런스 SLS 시트 HEDGE 행은 미포 65%·삼성重 100% — 그 사이에 둔 설정값). hedge_rate 는 계약별 수주시점 환율로 대체
A22: 헤지환율 방식 | D22: 계약별 수주시점 환율(fx_at_sign)
A23: spot_krw | D23: 건조시점 원/달러(평균) — 변수 환율 행 참조, 변수 범위 밖 분기는 sls spot_assumed | E23: =IFERROR(VLOOKUP(" 원/달러(평균)",환율,MATCH(E$1,변수H,0),0),1386.95) | F23: =IFERROR(VLOOKUP(" 원/달러(평균)",환율,MATCH(F$1,변수H,0),0),1449.19) | G23: =IFERROR(VLOOKUP(" 원/달러(평균)",환율,MATCH(G$1,변수H,0),0),1466.12) | H23: =IFERROR(VLOOKUP(" 원/달러(평균)",환율,MATCH(H$1,변수H,0),0),1501.75) | I23: =IFERROR(VLOOKUP(" 원/달러(평균)",환율,MATCH(I$1,변수H,0),0),1418.75) | J23: =IFERROR(VLOOKUP(" 원/달러(평균)",환율,MATCH(J$1,변수H,0),0),1343.39) | K23: =IFERROR(VLOOKUP(" 원/달러(평균)",환율,MATCH(K$1,변수H,0),0),1341.45) | L23: =IFERROR(VLOOKUP(" 원/달러(평균)",환율,MATCH(L$1,변수H,0),0),1341.45) | M23: =IFERROR(VLOOKUP(" 원/달러(평균)",환율,MATCH(M$1,변수H,0),0),1341.45) | N23: =IFERROR(VLOOKUP(" 원/달러(평균)",환율,MATCH(N$1,변수H,0),0),1341.45) | O23: =IFERROR(VLOOKUP(" 원/달러(평균)",환율,MATCH(O$1,변수H,0),0),1341.45) | P23: =IFERROR(VLOOKUP(" 원/달러(평균)",환율,MATCH(P$1,변수H,0),0),1341.45) | Q23: =IFERROR(VLOOKUP(" 원/달러(평균)",환율,MATCH(Q$1,변수H,0),0),1341.45) | R23: =IFERROR(VLOOKUP(" 원/달러(평균)",환율,MATCH(R$1,변수H,0),0),1341.45) | ... V23: =IFERROR(VLOOKUP(" 원/달러(평균)",환율,MATCH(V$1,변수H,0),0),1341.45)
A24: after_origin | D24: origin(2026Q2) 이후 분기 = 1 (잔고 캡 배율 적용 구간) | E24: 0 | F24: 0 | G24: 0 | H24: 0 | I24: 1 | J24: 1 | K24: 1 | L24: 1 | M24: 1 | N24: 1 | O24: 1 | P24: 1 | Q24: 1 | R24: 1 | S24: 1 | T24: 1 | U24: 1 | V24: 1
A26: ① 계약별 매출인식 스케줄(백만$, sls 저장값) | B26: type | C26: ships | D26: name | AC26: 포함(1/0) | AD26: 헤지환율 | AE26: 캡배율 | AF26: 체결일 | AG26: origin이내 | AH26: 코호트 | AI26: 계약액(백만$) | AJ26: 종료
A27: 20250922800050 | B27: VLCC | C27: 4 | D27: 원유운반선(157,200 DWT) 4척 | E27: 3.711 | F27: 28.455 | G27: 27.836 | H27: 28.145 | I27: 28.455 | J27: 28.455 | K27: 27.836 | L27: 28.145 | M27: 28.455 | N27: 28.455 | O27: 28.145 | P27: 28.145 | Q27: 28.456 | AC27: 1 | AD27: 1386.95 | AE27: 0.859276 | AF27: 2025-09-19 | AG27: 1 | AH27: ⑤초호황 | AI27: 342.694 | AJ27: 2028-09-30
A28: 20250922800051 | B28: VLCC | C28: 2 | D28: 원유운반선(157,000 DWT) 2척 | E28: 2.793 | F28: 21.411 | G28: 20.945 | H28: 21.178 | I28: 21.411 | J28: 21.411 | K28: 20.945 | L28: 21.178 | M28: 21.409 | AC28: 1 | AD28: 1386.95 | AE28: 0.859276 | AF28: 2025-09-19 | AG28: 1 | AH28: ⑤초호황 | AI28: 172.681 | AJ28: 2027-09-30
A29: 20250930800053 | B29: VLCC | C29: 1 | D29: 원유운반선(157,000 DWT) 1척 | E29: 0.276 | F29: 12.676 | G29: 12.4 | H29: 12.538 | I29: 12.676 | J29: 12.676 | K29: 12.4 | L29: 12.537 | AC29: 1 | AD29: 1386.95 | AE29: 0.859276 | AF29: 2025-09-29 | AG29: 1 | AH29: ⑤초호황 | AI29: 88.179 | AJ29: 2027-06-30
A30: 20251001800065 | B30: VLCC | C30: 1 | D30: 원유운반선(157,000 DWT) 1척 | E30: 0.113 | F30: 10.376 | G30: 10.151 | H30: 10.264 | I30: 10.376 | J30: 10.376 | K30: 10.151 | L30: 10.264 | M30: 10.376 | N30: 3.497 | AC30: 1 | AD30: 1386.95 | AE30: 0.859276 | AF30: 2025-09-30 | AG30: 1 | AH30: ⑤초호황 | AI30: 85.944 | AJ30: 2027-10-31
A31: 20251015800073 | B31: CONT | C31: 2 | D31: 컨테이너선 2척 | F31: 18.142 | G31: 20.668 | H31: 20.897 | I31: 21.127 | J31: 21.127 | K31: 20.668 | L31: 20.897 | M31: 21.127 | N31: 21.127 | O31: 20.897 | P31: 20.898 | AC31: 1 | AD31: 1449.19 | AE31: 0.859276 | AF31: 2025-10-14 | AG31: 1 | AH31: ⑤초호황 | AI31: 227.575 | AJ31: 2028-06-30
A32: 20251118800028 | B32: VLCC | C32: 1 | D32: 원유운반선(157,000 DWT) 1척 | F32: 5.105 | G32: 10.209 | H32: 10.322 | I32: 10.436 | J32: 10.436 | K32: 10.209 | L32: 10.322 | M32: 10.436 | N32: 10.436 | AC32: 1 | AD32: 1449.19 | AE32: 0.859276 | AF32: 2025-11-17 | AG32: 1 | AH32: ⑤초호황 | AI32: 87.911 | AJ32: 2027-12-31
A33: 20260114800029 | B33: VLCC | C33: 2 | D33: 원유운반선(157,000 DWT) 2척 | G33: 12.722 | H33: 14.842 | I33: 15.005 | J33: 15.005 | K33: 14.679 | L33: 14.842 | M33: 15.005 | N33: 15.005 | O33: 14.842 | P33: 14.842 | Q33: 15.005 | R33: 9.952 | AC33: 1 | AD33: 1466.12 | AE33: 0.859276 | AF33: 2026-01-13 | AG33: 1 | AH33: ⑤초호황 | AI33: 171.746 | AJ33: 2028-11-30
A34: 20260115800029 | B34: VLCC | C34: 2 | D34: 원유운반선(157,000 DWT) 2척 | G34: 11.085 | H34: 13.1 | I34: 13.244 | J34: 13.244 | K34: 12.956 | L34: 13.1 | M34: 13.244 | N34: 13.244 | O34: 13.1 | P34: 13.1 | Q34: 13.244 | R34: 13.244 | S34: 12.956 | T34: 4.317 | AC34: 1 | AD34: 1466.12 | AE34: 0.859276 | AF34: 2026-01-14 | AG34: 1 | AH34: ⑤초호황 | AI34: 173.178 | AJ34: 2029-04-30
A35: 20260129800084 | B35: VLCC | C35: 2 | D35: 원유운반선(157,000 DWT) 2척 | G35: 8.95 | H35: 12.928 | I35: 13.07 | J35: 13.07 | K35: 12.786 | L35: 12.928 | M35: 13.07 | N35: 13.07 | O35: 12.928 | P35: 12.928 | Q35: 13.07 | R35: 13.07 | S35: 12.786 | T35: 8.661 | AC35: 1 | AD35: 1466.12 | AE35: 0.859276 | AF35: 2026-01-28 | AG35: 1 | AH35: ⑤초호황 | AI35: 173.315 | AJ35: 2029-05-31
A36: 20260209800078 | B36: VLCC | C36: 2 | D36: 원유운반선(157,000 DWT) 2척 | G36: 9.024 | H36: 15.207 | I36: 15.374 | J36: 15.374 | K36: 15.04 | L36: 15.207 | M36: 15.374 | N36: 15.374 | O36: 15.207 | P36: 15.207 | Q36: 15.374 | R36: 15.372 | AC36: 1 | AD36: 1466.12 | AE36: 0.859276 | AF36: 2026-02-06 | AG36: 1 | AH36: ⑤초호황 | AI36: 177.134 | AJ36: 2028-12-31
A37: 20260317800064 | B37: VLCC | C37: 1 | D37: 원유운반선(157,000 DWT) 1척 | G37: 1.115 | H37: 6.34 | I37: 6.41 | J37: 6.41 | K37: 6.27 | L37: 6.34 | M37: 6.41 | N37: 6.41 | O37: 6.34 | P37: 6.34 | Q37: 6.41 | R37: 6.41 | S37: 6.27 | T37: 6.34 | U37: 6.41 | V37: 0.695 | AC37: 1 | AD37: 1466.12 | AE37: 0.859276 | AF37: 2026-03-16 | AG37: 1 | AH37: ⑤초호황 | AI37: 90.92 | AJ37: 2029-10-10
A38: 20260323800069 | B38: VLCC | C38: 1 | D38: 원유운반선(157,000 DWT) 1척 | G38: 0.913 | H38: 6.926 | I38: 7.003 | J38: 7.003 | K38: 6.85 | L38: 6.926 | M38: 7.003 | N38: 7.003 | O38: 6.926 | P38: 6.926 | Q38: 7.003 | R38: 7.003 | S38: 6.85 | T38: 6.926 | AC38: 1 | AD38: 1466.12 | AE38: 0.859276 | AF38: 2026-03-20 | AG38: 1 | AH38: ⑤초호황 | AI38: 91.261 | AJ38: 2029-06-30
A39: 20260331800063 | B39: VLCC | C39: 2 | D39: 원유운반선(157,000 DWT) 2척 | G39: 0.294 | H39: 13.373 | I39: 13.52 | J39: 13.52 | K39: 13.226 | L39: 13.373 | M39: 13.52 | N39: 13.52 | O39: 13.373 | P39: 13.373 | Q39: 13.52 | R39: 13.52 | S39: 13.226 | T39: 13.373 | U39: 13.521 | AC39: 1 | AD39: 1466.12 | AE39: 0.859276 | AF39: 2026-03-30 | AG39: 1 | AH39: ⑤초호황 | AI39: 188.252 | AJ39: 2029-09-30
A40: 20260416800003 | B40: VLCC | C40: 1 | D40: 원유운반선(157,000 DWT) 1척 | H40: 5.728 | I40: 6.757 | J40: 6.757 | K40: 6.61 | L40: 6.683 | M40: 6.757 | N40: 6.757 | O40: 6.683 | P40: 6.683 | Q40: 6.757 | R40: 6.757 | S40: 6.61 | T40: 6.683 | U40: 2.275 | AC40: 1 | AD40: 1501.75 | AE40: 0.859276 | AF40: 2026-04-14 | AG40: 1 | AH40: ⑤초호황 | AI40: 88.497 | AJ40: 2029-07-31
A41: 20260601800013 | B41: VLCC | C41: 2 | D41: 원유운반선(157,000 DWT) 2척 | H41: 6.555 | I41: 18.275 | J41: 18.275 | K41: 17.878 | L41: 18.077 | M41: 18.275 | N41: 18.275 | O41: 18.077 | P41: 18.077 | Q41: 18.275 | R41: 18.275 | AC41: 1 | AD41: 1501.75 | AE41: 0.859276 | AF41: 2026-05-29 | AG41: 1 | AH41: ⑤초호황 | AI41: 188.314 | AJ41: 2028-12-31
A42: 20260727800063 | B42: VLCC | C42: 2 | D42: 원유운반선(157,000 DWT) 2척 | I42: 10.497 | J42: 13.996 | K42: 13.692 | L42: 13.844 | M42: 13.996 | N42: 13.996 | O42: 13.844 | P42: 13.844 | Q42: 13.996 | R42: 13.996 | S42: 13.692 | T42: 13.844 | U42: 13.996 | V42: 13.992 | AC42: 0 | AD42: 1418.75 | AE42: 1 | AF42: 2026-07-24 | AG42: 0 | AH42: ⑤초호황 | AI42: 191.225 | AJ42: 2029-12-31
...

Sheet 시나리오
C1: 신규수주 시나리오(억원) — subQ 기준값 ± (시나리오 신규 − base 신규) × OPM | E1: 3Q26 | F1: 4Q26 | G1: 2026 | H1: 1Q27 | I1: 2Q27 | J1: 3Q27 | K1: 4Q27 | L1: 2027 | M1: 1Q28 | N1: 2Q28 | O1: 3Q28 | P1: 4Q28 | Q1: 2028
A2: 출처: forecast_panel.json.gz scenarios.{conservative,base,optimistic}.quarterly[].new_order_revenue (KRW_million → 억원 ÷100) — 공시 수주 체결 분기별 상계 후(net_panel) · calibrated=False · 행(subQ)에 포함된 시나리오: base. 보수/낙관/기존만 은 합산하지 않는다. 모델 산출값 — 목표주가·추천 아님
A3: 매출 = 기존(선표+잔고 소진+기타) + 시나리오 신규수주 매출; 영업이익 = 행 영업이익 + (시나리오 신규 − base 신규) × base OPM 경로. 보수/낙관·existing_only 는 행에 합산하지 않음(base 는 행과 동일). 모델 산출값 — 목표주가·추천 아님 | E3: 1 | F3: 2 | G3: 3 | H3: 4 | I3: 5 | J3: 6 | K3: 7 | L3: 8 | M3: 9 | N3: 10 | O3: 11 | P3: 12 | Q3: 13
E4: 2026.09 | F4: 2026.12 | G4: 2026.12A | H4: 2027.03 | I4: 2027.06 | J4: 2027.09 | K4: 2027.12 | L4: 2027.12A | M4: 2028.03 | N4: 2028.06 | O4: 2028.09 | P4: 2028.12 | Q4: 2028.12A
A5: base | D5: 기준(base — subQ 행에 포함) — 행에 포함
A6: scn:base:신규수주매출 | C6: 억원 | D6: 신규수주 매출(억원) — subQ 매출조선신규 참조 | E6: =subQ!K39 | F6: =subQ!L39 | G6: =SUM(E6:F6) | H6: =subQ!N39 | I6: =subQ!O39 | J6: =subQ!P39 | K6: =subQ!Q39 | L6: =SUM(H6:K6) | M6: =subQ!S39 | N6: =subQ!T39 | O6: =subQ!U39 | P6: =subQ!V39 | Q6: =SUM(M6:P6)
A7: scn:base:매출액 | C7: 억원 | D7: 매출액 = subQ 매출액 − base 신규 + 이 시나리오 신규 | E7: =IFERROR(subQ!K5-E6+E6,"") | F7: =IFERROR(subQ!L5-F6+F6,"") | G7: =IFERROR(SUM(E7:F7)+subQ!I5+subQ!J5,"") | H7: =IFERROR(subQ!N5-H6+H6,"") | I7: =IFERROR(subQ!O5-I6+I6,"") | J7: =IFERROR(subQ!P5-J6+J6,"") | K7: =IFERROR(subQ!Q5-K6+K6,"") | L7: =IFERROR(SUM(H7:K7),"") | M7: =IFERROR(subQ!S5-M6+M6,"") | N7: =IFERROR(subQ!T5-N6+N6,"") | O7: =IFERROR(subQ!U5-O6+O6,"") | P7: =IFERROR(subQ!V5-P6+P6,"") | Q7: =IFERROR(SUM(M7:P7),"")
