Workbook
Name 변수H: 변수!$C$1:$AB$1
Name 환율: 변수!$C$6:$AB$13
Name BS연결H: BS연결!$C$1:$AB$1
Name BS연결: BS연결!$C$5:$AB$107
Name BS별도H: BS별도!$C$1:$AB$1
Name BS별도: BS별도!$C$5:$AB$90
Name SUBQH: subQ!$A$1:$AB$1
Name subQ: subQ!$A$5:$AB$43

Sheet README
A1: HD현대마린솔루션(443060) 실적 모델 — ARGUS 한국조선
A2: 기준 분기 2026Q2 · 마지막 실적 2026Q2 · 생성 2026-10-13
A3: 모든 수치는 모델 산출값(DART 공개 재무제표 + 우리 추정)이다 — 목표주가·투자 추천 아님. 참고용 · 투자조언 아님.
A5: 시트
A6: 변수 가정 시계열. 환율 8행(ECB via frankfurter — L2 fx.json; 추정 분기 = 노란 가정), 추정 드라이버(노란 셀 = 모델값에서 역산한 가정, 바꾸면 재계산; 연녹 셀 = 3절 스칼라 참조 수식), 3절 스칼라 가정(세율·판관비율·지배주주비중·이자율·종가·PER 밴드·COE·외화 순노출·헤지비율)
A7: BS연결/BS별도 FnGuide 계정명 × 기간 값 덤프(백만원). 행1 분기라벨, 행4 YYYY.MM / YYYY.12A. 이름정의 BS연결H·BS연결(계정명 C열부터)
A8: subQ 분기 서브모델(억원 = 백만원/100). 확정 행: =IFERROR(VLOOKUP($D행,BS연결,MATCH(E$1,BS연결H,0),0)/100,"") 추정 행: 변수 시트 가정 셀 참조 수식. 외환손익·파생상품손익은 BS 계정 합·차, 기타금융손익은 잔차, OPM·EPS·BPS·PER·PBR 은 파생 수식
A9: SLS 선표(조선사만, sls json 있을 때): 요약 행(sls 저장값) + 계약별 스케줄(백만$) × (헤지비율 × 헤지환율 + (1−헤지비율) × 건조시점 환율[변수 원/달러(평균)]) → 원화 수식 블록 → 합계 행이 subQ 매출조선에 연결
A10: 시나리오 신규수주 보수/기준/낙관(forecast_panel 패널, 모델에 scenarios 가 있을 때만): 매출액·영업이익 = subQ 기준값 ± (시나리오 신규 − base 신규) × OPM. base 만 subQ 행에 포함, 나머지는 합산 안 함
A11: 분기/연간예상 subQ 를 이름(A열 key)으로 VLOOKUP 한 보고서 표(억원)
A12: TP PER 밴드 × 12M fwd EPS, PBR = ROE/COE × BPS — 모델 산출값 구간, 목표주가·추천 아님
A13: 외화 환율 QoQ, 외화 순노출 × Δ기말환율 → 환관련손익 추정
... A34: 백테스트: {"freeze": "2025Q2", "horizon": 4, "revenue_wape_pct": 5.3, "op_wape_pct": 4.2, "n": 4, "note": "단일 회사 4분기 — 통계 아님", "driver_at_freeze": "customer_yard_revenue_weighted", "selection_oos_at_freeze": {"freeze": "2024Q2", "n": 4, "wape_link": null, "wape_trend": null, "adopted": "undetermined", "decision": "undetermined", "note": "동결 2024Q2 이전 실적 1분기(<8) 또는 이후 실측 4분기 → OOS 비교 불가(undetermined), 유의성 조건만으로 채택"}, "frozen_inputs": "fin(연결/별도)·고객 조선사 모델·지주 자회사 모델은 2025Q2 까지의 분기만; 선표는 체결일 ≤ 2025Q2 말일 계약(원장 최신 금액·코호트 등급, 환산 없음); 잔고는 yards_cache 2025Q2; 시세·환율 forward·prices·forecast_panel 신규수주 미사용. 고객 가중치(suppliers.json 언급 비중)와 합병 체인링크는 현재 지식; 고객 연동 채택은 동결 모델 안에서도 자기 la−4분기 OOS 규칙(selection_oos_at_freeze)", "detail": [{"q": "2025Q3", "rev_pred": 5231.84, "rev_act": 5131.76, "op_pred": 894.32, "op_act": 935.96}, {"q": "2025Q4", "rev_pred": 5239.23, "rev_act": 5162.05, "op_pred": 895.58, "op_act": 905.28}, {"q": "2026Q1", "rev_pred": 5317.65, "rev_act": 5746.09, "op_pred": 908.99, "op_act": 933.94}, {"q": "2026Q2", "rev_pred": 5245.03, "rev_act": 5804.14, "op_pred": 896.57, "op_act": 976.25}]}

Sheet 변수
C1: 이름: 변수H | E1: 2Q24 | F1: 3Q24 | G1: 4Q24 | H1: 2024 | I1: 1Q25 | J1: 2Q25 | K1: 3Q25 | L1: 4Q25 | M1: 2025 | N1: 1Q26 | O1: 2Q26 | P1: 3Q26 | Q1: 4Q26 | R1: 2026 | S1: 1Q27 | T1: 2Q27 | U1: 3Q27 | V1: 4Q27 | W1: 2027 | X1: 1Q28 | Y1: 2Q28 | Z1: 3Q28 | AA1: 4Q28 | AB1: 2028
A2: 가정 시계열 — 노란 셀은 추정 가정(모델값에서 역산), 연녹 셀은 3절 스칼라 참조 수식. 바꾸면 subQ·분기·연간예상·TP·시나리오가 재계산됩니다.
E3: 1 | F3: 2 | G3: 3 | H3: 4 | I3: 5 | J3: 6 | K3: 7 | L3: 8 | M3: 9 | N3: 10 | O3: 11 | P3: 12 | Q3: 13 | R3: 14 | S3: 15 | T3: 16 | U3: 17 | V3: 18 | W3: 19 | X3: 20 | Y3: 21 | Z3: 22 | AA3: 23 | AB3: 24
E4: 2024.06 | F4: 2024.09 | G4: 2024.12 | H4: 2024.12A | I4: 2025.03 | J4: 2025.06 | K4: 2025.09 | L4: 2025.12 | M4: 2025.12A | N4: 2026.03 | O4: 2026.06 | P4: 2026.09 | Q4: 2026.12 | R4: 2026.12A | S4: 2027.03 | T4: 2027.06 | U4: 2027.09 | V4: 2027.12 | W4: 2027.12A | X4: 2028.03 | Y4: 2028.06 | Z4: 2028.09 | AA4: 2028.12 | AB4: 2028.12A
B5: 1. FX | C5: 이름: 환율
A6: USDKRW_avg | C6: 원/달러(평균) | E6: 1371.28 | F6: 1356.22 | G6: 1396.3 | H6: 1363.53 | I6: 1452.28 | J6: 1398.52 | K6: 1386.95 | L6: 1449.19 | M6: 1421.52 | N6: 1466.12 | O6: 1501.75 | P6: 1418.75 | Q6: 1343.63 | R6: 1456.58 | S6: 1333.09 | T6: 1333.09 | U6: 1333.09 | V6: 1333.09 | X6: 1333.09 | Y6: 1333.09 | Z6: 1333.09 | AA6: 1333.09
A7: USDKRW_end | C7: 원/달러(기말) | E7: 1377.73 | F7: 1312.17 | G7: 1474.78 | H7: 1474.78 | I7: 1474.54 | J7: 1355.13 | K7: 1403.67 | L7: 1444.2 | M7: 1444.2 | N7: 1524.8 | O7: 1550.89 | P7: 1355.4 | Q7: 1333.09 | R7: 1333.09 | S7: 1333.09 | T7: 1333.09 | U7: 1333.09 | V7: 1333.09 | X7: 1333.09 | Y7: 1333.09 | Z7: 1333.09 | AA7: 1333.09
A8: JPY100KRW_avg | C8: 원/100Y(평균) | E8: 880.14 | F8: 909.35 | G8: 917.25 | H8: 900.92 | I8: 952.59 | J8: 967.92 | K8: 940.32 | L8: 940.77 | M8: 950.17 | N8: 934.39 | O8: 942.16 | P8: 890.41 | Q8: 849.51 | R8: 918.81 | S8: 840.54 | T8: 840.54 | U8: 840.54 | V8: 840.54 | X8: 840.54 | Y8: 840.54 | Z8: 840.54 | AA8: 840.54
A9: JPY100KRW_end | C9: 원/100Y(기말) | E9: 857.76 | F9: 919.21 | G9: 939.65 | H9: 939.65 | I9: 986.84 | J9: 938.85 | K9: 948.49 | L9: 921.81 | M9: 921.81 | N9: 955.99 | O9: 954.75 | P9: 863.31 | Q9: 840.54 | R9: 840.54 | S9: 840.54 | T9: 840.54 | U9: 840.54 | V9: 840.54 | X9: 840.54 | Y9: 840.54 | Z9: 840.54 | AA9: 840.54
A10: EURKRW_avg | C10: W/Euro(평균) | E10: 1476.42 | F10: 1489.3 | G10: 1490.78 | H10: 1475.4 | I10: 1528.33 | J10: 1585.13 | K10: 1620.04 | L10: 1686.02 | M10: 1605.45 | N10: 1715.47 | O10: 1746.09 | P10: 1631.97 | Q10: 1507.34 | R10: 1688.95 | S10: 1490.54 | T10: 1490.54 | U10: 1490.54 | V10: 1490.54 | X10: 1490.54 | Y10: 1490.54 | Z10: 1490.54 | AA10: 1490.54
A11: EURKRW_end | C11: W/Euro(기말) | E11: 1474.86 | F11: 1469.1 | G11: 1532.14 | H11: 1532.14 | I11: 1594.72 | J11: 1588.22 | K11: 1648.04 | L11: 1696.94 | M11: 1696.94 | N11: 1753.21 | O11: 1767.09 | P11: 1539.06 | Q11: 1490.54 | R11: 1490.54 | S11: 1490.54 | T11: 1490.54 | U11: 1490.54 | V11: 1490.54 | X11: 1490.54 | Y11: 1490.54 | Z11: 1490.54 | AA11: 1490.54
A12: CNYKRW_avg | C12: 원/중국원(평균) | E12: 189.35 | F12: 189.24 | G12: 194.24 | H12: 189.49 | I12: 199.63 | J12: 193.41 | K12: 193.79 | L12: 204.38 | M12: 197.8 | N12: 211.75 | O12: 220.8 | P12: 210.43 | Q12: 200.5 | R12: 213.68 | S12: 199.18 | T12: 199.18 | U12: 199.18 | V12: 199.18 | X12: 199.18 | Y12: 199.18 | Z12: 199.18 | AA12: 199.18
A13: CNYKRW_end | C13: 원/중국원(기말) | E13: 189.7 | F13: 187.12 | G13: 202.04 | H13: 202.04 | I13: 203.3 | J13: 189.14 | K13: 197.16 | L13: 206.28 | M13: 206.28 | N13: 220.97 | O13: 228.56 | P13: 202.16 | Q13: 199.18 | R13: 199.18 | S13: 199.18 | T13: 199.18 | U13: 199.18 | V13: 199.18 | X13: 199.18 | Y13: 199.18 | Z13: 199.18 | AA13: 199.18
B14: 1b. 종가
A15: price_close_end | C15: 종가(기말) | E15: 130000 | F15: 103700 | G15: 161400 | I15: 133800 | J15: 205500 | K15: 210000 | L15: 193500 | N15: 179600 | O15: 224500 | P15: 237500 | Q15: 226000
A16: price_high | C16: 종가(최고) | E16: 207500 | F16: 145000 | G16: 164800 | I16: 199600 | J16: 215000 | K16: 227500 | L16: 257000 | N16: 202000 | O16: 287000 | P16: 254000 | Q16: 240500
A17: price_low | C17: 종가(최저) | E17: 111500 | F17: 99500 | G17: 101900 | I17: 126200 | J17: 135000 | K17: 174600 | L17: 179600 | N17: 158000 | O17: 170000 | P17: 175000 | Q17: 212500
A18: price_avg | C18: 종가(평균) | E18: 150119.4 | F18: 116051.6 | G18: 136139.3 | I18: 154941.4 | J18: 172028.3 | K18: 199518.5 | L18: 213530.5 | N18: 180433.9 | O18: 224118 | P18: 209638.7 | Q18: 225357.1
B20: 2. 추정 드라이버 | C20: 실적 열 = subQ 실현값(수식), 추정 열 = 가정(노란 = 모델값 역산, 연녹 = 3절 스칼라 참조)
A21: drv:매출액 | B21: yoy | C21: 매출액 YoY | J21: =IFERROR(subQ!J5/subQ!E5-1,"") | K21: =IFERROR(subQ!K5/subQ!F5-1,"") | L21: =IFERROR(subQ!L5/subQ!G5-1,"") | N21: =IFERROR(subQ!N5/subQ!I5-1,"") | O21: =IFERROR(subQ!O5/subQ!J5-1,"") | P21: 0.11093848 | Q21: 0.19046643 | S21: 0.1559989 | T21: 0.19194085 | U21: 0.22879039 | V21: 0.16928197 | X21: 0.13774545 | Y21: 0.15273648 | Z21: 0.21010589 | AA21: 0.25280668
A22: drv:판관비 | B22: ratio | C22: 판관비율(/매출) | E22: =IFERROR(subQ!E8/subQ!E5,"") | F22: =IFERROR(subQ!F8/subQ!F5,"") | G22: =IFERROR(subQ!G8/subQ!G5,"") | H22: =IFERROR(subQ!H8/subQ!H5,"") | I22: =IFERROR(subQ!I8/subQ!I5,"") | J22: =IFERROR(subQ!J8/subQ!J5,"") | K22: =IFERROR(subQ!K8/subQ!K5,"") | L22: =IFERROR(subQ!L8/subQ!L5,"") | ... O22: =IFERROR(subQ!O8/subQ!O5,"") | P22: =$D$52 | Q22: =$D$52 | R22: =IFERROR(subQ!R8/subQ!R5,"") | S22: =$D$52 | T22: =$D$52 | U22: =$D$52 | V22: =$D$52 | W22: =IFERROR(subQ!W8/subQ!W5,"") | X22: =$D$52 | Y22: =$D$52 | Z22: =$D$52 | AA22: =$D$52 | AB22: =IFERROR(subQ!AB8/subQ!AB5,"")
A23: drv:영업이익 | B23: ratio | C23: 영업이익률(OPM) | E23: =IFERROR(subQ!E9/subQ!E5,"") | F23: =IFERROR(subQ!F9/subQ!F5,"") | G23: =IFERROR(subQ!G9/subQ!G5,"") | H23: =IFERROR(subQ!H9/subQ!H5,"") | I23: =IFERROR(subQ!I9/subQ!I5,"") | J23: =IFERROR(subQ!J9/subQ!J5,"") | K23: =IFERROR(subQ!K9/subQ!K5,"") | L23: =IFERROR(subQ!L9/subQ!L5,"") | ... O23: =IFERROR(subQ!O9/subQ!O5,"") | P23: 0.17315522 | Q23: 0.17315488 | R23: =IFERROR(subQ!R9/subQ!R5,"") | S23: 0.17315547 | T23: 0.17315512 | U23: 0.1731545 | V23: 0.17315494 | W23: =IFERROR(subQ!W9/subQ!W5,"") | X23: 0.1731552 | Y23: 0.17315561 | Z23: 0.17315537 | AA23: 0.17315554 | AB23: =IFERROR(subQ!AB9/subQ!AB5,"")
A24: drv:외환손익 | B24: abs | C24: 외환손익 (가정, 억원) | E24: =subQ!E13 | F24: =subQ!F13 | G24: =subQ!G13 | H24: =subQ!H13 | I24: =subQ!I13 | J24: =subQ!J13 | K24: =subQ!K13 | L24: =subQ!L13 | ... O24: =subQ!O13 | P24: 0 | Q24: 0 | R24: =subQ!R13 | S24: 0 | T24: 0 | U24: 0 | V24: 0 | W24: =subQ!W13 | X24: 0 | Y24: 0 | Z24: 0 | AA24: 0 | AB24: =subQ!AB13
A25: drv:파생상품손익 | B25: abs | C25: 파생상품손익 (가정, 억원) | E25: =subQ!E14 | F25: =subQ!F14 | G25: =subQ!G14 | H25: =subQ!H14 | I25: =subQ!I14 | J25: =subQ!J14 | K25: =subQ!K14 | L25: =subQ!L14 | ... O25: =subQ!O14 | P25: 0 | Q25: 0 | R25: =subQ!R14 | S25: 0 | T25: 0 | U25: 0 | V25: 0 | W25: =subQ!W14 | X25: 0 | Y25: 0 | Z25: 0 | AA25: 0 | AB25: =subQ!AB14
A26: drv:기타금융손익 | B26: abs | C26: 기타금융손익 (가정, 억원) | E26: =subQ!E15 | F26: =subQ!F15 | G26: =subQ!G15 | H26: =subQ!H15 | I26: =subQ!I15 | J26: =subQ!J15 | K26: =subQ!K15 | L26: =subQ!L15 | ... O26: =subQ!O15 | P26: 0 | Q26: 0 | R26: =subQ!R15 | S26: 0 | T26: 0 | U26: 0 | V26: 0 | W26: =subQ!W15 | X26: 0 | Y26: 0 | Z26: 0 | AA26: 0 | AB26: =subQ!AB15
A27: drv:기타영업외손익 | B27: abs | C27: 기타영업외손익 (가정, 억원) | E27: =subQ!E16 | F27: =subQ!F16 | G27: =subQ!G16 | H27: =subQ!H16 | I27: =subQ!I16 | J27: =subQ!J16 | K27: =subQ!K16 | L27: =subQ!L16 | ... O27: =subQ!O16 | P27: 0 | Q27: 0 | R27: =subQ!R16 | S27: 0 | T27: 0 | U27: 0 | V27: 0 | W27: =subQ!W16 | X27: 0 | Y27: 0 | Z27: 0 | AA27: 0 | AB27: =subQ!AB16
A28: drv:지분법손익 | B28: abs | C28: 지분법손익 (가정, 억원) | E28: =subQ!E17 | F28: =subQ!F17 | G28: =subQ!G17 | H28: =subQ!H17 | I28: =subQ!I17 | J28: =subQ!J17 | K28: =subQ!K17 | L28: =subQ!L17 | ... O28: =subQ!O17 | P28: -0.52 | Q28: -0.52 | R28: =subQ!R17 | S28: -0.52 | T28: -0.52 | U28: -0.52 | V28: -0.52 | W28: =subQ!W17 | X28: -0.52 | Y28: -0.52 | Z28: -0.52 | AA28: -0.52 | AB28: =subQ!AB17
A29: drv:법인세비용 | B29: tax | C29: 법인세율(/세전) — 법인세 = MAX(세전,0) × 세율 | E29: =IFERROR(subQ!E19/subQ!E18,"") | F29: =IFERROR(subQ!F19/subQ!F18,"") | G29: =IFERROR(subQ!G19/subQ!G18,"") | H29: =IFERROR(subQ!H19/subQ!H18,"") | I29: =IFERROR(subQ!I19/subQ!I18,"") | J29: =IFERROR(subQ!J19/subQ!J18,"") | K29: =IFERROR(subQ!K19/subQ!K18,"") | L29: =IFERROR(subQ!L19/subQ!L18,"") | ... O29: =IFERROR(subQ!O19/subQ!O18,"") | P29: =$D$51 | Q29: =$D$51 | R29: =IFERROR(subQ!R19/subQ!R18,"") | S29: =$D$51 | T29: =$D$51 | U29: =$D$51 | V29: =$D$51 | W29: =IFERROR(subQ!W19/subQ!W18,"") | X29: =$D$51 | Y29: =$D$51 | Z29: =$D$51 | AA29: =$D$51 | AB29: =IFERROR(subQ!AB19/subQ!AB18,"")
A30: drv:지배주주순이익 | B30: ratio | C30: 지배주주 비중(/당기순이익) | E30: =IFERROR(subQ!E21/subQ!E20,"") | F30: =IFERROR(subQ!F21/subQ!F20,"") | G30: =IFERROR(subQ!G21/subQ!G20,"") | H30: =IFERROR(subQ!H21/subQ!H20,"") | I30: =IFERROR(subQ!I21/subQ!I20,"") | J30: =IFERROR(subQ!J21/subQ!J20,"") | K30: =IFERROR(subQ!K21/subQ!K20,"") | L30: =IFERROR(subQ!L21/subQ!L20,"") | ... O30: =IFERROR(subQ!O21/subQ!O20,"") | P30: =$D$53 | Q30: =$D$53 | R30: =IFERROR(subQ!R21/subQ!R20,"") | S30: =$D$53 | T30: =$D$53 | U30: =$D$53 | V30: =$D$53 | W30: =IFERROR(subQ!W21/subQ!W20,"") | X30: =$D$53 | Y30: =$D$53 | Z30: =$D$53 | AA30: =$D$53 | AB30: =IFERROR(subQ!AB21/subQ!AB20,"")
A31: drv:부채총계 | B31: qoq | C31: 부채총계 QoQ | F31: =IFERROR(subQ!F23/subQ!E23-1,"") | G31: =IFERROR(subQ!G23/subQ!F23-1,"") | I31: =IFERROR(subQ!I23/subQ!G23-1,"") | J31: =IFERROR(subQ!J23/subQ!I23-1,"") | K31: =IFERROR(subQ!K23/subQ!J23-1,"") | L31: =IFERROR(subQ!L23/subQ!K23-1,"") | N31: =IFERROR(subQ!N23/subQ!L23-1,"") | O31: =IFERROR(subQ!O23/subQ!N23-1,"") | P31: -4.81e-07 | Q31: 0 | S31: 0 | T31: 0 | U31: 0 | V31: 0 | X31: 0 | Y31: 0 | Z31: 0 | AA31: 0
A32: drv:자본총계 | B32: roll | C32: 자본총계 기타변동(배당 등, 억원) | F32: =IFERROR(subQ!E24+subQ!F20-subQ!F24,"") | G32: =IFERROR(subQ!F24+subQ!G20-subQ!G24,"") | I32: =IFERROR(subQ!G24+subQ!I20-subQ!I24,"") | J32: =IFERROR(subQ!I24+subQ!J20-subQ!J24,"") | K32: =IFERROR(subQ!J24+subQ!K20-subQ!K24,"") | L32: =IFERROR(subQ!K24+subQ!L20-subQ!L24,"") | N32: =IFERROR(subQ!L24+subQ!N20-subQ!N24,"") | O32: =IFERROR(subQ!N24+subQ!O20-subQ!O24,"") | P32: -0.005273056 | Q32: 0.00258669 | S32: -0.003946904 | T32: 1770.9265 | U32: -0.008338569 | V32: -0.009190603 | X32: 0.004733472 | Y32: 1770.9223 | Z32: 0.000603265 | AA32: -0.004683931
A33: drv:지배주주지분 | B33: roll | C33: 지배주주지분 기타변동(배당 등, 억원) | F33: =IFERROR(subQ!E25+subQ!F21-subQ!F25,"") | G33: =IFERROR(subQ!F25+subQ!G21-subQ!G25,"") | I33: =IFERROR(subQ!G25+subQ!I21-subQ!I25,"") | J33: =IFERROR(subQ!I25+subQ!J21-subQ!J25,"") | K33: =IFERROR(subQ!J25+subQ!K21-subQ!K25,"") | L33: =IFERROR(subQ!K25+subQ!L21-subQ!L25,"") | N33: =IFERROR(subQ!L25+subQ!N21-subQ!N25,"") | O33: =IFERROR(subQ!N25+subQ!O21-subQ!O25,"") | P33: -0.005273056 | Q33: 0.00258669 | S33: -0.003946904 | T33: 1770.9265 | U33: -0.008338569 | V33: -0.009190603 | X33: 0.004733472 | Y33: 1770.9223 | Z33: 0.000603265 | AA33: -0.004683931
A34: drv:총차입금 | B34: qoq | C34: 총차입금 QoQ | F34: =IFERROR(subQ!F26/subQ!E26-1,"") | G34: =IFERROR(subQ!G26/subQ!F26-1,"") | I34: =IFERROR(subQ!I26/subQ!G26-1,"") | J34: =IFERROR(subQ!J26/subQ!I26-1,"") | K34: =IFERROR(subQ!K26/subQ!J26-1,"") | L34: =IFERROR(subQ!L26/subQ!K26-1,"") | N34: =IFERROR(subQ!N26/subQ!L26-1,"") | O34: =IFERROR(subQ!O26/subQ!N26-1,"")
A35: drv:순차입금 | B35: qoq | C35: 순차입금 QoQ | F35: =IFERROR(subQ!F27/subQ!E27-1,"") | G35: =IFERROR(subQ!G27/subQ!F27-1,"") | I35: =IFERROR(subQ!I27/subQ!G27-1,"") | J35: =IFERROR(subQ!J27/subQ!I27-1,"") | K35: =IFERROR(subQ!K27/subQ!J27-1,"") | L35: =IFERROR(subQ!L27/subQ!K27-1,"") | N35: =IFERROR(subQ!N27/subQ!L27-1,"") | O35: =IFERROR(subQ!O27/subQ!N27-1,"")
A36: drv:이자발생자산 | B36: qoq | C36: 이자발생자산 QoQ | F36: =IFERROR(subQ!F28/subQ!E28-1,"") | G36: =IFERROR(subQ!G28/subQ!F28-1,"") | I36: =IFERROR(subQ!I28/subQ!G28-1,"") | J36: =IFERROR(subQ!J28/subQ!I28-1,"") | K36: =IFERROR(subQ!K28/subQ!J28-1,"") | L36: =IFERROR(subQ!L28/subQ!K28-1,"") | N36: =IFERROR(subQ!N28/subQ!L28-1,"") | O36: =IFERROR(subQ!O28/subQ!N28-1,"") | P36: 0.14396437 | Q36: 0.13597865 | S36: 0.12966032 | T36: -0.099812966 | U36: 0.13426874 | V36: 0.12194953 | X36: 0.11467029 | Y36: -0.063269228 | Z36: 0.12278151 | AA36: 0.11642798
A37: drv:현금및현금성자산 | B37: qoq | C37: 현금및현금성자산 QoQ | F37: =IFERROR(subQ!F29/subQ!E29-1,"") | G37: =IFERROR(subQ!G29/subQ!F29-1,"") | I37: =IFERROR(subQ!I29/subQ!G29-1,"") | J37: =IFERROR(subQ!J29/subQ!I29-1,"") | K37: =IFERROR(subQ!K29/subQ!J29-1,"") | L37: =IFERROR(subQ!L29/subQ!K29-1,"") | N37: =IFERROR(subQ!N29/subQ!L29-1,"") | O37: =IFERROR(subQ!O29/subQ!N29-1,"")
A38: drv:CAPEX | B38: yoy | C38: CAPEX YoY | J38: =IFERROR(subQ!J30/subQ!E30-1,"") | K38: =IFERROR(subQ!K30/subQ!F30-1,"") | L38: =IFERROR(subQ!L30/subQ!G30-1,"") | N38: =IFERROR(subQ!N30/subQ!I30-1,"") | O38: =IFERROR(subQ!O30/subQ!J30-1,"") | P38: 0.21213388 | Q38: -0.39755384 | S38: -0.14900905 | T38: 0.45183441 | U38: 0 | V38: 0 | X38: 0 | Y38: 0 | Z38: 0 | AA38: 0
A39: drv:영업활동현금흐름 | B39: yoy | C39: 영업활동현금흐름 YoY | J39: =IFERROR(subQ!J31/subQ!E31-1,"") | K39: =IFERROR(subQ!K31/subQ!F31-1,"") | L39: =IFERROR(subQ!L31/subQ!G31-1,"") | N39: =IFERROR(subQ!N31/subQ!I31-1,"") | O39: =IFERROR(subQ!O31/subQ!J31-1,"")
A40: drv:주식수 | B40: qoq | C40: 주식수 QoQ | F40: =IFERROR(subQ!F32/subQ!E32-1,"") | G40: =IFERROR(subQ!G32/subQ!F32-1,"") | I40: =IFERROR(subQ!I32/subQ!G32-1,"") | J40: =IFERROR(subQ!J32/subQ!I32-1,"") | K40: =IFERROR(subQ!K32/subQ!J32-1,"") | L40: =IFERROR(subQ!L32/subQ!K32-1,"") | N40: =IFERROR(subQ!N32/subQ!L32-1,"") | O40: =IFERROR(subQ!O32/subQ!N32-1,"") | P40: 0 | Q40: 0 | S40: 0 | T40: 0 | U40: 0 | V40: 0 | X40: 0 | Y40: 0 | Z40: 0 | AA40: 0
A41: drv:DPS | B41: abs | C41: DPS (가정, 원) | E41: =subQ!E35 | F41: =subQ!F35 | G41: =subQ!G35 | H41: =subQ!H35 | I41: =subQ!I35 | J41: =subQ!J35 | K41: =subQ!K35 | L41: =subQ!L35 | ... O41: =subQ!O35 | Q41: 3950 | R41: =subQ!R35 | V41: 3950 | W41: =subQ!W35 | AA41: 3950 | AB41: =subQ!AB35
...

Sheet BS연결
B1: (백만원) | C1: 이름: BS연결H | E1: 2Q24 | F1: 3Q24 | G1: 4Q24 | H1: 2024 | I1: 1Q25 | J1: 2Q25 | K1: 3Q25 | L1: 4Q25 | M1: 2025 | N1: 1Q26 | O1: 2Q26 | P1: 3Q26 | Q1: 4Q26 | R1: 2026 | S1: 1Q27 | T1: 2Q27 | U1: 3Q27 | V1: 4Q27 | W1: 2027 | X1: 1Q28 | Y1: 2Q28 | Z1: 3Q28 | AA1: 4Q28 | AB1: 2028
B2: 연결 | D2: fin json(kship_fin.py)
B3: HD현대마린솔루션(연) | C3: UPDATE: 26-10-13 | E3: 1 | F3: 2 | G3: 3 | H3: 4 | I3: 5 | J3: 6 | K3: 7 | L3: 8 | M3: 9 | N3: 10 | O3: 11 | P3: 12 | Q3: 13 | R3: 14 | S3: 15 | T3: 16 | U3: 17 | V3: 18 | W3: 19 | X3: 20 | Y3: 21 | Z3: 22 | AA3: 23 | AB3: 24
B4: Account Code | C4: AccountNAME | E4: 2024.06 | F4: 2024.09 | G4: 2024.12 | H4: 2024.12A | I4: 2025.03 | J4: 2025.06 | K4: 2025.09 | L4: 2025.12 | M4: 2025.12A | N4: 2026.03 | O4: 2026.06 | P4: 2026.09 | Q4: 2026.12 | R4: 2026.12A | S4: 2027.03 | T4: 2027.06 | U4: 2027.09 | V4: 2027.12 | W4: 2027.12A | X4: 2028.03 | Y4: 2028.06 | Z4: 2028.09 | AA4: 2028.12 | AB4: 2028.12A
A5: 1 | C5: 유동자산 | E5: 1014908.5 | F5: 1023380.8 | G5: 1075525.9 | H5: 1075525.9 | I5: 1151124.2 | J5: 1033004.1 | K5: 1087815.9 | L5: 1186808.8 | M5: 1186808.8 | N5: 1305046.8 | O5: 1288784.6
A6: 1 | C6: 현금및현금성자산 | E6: 320728.9 | F6: 222005.54 | G6: 298466.07 | H6: 298466.07 | I6: 455769.77 | J6: 275777.91 | K6: 361310.54 | L6: 377924.04 | M6: 377924.04 | N6: 430672.81 | O6: 456440.68
A7: 1 | C7: 단기금융상품 | E7: 127000 | F7: 252000 | G7: 182950 | H7: 182950 | I7: 117950 | J7: 196250 | K7: 156250 | L7: 186250 | M7: 186250 | N7: 175800 | O7: 91300
A8: 1 | C8: 단기금융자산 | E8: 127035.26 | F8: 252000 | G8: 182950 | H8: 182950 | I8: 117950 | J8: 196293.44 | K8: 156356.89 | L8: 186548.77 | M8: 186548.77 | N8: 176429.82 | O8: 91813.83
A9: 1 | C9: 매출채권및기타채권 | E9: 243155.53 | F9: 227269.49 | G9: 262855.9 | H9: 262855.9 | I9: 277282.77 | J9: 253016.46 | K9: 267872.37 | L9: 317784.36 | M9: 317784.36 | N9: 388551.16 | O9: 407057.37
A10: 1 | C10: 계약자산 | E10: 10836.09 | F10: 9541.13 | G10: 16841.28 | H10: 16841.28 | I10: 7717.35 | J10: 4832.41 | K10: 6050.73 | L10: 7395.13 | M10: 7395.13 | N10: 6018.45 | O10: 11279.42
A11: 1 | C11: 재고자산 | E11: 254656.63 | F11: 248671.94 | G11: 273426.86 | H11: 273426.86 | I11: 254700.3 | J11: 261585.98 | K11: 263800.98 | L11: 270685.74 | M11: 270685.74 | N11: 273514.24 | O11: 290071.86
A12: 1 | C12: 유동확정계약자산 | E12: 35.26 | J12: 43.44 | K12: 106.89 | L12: 213.33 | M12: 213.33 | N12: 557.3 | O12: 489.24
A13: 1 | C13: 당기법인세자산(선급법인세) | E13: 1087.2 | F13: 105.27 | G13: 747.65 | H13: 747.65 | I13: 694.24 | J13: 647.61 | K13: 429.38 | L13: 0 | M13: 0 | N13: 1231.96 | O13: 633.95
A14: 1 | C14: 기타유동자산 | E14: 57408.85 | F14: 63787.44 | G14: 40238.15 | H14: 40238.15 | I14: 37009.78 | J14: 40850.32 | K14: 31995.04 | L14: 26470.78 | M14: 26470.78 | N14: 28628.38 | O14: 31487.5
A15: 1 | C15: 비유동자산 | E15: 67598 | F15: 69071.57 | G15: 76702.05 | H15: 76702.05 | I15: 82828.82 | J15: 87144.2 | K15: 85312.9 | L15: 85511.25 | M15: 85511.25 | N15: 93730.46 | O15: 102758.28
A16: 1 | C16: 장기금융자산 | E16: 2 | F16: 2 | G16: 2 | H16: 2 | I16: 2 | J16: 2 | K16: 2 | L16: 560.54 | M16: 560.54 | N16: 592.94 | O16: 606.99
A17: 1 | C17: 투자자산 | E17: 72.71 | F17: 2832.84 | G17: 2982.29 | H17: 2982.29 | I17: 2892.68 | J17: 2615.47 | K17: 2552.46 | L17: 3222.17 | M17: 3222.17 | N17: 3238.47 | O17: 3130.38
A18: 1 | C18: 장기매출채권및기타채권 | E18: 4868.61 | F18: 4857.01 | G18: 9789.41 | H18: 9789.41 | I18: 9876.6 | J18: 9229.94 | K18: 9277.96 | L18: 6634.93 | M18: 6634.93 | N18: 6986.41 | O18: 10276.98
A19: 1 | C19: 유형자산 | E19: 13789.95 | F19: 15349.27 | G19: 19580.72 | H19: 19580.72 | I19: 20263.56 | J19: 23907.9 | K19: 26058.1 | L19: 29559.68 | M19: 29559.68 | N19: 32192.13 | O19: 33525.24
A20: 1 | C20: 사용권자산 | E20: 22118.95 | F20: 21076.12 | G20: 19891.23 | H20: 19891.23 | I20: 22420.14 | J20: 20311.08 | K20: 18560.43 | L20: 16938.19 | M20: 16938.19 | N20: 23768.32 | O20: 28131.79
A21: 1 | C21: 기타비유동자산 | E21: 25681.93 | F21: 23799.17 | G21: 24309.78 | H21: 24309.78 | I21: 25830.15 | J21: 22601.96 | K21: 20000.36 | L21: 23464.21 | M21: 23464.21 | N21: 28968.55 | O21: 31987.34
A22: 1 | C22: 무형자산 | E22: 4136.67 | F22: 4136.67 | G22: 4529.71 | H22: 4529.71 | I22: 4520.65 | J22: 4486.19 | K22: 5346.38 | L22: 5080.84 | M22: 5080.84 | N22: 5094.13 | O22: 5094.62
A23: 1 | C23: 이연법인세자산 | E23: 19048.13 | F23: 18096.61 | G23: 15510.14 | H23: 15510.14 | I23: 19445.19 | J23: 24302.74 | K23: 22077.64 | L23: 17549.43 | M23: 17549.43 | N23: 17250.77 | O23: 18743.72
A24: 1 | C24: 비유동확정계약자산 | E24: 70.71 | G24: 218.31 | H24: 218.31 | I24: 235.2 | J24: 19.97 | K24: 50.92 | L24: 18.73 | M24: 18.73 | N24: 94.6 | O24: 24.41
A25: 1 | C25: 자산총계 | E25: 1082506.5 | F25: 1092452.4 | G25: 1152228 | H25: 1152228 | I25: 1233953 | J25: 1120148.3 | K25: 1173128.8 | L25: 1272320.1 | M25: 1272320.1 | N25: 1398777.3 | O25: 1391542.9
A26: 1 | C26: 유동부채 | E26: 410848.05 | F26: 385699.29 | G26: 342617.75 | H26: 342617.75 | I26: 476464.19 | J26: 354776.17 | K26: 352862.86 | L26: 408739.5 | M26: 408739.5 | N26: 505489.89 | O26: 444266.97
A27: 1 | C27: 기타유동금융부채 | E27: 71969.15
A28: 1 | C28: 단기금융부채 | E28: 79885.46 | F28: 8024.92 | G28: 8088.06 | H28: 8088.06 | I28: 8466.28 | J28: 8353.32 | K28: 8389.48 | L28: 8299.7 | M28: 8299.7 | N28: 10960.63 | O28: 11416.07
A29: 1 | C29: 매입채무및기타채무 | E29: 183448.5 | F29: 177611.75 | G29: 183849.01 | H29: 183849.01 | I29: 302370.43 | J29: 182483.75 | K29: 178618.63 | L29: 214355.71 | M29: 214355.71 | N29: 302219.4 | O29: 222496.16
A30: 1 | C30: 계약부채 | E30: 95913.92 | F30: 114205.86 | G30: 104218.76 | H30: 104218.76 | I30: 108976.81 | J30: 102249.13 | K30: 107939.46 | L30: 125761.29 | M30: 125761.29 | N30: 128742.85 | O30: 145289.83
A31: 1 | C31: 선수금 | E31: 889.56 | F31: 689.15 | G31: 795.6 | H31: 795.6 | I31: 538.72 | J31: 248.48 | K31: 264.06 | L31: 2407.87 | M31: 2407.87 | N31: 1446.15 | O31: 2131.44
A32: 1 | C32: 기타유동부채 | E32: 889.56 | F32: 689.15 | G32: 795.6 | H32: 795.6 | I32: 538.72 | J32: 248.48 | K32: 264.06 | L32: 2407.87 | M32: 2407.87 | N32: 1446.15 | O32: 2131.44
A33: 1 | C33: 유동리스부채 | E33: 7881.05 | F33: 8024.92 | G33: 8088.06 | H33: 8088.06 | I33: 8466.28 | J33: 8309.88 | K33: 8282.59 | L33: 7980.6 | M33: 7980.6 | N33: 10454.12 | O33: 11005.38
A34: 1 | C34: 리스부채 | E34: 22619.47 | F34: 21660.38 | G34: 20551.84 | H34: 20551.84 | I34: 22896.14 | J34: 21196.65 | K34: 19480.47 | L34: 17912.1 | M34: 17912.1 | N34: 25246.21 | O34: 33234.54
A35: 1 | C35: 단기충당부채 | E35: 10709.57 | F35: 9597.34 | G35: 11061.71 | H35: 11061.71 | I35: 10708.91 | J35: 10462.45 | K35: 4571.28 | L35: 3584.78 | M35: 3584.78 | N35: 6164 | O35: 7558.12
A36: 1 | C36: 당기법인세부채(미지급법인세) | E36: 40001.02 | F36: 29250.68 | G36: 34604.6 | H36: 34604.6 | I36: 45403.04 | J36: 48266.24 | K36: 53079.96 | L36: 54330.15 | M36: 54330.15 | N36: 55956.87 | O36: 55375.34
A37: 1 | C37: 단기파생상품부채 | E37: 35.26 | J37: 43.44 | K37: 106.89 | L37: 319.1 | M37: 319.1 | N37: 506.51 | O37: 410.69
A38: 1 | C38: 비유동부채 | E38: 37196.98 | F38: 38504.91 | G38: 36075.66 | H38: 36075.66 | I38: 41878.19 | J38: 37092.66 | K38: 39681.78 | L38: 38855.71 | M38: 38855.71 | N38: 46250.24 | O38: 55159.28
A39: 1 | C39: 비유동계약부채 | E39: 16135.27 | F39: 18256.33 | G39: 18419.11 | H39: 18419.11 | I39: 22174.95 | J39: 19829.47 | K39: 23925.66 | L39: 24569.15 | M39: 24569.15 | N39: 27291.57 | O39: 28561.81
A40: 1 | C40: 확정급여부채 | E40: 863.8 | F40: 996.5 | G40: 32.94 | H40: 32.94 | I40: 43.18 | J40: 47.55 | K40: 188.27 | L40: 82.2 | M40: 82.2 | N40: 83.08 | O40: 84.62
...

Sheet BS별도
B1: (백만원) | C1: 이름: BS별도H | E1: 2Q24 | F1: 3Q24 | G1: 4Q24 | H1: 2024 | I1: 1Q25 | J1: 2Q25 | K1: 3Q25 | L1: 4Q25 | M1: 2025 | N1: 1Q26 | O1: 2Q26 | P1: 3Q26 | Q1: 4Q26 | R1: 2026 | S1: 1Q27 | T1: 2Q27 | U1: 3Q27 | V1: 4Q27 | W1: 2027 | X1: 1Q28 | Y1: 2Q28 | Z1: 3Q28 | AA1: 4Q28 | AB1: 2028
B2: 별도 | D2: fin json(kship_fin.py)
B3: HD현대마린솔루션(별) | C3: UPDATE: 26-10-13 | E3: 1 | F3: 2 | G3: 3 | H3: 4 | I3: 5 | J3: 6 | K3: 7 | L3: 8 | M3: 9 | N3: 10 | O3: 11 | P3: 12 | Q3: 13 | R3: 14 | S3: 15 | T3: 16 | U3: 17 | V3: 18 | W3: 19 | X3: 20 | Y3: 21 | Z3: 22 | AA3: 23 | AB3: 24
B4: Account Code | C4: AccountNAME | E4: 2024.06 | F4: 2024.09 | G4: 2024.12 | H4: 2024.12A | I4: 2025.03 | J4: 2025.06 | K4: 2025.09 | L4: 2025.12 | M4: 2025.12A | N4: 2026.03 | O4: 2026.06 | P4: 2026.09 | Q4: 2026.12 | R4: 2026.12A | S4: 2027.03 | T4: 2027.06 | U4: 2027.09 | V4: 2027.12 | W4: 2027.12A | X4: 2028.03 | Y4: 2028.06 | Z4: 2028.09 | AA4: 2028.12 | AB4: 2028.12A
A5: 1 | C5: 유동자산 | E5: 883902.77 | F5: 880210.43 | G5: 910176.47 | H5: 910176.47 | I5: 974324.86 | J5: 868596.21 | K5: 905002.35 | L5: 989677.18 | M5: 989677.18 | N5: 1049311.2 | O5: 1055321.6
A6: 1 | C6: 현금및현금성자산 | E6: 285853.89 | F6: 200840.24 | G6: 272638.23 | H6: 272638.23 | I6: 429223.17 | J6: 238214.98 | K6: 319812.06 | L6: 319123.45 | M6: 319123.45 | N6: 376504.38 | O6: 396609.2
A7: 1 | C7: 단기금융상품 | E7: 127000 | F7: 252000 | G7: 182950 | H7: 182950 | I7: 117950 | J7: 196250 | K7: 156250 | L7: 186250 | M7: 186250 | N7: 175800 | O7: 91300
A8: 1 | C8: 단기금융자산 | E8: 127035.26 | F8: 252000 | G8: 182950 | H8: 182950 | I8: 117950 | J8: 196293.44 | K8: 156356.89 | L8: 186548.77 | M8: 186548.77 | N8: 176429.82 | O8: 91813.83
A9: 1 | C9: 매출채권및기타채권 | E9: 225993.18 | F9: 163445.61 | G9: 191556.89 | H9: 191556.89 | I9: 191705.93 | J9: 193598.11 | K9: 191606.26 | L9: 241307.48 | M9: 241307.48 | N9: 251127.62 | O9: 284745.36
A10: 1 | C10: 계약자산 | E10: 10836.09 | F10: 9541.13 | G10: 16841.28 | H10: 16841.28 | I10: 7156.34 | J10: 4113.18 | K10: 5202.97 | L10: 6532.76 | M10: 6532.76 | N10: 5112.66 | O10: 10356.81
A11: 1 | C11: 재고자산 | E11: 189657.6 | F11: 200278.84 | G11: 210805.46 | H11: 210805.46 | I11: 198823.9 | J11: 209709.43 | K11: 210830.11 | L11: 216226.45 | M11: 216226.45 | N11: 221624.56 | O11: 247693.29
A12: 1 | C12: 유동확정계약자산 | E12: 35.26 | J12: 43.44 | K12: 106.89 | L12: 213.33 | M12: 213.33 | N12: 557.3 | O12: 489.24
A13: 1 | C13: 기타유동자산 | E13: 44526.75 | F13: 54104.61 | G13: 35384.62 | H13: 35384.62 | I13: 29465.52 | J13: 26667.07 | K13: 21194.06 | L13: 19938.27 | M13: 19938.27 | N13: 18512.14 | O13: 24103.07
A14: 1 | C14: 비유동자산 | E14: 113406.01 | F14: 116897.55 | G14: 122729.23 | H14: 122729.23 | I14: 125912.5 | J14: 130211.83 | K14: 129353.66 | L14: 128390.47 | M14: 128390.47 | N14: 137624.68 | O14: 138512
A15: 1 | C15: 종속기업및관계기업투자 | E15: 68755.33 | F15: 71770.06 | G15: 71784.79 | H15: 71784.79 | I15: 71784.79 | J15: 71784.79 | K15: 71784.79 | L15: 71784.79 | M15: 71784.79 | N15: 71784.79 | O15: 71784.79
A16: 1 | C16: 투자자산 | E16: 68828.04 | F16: 71782.07 | G16: 72005.1 | H16: 72005.1 | I16: 72021.99 | J16: 71806.76 | K16: 71837.71 | L16: 71847.09 | M16: 71847.09 | N16: 71881.39 | O16: 71812.47
A17: 1 | C17: 장기금융자산 | E17: 2 | F17: 2 | G17: 2 | H17: 2 | I17: 2 | J17: 2 | K17: 2 | L17: 2 | M17: 2 | N17: 2 | O17: 2
A18: 1 | C18: 장기매출채권및기타채권 | E18: 3829.19 | F18: 3829.19 | G18: 8656.31 | H18: 8656.31 | I18: 8723.03 | J18: 8270.98 | K18: 8292.85 | L18: 5664.76 | M18: 5664.76 | N18: 5966.28 | O18: 6026.32
A19: 1 | C19: 유형자산 | E19: 10786.46 | F19: 12226.03 | G19: 16325.7 | H19: 16325.7 | I19: 17187.75 | J19: 21089.43 | K19: 23343.75 | L19: 26611.29 | M19: 26611.29 | N19: 28670.08 | O19: 29282.61
A20: 1 | C20: 사용권자산 | E20: 14817.13 | F20: 13526.69 | G20: 12275.12 | H20: 12275.12 | I20: 12345.91 | J20: 11000.6 | K20: 9674.26 | L20: 8476.56 | M20: 8476.56 | N20: 15616.04 | O20: 13602.2
A21: 1 | C21: 기타비유동자산 | E21: 18380.11 | F21: 16249.74 | G21: 16471.14 | H21: 16471.14 | I21: 15719.03 | J21: 13291.48 | K21: 11114.19 | L21: 14412.73 | M21: 14412.73 | N21: 20414.2 | O21: 17242.33
A22: 1 | C22: 무형자산 | E22: 4136.67 | F22: 4136.67 | G22: 4136.67 | H22: 4136.67 | I22: 4136.67 | J22: 4136.67 | K22: 4990.88 | L22: 4723.02 | M22: 4723.02 | N22: 4723.02 | O22: 4723.02
A23: 1 | C23: 이연법인세자산 | E23: 7445.53 | F23: 8673.86 | G23: 5134.31 | H23: 5134.31 | I23: 8124.04 | J23: 11616.52 | K23: 9774.29 | L23: 5131.59 | M23: 5131.59 | N23: 5969.71 | O23: 9425.26
A24: 1 | C24: 비유동확정계약자산 | E24: 70.71 | G24: 218.31 | H24: 218.31 | I24: 235.2 | J24: 19.97 | K24: 50.92 | L24: 18.73 | M24: 18.73 | N24: 94.6 | O24: 24.41
A25: 1 | C25: 자산총계 | E25: 997308.78 | F25: 997107.98 | G25: 1032905.7 | H25: 1032905.7 | I25: 1100237.4 | J25: 998808.05 | K25: 1034356 | L25: 1118067.6 | M25: 1118067.6 | N25: 1186935.9 | O25: 1193833.6
A26: 1 | C26: 유동부채 | E26: 345766.94 | F26: 322220.38 | G26: 268406.21 | H26: 268406.21 | I26: 397732.5 | J26: 280432.11 | K26: 276178.67 | L26: 318980.37 | M26: 318980.37 | N26: 378260.11 | O26: 357626.6
A27: 1 | C27: 단기차입금 | E27: 70579.95 | F27: 45000 | G27: 0 | H27: 0 | L27: 0 | M27: 0
A28: 1 | C28: 단기금융부채(face) | E28: 70579.95 | F28: 45000 | G28: 0 | H28: 0 | L28: 0 | M28: 0
A29: 1 | C29: 매입채무및기타채무 | E29: 142879.04 | F29: 137133.49 | G29: 147234.14 | H29: 147234.14 | I29: 258148.19 | J29: 142505.89 | K29: 136626.63 | L29: 164544.94 | M29: 164544.94 | N29: 221736.64 | O29: 179476.26
A30: 1 | C30: 계약부채 | E30: 77525.73 | F30: 98254.99 | G30: 74075.07 | H30: 74075.07 | I30: 80555.69 | J30: 75889.6 | K30: 79748.48 | L30: 91659.55 | M30: 91659.55 | N30: 88644.2 | O30: 109172.54
A31: 1 | C31: 선수금 | E31: 889.56 | F31: 689.15 | G31: 795.6 | H31: 795.6 | I31: 538.72 | J31: 248.48 | K31: 264.06 | L31: 2367.19 | M31: 2367.19 | N31: 1446.15 | O31: 2131.44
A32: 1 | C32: 기타유동부채 | E32: 889.56 | F32: 689.15 | G32: 795.6 | H32: 795.6 | I32: 538.72 | J32: 248.48 | K32: 264.06 | L32: 2367.19 | M32: 2367.19 | N32: 1446.15 | O32: 2131.44
A33: 1 | C33: 유동리스부채 | E33: 5463.72 | F33: 5354.16 | G33: 5270.37 | H33: 5270.37 | I33: 5558.17 | J33: 5386 | K33: 5248.64 | L33: 5226.06 | M33: 5226.06 | N33: 7734.53 | O33: 6774
A34: 1 | C34: 리스부채 | E34: 15043.29 | F34: 13809.92 | G34: 12600.15 | H34: 12600.15 | I34: 12438.54 | J34: 11110.17 | K34: 9767.86 | L34: 8597.18 | M34: 8597.18 | N34: 16254.62 | O34: 14244.04
A35: 1 | C35: 단기금융부채 | E35: 5498.98 | F35: 5354.16 | G35: 5270.37 | H35: 5270.37 | I35: 5558.17 | J35: 5429.44 | K35: 5355.53 | L35: 5545.16 | M35: 5545.16 | N35: 8241.04 | O35: 7184.69
A36: 1 | C36: 단기충당부채 | E36: 10709.57 | F36: 9597.34 | G36: 11061.71 | H36: 11061.71 | I36: 10708.91 | J36: 10462.45 | K36: 4571.28 | L36: 3584.78 | M36: 3584.78 | N36: 6164 | O36: 7558.12
A37: 1 | C37: 당기법인세부채(미지급법인세) | E37: 37684.1 | F37: 26191.25 | G37: 29969.32 | H37: 29969.32 | I37: 42222.82 | J37: 45896.24 | K37: 49612.7 | L37: 51278.74 | M37: 51278.74 | N37: 52028.09 | O37: 52103.55
A38: 1 | C38: 단기파생상품부채 | E38: 35.26 | J38: 43.44 | K38: 106.89 | L38: 319.1 | M38: 319.1 | N38: 506.51 | O38: 410.69
A39: 1 | C39: 비유동부채 | E39: 15341.06 | F39: 14325.45 | G39: 12119.13 | H39: 12119.13 | I39: 11730.62 | J39: 9694.19 | K39: 8515.05 | L39: 7254.11 | M39: 7254.11 | N39: 12278.46 | O39: 11170.22
A40: 1 | C40: 확정급여부채 | E40: 570.72 | F40: 570.72 | G40: 0 | H40: 0 | L40: 0 | M40: 0
...

Sheet subQ
A1: YQ | C1: subQ 분기 서브모델(억원, U=100) | E1: 2Q24 | F1: 3Q24 | G1: 4Q24 | H1: 2024 | I1: 1Q25 | J1: 2Q25 | K1: 3Q25 | L1: 4Q25 | M1: 2025 | N1: 1Q26 | O1: 2Q26 | P1: 3Q26 | Q1: 4Q26 | R1: 2026 | S1: 1Q27 | T1: 2Q27 | U1: 3Q27 | V1: 4Q27 | W1: 2027 | X1: 1Q28 | Y1: 2Q28 | Z1: 3Q28 | AA1: 4Q28 | AB1: 2028
A2: A=이름(key) B=그룹 C=단위 D=FnGuide 계정명(VLOOKUP 키). 확정=VLOOKUP(BS), 추정=변수 가정 참조
E3: 1 | F3: 2 | G3: 3 | H3: 4 | I3: 5 | J3: 6 | K3: 7 | L3: 8 | M3: 9 | N3: 10 | O3: 11 | P3: 12 | Q3: 13 | R3: 14 | S3: 15 | T3: 16 | U3: 17 | V3: 18 | W3: 19 | X3: 20 | Y3: 21 | Z3: 22 | AA3: 23 | AB3: 24
E4: 2024.06 | F4: 2024.09 | G4: 2024.12 | H4: 2024.12A | I4: 2025.03 | J4: 2025.06 | K4: 2025.09 | L4: 2025.12 | M4: 2025.12A | N4: 2026.03 | O4: 2026.06 | P4: 2026.09 | Q4: 2026.12 | R4: 2026.12A | S4: 2027.03 | T4: 2027.06 | U4: 2027.09 | V4: 2027.12 | W4: 2027.12A | X4: 2028.03 | Y4: 2028.06 | Z4: 2028.09 | AA4: 2028.12 | AB4: 2028.12A
A5: 매출액 | B5: 손익 | C5: 억원 | D5: 매출액(수익) | E5: =IFERROR(VLOOKUP($D5,BS연결,MATCH(E$1,BS연결H,0),0)/100,"") | F5: =IFERROR(VLOOKUP($D5,BS연결,MATCH(F$1,BS연결H,0),0)/100,"") | G5: =IFERROR(VLOOKUP($D5,BS연결,MATCH(G$1,BS연결H,0),0)/100,"") | I5: =IFERROR(VLOOKUP($D5,BS연결,MATCH(I$1,BS연결H,0),0)/100,"") | J5: =IFERROR(VLOOKUP($D5,BS연결,MATCH(J$1,BS연결H,0),0)/100,"") | K5: =IFERROR(VLOOKUP($D5,BS연결,MATCH(K$1,BS연결H,0),0)/100,"") | L5: =IFERROR(VLOOKUP($D5,BS연결,MATCH(L$1,BS연결H,0),0)/100,"") | M5: =IFERROR(VLOOKUP($D5,BS연결,MATCH(M$1,BS연결H,0),0)/100,"") | N5: =IFERROR(VLOOKUP($D5,BS연결,MATCH(N$1,BS연결H,0),0)/100,"") | O5: =IFERROR(VLOOKUP($D5,BS연결,MATCH(O$1,BS연결H,0),0)/100,"") | P5: =IFERROR(K5*(1+변수!P21),"") | Q5: =IFERROR(L5*(1+변수!Q21),"") | R5: =SUM(N5:Q5) | S5: =IFERROR(N5*(1+변수!S21),"") | T5: =IFERROR(O5*(1+변수!T21),"") | U5: =IFERROR(P5*(1+변수!U21),"") | V5: =IFERROR(Q5*(1+변수!V21),"") | W5: =SUM(S5:V5) | X5: =IFERROR(S5*(1+변수!X21),"") | Y5: =IFERROR(T5*(1+변수!Y21),"") | Z5: =IFERROR(U5*(1+변수!Z21),"") | AA5: =IFERROR(V5*(1+변수!AA21),"") | AB5: =SUM(X5:AA5)
A6: 매출원가 | B6: 손익 | C6: 억원 | D6: 매출원가 | E6: =IFERROR(VLOOKUP($D6,BS연결,MATCH(E$1,BS연결H,0),0)/100,"") | F6: =IFERROR(VLOOKUP($D6,BS연결,MATCH(F$1,BS연결H,0),0)/100,"") | G6: =IFERROR(VLOOKUP($D6,BS연결,MATCH(G$1,BS연결H,0),0)/100,"") | I6: =IFERROR(VLOOKUP($D6,BS연결,MATCH(I$1,BS연결H,0),0)/100,"") | J6: =IFERROR(VLOOKUP($D6,BS연결,MATCH(J$1,BS연결H,0),0)/100,"") | K6: =IFERROR(VLOOKUP($D6,BS연결,MATCH(K$1,BS연결H,0),0)/100,"") | L6: =IFERROR(VLOOKUP($D6,BS연결,MATCH(L$1,BS연결H,0),0)/100,"") | M6: =IFERROR(VLOOKUP($D6,BS연결,MATCH(M$1,BS연결H,0),0)/100,"") | N6: =IFERROR(VLOOKUP($D6,BS연결,MATCH(N$1,BS연결H,0),0)/100,"") | O6: =IFERROR(VLOOKUP($D6,BS연결,MATCH(O$1,BS연결H,0),0)/100,"") | P6: =IFERROR(P5-P7,"") | Q6: =IFERROR(Q5-Q7,"") | R6: =SUM(N6:Q6) | S6: =IFERROR(S5-S7,"") | T6: =IFERROR(T5-T7,"") | U6: =IFERROR(U5-U7,"") | V6: =IFERROR(V5-V7,"") | W6: =SUM(S6:V6) | X6: =IFERROR(X5-X7,"") | Y6: =IFERROR(Y5-Y7,"") | Z6: =IFERROR(Z5-Z7,"") | AA6: =IFERROR(AA5-AA7,"") | AB6: =SUM(X6:AA6)
A7: 매출총이익 | B7: 손익 | C7: 억원 | D7: 매출총이익 | E7: =IFERROR(VLOOKUP($D7,BS연결,MATCH(E$1,BS연결H,0),0)/100,"") | F7: =IFERROR(VLOOKUP($D7,BS연결,MATCH(F$1,BS연결H,0),0)/100,"") | G7: =IFERROR(VLOOKUP($D7,BS연결,MATCH(G$1,BS연결H,0),0)/100,"") | I7: =IFERROR(VLOOKUP($D7,BS연결,MATCH(I$1,BS연결H,0),0)/100,"") | J7: =IFERROR(VLOOKUP($D7,BS연결,MATCH(J$1,BS연결H,0),0)/100,"") | K7: =IFERROR(VLOOKUP($D7,BS연결,MATCH(K$1,BS연결H,0),0)/100,"") | L7: =IFERROR(VLOOKUP($D7,BS연결,MATCH(L$1,BS연결H,0),0)/100,"") | M7: =IFERROR(VLOOKUP($D7,BS연결,MATCH(M$1,BS연결H,0),0)/100,"") | N7: =IFERROR(VLOOKUP($D7,BS연결,MATCH(N$1,BS연결H,0),0)/100,"") | O7: =IFERROR(VLOOKUP($D7,BS연결,MATCH(O$1,BS연결H,0),0)/100,"") | P7: =IFERROR(P9+P8,"") | Q7: =IFERROR(Q9+Q8,"") | R7: =SUM(N7:Q7) | S7: =IFERROR(S9+S8,"") | T7: =IFERROR(T9+T8,"") | U7: =IFERROR(U9+U8,"") | V7: =IFERROR(V9+V8,"") | W7: =SUM(S7:V7) | X7: =IFERROR(X9+X8,"") | Y7: =IFERROR(Y9+Y8,"") | Z7: =IFERROR(Z9+Z8,"") | AA7: =IFERROR(AA9+AA8,"") | AB7: =SUM(X7:AA7)
A8: 판관비 | B8: 손익 | C8: 억원 | D8: 판관비 | E8: =IFERROR(VLOOKUP($D8,BS연결,MATCH(E$1,BS연결H,0),0)/100,"") | F8: =IFERROR(VLOOKUP($D8,BS연결,MATCH(F$1,BS연결H,0),0)/100,"") | G8: =IFERROR(VLOOKUP($D8,BS연결,MATCH(G$1,BS연결H,0),0)/100,"") | I8: =IFERROR(VLOOKUP($D8,BS연결,MATCH(I$1,BS연결H,0),0)/100,"") | J8: =IFERROR(VLOOKUP($D8,BS연결,MATCH(J$1,BS연결H,0),0)/100,"") | K8: =IFERROR(VLOOKUP($D8,BS연결,MATCH(K$1,BS연결H,0),0)/100,"") | L8: =IFERROR(VLOOKUP($D8,BS연결,MATCH(L$1,BS연결H,0),0)/100,"") | M8: =IFERROR(VLOOKUP($D8,BS연결,MATCH(M$1,BS연결H,0),0)/100,"") | N8: =IFERROR(VLOOKUP($D8,BS연결,MATCH(N$1,BS연결H,0),0)/100,"") | O8: =IFERROR(VLOOKUP($D8,BS연결,MATCH(O$1,BS연결H,0),0)/100,"") | P8: =IFERROR(P5*변수!P22,"") | Q8: =IFERROR(Q5*변수!Q22,"") | R8: =SUM(N8:Q8) | S8: =IFERROR(S5*변수!S22,"") | T8: =IFERROR(T5*변수!T22,"") | U8: =IFERROR(U5*변수!U22,"") | V8: =IFERROR(V5*변수!V22,"") | W8: =SUM(S8:V8) | X8: =IFERROR(X5*변수!X22,"") | Y8: =IFERROR(Y5*변수!Y22,"") | Z8: =IFERROR(Z5*변수!Z22,"") | AA8: =IFERROR(AA5*변수!AA22,"") | AB8: =SUM(X8:AA8)
A9: 영업이익 | B9: 손익 | C9: 억원 | D9: 영업이익 | E9: =IFERROR(VLOOKUP($D9,BS연결,MATCH(E$1,BS연결H,0),0)/100,"") | F9: =IFERROR(VLOOKUP($D9,BS연결,MATCH(F$1,BS연결H,0),0)/100,"") | G9: =IFERROR(VLOOKUP($D9,BS연결,MATCH(G$1,BS연결H,0),0)/100,"") | I9: =IFERROR(VLOOKUP($D9,BS연결,MATCH(I$1,BS연결H,0),0)/100,"") | J9: =IFERROR(VLOOKUP($D9,BS연결,MATCH(J$1,BS연결H,0),0)/100,"") | K9: =IFERROR(VLOOKUP($D9,BS연결,MATCH(K$1,BS연결H,0),0)/100,"") | L9: =IFERROR(VLOOKUP($D9,BS연결,MATCH(L$1,BS연결H,0),0)/100,"") | M9: =IFERROR(VLOOKUP($D9,BS연결,MATCH(M$1,BS연결H,0),0)/100,"") | N9: =IFERROR(VLOOKUP($D9,BS연결,MATCH(N$1,BS연결H,0),0)/100,"") | O9: =IFERROR(VLOOKUP($D9,BS연결,MATCH(O$1,BS연결H,0),0)/100,"") | P9: =IFERROR(P5*변수!P23,"") | Q9: =IFERROR(Q5*변수!Q23,"") | R9: =SUM(N9:Q9) | S9: =IFERROR(S5*변수!S23,"") | T9: =IFERROR(T5*변수!T23,"") | U9: =IFERROR(U5*변수!U23,"") | V9: =IFERROR(V5*변수!V23,"") | W9: =SUM(S9:V9) | X9: =IFERROR(X5*변수!X23,"") | Y9: =IFERROR(Y5*변수!Y23,"") | Z9: =IFERROR(Z5*변수!Z23,"") | AA9: =IFERROR(AA5*변수!AA23,"") | AB9: =SUM(X9:AA9)
A10: OPM | B10: 손익 | C10: % | D10: 영업이익률 | E10: =IFERROR(E9/E5,"") | F10: =IFERROR(F9/F5,"") | G10: =IFERROR(G9/G5,"") | I10: =IFERROR(I9/I5,"") | J10: =IFERROR(J9/J5,"") | K10: =IFERROR(K9/K5,"") | L10: =IFERROR(L9/L5,"") | M10: =IFERROR(M9/M5,"") | N10: =IFERROR(N9/N5,"") | O10: =IFERROR(O9/O5,"") | P10: =IFERROR(P9/P5,"") | ... AB10: =IFERROR(AB9/AB5,"")
A11: 금융손익 | B11: 손익 | C11: 억원 | D11: 금융손익 | E11: =IFERROR(VLOOKUP($D11,BS연결,MATCH(E$1,BS연결H,0),0)/100,"") | F11: =IFERROR(VLOOKUP($D11,BS연결,MATCH(F$1,BS연결H,0),0)/100,"") | G11: =IFERROR(VLOOKUP($D11,BS연결,MATCH(G$1,BS연결H,0),0)/100,"") | I11: =IFERROR(VLOOKUP($D11,BS연결,MATCH(I$1,BS연결H,0),0)/100,"") | J11: =IFERROR(VLOOKUP($D11,BS연결,MATCH(J$1,BS연결H,0),0)/100,"") | K11: =IFERROR(VLOOKUP($D11,BS연결,MATCH(K$1,BS연결H,0),0)/100,"") | L11: =IFERROR(VLOOKUP($D11,BS연결,MATCH(L$1,BS연결H,0),0)/100,"") | M11: =IFERROR(VLOOKUP($D11,BS연결,MATCH(M$1,BS연결H,0),0)/100,"") | N11: =IFERROR(VLOOKUP($D11,BS연결,MATCH(N$1,BS연결H,0),0)/100,"") | O11: =IFERROR(VLOOKUP($D11,BS연결,MATCH(O$1,BS연결H,0),0)/100,"") | P11: =IFERROR(P12+P13+P14+P15,"") | Q11: =IFERROR(Q12+Q13+Q14+Q15,"") | R11: =SUM(N11:Q11) | S11: =IFERROR(S12+S13+S14+S15,"") | T11: =IFERROR(T12+T13+T14+T15,"") | U11: =IFERROR(U12+U13+U14+U15,"") | V11: =IFERROR(V12+V13+V14+V15,"") | W11: =SUM(S11:V11) | X11: =IFERROR(X12+X13+X14+X15,"") | Y11: =IFERROR(Y12+Y13+Y14+Y15,"") | Z11: =IFERROR(Z12+Z13+Z14+Z15,"") | AA11: =IFERROR(AA12+AA13+AA14+AA15,"") | AB11: =SUM(X11:AA11)
A12: 이자손익 | B12: 손익 | C12: 억원 | D12: 이자손익 | E12: =IFERROR(VLOOKUP($D12,BS연결,MATCH(E$1,BS연결H,0),0)/100,"") | F12: =IFERROR(VLOOKUP($D12,BS연결,MATCH(F$1,BS연결H,0),0)/100,"") | G12: =IFERROR(VLOOKUP($D12,BS연결,MATCH(G$1,BS연결H,0),0)/100,"") | I12: =IFERROR(VLOOKUP($D12,BS연결,MATCH(I$1,BS연결H,0),0)/100,"") | J12: =IFERROR(VLOOKUP($D12,BS연결,MATCH(J$1,BS연결H,0),0)/100,"") | K12: =IFERROR(VLOOKUP($D12,BS연결,MATCH(K$1,BS연결H,0),0)/100,"") | L12: =IFERROR(VLOOKUP($D12,BS연결,MATCH(L$1,BS연결H,0),0)/100,"") | M12: =IFERROR(VLOOKUP($D12,BS연결,MATCH(M$1,BS연결H,0),0)/100,"") | N12: =IFERROR(VLOOKUP($D12,BS연결,MATCH(N$1,BS연결H,0),0)/100,"") | O12: =IFERROR(VLOOKUP($D12,BS연결,MATCH(O$1,BS연결H,0),0)/100,"") | P12: =IFERROR((O28*변수!$D$54-O26*변수!$D$55)/4,"") | Q12: =IFERROR((P28*변수!$D$54-P26*변수!$D$55)/4,"") | R12: =SUM(N12:Q12) | S12: =IFERROR((Q28*변수!$D$54-Q26*변수!$D$55)/4,"") | T12: =IFERROR((S28*변수!$D$54-S26*변수!$D$55)/4,"") | U12: =IFERROR((T28*변수!$D$54-T26*변수!$D$55)/4,"") | V12: =IFERROR((U28*변수!$D$54-U26*변수!$D$55)/4,"") | W12: =SUM(S12:V12) | X12: =IFERROR((V28*변수!$D$54-V26*변수!$D$55)/4,"") | Y12: =IFERROR((X28*변수!$D$54-X26*변수!$D$55)/4,"") | Z12: =IFERROR((Y28*변수!$D$54-Y26*변수!$D$55)/4,"") | AA12: =IFERROR((Z28*변수!$D$54-Z26*변수!$D$55)/4,"") | AB12: =SUM(X12:AA12)
A13: 외환손익 | B13: 손익 | C13: 억원 | D13: 외환손익(실적만; 추정 환효과는 환관련손익) | E13: =IFERROR((VLOOKUP("외환차익",BS연결,MATCH(E$1,BS연결H,0),0)-VLOOKUP("외환차손",BS연결,MATCH(E$1,BS연결H,0),0)+VLOOKUP("외화환산이익",BS연결,MATCH(E$1,BS연결H,0),0)-VLOOKUP("외화환산손실",BS연결,MATCH(E$1,BS연결H,0),0))/100,"") | F13: =IFERROR((VLOOKUP("외환차익",BS연결,MATCH(F$1,BS연결H,0),0)-VLOOKUP("외환차손",BS연결,MATCH(F$1,BS연결H,0),0)+VLOOKUP("외화환산이익",BS연결,MATCH(F$1,BS연결H,0),0)-VLOOKUP("외화환산손실",BS연결,MATCH(F$1,BS연결H,0),0))/100,"") | G13: =IFERROR((VLOOKUP("외환차익",BS연결,MATCH(G$1,BS연결H,0),0)-VLOOKUP("외환차손",BS연결,MATCH(G$1,BS연결H,0),0)+VLOOKUP("외화환산이익",BS연결,MATCH(G$1,BS연결H,0),0)-VLOOKUP("외화환산손실",BS연결,MATCH(G$1,BS연결H,0),0))/100,"") | I13: =IFERROR((VLOOKUP("외환차익",BS연결,MATCH(I$1,BS연결H,0),0)-VLOOKUP("외환차손",BS연결,MATCH(I$1,BS연결H,0),0)+VLOOKUP("외화환산이익",BS연결,MATCH(I$1,BS연결H,0),0)-VLOOKUP("외화환산손실",BS연결,MATCH(I$1,BS연결H,0),0))/100,"") | J13: =IFERROR((VLOOKUP("외환차익",BS연결,MATCH(J$1,BS연결H,0),0)-VLOOKUP("외환차손",BS연결,MATCH(J$1,BS연결H,0),0)+VLOOKUP("외화환산이익",BS연결,MATCH(J$1,BS연결H,0),0)-VLOOKUP("외화환산손실",BS연결,MATCH(J$1,BS연결H,0),0))/100,"") | K13: =IFERROR((VLOOKUP("외환차익",BS연결,MATCH(K$1,BS연결H,0),0)-VLOOKUP("외환차손",BS연결,MATCH(K$1,BS연결H,0),0)+VLOOKUP("외화환산이익",BS연결,MATCH(K$1,BS연결H,0),0)-VLOOKUP("외화환산손실",BS연결,MATCH(K$1,BS연결H,0),0))/100,"") | L13: =IFERROR((VLOOKUP("외환차익",BS연결,MATCH(L$1,BS연결H,0),0)-VLOOKUP("외환차손",BS연결,MATCH(L$1,BS연결H,0),0)+VLOOKUP("외화환산이익",BS연결,MATCH(L$1,BS연결H,0),0)-VLOOKUP("외화환산손실",BS연결,MATCH(L$1,BS연결H,0),0))/100,"") | M13: =SUM(I13:L13) | N13: =IFERROR((VLOOKUP("외환차익",BS연결,MATCH(N$1,BS연결H,0),0)-VLOOKUP("외환차손",BS연결,MATCH(N$1,BS연결H,0),0)+VLOOKUP("외화환산이익",BS연결,MATCH(N$1,BS연결H,0),0)-VLOOKUP("외화환산손실",BS연결,MATCH(N$1,BS연결H,0),0))/100,"") | O13: =IFERROR((VLOOKUP("외환차익",BS연결,MATCH(O$1,BS연결H,0),0)-VLOOKUP("외환차손",BS연결,MATCH(O$1,BS연결H,0),0)+VLOOKUP("외화환산이익",BS연결,MATCH(O$1,BS연결H,0),0)-VLOOKUP("외화환산손실",BS연결,MATCH(O$1,BS연결H,0),0))/100,"") | P13: =변수!P24 | Q13: =변수!Q24 | R13: =SUM(N13:Q13) | S13: =변수!S24 | T13: =변수!T24 | U13: =변수!U24 | V13: =변수!V24 | W13: =SUM(S13:V13) | X13: =변수!X24 | Y13: =변수!Y24 | Z13: =변수!Z24 | AA13: =변수!AA24 | AB13: =SUM(X13:AA13)
A14: 파생상품손익 | B14: 손익 | C14: 억원 | D14: 파생상품손익 | F14: =IFERROR((VLOOKUP("파생상품이익",BS연결,MATCH(F$1,BS연결H,0),0)-VLOOKUP("파생상품손실",BS연결,MATCH(F$1,BS연결H,0),0))/100,"") | J14: =IFERROR((VLOOKUP("파생상품이익",BS연결,MATCH(J$1,BS연결H,0),0)-VLOOKUP("파생상품손실",BS연결,MATCH(J$1,BS연결H,0),0))/100,"") | K14: =IFERROR((VLOOKUP("파생상품이익",BS연결,MATCH(K$1,BS연결H,0),0)-VLOOKUP("파생상품손실",BS연결,MATCH(K$1,BS연결H,0),0))/100,"") | L14: =IFERROR((VLOOKUP("파생상품이익",BS연결,MATCH(L$1,BS연결H,0),0)-VLOOKUP("파생상품손실",BS연결,MATCH(L$1,BS연결H,0),0))/100,"") | M14: =SUM(I14:L14) | N14: =IFERROR((VLOOKUP("파생상품이익",BS연결,MATCH(N$1,BS연결H,0),0)-VLOOKUP("파생상품손실",BS연결,MATCH(N$1,BS연결H,0),0))/100,"") | O14: =IFERROR((VLOOKUP("파생상품이익",BS연결,MATCH(O$1,BS연결H,0),0)-VLOOKUP("파생상품손실",BS연결,MATCH(O$1,BS연결H,0),0))/100,"") | P14: =변수!P25 | Q14: =변수!Q25 | R14: =SUM(N14:Q14) | S14: =변수!S25 | T14: =변수!T25 | U14: =변수!U25 | V14: =변수!V25 | W14: =SUM(S14:V14) | X14: =변수!X25 | Y14: =변수!Y25 | Z14: =변수!Z25 | AA14: =변수!AA25 | AB14: =SUM(X14:AA14)
A15: 기타금융손익 | B15: 손익 | C15: 억원 | D15: 기타금융손익(금융손익 잔차) | F15: =IFERROR(F11-F12-F13-F14,"") | J15: =IFERROR(J11-J12-J13-J14,"") | K15: =IFERROR(K11-K12-K13-K14,"") | L15: =IFERROR(L11-L12-L13-L14,"") | M15: =SUM(I15:L15) | N15: =IFERROR(N11-N12-N13-N14,"") | O15: =IFERROR(O11-O12-O13-O14,"") | P15: =변수!P26 | Q15: =변수!Q26 | R15: =SUM(N15:Q15) | S15: =변수!S26 | T15: =변수!T26 | U15: =변수!U26 | V15: =변수!V26 | W15: =SUM(S15:V15) | X15: =변수!X26 | Y15: =변수!Y26 | Z15: =변수!Z26 | AA15: =변수!AA26 | AB15: =SUM(X15:AA15)
A16: 기타영업외손익 | B16: 손익 | C16: 억원 | D16: 기타영업외손익 | E16: =IFERROR(VLOOKUP($D16,BS연결,MATCH(E$1,BS연결H,0),0)/100,"") | F16: =IFERROR(VLOOKUP($D16,BS연결,MATCH(F$1,BS연결H,0),0)/100,"") | G16: =IFERROR(VLOOKUP($D16,BS연결,MATCH(G$1,BS연결H,0),0)/100,"") | I16: =IFERROR(VLOOKUP($D16,BS연결,MATCH(I$1,BS연결H,0),0)/100,"") | J16: =IFERROR(VLOOKUP($D16,BS연결,MATCH(J$1,BS연결H,0),0)/100,"") | K16: =IFERROR(VLOOKUP($D16,BS연결,MATCH(K$1,BS연결H,0),0)/100,"") | L16: =IFERROR(VLOOKUP($D16,BS연결,MATCH(L$1,BS연결H,0),0)/100,"") | M16: =IFERROR(VLOOKUP($D16,BS연결,MATCH(M$1,BS연결H,0),0)/100,"") | N16: =IFERROR(VLOOKUP($D16,BS연결,MATCH(N$1,BS연결H,0),0)/100,"") | O16: =IFERROR(VLOOKUP($D16,BS연결,MATCH(O$1,BS연결H,0),0)/100,"") | P16: =변수!P27 | Q16: =변수!Q27 | R16: =SUM(N16:Q16) | S16: =변수!S27 | T16: =변수!T27 | U16: =변수!U27 | V16: =변수!V27 | W16: =SUM(S16:V16) | X16: =변수!X27 | Y16: =변수!Y27 | Z16: =변수!Z27 | AA16: =변수!AA27 | AB16: =SUM(X16:AA16)
A17: 지분법손익 | B17: 손익 | C17: 억원 | D17: 종속기업,공동지배기업및관계기업관련손익 | F17: =IFERROR(VLOOKUP($D17,BS연결,MATCH(F$1,BS연결H,0),0)/100,"") | G17: =IFERROR(VLOOKUP($D17,BS연결,MATCH(G$1,BS연결H,0),0)/100,"") | I17: =IFERROR(VLOOKUP($D17,BS연결,MATCH(I$1,BS연결H,0),0)/100,"") | J17: =IFERROR(VLOOKUP($D17,BS연결,MATCH(J$1,BS연결H,0),0)/100,"") | K17: =IFERROR(VLOOKUP($D17,BS연결,MATCH(K$1,BS연결H,0),0)/100,"") | L17: =IFERROR(VLOOKUP($D17,BS연결,MATCH(L$1,BS연결H,0),0)/100,"") | M17: =IFERROR(VLOOKUP($D17,BS연결,MATCH(M$1,BS연결H,0),0)/100,"") | N17: =IFERROR(VLOOKUP($D17,BS연결,MATCH(N$1,BS연결H,0),0)/100,"") | O17: =IFERROR(VLOOKUP($D17,BS연결,MATCH(O$1,BS연결H,0),0)/100,"") | P17: =변수!P28 | Q17: =변수!Q28 | R17: =SUM(N17:Q17) | S17: =변수!S28 | T17: =변수!T28 | U17: =변수!U28 | V17: =변수!V28 | W17: =SUM(S17:V17) | X17: =변수!X28 | Y17: =변수!Y28 | Z17: =변수!Z28 | AA17: =변수!AA28 | AB17: =SUM(X17:AA17)
A18: 세전이익 | B18: 손익 | C18: 억원 | D18: 법인세비용차감전계속사업이익 | E18: =IFERROR(VLOOKUP($D18,BS연결,MATCH(E$1,BS연결H,0),0)/100,"") | F18: =IFERROR(VLOOKUP($D18,BS연결,MATCH(F$1,BS연결H,0),0)/100,"") | G18: =IFERROR(VLOOKUP($D18,BS연결,MATCH(G$1,BS연결H,0),0)/100,"") | I18: =IFERROR(VLOOKUP($D18,BS연결,MATCH(I$1,BS연결H,0),0)/100,"") | J18: =IFERROR(VLOOKUP($D18,BS연결,MATCH(J$1,BS연결H,0),0)/100,"") | K18: =IFERROR(VLOOKUP($D18,BS연결,MATCH(K$1,BS연결H,0),0)/100,"") | L18: =IFERROR(VLOOKUP($D18,BS연결,MATCH(L$1,BS연결H,0),0)/100,"") | M18: =IFERROR(VLOOKUP($D18,BS연결,MATCH(M$1,BS연결H,0),0)/100,"") | N18: =IFERROR(VLOOKUP($D18,BS연결,MATCH(N$1,BS연결H,0),0)/100,"") | O18: =IFERROR(VLOOKUP($D18,BS연결,MATCH(O$1,BS연결H,0),0)/100,"") | P18: =IFERROR(P9+P11+P16+P17,"") | Q18: =IFERROR(Q9+Q11+Q16+Q17,"") | R18: =SUM(N18:Q18) | S18: =IFERROR(S9+S11+S16+S17,"") | T18: =IFERROR(T9+T11+T16+T17,"") | U18: =IFERROR(U9+U11+U16+U17,"") | V18: =IFERROR(V9+V11+V16+V17,"") | W18: =SUM(S18:V18) | X18: =IFERROR(X9+X11+X16+X17,"") | Y18: =IFERROR(Y9+Y11+Y16+Y17,"") | Z18: =IFERROR(Z9+Z11+Z16+Z17,"") | AA18: =IFERROR(AA9+AA11+AA16+AA17,"") | AB18: =SUM(X18:AA18)
A19: 법인세비용 | B19: 손익 | C19: 억원 | D19: 법인세비용 | E19: =IFERROR(VLOOKUP($D19,BS연결,MATCH(E$1,BS연결H,0),0)/100,"") | F19: =IFERROR(VLOOKUP($D19,BS연결,MATCH(F$1,BS연결H,0),0)/100,"") | G19: =IFERROR(VLOOKUP($D19,BS연결,MATCH(G$1,BS연결H,0),0)/100,"") | I19: =IFERROR(VLOOKUP($D19,BS연결,MATCH(I$1,BS연결H,0),0)/100,"") | J19: =IFERROR(VLOOKUP($D19,BS연결,MATCH(J$1,BS연결H,0),0)/100,"") | K19: =IFERROR(VLOOKUP($D19,BS연결,MATCH(K$1,BS연결H,0),0)/100,"") | L19: =IFERROR(VLOOKUP($D19,BS연결,MATCH(L$1,BS연결H,0),0)/100,"") | M19: =IFERROR(VLOOKUP($D19,BS연결,MATCH(M$1,BS연결H,0),0)/100,"") | N19: =IFERROR(VLOOKUP($D19,BS연결,MATCH(N$1,BS연결H,0),0)/100,"") | O19: =IFERROR(VLOOKUP($D19,BS연결,MATCH(O$1,BS연결H,0),0)/100,"") | P19: =IFERROR(MAX(P18,0)*변수!P29,"") | Q19: =IFERROR(MAX(Q18,0)*변수!Q29,"") | R19: =SUM(N19:Q19) | S19: =IFERROR(MAX(S18,0)*변수!S29,"") | T19: =IFERROR(MAX(T18,0)*변수!T29,"") | U19: =IFERROR(MAX(U18,0)*변수!U29,"") | V19: =IFERROR(MAX(V18,0)*변수!V29,"") | W19: =SUM(S19:V19) | X19: =IFERROR(MAX(X18,0)*변수!X29,"") | Y19: =IFERROR(MAX(Y18,0)*변수!Y29,"") | Z19: =IFERROR(MAX(Z18,0)*변수!Z29,"") | AA19: =IFERROR(MAX(AA18,0)*변수!AA29,"") | AB19: =SUM(X19:AA19)
A20: 당기순이익 | B20: 손익 | C20: 억원 | D20: 당기순이익 | E20: =IFERROR(VLOOKUP($D20,BS연결,MATCH(E$1,BS연결H,0),0)/100,"") | F20: =IFERROR(VLOOKUP($D20,BS연결,MATCH(F$1,BS연결H,0),0)/100,"") | G20: =IFERROR(VLOOKUP($D20,BS연결,MATCH(G$1,BS연결H,0),0)/100,"") | I20: =IFERROR(VLOOKUP($D20,BS연결,MATCH(I$1,BS연결H,0),0)/100,"") | J20: =IFERROR(VLOOKUP($D20,BS연결,MATCH(J$1,BS연결H,0),0)/100,"") | K20: =IFERROR(VLOOKUP($D20,BS연결,MATCH(K$1,BS연결H,0),0)/100,"") | L20: =IFERROR(VLOOKUP($D20,BS연결,MATCH(L$1,BS연결H,0),0)/100,"") | M20: =IFERROR(VLOOKUP($D20,BS연결,MATCH(M$1,BS연결H,0),0)/100,"") | N20: =IFERROR(VLOOKUP($D20,BS연결,MATCH(N$1,BS연결H,0),0)/100,"") | O20: =IFERROR(VLOOKUP($D20,BS연결,MATCH(O$1,BS연결H,0),0)/100,"") | P20: =IFERROR(P18-P19,"") | Q20: =IFERROR(Q18-Q19,"") | R20: =SUM(N20:Q20) | S20: =IFERROR(S18-S19,"") | T20: =IFERROR(T18-T19,"") | U20: =IFERROR(U18-U19,"") | V20: =IFERROR(V18-V19,"") | W20: =SUM(S20:V20) | X20: =IFERROR(X18-X19,"") | Y20: =IFERROR(Y18-Y19,"") | Z20: =IFERROR(Z18-Z19,"") | AA20: =IFERROR(AA18-AA19,"") | AB20: =SUM(X20:AA20)
A21: 지배주주순이익 | B21: 손익 | C21: 억원 | D21: (지배주주지분)당기순이익 | E21: =IFERROR(VLOOKUP($D21,BS연결,MATCH(E$1,BS연결H,0),0)/100,"") | F21: =IFERROR(VLOOKUP($D21,BS연결,MATCH(F$1,BS연결H,0),0)/100,"") | G21: =IFERROR(VLOOKUP($D21,BS연결,MATCH(G$1,BS연결H,0),0)/100,"") | I21: =IFERROR(VLOOKUP($D21,BS연결,MATCH(I$1,BS연결H,0),0)/100,"") | J21: =IFERROR(VLOOKUP($D21,BS연결,MATCH(J$1,BS연결H,0),0)/100,"") | K21: =IFERROR(VLOOKUP($D21,BS연결,MATCH(K$1,BS연결H,0),0)/100,"") | L21: =IFERROR(VLOOKUP($D21,BS연결,MATCH(L$1,BS연결H,0),0)/100,"") | M21: =IFERROR(VLOOKUP($D21,BS연결,MATCH(M$1,BS연결H,0),0)/100,"") | N21: =IFERROR(VLOOKUP($D21,BS연결,MATCH(N$1,BS연결H,0),0)/100,"") | O21: =IFERROR(VLOOKUP($D21,BS연결,MATCH(O$1,BS연결H,0),0)/100,"") | P21: =IFERROR(P20*변수!P30,"") | Q21: =IFERROR(Q20*변수!Q30,"") | R21: =SUM(N21:Q21) | S21: =IFERROR(S20*변수!S30,"") | T21: =IFERROR(T20*변수!T30,"") | U21: =IFERROR(U20*변수!U30,"") | V21: =IFERROR(V20*변수!V30,"") | W21: =SUM(S21:V21) | X21: =IFERROR(X20*변수!X30,"") | Y21: =IFERROR(Y20*변수!Y30,"") | Z21: =IFERROR(Z20*변수!Z30,"") | AA21: =IFERROR(AA20*변수!AA30,"") | AB21: =SUM(X21:AA21)
A22: 자산총계 | B22: 재무상태 | C22: 억원 | D22: 자산총계 | E22: =IFERROR(VLOOKUP($D22,BS연결,MATCH(E$1,BS연결H,0),0)/100,"") | F22: =IFERROR(VLOOKUP($D22,BS연결,MATCH(F$1,BS연결H,0),0)/100,"") | G22: =IFERROR(VLOOKUP($D22,BS연결,MATCH(G$1,BS연결H,0),0)/100,"") | H22: =IFERROR(VLOOKUP($D22,BS연결,MATCH(H$1,BS연결H,0),0)/100,"") | I22: =IFERROR(VLOOKUP($D22,BS연결,MATCH(I$1,BS연결H,0),0)/100,"") | J22: =IFERROR(VLOOKUP($D22,BS연결,MATCH(J$1,BS연결H,0),0)/100,"") | K22: =IFERROR(VLOOKUP($D22,BS연결,MATCH(K$1,BS연결H,0),0)/100,"") | L22: =IFERROR(VLOOKUP($D22,BS연결,MATCH(L$1,BS연결H,0),0)/100,"") | ... O22: =IFERROR(VLOOKUP($D22,BS연결,MATCH(O$1,BS연결H,0),0)/100,"") | P22: =IFERROR(P23+P24,"") | Q22: =IFERROR(Q23+Q24,"") | R22: =Q22 | S22: =IFERROR(S23+S24,"") | T22: =IFERROR(T23+T24,"") | U22: =IFERROR(U23+U24,"") | V22: =IFERROR(V23+V24,"") | W22: =V22 | X22: =IFERROR(X23+X24,"") | Y22: =IFERROR(Y23+Y24,"") | Z22: =IFERROR(Z23+Z24,"") | AA22: =IFERROR(AA23+AA24,"") | AB22: =AA22
A23: 부채총계 | B23: 재무상태 | C23: 억원 | D23: 부채총계 | E23: =IFERROR(VLOOKUP($D23,BS연결,MATCH(E$1,BS연결H,0),0)/100,"") | F23: =IFERROR(VLOOKUP($D23,BS연결,MATCH(F$1,BS연결H,0),0)/100,"") | G23: =IFERROR(VLOOKUP($D23,BS연결,MATCH(G$1,BS연결H,0),0)/100,"") | H23: =IFERROR(VLOOKUP($D23,BS연결,MATCH(H$1,BS연결H,0),0)/100,"") | I23: =IFERROR(VLOOKUP($D23,BS연결,MATCH(I$1,BS연결H,0),0)/100,"") | J23: =IFERROR(VLOOKUP($D23,BS연결,MATCH(J$1,BS연결H,0),0)/100,"") | K23: =IFERROR(VLOOKUP($D23,BS연결,MATCH(K$1,BS연결H,0),0)/100,"") | L23: =IFERROR(VLOOKUP($D23,BS연결,MATCH(L$1,BS연결H,0),0)/100,"") | ... O23: =IFERROR(VLOOKUP($D23,BS연결,MATCH(O$1,BS연결H,0),0)/100,"") | P23: =IFERROR(O23*(1+변수!P31),"") | Q23: =IFERROR(P23*(1+변수!Q31),"") | R23: =Q23 | S23: =IFERROR(Q23*(1+변수!S31),"") | T23: =IFERROR(S23*(1+변수!T31),"") | U23: =IFERROR(T23*(1+변수!U31),"") | V23: =IFERROR(U23*(1+변수!V31),"") | W23: =V23 | X23: =IFERROR(V23*(1+변수!X31),"") | Y23: =IFERROR(X23*(1+변수!Y31),"") | Z23: =IFERROR(Y23*(1+변수!Z31),"") | AA23: =IFERROR(Z23*(1+변수!AA31),"") | AB23: =AA23
A24: 자본총계 | B24: 재무상태 | C24: 억원 | D24: 자본총계 | E24: =IFERROR(VLOOKUP($D24,BS연결,MATCH(E$1,BS연결H,0),0)/100,"") | F24: =IFERROR(VLOOKUP($D24,BS연결,MATCH(F$1,BS연결H,0),0)/100,"") | G24: =IFERROR(VLOOKUP($D24,BS연결,MATCH(G$1,BS연결H,0),0)/100,"") | H24: =IFERROR(VLOOKUP($D24,BS연결,MATCH(H$1,BS연결H,0),0)/100,"") | I24: =IFERROR(VLOOKUP($D24,BS연결,MATCH(I$1,BS연결H,0),0)/100,"") | J24: =IFERROR(VLOOKUP($D24,BS연결,MATCH(J$1,BS연결H,0),0)/100,"") | K24: =IFERROR(VLOOKUP($D24,BS연결,MATCH(K$1,BS연결H,0),0)/100,"") | L24: =IFERROR(VLOOKUP($D24,BS연결,MATCH(L$1,BS연결H,0),0)/100,"") | ... O24: =IFERROR(VLOOKUP($D24,BS연결,MATCH(O$1,BS연결H,0),0)/100,"") | P24: =IFERROR(O24+P20-변수!P32,"") | Q24: =IFERROR(P24+Q20-변수!Q32,"") | R24: =Q24 | S24: =IFERROR(Q24+S20-변수!S32,"") | T24: =IFERROR(S24+T20-변수!T32,"") | U24: =IFERROR(T24+U20-변수!U32,"") | V24: =IFERROR(U24+V20-변수!V32,"") | W24: =V24 | X24: =IFERROR(V24+X20-변수!X32,"") | Y24: =IFERROR(X24+Y20-변수!Y32,"") | Z24: =IFERROR(Y24+Z20-변수!Z32,"") | AA24: =IFERROR(Z24+AA20-변수!AA32,"") | AB24: =AA24
A25: 지배주주지분 | B25: 재무상태 | C25: 억원 | D25: 지배주주지분 | E25: =IFERROR(VLOOKUP($D25,BS연결,MATCH(E$1,BS연결H,0),0)/100,"") | F25: =IFERROR(VLOOKUP($D25,BS연결,MATCH(F$1,BS연결H,0),0)/100,"") | G25: =IFERROR(VLOOKUP($D25,BS연결,MATCH(G$1,BS연결H,0),0)/100,"") | H25: =IFERROR(VLOOKUP($D25,BS연결,MATCH(H$1,BS연결H,0),0)/100,"") | I25: =IFERROR(VLOOKUP($D25,BS연결,MATCH(I$1,BS연결H,0),0)/100,"") | J25: =IFERROR(VLOOKUP($D25,BS연결,MATCH(J$1,BS연결H,0),0)/100,"") | K25: =IFERROR(VLOOKUP($D25,BS연결,MATCH(K$1,BS연결H,0),0)/100,"") | L25: =IFERROR(VLOOKUP($D25,BS연결,MATCH(L$1,BS연결H,0),0)/100,"") | ... O25: =IFERROR(VLOOKUP($D25,BS연결,MATCH(O$1,BS연결H,0),0)/100,"") | P25: =IFERROR(O25+P21-변수!P33,"") | Q25: =IFERROR(P25+Q21-변수!Q33,"") | R25: =Q25 | S25: =IFERROR(Q25+S21-변수!S33,"") | T25: =IFERROR(S25+T21-변수!T33,"") | U25: =IFERROR(T25+U21-변수!U33,"") | V25: =IFERROR(U25+V21-변수!V33,"") | W25: =V25 | X25: =IFERROR(V25+X21-변수!X33,"") | Y25: =IFERROR(X25+Y21-변수!Y33,"") | Z25: =IFERROR(Y25+Z21-변수!Z33,"") | AA25: =IFERROR(Z25+AA21-변수!AA33,"") | AB25: =AA25
A26: 총차입금 | B26: 재무상태 | C26: 억원 | D26: 총차입금 | F26: =IFERROR(VLOOKUP($D26,BS연결,MATCH(F$1,BS연결H,0),0)/100,"") | G26: =IFERROR(VLOOKUP($D26,BS연결,MATCH(G$1,BS연결H,0),0)/100,"") | H26: =IFERROR(VLOOKUP($D26,BS연결,MATCH(H$1,BS연결H,0),0)/100,"") | J26: =IFERROR(VLOOKUP($D26,BS연결,MATCH(J$1,BS연결H,0),0)/100,"") | L26: =IFERROR(VLOOKUP($D26,BS연결,MATCH(L$1,BS연결H,0),0)/100,"") | M26: =IFERROR(VLOOKUP($D26,BS연결,MATCH(M$1,BS연결H,0),0)/100,"") | R26: =Q26 | W26: =V26 | AB26: =AA26
A27: 순차입금 | B27: 재무상태 | C27: 억원 | D27: 순차입금 | F27: =IFERROR(VLOOKUP($D27,BS연결,MATCH(F$1,BS연결H,0),0)/100,"") | G27: =IFERROR(VLOOKUP($D27,BS연결,MATCH(G$1,BS연결H,0),0)/100,"") | H27: =IFERROR(VLOOKUP($D27,BS연결,MATCH(H$1,BS연결H,0),0)/100,"") | J27: =IFERROR(VLOOKUP($D27,BS연결,MATCH(J$1,BS연결H,0),0)/100,"") | L27: =IFERROR(VLOOKUP($D27,BS연결,MATCH(L$1,BS연결H,0),0)/100,"") | M27: =IFERROR(VLOOKUP($D27,BS연결,MATCH(M$1,BS연결H,0),0)/100,"") | R27: =Q27 | W27: =V27 | AB27: =AA27
A28: 이자발생자산 | B28: 재무상태 | C28: 억원 | D28: 이자발생자산 | E28: =IFERROR(VLOOKUP($D28,BS연결,MATCH(E$1,BS연결H,0),0)/100,"") | F28: =IFERROR(VLOOKUP($D28,BS연결,MATCH(F$1,BS연결H,0),0)/100,"") | G28: =IFERROR(VLOOKUP($D28,BS연결,MATCH(G$1,BS연결H,0),0)/100,"") | H28: =IFERROR(VLOOKUP($D28,BS연결,MATCH(H$1,BS연결H,0),0)/100,"") | I28: =IFERROR(VLOOKUP($D28,BS연결,MATCH(I$1,BS연결H,0),0)/100,"") | J28: =IFERROR(VLOOKUP($D28,BS연결,MATCH(J$1,BS연결H,0),0)/100,"") | K28: =IFERROR(VLOOKUP($D28,BS연결,MATCH(K$1,BS연결H,0),0)/100,"") | L28: =IFERROR(VLOOKUP($D28,BS연결,MATCH(L$1,BS연결H,0),0)/100,"") | ... O28: =IFERROR(VLOOKUP($D28,BS연결,MATCH(O$1,BS연결H,0),0)/100,"") | P28: =IFERROR(O28*(1+변수!P36),"") | Q28: =IFERROR(P28*(1+변수!Q36),"") | R28: =Q28 | S28: =IFERROR(Q28*(1+변수!S36),"") | T28: =IFERROR(S28*(1+변수!T36),"") | U28: =IFERROR(T28*(1+변수!U36),"") | V28: =IFERROR(U28*(1+변수!V36),"") | W28: =V28 | X28: =IFERROR(V28*(1+변수!X36),"") | Y28: =IFERROR(X28*(1+변수!Y36),"") | Z28: =IFERROR(Y28*(1+변수!Z36),"") | AA28: =IFERROR(Z28*(1+변수!AA36),"") | AB28: =AA28
A29: 현금및현금성자산 | B29: 재무상태 | C29: 억원 | D29: 현금및현금성자산 | E29: =IFERROR(VLOOKUP($D29,BS연결,MATCH(E$1,BS연결H,0),0)/100,"") | F29: =IFERROR(VLOOKUP($D29,BS연결,MATCH(F$1,BS연결H,0),0)/100,"") | G29: =IFERROR(VLOOKUP($D29,BS연결,MATCH(G$1,BS연결H,0),0)/100,"") | H29: =IFERROR(VLOOKUP($D29,BS연결,MATCH(H$1,BS연결H,0),0)/100,"") | I29: =IFERROR(VLOOKUP($D29,BS연결,MATCH(I$1,BS연결H,0),0)/100,"") | J29: =IFERROR(VLOOKUP($D29,BS연결,MATCH(J$1,BS연결H,0),0)/100,"") | K29: =IFERROR(VLOOKUP($D29,BS연결,MATCH(K$1,BS연결H,0),0)/100,"") | L29: =IFERROR(VLOOKUP($D29,BS연결,MATCH(L$1,BS연결H,0),0)/100,"") | ... O29: =IFERROR(VLOOKUP($D29,BS연결,MATCH(O$1,BS연결H,0),0)/100,"") | R29: =Q29 | W29: =V29 | AB29: =AA29
A30: CAPEX | B30: 현금흐름 | C30: 억원 | D30: CAPEX | E30: =IFERROR(VLOOKUP($D30,BS연결,MATCH(E$1,BS연결H,0),0)/100,"") | F30: =IFERROR(VLOOKUP($D30,BS연결,MATCH(F$1,BS연결H,0),0)/100,"") | G30: =IFERROR(VLOOKUP($D30,BS연결,MATCH(G$1,BS연결H,0),0)/100,"") | I30: =IFERROR(VLOOKUP($D30,BS연결,MATCH(I$1,BS연결H,0),0)/100,"") | J30: =IFERROR(VLOOKUP($D30,BS연결,MATCH(J$1,BS연결H,0),0)/100,"") | K30: =IFERROR(VLOOKUP($D30,BS연결,MATCH(K$1,BS연결H,0),0)/100,"") | L30: =IFERROR(VLOOKUP($D30,BS연결,MATCH(L$1,BS연결H,0),0)/100,"") | M30: =IFERROR(VLOOKUP($D30,BS연결,MATCH(M$1,BS연결H,0),0)/100,"") | N30: =IFERROR(VLOOKUP($D30,BS연결,MATCH(N$1,BS연결H,0),0)/100,"") | O30: =IFERROR(VLOOKUP($D30,BS연결,MATCH(O$1,BS연결H,0),0)/100,"") | P30: =IFERROR(K30*(1+변수!P38),"") | Q30: =IFERROR(L30*(1+변수!Q38),"") | R30: =SUM(N30:Q30) | S30: =IFERROR(N30*(1+변수!S38),"") | T30: =IFERROR(O30*(1+변수!T38),"") | U30: =IFERROR(P30*(1+변수!U38),"") | V30: =IFERROR(Q30*(1+변수!V38),"") | W30: =SUM(S30:V30) | X30: =IFERROR(S30*(1+변수!X38),"") | Y30: =IFERROR(T30*(1+변수!Y38),"") | Z30: =IFERROR(U30*(1+변수!Z38),"") | AA30: =IFERROR(V30*(1+변수!AA38),"") | AB30: =SUM(X30:AA30)
A31: 영업활동현금흐름 | B31: 현금흐름 | C31: 억원 | D31: 영업활동으로인한현금흐름 | E31: =IFERROR(VLOOKUP($D31,BS연결,MATCH(E$1,BS연결H,0),0)/100,"") | F31: =IFERROR(VLOOKUP($D31,BS연결,MATCH(F$1,BS연결H,0),0)/100,"") | G31: =IFERROR(VLOOKUP($D31,BS연결,MATCH(G$1,BS연결H,0),0)/100,"") | I31: =IFERROR(VLOOKUP($D31,BS연결,MATCH(I$1,BS연결H,0),0)/100,"") | J31: =IFERROR(VLOOKUP($D31,BS연결,MATCH(J$1,BS연결H,0),0)/100,"") | K31: =IFERROR(VLOOKUP($D31,BS연결,MATCH(K$1,BS연결H,0),0)/100,"") | L31: =IFERROR(VLOOKUP($D31,BS연결,MATCH(L$1,BS연결H,0),0)/100,"") | M31: =IFERROR(VLOOKUP($D31,BS연결,MATCH(M$1,BS연결H,0),0)/100,"") | N31: =IFERROR(VLOOKUP($D31,BS연결,MATCH(N$1,BS연결H,0),0)/100,"") | O31: =IFERROR(VLOOKUP($D31,BS연결,MATCH(O$1,BS연결H,0),0)/100,"") | R31: =SUM(N31:Q31) | W31: =SUM(S31:V31) | AB31: =SUM(X31:AA31)
A32: 주식수 | B32: 주당 | C32: 백만주 | D32: 유통주식수 | E32: 44.45 | F32: 44.45 | G32: 44.829 | H32: =G32 | I32: 44.829 | J32: 44.829 | K32: 44.829 | L32: 44.831 | M32: =L32 | N32: 44.831 | O32: 44.833 | P32: =IFERROR(O32*(1+변수!P40),"") | Q32: =IFERROR(P32*(1+변수!Q40),"") | R32: =Q32 | S32: =IFERROR(Q32*(1+변수!S40),"") | T32: =IFERROR(S32*(1+변수!T40),"") | U32: =IFERROR(T32*(1+변수!U40),"") | V32: =IFERROR(U32*(1+변수!V40),"") | W32: =V32 | X32: =IFERROR(V32*(1+변수!X40),"") | Y32: =IFERROR(X32*(1+변수!Y40),"") | Z32: =IFERROR(Y32*(1+변수!Z40),"") | AA32: =IFERROR(Z32*(1+변수!AA40),"") | AB32: =AA32
A33: EPS | B33: 주당 | C33: 원 | D33: EPS | E33: =IFERROR(E21*100/E32,"") | F33: =IFERROR(F21*100/F32,"") | G33: =IFERROR(G21*100/G32,"") | I33: =IFERROR(I21*100/I32,"") | J33: =IFERROR(J21*100/J32,"") | K33: =IFERROR(K21*100/K32,"") | L33: =IFERROR(L21*100/L32,"") | M33: =SUM(I33:L33) | N33: =IFERROR(N21*100/N32,"") | O33: =IFERROR(O21*100/O32,"") | P33: =IFERROR(P21*100/P32,"") | Q33: =IFERROR(Q21*100/Q32,"") | R33: =SUM(N33:Q33) | S33: =IFERROR(S21*100/S32,"") | T33: =IFERROR(T21*100/T32,"") | U33: =IFERROR(U21*100/U32,"") | V33: =IFERROR(V21*100/V32,"") | W33: =SUM(S33:V33) | X33: =IFERROR(X21*100/X32,"") | Y33: =IFERROR(Y21*100/Y32,"") | Z33: =IFERROR(Z21*100/Z32,"") | AA33: =IFERROR(AA21*100/AA32,"") | AB33: =SUM(X33:AA33)
