Workbook
Name 변수H: 변수!$C$1:$AE$1
Name 환율: 변수!$C$6:$AE$13
Name BS연결H: BS연결!$C$1:$AE$1
Name BS연결: BS연결!$C$5:$AE$96
Name BS별도H: BS별도!$C$1:$AE$1
Name BS별도: BS별도!$C$5:$AE$85
Name SUBQH: subQ!$A$1:$AE$1
Name subQ: subQ!$A$5:$AE$40

Sheet README
A1: 현대힘스(460930) 실적 모델 — ARGUS 한국조선
A2: 기준 분기 2026Q2 · 마지막 실적 2026Q2 · 생성 2026-10-19
A3: 모든 수치는 모델 산출값(DART 공개 재무제표 + 우리 추정)이다 — 목표주가·투자 추천 아님. 참고용 · 투자조언 아님.
A5: 시트
A6: 변수 가정 시계열. 환율 8행(ECB via frankfurter — L2 fx.json; 추정 분기 = 노란 가정), 추정 드라이버(노란 셀 = 모델값에서 역산한 가정, 바꾸면 재계산; 연녹 셀 = 3절 스칼라 참조 수식), 3절 스칼라 가정(세율·판관비율·지배주주비중·이자율·종가·PER 밴드·COE·외화 순노출·헤지비율)
A7: BS연결/BS별도 FnGuide 계정명 × 기간 값 덤프(백만원). 행1 분기라벨, 행4 YYYY.MM / YYYY.12A. 이름정의 BS연결H·BS연결(계정명 C열부터)
A8: subQ 분기 서브모델(억원 = 백만원/100). 확정 행: =IFERROR(VLOOKUP($D행,BS연결,MATCH(E$1,BS연결H,0),0)/100,"") 추정 행: 변수 시트 가정 셀 참조 수식. 외환손익·파생상품손익은 BS 계정 합·차, 기타금융손익은 잔차, OPM·EPS·BPS·PER·PBR 은 파생 수식
A9: SLS 선표(조선사만, sls json 있을 때): 요약 행(sls 저장값) + 계약별 스케줄(백만$) × (헤지비율 × 헤지환율 + (1−헤지비율) × 건조시점 환율[변수 원/달러(평균)]) → 원화 수식 블록 → 합계 행이 subQ 매출조선에 연결
A10: 시나리오 신규수주 보수/기준/낙관(forecast_panel 패널, 모델에 scenarios 가 있을 때만): 매출액·영업이익 = subQ 기준값 ± (시나리오 신규 − base 신규) × OPM. base 만 subQ 행에 포함, 나머지는 합산 안 함
A11: 분기/연간예상 subQ 를 이름(A열 key)으로 VLOOKUP 한 보고서 표(억원)
A12: TP PER 밴드 × 12M fwd EPS, PBR = ROE/COE × BPS — 모델 산출값 구간, 목표주가·추천 아님
A13: 외화 환율 QoQ, 외화 순노출 × Δ기말환율 → 환관련손익 추정
... A34: 백테스트: {"freeze": "2025Q2", "horizon": 4, "revenue_wape_pct": 7.6, "op_wape_pct": 19.5, "n": 4, "note": "단일 회사 4분기 — 통계 아님", "driver_at_freeze": "customer_yard_revenue_weighted", "selection_oos_at_freeze": {"freeze": "2024Q2", "n": 4, "wape_link": null, "wape_trend": null, "adopted": "undetermined", "decision": "undetermined", "note": "동결 2024Q2 이전 실적 3분기(<8) 또는 이후 실측 4분기 → OOS 비교 불가(undetermined), 유의성 조건만으로 채택"}, "frozen_inputs": "fin(연결/별도)·고객 조선사 모델·지주 자회사 모델은 2025Q2 까지의 분기만; 선표는 체결일 ≤ 2025Q2 말일 계약(원장 최신 금액·코호트 등급, 환산 없음); 잔고는 yards_cache 2025Q2; 시세·환율 forward·prices·forecast_panel 신규수주 미사용. 고객 가중치(suppliers.json 언급 비중)와 합병 체인링크는 현재 지식; 고객 연동 채택은 동결 모델 안에서도 자기 la−4분기 OOS 규칙(selection_oos_at_freeze)", "detail": [{"q": "2025Q3", "rev_pred": 649.23, "rev_act": 605.92, "op_pred": 69.75, "op_act": 67.88}, {"q": "2025Q4", "rev_pred": 737.31, "rev_act": 669.42, "op_pred": 79.22, "op_act": 64.77}, {"q": "2026Q1", "rev_pred": 699.01, "rev_act": 646.1, "op_pred": 75.1, "op_act": 85.3}, {"q": "2026Q2", "rev_pred": 764.28, "rev_act": 727.68, "op_pred": 82.12, "op_act": 121.83}]}

Sheet 변수
C1: 이름: 변수H | E1: 4Q23 | F1: 2023 | G1: 1Q24 | H1: 2Q24 | I1: 3Q24 | J1: 4Q24 | K1: 2024 | L1: 1Q25 | M1: 2Q25 | N1: 3Q25 | O1: 4Q25 | P1: 2025 | Q1: 1Q26 | R1: 2Q26 | S1: 3Q26 | T1: 4Q26 | U1: 2026 | V1: 1Q27 | W1: 2Q27 | X1: 3Q27 | Y1: 4Q27 | Z1: 2027 | AA1: 1Q28 | AB1: 2Q28 | AC1: 3Q28 | AD1: 4Q28 | AE1: 2028
A2: 가정 시계열 — 노란 셀은 추정 가정(모델값에서 역산), 연녹 셀은 3절 스칼라 참조 수식. 바꾸면 subQ·분기·연간예상·TP·시나리오가 재계산됩니다.
E3: 1 | F3: 2 | G3: 3 | H3: 4 | I3: 5 | J3: 6 | K3: 7 | L3: 8 | M3: 9 | N3: 10 | O3: 11 | P3: 12 | Q3: 13 | R3: 14 | S3: 15 | T3: 16 | U3: 17 | V3: 18 | W3: 19 | X3: 20 | Y3: 21 | Z3: 22 | AA3: 23 | AB3: 24 | AC3: 25 | AD3: 26 | AE3: 27
E4: 2023.12 | F4: 2023.12A | G4: 2024.03 | H4: 2024.06 | I4: 2024.09 | J4: 2024.12 | K4: 2024.12A | L4: 2025.03 | M4: 2025.06 | N4: 2025.09 | O4: 2025.12 | P4: 2025.12A | Q4: 2026.03 | R4: 2026.06 | S4: 2026.09 | T4: 2026.12 | U4: 2026.12A | V4: 2027.03 | W4: 2027.06 | X4: 2027.09 | Y4: 2027.12 | Z4: 2027.12A | AA4: 2028.03 | AB4: 2028.06 | AC4: 2028.09 | AD4: 2028.12 | AE4: 2028.12A
B5: 1. FX | C5: 이름: 환율
A6: USDKRW_avg | C6: 원/달러(평균) | E6: 1322.01 | F6: 1306.85 | G6: 1330.14 | H6: 1371.28 | I6: 1356.22 | J6: 1396.3 | K6: 1363.53 | L6: 1452.28 | M6: 1398.52 | N6: 1386.95 | O6: 1449.19 | P6: 1421.52 | Q6: 1466.12 | R6: 1501.75 | S6: 1418.75 | T6: 1342.11 | U6: 1454.27 | V6: 1332.1 | W6: 1332.1 | X6: 1332.1 | Y6: 1332.1 | AA6: 1332.1 | AB6: 1332.1 | AC6: 1332.1 | AD6: 1332.1
A7: USDKRW_end | C7: 원/달러(기말) | E7: 1297.43 | F7: 1297.43 | G7: 1349.25 | H7: 1377.73 | I7: 1312.17 | J7: 1474.78 | K7: 1474.78 | L7: 1474.54 | M7: 1355.13 | N7: 1403.67 | O7: 1444.2 | P7: 1444.2 | Q7: 1524.8 | R7: 1550.89 | S7: 1355.4 | T7: 1332.1 | U7: 1332.1 | V7: 1332.1 | W7: 1332.1 | X7: 1332.1 | Y7: 1332.1 | AA7: 1332.1 | AB7: 1332.1 | AC7: 1332.1 | AD7: 1332.1
A8: JPY100KRW_avg | C8: 원/100Y(평균) | E8: 893.22 | F8: 931.11 | G8: 896.29 | H8: 880.14 | I8: 909.35 | J8: 917.25 | K8: 900.92 | L8: 952.59 | M8: 967.92 | N8: 940.32 | O8: 940.77 | P8: 950.17 | Q8: 934.39 | R8: 942.16 | S8: 890.41 | T8: 848.59 | U8: 917.39 | V8: 842.99 | W8: 842.99 | X8: 842.99 | Y8: 842.99 | AA8: 842.99 | AB8: 842.99 | AC8: 842.99 | AD8: 842.99
A9: JPY100KRW_end | C9: 원/100Y(기말) | E9: 917.04 | F9: 917.04 | G9: 892.42 | H9: 857.76 | I9: 919.21 | J9: 939.65 | K9: 939.65 | L9: 986.84 | M9: 938.85 | N9: 948.49 | O9: 921.81 | P9: 921.81 | Q9: 955.99 | R9: 954.75 | S9: 863.31 | T9: 842.99 | U9: 842.99 | V9: 842.99 | W9: 842.99 | X9: 842.99 | Y9: 842.99 | AA9: 842.99 | AB9: 842.99 | AC9: 842.99 | AD9: 842.99
A10: EURKRW_avg | C10: W/Euro(평균) | E10: 1420.91 | F10: 1412.88 | G10: 1444.21 | H10: 1476.42 | I10: 1489.3 | J10: 1490.78 | K10: 1475.4 | L10: 1528.33 | M10: 1585.13 | N10: 1620.04 | O10: 1686.02 | P10: 1605.45 | Q10: 1715.47 | R10: 1746.09 | S10: 1631.97 | T10: 1505.3 | U10: 1685.25 | V10: 1499.02 | W10: 1499.02 | X10: 1499.02 | Y10: 1499.02 | AA10: 1499.02 | AB10: 1499.02 | AC10: 1499.02 | AD10: 1499.02
A11: EURKRW_end | C11: W/Euro(기말) | E11: 1433.66 | F11: 1433.66 | G11: 1458.68 | H11: 1474.86 | I11: 1469.1 | J11: 1532.14 | K11: 1532.14 | L11: 1594.72 | M11: 1588.22 | N11: 1648.04 | O11: 1696.94 | P11: 1696.94 | Q11: 1753.21 | R11: 1767.09 | S11: 1539.06 | T11: 1499.02 | U11: 1499.02 | V11: 1499.02 | W11: 1499.02 | X11: 1499.02 | Y11: 1499.02 | AA11: 1499.02 | AB11: 1499.02 | AC11: 1499.02 | AD11: 1499.02
A12: CNYKRW_avg | C12: 원/중국원(평균) | E12: 182.86 | F12: 184.52 | G12: 185.04 | H12: 189.35 | I12: 189.24 | J12: 194.24 | K12: 189.49 | L12: 199.63 | M12: 193.41 | N12: 193.79 | O12: 204.38 | P12: 197.8 | Q12: 211.75 | R12: 220.8 | S12: 210.43 | T12: 200.38 | U12: 213.41 | V12: 199.23 | W12: 199.23 | X12: 199.23 | Y12: 199.23 | AA12: 199.23 | AB12: 199.23 | AC12: 199.23 | AD12: 199.23
A13: CNYKRW_end | C13: 원/중국원(기말) | E13: 182.61 | F13: 182.61 | G13: 186.66 | H13: 189.7 | I13: 187.12 | J13: 202.04 | K13: 202.04 | L13: 203.3 | M13: 189.14 | N13: 197.16 | O13: 206.28 | P13: 206.28 | Q13: 220.97 | R13: 228.56 | S13: 202.16 | T13: 199.23 | U13: 199.23 | V13: 199.23 | W13: 199.23 | X13: 199.23 | Y13: 199.23 | AA13: 199.23 | AB13: 199.23 | AC13: 199.23 | AD13: 199.23
B14: 1b. 종가
A15: price_close_end | C15: 종가(기말) | G15: 17890 | H15: 15360 | I15: 11140 | J15: 13430 | L15: 14000 | M15: 18540 | N15: 26550 | O15: 17690 | Q15: 17810 | R15: 12080 | S15: 12890 | T15: 11470
A16: price_high | C16: 종가(최고) | G16: 29200 | H16: 19700 | I16: 16580 | J16: 17770 | L16: 22350 | M16: 22600 | N16: 33450 | O16: 27000 | Q16: 22950 | R16: 21700 | S16: 16730 | T16: 13220
A17: price_low | C17: 종가(최저) | G17: 13890 | H17: 14070 | I17: 10270 | J17: 9580 | L17: 12880 | M17: 12350 | N17: 17730 | O17: 17550 | Q17: 15260 | R17: 11240 | S17: 10380 | T17: 10830
A18: price_avg | C18: 종가(평균) | G18: 17793.7 | H18: 16068 | I18: 13288.4 | J18: 12433.6 | L18: 17395.2 | M18: 17968.2 | N18: 22917.1 | O18: 20329 | Q18: 18322.2 | R18: 16938 | S18: 13352.1 | T18: 12113.6
B20: 2. 추정 드라이버 | C20: 실적 열 = subQ 실현값(수식), 추정 열 = 가정(노란 = 모델값 역산, 연녹 = 3절 스칼라 참조)
A21: drv:매출액 | B21: yoy | C21: 매출액 YoY | J21: =IFERROR(subQ!J5/subQ!E5-1,"") | L21: =IFERROR(subQ!L5/subQ!G5-1,"") | M21: =IFERROR(subQ!M5/subQ!H5-1,"") | N21: =IFERROR(subQ!N5/subQ!I5-1,"") | O21: =IFERROR(subQ!O5/subQ!J5-1,"") | Q21: =IFERROR(subQ!Q5/subQ!L5-1,"") | R21: =IFERROR(subQ!R5/subQ!M5-1,"") | S21: 0.153316 | T21: 0.1465214 | V21: 0.14531611 | W21: 0.12314108 | X21: 0.169915 | Y21: 0.19519218 | AA21: 0.19194854 | AB21: 0.17783161 | AC21: 0.16573707 | AD21: 0.1680457
A22: drv:판관비 | B22: ratio | C22: 판관비율(/매출) | E22: =IFERROR(subQ!E8/subQ!E5,"") | F22: =IFERROR(subQ!F8/subQ!F5,"") | G22: =IFERROR(subQ!G8/subQ!G5,"") | H22: =IFERROR(subQ!H8/subQ!H5,"") | I22: =IFERROR(subQ!I8/subQ!I5,"") | J22: =IFERROR(subQ!J8/subQ!J5,"") | K22: =IFERROR(subQ!K8/subQ!K5,"") | L22: =IFERROR(subQ!L8/subQ!L5,"") | ... R22: =IFERROR(subQ!R8/subQ!R5,"") | S22: =$D$49 | T22: =$D$49 | U22: =IFERROR(subQ!U8/subQ!U5,"") | V22: =$D$49 | W22: =$D$49 | X22: =$D$49 | Y22: =$D$49 | Z22: =IFERROR(subQ!Z8/subQ!Z5,"") | AA22: =$D$49 | AB22: =$D$49 | AC22: =$D$49 | AD22: =$D$49 | AE22: =IFERROR(subQ!AE8/subQ!AE5,"")
A23: drv:영업이익 | B23: ratio | C23: 영업이익률(OPM) | E23: =IFERROR(subQ!E9/subQ!E5,"") | F23: =IFERROR(subQ!F9/subQ!F5,"") | G23: =IFERROR(subQ!G9/subQ!G5,"") | H23: =IFERROR(subQ!H9/subQ!H5,"") | I23: =IFERROR(subQ!I9/subQ!I5,"") | J23: =IFERROR(subQ!J9/subQ!J5,"") | K23: =IFERROR(subQ!K9/subQ!K5,"") | L23: =IFERROR(subQ!L9/subQ!L5,"") | ... R23: =IFERROR(subQ!R9/subQ!R5,"") | S23: 0.11804184 | T23: 0.1180456 | U23: =IFERROR(subQ!U9/subQ!U5,"") | V23: 0.11804214 | W23: 0.11804867 | X23: 0.11804638 | Y23: 0.11804079 | Z23: =IFERROR(subQ!Z9/subQ!Z5,"") | AA23: 0.11804587 | AB23: 0.1180412 | AC23: 0.11804084 | AD23: 0.11804454 | AE23: =IFERROR(subQ!AE9/subQ!AE5,"")
A24: drv:외환손익 | B24: abs | C24: 외환손익 (가정, 억원) | E24: =subQ!E13 | F24: =subQ!F13 | G24: =subQ!G13 | H24: =subQ!H13 | I24: =subQ!I13 | J24: =subQ!J13 | K24: =subQ!K13 | L24: =subQ!L13 | ... R24: =subQ!R13 | S24: 0 | T24: 0 | U24: =subQ!U13 | V24: 0 | W24: 0 | X24: 0 | Y24: 0 | Z24: =subQ!Z13 | AA24: 0 | AB24: 0 | AC24: 0 | AD24: 0 | AE24: =subQ!AE13
A25: drv:기타영업외손익 | B25: abs | C25: 기타영업외손익 (가정, 억원) | E25: =subQ!E14 | F25: =subQ!F14 | G25: =subQ!G14 | H25: =subQ!H14 | I25: =subQ!I14 | J25: =subQ!J14 | K25: =subQ!K14 | L25: =subQ!L14 | ... R25: =subQ!R14 | S25: 0 | T25: 0 | U25: =subQ!U14 | V25: 0 | W25: 0 | X25: 0 | Y25: 0 | Z25: =subQ!Z14 | AA25: 0 | AB25: 0 | AC25: 0 | AD25: 0 | AE25: =subQ!AE14
A26: drv:법인세비용 | B26: tax | C26: 법인세율(/세전) — 법인세 = MAX(세전,0) × 세율 | E26: =IFERROR(subQ!E16/subQ!E15,"") | F26: =IFERROR(subQ!F16/subQ!F15,"") | G26: =IFERROR(subQ!G16/subQ!G15,"") | H26: =IFERROR(subQ!H16/subQ!H15,"") | I26: =IFERROR(subQ!I16/subQ!I15,"") | J26: =IFERROR(subQ!J16/subQ!J15,"") | K26: =IFERROR(subQ!K16/subQ!K15,"") | L26: =IFERROR(subQ!L16/subQ!L15,"") | ... R26: =IFERROR(subQ!R16/subQ!R15,"") | S26: =$D$48 | T26: =$D$48 | U26: =IFERROR(subQ!U16/subQ!U15,"") | V26: =$D$48 | W26: =$D$48 | X26: =$D$48 | Y26: =$D$48 | Z26: =IFERROR(subQ!Z16/subQ!Z15,"") | AA26: =$D$48 | AB26: =$D$48 | AC26: =$D$48 | AD26: =$D$48 | AE26: =IFERROR(subQ!AE16/subQ!AE15,"")
A27: drv:지배주주순이익 | B27: ratio | C27: 지배주주 비중(/당기순이익) | E27: =IFERROR(subQ!E18/subQ!E17,"") | F27: =IFERROR(subQ!F18/subQ!F17,"") | G27: =IFERROR(subQ!G18/subQ!G17,"") | H27: =IFERROR(subQ!H18/subQ!H17,"") | I27: =IFERROR(subQ!I18/subQ!I17,"") | J27: =IFERROR(subQ!J18/subQ!J17,"") | K27: =IFERROR(subQ!K18/subQ!K17,"") | L27: =IFERROR(subQ!L18/subQ!L17,"") | ... R27: =IFERROR(subQ!R18/subQ!R17,"") | S27: =$D$50 | T27: =$D$50 | U27: =IFERROR(subQ!U18/subQ!U17,"") | V27: =$D$50 | W27: =$D$50 | X27: =$D$50 | Y27: =$D$50 | Z27: =IFERROR(subQ!Z18/subQ!Z17,"") | AA27: =$D$50 | AB27: =$D$50 | AC27: =$D$50 | AD27: =$D$50 | AE27: =IFERROR(subQ!AE18/subQ!AE17,"")
A28: drv:부채총계 | B28: qoq | C28: 부채총계 QoQ | G28: =IFERROR(subQ!G20/subQ!E20-1,"") | H28: =IFERROR(subQ!H20/subQ!G20-1,"") | I28: =IFERROR(subQ!I20/subQ!H20-1,"") | J28: =IFERROR(subQ!J20/subQ!I20-1,"") | L28: =IFERROR(subQ!L20/subQ!J20-1,"") | M28: =IFERROR(subQ!M20/subQ!L20-1,"") | N28: =IFERROR(subQ!N20/subQ!M20-1,"") | O28: =IFERROR(subQ!O20/subQ!N20-1,"") | Q28: =IFERROR(subQ!Q20/subQ!O20-1,"") | R28: =IFERROR(subQ!R20/subQ!Q20-1,"") | S28: 4.805e-06 | T28: 0 | V28: 0 | W28: 0 | X28: 0 | Y28: 0 | AA28: 0 | AB28: 0 | AC28: 0 | AD28: 0
A29: drv:자본총계 | B29: roll | C29: 자본총계 기타변동(배당 등, 억원) | G29: =IFERROR(subQ!E21+subQ!G17-subQ!G21,"") | H29: =IFERROR(subQ!G21+subQ!H17-subQ!H21,"") | I29: =IFERROR(subQ!H21+subQ!I17-subQ!I21,"") | J29: =IFERROR(subQ!I21+subQ!J17-subQ!J21,"") | L29: =IFERROR(subQ!J21+subQ!L17-subQ!L21,"") | M29: =IFERROR(subQ!L21+subQ!M17-subQ!M21,"") | N29: =IFERROR(subQ!M21+subQ!N17-subQ!N21,"") | O29: =IFERROR(subQ!N21+subQ!O17-subQ!O21,"") | Q29: =IFERROR(subQ!O21+subQ!Q17-subQ!Q21,"") | R29: =IFERROR(subQ!Q21+subQ!R17-subQ!R21,"") | S29: -0.00361218 | T29: 0.000316228 | V29: -0.000225188 | W29: 46.169328 | X29: -0.003241731 | Y29: -0.002810809 | AA29: -0.002994442 | AB29: 46.158111 | AC29: 0.002297326 | AD29: -0.006767971
A30: drv:지배주주지분 | B30: roll | C30: 지배주주지분 기타변동(배당 등, 억원) | G30: =IFERROR(subQ!E22+subQ!G18-subQ!G22,"") | H30: =IFERROR(subQ!G22+subQ!H18-subQ!H22,"") | I30: =IFERROR(subQ!H22+subQ!I18-subQ!I22,"") | J30: =IFERROR(subQ!I22+subQ!J18-subQ!J22,"") | L30: =IFERROR(subQ!J22+subQ!L18-subQ!L22,"") | M30: =IFERROR(subQ!L22+subQ!M18-subQ!M22,"") | N30: =IFERROR(subQ!M22+subQ!N18-subQ!N22,"") | O30: =IFERROR(subQ!N22+subQ!O18-subQ!O22,"") | Q30: =IFERROR(subQ!O22+subQ!Q18-subQ!Q22,"") | R30: =IFERROR(subQ!Q22+subQ!R18-subQ!R22,"") | S30: -0.00361218 | T30: 0.000316228 | V30: -0.000225188 | W30: 46.169328 | X30: -0.003241731 | Y30: -0.002810809 | AA30: -0.002994442 | AB30: 46.158111 | AC30: 0.002297326 | AD30: -0.006767971
A31: drv:총차입금 | B31: qoq | C31: 총차입금 QoQ | G31: =IFERROR(subQ!G23/subQ!E23-1,"") | H31: =IFERROR(subQ!H23/subQ!G23-1,"") | I31: =IFERROR(subQ!I23/subQ!H23-1,"") | J31: =IFERROR(subQ!J23/subQ!I23-1,"") | L31: =IFERROR(subQ!L23/subQ!J23-1,"") | M31: =IFERROR(subQ!M23/subQ!L23-1,"") | N31: =IFERROR(subQ!N23/subQ!M23-1,"") | O31: =IFERROR(subQ!O23/subQ!N23-1,"") | Q31: =IFERROR(subQ!Q23/subQ!O23-1,"") | R31: =IFERROR(subQ!R23/subQ!Q23-1,"") | S31: -1.3191e-05 | T31: 0 | V31: 0 | W31: 0 | X31: 0 | Y31: 0 | AA31: 0 | AB31: 0 | AC31: 0 | AD31: 0
A32: drv:순차입금 | B32: qoq | C32: 순차입금 QoQ | G32: =IFERROR(subQ!G24/subQ!E24-1,"") | H32: =IFERROR(subQ!H24/subQ!G24-1,"") | I32: =IFERROR(subQ!I24/subQ!H24-1,"") | J32: =IFERROR(subQ!J24/subQ!I24-1,"") | L32: =IFERROR(subQ!L24/subQ!J24-1,"") | M32: =IFERROR(subQ!M24/subQ!L24-1,"") | N32: =IFERROR(subQ!N24/subQ!M24-1,"") | O32: =IFERROR(subQ!O24/subQ!N24-1,"") | Q32: =IFERROR(subQ!Q24/subQ!O24-1,"") | R32: =IFERROR(subQ!R24/subQ!Q24-1,"") | S32: 0.2825025 | T32: 0.24283505 | V32: 0.18927219 | W32: 0.073530721 | X32: 0.16454804 | Y32: 0.15889099 | AA32: 0.13252716 | AB32: 0.065340678 | AC32: 0.11922773 | AD32: 0.11986255
A33: drv:이자발생자산 | B33: qoq | C33: 이자발생자산 QoQ | G33: =IFERROR(subQ!G25/subQ!E25-1,"") | H33: =IFERROR(subQ!H25/subQ!G25-1,"") | I33: =IFERROR(subQ!I25/subQ!H25-1,"") | J33: =IFERROR(subQ!J25/subQ!I25-1,"") | L33: =IFERROR(subQ!L25/subQ!J25-1,"") | M33: =IFERROR(subQ!M25/subQ!L25-1,"") | N33: =IFERROR(subQ!N25/subQ!M25-1,"") | O33: =IFERROR(subQ!O25/subQ!N25-1,"") | Q33: =IFERROR(subQ!Q25/subQ!O25-1,"") | R33: =IFERROR(subQ!R25/subQ!Q25-1,"") | S33: 0.14409266 | T33: 0.13883141 | V33: 0.11809112 | W33: 0.048783371 | X33: 0.11179197 | Y33: 0.1130567 | AA33: 0.098180949 | AB33: 0.049920703 | AC33: 0.092418723 | AD33: 0.095201085
A34: drv:현금및현금성자산 | B34: qoq | C34: 현금및현금성자산 QoQ | G34: =IFERROR(subQ!G26/subQ!E26-1,"") | H34: =IFERROR(subQ!H26/subQ!G26-1,"") | I34: =IFERROR(subQ!I26/subQ!H26-1,"") | J34: =IFERROR(subQ!J26/subQ!I26-1,"") | L34: =IFERROR(subQ!L26/subQ!J26-1,"") | M34: =IFERROR(subQ!M26/subQ!L26-1,"") | N34: =IFERROR(subQ!N26/subQ!M26-1,"") | O34: =IFERROR(subQ!O26/subQ!N26-1,"") | Q34: =IFERROR(subQ!Q26/subQ!O26-1,"") | R34: =IFERROR(subQ!R26/subQ!Q26-1,"")
A35: drv:CAPEX | B35: yoy | C35: CAPEX YoY | J35: =IFERROR(subQ!J27/subQ!E27-1,"") | L35: =IFERROR(subQ!L27/subQ!G27-1,"") | M35: =IFERROR(subQ!M27/subQ!H27-1,"") | N35: =IFERROR(subQ!N27/subQ!I27-1,"") | O35: =IFERROR(subQ!O27/subQ!J27-1,"") | Q35: =IFERROR(subQ!Q27/subQ!L27-1,"") | R35: =IFERROR(subQ!R27/subQ!M27-1,"") | S35: 0.047433027 | T35: 0 | V35: 0 | W35: 0 | X35: 0 | Y35: 0 | AA35: 0 | AB35: 0 | AC35: 0 | AD35: 0
A36: drv:영업활동현금흐름 | B36: yoy | C36: 영업활동현금흐름 YoY | J36: =IFERROR(subQ!J28/subQ!E28-1,"") | L36: =IFERROR(subQ!L28/subQ!G28-1,"") | M36: =IFERROR(subQ!M28/subQ!H28-1,"") | N36: =IFERROR(subQ!N28/subQ!I28-1,"") | O36: =IFERROR(subQ!O28/subQ!J28-1,"") | Q36: =IFERROR(subQ!Q28/subQ!L28-1,"") | R36: =IFERROR(subQ!R28/subQ!M28-1,"")
A37: drv:주식수 | B37: qoq | C37: 주식수 QoQ | G37: =IFERROR(subQ!G29/subQ!E29-1,"") | H37: =IFERROR(subQ!H29/subQ!G29-1,"") | I37: =IFERROR(subQ!I29/subQ!H29-1,"") | J37: =IFERROR(subQ!J29/subQ!I29-1,"") | L37: =IFERROR(subQ!L29/subQ!J29-1,"") | M37: =IFERROR(subQ!M29/subQ!L29-1,"") | N37: =IFERROR(subQ!N29/subQ!M29-1,"") | O37: =IFERROR(subQ!O29/subQ!N29-1,"") | Q37: =IFERROR(subQ!Q29/subQ!O29-1,"") | R37: =IFERROR(subQ!R29/subQ!Q29-1,"") | S37: 0 | T37: 0 | V37: 0 | W37: 0 | X37: 0 | Y37: 0 | AA37: 0 | AB37: 0 | AC37: 0 | AD37: 0
A38: drv:DPS | B38: abs | C38: DPS (가정, 원) | E38: =subQ!E32 | F38: =subQ!F32 | G38: =subQ!G32 | H38: =subQ!H32 | I38: =subQ!I32 | J38: =subQ!J32 | K38: =subQ!K32 | L38: =subQ!L32 | ... R38: =subQ!R32 | T38: 130 | U38: =subQ!U32 | Y38: 130 | Z38: =subQ!Z32 | AD38: 130 | AE38: =subQ!AE32
B40: 3. 밸류에이션·스칼라 | C40: 노란 셀 = 가정. '연결' 표시는 추정 전 분기 수식이 이 셀을 참조한다는 뜻
A41: sc:종가 | C41: 종가 | D41: 11470 | E41: 원 — 네이버 정규장 종가(aik 확정종가 대조 · aik 11,000원)
A42: sc:기준일 | C42: 기준일 | D42: 20261019 | E42: 종가 기준일
...

Sheet BS연결
B1: (백만원) | C1: 이름: BS연결H | E1: 4Q23 | F1: 2023 | G1: 1Q24 | H1: 2Q24 | I1: 3Q24 | J1: 4Q24 | K1: 2024 | L1: 1Q25 | M1: 2Q25 | N1: 3Q25 | O1: 4Q25 | P1: 2025 | Q1: 1Q26 | R1: 2Q26 | S1: 3Q26 | T1: 4Q26 | U1: 2026 | V1: 1Q27 | W1: 2Q27 | X1: 3Q27 | Y1: 4Q27 | Z1: 2027 | AA1: 1Q28 | AB1: 2Q28 | AC1: 3Q28 | AD1: 4Q28 | AE1: 2028
B2: 연결 | D2: fin json(kship_fin.py)
B3: 현대힘스(연) | C3: UPDATE: 26-10-19 | E3: 1 | F3: 2 | G3: 3 | H3: 4 | I3: 5 | J3: 6 | K3: 7 | L3: 8 | M3: 9 | N3: 10 | O3: 11 | P3: 12 | Q3: 13 | R3: 14 | S3: 15 | T3: 16 | U3: 17 | V3: 18 | W3: 19 | X3: 20 | Y3: 21 | Z3: 22 | AA3: 23 | AB3: 24 | AC3: 25 | AD3: 26 | AE3: 27
B4: Account Code | C4: AccountNAME | E4: 2023.12 | F4: 2023.12A | G4: 2024.03 | H4: 2024.06 | I4: 2024.09 | J4: 2024.12 | K4: 2024.12A | L4: 2025.03 | M4: 2025.06 | N4: 2025.09 | O4: 2025.12 | P4: 2025.12A | Q4: 2026.03 | R4: 2026.06 | S4: 2026.09 | T4: 2026.12 | U4: 2026.12A | V4: 2027.03 | W4: 2027.06 | X4: 2027.09 | Y4: 2027.12 | Z4: 2027.12A | AA4: 2028.03 | AB4: 2028.06 | AC4: 2028.09 | AD4: 2028.12 | AE4: 2028.12A
A5: 1 | C5: 유동자산 | E5: 45057.51 | F5: 45057.51 | G5: 84838.45 | H5: 92716.28 | I5: 67685.72 | J5: 72618.6 | K5: 72618.6 | L5: 76856.5 | M5: 78540.06 | N5: 80587.74 | O5: 85865.98 | P5: 85865.98 | Q5: 87014.83 | R5: 91892.31
A6: 1 | C6: 현금및현금성자산 | E6: 6483.61 | F6: 6483.61 | G6: 23353.22 | H6: 40086.39 | I6: 28348.53 | J6: 36765.38 | K6: 36765.38 | L6: 39928.09 | M6: 35142.46 | N6: 32177.49 | O6: 33438.64 | P6: 33438.64 | Q6: 42154.45 | R6: 43421.91
A7: 1 | C7: 단기금융상품 | E7: 500 | F7: 500 | G7: 21948.85 | H7: 18627.12 | I7: 3630.54 | J7: 651.96 | K7: 651.96 | L7: 651.96 | M7: 6675.04 | N7: 10635.59 | O7: 6651.96 | P7: 6651.96 | Q7: 161.66 | R7: 3017.03
A8: 1 | C8: 단기금융자산 | E8: 500 | F8: 500 | G8: 21948.85 | H8: 18627.12 | I8: 3630.54 | J8: 651.96 | K8: 651.96 | L8: 651.96 | M8: 6675.04 | N8: 10635.59 | O8: 6651.96 | P8: 6651.96 | Q8: 161.66 | R8: 3017.03
A9: 1 | C9: 매출채권및기타채권 | E9: 13247.97 | F9: 13247.97 | G9: 16515.07 | H9: 12583.79 | I9: 14893.2 | J9: 13451.5 | K9: 13451.5 | L9: 15612.81 | M9: 15164.72 | N9: 11556.05 | O9: 16456.06 | P9: 16456.06 | Q9: 15908.38 | R9: 16649.14
A10: 1 | C10: 재고자산 | E10: 24644.44 | F10: 24644.44 | G10: 22316.4 | H10: 20787.96 | I10: 20178.03 | J10: 21526.02 | K10: 21526.02 | L10: 19197.14 | M10: 20457.06 | N10: 23367.51 | O10: 22974.81 | P10: 22974.81 | Q10: 23368.1 | R10: 22458.02
A11: 1 | C11: 당기법인세자산(선급법인세) | E11: 2.54 | F11: 2.54 | G11: 3.1 | H11: 3.21 | I11: 4.24 | O11: 13 | P11: 13 | Q11: 13 | R11: 0
A12: 1 | C12: 기타유동자산 | E12: 178.94 | F12: 178.94 | G12: 701.81 | H12: 627.82 | I12: 631.17 | J12: 223.74 | K12: 223.74 | L12: 1466.5 | M12: 1100.79 | N12: 2851.1 | O12: 2476.97 | P12: 2476.97 | Q12: 2914.96 | R12: 3851.92
A13: 1 | C13: 비유동자산 | E13: 205426.24 | F13: 205426.24 | G13: 233040.91 | H13: 230839.69 | I13: 253434.94 | J13: 253913.36 | K13: 253913.36 | L13: 251055.09 | M13: 253269.84 | N13: 252602.14 | O13: 247491.65 | P13: 247491.65 | Q13: 245254.98 | R13: 242377.39
A14: 1 | C14: 장기매출채권및기타채권 | E14: 180.2 | F14: 180.2 | G14: 474.9 | H14: 445.02 | N14: 116.66 | O14: 150.37 | P14: 150.37 | Q14: 444.37 | R14: 454.37
A15: 1 | C15: 장기금융자산 | E15: 26.04 | F15: 26.04 | G15: 27.87 | H15: 29.55 | I15: 31.23 | J15: 29.87 | K15: 29.87 | L15: 31.47 | M15: 33.07 | N15: 31.7 | O15: 25.39 | P15: 25.39 | Q15: 22.86 | R15: 24.08
A16: 1 | C16: 투자자산 | E16: 26.04 | F16: 26.04 | G16: 27.87 | H16: 29.55 | I16: 31.23 | J16: 29.87 | K16: 29.87 | L16: 31.47 | M16: 33.07 | N16: 31.7 | O16: 25.39 | P16: 25.39 | Q16: 22.86 | R16: 24.08
A17: 1 | C17: 투자부동산 | E17: 18892.53 | F17: 18892.53 | G17: 22899.15 | H17: 22795.11 | I17: 40549.25 | J17: 38685.2 | K17: 38685.2 | L17: 19529.67 | M17: 19449.89 | N17: 19370.11 | O17: 19294.19 | P17: 19294.19 | Q17: 19214.38 | R17: 19134.58
A18: 1 | C18: 유형자산 | E18: 180465.83 | F18: 180465.83 | G18: 176317.43 | H18: 176203.2 | I18: 182557.38 | J18: 184483.17 | K18: 184483.17 | L18: 202926.73 | M18: 207063.4 | N18: 208093.28 | O18: 204079.66 | P18: 204079.66 | Q18: 203569.76 | R18: 202408.29
A19: 1 | C19: 무형자산 | E19: 1567.3 | F19: 1567.3 | G19: 1491.48 | H19: 1415.67 | I19: 1356.86 | J19: 1341.06 | K19: 1341.06 | L19: 1258.11 | M19: 2426.18 | N19: 2348.83 | O19: 2263.89 | P19: 2263.89 | Q19: 2179.89
A20: 1 | C20: 사용권자산 | E20: 1731.22 | F20: 1731.22 | G20: 29523.04 | H20: 28011.86 | I20: 26529.69 | J20: 26987.91 | K20: 26987.91 | L20: 25222.55 | M20: 23629.67 | N20: 22124.28 | O20: 20673.7 | P20: 20673.7 | Q20: 19176.7 | R20: 17670.94
A21: 1 | C21: 기타비유동자산 | E21: 2674.01 | F21: 2674.01 | G21: 30329.26 | H21: 28670.03 | I21: 27040.04 | J21: 27203.45 | K21: 27203.45 | L21: 25222.55 | M21: 23812.14 | N21: 22124.28 | O21: 21173.09 | P21: 21173.09 | Q21: 19442.64 | R21: 17670.94
A22: 1 | C22: 이연법인세자산 | E22: 402.61 | F22: 402.61 | G22: 283.08 | H22: 63.4 | I22: 285.32 | J22: 504.64 | K22: 504.64 | L22: 414.06 | M22: 368.5 | N22: 517.28 | O22: 505.06 | P22: 505.06 | Q22: 381.08 | R22: 522.21
A23: 1 | C23: 자산총계 | E23: 250483.75 | F23: 250483.75 | G23: 317879.36 | H23: 323555.98 | I23: 321120.66 | J23: 326531.97 | K23: 326531.97 | L23: 327911.59 | M23: 331809.9 | N23: 333189.88 | O23: 333357.62 | P23: 333357.62 | Q23: 332269.81 | R23: 334269.7
A24: 1 | C24: 유동부채 | E24: 34525.89 | F24: 34525.89 | G24: 37473.28 | H24: 38976.85 | I24: 36097.26 | J24: 40284.86 | K24: 40284.86 | L24: 42321.19 | M24: 41439.01 | N24: 44673.96 | O24: 44663.34 | P24: 44663.34 | Q24: 44601.26 | R24: 40567.4
A25: 1 | C25: 단기차입금 | E25: 2000 | F25: 2000 | G25: 2000 | H25: 2000 | I25: 2000 | J25: 9676.92 | K25: 9676.92 | L25: 9676.92 | M25: 9676.92 | N25: 8498.92 | O25: 5712.92 | P25: 5712.92 | Q25: 5926.92 | R25: 5640.92
A26: 1 | C26: 유동리스부채 | E26: 157.59 | F26: 157.59 | G26: 5549.06 | H26: 5611.73 | I26: 5681.39 | J26: 5758.74 | K26: 5758.74 | L26: 5814.41 | M26: 5801.67 | N26: 5853.8 | O26: 5965.99 | P26: 5965.99 | Q26: 6026.51 | R26: 6078.45
A27: 1 | C27: 리스부채 | E27: 1753.55 | F27: 1753.55 | G27: 29707.5 | H27: 28342.91 | I27: 26995.1 | J27: 27578.71 | K27: 27578.71 | L27: 25914.82 | M27: 24406.44 | N27: 22975.34 | O27: 21586.49 | P27: 21586.49 | Q27: 20125.22 | R27: 18639.76
A28: 1 | C28: 단기금융부채 | E28: 157.59 | F28: 157.59 | G28: 5549.06 | H28: 5611.73 | I28: 5681.39 | J28: 5758.74 | K28: 5758.74 | L28: 5814.41 | M28: 5801.67 | N28: 5853.8 | O28: 5965.99 | P28: 5965.99 | Q28: 6026.51 | R28: 6078.45
A29: 1 | C29: 매입채무및기타채무 | E29: 20301.54 | F29: 20301.54 | G29: 16978.95 | H29: 18812.97 | I29: 17396.99 | J29: 21064.46 | K29: 21064.46 | L29: 22657.02 | M29: 21267.02 | N29: 23204.56 | O29: 24596.55 | P29: 24596.55 | Q29: 25088.04 | R29: 21825.79
A30: 1 | C30: 기타유동부채 | E30: 106.96 | F30: 106.96 | G30: 89.64 | H30: 143.69 | I30: 171.05 | J30: 237.49 | K30: 237.49 | L30: 110.85 | M30: 116.55 | N30: 120.28 | O30: 4142.41 | P30: 4142.41 | Q30: 3385.75 | R30: 2477.15
A31: 1 | C31: 당기법인세부채(미지급법인세) | E31: 728.13 | F31: 728.13 | G31: 1461.76 | H31: 1383.92 | I31: 827.37 | J31: 1439.3 | K31: 1439.3 | L31: 1853.71 | M31: 2390.11 | N31: 2770.18 | O31: 4245.47 | P31: 4245.47 | Q31: 4174.04 | R31: 4545.1
... A35: 1 | C35: 장기금융부채 | E35: 1595.96 | F35: 1595.96 | G35: 24158.44 | H35: 22731.18 | I35: 21313.71 | J35: 21819.97 | K35: 21819.97 | L35: 20100.41 | M35: 18604.77 | N35: 17121.54 | O35: 15620.5 | P35: 15620.5 | Q35: 14098.71 | R35: 12561.31
A36: 1 | C36: 장기매입채무및기타채무 | E36: 95 | F36: 95 | G36: 95 | H36: 75 | O36: 20.67 | P36: 20.67 | Q36: 20.67 | R36: 20.67
A37: 1 | C37: 장기선수금 | E37: 1497.2 | F37: 1497.2 | G37: 1692.97 | H37: 1141.64 | N37: 390.54
A38: 1 | C38: 이연법인세부채 | E38: 426.49 | F38: 426.49 | G38: 424.18 | H38: 420.9 | I38: 418.11 | J38: 415.31 | K38: 415.31 | L38: 412.52 | M38: 409.72 | N38: 406.93 | O38: 404.14 | P38: 404.14 | Q38: 272.83 | R38: 270.17
A39: 1 | C39: 부채총계 | E39: 73648.23 | F39: 73648.23 | G39: 99532.34 | H39: 97114.8 | I39: 90519.57 | J39: 92994.27 | K39: 92994.27 | L39: 92244.89 | M39: 89586.79 | N39: 85801.86 | O39: 80458.59 | P39: 80458.59 | Q39: 77416.75 | R39: 70758.66
A40: 1 | C40: 지배주주지분 | E40: 176835.52 | F40: 176835.52 | G40: 218347.02 | H40: 226441.18 | I40: 230601.09 | J40: 233537.69 | K40: 233537.69 | L40: 235666.7 | M40: 242223.11 | N40: 247388.02 | O40: 252899.03 | P40: 252899.03 | Q40: 254853.07 | R40: 263511.04
A41: 1 | C41: 자본금 | E41: 14800 | F41: 14800 | G41: 17412 | H41: 17636.94 | I41: 17666.94 | J41: 17696.14 | K41: 17696.14 | L41: 17712.64 | M41: 17739.94 | N41: 17749.94 | O41: 17755.34 | P41: 17755.34 | Q41: 17755.34 | R41: 17755.34
A42: 1 | C42: 자본잉여금 | E42: 133200 | F42: 133200 | G42: 167350.53 | H42: 170622.6 | I42: 170925.56 | J42: 171220.05 | K42: 171220.05 | L42: 171427.25 | M42: 171772.09 | N42: 171897.41 | O42: 173107.96 | P42: 173107.96 | Q42: 173107.96 | R42: 173107.96
A43: 1 | C43: 기타자본 | E43: 202.25 | F43: 202.25 | G43: 677.84 | H43: 204.72 | I43: 176.44 | J43: 149.06 | K43: 149.06 | L43: 111.85 | M43: 39.38 | N43: 13.81 | O43: 0 | P43: 0 | Q43: 0 | R43: 0
...

Sheet BS별도
B1: (백만원) | C1: 이름: BS별도H | E1: 4Q23 | F1: 2023 | G1: 1Q24 | H1: 2Q24 | I1: 3Q24 | J1: 4Q24 | K1: 2024 | L1: 1Q25 | M1: 2Q25 | N1: 3Q25 | O1: 4Q25 | P1: 2025 | Q1: 1Q26 | R1: 2Q26 | S1: 3Q26 | T1: 4Q26 | U1: 2026 | V1: 1Q27 | W1: 2Q27 | X1: 3Q27 | Y1: 4Q27 | Z1: 2027 | AA1: 1Q28 | AB1: 2Q28 | AC1: 3Q28 | AD1: 4Q28 | AE1: 2028
B2: 별도 | D2: fin json(kship_fin.py)
B3: 현대힘스(별) | C3: UPDATE: 26-10-19 | E3: 1 | F3: 2 | G3: 3 | H3: 4 | I3: 5 | J3: 6 | K3: 7 | L3: 8 | M3: 9 | N3: 10 | O3: 11 | P3: 12 | Q3: 13 | R3: 14 | S3: 15 | T3: 16 | U3: 17 | V3: 18 | W3: 19 | X3: 20 | Y3: 21 | Z3: 22 | AA3: 23 | AB3: 24 | AC3: 25 | AD3: 26 | AE3: 27
B4: Account Code | C4: AccountNAME | E4: 2023.12 | F4: 2023.12A | G4: 2024.03 | H4: 2024.06 | I4: 2024.09 | J4: 2024.12 | K4: 2024.12A | L4: 2025.03 | M4: 2025.06 | N4: 2025.09 | O4: 2025.12 | P4: 2025.12A | Q4: 2026.03 | R4: 2026.06 | S4: 2026.09 | T4: 2026.12 | U4: 2026.12A | V4: 2027.03 | W4: 2027.06 | X4: 2027.09 | Y4: 2027.12 | Z4: 2027.12A | AA4: 2028.03 | AB4: 2028.06 | AC4: 2028.09 | AD4: 2028.12 | AE4: 2028.12A
A5: 1 | C5: 유동자산 | E5: 37106.17 | F5: 37106.17 | G5: 78148.57 | H5: 86222.45 | I5: 61184.73 | J5: 67385.44 | K5: 67385.44 | L5: 71994.06 | M5: 73918.02 | N5: 76672.11 | O5: 78466.33 | P5: 78466.33 | Q5: 80742.65 | R5: 85867.46
A6: 1 | C6: 현금및현금성자산 | E6: 3958.7 | F6: 3958.7 | G6: 20489.27 | H6: 36038.81 | I6: 23911.47 | J6: 34042.86 | K6: 34042.86 | L6: 36962.21 | M6: 33777.84 | N6: 31181.21 | O6: 32385.17 | P6: 32385.17 | Q6: 40274.82 | R6: 42293.9
A7: 1 | C7: 매출채권및기타채권 | E7: 12542.25 | F7: 12542.25 | G7: 14389.71 | H7: 11266.82 | I7: 14113.63 | J7: 12115.68 | K7: 12115.68 | L7: 14917.28 | M7: 14093.19 | N7: 10747.07 | O7: 15155.37 | P7: 15155.37 | Q7: 15393.31 | R7: 15929.43
A8: 1 | C8: 재고자산 | E8: 20459.14 | F8: 20459.14 | G8: 21154.83 | H8: 19740.58 | I8: 18941.87 | J8: 20379.31 | K8: 20379.31 | L8: 18056.83 | M8: 18643.66 | N8: 21658.51 | O8: 22177.17 | P8: 22177.17 | Q8: 22342.94 | R8: 20881.49
A9: 1 | C9: 기타유동자산 | E9: 146.07 | F9: 146.07 | G9: 665.91 | H9: 549.13 | I9: 587.22 | J9: 195.62 | K9: 195.62 | L9: 1405.78 | M9: 728.29 | N9: 2449.73 | O9: 2096.66 | P9: 2096.66 | Q9: 2569.92 | R9: 3745.61
A10: 1 | C10: 비유동자산 | E10: 204913.1 | F10: 204913.1 | G10: 232401.29 | H10: 229701.6 | I10: 252295.78 | J10: 252697.71 | K10: 252697.71 | L10: 249379.44 | M10: 249215.17 | N10: 247153.11 | O10: 245842.44 | P10: 245842.44 | Q10: 243171.16 | R10: 240355.36
A11: 1 | C11: 종속기업및관계기업투자 | E11: 8297.13 | F11: 8297.13 | G11: 8297.13 | H11: 8297.13 | I11: 8297.13 | J11: 8297.13 | K11: 8297.13 | L11: 8297.13 | M11: 8297.13 | N11: 8297.13 | O11: 8297.13 | P11: 8297.13 | Q11: 8297.13
A12: 1 | C12: 투자자산 | E12: 8297.13 | F12: 8297.13 | G12: 8297.13 | H12: 8297.13 | I12: 8297.13 | J12: 8297.13 | K12: 8297.13 | L12: 8297.13 | M12: 8297.13 | N12: 8297.13 | O12: 8297.13 | P12: 8297.13 | Q12: 8297.13
A13: 1 | C13: 장기매출채권및기타채권 | E13: 165.11 | F13: 165.11 | G13: 465.11 | H13: 435.11 | N13: 105 | O13: 139.37 | P13: 139.37 | Q13: 434.37 | R13: 434.37
A14: 1 | C14: 투자부동산 | E14: 16327.01 | F14: 16327.01 | G14: 20338.06 | H14: 20259.23 | I14: 40549.25 | J14: 38685.2 | K14: 38685.2 | L14: 19529.67 | M14: 19449.89 | N14: 19370.11 | O14: 19294.19 | P14: 19294.19 | Q14: 19214.38 | R14: 19134.58
A15: 1 | C15: 유형자산 | E15: 175764.69 | F15: 175764.69 | G15: 171452.91 | H15: 170808.6 | I15: 174615.65 | J15: 176514.17 | K15: 176514.17 | L15: 194484.09 | M15: 196227.92 | N15: 195833.7 | O15: 195614.52 | P15: 195614.52 | Q15: 194641.66 | R15: 193545.23
A16: 1 | C16: 무형자산 | E16: 1335.98 | F16: 1335.98 | G16: 1273.24 | H16: 1210.51 | I16: 1164.78 | J16: 1119.09 | K16: 1119.09 | L16: 1052.9 | M16: 1020 | N16: 959.42 | O16: 891.24 | P16: 891.24 | Q16: 824.01 | R16: 819.95
A17: 1 | C17: 사용권자산 | E17: 1730.17 | F17: 1730.17 | G17: 29513.92 | H17: 28005.78 | I17: 26526.65 | J17: 26987.91 | K17: 26987.91 | L17: 25222.55 | M17: 23629.67 | N17: 22124.28 | O17: 20673.7 | P17: 20673.7 | Q17: 19176.7 | R17: 17670.94
A18: 1 | C18: 기타비유동자산 | E18: 2672.96 | F18: 2672.96 | G18: 30320.14 | H18: 28663.95 | I18: 27037 | J18: 27203.45 | K18: 27203.45 | L18: 25222.55 | M18: 23812.14 | N18: 22124.28 | O18: 21173.09 | P18: 21173.09 | Q18: 19442.64 | R18: 17670.94
A19: 1 | C19: 이연법인세자산 | E19: 350.23 | F19: 350.23 | G19: 254.7 | H19: 27.08 | I19: 244.87 | J19: 430.56 | K19: 430.56 | L19: 339.99 | M19: 303.09 | N19: 463.46 | O19: 432.9 | P19: 432.9 | Q19: 316.98 | R19: 449.3
A20: 1 | C20: 자산총계 | E20: 242019.27 | F20: 242019.27 | G20: 310549.86 | H20: 315924.06 | I20: 313480.51 | J20: 320083.16 | K20: 320083.16 | L20: 321373.5 | M20: 323133.2 | N20: 323825.21 | O20: 324308.78 | P20: 324308.78 | Q20: 323913.81 | R20: 326222.82
A21: 1 | C21: 유동부채 | E21: 28760.81 | F21: 28760.81 | G21: 33982.71 | H21: 35461.06 | I21: 32782.06 | J21: 36125.24 | K21: 36125.24 | L21: 39011.11 | M21: 37797.42 | N21: 40579.43 | O21: 40811.8 | P21: 40811.8 | Q21: 41193.1 | R21: 37567.79
A22: 1 | C22: 단기차입금 | E22: 7033.33 | F22: 7033.33 | G22: 8558.33 | H22: 8516.67 | I22: 7676.92 | J22: 7676.92 | K22: 7676.92 | L22: 7676.92 | M22: 7676.92 | N22: 6498.92 | O22: 3712.92 | P22: 3712.92 | Q22: 3926.92 | R22: 4140.92
A23: 1 | C23: 단기금융부채(face) | E23: 7033.33 | F23: 7033.33 | G23: 8558.33 | H23: 8516.67 | I23: 7676.92 | J23: 7676.92 | K23: 7676.92 | L23: 7676.92 | M23: 7676.92 | N23: 6498.92 | O23: 3712.92 | P23: 3712.92 | Q23: 3926.92 | R23: 4140.92
A24: 1 | C24: 유동리스부채 | E24: 156.56 | F24: 156.56 | G24: 5540.23 | H24: 5605.81 | I24: 5678.41 | J24: 5758.74 | K24: 5758.74 | L24: 5814.41 | M24: 5801.67 | N24: 5853.8 | O24: 5965.99 | P24: 5965.99 | Q24: 6026.51 | R24: 6078.45
A25: 1 | C25: 리스부채 | E25: 1752.52 | F25: 1752.52 | G25: 29698.67 | H25: 28336.99 | I25: 26992.12 | J25: 27578.71 | K25: 27578.71 | L25: 25914.82 | M25: 24406.44 | N25: 22975.34 | O25: 21586.49 | P25: 21586.49 | Q25: 20125.22 | R25: 18639.76
... A33: 1 | C33: 장기금융부채 | E33: 1595.96 | F33: 1595.96 | G33: 24158.44 | H33: 22731.18 | I33: 21313.71 | J33: 21819.97 | K33: 21819.97 | L33: 20100.41 | M33: 18604.77 | N33: 17121.54 | O33: 15620.5 | P33: 15620.5 | Q33: 14098.71 | R33: 12561.31
A34: 1 | C34: 장기선수금 | E34: 1497.2 | F34: 1497.2 | G34: 1692.97 | H34: 1141.64 | N34: 390.54
A35: 1 | C35: 부채총계 | E35: 67361.66 | F35: 67361.66 | G35: 95522.59 | H35: 93103.11 | I35: 86786.27 | J35: 88419.34 | K35: 88419.34 | L35: 87683.29 | M35: 82935.97 | N35: 78557.9 | O35: 73460.42 | P35: 73460.42 | Q35: 71235.76 | R35: 64988.88
A36: 1 | C36: 자본금 | E36: 14800 | F36: 14800 | G36: 17412 | H36: 17636.94 | I36: 17666.94 | J36: 17696.14 | K36: 17696.14 | L36: 17712.64 | M36: 17739.94 | N36: 17749.94 | O36: 17755.34 | P36: 17755.34 | Q36: 17755.34 | R36: 17755.34
A37: 1 | C37: 자본잉여금 | E37: 133200 | F37: 133200 | G37: 167350.53 | H37: 170622.6 | I37: 170925.56 | J37: 171220.05 | K37: 171220.05 | L37: 171427.25 | M37: 171772.09 | N37: 171897.41 | O37: 173107.96 | P37: 173107.96 | Q37: 173107.96 | R37: 173107.96
A38: 1 | C38: 기타자본 | E38: 202.25 | F38: 202.25 | G38: 677.84 | H38: 204.72 | I38: 176.44 | J38: 149.06 | K38: 149.06 | L38: 111.85 | M38: 39.38 | N38: 13.81 | O38: 0 | P38: 0 | Q38: 0 | R38: 0
A39: 1 | C39: 이익잉여금 | E39: 26455.36 | F39: 26455.36 | G39: 29586.9 | H39: 34356.69 | I39: 37925.3 | J39: 42598.56 | K39: 42598.56 | L39: 44438.48 | M39: 50645.81 | N39: 55606.15 | O39: 59985.07 | P39: 59985.07 | Q39: 61814.76 | R39: 70370.65
A40: 1 | C40: 자본총계 | E40: 174657.62 | F40: 174657.62 | G40: 215027.27 | H40: 222820.95 | I40: 226694.24 | J40: 231663.82 | K40: 231663.82 | L40: 233690.21 | M40: 240197.22 | N40: 245267.31 | O40: 250848.36 | P40: 250848.36 | Q40: 252678.05 | R40: 261233.94
A41: 1 | C41: 부채와자본총계 | E41: 242019.27 | F41: 242019.27 | G41: 310549.86 | H41: 315924.06 | I41: 313480.51 | J41: 320083.16 | K41: 320083.16 | L41: 321373.5 | M41: 323133.2 | N41: 323825.21 | O41: 324308.78 | P41: 324308.78 | Q41: 323913.81 | R41: 326222.82
A42: 1 | C42: 지배주주지분 | E42: 174657.62 | F42: 174657.62 | G42: 215027.27 | H42: 222820.95 | I42: 226694.24 | J42: 231663.82 | K42: 231663.82 | L42: 233690.21 | M42: 240197.22 | N42: 245267.31 | O42: 250848.36 | P42: 250848.36 | Q42: 252678.05 | R42: 261233.94
A43: 1 | C43: 총차입금 | E43: 42541.02 | F43: 42541.02 | G43: 44246.79 | H43: 42285.9 | I43: 39526.92 | J43: 37607.69 | K43: 37607.69 | L43: 35688.46 | M43: 33769.23 | N43: 26950 | O43: 20380.77 | P43: 20380.77 | Q43: 19561.54 | R43: 18742.3
A44: 1 | C44: 순차입금 | E44: 38582.32 | F44: 38582.32 | G44: 2308.67 | H44: -12380.03 | I44: 11984.91 | J44: 2912.87 | K44: 2912.87 | L44: -1925.71 | M44: -6683.65 | N44: -14866.8 | O44: -18656.36 | P44: -18656.36 | Q44: -20874.94 | R44: -26568.63
A45: 1 | C45: 이자발생자산 | E45: 3958.7 | F45: 3958.7 | G45: 41938.12 | H45: 54665.93 | I45: 27542.01 | J45: 34694.82 | K45: 34694.82 | L45: 37614.17 | M45: 40452.88 | N45: 41816.8 | O45: 39037.13 | P45: 39037.13 | Q45: 40436.48 | R45: 45310.93
A46: 1 | C46: 단기금융상품 | G46: 21448.85 | H46: 18627.12 | I46: 3630.54 | J46: 651.96 | K46: 651.96 | L46: 651.96 | M46: 6675.04 | N46: 10635.59 | O46: 6651.96 | P46: 6651.96 | Q46: 161.66 | R46: 3017.03
A47: 1 | C47: 단기금융자산 | G47: 21448.85 | H47: 18627.12 | I47: 3630.54 | J47: 651.96 | K47: 651.96 | L47: 651.96 | M47: 6675.04 | N47: 10635.59 | O47: 6651.96 | P47: 6651.96 | Q47: 161.66 | R47: 3017.03
...

Sheet subQ
A1: YQ | C1: subQ 분기 서브모델(억원, U=100) | E1: 4Q23 | F1: 2023 | G1: 1Q24 | H1: 2Q24 | I1: 3Q24 | J1: 4Q24 | K1: 2024 | L1: 1Q25 | M1: 2Q25 | N1: 3Q25 | O1: 4Q25 | P1: 2025 | Q1: 1Q26 | R1: 2Q26 | S1: 3Q26 | T1: 4Q26 | U1: 2026 | V1: 1Q27 | W1: 2Q27 | X1: 3Q27 | Y1: 4Q27 | Z1: 2027 | AA1: 1Q28 | AB1: 2Q28 | AC1: 3Q28 | AD1: 4Q28 | AE1: 2028
A2: A=이름(key) B=그룹 C=단위 D=FnGuide 계정명(VLOOKUP 키). 확정=VLOOKUP(BS), 추정=변수 가정 참조
E3: 1 | F3: 2 | G3: 3 | H3: 4 | I3: 5 | J3: 6 | K3: 7 | L3: 8 | M3: 9 | N3: 10 | O3: 11 | P3: 12 | Q3: 13 | R3: 14 | S3: 15 | T3: 16 | U3: 17 | V3: 18 | W3: 19 | X3: 20 | Y3: 21 | Z3: 22 | AA3: 23 | AB3: 24 | AC3: 25 | AD3: 26 | AE3: 27
E4: 2023.12 | F4: 2023.12A | G4: 2024.03 | H4: 2024.06 | I4: 2024.09 | J4: 2024.12 | K4: 2024.12A | L4: 2025.03 | M4: 2025.06 | N4: 2025.09 | O4: 2025.12 | P4: 2025.12A | Q4: 2026.03 | R4: 2026.06 | S4: 2026.09 | T4: 2026.12 | U4: 2026.12A | V4: 2027.03 | W4: 2027.06 | X4: 2027.09 | Y4: 2027.12 | Z4: 2027.12A | AA4: 2028.03 | AB4: 2028.06 | AC4: 2028.09 | AD4: 2028.12 | AE4: 2028.12A
A5: 매출액 | B5: 손익 | C5: 억원 | D5: 매출액(수익) | E5: =IFERROR(VLOOKUP($D5,BS연결,MATCH(E$1,BS연결H,0),0)/100,"") | G5: =IFERROR(VLOOKUP($D5,BS연결,MATCH(G$1,BS연결H,0),0)/100,"") | H5: =IFERROR(VLOOKUP($D5,BS연결,MATCH(H$1,BS연결H,0),0)/100,"") | I5: =IFERROR(VLOOKUP($D5,BS연결,MATCH(I$1,BS연결H,0),0)/100,"") | J5: =IFERROR(VLOOKUP($D5,BS연결,MATCH(J$1,BS연결H,0),0)/100,"") | K5: =IFERROR(VLOOKUP($D5,BS연결,MATCH(K$1,BS연결H,0),0)/100,"") | L5: =IFERROR(VLOOKUP($D5,BS연결,MATCH(L$1,BS연결H,0),0)/100,"") | M5: =IFERROR(VLOOKUP($D5,BS연결,MATCH(M$1,BS연결H,0),0)/100,"") | N5: =IFERROR(VLOOKUP($D5,BS연결,MATCH(N$1,BS연결H,0),0)/100,"") | ... R5: =IFERROR(VLOOKUP($D5,BS연결,MATCH(R$1,BS연결H,0),0)/100,"") | S5: =IFERROR(N5*(1+변수!S21),"") | T5: =IFERROR(O5*(1+변수!T21),"") | U5: =SUM(Q5:T5) | V5: =IFERROR(Q5*(1+변수!V21),"") | W5: =IFERROR(R5*(1+변수!W21),"") | X5: =IFERROR(S5*(1+변수!X21),"") | Y5: =IFERROR(T5*(1+변수!Y21),"") | Z5: =SUM(V5:Y5) | AA5: =IFERROR(V5*(1+변수!AA21),"") | AB5: =IFERROR(W5*(1+변수!AB21),"") | AC5: =IFERROR(X5*(1+변수!AC21),"") | AD5: =IFERROR(Y5*(1+변수!AD21),"") | AE5: =SUM(AA5:AD5)
A6: 매출원가 | B6: 손익 | C6: 억원 | D6: 매출원가 | E6: =IFERROR(VLOOKUP($D6,BS연결,MATCH(E$1,BS연결H,0),0)/100,"") | G6: =IFERROR(VLOOKUP($D6,BS연결,MATCH(G$1,BS연결H,0),0)/100,"") | H6: =IFERROR(VLOOKUP($D6,BS연결,MATCH(H$1,BS연결H,0),0)/100,"") | I6: =IFERROR(VLOOKUP($D6,BS연결,MATCH(I$1,BS연결H,0),0)/100,"") | J6: =IFERROR(VLOOKUP($D6,BS연결,MATCH(J$1,BS연결H,0),0)/100,"") | K6: =IFERROR(VLOOKUP($D6,BS연결,MATCH(K$1,BS연결H,0),0)/100,"") | L6: =IFERROR(VLOOKUP($D6,BS연결,MATCH(L$1,BS연결H,0),0)/100,"") | M6: =IFERROR(VLOOKUP($D6,BS연결,MATCH(M$1,BS연결H,0),0)/100,"") | N6: =IFERROR(VLOOKUP($D6,BS연결,MATCH(N$1,BS연결H,0),0)/100,"") | ... R6: =IFERROR(VLOOKUP($D6,BS연결,MATCH(R$1,BS연결H,0),0)/100,"") | S6: =IFERROR(S5-S7,"") | T6: =IFERROR(T5-T7,"") | U6: =SUM(Q6:T6) | V6: =IFERROR(V5-V7,"") | W6: =IFERROR(W5-W7,"") | X6: =IFERROR(X5-X7,"") | Y6: =IFERROR(Y5-Y7,"") | Z6: =SUM(V6:Y6) | AA6: =IFERROR(AA5-AA7,"") | AB6: =IFERROR(AB5-AB7,"") | AC6: =IFERROR(AC5-AC7,"") | AD6: =IFERROR(AD5-AD7,"") | AE6: =SUM(AA6:AD6)
A7: 매출총이익 | B7: 손익 | C7: 억원 | D7: 매출총이익 | E7: =IFERROR(VLOOKUP($D7,BS연결,MATCH(E$1,BS연결H,0),0)/100,"") | G7: =IFERROR(VLOOKUP($D7,BS연결,MATCH(G$1,BS연결H,0),0)/100,"") | H7: =IFERROR(VLOOKUP($D7,BS연결,MATCH(H$1,BS연결H,0),0)/100,"") | I7: =IFERROR(VLOOKUP($D7,BS연결,MATCH(I$1,BS연결H,0),0)/100,"") | J7: =IFERROR(VLOOKUP($D7,BS연결,MATCH(J$1,BS연결H,0),0)/100,"") | K7: =IFERROR(VLOOKUP($D7,BS연결,MATCH(K$1,BS연결H,0),0)/100,"") | L7: =IFERROR(VLOOKUP($D7,BS연결,MATCH(L$1,BS연결H,0),0)/100,"") | M7: =IFERROR(VLOOKUP($D7,BS연결,MATCH(M$1,BS연결H,0),0)/100,"") | N7: =IFERROR(VLOOKUP($D7,BS연결,MATCH(N$1,BS연결H,0),0)/100,"") | ... R7: =IFERROR(VLOOKUP($D7,BS연결,MATCH(R$1,BS연결H,0),0)/100,"") | S7: =IFERROR(S9+S8,"") | T7: =IFERROR(T9+T8,"") | U7: =SUM(Q7:T7) | V7: =IFERROR(V9+V8,"") | W7: =IFERROR(W9+W8,"") | X7: =IFERROR(X9+X8,"") | Y7: =IFERROR(Y9+Y8,"") | Z7: =SUM(V7:Y7) | AA7: =IFERROR(AA9+AA8,"") | AB7: =IFERROR(AB9+AB8,"") | AC7: =IFERROR(AC9+AC8,"") | AD7: =IFERROR(AD9+AD8,"") | AE7: =SUM(AA7:AD7)
A8: 판관비 | B8: 손익 | C8: 억원 | D8: 판관비 | E8: =IFERROR(VLOOKUP($D8,BS연결,MATCH(E$1,BS연결H,0),0)/100,"") | G8: =IFERROR(VLOOKUP($D8,BS연결,MATCH(G$1,BS연결H,0),0)/100,"") | H8: =IFERROR(VLOOKUP($D8,BS연결,MATCH(H$1,BS연결H,0),0)/100,"") | I8: =IFERROR(VLOOKUP($D8,BS연결,MATCH(I$1,BS연결H,0),0)/100,"") | J8: =IFERROR(VLOOKUP($D8,BS연결,MATCH(J$1,BS연결H,0),0)/100,"") | K8: =IFERROR(VLOOKUP($D8,BS연결,MATCH(K$1,BS연결H,0),0)/100,"") | L8: =IFERROR(VLOOKUP($D8,BS연결,MATCH(L$1,BS연결H,0),0)/100,"") | M8: =IFERROR(VLOOKUP($D8,BS연결,MATCH(M$1,BS연결H,0),0)/100,"") | N8: =IFERROR(VLOOKUP($D8,BS연결,MATCH(N$1,BS연결H,0),0)/100,"") | ... R8: =IFERROR(VLOOKUP($D8,BS연결,MATCH(R$1,BS연결H,0),0)/100,"") | S8: =IFERROR(S5*변수!S22,"") | T8: =IFERROR(T5*변수!T22,"") | U8: =SUM(Q8:T8) | V8: =IFERROR(V5*변수!V22,"") | W8: =IFERROR(W5*변수!W22,"") | X8: =IFERROR(X5*변수!X22,"") | Y8: =IFERROR(Y5*변수!Y22,"") | Z8: =SUM(V8:Y8) | AA8: =IFERROR(AA5*변수!AA22,"") | AB8: =IFERROR(AB5*변수!AB22,"") | AC8: =IFERROR(AC5*변수!AC22,"") | AD8: =IFERROR(AD5*변수!AD22,"") | AE8: =SUM(AA8:AD8)
A9: 영업이익 | B9: 손익 | C9: 억원 | D9: 영업이익 | E9: =IFERROR(VLOOKUP($D9,BS연결,MATCH(E$1,BS연결H,0),0)/100,"") | G9: =IFERROR(VLOOKUP($D9,BS연결,MATCH(G$1,BS연결H,0),0)/100,"") | H9: =IFERROR(VLOOKUP($D9,BS연결,MATCH(H$1,BS연결H,0),0)/100,"") | I9: =IFERROR(VLOOKUP($D9,BS연결,MATCH(I$1,BS연결H,0),0)/100,"") | J9: =IFERROR(VLOOKUP($D9,BS연결,MATCH(J$1,BS연결H,0),0)/100,"") | K9: =IFERROR(VLOOKUP($D9,BS연결,MATCH(K$1,BS연결H,0),0)/100,"") | L9: =IFERROR(VLOOKUP($D9,BS연결,MATCH(L$1,BS연결H,0),0)/100,"") | M9: =IFERROR(VLOOKUP($D9,BS연결,MATCH(M$1,BS연결H,0),0)/100,"") | N9: =IFERROR(VLOOKUP($D9,BS연결,MATCH(N$1,BS연결H,0),0)/100,"") | ... R9: =IFERROR(VLOOKUP($D9,BS연결,MATCH(R$1,BS연결H,0),0)/100,"") | S9: =IFERROR(S5*변수!S23,"") | T9: =IFERROR(T5*변수!T23,"") | U9: =SUM(Q9:T9) | V9: =IFERROR(V5*변수!V23,"") | W9: =IFERROR(W5*변수!W23,"") | X9: =IFERROR(X5*변수!X23,"") | Y9: =IFERROR(Y5*변수!Y23,"") | Z9: =SUM(V9:Y9) | AA9: =IFERROR(AA5*변수!AA23,"") | AB9: =IFERROR(AB5*변수!AB23,"") | AC9: =IFERROR(AC5*변수!AC23,"") | AD9: =IFERROR(AD5*변수!AD23,"") | AE9: =SUM(AA9:AD9)
A10: OPM | B10: 손익 | C10: % | D10: 영업이익률 | E10: =IFERROR(E9/E5,"") | G10: =IFERROR(G9/G5,"") | H10: =IFERROR(H9/H5,"") | I10: =IFERROR(I9/I5,"") | J10: =IFERROR(J9/J5,"") | K10: =IFERROR(K9/K5,"") | L10: =IFERROR(L9/L5,"") | M10: =IFERROR(M9/M5,"") | N10: =IFERROR(N9/N5,"") | ... AE10: =IFERROR(AE9/AE5,"")
A11: 금융손익 | B11: 손익 | C11: 억원 | D11: 금융손익 | E11: =IFERROR(VLOOKUP($D11,BS연결,MATCH(E$1,BS연결H,0),0)/100,"") | G11: =IFERROR(VLOOKUP($D11,BS연결,MATCH(G$1,BS연결H,0),0)/100,"") | H11: =IFERROR(VLOOKUP($D11,BS연결,MATCH(H$1,BS연결H,0),0)/100,"") | I11: =IFERROR(VLOOKUP($D11,BS연결,MATCH(I$1,BS연결H,0),0)/100,"") | J11: =IFERROR(VLOOKUP($D11,BS연결,MATCH(J$1,BS연결H,0),0)/100,"") | K11: =IFERROR(VLOOKUP($D11,BS연결,MATCH(K$1,BS연결H,0),0)/100,"") | L11: =IFERROR(VLOOKUP($D11,BS연결,MATCH(L$1,BS연결H,0),0)/100,"") | M11: =IFERROR(VLOOKUP($D11,BS연결,MATCH(M$1,BS연결H,0),0)/100,"") | N11: =IFERROR(VLOOKUP($D11,BS연결,MATCH(N$1,BS연결H,0),0)/100,"") | ... R11: =IFERROR(VLOOKUP($D11,BS연결,MATCH(R$1,BS연결H,0),0)/100,"") | S11: =IFERROR(S12+S13,"") | T11: =IFERROR(T12+T13,"") | U11: =SUM(Q11:T11) | V11: =IFERROR(V12+V13,"") | W11: =IFERROR(W12+W13,"") | X11: =IFERROR(X12+X13,"") | Y11: =IFERROR(Y12+Y13,"") | Z11: =SUM(V11:Y11) | AA11: =IFERROR(AA12+AA13,"") | AB11: =IFERROR(AB12+AB13,"") | AC11: =IFERROR(AC12+AC13,"") | AD11: =IFERROR(AD12+AD13,"") | AE11: =SUM(AA11:AD11)
A12: 이자손익 | B12: 손익 | C12: 억원 | D12: 이자손익 | E12: =IFERROR(VLOOKUP($D12,BS연결,MATCH(E$1,BS연결H,0),0)/100,"") | G12: =IFERROR(VLOOKUP($D12,BS연결,MATCH(G$1,BS연결H,0),0)/100,"") | H12: =IFERROR(VLOOKUP($D12,BS연결,MATCH(H$1,BS연결H,0),0)/100,"") | I12: =IFERROR(VLOOKUP($D12,BS연결,MATCH(I$1,BS연결H,0),0)/100,"") | J12: =IFERROR(VLOOKUP($D12,BS연결,MATCH(J$1,BS연결H,0),0)/100,"") | K12: =IFERROR(VLOOKUP($D12,BS연결,MATCH(K$1,BS연결H,0),0)/100,"") | L12: =IFERROR(VLOOKUP($D12,BS연결,MATCH(L$1,BS연결H,0),0)/100,"") | M12: =IFERROR(VLOOKUP($D12,BS연결,MATCH(M$1,BS연결H,0),0)/100,"") | N12: =IFERROR(VLOOKUP($D12,BS연결,MATCH(N$1,BS연결H,0),0)/100,"") | ... P12: =IFERROR(VLOOKUP($D12,BS연결,MATCH(P$1,BS연결H,0),0)/100,"") | R12: =IFERROR(VLOOKUP($D12,BS연결,MATCH(R$1,BS연결H,0),0)/100,"") | S12: =IFERROR((R25*변수!$D$51-R23*변수!$D$52)/4,"") | T12: =IFERROR((S25*변수!$D$51-S23*변수!$D$52)/4,"") | U12: =SUM(Q12:T12) | V12: =IFERROR((T25*변수!$D$51-T23*변수!$D$52)/4,"") | W12: =IFERROR((V25*변수!$D$51-V23*변수!$D$52)/4,"") | X12: =IFERROR((W25*변수!$D$51-W23*변수!$D$52)/4,"") | Y12: =IFERROR((X25*변수!$D$51-X23*변수!$D$52)/4,"") | Z12: =SUM(V12:Y12) | AA12: =IFERROR((Y25*변수!$D$51-Y23*변수!$D$52)/4,"") | AB12: =IFERROR((AA25*변수!$D$51-AA23*변수!$D$52)/4,"") | AC12: =IFERROR((AB25*변수!$D$51-AB23*변수!$D$52)/4,"") | AD12: =IFERROR((AC25*변수!$D$51-AC23*변수!$D$52)/4,"") | AE12: =SUM(AA12:AD12)
A13: 외환손익 | B13: 손익 | C13: 억원 | D13: 외환손익(실적만; 추정 환효과는 환관련손익) | E13: =IFERROR((VLOOKUP("외환차익",BS연결,MATCH(E$1,BS연결H,0),0)-VLOOKUP("외환차손",BS연결,MATCH(E$1,BS연결H,0),0)+VLOOKUP("외화환산이익",BS연결,MATCH(E$1,BS연결H,0),0)-VLOOKUP("외화환산손실",BS연결,MATCH(E$1,BS연결H,0),0))/100,"") | G13: =IFERROR((VLOOKUP("외환차익",BS연결,MATCH(G$1,BS연결H,0),0)-VLOOKUP("외환차손",BS연결,MATCH(G$1,BS연결H,0),0)+VLOOKUP("외화환산이익",BS연결,MATCH(G$1,BS연결H,0),0)-VLOOKUP("외화환산손실",BS연결,MATCH(G$1,BS연결H,0),0))/100,"") | H13: =IFERROR((VLOOKUP("외환차익",BS연결,MATCH(H$1,BS연결H,0),0)-VLOOKUP("외환차손",BS연결,MATCH(H$1,BS연결H,0),0)+VLOOKUP("외화환산이익",BS연결,MATCH(H$1,BS연결H,0),0)-VLOOKUP("외화환산손실",BS연결,MATCH(H$1,BS연결H,0),0))/100,"") | I13: =IFERROR((VLOOKUP("외환차익",BS연결,MATCH(I$1,BS연결H,0),0)-VLOOKUP("외환차손",BS연결,MATCH(I$1,BS연결H,0),0)+VLOOKUP("외화환산이익",BS연결,MATCH(I$1,BS연결H,0),0)-VLOOKUP("외화환산손실",BS연결,MATCH(I$1,BS연결H,0),0))/100,"") | J13: =IFERROR((VLOOKUP("외환차익",BS연결,MATCH(J$1,BS연결H,0),0)-VLOOKUP("외환차손",BS연결,MATCH(J$1,BS연결H,0),0)+VLOOKUP("외화환산이익",BS연결,MATCH(J$1,BS연결H,0),0)-VLOOKUP("외화환산손실",BS연결,MATCH(J$1,BS연결H,0),0))/100,"") | K13: =SUM(G13:J13) | M13: =IFERROR((VLOOKUP("외환차익",BS연결,MATCH(M$1,BS연결H,0),0)-VLOOKUP("외환차손",BS연결,MATCH(M$1,BS연결H,0),0)+VLOOKUP("외화환산이익",BS연결,MATCH(M$1,BS연결H,0),0)-VLOOKUP("외화환산손실",BS연결,MATCH(M$1,BS연결H,0),0))/100,"") | N13: =IFERROR((VLOOKUP("외환차익",BS연결,MATCH(N$1,BS연결H,0),0)-VLOOKUP("외환차손",BS연결,MATCH(N$1,BS연결H,0),0)+VLOOKUP("외화환산이익",BS연결,MATCH(N$1,BS연결H,0),0)-VLOOKUP("외화환산손실",BS연결,MATCH(N$1,BS연결H,0),0))/100,"") | O13: =IFERROR((VLOOKUP("외환차익",BS연결,MATCH(O$1,BS연결H,0),0)-VLOOKUP("외환차손",BS연결,MATCH(O$1,BS연결H,0),0)+VLOOKUP("외화환산이익",BS연결,MATCH(O$1,BS연결H,0),0)-VLOOKUP("외화환산손실",BS연결,MATCH(O$1,BS연결H,0),0))/100,"") | P13: =SUM(L13:O13) | R13: =IFERROR((VLOOKUP("외환차익",BS연결,MATCH(R$1,BS연결H,0),0)-VLOOKUP("외환차손",BS연결,MATCH(R$1,BS연결H,0),0)+VLOOKUP("외화환산이익",BS연결,MATCH(R$1,BS연결H,0),0)-VLOOKUP("외화환산손실",BS연결,MATCH(R$1,BS연결H,0),0))/100,"") | S13: =변수!S24 | T13: =변수!T24 | U13: =SUM(Q13:T13) | V13: =변수!V24 | W13: =변수!W24 | X13: =변수!X24 | Y13: =변수!Y24 | Z13: =SUM(V13:Y13) | AA13: =변수!AA24 | AB13: =변수!AB24 | AC13: =변수!AC24 | AD13: =변수!AD24 | AE13: =SUM(AA13:AD13)
A14: 기타영업외손익 | B14: 손익 | C14: 억원 | D14: 기타영업외손익 | E14: =IFERROR(VLOOKUP($D14,BS연결,MATCH(E$1,BS연결H,0),0)/100,"") | G14: =IFERROR(VLOOKUP($D14,BS연결,MATCH(G$1,BS연결H,0),0)/100,"") | H14: =IFERROR(VLOOKUP($D14,BS연결,MATCH(H$1,BS연결H,0),0)/100,"") | I14: =IFERROR(VLOOKUP($D14,BS연결,MATCH(I$1,BS연결H,0),0)/100,"") | J14: =IFERROR(VLOOKUP($D14,BS연결,MATCH(J$1,BS연결H,0),0)/100,"") | K14: =IFERROR(VLOOKUP($D14,BS연결,MATCH(K$1,BS연결H,0),0)/100,"") | L14: =IFERROR(VLOOKUP($D14,BS연결,MATCH(L$1,BS연결H,0),0)/100,"") | M14: =IFERROR(VLOOKUP($D14,BS연결,MATCH(M$1,BS연결H,0),0)/100,"") | N14: =IFERROR(VLOOKUP($D14,BS연결,MATCH(N$1,BS연결H,0),0)/100,"") | ... R14: =IFERROR(VLOOKUP($D14,BS연결,MATCH(R$1,BS연결H,0),0)/100,"") | S14: =변수!S25 | T14: =변수!T25 | U14: =SUM(Q14:T14) | V14: =변수!V25 | W14: =변수!W25 | X14: =변수!X25 | Y14: =변수!Y25 | Z14: =SUM(V14:Y14) | AA14: =변수!AA25 | AB14: =변수!AB25 | AC14: =변수!AC25 | AD14: =변수!AD25 | AE14: =SUM(AA14:AD14)
A15: 세전이익 | B15: 손익 | C15: 억원 | D15: 법인세비용차감전계속사업이익 | E15: =IFERROR(VLOOKUP($D15,BS연결,MATCH(E$1,BS연결H,0),0)/100,"") | G15: =IFERROR(VLOOKUP($D15,BS연결,MATCH(G$1,BS연결H,0),0)/100,"") | H15: =IFERROR(VLOOKUP($D15,BS연결,MATCH(H$1,BS연결H,0),0)/100,"") | I15: =IFERROR(VLOOKUP($D15,BS연결,MATCH(I$1,BS연결H,0),0)/100,"") | J15: =IFERROR(VLOOKUP($D15,BS연결,MATCH(J$1,BS연결H,0),0)/100,"") | K15: =IFERROR(VLOOKUP($D15,BS연결,MATCH(K$1,BS연결H,0),0)/100,"") | L15: =IFERROR(VLOOKUP($D15,BS연결,MATCH(L$1,BS연결H,0),0)/100,"") | M15: =IFERROR(VLOOKUP($D15,BS연결,MATCH(M$1,BS연결H,0),0)/100,"") | N15: =IFERROR(VLOOKUP($D15,BS연결,MATCH(N$1,BS연결H,0),0)/100,"") | ... R15: =IFERROR(VLOOKUP($D15,BS연결,MATCH(R$1,BS연결H,0),0)/100,"") | S15: =IFERROR(S9+S11+S14,"") | T15: =IFERROR(T9+T11+T14,"") | U15: =SUM(Q15:T15) | V15: =IFERROR(V9+V11+V14,"") | W15: =IFERROR(W9+W11+W14,"") | X15: =IFERROR(X9+X11+X14,"") | Y15: =IFERROR(Y9+Y11+Y14,"") | Z15: =SUM(V15:Y15) | AA15: =IFERROR(AA9+AA11+AA14,"") | AB15: =IFERROR(AB9+AB11+AB14,"") | AC15: =IFERROR(AC9+AC11+AC14,"") | AD15: =IFERROR(AD9+AD11+AD14,"") | AE15: =SUM(AA15:AD15)
A16: 법인세비용 | B16: 손익 | C16: 억원 | D16: 법인세비용 | E16: =IFERROR(VLOOKUP($D16,BS연결,MATCH(E$1,BS연결H,0),0)/100,"") | G16: =IFERROR(VLOOKUP($D16,BS연결,MATCH(G$1,BS연결H,0),0)/100,"") | H16: =IFERROR(VLOOKUP($D16,BS연결,MATCH(H$1,BS연결H,0),0)/100,"") | I16: =IFERROR(VLOOKUP($D16,BS연결,MATCH(I$1,BS연결H,0),0)/100,"") | J16: =IFERROR(VLOOKUP($D16,BS연결,MATCH(J$1,BS연결H,0),0)/100,"") | K16: =IFERROR(VLOOKUP($D16,BS연결,MATCH(K$1,BS연결H,0),0)/100,"") | L16: =IFERROR(VLOOKUP($D16,BS연결,MATCH(L$1,BS연결H,0),0)/100,"") | M16: =IFERROR(VLOOKUP($D16,BS연결,MATCH(M$1,BS연결H,0),0)/100,"") | N16: =IFERROR(VLOOKUP($D16,BS연결,MATCH(N$1,BS연결H,0),0)/100,"") | ... R16: =IFERROR(VLOOKUP($D16,BS연결,MATCH(R$1,BS연결H,0),0)/100,"") | S16: =IFERROR(MAX(S15,0)*변수!S26,"") | T16: =IFERROR(MAX(T15,0)*변수!T26,"") | U16: =SUM(Q16:T16) | V16: =IFERROR(MAX(V15,0)*변수!V26,"") | W16: =IFERROR(MAX(W15,0)*변수!W26,"") | X16: =IFERROR(MAX(X15,0)*변수!X26,"") | Y16: =IFERROR(MAX(Y15,0)*변수!Y26,"") | Z16: =SUM(V16:Y16) | AA16: =IFERROR(MAX(AA15,0)*변수!AA26,"") | AB16: =IFERROR(MAX(AB15,0)*변수!AB26,"") | AC16: =IFERROR(MAX(AC15,0)*변수!AC26,"") | AD16: =IFERROR(MAX(AD15,0)*변수!AD26,"") | AE16: =SUM(AA16:AD16)
A17: 당기순이익 | B17: 손익 | C17: 억원 | D17: 당기순이익 | E17: =IFERROR(VLOOKUP($D17,BS연결,MATCH(E$1,BS연결H,0),0)/100,"") | G17: =IFERROR(VLOOKUP($D17,BS연결,MATCH(G$1,BS연결H,0),0)/100,"") | H17: =IFERROR(VLOOKUP($D17,BS연결,MATCH(H$1,BS연결H,0),0)/100,"") | I17: =IFERROR(VLOOKUP($D17,BS연결,MATCH(I$1,BS연결H,0),0)/100,"") | J17: =IFERROR(VLOOKUP($D17,BS연결,MATCH(J$1,BS연결H,0),0)/100,"") | K17: =IFERROR(VLOOKUP($D17,BS연결,MATCH(K$1,BS연결H,0),0)/100,"") | L17: =IFERROR(VLOOKUP($D17,BS연결,MATCH(L$1,BS연결H,0),0)/100,"") | M17: =IFERROR(VLOOKUP($D17,BS연결,MATCH(M$1,BS연결H,0),0)/100,"") | N17: =IFERROR(VLOOKUP($D17,BS연결,MATCH(N$1,BS연결H,0),0)/100,"") | ... R17: =IFERROR(VLOOKUP($D17,BS연결,MATCH(R$1,BS연결H,0),0)/100,"") | S17: =IFERROR(S15-S16,"") | T17: =IFERROR(T15-T16,"") | U17: =SUM(Q17:T17) | V17: =IFERROR(V15-V16,"") | W17: =IFERROR(W15-W16,"") | X17: =IFERROR(X15-X16,"") | Y17: =IFERROR(Y15-Y16,"") | Z17: =SUM(V17:Y17) | AA17: =IFERROR(AA15-AA16,"") | AB17: =IFERROR(AB15-AB16,"") | AC17: =IFERROR(AC15-AC16,"") | AD17: =IFERROR(AD15-AD16,"") | AE17: =SUM(AA17:AD17)
A18: 지배주주순이익 | B18: 손익 | C18: 억원 | D18: (지배주주지분)당기순이익 | E18: =IFERROR(VLOOKUP($D18,BS연결,MATCH(E$1,BS연결H,0),0)/100,"") | G18: =IFERROR(VLOOKUP($D18,BS연결,MATCH(G$1,BS연결H,0),0)/100,"") | H18: =IFERROR(VLOOKUP($D18,BS연결,MATCH(H$1,BS연결H,0),0)/100,"") | I18: =IFERROR(VLOOKUP($D18,BS연결,MATCH(I$1,BS연결H,0),0)/100,"") | J18: =IFERROR(VLOOKUP($D18,BS연결,MATCH(J$1,BS연결H,0),0)/100,"") | K18: =IFERROR(VLOOKUP($D18,BS연결,MATCH(K$1,BS연결H,0),0)/100,"") | L18: =IFERROR(VLOOKUP($D18,BS연결,MATCH(L$1,BS연결H,0),0)/100,"") | M18: =IFERROR(VLOOKUP($D18,BS연결,MATCH(M$1,BS연결H,0),0)/100,"") | N18: =IFERROR(VLOOKUP($D18,BS연결,MATCH(N$1,BS연결H,0),0)/100,"") | ... R18: =IFERROR(VLOOKUP($D18,BS연결,MATCH(R$1,BS연결H,0),0)/100,"") | S18: =IFERROR(S17*변수!S27,"") | T18: =IFERROR(T17*변수!T27,"") | U18: =SUM(Q18:T18) | V18: =IFERROR(V17*변수!V27,"") | W18: =IFERROR(W17*변수!W27,"") | X18: =IFERROR(X17*변수!X27,"") | Y18: =IFERROR(Y17*변수!Y27,"") | Z18: =SUM(V18:Y18) | AA18: =IFERROR(AA17*변수!AA27,"") | AB18: =IFERROR(AB17*변수!AB27,"") | AC18: =IFERROR(AC17*변수!AC27,"") | AD18: =IFERROR(AD17*변수!AD27,"") | AE18: =SUM(AA18:AD18)
A19: 자산총계 | B19: 재무상태 | C19: 억원 | D19: 자산총계 | E19: =IFERROR(VLOOKUP($D19,BS연결,MATCH(E$1,BS연결H,0),0)/100,"") | F19: =IFERROR(VLOOKUP($D19,BS연결,MATCH(F$1,BS연결H,0),0)/100,"") | G19: =IFERROR(VLOOKUP($D19,BS연결,MATCH(G$1,BS연결H,0),0)/100,"") | H19: =IFERROR(VLOOKUP($D19,BS연결,MATCH(H$1,BS연결H,0),0)/100,"") | I19: =IFERROR(VLOOKUP($D19,BS연결,MATCH(I$1,BS연결H,0),0)/100,"") | J19: =IFERROR(VLOOKUP($D19,BS연결,MATCH(J$1,BS연결H,0),0)/100,"") | K19: =IFERROR(VLOOKUP($D19,BS연결,MATCH(K$1,BS연결H,0),0)/100,"") | L19: =IFERROR(VLOOKUP($D19,BS연결,MATCH(L$1,BS연결H,0),0)/100,"") | ... R19: =IFERROR(VLOOKUP($D19,BS연결,MATCH(R$1,BS연결H,0),0)/100,"") | S19: =IFERROR(S20+S21,"") | T19: =IFERROR(T20+T21,"") | U19: =T19 | V19: =IFERROR(V20+V21,"") | W19: =IFERROR(W20+W21,"") | X19: =IFERROR(X20+X21,"") | Y19: =IFERROR(Y20+Y21,"") | Z19: =Y19 | AA19: =IFERROR(AA20+AA21,"") | AB19: =IFERROR(AB20+AB21,"") | AC19: =IFERROR(AC20+AC21,"") | AD19: =IFERROR(AD20+AD21,"") | AE19: =AD19
A20: 부채총계 | B20: 재무상태 | C20: 억원 | D20: 부채총계 | E20: =IFERROR(VLOOKUP($D20,BS연결,MATCH(E$1,BS연결H,0),0)/100,"") | F20: =IFERROR(VLOOKUP($D20,BS연결,MATCH(F$1,BS연결H,0),0)/100,"") | G20: =IFERROR(VLOOKUP($D20,BS연결,MATCH(G$1,BS연결H,0),0)/100,"") | H20: =IFERROR(VLOOKUP($D20,BS연결,MATCH(H$1,BS연결H,0),0)/100,"") | I20: =IFERROR(VLOOKUP($D20,BS연결,MATCH(I$1,BS연결H,0),0)/100,"") | J20: =IFERROR(VLOOKUP($D20,BS연결,MATCH(J$1,BS연결H,0),0)/100,"") | K20: =IFERROR(VLOOKUP($D20,BS연결,MATCH(K$1,BS연결H,0),0)/100,"") | L20: =IFERROR(VLOOKUP($D20,BS연결,MATCH(L$1,BS연결H,0),0)/100,"") | ... R20: =IFERROR(VLOOKUP($D20,BS연결,MATCH(R$1,BS연결H,0),0)/100,"") | S20: =IFERROR(R20*(1+변수!S28),"") | T20: =IFERROR(S20*(1+변수!T28),"") | U20: =T20 | V20: =IFERROR(T20*(1+변수!V28),"") | W20: =IFERROR(V20*(1+변수!W28),"") | X20: =IFERROR(W20*(1+변수!X28),"") | Y20: =IFERROR(X20*(1+변수!Y28),"") | Z20: =Y20 | AA20: =IFERROR(Y20*(1+변수!AA28),"") | AB20: =IFERROR(AA20*(1+변수!AB28),"") | AC20: =IFERROR(AB20*(1+변수!AC28),"") | AD20: =IFERROR(AC20*(1+변수!AD28),"") | AE20: =AD20
A21: 자본총계 | B21: 재무상태 | C21: 억원 | D21: 자본총계 | E21: =IFERROR(VLOOKUP($D21,BS연결,MATCH(E$1,BS연결H,0),0)/100,"") | F21: =IFERROR(VLOOKUP($D21,BS연결,MATCH(F$1,BS연결H,0),0)/100,"") | G21: =IFERROR(VLOOKUP($D21,BS연결,MATCH(G$1,BS연결H,0),0)/100,"") | H21: =IFERROR(VLOOKUP($D21,BS연결,MATCH(H$1,BS연결H,0),0)/100,"") | I21: =IFERROR(VLOOKUP($D21,BS연결,MATCH(I$1,BS연결H,0),0)/100,"") | J21: =IFERROR(VLOOKUP($D21,BS연결,MATCH(J$1,BS연결H,0),0)/100,"") | K21: =IFERROR(VLOOKUP($D21,BS연결,MATCH(K$1,BS연결H,0),0)/100,"") | L21: =IFERROR(VLOOKUP($D21,BS연결,MATCH(L$1,BS연결H,0),0)/100,"") | ... R21: =IFERROR(VLOOKUP($D21,BS연결,MATCH(R$1,BS연결H,0),0)/100,"") | S21: =IFERROR(R21+S17-변수!S29,"") | T21: =IFERROR(S21+T17-변수!T29,"") | U21: =T21 | V21: =IFERROR(T21+V17-변수!V29,"") | W21: =IFERROR(V21+W17-변수!W29,"") | X21: =IFERROR(W21+X17-변수!X29,"") | Y21: =IFERROR(X21+Y17-변수!Y29,"") | Z21: =Y21 | AA21: =IFERROR(Y21+AA17-변수!AA29,"") | AB21: =IFERROR(AA21+AB17-변수!AB29,"") | AC21: =IFERROR(AB21+AC17-변수!AC29,"") | AD21: =IFERROR(AC21+AD17-변수!AD29,"") | AE21: =AD21
A22: 지배주주지분 | B22: 재무상태 | C22: 억원 | D22: 지배주주지분 | E22: =IFERROR(VLOOKUP($D22,BS연결,MATCH(E$1,BS연결H,0),0)/100,"") | F22: =IFERROR(VLOOKUP($D22,BS연결,MATCH(F$1,BS연결H,0),0)/100,"") | G22: =IFERROR(VLOOKUP($D22,BS연결,MATCH(G$1,BS연결H,0),0)/100,"") | H22: =IFERROR(VLOOKUP($D22,BS연결,MATCH(H$1,BS연결H,0),0)/100,"") | I22: =IFERROR(VLOOKUP($D22,BS연결,MATCH(I$1,BS연결H,0),0)/100,"") | J22: =IFERROR(VLOOKUP($D22,BS연결,MATCH(J$1,BS연결H,0),0)/100,"") | K22: =IFERROR(VLOOKUP($D22,BS연결,MATCH(K$1,BS연결H,0),0)/100,"") | L22: =IFERROR(VLOOKUP($D22,BS연결,MATCH(L$1,BS연결H,0),0)/100,"") | ... R22: =IFERROR(VLOOKUP($D22,BS연결,MATCH(R$1,BS연결H,0),0)/100,"") | S22: =IFERROR(R22+S18-변수!S30,"") | T22: =IFERROR(S22+T18-변수!T30,"") | U22: =T22 | V22: =IFERROR(T22+V18-변수!V30,"") | W22: =IFERROR(V22+W18-변수!W30,"") | X22: =IFERROR(W22+X18-변수!X30,"") | Y22: =IFERROR(X22+Y18-변수!Y30,"") | Z22: =Y22 | AA22: =IFERROR(Y22+AA18-변수!AA30,"") | AB22: =IFERROR(AA22+AB18-변수!AB30,"") | AC22: =IFERROR(AB22+AC18-변수!AC30,"") | AD22: =IFERROR(AC22+AD18-변수!AD30,"") | AE22: =AD22
A23: 총차입금 | B23: 재무상태 | C23: 억원 | D23: 총차입금 | E23: =IFERROR(VLOOKUP($D23,BS연결,MATCH(E$1,BS연결H,0),0)/100,"") | F23: =IFERROR(VLOOKUP($D23,BS연결,MATCH(F$1,BS연결H,0),0)/100,"") | G23: =IFERROR(VLOOKUP($D23,BS연결,MATCH(G$1,BS연결H,0),0)/100,"") | H23: =IFERROR(VLOOKUP($D23,BS연결,MATCH(H$1,BS연결H,0),0)/100,"") | I23: =IFERROR(VLOOKUP($D23,BS연결,MATCH(I$1,BS연결H,0),0)/100,"") | J23: =IFERROR(VLOOKUP($D23,BS연결,MATCH(J$1,BS연결H,0),0)/100,"") | K23: =IFERROR(VLOOKUP($D23,BS연결,MATCH(K$1,BS연결H,0),0)/100,"") | L23: =IFERROR(VLOOKUP($D23,BS연결,MATCH(L$1,BS연결H,0),0)/100,"") | ... R23: =IFERROR(VLOOKUP($D23,BS연결,MATCH(R$1,BS연결H,0),0)/100,"") | S23: =IFERROR(R23*(1+변수!S31),"") | T23: =IFERROR(S23*(1+변수!T31),"") | U23: =T23 | V23: =IFERROR(T23*(1+변수!V31),"") | W23: =IFERROR(V23*(1+변수!W31),"") | X23: =IFERROR(W23*(1+변수!X31),"") | Y23: =IFERROR(X23*(1+변수!Y31),"") | Z23: =Y23 | AA23: =IFERROR(Y23*(1+변수!AA31),"") | AB23: =IFERROR(AA23*(1+변수!AB31),"") | AC23: =IFERROR(AB23*(1+변수!AC31),"") | AD23: =IFERROR(AC23*(1+변수!AD31),"") | AE23: =AD23
A24: 순차입금 | B24: 재무상태 | C24: 억원 | D24: 순차입금 | E24: =IFERROR(VLOOKUP($D24,BS연결,MATCH(E$1,BS연결H,0),0)/100,"") | F24: =IFERROR(VLOOKUP($D24,BS연결,MATCH(F$1,BS연결H,0),0)/100,"") | G24: =IFERROR(VLOOKUP($D24,BS연결,MATCH(G$1,BS연결H,0),0)/100,"") | H24: =IFERROR(VLOOKUP($D24,BS연결,MATCH(H$1,BS연결H,0),0)/100,"") | I24: =IFERROR(VLOOKUP($D24,BS연결,MATCH(I$1,BS연결H,0),0)/100,"") | J24: =IFERROR(VLOOKUP($D24,BS연결,MATCH(J$1,BS연결H,0),0)/100,"") | K24: =IFERROR(VLOOKUP($D24,BS연결,MATCH(K$1,BS연결H,0),0)/100,"") | L24: =IFERROR(VLOOKUP($D24,BS연결,MATCH(L$1,BS연결H,0),0)/100,"") | ... R24: =IFERROR(VLOOKUP($D24,BS연결,MATCH(R$1,BS연결H,0),0)/100,"") | S24: =IFERROR(R24*(1+변수!S32),"") | T24: =IFERROR(S24*(1+변수!T32),"") | U24: =T24 | V24: =IFERROR(T24*(1+변수!V32),"") | W24: =IFERROR(V24*(1+변수!W32),"") | X24: =IFERROR(W24*(1+변수!X32),"") | Y24: =IFERROR(X24*(1+변수!Y32),"") | Z24: =Y24 | AA24: =IFERROR(Y24*(1+변수!AA32),"") | AB24: =IFERROR(AA24*(1+변수!AB32),"") | AC24: =IFERROR(AB24*(1+변수!AC32),"") | AD24: =IFERROR(AC24*(1+변수!AD32),"") | AE24: =AD24
A25: 이자발생자산 | B25: 재무상태 | C25: 억원 | D25: 이자발생자산 | E25: =IFERROR(VLOOKUP($D25,BS연결,MATCH(E$1,BS연결H,0),0)/100,"") | F25: =IFERROR(VLOOKUP($D25,BS연결,MATCH(F$1,BS연결H,0),0)/100,"") | G25: =IFERROR(VLOOKUP($D25,BS연결,MATCH(G$1,BS연결H,0),0)/100,"") | H25: =IFERROR(VLOOKUP($D25,BS연결,MATCH(H$1,BS연결H,0),0)/100,"") | I25: =IFERROR(VLOOKUP($D25,BS연결,MATCH(I$1,BS연결H,0),0)/100,"") | J25: =IFERROR(VLOOKUP($D25,BS연결,MATCH(J$1,BS연결H,0),0)/100,"") | K25: =IFERROR(VLOOKUP($D25,BS연결,MATCH(K$1,BS연결H,0),0)/100,"") | L25: =IFERROR(VLOOKUP($D25,BS연결,MATCH(L$1,BS연결H,0),0)/100,"") | ... R25: =IFERROR(VLOOKUP($D25,BS연결,MATCH(R$1,BS연결H,0),0)/100,"") | S25: =IFERROR(R25*(1+변수!S33),"") | T25: =IFERROR(S25*(1+변수!T33),"") | U25: =T25 | V25: =IFERROR(T25*(1+변수!V33),"") | W25: =IFERROR(V25*(1+변수!W33),"") | X25: =IFERROR(W25*(1+변수!X33),"") | Y25: =IFERROR(X25*(1+변수!Y33),"") | Z25: =Y25 | AA25: =IFERROR(Y25*(1+변수!AA33),"") | AB25: =IFERROR(AA25*(1+변수!AB33),"") | AC25: =IFERROR(AB25*(1+변수!AC33),"") | AD25: =IFERROR(AC25*(1+변수!AD33),"") | AE25: =AD25
A26: 현금및현금성자산 | B26: 재무상태 | C26: 억원 | D26: 현금및현금성자산 | E26: =IFERROR(VLOOKUP($D26,BS연결,MATCH(E$1,BS연결H,0),0)/100,"") | F26: =IFERROR(VLOOKUP($D26,BS연결,MATCH(F$1,BS연결H,0),0)/100,"") | G26: =IFERROR(VLOOKUP($D26,BS연결,MATCH(G$1,BS연결H,0),0)/100,"") | H26: =IFERROR(VLOOKUP($D26,BS연결,MATCH(H$1,BS연결H,0),0)/100,"") | I26: =IFERROR(VLOOKUP($D26,BS연결,MATCH(I$1,BS연결H,0),0)/100,"") | J26: =IFERROR(VLOOKUP($D26,BS연결,MATCH(J$1,BS연결H,0),0)/100,"") | K26: =IFERROR(VLOOKUP($D26,BS연결,MATCH(K$1,BS연결H,0),0)/100,"") | L26: =IFERROR(VLOOKUP($D26,BS연결,MATCH(L$1,BS연결H,0),0)/100,"") | ... R26: =IFERROR(VLOOKUP($D26,BS연결,MATCH(R$1,BS연결H,0),0)/100,"") | U26: =T26 | Z26: =Y26 | AE26: =AD26
