Workbook
Name 변수H: 변수!$C$1:$R$1
Name 환율: 변수!$C$6:$R$13
Name BS연결H: BS연결!$C$1:$R$1
Name BS연결: BS연결!$C$5:$R$5
Name BS별도H: BS별도!$C$1:$R$1
Name BS별도: BS별도!$C$5:$R$63
Name SUBQH: subQ!$A$1:$R$1
Name subQ: subQ!$A$5:$R$37

Sheet README
A1: 케이앤에스아이앤씨(487400) 실적 모델 — ARGUS 한국조선
A2: 기준 분기 2026Q2 · 마지막 실적 2026Q2 · 생성 2026-10-26
A3: 모든 수치는 모델 산출값(DART 공개 재무제표 + 우리 추정)이다 — 목표주가·투자 추천 아님. 참고용 · 투자조언 아님.
A5: 시트
A6: 변수 가정 시계열. 환율 8행(ECB via frankfurter — L2 fx.json; 추정 분기 = 노란 가정), 추정 드라이버(노란 셀 = 모델값에서 역산한 가정, 바꾸면 재계산; 연녹 셀 = 3절 스칼라 참조 수식), 3절 스칼라 가정(세율·판관비율·지배주주비중·이자율·종가·PER 밴드·COE·외화 순노출·헤지비율)
A7: BS연결/BS별도 FnGuide 계정명 × 기간 값 덤프(백만원). 행1 분기라벨, 행4 YYYY.MM / YYYY.12A. 이름정의 BS연결H·BS연결(계정명 C열부터)
A8: subQ 분기 서브모델(억원 = 백만원/100). 확정 행: =IFERROR(VLOOKUP($D행,BS연결,MATCH(E$1,BS연결H,0),0)/100,"") 추정 행: 변수 시트 가정 셀 참조 수식. 외환손익·파생상품손익은 BS 계정 합·차, 기타금융손익은 잔차, OPM·EPS·BPS·PER·PBR 은 파생 수식
A9: SLS 선표(조선사만, sls json 있을 때): 요약 행(sls 저장값) + 계약별 스케줄(백만$) × (헤지비율 × 헤지환율 + (1−헤지비율) × 건조시점 환율[변수 원/달러(평균)]) → 원화 수식 블록 → 합계 행이 subQ 매출조선에 연결
A10: 시나리오 신규수주 보수/기준/낙관(forecast_panel 패널, 모델에 scenarios 가 있을 때만): 매출액·영업이익 = subQ 기준값 ± (시나리오 신규 − base 신규) × OPM. base 만 subQ 행에 포함, 나머지는 합산 안 함
A11: 분기/연간예상 subQ 를 이름(A열 key)으로 VLOOKUP 한 보고서 표(억원)
A12: TP PER 밴드 × 12M fwd EPS, PBR = ROE/COE × BPS — 모델 산출값 구간, 목표주가·추천 아님
A13: 외화 환율 QoQ, 외화 순노출 × Δ기말환율 → 환관련손익 추정
... A34: 백테스트: {"freeze": "2025Q2", "horizon": 4, "revenue_wape_pct": null, "op_wape_pct": null, "n": 0, "note": "freeze 2025Q2 이후 실적 분기 없음 → 백테스트 없음"}

Sheet 변수
C1: 이름: 변수H | E1: 2Q26 | F1: 3Q26 | G1: 4Q26 | H1: 2026 | I1: 1Q27 | J1: 2Q27 | K1: 3Q27 | L1: 4Q27 | M1: 2027 | N1: 1Q28 | O1: 2Q28 | P1: 3Q28 | Q1: 4Q28 | R1: 2028
A2: 가정 시계열 — 노란 셀은 추정 가정(모델값에서 역산), 연녹 셀은 3절 스칼라 참조 수식. 바꾸면 subQ·분기·연간예상·TP·시나리오가 재계산됩니다.
E3: 1 | F3: 2 | G3: 3 | H3: 4 | I3: 5 | J3: 6 | K3: 7 | L3: 8 | M3: 9 | N3: 10 | O3: 11 | P3: 12 | Q3: 13 | R3: 14
E4: 2026.06 | F4: 2026.09 | G4: 2026.12 | H4: 2026.12A | I4: 2027.03 | J4: 2027.06 | K4: 2027.09 | L4: 2027.12 | M4: 2027.12A | N4: 2028.03 | O4: 2028.06 | P4: 2028.09 | Q4: 2028.12 | R4: 2028.12A
B5: 1. FX | C5: 이름: 환율
A6: USDKRW_avg | C6: 원/달러(평균) | E6: 1501.75 | F6: 1418.75 | G6: 1337.49 | H6: 1451.19 | I6: 1324.45 | J6: 1324.45 | K6: 1324.45 | L6: 1324.45 | N6: 1324.45 | O6: 1324.45 | P6: 1324.45 | Q6: 1324.45
A7: USDKRW_end | C7: 원/달러(기말) | E7: 1550.89 | F7: 1355.4 | G7: 1324.45 | H7: 1324.45 | I7: 1324.45 | J7: 1324.45 | K7: 1324.45 | L7: 1324.45 | N7: 1324.45 | O7: 1324.45 | P7: 1324.45 | Q7: 1324.45
A8: JPY100KRW_avg | C8: 원/100Y(평균) | E8: 942.16 | F8: 890.41 | G8: 846.51 | H8: 915.57 | I8: 844.67 | J8: 844.67 | K8: 844.67 | L8: 844.67 | N8: 844.67 | O8: 844.67 | P8: 844.67 | Q8: 844.67
A9: JPY100KRW_end | C9: 원/100Y(기말) | E9: 954.75 | F9: 863.31 | G9: 844.67 | H9: 844.67 | I9: 844.67 | J9: 844.67 | K9: 844.67 | L9: 844.67 | N9: 844.67 | O9: 844.67 | P9: 844.67 | Q9: 844.67
A10: EURKRW_avg | C10: W/Euro(평균) | E10: 1746.09 | F10: 1631.97 | G10: 1500.06 | H10: 1680.5 | I10: 1482.45 | J10: 1482.45 | K10: 1482.45 | L10: 1482.45 | N10: 1482.45 | O10: 1482.45 | P10: 1482.45 | Q10: 1482.45
A11: EURKRW_end | C11: W/Euro(기말) | E11: 1767.09 | F11: 1539.06 | G11: 1482.45 | H11: 1482.45 | I11: 1482.45 | J11: 1482.45 | K11: 1482.45 | L11: 1482.45 | N11: 1482.45 | O11: 1482.45 | P11: 1482.45 | Q11: 1482.45
A12: CNYKRW_avg | C12: 원/중국원(평균) | E12: 220.8 | F12: 210.43 | G12: 199.88 | H12: 213.06 | I12: 198.56 | J12: 198.56 | K12: 198.56 | L12: 198.56 | N12: 198.56 | O12: 198.56 | P12: 198.56 | Q12: 198.56
A13: CNYKRW_end | C13: 원/중국원(기말) | E13: 228.56 | F13: 202.16 | G13: 198.56 | H13: 198.56 | I13: 198.56 | J13: 198.56 | K13: 198.56 | L13: 198.56 | N13: 198.56 | O13: 198.56 | P13: 198.56 | Q13: 198.56
B14: 1b. 종가
A15: price_close_end | C15: 종가(기말) | F15: 6510 | G15: 4200
A16: price_high | C16: 종가(최고) | F16: 24600 | G16: 6840
A17: price_low | C17: 종가(최저) | F17: 6450 | G17: 4165
A18: price_avg | C18: 종가(평균) | F18: 8729.1 | G18: 5254.4
B20: 2. 추정 드라이버 | C20: 실적 열 = subQ 실현값(수식), 추정 열 = 가정(노란 = 모델값 역산, 연녹 = 3절 스칼라 참조)
A21: drv:매출액 | B21: yoy | C21: 매출액 YoY | F21: -7.1141e-05 | G21: 0 | I21: 0 | J21: -7.1141e-05 | K21: 0 | L21: 0 | N21: 0 | O21: 0 | P21: 0 | Q21: 0
A22: drv:판관비 | B22: ratio | C22: 판관비율(/매출) | E22: =IFERROR(subQ!E8/subQ!E5,"") | F22: =$D$49 | G22: =$D$49 | H22: =IFERROR(subQ!H8/subQ!H5,"") | I22: =$D$49 | J22: =$D$49 | K22: =$D$49 | L22: =$D$49 | M22: =IFERROR(subQ!M8/subQ!M5,"") | N22: =$D$49 | O22: =$D$49 | P22: =$D$49 | Q22: =$D$49 | R22: =IFERROR(subQ!R8/subQ!R5,"")
A23: drv:영업이익 | B23: ratio | C23: 영업이익률(OPM) | E23: =IFERROR(subQ!E9/subQ!E5,"") | F23: -0.2 | G23: -0.2 | H23: =IFERROR(subQ!H9/subQ!H5,"") | I23: -0.2 | J23: -0.2 | K23: -0.2 | L23: -0.2 | M23: =IFERROR(subQ!M9/subQ!M5,"") | N23: -0.2 | O23: -0.2 | P23: -0.2 | Q23: -0.2 | R23: =IFERROR(subQ!R9/subQ!R5,"")
A24: drv:금융손익 | B24: abs | C24: 금융손익 (가정, 억원) | E24: =subQ!E11 | F24: -0.67 | G24: -0.67 | H24: =subQ!H11 | I24: -0.67 | J24: -0.67 | K24: -0.67 | L24: -0.67 | M24: =subQ!M11 | N24: -0.67 | O24: -0.67 | P24: -0.67 | Q24: -0.67 | R24: =subQ!R11
A25: drv:이자손익 | B25: abs | C25: 이자손익 (가정, 억원) | E25: =subQ!E12 | H25: =subQ!H12 | M25: =subQ!M12 | R25: =subQ!R12
A26: drv:외환손익 | B26: abs | C26: 외환손익 (가정, 억원) | E26: =subQ!E13 | H26: =subQ!H13 | M26: =subQ!M13 | R26: =subQ!R13
A27: drv:기타영업외손익 | B27: abs | C27: 기타영업외손익 (가정, 억원) | E27: =subQ!E14 | F27: 0 | G27: 0 | H27: =subQ!H14 | I27: 0 | J27: 0 | K27: 0 | L27: 0 | M27: =subQ!M14 | N27: 0 | O27: 0 | P27: 0 | Q27: 0 | R27: =subQ!R14
A28: drv:법인세비용 | B28: ratio | C28: 법인세율(/세전) | E28: =IFERROR(subQ!E16/subQ!E15,"") | F28: 0 | G28: 0 | H28: =IFERROR(subQ!H16/subQ!H15,"") | I28: 0 | J28: 0 | K28: 0 | L28: 0 | M28: =IFERROR(subQ!M16/subQ!M15,"") | N28: 0 | O28: 0 | P28: 0 | Q28: 0 | R28: =IFERROR(subQ!R16/subQ!R15,"")
A29: drv:지배주주순이익 | B29: ratio | C29: 지배주주 비중(/당기순이익) | E29: =IFERROR(subQ!E18/subQ!E17,"") | F29: =$D$50 | G29: =$D$50 | H29: =IFERROR(subQ!H18/subQ!H17,"") | I29: =$D$50 | J29: =$D$50 | K29: =$D$50 | L29: =$D$50 | M29: =IFERROR(subQ!M18/subQ!M17,"") | N29: =$D$50 | O29: =$D$50 | P29: =$D$50 | Q29: =$D$50 | R29: =IFERROR(subQ!R18/subQ!R17,"")
A30: drv:부채총계 | B30: qoq | C30: 부채총계 QoQ | F30: -2.3763e-05 | G30: 0 | I30: 0 | J30: 0 | K30: 0 | L30: 0 | N30: 0 | O30: 0 | P30: 0 | Q30: 0
A31: drv:자본총계 | B31: roll | C31: 자본총계 기타변동(배당 등, 억원) | F31: -0.005200001 | G31: -2e-09 | I31: -0.010000001 | J31: -2e-09 | K31: -0.010000001 | L31: -1e-09 | N31: -2e-09 | O31: -0.010000001 | P31: -2e-09 | Q31: -0.010000001
A32: drv:지배주주지분 | B32: roll | C32: 지배주주지분 기타변동(배당 등, 억원) | F32: -0.005200001 | G32: -2e-09 | I32: -0.010000001 | J32: -2e-09 | K32: -0.010000001 | L32: -1e-09 | N32: -2e-09 | O32: -0.010000001 | P32: -2e-09 | Q32: -0.010000001
A33: drv:총차입금 | B33: qoq | C33: 총차입금 QoQ | F33: 0 | G33: 0 | I33: 0 | J33: 0 | K33: 0 | L33: 0 | N33: 0 | O33: 0 | P33: 0 | Q33: 0
A34: drv:순차입금 | B34: qoq | C34: 순차입금 QoQ | F34: -0.2364008 | G34: -0.30971129 | I34: -0.44812602 | J34: -0.81299213 | K34: -4.3421053 | L34: 1.3007874 | N34: 0.56468173 | O34: 0.36132983 | P34: 0.26542416 | Q34: 0.20949721
A35: drv:이자발생자산 | B35: qoq | C35: 이자발생자산 QoQ | F35: -0.070318013 | G35: -0.075717298 | I35: -0.081920063 | J35: -0.089121746 | K35: -0.097960152 | L35: -0.108467 | N35: -0.12181094 | O35: -0.13870697 | P35: -0.16085007 | Q35: -0.1919145
A36: drv:현금및현금성자산 | B36: qoq | C36: 현금및현금성자산 QoQ
A37: drv:주식수 | B37: qoq | C37: 주식수 QoQ | F37: 0.3173555 | G37: 0 | I37: 0 | J37: 0 | K37: 0 | L37: 0 | N37: 0 | O37: 0 | P37: 0 | Q37: 0
A38: drv:DPS | B38: abs | C38: DPS (가정, 원) | E38: =subQ!E30 | G38: 0 | H38: =subQ!H30 | L38: 0 | M38: =subQ!M30 | Q38: 0 | R38: =subQ!R30
B40: 3. 밸류에이션·스칼라 | C40: 노란 셀 = 가정. '연결' 표시는 추정 전 분기 수식이 이 셀을 참조한다는 뜻
A41: sc:종가 | C41: 종가 | D41: 4200 | E41: 원 — 네이버 정규장 종가(aik 확정종가 대조 · aik 4,495원)
A42: sc:기준일 | C42: 기준일 | D42: 20261026 | E42: 종가 기준일
...

Sheet BS연결
B1: (백만원) | C1: 이름: BS연결H | E1: 2Q26 | F1: 3Q26 | G1: 4Q26 | H1: 2026 | I1: 1Q27 | J1: 2Q27 | K1: 3Q27 | L1: 4Q27 | M1: 2027 | N1: 1Q28 | O1: 2Q28 | P1: 3Q28 | Q1: 4Q28 | R1: 2028
B2: 연결 | D2: fin json(kship_fin.py)
B3: 케이앤에스아이앤씨(연) | C3: UPDATE: 26-10-26 | E3: 1 | F3: 2 | G3: 3 | H3: 4 | I3: 5 | J3: 6 | K3: 7 | L3: 8 | M3: 9 | N3: 10 | O3: 11 | P3: 12 | Q3: 13 | R3: 14
B4: Account Code | C4: AccountNAME | E4: 2026.06 | F4: 2026.09 | G4: 2026.12 | H4: 2026.12A | I4: 2027.03 | J4: 2027.06 | K4: 2027.09 | L4: 2027.12 | M4: 2027.12A | N4: 2028.03 | O4: 2028.06 | P4: 2028.09 | Q4: 2028.12 | R4: 2028.12A

Sheet BS별도
B1: (백만원) | C1: 이름: BS별도H | E1: 2Q26 | F1: 3Q26 | G1: 4Q26 | H1: 2026 | I1: 1Q27 | J1: 2Q27 | K1: 3Q27 | L1: 4Q27 | M1: 2027 | N1: 1Q28 | O1: 2Q28 | P1: 3Q28 | Q1: 4Q28 | R1: 2028
B2: 별도 | D2: fin json(kship_fin.py)
B3: 케이앤에스아이앤씨(별) | C3: UPDATE: 26-10-26 | E3: 1 | F3: 2 | G3: 3 | H3: 4 | I3: 5 | J3: 6 | K3: 7 | L3: 8 | M3: 9 | N3: 10 | O3: 11 | P3: 12 | Q3: 13 | R3: 14
B4: Account Code | C4: AccountNAME | E4: 2026.06 | F4: 2026.09 | G4: 2026.12 | H4: 2026.12A | I4: 2027.03 | J4: 2027.06 | K4: 2027.09 | L4: 2027.12 | M4: 2027.12A | N4: 2028.03 | O4: 2028.06 | P4: 2028.09 | Q4: 2028.12 | R4: 2028.12A
A5: 1 | C5: 유동자산 | E5: 20261.86
A6: 1 | C6: 현금및현금성자산 | E6: 11490.67
A7: 1 | C7: 매출채권및기타채권 | E7: 1057.1
A8: 1 | C8: 기타유동자산 | E8: 347.53
A9: 1 | C9: 재고자산 | E9: 7358.62
A10: 1 | C10: 비유동자산 | E10: 8062.05
A11: 1 | C11: 장기금융자산 | E11: 243.45
A12: 1 | C12: 투자자산 | E12: 243.45
A13: 1 | C13: 유형자산 | E13: 7086.2
A14: 1 | C14: 무형자산 | E14: 732.4
A15: 1 | C15: 자산총계 | E15: 28323.91
A16: 1 | C16: 유동부채 | E16: 15986.26
... A63: 1 | C63: 이자손익 | E63: -63.22

Sheet subQ
A1: YQ | C1: subQ 분기 서브모델(억원, U=100) | E1: 2Q26 | F1: 3Q26 | G1: 4Q26 | H1: 2026 | I1: 1Q27 | J1: 2Q27 | K1: 3Q27 | L1: 4Q27 | M1: 2027 | N1: 1Q28 | O1: 2Q28 | P1: 3Q28 | Q1: 4Q28 | R1: 2028
A2: A=이름(key) B=그룹 C=단위 D=FnGuide 계정명(VLOOKUP 키). 확정=VLOOKUP(BS), 추정=변수 가정 참조
E3: 1 | F3: 2 | G3: 3 | H3: 4 | I3: 5 | J3: 6 | K3: 7 | L3: 8 | M3: 9 | N3: 10 | O3: 11 | P3: 12 | Q3: 13 | R3: 14
E4: 2026.06 | F4: 2026.09 | G4: 2026.12 | H4: 2026.12A | I4: 2027.03 | J4: 2027.06 | K4: 2027.09 | L4: 2027.12 | M4: 2027.12A | N4: 2028.03 | O4: 2028.06 | P4: 2028.09 | Q4: 2028.12 | R4: 2028.12A
A5: 매출액 | B5: 손익 | C5: 억원 | D5: 매출액(수익) | E5: =IFERROR(VLOOKUP($D5,BS별도,MATCH(E$1,BS별도H,0),0)/100,"") | F5: =IFERROR(E5*(1+변수!F21),"") | G5: =IFERROR(F5*(1+변수!G21),"") | I5: =IFERROR(G5*(1+변수!I21),"") | J5: =IFERROR(E5*(1+변수!J21),"") | K5: =IFERROR(F5*(1+변수!K21),"") | L5: =IFERROR(G5*(1+변수!L21),"") | M5: =SUM(I5:L5) | N5: =IFERROR(I5*(1+변수!N21),"") | O5: =IFERROR(J5*(1+변수!O21),"") | P5: =IFERROR(K5*(1+변수!P21),"") | Q5: =IFERROR(L5*(1+변수!Q21),"") | R5: =SUM(N5:Q5)
A6: 매출원가 | B6: 손익 | C6: 억원 | D6: 매출원가 | E6: =IFERROR(VLOOKUP($D6,BS별도,MATCH(E$1,BS별도H,0),0)/100,"") | F6: =IFERROR(F5-F7,"") | G6: =IFERROR(G5-G7,"") | I6: =IFERROR(I5-I7,"") | J6: =IFERROR(J5-J7,"") | K6: =IFERROR(K5-K7,"") | L6: =IFERROR(L5-L7,"") | M6: =SUM(I6:L6) | N6: =IFERROR(N5-N7,"") | O6: =IFERROR(O5-O7,"") | P6: =IFERROR(P5-P7,"") | Q6: =IFERROR(Q5-Q7,"") | R6: =SUM(N6:Q6)
A7: 매출총이익 | B7: 손익 | C7: 억원 | D7: 매출총이익 | E7: =IFERROR(VLOOKUP($D7,BS별도,MATCH(E$1,BS별도H,0),0)/100,"") | F7: =IFERROR(F9+F8,"") | G7: =IFERROR(G9+G8,"") | I7: =IFERROR(I9+I8,"") | J7: =IFERROR(J9+J8,"") | K7: =IFERROR(K9+K8,"") | L7: =IFERROR(L9+L8,"") | M7: =SUM(I7:L7) | N7: =IFERROR(N9+N8,"") | O7: =IFERROR(O9+O8,"") | P7: =IFERROR(P9+P8,"") | Q7: =IFERROR(Q9+Q8,"") | R7: =SUM(N7:Q7)
A8: 판관비 | B8: 손익 | C8: 억원 | D8: 판관비 | E8: =IFERROR(VLOOKUP($D8,BS별도,MATCH(E$1,BS별도H,0),0)/100,"") | F8: =IFERROR(F5*변수!F22,"") | G8: =IFERROR(G5*변수!G22,"") | I8: =IFERROR(I5*변수!I22,"") | J8: =IFERROR(J5*변수!J22,"") | K8: =IFERROR(K5*변수!K22,"") | L8: =IFERROR(L5*변수!L22,"") | M8: =SUM(I8:L8) | N8: =IFERROR(N5*변수!N22,"") | O8: =IFERROR(O5*변수!O22,"") | P8: =IFERROR(P5*변수!P22,"") | Q8: =IFERROR(Q5*변수!Q22,"") | R8: =SUM(N8:Q8)
A9: 영업이익 | B9: 손익 | C9: 억원 | D9: 영업이익 | E9: =IFERROR(VLOOKUP($D9,BS별도,MATCH(E$1,BS별도H,0),0)/100,"") | F9: =IFERROR(F5*변수!F23,"") | G9: =IFERROR(G5*변수!G23,"") | I9: =IFERROR(I5*변수!I23,"") | J9: =IFERROR(J5*변수!J23,"") | K9: =IFERROR(K5*변수!K23,"") | L9: =IFERROR(L5*변수!L23,"") | M9: =SUM(I9:L9) | N9: =IFERROR(N5*변수!N23,"") | O9: =IFERROR(O5*변수!O23,"") | P9: =IFERROR(P5*변수!P23,"") | Q9: =IFERROR(Q5*변수!Q23,"") | R9: =SUM(N9:Q9)
A10: OPM | B10: 손익 | C10: % | D10: 영업이익률 | E10: =IFERROR(E9/E5,"") | F10: =IFERROR(F9/F5,"") | G10: =IFERROR(G9/G5,"") | I10: =IFERROR(I9/I5,"") | J10: =IFERROR(J9/J5,"") | K10: =IFERROR(K9/K5,"") | L10: =IFERROR(L9/L5,"") | M10: =IFERROR(M9/M5,"") | N10: =IFERROR(N9/N5,"") | O10: =IFERROR(O9/O5,"") | P10: =IFERROR(P9/P5,"") | ... R10: =IFERROR(R9/R5,"")
A11: 금융손익 | B11: 손익 | C11: 억원 | D11: 금융손익 | E11: =IFERROR(VLOOKUP($D11,BS별도,MATCH(E$1,BS별도H,0),0)/100,"") | F11: =변수!F24 | G11: =변수!G24 | I11: =변수!I24 | J11: =변수!J24 | K11: =변수!K24 | L11: =변수!L24 | M11: =SUM(I11:L11) | N11: =변수!N24 | O11: =변수!O24 | P11: =변수!P24 | Q11: =변수!Q24 | R11: =SUM(N11:Q11)
A12: 이자손익 | B12: 손익 | C12: 억원 | D12: 이자손익 | E12: =IFERROR(VLOOKUP($D12,BS별도,MATCH(E$1,BS별도H,0),0)/100,"") | M12: =SUM(I12:L12) | R12: =SUM(N12:Q12)
A13: 외환손익 | B13: 손익 | C13: 억원 | D13: 외환손익(실적만; 추정 환효과는 환관련손익) | E13: =IFERROR((VLOOKUP("외환차익",BS별도,MATCH(E$1,BS별도H,0),0)-VLOOKUP("외환차손",BS별도,MATCH(E$1,BS별도H,0),0)+VLOOKUP("외화환산이익",BS별도,MATCH(E$1,BS별도H,0),0)-VLOOKUP("외화환산손실",BS별도,MATCH(E$1,BS별도H,0),0))/100,"") | M13: =SUM(I13:L13) | R13: =SUM(N13:Q13)
A14: 기타영업외손익 | B14: 손익 | C14: 억원 | D14: 기타영업외손익 | E14: =IFERROR(VLOOKUP($D14,BS별도,MATCH(E$1,BS별도H,0),0)/100,"") | F14: =변수!F27 | G14: =변수!G27 | I14: =변수!I27 | J14: =변수!J27 | K14: =변수!K27 | L14: =변수!L27 | M14: =SUM(I14:L14) | N14: =변수!N27 | O14: =변수!O27 | P14: =변수!P27 | Q14: =변수!Q27 | R14: =SUM(N14:Q14)
A15: 세전이익 | B15: 손익 | C15: 억원 | D15: 법인세비용차감전계속사업이익 | E15: =IFERROR(VLOOKUP($D15,BS별도,MATCH(E$1,BS별도H,0),0)/100,"") | F15: =IFERROR(F9+F11+F14,"") | G15: =IFERROR(G9+G11+G14,"") | I15: =IFERROR(I9+I11+I14,"") | J15: =IFERROR(J9+J11+J14,"") | K15: =IFERROR(K9+K11+K14,"") | L15: =IFERROR(L9+L11+L14,"") | M15: =SUM(I15:L15) | N15: =IFERROR(N9+N11+N14,"") | O15: =IFERROR(O9+O11+O14,"") | P15: =IFERROR(P9+P11+P14,"") | Q15: =IFERROR(Q9+Q11+Q14,"") | R15: =SUM(N15:Q15)
A16: 법인세비용 | B16: 손익 | C16: 억원 | D16: 법인세비용 | F16: =IFERROR(F15*변수!F28,"") | G16: =IFERROR(G15*변수!G28,"") | I16: =IFERROR(I15*변수!I28,"") | J16: =IFERROR(J15*변수!J28,"") | K16: =IFERROR(K15*변수!K28,"") | L16: =IFERROR(L15*변수!L28,"") | M16: =SUM(I16:L16) | N16: =IFERROR(N15*변수!N28,"") | O16: =IFERROR(O15*변수!O28,"") | P16: =IFERROR(P15*변수!P28,"") | Q16: =IFERROR(Q15*변수!Q28,"") | R16: =SUM(N16:Q16)
A17: 당기순이익 | B17: 손익 | C17: 억원 | D17: 당기순이익 | E17: =IFERROR(VLOOKUP($D17,BS별도,MATCH(E$1,BS별도H,0),0)/100,"") | F17: =IFERROR(F15-F16,"") | G17: =IFERROR(G15-G16,"") | I17: =IFERROR(I15-I16,"") | J17: =IFERROR(J15-J16,"") | K17: =IFERROR(K15-K16,"") | L17: =IFERROR(L15-L16,"") | M17: =SUM(I17:L17) | N17: =IFERROR(N15-N16,"") | O17: =IFERROR(O15-O16,"") | P17: =IFERROR(P15-P16,"") | Q17: =IFERROR(Q15-Q16,"") | R17: =SUM(N17:Q17)
A18: 지배주주순이익 | B18: 손익 | C18: 억원 | D18: (지배주주지분)당기순이익 | E18: =IFERROR(VLOOKUP($D18,BS별도,MATCH(E$1,BS별도H,0),0)/100,"") | F18: =IFERROR(F17*변수!F29,"") | G18: =IFERROR(G17*변수!G29,"") | I18: =IFERROR(I17*변수!I29,"") | J18: =IFERROR(J17*변수!J29,"") | K18: =IFERROR(K17*변수!K29,"") | L18: =IFERROR(L17*변수!L29,"") | M18: =SUM(I18:L18) | N18: =IFERROR(N17*변수!N29,"") | O18: =IFERROR(O17*변수!O29,"") | P18: =IFERROR(P17*변수!P29,"") | Q18: =IFERROR(Q17*변수!Q29,"") | R18: =SUM(N18:Q18)
A19: 자산총계 | B19: 재무상태 | C19: 억원 | D19: 자산총계 | E19: =IFERROR(VLOOKUP($D19,BS별도,MATCH(E$1,BS별도H,0),0)/100,"") | F19: =IFERROR(F20+F21,"") | G19: =IFERROR(G20+G21,"") | H19: =G19 | I19: =IFERROR(I20+I21,"") | J19: =IFERROR(J20+J21,"") | K19: =IFERROR(K20+K21,"") | L19: =IFERROR(L20+L21,"") | M19: =L19 | N19: =IFERROR(N20+N21,"") | O19: =IFERROR(O20+O21,"") | P19: =IFERROR(P20+P21,"") | Q19: =IFERROR(Q20+Q21,"") | R19: =Q19
A20: 부채총계 | B20: 재무상태 | C20: 억원 | D20: 부채총계 | E20: =IFERROR(VLOOKUP($D20,BS별도,MATCH(E$1,BS별도H,0),0)/100,"") | F20: =IFERROR(E20*(1+변수!F30),"") | G20: =IFERROR(F20*(1+변수!G30),"") | H20: =G20 | I20: =IFERROR(G20*(1+변수!I30),"") | J20: =IFERROR(I20*(1+변수!J30),"") | K20: =IFERROR(J20*(1+변수!K30),"") | L20: =IFERROR(K20*(1+변수!L30),"") | M20: =L20 | N20: =IFERROR(L20*(1+변수!N30),"") | O20: =IFERROR(N20*(1+변수!O30),"") | P20: =IFERROR(O20*(1+변수!P30),"") | Q20: =IFERROR(P20*(1+변수!Q30),"") | R20: =Q20
A21: 자본총계 | B21: 재무상태 | C21: 억원 | D21: 자본총계 | E21: =IFERROR(VLOOKUP($D21,BS별도,MATCH(E$1,BS별도H,0),0)/100,"") | F21: =IFERROR(E21+F17-변수!F31,"") | G21: =IFERROR(F21+G17-변수!G31,"") | H21: =G21 | I21: =IFERROR(G21+I17-변수!I31,"") | J21: =IFERROR(I21+J17-변수!J31,"") | K21: =IFERROR(J21+K17-변수!K31,"") | L21: =IFERROR(K21+L17-변수!L31,"") | M21: =L21 | N21: =IFERROR(L21+N17-변수!N31,"") | O21: =IFERROR(N21+O17-변수!O31,"") | P21: =IFERROR(O21+P17-변수!P31,"") | Q21: =IFERROR(P21+Q17-변수!Q31,"") | R21: =Q21
A22: 지배주주지분 | B22: 재무상태 | C22: 억원 | D22: 지배주주지분 | E22: =IFERROR(VLOOKUP($D22,BS별도,MATCH(E$1,BS별도H,0),0)/100,"") | F22: =IFERROR(E22+F18-변수!F32,"") | G22: =IFERROR(F22+G18-변수!G32,"") | H22: =G22 | I22: =IFERROR(G22+I18-변수!I32,"") | J22: =IFERROR(I22+J18-변수!J32,"") | K22: =IFERROR(J22+K18-변수!K32,"") | L22: =IFERROR(K22+L18-변수!L32,"") | M22: =L22 | N22: =IFERROR(L22+N18-변수!N32,"") | O22: =IFERROR(N22+O18-변수!O32,"") | P22: =IFERROR(O22+P18-변수!P32,"") | Q22: =IFERROR(P22+Q18-변수!Q32,"") | R22: =Q22
A23: 총차입금 | B23: 재무상태 | C23: 억원 | D23: 총차입금 | E23: =IFERROR(VLOOKUP($D23,BS별도,MATCH(E$1,BS별도H,0),0)/100,"") | F23: =IFERROR(E23*(1+변수!F33),"") | G23: =IFERROR(F23*(1+변수!G33),"") | H23: =G23 | I23: =IFERROR(G23*(1+변수!I33),"") | J23: =IFERROR(I23*(1+변수!J33),"") | K23: =IFERROR(J23*(1+변수!K33),"") | L23: =IFERROR(K23*(1+변수!L33),"") | M23: =L23 | N23: =IFERROR(L23*(1+변수!N33),"") | O23: =IFERROR(N23*(1+변수!O33),"") | P23: =IFERROR(O23*(1+변수!P33),"") | Q23: =IFERROR(P23*(1+변수!Q33),"") | R23: =Q23
A24: 순차입금 | B24: 재무상태 | C24: 억원 | D24: 순차입금 | E24: =IFERROR(VLOOKUP($D24,BS별도,MATCH(E$1,BS별도H,0),0)/100,"") | F24: =IFERROR(E24*(1+변수!F34),"") | G24: =IFERROR(F24*(1+변수!G34),"") | H24: =G24 | I24: =IFERROR(G24*(1+변수!I34),"") | J24: =IFERROR(I24*(1+변수!J34),"") | K24: =IFERROR(J24*(1+변수!K34),"") | L24: =IFERROR(K24*(1+변수!L34),"") | M24: =L24 | N24: =IFERROR(L24*(1+변수!N34),"") | O24: =IFERROR(N24*(1+변수!O34),"") | P24: =IFERROR(O24*(1+변수!P34),"") | Q24: =IFERROR(P24*(1+변수!Q34),"") | R24: =Q24
A25: 이자발생자산 | B25: 재무상태 | C25: 억원 | D25: 이자발생자산 | E25: =IFERROR(VLOOKUP($D25,BS별도,MATCH(E$1,BS별도H,0),0)/100,"") | F25: =IFERROR(E25*(1+변수!F35),"") | G25: =IFERROR(F25*(1+변수!G35),"") | H25: =G25 | I25: =IFERROR(G25*(1+변수!I35),"") | J25: =IFERROR(I25*(1+변수!J35),"") | K25: =IFERROR(J25*(1+변수!K35),"") | L25: =IFERROR(K25*(1+변수!L35),"") | M25: =L25 | N25: =IFERROR(L25*(1+변수!N35),"") | O25: =IFERROR(N25*(1+변수!O35),"") | P25: =IFERROR(O25*(1+변수!P35),"") | Q25: =IFERROR(P25*(1+변수!Q35),"") | R25: =Q25
A26: 현금및현금성자산 | B26: 재무상태 | C26: 억원 | D26: 현금및현금성자산 | E26: =IFERROR(VLOOKUP($D26,BS별도,MATCH(E$1,BS별도H,0),0)/100,"") | H26: =G26 | M26: =L26 | R26: =Q26
A27: 주식수 | B27: 주당 | C27: 백만주 | D27: 유통주식수 | E27: 7.789 | F27: =IFERROR(E27*(1+변수!F37),"") | G27: =IFERROR(F27*(1+변수!G37),"") | H27: =G27 | I27: =IFERROR(G27*(1+변수!I37),"") | J27: =IFERROR(I27*(1+변수!J37),"") | K27: =IFERROR(J27*(1+변수!K37),"") | L27: =IFERROR(K27*(1+변수!L37),"") | M27: =L27 | N27: =IFERROR(L27*(1+변수!N37),"") | O27: =IFERROR(N27*(1+변수!O37),"") | P27: =IFERROR(O27*(1+변수!P37),"") | Q27: =IFERROR(P27*(1+변수!Q37),"") | R27: =Q27
A28: EPS | B28: 주당 | C28: 원 | D28: EPS | E28: =IFERROR(E18*100/E27,"") | F28: =IFERROR(F18*100/F27,"") | G28: =IFERROR(G18*100/G27,"") | I28: =IFERROR(I18*100/I27,"") | J28: =IFERROR(J18*100/J27,"") | K28: =IFERROR(K18*100/K27,"") | L28: =IFERROR(L18*100/L27,"") | M28: =SUM(I28:L28) | N28: =IFERROR(N18*100/N27,"") | O28: =IFERROR(O18*100/O27,"") | P28: =IFERROR(P18*100/P27,"") | Q28: =IFERROR(Q18*100/Q27,"") | R28: =SUM(N28:Q28)
A29: BPS | B29: 주당 | C29: 원 | D29: BPS | E29: =IFERROR(E22*100/E27,"") | F29: =IFERROR(F22*100/F27,"") | G29: =IFERROR(G22*100/G27,"") | H29: =G29 | I29: =IFERROR(I22*100/I27,"") | J29: =IFERROR(J22*100/J27,"") | K29: =IFERROR(K22*100/K27,"") | L29: =IFERROR(L22*100/L27,"") | M29: =L29 | N29: =IFERROR(N22*100/N27,"") | O29: =IFERROR(O22*100/O27,"") | P29: =IFERROR(P22*100/P27,"") | Q29: =IFERROR(Q22*100/Q27,"") | R29: =Q29
A30: DPS | B30: 주당 | C30: 원 | D30: DPS(보통주) | G30: =변수!G38 | H30: 0 | L30: =변수!L38 | M30: =SUM(I30:L30) | Q30: =변수!Q38 | R30: =SUM(N30:Q30)
A31: PBR | B31: 주당 | C31: 배 | D31: PBR | F31: =IFERROR(변수!$D$41/F29,"") | G31: =IFERROR(변수!$D$41/G29,"") | H31: =G31 | I31: =IFERROR(변수!$D$41/I29,"") | J31: =IFERROR(변수!$D$41/J29,"") | K31: =IFERROR(변수!$D$41/K29,"") | L31: =IFERROR(변수!$D$41/L29,"") | M31: =L31 | N31: =IFERROR(변수!$D$41/N29,"") | O31: =IFERROR(변수!$D$41/O29,"") | P31: =IFERROR(변수!$D$41/P29,"") | Q31: =IFERROR(변수!$D$41/Q29,"") | R31: =Q31
A32: 매출전사 | B32: 사업부 | C32: 억원 | D32: 매출 전사(부문 미분리) | E32: 37.95 | F32: =IFERROR(F5,"") | G32: =IFERROR(G5,"") | I32: =IFERROR(I5,"") | J32: =IFERROR(J5,"") | K32: =IFERROR(K5,"") | L32: =IFERROR(L5,"") | M32: =SUM(I32:L32) | N32: =IFERROR(N5,"") | O32: =IFERROR(O5,"") | P32: =IFERROR(P5,"") | Q32: =IFERROR(Q5,"") | R32: =SUM(N32:Q32)
A33: OP전사 | B33: 사업부 | C33: 억원 | D33: OP 전사(부문 미분리) | E33: -14.75 | F33: =IFERROR(F9,"") | G33: =IFERROR(G9,"") | I33: =IFERROR(I9,"") | J33: =IFERROR(J9,"") | K33: =IFERROR(K9,"") | L33: =IFERROR(L9,"") | M33: =SUM(I33:L33) | N33: =IFERROR(N9,"") | O33: =IFERROR(O9,"") | P33: =IFERROR(P9,"") | Q33: =IFERROR(Q9,"") | R33: =SUM(N33:Q33)
B34: 비율(참고)
A35: NPM | C35: % | D35: 지배주주순이익 / 매출액 | E35: =IFERROR(E18/E5,"") | F35: =IFERROR(F18/F5,"") | G35: =IFERROR(G18/G5,"") | H35: =IFERROR(H18/H5,"") | I35: =IFERROR(I18/I5,"") | J35: =IFERROR(J18/J5,"") | K35: =IFERROR(K18/K5,"") | L35: =IFERROR(L18/L5,"") | ... R35: =IFERROR(R18/R5,"")
A36: 매출원가율 | C36: % | D36: 매출원가 / 매출액 | E36: =IFERROR(E6/E5,"") | F36: =IFERROR(F6/F5,"") | G36: =IFERROR(G6/G5,"") | H36: =IFERROR(H6/H5,"") | I36: =IFERROR(I6/I5,"") | J36: =IFERROR(J6/J5,"") | K36: =IFERROR(K6/K5,"") | L36: =IFERROR(L6/L5,"") | ... R36: =IFERROR(R6/R5,"")
A37: 판관비율 | C37: % | D37: 판관비 / 매출액 | E37: =IFERROR(E8/E5,"") | F37: =IFERROR(F8/F5,"") | G37: =IFERROR(G8/G5,"") | H37: =IFERROR(H8/H5,"") | I37: =IFERROR(I8/I5,"") | J37: =IFERROR(J8/J5,"") | K37: =IFERROR(K8/K5,"") | L37: =IFERROR(L8/L5,"") | ... R37: =IFERROR(R8/R5,"")

Sheet 분기
C1: 이름: 분기H — subQ 를 이름으로 VLOOKUP(억원) | E1: 2Q26 | F1: 3Q26 | G1: 4Q26 | H1: 1Q27 | I1: 2Q27 | J1: 3Q27 | K1: 4Q27 | L1: 1Q28 | M1: 2Q28 | N1: 3Q28 | O1: 4Q28
C2: 종가: | D2: =변수!D41
C3: 기준일: | D3: 20261026 | E3: 1 | F3: 2 | G3: 3 | H3: 4 | I3: 5 | J3: 6 | K3: 7 | L3: 8 | M3: 9 | N3: 10 | O3: 11
E4: 2026.06 | F4: 2026.09 | G4: 2026.12 | H4: 2027.03 | I4: 2027.06 | J4: 2027.09 | K4: 2027.12 | L4: 2028.03 | M4: 2028.06 | N4: 2028.09 | O4: 2028.12
A5: 매출액 | D5: 매출액 | E5: =IFERROR(VLOOKUP($A5,subQ,MATCH(E$1,SUBQH,0),0),"") | F5: =IFERROR(VLOOKUP($A5,subQ,MATCH(F$1,SUBQH,0),0),"") | G5: =IFERROR(VLOOKUP($A5,subQ,MATCH(G$1,SUBQH,0),0),"") | H5: =IFERROR(VLOOKUP($A5,subQ,MATCH(H$1,SUBQH,0),0),"") | I5: =IFERROR(VLOOKUP($A5,subQ,MATCH(I$1,SUBQH,0),0),"") | J5: =IFERROR(VLOOKUP($A5,subQ,MATCH(J$1,SUBQH,0),0),"") | K5: =IFERROR(VLOOKUP($A5,subQ,MATCH(K$1,SUBQH,0),0),"") | L5: =IFERROR(VLOOKUP($A5,subQ,MATCH(L$1,SUBQH,0),0),"") | ... O5: =IFERROR(VLOOKUP($A5,subQ,MATCH(O$1,SUBQH,0),0),"")
A6: 매출원가 | D6: 매출원가 | E6: =IFERROR(VLOOKUP($A6,subQ,MATCH(E$1,SUBQH,0),0),"") | F6: =IFERROR(VLOOKUP($A6,subQ,MATCH(F$1,SUBQH,0),0),"") | G6: =IFERROR(VLOOKUP($A6,subQ,MATCH(G$1,SUBQH,0),0),"") | H6: =IFERROR(VLOOKUP($A6,subQ,MATCH(H$1,SUBQH,0),0),"") | I6: =IFERROR(VLOOKUP($A6,subQ,MATCH(I$1,SUBQH,0),0),"") | J6: =IFERROR(VLOOKUP($A6,subQ,MATCH(J$1,SUBQH,0),0),"") | K6: =IFERROR(VLOOKUP($A6,subQ,MATCH(K$1,SUBQH,0),0),"") | L6: =IFERROR(VLOOKUP($A6,subQ,MATCH(L$1,SUBQH,0),0),"") | ... O6: =IFERROR(VLOOKUP($A6,subQ,MATCH(O$1,SUBQH,0),0),"")
A7: 매출총이익 | D7: 매출총이익 | E7: =IFERROR(VLOOKUP($A7,subQ,MATCH(E$1,SUBQH,0),0),"") | F7: =IFERROR(VLOOKUP($A7,subQ,MATCH(F$1,SUBQH,0),0),"") | G7: =IFERROR(VLOOKUP($A7,subQ,MATCH(G$1,SUBQH,0),0),"") | H7: =IFERROR(VLOOKUP($A7,subQ,MATCH(H$1,SUBQH,0),0),"") | I7: =IFERROR(VLOOKUP($A7,subQ,MATCH(I$1,SUBQH,0),0),"") | J7: =IFERROR(VLOOKUP($A7,subQ,MATCH(J$1,SUBQH,0),0),"") | K7: =IFERROR(VLOOKUP($A7,subQ,MATCH(K$1,SUBQH,0),0),"") | L7: =IFERROR(VLOOKUP($A7,subQ,MATCH(L$1,SUBQH,0),0),"") | ... O7: =IFERROR(VLOOKUP($A7,subQ,MATCH(O$1,SUBQH,0),0),"")
A8: 판관비 | D8: 판매비와관리비 | E8: =IFERROR(VLOOKUP($A8,subQ,MATCH(E$1,SUBQH,0),0),"") | F8: =IFERROR(VLOOKUP($A8,subQ,MATCH(F$1,SUBQH,0),0),"") | G8: =IFERROR(VLOOKUP($A8,subQ,MATCH(G$1,SUBQH,0),0),"") | H8: =IFERROR(VLOOKUP($A8,subQ,MATCH(H$1,SUBQH,0),0),"") | I8: =IFERROR(VLOOKUP($A8,subQ,MATCH(I$1,SUBQH,0),0),"") | J8: =IFERROR(VLOOKUP($A8,subQ,MATCH(J$1,SUBQH,0),0),"") | K8: =IFERROR(VLOOKUP($A8,subQ,MATCH(K$1,SUBQH,0),0),"") | L8: =IFERROR(VLOOKUP($A8,subQ,MATCH(L$1,SUBQH,0),0),"") | ... O8: =IFERROR(VLOOKUP($A8,subQ,MATCH(O$1,SUBQH,0),0),"")
A9: 영업이익 | D9: 영업이익 | E9: =IFERROR(VLOOKUP($A9,subQ,MATCH(E$1,SUBQH,0),0),"") | F9: =IFERROR(VLOOKUP($A9,subQ,MATCH(F$1,SUBQH,0),0),"") | G9: =IFERROR(VLOOKUP($A9,subQ,MATCH(G$1,SUBQH,0),0),"") | H9: =IFERROR(VLOOKUP($A9,subQ,MATCH(H$1,SUBQH,0),0),"") | I9: =IFERROR(VLOOKUP($A9,subQ,MATCH(I$1,SUBQH,0),0),"") | J9: =IFERROR(VLOOKUP($A9,subQ,MATCH(J$1,SUBQH,0),0),"") | K9: =IFERROR(VLOOKUP($A9,subQ,MATCH(K$1,SUBQH,0),0),"") | L9: =IFERROR(VLOOKUP($A9,subQ,MATCH(L$1,SUBQH,0),0),"") | ... O9: =IFERROR(VLOOKUP($A9,subQ,MATCH(O$1,SUBQH,0),0),"")
A10: OPM | D10: 영업이익률 | E10: =IFERROR(VLOOKUP($A10,subQ,MATCH(E$1,SUBQH,0),0),"") | F10: =IFERROR(VLOOKUP($A10,subQ,MATCH(F$1,SUBQH,0),0),"") | G10: =IFERROR(VLOOKUP($A10,subQ,MATCH(G$1,SUBQH,0),0),"") | H10: =IFERROR(VLOOKUP($A10,subQ,MATCH(H$1,SUBQH,0),0),"") | I10: =IFERROR(VLOOKUP($A10,subQ,MATCH(I$1,SUBQH,0),0),"") | J10: =IFERROR(VLOOKUP($A10,subQ,MATCH(J$1,SUBQH,0),0),"") | K10: =IFERROR(VLOOKUP($A10,subQ,MATCH(K$1,SUBQH,0),0),"") | L10: =IFERROR(VLOOKUP($A10,subQ,MATCH(L$1,SUBQH,0),0),"") | ... O10: =IFERROR(VLOOKUP($A10,subQ,MATCH(O$1,SUBQH,0),0),"")
A11: 금융손익 | D11: 금융손익(이자·환 포함) | E11: =IFERROR(VLOOKUP($A11,subQ,MATCH(E$1,SUBQH,0),0),"") | F11: =IFERROR(VLOOKUP($A11,subQ,MATCH(F$1,SUBQH,0),0),"") | G11: =IFERROR(VLOOKUP($A11,subQ,MATCH(G$1,SUBQH,0),0),"") | H11: =IFERROR(VLOOKUP($A11,subQ,MATCH(H$1,SUBQH,0),0),"") | I11: =IFERROR(VLOOKUP($A11,subQ,MATCH(I$1,SUBQH,0),0),"") | J11: =IFERROR(VLOOKUP($A11,subQ,MATCH(J$1,SUBQH,0),0),"") | K11: =IFERROR(VLOOKUP($A11,subQ,MATCH(K$1,SUBQH,0),0),"") | L11: =IFERROR(VLOOKUP($A11,subQ,MATCH(L$1,SUBQH,0),0),"") | ... O11: =IFERROR(VLOOKUP($A11,subQ,MATCH(O$1,SUBQH,0),0),"")
A12: 이자손익 | D12: 이자손익(이자수익 − 이자비용) | E12: =IFERROR(VLOOKUP($A12,subQ,MATCH(E$1,SUBQH,0),0),"") | F12: =IFERROR(VLOOKUP($A12,subQ,MATCH(F$1,SUBQH,0),0),"") | G12: =IFERROR(VLOOKUP($A12,subQ,MATCH(G$1,SUBQH,0),0),"") | H12: =IFERROR(VLOOKUP($A12,subQ,MATCH(H$1,SUBQH,0),0),"") | I12: =IFERROR(VLOOKUP($A12,subQ,MATCH(I$1,SUBQH,0),0),"") | J12: =IFERROR(VLOOKUP($A12,subQ,MATCH(J$1,SUBQH,0),0),"") | K12: =IFERROR(VLOOKUP($A12,subQ,MATCH(K$1,SUBQH,0),0),"") | L12: =IFERROR(VLOOKUP($A12,subQ,MATCH(L$1,SUBQH,0),0),"") | ... O12: =IFERROR(VLOOKUP($A12,subQ,MATCH(O$1,SUBQH,0),0),"")
A13: 외환손익 | D13: 외환손익(실적만; 추정 환효과는 환관련손익) | E13: =IFERROR(VLOOKUP($A13,subQ,MATCH(E$1,SUBQH,0),0),"") | F13: =IFERROR(VLOOKUP($A13,subQ,MATCH(F$1,SUBQH,0),0),"") | G13: =IFERROR(VLOOKUP($A13,subQ,MATCH(G$1,SUBQH,0),0),"") | H13: =IFERROR(VLOOKUP($A13,subQ,MATCH(H$1,SUBQH,0),0),"") | I13: =IFERROR(VLOOKUP($A13,subQ,MATCH(I$1,SUBQH,0),0),"") | J13: =IFERROR(VLOOKUP($A13,subQ,MATCH(J$1,SUBQH,0),0),"") | K13: =IFERROR(VLOOKUP($A13,subQ,MATCH(K$1,SUBQH,0),0),"") | L13: =IFERROR(VLOOKUP($A13,subQ,MATCH(L$1,SUBQH,0),0),"") | ... O13: =IFERROR(VLOOKUP($A13,subQ,MATCH(O$1,SUBQH,0),0),"")
A14: 기타영업외손익 | D14: 기타영업외손익 | E14: =IFERROR(VLOOKUP($A14,subQ,MATCH(E$1,SUBQH,0),0),"") | F14: =IFERROR(VLOOKUP($A14,subQ,MATCH(F$1,SUBQH,0),0),"") | G14: =IFERROR(VLOOKUP($A14,subQ,MATCH(G$1,SUBQH,0),0),"") | H14: =IFERROR(VLOOKUP($A14,subQ,MATCH(H$1,SUBQH,0),0),"") | I14: =IFERROR(VLOOKUP($A14,subQ,MATCH(I$1,SUBQH,0),0),"") | J14: =IFERROR(VLOOKUP($A14,subQ,MATCH(J$1,SUBQH,0),0),"") | K14: =IFERROR(VLOOKUP($A14,subQ,MATCH(K$1,SUBQH,0),0),"") | L14: =IFERROR(VLOOKUP($A14,subQ,MATCH(L$1,SUBQH,0),0),"") | ... O14: =IFERROR(VLOOKUP($A14,subQ,MATCH(O$1,SUBQH,0),0),"")
A15: 세전이익 | D15: 법인세비용차감전이익 | E15: =IFERROR(VLOOKUP($A15,subQ,MATCH(E$1,SUBQH,0),0),"") | F15: =IFERROR(VLOOKUP($A15,subQ,MATCH(F$1,SUBQH,0),0),"") | G15: =IFERROR(VLOOKUP($A15,subQ,MATCH(G$1,SUBQH,0),0),"") | H15: =IFERROR(VLOOKUP($A15,subQ,MATCH(H$1,SUBQH,0),0),"") | I15: =IFERROR(VLOOKUP($A15,subQ,MATCH(I$1,SUBQH,0),0),"") | J15: =IFERROR(VLOOKUP($A15,subQ,MATCH(J$1,SUBQH,0),0),"") | K15: =IFERROR(VLOOKUP($A15,subQ,MATCH(K$1,SUBQH,0),0),"") | L15: =IFERROR(VLOOKUP($A15,subQ,MATCH(L$1,SUBQH,0),0),"") | ... O15: =IFERROR(VLOOKUP($A15,subQ,MATCH(O$1,SUBQH,0),0),"")
A16: 법인세비용 | D16: 법인세비용 | E16: =IFERROR(VLOOKUP($A16,subQ,MATCH(E$1,SUBQH,0),0),"") | F16: =IFERROR(VLOOKUP($A16,subQ,MATCH(F$1,SUBQH,0),0),"") | G16: =IFERROR(VLOOKUP($A16,subQ,MATCH(G$1,SUBQH,0),0),"") | H16: =IFERROR(VLOOKUP($A16,subQ,MATCH(H$1,SUBQH,0),0),"") | I16: =IFERROR(VLOOKUP($A16,subQ,MATCH(I$1,SUBQH,0),0),"") | J16: =IFERROR(VLOOKUP($A16,subQ,MATCH(J$1,SUBQH,0),0),"") | K16: =IFERROR(VLOOKUP($A16,subQ,MATCH(K$1,SUBQH,0),0),"") | L16: =IFERROR(VLOOKUP($A16,subQ,MATCH(L$1,SUBQH,0),0),"") | ... O16: =IFERROR(VLOOKUP($A16,subQ,MATCH(O$1,SUBQH,0),0),"")
... A34: NPM | D34: NPM | E34: =IFERROR(VLOOKUP($A34,subQ,MATCH(E$1,SUBQH,0),0),"") | F34: =IFERROR(VLOOKUP($A34,subQ,MATCH(F$1,SUBQH,0),0),"") | G34: =IFERROR(VLOOKUP($A34,subQ,MATCH(G$1,SUBQH,0),0),"") | H34: =IFERROR(VLOOKUP($A34,subQ,MATCH(H$1,SUBQH,0),0),"") | I34: =IFERROR(VLOOKUP($A34,subQ,MATCH(I$1,SUBQH,0),0),"") | J34: =IFERROR(VLOOKUP($A34,subQ,MATCH(J$1,SUBQH,0),0),"") | K34: =IFERROR(VLOOKUP($A34,subQ,MATCH(K$1,SUBQH,0),0),"") | L34: =IFERROR(VLOOKUP($A34,subQ,MATCH(L$1,SUBQH,0),0),"") | ... O34: =IFERROR(VLOOKUP($A34,subQ,MATCH(O$1,SUBQH,0),0),"")
A35: 매출액 YoY | D35: 매출액 YoY | I35: =IFERROR(I5/E5-1,"") | J35: =IFERROR(J5/F5-1,"") | K35: =IFERROR(K5/G5-1,"") | L35: =IFERROR(L5/H5-1,"") | M35: =IFERROR(M5/I5-1,"") | N35: =IFERROR(N5/J5-1,"") | O35: =IFERROR(O5/K5-1,"")
A36: 영업이익 YoY | D36: 영업이익 YoY | I36: =IFERROR(I9/E9-1,"") | J36: =IFERROR(J9/F9-1,"") | K36: =IFERROR(K9/G9-1,"") | L36: =IFERROR(L9/H9-1,"") | M36: =IFERROR(M9/I9-1,"") | N36: =IFERROR(N9/J9-1,"") | O36: =IFERROR(O9/K9-1,"")
A37: 지배주주순이익 YoY | D37: 지배주주순이익 YoY | I37: =IFERROR(I18/E18-1,"") | J37: =IFERROR(J18/F18-1,"") | K37: =IFERROR(K18/G18-1,"") | L37: =IFERROR(L18/H18-1,"") | M37: =IFERROR(M18/I18-1,"") | N37: =IFERROR(N18/J18-1,"") | O37: =IFERROR(O18/K18-1,"")

Sheet 연간예상
C1: 이름: 연간예상H — subQ 를 이름으로 VLOOKUP(억원) | E1: 2026 | F1: 2027 | G1: 2028
C2: 종가: | D2: =변수!D41
C3: 기준일: | D3: 20261026 | E3: 1 | F3: 2 | G3: 3
E4: 2026.12A | F4: 2027.12A | G4: 2028.12A
A5: 매출액 | D5: 매출액 | E5: =IFERROR(VLOOKUP($A5,subQ,MATCH(E$1,SUBQH,0),0),"") | F5: =IFERROR(VLOOKUP($A5,subQ,MATCH(F$1,SUBQH,0),0),"") | G5: =IFERROR(VLOOKUP($A5,subQ,MATCH(G$1,SUBQH,0),0),"")
A6: 매출원가 | D6: 매출원가 | E6: =IFERROR(VLOOKUP($A6,subQ,MATCH(E$1,SUBQH,0),0),"") | F6: =IFERROR(VLOOKUP($A6,subQ,MATCH(F$1,SUBQH,0),0),"") | G6: =IFERROR(VLOOKUP($A6,subQ,MATCH(G$1,SUBQH,0),0),"")
A7: 매출총이익 | D7: 매출총이익 | E7: =IFERROR(VLOOKUP($A7,subQ,MATCH(E$1,SUBQH,0),0),"") | F7: =IFERROR(VLOOKUP($A7,subQ,MATCH(F$1,SUBQH,0),0),"") | G7: =IFERROR(VLOOKUP($A7,subQ,MATCH(G$1,SUBQH,0),0),"")
A8: 판관비 | D8: 판매비와관리비 | E8: =IFERROR(VLOOKUP($A8,subQ,MATCH(E$1,SUBQH,0),0),"") | F8: =IFERROR(VLOOKUP($A8,subQ,MATCH(F$1,SUBQH,0),0),"") | G8: =IFERROR(VLOOKUP($A8,subQ,MATCH(G$1,SUBQH,0),0),"")
A9: 영업이익 | D9: 영업이익 | E9: =IFERROR(VLOOKUP($A9,subQ,MATCH(E$1,SUBQH,0),0),"") | F9: =IFERROR(VLOOKUP($A9,subQ,MATCH(F$1,SUBQH,0),0),"") | G9: =IFERROR(VLOOKUP($A9,subQ,MATCH(G$1,SUBQH,0),0),"")
A10: OPM | D10: 영업이익률 | E10: =IFERROR(VLOOKUP($A10,subQ,MATCH(E$1,SUBQH,0),0),"") | F10: =IFERROR(VLOOKUP($A10,subQ,MATCH(F$1,SUBQH,0),0),"") | G10: =IFERROR(VLOOKUP($A10,subQ,MATCH(G$1,SUBQH,0),0),"")
A11: 금융손익 | D11: 금융손익(이자·환 포함) | E11: =IFERROR(VLOOKUP($A11,subQ,MATCH(E$1,SUBQH,0),0),"") | F11: =IFERROR(VLOOKUP($A11,subQ,MATCH(F$1,SUBQH,0),0),"") | G11: =IFERROR(VLOOKUP($A11,subQ,MATCH(G$1,SUBQH,0),0),"")
A12: 이자손익 | D12: 이자손익(이자수익 − 이자비용) | E12: =IFERROR(VLOOKUP($A12,subQ,MATCH(E$1,SUBQH,0),0),"") | F12: =IFERROR(VLOOKUP($A12,subQ,MATCH(F$1,SUBQH,0),0),"") | G12: =IFERROR(VLOOKUP($A12,subQ,MATCH(G$1,SUBQH,0),0),"")
A13: 외환손익 | D13: 외환손익(실적만; 추정 환효과는 환관련손익) | E13: =IFERROR(VLOOKUP($A13,subQ,MATCH(E$1,SUBQH,0),0),"") | F13: =IFERROR(VLOOKUP($A13,subQ,MATCH(F$1,SUBQH,0),0),"") | G13: =IFERROR(VLOOKUP($A13,subQ,MATCH(G$1,SUBQH,0),0),"")
A14: 기타영업외손익 | D14: 기타영업외손익 | E14: =IFERROR(VLOOKUP($A14,subQ,MATCH(E$1,SUBQH,0),0),"") | F14: =IFERROR(VLOOKUP($A14,subQ,MATCH(F$1,SUBQH,0),0),"") | G14: =IFERROR(VLOOKUP($A14,subQ,MATCH(G$1,SUBQH,0),0),"")
A15: 세전이익 | D15: 법인세비용차감전이익 | E15: =IFERROR(VLOOKUP($A15,subQ,MATCH(E$1,SUBQH,0),0),"") | F15: =IFERROR(VLOOKUP($A15,subQ,MATCH(F$1,SUBQH,0),0),"") | G15: =IFERROR(VLOOKUP($A15,subQ,MATCH(G$1,SUBQH,0),0),"")
A16: 법인세비용 | D16: 법인세비용 | E16: =IFERROR(VLOOKUP($A16,subQ,MATCH(E$1,SUBQH,0),0),"") | F16: =IFERROR(VLOOKUP($A16,subQ,MATCH(F$1,SUBQH,0),0),"") | G16: =IFERROR(VLOOKUP($A16,subQ,MATCH(G$1,SUBQH,0),0),"")
... A34: NPM | D34: NPM | E34: =IFERROR(VLOOKUP($A34,subQ,MATCH(E$1,SUBQH,0),0),"") | F34: =IFERROR(VLOOKUP($A34,subQ,MATCH(F$1,SUBQH,0),0),"") | G34: =IFERROR(VLOOKUP($A34,subQ,MATCH(G$1,SUBQH,0),0),"")
A35: 매출액 YoY | D35: 매출액 YoY | F35: =IFERROR(F5/E5-1,"") | G35: =IFERROR(G5/F5-1,"")
A36: 영업이익 YoY | D36: 영업이익 YoY | F36: =IFERROR(F9/E9-1,"") | G36: =IFERROR(G9/F9-1,"")
A37: 지배주주순이익 YoY | D37: 지배주주순이익 YoY | F37: =IFERROR(F18/E18-1,"") | G37: =IFERROR(G18/F18-1,"")

Sheet TP
B1: 종가 | C1: =변수!D41
B2: 기준일 | C2: =변수!D42
B3: 모델 산출값 — 목표주가·추천 아님. 밴드·COE 는 변수 시트 3절의 가정
C5: FY | D5: 2026 | E5: 2027 | F5: 2028
D6: E | E6: E | F6: E
C7: EPS(원) | D7: =IFERROR(VLOOKUP("EPS",subQ,MATCH(D$5,SUBQH,0),0),"") | E7: =IFERROR(VLOOKUP("EPS",subQ,MATCH(E$5,SUBQH,0),0),"") | F7: =IFERROR(VLOOKUP("EPS",subQ,MATCH(F$5,SUBQH,0),0),"")
C8: BPS(원) | D8: =IFERROR(VLOOKUP("BPS",subQ,MATCH(D$5,SUBQH,0),0),"") | E8: =IFERROR(VLOOKUP("BPS",subQ,MATCH(E$5,SUBQH,0),0),"") | F8: =IFERROR(VLOOKUP("BPS",subQ,MATCH(F$5,SUBQH,0),0),"")
C9: 지배주주순이익(억원) | D9: =IFERROR(VLOOKUP("지배주주순이익",subQ,MATCH(D$5,SUBQH,0),0),"") | E9: =IFERROR(VLOOKUP("지배주주순이익",subQ,MATCH(E$5,SUBQH,0),0),"") | F9: =IFERROR(VLOOKUP("지배주주순이익",subQ,MATCH(F$5,SUBQH,0),0),"")
C10: 영업이익(억원) | D10: =IFERROR(VLOOKUP("영업이익",subQ,MATCH(D$5,SUBQH,0),0),"") | E10: =IFERROR(VLOOKUP("영업이익",subQ,MATCH(E$5,SUBQH,0),0),"") | F10: =IFERROR(VLOOKUP("영업이익",subQ,MATCH(F$5,SUBQH,0),0),"")
C11: ROE(EPS/기초BPS) | E11: =IFERROR(E7/D8,"") | F11: =IFERROR(F7/E8,"")
B13: PER
C14: 12M fwd EPS | D14: =IFERROR(D7*변수!D47+E7*(1-변수!D47),"")
C15: 적정가치 @PER_lo | D15: =변수!D44 | E15: =IFERROR(ROUND($D$14*D15,-2),"") | F15: =IFERROR(E15/$C$1-1,"") | G15: 배 · 원 · 종가 대비
C16: 적정가치 @PER_mid | D16: =변수!D45 | E16: =IFERROR(ROUND($D$14*D16,-2),"") | F16: =IFERROR(E16/$C$1-1,"") | G16: 배 · 원 · 종가 대비
C17: 적정가치 @PER_hi | D17: =변수!D46 | E17: =IFERROR(ROUND($D$14*D17,-2),"") | F17: =IFERROR(E17/$C$1-1,"") | G17: 배 · 원 · 종가 대비
C18: 현재 PER(종가/12M fwd EPS) | D18: =IFERROR($C$1/$D$14,"")
B20: PBR
C21: 최근 BPS(마지막 실적 분기) | D21: =IFERROR(VLOOKUP("BPS",subQ,MATCH("2Q26",SUBQH,0),0),"")
C22: ROE fwd(12M fwd EPS / BPS) | D22: =IFERROR($D$14/$D$21,"")
C23: COE | D23: =변수!D43
C24: 적정 PBR = ROE/COE | D24: =IFERROR(D22/D23,"")
C25: 적정가치(PBR) = BPS × 적정PBR | D25: =IFERROR(ROUND(D21*D24,-2),"") | E25: =IFERROR(D25/$C$1-1,"")
C26: 현재 PBR(종가/BPS) | D26: =IFERROR($C$1/D21,"")
B28: 모델 json valuation(참고)
C29: eps_fwd12m | D29: -322
C30: bps_latest | D30: 1313.2
C31: per_now
C32: pbr_now | D32: 3.2
C33: roe_fwd | D33: -0.2452
C34: fair_pbr
C35: fair_value_pbr
C36: ev_ebitda
C37: note | D37: 모델 산출값 — 목표주가·추천 아님

Sheet 외화
C1: 이름: 외화QH — 환율 QoQ · 외화 순노출 × Δ기말환율 | E1: 2Q26 | F1: 3Q26 | G1: 4Q26 | H1: 1Q27 | I1: 2Q27 | J1: 3Q27 | K1: 4Q27 | L1: 1Q28 | M1: 2Q28 | N1: 3Q28 | O1: 4Q28
E3: 1 | F3: 2 | G3: 3 | H3: 4 | I3: 5 | J3: 6 | K3: 7 | L3: 8 | M3: 9 | N3: 10 | O3: 11
E4: 2026.06 | F4: 2026.09 | G4: 2026.12 | H4: 2027.03 | I4: 2027.06 | J4: 2027.09 | K4: 2027.12 | L4: 2028.03 | M4: 2028.06 | N4: 2028.09 | O4: 2028.12
D5: 원/달러(평균) | E5: =IFERROR(VLOOKUP($D5,환율,MATCH(E$1,변수H,0),0),"") | F5: =IFERROR(VLOOKUP($D5,환율,MATCH(F$1,변수H,0),0),"") | G5: =IFERROR(VLOOKUP($D5,환율,MATCH(G$1,변수H,0),0),"") | H5: =IFERROR(VLOOKUP($D5,환율,MATCH(H$1,변수H,0),0),"") | I5: =IFERROR(VLOOKUP($D5,환율,MATCH(I$1,변수H,0),0),"") | J5: =IFERROR(VLOOKUP($D5,환율,MATCH(J$1,변수H,0),0),"") | K5: =IFERROR(VLOOKUP($D5,환율,MATCH(K$1,변수H,0),0),"") | L5: =IFERROR(VLOOKUP($D5,환율,MATCH(L$1,변수H,0),0),"") | ... O5: =IFERROR(VLOOKUP($D5,환율,MATCH(O$1,변수H,0),0),"")
A6: 원/달러(평균) QoQ | F6: =IFERROR(F5/E5-1,"") | G6: =IFERROR(G5/F5-1,"") | H6: =IFERROR(H5/G5-1,"") | I6: =IFERROR(I5/H5-1,"") | J6: =IFERROR(J5/I5-1,"") | K6: =IFERROR(K5/J5-1,"") | L6: =IFERROR(L5/K5-1,"") | M6: =IFERROR(M5/L5-1,"") | ... O6: =IFERROR(O5/N5-1,"")
D7: 원/달러(기말) | E7: =IFERROR(VLOOKUP($D7,환율,MATCH(E$1,변수H,0),0),"") | F7: =IFERROR(VLOOKUP($D7,환율,MATCH(F$1,변수H,0),0),"") | G7: =IFERROR(VLOOKUP($D7,환율,MATCH(G$1,변수H,0),0),"") | H7: =IFERROR(VLOOKUP($D7,환율,MATCH(H$1,변수H,0),0),"") | I7: =IFERROR(VLOOKUP($D7,환율,MATCH(I$1,변수H,0),0),"") | J7: =IFERROR(VLOOKUP($D7,환율,MATCH(J$1,변수H,0),0),"") | K7: =IFERROR(VLOOKUP($D7,환율,MATCH(K$1,변수H,0),0),"") | L7: =IFERROR(VLOOKUP($D7,환율,MATCH(L$1,변수H,0),0),"") | ... O7: =IFERROR(VLOOKUP($D7,환율,MATCH(O$1,변수H,0),0),"")
A8: 원/달러(기말) QoQ | F8: =IFERROR(F7/E7-1,"") | G8: =IFERROR(G7/F7-1,"") | H8: =IFERROR(H7/G7-1,"") | I8: =IFERROR(I7/H7-1,"") | J8: =IFERROR(J7/I7-1,"") | K8: =IFERROR(K7/J7-1,"") | L8: =IFERROR(L7/K7-1,"") | M8: =IFERROR(M7/L7-1,"") | ... O8: =IFERROR(O7/N7-1,"")
D9: W/Euro(평균) | E9: =IFERROR(VLOOKUP($D9,환율,MATCH(E$1,변수H,0),0),"") | F9: =IFERROR(VLOOKUP($D9,환율,MATCH(F$1,변수H,0),0),"") | G9: =IFERROR(VLOOKUP($D9,환율,MATCH(G$1,변수H,0),0),"") | H9: =IFERROR(VLOOKUP($D9,환율,MATCH(H$1,변수H,0),0),"") | I9: =IFERROR(VLOOKUP($D9,환율,MATCH(I$1,변수H,0),0),"") | J9: =IFERROR(VLOOKUP($D9,환율,MATCH(J$1,변수H,0),0),"") | K9: =IFERROR(VLOOKUP($D9,환율,MATCH(K$1,변수H,0),0),"") | L9: =IFERROR(VLOOKUP($D9,환율,MATCH(L$1,변수H,0),0),"") | ... O9: =IFERROR(VLOOKUP($D9,환율,MATCH(O$1,변수H,0),0),"")
A10: W/Euro(평균) QoQ | F10: =IFERROR(F9/E9-1,"") | G10: =IFERROR(G9/F9-1,"") | H10: =IFERROR(H9/G9-1,"") | I10: =IFERROR(I9/H9-1,"") | J10: =IFERROR(J9/I9-1,"") | K10: =IFERROR(K9/J9-1,"") | L10: =IFERROR(L9/K9-1,"") | M10: =IFERROR(M9/L9-1,"") | ... O10: =IFERROR(O9/N9-1,"")
D11: W/Euro(기말) | E11: =IFERROR(VLOOKUP($D11,환율,MATCH(E$1,변수H,0),0),"") | F11: =IFERROR(VLOOKUP($D11,환율,MATCH(F$1,변수H,0),0),"") | G11: =IFERROR(VLOOKUP($D11,환율,MATCH(G$1,변수H,0),0),"") | H11: =IFERROR(VLOOKUP($D11,환율,MATCH(H$1,변수H,0),0),"") | I11: =IFERROR(VLOOKUP($D11,환율,MATCH(I$1,변수H,0),0),"") | J11: =IFERROR(VLOOKUP($D11,환율,MATCH(J$1,변수H,0),0),"") | K11: =IFERROR(VLOOKUP($D11,환율,MATCH(K$1,변수H,0),0),"") | L11: =IFERROR(VLOOKUP($D11,환율,MATCH(L$1,변수H,0),0),"") | ... O11: =IFERROR(VLOOKUP($D11,환율,MATCH(O$1,변수H,0),0),"")
A12: W/Euro(기말) QoQ | F12: =IFERROR(F11/E11-1,"") | G12: =IFERROR(G11/F11-1,"") | H12: =IFERROR(H11/G11-1,"") | I12: =IFERROR(I11/H11-1,"") | J12: =IFERROR(J11/I11-1,"") | K12: =IFERROR(K11/J11-1,"") | L12: =IFERROR(L11/K11-1,"") | M12: =IFERROR(M11/L11-1,"") | ... O12: =IFERROR(O11/N11-1,"")
D13: 원/100Y(기말) | E13: =IFERROR(VLOOKUP($D13,환율,MATCH(E$1,변수H,0),0),"") | F13: =IFERROR(VLOOKUP($D13,환율,MATCH(F$1,변수H,0),0),"") | G13: =IFERROR(VLOOKUP($D13,환율,MATCH(G$1,변수H,0),0),"") | H13: =IFERROR(VLOOKUP($D13,환율,MATCH(H$1,변수H,0),0),"") | I13: =IFERROR(VLOOKUP($D13,환율,MATCH(I$1,변수H,0),0),"") | J13: =IFERROR(VLOOKUP($D13,환율,MATCH(J$1,변수H,0),0),"") | K13: =IFERROR(VLOOKUP($D13,환율,MATCH(K$1,변수H,0),0),"") | L13: =IFERROR(VLOOKUP($D13,환율,MATCH(L$1,변수H,0),0),"") | ... O13: =IFERROR(VLOOKUP($D13,환율,MATCH(O$1,변수H,0),0),"")
A14: 원/100Y(기말) QoQ | F14: =IFERROR(F13/E13-1,"") | G14: =IFERROR(G13/F13-1,"") | H14: =IFERROR(H13/G13-1,"") | I14: =IFERROR(I13/H13-1,"") | J14: =IFERROR(J13/I13-1,"") | K14: =IFERROR(K13/J13-1,"") | L14: =IFERROR(L13/K13-1,"") | M14: =IFERROR(M13/L13-1,"") | ... O14: =IFERROR(O13/N13-1,"")
A16: 외화순노출 | C16: 외화 순노출(백만$) | D16: =변수!D54 | E16: 외화 순노출 × Δ기말환율 (외화 시트 방식)
A17: 환관련손익추정 | C17: 환관련손익 추정(억원) = 순노출 × Δ원/달러(기말) / 100 | F17: =IFERROR($D$16*(F7-E7)/100,"") | G17: =IFERROR($D$16*(G7-F7)/100,"") | H17: =IFERROR($D$16*(H7-G7)/100,"") | I17: =IFERROR($D$16*(I7-H7)/100,"") | J17: =IFERROR($D$16*(J7-I7)/100,"") | K17: =IFERROR($D$16*(K7-J7)/100,"") | L17: =IFERROR($D$16*(L7-K7)/100,"") | M17: =IFERROR($D$16*(M7-L7)/100,"") | ... O17: =IFERROR($D$16*(O7-N7)/100,"")
A18: fx_pnl.by_q | C18: 모델 fx_pnl.by_q(억원, 참고)
C19: 외화 순노출 미공시(face) → 0 + 표기
